Workbook

Sheet Executive Summary
A1: PRIV-CHK-A.2.3.2 — PII Principal Obligations (Processor) Compliance Checklist
A3: DOCUMENT INFORMATION
A4: Document ID | B4: PRIV-CHK-A.2.3.2
A5: Source Policy | B5: PRIV-POL-A.2.3.2
A6: ISO Controls | B6: PII Principal Obligations (Processor)
A7: Generated | B7: 10.03.2026
A8: Prepared By
A9: Organisation
A10: Review Cycle | B10: Annual
A12: OVERALL COMPLIANCE STATUS
A13: Overall Compliance | B13: ='Dashboard'!G7
A14: Status | B14: =IF(Dashboard!G7="N/A","NOT ASSESSED",IF(ISNUMBER(VALUE(SUBSTITUTE(Dashboard!G7,"%",""))),IF(VALUE(SUBSTITUTE(Dashboard!G7,"%",""))>=90,"GREEN",IF(VALUE(SUBSTITUTE(Dashboard!G7,"%",""))>=70,"AMBER","RED")),"NOT ASSESSED"))
A16: KEY METRICS
A17: Total Requirements | B17: ='Dashboard'!B7
A18: Compliant | B18: ='Dashboard'!C7
A19: Partial | B19: ='Dashboard'!D7
A20: Non-Compliant | B20: ='Dashboard'!E7
A21: Not Applicable | B21: ='Dashboard'!F7
A22: Owner Coverage | B22: =IF(Dashboard!B7=0,"N/A",ROUND((COUNTA('Rights Fulfilment Capabilities'!F4:F8)+COUNTA('Request Handling and Notification'!F4:F7)+COUNTA('Evidence and Demonstrability'!F4:F6))/Dashboard!B7*100,0)&"%")
A24: DOMAIN STATUS SUMMARY
A25: Domain | B25: Compliance % | C25: Compliant | D25: Gaps | E25: Status
A26: Rights Fulfilment Capabilities | B26: ='Dashboard'!G4 | C26: ='Dashboard'!C4 | D26: ='Dashboard'!E4 | E26: =IF(Dashboard!G4="N/A","--",IF(ISNUMBER(VALUE(SUBSTITUTE(Dashboard!G4,"%",""))),IF(VALUE(SUBSTITUTE(Dashboard!G4,"%",""))>=90,"PASS",IF(VALUE(SUBSTITUTE(Dashboard!G4,"%",""))>=70,"REVIEW","FAIL")),"--"))
A27: Request Handling and Notification | B27: ='Dashboard'!G5 | C27: ='Dashboard'!C5 | D27: ='Dashboard'!E5 | E27: =IF(Dashboard!G5="N/A","--",IF(ISNUMBER(VALUE(SUBSTITUTE(Dashboard!G5,"%",""))),IF(VALUE(SUBSTITUTE(Dashboard!G5,"%",""))>=90,"PASS",IF(VALUE(SUBSTITUTE(Dashboard!G5,"%",""))>=70,"REVIEW","FAIL")),"--"))
A28: Evidence and Demonstrability | B28: ='Dashboard'!G6 | C28: ='Dashboard'!C6 | D28: ='Dashboard'!E6 | E28: =IF(Dashboard!G6="N/A","--",IF(ISNUMBER(VALUE(SUBSTITUTE(Dashboard!G6,"%",""))),IF(VALUE(SUBSTITUTE(Dashboard!G6,"%",""))>=90,"PASS",IF(VALUE(SUBSTITUTE(Dashboard!G6,"%",""))>=70,"REVIEW","FAIL")),"--"))
A30: CRITICAL ISSUES
A31: # | B31: Issue Description | C31: Domain | D31: Owner | E31: Due Date
A32: 1
A33: 2
A34: 3
A35: 4
A36: 5
A38: MANAGEMENT COMMENTARY
A39: [Enter management commentary on pii principal obligations (processor) posture]
A43: APPROVAL
A44: Assessed By
A45: Name:
A46: Date:
A47: Signature:
A48: Decision:
A50: Reviewed By (DPO)
...

Sheet Dashboard
A1: PII Principal Obligations (Processor) — Compliance Dashboard
A3: Domain | B3: Total Reqs | C3: Compliant | D3: Partial | E3: Non-Compliant | F3: N/A | G3: Compliance %
A4: Rights Fulfilment Capabilities | B4: =COUNTA('Rights Fulfilment Capabilities'!D4:D8) | C4: =COUNTIF('Rights Fulfilment Capabilities'!D4:D8,"Compliant") | D4: =COUNTIF('Rights Fulfilment Capabilities'!D4:D8,"Partial") | E4: =COUNTIF('Rights Fulfilment Capabilities'!D4:D8,"Non-Compliant") | F4: =COUNTIF('Rights Fulfilment Capabilities'!D4:D8,"N/A") | G4: =IF((B4-F4)=0,"N/A",ROUND(C4/(B4-F4)*100,1)&"%")
A5: Request Handling and Notification | B5: =COUNTA('Request Handling and Notification'!D4:D7) | C5: =COUNTIF('Request Handling and Notification'!D4:D7,"Compliant") | D5: =COUNTIF('Request Handling and Notification'!D4:D7,"Partial") | E5: =COUNTIF('Request Handling and Notification'!D4:D7,"Non-Compliant") | F5: =COUNTIF('Request Handling and Notification'!D4:D7,"N/A") | G5: =IF((B5-F5)=0,"N/A",ROUND(C5/(B5-F5)*100,1)&"%")
A6: Evidence and Demonstrability | B6: =COUNTA('Evidence and Demonstrability'!D4:D6) | C6: =COUNTIF('Evidence and Demonstrability'!D4:D6,"Compliant") | D6: =COUNTIF('Evidence and Demonstrability'!D4:D6,"Partial") | E6: =COUNTIF('Evidence and Demonstrability'!D4:D6,"Non-Compliant") | F6: =COUNTIF('Evidence and Demonstrability'!D4:D6,"N/A") | G6: =IF((B6-F6)=0,"N/A",ROUND(C6/(B6-F6)*100,1)&"%")
A7: TOTAL | B7: =SUM(B4:B6) | C7: =SUM(C4:C6) | D7: =SUM(D4:D6) | E7: =SUM(E4:E6) | F7: =SUM(F4:F6) | G7: =IF((B7-F7)=0,"N/A",ROUND(C7/(B7-F7)*100,1)&"%")
A9: COMPLIANCE BY STATUS
A10: Compliant | B10: =C7 | C10: =IF(B7=0,"",ROUND(B10/B7*100,1)&"%")
A11: Partial | B11: =D7 | C11: =IF(B7=0,"",ROUND(B11/B7*100,1)&"%")
A12: Non-Compliant | B12: =E7 | C12: =IF(B7=0,"",ROUND(B12/B7*100,1)&"%")
A13: N/A | B13: =F7 | C13: =IF(B7=0,"",ROUND(B13/B7*100,1)&"%")
A15: TOP GAPS (Manual Entry)
A16: Priority | B16: Domain | C16: Requirement | D16: Owner | E16: Due Date | F16: Status
A28: COMPLIANCE TREND (Manual Entry)
A29: Assessment Date | B29: Overall % | C29: Compliant | D29: Gaps | E29: Assessor | F29: Notes

Sheet Rights Fulfilment Capabilities
A1: Rights Fulfilment Capabilities — Compliance Checklist
A2: ISO/IEC 27701:2025 — Controls A.2.3.2: PII Principal Obligations (Processor)
A3: Req # | B3: Section | C3: Requirement | D3: Status | E3: Evidence | F3: Owner | G3: Due Date | H3: Notes
A4: A.2.3.2-01 | B4: Proactive Capability Obligation | C4: The organisation shall provide customers with the means to comply with their obligations to PII principals (data subjects). This obligation is proactive — the organisation has a duty to ensure the means are available regardless of whether the customer explicitly requests assistance.
A5: A.2.3.2-02 | B5: Access and Portability | C5: The organisation shall make available the capability to retrieve all PII held for a specific data subject in a structured, commonly used, and machine-readable format upon customer instruction, to support customer fulfilment of access and portability rights.
A6: A.2.3.2-03 | B6: Rectification and Erasure | C6: The organisation shall make available the capability to: update or correct PII for a specific data subject (rectification) upon customer instruction; and delete all PII for a specific data subject across all systems (including backups, within the agreed timeframe) upon customer instruction.
A7: A.2.3.2-04 | B7: Restriction and Objection | C7: The organisation shall make available the capability to: mark specific data subjects' PII as restricted, ensuring no further processing occurs (storage only), upon customer instruction; and cease processing specific data subjects' PII for specified purposes upon customer instruction.
A8: A.2.3.2-05 | B8: Capability Timeframes | C8: Rights fulfilment capabilities shall be available within the timeframe required for the customer to meet their regulatory obligations — typically within the applicable response window less reasonable lead time. Capability response times shall be defined in the processor agreement.

Sheet Request Handling and Notification
A1: Request Handling and Notification — Compliance Checklist
A2: ISO/IEC 27701:2025 — Controls A.2.3.2: PII Principal Obligations (Processor)
A3: Req # | B3: Section | C3: Requirement | D3: Status | E3: Evidence | F3: Owner | G3: Due Date | H3: Notes
A4: A.2.3.2-06 | B4: Capability Documentation | C4: The means to fulfil data subject rights shall be documented in PRIV-IMP-A.2.3.2-TG, specifying how each capability is accessed and invoked by the customer. The documentation shall be kept current and made available to customers on request.
A5: A.2.3.2-07 | B5: Contractual Commitment | C5: Data subject rights assistance capabilities shall be maintained as a contractual commitment in processor agreements per PRIV-POL-A.2.2.2-7. The processor agreement shall specify response timeframes for each rights fulfilment type.
A6: A.2.3.2-08 | B6: Forwarding Direct Requests | C6: The organisation shall forward to the customer, without undue delay, any data subject rights requests received directly (e.g. a data subject contacting the organisation directly). The organisation shall not respond directly to data subject rights requests without explicit customer authorisation.
A7: A.2.3.2-09 | B7: Customer Request Log | C7: All customer instructions for data subject rights fulfilment shall be logged with: customer identity; request type; date received; fulfilment date; and outcome. The log shall be retained for 5 years.

Sheet Evidence and Demonstrability
A1: Evidence and Demonstrability — Compliance Checklist
A2: ISO/IEC 27701:2025 — Controls A.2.3.2: PII Principal Obligations (Processor)
A3: Req # | B3: Section | C3: Requirement | D3: Status | E3: Evidence | F3: Owner | G3: Due Date | H3: Notes
A4: A.2.3.2-10 | B4: Technical Capability Evidence | C4: The organisation shall maintain technical documentation demonstrating that access, rectification, erasure, restriction, and objection capabilities are operational and tested. Documentation shall be current and reflect the actual state of capabilities.
A5: A.2.3.2-11 | B5: Agreement Clauses | C5: Processor agreements shall contain the Article 28(3)(e) assistance commitment. The DPO shall verify this commitment is present in all agreements before execution and flag any gaps for remediation.
A6: A.2.3.2-12 | B6: Capability Review | C6: Data subject rights fulfilment capabilities shall be reviewed and tested at minimum annually and whenever material changes are made to systems processing customer PII, to confirm capabilities remain operational and within required timeframes.
