Workbook

Sheet Executive Summary
A1: ISMS-OP-CHK-A.8.23 — Web Filtering Compliance Checklist
A3: DOCUMENT INFORMATION
A4: Document ID | B4: ISMS-OP-CHK-A.8.23
A5: Source Policy | B5: ISMS-OP-POL-A.8.23
A6: ISO Controls | B6: Web Filtering
A7: Generated | B7: 08.02.2026
A8: Prepared By
A9: Organisation
A10: Review Cycle | B10: Annual
A12: OVERALL COMPLIANCE STATUS
A13: Overall Compliance | B13: ='Dashboard'!G13
A14: Status | B14: =IF(Dashboard!G13="N/A","NOT ASSESSED",IF(ISNUMBER(VALUE(SUBSTITUTE(Dashboard!G13,"%",""))),IF(VALUE(SUBSTITUTE(Dashboard!G13,"%",""))>=90,"GREEN",IF(VALUE(SUBSTITUTE(Dashboard!G13,"%",""))>=70,"AMBER","RED")),"NOT ASSESSED"))
A16: KEY METRICS
A17: Total Requirements | B17: ='Dashboard'!B13
A18: Compliant | B18: ='Dashboard'!C13
A19: Partial | B19: ='Dashboard'!D13
A20: Non-Compliant | B20: ='Dashboard'!E13
A21: Not Applicable | B21: ='Dashboard'!F13
A22: Owner Coverage | B22: =IF(Dashboard!B13=0,"N/A",ROUND((COUNTA('Web Filtering Architecture'!F4:F14)+COUNTA('URL Categorisation & Filtering'!F4:F8)+COUNTA('TLS Inspection'!F4:F8)+COUNTA('Threat Intelligence Integration'!F4:F7)+COUNTA('Exception and Override Process'!F4:F8)+COUNTA('Remote Worker & BYOD'!F4:F8)+COUNTA('Employee Privacy & Web'!F4:F10)+COUNTA('Testing & Validation'!F4:F5)+COUNTA('Metrics & Mgmt Reporting'!F4:F4))/Dashboard!B13*100,0)&"%")
A24: DOMAIN STATUS SUMMARY
A25: Domain | B25: Compliance % | C25: Compliant | D25: Gaps | E25: Status
A26: Web Filtering Architecture | B26: ='Dashboard'!G4 | C26: ='Dashboard'!C4 | D26: ='Dashboard'!E4 | E26: =IF(Dashboard!G4="N/A","--",IF(ISNUMBER(VALUE(SUBSTITUTE(Dashboard!G4,"%",""))),IF(VALUE(SUBSTITUTE(Dashboard!G4,"%",""))>=90,"PASS",IF(VALUE(SUBSTITUTE(Dashboard!G4,"%",""))>=70,"REVIEW","FAIL")),"--"))
A27: URL Categorisation & Filtering | B27: ='Dashboard'!G5 | C27: ='Dashboard'!C5 | D27: ='Dashboard'!E5 | E27: =IF(Dashboard!G5="N/A","--",IF(ISNUMBER(VALUE(SUBSTITUTE(Dashboard!G5,"%",""))),IF(VALUE(SUBSTITUTE(Dashboard!G5,"%",""))>=90,"PASS",IF(VALUE(SUBSTITUTE(Dashboard!G5,"%",""))>=70,"REVIEW","FAIL")),"--"))
A28: TLS Inspection | B28: ='Dashboard'!G6 | C28: ='Dashboard'!C6 | D28: ='Dashboard'!E6 | E28: =IF(Dashboard!G6="N/A","--",IF(ISNUMBER(VALUE(SUBSTITUTE(Dashboard!G6,"%",""))),IF(VALUE(SUBSTITUTE(Dashboard!G6,"%",""))>=90,"PASS",IF(VALUE(SUBSTITUTE(Dashboard!G6,"%",""))>=70,"REVIEW","FAIL")),"--"))
A29: Threat Intelligence Integration | B29: ='Dashboard'!G7 | C29: ='Dashboard'!C7 | D29: ='Dashboard'!E7 | E29: =IF(Dashboard!G7="N/A","--",IF(ISNUMBER(VALUE(SUBSTITUTE(Dashboard!G7,"%",""))),IF(VALUE(SUBSTITUTE(Dashboard!G7,"%",""))>=90,"PASS",IF(VALUE(SUBSTITUTE(Dashboard!G7,"%",""))>=70,"REVIEW","FAIL")),"--"))
A30: Exception and Override Process | B30: ='Dashboard'!G8 | C30: ='Dashboard'!C8 | D30: ='Dashboard'!E8 | E30: =IF(Dashboard!G8="N/A","--",IF(ISNUMBER(VALUE(SUBSTITUTE(Dashboard!G8,"%",""))),IF(VALUE(SUBSTITUTE(Dashboard!G8,"%",""))>=90,"PASS",IF(VALUE(SUBSTITUTE(Dashboard!G8,"%",""))>=70,"REVIEW","FAIL")),"--"))
A31: Remote Worker & BYOD | B31: ='Dashboard'!G9 | C31: ='Dashboard'!C9 | D31: ='Dashboard'!E9 | E31: =IF(Dashboard!G9="N/A","--",IF(ISNUMBER(VALUE(SUBSTITUTE(Dashboard!G9,"%",""))),IF(VALUE(SUBSTITUTE(Dashboard!G9,"%",""))>=90,"PASS",IF(VALUE(SUBSTITUTE(Dashboard!G9,"%",""))>=70,"REVIEW","FAIL")),"--"))
A32: Employee Privacy & Web | B32: ='Dashboard'!G10 | C32: ='Dashboard'!C10 | D32: ='Dashboard'!E10 | E32: =IF(Dashboard!G10="N/A","--",IF(ISNUMBER(VALUE(SUBSTITUTE(Dashboard!G10,"%",""))),IF(VALUE(SUBSTITUTE(Dashboard!G10,"%",""))>=90,"PASS",IF(VALUE(SUBSTITUTE(Dashboard!G10,"%",""))>=70,"REVIEW","FAIL")),"--"))
A33: Testing & Validation | B33: ='Dashboard'!G11 | C33: ='Dashboard'!C11 | D33: ='Dashboard'!E11 | E33: =IF(Dashboard!G11="N/A","--",IF(ISNUMBER(VALUE(SUBSTITUTE(Dashboard!G11,"%",""))),IF(VALUE(SUBSTITUTE(Dashboard!G11,"%",""))>=90,"PASS",IF(VALUE(SUBSTITUTE(Dashboard!G11,"%",""))>=70,"REVIEW","FAIL")),"--"))
A34: Metrics & Mgmt Reporting | B34: ='Dashboard'!G12 | C34: ='Dashboard'!C12 | D34: ='Dashboard'!E12 | E34: =IF(Dashboard!G12="N/A","--",IF(ISNUMBER(VALUE(SUBSTITUTE(Dashboard!G12,"%",""))),IF(VALUE(SUBSTITUTE(Dashboard!G12,"%",""))>=90,"PASS",IF(VALUE(SUBSTITUTE(Dashboard!G12,"%",""))>=70,"REVIEW","FAIL")),"--"))
A36: CRITICAL ISSUES
A37: # | B37: Issue Description | C37: Domain | D37: Owner | E37: Due Date
A38: 1
A39: 2
A40: 3
A41: 4
A42: 5
A44: MANAGEMENT COMMENTARY
A45: [Enter management commentary on web filtering posture]
A49: APPROVAL
...

Sheet Dashboard
A1: Web Filtering — Compliance Dashboard
A3: Domain | B3: Total Reqs | C3: Compliant | D3: Partial | E3: Non-Compliant | F3: N/A | G3: Compliance %
A4: Web Filtering Architecture | B4: =COUNTA('Web Filtering Architecture'!D4:D14) | C4: =COUNTIF('Web Filtering Architecture'!D4:D14,"Compliant") | D4: =COUNTIF('Web Filtering Architecture'!D4:D14,"Partial") | E4: =COUNTIF('Web Filtering Architecture'!D4:D14,"Non-Compliant") | F4: =COUNTIF('Web Filtering Architecture'!D4:D14,"N/A") | G4: =IF((B4-F4)=0,"N/A",ROUND(C4/(B4-F4)*100,1)&"%")
A5: URL Categorisation & Filtering | B5: =COUNTA('URL Categorisation & Filtering'!D4:D8) | C5: =COUNTIF('URL Categorisation & Filtering'!D4:D8,"Compliant") | D5: =COUNTIF('URL Categorisation & Filtering'!D4:D8,"Partial") | E5: =COUNTIF('URL Categorisation & Filtering'!D4:D8,"Non-Compliant") | F5: =COUNTIF('URL Categorisation & Filtering'!D4:D8,"N/A") | G5: =IF((B5-F5)=0,"N/A",ROUND(C5/(B5-F5)*100,1)&"%")
A6: TLS Inspection | B6: =COUNTA('TLS Inspection'!D4:D8) | C6: =COUNTIF('TLS Inspection'!D4:D8,"Compliant") | D6: =COUNTIF('TLS Inspection'!D4:D8,"Partial") | E6: =COUNTIF('TLS Inspection'!D4:D8,"Non-Compliant") | F6: =COUNTIF('TLS Inspection'!D4:D8,"N/A") | G6: =IF((B6-F6)=0,"N/A",ROUND(C6/(B6-F6)*100,1)&"%")
A7: Threat Intelligence Integration | B7: =COUNTA('Threat Intelligence Integration'!D4:D7) | C7: =COUNTIF('Threat Intelligence Integration'!D4:D7,"Compliant") | D7: =COUNTIF('Threat Intelligence Integration'!D4:D7,"Partial") | E7: =COUNTIF('Threat Intelligence Integration'!D4:D7,"Non-Compliant") | F7: =COUNTIF('Threat Intelligence Integration'!D4:D7,"N/A") | G7: =IF((B7-F7)=0,"N/A",ROUND(C7/(B7-F7)*100,1)&"%")
A8: Exception and Override Process | B8: =COUNTA('Exception and Override Process'!D4:D8) | C8: =COUNTIF('Exception and Override Process'!D4:D8,"Compliant") | D8: =COUNTIF('Exception and Override Process'!D4:D8,"Partial") | E8: =COUNTIF('Exception and Override Process'!D4:D8,"Non-Compliant") | F8: =COUNTIF('Exception and Override Process'!D4:D8,"N/A") | G8: =IF((B8-F8)=0,"N/A",ROUND(C8/(B8-F8)*100,1)&"%")
A9: Remote Worker & BYOD | B9: =COUNTA('Remote Worker & BYOD'!D4:D8) | C9: =COUNTIF('Remote Worker & BYOD'!D4:D8,"Compliant") | D9: =COUNTIF('Remote Worker & BYOD'!D4:D8,"Partial") | E9: =COUNTIF('Remote Worker & BYOD'!D4:D8,"Non-Compliant") | F9: =COUNTIF('Remote Worker & BYOD'!D4:D8,"N/A") | G9: =IF((B9-F9)=0,"N/A",ROUND(C9/(B9-F9)*100,1)&"%")
A10: Employee Privacy & Web | B10: =COUNTA('Employee Privacy & Web'!D4:D10) | C10: =COUNTIF('Employee Privacy & Web'!D4:D10,"Compliant") | D10: =COUNTIF('Employee Privacy & Web'!D4:D10,"Partial") | E10: =COUNTIF('Employee Privacy & Web'!D4:D10,"Non-Compliant") | F10: =COUNTIF('Employee Privacy & Web'!D4:D10,"N/A") | G10: =IF((B10-F10)=0,"N/A",ROUND(C10/(B10-F10)*100,1)&"%")
A11: Testing & Validation | B11: =COUNTA('Testing & Validation'!D4:D5) | C11: =COUNTIF('Testing & Validation'!D4:D5,"Compliant") | D11: =COUNTIF('Testing & Validation'!D4:D5,"Partial") | E11: =COUNTIF('Testing & Validation'!D4:D5,"Non-Compliant") | F11: =COUNTIF('Testing & Validation'!D4:D5,"N/A") | G11: =IF((B11-F11)=0,"N/A",ROUND(C11/(B11-F11)*100,1)&"%")
A12: Metrics & Mgmt Reporting | B12: =COUNTA('Metrics & Mgmt Reporting'!D4:D4) | C12: =COUNTIF('Metrics & Mgmt Reporting'!D4:D4,"Compliant") | D12: =COUNTIF('Metrics & Mgmt Reporting'!D4:D4,"Partial") | E12: =COUNTIF('Metrics & Mgmt Reporting'!D4:D4,"Non-Compliant") | F12: =COUNTIF('Metrics & Mgmt Reporting'!D4:D4,"N/A") | G12: =IF((B12-F12)=0,"N/A",ROUND(C12/(B12-F12)*100,1)&"%")
A13: TOTAL | B13: =SUM(B4:B12) | C13: =SUM(C4:C12) | D13: =SUM(D4:D12) | E13: =SUM(E4:E12) | F13: =SUM(F4:F12) | G13: =IF((B13-F13)=0,"N/A",ROUND(C13/(B13-F13)*100,1)&"%")
A15: COMPLIANCE BY STATUS
A16: Compliant | B16: =C13 | C16: =IF(B13=0,"",ROUND(B16/B13*100,1)&"%")
A17: Partial | B17: =D13 | C17: =IF(B13=0,"",ROUND(B17/B13*100,1)&"%")
A18: Non-Compliant | B18: =E13 | C18: =IF(B13=0,"",ROUND(B18/B13*100,1)&"%")
A19: N/A | B19: =F13 | C19: =IF(B13=0,"",ROUND(B19/B13*100,1)&"%")
A21: TOP GAPS (Manual Entry)
A22: Priority | B22: Domain | C22: Requirement | D22: Owner | E22: Due Date | F22: Status
A34: COMPLIANCE TREND (Manual Entry)
A35: Assessment Date | B35: Overall % | C35: Compliant | D35: Gaps | E35: Assessor | F35: Notes

Sheet Web Filtering Architecture
A1: Web Filtering Architecture — Compliance Checklist
A2: ISO/IEC 27001:2022 — Control A.8.23: Web Filtering
A3: Req # | B3: Section | C3: Requirement | D3: Status | E3: Evidence | F3: Owner | G3: Due Date | H3: Notes
A4: A.8.23-01 | B4: Implement Web Filtering Using One Or | C4: The organisation shall implement web filtering using one or more of the following technologies:.
A5: A.8.23-02 | B5: Dns Filtering | C5: DNS filtering shall be enforced on all managed devices as the baseline. Direct DNS queries to external resolvers (including DNS over HTTPS (DoH) and DNS over TLS (DoT) to non-approved resolvers) shall be blocked at the firewall to prevent filter bypass.
A6: A.8.23-03 | B6: The Web Filtering Platform | C6: The web filtering platform shall meet the following service level objectives:.
A7: A.8.23-04 | B7: It Operations | C7: If the filtering platform experiences sustained degradation exceeding SLO thresholds, IT Operations shall implement the documented incident response procedure. Fail-open (allowing unfiltered traffic) is permitted only as a temporary measure during platform failure and shall be logged, reported to the CISO, and remediated within 4 hours.
A8: A.8.23-05 | B8: Changes To Web Filtering Configuration | C8: Changes to web filtering configuration (category policies, block/allow lists, TLS inspection settings, deployment architecture) shall follow the organisation's change management process:.
A9: A.8.23-06 | B9: Emergency Changes (E.G., Blocking An | C9: Emergency changes (e.g., blocking an active phishing campaign) may bypass standard approval but shall be retrospectively documented within 24 hours.
A10: A.8.23-07 | B10: The Vendor | C10: The vendor shall be included in the organisation's vendor risk management programme.
A11: A.8.23-08 | B11: Soc 2 Type Ii Report Or | C11: SOC 2 Type II report or ISO 27001 certification shall be reviewed annually.
A12: A.8.23-09 | B12: Sla Compliance (Availability, Latency, | C12: SLA compliance (availability, latency, threat detection rate, support response time) shall be monitored against contractual thresholds.
A13: A.8.23-10 | B13: Data Processing Agreements | C13: Data processing agreements shall address: employee browsing data handling, data residency, retention periods, and incident notification.
A14: A.8.23-11 | B14: Vendor Lock-In Risk | C14: Vendor lock-in risk shall be assessed; the organisation shall maintain the ability to migrate to an alternative provider within a reasonable timeframe.

Sheet URL Categorisation & Filtering
A1: URL Categorisation & Filtering — Compliance Checklist
A2: ISO/IEC 27001:2022 — Control A.8.23: Web Filtering
A3: Req # | B3: Section | C3: Requirement | D3: Status | E3: Evidence | F3: Owner | G3: Due Date | H3: Notes
A4: A.8.23-12 | B4: The Following Categories | C4: The following categories shall be blocked for all users without exception:.
A5: A.8.23-13 | B5: The Following Categories | C5: The following categories shall be blocked unless an approved exception exists:.
A6: A.8.23-14 | B6: The Following Categories | C6: The following categories shall not be filtered or restricted:.
A7: A.8.23-15 | B7: Websites Not Categorised By The | C7: Websites not categorised by the filtering solution shall be handled as follows:.
A8: A.8.23-16 | B8: Access To Uncategorised Sites | C8: All access to uncategorised sites shall be logged for security review.

Sheet TLS Inspection
A1: TLS Inspection — Compliance Checklist
A2: ISO/IEC 27001:2022 — Control A.8.23: Web Filtering
A3: Req # | B3: Section | C3: Requirement | D3: Status | E3: Evidence | F3: Owner | G3: Due Date | H3: Notes
A4: A.8.23-17 | B4: The Following Categories | C4: The following categories shall be excluded from TLS inspection to protect privacy and avoid technical issues:.
A5: A.8.23-18 | B5: Be Informed In Advance That Encrypted | C5: Employees shall be informed in advance that encrypted web traffic may be decrypted and inspected for security purposes.
A6: A.8.23-19 | B6: The Acceptable Use Policy | C6: The acceptable use policy shall document TLS inspection and its purpose.
A7: A.8.23-20 | B7: Tls Inspection Data | C7: TLS inspection data shall be processed only for security purposes (malware detection, data leakage prevention, policy enforcement) — not for behavioural monitoring.
A8: A.8.23-21 | B8: Byod And Guest Network Traffic | C8: BYOD and guest network traffic shall not be subject to TLS inspection.

Sheet Threat Intelligence Integration
A1: Threat Intelligence Integration — Compliance Checklist
A2: ISO/IEC 27001:2022 — Control A.8.23: Web Filtering
A3: Req # | B3: Section | C3: Requirement | D3: Status | E3: Evidence | F3: Owner | G3: Due Date | H3: Notes
A4: A.8.23-22 | B4: Web Filtering Block Lists | C4: Web filtering block lists shall be updated using threat intelligence from multiple sources:.
A5: A.8.23-23 | B5: Employee-Reported Phishing Urls | C5: Employee-reported phishing URLs shall be assessed and added to the block list within 4 hours during business hours.
A6: A.8.23-24 | B6: Phishing Simulation Urls | C6: Phishing simulation URLs shall be excluded from web filtering during testing campaigns (coordinated between Information Security and IT Operations).
A7: A.8.23-25 | B7: Web Filtering Events | C7: Web filtering events shall be integrated with the organisation's incident management process (A.5.24-28). The following thresholds shall trigger incident creation:.

Sheet Exception and Override Process
A1: Exception and Override Process — Compliance Checklist
A2: ISO/IEC 27001:2022 — Control A.8.23: Web Filtering
A3: Req # | B3: Section | C3: Requirement | D3: Status | E3: Evidence | F3: Owner | G3: Due Date | H3: Notes
A4: A.8.23-26 | B4: Be Reviewed Quarterly By It Security | C4: All exceptions shall be reviewed quarterly by IT Security.
A5: A.8.23-27 | B5: Expired Exceptions | C5: Expired exceptions shall be automatically revoked.
A6: A.8.23-28 | B6: Unused Exceptions (No Access Recorded In | C6: Unused exceptions (no access recorded in 90 days) shall be removed.
A7: A.8.23-29 | B7: The Total Number Of Active Exceptions | C7: The total number of active exceptions shall be reported to the CISO quarterly.
A8: A.8.23-30 | B8: Be The Minimum Scope Needed: Specific | C8: Exceptions shall be the minimum scope needed: specific URL preferred over full domain; domain preferred over entire category.

Sheet Remote Worker & BYOD
A1: Remote Worker & BYOD — Compliance Checklist
A2: ISO/IEC 27001:2022 — Control A.8.23: Web Filtering
A3: Req # | B3: Section | C3: Requirement | D3: Status | E3: Evidence | F3: Owner | G3: Due Date | H3: Notes
A4: A.8.23-31 | B4: Cloud-Delivered Swg Or Dns Filtering | C4: Cloud-delivered SWG or DNS filtering agent shall be installed on all managed endpoints.
A5: A.8.23-32 | B5: Web Filtering Policies | C5: Web filtering policies shall apply consistently whether the user is on the corporate network, home Wi-Fi, mobile hotspot, or public network.
A6: A.8.23-33 | B6: Split Tunnelling (Vpn) | C6: Split tunnelling (VPN) shall not bypass web filtering; web traffic shall be routed through the filtering solution regardless of VPN configuration.
A7: A.8.23-34 | B7: Tls Inspection | C7: TLS inspection shall not be performed on personal devices (privacy and legal constraints).
A8: A.8.23-35 | B8: Separate, Less Intrusive Filtering | C8: Separate, less intrusive filtering policies shall apply to BYOD compared to corporate-managed devices.

Sheet Employee Privacy & Web
A1: Employee Privacy & Web — Compliance Checklist
A2: ISO/IEC 27001:2022 — Control A.8.23: Web Filtering
A3: Req # | B3: Section | C3: Requirement | D3: Status | E3: Evidence | F3: Owner | G3: Due Date | H3: Notes
A4: A.8.23-36 | B4: Web Filtering That Processes Employee | C4: Web filtering that processes employee browsing data shall comply with Swiss employment law:.
A5: A.8.23-37 | B5: Argv3 Art. 26: Web Filtering Systems | C5: ArGV3 Art. 26: Web filtering systems shall not be used primarily to monitor employee behaviour. Their purpose is security (malware prevention, data leakage prevention, policy enforcement).
A6: A.8.23-38 | B6: Co Art. 328B: Processing Of Employee | C6: CO Art. 328b: Processing of employee web browsing data shall be proportional and limited to security purposes.
A7: A.8.23-39 | B7: Transparency: Employees | C7: Transparency: Employees shall be informed that web filtering is in place, what categories are filtered, and that access to blocked sites is logged. This information shall be included in the acceptable use policy and employment documentation.
A8: A.8.23-40 | B8: Non-Personalised Monitoring By Default: | C8: Non-personalised monitoring by default: Web filtering logs shall be reviewed in aggregate for security monitoring (e.g., total blocked requests by category, top blocked domains). Individual user browsing activity shall not be reviewed unless:.
A9: A.8.23-41 | B9: Purpose Limitation: Web Filtering Data | C9: Purpose limitation: Web filtering data shall not be used for HR performance evaluation, disciplinary action for non-security matters, or general behavioural profiling.
A10: A.8.23-42 | B10: Data Minimisation: Web Filtering Logs | C10: Data minimisation: Web filtering logs shall be retained only as long as necessary for security purposes (per log retention schedule in the Logging and Monitoring Policy, A.8.15).

Sheet Testing & Validation
A1: Testing & Validation — Compliance Checklist
A2: ISO/IEC 27001:2022 — Control A.8.23: Web Filtering
A3: Req # | B3: Section | C3: Requirement | D3: Status | E3: Evidence | F3: Owner | G3: Due Date | H3: Notes
A4: A.8.23-43 | B4: The Effectiveness Of Web Filtering | C4: The effectiveness of web filtering controls shall be tested on a regular basis:.
A5: A.8.23-44 | B5: Test Results | C5: Test results shall be documented and remediation actions tracked for any identified weaknesses.

Sheet Metrics & Mgmt Reporting
A1: Metrics & Mgmt Reporting — Compliance Checklist
A2: ISO/IEC 27001:2022 — Control A.8.23: Web Filtering
A3: Req # | B3: Section | C3: Requirement | D3: Status | E3: Evidence | F3: Owner | G3: Due Date | H3: Notes
A4: A.8.23-45 | B4: The Following Metrics | C4: The following metrics shall be reported:.
