Workbook

Sheet Executive Summary
A1: ISMS-OP-CHK-A.8.4 — Access to Source Code Compliance Checklist
A3: DOCUMENT INFORMATION
A4: Document ID | B4: ISMS-OP-CHK-A.8.4
A5: Source Policy | B5: ISMS-OP-POL-A.8.4
A6: ISO Controls | B6: Access to Source Code
A7: Generated | B7: 30.09.2026
A8: Prepared By
A9: Organisation
A10: Review Cycle | B10: Annual
A12: OVERALL COMPLIANCE STATUS
A13: Overall Compliance | B13: ='Dashboard'!G15
A14: Status | B14: =IF(Dashboard!H15>0,"INCOMPLETE",IF(Dashboard!G15="N/A","NOT ASSESSED",IF(ISNUMBER(VALUE(SUBSTITUTE(Dashboard!G15,"%",""))),IF(VALUE(SUBSTITUTE(Dashboard!G15,"%",""))>=90,"GREEN",IF(VALUE(SUBSTITUTE(Dashboard!G15,"%",""))>=70,"AMBER","RED")),"NOT ASSESSED")))
A16: KEY METRICS
A17: Total Requirements | B17: ='Dashboard'!B15
A18: Compliant | B18: ='Dashboard'!C15
A19: Partial | B19: ='Dashboard'!D15
A20: Non-Compliant | B20: ='Dashboard'!E15
A21: Not Applicable | B21: ='Dashboard'!F15
A22: Unanswered | B22: ='Dashboard'!H15
A23: Owner Coverage | B23: =IF(Dashboard!B15=0,"N/A",ROUND((COUNTA('Repository Classification'!F4:F8)+COUNTA('Role-Based Access Control'!F4:F5)+COUNTA('Access Request and Approval'!F4:F6)+COUNTA('Access Review & Deprovisioning'!F4:F6)+COUNTA('Branch Prot and Code Review'!F4:F10)+COUNTA('Secret Management'!F4:F9)+COUNTA('Auth and Multi-Factor Auth'!F4:F7)+COUNTA('Audit Logging and Monitoring'!F4:F8)+COUNTA('Backup and Recovery'!F4:F6)+COUNTA('Third-Party Access Management'!F4:F7)+COUNTA('Exception Management'!F4:F6))/Dashboard!B15*100,0)&"%")
A25: DOMAIN STATUS SUMMARY
A26: Domain | B26: Compliance % | C26: Compliant | D26: Gaps | E26: Status
A27: Repository Classification | B27: ='Dashboard'!G4 | C27: ='Dashboard'!C4 | D27: ='Dashboard'!E4 | E27: =IF(Dashboard!H4>0,"INCOMPLETE",IF(Dashboard!G4="N/A","--",IF(ISNUMBER(VALUE(SUBSTITUTE(Dashboard!G4,"%",""))),IF(VALUE(SUBSTITUTE(Dashboard!G4,"%",""))>=90,"PASS",IF(VALUE(SUBSTITUTE(Dashboard!G4,"%",""))>=70,"REVIEW","FAIL")),"--")))
A28: Role-Based Access Control | B28: ='Dashboard'!G5 | C28: ='Dashboard'!C5 | D28: ='Dashboard'!E5 | E28: =IF(Dashboard!H5>0,"INCOMPLETE",IF(Dashboard!G5="N/A","--",IF(ISNUMBER(VALUE(SUBSTITUTE(Dashboard!G5,"%",""))),IF(VALUE(SUBSTITUTE(Dashboard!G5,"%",""))>=90,"PASS",IF(VALUE(SUBSTITUTE(Dashboard!G5,"%",""))>=70,"REVIEW","FAIL")),"--")))
A29: Access Request and Approval | B29: ='Dashboard'!G6 | C29: ='Dashboard'!C6 | D29: ='Dashboard'!E6 | E29: =IF(Dashboard!H6>0,"INCOMPLETE",IF(Dashboard!G6="N/A","--",IF(ISNUMBER(VALUE(SUBSTITUTE(Dashboard!G6,"%",""))),IF(VALUE(SUBSTITUTE(Dashboard!G6,"%",""))>=90,"PASS",IF(VALUE(SUBSTITUTE(Dashboard!G6,"%",""))>=70,"REVIEW","FAIL")),"--")))
A30: Access Review & Deprovisioning | B30: ='Dashboard'!G7 | C30: ='Dashboard'!C7 | D30: ='Dashboard'!E7 | E30: =IF(Dashboard!H7>0,"INCOMPLETE",IF(Dashboard!G7="N/A","--",IF(ISNUMBER(VALUE(SUBSTITUTE(Dashboard!G7,"%",""))),IF(VALUE(SUBSTITUTE(Dashboard!G7,"%",""))>=90,"PASS",IF(VALUE(SUBSTITUTE(Dashboard!G7,"%",""))>=70,"REVIEW","FAIL")),"--")))
A31: Branch Prot and Code Review | B31: ='Dashboard'!G8 | C31: ='Dashboard'!C8 | D31: ='Dashboard'!E8 | E31: =IF(Dashboard!H8>0,"INCOMPLETE",IF(Dashboard!G8="N/A","--",IF(ISNUMBER(VALUE(SUBSTITUTE(Dashboard!G8,"%",""))),IF(VALUE(SUBSTITUTE(Dashboard!G8,"%",""))>=90,"PASS",IF(VALUE(SUBSTITUTE(Dashboard!G8,"%",""))>=70,"REVIEW","FAIL")),"--")))
A32: Secret Management | B32: ='Dashboard'!G9 | C32: ='Dashboard'!C9 | D32: ='Dashboard'!E9 | E32: =IF(Dashboard!H9>0,"INCOMPLETE",IF(Dashboard!G9="N/A","--",IF(ISNUMBER(VALUE(SUBSTITUTE(Dashboard!G9,"%",""))),IF(VALUE(SUBSTITUTE(Dashboard!G9,"%",""))>=90,"PASS",IF(VALUE(SUBSTITUTE(Dashboard!G9,"%",""))>=70,"REVIEW","FAIL")),"--")))
A33: Auth and Multi-Factor Auth | B33: ='Dashboard'!G10 | C33: ='Dashboard'!C10 | D33: ='Dashboard'!E10 | E33: =IF(Dashboard!H10>0,"INCOMPLETE",IF(Dashboard!G10="N/A","--",IF(ISNUMBER(VALUE(SUBSTITUTE(Dashboard!G10,"%",""))),IF(VALUE(SUBSTITUTE(Dashboard!G10,"%",""))>=90,"PASS",IF(VALUE(SUBSTITUTE(Dashboard!G10,"%",""))>=70,"REVIEW","FAIL")),"--")))
A34: Audit Logging and Monitoring | B34: ='Dashboard'!G11 | C34: ='Dashboard'!C11 | D34: ='Dashboard'!E11 | E34: =IF(Dashboard!H11>0,"INCOMPLETE",IF(Dashboard!G11="N/A","--",IF(ISNUMBER(VALUE(SUBSTITUTE(Dashboard!G11,"%",""))),IF(VALUE(SUBSTITUTE(Dashboard!G11,"%",""))>=90,"PASS",IF(VALUE(SUBSTITUTE(Dashboard!G11,"%",""))>=70,"REVIEW","FAIL")),"--")))
A35: Backup and Recovery | B35: ='Dashboard'!G12 | C35: ='Dashboard'!C12 | D35: ='Dashboard'!E12 | E35: =IF(Dashboard!H12>0,"INCOMPLETE",IF(Dashboard!G12="N/A","--",IF(ISNUMBER(VALUE(SUBSTITUTE(Dashboard!G12,"%",""))),IF(VALUE(SUBSTITUTE(Dashboard!G12,"%",""))>=90,"PASS",IF(VALUE(SUBSTITUTE(Dashboard!G12,"%",""))>=70,"REVIEW","FAIL")),"--")))
A36: Third-Party Access Management | B36: ='Dashboard'!G13 | C36: ='Dashboard'!C13 | D36: ='Dashboard'!E13 | E36: =IF(Dashboard!H13>0,"INCOMPLETE",IF(Dashboard!G13="N/A","--",IF(ISNUMBER(VALUE(SUBSTITUTE(Dashboard!G13,"%",""))),IF(VALUE(SUBSTITUTE(Dashboard!G13,"%",""))>=90,"PASS",IF(VALUE(SUBSTITUTE(Dashboard!G13,"%",""))>=70,"REVIEW","FAIL")),"--")))
A37: Exception Management | B37: ='Dashboard'!G14 | C37: ='Dashboard'!C14 | D37: ='Dashboard'!E14 | E37: =IF(Dashboard!H14>0,"INCOMPLETE",IF(Dashboard!G14="N/A","--",IF(ISNUMBER(VALUE(SUBSTITUTE(Dashboard!G14,"%",""))),IF(VALUE(SUBSTITUTE(Dashboard!G14,"%",""))>=90,"PASS",IF(VALUE(SUBSTITUTE(Dashboard!G14,"%",""))>=70,"REVIEW","FAIL")),"--")))
A39: CRITICAL ISSUES
A40: # | B40: Issue Description | C40: Domain | D40: Owner | E40: Due Date
A41: 1
A42: 2
A43: 3
A44: 4
A45: 5
...

Sheet Dashboard
A1: Access to Source Code — Compliance Dashboard
A3: Domain | B3: Total Reqs | C3: Compliant | D3: Partial | E3: Non-Compliant | F3: N/A | G3: Compliance % | H3: Unassessed
A4: Repository Classification | B4: =COUNTA('Repository Classification'!A4:A8) | C4: =COUNTIF('Repository Classification'!D4:D8,"Compliant") | D4: =COUNTIF('Repository Classification'!D4:D8,"Partial") | E4: =COUNTIF('Repository Classification'!D4:D8,"Non-Compliant") | F4: =COUNTIF('Repository Classification'!D4:D8,"N/A") | G4: =IF((B4-F4)=0,"N/A",ROUND(C4/(B4-F4)*100,1)&"%") | H4: =B4-(C4+D4+E4+F4)
A5: Role-Based Access Control | B5: =COUNTA('Role-Based Access Control'!A4:A5) | C5: =COUNTIF('Role-Based Access Control'!D4:D5,"Compliant") | D5: =COUNTIF('Role-Based Access Control'!D4:D5,"Partial") | E5: =COUNTIF('Role-Based Access Control'!D4:D5,"Non-Compliant") | F5: =COUNTIF('Role-Based Access Control'!D4:D5,"N/A") | G5: =IF((B5-F5)=0,"N/A",ROUND(C5/(B5-F5)*100,1)&"%") | H5: =B5-(C5+D5+E5+F5)
A6: Access Request and Approval | B6: =COUNTA('Access Request and Approval'!A4:A6) | C6: =COUNTIF('Access Request and Approval'!D4:D6,"Compliant") | D6: =COUNTIF('Access Request and Approval'!D4:D6,"Partial") | E6: =COUNTIF('Access Request and Approval'!D4:D6,"Non-Compliant") | F6: =COUNTIF('Access Request and Approval'!D4:D6,"N/A") | G6: =IF((B6-F6)=0,"N/A",ROUND(C6/(B6-F6)*100,1)&"%") | H6: =B6-(C6+D6+E6+F6)
A7: Access Review & Deprovisioning | B7: =COUNTA('Access Review & Deprovisioning'!A4:A6) | C7: =COUNTIF('Access Review & Deprovisioning'!D4:D6,"Compliant") | D7: =COUNTIF('Access Review & Deprovisioning'!D4:D6,"Partial") | E7: =COUNTIF('Access Review & Deprovisioning'!D4:D6,"Non-Compliant") | F7: =COUNTIF('Access Review & Deprovisioning'!D4:D6,"N/A") | G7: =IF((B7-F7)=0,"N/A",ROUND(C7/(B7-F7)*100,1)&"%") | H7: =B7-(C7+D7+E7+F7)
A8: Branch Prot and Code Review | B8: =COUNTA('Branch Prot and Code Review'!A4:A10) | C8: =COUNTIF('Branch Prot and Code Review'!D4:D10,"Compliant") | D8: =COUNTIF('Branch Prot and Code Review'!D4:D10,"Partial") | E8: =COUNTIF('Branch Prot and Code Review'!D4:D10,"Non-Compliant") | F8: =COUNTIF('Branch Prot and Code Review'!D4:D10,"N/A") | G8: =IF((B8-F8)=0,"N/A",ROUND(C8/(B8-F8)*100,1)&"%") | H8: =B8-(C8+D8+E8+F8)
A9: Secret Management | B9: =COUNTA('Secret Management'!A4:A9) | C9: =COUNTIF('Secret Management'!D4:D9,"Compliant") | D9: =COUNTIF('Secret Management'!D4:D9,"Partial") | E9: =COUNTIF('Secret Management'!D4:D9,"Non-Compliant") | F9: =COUNTIF('Secret Management'!D4:D9,"N/A") | G9: =IF((B9-F9)=0,"N/A",ROUND(C9/(B9-F9)*100,1)&"%") | H9: =B9-(C9+D9+E9+F9)
A10: Auth and Multi-Factor Auth | B10: =COUNTA('Auth and Multi-Factor Auth'!A4:A7) | C10: =COUNTIF('Auth and Multi-Factor Auth'!D4:D7,"Compliant") | D10: =COUNTIF('Auth and Multi-Factor Auth'!D4:D7,"Partial") | E10: =COUNTIF('Auth and Multi-Factor Auth'!D4:D7,"Non-Compliant") | F10: =COUNTIF('Auth and Multi-Factor Auth'!D4:D7,"N/A") | G10: =IF((B10-F10)=0,"N/A",ROUND(C10/(B10-F10)*100,1)&"%") | H10: =B10-(C10+D10+E10+F10)
A11: Audit Logging and Monitoring | B11: =COUNTA('Audit Logging and Monitoring'!A4:A8) | C11: =COUNTIF('Audit Logging and Monitoring'!D4:D8,"Compliant") | D11: =COUNTIF('Audit Logging and Monitoring'!D4:D8,"Partial") | E11: =COUNTIF('Audit Logging and Monitoring'!D4:D8,"Non-Compliant") | F11: =COUNTIF('Audit Logging and Monitoring'!D4:D8,"N/A") | G11: =IF((B11-F11)=0,"N/A",ROUND(C11/(B11-F11)*100,1)&"%") | H11: =B11-(C11+D11+E11+F11)
A12: Backup and Recovery | B12: =COUNTA('Backup and Recovery'!A4:A6) | C12: =COUNTIF('Backup and Recovery'!D4:D6,"Compliant") | D12: =COUNTIF('Backup and Recovery'!D4:D6,"Partial") | E12: =COUNTIF('Backup and Recovery'!D4:D6,"Non-Compliant") | F12: =COUNTIF('Backup and Recovery'!D4:D6,"N/A") | G12: =IF((B12-F12)=0,"N/A",ROUND(C12/(B12-F12)*100,1)&"%") | H12: =B12-(C12+D12+E12+F12)
A13: Third-Party Access Management | B13: =COUNTA('Third-Party Access Management'!A4:A7) | C13: =COUNTIF('Third-Party Access Management'!D4:D7,"Compliant") | D13: =COUNTIF('Third-Party Access Management'!D4:D7,"Partial") | E13: =COUNTIF('Third-Party Access Management'!D4:D7,"Non-Compliant") | F13: =COUNTIF('Third-Party Access Management'!D4:D7,"N/A") | G13: =IF((B13-F13)=0,"N/A",ROUND(C13/(B13-F13)*100,1)&"%") | H13: =B13-(C13+D13+E13+F13)
A14: Exception Management | B14: =COUNTA('Exception Management'!A4:A6) | C14: =COUNTIF('Exception Management'!D4:D6,"Compliant") | D14: =COUNTIF('Exception Management'!D4:D6,"Partial") | E14: =COUNTIF('Exception Management'!D4:D6,"Non-Compliant") | F14: =COUNTIF('Exception Management'!D4:D6,"N/A") | G14: =IF((B14-F14)=0,"N/A",ROUND(C14/(B14-F14)*100,1)&"%") | H14: =B14-(C14+D14+E14+F14)
A15: TOTAL | B15: =SUM(B4:B14) | C15: =SUM(C4:C14) | D15: =SUM(D4:D14) | E15: =SUM(E4:E14) | F15: =SUM(F4:F14) | G15: =IF((B15-F15)=0,"N/A",ROUND(C15/(B15-F15)*100,1)&"%") | H15: =SUM(H4:H14)
A17: COMPLIANCE BY STATUS
A18: Compliant | B18: =C15 | C18: =IF(B15=0,"",ROUND(B18/B15*100,1)&"%")
A19: Partial | B19: =D15 | C19: =IF(B15=0,"",ROUND(B19/B15*100,1)&"%")
A20: Non-Compliant | B20: =E15 | C20: =IF(B15=0,"",ROUND(B20/B15*100,1)&"%")
A21: N/A | B21: =F15 | C21: =IF(B15=0,"",ROUND(B21/B15*100,1)&"%")
A23: TOP GAPS (Manual Entry)
A24: Priority | B24: Domain | C24: Requirement | D24: Owner | E24: Due Date | F24: Status
A36: COMPLIANCE TREND (Manual Entry)
A37: Assessment Date | B37: Overall % | C37: Compliant | D37: Gaps | E37: Assessor | F37: Notes

Sheet Repository Classification
A1: Repository Classification — Compliance Checklist
A2: ISO/IEC 27001:2022 — Control A.8.4: Access to Source Code
A3: Req # | B3: Section | C3: Requirement | D3: Status | E3: Evidence | F3: Owner | G3: Due Date | H3: Notes
A4: A.8.4-01 | B4: Source Code Repositories | C4: All source code repositories shall be classified to determine appropriate protection levels.
A5: A.8.4-02 | B5: Repository Classification | C5: Repository classification shall be assigned by the repository owner during creation and reviewed annually. Classification shall be updated when the repository purpose changes.
A6: A.8.4-03 | B6: Inherited And Dormant Repositories*: | C6: Inherited and Dormant Repositories*: Repositories that are inherited (e.g., through acquisition, team restructuring, or developer departure) or dormant (no commits >12 months) shall be handled as follows:.
A7: A.8.4-04 | B7: Inherited Repositories: The Receiving | C7: Inherited repositories: The receiving team lead shall be assigned as interim repository owner within 5 business days. The repository shall be reviewed for classification accuracy, access permissions, and secret scanning compliance within 30 days.
A8: A.8.4-05 | B8: Dormant Repositories: Repositories With | C8: Dormant repositories: Repositories with no commit activity for 12 months shall be flagged for review. The repository owner shall confirm: (a) the repository is still needed (retain with current classification), (b) the repository should be archived (move to Archived classification, restrict to read-only), or (c) the repository should be deleted (follow data retention policy). Non-response after 30 days shall result in automatic archival with notification to the Development Manager.

Sheet Role-Based Access Control
A1: Role-Based Access Control — Compliance Checklist
A2: ISO/IEC 27001:2022 — Control A.8.4: Access to Source Code
A3: Req # | B3: Section | C3: Requirement | D3: Status | E3: Evidence | F3: Owner | G3: Due Date | H3: Notes
A4: A.8.4-06 | B4: Repository Access | C4: Repository access shall be granted based on defined roles with the minimum permissions required.
A5: A.8.4-07 | B5: Admin Or Owner Access | C5: Admin or owner access shall not be granted to external contractors except in documented exceptional cases with CISO approval.

Sheet Access Request and Approval
A1: Access Request and Approval — Compliance Checklist
A2: ISO/IEC 27001:2022 — Control A.8.4: Access to Source Code
A3: Req # | B3: Section | C3: Requirement | D3: Status | E3: Evidence | F3: Owner | G3: Due Date | H3: Notes
A4: A.8.4-08 | B4: Repository Access Requests | C4: All repository access requests shall include:.
A5: A.8.4-09 | B5: Be Provisioned Within 24 Hours Of | C5: Access shall be provisioned within 24 hours of approval during business hours. Emergency access requests shall follow an expedited approval process with post-facto review within 48 hours.
A6: A.8.4-10 | B6: Access Requests And Approvals | C6: All access requests and approvals shall be documented and retained for a minimum of 3 years.

Sheet Access Review & Deprovisioning
A1: Access Review & Deprovisioning — Compliance Checklist
A2: ISO/IEC 27001:2022 — Control A.8.4: Access to Source Code
A3: Req # | B3: Section | C3: Requirement | D3: Status | E3: Evidence | F3: Owner | G3: Due Date | H3: Notes
A4: A.8.4-11 | B4: Repository Access | C4: Repository access shall be reviewed quarterly to confirm continued business justification.
A5: A.8.4-12 | B5: Repository Access | C5: Repository access shall be revoked within the same business day of employment termination, role change that removes the access need, or contract expiration.
A6: A.8.4-13 | B6: Be Verified Within 24 Hours Of | C6: Deprovisioning shall be verified within 24 hours of the trigger event.

Sheet Branch Prot and Code Review
A1: Branch Prot and Code Review — Compliance Checklist
A2: ISO/IEC 27001:2022 — Control A.8.4: Access to Source Code
A3: Req # | B3: Section | C3: Requirement | D3: Status | E3: Evidence | F3: Owner | G3: Due Date | H3: Notes
A4: A.8.4-14 | B4: The Main Branch (Main/Master/Trunk) Of | C4: The main branch (main/master/trunk) of Production and Internal Tools repositories shall be protected.
A5: A.8.4-15 | B5: Release Branches (Release/, Hotfix/) | C5: Release branches (release/, hotfix/) shall have the same protection as the main branch.
A6: A.8.4-16 | B6: Only Repository Administrators | C6: Only repository administrators shall be able to modify branch protection rules. Temporary branch protection removal shall require documented justification, CISO approval, and automatic re-enablement after the specified period.
A7: A.8.4-17 | B7: Code Changes To Protected Branches | C7: All code changes to protected branches shall be submitted via pull requests.
A8: A.8.4-18 | B8: Pull Requests | C8: Pull requests shall not be approved by the code author (separation of duties).
A9: A.8.4-19 | B9: Pull Requests | C9: Pull requests shall include a clear description of changes, link to related issue or ticket where applicable, and evidence of testing.
A10: A.8.4-20 | B10: Security-Relevant Changes | C10: Security-relevant changes shall include a security impact assessment.

Sheet Secret Management
A1: Secret Management — Compliance Checklist
A2: ISO/IEC 27001:2022 — Control A.8.4: Access to Source Code
A3: Req # | B3: Section | C3: Requirement | D3: Status | E3: Evidence | F3: Owner | G3: Due Date | H3: Notes
A4: A.8.4-21 | B4: Source Code Repositories | C4: Source code repositories shall not contain passwords, API keys, tokens, private keys, database connection strings with embedded credentials, SSH private keys, encryption keys, or any other sensitive authentication material.
A5: A.8.4-22 | B5: Have Automated Secret Scanning Enabled | C5: All repositories shall have automated secret scanning enabled using [Secret Scanning Tool] (e.g., GitLeaks, TruffleHog, GitHub Secret Scanning, or equivalent).
A6: A.8.4-23 | B6: Production Repositories | C6: Production repositories shall have pre-commit secret scanning enabled (blocking mode).
A7: A.8.4-24 | B7: Secret Scanning | C7: Secret scanning shall detect generic secrets (regex-based patterns), provider-specific secrets (AWS keys, GitHub tokens, Azure credentials), and custom patterns defined by the security team.
A8: A.8.4-25 | B8: Include: (1) Immediate Rotation Of | C8: Remediation shall include: (1) immediate rotation of exposed secret, (2) removal from repository history if committed, (3) impact assessment (was the secret accessed by unauthorised parties?), and (4) incident reporting if required.
A9: A.8.4-26 | B9: Be Trained On Secret Management Best | C9: Developers shall be trained on secret management best practices, including use of environment variables, secrets management systems, and pre-commit hooks.

Sheet Auth and Multi-Factor Auth
A1: Auth and Multi-Factor Auth — Compliance Checklist
A2: ISO/IEC 27001:2022 — Control A.8.4: Access to Source Code
A3: Req # | B3: Section | C3: Requirement | D3: Status | E3: Evidence | F3: Owner | G3: Due Date | H3: Notes
A4: A.8.4-27 | B4: Access To Source Code Repositories | C4: Access to source code repositories shall be authenticated using approved methods: username/password (with MFA), SSH public key authentication, personal access tokens (with expiration), certificate-based authentication, or single sign-on (SSO) via the organisational identity provider.
A5: A.8.4-28 | B5: Multi-Factor Authentication | C5: Multi-factor authentication shall be required for:.
A6: A.8.4-29 | B6: Accepted Mfa Methods: Authenticator | C6: Accepted MFA methods: authenticator applications (e.g., Google Authenticator, Microsoft Authenticator, Authy), hardware security keys (e.g., YubiKey), or push notification to registered device. SMS-based codes are the least preferred method and shall only be used if other methods are unavailable.
A7: A.8.4-30 | B7: Service Accounts*: Service Accounts | C7: Service Accounts*: Service accounts cannot perform interactive MFA. Compensating controls shall include: tokens issued with minimum required scopes, token expiration enforced (maximum 1 year; 90 days recommended for high-privilege accounts), activity logged and monitored for anomalies, and quarterly review for continued need.

Sheet Audit Logging and Monitoring
A1: Audit Logging and Monitoring — Compliance Checklist
A2: ISO/IEC 27001:2022 — Control A.8.4: Access to Source Code
A3: Req # | B3: Section | C3: Requirement | D3: Status | E3: Evidence | F3: Owner | G3: Due Date | H3: Notes
A4: A.8.4-31 | B4: Repository Platforms | C4: Repository platforms shall log the following events:.
A5: A.8.4-32 | B5: Include: Timestamp (Utc), User Identity, | C5: Logs shall include: timestamp (UTC), user identity, source IP address, action performed, repository affected, and success or failure status.
A6: A.8.4-33 | B6: Be Tamper-Evident And Protected From | C6: Logs shall be tamper-evident and protected from unauthorised modification or deletion.
A7: A.8.4-34 | B7: Repository Access Logs | C7: Repository access logs shall be monitored for: multiple failed authentication attempts, access from unusual geographic locations, access outside normal business hours, bulk download operations, permission elevation attempts, force pushes to protected branches, and secret scanning alerts.
A8: A.8.4-35 | B8: Security Alerts | C8: Security alerts shall be generated and delivered to the security operations team within 15 minutes of detection. Critical events (confirmed unauthorised access, mass permission changes) shall trigger immediate incident response per the organisation's incident management process. Confirmed security incidents involving source code (unauthorised access, code tampering, intellectual property theft) shall be escalated to the CISO within 1 hour of confirmation. Where the incident involves customer data or production systems, the incident management process (A.5.24-28) shall be activated immediately.

Sheet Backup and Recovery
A1: Backup and Recovery — Compliance Checklist
A2: ISO/IEC 27001:2022 — Control A.8.4: Access to Source Code
A3: Req # | B3: Section | C3: Requirement | D3: Status | E3: Evidence | F3: Owner | G3: Due Date | H3: Notes
A4: A.8.4-36 | B4: Source Code Repositories | C4: All source code repositories shall be backed up to enable recovery from data loss, corruption, or platform failure.
A5: A.8.4-37 | B5: Include Source Code (All Branches, | C5: Backups shall include source code (all branches, commits, full history), repository metadata (permissions, settings, configurations), pull request history, and issue tracking data if integrated.
A6: A.8.4-38 | B6: Recovery Testing | C6: Recovery testing shall verify: repository restoration within RTO, data integrity (all commits, branches, history intact), permission restoration, and functionality of restored repository. Testing shall use a representative sample of repositories (minimum 3 Production repositories per quarter, rotating to cover all annually). Results shall be documented.

Sheet Third-Party Access Management
A1: Third-Party Access Management — Compliance Checklist
A2: ISO/IEC 27001:2022 — Control A.8.4: Access to Source Code
A3: Req # | B3: Section | C3: Requirement | D3: Status | E3: Evidence | F3: Owner | G3: Due Date | H3: Notes
A4: A.8.4-39 | B4: Third-Party Developers, Contractors, And | C4: Third-party developers, contractors, and offshore development teams shall meet the following requirements before receiving repository access:.
A5: A.8.4-40 | B5: Code Contributions From Third Parties | C5: All code contributions from third parties shall require review by an internal developer (minimum one reviewer) and security review for security-relevant changes.
A6: A.8.4-41 | B6: Third-Party Access | C6: Third-party access shall be immediately revoked upon contract expiration, contract termination, security incident involving the third party, or repository owner request.
A7: A.8.4-42 | B7: Third-Party Access | C7: Third-party access shall be documented in a third-party access register with: contracting company, individual names, repositories accessed, contract dates, and project manager accountability.

Sheet Exception Management
A1: Exception Management — Compliance Checklist
A2: ISO/IEC 27001:2022 — Control A.8.4: Access to Source Code
A3: Req # | B3: Section | C3: Requirement | D3: Status | E3: Evidence | F3: Owner | G3: Due Date | H3: Notes
A4: A.8.4-43 | B4: Exceptions To This Policy | C4: Exceptions to this policy shall be requested in writing and shall include:.
A5: A.8.4-44 | B5: Be Approved By The Repository Owner | C5: Exceptions shall be approved by the repository owner and Information Security Manager (mandatory), plus the CISO for Production repository exceptions. All active exceptions shall be reviewed quarterly.
A6: A.8.4-45 | B6: Compensating Controls | C6: Where technically infeasible to meet a requirement, compensating controls shall be implemented to achieve equivalent risk reduction, documented, verified by the Information Security Manager, and reviewed annually.
