Workbook

Sheet Executive Summary
A1: ISMS-OP-CHK-A.5.14 — Information Transfer Compliance Checklist
A3: DOCUMENT INFORMATION
A4: Document ID | B4: ISMS-OP-CHK-A.5.14
A5: Source Policy | B5: ISMS-OP-POL-A.5.14
A6: ISO Controls | B6: Information Transfer
A7: Generated | B7: 08.02.2026
A8: Prepared By
A9: Organisation
A10: Review Cycle | B10: Annual
A12: OVERALL COMPLIANCE STATUS
A13: Overall Compliance | B13: ='Dashboard'!G10
A14: Status | B14: =IF(Dashboard!G10="N/A","NOT ASSESSED",IF(ISNUMBER(VALUE(SUBSTITUTE(Dashboard!G10,"%",""))),IF(VALUE(SUBSTITUTE(Dashboard!G10,"%",""))>=90,"GREEN",IF(VALUE(SUBSTITUTE(Dashboard!G10,"%",""))>=70,"AMBER","RED")),"NOT ASSESSED"))
A16: KEY METRICS
A17: Total Requirements | B17: ='Dashboard'!B10
A18: Compliant | B18: ='Dashboard'!C10
A19: Partial | B19: ='Dashboard'!D10
A20: Non-Compliant | B20: ='Dashboard'!E10
A21: Not Applicable | B21: ='Dashboard'!F10
A22: Owner Coverage | B22: =IF(Dashboard!B10=0,"N/A",ROUND((COUNTA('Information Virus Checking'!F4:F4)+COUNTA('Information Encryption'!F4:F5)+COUNTA('Transfer Agreements'!F4:F5)+COUNTA('Data Transfer Methods'!F4:F33)+COUNTA('Cross-Border Data Transfers'!F4:F7)+COUNTA('Lost or Missing Information'!F4:F5))/Dashboard!B10*100,0)&"%")
A24: DOMAIN STATUS SUMMARY
A25: Domain | B25: Compliance % | C25: Compliant | D25: Gaps | E25: Status
A26: Information Virus Checking | B26: ='Dashboard'!G4 | C26: ='Dashboard'!C4 | D26: ='Dashboard'!E4 | E26: =IF(Dashboard!G4="N/A","--",IF(ISNUMBER(VALUE(SUBSTITUTE(Dashboard!G4,"%",""))),IF(VALUE(SUBSTITUTE(Dashboard!G4,"%",""))>=90,"PASS",IF(VALUE(SUBSTITUTE(Dashboard!G4,"%",""))>=70,"REVIEW","FAIL")),"--"))
A27: Information Encryption | B27: ='Dashboard'!G5 | C27: ='Dashboard'!C5 | D27: ='Dashboard'!E5 | E27: =IF(Dashboard!G5="N/A","--",IF(ISNUMBER(VALUE(SUBSTITUTE(Dashboard!G5,"%",""))),IF(VALUE(SUBSTITUTE(Dashboard!G5,"%",""))>=90,"PASS",IF(VALUE(SUBSTITUTE(Dashboard!G5,"%",""))>=70,"REVIEW","FAIL")),"--"))
A28: Transfer Agreements | B28: ='Dashboard'!G6 | C28: ='Dashboard'!C6 | D28: ='Dashboard'!E6 | E28: =IF(Dashboard!G6="N/A","--",IF(ISNUMBER(VALUE(SUBSTITUTE(Dashboard!G6,"%",""))),IF(VALUE(SUBSTITUTE(Dashboard!G6,"%",""))>=90,"PASS",IF(VALUE(SUBSTITUTE(Dashboard!G6,"%",""))>=70,"REVIEW","FAIL")),"--"))
A29: Data Transfer Methods | B29: ='Dashboard'!G7 | C29: ='Dashboard'!C7 | D29: ='Dashboard'!E7 | E29: =IF(Dashboard!G7="N/A","--",IF(ISNUMBER(VALUE(SUBSTITUTE(Dashboard!G7,"%",""))),IF(VALUE(SUBSTITUTE(Dashboard!G7,"%",""))>=90,"PASS",IF(VALUE(SUBSTITUTE(Dashboard!G7,"%",""))>=70,"REVIEW","FAIL")),"--"))
A30: Cross-Border Data Transfers | B30: ='Dashboard'!G8 | C30: ='Dashboard'!C8 | D30: ='Dashboard'!E8 | E30: =IF(Dashboard!G8="N/A","--",IF(ISNUMBER(VALUE(SUBSTITUTE(Dashboard!G8,"%",""))),IF(VALUE(SUBSTITUTE(Dashboard!G8,"%",""))>=90,"PASS",IF(VALUE(SUBSTITUTE(Dashboard!G8,"%",""))>=70,"REVIEW","FAIL")),"--"))
A31: Lost or Missing Information | B31: ='Dashboard'!G9 | C31: ='Dashboard'!C9 | D31: ='Dashboard'!E9 | E31: =IF(Dashboard!G9="N/A","--",IF(ISNUMBER(VALUE(SUBSTITUTE(Dashboard!G9,"%",""))),IF(VALUE(SUBSTITUTE(Dashboard!G9,"%",""))>=90,"PASS",IF(VALUE(SUBSTITUTE(Dashboard!G9,"%",""))>=70,"REVIEW","FAIL")),"--"))
A33: CRITICAL ISSUES
A34: # | B34: Issue Description | C34: Domain | D34: Owner | E34: Due Date
A35: 1
A36: 2
A37: 3
A38: 4
A39: 5
A41: MANAGEMENT COMMENTARY
A42: [Enter management commentary on information transfer posture]
A46: APPROVAL
A47: Assessed By
A48: Name:
A49: Date:
...

Sheet Dashboard
A1: Information Transfer — Compliance Dashboard
A3: Domain | B3: Total Reqs | C3: Compliant | D3: Partial | E3: Non-Compliant | F3: N/A | G3: Compliance %
A4: Information Virus Checking | B4: =COUNTA('Information Virus Checking'!D4:D4) | C4: =COUNTIF('Information Virus Checking'!D4:D4,"Compliant") | D4: =COUNTIF('Information Virus Checking'!D4:D4,"Partial") | E4: =COUNTIF('Information Virus Checking'!D4:D4,"Non-Compliant") | F4: =COUNTIF('Information Virus Checking'!D4:D4,"N/A") | G4: =IF((B4-F4)=0,"N/A",ROUND(C4/(B4-F4)*100,1)&"%")
A5: Information Encryption | B5: =COUNTA('Information Encryption'!D4:D5) | C5: =COUNTIF('Information Encryption'!D4:D5,"Compliant") | D5: =COUNTIF('Information Encryption'!D4:D5,"Partial") | E5: =COUNTIF('Information Encryption'!D4:D5,"Non-Compliant") | F5: =COUNTIF('Information Encryption'!D4:D5,"N/A") | G5: =IF((B5-F5)=0,"N/A",ROUND(C5/(B5-F5)*100,1)&"%")
A6: Transfer Agreements | B6: =COUNTA('Transfer Agreements'!D4:D5) | C6: =COUNTIF('Transfer Agreements'!D4:D5,"Compliant") | D6: =COUNTIF('Transfer Agreements'!D4:D5,"Partial") | E6: =COUNTIF('Transfer Agreements'!D4:D5,"Non-Compliant") | F6: =COUNTIF('Transfer Agreements'!D4:D5,"N/A") | G6: =IF((B6-F6)=0,"N/A",ROUND(C6/(B6-F6)*100,1)&"%")
A7: Data Transfer Methods | B7: =COUNTA('Data Transfer Methods'!D4:D33) | C7: =COUNTIF('Data Transfer Methods'!D4:D33,"Compliant") | D7: =COUNTIF('Data Transfer Methods'!D4:D33,"Partial") | E7: =COUNTIF('Data Transfer Methods'!D4:D33,"Non-Compliant") | F7: =COUNTIF('Data Transfer Methods'!D4:D33,"N/A") | G7: =IF((B7-F7)=0,"N/A",ROUND(C7/(B7-F7)*100,1)&"%")
A8: Cross-Border Data Transfers | B8: =COUNTA('Cross-Border Data Transfers'!D4:D7) | C8: =COUNTIF('Cross-Border Data Transfers'!D4:D7,"Compliant") | D8: =COUNTIF('Cross-Border Data Transfers'!D4:D7,"Partial") | E8: =COUNTIF('Cross-Border Data Transfers'!D4:D7,"Non-Compliant") | F8: =COUNTIF('Cross-Border Data Transfers'!D4:D7,"N/A") | G8: =IF((B8-F8)=0,"N/A",ROUND(C8/(B8-F8)*100,1)&"%")
A9: Lost or Missing Information | B9: =COUNTA('Lost or Missing Information'!D4:D5) | C9: =COUNTIF('Lost or Missing Information'!D4:D5,"Compliant") | D9: =COUNTIF('Lost or Missing Information'!D4:D5,"Partial") | E9: =COUNTIF('Lost or Missing Information'!D4:D5,"Non-Compliant") | F9: =COUNTIF('Lost or Missing Information'!D4:D5,"N/A") | G9: =IF((B9-F9)=0,"N/A",ROUND(C9/(B9-F9)*100,1)&"%")
A10: TOTAL | B10: =SUM(B4:B9) | C10: =SUM(C4:C9) | D10: =SUM(D4:D9) | E10: =SUM(E4:E9) | F10: =SUM(F4:F9) | G10: =IF((B10-F10)=0,"N/A",ROUND(C10/(B10-F10)*100,1)&"%")
A12: COMPLIANCE BY STATUS
A13: Compliant | B13: =C10 | C13: =IF(B10=0,"",ROUND(B13/B10*100,1)&"%")
A14: Partial | B14: =D10 | C14: =IF(B10=0,"",ROUND(B14/B10*100,1)&"%")
A15: Non-Compliant | B15: =E10 | C15: =IF(B10=0,"",ROUND(B15/B10*100,1)&"%")
A16: N/A | B16: =F10 | C16: =IF(B10=0,"",ROUND(B16/B10*100,1)&"%")
A18: TOP GAPS (Manual Entry)
A19: Priority | B19: Domain | C19: Requirement | D19: Owner | E19: Due Date | F19: Status
A31: COMPLIANCE TREND (Manual Entry)
A32: Assessment Date | B32: Overall % | C32: Compliant | D32: Gaps | E32: Assessor | F32: Notes

Sheet Information Virus Checking
A1: Information Virus Checking — Compliance Checklist
A2: ISO/IEC 27001:2022 — Control A.5.14: Information Transfer
A3: Req # | B3: Section | C3: Requirement | D3: Status | E3: Evidence | F3: Owner | G3: Due Date | H3: Notes
A4: A.5.14-01 | B4: Information That Is Transferred | C4: Information that is transferred shall be checked for malware before being sent or before being opened when received. This applies to all electronic transfers including email attachments, file transfers, and removable media.

Sheet Information Encryption
A1: Information Encryption — Compliance Checklist
A2: ISO/IEC 27001:2022 — Control A.5.14: Information Transfer
A3: Req # | B3: Section | C3: Requirement | D3: Status | E3: Evidence | F3: Owner | G3: Due Date | H3: Notes
A4: A.5.14-02 | B4: Personal And Confidential Information | C4: Personal and confidential information shall always be encrypted before being transferred, in line with the Use of Cryptography Policy.
A5: A.5.14-03 | B5: Encryption Credentials For Username And | C5: Encryption credentials for username and password, where used, shall be shared via two separate and distinct communication methods. The preferred method is to share the access link or username via email and the password or passphrase via a voice call or secure messaging channel.

Sheet Transfer Agreements
A1: Transfer Agreements — Compliance Checklist
A2: ISO/IEC 27001:2022 — Control A.5.14: Information Transfer
A3: Req # | B3: Section | C3: Requirement | D3: Status | E3: Evidence | F3: Owner | G3: Due Date | H3: Notes
A4: A.5.14-04 | B4: Formal Transfer Agreements | C4: Formal transfer agreements shall be established with all third-party recipients of personal or confidential data. Transfer agreements shall address:.
A5: A.5.14-05 | B5: Transfer Agreements | C5: Transfer agreements shall be reviewed annually or upon material changes to the transfer arrangement.

Sheet Data Transfer Methods
A1: Data Transfer Methods — Compliance Checklist
A2: ISO/IEC 27001:2022 — Control A.5.14: Information Transfer
A3: Req # | B3: Section | C3: Requirement | D3: Status | E3: Evidence | F3: Owner | G3: Due Date | H3: Notes
A4: A.5.14-06 | B4: Organisation-Approved Transfer Methods | C4: All organisation-approved transfer methods shall support:.
A5: A.5.14-07 | B5: For Automated Or Bulk File Transfers | C5: For automated or bulk file transfers, the following protocols shall be used:.
A6: A.5.14-08 | B6: Always Be Given To An Alternative | C6: Consideration shall always be given to an alternative secure method of transferring sensitive data wherever possible and practicable.
A7: A.5.14-09 | B7: Email Communication | C7: Email communication shall not be used to transfer unencrypted personal or confidential information.
A8: A.5.14-10 | B8: An Encrypted Attachment | C8: An encrypted attachment shall be used with a key length that meets the Use of Cryptography Policy requirements (AES-256 minimum).
A9: A.5.14-11 | B9: The Password Or Decryption Key | C9: The password or decryption key shall be shared via a separate communication channel (voice call, secure messaging).
A10: A.5.14-12 | B10: Filename Or Subject Line | C10: Filename or subject line shall not reveal the full contents of attachments or disclose any sensitive personal data.
A11: A.5.14-13 | B11: Email Messages | C11: Email messages containing sensitive transfers shall include clear instructions of the recipient's responsibilities and instructions on what to do if they are not the correct recipient.
A12: A.5.14-14 | B12: The Use Of Personal Email Accounts | C12: The use of personal email accounts for transferring organisation data is prohibited. Where technically feasible, the organisation shall implement controls to prevent forwarding of organisation email to external personal accounts (e.g., mail flow rules, DLP policies, conditional access).
A13: A.5.14-15 | B13: Implement Email Domain Authentication | C13: The organisation shall implement email domain authentication (SPF, DKIM, DMARC) to protect against email spoofing and interception. DMARC policy shall be set to quarantine or reject (not none) for production domains.
A14: A.5.14-16 | B14: Data Transfers Which Occur Via Physical | C14: Data transfers which occur via physical media such as paper reports, memory cards, or external drives shall only be dispatched via an organisation-approved secure courier (a courier service providing tracked, signed-for delivery with tamper-evident packaging and chain of custody documentation, e.g., Swiss Post registered mail, DHL Express with signature, or equivalent). Standard postal services shall not be used for confidential or personal data.
A15: A.5.14-17 | B15: The Recipient | C15: The recipient shall be clearly stated on the parcel and the physical media shall be securely packaged to prevent damage or tampering. Tamper-evident packaging shall be used for confidential material.
... A33: A.5.14-35 | B33: Bluetooth Profiles | C33: Bluetooth profiles shall be limited to those required for the approved function.

Sheet Cross-Border Data Transfers
A1: Cross-Border Data Transfers — Compliance Checklist
A2: ISO/IEC 27001:2022 — Control A.5.14: Information Transfer
A3: Req # | B3: Section | C3: Requirement | D3: Status | E3: Evidence | F3: Owner | G3: Due Date | H3: Notes
A4: A.5.14-36 | B4: Personal Data | C4: Personal data shall not be transferred to a country outside Switzerland unless one of the following conditions is met:.
A5: A.5.14-37 | B5: A Register Of All Cross-Border Data | C5: A register of all cross-border data transfers shall be maintained in the organisation's GRC platform, document management system, or equivalent central location. The register shall document the recipient, destination country, legal basis, safeguards, and review date. The register shall be reviewed annually by the CISO or Data Protection Advisor.
A6: A.5.14-38 | B6: For Transfers To Countries Without An | C6: For transfers to countries without an adequacy decision (relying on SCCs or other safeguards), a Transfer Impact Assessment shall be conducted before the transfer commences. The TIA shall evaluate:.
A7: A.5.14-39 | B7: Tia Results | C7: TIA results shall be documented and approved by the CISO or Data Protection Advisor before the transfer is authorised. TIAs shall be reviewed annually or when circumstances change (legal changes in destination country, security incident).

Sheet Lost or Missing Information
A1: Lost or Missing Information — Compliance Checklist
A2: ISO/IEC 27001:2022 — Control A.5.14: Information Transfer
A3: Req # | B3: Section | C3: Requirement | D3: Status | E3: Evidence | F3: Owner | G3: Due Date | H3: Notes
A4: A.5.14-40 | B4: Is Missing, Did Not Arrive, Or | C4: If it is discovered or suspected that information has been lost, is missing, did not arrive, or has gone to the wrong person, then the employee or third-party user shall immediately inform their line manager and the information security management team. The Incident Management process shall be followed.
A5: A.5.14-41 | B5: Lost Or Misdirected Information | C5: Lost or misdirected information shall be classified as:.
