Workbook

Sheet Executive Summary
A1: ISMS-OP-CHK-A.8.27 — Secure System Architecture and Engineering Principles Compliance Checklist
A3: DOCUMENT INFORMATION
A4: Document ID | B4: ISMS-OP-CHK-A.8.27
A5: Source Policy | B5: ISMS-OP-POL-A.8.27
A6: ISO Controls | B6: Secure System Architecture and Engineering Principles
A7: Generated | B7: 30.09.2026
A8: Prepared By
A9: Organisation
A10: Review Cycle | B10: Annual
A12: OVERALL COMPLIANCE STATUS
A13: Overall Compliance | B13: ='Dashboard'!G11
A14: Status | B14: =IF(Dashboard!H11>0,"INCOMPLETE",IF(Dashboard!G11="N/A","NOT ASSESSED",IF(ISNUMBER(VALUE(SUBSTITUTE(Dashboard!G11,"%",""))),IF(VALUE(SUBSTITUTE(Dashboard!G11,"%",""))>=90,"GREEN",IF(VALUE(SUBSTITUTE(Dashboard!G11,"%",""))>=70,"AMBER","RED")),"NOT ASSESSED")))
A16: KEY METRICS
A17: Total Requirements | B17: ='Dashboard'!B11
A18: Compliant | B18: ='Dashboard'!C11
A19: Partial | B19: ='Dashboard'!D11
A20: Non-Compliant | B20: ='Dashboard'!E11
A21: Not Applicable | B21: ='Dashboard'!F11
A22: Unanswered | B22: ='Dashboard'!H11
A23: Owner Coverage | B23: =IF(Dashboard!B11=0,"N/A",ROUND((COUNTA('Sec Architecture Documentation'!F4:F6)+COUNTA('Architecture Review Process'!F4:F12)+COUNTA('Technology Select Sec Criteria'!F4:F5)+COUNTA('Security Baselines'!F4:F7)+COUNTA('Secure Architecture Patterns'!F4:F7)+COUNTA('Third-Party & Acquired Systems'!F4:F12)+COUNTA('Compliance Measurement'!F4:F5))/Dashboard!B11*100,0)&"%")
A25: DOMAIN STATUS SUMMARY
A26: Domain | B26: Compliance % | C26: Compliant | D26: Gaps | E26: Status
A27: Sec Architecture Documentation | B27: ='Dashboard'!G4 | C27: ='Dashboard'!C4 | D27: ='Dashboard'!E4 | E27: =IF(Dashboard!H4>0,"INCOMPLETE",IF(Dashboard!G4="N/A","--",IF(ISNUMBER(VALUE(SUBSTITUTE(Dashboard!G4,"%",""))),IF(VALUE(SUBSTITUTE(Dashboard!G4,"%",""))>=90,"PASS",IF(VALUE(SUBSTITUTE(Dashboard!G4,"%",""))>=70,"REVIEW","FAIL")),"--")))
A28: Architecture Review Process | B28: ='Dashboard'!G5 | C28: ='Dashboard'!C5 | D28: ='Dashboard'!E5 | E28: =IF(Dashboard!H5>0,"INCOMPLETE",IF(Dashboard!G5="N/A","--",IF(ISNUMBER(VALUE(SUBSTITUTE(Dashboard!G5,"%",""))),IF(VALUE(SUBSTITUTE(Dashboard!G5,"%",""))>=90,"PASS",IF(VALUE(SUBSTITUTE(Dashboard!G5,"%",""))>=70,"REVIEW","FAIL")),"--")))
A29: Technology Select Sec Criteria | B29: ='Dashboard'!G6 | C29: ='Dashboard'!C6 | D29: ='Dashboard'!E6 | E29: =IF(Dashboard!H6>0,"INCOMPLETE",IF(Dashboard!G6="N/A","--",IF(ISNUMBER(VALUE(SUBSTITUTE(Dashboard!G6,"%",""))),IF(VALUE(SUBSTITUTE(Dashboard!G6,"%",""))>=90,"PASS",IF(VALUE(SUBSTITUTE(Dashboard!G6,"%",""))>=70,"REVIEW","FAIL")),"--")))
A30: Security Baselines | B30: ='Dashboard'!G7 | C30: ='Dashboard'!C7 | D30: ='Dashboard'!E7 | E30: =IF(Dashboard!H7>0,"INCOMPLETE",IF(Dashboard!G7="N/A","--",IF(ISNUMBER(VALUE(SUBSTITUTE(Dashboard!G7,"%",""))),IF(VALUE(SUBSTITUTE(Dashboard!G7,"%",""))>=90,"PASS",IF(VALUE(SUBSTITUTE(Dashboard!G7,"%",""))>=70,"REVIEW","FAIL")),"--")))
A31: Secure Architecture Patterns | B31: ='Dashboard'!G8 | C31: ='Dashboard'!C8 | D31: ='Dashboard'!E8 | E31: =IF(Dashboard!H8>0,"INCOMPLETE",IF(Dashboard!G8="N/A","--",IF(ISNUMBER(VALUE(SUBSTITUTE(Dashboard!G8,"%",""))),IF(VALUE(SUBSTITUTE(Dashboard!G8,"%",""))>=90,"PASS",IF(VALUE(SUBSTITUTE(Dashboard!G8,"%",""))>=70,"REVIEW","FAIL")),"--")))
A32: Third-Party & Acquired Systems | B32: ='Dashboard'!G9 | C32: ='Dashboard'!C9 | D32: ='Dashboard'!E9 | E32: =IF(Dashboard!H9>0,"INCOMPLETE",IF(Dashboard!G9="N/A","--",IF(ISNUMBER(VALUE(SUBSTITUTE(Dashboard!G9,"%",""))),IF(VALUE(SUBSTITUTE(Dashboard!G9,"%",""))>=90,"PASS",IF(VALUE(SUBSTITUTE(Dashboard!G9,"%",""))>=70,"REVIEW","FAIL")),"--")))
A33: Compliance Measurement | B33: ='Dashboard'!G10 | C33: ='Dashboard'!C10 | D33: ='Dashboard'!E10 | E33: =IF(Dashboard!H10>0,"INCOMPLETE",IF(Dashboard!G10="N/A","--",IF(ISNUMBER(VALUE(SUBSTITUTE(Dashboard!G10,"%",""))),IF(VALUE(SUBSTITUTE(Dashboard!G10,"%",""))>=90,"PASS",IF(VALUE(SUBSTITUTE(Dashboard!G10,"%",""))>=70,"REVIEW","FAIL")),"--")))
A35: CRITICAL ISSUES
A36: # | B36: Issue Description | C36: Domain | D36: Owner | E36: Due Date
A37: 1
A38: 2
A39: 3
A40: 4
A41: 5
A43: MANAGEMENT COMMENTARY
A44: [Enter management commentary on secure system architecture and engineering principles posture]
A48: APPROVAL
A49: Assessed By
...

Sheet Dashboard
A1: Secure System Architecture and Engineering Principles — Compliance Dashboard
A3: Domain | B3: Total Reqs | C3: Compliant | D3: Partial | E3: Non-Compliant | F3: N/A | G3: Compliance % | H3: Unassessed
A4: Sec Architecture Documentation | B4: =COUNTA('Sec Architecture Documentation'!A4:A6) | C4: =COUNTIF('Sec Architecture Documentation'!D4:D6,"Compliant") | D4: =COUNTIF('Sec Architecture Documentation'!D4:D6,"Partial") | E4: =COUNTIF('Sec Architecture Documentation'!D4:D6,"Non-Compliant") | F4: =COUNTIF('Sec Architecture Documentation'!D4:D6,"N/A") | G4: =IF((B4-F4)=0,"N/A",ROUND(C4/(B4-F4)*100,1)&"%") | H4: =B4-(C4+D4+E4+F4)
A5: Architecture Review Process | B5: =COUNTA('Architecture Review Process'!A4:A12) | C5: =COUNTIF('Architecture Review Process'!D4:D12,"Compliant") | D5: =COUNTIF('Architecture Review Process'!D4:D12,"Partial") | E5: =COUNTIF('Architecture Review Process'!D4:D12,"Non-Compliant") | F5: =COUNTIF('Architecture Review Process'!D4:D12,"N/A") | G5: =IF((B5-F5)=0,"N/A",ROUND(C5/(B5-F5)*100,1)&"%") | H5: =B5-(C5+D5+E5+F5)
A6: Technology Select Sec Criteria | B6: =COUNTA('Technology Select Sec Criteria'!A4:A5) | C6: =COUNTIF('Technology Select Sec Criteria'!D4:D5,"Compliant") | D6: =COUNTIF('Technology Select Sec Criteria'!D4:D5,"Partial") | E6: =COUNTIF('Technology Select Sec Criteria'!D4:D5,"Non-Compliant") | F6: =COUNTIF('Technology Select Sec Criteria'!D4:D5,"N/A") | G6: =IF((B6-F6)=0,"N/A",ROUND(C6/(B6-F6)*100,1)&"%") | H6: =B6-(C6+D6+E6+F6)
A7: Security Baselines | B7: =COUNTA('Security Baselines'!A4:A7) | C7: =COUNTIF('Security Baselines'!D4:D7,"Compliant") | D7: =COUNTIF('Security Baselines'!D4:D7,"Partial") | E7: =COUNTIF('Security Baselines'!D4:D7,"Non-Compliant") | F7: =COUNTIF('Security Baselines'!D4:D7,"N/A") | G7: =IF((B7-F7)=0,"N/A",ROUND(C7/(B7-F7)*100,1)&"%") | H7: =B7-(C7+D7+E7+F7)
A8: Secure Architecture Patterns | B8: =COUNTA('Secure Architecture Patterns'!A4:A7) | C8: =COUNTIF('Secure Architecture Patterns'!D4:D7,"Compliant") | D8: =COUNTIF('Secure Architecture Patterns'!D4:D7,"Partial") | E8: =COUNTIF('Secure Architecture Patterns'!D4:D7,"Non-Compliant") | F8: =COUNTIF('Secure Architecture Patterns'!D4:D7,"N/A") | G8: =IF((B8-F8)=0,"N/A",ROUND(C8/(B8-F8)*100,1)&"%") | H8: =B8-(C8+D8+E8+F8)
A9: Third-Party & Acquired Systems | B9: =COUNTA('Third-Party & Acquired Systems'!A4:A12) | C9: =COUNTIF('Third-Party & Acquired Systems'!D4:D12,"Compliant") | D9: =COUNTIF('Third-Party & Acquired Systems'!D4:D12,"Partial") | E9: =COUNTIF('Third-Party & Acquired Systems'!D4:D12,"Non-Compliant") | F9: =COUNTIF('Third-Party & Acquired Systems'!D4:D12,"N/A") | G9: =IF((B9-F9)=0,"N/A",ROUND(C9/(B9-F9)*100,1)&"%") | H9: =B9-(C9+D9+E9+F9)
A10: Compliance Measurement | B10: =COUNTA('Compliance Measurement'!A4:A5) | C10: =COUNTIF('Compliance Measurement'!D4:D5,"Compliant") | D10: =COUNTIF('Compliance Measurement'!D4:D5,"Partial") | E10: =COUNTIF('Compliance Measurement'!D4:D5,"Non-Compliant") | F10: =COUNTIF('Compliance Measurement'!D4:D5,"N/A") | G10: =IF((B10-F10)=0,"N/A",ROUND(C10/(B10-F10)*100,1)&"%") | H10: =B10-(C10+D10+E10+F10)
A11: TOTAL | B11: =SUM(B4:B10) | C11: =SUM(C4:C10) | D11: =SUM(D4:D10) | E11: =SUM(E4:E10) | F11: =SUM(F4:F10) | G11: =IF((B11-F11)=0,"N/A",ROUND(C11/(B11-F11)*100,1)&"%") | H11: =SUM(H4:H10)
A13: COMPLIANCE BY STATUS
A14: Compliant | B14: =C11 | C14: =IF(B11=0,"",ROUND(B14/B11*100,1)&"%")
A15: Partial | B15: =D11 | C15: =IF(B11=0,"",ROUND(B15/B11*100,1)&"%")
A16: Non-Compliant | B16: =E11 | C16: =IF(B11=0,"",ROUND(B16/B11*100,1)&"%")
A17: N/A | B17: =F11 | C17: =IF(B11=0,"",ROUND(B17/B11*100,1)&"%")
A19: TOP GAPS (Manual Entry)
A20: Priority | B20: Domain | C20: Requirement | D20: Owner | E20: Due Date | F20: Status
A32: COMPLIANCE TREND (Manual Entry)
A33: Assessment Date | B33: Overall % | C33: Compliant | D33: Gaps | E33: Assessor | F33: Notes

Sheet Sec Architecture Documentation
A1: Sec Architecture Documentation — Compliance Checklist
A2: ISO/IEC 27001:2022 — Control A.8.27: Secure System Architecture and Engineering Principles
A3: Req # | B3: Section | C3: Requirement | D3: Status | E3: Evidence | F3: Owner | G3: Due Date | H3: Notes
A4: A.8.27-01 | B4: Systems Classified As High-Risk Or | C4: All systems classified as High-Risk or Medium-Risk shall have documented security architecture. Low-Risk systems shall have, at minimum, a completed security checklist.
A5: A.8.27-02 | B5: Documentation Storage*: Security | C5: Documentation Storage*: Security architecture documentation shall be stored in [Architecture Tool / Confluence / SharePoint] with access restricted to: CISO, Development Manager, System Owner, and personnel with documented need-to-know approved by the CISO. Documentation shall be version-controlled.
A6: A.8.27-03 | B6: Documentation Currency*: Security | C6: Documentation Currency*: Security architecture documentation shall be reviewed and updated: when significant changes are made to the system, when new threats are identified that affect the system, and at least annually for High-Risk systems.

Sheet Architecture Review Process
A1: Architecture Review Process — Compliance Checklist
A2: ISO/IEC 27001:2022 — Control A.8.27: Secure System Architecture and Engineering Principles
A3: Req # | B3: Section | C3: Requirement | D3: Status | E3: Evidence | F3: Owner | G3: Due Date | H3: Notes
A4: A.8.27-04 | B4: New Systems And Significant Changes To | C4: All new systems and significant changes to existing systems shall undergo security architecture review before implementation.
A5: A.8.27-05 | B5: Approval Criteria*: Architecture | C5: Approval Criteria*: Architecture shall not be approved if:.
A6: A.8.27-06 | B6: Incomplete Submissions | C6: Incomplete submissions shall be returned within 3 business days with specific gaps identified. Clock resets upon resubmission of complete documentation.
A7: A.8.27-07 | B7: Engage External Security Architecture | C7: Organisations shall engage external security architecture specialists when:.
A8: A.8.27-08 | B8: External Reviewers | C8: External reviewers shall be selected based on: relevant industry certifications (CISSP, CCSP, or equivalent), demonstrated experience with similar architectures, and independence from implementation vendors.
A9: A.8.27-09 | B9: The Stride Methodology | C9: Where threat modelling is required, the STRIDE methodology shall be used as the primary approach:.
A10: A.8.27-10 | B10: Threat Models | C10: Threat models shall be retained for:.
A11: A.8.27-11 | B11: Major Incidents: Threat Models For | C11: Major incidents: Threat models for systems involved in security incidents shall be retained permanently (minimum 7 years).
A12: A.8.27-12 | B12: Threat Models | C12: Threat models shall be reviewed and updated: at each major release, when the system architecture changes significantly, when new threat intelligence relevant to the system is identified, and at least annually for High-Risk systems.

Sheet Technology Select Sec Criteria
A1: Technology Select Sec Criteria — Compliance Checklist
A2: ISO/IEC 27001:2022 — Control A.8.27: Secure System Architecture and Engineering Principles
A3: Req # | B3: Section | C3: Requirement | D3: Status | E3: Evidence | F3: Owner | G3: Due Date | H3: Notes
A4: A.8.27-13 | B4: Platforms, Frameworks, Or Third-Party | C4: When selecting new technologies, platforms, frameworks, or third-party components, security shall be a selection criterion with equal weight to functional requirements.
A5: A.8.27-14 | B5: Technology Selection Decisions For | C5: Technology selection decisions for High-Risk systems shall be documented with security assessment evidence and approved by the CISO before procurement.

Sheet Security Baselines
A1: Security Baselines — Compliance Checklist
A2: ISO/IEC 27001:2022 — Control A.8.27: Secure System Architecture and Engineering Principles
A3: Req # | B3: Section | C3: Requirement | D3: Status | E3: Evidence | F3: Owner | G3: Due Date | H3: Notes
A4: A.8.27-15 | B4: Maintain Security Baselines For Each | C4: The organisation shall maintain security baselines for each system tier, defining the minimum security controls required.
A5: A.8.27-16 | B5: System Tier | C5: System tier shall be reviewed and potentially reclassified when:.
A6: A.8.27-17 | B6: Re-Classification Triggers Updated | C6: Re-classification triggers updated security baseline requirements and architecture review. The System Owner shall request a re-classification review from the CISO when any trigger occurs.
A7: A.8.27-18 | B7: Security Baselines | C7: Security baselines shall be reviewed annually by the CISO and updated to reflect current threats, technology changes, and regulatory requirements.

Sheet Secure Architecture Patterns
A1: Secure Architecture Patterns — Compliance Checklist
A2: ISO/IEC 27001:2022 — Control A.8.27: Secure System Architecture and Engineering Principles
A3: Req # | B3: Section | C3: Requirement | D3: Status | E3: Evidence | F3: Owner | G3: Due Date | H3: Notes
A4: A.8.27-19 | B4: Maintain A Catalogue Of Approved Secure | C4: The organisation shall maintain a catalogue of approved secure architecture patterns that system designers shall reference when building new systems or modifying existing ones.
A5: A.8.27-20 | B5: Approved Pattern | C5: Each approved pattern shall document:.
A6: A.8.27-21 | B6: Approved Patterns | C6: Approved patterns shall be reviewed annually for continued appropriateness.
A7: A.8.27-22 | B7: New Patterns | C7: New patterns shall be validated through threat modelling before addition to the catalogue.

Sheet Third-Party & Acquired Systems
A1: Third-Party & Acquired Systems — Compliance Checklist
A2: ISO/IEC 27001:2022 — Control A.8.27: Secure System Architecture and Engineering Principles
A3: Req # | B3: Section | C3: Requirement | D3: Status | E3: Evidence | F3: Owner | G3: Due Date | H3: Notes
A4: A.8.27-23 | B4: Secure Engineering Principles | C4: Secure engineering principles shall apply to third-party developed and acquired systems that are integrated into the organisation's environment.
A5: A.8.27-24 | B5: Security Architecture Documentation | C5: Security architecture documentation shall be reviewed before procurement approval.
A6: A.8.27-25 | B6: Vendor Security Assessment | C6: Vendor security assessment shall be conducted per the Supplier and Cloud Services Policy (A.5.19-23).
A7: A.8.27-26 | B7: Architecture Compatibility With The | C7: Architecture compatibility with the organisation's security standards shall be verified.
A8: A.8.27-27 | B8: Third-Party Developers | C8: Third-party developers shall be contractually required to follow the organisation's secure engineering principles.
A9: A.8.27-28 | B9: Security Architecture Review | C9: Security architecture review shall be required at design milestone.
A10: A.8.27-29 | B10: Evidence Of Secure Development Practices | C10: Evidence of secure development practices shall be provided.
A11: A.8.27-30 | B11: Security Testing Results | C11: Security testing results shall be provided before acceptance.
A12: A.8.27-31 | B12: Vendor Non-Compliance | C12: Vendor non-compliance shall trigger issue escalation per contract terms.

Sheet Compliance Measurement
A1: Compliance Measurement — Compliance Checklist
A2: ISO/IEC 27001:2022 — Control A.8.27: Secure System Architecture and Engineering Principles
A3: Req # | B3: Section | C3: Requirement | D3: Status | E3: Evidence | F3: Owner | G3: Due Date | H3: Notes
A4: A.8.27-32 | B4: The Following Metrics | C4: The following metrics shall be tracked and reported to the CISO quarterly:.
A5: A.8.27-33 | B5: Metrics Breaching Red Thresholds | C5: Metrics breaching red thresholds shall be escalated to the CISO for immediate attention and reported at the next Management Review.
