Workbook

Sheet Executive Summary
A1: ISMS-OP-CHK-A.8.24 — Use of Cryptography Compliance Checklist
A3: DOCUMENT INFORMATION
A4: Document ID | B4: ISMS-OP-CHK-A.8.24
A5: Source Policy | B5: ISMS-OP-POL-A.8.24
A6: ISO Control | B6: ISO/IEC 27001:2022 — Control A.8.24: Use of Cryptography
A7: Generated | B7: 07.02.2026
A8: Prepared By
A9: Organisation
A10: Review Cycle | B10: Annual
A12: OVERALL COMPLIANCE STATUS
A13: Overall Compliance | B13: ='Dashboard'!G9
A14: Status | B14: =IF(Dashboard!G9="N/A","NOT ASSESSED",IF(ISNUMBER(VALUE(SUBSTITUTE(Dashboard!G9,"%",""))),IF(VALUE(SUBSTITUTE(Dashboard!G9,"%",""))>=90,"GREEN",IF(VALUE(SUBSTITUTE(Dashboard!G9,"%",""))>=70,"AMBER","RED")),"NOT ASSESSED"))
A16: KEY METRICS
A17: Total Requirements | B17: ='Dashboard'!B9
A18: Compliant | B18: ='Dashboard'!C9
A19: Partial | B19: ='Dashboard'!D9
A20: Non-Compliant | B20: ='Dashboard'!E9
A21: Not Applicable | B21: ='Dashboard'!F9
A22: Owner Coverage | B22: =IF(Dashboard!B9=0,"N/A",ROUND((COUNTA('Encryption Standards'!F4:F7)+COUNTA('Data in Transit'!F4:F14)+COUNTA('Data at Rest'!F4:F11)+COUNTA('Key Management'!F4:F21)+COUNTA('Crypto Governance'!F4:F9))/Dashboard!B9*100,0)&"%")
A24: DOMAIN STATUS SUMMARY
A25: Domain | B25: Compliance % | C25: Compliant | D25: Gaps | E25: Status
A26: Encryption Standards | B26: ='Dashboard'!G4 | C26: ='Dashboard'!C4 | D26: ='Dashboard'!E4 | E26: =IF(Dashboard!G4="N/A","--",IF(ISNUMBER(VALUE(SUBSTITUTE(Dashboard!G4,"%",""))),IF(VALUE(SUBSTITUTE(Dashboard!G4,"%",""))>=90,"PASS",IF(VALUE(SUBSTITUTE(Dashboard!G4,"%",""))>=70,"REVIEW","FAIL")),"--"))
A27: Data in Transit | B27: ='Dashboard'!G5 | C27: ='Dashboard'!C5 | D27: ='Dashboard'!E5 | E27: =IF(Dashboard!G5="N/A","--",IF(ISNUMBER(VALUE(SUBSTITUTE(Dashboard!G5,"%",""))),IF(VALUE(SUBSTITUTE(Dashboard!G5,"%",""))>=90,"PASS",IF(VALUE(SUBSTITUTE(Dashboard!G5,"%",""))>=70,"REVIEW","FAIL")),"--"))
A28: Data at Rest | B28: ='Dashboard'!G6 | C28: ='Dashboard'!C6 | D28: ='Dashboard'!E6 | E28: =IF(Dashboard!G6="N/A","--",IF(ISNUMBER(VALUE(SUBSTITUTE(Dashboard!G6,"%",""))),IF(VALUE(SUBSTITUTE(Dashboard!G6,"%",""))>=90,"PASS",IF(VALUE(SUBSTITUTE(Dashboard!G6,"%",""))>=70,"REVIEW","FAIL")),"--"))
A29: Key Management | B29: ='Dashboard'!G7 | C29: ='Dashboard'!C7 | D29: ='Dashboard'!E7 | E29: =IF(Dashboard!G7="N/A","--",IF(ISNUMBER(VALUE(SUBSTITUTE(Dashboard!G7,"%",""))),IF(VALUE(SUBSTITUTE(Dashboard!G7,"%",""))>=90,"PASS",IF(VALUE(SUBSTITUTE(Dashboard!G7,"%",""))>=70,"REVIEW","FAIL")),"--"))
A30: Crypto Governance | B30: ='Dashboard'!G8 | C30: ='Dashboard'!C8 | D30: ='Dashboard'!E8 | E30: =IF(Dashboard!G8="N/A","--",IF(ISNUMBER(VALUE(SUBSTITUTE(Dashboard!G8,"%",""))),IF(VALUE(SUBSTITUTE(Dashboard!G8,"%",""))>=90,"PASS",IF(VALUE(SUBSTITUTE(Dashboard!G8,"%",""))>=70,"REVIEW","FAIL")),"--"))
A32: CRITICAL ISSUES
A33: # | B33: Issue Description | C33: Domain | D33: Owner | E33: Due Date
A34: 1
A35: 2
A36: 3
A37: 4
A38: 5
A40: MANAGEMENT COMMENTARY
A41: [Enter management commentary on cryptographic compliance posture]
A45: APPROVAL
A46: Assessed By
A47: Name:
A48: Date:
A49: Signature:
...

Sheet Dashboard
A1: Use of Cryptography — Compliance Dashboard
A3: Domain | B3: Total Reqs | C3: Compliant | D3: Partial | E3: Non-Compliant | F3: N/A | G3: Compliance %
A4: Encryption Standards | B4: =COUNTA('Encryption Standards'!D4:D7) | C4: =COUNTIF('Encryption Standards'!D4:D7,"Compliant") | D4: =COUNTIF('Encryption Standards'!D4:D7,"Partial") | E4: =COUNTIF('Encryption Standards'!D4:D7,"Non-Compliant") | F4: =COUNTIF('Encryption Standards'!D4:D7,"N/A") | G4: =IF((B4-F4)=0,"N/A",ROUND(C4/(B4-F4)*100,1)&"%")
A5: Data in Transit | B5: =COUNTA('Data in Transit'!D4:D14) | C5: =COUNTIF('Data in Transit'!D4:D14,"Compliant") | D5: =COUNTIF('Data in Transit'!D4:D14,"Partial") | E5: =COUNTIF('Data in Transit'!D4:D14,"Non-Compliant") | F5: =COUNTIF('Data in Transit'!D4:D14,"N/A") | G5: =IF((B5-F5)=0,"N/A",ROUND(C5/(B5-F5)*100,1)&"%")
A6: Data at Rest | B6: =COUNTA('Data at Rest'!D4:D11) | C6: =COUNTIF('Data at Rest'!D4:D11,"Compliant") | D6: =COUNTIF('Data at Rest'!D4:D11,"Partial") | E6: =COUNTIF('Data at Rest'!D4:D11,"Non-Compliant") | F6: =COUNTIF('Data at Rest'!D4:D11,"N/A") | G6: =IF((B6-F6)=0,"N/A",ROUND(C6/(B6-F6)*100,1)&"%")
A7: Key Management | B7: =COUNTA('Key Management'!D4:D21) | C7: =COUNTIF('Key Management'!D4:D21,"Compliant") | D7: =COUNTIF('Key Management'!D4:D21,"Partial") | E7: =COUNTIF('Key Management'!D4:D21,"Non-Compliant") | F7: =COUNTIF('Key Management'!D4:D21,"N/A") | G7: =IF((B7-F7)=0,"N/A",ROUND(C7/(B7-F7)*100,1)&"%")
A8: Crypto Governance | B8: =COUNTA('Crypto Governance'!D4:D9) | C8: =COUNTIF('Crypto Governance'!D4:D9,"Compliant") | D8: =COUNTIF('Crypto Governance'!D4:D9,"Partial") | E8: =COUNTIF('Crypto Governance'!D4:D9,"Non-Compliant") | F8: =COUNTIF('Crypto Governance'!D4:D9,"N/A") | G8: =IF((B8-F8)=0,"N/A",ROUND(C8/(B8-F8)*100,1)&"%")
A9: TOTAL | B9: =SUM(B4:B8) | C9: =SUM(C4:C8) | D9: =SUM(D4:D8) | E9: =SUM(E4:E8) | F9: =SUM(F4:F8) | G9: =IF((B9-F9)=0,"N/A",ROUND(C9/(B9-F9)*100,1)&"%")
A11: COMPLIANCE BY STATUS
A12: Compliant | B12: =C9 | C12: =IF(B9=0,"",ROUND(B12/B9*100,1)&"%")
A13: Partial | B13: =D9 | C13: =IF(B9=0,"",ROUND(B13/B9*100,1)&"%")
A14: Non-Compliant | B14: =E9 | C14: =IF(B9=0,"",ROUND(B14/B9*100,1)&"%")
A15: N/A | B15: =F9 | C15: =IF(B9=0,"",ROUND(B15/B9*100,1)&"%")
A17: TOP GAPS (Manual Entry)
A18: Priority | B18: Domain | C18: Requirement | D18: Owner | E18: Due Date | F18: Status
A30: COMPLIANCE TREND (Manual Entry)
A31: Assessment Date | B31: Overall % | C31: Compliant | D31: Gaps | E31: Assessor | F31: Notes

Sheet Encryption Standards
A1: Encryption Standards — Compliance Checklist
A2: ISO/IEC 27001:2022 — Control A.8.24: Use of Cryptography
A3: Req # | B3: Section | C3: Requirement | D3: Status | E3: Evidence | F3: Owner | G3: Due Date | H3: Notes
A4: A.8.24-01 | B4: Approved Algorithms | C4: The organisation shall use the following minimum cryptographic standards: AES-256 (symmetric), RSA 2048+ (asymmetric), ECDSA/ECDH P-256+ (asymmetric), SHA-256+ (hash), PBKDF2/scrypt/Argon2 (key derivation).
A5: A.8.24-02 | B5: Prohibited Algorithms | C5: Prohibited algorithms (MD5, SHA-1, DES, 3DES, RC4, RSA below 2048-bit) shall not be used for any purpose.
A6: A.8.24-03 | B6: Post-Quantum Monitoring | C6: The organisation shall monitor NIST post-quantum cryptography standards (FIPS 203/204/205) and plan migration as adoption timelines are established.
A7: A.8.24-04 | B7: Crypto-Agility Assessment | C7: A crypto-agility assessment shall be conducted to identify systems and data stores requiring PQC migration planning, prioritising long-lived keys and data with retention exceeding 10 years.

Sheet Data in Transit
A1: Data in Transit — Compliance Checklist
A2: ISO/IEC 27001:2022 — Control A.8.24: Use of Cryptography
A3: Req # | B3: Section | C3: Requirement | D3: Status | E3: Evidence | F3: Owner | G3: Due Date | H3: Notes
A4: A.8.24-05 | B4: Encrypted Transport | C4: All network communications carrying confidential or personal data shall use encrypted transport.
A5: A.8.24-06 | B5: TLS Version | C5: TLS 1.3 shall be used where supported; TLS 1.2 is the minimum acceptable version.
A6: A.8.24-07 | B6: Disable Legacy TLS | C6: TLS 1.0 and TLS 1.1 shall be disabled on all systems.
A7: A.8.24-08 | B7: Disable SSL | C7: SSL (all versions) shall be disabled on all systems.
A8: A.8.24-09 | B8: AEAD Cipher Suites | C8: Only cipher suites using AEAD (e.g., AES-GCM) shall be enabled where feasible.
A9: A.8.24-10 | B9: Email — No Unencrypted PII | C9: Email shall not be used to transfer confidential or personal data in an unencrypted format.
A10: A.8.24-11 | B10: Email — Encrypted Attachments | C10: Where confidential data must be sent via email, an encrypted attachment shall be used with a key length meeting approved algorithm requirements.
A11: A.8.24-12 | B11: Email Encryption Solution | C11: The organisation shall evaluate and approve an email encryption solution appropriate to its needs.
A12: A.8.24-13 | B12: WEP Prohibited | C12: WEP shall not be used on any wireless network.
A13: A.8.24-14 | B13: Encrypted Transfer Channels | C13: The transfer of confidential and personal information shall use encrypted channels (SFTP, SCP, VPN, SSH; Telnet prohibited).
A14: A.8.24-15 | B14: Bluetooth Restriction | C14: Bluetooth shall not be used as a communication method for unencrypted confidential, personal, or otherwise sensitive data.

Sheet Data at Rest
A1: Data at Rest — Compliance Checklist
A2: ISO/IEC 27001:2022 — Control A.8.24: Use of Cryptography
A3: Req # | B3: Section | C3: Requirement | D3: Status | E3: Evidence | F3: Owner | G3: Due Date | H3: Notes
A4: A.8.24-16 | B4: Full-Disk Encryption | C4: Mobile devices, laptops, and removable media shall have full-disk encryption enabled at the hardware or operating system level.
A5: A.8.24-17 | B5: Encryption Not Disabled | C5: Device encryption shall not be disabled.
A6: A.8.24-18 | B6: Cloud/Web TLS | C6: Web and cloud services that process, store, or transmit confidential or personal data shall implement TLS 1.2 at a minimum.
A7: A.8.24-19 | B7: Valid Certificates | C7: All servers shall have a valid certificate issued by a recognised Certificate Authority; system owners are responsible for renewal before expiry.
A8: A.8.24-20 | B8: Backup Encryption | C8: Backups containing confidential or personal data shall be encrypted using organisation-approved encryption technology.
A9: A.8.24-21 | B9: No Sole Vendor-Proprietary | C9: Backup encryption shall not rely solely on vendor-proprietary mechanisms without documented assurance of the encryption standard used.
A10: A.8.24-22 | B10: Database Encryption | C10: Databases containing confidential information or personal data shall be encrypted at rest at either the database application layer or the disk/volume layer.
A11: A.8.24-23 | B11: Approved Technology Only | C11: Only organisation-approved encryption technology and processes shall be used.

Sheet Key Management
A1: Key Management — Compliance Checklist
A2: ISO/IEC 27001:2022 — Control A.8.24: Use of Cryptography
A3: Req # | B3: Section | C3: Requirement | D3: Status | E3: Evidence | F3: Owner | G3: Due Date | H3: Notes
A4: A.8.24-24 | B4: FIPS-Compliant Generation | C4: Cryptographic keys shall be generated within cryptographic modules with at least FIPS 140-2 or FIPS 140-3 compliance, or equivalent validated assurance.
A5: A.8.24-25 | B5: Validated RNG | C5: Any random values required for key generation shall be generated within the cryptographic module using a validated random bit generator.
A6: A.8.24-26 | B6: Secure Distribution | C6: Keys shall be transported using secure channels; key material shall not be transmitted in plaintext over any network.
A7: A.8.24-27 | B7: No Plaintext Storage | C7: Keys shall never be stored in plaintext format.
A8: A.8.24-28 | B8: Secure Key Storage | C8: Keys shall be stored in a cryptographic vault, HSM, or cloud key management service (KMS).
A9: A.8.24-29 | B9: No Hard-Coded Keys | C9: Keys shall not be hard-coded in source code, stored in config files in plaintext, or shared via email/messaging. Secrets shall be managed through a dedicated secrets management solution.
A10: A.8.24-30 | B10: KEK Strength | C10: Key encryption keys (KEKs) used to wrap stored keys shall be at least as strong as the keys they protect.
A11: A.8.24-31 | B11: Integrity Protection | C11: Keys shall have integrity protections applied while in storage.
A12: A.8.24-32 | B12: Least Privilege Access | C12: Access to cryptographic keys shall follow the principle of least privilege.
A13: A.8.24-33 | B13: MFA for Key Custodians | C13: Multi-factor authentication shall be required for key custodians.
A14: A.8.24-34 | B14: Key Access Register | C14: A register of individuals with access to key material shall be maintained.
A15: A.8.24-35 | B15: Rotation Periods Defined | C15: Key rotation periods shall be defined based on key type, risk, and regulatory requirements (TLS: 398d, AES: 2y, RSA/ECDSA: 3y, API keys: 90d, DB keys: 1y).
... A21: A.8.24-41 | B21: Export Control Guidance | C21: Personnel shall seek guidance from the legal department should export of cryptographic technologies or encrypted data be required.

Sheet Crypto Governance
A1: Crypto Governance — Compliance Checklist
A2: ISO/IEC 27001:2022 — Control A.8.24: Use of Cryptography
A3: Req # | B3: Section | C3: Requirement | D3: Status | E3: Evidence | F3: Owner | G3: Due Date | H3: Notes
A4: A.8.24-42 | B4: Trust Store Protection | C4: Trust stores shall be protected against injection of unauthorised root certificates; access controls shall be managed per entity and application.
A5: A.8.24-43 | B5: Trust Store Update Process | C5: A secure process for updating the trust store shall be implemented.
A6: A.8.24-44 | B6: Approved Libraries Only | C6: Only reputable cryptographic libraries shall be used that are actively maintained, regularly updated, and validated by third-party organisations (NIST/FIPS, Common Criteria).
A7: A.8.24-45 | B7: No Custom Crypto | C7: Custom cryptographic implementations shall not be developed unless specifically approved by the CISO with documented justification.
A8: A.8.24-46 | B8: [PCI — Optional] Cardholder Key Storage | C8: Secret and private keys used to encrypt/decrypt cardholder data shall be stored encrypted with a KEK at least as strong, stored separately, or within a PTS-approved device or HSM.
A9: A.8.24-47 | B9: [PCI — Optional] CDE Encryption | C9: Cardholder data environment encryption shall meet PCI DSS requirements in addition to this policy.
