Workbook

Sheet Executive Summary
A1: ISMS-OP-CHK-A.8.24 — Use of Cryptography Compliance Checklist
A3: DOCUMENT INFORMATION
A4: Document ID | B4: ISMS-OP-CHK-A.8.24
A5: Source Policy | B5: ISMS-OP-POL-A.8.24
A6: ISO Controls | B6: Use of Cryptography
A7: Generated | B7: 30.09.2026
A8: Prepared By
A9: Organisation
A10: Review Cycle | B10: Annual
A12: OVERALL COMPLIANCE STATUS
A13: Overall Compliance | B13: ='Dashboard'!G7
A14: Status | B14: =IF(Dashboard!H7>0,"INCOMPLETE",IF(Dashboard!G7="N/A","NOT ASSESSED",IF(ISNUMBER(VALUE(SUBSTITUTE(Dashboard!G7,"%",""))),IF(VALUE(SUBSTITUTE(Dashboard!G7,"%",""))>=90,"GREEN",IF(VALUE(SUBSTITUTE(Dashboard!G7,"%",""))>=70,"AMBER","RED")),"NOT ASSESSED")))
A16: KEY METRICS
A17: Total Requirements | B17: ='Dashboard'!B7
A18: Compliant | B18: ='Dashboard'!C7
A19: Partial | B19: ='Dashboard'!D7
A20: Non-Compliant | B20: ='Dashboard'!E7
A21: Not Applicable | B21: ='Dashboard'!F7
A22: Unanswered | B22: ='Dashboard'!H7
A23: Owner Coverage | B23: =IF(Dashboard!B7=0,"N/A",ROUND((COUNTA('Cryptographic Controls'!F4:F25)+COUNTA('Cryptographic Key Management'!F4:F25)+COUNTA('Optional Payment Card Data'!F4:F5))/Dashboard!B7*100,0)&"%")
A25: DOMAIN STATUS SUMMARY
A26: Domain | B26: Compliance % | C26: Compliant | D26: Gaps | E26: Status
A27: Cryptographic Controls | B27: ='Dashboard'!G4 | C27: ='Dashboard'!C4 | D27: ='Dashboard'!E4 | E27: =IF(Dashboard!H4>0,"INCOMPLETE",IF(Dashboard!G4="N/A","--",IF(ISNUMBER(VALUE(SUBSTITUTE(Dashboard!G4,"%",""))),IF(VALUE(SUBSTITUTE(Dashboard!G4,"%",""))>=90,"PASS",IF(VALUE(SUBSTITUTE(Dashboard!G4,"%",""))>=70,"REVIEW","FAIL")),"--")))
A28: Cryptographic Key Management | B28: ='Dashboard'!G5 | C28: ='Dashboard'!C5 | D28: ='Dashboard'!E5 | E28: =IF(Dashboard!H5>0,"INCOMPLETE",IF(Dashboard!G5="N/A","--",IF(ISNUMBER(VALUE(SUBSTITUTE(Dashboard!G5,"%",""))),IF(VALUE(SUBSTITUTE(Dashboard!G5,"%",""))>=90,"PASS",IF(VALUE(SUBSTITUTE(Dashboard!G5,"%",""))>=70,"REVIEW","FAIL")),"--")))
A29: Optional Payment Card Data | B29: ='Dashboard'!G6 | C29: ='Dashboard'!C6 | D29: ='Dashboard'!E6 | E29: =IF(Dashboard!H6>0,"INCOMPLETE",IF(Dashboard!G6="N/A","--",IF(ISNUMBER(VALUE(SUBSTITUTE(Dashboard!G6,"%",""))),IF(VALUE(SUBSTITUTE(Dashboard!G6,"%",""))>=90,"PASS",IF(VALUE(SUBSTITUTE(Dashboard!G6,"%",""))>=70,"REVIEW","FAIL")),"--")))
A31: CRITICAL ISSUES
A32: # | B32: Issue Description | C32: Domain | D32: Owner | E32: Due Date
A33: 1
A34: 2
A35: 3
A36: 4
A37: 5
A39: MANAGEMENT COMMENTARY
A40: [Enter management commentary on use of cryptography posture]
A44: APPROVAL
A45: Assessed By
A46: Name:
A47: Date:
A48: Signature:
A49: Decision:
...

Sheet Dashboard
A1: Use of Cryptography — Compliance Dashboard
A3: Domain | B3: Total Reqs | C3: Compliant | D3: Partial | E3: Non-Compliant | F3: N/A | G3: Compliance % | H3: Unassessed
A4: Cryptographic Controls | B4: =COUNTA('Cryptographic Controls'!A4:A25) | C4: =COUNTIF('Cryptographic Controls'!D4:D25,"Compliant") | D4: =COUNTIF('Cryptographic Controls'!D4:D25,"Partial") | E4: =COUNTIF('Cryptographic Controls'!D4:D25,"Non-Compliant") | F4: =COUNTIF('Cryptographic Controls'!D4:D25,"N/A") | G4: =IF((B4-F4)=0,"N/A",ROUND(C4/(B4-F4)*100,1)&"%") | H4: =B4-(C4+D4+E4+F4)
A5: Cryptographic Key Management | B5: =COUNTA('Cryptographic Key Management'!A4:A25) | C5: =COUNTIF('Cryptographic Key Management'!D4:D25,"Compliant") | D5: =COUNTIF('Cryptographic Key Management'!D4:D25,"Partial") | E5: =COUNTIF('Cryptographic Key Management'!D4:D25,"Non-Compliant") | F5: =COUNTIF('Cryptographic Key Management'!D4:D25,"N/A") | G5: =IF((B5-F5)=0,"N/A",ROUND(C5/(B5-F5)*100,1)&"%") | H5: =B5-(C5+D5+E5+F5)
A6: Optional Payment Card Data | B6: =COUNTA('Optional Payment Card Data'!A4:A5) | C6: =COUNTIF('Optional Payment Card Data'!D4:D5,"Compliant") | D6: =COUNTIF('Optional Payment Card Data'!D4:D5,"Partial") | E6: =COUNTIF('Optional Payment Card Data'!D4:D5,"Non-Compliant") | F6: =COUNTIF('Optional Payment Card Data'!D4:D5,"N/A") | G6: =IF((B6-F6)=0,"N/A",ROUND(C6/(B6-F6)*100,1)&"%") | H6: =B6-(C6+D6+E6+F6)
A7: TOTAL | B7: =SUM(B4:B6) | C7: =SUM(C4:C6) | D7: =SUM(D4:D6) | E7: =SUM(E4:E6) | F7: =SUM(F4:F6) | G7: =IF((B7-F7)=0,"N/A",ROUND(C7/(B7-F7)*100,1)&"%") | H7: =SUM(H4:H6)
A9: COMPLIANCE BY STATUS
A10: Compliant | B10: =C7 | C10: =IF(B7=0,"",ROUND(B10/B7*100,1)&"%")
A11: Partial | B11: =D7 | C11: =IF(B7=0,"",ROUND(B11/B7*100,1)&"%")
A12: Non-Compliant | B12: =E7 | C12: =IF(B7=0,"",ROUND(B12/B7*100,1)&"%")
A13: N/A | B13: =F7 | C13: =IF(B7=0,"",ROUND(B13/B7*100,1)&"%")
A15: TOP GAPS (Manual Entry)
A16: Priority | B16: Domain | C16: Requirement | D16: Owner | E16: Due Date | F16: Status
A28: COMPLIANCE TREND (Manual Entry)
A29: Assessment Date | B29: Overall % | C29: Compliant | D29: Gaps | E29: Assessor | F29: Notes

Sheet Cryptographic Controls
A1: Cryptographic Controls — Compliance Checklist
A2: ISO/IEC 27001:2022 — Control A.8.24: Use of Cryptography
A3: Req # | B3: Section | C3: Requirement | D3: Status | E3: Evidence | F3: Owner | G3: Due Date | H3: Notes
A4: A.8.24-01 | B4: Use The Following Minimum Cryptographic | C4: The organisation shall use the following minimum cryptographic standards:.
A5: A.8.24-02 | B5: Prohibited Algorithms:* Md5, Sha-1, Des, | C5: Prohibited algorithms:* MD5, SHA-1, DES, 3DES, RC4, RSA below 2048-bit. These shall not be used for any purpose.
A6: A.8.24-03 | B6: Monitor Nist Post-Quantum Cryptography | C6: The organisation shall monitor NIST post-quantum cryptography standards (FIPS 203 ML-KEM, FIPS 204 ML-DSA, FIPS 205 SLH-DSA) and plan migration as adoption timelines are established. A crypto-agility assessment shall be conducted to identify systems and data stores requiring PQC migration planning, prioritising long-lived keys and data with retention periods exceeding 10 years.
A7: A.8.24-04 | B7: Network Communications Carrying | C7: All network communications carrying confidential or personal data shall use encrypted transport:.
A8: A.8.24-05 | B8: Tls 1.3 Is Preferred And | C8: TLS 1.3 is preferred and shall be used where supported.
A9: A.8.24-06 | B9: Tls 1.0 And Tls 1.1 | C9: TLS 1.0 and TLS 1.1 shall be disabled on all systems.
A10: A.8.24-07 | B10: Ssl (All Versions) | C10: SSL (all versions) shall be disabled on all systems.
A11: A.8.24-08 | B11: Only Cipher Suites Using Aead (E.G | C11: Only cipher suites using AEAD (e.g., AES-GCM) shall be enabled where feasible.
A12: A.8.24-09 | B12: Mobile Devices, Laptops, And Removable | C12: Mobile devices, laptops, and removable media shall have full-disk encryption enabled at the hardware or operating system level.
A13: A.8.24-10 | B13: Device Encryption | C13: Device encryption shall not be disabled.
A14: A.8.24-11 | B14: Access To Encrypted Storage | C14: Access to encrypted storage shall be protected by a password, passphrase, PIN, or biometric authentication.
A15: A.8.24-12 | B15: Not Be Used To Transfer Confidential | C15: Email shall not be used to transfer confidential or personal data in an unencrypted format, in line with the Information Transfer Policy.
... A25: A.8.24-22 | B25: Not Be Used As A Communication | C25: Bluetooth shall not be used as a communication method for unencrypted confidential, personal, or otherwise sensitive data. See the Information Transfer Policy.

Sheet Cryptographic Key Management
A1: Cryptographic Key Management — Compliance Checklist
A2: ISO/IEC 27001:2022 — Control A.8.24: Use of Cryptography
A3: Req # | B3: Section | C3: Requirement | D3: Status | E3: Evidence | F3: Owner | G3: Due Date | H3: Notes
A4: A.8.24-23 | B4: Cryptographic Keys | C4: Cryptographic keys shall be generated within cryptographic modules with at least FIPS 140-2 or FIPS 140-3 compliance, or equivalent validated assurance.
A5: A.8.24-24 | B5: Any Random Values Required For Key | C5: Any random values required for key generation shall be generated within the cryptographic module using a validated random bit generator.
A6: A.8.24-25 | B6: Be Transported Using Secure Channels. | C6: Keys shall be transported using secure channels. Key material shall not be transmitted in plaintext over any network.
A7: A.8.24-26 | B7: Never Be Stored In Plaintext Format | C7: Keys shall never be stored in plaintext format.
A8: A.8.24-27 | B8: Be Stored In A Cryptographic Vault | C8: Keys shall be stored in a cryptographic vault, HSM, or cloud key management service (KMS).
A9: A.8.24-28 | B9: Not Be Hard-Coded In Source Code | C9: Keys shall not be hard-coded in source code, stored in configuration files in plaintext, or shared via email or messaging. This extends to API keys, tokens, service credentials, and other secrets — these shall be managed through a dedicated secrets management solution (e.g., AWS KMS, Azure Key Vault, HashiCorp Vault, or equivalent). Secrets do not require the same encryption-at-rest standards as data encryption keys but shall never be stored in plaintext and shall be rotated according to the key rotation periods above.
A10: A.8.24-29 | B10: Key Encryption Keys (Keks) Used To | C10: Key encryption keys (KEKs) used to wrap stored keys shall be at least as strong as the keys they protect.
A11: A.8.24-30 | B11: Have Integrity Protections Applied While | C11: Keys shall have integrity protections applied while in storage.
A12: A.8.24-31 | B12: Access To Cryptographic Keys | C12: Access to cryptographic keys shall follow the principle of least privilege.
A13: A.8.24-32 | B13: Administrative And Operational Access To | C13: Administrative and operational access to keys shall be separated where possible.
A14: A.8.24-33 | B14: Multi-Factor Authentication | C14: Multi-factor authentication shall be required for key custodians.
A15: A.8.24-34 | B15: A Register Of Individuals With Access | C15: A register of individuals with access to key material shall be maintained.
... A25: A.8.24-44 | B25: Custom Cryptographic Implementations | C25: Custom cryptographic implementations shall not be developed unless specifically approved by the CISO with documented justification.

Sheet Optional Payment Card Data
A1: Optional Payment Card Data — Compliance Checklist
A2: ISO/IEC 27001:2022 — Control A.8.24: Use of Cryptography
A3: Req # | B3: Section | C3: Requirement | D3: Status | E3: Evidence | F3: Owner | G3: Due Date | H3: Notes
A4: A.8.24-45 | B4: Secret And Private Keys Used To | C4: Secret and private keys used to encrypt/decrypt cardholder data shall be stored encrypted with a key-encrypting key at least as strong as the data-encrypting key, stored separately from the data-encrypting key, or within a PTS-approved device or HSM.
A5: A.8.24-46 | B5: Cardholder Data Environment Encryption | C5: Cardholder data environment encryption shall meet PCI DSS requirements in addition to this policy.
