Workbook

Sheet Executive Summary
A1: ISMS-OP-CHK-A.8.28 — Secure Coding Compliance Checklist
A3: DOCUMENT INFORMATION
A4: Document ID | B4: ISMS-OP-CHK-A.8.28
A5: Source Policy | B5: ISMS-OP-POL-A.8.28
A6: ISO Controls | B6: Secure Coding
A7: Generated | B7: 30.09.2026
A8: Prepared By
A9: Organisation
A10: Review Cycle | B10: Annual
A12: OVERALL COMPLIANCE STATUS
A13: Overall Compliance | B13: ='Dashboard'!G14
A14: Status | B14: =IF(Dashboard!H14>0,"INCOMPLETE",IF(Dashboard!G14="N/A","NOT ASSESSED",IF(ISNUMBER(VALUE(SUBSTITUTE(Dashboard!G14,"%",""))),IF(VALUE(SUBSTITUTE(Dashboard!G14,"%",""))>=90,"GREEN",IF(VALUE(SUBSTITUTE(Dashboard!G14,"%",""))>=70,"AMBER","RED")),"NOT ASSESSED")))
A16: KEY METRICS
A17: Total Requirements | B17: ='Dashboard'!B14
A18: Compliant | B18: ='Dashboard'!C14
A19: Partial | B19: ='Dashboard'!D14
A20: Non-Compliant | B20: ='Dashboard'!E14
A21: Not Applicable | B21: ='Dashboard'!F14
A22: Unanswered | B22: ='Dashboard'!H14
A23: Owner Coverage | B23: =IF(Dashboard!B14=0,"N/A",ROUND((COUNTA('Secure Coding Standards'!F4:F7)+COUNTA('Common Vulnerability Prevention'!F4:F11)+COUNTA('Dependency and Library Mgmt'!F4:F11)+COUNTA('Code Review Requirements'!F4:F17)+COUNTA('Static App Sec Testing (SAST)'!F4:F13)+COUNTA('Secure Coding Training'!F4:F7)+COUNTA('Insecure Coding Practices'!F4:F8)+COUNTA('Outsourced Development'!F4:F15)+COUNTA('Sec Champion Programme'!F4:F4)+COUNTA('Exception Management'!F4:F6))/Dashboard!B14*100,0)&"%")
A25: DOMAIN STATUS SUMMARY
A26: Domain | B26: Compliance % | C26: Compliant | D26: Gaps | E26: Status
A27: Secure Coding Standards | B27: ='Dashboard'!G4 | C27: ='Dashboard'!C4 | D27: ='Dashboard'!E4 | E27: =IF(Dashboard!H4>0,"INCOMPLETE",IF(Dashboard!G4="N/A","--",IF(ISNUMBER(VALUE(SUBSTITUTE(Dashboard!G4,"%",""))),IF(VALUE(SUBSTITUTE(Dashboard!G4,"%",""))>=90,"PASS",IF(VALUE(SUBSTITUTE(Dashboard!G4,"%",""))>=70,"REVIEW","FAIL")),"--")))
A28: Common Vulnerability Prevention | B28: ='Dashboard'!G5 | C28: ='Dashboard'!C5 | D28: ='Dashboard'!E5 | E28: =IF(Dashboard!H5>0,"INCOMPLETE",IF(Dashboard!G5="N/A","--",IF(ISNUMBER(VALUE(SUBSTITUTE(Dashboard!G5,"%",""))),IF(VALUE(SUBSTITUTE(Dashboard!G5,"%",""))>=90,"PASS",IF(VALUE(SUBSTITUTE(Dashboard!G5,"%",""))>=70,"REVIEW","FAIL")),"--")))
A29: Dependency and Library Mgmt | B29: ='Dashboard'!G6 | C29: ='Dashboard'!C6 | D29: ='Dashboard'!E6 | E29: =IF(Dashboard!H6>0,"INCOMPLETE",IF(Dashboard!G6="N/A","--",IF(ISNUMBER(VALUE(SUBSTITUTE(Dashboard!G6,"%",""))),IF(VALUE(SUBSTITUTE(Dashboard!G6,"%",""))>=90,"PASS",IF(VALUE(SUBSTITUTE(Dashboard!G6,"%",""))>=70,"REVIEW","FAIL")),"--")))
A30: Code Review Requirements | B30: ='Dashboard'!G7 | C30: ='Dashboard'!C7 | D30: ='Dashboard'!E7 | E30: =IF(Dashboard!H7>0,"INCOMPLETE",IF(Dashboard!G7="N/A","--",IF(ISNUMBER(VALUE(SUBSTITUTE(Dashboard!G7,"%",""))),IF(VALUE(SUBSTITUTE(Dashboard!G7,"%",""))>=90,"PASS",IF(VALUE(SUBSTITUTE(Dashboard!G7,"%",""))>=70,"REVIEW","FAIL")),"--")))
A31: Static App Sec Testing (SAST) | B31: ='Dashboard'!G8 | C31: ='Dashboard'!C8 | D31: ='Dashboard'!E8 | E31: =IF(Dashboard!H8>0,"INCOMPLETE",IF(Dashboard!G8="N/A","--",IF(ISNUMBER(VALUE(SUBSTITUTE(Dashboard!G8,"%",""))),IF(VALUE(SUBSTITUTE(Dashboard!G8,"%",""))>=90,"PASS",IF(VALUE(SUBSTITUTE(Dashboard!G8,"%",""))>=70,"REVIEW","FAIL")),"--")))
A32: Secure Coding Training | B32: ='Dashboard'!G9 | C32: ='Dashboard'!C9 | D32: ='Dashboard'!E9 | E32: =IF(Dashboard!H9>0,"INCOMPLETE",IF(Dashboard!G9="N/A","--",IF(ISNUMBER(VALUE(SUBSTITUTE(Dashboard!G9,"%",""))),IF(VALUE(SUBSTITUTE(Dashboard!G9,"%",""))>=90,"PASS",IF(VALUE(SUBSTITUTE(Dashboard!G9,"%",""))>=70,"REVIEW","FAIL")),"--")))
A33: Insecure Coding Practices | B33: ='Dashboard'!G10 | C33: ='Dashboard'!C10 | D33: ='Dashboard'!E10 | E33: =IF(Dashboard!H10>0,"INCOMPLETE",IF(Dashboard!G10="N/A","--",IF(ISNUMBER(VALUE(SUBSTITUTE(Dashboard!G10,"%",""))),IF(VALUE(SUBSTITUTE(Dashboard!G10,"%",""))>=90,"PASS",IF(VALUE(SUBSTITUTE(Dashboard!G10,"%",""))>=70,"REVIEW","FAIL")),"--")))
A34: Outsourced Development | B34: ='Dashboard'!G11 | C34: ='Dashboard'!C11 | D34: ='Dashboard'!E11 | E34: =IF(Dashboard!H11>0,"INCOMPLETE",IF(Dashboard!G11="N/A","--",IF(ISNUMBER(VALUE(SUBSTITUTE(Dashboard!G11,"%",""))),IF(VALUE(SUBSTITUTE(Dashboard!G11,"%",""))>=90,"PASS",IF(VALUE(SUBSTITUTE(Dashboard!G11,"%",""))>=70,"REVIEW","FAIL")),"--")))
A35: Sec Champion Programme | B35: ='Dashboard'!G12 | C35: ='Dashboard'!C12 | D35: ='Dashboard'!E12 | E35: =IF(Dashboard!H12>0,"INCOMPLETE",IF(Dashboard!G12="N/A","--",IF(ISNUMBER(VALUE(SUBSTITUTE(Dashboard!G12,"%",""))),IF(VALUE(SUBSTITUTE(Dashboard!G12,"%",""))>=90,"PASS",IF(VALUE(SUBSTITUTE(Dashboard!G12,"%",""))>=70,"REVIEW","FAIL")),"--")))
A36: Exception Management | B36: ='Dashboard'!G13 | C36: ='Dashboard'!C13 | D36: ='Dashboard'!E13 | E36: =IF(Dashboard!H13>0,"INCOMPLETE",IF(Dashboard!G13="N/A","--",IF(ISNUMBER(VALUE(SUBSTITUTE(Dashboard!G13,"%",""))),IF(VALUE(SUBSTITUTE(Dashboard!G13,"%",""))>=90,"PASS",IF(VALUE(SUBSTITUTE(Dashboard!G13,"%",""))>=70,"REVIEW","FAIL")),"--")))
A38: CRITICAL ISSUES
A39: # | B39: Issue Description | C39: Domain | D39: Owner | E39: Due Date
A40: 1
A41: 2
A42: 3
A43: 4
A44: 5
A46: MANAGEMENT COMMENTARY
...

Sheet Dashboard
A1: Secure Coding — Compliance Dashboard
A3: Domain | B3: Total Reqs | C3: Compliant | D3: Partial | E3: Non-Compliant | F3: N/A | G3: Compliance % | H3: Unassessed
A4: Secure Coding Standards | B4: =COUNTA('Secure Coding Standards'!A4:A7) | C4: =COUNTIF('Secure Coding Standards'!D4:D7,"Compliant") | D4: =COUNTIF('Secure Coding Standards'!D4:D7,"Partial") | E4: =COUNTIF('Secure Coding Standards'!D4:D7,"Non-Compliant") | F4: =COUNTIF('Secure Coding Standards'!D4:D7,"N/A") | G4: =IF((B4-F4)=0,"N/A",ROUND(C4/(B4-F4)*100,1)&"%") | H4: =B4-(C4+D4+E4+F4)
A5: Common Vulnerability Prevention | B5: =COUNTA('Common Vulnerability Prevention'!A4:A11) | C5: =COUNTIF('Common Vulnerability Prevention'!D4:D11,"Compliant") | D5: =COUNTIF('Common Vulnerability Prevention'!D4:D11,"Partial") | E5: =COUNTIF('Common Vulnerability Prevention'!D4:D11,"Non-Compliant") | F5: =COUNTIF('Common Vulnerability Prevention'!D4:D11,"N/A") | G5: =IF((B5-F5)=0,"N/A",ROUND(C5/(B5-F5)*100,1)&"%") | H5: =B5-(C5+D5+E5+F5)
A6: Dependency and Library Mgmt | B6: =COUNTA('Dependency and Library Mgmt'!A4:A11) | C6: =COUNTIF('Dependency and Library Mgmt'!D4:D11,"Compliant") | D6: =COUNTIF('Dependency and Library Mgmt'!D4:D11,"Partial") | E6: =COUNTIF('Dependency and Library Mgmt'!D4:D11,"Non-Compliant") | F6: =COUNTIF('Dependency and Library Mgmt'!D4:D11,"N/A") | G6: =IF((B6-F6)=0,"N/A",ROUND(C6/(B6-F6)*100,1)&"%") | H6: =B6-(C6+D6+E6+F6)
A7: Code Review Requirements | B7: =COUNTA('Code Review Requirements'!A4:A17) | C7: =COUNTIF('Code Review Requirements'!D4:D17,"Compliant") | D7: =COUNTIF('Code Review Requirements'!D4:D17,"Partial") | E7: =COUNTIF('Code Review Requirements'!D4:D17,"Non-Compliant") | F7: =COUNTIF('Code Review Requirements'!D4:D17,"N/A") | G7: =IF((B7-F7)=0,"N/A",ROUND(C7/(B7-F7)*100,1)&"%") | H7: =B7-(C7+D7+E7+F7)
A8: Static App Sec Testing (SAST) | B8: =COUNTA('Static App Sec Testing (SAST)'!A4:A13) | C8: =COUNTIF('Static App Sec Testing (SAST)'!D4:D13,"Compliant") | D8: =COUNTIF('Static App Sec Testing (SAST)'!D4:D13,"Partial") | E8: =COUNTIF('Static App Sec Testing (SAST)'!D4:D13,"Non-Compliant") | F8: =COUNTIF('Static App Sec Testing (SAST)'!D4:D13,"N/A") | G8: =IF((B8-F8)=0,"N/A",ROUND(C8/(B8-F8)*100,1)&"%") | H8: =B8-(C8+D8+E8+F8)
A9: Secure Coding Training | B9: =COUNTA('Secure Coding Training'!A4:A7) | C9: =COUNTIF('Secure Coding Training'!D4:D7,"Compliant") | D9: =COUNTIF('Secure Coding Training'!D4:D7,"Partial") | E9: =COUNTIF('Secure Coding Training'!D4:D7,"Non-Compliant") | F9: =COUNTIF('Secure Coding Training'!D4:D7,"N/A") | G9: =IF((B9-F9)=0,"N/A",ROUND(C9/(B9-F9)*100,1)&"%") | H9: =B9-(C9+D9+E9+F9)
A10: Insecure Coding Practices | B10: =COUNTA('Insecure Coding Practices'!A4:A8) | C10: =COUNTIF('Insecure Coding Practices'!D4:D8,"Compliant") | D10: =COUNTIF('Insecure Coding Practices'!D4:D8,"Partial") | E10: =COUNTIF('Insecure Coding Practices'!D4:D8,"Non-Compliant") | F10: =COUNTIF('Insecure Coding Practices'!D4:D8,"N/A") | G10: =IF((B10-F10)=0,"N/A",ROUND(C10/(B10-F10)*100,1)&"%") | H10: =B10-(C10+D10+E10+F10)
A11: Outsourced Development | B11: =COUNTA('Outsourced Development'!A4:A15) | C11: =COUNTIF('Outsourced Development'!D4:D15,"Compliant") | D11: =COUNTIF('Outsourced Development'!D4:D15,"Partial") | E11: =COUNTIF('Outsourced Development'!D4:D15,"Non-Compliant") | F11: =COUNTIF('Outsourced Development'!D4:D15,"N/A") | G11: =IF((B11-F11)=0,"N/A",ROUND(C11/(B11-F11)*100,1)&"%") | H11: =B11-(C11+D11+E11+F11)
A12: Sec Champion Programme | B12: =COUNTA('Sec Champion Programme'!A4:A4) | C12: =COUNTIF('Sec Champion Programme'!D4:D4,"Compliant") | D12: =COUNTIF('Sec Champion Programme'!D4:D4,"Partial") | E12: =COUNTIF('Sec Champion Programme'!D4:D4,"Non-Compliant") | F12: =COUNTIF('Sec Champion Programme'!D4:D4,"N/A") | G12: =IF((B12-F12)=0,"N/A",ROUND(C12/(B12-F12)*100,1)&"%") | H12: =B12-(C12+D12+E12+F12)
A13: Exception Management | B13: =COUNTA('Exception Management'!A4:A6) | C13: =COUNTIF('Exception Management'!D4:D6,"Compliant") | D13: =COUNTIF('Exception Management'!D4:D6,"Partial") | E13: =COUNTIF('Exception Management'!D4:D6,"Non-Compliant") | F13: =COUNTIF('Exception Management'!D4:D6,"N/A") | G13: =IF((B13-F13)=0,"N/A",ROUND(C13/(B13-F13)*100,1)&"%") | H13: =B13-(C13+D13+E13+F13)
A14: TOTAL | B14: =SUM(B4:B13) | C14: =SUM(C4:C13) | D14: =SUM(D4:D13) | E14: =SUM(E4:E13) | F14: =SUM(F4:F13) | G14: =IF((B14-F14)=0,"N/A",ROUND(C14/(B14-F14)*100,1)&"%") | H14: =SUM(H4:H13)
A16: COMPLIANCE BY STATUS
A17: Compliant | B17: =C14 | C17: =IF(B14=0,"",ROUND(B17/B14*100,1)&"%")
A18: Partial | B18: =D14 | C18: =IF(B14=0,"",ROUND(B18/B14*100,1)&"%")
A19: Non-Compliant | B19: =E14 | C19: =IF(B14=0,"",ROUND(B19/B14*100,1)&"%")
A20: N/A | B20: =F14 | C20: =IF(B14=0,"",ROUND(B20/B14*100,1)&"%")
A22: TOP GAPS (Manual Entry)
A23: Priority | B23: Domain | C23: Requirement | D23: Owner | E23: Due Date | F23: Status
A35: COMPLIANCE TREND (Manual Entry)
A36: Assessment Date | B36: Overall % | C36: Compliant | D36: Gaps | E36: Assessor | F36: Notes

Sheet Secure Coding Standards
A1: Secure Coding Standards — Compliance Checklist
A2: ISO/IEC 27001:2022 — Control A.8.28: Secure Coding
A3: Req # | B3: Section | C3: Requirement | D3: Status | E3: Evidence | F3: Owner | G3: Due Date | H3: Notes
A4: A.8.28-01 | B4: Establish And Maintain Documented Secure | C4: The organisation shall establish and maintain documented secure coding standards applicable to each programming language and framework in active use.
A5: A.8.28-02 | B5: The Development Manager | C5: The Development Manager shall maintain a register of approved languages and their associated secure coding references. At minimum:.
A6: A.8.28-03 | B6: The Development Manager | C6: Where a language is used that has no entry in this register, the Development Manager shall document the applicable secure coding reference before the language enters production use.
A7: A.8.28-04 | B7: Coding Standards Review*: Secure Coding | C7: Coding Standards Review*: Secure coding standards shall be reviewed annually, or when a new language or framework is adopted, or when a significant vulnerability class emerges that requires additional guidance.

Sheet Common Vulnerability Prevention
A1: Common Vulnerability Prevention — Compliance Checklist
A2: ISO/IEC 27001:2022 — Control A.8.28: Secure Coding
A3: Req # | B3: Section | C3: Requirement | D3: Status | E3: Evidence | F3: Owner | G3: Due Date | H3: Notes
A4: A.8.28-05 | B4: Write Code That Prevents The | C4: Developers shall write code that prevents the vulnerability classes identified by the OWASP Top 10 and CWE/SANS Top 25. The following sections define mandatory coding practices for the most prevalent vulnerability categories.
A5: A.8.28-06 | B5: Input From External Sources | C5: All input from external sources shall be treated as untrusted and validated before processing.
A6: A.8.28-07 | B6: Output Rendered To Users Or External | C6: All output rendered to users or external systems shall be encoded to prevent injection attacks.
A7: A.8.28-08 | B7: Application Code Implementing | C7: Application code implementing authentication and session handling shall follow established secure patterns.
A8: A.8.28-09 | B8: Generate Session Identifiers Using | C8: Generate session identifiers using cryptographically secure random number generators. Session IDs shall be of sufficient length (minimum 128 bits of entropy).
A9: A.8.28-10 | B9: Application Error Handling | C9: Application error handling shall prevent information disclosure and support security monitoring.
A10: A.8.28-11 | B10: Application Code That Implements Or Uses | C10: Application code that implements or uses cryptography shall follow the organisation's cryptographic policy.
A11: A.8.28-12 | B11: Application Code | C11: Application code shall enforce authorisation consistently.

Sheet Dependency and Library Mgmt
A1: Dependency and Library Mgmt — Compliance Checklist
A2: ISO/IEC 27001:2022 — Control A.8.28: Secure Coding
A3: Req # | B3: Section | C3: Requirement | D3: Status | E3: Evidence | F3: Owner | G3: Due Date | H3: Notes
A4: A.8.28-13 | B4: Third-Party Libraries, Frameworks, And | C4: Third-party libraries, frameworks, and open source components introduce supply chain risk and shall be managed throughout their lifecycle.
A5: A.8.28-14 | B5: Maintain A Dependency Inventory For Each | C5: Maintain a dependency inventory for each application. All production applications shall maintain a Software Bill of Materials (SBOM) in CycloneDX or SPDX format, generated automatically via the build pipeline.
A6: A.8.28-15 | B6: Sca Scanning | C6: SCA scanning shall run on every build (CI/CD pipeline integration). Builds shall fail if critical or high-severity dependency vulnerabilities are detected and unresolved.
A7: A.8.28-16 | B7: Evaluate New Dependencies Before | C7: Evaluate new dependencies before adoption: check maintenance status, known vulnerabilities, licence compatibility, and community activity. Abandoned or unmaintained libraries shall not be introduced.
A8: A.8.28-17 | B8: Sbom Generation | C8: SBOM generation shall be standard practice for all applications, not limited to high-risk applications.
A9: A.8.28-18 | B9: Storage And Access: Sboms Stored In | C9: Storage and access: SBOMs stored in [Artifact Repository / Dependency Track / SBOM Platform], accessible to the Development Team, Security Team, Legal (for licence compliance), and Incident Response team. Each SBOM shall be tagged with the corresponding application version (1:1 relationship).
A10: A.8.28-19 | B10: Timeline: All Production Applications | C10: Timeline: All production applications shall generate SBOMs by [Date — suggest 6 months from policy effective date]. Phased rollout: critical applications first (Month 1–3), then all production (Month 4–6).
A11: A.8.28-20 | B11: Pinning Dependency Versions Ensures | C11: Pinning dependency versions ensures reproducible builds but creates staleness risk if versions are never updated. The organisation shall maintain a dependency update cadence to balance stability with security.

Sheet Code Review Requirements
A1: Code Review Requirements — Compliance Checklist
A2: ISO/IEC 27001:2022 — Control A.8.28: Secure Coding
A3: Req # | B3: Section | C3: Requirement | D3: Status | E3: Evidence | F3: Owner | G3: Due Date | H3: Notes
A4: A.8.28-21 | B4: Code Changes | C4: All code changes shall be reviewed before merging to protected branches.
A5: A.8.28-22 | B5: The Number Of Reviewers And Their | C5: The number of reviewers and their qualifications shall be determined by the risk classification of the code change:.
A6: A.8.28-23 | B6: Qualifications: Security Champion | C6: Qualifications: Security Champion shall have completed Security Champion training.
A7: A.8.28-24 | B7: Approval: Both Reviewers | C7: Approval: Both reviewers shall approve before merge.
A8: A.8.28-25 | B8: Qualifications: Reviewer | C8: Qualifications: Reviewer shall understand infrastructure implications.
A9: A.8.28-26 | B9: Testing | C9: Testing: Shall include automated security tests (SAST passed, integration tests passed).
A10: A.8.28-27 | B10: Security Champions | C10: Security Champions shall have dedicated time allocation for security reviews (10% of work time).
A11: A.8.28-28 | B11: If Security Champion Unavailable: | C11: If Security Champion unavailable: Security Team shall provide review within 48 hours.
A12: A.8.28-29 | B12: Documentation: Pr Description | C12: Documentation: PR description shall state the review type required based on code classification (standard, security-critical, high-risk). CI/CD checks shall verify that the review approval count matches the requirement.
A13: A.8.28-30 | B13: The Code Author | C13: The code author shall not approve their own code (separation of duties).
A14: A.8.28-31 | B14: Verify Adherence To The Organisation'S | C14: Reviewers shall verify adherence to the organisation's secure coding standards.
A15: A.8.28-32 | B15: Check For: Hard-Coded Secrets, Insecure | C15: Reviewers shall check for: hard-coded secrets, insecure coding patterns, missing input validation, missing output encoding, excessive permissions, inadequate error handling, and missing logging.
... A17: A.8.28-34 | B17: Be Completed Before The Code Is | C17: Reviews shall be completed before the code is merged to a protected branch.

Sheet Static App Sec Testing (SAST)
A1: Static App Sec Testing (SAST) — Compliance Checklist
A2: ISO/IEC 27001:2022 — Control A.8.28: Secure Coding
A3: Req # | B3: Section | C3: Requirement | D3: Status | E3: Evidence | F3: Owner | G3: Due Date | H3: Notes
A4: A.8.28-35 | B4: Automated Static Analysis | C4: Automated static analysis shall be integrated into the development workflow to detect security defects before deployment.
A5: A.8.28-36 | B5: Deploy A Sast Tool ([Sast Tool] | C5: The organisation shall deploy a SAST tool ([SAST Tool] — e.g., SonarQube, Semgrep, CodeQL, Checkmarx, or equivalent) integrated into the CI/CD pipeline.
A6: A.8.28-37 | B6: Sast Scans | C6: SAST scans shall run on every pull request or merge request to a protected branch.
A7: A.8.28-38 | B7: Sast Results | C7: SAST results shall be reviewed before merging. Critical and high-severity findings shall block the merge until resolved or explicitly accepted as false positives with documented justification.
A8: A.8.28-39 | B8: Sast Rule Sets | C8: SAST rule sets shall cover, at minimum, the OWASP Top 10 and CWE/SANS Top 25 vulnerability classes.
A9: A.8.28-40 | B9: False Positives | C9: False positives shall be documented and suppressed following the suppression procedure below. Suppression without justification and peer review is prohibited.
A10: A.8.28-41 | B10: Sast Tool Configuration And Rule Sets | C10: SAST tool configuration and rule sets shall be reviewed annually by the Development Manager and Security Team.
A11: A.8.28-42 | B11: Peer Review Required: Another Developer | C11: Peer review required: Another developer OR Security Champion shall review the suppression request.
A12: A.8.28-43 | B12: Security Team Approval (For | C12: Security Team approval (for Critical/High findings): The Security Team shall approve suppression of Critical/High severity findings. Medium/Low findings may be approved by a peer reviewer.
A13: A.8.28-44 | B13: Quarterly Review: Security Team | C13: Quarterly review: Security Team shall sample 20% of suppressed findings.

Sheet Secure Coding Training
A1: Secure Coding Training — Compliance Checklist
A2: ISO/IEC 27001:2022 — Control A.8.28: Secure Coding
A3: Req # | B3: Section | C3: Requirement | D3: Status | E3: Evidence | F3: Owner | G3: Due Date | H3: Notes
A4: A.8.28-45 | B4: Receive Training To Write Secure Code | C4: Developers shall receive training to write secure code effectively.
A5: A.8.28-46 | B5: Training Content* | C5: Training Content* shall cover, at minimum:.
A6: A.8.28-47 | B6: Training Evidence*: Completion Records | C6: Training Evidence*: Completion records shall be maintained in [HR System / LMS] and reviewed by the Development Manager quarterly.
A7: A.8.28-48 | B7: Training Requirements | C7: Training requirements shall be enforced through escalating consequences for non-compliance:.

Sheet Insecure Coding Practices
A1: Insecure Coding Practices — Compliance Checklist
A2: ISO/IEC 27001:2022 — Control A.8.28: Secure Coding
A3: Req # | B3: Section | C3: Requirement | D3: Status | E3: Evidence | F3: Owner | G3: Due Date | H3: Notes
A4: A.8.28-49 | B4: The Prohibition On Hard-Coded Secrets In | C4: The prohibition on hard-coded secrets in the table above shall be enforced through automated detection at multiple layers.
A5: A.8.28-50 | B5: Blocks Commit If Secrets Detected | C5: Blocks commit if secrets detected (developer shall remove before re-commit).
A6: A.8.28-51 | B6: Onboarding: All Developers | C6: Onboarding: All developers shall be instructed to install the pre-commit hook during onboarding.
A7: A.8.28-52 | B7: Fail If Secrets Are Detected (No | C7: Builds shall fail if secrets are detected (no merge until remediated).
A8: A.8.28-53 | B8: Documentation: Secrets Detection Tool | C8: Documentation: Secrets detection tool configuration shall be maintained in [CI/CD Config Repository] and reviewed quarterly by the Security Team.

Sheet Outsourced Development
A1: Outsourced Development — Compliance Checklist
A2: ISO/IEC 27001:2022 — Control A.8.28: Secure Coding
A3: Req # | B3: Section | C3: Requirement | D3: Status | E3: Evidence | F3: Owner | G3: Due Date | H3: Notes
A4: A.8.28-54 | B4: Code Produced By External Contractors | C4: Code produced by external contractors and outsourced development teams shall meet the same secure coding standards as internally developed code.
A5: A.8.28-55 | B5: Require Adherence To The Organisation'S | C5: Contracts shall require adherence to the organisation's secure coding standards and this policy.
A6: A.8.28-56 | B6: Provide Evidence Of Secure Coding | C6: Contractors shall provide evidence of secure coding training for their developers.
A7: A.8.28-57 | B7: Contractor-Produced Code | C7: All contractor-produced code shall undergo the same code review and SAST scanning as internal code.
A8: A.8.28-58 | B8: Remediate Security Findings Within The | C8: Contractors shall remediate security findings within the organisation's defined SLAs.
A9: A.8.28-59 | B9: Contractor Code | C9: Contractor code shall be reviewed by an internal developer before merging.
A10: A.8.28-60 | B10: Sast And Sca Results For | C10: SAST and SCA results for contractor-produced code shall be visible to the organisation's Security Team.
A11: A.8.28-61 | B11: High-Risk Code Produced By Contractors | C11: High-risk code produced by contractors (authentication, authorisation, cryptography, data protection) shall receive a security-focused code review by a Security Champion or Security Architect.
A12: A.8.28-62 | B12: In Addition To Ongoing Code Review | C12: In addition to ongoing code review and scanning, the organisation shall conduct periodic audits of contractor-produced code to verify sustained quality and compliance.
A13: A.8.28-63 | B13: Poor Performance: 3 Consecutive Quarters | C13: Poor performance: 3 consecutive quarters below threshold shall trigger contract review and possible termination.
A14: A.8.28-64 | B14: Action: Contractors | C14: Action: Contractors shall address Critical/High recommendations within 90 days.
A15: A.8.28-65 | B15: Documentation: Contractor Audit Reports | C15: Documentation: Contractor audit reports shall be retained for contract duration + 3 years.

Sheet Sec Champion Programme
A1: Sec Champion Programme — Compliance Checklist
A2: ISO/IEC 27001:2022 — Control A.8.28: Secure Coding
A3: Req # | B3: Section | C3: Requirement | D3: Status | E3: Evidence | F3: Owner | G3: Due Date | H3: Notes
A4: A.8.28-66 | B4: Documentation: Security Champion | C4: Documentation: Security Champion Register shall be maintained in [HR System / Wiki] with names, teams, appointment dates, and training completion.

Sheet Exception Management
A1: Exception Management — Compliance Checklist
A2: ISO/IEC 27001:2022 — Control A.8.28: Secure Coding
A3: Req # | B3: Section | C3: Requirement | D3: Status | E3: Evidence | F3: Owner | G3: Due Date | H3: Notes
A4: A.8.28-67 | B4: Exceptions To This Policy | C4: Exceptions to this policy shall be requested in writing and shall include:.
A5: A.8.28-68 | B5: Be Approved By The Development Manager | C5: Exceptions shall be approved by the Development Manager and Information Security Manager (mandatory), plus the CISO for production application exceptions. All active exceptions shall be reviewed quarterly.
A6: A.8.28-69 | B6: Legacy Code Base That Cannot Be | C6: Where technically infeasible to meet a requirement (e.g., legacy code base that cannot be refactored immediately), compensating controls shall be implemented, documented, verified by the Information Security Manager, and reviewed annually.
