Workbook

Sheet Instructions_Legend
A1: ISMS Control ISMS-IMP-A.8.12.2 - Data Classification
A2: ISO/IEC 27001:2022 Control A.8.12 - Data Leakage Prevention
A4: Document ID: | B4: ISMS-IMP-A.8.12.2
A5: Assessment Area: | B5: Data Classification
A6: Related Policy: | B6: ISMS-POL-A.8.12-S2.1
A7: Version: | B7: 1.0
A8: Assessment Date: | B8: [USER INPUT]
A9: Completed By: | B9: [USER INPUT]
A10: Organization: | B10: [USER INPUT]
A11: Review Cycle: | B11: Quarterly
A14: HOW TO USE THIS WORKBOOK
A15: 1. Complete each worksheet tab in sequence (Schema → Inventory → Locations → Owners → ...)
A16: 2. Fill ALL yellow-highlighted cells with your organization's information
A17: 3. Use dropdown menus where provided (do not type free-form text in dropdown cells)
A18: 4. Document your data classification schema (minimum 4 levels: Public/Internal/Confidential/Restricted)
A19: 5. Inventory ALL sensitive data categories (PII, financial, IP, credentials, business confidential)
A20: 6. Map data to storage locations (file servers, databases, cloud, endpoints)
A21: 7. Assign data owners and stewards for accountability
A22: 8. Map data categories to regulatory requirements (FADP, GDPR, PCI-DSS)
A23: 9. Provide evidence IDs for all assessments (format: A812-2-[CATEGORY]-[###])
A24: 10. Review Summary Dashboard for overall classification compliance score
A25: 11. Obtain DPO/CISO approval before finalizing
A28: LEGEND - RESPONSE VALUES
A29: Yes | B29: Fully implemented and documented
A30: No | B30: Not implemented
A31: Partial | B31: Partially implemented (explain in notes)
A32: Planned | B32: Scheduled for implementation (provide target date)
A33: N/A | B33: Not applicable (provide justification)
A36: DATA CLASSIFICATION LEVELS (Standard)
A37: Public | B37: Information approved for public disclosure
A38: Internal | B38: Information for internal use only, no external sharing
A39: Confidential | B39: Sensitive information requiring protection, limited internal access
A40: Restricted | B40: Highly sensitive data, need-to-know basis, strict controls
A43: EVIDENCE NAMING CONVENTION
A44: Format: A812-2-[CATEGORY]-[###]
A45: Examples:
A46: • A812-2-CLS-001 = Classification - Schema document
A47: • A812-2-INV-001 = Inventory - Data discovery report
A48: • A812-2-OWN-001 = Ownership - Assignment matrix
A49: • A812-2-REG-001 = Regulatory - FADP compliance mapping
...

Sheet Classification_Schema
A1: DATA CLASSIFICATION SCHEMA
A2: Document your organizational data classification levels and handling requirements
A3: Classification Level | B3: Definition | C3: Examples | D3: Handling Requirements | E3: Access Controls | F3: Encryption Required | G3: DLP Monitoring | H3: Retention Period | I3: Disposal Method | J3: Evidence ID
A4: Public | B4: [Define what Public means for your organization] | C4: [Examples: Press releases, marketing materials, public website] | D4: [Handling: Can be shared externally] | E4: [Access: No restrictions]
A5: Internal | B5: [Define Internal classification] | C5: [Examples: Internal policies, procedures, org charts] | D5: [Handling: Internal use only, no external sharing without approval] | E5: [Access: All employees]
A6: Confidential | B6: [Define Confidential classification] | C6: [Examples: Customer lists, financial reports, contracts] | D6: [Handling: Limited distribution, need-to-know basis] | E6: [Access: Authorized personnel only]
A7: Restricted | B7: [Define Restricted classification] | C7: [Examples: Trade secrets, M&A, executive comp, PII] | D7: [Handling: Strictly controlled, encrypted, logged access] | E7: [Access: Explicit authorization required]

Sheet Sensitive_Data_Inventory
A1: SENSITIVE DATA INVENTORY
A2: Inventory ALL sensitive data categories requiring DLP protection
A3: Data Category | B3: Data Type | C3: Classification Level | D3: Regulatory Requirement | E3: Data Examples | F3: Business Owner | G3: Data Steward | H3: Estimated Volume | I3: Discovery Status | J3: DLP Protection | K3: Evidence ID
A4: Personal Names | B4: PII | C4: Confidential | D4: FADP/GDPR | E4: First name, last name, full name | F4: [Owner] | G4: [Steward] | H4: [Volume] | I4: Discovered | J4: Yes | K4: A812-2-INV-001
A5: Email Addresses | B5: PII | C5: Confidential | D5: FADP/GDPR | E5: john.doe@example.com | F5: [Owner] | G5: [Steward] | H5: [Volume] | I5: Discovered | J5: Yes | K5: A812-2-INV-002
A6: Swiss Social Security (AHV) | B6: PII | C6: Restricted | D6: FADP | E6: 756.1234.5678.90 | F6: [Owner] | G6: [Steward] | H6: [Volume] | I6: Discovered | J6: Yes | K6: A812-2-INV-003
A7: Credit Card Numbers | B7: Financial | C7: Restricted | D7: PCI-DSS | E7: 4111-1111-1111-1111 | F7: [Owner] | G7: [Steward] | H7: [Volume] | I7: Discovered | J7: Yes | K7: A812-2-INV-004
A8: Bank Account (IBAN) | B8: Financial | C8: Restricted | D8: FADP/GDPR | E8: CH93 0076 2011 6238 5295 7 | F8: [Owner] | G8: [Steward] | H8: [Volume] | I8: Discovered | J8: Partial | K8: A812-2-INV-005
A9: API Keys | B9: Credentials | C9: Restricted | D9: None | E9: sk_live_abcd1234efgh5678 | F9: [Owner] | G9: [Steward] | H9: [Volume] | I9: In Progress | J9: Partial | K9: A812-2-INV-006
A10: Source Code | B10: IP | C10: Confidential | D10: None | E10: Proprietary algorithms, trade secrets | F10: [Owner] | G10: [Steward] | H10: [Volume] | I10: Discovered | J10: Yes | K10: A812-2-INV-007
A11: Customer Lists | B11: Business Confidential | C11: Confidential | D11: FADP/GDPR | E11: CRM exports, contact databases | F11: [Owner] | G11: [Steward] | H11: [Volume] | I11: Discovered | J11: Partial | K11: A812-2-INV-008
A12: M&A Documents | B12: Business Confidential | C12: Restricted | D12: None | E12: Acquisition targets, financial models | F12: [Owner] | G12: [Steward] | H12: [Volume] | I12: Discovered | J12: Yes | K12: A812-2-INV-009
A13: Employee Health Records | B13: PII | C13: Restricted | D13: FADP/GDPR | E13: Medical diagnoses, disability status | F13: [Owner] | G13: [Steward] | H13: [Volume] | I13: Discovered | J13: Partial | K13: A812-2-INV-010

Sheet Data_Location_Mapping
A1: DATA LOCATION MAPPING
A2: Map sensitive data categories to storage locations (file servers, databases, cloud, endpoints)
A3: Data Category | B3: Storage Location Type | C3: Specific Location | D3: Path/Schema | E3: Estimated Records/Files | F3: Last Discovery Scan | G3: DLP Coverage | H3: Encryption at Rest | I3: Access Controls | J3: Data Owner Notified | K3: Evidence ID
A4: Credit Card Numbers | B4: Database | C4: SQL-PROD-01 | D4: dbo.Payments.CCNumber | E4: 250000 | F4: 2024-12-10 | G4: Yes | H4: Yes | I4: Yes | J4: Yes | K4: A812-2-LOC-001
A5: Customer PII | B5: File Server | C5: FS-HR-01 | D5: \\HR\PersonnelFiles\ | E5: 5000 | F5: 2024-12-15 | G5: Partial | H5: Yes | I5: Yes | J5: Yes | K5: A812-2-LOC-002
A6: Source Code | B6: Cloud | C6: GitHub Enterprise | D6: /repos/proprietary/ | E6: 150 | F6: 2024-12-01 | G6: Yes | H6: Yes | I6: Yes | J6: Yes | K6: A812-2-LOC-003
A7: API Keys | B7: Endpoint | C7: Developer Workstations | D7: Various local configs | E7: [Unknown] | F7: 2024-11-20 | G7: No | H7: Partial | I7: Partial | J7: No | K7: A812-2-LOC-004
A8: Email Archives | B8: Email | C8: M365 Exchange Online | D8: All mailboxes | E8: 2000000 | F8: 2024-12-20 | G8: Yes | H8: Yes | I8: Yes | J8: Yes | K8: A812-2-LOC-005

Sheet Data_Owner_Assignment
A1: DATA OWNER ASSIGNMENT
A2: Assign data owners and stewards for each data category - accountability is key!
A3: Data Category | B3: Business Owner Name | C3: Business Owner Department | D3: Business Owner Email | E3: Data Steward Name | F3: Data Steward Department | G3: Data Steward Email | H3: Ownership Documented | I3: Owner Training Complete | J3: Last Review Date | K3: Evidence ID
A4: Customer PII | B4: Jane Smith | C4: Sales | D4: jane.smith@example.com | E4: John Security | F4: IT Security | G4: john.sec@example.com | H4: Yes | I4: Yes | J4: 2024-12-01 | K4: A812-2-OWN-001
A5: Financial Data | B5: Robert Johnson | C5: Finance | D5: robert.j@example.com | E5: Mary InfoSec | F5: IT Security | G5: mary.is@example.com | H5: Yes | I5: Partial | J5: 2024-11-15 | K5: A812-2-OWN-002
A6: Source Code | B6: Alice Developer | C6: R&D | D6: alice.dev@example.com | E6: Bob CISO | F6: IT Security | G6: bob.ciso@example.com | H6: Yes | I6: Yes | J6: 2024-12-10 | K6: A812-2-OWN-003

Sheet Regulatory_Mapping
A1: REGULATORY COMPLIANCE MAPPING
A2: Map data categories to regulatory requirements (FADP, GDPR, PCI-DSS, etc.)
A3: Data Category | B3: Regulation | C3: Specific Article/Section | D3: Requirement Summary | E3: Compliance Status | F3: DLP Controls Required | G3: Breach Notification Required | H3: Data Subject Rights | I3: Evidence ID
A4: Personal Names | B4: FADP | C4: Article 4(1) | D4: Defined as personal data, requires appropriate protection measures | E4: Compliant | F4: Yes | G4: Yes | H4: Access, deletion, portability | I4: A812-2-REG-001
A5: Special Category PII | B5: GDPR | C5: Article 9 | D5: Sensitive data (health, biometric, etc.) - strict processing rules | E5: Compliant | F5: Yes | G5: Yes | H5: All GDPR rights apply | I5: A812-2-REG-002
A6: Credit Card Numbers | B6: PCI-DSS | C6: Requirement 3 | D6: Protect stored cardholder data with encryption and access controls | E6: Partial | F6: Yes | G6: Yes | H6: N/A (PCI-DSS) | I6: A812-2-REG-003
A7: Swiss AHV Number | B7: FADP | C7: Article 5 | D7: Special category personal data, heightened protection required | E7: Compliant | F7: Yes | G7: Yes | H7: Access, deletion, correction | I7: A812-2-REG-004
A8: Employee Health Data | B8: FADP/GDPR | C8: FADP Art 5, GDPR Art 9 | D8: Health data is special category, strict consent and security | E8: Compliant | F8: Yes | G8: Yes | H8: All data subject rights | I8: A812-2-REG-005

Sheet Labeling_Methods
A1: DATA LABELING METHODS
A2: Assess data labeling and classification marking methods across systems
A3: System/Application | B3: Labeling Method | C3: Classification Tool | D3: Supported Labels | E3: User Training Provided | F3: Enforcement Capability | G3: DLP Integration | H3: Adoption Rate % | I3: Evidence ID
A4: Microsoft 365 | B4: Automated | C4: Microsoft Purview (AIP) | D4: Public, Internal, Confidential, Restricted | E4: Yes | F4: Yes | G4: Yes | H4: 85 | I4: A812-2-LBL-001
A5: SharePoint | B5: Manual | C5: Built-in Classification | D5: Public, Internal, Restricted | E5: Partial | F5: Partial | G5: Partial | H5: 60 | I5: A812-2-LBL-002
A6: File Servers | B6: None | C6: None | D6: None | E6: No | F6: No | G6: No | H6: 0 | I6: A812-2-LBL-003
A7: Email (Outlook) | B7: Manual | C7: Azure Information Protection | D7: All 4 levels | E7: Yes | F7: Yes | G7: Yes | H7: 70 | I7: A812-2-LBL-004

Sheet Discovery_Results
A1: DATA DISCOVERY RESULTS
A2: Document data discovery and scanning results (Spirion, BigID, manual audits)
A3: Discovery Tool | B3: Scan Target | C3: Scan Date | D3: Data Categories Found | E3: Total Findings | F3: Critical Findings | G3: False Positive Rate % | H3: Remediation Status | I3: Data Owner Notified | J3: Evidence ID
A4: Spirion | B4: FS-HR-01 | C4: 2024-12-15 | D4: PII, SSN, AHV | E4: 5243 | F4: 1200 | G4: 15 | H4: In Progress | I4: Yes | J4: A812-2-DSC-001
A5: BigID | B5: SQL-PROD-01 | C5: 2024-12-10 | D5: PII, CCN, IBAN | E5: 250000 | F5: 50000 | G5: 5 | H5: In Progress | I5: Yes | J5: A812-2-DSC-002
A6: Manual Audit | B6: SharePoint | C6: 2024-11-20 | D6: Business Confidential | E6: 1500 | F6: 300 | G6: 30 | H6: Complete | I6: Yes | J6: A812-2-DSC-003

Sheet Gap_Analysis
A1: GAP ANALYSIS - IDENTIFIED DEFICIENCIES
A2: Document all data classification gaps and remediation plans
A3: Gap ID | B3: Gap Description | C3: Affected Data Category | D3: Risk Level | E3: Business Impact | F3: Root Cause | G3: Remediation Plan | H3: Owner | I3: Target Date | J3: Status | K3: Evidence ID
A4: GAP-A812-2-001 | B4: No data classification schema documented | C4: All data | D4: Critical | E4: Uncontrolled data handling, no DLP baseline | F4: Schema never formally defined | G4: Create and approve 4-tier classification schema | H4: [Owner] | I4: [Date] | J4: Open | K4: A812-2-GAP-001
A5: GAP-A812-2-002 | B5: PII found on file servers without DLP protection | C5: Customer PII | D5: High | E5: Potential FADP/GDPR violation, unmonitored exfiltration | F5: File servers not in DLP scope | G5: Deploy endpoint DLP to file servers | H5: [Owner] | I5: [Date] | J5: Open | K5: A812-2-GAP-002
A6: GAP-A812-2-003 | B6: Data owners not assigned for 40% of data categories | C6: Multiple | D6: High | E6: Lack of accountability, unclear data stewardship | F6: Ownership process not established | G6: Execute data owner assignment workshops | H6: [Owner] | I6: [Date] | J6: Open | K6: A812-2-GAP-003

Sheet Evidence_Register
A1: EVIDENCE REGISTER - AUDIT TRAIL
A2: Track all evidence collected during data classification assessment
A3: Evidence ID | B3: Evidence Type | C3: Description | D3: Location/Link | E3: Date Collected | F3: Collected By | G3: Related Requirement | H3: Verification Status

Sheet Summary_Dashboard
A1: Data Classification - COMPLIANCE DASHBOARD
A3: Assessment Date: | B3: [USER INPUT] | D3: DPO Approval: | E3: [Dropdown]
A4: Completed By: | B4: [USER INPUT] | D4: Last Review: | E4: [Date]
A6: KEY PERFORMANCE INDICATORS
A7: KPI | B7: Current Value | C7: Target | D7: Status | E7: Trend | F7: Notes
A8: Classification Schema Documented | B8: =COUNTIF(Classification_Schema!F$4:F$10,"Yes") | C8: 4 | D8: =IF(B8>=4,"✅ Pass","❌ Fail") | E8: →
A9: Sensitive Data Categories Inventoried | B9: =COUNTA(Sensitive_Data_Inventory!A$4:A$33)-10 | C9: ≥20 | D9: =IF(B9>=20,"✅ Pass","❌ Fail") | E9: →
A10: Data Locations Mapped | B10: =COUNTA(Data_Location_Mapping!A$6:A$45)-5 | C10: ≥30 | D10: =IF(B10>=30,"✅ Pass","❌ Fail") | E10: →
A11: Data Owners Assigned % | B11: =COUNTIF(Data_Owner_Assignment!H$4:H$33,"Yes")/B9*100 | C11: ≥90% | D11: =IF(B11>=90,"✅ Pass","❌ Fail") | E11: →
A12: DLP Protection Coverage % | B12: =COUNTIF(Sensitive_Data_Inventory!J$4:J$33,"Yes")/B9*100 | C12: ≥80% | D12: =IF(B12>=80,"✅ Pass","❌ Fail") | E12: →
A13: Regulatory Compliance % | B13: =COUNTIF(Regulatory_Mapping!E$4:E$28,"Compliant")/(COUNTA(Regulatory_Mapping!A$4:A$28)-5)*100 | C13: ≥90% | D13: =IF(B13>=90,"✅ Pass","❌ Fail") | E13: →
A14: Labeling Tool Adoption % | B14: =AVERAGE(Labeling_Methods!H$4:H$23) | C14: ≥75% | D14: =IF(B14>=75,"✅ Pass","❌ Fail") | E14: →
A15: Data Discovery Coverage % | B15: =COUNTIF(Discovery_Results!H$4:H$33,"Complete")/(COUNTA(Discovery_Results!A$4:A$33)-3)*100 | C15: ≥80% | D15: =IF(B15>=80,"✅ Pass","❌ Fail") | E15: →
A16: Total Gaps Identified | B16: =COUNTA(Gap_Analysis!A$4:A$43)-3 | C16: ≤10 | D16: =IF(B16<=10,"✅ Pass","❌ Fail") | E16: →
A17: Critical/High Gaps | B17: =COUNTIFS(Gap_Analysis!D$4:D$43,"Critical")+COUNTIFS(Gap_Analysis!D$4:D$43,"High") | C17: 0 | D17: =IF(B17=0,"✅ Pass","❌ Fail") | E17: →
A18: Overall Classification Compliance % | B18: =AVERAGE(B11:B15) | C18: ≥85% | D18: =IF(B18>=85,"✅ Compliant",IF(B18>=70,"⚠️ Partial","❌ Non-Compliant")) | E18: →
A21: GAP SUMMARY BY RISK LEVEL
A22: Risk Level | B22: Count | C22: % of Total
A23: Critical | B23: =COUNTIF(Gap_Analysis!D$4:D$43,"Critical") | C23: =B23/B16*100
A24: High | B24: =COUNTIF(Gap_Analysis!D$4:D$43,"High") | C24: =B24/B16*100
A25: Medium | B25: =COUNTIF(Gap_Analysis!D$4:D$43,"Medium") | C25: =B25/B16*100
A26: Low | B26: =COUNTIF(Gap_Analysis!D$4:D$43,"Low") | C26: =B26/B16*100
A29: EVIDENCE COMPLETENESS
A30: Metric | B30: Value
A31: Evidence Items Collected | B31: =COUNTA(Evidence_Register!A$4:A$105)
A32: Evidence Items Verified | B32: =COUNTIF(Evidence_Register!H$4:H$105,"Verified")
A33: Evidence Completeness % | B33: =B32/B31*100
A36: APPROVAL SIGN-OFF
A37: Approver | B37: Name | C37: Signature | D37: Date | E37: Status
A38: DPO
A39: CISO
A40: Legal Counsel
