Workbook

Sheet Executive Summary
A1: ISMS-OP-CHK-A.7.4-5-11 — Physical Infrastructure Security Compliance Checklist
A3: DOCUMENT INFORMATION
A4: Document ID | B4: ISMS-OP-CHK-A.7.4-5-11
A5: Source Policy | B5: ISMS-OP-POL-A.7.4-5-11
A6: ISO Controls | B6: Physical Infrastructure Security
A7: Generated | B7: 08.02.2026
A8: Prepared By
A9: Organisation
A10: Review Cycle | B10: Annual
A12: OVERALL COMPLIANCE STATUS
A13: Overall Compliance | B13: ='Dashboard'!G10
A14: Status | B14: =IF(Dashboard!G10="N/A","NOT ASSESSED",IF(ISNUMBER(VALUE(SUBSTITUTE(Dashboard!G10,"%",""))),IF(VALUE(SUBSTITUTE(Dashboard!G10,"%",""))>=90,"GREEN",IF(VALUE(SUBSTITUTE(Dashboard!G10,"%",""))>=70,"AMBER","RED")),"NOT ASSESSED"))
A16: KEY METRICS
A17: Total Requirements | B17: ='Dashboard'!B10
A18: Compliant | B18: ='Dashboard'!C10
A19: Partial | B19: ='Dashboard'!D10
A20: Non-Compliant | B20: ='Dashboard'!E10
A21: Not Applicable | B21: ='Dashboard'!F10
A22: Owner Coverage | B22: =IF(Dashboard!B10=0,"N/A",ROUND((COUNTA('Physical Security Monitoring'!F4:F26)+COUNTA('Environmental Protection'!F4:F27)+COUNTA('Supporting Utilities'!F4:F21)+COUNTA('Facility Criticality Tiers'!F4:F5)+COUNTA('Incident Classification'!F4:F5)+COUNTA('Compliance Measurement'!F4:F4))/Dashboard!B10*100,0)&"%")
A24: DOMAIN STATUS SUMMARY
A25: Domain | B25: Compliance % | C25: Compliant | D25: Gaps | E25: Status
A26: Physical Security Monitoring | B26: ='Dashboard'!G4 | C26: ='Dashboard'!C4 | D26: ='Dashboard'!E4 | E26: =IF(Dashboard!G4="N/A","--",IF(ISNUMBER(VALUE(SUBSTITUTE(Dashboard!G4,"%",""))),IF(VALUE(SUBSTITUTE(Dashboard!G4,"%",""))>=90,"PASS",IF(VALUE(SUBSTITUTE(Dashboard!G4,"%",""))>=70,"REVIEW","FAIL")),"--"))
A27: Environmental Protection | B27: ='Dashboard'!G5 | C27: ='Dashboard'!C5 | D27: ='Dashboard'!E5 | E27: =IF(Dashboard!G5="N/A","--",IF(ISNUMBER(VALUE(SUBSTITUTE(Dashboard!G5,"%",""))),IF(VALUE(SUBSTITUTE(Dashboard!G5,"%",""))>=90,"PASS",IF(VALUE(SUBSTITUTE(Dashboard!G5,"%",""))>=70,"REVIEW","FAIL")),"--"))
A28: Supporting Utilities | B28: ='Dashboard'!G6 | C28: ='Dashboard'!C6 | D28: ='Dashboard'!E6 | E28: =IF(Dashboard!G6="N/A","--",IF(ISNUMBER(VALUE(SUBSTITUTE(Dashboard!G6,"%",""))),IF(VALUE(SUBSTITUTE(Dashboard!G6,"%",""))>=90,"PASS",IF(VALUE(SUBSTITUTE(Dashboard!G6,"%",""))>=70,"REVIEW","FAIL")),"--"))
A29: Facility Criticality Tiers | B29: ='Dashboard'!G7 | C29: ='Dashboard'!C7 | D29: ='Dashboard'!E7 | E29: =IF(Dashboard!G7="N/A","--",IF(ISNUMBER(VALUE(SUBSTITUTE(Dashboard!G7,"%",""))),IF(VALUE(SUBSTITUTE(Dashboard!G7,"%",""))>=90,"PASS",IF(VALUE(SUBSTITUTE(Dashboard!G7,"%",""))>=70,"REVIEW","FAIL")),"--"))
A30: Incident Classification | B30: ='Dashboard'!G8 | C30: ='Dashboard'!C8 | D30: ='Dashboard'!E8 | E30: =IF(Dashboard!G8="N/A","--",IF(ISNUMBER(VALUE(SUBSTITUTE(Dashboard!G8,"%",""))),IF(VALUE(SUBSTITUTE(Dashboard!G8,"%",""))>=90,"PASS",IF(VALUE(SUBSTITUTE(Dashboard!G8,"%",""))>=70,"REVIEW","FAIL")),"--"))
A31: Compliance Measurement | B31: ='Dashboard'!G9 | C31: ='Dashboard'!C9 | D31: ='Dashboard'!E9 | E31: =IF(Dashboard!G9="N/A","--",IF(ISNUMBER(VALUE(SUBSTITUTE(Dashboard!G9,"%",""))),IF(VALUE(SUBSTITUTE(Dashboard!G9,"%",""))>=90,"PASS",IF(VALUE(SUBSTITUTE(Dashboard!G9,"%",""))>=70,"REVIEW","FAIL")),"--"))
A33: CRITICAL ISSUES
A34: # | B34: Issue Description | C34: Domain | D34: Owner | E34: Due Date
A35: 1
A36: 2
A37: 3
A38: 4
A39: 5
A41: MANAGEMENT COMMENTARY
A42: [Enter management commentary on physical infrastructure security posture]
A46: APPROVAL
A47: Assessed By
A48: Name:
A49: Date:
...

Sheet Dashboard
A1: Physical Infrastructure Security — Compliance Dashboard
A3: Domain | B3: Total Reqs | C3: Compliant | D3: Partial | E3: Non-Compliant | F3: N/A | G3: Compliance %
A4: Physical Security Monitoring | B4: =COUNTA('Physical Security Monitoring'!D4:D26) | C4: =COUNTIF('Physical Security Monitoring'!D4:D26,"Compliant") | D4: =COUNTIF('Physical Security Monitoring'!D4:D26,"Partial") | E4: =COUNTIF('Physical Security Monitoring'!D4:D26,"Non-Compliant") | F4: =COUNTIF('Physical Security Monitoring'!D4:D26,"N/A") | G4: =IF((B4-F4)=0,"N/A",ROUND(C4/(B4-F4)*100,1)&"%")
A5: Environmental Protection | B5: =COUNTA('Environmental Protection'!D4:D27) | C5: =COUNTIF('Environmental Protection'!D4:D27,"Compliant") | D5: =COUNTIF('Environmental Protection'!D4:D27,"Partial") | E5: =COUNTIF('Environmental Protection'!D4:D27,"Non-Compliant") | F5: =COUNTIF('Environmental Protection'!D4:D27,"N/A") | G5: =IF((B5-F5)=0,"N/A",ROUND(C5/(B5-F5)*100,1)&"%")
A6: Supporting Utilities | B6: =COUNTA('Supporting Utilities'!D4:D21) | C6: =COUNTIF('Supporting Utilities'!D4:D21,"Compliant") | D6: =COUNTIF('Supporting Utilities'!D4:D21,"Partial") | E6: =COUNTIF('Supporting Utilities'!D4:D21,"Non-Compliant") | F6: =COUNTIF('Supporting Utilities'!D4:D21,"N/A") | G6: =IF((B6-F6)=0,"N/A",ROUND(C6/(B6-F6)*100,1)&"%")
A7: Facility Criticality Tiers | B7: =COUNTA('Facility Criticality Tiers'!D4:D5) | C7: =COUNTIF('Facility Criticality Tiers'!D4:D5,"Compliant") | D7: =COUNTIF('Facility Criticality Tiers'!D4:D5,"Partial") | E7: =COUNTIF('Facility Criticality Tiers'!D4:D5,"Non-Compliant") | F7: =COUNTIF('Facility Criticality Tiers'!D4:D5,"N/A") | G7: =IF((B7-F7)=0,"N/A",ROUND(C7/(B7-F7)*100,1)&"%")
A8: Incident Classification | B8: =COUNTA('Incident Classification'!D4:D5) | C8: =COUNTIF('Incident Classification'!D4:D5,"Compliant") | D8: =COUNTIF('Incident Classification'!D4:D5,"Partial") | E8: =COUNTIF('Incident Classification'!D4:D5,"Non-Compliant") | F8: =COUNTIF('Incident Classification'!D4:D5,"N/A") | G8: =IF((B8-F8)=0,"N/A",ROUND(C8/(B8-F8)*100,1)&"%")
A9: Compliance Measurement | B9: =COUNTA('Compliance Measurement'!D4:D4) | C9: =COUNTIF('Compliance Measurement'!D4:D4,"Compliant") | D9: =COUNTIF('Compliance Measurement'!D4:D4,"Partial") | E9: =COUNTIF('Compliance Measurement'!D4:D4,"Non-Compliant") | F9: =COUNTIF('Compliance Measurement'!D4:D4,"N/A") | G9: =IF((B9-F9)=0,"N/A",ROUND(C9/(B9-F9)*100,1)&"%")
A10: TOTAL | B10: =SUM(B4:B9) | C10: =SUM(C4:C9) | D10: =SUM(D4:D9) | E10: =SUM(E4:E9) | F10: =SUM(F4:F9) | G10: =IF((B10-F10)=0,"N/A",ROUND(C10/(B10-F10)*100,1)&"%")
A12: COMPLIANCE BY STATUS
A13: Compliant | B13: =C10 | C13: =IF(B10=0,"",ROUND(B13/B10*100,1)&"%")
A14: Partial | B14: =D10 | C14: =IF(B10=0,"",ROUND(B14/B10*100,1)&"%")
A15: Non-Compliant | B15: =E10 | C15: =IF(B10=0,"",ROUND(B15/B10*100,1)&"%")
A16: N/A | B16: =F10 | C16: =IF(B10=0,"",ROUND(B16/B10*100,1)&"%")
A18: TOP GAPS (Manual Entry)
A19: Priority | B19: Domain | C19: Requirement | D19: Owner | E19: Due Date | F19: Status
A31: COMPLIANCE TREND (Manual Entry)
A32: Assessment Date | B32: Overall % | C32: Compliant | D32: Gaps | E32: Assessor | F32: Notes

Sheet Physical Security Monitoring
A1: Physical Security Monitoring — Compliance Checklist
A2: ISO/IEC 27001:2022 — Controls A.7.4-5-11: Physical Infrastructure Security
A3: Req # | B3: Section | C3: Requirement | D3: Status | E3: Evidence | F3: Owner | G3: Due Date | H3: Notes
A4: A.7.4-5-11-01 | B4: Physical Security Monitoring | C4: Physical security monitoring shall detect and deter unauthorised physical access to facilities and restricted areas. Monitoring system design and implementation shall be proportionate to facility criticality.
A5: A.7.4-5-11-02 | B5: The Following Physical Security Systems | C5: The following physical security systems shall be implemented and maintained. Organisations shall specify the actual systems deployed (or document selection status) for each category:.
A6: A.7.4-5-11-03 | B6: Integration Requirements*: Where | C6: Integration requirements*: Where technically feasible, physical security systems should feed events to [SIEM] for correlation with logical security events. At minimum, access control events and intrusion detection alarms shall be forwarded.
A7: A.7.4-5-11-04 | B7: Electronic Access Control | C7: Electronic access control shall be implemented at all facility entry and exit points with authentication, event logging, and integration with identity management.
A8: A.7.4-5-11-05 | B8: Access Events (Granted, Denied, Forced | C8: Access events (granted, denied, forced door, door held open) shall be logged with timestamp, individual identity, and door identifier.
A9: A.7.4-5-11-06 | B9: Access Logs | C9: Access logs shall be retained for a minimum of 12 months.
A10: A.7.4-5-11-07 | B10: Access Rights | C10: Access rights shall be reviewed semi-annually and revoked when no longer required (e.g., role change, termination).
A11: A.7.4-5-11-08 | B11: Same-Day Access Revocation | C11: Same-day access revocation shall be enforced upon employment termination.
A12: A.7.4-5-11-09 | B12: Physical Access Rights | C12: Physical access rights shall be reviewed semi-annually using the following structured workflow:.
A13: A.7.4-5-11-10 | B13: Cctv Coverage | C13: CCTV coverage shall be provided at facility entrances, restricted area access points, and critical infrastructure locations (server rooms, utility rooms).
A14: A.7.4-5-11-11 | B14: Cctv Systems | C14: CCTV systems shall record continuously during operational hours at minimum; 24/7 recording is required for Tier 1 facilities.
A15: A.7.4-5-11-12 | B15: Cctv Systems | C15: CCTV systems shall comply with applicable data protection requirements (Swiss nFADP, cantonal regulations). Signage indicating video surveillance shall be displayed at monitored areas.
... A26: A.7.4-5-11-23 | B26: Monitoring Equipment | C26: Monitoring equipment shall be on UPS-backed power to ensure continued operation during power interruptions.

Sheet Environmental Protection
A1: Environmental Protection — Compliance Checklist
A2: ISO/IEC 27001:2022 — Controls A.7.4-5-11: Physical Infrastructure Security
A3: Req # | B3: Section | C3: Requirement | D3: Status | E3: Evidence | F3: Owner | G3: Due Date | H3: Notes
A4: A.7.4-5-11-24 | B4: Environmental Protection Controls | C4: Environmental protection controls shall prevent or mitigate damage from fire, water, climate extremes, and other physical threats. Protection levels shall be proportionate to facility criticality.
A5: A.7.4-5-11-25 | B5: An Environmental Threat Risk Assessment | C5: An environmental threat risk assessment shall be conducted for each facility, considering geographic location, building characteristics, historical events, and surrounding hazards.
A6: A.7.4-5-11-26 | B6: The Assessment | C6: The assessment shall be reviewed annually and updated following incidents or significant facility changes.
A7: A.7.4-5-11-27 | B7: Fire Detection | C7: Fire detection shall be implemented in all facilities containing information processing equipment.
A8: A.7.4-5-11-28 | B8: Notes On Suppression Agents*: Clean | C8: Notes on suppression agents*: Clean agent systems compliant with NFPA 2001 and ISO 14520 are required for occupied spaces containing electronic equipment. Water-based sprinkler systems shall not be used in server rooms or datacentres. Organisations should consider the long-term availability and environmental profile of selected agents when specifying suppression systems.
A9: A.7.4-5-11-29 | B9: Fire Doors On Security Perimeters | C9: Fire doors on security perimeters shall be alarmed, monitored, and tested in accordance with applicable fire codes.
A10: A.7.4-5-11-30 | B10: Emergency Lighting And Evacuation Routes | C10: Emergency lighting and evacuation routes shall be maintained and tested semi-annually.
A11: A.7.4-5-11-31 | B11: Water Detection Sensors | C11: Water detection sensors shall be installed in Tier 1 facilities — below raised floors, above suspended ceilings, near cooling infrastructure, and in all zones where water ingress is possible.
A12: A.7.4-5-11-32 | B12: Tier 2 Facilities | C12: Tier 2 facilities shall have water detection in high-risk areas (near plumbing, HVAC systems, ground-level rooms).
A13: A.7.4-5-11-33 | B13: Water Alarms | C13: Water alarms shall trigger immediate alert to facilities management.
A14: A.7.4-5-11-34 | B14: Implement Drainage, Waterproofing, And | C14: Facilities shall implement drainage, waterproofing, and physical barriers appropriate to identified flood risk.
A15: A.7.4-5-11-35 | B15: Information Processing Equipment | C15: Information processing equipment shall be maintained within controlled temperature and humidity ranges to prevent damage and ensure reliable operation.
... A27: A.7.4-5-11-47 | B27: Personnel With Facility Access | C27: All personnel with facility access shall complete physical security awareness training. Training is delivered annually with new-hire completion required within 10 business days of facility access being granted.

Sheet Supporting Utilities
A1: Supporting Utilities — Compliance Checklist
A2: ISO/IEC 27001:2022 — Controls A.7.4-5-11: Physical Infrastructure Security
A3: Req # | B3: Section | C3: Requirement | D3: Status | E3: Evidence | F3: Owner | G3: Due Date | H3: Notes
A4: A.7.4-5-11-48 | B4: Utility Systems | C4: Utility systems shall be implemented with capacity and redundancy proportionate to facility criticality, and tested regularly to ensure reliability.
A5: A.7.4-5-11-49 | B5: Ups Systems | C5: UPS systems shall protect all critical information processing equipment, network infrastructure, and security systems (access control, CCTV, fire detection).
A6: A.7.4-5-11-50 | B6: Ups Systems | C6: UPS systems shall be configured to support orderly shutdown of equipment that supports critical business operations if extended outage exceeds UPS runtime.
A7: A.7.4-5-11-51 | B7: Ups Capacity | C7: UPS capacity shall be calculated using the following four-step process to ensure adequate runtime for protected equipment:.
A8: A.7.4-5-11-52 | B8: Be Inspected Weekly And Load-Tested | C8: Where generators are installed, they shall be inspected weekly and load-tested according to the testing schedule below.
A9: A.7.4-5-11-53 | B9: The Fuel Type | C9: The fuel type shall be selected based on facility requirements, local infrastructure, and environmental considerations:.
A10: A.7.4-5-11-54 | B10: Cooling Capacity | C10: Cooling capacity shall be sufficient for the current heat load plus planned growth.
A11: A.7.4-5-11-55 | B11: Cooling Systems | C11: Cooling systems shall be maintained per manufacturer service schedules, with air filters replaced at recommended intervals.
A12: A.7.4-5-11-56 | B12: Power And Telecommunications Cabling | C12: Power and telecommunications cabling carrying data or supporting information services shall be protected from interception, interference, or damage.
A13: A.7.4-5-11-57 | B13: Power Cables | C13: Power cables shall be segregated from communications cables to prevent interference.
A14: A.7.4-5-11-58 | B14: Access To Cable Rooms And Patch | C14: Access to cable rooms and patch panels shall be restricted by physical access control.
A15: A.7.4-5-11-59 | B15: Automated And Manual Failover Procedures | C15: Automated and manual failover procedures shall be documented and tested to ensure connectivity continuity:.
... A21: A.7.4-5-11-65 | B21: Utility Incidents | C21: Utility incidents shall be logged and reported per the incident management process.

Sheet Facility Criticality Tiers
A1: Facility Criticality Tiers — Compliance Checklist
A2: ISO/IEC 27001:2022 — Controls A.7.4-5-11: Physical Infrastructure Security
A3: Req # | B3: Section | C3: Requirement | D3: Status | E3: Evidence | F3: Owner | G3: Due Date | H3: Notes
A4: A.7.4-5-11-66 | B4: Be Classified Into Criticality Tiers | C4: Facilities shall be classified into criticality tiers based on business impact analysis. The tier classification drives monitoring intensity, environmental protection requirements, and utility resilience levels throughout this policy.
A5: A.7.4-5-11-67 | B5: Tier Assignment Process*: System Owners, | C5: Tier assignment process*: System owners, in consultation with the Facilities Manager and CISO, shall determine the appropriate tier for each facility based on business impact analysis results. Tier assignments shall be reviewed annually.

Sheet Incident Classification
A1: Incident Classification — Compliance Checklist
A2: ISO/IEC 27001:2022 — Controls A.7.4-5-11: Physical Infrastructure Security
A3: Req # | B3: Section | C3: Requirement | D3: Status | E3: Evidence | F3: Owner | G3: Due Date | H3: Notes
A4: A.7.4-5-11-68 | B4: Physical Infrastructure Security Events | C4: Physical infrastructure security events shall be classified and responded to based on severity:.
A5: A.7.4-5-11-69 | B5: Physical Security Incidents | C5: Physical security incidents shall be reported and managed through the organisation's incident management process (A.5.24–28).

Sheet Compliance Measurement
A1: Compliance Measurement — Compliance Checklist
A2: ISO/IEC 27001:2022 — Controls A.7.4-5-11: Physical Infrastructure Security
A3: Req # | B3: Section | C3: Requirement | D3: Status | E3: Evidence | F3: Owner | G3: Due Date | H3: Notes
A4: A.7.4-5-11-70 | B4: Be Assessed Using The Following Weighted | C4: Compliance shall be assessed using the following weighted metrics:.
