Workbook

Sheet Instructions
A1: ISMS BC/DR Assessment - RPO/RTO Compliance Matrix
A3: Document ID: | B3: ISMS-IMP-A.8.13.3
A4: Assessment: | B4: RPO/RTO Compliance Matrix
A5: Version: | B5: 1.0
A6: Generated: | B6: 31.01.2026 03:18
A8: PURPOSE
A9: This workbook aligns Business Impact Analysis (BIA) requirements with technical BC/DR capabilities to identify gaps.
A10: Use this to ensure technical capabilities meet business requirements for RPO (Recovery Point Objective) and RTO (Recovery Time Objective).
A12: KEY PRINCIPLE: Requirements come from business (BIA), capabilities come from testing (not assumptions).
A14: ASSESSMENT WORKFLOW
A15: 1. Populate System_Inventory from BIA results (business RPO/RTO requirements)
A16: 2. Populate Capability_Assessment with TESTED technical capabilities
A17: 3. Review Compliance_Matrix (formulas automatically compare requirements vs capabilities)
A18: 4. Document identified gaps in Gap_Analysis with remediation plans
A19: 5. Collect evidence in Evidence_Register (MINIMUM 5 evidence items for audit)
A20: 6. Review Summary dashboard for overall compliance metrics
A21: 7. Complete Approval_Sign_Off workflow (3 levels: Assessor → ISO → CISO)
... A24: WORKSHEET DESCRIPTIONS
A25: Instructions: | B25: This sheet - comprehensive usage guide
A26: Summary: | B26: Executive dashboard with compliance metrics and gap summary
A27: System_Inventory: | B27: BIA results - business requirements (RPO/RTO from business impact)
A28: Capability_Assessment: | B28: Technical capabilities - TESTED recovery times (not assumptions)
A29: Compliance_Matrix: | B29: Automated comparison - requirement vs capability for each system
A30: Gap_Analysis: | B30: Identified gaps with risk scoring and remediation tracking
A31: Evidence_Register: | B31: 100 evidence slots for audit traceability (minimum 5 required)
A32: Approval_Sign_Off: | B32: 3-level approval workflow (Assessor → ISO → CISO)
A34: DATA ENTRY GUIDELINES
A35: TIME FORMAT: All times in HOURS (e.g., 0.25 = 15 min, 0.5 = 30 min, 1 = 1 hour, 24 = 1 day, 168 = 1 week)
A36: SYSTEM_INVENTORY: Data from Business Impact Analysis (BIA) - business requirements
A37: CAPABILITY_ASSESSMENT: Data from TESTING - actual measured recovery times (restore tests, failover tests)
A38: CRITICAL: Capabilities must be TESTED, not assumed - untested = "Unknown"
A39: COMPLIANCE: Use dropdown lists where provided for consistent data entry
A40: RPO COMPLIANCE: System is RPO compliant if Backup Frequency ≤ RPO Requirement
A41: RTO COMPLIANCE: System is RTO compliant if Recovery Capability ≤ RTO Requirement
A42: OVERALL COMPLIANCE: Both RPO AND RTO must be compliant for overall compliance
A44: AUTOMATIC FORMULA LOGIC
A45: RPO Capability = Backup Frequency (how often you backup determines your RPO)
A46: RTO Capability = MIN(Restore Time, Failover Time) - whichever is faster
... A63: STATUS INDICATOR LEGEND
A64: ✅ | B64: Compliant / Success / Yes / Verified / Closed
...

Sheet Summary
A1: RPO/RTO COMPLIANCE DASHBOARD
A2: Assessment Date: 31.01.2026 | Assessment ID: ISMS-IMP-A.8.13.3
A4: OVERALL RPO/RTO COMPLIANCE
A5: Total Systems Assessed: | B5: =COUNTA(System_Inventory!A5:A114)
A6: Systems with Full Compliance (RPO & RTO): | B6: =COUNTIF(Compliance_Matrix!E5:E114,"{CHECK}*")
A7: Systems with Partial Compliance: | B7: =COUNTIF(Compliance_Matrix!E5:E114,"{WARNING}*")
A8: Non-Compliant Systems: | B8: =COUNTIF(Compliance_Matrix!E5:E114,"{XMARK}*")
A9: Unknown Status (Not Tested): | B9: =COUNTIF(Compliance_Matrix!E5:E114,"❓*")
A10: Overall Compliance Rate: | B10: =IF(B5>0,B6/B5,0)
A12: COMPLIANCE BY CRITICALITY TIER
A13: Tier 1 - Critical Systems: | B13: =COUNTIF(System_Inventory!C5:C114,"Tier 1*")
A14: Tier 1 - Full Compliance: | B14: =SUMPRODUCT((System_Inventory!C5:C114="Tier 1 - Critical")*(Compliance_Matrix!E5:E114="{CHECK} Full Compliance"))
A15: Tier 1 - Compliance Rate: | B15: =IF(B13>0,B14/B13,0)
A17: Tier 2 - Important Systems: | B17: =COUNTIF(System_Inventory!C5:C114,"Tier 2*")
A18: Tier 2 - Full Compliance: | B18: =SUMPRODUCT((System_Inventory!C5:C114="Tier 2 - Important")*(Compliance_Matrix!E5:E114="{CHECK} Full Compliance"))
A19: Tier 2 - Compliance Rate: | B19: =IF(B17>0,B18/B17,0)
A21: GAP ANALYSIS SUMMARY
A22: Total Gaps Identified: | B22: =COUNTA(Gap_Analysis!A5:A114)
A23: 🔴 Critical Priority Gaps: | B23: =COUNTIF(Gap_Analysis!F5:F114,"🔴*")
A24: 🟡 High Priority Gaps: | B24: =COUNTIF(Gap_Analysis!F5:F114,"🟡*")
A25: 🟢 Medium Priority Gaps: | B25: =COUNTIF(Gap_Analysis!F5:F114,"🟢*")
A26: ⚪ Low Priority Gaps: | B26: =COUNTIF(Gap_Analysis!F5:F114,"⚪*")
A28: Open Gaps (🔴): | B28: =COUNTIF(Gap_Analysis!H5:H114,"🔴*")
A29: In Progress Gaps (⏳): | B29: =COUNTIF(Gap_Analysis!H5:H114,"⏳*")
A30: Closed Gaps (✅): | B30: =COUNTIF(Gap_Analysis!H5:H114,"{CHECK}*")
A32: Average Risk Score: | B32: =IFERROR(AVERAGE(Gap_Analysis!E5:E114),0)
A34: EVIDENCE & APPROVAL STATUS
A35: Evidence Items Collected: | B35: =COUNTA(Evidence_Register!A5:A104)
A36: Verified Evidence: | B36: =COUNTIF(Evidence_Register!H5:H104,"{CHECK}*")
A37: Minimum Evidence Required: | B37: 5
A38: Evidence Compliance: | B38: =IF(B40>=B42,"{CHECK} Sufficient","{XMARK} Insufficient")
A40: Assessment Status: | B40: =Approval_Sign_Off!B15
A41: Level 1 - Assessor Completed: | B41: =IF(Approval_Sign_Off!B27<>"","{CHECK} Complete","⏳ Pending")
A42: Level 2 - ISO Review: | B42: =IF(Approval_Sign_Off!B38<>"","{CHECK} Complete","⏳ Pending")
A43: Level 3 - CISO Approval: | B43: =IF(Approval_Sign_Off!B50<>"","{CHECK} Complete","⏳ Pending")
A45: PRIORITY ACTIONS
A46: 1. Address all 🔴 Critical priority gaps immediately (target: 90 days)
A47: 2. Test all systems marked ❓ Unknown (capability assessment needed)
A48: 3. Focus on Tier 1 systems first (business-critical)
A49: 4. Close RPO gaps: Increase backup frequency OR implement replication
...

Sheet System_Inventory
A1: SYSTEM INVENTORY - BIA RESULTS (Business Requirements)
A2: Source: Business Impact Analysis (BIA) - RPO/RTO requirements from business stakeholders
A4: System Name | B4: Business Process | C4: Criticality Tier | D4: MTPD (hours) | E4: RPO Requirement (hours) | F4: RTO Requirement (hours) | G4: Business Justification
A5: E-Commerce Website | B5: Online Sales | C5: Tier 1 - Critical | D5: 4 | E5: 1 | F5: 2 | G5: Revenue loss $5K/hour, customer exodus after 4 hours downtime
A6: Payment Gateway | B6: Payment Processing | C6: Tier 1 - Critical | D6: 1 | E6: 0.25 | F6: 0.5 | G6: Revenue loss immediate, regulatory compliance (PCI-DSS), reputation damage
A7: Email System | B7: Communication | C7: Tier 1 - Critical | D7: 8 | E7: 4 | F7: 4 | G7: Business communication essential, brief outage tolerable, regulatory notifications
A8: CRM System | B8: Customer Management | C8: Tier 1 - Critical | D8: 12 | E8: 2 | F8: 6 | G8: Sales operations halt, customer service degraded, revenue impact
A9: ERP System | B9: Finance, HR, Procurement | C9: Tier 2 - Important | D9: 24 | E9: 4 | F9: 12 | G9: Can operate manually for 24 hours, critical for month-end close
A10: HR Information System | B10: HR Operations | C10: Tier 2 - Important | D10: 48 | E10: 24 | F10: 24 | G10: Payroll at risk beyond 2 days, can work around short-term
A11: File Server | B11: Document Storage | C11: Tier 3 - Standard | D11: 168 | E11: 24 | F11: 48 | G11: Inconvenience only, users have local copies, non-critical operations
A12: Document Repository | B12: Knowledge Management | C12: Tier 3 - Standard | D12: 168 | E12: 168 | F12: 72 | G12: Non-critical reference system, acceptable long recovery time
A13: Test Database | B13: Development Testing | C13: Tier 4 - Low | D13: 720 | E13: 168 | F13: 168 | G13: Can rebuild from production, low business impact, dev environment only
A14: Training System | B14: Employee Training | C14: Tier 4 - Low | D14: 720 | E14: 720 | F14: 168 | G14: Training can be postponed, minimal business impact, non-essential
A117: DATA SOURCE: Business Impact Analysis (BIA) - Requirements are business-driven, not IT-driven
A118: MTPD = Maximum Tolerable Period of Disruption | RPO = Recovery Point Objective | RTO = Recovery Time Objective

Sheet Capability_Assessment
A1: CAPABILITY ASSESSMENT (Technical Capabilities - TESTED)
A2: Source: Testing Results - Actual measured recovery times (restore tests, failover tests)
A4: System Name | B4: Backup Frequency (hours) | C4: Restore Time Tested (hours) | D4: Failover Time Tested (hours) | E4: RPO Capability (hours) | F4: RTO Capability (hours) | G4: Test Notes / Observations
A5: E-Commerce Website | B5: 1 | C5: 4 | D5: 0.5 | E5: =IF(ISNUMBER(B5),B5,"") | F5: =IF(AND(ISNUMBER(C5),ISNUMBER(D5)),MIN(C5,D5),IF(ISNUMBER(C5),C5,IF(ISNUMBER(D5),D5,""))) | G5: Hourly backups, Active-Passive cluster, tested failover 30 min
A6: Payment Gateway | B6: 0.25 | D6: 0.08 | E6: =IF(ISNUMBER(B6),B6,"") | F6: =IF(AND(ISNUMBER(C6),ISNUMBER(D6)),MIN(C6,D6),IF(ISNUMBER(C6),C6,IF(ISNUMBER(D6),D6,""))) | G6: 15-min transaction log backups, Active-Active cluster, failover ~5 min
A7: Email System | B7: 4 | C7: 12 | E7: =IF(ISNUMBER(B7),B7,"") | F7: =IF(AND(ISNUMBER(C7),ISNUMBER(D7)),MIN(C7,D7),IF(ISNUMBER(C7),C7,IF(ISNUMBER(D7),D7,""))) | G7: Every 4 hours backup via cloud, no redundancy, restore tested at 12 hours
A8: CRM System | B8: 2 | C8: 8 | E8: =IF(ISNUMBER(B8),B8,"") | F8: =IF(AND(ISNUMBER(C8),ISNUMBER(D8)),MIN(C8,D8),IF(ISNUMBER(C8),C8,IF(ISNUMBER(D8),D8,""))) | G8: Every 2 hours incremental backup, restore tested at 8 hours, no failover
A9: ERP System | B9: 24 | C9: 8 | E9: =IF(ISNUMBER(B9),B9,"") | F9: =IF(AND(ISNUMBER(C9),ISNUMBER(D9)),MIN(C9,D9),IF(ISNUMBER(C9),C9,IF(ISNUMBER(D9),D9,""))) | G9: Daily full backup, restore tested at 8 hours, cold standby available
A10: HR Information System | B10: 24 | C10: 20 | E10: =IF(ISNUMBER(B10),B10,"") | F10: =IF(AND(ISNUMBER(C10),ISNUMBER(D10)),MIN(C10,D10),IF(ISNUMBER(C10),C10,IF(ISNUMBER(D10),D10,""))) | G10: Daily backup, complex dependencies, restore tested at 20 hours
A11: File Server | B11: 168 | C11: 24 | E11: =IF(ISNUMBER(B11),B11,"") | F11: =IF(AND(ISNUMBER(C11),ISNUMBER(D11)),MIN(C11,D11),IF(ISNUMBER(C11),C11,IF(ISNUMBER(D11),D11,""))) | G11: Weekly backup to tape, restore tested at ~24 hours, low priority
A12: Document Repository | B12: 168 | C12: 48 | E12: =IF(ISNUMBER(B12),B12,"") | F12: =IF(AND(ISNUMBER(C12),ISNUMBER(D12)),MIN(C12,D12),IF(ISNUMBER(C12),C12,IF(ISNUMBER(D12),D12,""))) | G12: Weekly backup, large data volume, restore takes ~2 days
A13: Test Database | B13: 168 | C13: 4 | E13: =IF(ISNUMBER(B13),B13,"") | F13: =IF(AND(ISNUMBER(C13),ISNUMBER(D13)),MIN(C13,D13),IF(ISNUMBER(C13),C13,IF(ISNUMBER(D13),D13,""))) | G13: Weekly backup, small DB, fast restore, can rebuild from production
A14: Training System | B14: 720 | C14: 168 | E14: =IF(ISNUMBER(B14),B14,"") | F14: =IF(AND(ISNUMBER(C14),ISNUMBER(D14)),MIN(C14,D14),IF(ISNUMBER(C14),C14,IF(ISNUMBER(D14),D14,""))) | G14: Monthly backup, rarely tested, long restore time acceptable
E15: =IF(ISNUMBER(B15),B15,"") | F15: =IF(AND(ISNUMBER(C15),ISNUMBER(D15)),MIN(C15,D15),IF(ISNUMBER(C15),C15,IF(ISNUMBER(D15),D15,"")))
E16: =IF(ISNUMBER(B16),B16,"") | F16: =IF(AND(ISNUMBER(C16),ISNUMBER(D16)),MIN(C16,D16),IF(ISNUMBER(C16),C16,IF(ISNUMBER(D16),D16,"")))
E17: =IF(ISNUMBER(B17),B17,"") | F17: =IF(AND(ISNUMBER(C17),ISNUMBER(D17)),MIN(C17,D17),IF(ISNUMBER(C17),C17,IF(ISNUMBER(D17),D17,"")))
E18: =IF(ISNUMBER(B18),B18,"") | F18: =IF(AND(ISNUMBER(C18),ISNUMBER(D18)),MIN(C18,D18),IF(ISNUMBER(C18),C18,IF(ISNUMBER(D18),D18,"")))
E19: =IF(ISNUMBER(B19),B19,"") | F19: =IF(AND(ISNUMBER(C19),ISNUMBER(D19)),MIN(C19,D19),IF(ISNUMBER(C19),C19,IF(ISNUMBER(D19),D19,"")))
E20: =IF(ISNUMBER(B20),B20,"") | F20: =IF(AND(ISNUMBER(C20),ISNUMBER(D20)),MIN(C20,D20),IF(ISNUMBER(C20),C20,IF(ISNUMBER(D20),D20,"")))
E21: =IF(ISNUMBER(B21),B21,"") | F21: =IF(AND(ISNUMBER(C21),ISNUMBER(D21)),MIN(C21,D21),IF(ISNUMBER(C21),C21,IF(ISNUMBER(D21),D21,"")))
E22: =IF(ISNUMBER(B22),B22,"") | F22: =IF(AND(ISNUMBER(C22),ISNUMBER(D22)),MIN(C22,D22),IF(ISNUMBER(C22),C22,IF(ISNUMBER(D22),D22,"")))
E23: =IF(ISNUMBER(B23),B23,"") | F23: =IF(AND(ISNUMBER(C23),ISNUMBER(D23)),MIN(C23,D23),IF(ISNUMBER(C23),C23,IF(ISNUMBER(D23),D23,"")))
E24: =IF(ISNUMBER(B24),B24,"") | F24: =IF(AND(ISNUMBER(C24),ISNUMBER(D24)),MIN(C24,D24),IF(ISNUMBER(C24),C24,IF(ISNUMBER(D24),D24,"")))
E25: =IF(ISNUMBER(B25),B25,"") | F25: =IF(AND(ISNUMBER(C25),ISNUMBER(D25)),MIN(C25,D25),IF(ISNUMBER(C25),C25,IF(ISNUMBER(D25),D25,"")))
E26: =IF(ISNUMBER(B26),B26,"") | F26: =IF(AND(ISNUMBER(C26),ISNUMBER(D26)),MIN(C26,D26),IF(ISNUMBER(C26),C26,IF(ISNUMBER(D26),D26,"")))
... E114: =IF(ISNUMBER(B114),B114,"") | F114: =IF(AND(ISNUMBER(C114),ISNUMBER(D114)),MIN(C114,D114),IF(ISNUMBER(C114),C114,IF(ISNUMBER(D114),D114,"")))
A117: DATA SOURCE: Testing Results - CRITICAL: Capabilities must be TESTED, not assumed. Untested = Unknown compliance.
A118: RPO Capability = Backup Frequency | RTO Capability = MIN(Restore Time, Failover Time) - formulas auto-calculate

Sheet Compliance_Matrix
A1: RPO/RTO COMPLIANCE MATRIX (Requirement vs Capability)
A2: Automatic comparison: Business Requirements (System_Inventory) vs Technical Capabilities (Capability_Assessment)
A4: System Name | B4: Criticality | C4: RPO: Req vs Cap | D4: RTO: Req vs Cap | E4: Overall Compliance | F4: Priority | G4: Gap Summary | H4: Next Action Required
A5: =System_Inventory!A5 | B5: =System_Inventory!C5 | C5: =IF(A5="","",IF(OR(System_Inventory!E5="",Capability_Assessment!E5=""),"❓ Unknown",IF(Capability_Assessment!E5<=System_Inventory!E5,"✅ Compliant","❌ Non-Compliant"))) | D5: =IF(A5="","",IF(OR(System_Inventory!F5="",Capability_Assessment!F5=""),"❓ Unknown",IF(Capability_Assessment!F5<=System_Inventory!F5,"✅ Compliant","❌ Non-Compliant"))) | E5: =IF(A5="","",IF(OR(C5="❓ Unknown",D5="❓ Unknown"),"❓ Unknown",IF(AND(C5="✅ Compliant",D5="✅ Compliant"),"✅ Full Compliance",IF(OR(C5="✅ Compliant",D5="✅ Compliant"),"⚠ Partial Compliance","❌ Non-Compliant")))) | F5: =IF(A5="","",IF(AND(B5="Tier 1 - Critical",E5="❌ Non-Compliant"),"🔴 Critical",IF(B5="Tier 1 - Critical","🟡 High",IF(E5="❌ Non-Compliant","🟡 High",IF(E5="⚠ Partial Compliance","🟢 Medium","⚪ Low"))))) | G5: =IF(A5="","",IF(C5="❌ Non-Compliant",IF(D5="❌ Non-Compliant","Both RPO & RTO gaps","RPO gap only"),IF(D5="❌ Non-Compliant","RTO gap only",IF(E5="❓ Unknown","Testing required","No gaps")))) | H5: Monitor continuously, maintain current state
A6: =System_Inventory!A6 | B6: =System_Inventory!C6 | C6: =IF(A6="","",IF(OR(System_Inventory!E6="",Capability_Assessment!E6=""),"❓ Unknown",IF(Capability_Assessment!E6<=System_Inventory!E6,"✅ Compliant","❌ Non-Compliant"))) | D6: =IF(A6="","",IF(OR(System_Inventory!F6="",Capability_Assessment!F6=""),"❓ Unknown",IF(Capability_Assessment!F6<=System_Inventory!F6,"✅ Compliant","❌ Non-Compliant"))) | E6: =IF(A6="","",IF(OR(C6="❓ Unknown",D6="❓ Unknown"),"❓ Unknown",IF(AND(C6="✅ Compliant",D6="✅ Compliant"),"✅ Full Compliance",IF(OR(C6="✅ Compliant",D6="✅ Compliant"),"⚠ Partial Compliance","❌ Non-Compliant")))) | F6: =IF(A6="","",IF(AND(B6="Tier 1 - Critical",E6="❌ Non-Compliant"),"🔴 Critical",IF(B6="Tier 1 - Critical","🟡 High",IF(E6="❌ Non-Compliant","🟡 High",IF(E6="⚠ Partial Compliance","🟢 Medium","⚪ Low"))))) | G6: =IF(A6="","",IF(C6="❌ Non-Compliant",IF(D6="❌ Non-Compliant","Both RPO & RTO gaps","RPO gap only"),IF(D6="❌ Non-Compliant","RTO gap only",IF(E6="❓ Unknown","Testing required","No gaps")))) | H6: Monitor continuously, critical system
A7: =System_Inventory!A7 | B7: =System_Inventory!C7 | C7: =IF(A7="","",IF(OR(System_Inventory!E7="",Capability_Assessment!E7=""),"❓ Unknown",IF(Capability_Assessment!E7<=System_Inventory!E7,"✅ Compliant","❌ Non-Compliant"))) | D7: =IF(A7="","",IF(OR(System_Inventory!F7="",Capability_Assessment!F7=""),"❓ Unknown",IF(Capability_Assessment!F7<=System_Inventory!F7,"✅ Compliant","❌ Non-Compliant"))) | E7: =IF(A7="","",IF(OR(C7="❓ Unknown",D7="❓ Unknown"),"❓ Unknown",IF(AND(C7="✅ Compliant",D7="✅ Compliant"),"✅ Full Compliance",IF(OR(C7="✅ Compliant",D7="✅ Compliant"),"⚠ Partial Compliance","❌ Non-Compliant")))) | F7: =IF(A7="","",IF(AND(B7="Tier 1 - Critical",E7="❌ Non-Compliant"),"🔴 Critical",IF(B7="Tier 1 - Critical","🟡 High",IF(E7="❌ Non-Compliant","🟡 High",IF(E7="⚠ Partial Compliance","🟢 Medium","⚪ Low"))))) | G7: =IF(A7="","",IF(C7="❌ Non-Compliant",IF(D7="❌ Non-Compliant","Both RPO & RTO gaps","RPO gap only"),IF(D7="❌ Non-Compliant","RTO gap only",IF(E7="❓ Unknown","Testing required","No gaps")))) | H7: Consider more frequent backups (currently 4hr, need 4hr RTO)
A8: =System_Inventory!A8 | B8: =System_Inventory!C8 | C8: =IF(A8="","",IF(OR(System_Inventory!E8="",Capability_Assessment!E8=""),"❓ Unknown",IF(Capability_Assessment!E8<=System_Inventory!E8,"✅ Compliant","❌ Non-Compliant"))) | D8: =IF(A8="","",IF(OR(System_Inventory!F8="",Capability_Assessment!F8=""),"❓ Unknown",IF(Capability_Assessment!F8<=System_Inventory!F8,"✅ Compliant","❌ Non-Compliant"))) | E8: =IF(A8="","",IF(OR(C8="❓ Unknown",D8="❓ Unknown"),"❓ Unknown",IF(AND(C8="✅ Compliant",D8="✅ Compliant"),"✅ Full Compliance",IF(OR(C8="✅ Compliant",D8="✅ Compliant"),"⚠ Partial Compliance","❌ Non-Compliant")))) | F8: =IF(A8="","",IF(AND(B8="Tier 1 - Critical",E8="❌ Non-Compliant"),"🔴 Critical",IF(B8="Tier 1 - Critical","🟡 High",IF(E8="❌ Non-Compliant","🟡 High",IF(E8="⚠ Partial Compliance","🟢 Medium","⚪ Low"))))) | G8: =IF(A8="","",IF(C8="❌ Non-Compliant",IF(D8="❌ Non-Compliant","Both RPO & RTO gaps","RPO gap only"),IF(D8="❌ Non-Compliant","RTO gap only",IF(E8="❓ Unknown","Testing required","No gaps")))) | H8: Implement hot standby for faster recovery
A9: =System_Inventory!A9 | B9: =System_Inventory!C9 | C9: =IF(A9="","",IF(OR(System_Inventory!E9="",Capability_Assessment!E9=""),"❓ Unknown",IF(Capability_Assessment!E9<=System_Inventory!E9,"✅ Compliant","❌ Non-Compliant"))) | D9: =IF(A9="","",IF(OR(System_Inventory!F9="",Capability_Assessment!F9=""),"❓ Unknown",IF(Capability_Assessment!F9<=System_Inventory!F9,"✅ Compliant","❌ Non-Compliant"))) | E9: =IF(A9="","",IF(OR(C9="❓ Unknown",D9="❓ Unknown"),"❓ Unknown",IF(AND(C9="✅ Compliant",D9="✅ Compliant"),"✅ Full Compliance",IF(OR(C9="✅ Compliant",D9="✅ Compliant"),"⚠ Partial Compliance","❌ Non-Compliant")))) | F9: =IF(A9="","",IF(AND(B9="Tier 1 - Critical",E9="❌ Non-Compliant"),"🔴 Critical",IF(B9="Tier 1 - Critical","🟡 High",IF(E9="❌ Non-Compliant","🟡 High",IF(E9="⚠ Partial Compliance","🟢 Medium","⚪ Low"))))) | G9: =IF(A9="","",IF(C9="❌ Non-Compliant",IF(D9="❌ Non-Compliant","Both RPO & RTO gaps","RPO gap only"),IF(D9="❌ Non-Compliant","RTO gap only",IF(E9="❓ Unknown","Testing required","No gaps")))) | H9: Acceptable compliance, monitor quarterly
A10: =System_Inventory!A10 | B10: =System_Inventory!C10 | C10: =IF(A10="","",IF(OR(System_Inventory!E10="",Capability_Assessment!E10=""),"❓ Unknown",IF(Capability_Assessment!E10<=System_Inventory!E10,"✅ Compliant","❌ Non-Compliant"))) | D10: =IF(A10="","",IF(OR(System_Inventory!F10="",Capability_Assessment!F10=""),"❓ Unknown",IF(Capability_Assessment!F10<=System_Inventory!F10,"✅ Compliant","❌ Non-Compliant"))) | E10: =IF(A10="","",IF(OR(C10="❓ Unknown",D10="❓ Unknown"),"❓ Unknown",IF(AND(C10="✅ Compliant",D10="✅ Compliant"),"✅ Full Compliance",IF(OR(C10="✅ Compliant",D10="✅ Compliant"),"⚠ Partial Compliance","❌ Non-Compliant")))) | F10: =IF(A10="","",IF(AND(B10="Tier 1 - Critical",E10="❌ Non-Compliant"),"🔴 Critical",IF(B10="Tier 1 - Critical","🟡 High",IF(E10="❌ Non-Compliant","🟡 High",IF(E10="⚠ Partial Compliance","🟢 Medium","⚪ Low"))))) | G10: =IF(A10="","",IF(C10="❌ Non-Compliant",IF(D10="❌ Non-Compliant","Both RPO & RTO gaps","RPO gap only"),IF(D10="❌ Non-Compliant","RTO gap only",IF(E10="❓ Unknown","Testing required","No gaps")))) | H10: Acceptable compliance, monitor quarterly
A11: =System_Inventory!A11 | B11: =System_Inventory!C11 | C11: =IF(A11="","",IF(OR(System_Inventory!E11="",Capability_Assessment!E11=""),"❓ Unknown",IF(Capability_Assessment!E11<=System_Inventory!E11,"✅ Compliant","❌ Non-Compliant"))) | D11: =IF(A11="","",IF(OR(System_Inventory!F11="",Capability_Assessment!F11=""),"❓ Unknown",IF(Capability_Assessment!F11<=System_Inventory!F11,"✅ Compliant","❌ Non-Compliant"))) | E11: =IF(A11="","",IF(OR(C11="❓ Unknown",D11="❓ Unknown"),"❓ Unknown",IF(AND(C11="✅ Compliant",D11="✅ Compliant"),"✅ Full Compliance",IF(OR(C11="✅ Compliant",D11="✅ Compliant"),"⚠ Partial Compliance","❌ Non-Compliant")))) | F11: =IF(A11="","",IF(AND(B11="Tier 1 - Critical",E11="❌ Non-Compliant"),"🔴 Critical",IF(B11="Tier 1 - Critical","🟡 High",IF(E11="❌ Non-Compliant","🟡 High",IF(E11="⚠ Partial Compliance","🟢 Medium","⚪ Low"))))) | G11: =IF(A11="","",IF(C11="❌ Non-Compliant",IF(D11="❌ Non-Compliant","Both RPO & RTO gaps","RPO gap only"),IF(D11="❌ Non-Compliant","RTO gap only",IF(E11="❓ Unknown","Testing required","No gaps")))) | H11: Acceptable for Tier 3, no action required
A12: =System_Inventory!A12 | B12: =System_Inventory!C12 | C12: =IF(A12="","",IF(OR(System_Inventory!E12="",Capability_Assessment!E12=""),"❓ Unknown",IF(Capability_Assessment!E12<=System_Inventory!E12,"✅ Compliant","❌ Non-Compliant"))) | D12: =IF(A12="","",IF(OR(System_Inventory!F12="",Capability_Assessment!F12=""),"❓ Unknown",IF(Capability_Assessment!F12<=System_Inventory!F12,"✅ Compliant","❌ Non-Compliant"))) | E12: =IF(A12="","",IF(OR(C12="❓ Unknown",D12="❓ Unknown"),"❓ Unknown",IF(AND(C12="✅ Compliant",D12="✅ Compliant"),"✅ Full Compliance",IF(OR(C12="✅ Compliant",D12="✅ Compliant"),"⚠ Partial Compliance","❌ Non-Compliant")))) | F12: =IF(A12="","",IF(AND(B12="Tier 1 - Critical",E12="❌ Non-Compliant"),"🔴 Critical",IF(B12="Tier 1 - Critical","🟡 High",IF(E12="❌ Non-Compliant","🟡 High",IF(E12="⚠ Partial Compliance","🟢 Medium","⚪ Low"))))) | G12: =IF(A12="","",IF(C12="❌ Non-Compliant",IF(D12="❌ Non-Compliant","Both RPO & RTO gaps","RPO gap only"),IF(D12="❌ Non-Compliant","RTO gap only",IF(E12="❓ Unknown","Testing required","No gaps")))) | H12: Acceptable for Tier 3, no action required
A13: =System_Inventory!A13 | B13: =System_Inventory!C13 | C13: =IF(A13="","",IF(OR(System_Inventory!E13="",Capability_Assessment!E13=""),"❓ Unknown",IF(Capability_Assessment!E13<=System_Inventory!E13,"✅ Compliant","❌ Non-Compliant"))) | D13: =IF(A13="","",IF(OR(System_Inventory!F13="",Capability_Assessment!F13=""),"❓ Unknown",IF(Capability_Assessment!F13<=System_Inventory!F13,"✅ Compliant","❌ Non-Compliant"))) | E13: =IF(A13="","",IF(OR(C13="❓ Unknown",D13="❓ Unknown"),"❓ Unknown",IF(AND(C13="✅ Compliant",D13="✅ Compliant"),"✅ Full Compliance",IF(OR(C13="✅ Compliant",D13="✅ Compliant"),"⚠ Partial Compliance","❌ Non-Compliant")))) | F13: =IF(A13="","",IF(AND(B13="Tier 1 - Critical",E13="❌ Non-Compliant"),"🔴 Critical",IF(B13="Tier 1 - Critical","🟡 High",IF(E13="❌ Non-Compliant","🟡 High",IF(E13="⚠ Partial Compliance","🟢 Medium","⚪ Low"))))) | G13: =IF(A13="","",IF(C13="❌ Non-Compliant",IF(D13="❌ Non-Compliant","Both RPO & RTO gaps","RPO gap only"),IF(D13="❌ Non-Compliant","RTO gap only",IF(E13="❓ Unknown","Testing required","No gaps")))) | H13: Acceptable for Tier 4, no action required
A14: =System_Inventory!A14 | B14: =System_Inventory!C14 | C14: =IF(A14="","",IF(OR(System_Inventory!E14="",Capability_Assessment!E14=""),"❓ Unknown",IF(Capability_Assessment!E14<=System_Inventory!E14,"✅ Compliant","❌ Non-Compliant"))) | D14: =IF(A14="","",IF(OR(System_Inventory!F14="",Capability_Assessment!F14=""),"❓ Unknown",IF(Capability_Assessment!F14<=System_Inventory!F14,"✅ Compliant","❌ Non-Compliant"))) | E14: =IF(A14="","",IF(OR(C14="❓ Unknown",D14="❓ Unknown"),"❓ Unknown",IF(AND(C14="✅ Compliant",D14="✅ Compliant"),"✅ Full Compliance",IF(OR(C14="✅ Compliant",D14="✅ Compliant"),"⚠ Partial Compliance","❌ Non-Compliant")))) | F14: =IF(A14="","",IF(AND(B14="Tier 1 - Critical",E14="❌ Non-Compliant"),"🔴 Critical",IF(B14="Tier 1 - Critical","🟡 High",IF(E14="❌ Non-Compliant","🟡 High",IF(E14="⚠ Partial Compliance","🟢 Medium","⚪ Low"))))) | G14: =IF(A14="","",IF(C14="❌ Non-Compliant",IF(D14="❌ Non-Compliant","Both RPO & RTO gaps","RPO gap only"),IF(D14="❌ Non-Compliant","RTO gap only",IF(E14="❓ Unknown","Testing required","No gaps")))) | H14: Acceptable for Tier 4, no action required
A15: =System_Inventory!A15 | B15: =System_Inventory!C15 | C15: =IF(A15="","",IF(OR(System_Inventory!E15="",Capability_Assessment!E15=""),"❓ Unknown",IF(Capability_Assessment!E15<=System_Inventory!E15,"✅ Compliant","❌ Non-Compliant"))) | D15: =IF(A15="","",IF(OR(System_Inventory!F15="",Capability_Assessment!F15=""),"❓ Unknown",IF(Capability_Assessment!F15<=System_Inventory!F15,"✅ Compliant","❌ Non-Compliant"))) | E15: =IF(A15="","",IF(OR(C15="❓ Unknown",D15="❓ Unknown"),"❓ Unknown",IF(AND(C15="✅ Compliant",D15="✅ Compliant"),"✅ Full Compliance",IF(OR(C15="✅ Compliant",D15="✅ Compliant"),"⚠ Partial Compliance","❌ Non-Compliant")))) | F15: =IF(A15="","",IF(AND(B15="Tier 1 - Critical",E15="❌ Non-Compliant"),"🔴 Critical",IF(B15="Tier 1 - Critical","🟡 High",IF(E15="❌ Non-Compliant","🟡 High",IF(E15="⚠ Partial Compliance","🟢 Medium","⚪ Low"))))) | G15: =IF(A15="","",IF(C15="❌ Non-Compliant",IF(D15="❌ Non-Compliant","Both RPO & RTO gaps","RPO gap only"),IF(D15="❌ Non-Compliant","RTO gap only",IF(E15="❓ Unknown","Testing required","No gaps"))))
A16: =System_Inventory!A16 | B16: =System_Inventory!C16 | C16: =IF(A16="","",IF(OR(System_Inventory!E16="",Capability_Assessment!E16=""),"❓ Unknown",IF(Capability_Assessment!E16<=System_Inventory!E16,"✅ Compliant","❌ Non-Compliant"))) | D16: =IF(A16="","",IF(OR(System_Inventory!F16="",Capability_Assessment!F16=""),"❓ Unknown",IF(Capability_Assessment!F16<=System_Inventory!F16,"✅ Compliant","❌ Non-Compliant"))) | E16: =IF(A16="","",IF(OR(C16="❓ Unknown",D16="❓ Unknown"),"❓ Unknown",IF(AND(C16="✅ Compliant",D16="✅ Compliant"),"✅ Full Compliance",IF(OR(C16="✅ Compliant",D16="✅ Compliant"),"⚠ Partial Compliance","❌ Non-Compliant")))) | F16: =IF(A16="","",IF(AND(B16="Tier 1 - Critical",E16="❌ Non-Compliant"),"🔴 Critical",IF(B16="Tier 1 - Critical","🟡 High",IF(E16="❌ Non-Compliant","🟡 High",IF(E16="⚠ Partial Compliance","🟢 Medium","⚪ Low"))))) | G16: =IF(A16="","",IF(C16="❌ Non-Compliant",IF(D16="❌ Non-Compliant","Both RPO & RTO gaps","RPO gap only"),IF(D16="❌ Non-Compliant","RTO gap only",IF(E16="❓ Unknown","Testing required","No gaps"))))
A17: =System_Inventory!A17 | B17: =System_Inventory!C17 | C17: =IF(A17="","",IF(OR(System_Inventory!E17="",Capability_Assessment!E17=""),"❓ Unknown",IF(Capability_Assessment!E17<=System_Inventory!E17,"✅ Compliant","❌ Non-Compliant"))) | D17: =IF(A17="","",IF(OR(System_Inventory!F17="",Capability_Assessment!F17=""),"❓ Unknown",IF(Capability_Assessment!F17<=System_Inventory!F17,"✅ Compliant","❌ Non-Compliant"))) | E17: =IF(A17="","",IF(OR(C17="❓ Unknown",D17="❓ Unknown"),"❓ Unknown",IF(AND(C17="✅ Compliant",D17="✅ Compliant"),"✅ Full Compliance",IF(OR(C17="✅ Compliant",D17="✅ Compliant"),"⚠ Partial Compliance","❌ Non-Compliant")))) | F17: =IF(A17="","",IF(AND(B17="Tier 1 - Critical",E17="❌ Non-Compliant"),"🔴 Critical",IF(B17="Tier 1 - Critical","🟡 High",IF(E17="❌ Non-Compliant","🟡 High",IF(E17="⚠ Partial Compliance","🟢 Medium","⚪ Low"))))) | G17: =IF(A17="","",IF(C17="❌ Non-Compliant",IF(D17="❌ Non-Compliant","Both RPO & RTO gaps","RPO gap only"),IF(D17="❌ Non-Compliant","RTO gap only",IF(E17="❓ Unknown","Testing required","No gaps"))))
A18: =System_Inventory!A18 | B18: =System_Inventory!C18 | C18: =IF(A18="","",IF(OR(System_Inventory!E18="",Capability_Assessment!E18=""),"❓ Unknown",IF(Capability_Assessment!E18<=System_Inventory!E18,"✅ Compliant","❌ Non-Compliant"))) | D18: =IF(A18="","",IF(OR(System_Inventory!F18="",Capability_Assessment!F18=""),"❓ Unknown",IF(Capability_Assessment!F18<=System_Inventory!F18,"✅ Compliant","❌ Non-Compliant"))) | E18: =IF(A18="","",IF(OR(C18="❓ Unknown",D18="❓ Unknown"),"❓ Unknown",IF(AND(C18="✅ Compliant",D18="✅ Compliant"),"✅ Full Compliance",IF(OR(C18="✅ Compliant",D18="✅ Compliant"),"⚠ Partial Compliance","❌ Non-Compliant")))) | F18: =IF(A18="","",IF(AND(B18="Tier 1 - Critical",E18="❌ Non-Compliant"),"🔴 Critical",IF(B18="Tier 1 - Critical","🟡 High",IF(E18="❌ Non-Compliant","🟡 High",IF(E18="⚠ Partial Compliance","🟢 Medium","⚪ Low"))))) | G18: =IF(A18="","",IF(C18="❌ Non-Compliant",IF(D18="❌ Non-Compliant","Both RPO & RTO gaps","RPO gap only"),IF(D18="❌ Non-Compliant","RTO gap only",IF(E18="❓ Unknown","Testing required","No gaps"))))
A19: =System_Inventory!A19 | B19: =System_Inventory!C19 | C19: =IF(A19="","",IF(OR(System_Inventory!E19="",Capability_Assessment!E19=""),"❓ Unknown",IF(Capability_Assessment!E19<=System_Inventory!E19,"✅ Compliant","❌ Non-Compliant"))) | D19: =IF(A19="","",IF(OR(System_Inventory!F19="",Capability_Assessment!F19=""),"❓ Unknown",IF(Capability_Assessment!F19<=System_Inventory!F19,"✅ Compliant","❌ Non-Compliant"))) | E19: =IF(A19="","",IF(OR(C19="❓ Unknown",D19="❓ Unknown"),"❓ Unknown",IF(AND(C19="✅ Compliant",D19="✅ Compliant"),"✅ Full Compliance",IF(OR(C19="✅ Compliant",D19="✅ Compliant"),"⚠ Partial Compliance","❌ Non-Compliant")))) | F19: =IF(A19="","",IF(AND(B19="Tier 1 - Critical",E19="❌ Non-Compliant"),"🔴 Critical",IF(B19="Tier 1 - Critical","🟡 High",IF(E19="❌ Non-Compliant","🟡 High",IF(E19="⚠ Partial Compliance","🟢 Medium","⚪ Low"))))) | G19: =IF(A19="","",IF(C19="❌ Non-Compliant",IF(D19="❌ Non-Compliant","Both RPO & RTO gaps","RPO gap only"),IF(D19="❌ Non-Compliant","RTO gap only",IF(E19="❓ Unknown","Testing required","No gaps"))))
A20: =System_Inventory!A20 | B20: =System_Inventory!C20 | C20: =IF(A20="","",IF(OR(System_Inventory!E20="",Capability_Assessment!E20=""),"❓ Unknown",IF(Capability_Assessment!E20<=System_Inventory!E20,"✅ Compliant","❌ Non-Compliant"))) | D20: =IF(A20="","",IF(OR(System_Inventory!F20="",Capability_Assessment!F20=""),"❓ Unknown",IF(Capability_Assessment!F20<=System_Inventory!F20,"✅ Compliant","❌ Non-Compliant"))) | E20: =IF(A20="","",IF(OR(C20="❓ Unknown",D20="❓ Unknown"),"❓ Unknown",IF(AND(C20="✅ Compliant",D20="✅ Compliant"),"✅ Full Compliance",IF(OR(C20="✅ Compliant",D20="✅ Compliant"),"⚠ Partial Compliance","❌ Non-Compliant")))) | F20: =IF(A20="","",IF(AND(B20="Tier 1 - Critical",E20="❌ Non-Compliant"),"🔴 Critical",IF(B20="Tier 1 - Critical","🟡 High",IF(E20="❌ Non-Compliant","🟡 High",IF(E20="⚠ Partial Compliance","🟢 Medium","⚪ Low"))))) | G20: =IF(A20="","",IF(C20="❌ Non-Compliant",IF(D20="❌ Non-Compliant","Both RPO & RTO gaps","RPO gap only"),IF(D20="❌ Non-Compliant","RTO gap only",IF(E20="❓ Unknown","Testing required","No gaps"))))
A21: =System_Inventory!A21 | B21: =System_Inventory!C21 | C21: =IF(A21="","",IF(OR(System_Inventory!E21="",Capability_Assessment!E21=""),"❓ Unknown",IF(Capability_Assessment!E21<=System_Inventory!E21,"✅ Compliant","❌ Non-Compliant"))) | D21: =IF(A21="","",IF(OR(System_Inventory!F21="",Capability_Assessment!F21=""),"❓ Unknown",IF(Capability_Assessment!F21<=System_Inventory!F21,"✅ Compliant","❌ Non-Compliant"))) | E21: =IF(A21="","",IF(OR(C21="❓ Unknown",D21="❓ Unknown"),"❓ Unknown",IF(AND(C21="✅ Compliant",D21="✅ Compliant"),"✅ Full Compliance",IF(OR(C21="✅ Compliant",D21="✅ Compliant"),"⚠ Partial Compliance","❌ Non-Compliant")))) | F21: =IF(A21="","",IF(AND(B21="Tier 1 - Critical",E21="❌ Non-Compliant"),"🔴 Critical",IF(B21="Tier 1 - Critical","🟡 High",IF(E21="❌ Non-Compliant","🟡 High",IF(E21="⚠ Partial Compliance","🟢 Medium","⚪ Low"))))) | G21: =IF(A21="","",IF(C21="❌ Non-Compliant",IF(D21="❌ Non-Compliant","Both RPO & RTO gaps","RPO gap only"),IF(D21="❌ Non-Compliant","RTO gap only",IF(E21="❓ Unknown","Testing required","No gaps"))))
A22: =System_Inventory!A22 | B22: =System_Inventory!C22 | C22: =IF(A22="","",IF(OR(System_Inventory!E22="",Capability_Assessment!E22=""),"❓ Unknown",IF(Capability_Assessment!E22<=System_Inventory!E22,"✅ Compliant","❌ Non-Compliant"))) | D22: =IF(A22="","",IF(OR(System_Inventory!F22="",Capability_Assessment!F22=""),"❓ Unknown",IF(Capability_Assessment!F22<=System_Inventory!F22,"✅ Compliant","❌ Non-Compliant"))) | E22: =IF(A22="","",IF(OR(C22="❓ Unknown",D22="❓ Unknown"),"❓ Unknown",IF(AND(C22="✅ Compliant",D22="✅ Compliant"),"✅ Full Compliance",IF(OR(C22="✅ Compliant",D22="✅ Compliant"),"⚠ Partial Compliance","❌ Non-Compliant")))) | F22: =IF(A22="","",IF(AND(B22="Tier 1 - Critical",E22="❌ Non-Compliant"),"🔴 Critical",IF(B22="Tier 1 - Critical","🟡 High",IF(E22="❌ Non-Compliant","🟡 High",IF(E22="⚠ Partial Compliance","🟢 Medium","⚪ Low"))))) | G22: =IF(A22="","",IF(C22="❌ Non-Compliant",IF(D22="❌ Non-Compliant","Both RPO & RTO gaps","RPO gap only"),IF(D22="❌ Non-Compliant","RTO gap only",IF(E22="❓ Unknown","Testing required","No gaps"))))
A23: =System_Inventory!A23 | B23: =System_Inventory!C23 | C23: =IF(A23="","",IF(OR(System_Inventory!E23="",Capability_Assessment!E23=""),"❓ Unknown",IF(Capability_Assessment!E23<=System_Inventory!E23,"✅ Compliant","❌ Non-Compliant"))) | D23: =IF(A23="","",IF(OR(System_Inventory!F23="",Capability_Assessment!F23=""),"❓ Unknown",IF(Capability_Assessment!F23<=System_Inventory!F23,"✅ Compliant","❌ Non-Compliant"))) | E23: =IF(A23="","",IF(OR(C23="❓ Unknown",D23="❓ Unknown"),"❓ Unknown",IF(AND(C23="✅ Compliant",D23="✅ Compliant"),"✅ Full Compliance",IF(OR(C23="✅ Compliant",D23="✅ Compliant"),"⚠ Partial Compliance","❌ Non-Compliant")))) | F23: =IF(A23="","",IF(AND(B23="Tier 1 - Critical",E23="❌ Non-Compliant"),"🔴 Critical",IF(B23="Tier 1 - Critical","🟡 High",IF(E23="❌ Non-Compliant","🟡 High",IF(E23="⚠ Partial Compliance","🟢 Medium","⚪ Low"))))) | G23: =IF(A23="","",IF(C23="❌ Non-Compliant",IF(D23="❌ Non-Compliant","Both RPO & RTO gaps","RPO gap only"),IF(D23="❌ Non-Compliant","RTO gap only",IF(E23="❓ Unknown","Testing required","No gaps"))))
A24: =System_Inventory!A24 | B24: =System_Inventory!C24 | C24: =IF(A24="","",IF(OR(System_Inventory!E24="",Capability_Assessment!E24=""),"❓ Unknown",IF(Capability_Assessment!E24<=System_Inventory!E24,"✅ Compliant","❌ Non-Compliant"))) | D24: =IF(A24="","",IF(OR(System_Inventory!F24="",Capability_Assessment!F24=""),"❓ Unknown",IF(Capability_Assessment!F24<=System_Inventory!F24,"✅ Compliant","❌ Non-Compliant"))) | E24: =IF(A24="","",IF(OR(C24="❓ Unknown",D24="❓ Unknown"),"❓ Unknown",IF(AND(C24="✅ Compliant",D24="✅ Compliant"),"✅ Full Compliance",IF(OR(C24="✅ Compliant",D24="✅ Compliant"),"⚠ Partial Compliance","❌ Non-Compliant")))) | F24: =IF(A24="","",IF(AND(B24="Tier 1 - Critical",E24="❌ Non-Compliant"),"🔴 Critical",IF(B24="Tier 1 - Critical","🟡 High",IF(E24="❌ Non-Compliant","🟡 High",IF(E24="⚠ Partial Compliance","🟢 Medium","⚪ Low"))))) | G24: =IF(A24="","",IF(C24="❌ Non-Compliant",IF(D24="❌ Non-Compliant","Both RPO & RTO gaps","RPO gap only"),IF(D24="❌ Non-Compliant","RTO gap only",IF(E24="❓ Unknown","Testing required","No gaps"))))
A25: =System_Inventory!A25 | B25: =System_Inventory!C25 | C25: =IF(A25="","",IF(OR(System_Inventory!E25="",Capability_Assessment!E25=""),"❓ Unknown",IF(Capability_Assessment!E25<=System_Inventory!E25,"✅ Compliant","❌ Non-Compliant"))) | D25: =IF(A25="","",IF(OR(System_Inventory!F25="",Capability_Assessment!F25=""),"❓ Unknown",IF(Capability_Assessment!F25<=System_Inventory!F25,"✅ Compliant","❌ Non-Compliant"))) | E25: =IF(A25="","",IF(OR(C25="❓ Unknown",D25="❓ Unknown"),"❓ Unknown",IF(AND(C25="✅ Compliant",D25="✅ Compliant"),"✅ Full Compliance",IF(OR(C25="✅ Compliant",D25="✅ Compliant"),"⚠ Partial Compliance","❌ Non-Compliant")))) | F25: =IF(A25="","",IF(AND(B25="Tier 1 - Critical",E25="❌ Non-Compliant"),"🔴 Critical",IF(B25="Tier 1 - Critical","🟡 High",IF(E25="❌ Non-Compliant","🟡 High",IF(E25="⚠ Partial Compliance","🟢 Medium","⚪ Low"))))) | G25: =IF(A25="","",IF(C25="❌ Non-Compliant",IF(D25="❌ Non-Compliant","Both RPO & RTO gaps","RPO gap only"),IF(D25="❌ Non-Compliant","RTO gap only",IF(E25="❓ Unknown","Testing required","No gaps"))))
A26: =System_Inventory!A26 | B26: =System_Inventory!C26 | C26: =IF(A26="","",IF(OR(System_Inventory!E26="",Capability_Assessment!E26=""),"❓ Unknown",IF(Capability_Assessment!E26<=System_Inventory!E26,"✅ Compliant","❌ Non-Compliant"))) | D26: =IF(A26="","",IF(OR(System_Inventory!F26="",Capability_Assessment!F26=""),"❓ Unknown",IF(Capability_Assessment!F26<=System_Inventory!F26,"✅ Compliant","❌ Non-Compliant"))) | E26: =IF(A26="","",IF(OR(C26="❓ Unknown",D26="❓ Unknown"),"❓ Unknown",IF(AND(C26="✅ Compliant",D26="✅ Compliant"),"✅ Full Compliance",IF(OR(C26="✅ Compliant",D26="✅ Compliant"),"⚠ Partial Compliance","❌ Non-Compliant")))) | F26: =IF(A26="","",IF(AND(B26="Tier 1 - Critical",E26="❌ Non-Compliant"),"🔴 Critical",IF(B26="Tier 1 - Critical","🟡 High",IF(E26="❌ Non-Compliant","🟡 High",IF(E26="⚠ Partial Compliance","🟢 Medium","⚪ Low"))))) | G26: =IF(A26="","",IF(C26="❌ Non-Compliant",IF(D26="❌ Non-Compliant","Both RPO & RTO gaps","RPO gap only"),IF(D26="❌ Non-Compliant","RTO gap only",IF(E26="❓ Unknown","Testing required","No gaps"))))
... A114: =System_Inventory!A114 | B114: =System_Inventory!C114 | C114: =IF(A114="","",IF(OR(System_Inventory!E114="",Capability_Assessment!E114=""),"❓ Unknown",IF(Capability_Assessment!E114<=System_Inventory!E114,"✅ Compliant","❌ Non-Compliant"))) | D114: =IF(A114="","",IF(OR(System_Inventory!F114="",Capability_Assessment!F114=""),"❓ Unknown",IF(Capability_Assessment!F114<=System_Inventory!F114,"✅ Compliant","❌ Non-Compliant"))) | E114: =IF(A114="","",IF(OR(C114="❓ Unknown",D114="❓ Unknown"),"❓ Unknown",IF(AND(C114="✅ Compliant",D114="✅ Compliant"),"✅ Full Compliance",IF(OR(C114="✅ Compliant",D114="✅ Compliant"),"⚠ Partial Compliance","❌ Non-Compliant")))) | F114: =IF(A114="","",IF(AND(B114="Tier 1 - Critical",E114="❌ Non-Compliant"),"🔴 Critical",IF(B114="Tier 1 - Critical","🟡 High",IF(E114="❌ Non-Compliant","🟡 High",IF(E114="⚠ Partial Compliance","🟢 Medium","⚪ Low"))))) | G114: =IF(A114="","",IF(C114="❌ Non-Compliant",IF(D114="❌ Non-Compliant","Both RPO & RTO gaps","RPO gap only"),IF(D114="❌ Non-Compliant","RTO gap only",IF(E114="❓ Unknown","Testing required","No gaps"))))
A117: COMPLIANCE SUMMARY METRICS
A118: Total Systems: | B118: =COUNTA(A5:A114)
A119: Full Compliance (✅): | B119: =COUNTIF(E5:E114,"✅*")
A120: Partial Compliance (⚠️): | B120: =COUNTIF(E5:E114,"⚠*")
A121: Non-Compliant (❌): | B121: =COUNTIF(E5:E114,"❌*")
A122: Unknown (❓): | B122: =COUNTIF(E5:E114,"❓*")
A123: Overall Compliance Rate: | B123: =IF(B118>0,B119/B118,0)

Sheet Gap_Analysis
A1: GAP ANALYSIS & REMEDIATION TRACKING
A2: Document identified gaps with risk scoring and remediation plans
A4: Gap ID | B4: System | C4: Gap Type | D4: Gap Description | E4: Risk Score (1-10) | F4: Priority | G4: Remediation Plan | H4: Status
A5: GAP-001 | C5: E-Commerce Website | D5: RTO Gap | E5: RTO requirement 2hr, current capability 4hr (restore time), missing redundancy | F5: 8 | G5: 🟡 High | H5: Implement Active-Passive cluster to achieve <2hr RTO via failover | I5: ⏳ In Progress
A6: GAP-002 | C6: Payment Gateway | D6: Testing Gap | E6: Failover capability exists but not tested in last 90 days, compliance unknown | F6: 9 | G6: 🔴 Critical | H6: Schedule failover test within 30 days, document results | I6: 🔴 Open
A7: GAP-003 | C7: CRM System | D7: RTO Gap | E7: RTO requirement 6hr, current restore time 8hr, no failover capability | F7: 7 | G7: 🟡 High | H7: Optimize restore procedures, implement parallel restore, target <6hr | I7: ⏳ In Progress
A8: GAP-004 | C8: Email System | D8: RTO Gap | E8: RTO requirement 4hr, restore time 12hr, no redundancy | F8: 6 | G8: 🟡 High | H8: Consider cloud email with built-in redundancy (Office 365, Gmail) | I8: 🔴 Open
A9: GAP-005 | C9: HR Information System | D9: Both RPO & RTO | E9: RPO req 24hr, backup frequency 24hr (at limit), RTO req 24hr, restore time 20hr | F9: 5 | G9: 🟢 Medium | H9: Monitor closely, acceptable but no margin for error | I9: ➖ Risk Accepted
A10: GAP-006 | C10: File Server | D10: RPO Gap | E10: RPO requirement 24hr, backup frequency 168hr (weekly) | F10: 4 | G10: 🟢 Medium | H10: Increase backup frequency to daily (24hr) to meet RPO requirement | I10: ✅ Closed
A11: GAP-007 | C11: Document Repository | D11: Testing Gap | E11: Restore time not tested, compliance status unknown | F11: 3 | G11: 🟢 Medium | H11: Schedule restore test, document actual restore time | I11: ⏳ In Progress
A12: GAP-008 | C12: Test Database | D12: Documentation Gap | E12: BIA not performed, RPO/RTO requirements undefined | F12: 2 | G12: ⚪ Low | H12: Conduct BIA for dev/test systems, document acceptable recovery times | I12: 🔴 Open
A13: GAP-009 | C13: Payment Gateway | D13: RPO Gap | E13: RPO requirement 15min, backup frequency 15min (at limit, no margin) | F13: 8 | G13: 🔴 Critical | H13: Implement continuous replication (synchronous) to eliminate RPO gap | I13: ⏳ In Progress
A14: GAP-010 | C14: Training System | D14: Both RPO & RTO | E14: Requirements far exceed capabilities but Tier 4 (low priority), risk acceptable | F14: 1 | G14: ⚪ Low | H14: No action required, business accepts risk for non-critical system | I14: ➖ Risk Accepted
A15: GAP-011
A16: GAP-012
A17: GAP-013
A18: GAP-014
A19: GAP-015
A20: GAP-016
A21: GAP-017
A22: GAP-018
A23: GAP-019
A24: GAP-020
A25: GAP-021
A26: GAP-022
... A117: GAP SUMMARY METRICS
A118: Total Gaps Identified: | B118: =COUNTA(B5:B114)
A119: 🔴 Critical Priority: | B119: =COUNTIF(F5:F114,"🔴*")
A120: 🟡 High Priority: | B120: =COUNTIF(F5:F114,"🟡*")
A121: 🟢 Medium Priority: | B121: =COUNTIF(F5:F114,"🟢*")
A122: ⚪ Low Priority: | B122: =COUNTIF(F5:F114,"⚪*")
A124: 🔴 Open Gaps: | B124: =COUNTIF(H5:H114,"🔴*")
A125: ⏳ In Progress: | B125: =COUNTIF(H5:H114,"⏳*")
A126: ✅ Closed Gaps: | B126: =COUNTIF(H5:H114,"✅*")
A127: ➖ Risk Accepted: | B127: =COUNTIF(H5:H114,"➖*")
A129: Average Risk Score: | B129: =IFERROR(AVERAGE(E5:E114),0)
A130: Max Risk Score: | B130: =IFERROR(MAX(E5:E114),0)

Sheet Evidence_Register
A1: EVIDENCE REGISTER
A2: Document all evidence supporting this assessment (MINIMUM 5 evidence items required for audit compliance)
A4: Evidence ID | B4: Evidence Type | C4: Description | D4: Related Sheet/Row | E4: Location/Path | F4: Date Collected | G4: Collected By | H4: Verification Status
A5: EVD-001 | C5: BIA Report | D5: Business Impact Analysis Q1 2024 - RPO/RTO requirements | E5: System_Inventory (all rows) | F5: /evidence/bia/BIA_Report_Q1_2024.pdf | G5: 31.01.2026 | H5: BC/DR Coordinator | I5: ✅ Verified
A6: EVD-002 | C6: Test Result | D6: E-Commerce restore test results - 4hr restore time | E6: Capability_Assessment!A5 | F6: /evidence/testing/ecommerce_restore_test_2024-01-05.pdf | G6: 26.01.2026 | H6: Infrastructure Team | I6: ✅ Verified
A7: EVD-003 | C7: Test Result | D7: Payment Gateway failover test - 5min failover time | E7: Capability_Assessment!A6 | F7: /evidence/testing/payment_failover_test_2024-01-03.pdf | G7: 24.01.2026 | H7: Infrastructure Team | I7: ✅ Verified
A8: EVD-004 | C8: Screenshot | D8: Backup monitoring dashboard - all systems backup status | E8: Backup_Inventory (WB1) | F8: /evidence/monitoring/backup_dashboard_2024-01-10.png | G8: 31.01.2026 | H8: Backup Administrator | I8: ✅ Verified
A9: EVD-005 | C9: Config File | D9: Backup schedule configuration - all systems | E9: System_Inventory | F9: /evidence/configs/backup_schedules.json | G9: 29.01.2026 | H9: Backup Administrator | I9: ✅ Verified
A10: EVD-006 | C10: Report | D10: RPO/RTO compliance calculations - automated report | E10: Compliance_Matrix | F10: /evidence/reports/rpo_rto_compliance_2024-01-10.xlsx | G10: 31.01.2026 | H10: Assessment Team | I10: ⏳ Pending
A11: EVD-007 | C11: Diagram | D11: High-availability architecture diagram - critical systems | E11: Capability_Assessment (Tier 1) | F11: /evidence/diagrams/ha_architecture_2024.vsdx | G11: 21.01.2026 | H11: Solutions Architect | I11: ✅ Verified
A12: EVD-008 | C12: Policy Document | D12: BC/DR Policy - RPO/RTO requirements policy | E12: All worksheets | F12: /evidence/policies/ISMS-POL-A813-814-530.pdf | G12: 01.01.2026 | H12: ISO Coordinator | I12: ✅ Verified
A13: EVD-009
A14: EVD-010
A15: EVD-011
A16: EVD-012
A17: EVD-013
A18: EVD-014
A19: EVD-015
A20: EVD-016
A21: EVD-017
A22: EVD-018
A23: EVD-019
A24: EVD-020
... A107: EVIDENCE COLLECTION SUMMARY
A108: Total Evidence Items: | B108: =COUNTA(A5:A104)
A109: ✅ Verified Evidence: | B109: =COUNTIF(H5:H104,"✅*")
A110: ⏳ Pending Verification: | B110: =COUNTIF(H5:H104,"⏳*")
A111: ❌ Not Verified: | B111: =COUNTIF(H5:H104,"❌*")
A113: Minimum Required: | B113: 5
A114: Compliance Status: | B114: =IF(B108>=5,"✅ Sufficient Evidence","❌ Insufficient Evidence")

Sheet Approval_Sign_Off
A1: ASSESSMENT APPROVAL & SIGN-OFF
A3: ASSESSMENT SUMMARY
A4: Assessment Document: | B4: RPO/RTO Compliance Matrix
A5: Assessment ID: | B5: ISMS-IMP-A.8.13.3
A6: ISO 27001:2022 Controls: | B6: A.8.13 (Information Backup)
A7: Assessment Period: | B7: [USER INPUT - e.g., Q1 2024, January 2024]
A8: Total Systems Assessed: | B8: =Summary!B5
A9: Overall RPO/RTO Compliance Rate: | B9: =Summary!B10
A10: Critical Priority Gaps: | B10: =Summary!B23
A11: Open Gaps Requiring Remediation: | B11: =Summary!B29
A12: Critical Gaps Summary: | B12: [USER INPUT - list critical gaps from Gap_Analysis]
A13: Evidence Items Collected: | B13: =COUNTA(Evidence_Register!A5:A104)
A14: Assessment Status: | B14: [SELECT FROM DROPDOWN]
A17: LEVEL 1: ASSESSMENT COMPLETED BY
A18: Name:
A19: Role/Title:
A20: Department:
A21: Email:
A22: Date Completed: | B22: =TODAY()
A23: Signature/Initials:
A26: LEVEL 2: REVIEWED BY (INFORMATION SECURITY OFFICER)
A27: Name:
A28: Review Date:
A29: Review Notes:
A32: Recommendation:
A35: LEVEL 3: APPROVED BY (CISO / SECURITY DIRECTOR)
A36: Name:
A37: Approval Date:
A38: Approval Decision:
A39: Conditions/Notes:
A44: NEXT REVIEW DETAILS
A45: Next Review Date (Quarterly): | B45: =TODAY()+90
A46: Review Responsible:
A47: Special Considerations:
A50: APPROVAL WORKFLOW REQUIREMENTS
A51: • All 3 approval levels must be completed for final approval
A52: • Minimum 5 evidence items must be documented in Evidence_Register
A53: • Assessment status must be "Final" before CISO approval
A54: • If "Requires Remediation", re-assessment required after gap closure
A55: • Quarterly re-assessment recommended for continuous compliance (RPO/RTO capabilities change)
...
