Workbook

Sheet Executive Summary
A1: CLD-SEC-CHK-A.5.39 — Agreement on Cloud Service Partner Roles Compliance Checklist
A3: DOCUMENT INFORMATION
A4: Document ID | B4: CLD-SEC-CHK-A.5.39
A5: Source Policy | B5: CLD-SEC-POL-A.5.39
A6: ISO Controls | B6: Agreement on Cloud Service Partner Roles
A7: Generated | B7: 01.08.2026
A8: Prepared By
A9: Organisation
A10: Review Cycle | B10: Annual
A12: OVERALL COMPLIANCE STATUS
A13: Overall Compliance | B13: ='Dashboard'!G6
A14: Status | B14: =IF(Dashboard!G6="N/A","NOT ASSESSED",IF(ISNUMBER(VALUE(SUBSTITUTE(Dashboard!G6,"%",""))),IF(VALUE(SUBSTITUTE(Dashboard!G6,"%",""))>=90,"GREEN",IF(VALUE(SUBSTITUTE(Dashboard!G6,"%",""))>=70,"AMBER","RED")),"NOT ASSESSED"))
A16: KEY METRICS
A17: Total Requirements | B17: ='Dashboard'!B6
A18: Compliant | B18: ='Dashboard'!C6
A19: Partial | B19: ='Dashboard'!D6
A20: Non-Compliant | B20: ='Dashboard'!E6
A21: Not Applicable | B21: ='Dashboard'!F6
A22: Owner Coverage | B22: =IF(Dashboard!B6=0,"N/A",ROUND((COUNTA('Defining and Agreeing CSN Roles'!F4:F7)+COUNTA('Governance and Oversight'!F4:F7))/Dashboard!B6*100,0)&"%")
A24: DOMAIN STATUS SUMMARY
A25: Domain | B25: Compliance % | C25: Compliant | D25: Gaps | E25: Status
A26: Defining and Agreeing CSN Roles | B26: ='Dashboard'!G4 | C26: ='Dashboard'!C4 | D26: ='Dashboard'!E4 | E26: =IF(Dashboard!G4="N/A","--",IF(ISNUMBER(VALUE(SUBSTITUTE(Dashboard!G4,"%",""))),IF(VALUE(SUBSTITUTE(Dashboard!G4,"%",""))>=90,"PASS",IF(VALUE(SUBSTITUTE(Dashboard!G4,"%",""))>=70,"REVIEW","FAIL")),"--"))
A27: Governance and Oversight | B27: ='Dashboard'!G5 | C27: ='Dashboard'!C5 | D27: ='Dashboard'!E5 | E27: =IF(Dashboard!G5="N/A","--",IF(ISNUMBER(VALUE(SUBSTITUTE(Dashboard!G5,"%",""))),IF(VALUE(SUBSTITUTE(Dashboard!G5,"%",""))>=90,"PASS",IF(VALUE(SUBSTITUTE(Dashboard!G5,"%",""))>=70,"REVIEW","FAIL")),"--"))
A29: CRITICAL ISSUES
A30: # | B30: Issue Description | C30: Domain | D30: Owner | E30: Due Date
A31: 1
A32: 2
A33: 3
A34: 4
A35: 5
A37: MANAGEMENT COMMENTARY
A38: [Enter management commentary on agreement on cloud service partner roles posture]
A42: APPROVAL
A43: Assessed By
A44: Name:
A45: Date:
A46: Signature:
A47: Decision:
A49: Reviewed By (DPO)
A50: Name:
...

Sheet Dashboard
A1: Agreement on Cloud Service Partner Roles — Compliance Dashboard
A3: Domain | B3: Total Reqs | C3: Compliant | D3: Partial | E3: Non-Compliant | F3: N/A | G3: Compliance %
A4: Defining and Agreeing CSN Roles | B4: =COUNTA('Defining and Agreeing CSN Roles'!D4:D7) | C4: =COUNTIF('Defining and Agreeing CSN Roles'!D4:D7,"Compliant") | D4: =COUNTIF('Defining and Agreeing CSN Roles'!D4:D7,"Partial") | E4: =COUNTIF('Defining and Agreeing CSN Roles'!D4:D7,"Non-Compliant") | F4: =COUNTIF('Defining and Agreeing CSN Roles'!D4:D7,"N/A") | G4: =IF((B4-F4)=0,"N/A",ROUND(C4/(B4-F4)*100,1)&"%")
A5: Governance and Oversight | B5: =COUNTA('Governance and Oversight'!D4:D7) | C5: =COUNTIF('Governance and Oversight'!D4:D7,"Compliant") | D5: =COUNTIF('Governance and Oversight'!D4:D7,"Partial") | E5: =COUNTIF('Governance and Oversight'!D4:D7,"Non-Compliant") | F5: =COUNTIF('Governance and Oversight'!D4:D7,"N/A") | G5: =IF((B5-F5)=0,"N/A",ROUND(C5/(B5-F5)*100,1)&"%")
A6: TOTAL | B6: =SUM(B4:B5) | C6: =SUM(C4:C5) | D6: =SUM(D4:D5) | E6: =SUM(E4:E5) | F6: =SUM(F4:F5) | G6: =IF((B6-F6)=0,"N/A",ROUND(C6/(B6-F6)*100,1)&"%")
A8: COMPLIANCE BY STATUS
A9: Compliant | B9: =C6 | C9: =IF(B6=0,"",ROUND(B9/B6*100,1)&"%")
A10: Partial | B10: =D6 | C10: =IF(B6=0,"",ROUND(B10/B6*100,1)&"%")
A11: Non-Compliant | B11: =E6 | C11: =IF(B6=0,"",ROUND(B11/B6*100,1)&"%")
A12: N/A | B12: =F6 | C12: =IF(B6=0,"",ROUND(B12/B6*100,1)&"%")
A14: TOP GAPS (Manual Entry)
A15: Priority | B15: Domain | C15: Requirement | D15: Owner | E15: Due Date | F15: Status
A27: COMPLIANCE TREND (Manual Entry)
A28: Assessment Date | B28: Overall % | C28: Compliant | D28: Gaps | E28: Assessor | F28: Notes

Sheet Defining and Agreeing CSN Roles
A1: Defining and Agreeing CSN Roles — Compliance Checklist
A2: ISO/IEC 27017:2026 — Controls 5.39: Agreement on Cloud Service Partner Roles
A3: Req # | B3: Section | C3: Requirement | D3: Status | E3: Evidence | F3: Owner | G3: Due Date | H3: Notes
A4: 5.39-01 | B4: Classify CSN Sub-Role | C4: The organisation shall classify each prospective cloud service partner (CSN) against the ISO/IEC 22123-3 sub-roles (cloud service developer, cloud auditor, cloud service broker) before engagement.
A5: 5.39-02 | B5: Written Agreement Before Work Begins | C5: The organisation shall reach written agreement with the CSN on its roles and responsibilities before the CSN begins any activity affecting a cloud service the organisation consumes or delivers.
A6: 5.39-03 | B6: Consistency with Shared Responsibility Allocation | C6: The organisation shall verify that the agreement with the CSN is consistent with the shared roles and responsibilities already established between the organisation and its CSC or CSP counterparty under CLD-SEC-POL-A.5.38.
A7: 5.39-04 | B7: Contractual Requirements | C7: Every cloud service partner engagement shall be governed by a written agreement, negotiated per ISMS-POL-A.5.19-23-S2, that identifies the CSN's sub-role(s) and states the specific information security responsibilities assigned.

Sheet Governance and Oversight
A1: Governance and Oversight — Compliance Checklist
A2: ISO/IEC 27017:2026 — Controls 5.39: Agreement on Cloud Service Partner Roles
A3: Req # | B3: Section | C3: Requirement | D3: Status | E3: Evidence | F3: Owner | G3: Due Date | H3: Notes
A4: 5.39-05 | B4: Recognise Dual CSN/CSP Role | C4: Where a cloud service partner also independently delivers a cloud service to the organisation, the organisation shall apply CLD-SEC-POL-A.5.38 to that CSP relationship in addition to CSN-specific requirements.
A5: 5.39-06 | B5: CSN Role Register | C5: The organisation shall maintain a CSN Role Register listing all active cloud service partners with assigned sub-role(s), scope, and agreement reference.
A6: 5.39-07 | B6: Annual Review | C6: The organisation shall review the CSN Role Register at least annually, confirming each active CSN's classification, agreed responsibilities, and continued consistency with the relevant Shared Responsibility Matrix.
A7: 5.39-08 | B7: Escalation of Scope Conflicts | C7: The organisation shall escalate to the Cloud Security Manager, and where unresolved to the CISO, any instance where a CSN's actual activity exceeds its agreed scope or conflicts with the CSC/CSP shared responsibility allocation.
