Workbook

Sheet Executive Summary
A1: ISMS-OP-CHK-A.5.24-28 — Incident Management Compliance Checklist
A3: DOCUMENT INFORMATION
A4: Document ID | B4: ISMS-OP-CHK-A.5.24-28
A5: Source Policy | B5: ISMS-OP-POL-A.5.24-28
A6: ISO Controls | B6: Incident Management
A7: Generated | B7: 08.02.2026
A8: Prepared By
A9: Organisation
A10: Review Cycle | B10: Annual
A12: OVERALL COMPLIANCE STATUS
A13: Overall Compliance | B13: ='Dashboard'!G12
A14: Status | B14: =IF(Dashboard!G12="N/A","NOT ASSESSED",IF(ISNUMBER(VALUE(SUBSTITUTE(Dashboard!G12,"%",""))),IF(VALUE(SUBSTITUTE(Dashboard!G12,"%",""))>=90,"GREEN",IF(VALUE(SUBSTITUTE(Dashboard!G12,"%",""))>=70,"AMBER","RED")),"NOT ASSESSED"))
A16: KEY METRICS
A17: Total Requirements | B17: ='Dashboard'!B12
A18: Compliant | B18: ='Dashboard'!C12
A19: Partial | B19: ='Dashboard'!D12
A20: Non-Compliant | B20: ='Dashboard'!E12
A21: Not Applicable | B21: ='Dashboard'!F12
A22: Owner Coverage | B22: =IF(Dashboard!B12=0,"N/A",ROUND((COUNTA('Incident Reporting'!F4:F7)+COUNTA('Event Assessment and Triage'!F4:F7)+COUNTA('Incident Classification'!F4:F4)+COUNTA('Incident Response'!F4:F13)+COUNTA('Significant Incidents'!F4:F5)+COUNTA('Data Breach Notification'!F4:F8)+COUNTA('Lessons Learned'!F4:F11)+COUNTA('Incident Response Testing'!F4:F5))/Dashboard!B12*100,0)&"%")
A24: DOMAIN STATUS SUMMARY
A25: Domain | B25: Compliance % | C25: Compliant | D25: Gaps | E25: Status
A26: Incident Reporting | B26: ='Dashboard'!G4 | C26: ='Dashboard'!C4 | D26: ='Dashboard'!E4 | E26: =IF(Dashboard!G4="N/A","--",IF(ISNUMBER(VALUE(SUBSTITUTE(Dashboard!G4,"%",""))),IF(VALUE(SUBSTITUTE(Dashboard!G4,"%",""))>=90,"PASS",IF(VALUE(SUBSTITUTE(Dashboard!G4,"%",""))>=70,"REVIEW","FAIL")),"--"))
A27: Event Assessment and Triage | B27: ='Dashboard'!G5 | C27: ='Dashboard'!C5 | D27: ='Dashboard'!E5 | E27: =IF(Dashboard!G5="N/A","--",IF(ISNUMBER(VALUE(SUBSTITUTE(Dashboard!G5,"%",""))),IF(VALUE(SUBSTITUTE(Dashboard!G5,"%",""))>=90,"PASS",IF(VALUE(SUBSTITUTE(Dashboard!G5,"%",""))>=70,"REVIEW","FAIL")),"--"))
A28: Incident Classification | B28: ='Dashboard'!G6 | C28: ='Dashboard'!C6 | D28: ='Dashboard'!E6 | E28: =IF(Dashboard!G6="N/A","--",IF(ISNUMBER(VALUE(SUBSTITUTE(Dashboard!G6,"%",""))),IF(VALUE(SUBSTITUTE(Dashboard!G6,"%",""))>=90,"PASS",IF(VALUE(SUBSTITUTE(Dashboard!G6,"%",""))>=70,"REVIEW","FAIL")),"--"))
A29: Incident Response | B29: ='Dashboard'!G7 | C29: ='Dashboard'!C7 | D29: ='Dashboard'!E7 | E29: =IF(Dashboard!G7="N/A","--",IF(ISNUMBER(VALUE(SUBSTITUTE(Dashboard!G7,"%",""))),IF(VALUE(SUBSTITUTE(Dashboard!G7,"%",""))>=90,"PASS",IF(VALUE(SUBSTITUTE(Dashboard!G7,"%",""))>=70,"REVIEW","FAIL")),"--"))
A30: Significant Incidents | B30: ='Dashboard'!G8 | C30: ='Dashboard'!C8 | D30: ='Dashboard'!E8 | E30: =IF(Dashboard!G8="N/A","--",IF(ISNUMBER(VALUE(SUBSTITUTE(Dashboard!G8,"%",""))),IF(VALUE(SUBSTITUTE(Dashboard!G8,"%",""))>=90,"PASS",IF(VALUE(SUBSTITUTE(Dashboard!G8,"%",""))>=70,"REVIEW","FAIL")),"--"))
A31: Data Breach Notification | B31: ='Dashboard'!G9 | C31: ='Dashboard'!C9 | D31: ='Dashboard'!E9 | E31: =IF(Dashboard!G9="N/A","--",IF(ISNUMBER(VALUE(SUBSTITUTE(Dashboard!G9,"%",""))),IF(VALUE(SUBSTITUTE(Dashboard!G9,"%",""))>=90,"PASS",IF(VALUE(SUBSTITUTE(Dashboard!G9,"%",""))>=70,"REVIEW","FAIL")),"--"))
A32: Lessons Learned | B32: ='Dashboard'!G10 | C32: ='Dashboard'!C10 | D32: ='Dashboard'!E10 | E32: =IF(Dashboard!G10="N/A","--",IF(ISNUMBER(VALUE(SUBSTITUTE(Dashboard!G10,"%",""))),IF(VALUE(SUBSTITUTE(Dashboard!G10,"%",""))>=90,"PASS",IF(VALUE(SUBSTITUTE(Dashboard!G10,"%",""))>=70,"REVIEW","FAIL")),"--"))
A33: Incident Response Testing | B33: ='Dashboard'!G11 | C33: ='Dashboard'!C11 | D33: ='Dashboard'!E11 | E33: =IF(Dashboard!G11="N/A","--",IF(ISNUMBER(VALUE(SUBSTITUTE(Dashboard!G11,"%",""))),IF(VALUE(SUBSTITUTE(Dashboard!G11,"%",""))>=90,"PASS",IF(VALUE(SUBSTITUTE(Dashboard!G11,"%",""))>=70,"REVIEW","FAIL")),"--"))
A35: CRITICAL ISSUES
A36: # | B36: Issue Description | C36: Domain | D36: Owner | E36: Due Date
A37: 1
A38: 2
A39: 3
A40: 4
A41: 5
A43: MANAGEMENT COMMENTARY
A44: [Enter management commentary on incident management posture]
A48: APPROVAL
A49: Assessed By
...

Sheet Dashboard
A1: Incident Management — Compliance Dashboard
A3: Domain | B3: Total Reqs | C3: Compliant | D3: Partial | E3: Non-Compliant | F3: N/A | G3: Compliance %
A4: Incident Reporting | B4: =COUNTA('Incident Reporting'!D4:D7) | C4: =COUNTIF('Incident Reporting'!D4:D7,"Compliant") | D4: =COUNTIF('Incident Reporting'!D4:D7,"Partial") | E4: =COUNTIF('Incident Reporting'!D4:D7,"Non-Compliant") | F4: =COUNTIF('Incident Reporting'!D4:D7,"N/A") | G4: =IF((B4-F4)=0,"N/A",ROUND(C4/(B4-F4)*100,1)&"%")
A5: Event Assessment and Triage | B5: =COUNTA('Event Assessment and Triage'!D4:D7) | C5: =COUNTIF('Event Assessment and Triage'!D4:D7,"Compliant") | D5: =COUNTIF('Event Assessment and Triage'!D4:D7,"Partial") | E5: =COUNTIF('Event Assessment and Triage'!D4:D7,"Non-Compliant") | F5: =COUNTIF('Event Assessment and Triage'!D4:D7,"N/A") | G5: =IF((B5-F5)=0,"N/A",ROUND(C5/(B5-F5)*100,1)&"%")
A6: Incident Classification | B6: =COUNTA('Incident Classification'!D4:D4) | C6: =COUNTIF('Incident Classification'!D4:D4,"Compliant") | D6: =COUNTIF('Incident Classification'!D4:D4,"Partial") | E6: =COUNTIF('Incident Classification'!D4:D4,"Non-Compliant") | F6: =COUNTIF('Incident Classification'!D4:D4,"N/A") | G6: =IF((B6-F6)=0,"N/A",ROUND(C6/(B6-F6)*100,1)&"%")
A7: Incident Response | B7: =COUNTA('Incident Response'!D4:D13) | C7: =COUNTIF('Incident Response'!D4:D13,"Compliant") | D7: =COUNTIF('Incident Response'!D4:D13,"Partial") | E7: =COUNTIF('Incident Response'!D4:D13,"Non-Compliant") | F7: =COUNTIF('Incident Response'!D4:D13,"N/A") | G7: =IF((B7-F7)=0,"N/A",ROUND(C7/(B7-F7)*100,1)&"%")
A8: Significant Incidents | B8: =COUNTA('Significant Incidents'!D4:D5) | C8: =COUNTIF('Significant Incidents'!D4:D5,"Compliant") | D8: =COUNTIF('Significant Incidents'!D4:D5,"Partial") | E8: =COUNTIF('Significant Incidents'!D4:D5,"Non-Compliant") | F8: =COUNTIF('Significant Incidents'!D4:D5,"N/A") | G8: =IF((B8-F8)=0,"N/A",ROUND(C8/(B8-F8)*100,1)&"%")
A9: Data Breach Notification | B9: =COUNTA('Data Breach Notification'!D4:D8) | C9: =COUNTIF('Data Breach Notification'!D4:D8,"Compliant") | D9: =COUNTIF('Data Breach Notification'!D4:D8,"Partial") | E9: =COUNTIF('Data Breach Notification'!D4:D8,"Non-Compliant") | F9: =COUNTIF('Data Breach Notification'!D4:D8,"N/A") | G9: =IF((B9-F9)=0,"N/A",ROUND(C9/(B9-F9)*100,1)&"%")
A10: Lessons Learned | B10: =COUNTA('Lessons Learned'!D4:D11) | C10: =COUNTIF('Lessons Learned'!D4:D11,"Compliant") | D10: =COUNTIF('Lessons Learned'!D4:D11,"Partial") | E10: =COUNTIF('Lessons Learned'!D4:D11,"Non-Compliant") | F10: =COUNTIF('Lessons Learned'!D4:D11,"N/A") | G10: =IF((B10-F10)=0,"N/A",ROUND(C10/(B10-F10)*100,1)&"%")
A11: Incident Response Testing | B11: =COUNTA('Incident Response Testing'!D4:D5) | C11: =COUNTIF('Incident Response Testing'!D4:D5,"Compliant") | D11: =COUNTIF('Incident Response Testing'!D4:D5,"Partial") | E11: =COUNTIF('Incident Response Testing'!D4:D5,"Non-Compliant") | F11: =COUNTIF('Incident Response Testing'!D4:D5,"N/A") | G11: =IF((B11-F11)=0,"N/A",ROUND(C11/(B11-F11)*100,1)&"%")
A12: TOTAL | B12: =SUM(B4:B11) | C12: =SUM(C4:C11) | D12: =SUM(D4:D11) | E12: =SUM(E4:E11) | F12: =SUM(F4:F11) | G12: =IF((B12-F12)=0,"N/A",ROUND(C12/(B12-F12)*100,1)&"%")
A14: COMPLIANCE BY STATUS
A15: Compliant | B15: =C12 | C15: =IF(B12=0,"",ROUND(B15/B12*100,1)&"%")
A16: Partial | B16: =D12 | C16: =IF(B12=0,"",ROUND(B16/B12*100,1)&"%")
A17: Non-Compliant | B17: =E12 | C17: =IF(B12=0,"",ROUND(B17/B12*100,1)&"%")
A18: N/A | B18: =F12 | C18: =IF(B12=0,"",ROUND(B18/B12*100,1)&"%")
A20: TOP GAPS (Manual Entry)
A21: Priority | B21: Domain | C21: Requirement | D21: Owner | E21: Due Date | F21: Status
A33: COMPLIANCE TREND (Manual Entry)
A34: Assessment Date | B34: Overall % | C34: Compliant | D34: Gaps | E34: Assessor | F34: Notes

Sheet Incident Reporting
A1: Incident Reporting — Compliance Checklist
A2: ISO/IEC 27001:2022 — Controls A.5.24-28: Incident Management
A3: Req # | B3: Section | C3: Requirement | D3: Status | E3: Evidence | F3: Owner | G3: Due Date | H3: Notes
A4: A.5.24-28-01 | B4: Employees And Third-Party Users | C4: All employees and third-party users shall report security events immediately upon discovery to the information security management team through the designated reporting channels:.
A5: A.5.24-28-02 | B5: Reporting Channels | C5: Reporting channels shall be communicated during onboarding and annual awareness training, and published on the organisation intranet.
A6: A.5.24-28-03 | B6: Include, Where Known | C6: Reports shall include, where known:.
A7: A.5.24-28-04 | B7: Not Attempt To Investigate Or Resolve | C7: Employees shall not attempt to investigate or resolve suspected incidents themselves. Preservation of evidence takes priority over curiosity.

Sheet Event Assessment and Triage
A1: Event Assessment and Triage — Compliance Checklist
A2: ISO/IEC 27001:2022 — Controls A.5.24-28: Incident Management
A3: Req # | B3: Section | C3: Requirement | D3: Status | E3: Evidence | F3: Owner | G3: Due Date | H3: Notes
A4: A.5.24-28-05 | B4: The Information Security Management Team | C4: The information security management team shall assess all reported security events to determine whether they constitute a security incident.
A5: A.5.24-28-06 | B5: Consider | C5: Assessment shall consider:.
A6: A.5.24-28-07 | B6: Events That Do Not Meet The | C6: Events that do not meet the threshold for an incident shall be logged, and trends shall be monitored.
A7: A.5.24-28-08 | B7: Reported Security Events And Confirmed | C7: All reported security events and confirmed incidents shall be recorded in the incident register with the following minimum fields:.

Sheet Incident Classification
A1: Incident Classification — Compliance Checklist
A2: ISO/IEC 27001:2022 — Controls A.5.24-28: Incident Management
A3: Req # | B3: Section | C3: Requirement | D3: Status | E3: Evidence | F3: Owner | G3: Due Date | H3: Notes
A4: A.5.24-28-09 | B4: Confirmed Incidents | C4: Confirmed incidents shall be classified by severity to determine response priority, escalation, and communication requirements:.

Sheet Incident Response
A1: Incident Response — Compliance Checklist
A2: ISO/IEC 27001:2022 — Controls A.5.24-28: Incident Management
A3: Req # | B3: Section | C3: Requirement | D3: Status | E3: Evidence | F3: Owner | G3: Due Date | H3: Notes
A4: A.5.24-28-10 | B4: Be Managed Through The Following Phases | C4: Incidents shall be managed through the following phases, aligned with NIST SP 800-61:.
A5: A.5.24-28-11 | B5: Containment — Limit The Impact And | C5: Containment — Limit the impact and prevent further damage. Short-term containment actions (e.g., isolating affected systems, disabling compromised accounts) shall be taken immediately. Long-term containment strategies shall be planned where eradication cannot be immediate.
A6: A.5.24-28-12 | B6: Recovery — Restore Systems And Services | C6: Recovery — Restore systems and services to normal operations. Recovery shall be verified through testing before returning systems to production. Monitoring shall be enhanced during the recovery period to detect recurrence.
A7: A.5.24-28-13 | B7: Incident Response Actions | C7: All incident response actions shall be documented with timestamps, actions taken, and personnel involved.
A8: A.5.24-28-14 | B8: The Following Roles | C8: The following roles shall be assigned within the incident response capability:.
A9: A.5.24-28-15 | B9: Role Assignments | C9: Role assignments shall be documented, communicated to all team members, and reviewed annually. Deputies shall be assigned for each role to ensure availability.
A10: A.5.24-28-16 | B10: The Incident Response Team Leader | C10: The incident response team leader shall escalate incidents to senior management when:.
A11: A.5.24-28-17 | B11: Incident Information | C11: Incident information shall be shared on a strict need-to-know basis. Communication during an active incident shall be coordinated through the incident response team leader.
A12: A.5.24-28-18 | B12: Internal Status Updates | C12: Internal status updates shall be provided at regular intervals for Critical and High incidents.
A13: A.5.24-28-19 | B13: External Communication (Media, | C13: External communication (media, customers, partners) shall be approved by senior management and reviewed by legal counsel before release.

Sheet Significant Incidents
A1: Significant Incidents — Compliance Checklist
A2: ISO/IEC 27001:2022 — Controls A.5.24-28: Incident Management
A3: Req # | B3: Section | C3: Requirement | D3: Status | E3: Evidence | F3: Owner | G3: Due Date | H3: Notes
A4: A.5.24-28-20 | B4: In All Instances Where A Situation | C4: In all instances where a situation may lead to an external investigation or legal proceedings, specialist external resources shall be engaged.
A5: A.5.24-28-21 | B5: At The Earliest Opportunity, All Work | C5: At the earliest opportunity, all work on, access to, modification of, or tampering with affected systems, documents, locations, files, databases, applications, or other in-scope entities shall stop. The only exceptions are the preservation of life, health, and safety, or the bare minimum actions required to triage and make safe.

Sheet Data Breach Notification
A1: Data Breach Notification — Compliance Checklist
A2: ISO/IEC 27001:2022 — Controls A.5.24-28: Incident Management
A3: Req # | B3: Section | C3: Requirement | D3: Status | E3: Evidence | F3: Owner | G3: Due Date | H3: Notes
A4: A.5.24-28-22 | B4: The Organisation | C4: Where both nFADP and GDPR apply, the organisation shall meet the stricter timeline (72 hours).
A5: A.5.24-28-23 | B5: Breach Notifications To Supervisory | C5: Breach notifications to supervisory authorities shall include, at minimum:.
A6: A.5.24-28-24 | B6: Be Provided In Phases Without Undue | C6: Where full information is not available at the time of notification, it shall be provided in phases without undue delay.
A7: A.5.24-28-25 | B7: Not All Security Incidents Involving | C7: Not all security incidents involving personal data require notification. The incident response team shall assess:.
A8: A.5.24-28-26 | B8: The Assessment And Decision (Including | C8: The assessment and decision (including the rationale for not notifying, if applicable) shall be documented.

Sheet Lessons Learned
A1: Lessons Learned — Compliance Checklist
A2: ISO/IEC 27001:2022 — Controls A.5.24-28: Incident Management
A3: Req # | B3: Section | C3: Requirement | D3: Status | E3: Evidence | F3: Owner | G3: Due Date | H3: Notes
A4: A.5.24-28-27 | B4: A Post-Incident Review | C4: A post-incident review shall be conducted for all Critical and High severity incidents, and optionally for Medium incidents where useful lessons may be derived.
A5: A.5.24-28-28 | B5: The Review | C5: The review shall be held within 5 business days of incident resolution, while details are still fresh. The review shall include all personnel who contributed to the response.
A6: A.5.24-28-29 | B6: The Review | C6: The review shall document:.
A7: A.5.24-28-30 | B7: Action Items | C7: Action items shall be tracked to completion.
A8: A.5.24-28-31 | B8: Lessons Learned | C8: Lessons learned shall be communicated to relevant personnel.
A9: A.5.24-28-32 | B9: The Incident Response Plan | C9: The incident response plan shall be updated where findings indicate gaps.
A10: A.5.24-28-33 | B10: Trends Across Incidents | C10: Trends across incidents shall be reviewed quarterly to identify systemic issues.
A11: A.5.24-28-34 | B11: Be Conducted In A Blame-Free Manner | C11: Reviews shall be conducted in a blame-free manner, focusing on system and process improvement rather than individual fault.

Sheet Incident Response Testing
A1: Incident Response Testing — Compliance Checklist
A2: ISO/IEC 27001:2022 — Controls A.5.24-28: Incident Management
A3: Req # | B3: Section | C3: Requirement | D3: Status | E3: Evidence | F3: Owner | G3: Due Date | H3: Notes
A4: A.5.24-28-35 | B4: The Incident Response Plan | C4: The incident response plan shall be tested at least annually through tabletop exercises or simulations to verify that:.
A5: A.5.24-28-36 | B5: Test Results And Improvements | C5: Test results and improvements shall be documented, including participants, scenario details, observed gaps, and corrective actions with owners and deadlines.
