Workbook

Sheet Executive Summary
A1: ISMS-OP-CHK-A.5.5-6 — Contact with Authorities and Special Interest Groups Compliance Checklist
A3: DOCUMENT INFORMATION
A4: Document ID | B4: ISMS-OP-CHK-A.5.5-6
A5: Source Policy | B5: ISMS-OP-POL-A.5.5-6
A6: ISO Controls | B6: Contact with Authorities and Special Interest Groups
A7: Generated | B7: 30.09.2026
A8: Prepared By
A9: Organisation
A10: Review Cycle | B10: Annual
A12: OVERALL COMPLIANCE STATUS
A13: Overall Compliance | B13: ='Dashboard'!G12
A14: Status | B14: =IF(Dashboard!H12>0,"INCOMPLETE",IF(Dashboard!G12="N/A","NOT ASSESSED",IF(ISNUMBER(VALUE(SUBSTITUTE(Dashboard!G12,"%",""))),IF(VALUE(SUBSTITUTE(Dashboard!G12,"%",""))>=90,"GREEN",IF(VALUE(SUBSTITUTE(Dashboard!G12,"%",""))>=70,"AMBER","RED")),"NOT ASSESSED")))
A16: KEY METRICS
A17: Total Requirements | B17: ='Dashboard'!B12
A18: Compliant | B18: ='Dashboard'!C12
A19: Partial | B19: ='Dashboard'!D12
A20: Non-Compliant | B20: ='Dashboard'!E12
A21: Not Applicable | B21: ='Dashboard'!F12
A22: Unanswered | B22: ='Dashboard'!H12
A23: Owner Coverage | B23: =IF(Dashboard!B12=0,"N/A",ROUND((COUNTA('Authority Contact Register'!F4:F10)+COUNTA('Mandatory Notifications'!F4:F8)+COUNTA('Customer and Stakeholder Comms'!F4:F4)+COUNTA('Authorised Spokespersons'!F4:F9)+COUNTA('Special Interest Group'!F4:F6)+COUNTA('Information Sharing Protocols'!F4:F8)+COUNTA('Testing and Exercising'!F4:F5)+COUNTA('Compliance Measurement'!F4:F6))/Dashboard!B12*100,0)&"%")
A25: DOMAIN STATUS SUMMARY
A26: Domain | B26: Compliance % | C26: Compliant | D26: Gaps | E26: Status
A27: Authority Contact Register | B27: ='Dashboard'!G4 | C27: ='Dashboard'!C4 | D27: ='Dashboard'!E4 | E27: =IF(Dashboard!H4>0,"INCOMPLETE",IF(Dashboard!G4="N/A","--",IF(ISNUMBER(VALUE(SUBSTITUTE(Dashboard!G4,"%",""))),IF(VALUE(SUBSTITUTE(Dashboard!G4,"%",""))>=90,"PASS",IF(VALUE(SUBSTITUTE(Dashboard!G4,"%",""))>=70,"REVIEW","FAIL")),"--")))
A28: Mandatory Notifications | B28: ='Dashboard'!G5 | C28: ='Dashboard'!C5 | D28: ='Dashboard'!E5 | E28: =IF(Dashboard!H5>0,"INCOMPLETE",IF(Dashboard!G5="N/A","--",IF(ISNUMBER(VALUE(SUBSTITUTE(Dashboard!G5,"%",""))),IF(VALUE(SUBSTITUTE(Dashboard!G5,"%",""))>=90,"PASS",IF(VALUE(SUBSTITUTE(Dashboard!G5,"%",""))>=70,"REVIEW","FAIL")),"--")))
A29: Customer and Stakeholder Comms | B29: ='Dashboard'!G6 | C29: ='Dashboard'!C6 | D29: ='Dashboard'!E6 | E29: =IF(Dashboard!H6>0,"INCOMPLETE",IF(Dashboard!G6="N/A","--",IF(ISNUMBER(VALUE(SUBSTITUTE(Dashboard!G6,"%",""))),IF(VALUE(SUBSTITUTE(Dashboard!G6,"%",""))>=90,"PASS",IF(VALUE(SUBSTITUTE(Dashboard!G6,"%",""))>=70,"REVIEW","FAIL")),"--")))
A30: Authorised Spokespersons | B30: ='Dashboard'!G7 | C30: ='Dashboard'!C7 | D30: ='Dashboard'!E7 | E30: =IF(Dashboard!H7>0,"INCOMPLETE",IF(Dashboard!G7="N/A","--",IF(ISNUMBER(VALUE(SUBSTITUTE(Dashboard!G7,"%",""))),IF(VALUE(SUBSTITUTE(Dashboard!G7,"%",""))>=90,"PASS",IF(VALUE(SUBSTITUTE(Dashboard!G7,"%",""))>=70,"REVIEW","FAIL")),"--")))
A31: Special Interest Group | B31: ='Dashboard'!G8 | C31: ='Dashboard'!C8 | D31: ='Dashboard'!E8 | E31: =IF(Dashboard!H8>0,"INCOMPLETE",IF(Dashboard!G8="N/A","--",IF(ISNUMBER(VALUE(SUBSTITUTE(Dashboard!G8,"%",""))),IF(VALUE(SUBSTITUTE(Dashboard!G8,"%",""))>=90,"PASS",IF(VALUE(SUBSTITUTE(Dashboard!G8,"%",""))>=70,"REVIEW","FAIL")),"--")))
A32: Information Sharing Protocols | B32: ='Dashboard'!G9 | C32: ='Dashboard'!C9 | D32: ='Dashboard'!E9 | E32: =IF(Dashboard!H9>0,"INCOMPLETE",IF(Dashboard!G9="N/A","--",IF(ISNUMBER(VALUE(SUBSTITUTE(Dashboard!G9,"%",""))),IF(VALUE(SUBSTITUTE(Dashboard!G9,"%",""))>=90,"PASS",IF(VALUE(SUBSTITUTE(Dashboard!G9,"%",""))>=70,"REVIEW","FAIL")),"--")))
A33: Testing and Exercising | B33: ='Dashboard'!G10 | C33: ='Dashboard'!C10 | D33: ='Dashboard'!E10 | E33: =IF(Dashboard!H10>0,"INCOMPLETE",IF(Dashboard!G10="N/A","--",IF(ISNUMBER(VALUE(SUBSTITUTE(Dashboard!G10,"%",""))),IF(VALUE(SUBSTITUTE(Dashboard!G10,"%",""))>=90,"PASS",IF(VALUE(SUBSTITUTE(Dashboard!G10,"%",""))>=70,"REVIEW","FAIL")),"--")))
A34: Compliance Measurement | B34: ='Dashboard'!G11 | C34: ='Dashboard'!C11 | D34: ='Dashboard'!E11 | E34: =IF(Dashboard!H11>0,"INCOMPLETE",IF(Dashboard!G11="N/A","--",IF(ISNUMBER(VALUE(SUBSTITUTE(Dashboard!G11,"%",""))),IF(VALUE(SUBSTITUTE(Dashboard!G11,"%",""))>=90,"PASS",IF(VALUE(SUBSTITUTE(Dashboard!G11,"%",""))>=70,"REVIEW","FAIL")),"--")))
A36: CRITICAL ISSUES
A37: # | B37: Issue Description | C37: Domain | D37: Owner | E37: Due Date
A38: 1
A39: 2
A40: 3
A41: 4
A42: 5
A44: MANAGEMENT COMMENTARY
A45: [Enter management commentary on contact with authorities and special interest groups posture]
A49: APPROVAL
...

Sheet Dashboard
A1: Contact with Authorities and Special Interest Groups — Compliance Dashboard
A3: Domain | B3: Total Reqs | C3: Compliant | D3: Partial | E3: Non-Compliant | F3: N/A | G3: Compliance % | H3: Unassessed
A4: Authority Contact Register | B4: =COUNTA('Authority Contact Register'!A4:A10) | C4: =COUNTIF('Authority Contact Register'!D4:D10,"Compliant") | D4: =COUNTIF('Authority Contact Register'!D4:D10,"Partial") | E4: =COUNTIF('Authority Contact Register'!D4:D10,"Non-Compliant") | F4: =COUNTIF('Authority Contact Register'!D4:D10,"N/A") | G4: =IF((B4-F4)=0,"N/A",ROUND(C4/(B4-F4)*100,1)&"%") | H4: =B4-(C4+D4+E4+F4)
A5: Mandatory Notifications | B5: =COUNTA('Mandatory Notifications'!A4:A8) | C5: =COUNTIF('Mandatory Notifications'!D4:D8,"Compliant") | D5: =COUNTIF('Mandatory Notifications'!D4:D8,"Partial") | E5: =COUNTIF('Mandatory Notifications'!D4:D8,"Non-Compliant") | F5: =COUNTIF('Mandatory Notifications'!D4:D8,"N/A") | G5: =IF((B5-F5)=0,"N/A",ROUND(C5/(B5-F5)*100,1)&"%") | H5: =B5-(C5+D5+E5+F5)
A6: Customer and Stakeholder Comms | B6: =COUNTA('Customer and Stakeholder Comms'!A4:A4) | C6: =COUNTIF('Customer and Stakeholder Comms'!D4:D4,"Compliant") | D6: =COUNTIF('Customer and Stakeholder Comms'!D4:D4,"Partial") | E6: =COUNTIF('Customer and Stakeholder Comms'!D4:D4,"Non-Compliant") | F6: =COUNTIF('Customer and Stakeholder Comms'!D4:D4,"N/A") | G6: =IF((B6-F6)=0,"N/A",ROUND(C6/(B6-F6)*100,1)&"%") | H6: =B6-(C6+D6+E6+F6)
A7: Authorised Spokespersons | B7: =COUNTA('Authorised Spokespersons'!A4:A9) | C7: =COUNTIF('Authorised Spokespersons'!D4:D9,"Compliant") | D7: =COUNTIF('Authorised Spokespersons'!D4:D9,"Partial") | E7: =COUNTIF('Authorised Spokespersons'!D4:D9,"Non-Compliant") | F7: =COUNTIF('Authorised Spokespersons'!D4:D9,"N/A") | G7: =IF((B7-F7)=0,"N/A",ROUND(C7/(B7-F7)*100,1)&"%") | H7: =B7-(C7+D7+E7+F7)
A8: Special Interest Group | B8: =COUNTA('Special Interest Group'!A4:A6) | C8: =COUNTIF('Special Interest Group'!D4:D6,"Compliant") | D8: =COUNTIF('Special Interest Group'!D4:D6,"Partial") | E8: =COUNTIF('Special Interest Group'!D4:D6,"Non-Compliant") | F8: =COUNTIF('Special Interest Group'!D4:D6,"N/A") | G8: =IF((B8-F8)=0,"N/A",ROUND(C8/(B8-F8)*100,1)&"%") | H8: =B8-(C8+D8+E8+F8)
A9: Information Sharing Protocols | B9: =COUNTA('Information Sharing Protocols'!A4:A8) | C9: =COUNTIF('Information Sharing Protocols'!D4:D8,"Compliant") | D9: =COUNTIF('Information Sharing Protocols'!D4:D8,"Partial") | E9: =COUNTIF('Information Sharing Protocols'!D4:D8,"Non-Compliant") | F9: =COUNTIF('Information Sharing Protocols'!D4:D8,"N/A") | G9: =IF((B9-F9)=0,"N/A",ROUND(C9/(B9-F9)*100,1)&"%") | H9: =B9-(C9+D9+E9+F9)
A10: Testing and Exercising | B10: =COUNTA('Testing and Exercising'!A4:A5) | C10: =COUNTIF('Testing and Exercising'!D4:D5,"Compliant") | D10: =COUNTIF('Testing and Exercising'!D4:D5,"Partial") | E10: =COUNTIF('Testing and Exercising'!D4:D5,"Non-Compliant") | F10: =COUNTIF('Testing and Exercising'!D4:D5,"N/A") | G10: =IF((B10-F10)=0,"N/A",ROUND(C10/(B10-F10)*100,1)&"%") | H10: =B10-(C10+D10+E10+F10)
A11: Compliance Measurement | B11: =COUNTA('Compliance Measurement'!A4:A6) | C11: =COUNTIF('Compliance Measurement'!D4:D6,"Compliant") | D11: =COUNTIF('Compliance Measurement'!D4:D6,"Partial") | E11: =COUNTIF('Compliance Measurement'!D4:D6,"Non-Compliant") | F11: =COUNTIF('Compliance Measurement'!D4:D6,"N/A") | G11: =IF((B11-F11)=0,"N/A",ROUND(C11/(B11-F11)*100,1)&"%") | H11: =B11-(C11+D11+E11+F11)
A12: TOTAL | B12: =SUM(B4:B11) | C12: =SUM(C4:C11) | D12: =SUM(D4:D11) | E12: =SUM(E4:E11) | F12: =SUM(F4:F11) | G12: =IF((B12-F12)=0,"N/A",ROUND(C12/(B12-F12)*100,1)&"%") | H12: =SUM(H4:H11)
A14: COMPLIANCE BY STATUS
A15: Compliant | B15: =C12 | C15: =IF(B12=0,"",ROUND(B15/B12*100,1)&"%")
A16: Partial | B16: =D12 | C16: =IF(B12=0,"",ROUND(B16/B12*100,1)&"%")
A17: Non-Compliant | B17: =E12 | C17: =IF(B12=0,"",ROUND(B17/B12*100,1)&"%")
A18: N/A | B18: =F12 | C18: =IF(B12=0,"",ROUND(B18/B12*100,1)&"%")
A20: TOP GAPS (Manual Entry)
A21: Priority | B21: Domain | C21: Requirement | D21: Owner | E21: Due Date | F21: Status
A33: COMPLIANCE TREND (Manual Entry)
A34: Assessment Date | B34: Overall % | C34: Compliant | D34: Gaps | E34: Assessor | F34: Notes

Sheet Authority Contact Register
A1: Authority Contact Register — Compliance Checklist
A2: ISO/IEC 27001:2022 — Controls A.5.5-6: Contact with Authorities and Special Interest Groups
A3: Req # | B3: Section | C3: Requirement | D3: Status | E3: Evidence | F3: Owner | G3: Due Date | H3: Notes
A4: A.5.5-6-01 | B4: [Organisation] | C4: [Organisation] shall maintain active, verified contacts with the following authorities:.
A5: A.5.5-6-02 | B5: The Authority Contact Register | C5: The authority contact register shall be:.
A6: A.5.5-6-03 | B6: Verified Quarterly — The Ciso Or | C6: Verified quarterly — the CISO or delegate shall confirm that all contact details remain current, contact persons are still in their roles, and communication channels are operational.
A7: A.5.5-6-04 | B7: Available Offline — A Printed Or | C7: Available offline — a printed or locally stored copy of critical contacts (NCSC, FDPIC, cantonal police, emergency services) shall be maintained for use during incidents when primary systems may be unavailable.
A8: A.5.5-6-05 | B8: Access-Restricted To Authorised | C8: Access-restricted to authorised personnel only. The register may contain personal contact details of authority liaison officers and shall be classified as Internal.
A9: A.5.5-6-06 | B9: Changes To The Authority Contact | C9: Changes to the authority contact register shall follow documented change control:.
A10: A.5.5-6-07 | B10: Version Control*: Contact Registry | C10: Version control*: Contact registry shall use date-based versioning (YYYY-MM-DD format) and retain all historical versions for audit trail.

Sheet Mandatory Notifications
A1: Mandatory Notifications — Compliance Checklist
A2: ISO/IEC 27001:2022 — Controls A.5.5-6: Contact with Authorities and Special Interest Groups
A3: Req # | B3: Section | C3: Requirement | D3: Status | E3: Evidence | F3: Owner | G3: Due Date | H3: Notes
A4: A.5.5-6-08 | B4: Nfadp Art. 24 Does Not Stipulate | C4: nFADP Art. 24 does not stipulate a fixed notification deadline but requires reporting 'as soon as possible'. The FDPIC has published guidelines clarifying that this means without undue delay once the controller becomes aware of the breach. [Organisation] shall target notification within 72 hours as an internal standard to demonstrate diligence, even though Swiss law does not mandate this specific timeframe.
A5: A.5.5-6-09 | B5: Swiss Isg (Information Security Act): | C5: Swiss ISG (Information Security Act): Since 1 April 2025, operators of critical infrastructure must report cyberattacks to the NCSC within 24 hours of discovery. Failure to report may result in fines up to CHF 100'000 (penalties in force since 1 October 2025). [Organisation] shall assess whether it falls within the ISG's definition of critical infrastructure and comply accordingly.
A6: A.5.5-6-10 | B6: Fdpic Breach Reporting Portal: | C6: FDPIC breach reporting portal: Notifications shall be submitted via the FDPIC's dedicated portal at databreach.edoeb.admin.ch/report.
A7: A.5.5-6-11 | B7: Processor Obligations: Where | C7: Processor obligations: Where [Organisation] acts as a data processor, it shall notify the data controller as soon as possible of any data security breach, in addition to its own notification obligations.
A8: A.5.5-6-12 | B8: A Data Breach That Also Constitutes | C8: Where an event triggers multiple notification obligations (e.g., a data breach that also constitutes a cyber incident), each obligation shall be addressed independently but coordinated to ensure consistent messaging.

Sheet Customer and Stakeholder Comms
A1: Customer and Stakeholder Comms — Compliance Checklist
A2: ISO/IEC 27001:2022 — Controls A.5.5-6: Contact with Authorities and Special Interest Groups
A3: Req # | B3: Section | C3: Requirement | D3: Status | E3: Evidence | F3: Owner | G3: Due Date | H3: Notes
A4: A.5.5-6-13 | B4: Systems, Or Service Availability, | C4: When a security incident affects customer data, systems, or service availability, [Organisation] shall communicate with affected customers according to:.

Sheet Authorised Spokespersons
A1: Authorised Spokespersons — Compliance Checklist
A2: ISO/IEC 27001:2022 — Controls A.5.5-6: Contact with Authorities and Special Interest Groups
A3: Req # | B3: Section | C3: Requirement | D3: Status | E3: Evidence | F3: Owner | G3: Due Date | H3: Notes
A4: A.5.5-6-14 | B4: No Employee | C4: No employee shall contact authorities regarding [Organisation]'s security matters without prior authorisation from the CISO or Legal Counsel, except for immediate life-safety emergencies.
A5: A.5.5-6-15 | B5: Authority Communications | C5: All authority communications shall be documented — a record of date, time, authority contacted, contact person, subject, content summary, and any commitments made shall be maintained in the communication log.
A6: A.5.5-6-16 | B6: Legal Counsel | C6: Legal Counsel shall review all communications involving potential legal liability, regulatory filings, or responses to formal authority requests before submission.
A7: A.5.5-6-17 | B7: Classified Or Confidential Information | C7: Classified or confidential information requires explicit CISO and Legal Counsel approval before disclosure to any authority, even where a notification obligation exists. Disclosure shall be limited to the minimum information necessary to fulfil the obligation.
A8: A.5.5-6-18 | B8: Verbal Communications With Authorities | C8: Verbal communications with authorities shall be followed up with a written summary within 24 hours, stored in the communication log.
A9: A.5.5-6-19 | B9: Route To The Appropriate Spokesperson — | C9: Route to the appropriate spokesperson — the recipient shall forward the inquiry to the CISO and Legal Counsel without providing any substantive response.

Sheet Special Interest Group
A1: Special Interest Group — Compliance Checklist
A2: ISO/IEC 27001:2022 — Controls A.5.5-6: Contact with Authorities and Special Interest Groups
A3: Req # | B3: Section | C3: Requirement | D3: Status | E3: Evidence | F3: Owner | G3: Due Date | H3: Notes
A4: A.5.5-6-20 | B4: [Organisation] | C4: [Organisation] shall maintain active participation in relevant security communities to receive threat intelligence, access best practices, and contribute to collective security improvement.
A5: A.5.5-6-21 | B5: The Ciso | C5: The CISO shall determine which groups are relevant based on [Organisation]'s industry sector, technology stack, threat landscape, and regulatory environment. The selection shall be reviewed annually.
A6: A.5.5-6-22 | B6: The Ciso | C6: The CISO shall maintain a register of all special interest group memberships and subscriptions, recording:.

Sheet Information Sharing Protocols
A1: Information Sharing Protocols — Compliance Checklist
A2: ISO/IEC 27001:2022 — Controls A.5.5-6: Contact with Authorities and Special Interest Groups
A3: Req # | B3: Section | C3: Requirement | D3: Status | E3: Evidence | F3: Owner | G3: Due Date | H3: Notes
A4: A.5.5-6-23 | B4: Information Sharing With External | C4: All information sharing with external parties — authorities, special interest groups, and peer organisations — shall use the Traffic Light Protocol (TLP) version 2.0, as defined by FIRST, to classify and control distribution.
A5: A.5.5-6-24 | B5: Pre-Disclosure Review — All Information | C5: Pre-disclosure review — All information proposed for external sharing shall be reviewed by the CISO (and Legal Counsel where the information involves personal data, contractual obligations, or potential legal liability) to confirm:.
A6: A.5.5-6-25 | B6: Anonymisation — Incident Data Shared | C6: Anonymisation — Incident data shared with external groups shall be anonymised to remove identifying details of [Organisation], its clients, and affected individuals, unless disclosure is required by law or authorised by the data subjects.
A7: A.5.5-6-26 | B7: Receiving Intelligence — Information | C7: Receiving intelligence — Information received from external groups shall be handled according to its TLP classification. TLP:RED and TLP:AMBER information shall not be forwarded outside the designated recipients without the originator's explicit consent.
A8: A.5.5-6-27 | B8: Record Keeping — A Log Of | C8: Record keeping — A log of all information shared externally (excluding routine advisory receipt) shall be maintained, recording: date, recipient group, TLP classification, subject, and approving authority.

Sheet Testing and Exercising
A1: Testing and Exercising — Compliance Checklist
A2: ISO/IEC 27001:2022 — Controls A.5.5-6: Contact with Authorities and Special Interest Groups
A3: Req # | B3: Section | C3: Requirement | D3: Status | E3: Evidence | F3: Owner | G3: Due Date | H3: Notes
A4: A.5.5-6-28 | B4: Beyond Quarterly Contact Verification, | C4: Beyond quarterly contact verification, [Organisation] shall conduct:.
A5: A.5.5-6-29 | B5: Annual Tabletop Exercise | C5: Annual tabletop exercise shall include:.

Sheet Compliance Measurement
A1: Compliance Measurement — Compliance Checklist
A2: ISO/IEC 27001:2022 — Controls A.5.5-6: Contact with Authorities and Special Interest Groups
A3: Req # | B3: Section | C3: Requirement | D3: Status | E3: Evidence | F3: Owner | G3: Due Date | H3: Notes
A4: A.5.5-6-30 | B4: The Following Metrics | C4: The following metrics shall be tracked and reported to the CISO quarterly:.
A5: A.5.5-6-31 | B5: In Addition To Governance Metrics, The | C5: In addition to governance metrics, the following operational metrics shall be tracked:.
A6: A.5.5-6-32 | B6: Metrics Breaching Red Thresholds | C6: Metrics breaching red thresholds shall be escalated to the CISO for immediate attention and reported at the next Management Review.
