Workbook

Sheet Executive Summary
A1: ISMS-OP-CHK-A.5.17 — Authentication Information Compliance Checklist
A3: DOCUMENT INFORMATION
A4: Document ID | B4: ISMS-OP-CHK-A.5.17
A5: Source Policy | B5: ISMS-OP-POL-A.5.17
A6: ISO Controls | B6: Authentication Information
A7: Generated | B7: 30.09.2026
A8: Prepared By
A9: Organisation
A10: Review Cycle | B10: Annual
A12: OVERALL COMPLIANCE STATUS
A13: Overall Compliance | B13: ='Dashboard'!G10
A14: Status | B14: =IF(Dashboard!H10>0,"INCOMPLETE",IF(Dashboard!G10="N/A","NOT ASSESSED",IF(ISNUMBER(VALUE(SUBSTITUTE(Dashboard!G10,"%",""))),IF(VALUE(SUBSTITUTE(Dashboard!G10,"%",""))>=90,"GREEN",IF(VALUE(SUBSTITUTE(Dashboard!G10,"%",""))>=70,"AMBER","RED")),"NOT ASSESSED")))
A16: KEY METRICS
A17: Total Requirements | B17: ='Dashboard'!B10
A18: Compliant | B18: ='Dashboard'!C10
A19: Partial | B19: ='Dashboard'!D10
A20: Non-Compliant | B20: ='Dashboard'!E10
A21: Not Applicable | B21: ='Dashboard'!F10
A22: Unanswered | B22: ='Dashboard'!H10
A23: Owner Coverage | B23: =IF(Dashboard!B10=0,"N/A",ROUND((COUNTA('Authentication Info Allocation'!F4:F13)+COUNTA('Password Requirements'!F4:F8)+COUNTA('Multi-Factor Authentication'!F4:F16)+COUNTA('Authentication Info Protection'!F4:F13)+COUNTA('Password Reset and Recovery'!F4:F16)+COUNTA('Compliance Measurement'!F4:F5))/Dashboard!B10*100,0)&"%")
A25: DOMAIN STATUS SUMMARY
A26: Domain | B26: Compliance % | C26: Compliant | D26: Gaps | E26: Status
A27: Authentication Info Allocation | B27: ='Dashboard'!G4 | C27: ='Dashboard'!C4 | D27: ='Dashboard'!E4 | E27: =IF(Dashboard!H4>0,"INCOMPLETE",IF(Dashboard!G4="N/A","--",IF(ISNUMBER(VALUE(SUBSTITUTE(Dashboard!G4,"%",""))),IF(VALUE(SUBSTITUTE(Dashboard!G4,"%",""))>=90,"PASS",IF(VALUE(SUBSTITUTE(Dashboard!G4,"%",""))>=70,"REVIEW","FAIL")),"--")))
A28: Password Requirements | B28: ='Dashboard'!G5 | C28: ='Dashboard'!C5 | D28: ='Dashboard'!E5 | E28: =IF(Dashboard!H5>0,"INCOMPLETE",IF(Dashboard!G5="N/A","--",IF(ISNUMBER(VALUE(SUBSTITUTE(Dashboard!G5,"%",""))),IF(VALUE(SUBSTITUTE(Dashboard!G5,"%",""))>=90,"PASS",IF(VALUE(SUBSTITUTE(Dashboard!G5,"%",""))>=70,"REVIEW","FAIL")),"--")))
A29: Multi-Factor Authentication | B29: ='Dashboard'!G6 | C29: ='Dashboard'!C6 | D29: ='Dashboard'!E6 | E29: =IF(Dashboard!H6>0,"INCOMPLETE",IF(Dashboard!G6="N/A","--",IF(ISNUMBER(VALUE(SUBSTITUTE(Dashboard!G6,"%",""))),IF(VALUE(SUBSTITUTE(Dashboard!G6,"%",""))>=90,"PASS",IF(VALUE(SUBSTITUTE(Dashboard!G6,"%",""))>=70,"REVIEW","FAIL")),"--")))
A30: Authentication Info Protection | B30: ='Dashboard'!G7 | C30: ='Dashboard'!C7 | D30: ='Dashboard'!E7 | E30: =IF(Dashboard!H7>0,"INCOMPLETE",IF(Dashboard!G7="N/A","--",IF(ISNUMBER(VALUE(SUBSTITUTE(Dashboard!G7,"%",""))),IF(VALUE(SUBSTITUTE(Dashboard!G7,"%",""))>=90,"PASS",IF(VALUE(SUBSTITUTE(Dashboard!G7,"%",""))>=70,"REVIEW","FAIL")),"--")))
A31: Password Reset and Recovery | B31: ='Dashboard'!G8 | C31: ='Dashboard'!C8 | D31: ='Dashboard'!E8 | E31: =IF(Dashboard!H8>0,"INCOMPLETE",IF(Dashboard!G8="N/A","--",IF(ISNUMBER(VALUE(SUBSTITUTE(Dashboard!G8,"%",""))),IF(VALUE(SUBSTITUTE(Dashboard!G8,"%",""))>=90,"PASS",IF(VALUE(SUBSTITUTE(Dashboard!G8,"%",""))>=70,"REVIEW","FAIL")),"--")))
A32: Compliance Measurement | B32: ='Dashboard'!G9 | C32: ='Dashboard'!C9 | D32: ='Dashboard'!E9 | E32: =IF(Dashboard!H9>0,"INCOMPLETE",IF(Dashboard!G9="N/A","--",IF(ISNUMBER(VALUE(SUBSTITUTE(Dashboard!G9,"%",""))),IF(VALUE(SUBSTITUTE(Dashboard!G9,"%",""))>=90,"PASS",IF(VALUE(SUBSTITUTE(Dashboard!G9,"%",""))>=70,"REVIEW","FAIL")),"--")))
A34: CRITICAL ISSUES
A35: # | B35: Issue Description | C35: Domain | D35: Owner | E35: Due Date
A36: 1
A37: 2
A38: 3
A39: 4
A40: 5
A42: MANAGEMENT COMMENTARY
A43: [Enter management commentary on authentication information posture]
A47: APPROVAL
A48: Assessed By
A49: Name:
...

Sheet Dashboard
A1: Authentication Information — Compliance Dashboard
A3: Domain | B3: Total Reqs | C3: Compliant | D3: Partial | E3: Non-Compliant | F3: N/A | G3: Compliance % | H3: Unassessed
A4: Authentication Info Allocation | B4: =COUNTA('Authentication Info Allocation'!A4:A13) | C4: =COUNTIF('Authentication Info Allocation'!D4:D13,"Compliant") | D4: =COUNTIF('Authentication Info Allocation'!D4:D13,"Partial") | E4: =COUNTIF('Authentication Info Allocation'!D4:D13,"Non-Compliant") | F4: =COUNTIF('Authentication Info Allocation'!D4:D13,"N/A") | G4: =IF((B4-F4)=0,"N/A",ROUND(C4/(B4-F4)*100,1)&"%") | H4: =B4-(C4+D4+E4+F4)
A5: Password Requirements | B5: =COUNTA('Password Requirements'!A4:A8) | C5: =COUNTIF('Password Requirements'!D4:D8,"Compliant") | D5: =COUNTIF('Password Requirements'!D4:D8,"Partial") | E5: =COUNTIF('Password Requirements'!D4:D8,"Non-Compliant") | F5: =COUNTIF('Password Requirements'!D4:D8,"N/A") | G5: =IF((B5-F5)=0,"N/A",ROUND(C5/(B5-F5)*100,1)&"%") | H5: =B5-(C5+D5+E5+F5)
A6: Multi-Factor Authentication | B6: =COUNTA('Multi-Factor Authentication'!A4:A16) | C6: =COUNTIF('Multi-Factor Authentication'!D4:D16,"Compliant") | D6: =COUNTIF('Multi-Factor Authentication'!D4:D16,"Partial") | E6: =COUNTIF('Multi-Factor Authentication'!D4:D16,"Non-Compliant") | F6: =COUNTIF('Multi-Factor Authentication'!D4:D16,"N/A") | G6: =IF((B6-F6)=0,"N/A",ROUND(C6/(B6-F6)*100,1)&"%") | H6: =B6-(C6+D6+E6+F6)
A7: Authentication Info Protection | B7: =COUNTA('Authentication Info Protection'!A4:A13) | C7: =COUNTIF('Authentication Info Protection'!D4:D13,"Compliant") | D7: =COUNTIF('Authentication Info Protection'!D4:D13,"Partial") | E7: =COUNTIF('Authentication Info Protection'!D4:D13,"Non-Compliant") | F7: =COUNTIF('Authentication Info Protection'!D4:D13,"N/A") | G7: =IF((B7-F7)=0,"N/A",ROUND(C7/(B7-F7)*100,1)&"%") | H7: =B7-(C7+D7+E7+F7)
A8: Password Reset and Recovery | B8: =COUNTA('Password Reset and Recovery'!A4:A16) | C8: =COUNTIF('Password Reset and Recovery'!D4:D16,"Compliant") | D8: =COUNTIF('Password Reset and Recovery'!D4:D16,"Partial") | E8: =COUNTIF('Password Reset and Recovery'!D4:D16,"Non-Compliant") | F8: =COUNTIF('Password Reset and Recovery'!D4:D16,"N/A") | G8: =IF((B8-F8)=0,"N/A",ROUND(C8/(B8-F8)*100,1)&"%") | H8: =B8-(C8+D8+E8+F8)
A9: Compliance Measurement | B9: =COUNTA('Compliance Measurement'!A4:A5) | C9: =COUNTIF('Compliance Measurement'!D4:D5,"Compliant") | D9: =COUNTIF('Compliance Measurement'!D4:D5,"Partial") | E9: =COUNTIF('Compliance Measurement'!D4:D5,"Non-Compliant") | F9: =COUNTIF('Compliance Measurement'!D4:D5,"N/A") | G9: =IF((B9-F9)=0,"N/A",ROUND(C9/(B9-F9)*100,1)&"%") | H9: =B9-(C9+D9+E9+F9)
A10: TOTAL | B10: =SUM(B4:B9) | C10: =SUM(C4:C9) | D10: =SUM(D4:D9) | E10: =SUM(E4:E9) | F10: =SUM(F4:F9) | G10: =IF((B10-F10)=0,"N/A",ROUND(C10/(B10-F10)*100,1)&"%") | H10: =SUM(H4:H9)
A12: COMPLIANCE BY STATUS
A13: Compliant | B13: =C10 | C13: =IF(B10=0,"",ROUND(B13/B10*100,1)&"%")
A14: Partial | B14: =D10 | C14: =IF(B10=0,"",ROUND(B14/B10*100,1)&"%")
A15: Non-Compliant | B15: =E10 | C15: =IF(B10=0,"",ROUND(B15/B10*100,1)&"%")
A16: N/A | B16: =F10 | C16: =IF(B10=0,"",ROUND(B16/B10*100,1)&"%")
A18: TOP GAPS (Manual Entry)
A19: Priority | B19: Domain | C19: Requirement | D19: Owner | E19: Due Date | F19: Status
A31: COMPLIANCE TREND (Manual Entry)
A32: Assessment Date | B32: Overall % | C32: Compliant | D32: Gaps | E32: Assessor | F32: Notes

Sheet Authentication Info Allocation
A1: Authentication Info Allocation — Compliance Checklist
A2: ISO/IEC 27001:2022 — Control A.5.17: Authentication Information
A3: Req # | B3: Section | C3: Requirement | D3: Status | E3: Evidence | F3: Owner | G3: Due Date | H3: Notes
A4: A.5.17-01 | B4: Before Issuing New Or Replacement | C4: Before issuing new or replacement authentication credentials, the identity of the requesting person shall be verified through at least one of the following methods:.
A5: A.5.17-02 | B5: The Verification Method Used | C5: The verification method used shall be documented for audit purposes.
A6: A.5.17-03 | B6: Authentication Information | C6: Authentication information shall be distributed through secure channels. Insecure methods such as unencrypted email or plain-text messaging shall not be used for credential distribution.
A7: A.5.17-04 | B7: Shall Have A Maximum | C7: Shall have a maximum validity of 24 hours.
A8: A.5.17-05 | B8: Shall Require Change On | C8: Shall require change on first use.
A9: A.5.17-06 | B9: Shall Be Generated With | C9: Shall be generated with sufficient randomness and length to resist guessing.
A10: A.5.17-07 | B10: Shall Be Invalidated After | C10: Shall be invalidated after successful use.
A11: A.5.17-08 | B11: Vendor-Supplied And Default Passwords | C11: Vendor-supplied and default passwords shall be changed immediately upon installation, before any system is connected to the production network.
A12: A.5.17-09 | B12: Default Accounts | C12: Default accounts shall be disabled or renamed where technically feasible.
A13: A.5.17-10 | B13: System Limitation), The Following | C13: Where default credentials cannot be changed (vendor firmware dependency, system limitation), the following compensating controls shall be applied:.

Sheet Password Requirements
A1: Password Requirements — Compliance Checklist
A2: ISO/IEC 27001:2022 — Control A.5.17: Authentication Information
A3: Req # | B3: Section | C3: Requirement | D3: Status | E3: Evidence | F3: Owner | G3: Due Date | H3: Notes
A4: A.5.17-11 | B4: Enforce The Following Password | C4: The organisation shall enforce the following password standards, aligned with NIST SP 800-63B-4:.
A5: A.5.17-12 | B5: Privileged Accounts (Administrator, Tier | C5: Privileged accounts (administrator, Tier 0/1 accounts) shall enforce:.
A6: A.5.17-13 | B6: Not | C6: Personnel shall not:.
A7: A.5.17-14 | B7: Store Passwords Using Approved One-Way | C7: Systems shall store passwords using approved one-way cryptographic hashing with unique per-password salt:.
A8: A.5.17-15 | B8: Password Databases | C8: Password databases shall be protected with encryption at rest and access restricted to authorised service accounts.

Sheet Multi-Factor Authentication
A1: Multi-Factor Authentication — Compliance Checklist
A2: ISO/IEC 27001:2022 — Control A.5.17: Authentication Information
A3: Req # | B3: Section | C3: Requirement | D3: Status | E3: Evidence | F3: Owner | G3: Due Date | H3: Notes
A4: A.5.17-16 | B4: Multi-Factor Authentication | C4: Multi-factor authentication shall be required for the following access types:.
A5: A.5.17-17 | B5: Acceptable Authentication Factors | C5: Acceptable authentication factors shall be drawn from at least two different categories:.
A6: A.5.17-18 | B6: Mfa Methods | C6: MFA methods shall be selected with preference for phishing resistance:.
A7: A.5.17-19 | B7: Sms-Based Otp | C7: SMS-based OTP shall be documented in the risk register with a migration plan to a stronger method. New system deployments shall not implement SMS-based MFA as the sole second factor.
A8: A.5.17-20 | B8: Plan And Execute Migration Toward | C8: The organisation shall plan and execute migration toward phishing-resistant authentication (FIDO2/WebAuthn passkeys) as the primary MFA method. FIDO2 uses public-key cryptography bound to the legitimate service origin, preventing credential phishing even if users are tricked by fraudulent sites.
A9: A.5.17-21 | B9: Backup Mfa Method: Users Are Encouraged | C9: Backup MFA method: Users are encouraged to register a backup MFA method (e.g., second hardware key stored securely, backup authenticator app). Privileged users shall register at least two independent MFA methods.
A10: A.5.17-22 | B10: Template Storage: Biometric Templates | C10: Template storage: Biometric templates shall be stored locally on the device (not centralised) where technically feasible. If centralised storage is required, templates shall be encrypted at rest with AES-256.
A11: A.5.17-23 | B11: Liveness Detection: Biometric Systems | C11: Liveness detection: Biometric systems shall implement liveness detection to prevent replay attacks (e.g., photographs, silicone fingerprints).
A12: A.5.17-24 | B12: Fallback: A Non-Biometric Fallback | C12: Fallback: A non-biometric fallback authentication method shall always be available (biometrics shall not be the sole authentication factor).
A13: A.5.17-25 | B13: Consent: Personnel | C13: Consent: Personnel shall provide informed consent before biometric enrolment, in compliance with Swiss nFADP requirements for sensitive personal data processing.
A14: A.5.17-26 | B14: Revocation: Biometric Templates | C14: Revocation: Biometric templates shall be deleted upon employment termination or when the individual withdraws consent.
A15: A.5.17-27 | B15: Accuracy: Biometric Systems | C15: Accuracy: Biometric systems shall be configured with a false acceptance rate (FAR) appropriate to the risk level (recommended: FAR <= 1:50'000 for standard access, FAR <= 1:1'000'000 for privileged access).
A16: A.5.17-28 | B16: Systems That Cannot Support Mfa | C16: Systems that cannot support MFA shall be documented in the risk register with:.

Sheet Authentication Info Protection
A1: Authentication Info Protection — Compliance Checklist
A2: ISO/IEC 27001:2022 — Control A.5.17: Authentication Information
A3: Req # | B3: Section | C3: Requirement | D3: Status | E3: Evidence | F3: Owner | G3: Due Date | H3: Notes
A4: A.5.17-29 | B4: Personnel | C4: All personnel shall:.
A5: A.5.17-30 | B5: The Main Access Authentication System | C5: The main access authentication system shall:.
A6: A.5.17-31 | B6: Validate The Log-On Information Only On | C6: Validate the log-on information only on completion of all input data; if an error condition arises, the system shall not indicate which part of the data is correct or incorrect.
A7: A.5.17-32 | B7: Shared Authentication Information Is | C7: Shared authentication information is discouraged and shall be avoided wherever possible. Where shared credentials are required (legacy systems, vendor-mandated accounts):.
A8: A.5.17-33 | B8: Be Stored In The Approved Credential | C8: Credentials shall be stored in the approved credential vault [Password Manager], not in plaintext documents, email, or chat.
A9: A.5.17-34 | B9: A Named Custodian | C9: A named custodian shall be assigned for each shared credential.
A10: A.5.17-35 | B10: Check-Out Logging With User | C10: Check-out logging with user identification and timestamp shall be maintained.
A11: A.5.17-36 | B11: Individual Accountability | C11: Individual accountability shall be maintained through audit logging.
A12: A.5.17-37 | B12: Access And Usage | C12: Access and usage shall be reviewed quarterly; annual reauthorisation required.
A13: A.5.17-38 | B13: Shared Accounts | C13: Shared accounts shall be included in the privileged account register and access review process.

Sheet Password Reset and Recovery
A1: Password Reset and Recovery — Compliance Checklist
A2: ISO/IEC 27001:2022 — Control A.5.17: Authentication Information
A3: Req # | B3: Section | C3: Requirement | D3: Status | E3: Evidence | F3: Owner | G3: Due Date | H3: Notes
A4: A.5.17-39 | B4: Mfa-Based Verification (Authenticator | C4: MFA-based verification (authenticator push, FIDO2, or hardware token) shall be required before a password reset is permitted.
A5: A.5.17-40 | B5: Knowledge-Based Security Questions | C5: Knowledge-based security questions shall not be used as the sole verification method due to their susceptibility to social engineering.
A6: A.5.17-41 | B6: Reset Tokens | C6: Reset tokens shall be time-limited (maximum 1 hour validity) and single-use.
A7: A.5.17-42 | B7: Reset Activities | C7: All reset activities shall be logged, including the verification method used.
A8: A.5.17-43 | B8: The User | C8: The user shall be notified of the password change via a registered secondary contact (email or mobile).
A9: A.5.17-44 | B9: The Reset Process | C9: The reset process shall not reveal whether an account exists (prevent account enumeration).
A10: A.5.17-45 | B10: Helpdesk-Assisted Password Resets | C10: Helpdesk-assisted password resets shall follow this procedure:.
A11: A.5.17-46 | B11: Verify Identity: The Helpdesk | C11: Verify identity: The helpdesk shall verify the caller's identity using at least one pre-registered verification method (secondary email, registered mobile number, manager confirmation, or in-person with photo ID).
A12: A.5.17-47 | B12: Generate Temporary Password: A Random | C12: Generate temporary password: A random temporary password shall be generated meeting minimum length requirements.
A13: A.5.17-48 | B13: Communicate Securely: The Temporary | C13: Communicate securely: The temporary password shall be communicated via a secure channel (not unencrypted email); where possible, use the identity provider's secure reset link.
A14: A.5.17-49 | B14: Force Change: The Temporary Password | C14: Force change: The temporary password shall expire on first use, requiring the user to set a new password immediately.
A15: A.5.17-50 | B15: Document: The Reset Request, | C15: Document: The reset request, verification method used, and timestamp shall be recorded in the IT service management system.
A16: A.5.17-51 | B16: Helpdesk Personnel | C16: Helpdesk personnel shall not have access to view user passwords after issuance.

Sheet Compliance Measurement
A1: Compliance Measurement — Compliance Checklist
A2: ISO/IEC 27001:2022 — Control A.5.17: Authentication Information
A3: Req # | B3: Section | C3: Requirement | D3: Status | E3: Evidence | F3: Owner | G3: Due Date | H3: Notes
A4: A.5.17-52 | B4: The Information Security Management Team | C4: The information security management team shall verify compliance with this policy through various methods, including but not limited to, identity provider configuration audits, MFA coverage reports, breach screening verification, authentication log analysis, penetration testing, internal and external audits, and feedback to the policy owner.
A5: A.5.17-53 | B5: Be Reported To The Ciso Quarterly | C5: Metrics shall be reported to the CISO quarterly. Metrics falling below target shall include a remediation plan with owner and target date.
