Workbook

Sheet Instructions & Guide
A1: ISMS-IMP-A.8.20-21-22.S3 - Network Services Catalog & Security Assessment ISO/IEC 27001:2022 - Controls A.8.20, A.8.21, A.8.22: Network Security
A3: Document Information
A4: Workbook: | B4: Network Services Catalog & Security Assessment
A5: Generated: | B5: 08.02.2026
A6: Version: | B6: 1.0
A7: Control: | B7: ISO 27001:2022 A.8.21 (Security of Network Services)
A8: Purpose: | B8: Catalog network services and assess security controls
A9: Related IMP: | B9: ISMS-IMP-A.8.20-21-22-S4 (Services Security Process)
A11: Assessment Approach
A12: 1. SERVICE DISCOVERY: Identify all network services (DNS, DHCP, NTP, Proxy, Load Balancer, AAA, SNMP, Syslog)
A13: 2. CATALOG: Document each service in Services_Catalog (purpose, hosting, criticality, redundancy)
A14: 3. SERVICE-SPECIFIC ASSESSMENT: Complete dedicated assessment sheets (DNS, DHCP, NTP, Proxy)
A15: 4. SECURITY EVALUATION: Assess security controls per service type (authentication, encryption, logging, etc.)
A16: 5. AVAILABILITY: Document redundancy, failover, SLA requirements
A17: 6. MONITORING: Verify service health monitoring and alerting
A18: 7. GAP IDENTIFICATION: Document missing controls or misconfigurations
A19: 8. REMEDIATION: Prioritize and track service security improvements
A21: Network Service Type Definitions
A22: Service Type | B22: Purpose | C22: Key Security Controls
A23: DNS | B23: Domain name resolution | C23: DNSSEC, Split DNS, Rate Limiting, Query Logging
A24: DHCP | B24: IP address assignment | C24: DHCP Snooping, Rogue Detection, Scope Management
A25: NTP | B25: Time synchronization | C25: Authentication, Access Control, Stratum Hierarchy
A26: Proxy/Web Filter | B26: Web traffic filtering | C26: Authentication, SSL Inspection, Logging, Bypass Prevention
A27: Load Balancer | B27: Traffic distribution | C27: SSL Termination, Health Checks, Session Persistence
A28: RADIUS/TACACS+ | B28: AAA services | C28: Strong Authentication, Command Authorization, Logging
A29: SNMP | B29: Device monitoring | C29: SNMPv3 Only, Authentication, Encryption
A30: Syslog | B30: Centralized logging | C30: TLS Encryption, Retention, Rotation
A31: SMTP Relay | B31: Email routing | C31: Authentication, Relay Controls, SPF/DKIM
A32: FTP/SFTP | B32: File transfer | C32: Encryption (SFTP), Authentication, Access Control
A34: Service Criticality Assessment Guidelines
A35: Criticality | B35: Definition | C35: Examples
A36: Critical | B36: Service failure causes immediate business impact | C36: Internal DNS, Primary DHCP, Authentication (RADIUS/TACACS+)
A37: High | B37: Service failure causes significant degradation | C37: Web Proxy, External DNS, Load Balancer
A38: Medium | B38: Service failure causes localized impact | C38: NTP, Secondary DHCP, SNMP monitoring
A39: Low | B39: Service failure causes minimal impact | C39: Guest Wi-Fi DHCP, Development services
A41: ⚠ IMPORTANT ASSESSMENT NOTES
A42: • Each service type has dedicated assessment sheet with specific security controls
A43: • Services_Catalog is the master list - link to detailed assessments
A44: • Verify redundancy for all Critical/High services (no single points of failure)
A45: • Ensure all services are monitored (health checks, alerting)
...

Sheet Services_Catalog
A1: Network Services Catalog - Generated 08.02.2026
A2: 📋 Master catalog of all network services. Yellow cells are input fields. Link to detailed assessments in service-specific sheets.
A3: Service ID | B3: Service Type | C3: Service Name | D3: Purpose | E3: Hosting Location | F3: IP Address | G3: Port(s) | H3: Criticality | I3: Redundancy Level | J3: Monitoring Status | K3: SLA Uptime % | L3: Owner | M3: Last Security Review | N3: Status | O3: Notes | P3: Assessment Link
A4: =IF(B4<>"","SVC-" & TEXT(1,"000"),"")
A5: =IF(B5<>"","SVC-" & TEXT(2,"000"),"")
A6: =IF(B6<>"","SVC-" & TEXT(3,"000"),"")
A7: =IF(B7<>"","SVC-" & TEXT(4,"000"),"")
A8: =IF(B8<>"","SVC-" & TEXT(5,"000"),"")
A9: =IF(B9<>"","SVC-" & TEXT(6,"000"),"")
A10: =IF(B10<>"","SVC-" & TEXT(7,"000"),"")
A11: =IF(B11<>"","SVC-" & TEXT(8,"000"),"")
A12: =IF(B12<>"","SVC-" & TEXT(9,"000"),"")
A13: =IF(B13<>"","SVC-" & TEXT(10,"000"),"")
A14: =IF(B14<>"","SVC-" & TEXT(11,"000"),"")
A15: =IF(B15<>"","SVC-" & TEXT(12,"000"),"")
A16: =IF(B16<>"","SVC-" & TEXT(13,"000"),"")
A17: =IF(B17<>"","SVC-" & TEXT(14,"000"),"")
A18: =IF(B18<>"","SVC-" & TEXT(15,"000"),"")
A19: =IF(B19<>"","SVC-" & TEXT(16,"000"),"")
A20: =IF(B20<>"","SVC-" & TEXT(17,"000"),"")
A21: =IF(B21<>"","SVC-" & TEXT(18,"000"),"")
A22: =IF(B22<>"","SVC-" & TEXT(19,"000"),"")
A23: =IF(B23<>"","SVC-" & TEXT(20,"000"),"")
A24: =IF(B24<>"","SVC-" & TEXT(21,"000"),"")
A25: =IF(B25<>"","SVC-" & TEXT(22,"000"),"")
A26: =IF(B26<>"","SVC-" & TEXT(23,"000"),"")
A27: =IF(B27<>"","SVC-" & TEXT(24,"000"),"")
A28: =IF(B28<>"","SVC-" & TEXT(25,"000"),"")
A29: =IF(B29<>"","SVC-" & TEXT(26,"000"),"")
A30: =IF(B30<>"","SVC-" & TEXT(27,"000"),"")
A31: =IF(B31<>"","SVC-" & TEXT(28,"000"),"")
A32: =IF(B32<>"","SVC-" & TEXT(29,"000"),"")
A33: =IF(B33<>"","SVC-" & TEXT(30,"000"),"")
A34: =IF(B34<>"","SVC-" & TEXT(31,"000"),"")
A35: =IF(B35<>"","SVC-" & TEXT(32,"000"),"")
A36: =IF(B36<>"","SVC-" & TEXT(33,"000"),"")
A37: =IF(B37<>"","SVC-" & TEXT(34,"000"),"")
A38: =IF(B38<>"","SVC-" & TEXT(35,"000"),"")
A39: =IF(B39<>"","SVC-" & TEXT(36,"000"),"")
A40: =IF(B40<>"","SVC-" & TEXT(37,"000"),"")
...

Sheet DNS_Security_Assessment
A1: DNS Security Assessment
A2: 📋 Assess DNS security controls per IMP-S4 guidance. One row per DNS service instance.
A3: Service ID | B3: DNS Type | C3: DNSSEC Enabled | D3: Split DNS | E3: Rate Limiting | F3: Query Logging | G3: RPZ/Filtering | H3: Recursion Control | I3: Cache Poisoning Protection | J3: Zone Transfer Controls | K3: TSIG/SIG(0) | L3: Compliance Score % | M3: Last Assessed | N3: Notes
L4: =IF(COUNTIF(C4:K4,"Yes")+COUNTIF(C4:K4,"No")=0,"",COUNTIF(C4:K4,"Yes")/(COUNTIF(C4:K4,"Yes")+COUNTIF(C4:K4,"No"))*100)
L5: =IF(COUNTIF(C5:K5,"Yes")+COUNTIF(C5:K5,"No")=0,"",COUNTIF(C5:K5,"Yes")/(COUNTIF(C5:K5,"Yes")+COUNTIF(C5:K5,"No"))*100)
L6: =IF(COUNTIF(C6:K6,"Yes")+COUNTIF(C6:K6,"No")=0,"",COUNTIF(C6:K6,"Yes")/(COUNTIF(C6:K6,"Yes")+COUNTIF(C6:K6,"No"))*100)
L7: =IF(COUNTIF(C7:K7,"Yes")+COUNTIF(C7:K7,"No")=0,"",COUNTIF(C7:K7,"Yes")/(COUNTIF(C7:K7,"Yes")+COUNTIF(C7:K7,"No"))*100)
L8: =IF(COUNTIF(C8:K8,"Yes")+COUNTIF(C8:K8,"No")=0,"",COUNTIF(C8:K8,"Yes")/(COUNTIF(C8:K8,"Yes")+COUNTIF(C8:K8,"No"))*100)
L9: =IF(COUNTIF(C9:K9,"Yes")+COUNTIF(C9:K9,"No")=0,"",COUNTIF(C9:K9,"Yes")/(COUNTIF(C9:K9,"Yes")+COUNTIF(C9:K9,"No"))*100)
L10: =IF(COUNTIF(C10:K10,"Yes")+COUNTIF(C10:K10,"No")=0,"",COUNTIF(C10:K10,"Yes")/(COUNTIF(C10:K10,"Yes")+COUNTIF(C10:K10,"No"))*100)
L11: =IF(COUNTIF(C11:K11,"Yes")+COUNTIF(C11:K11,"No")=0,"",COUNTIF(C11:K11,"Yes")/(COUNTIF(C11:K11,"Yes")+COUNTIF(C11:K11,"No"))*100)
L12: =IF(COUNTIF(C12:K12,"Yes")+COUNTIF(C12:K12,"No")=0,"",COUNTIF(C12:K12,"Yes")/(COUNTIF(C12:K12,"Yes")+COUNTIF(C12:K12,"No"))*100)
L13: =IF(COUNTIF(C13:K13,"Yes")+COUNTIF(C13:K13,"No")=0,"",COUNTIF(C13:K13,"Yes")/(COUNTIF(C13:K13,"Yes")+COUNTIF(C13:K13,"No"))*100)
L14: =IF(COUNTIF(C14:K14,"Yes")+COUNTIF(C14:K14,"No")=0,"",COUNTIF(C14:K14,"Yes")/(COUNTIF(C14:K14,"Yes")+COUNTIF(C14:K14,"No"))*100)
L15: =IF(COUNTIF(C15:K15,"Yes")+COUNTIF(C15:K15,"No")=0,"",COUNTIF(C15:K15,"Yes")/(COUNTIF(C15:K15,"Yes")+COUNTIF(C15:K15,"No"))*100)
... L23: =IF(COUNTIF(C23:K23,"Yes")+COUNTIF(C23:K23,"No")=0,"",COUNTIF(C23:K23,"Yes")/(COUNTIF(C23:K23,"Yes")+COUNTIF(C23:K23,"No"))*100)
A25: DNS Security Controls - Implementation Reference (per IMP-S4)
A26: Control | B26: Implementation Guidance
A27: DNSSEC | B27: Enable zone signing, publish DS records to parent, configure trust anchors
A28: Split DNS | B28: Internal view for private zones, external view for public zones
A29: Rate Limiting | B29: Configure response rate limiting (RRL) to prevent DDoS amplification
A30: Query Logging | B30: Enable query logging for security monitoring and forensics
A31: RPZ/Filtering | B31: Implement Response Policy Zones for malware/phishing domain blocking
A32: Recursion Control | B32: Disable recursion on authoritative servers, restrict recursive queries by ACL
A33: Cache Poisoning Protection | B33: Enable DNSSEC validation, source port randomization
A34: Zone Transfer Controls | B34: Restrict zone transfers (AXFR) to authorized secondary servers only
A35: TSIG/SIG(0) | B35: Use TSIG for authenticated zone transfers and dynamic updates

Sheet DHCP_Security_Assessment
A1: DHCP Security Assessment
A2: 📋 Assess DHCP security controls per IMP-S4 guidance. One row per DHCP server/scope.
A3: Service ID | B3: DHCP Scope | C3: DHCP Snooping | D3: Rogue DHCP Detection | E3: Server Hardening | F3: Lease Time Appropriate | G3: Utilization Monitoring | H3: Reservation Management | I3: Logging Enabled | J3: Compliance Score % | K3: Last Assessed | L3: Notes
J4: =IF(COUNTIF(C4:I4,"Yes")+COUNTIF(C4:I4,"No")=0,"",COUNTIF(C4:I4,"Yes")/(COUNTIF(C4:I4,"Yes")+COUNTIF(C4:I4,"No"))*100)
J5: =IF(COUNTIF(C5:I5,"Yes")+COUNTIF(C5:I5,"No")=0,"",COUNTIF(C5:I5,"Yes")/(COUNTIF(C5:I5,"Yes")+COUNTIF(C5:I5,"No"))*100)
J6: =IF(COUNTIF(C6:I6,"Yes")+COUNTIF(C6:I6,"No")=0,"",COUNTIF(C6:I6,"Yes")/(COUNTIF(C6:I6,"Yes")+COUNTIF(C6:I6,"No"))*100)
J7: =IF(COUNTIF(C7:I7,"Yes")+COUNTIF(C7:I7,"No")=0,"",COUNTIF(C7:I7,"Yes")/(COUNTIF(C7:I7,"Yes")+COUNTIF(C7:I7,"No"))*100)
J8: =IF(COUNTIF(C8:I8,"Yes")+COUNTIF(C8:I8,"No")=0,"",COUNTIF(C8:I8,"Yes")/(COUNTIF(C8:I8,"Yes")+COUNTIF(C8:I8,"No"))*100)
J9: =IF(COUNTIF(C9:I9,"Yes")+COUNTIF(C9:I9,"No")=0,"",COUNTIF(C9:I9,"Yes")/(COUNTIF(C9:I9,"Yes")+COUNTIF(C9:I9,"No"))*100)
J10: =IF(COUNTIF(C10:I10,"Yes")+COUNTIF(C10:I10,"No")=0,"",COUNTIF(C10:I10,"Yes")/(COUNTIF(C10:I10,"Yes")+COUNTIF(C10:I10,"No"))*100)
J11: =IF(COUNTIF(C11:I11,"Yes")+COUNTIF(C11:I11,"No")=0,"",COUNTIF(C11:I11,"Yes")/(COUNTIF(C11:I11,"Yes")+COUNTIF(C11:I11,"No"))*100)
J12: =IF(COUNTIF(C12:I12,"Yes")+COUNTIF(C12:I12,"No")=0,"",COUNTIF(C12:I12,"Yes")/(COUNTIF(C12:I12,"Yes")+COUNTIF(C12:I12,"No"))*100)
J13: =IF(COUNTIF(C13:I13,"Yes")+COUNTIF(C13:I13,"No")=0,"",COUNTIF(C13:I13,"Yes")/(COUNTIF(C13:I13,"Yes")+COUNTIF(C13:I13,"No"))*100)
J14: =IF(COUNTIF(C14:I14,"Yes")+COUNTIF(C14:I14,"No")=0,"",COUNTIF(C14:I14,"Yes")/(COUNTIF(C14:I14,"Yes")+COUNTIF(C14:I14,"No"))*100)
J15: =IF(COUNTIF(C15:I15,"Yes")+COUNTIF(C15:I15,"No")=0,"",COUNTIF(C15:I15,"Yes")/(COUNTIF(C15:I15,"Yes")+COUNTIF(C15:I15,"No"))*100)
... J18: =IF(COUNTIF(C18:I18,"Yes")+COUNTIF(C18:I18,"No")=0,"",COUNTIF(C18:I18,"Yes")/(COUNTIF(C18:I18,"Yes")+COUNTIF(C18:I18,"No"))*100)
A20: DHCP Security Controls - Implementation Reference
A21: Control | B21: Implementation Guidance
A22: DHCP Snooping | B22: Enable on access switches to prevent rogue DHCP servers
A23: Rogue Detection | B23: Active scanning or monitoring for unauthorized DHCP responses
A24: Server Hardening | B24: Apply OS hardening, disable unnecessary services, patch regularly
A25: Lease Time | B25: Appropriate lease time (8 hours workstations, 24 hours servers, 1 hour guest)
A26: Utilization Monitoring | B26: Monitor scope utilization, alert at 80% threshold
A27: Reservation Management | B27: Document static reservations, review regularly
A28: Logging | B28: Enable DHCP server logging for all lease actions

Sheet NTP_Security_Assessment
A1: NTP Security Assessment
A2: 📋 Assess NTP security controls per IMP-S4 guidance. One row per NTP server/client.
A3: Service ID | B3: NTP Role | C3: Authentication | D3: Access Control | E3: Stratum Appropriate | F3: Source Validation | G3: Monitoring | H3: Compliance Score % | I3: Stratum Level | J3: Last Assessed | K3: Notes
H4: =IF(COUNTIF(C4:G4,"Yes")+COUNTIF(C4:G4,"No")=0,"",COUNTIF(C4:G4,"Yes")/(COUNTIF(C4:G4,"Yes")+COUNTIF(C4:G4,"No"))*100)
H5: =IF(COUNTIF(C5:G5,"Yes")+COUNTIF(C5:G5,"No")=0,"",COUNTIF(C5:G5,"Yes")/(COUNTIF(C5:G5,"Yes")+COUNTIF(C5:G5,"No"))*100)
H6: =IF(COUNTIF(C6:G6,"Yes")+COUNTIF(C6:G6,"No")=0,"",COUNTIF(C6:G6,"Yes")/(COUNTIF(C6:G6,"Yes")+COUNTIF(C6:G6,"No"))*100)
H7: =IF(COUNTIF(C7:G7,"Yes")+COUNTIF(C7:G7,"No")=0,"",COUNTIF(C7:G7,"Yes")/(COUNTIF(C7:G7,"Yes")+COUNTIF(C7:G7,"No"))*100)
H8: =IF(COUNTIF(C8:G8,"Yes")+COUNTIF(C8:G8,"No")=0,"",COUNTIF(C8:G8,"Yes")/(COUNTIF(C8:G8,"Yes")+COUNTIF(C8:G8,"No"))*100)
H9: =IF(COUNTIF(C9:G9,"Yes")+COUNTIF(C9:G9,"No")=0,"",COUNTIF(C9:G9,"Yes")/(COUNTIF(C9:G9,"Yes")+COUNTIF(C9:G9,"No"))*100)
H10: =IF(COUNTIF(C10:G10,"Yes")+COUNTIF(C10:G10,"No")=0,"",COUNTIF(C10:G10,"Yes")/(COUNTIF(C10:G10,"Yes")+COUNTIF(C10:G10,"No"))*100)
H11: =IF(COUNTIF(C11:G11,"Yes")+COUNTIF(C11:G11,"No")=0,"",COUNTIF(C11:G11,"Yes")/(COUNTIF(C11:G11,"Yes")+COUNTIF(C11:G11,"No"))*100)
H12: =IF(COUNTIF(C12:G12,"Yes")+COUNTIF(C12:G12,"No")=0,"",COUNTIF(C12:G12,"Yes")/(COUNTIF(C12:G12,"Yes")+COUNTIF(C12:G12,"No"))*100)
H13: =IF(COUNTIF(C13:G13,"Yes")+COUNTIF(C13:G13,"No")=0,"",COUNTIF(C13:G13,"Yes")/(COUNTIF(C13:G13,"Yes")+COUNTIF(C13:G13,"No"))*100)
A15: NTP Security Controls - Implementation Reference
A16: Control | B16: Implementation Guidance
A17: Authentication | B17: Enable NTP authentication (MD5 keys) between servers
A18: Access Control | B18: Restrict NTP queries and modifications (restrict default kod nomodify notrap)
A19: Stratum Hierarchy | B19: Appropriate stratum levels (Stratum 1/2 for internal servers)
A20: Source Validation | B20: Verify NTP server sources, use multiple reliable sources
A21: Monitoring | B21: Monitor time offset, alert on significant drift (>1 second)

Sheet Proxy_Security_Assessment
A1: Proxy/Web Filter Security Assessment
A2: 📋 Assess Proxy/Web Filtering security controls per IMP-S4 guidance.
A3: Service ID | B3: Proxy Type | C3: Authentication | D3: SSL Inspection | E3: Category Filtering | F3: Malware Scanning | G3: Logging | H3: Bypass Prevention | I3: Redundancy | J3: Compliance Score % | K3: Last Assessed | L3: Filter Categories | M3: Notes
J4: =IF(COUNTIF(C4:I4,"Yes")+COUNTIF(C4:I4,"No")=0,"",COUNTIF(C4:I4,"Yes")/(COUNTIF(C4:I4,"Yes")+COUNTIF(C4:I4,"No"))*100)
J5: =IF(COUNTIF(C5:I5,"Yes")+COUNTIF(C5:I5,"No")=0,"",COUNTIF(C5:I5,"Yes")/(COUNTIF(C5:I5,"Yes")+COUNTIF(C5:I5,"No"))*100)
J6: =IF(COUNTIF(C6:I6,"Yes")+COUNTIF(C6:I6,"No")=0,"",COUNTIF(C6:I6,"Yes")/(COUNTIF(C6:I6,"Yes")+COUNTIF(C6:I6,"No"))*100)
J7: =IF(COUNTIF(C7:I7,"Yes")+COUNTIF(C7:I7,"No")=0,"",COUNTIF(C7:I7,"Yes")/(COUNTIF(C7:I7,"Yes")+COUNTIF(C7:I7,"No"))*100)
J8: =IF(COUNTIF(C8:I8,"Yes")+COUNTIF(C8:I8,"No")=0,"",COUNTIF(C8:I8,"Yes")/(COUNTIF(C8:I8,"Yes")+COUNTIF(C8:I8,"No"))*100)
J9: =IF(COUNTIF(C9:I9,"Yes")+COUNTIF(C9:I9,"No")=0,"",COUNTIF(C9:I9,"Yes")/(COUNTIF(C9:I9,"Yes")+COUNTIF(C9:I9,"No"))*100)
J10: =IF(COUNTIF(C10:I10,"Yes")+COUNTIF(C10:I10,"No")=0,"",COUNTIF(C10:I10,"Yes")/(COUNTIF(C10:I10,"Yes")+COUNTIF(C10:I10,"No"))*100)
J11: =IF(COUNTIF(C11:I11,"Yes")+COUNTIF(C11:I11,"No")=0,"",COUNTIF(C11:I11,"Yes")/(COUNTIF(C11:I11,"Yes")+COUNTIF(C11:I11,"No"))*100)
J12: =IF(COUNTIF(C12:I12,"Yes")+COUNTIF(C12:I12,"No")=0,"",COUNTIF(C12:I12,"Yes")/(COUNTIF(C12:I12,"Yes")+COUNTIF(C12:I12,"No"))*100)
J13: =IF(COUNTIF(C13:I13,"Yes")+COUNTIF(C13:I13,"No")=0,"",COUNTIF(C13:I13,"Yes")/(COUNTIF(C13:I13,"Yes")+COUNTIF(C13:I13,"No"))*100)
J14: =IF(COUNTIF(C14:I14,"Yes")+COUNTIF(C14:I14,"No")=0,"",COUNTIF(C14:I14,"Yes")/(COUNTIF(C14:I14,"Yes")+COUNTIF(C14:I14,"No"))*100)
J15: =IF(COUNTIF(C15:I15,"Yes")+COUNTIF(C15:I15,"No")=0,"",COUNTIF(C15:I15,"Yes")/(COUNTIF(C15:I15,"Yes")+COUNTIF(C15:I15,"No"))*100)
... J18: =IF(COUNTIF(C18:I18,"Yes")+COUNTIF(C18:I18,"No")=0,"",COUNTIF(C18:I18,"Yes")/(COUNTIF(C18:I18,"Yes")+COUNTIF(C18:I18,"No"))*100)
A20: Proxy Security Controls - Implementation Reference
A21: Control | B21: Implementation Guidance
A22: Authentication | B22: LDAP/AD authentication, Kerberos/NTLM for transparent proxy
A23: SSL Inspection | B23: SSL/TLS decryption and inspection (with CA cert deployment)
A24: Category Filtering | B24: Block malicious/inappropriate categories (malware, adult, gambling, etc.)
A25: Malware Scanning | B25: Real-time malware scanning of downloaded content
A26: Logging | B26: Log all requests with user, URL, timestamp, action (allow/block)
A27: Bypass Prevention | B27: Block direct internet access, enforce proxy via firewall rules
A28: Redundancy | B28: High availability configuration (multiple proxy servers)

Sheet Additional_Services
A1: Additional Network Services Assessment
A2: 📋 Assess other network services: Load Balancers, AAA (RADIUS/TACACS+), SNMP, Syslog, SMTP, FTP, etc.
A3: Service ID | B3: Service Type | C3: Authentication | D3: Encryption | E3: Access Control | F3: Logging | G3: Monitoring | H3: Hardening Applied | I3: Compliance Score % | J3: Last Assessed | K3: Key Controls | L3: Notes
I4: =IF(COUNTIF(C4:H4,"Yes")+COUNTIF(C4:H4,"No")=0,"",COUNTIF(C4:H4,"Yes")/(COUNTIF(C4:H4,"Yes")+COUNTIF(C4:H4,"No"))*100)
I5: =IF(COUNTIF(C5:H5,"Yes")+COUNTIF(C5:H5,"No")=0,"",COUNTIF(C5:H5,"Yes")/(COUNTIF(C5:H5,"Yes")+COUNTIF(C5:H5,"No"))*100)
I6: =IF(COUNTIF(C6:H6,"Yes")+COUNTIF(C6:H6,"No")=0,"",COUNTIF(C6:H6,"Yes")/(COUNTIF(C6:H6,"Yes")+COUNTIF(C6:H6,"No"))*100)
I7: =IF(COUNTIF(C7:H7,"Yes")+COUNTIF(C7:H7,"No")=0,"",COUNTIF(C7:H7,"Yes")/(COUNTIF(C7:H7,"Yes")+COUNTIF(C7:H7,"No"))*100)
I8: =IF(COUNTIF(C8:H8,"Yes")+COUNTIF(C8:H8,"No")=0,"",COUNTIF(C8:H8,"Yes")/(COUNTIF(C8:H8,"Yes")+COUNTIF(C8:H8,"No"))*100)
I9: =IF(COUNTIF(C9:H9,"Yes")+COUNTIF(C9:H9,"No")=0,"",COUNTIF(C9:H9,"Yes")/(COUNTIF(C9:H9,"Yes")+COUNTIF(C9:H9,"No"))*100)
I10: =IF(COUNTIF(C10:H10,"Yes")+COUNTIF(C10:H10,"No")=0,"",COUNTIF(C10:H10,"Yes")/(COUNTIF(C10:H10,"Yes")+COUNTIF(C10:H10,"No"))*100)
I11: =IF(COUNTIF(C11:H11,"Yes")+COUNTIF(C11:H11,"No")=0,"",COUNTIF(C11:H11,"Yes")/(COUNTIF(C11:H11,"Yes")+COUNTIF(C11:H11,"No"))*100)
I12: =IF(COUNTIF(C12:H12,"Yes")+COUNTIF(C12:H12,"No")=0,"",COUNTIF(C12:H12,"Yes")/(COUNTIF(C12:H12,"Yes")+COUNTIF(C12:H12,"No"))*100)
I13: =IF(COUNTIF(C13:H13,"Yes")+COUNTIF(C13:H13,"No")=0,"",COUNTIF(C13:H13,"Yes")/(COUNTIF(C13:H13,"Yes")+COUNTIF(C13:H13,"No"))*100)
I14: =IF(COUNTIF(C14:H14,"Yes")+COUNTIF(C14:H14,"No")=0,"",COUNTIF(C14:H14,"Yes")/(COUNTIF(C14:H14,"Yes")+COUNTIF(C14:H14,"No"))*100)
I15: =IF(COUNTIF(C15:H15,"Yes")+COUNTIF(C15:H15,"No")=0,"",COUNTIF(C15:H15,"Yes")/(COUNTIF(C15:H15,"Yes")+COUNTIF(C15:H15,"No"))*100)
... I33: =IF(COUNTIF(C33:H33,"Yes")+COUNTIF(C33:H33,"No")=0,"",COUNTIF(C33:H33,"Yes")/(COUNTIF(C33:H33,"Yes")+COUNTIF(C33:H33,"No"))*100)
A35: Service-Specific Security Controls Reference
A36: Service Type | B36: Key Security Controls
A37: Load Balancer | B37: SSL/TLS termination, strong ciphers, health checks, session persistence security, DDoS protection
A38: RADIUS/TACACS+ | B38: Strong authentication, command authorization (TACACS+), encrypted communication, MFA support, logging
A39: SNMP | B39: SNMPv3 only (v1/v2c disabled), authentication (authPriv), encryption, access control, trap security
A40: Syslog | B40: TLS encryption (rsyslog/syslog-ng), log retention policy, log rotation, integrity protection
A41: SMTP Relay | B41: Authentication required, relay restrictions, SPF/DKIM/DMARC, TLS encryption, rate limiting
A42: FTP/SFTP | B42: Use SFTP (SSH), disable FTP, strong authentication, access control, logging

Sheet Service_Compliance_Summary
A1: Service Security Compliance Summary
A3: Overall Service Statistics
A4: Metric | B4: Value
A5: Total Services Cataloged | B5: =COUNTA(Services_Catalog!B4:B103)
A6: Critical Services | B6: =COUNTIF(Services_Catalog!H4:H103,"Critical")
A7: Services with Redundancy | B7: =COUNTIF(Services_Catalog!I4:I103,"Active-Active")+COUNTIF(Services_Catalog!I4:I103,"Active-Passive")+COUNTIF(Services_Catalog!I4:I103,"Clustered")
A8: Single Points of Failure | B8: =COUNTIF(Services_Catalog!I4:I103,"Single Point of Failure")
A9: Monitored Services | B9: =COUNTIF(Services_Catalog!J4:J103,"Monitored")
A10: Services Needing Review | B10: =COUNTIF(Services_Catalog!M4:M103,"<"&TODAY()-90)
A12: Service Distribution by Type
A13: Service Type | B13: Count
A14: DNS | B14: =COUNTIF(Services_Catalog!B4:B103,"DNS")
A15: DHCP | B15: =COUNTIF(Services_Catalog!B4:B103,"DHCP")
A16: NTP | B16: =COUNTIF(Services_Catalog!B4:B103,"NTP")
A17: Proxy/Web Filter | B17: =COUNTIF(Services_Catalog!B4:B103,"Proxy/Web Filter")
A18: Load Balancer | B18: =COUNTIF(Services_Catalog!B4:B103,"Load Balancer")
A19: RADIUS/TACACS+ (AAA) | B19: =COUNTIF(Services_Catalog!B4:B103,"RADIUS/TACACS+ (AAA)")
A20: SNMP | B20: =COUNTIF(Services_Catalog!B4:B103,"SNMP")
A21: Syslog | B21: =COUNTIF(Services_Catalog!B4:B103,"Syslog")
A22: SMTP Relay | B22: =COUNTIF(Services_Catalog!B4:B103,"SMTP Relay")
A23: FTP/SFTP | B23: =COUNTIF(Services_Catalog!B4:B103,"FTP/SFTP")
A24: Other | B24: =COUNTIF(Services_Catalog!B4:B103,"Other")
A26: Average Compliance Scores by Service Type
A27: Service Type | B27: Avg Compliance % | C27: Services Assessed
A28: DNS | B28: =AVERAGE(DNS_Security_Assessment!L4:L23) | C28: =COUNTA(DNS_Security_Assessment!L4:L23)
A29: DHCP | B29: =AVERAGE(DHCP_Security_Assessment!J4:J18) | C29: =COUNTA(DHCP_Security_Assessment!J4:J18)
A30: NTP | B30: =AVERAGE(NTP_Security_Assessment!H4:H13) | C30: =COUNTA(NTP_Security_Assessment!H4:H13)
A31: Proxy | B31: =AVERAGE(Proxy_Security_Assessment!J4:J18) | C31: =COUNTA(Proxy_Security_Assessment!J4:J18)
A32: Other Services | B32: =AVERAGE(Additional_Services!I4:I33) | C32: =COUNTA(Additional_Services!I4:I33)

Sheet Gap_Analysis
A1: Service Security Gaps - Remediation Tracking
A2: 📋 Document all service security gaps (missing controls, misconfigurations). Track remediation progress.
A3: Gap ID | B3: Service ID | C3: Service Type | D3: Security Gap | E3: Current State | F3: Severity | G3: Remediation Plan | H3: Owner | I3: Status | J3: Target Date
A4: =IF(B4<>"","SVC-GAP-" & TEXT(1,"000"),"")
A5: =IF(B5<>"","SVC-GAP-" & TEXT(2,"000"),"")
A6: =IF(B6<>"","SVC-GAP-" & TEXT(3,"000"),"")
A7: =IF(B7<>"","SVC-GAP-" & TEXT(4,"000"),"")
A8: =IF(B8<>"","SVC-GAP-" & TEXT(5,"000"),"")
A9: =IF(B9<>"","SVC-GAP-" & TEXT(6,"000"),"")
A10: =IF(B10<>"","SVC-GAP-" & TEXT(7,"000"),"")
A11: =IF(B11<>"","SVC-GAP-" & TEXT(8,"000"),"")
A12: =IF(B12<>"","SVC-GAP-" & TEXT(9,"000"),"")
A13: =IF(B13<>"","SVC-GAP-" & TEXT(10,"000"),"")
A14: =IF(B14<>"","SVC-GAP-" & TEXT(11,"000"),"")
A15: =IF(B15<>"","SVC-GAP-" & TEXT(12,"000"),"")
A16: =IF(B16<>"","SVC-GAP-" & TEXT(13,"000"),"")
A17: =IF(B17<>"","SVC-GAP-" & TEXT(14,"000"),"")
A18: =IF(B18<>"","SVC-GAP-" & TEXT(15,"000"),"")
A19: =IF(B19<>"","SVC-GAP-" & TEXT(16,"000"),"")
A20: =IF(B20<>"","SVC-GAP-" & TEXT(17,"000"),"")
A21: =IF(B21<>"","SVC-GAP-" & TEXT(18,"000"),"")
A22: =IF(B22<>"","SVC-GAP-" & TEXT(19,"000"),"")
A23: =IF(B23<>"","SVC-GAP-" & TEXT(20,"000"),"")
A24: =IF(B24<>"","SVC-GAP-" & TEXT(21,"000"),"")
A25: =IF(B25<>"","SVC-GAP-" & TEXT(22,"000"),"")
A26: =IF(B26<>"","SVC-GAP-" & TEXT(23,"000"),"")
A27: =IF(B27<>"","SVC-GAP-" & TEXT(24,"000"),"")
A28: =IF(B28<>"","SVC-GAP-" & TEXT(25,"000"),"")
A29: =IF(B29<>"","SVC-GAP-" & TEXT(26,"000"),"")
A30: =IF(B30<>"","SVC-GAP-" & TEXT(27,"000"),"")
A31: =IF(B31<>"","SVC-GAP-" & TEXT(28,"000"),"")
A32: =IF(B32<>"","SVC-GAP-" & TEXT(29,"000"),"")
A33: =IF(B33<>"","SVC-GAP-" & TEXT(30,"000"),"")
A34: =IF(B34<>"","SVC-GAP-" & TEXT(31,"000"),"")
A35: =IF(B35<>"","SVC-GAP-" & TEXT(32,"000"),"")
A36: =IF(B36<>"","SVC-GAP-" & TEXT(33,"000"),"")
A37: =IF(B37<>"","SVC-GAP-" & TEXT(34,"000"),"")
A38: =IF(B38<>"","SVC-GAP-" & TEXT(35,"000"),"")
A39: =IF(B39<>"","SVC-GAP-" & TEXT(36,"000"),"")
A40: =IF(B40<>"","SVC-GAP-" & TEXT(37,"000"),"")
...

Sheet Service_Dependencies
A1: Service Dependencies Mapping
A2: 📋 Map service dependencies to understand impact of service failures.
A3: Service ID | B3: Service Name | C3: Depends On | D3: Required By | E3: Impact of Failure | F3: Notes
A35: Common Service Dependencies - Examples
A36: Service | B36: Typical Dependencies
A37: Active Directory | B37: Depends On: DNS, NTP, DHCP (optional)
A38: Email (Exchange/O365) | B38: Depends On: DNS, Active Directory, Network Connectivity
A39: Web Applications | B39: Depends On: DNS, Load Balancer, Database, Authentication (LDAP/AD)
A40: VPN Access | B40: Depends On: RADIUS/TACACS+, Active Directory, DNS
A41: DHCP | B41: Depends On: Network connectivity (usually no dependencies)
A42: DNS | B42: Depends On: Network connectivity, NTP (for DNSSEC)
