Workbook

Sheet Instructions & Legend
A1: ISMS-IMP-A.8.20-21-22.S1 - Network Infrastructure Inventory ISO/IEC 27001:2022 - Controls A.8.20, A.8.21, A.8.22: Network Security
A3: Document Information
A4: Workbook: | B4: Network Infrastructure Inventory
A5: Generated: | B5: 08.02.2026
A6: Version: | B6: 1.0
A7: Control: | B7: ISO 27001:2022 A.8.20 (Networks Security)
A8: Purpose: | B8: Systematic inventory of network infrastructure devices
A9: Related IMP: | B9: ISMS-IMP-A.8.20-21-22-S1 (Network Discovery Process)
A11: Usage Instructions
A12: 1. START WITH DISCOVERY: Use IMP-S1 guidance to discover all network devices (nmap, SNMP, cloud APIs, manual)
A13: 2. DEVICE INVENTORY: Fill in Device_Inventory sheet with discovered devices (auto-generates Device IDs)
A14: 3. REQUIRED FIELDS: Device Type, Primary IP, Hostname, Location, Criticality, Status are MANDATORY
A15: 4. CRITICALITY: Assess each device using Device_Criticality_Matrix guidance
A16: 5. GAPS: Document undiscovered/unreachable devices in Gap_Analysis sheet
A17: 6. EVIDENCE: Track discovery evidence (configs, scans, diagrams) in Evidence_Register
A18: 7. VALIDATION: Review Validation_Rules sheet for data quality checks
A19: 8. SUMMARY: Review Device_Type_Summary for statistics and charts
A21: Field Definitions (Device Inventory)
A22: Field | B22: Description | C22: Required | D22: Format/Values
A23: Device ID | B23: Auto-generated unique identifier (NET-DEV-001, NET-DEV-002, ...) | C23: Auto | D23: NET-DEV-XXX
A24: Device Type | B24: Category of network device | C24: Yes | D24: Router, Switch, Firewall, etc.
A25: Make/Model | B25: Manufacturer and model number | C25: No | D25: e.g., Cisco Catalyst 9300-48P
A26: Hostname | B26: Device hostname or DNS name | C26: Yes | D26: e.g., switch-core-01.example.com
A27: Primary IP | B27: Primary management IP address | C27: Yes | D27: IPv4 format (e.g., 10.1.0.1)
A28: Management IP | B28: Secondary management IP (if different) | C28: No | D28: IPv4 format
A29: Location | B29: Physical or logical location | C29: Yes | D29: e.g., Datacenter Rack A10
A30: Security Zone | B30: Network security zone/segment | C30: No | D30: DMZ, Internal, Management, etc.
A31: Purpose | B31: Device function/purpose | C31: No | D31: e.g., Core switching, Internet gateway
A32: Criticality | B32: Business impact if device fails | C32: Yes | D32: Critical, High, Medium, Low
A33: Owner | B33: Responsible team or person | C33: No | D33: e.g., Network Operations Team
... A40: Notes | B40: Additional information | C40: No | D40: Free text
A42: Criticality Classification Legend
A43: Criticality | B43: Definition | C43: Examples
A44: Critical | B44: Mission-critical - failure causes immediate service outage | C44: Core routers, primary firewalls, datacenter switches
A45: High | B45: Important - failure causes significant degradation | C45: Distribution switches, backup firewalls, WAN routers
A46: Medium | B46: Standard - failure causes localized impact | C46: Access switches, branch routers, management devices
A47: Low | B47: Minimal impact - failure causes minor inconvenience | C47: Lab devices, test equipment, guest Wi-Fi APs

Sheet Device_Inventory
A1: Network Infrastructure Inventory - Generated 08.02.2026
A2: 📋 Complete inventory for all network devices discovered per IMP-S1. Yellow cells are input fields. Device IDs auto-generate.
A3: Device ID | B3: Device Type | C3: Make/Model | D3: Hostname | E3: Primary IP | F3: Management IP | G3: Location | H3: Security Zone | I3: Purpose | J3: Criticality | K3: Owner | L3: Last Discovered | M3: Discovery Method | N3: Firmware Version | O3: Serial Number | P3: Compliance Status | Q3: Status | R3: Notes
A4: =IF(B4<>"","NET-DEV-" & TEXT(1,"000"),"")
A5: =IF(B5<>"","NET-DEV-" & TEXT(2,"000"),"")
A6: =IF(B6<>"","NET-DEV-" & TEXT(3,"000"),"")
A7: =IF(B7<>"","NET-DEV-" & TEXT(4,"000"),"")
A8: =IF(B8<>"","NET-DEV-" & TEXT(5,"000"),"")
A9: =IF(B9<>"","NET-DEV-" & TEXT(6,"000"),"")
A10: =IF(B10<>"","NET-DEV-" & TEXT(7,"000"),"")
A11: =IF(B11<>"","NET-DEV-" & TEXT(8,"000"),"")
A12: =IF(B12<>"","NET-DEV-" & TEXT(9,"000"),"")
A13: =IF(B13<>"","NET-DEV-" & TEXT(10,"000"),"")
A14: =IF(B14<>"","NET-DEV-" & TEXT(11,"000"),"")
A15: =IF(B15<>"","NET-DEV-" & TEXT(12,"000"),"")
A16: =IF(B16<>"","NET-DEV-" & TEXT(13,"000"),"")
A17: =IF(B17<>"","NET-DEV-" & TEXT(14,"000"),"")
A18: =IF(B18<>"","NET-DEV-" & TEXT(15,"000"),"")
A19: =IF(B19<>"","NET-DEV-" & TEXT(16,"000"),"")
A20: =IF(B20<>"","NET-DEV-" & TEXT(17,"000"),"")
A21: =IF(B21<>"","NET-DEV-" & TEXT(18,"000"),"")
A22: =IF(B22<>"","NET-DEV-" & TEXT(19,"000"),"")
A23: =IF(B23<>"","NET-DEV-" & TEXT(20,"000"),"")
A24: =IF(B24<>"","NET-DEV-" & TEXT(21,"000"),"")
A25: =IF(B25<>"","NET-DEV-" & TEXT(22,"000"),"")
A26: =IF(B26<>"","NET-DEV-" & TEXT(23,"000"),"")
A27: =IF(B27<>"","NET-DEV-" & TEXT(24,"000"),"")
A28: =IF(B28<>"","NET-DEV-" & TEXT(25,"000"),"")
A29: =IF(B29<>"","NET-DEV-" & TEXT(26,"000"),"")
A30: =IF(B30<>"","NET-DEV-" & TEXT(27,"000"),"")
A31: =IF(B31<>"","NET-DEV-" & TEXT(28,"000"),"")
A32: =IF(B32<>"","NET-DEV-" & TEXT(29,"000"),"")
A33: =IF(B33<>"","NET-DEV-" & TEXT(30,"000"),"")
A34: =IF(B34<>"","NET-DEV-" & TEXT(31,"000"),"")
A35: =IF(B35<>"","NET-DEV-" & TEXT(32,"000"),"")
A36: =IF(B36<>"","NET-DEV-" & TEXT(33,"000"),"")
A37: =IF(B37<>"","NET-DEV-" & TEXT(34,"000"),"")
A38: =IF(B38<>"","NET-DEV-" & TEXT(35,"000"),"")
A39: =IF(B39<>"","NET-DEV-" & TEXT(36,"000"),"")
A40: =IF(B40<>"","NET-DEV-" & TEXT(37,"000"),"")
...

Sheet Device_Criticality_Matrix
A1: Device Criticality Assessment Matrix
A2: Use this matrix to assess device criticality based on business impact if device fails
A4: Assessment Criteria
A5: Criticality | B5: Service Impact | C5: Recovery Time | D5: User Impact | E5: Revenue Impact | F5: Redundancy
A6: Critical | B6: Complete outage of critical services | C6: < 1 hour | D6: All users affected | E6: Significant revenue loss | F6: Single point of failure
A7: High | B7: Significant service degradation | C7: < 4 hours | D7: Large user group affected | E7: Notable revenue impact | F7: Limited redundancy
A8: Medium | B8: Localized service impact | C8: < 24 hours | D8: Department/team affected | E8: Minimal revenue impact | F8: Redundant but important
A9: Low | B9: Minimal or no service impact | C9: > 24 hours acceptable | D9: Few users affected | E9: No revenue impact | F9: Fully redundant or non-critical
A11: Device Type - Typical Criticality Mapping (Guidance Only)
A12: Device Type | B12: Typical Criticality | C12: Rationale
A13: Core Router | B13: Critical | C13: Single point of failure for all WAN/Internet traffic
A14: Core Switch | B14: Critical | C14: Aggregates all access layer traffic
A15: Primary Firewall | B15: Critical | C15: Controls all ingress/egress traffic
A16: Datacenter Switch | B16: Critical | C16: Connects production servers
A17: Distribution Switch | B17: High | C17: Aggregates multiple access switches
A18: WAN Router | B18: High | C18: Connects branch to HQ
A19: Secondary Firewall | B19: High | C19: Backup for primary firewall
A20: Access Switch | B20: Medium | C20: Localized impact (single floor/department)
A21: Wireless AP | B21: Medium | C21: Affects wireless users only
A22: Management Device | B22: Medium | C22: Does not forward production traffic
A23: Guest Wi-Fi AP | B23: Low | C23: Non-business critical
A24: Lab Equipment | B24: Low | C24: Test/development only
A26: ⚠️ IMPORTANCriticality assessment must consider YOUR organization's specific context, not just device type. Always assess based on business impact.

Sheet Device_Type_Summary
A1: Device Type Summary & Statistics
A3: Summary Statistics
A4: Metric | B4: Count | C4: Formula
A5: Total Devices Inventoried | B5: =COUNTA(Device_Inventory!B4:B153) | C5: =COUNTA(Device_Inventory!B4:B153)
A6: Active Devices | B6: =COUNTIF(Device_Inventory!Q4:Q153,"Active") | C6: =COUNTIF(Device_Inventory!Q4:Q153,"Active")
A7: Offline Devices | B7: =COUNTIF(Device_Inventory!Q4:Q153,"Offline") | C7: =COUNTIF(Device_Inventory!Q4:Q153,"Offline")
A8: Critical Devices | B8: =COUNTIF(Device_Inventory!J4:J153,"Critical") | C8: =COUNTIF(Device_Inventory!J4:J153,"Critical")
A9: High Criticality | B9: =COUNTIF(Device_Inventory!J4:J153,"High") | C9: =COUNTIF(Device_Inventory!J4:J153,"High")
A10: Medium Criticality | B10: =COUNTIF(Device_Inventory!J4:J153,"Medium") | C10: =COUNTIF(Device_Inventory!J4:J153,"Medium")
A11: Low Criticality | B11: =COUNTIF(Device_Inventory!J4:J153,"Low") | C11: =COUNTIF(Device_Inventory!J4:J153,"Low")
A12: Compliant Devices | B12: =COUNTIF(Device_Inventory!P4:P153,"Compliant") | C12: =COUNTIF(Device_Inventory!P4:P153,"Compliant")
A13: Non-Compliant Devices | B13: =COUNTIF(Device_Inventory!P4:P153,"Non-Compliant") | C13: =COUNTIF(Device_Inventory!P4:P153,"Non-Compliant")
A15: Device Count by Type
A16: Device Type | B16: Count
A17: Router | B17: =COUNTIF(Device_Inventory!B4:B153,"Router")
A18: Switch | B18: =COUNTIF(Device_Inventory!B4:B153,"Switch")
A19: Firewall | B19: =COUNTIF(Device_Inventory!B4:B153,"Firewall")
A20: Wireless AP | B20: =COUNTIF(Device_Inventory!B4:B153,"Wireless AP")
A21: Load Balancer | B21: =COUNTIF(Device_Inventory!B4:B153,"Load Balancer")
A22: VPN Concentrator | B22: =COUNTIF(Device_Inventory!B4:B153,"VPN Concentrator")
A23: IDS/IPS | B23: =COUNTIF(Device_Inventory!B4:B153,"IDS/IPS")
A24: Network Management | B24: =COUNTIF(Device_Inventory!B4:B153,"Network Management")
A25: Other | B25: =COUNTIF(Device_Inventory!B4:B153,"Other")
A27: Device Count by Criticality
A28: Criticality | B28: Count
A29: Critical | B29: =COUNTIF(Device_Inventory!J4:J153,"Critical")
A30: High | B30: =COUNTIF(Device_Inventory!J4:J153,"High")
A31: Medium | B31: =COUNTIF(Device_Inventory!J4:J153,"Medium")
A32: Low | B32: =COUNTIF(Device_Inventory!J4:J153,"Low")

Sheet Discovery_Metadata
A1: Network Discovery Process Metadata
A3: Discovery Project Information
A4: Project Name: | B4: [Enter discovery project name]
A5: Start Date: | B5: [YYYY-MM-DD]
A6: Completion Date: | B6: [YYYY-MM-DD]
A7: Lead Assessor: | B7: [Name]
A8: Team Members: | B8: [Names]
A9: Scope: | B9: [Network segments/locations covered]
A11: Discovery Methods Used
A12: Method | B12: Used (Y/N) | C12: Tool/Platform | D12: Coverage | E12: Notes
A13: Nmap Network Scan | C13: nmap
A14: SNMP Walk | C14: SNMPwalk
A15: AWS Discovery | C15: AWS CLI / boto3
A16: Azure Discovery | C16: Azure CLI
A17: GCP Discovery | C17: GCP SDK
A18: NetFlow Analysis
A19: Documentation Review | C19: CMDB / Wiki
A20: Administrator Interviews | C20: N/A
A21: Physical Site Survey | C21: N/A
A22: Other
A24: Discovery Scope
A25: Network Segment/Zone | B25: IP Range | C25: Included (Y/N) | D25: Devices Found | E25: Notes
A47: Discovery Challenges & Limitations
A48: [Document any challenges encountered during discovery: - Unreachable networks - Firewall blocking scans - Missing credentials - Undocumented devices - Other limitations]

Sheet Gap_Analysis
A1: Network Discovery Gap Analysis
A2: 📋 Document gaps: undocumented devices, unreachable devices, missing information, or discovery failures
A3: Gap ID | B3: Gap Type | C3: Device/Location | D3: Description | E3: Severity | F3: Impact | G3: Remediation Plan | H3: Owner | I3: Status | J3: Target Date
A4: =IF(B4<>"","DISC-GAP-" & TEXT(1,"000"),"")
A5: =IF(B5<>"","DISC-GAP-" & TEXT(2,"000"),"")
A6: =IF(B6<>"","DISC-GAP-" & TEXT(3,"000"),"")
A7: =IF(B7<>"","DISC-GAP-" & TEXT(4,"000"),"")
A8: =IF(B8<>"","DISC-GAP-" & TEXT(5,"000"),"")
A9: =IF(B9<>"","DISC-GAP-" & TEXT(6,"000"),"")
A10: =IF(B10<>"","DISC-GAP-" & TEXT(7,"000"),"")
A11: =IF(B11<>"","DISC-GAP-" & TEXT(8,"000"),"")
A12: =IF(B12<>"","DISC-GAP-" & TEXT(9,"000"),"")
A13: =IF(B13<>"","DISC-GAP-" & TEXT(10,"000"),"")
A14: =IF(B14<>"","DISC-GAP-" & TEXT(11,"000"),"")
A15: =IF(B15<>"","DISC-GAP-" & TEXT(12,"000"),"")
A16: =IF(B16<>"","DISC-GAP-" & TEXT(13,"000"),"")
A17: =IF(B17<>"","DISC-GAP-" & TEXT(14,"000"),"")
A18: =IF(B18<>"","DISC-GAP-" & TEXT(15,"000"),"")
A19: =IF(B19<>"","DISC-GAP-" & TEXT(16,"000"),"")
A20: =IF(B20<>"","DISC-GAP-" & TEXT(17,"000"),"")
A21: =IF(B21<>"","DISC-GAP-" & TEXT(18,"000"),"")
A22: =IF(B22<>"","DISC-GAP-" & TEXT(19,"000"),"")
A23: =IF(B23<>"","DISC-GAP-" & TEXT(20,"000"),"")
A24: =IF(B24<>"","DISC-GAP-" & TEXT(21,"000"),"")
A25: =IF(B25<>"","DISC-GAP-" & TEXT(22,"000"),"")
A26: =IF(B26<>"","DISC-GAP-" & TEXT(23,"000"),"")
A27: =IF(B27<>"","DISC-GAP-" & TEXT(24,"000"),"")
A28: =IF(B28<>"","DISC-GAP-" & TEXT(25,"000"),"")
A29: =IF(B29<>"","DISC-GAP-" & TEXT(26,"000"),"")
A30: =IF(B30<>"","DISC-GAP-" & TEXT(27,"000"),"")
A31: =IF(B31<>"","DISC-GAP-" & TEXT(28,"000"),"")
A32: =IF(B32<>"","DISC-GAP-" & TEXT(29,"000"),"")
A33: =IF(B33<>"","DISC-GAP-" & TEXT(30,"000"),"")
A34: =IF(B34<>"","DISC-GAP-" & TEXT(31,"000"),"")
A35: =IF(B35<>"","DISC-GAP-" & TEXT(32,"000"),"")
A36: =IF(B36<>"","DISC-GAP-" & TEXT(33,"000"),"")
A37: =IF(B37<>"","DISC-GAP-" & TEXT(34,"000"),"")
A38: =IF(B38<>"","DISC-GAP-" & TEXT(35,"000"),"")
A39: =IF(B39<>"","DISC-GAP-" & TEXT(36,"000"),"")
A40: =IF(B40<>"","DISC-GAP-" & TEXT(37,"000"),"")
...

Sheet Evidence_Register
A1: Discovery Evidence Register
A2: 📋 Track all evidence collected during network discovery (scan results, configs, diagrams, documentation)
A3: Evidence ID | B3: Evidence Type | C3: Description | D3: File Location | E3: Collection Date | F3: Collected By | G3: Status | H3: Notes
A4: =IF(B4<>"","EVID-" & TEXT(1,"000"),"")
A5: =IF(B5<>"","EVID-" & TEXT(2,"000"),"")
A6: =IF(B6<>"","EVID-" & TEXT(3,"000"),"")
A7: =IF(B7<>"","EVID-" & TEXT(4,"000"),"")
A8: =IF(B8<>"","EVID-" & TEXT(5,"000"),"")
A9: =IF(B9<>"","EVID-" & TEXT(6,"000"),"")
A10: =IF(B10<>"","EVID-" & TEXT(7,"000"),"")
A11: =IF(B11<>"","EVID-" & TEXT(8,"000"),"")
A12: =IF(B12<>"","EVID-" & TEXT(9,"000"),"")
A13: =IF(B13<>"","EVID-" & TEXT(10,"000"),"")
A14: =IF(B14<>"","EVID-" & TEXT(11,"000"),"")
A15: =IF(B15<>"","EVID-" & TEXT(12,"000"),"")
A16: =IF(B16<>"","EVID-" & TEXT(13,"000"),"")
A17: =IF(B17<>"","EVID-" & TEXT(14,"000"),"")
A18: =IF(B18<>"","EVID-" & TEXT(15,"000"),"")
A19: =IF(B19<>"","EVID-" & TEXT(16,"000"),"")
A20: =IF(B20<>"","EVID-" & TEXT(17,"000"),"")
A21: =IF(B21<>"","EVID-" & TEXT(18,"000"),"")
A22: =IF(B22<>"","EVID-" & TEXT(19,"000"),"")
A23: =IF(B23<>"","EVID-" & TEXT(20,"000"),"")
A24: =IF(B24<>"","EVID-" & TEXT(21,"000"),"")
A25: =IF(B25<>"","EVID-" & TEXT(22,"000"),"")
A26: =IF(B26<>"","EVID-" & TEXT(23,"000"),"")
A27: =IF(B27<>"","EVID-" & TEXT(24,"000"),"")
A28: =IF(B28<>"","EVID-" & TEXT(25,"000"),"")
A29: =IF(B29<>"","EVID-" & TEXT(26,"000"),"")
A30: =IF(B30<>"","EVID-" & TEXT(27,"000"),"")
A31: =IF(B31<>"","EVID-" & TEXT(28,"000"),"")
A32: =IF(B32<>"","EVID-" & TEXT(29,"000"),"")
A33: =IF(B33<>"","EVID-" & TEXT(30,"000"),"")
A35: Evidence Types: Configuration Backup, Discovery Report (nmap XML), Network Diagram, Scan Results, SNMP Walk Output, Cloud Discovery JSON, Documentation, Screenshots
A36: 💡 TIP: Store evidence in organized directory structure: /evidence/discovery/YYYY-MM-DD/ with subdirectories for scans, configs, diagrams, etc.

Sheet Validation_Rules
A1: Data Validation Rules & Quality Checks
A2: This sheet defines data quality rules to ensure inventory completeness and accuracy
A4: Required Field Validation
A5: Field | B5: Required | C5: Validation Rule | D5: Status
A6: Device Type | B6: Yes | C6: Must be selected from dropdown | D6: =IF(COUNTBLANK(Device_Inventory!B4:B153)=150,"✔ All blank (OK)","⚠ Check required")
A7: Hostname | B7: Yes | C7: Must not be blank | D7: =IF(COUNTBLANK(Device_Inventory!D4:D153)=150,"✔ All blank (OK)","⚠ Check required")
A8: Primary IP | B8: Yes | C8: Must not be blank | D8: =IF(COUNTBLANK(Device_Inventory!E4:E153)=150,"✔ All blank (OK)","⚠ Check required")
A9: Location | B9: Yes | C9: Must not be blank | D9: =IF(COUNTBLANK(Device_Inventory!G4:G153)=150,"✔ All blank (OK)","⚠ Check required")
A10: Criticality | B10: Yes | C10: Must be selected from dropdown | D10: =IF(COUNTBLANK(Device_Inventory!J4:J153)=150,"✔ All blank (OK)","⚠ Check required")
A11: Status | B11: Yes | C11: Must be selected from dropdown | D11: =IF(COUNTBLANK(Device_Inventory!Q4:Q153)=150,"✔ All blank (OK)","⚠ Check required")
A13: Data Quality Checks
A14: Check | B14: Description | C14: Status
A15: No Duplicate IPs | B15: Check for duplicate primary IPs | C15: Manual verification required
A16: No Duplicate Hostnames | B16: Check for duplicate hostnames | C16: Manual verification required
A17: Valid IP Format | B17: Verify all IPs follow IPv4 format | C17: Manual verification required
A18: Criticality Assigned | B18: All active devices have criticality | C18: =IF(COUNTIFS(Device_Inventory!Q4:Q153,"Active",Device_Inventory!J4:J153,"")=0,"✔ OK","⚠ Missing criticality")
A19: Owner Assigned | B19: All critical/high devices have owner | C19: Manual verification required
A20: Recent Discovery | B20: All devices discovered within last 90 days | C20: Manual verification required
A22: Inventory Completeness Metrics
A23: Metric | B23: Target | C23: Actual | D23: Status
A24: Device Type Filled | B24: 100% | C24: =COUNTA(Device_Inventory!B4:B153)/COUNTA(Device_Inventory!A4:A153) | D24: =IF(C24>=1,"✔","⚠ ")
A25: Hostname Filled | B25: 100% | C25: =COUNTA(Device_Inventory!D4:D153)/COUNTA(Device_Inventory!A4:A153) | D25: =IF(C25>=1,"✔","⚠ ")
A26: Criticality Assigned | B26: 100% | C26: =COUNTA(Device_Inventory!J4:J153)/COUNTA(Device_Inventory!A4:A153) | D26: =IF(C26>=1,"✔","⚠ ")
A27: Owner Assigned | B27: ≥80% | C27: =COUNTA(Device_Inventory!K4:K153)/COUNTA(Device_Inventory!A4:A153) | D27: =IF(C27>=0.8,"✔","⚠ ")
A28: Firmware Version | B28: ≥70% | C28: =COUNTA(Device_Inventory!N4:N153)/COUNTA(Device_Inventory!A4:A153) | D28: =IF(C28>=0.7,"✔","⚠ ")
