Workbook

Sheet Instructions & Legend
A1: ISMS-IMP-A.5.31.2 - Applicability Matrix ISO/IEC 27001:2022 - Control A.5.31: Legal, Statutory, Regulatory and Contractual Requirements
A3: Document Information
A4: Document ID | B4: ISMS-IMP-A.5.31.2
A5: Workbook Title | B5: Applicability Matrix
A6: Control Reference | B6: ISO/IEC 27001:2022 - Control A.5.31: Legal, Statutory, Regulatory and Contractual Requirements
A7: Version | B7: 1.0
A8: Assessment Date
A9: Completed By
A10: Organisation
A12: Instructions
A13: 1. Complete the Applicability Assessment — map each regulatory requirement to the organisation.
A14: 2. Use the Template Blank sheet to assess newly identified regulations.
A15: 3. Document applicability rationale for included and excluded requirements.
A16: 4. Assign compliance owners and target compliance dates for each applicable requirement.
A17: 5. Review the Summary Dashboard for applicability assessment completeness.
A18: 6. Maintain the Evidence Register with applicability determination records.
A19: 7. Obtain final approval and sign-off in the Approval Sign-Off sheet.
A21: Status Legend
A22: Symbol | B22: Status | C22: Description
A23: ✓ | B23: Compliant / Complete | C23: Requirement fully met
A24: ⚠ | B24: Partial / In Progress | C24: Partially met or in progress
A25: ✗ | B25: Non-Compliant / Not Started | C25: Requirement not met
A26: — | B26: Not Applicable | C26: Not applicable to this assessment

Sheet Applicability Assessment
A1: SECTION A: REGULATION IDENTIFICATION
A2: Regulation ID: | B2: REG-EU-002
A3: Regulation Name: | B3: Network and Information Systems Directive (Revised)
A4: Jurisdiction: | B4: European Union
A5: Issuing Authority: | B5: European Commission
A6: Citation: | B6: Directive (EU) 2022/2555
A7: Effective Date: | B7: 2024-10-17
A8: Assessment Date:
A9: Assessor: | B9: Compliance Officer / CISO
A10: Trigger Event: | B10: Annual review of Tier 2 regulations; assessing if NIS2 thresholds now met
A12: SECTION B: GEOGRAPHIC SCOPE ASSESSMENT
A13: Question | C13: Y/N | D13: Evidence / Notes
A14: G1: Physical operations in jurisdiction?
A15: G2: Legal entities registered in jurisdiction?
A16: G3: Employees located in jurisdiction?
A17: G4: Customers located in jurisdiction? | C17: Y
A18: G5: Data subjects in jurisdiction? | C18: Y
A19: G6: Actively targeting jurisdiction (marketing, sales)?
A20: G7: Extraterritorial application to [Organisation]? | C20: Y
A22: Geographic Score: | C22: =COUNTIF(C14:C20,"Y")
A23: Geographic Rating: | C23: =IF(C22<=1,"Low",IF(C22<=3,"Moderate","High"))
A25: SECTION C: OPERATIONAL SCOPE ASSESSMENT
A26: Question | C26: Y/N | D26: Evidence / Notes
A27: O1: Services offered covered by regulation? | C27: Y
A28: O2: Industry sectors operated in covered?
A29: O3: Data types processed covered by regulation? | C29: Y
A30: O4: Size/revenue/employee thresholds met?
A31: O5: Specific operations or activities covered?
A33: Operational Score: | C33: =COUNTIF(C27:C31,"Y")
A34: Operational Rating: | C34: =IF(C33<=1,"Low",IF(C33<=3,"Moderate","High"))
A36: SECTION D: CONTRACTUAL SCOPE ASSESSMENT
A37: Question | C37: Y/N | D37: Evidence / Notes
A38: C1: Contracts explicitly require compliance?
A39: C2: Certifications/attestations required?
A40: C3: Audit rights granted to customers/partners?
A41: C4: Market expectation or industry norm? | C41: Y
A43: Contractual Score: | C43: =COUNTIF(C38:C41,"Y")
A44: Contractual Rating: | C44: =IF(C43=0,"None",IF(C43<=2,"Moderate","High"))
A46: SECTION E: OVERALL DETERMINATION
A47: Summary of Assessment Scores:
...

Sheet Template Blank
A1: SECTION A: REGULATION IDENTIFICATION
A2: Regulation ID:
A3: Regulation Name:
A4: Jurisdiction:
A5: Issuing Authority:
A6: Citation:
A7: Effective Date:
A8: Assessment Date:
A9: Assessor:
A10: Trigger Event:
A12: SECTION B: GEOGRAPHIC SCOPE ASSESSMENT
A13: Question | C13: Y/N | D13: Evidence / Notes
A14: G1: Physical operations in jurisdiction?
A15: G2: Legal entities registered in jurisdiction?
A16: G3: Employees located in jurisdiction?
A17: G4: Customers located in jurisdiction?
A18: G5: Data subjects in jurisdiction?
A19: G6: Actively targeting jurisdiction (marketing, sales)?
A20: G7: Extraterritorial application to [Organisation]?
A22: Geographic Score: | C22: =COUNTIF(C14:C20,"Y")
A23: Geographic Rating: | C23: =IF(C22<=1,"Low",IF(C22<=3,"Moderate","High"))
A25: SECTION C: OPERATIONAL SCOPE ASSESSMENT
A26: Question | C26: Y/N | D26: Evidence / Notes
A27: O1: Services offered covered by regulation?
A28: O2: Industry sectors operated in covered?
A29: O3: Data types processed covered by regulation?
A30: O4: Size/revenue/employee thresholds met?
A31: O5: Specific operations or activities covered?
A33: Operational Score: | C33: =COUNTIF(C27:C31,"Y")
A34: Operational Rating: | C34: =IF(C33<=1,"Low",IF(C33<=3,"Moderate","High"))
A36: SECTION D: CONTRACTUAL SCOPE ASSESSMENT
A37: Question | C37: Y/N | D37: Evidence / Notes
A38: C1: Contracts explicitly require compliance?
A39: C2: Certifications/attestations required?
A40: C3: Audit rights granted to customers/partners?
A41: C4: Market expectation or industry norm?
A43: Contractual Score: | C43: =COUNTIF(C38:C41,"Y")
A44: Contractual Rating: | C44: =IF(C43=0,"None",IF(C43<=2,"Moderate","High"))
A46: SECTION E: OVERALL DETERMINATION
A47: Summary of Assessment Scores:
...

Sheet Summary Dashboard
A1: APPLICABILITY MATRIX — SUMMARY DASHBOARD
A2: ISO/IEC 27001:2022 — Control A.5.31: Legal, Statutory, Regulatory and Contractual Requirements | Applicability Matrix
A4: TABLE 1: ASSESSMENT AREA COMPLIANCE OVERVIEW
A5: Assessment Area | B5: Total Items | C5: Compliant | D5: Partial | E5: Non-Compliant | F5: N/A | G5: Compliance %
A6: Applicability Assessment | B6: =COUNTA('Applicability Assessment'!C2:C100) | C6: =COUNTIF('Applicability Assessment'!C2:C100,"Y") | D6: 0 | E6: =COUNTIF('Applicability Assessment'!C2:C100,"N") | F6: =B6-C6-D6-E6 | G6: =IFERROR(IF((B6-F6)=0,0,C6/(B6-F6)),"")
A7: TOTAL | B7: =SUM(B6:B6) | C7: =SUM(C6:C6) | D7: =SUM(D6:D6) | E7: =SUM(E6:E6) | F7: =SUM(F6:F6) | G7: =IFERROR(IF((B7-F7)=0,0,C7/(B7-F7)),"")
A9: TABLE 2: KEY METRICS
A10: Metric | B10: Value
A11: Total scope questions answered | B11: =COUNTA('Applicability Assessment'!C2:C100)
A12: Geographic scope indicators (Yes) | B12: =COUNTIF('Applicability Assessment'!C2:C24,"Y")
A13: Operational scope indicators (Yes) | B13: =COUNTIF('Applicability Assessment'!C25:C65,"Y")
A14: Contractual scope indicators (Yes) | B14: =COUNTIF('Applicability Assessment'!C36:C65,"Y")
A15: Negative scope determinations (No answers) | B15: =COUNTIF('Applicability Assessment'!C2:C100,"N")
A17: TABLE 3: CRITICAL FINDINGS REQUIRING IMMEDIATE ATTENTION
A18: Finding | B18: Count | C18: Action Required
A19: Total unanswered questions | B19: =COUNTBLANK('Applicability Assessment'!C2:C100) | C19: Complete all Y/N questions to produce valid applicability assessment
A20: Negative scope determinations (No answers) | B20: =COUNTIF('Applicability Assessment'!C2:C100,"N") | C20: Review each N answer with legal counsel to confirm exclusion rationale
A21: Geographic scope questions unanswered | B21: =COUNTBLANK('Applicability Assessment'!C2:C30) | C21: Complete all geographic scope questions before finalising applicability
A25: FINAL DECISION:
A28: NEXT REVIEW DETAILS
A29: Next Review Date:
A30: Review Responsible:
A31: Special Considerations:

Sheet Approval Sign-Off
A1: ASSESSMENT APPROVAL AND SIGN-OFF
A2: ISO/IEC 27001:2022 - Control A.5.31: Legal, Statutory, Regulatory and Contractual Requirements
A3: ASSESSMENT SUMMARY
A4: Document: | B4: ISMS-IMP-A.5.31.2 - Applicability Matrix
A5: Assessment Period:
A6: Overall Compliance Rating: | B6: =IFERROR(AVERAGE('Summary Dashboard'!G6:G6),"")
A7: Assessment Status:
A8: Assessed By:
A11: COMPLETED BY (ASSESSOR)
A12: Name:
A13: Title:
A14: Date:
A15: Signature:
A16: Comments:
A18: REVIEWED BY (INFORMATION SECURITY OFFICER)
A19: Name:
A20: Title:
A21: Date:
... A38: Special Considerations:
