Workbook

Sheet Executive Summary
A1: ISMS-OP-CHK-A.5.29 — Information Security During Disruption Compliance Checklist
A3: DOCUMENT INFORMATION
A4: Document ID | B4: ISMS-OP-CHK-A.5.29
A5: Source Policy | B5: ISMS-OP-POL-A.5.29
A6: ISO Controls | B6: Information Security During Disruption
A7: Generated | B7: 08.02.2026
A8: Prepared By
A9: Organisation
A10: Review Cycle | B10: Annual
A12: OVERALL COMPLIANCE STATUS
A13: Overall Compliance | B13: ='Dashboard'!G11
A14: Status | B14: =IF(Dashboard!G11="N/A","NOT ASSESSED",IF(ISNUMBER(VALUE(SUBSTITUTE(Dashboard!G11,"%",""))),IF(VALUE(SUBSTITUTE(Dashboard!G11,"%",""))>=90,"GREEN",IF(VALUE(SUBSTITUTE(Dashboard!G11,"%",""))>=70,"AMBER","RED")),"NOT ASSESSED"))
A16: KEY METRICS
A17: Total Requirements | B17: ='Dashboard'!B11
A18: Compliant | B18: ='Dashboard'!C11
A19: Partial | B19: ='Dashboard'!D11
A20: Non-Compliant | B20: ='Dashboard'!E11
A21: Not Applicable | B21: ='Dashboard'!F11
A22: Owner Coverage | B22: =IF(Dashboard!B11=0,"N/A",ROUND((COUNTA('Minimum Security Baseline'!F4:F6)+COUNTA('Tiered Security Posture'!F4:F8)+COUNTA('BC DR Plan Security Reqs'!F4:F11)+COUNTA('Recovery Site Security'!F4:F6)+COUNTA('Emergency Access Procedures'!F4:F6)+COUNTA('Personnel Availability'!F4:F8)+COUNTA('Post-Disruption Sec Validation'!F4:F8))/Dashboard!B11*100,0)&"%")
A24: DOMAIN STATUS SUMMARY
A25: Domain | B25: Compliance % | C25: Compliant | D25: Gaps | E25: Status
A26: Minimum Security Baseline | B26: ='Dashboard'!G4 | C26: ='Dashboard'!C4 | D26: ='Dashboard'!E4 | E26: =IF(Dashboard!G4="N/A","--",IF(ISNUMBER(VALUE(SUBSTITUTE(Dashboard!G4,"%",""))),IF(VALUE(SUBSTITUTE(Dashboard!G4,"%",""))>=90,"PASS",IF(VALUE(SUBSTITUTE(Dashboard!G4,"%",""))>=70,"REVIEW","FAIL")),"--"))
A27: Tiered Security Posture | B27: ='Dashboard'!G5 | C27: ='Dashboard'!C5 | D27: ='Dashboard'!E5 | E27: =IF(Dashboard!G5="N/A","--",IF(ISNUMBER(VALUE(SUBSTITUTE(Dashboard!G5,"%",""))),IF(VALUE(SUBSTITUTE(Dashboard!G5,"%",""))>=90,"PASS",IF(VALUE(SUBSTITUTE(Dashboard!G5,"%",""))>=70,"REVIEW","FAIL")),"--"))
A28: BC DR Plan Security Reqs | B28: ='Dashboard'!G6 | C28: ='Dashboard'!C6 | D28: ='Dashboard'!E6 | E28: =IF(Dashboard!G6="N/A","--",IF(ISNUMBER(VALUE(SUBSTITUTE(Dashboard!G6,"%",""))),IF(VALUE(SUBSTITUTE(Dashboard!G6,"%",""))>=90,"PASS",IF(VALUE(SUBSTITUTE(Dashboard!G6,"%",""))>=70,"REVIEW","FAIL")),"--"))
A29: Recovery Site Security | B29: ='Dashboard'!G7 | C29: ='Dashboard'!C7 | D29: ='Dashboard'!E7 | E29: =IF(Dashboard!G7="N/A","--",IF(ISNUMBER(VALUE(SUBSTITUTE(Dashboard!G7,"%",""))),IF(VALUE(SUBSTITUTE(Dashboard!G7,"%",""))>=90,"PASS",IF(VALUE(SUBSTITUTE(Dashboard!G7,"%",""))>=70,"REVIEW","FAIL")),"--"))
A30: Emergency Access Procedures | B30: ='Dashboard'!G8 | C30: ='Dashboard'!C8 | D30: ='Dashboard'!E8 | E30: =IF(Dashboard!G8="N/A","--",IF(ISNUMBER(VALUE(SUBSTITUTE(Dashboard!G8,"%",""))),IF(VALUE(SUBSTITUTE(Dashboard!G8,"%",""))>=90,"PASS",IF(VALUE(SUBSTITUTE(Dashboard!G8,"%",""))>=70,"REVIEW","FAIL")),"--"))
A31: Personnel Availability | B31: ='Dashboard'!G9 | C31: ='Dashboard'!C9 | D31: ='Dashboard'!E9 | E31: =IF(Dashboard!G9="N/A","--",IF(ISNUMBER(VALUE(SUBSTITUTE(Dashboard!G9,"%",""))),IF(VALUE(SUBSTITUTE(Dashboard!G9,"%",""))>=90,"PASS",IF(VALUE(SUBSTITUTE(Dashboard!G9,"%",""))>=70,"REVIEW","FAIL")),"--"))
A32: Post-Disruption Sec Validation | B32: ='Dashboard'!G10 | C32: ='Dashboard'!C10 | D32: ='Dashboard'!E10 | E32: =IF(Dashboard!G10="N/A","--",IF(ISNUMBER(VALUE(SUBSTITUTE(Dashboard!G10,"%",""))),IF(VALUE(SUBSTITUTE(Dashboard!G10,"%",""))>=90,"PASS",IF(VALUE(SUBSTITUTE(Dashboard!G10,"%",""))>=70,"REVIEW","FAIL")),"--"))
A34: CRITICAL ISSUES
A35: # | B35: Issue Description | C35: Domain | D35: Owner | E35: Due Date
A36: 1
A37: 2
A38: 3
A39: 4
A40: 5
A42: MANAGEMENT COMMENTARY
A43: [Enter management commentary on information security during disruption posture]
A47: APPROVAL
A48: Assessed By
A49: Name:
...

Sheet Dashboard
A1: Information Security During Disruption — Compliance Dashboard
A3: Domain | B3: Total Reqs | C3: Compliant | D3: Partial | E3: Non-Compliant | F3: N/A | G3: Compliance %
A4: Minimum Security Baseline | B4: =COUNTA('Minimum Security Baseline'!D4:D6) | C4: =COUNTIF('Minimum Security Baseline'!D4:D6,"Compliant") | D4: =COUNTIF('Minimum Security Baseline'!D4:D6,"Partial") | E4: =COUNTIF('Minimum Security Baseline'!D4:D6,"Non-Compliant") | F4: =COUNTIF('Minimum Security Baseline'!D4:D6,"N/A") | G4: =IF((B4-F4)=0,"N/A",ROUND(C4/(B4-F4)*100,1)&"%")
A5: Tiered Security Posture | B5: =COUNTA('Tiered Security Posture'!D4:D8) | C5: =COUNTIF('Tiered Security Posture'!D4:D8,"Compliant") | D5: =COUNTIF('Tiered Security Posture'!D4:D8,"Partial") | E5: =COUNTIF('Tiered Security Posture'!D4:D8,"Non-Compliant") | F5: =COUNTIF('Tiered Security Posture'!D4:D8,"N/A") | G5: =IF((B5-F5)=0,"N/A",ROUND(C5/(B5-F5)*100,1)&"%")
A6: BC DR Plan Security Reqs | B6: =COUNTA('BC DR Plan Security Reqs'!D4:D11) | C6: =COUNTIF('BC DR Plan Security Reqs'!D4:D11,"Compliant") | D6: =COUNTIF('BC DR Plan Security Reqs'!D4:D11,"Partial") | E6: =COUNTIF('BC DR Plan Security Reqs'!D4:D11,"Non-Compliant") | F6: =COUNTIF('BC DR Plan Security Reqs'!D4:D11,"N/A") | G6: =IF((B6-F6)=0,"N/A",ROUND(C6/(B6-F6)*100,1)&"%")
A7: Recovery Site Security | B7: =COUNTA('Recovery Site Security'!D4:D6) | C7: =COUNTIF('Recovery Site Security'!D4:D6,"Compliant") | D7: =COUNTIF('Recovery Site Security'!D4:D6,"Partial") | E7: =COUNTIF('Recovery Site Security'!D4:D6,"Non-Compliant") | F7: =COUNTIF('Recovery Site Security'!D4:D6,"N/A") | G7: =IF((B7-F7)=0,"N/A",ROUND(C7/(B7-F7)*100,1)&"%")
A8: Emergency Access Procedures | B8: =COUNTA('Emergency Access Procedures'!D4:D6) | C8: =COUNTIF('Emergency Access Procedures'!D4:D6,"Compliant") | D8: =COUNTIF('Emergency Access Procedures'!D4:D6,"Partial") | E8: =COUNTIF('Emergency Access Procedures'!D4:D6,"Non-Compliant") | F8: =COUNTIF('Emergency Access Procedures'!D4:D6,"N/A") | G8: =IF((B8-F8)=0,"N/A",ROUND(C8/(B8-F8)*100,1)&"%")
A9: Personnel Availability | B9: =COUNTA('Personnel Availability'!D4:D8) | C9: =COUNTIF('Personnel Availability'!D4:D8,"Compliant") | D9: =COUNTIF('Personnel Availability'!D4:D8,"Partial") | E9: =COUNTIF('Personnel Availability'!D4:D8,"Non-Compliant") | F9: =COUNTIF('Personnel Availability'!D4:D8,"N/A") | G9: =IF((B9-F9)=0,"N/A",ROUND(C9/(B9-F9)*100,1)&"%")
A10: Post-Disruption Sec Validation | B10: =COUNTA('Post-Disruption Sec Validation'!D4:D8) | C10: =COUNTIF('Post-Disruption Sec Validation'!D4:D8,"Compliant") | D10: =COUNTIF('Post-Disruption Sec Validation'!D4:D8,"Partial") | E10: =COUNTIF('Post-Disruption Sec Validation'!D4:D8,"Non-Compliant") | F10: =COUNTIF('Post-Disruption Sec Validation'!D4:D8,"N/A") | G10: =IF((B10-F10)=0,"N/A",ROUND(C10/(B10-F10)*100,1)&"%")
A11: TOTAL | B11: =SUM(B4:B10) | C11: =SUM(C4:C10) | D11: =SUM(D4:D10) | E11: =SUM(E4:E10) | F11: =SUM(F4:F10) | G11: =IF((B11-F11)=0,"N/A",ROUND(C11/(B11-F11)*100,1)&"%")
A13: COMPLIANCE BY STATUS
A14: Compliant | B14: =C11 | C14: =IF(B11=0,"",ROUND(B14/B11*100,1)&"%")
A15: Partial | B15: =D11 | C15: =IF(B11=0,"",ROUND(B15/B11*100,1)&"%")
A16: Non-Compliant | B16: =E11 | C16: =IF(B11=0,"",ROUND(B16/B11*100,1)&"%")
A17: N/A | B17: =F11 | C17: =IF(B11=0,"",ROUND(B17/B11*100,1)&"%")
A19: TOP GAPS (Manual Entry)
A20: Priority | B20: Domain | C20: Requirement | D20: Owner | E20: Due Date | F20: Status
A32: COMPLIANCE TREND (Manual Entry)
A33: Assessment Date | B33: Overall % | C33: Compliant | D33: Gaps | E33: Assessor | F33: Notes

Sheet Minimum Security Baseline
A1: Minimum Security Baseline — Compliance Checklist
A2: ISO/IEC 27001:2022 — Control A.5.29: Information Security During Disruption
A3: Req # | B3: Section | C3: Requirement | D3: Status | E3: Evidence | F3: Owner | G3: Due Date | H3: Notes
A4: A.5.29-01 | B4: The Following Security Controls | C4: The following security controls shall be maintained at all times, regardless of the disruption state. These controls are not subject to relaxation or exception:.
A5: A.5.29-02 | B5: Mandatory Tracking*: Any Approved | C5: Mandatory tracking*: Any approved control degradation shall immediately create a time-bound entry in the Security Debt Register, including: owner, compensating controls in effect, start date, target closure date, and evidence of closure upon remediation.
A6: A.5.29-03 | B6: Emergency Changes | C6: Emergency changes shall not disable security controls from the 'Never Acceptable' list (logging, authentication, encryption, firewalls, change management itself).

Sheet Tiered Security Posture
A1: Tiered Security Posture — Compliance Checklist
A2: ISO/IEC 27001:2022 — Control A.5.29: Information Security During Disruption
A3: Req # | B3: Section | C3: Requirement | D3: Status | E3: Evidence | F3: Owner | G3: Due Date | H3: Notes
A4: A.5.29-04 | B4: Operate At One Of Five Defined | C4: The organisation shall operate at one of five defined security posture levels. The current posture level determines which controls are fully active, which may be degraded, and what additional measures are required.
A5: A.5.29-05 | B5: Transitions Between Posture Levels | C5: Transitions between posture levels shall be formally authorised. Verbal authorisation is permitted in urgent situations, followed by written confirmation within 4 hours.
A6: A.5.29-06 | B6: Be Recorded With: Date/Time, Authorising | C6: Each transition shall be recorded with: date/time, authorising person, justification, current state, target state, and any controls affected.
A7: A.5.29-07 | B7: Be Informed Of The Current Security | C7: All personnel shall be informed of the current security posture level and associated requirements.
A8: A.5.29-08 | B8: Communication Delivery | C8: Communication delivery shall be verified (email sent, intranet banner live, collaboration platform message posted). Non-receipt triggers escalation to alternative communication methods.

Sheet BC DR Plan Security Reqs
A1: BC DR Plan Security Reqs — Compliance Checklist
A2: ISO/IEC 27001:2022 — Control A.5.29: Information Security During Disruption
A3: Req # | B3: Section | C3: Requirement | D3: Status | E3: Evidence | F3: Owner | G3: Due Date | H3: Notes
A4: A.5.29-09 | B4: Business Continuity And Disaster | C4: All business continuity and disaster recovery plans shall include security requirements reviewed and approved by the CISO. Security is not an afterthought in continuity planning — it is a design requirement.
A5: A.5.29-10 | B5: Bc/Dr Plans | C5: BC/DR plans shall address the following four areas:.
A6: A.5.29-11 | B6: Crisis Communication Participants | C6: All crisis communication participants shall authenticate using their organisational credentials.
A7: A.5.29-12 | B7: During Emergency Posture, If Mfa | C7: During Emergency posture, if MFA infrastructure is unavailable, participants shall use pre-shared authentication phrases to verify identity (rotated monthly, distributed via offline contact list).
A8: A.5.29-13 | B8: The Ciso Or Designated Backup | C8: The CISO or designated backup shall review and approve the security sections of all BC/DR plans before the plans are approved.
A9: A.5.29-14 | B9: Security Review | C9: Security review shall occur after each update to a BC/DR plan.
A10: A.5.29-15 | B10: At Least One Security-Specific Test | C10: At least one security-specific test scenario shall be included in annual BC/DR testing.
A11: A.5.29-16 | B11: Security Deviations Observed During | C11: Security deviations observed during testing shall be documented and addressed within 30 days.

Sheet Recovery Site Security
A1: Recovery Site Security — Compliance Checklist
A2: ISO/IEC 27001:2022 — Control A.5.29: Information Security During Disruption
A3: Req # | B3: Section | C3: Requirement | D3: Status | E3: Evidence | F3: Owner | G3: Due Date | H3: Notes
A4: A.5.29-17 | B4: Recovery Sites — Whether Hot, Warm | C4: Recovery sites — whether hot, warm, cold standby, or cloud-based disaster recovery environments — shall maintain security controls equivalent to the primary site. A recovery environment with weaker security than the primary site creates an exploitable gap.
A5: A.5.29-18 | B5: Failover Testing*: Annual Failover Test | C5: Failover testing*: Annual failover test to recovery site. Security validation during test shall confirm authentication works (including MFA), network segmentation is enforced, logging is active and forwarding to [SIEM], encryption is verified, and access controls match primary site. Security findings documented and remediated within 30 days.
A6: A.5.29-19 | B6: Recovery Site Security | C6: Recovery site security shall be verified:.

Sheet Emergency Access Procedures
A1: Emergency Access Procedures — Compliance Checklist
A2: ISO/IEC 27001:2022 — Control A.5.29: Information Security During Disruption
A3: Req # | B3: Section | C3: Requirement | D3: Status | E3: Evidence | F3: Owner | G3: Due Date | H3: Notes
A4: A.5.29-20 | B4: Maintain Pre-Configured Emergency Access | C4: The organisation shall maintain pre-configured emergency access accounts ('break-glass accounts') for scenarios where normal authentication or access systems are unavailable.
A5: A.5.29-21 | B5: Break-Glass Accounts And Procedures | C5: Break-glass accounts and procedures shall be tested at least annually to verify:.
A6: A.5.29-22 | B6: Test Results | C6: Test results shall be documented. Failed tests shall trigger immediate remediation.

Sheet Personnel Availability
A1: Personnel Availability — Compliance Checklist
A2: ISO/IEC 27001:2022 — Control A.5.29: Information Security During Disruption
A3: Req # | B3: Section | C3: Requirement | D3: Status | E3: Evidence | F3: Owner | G3: Due Date | H3: Notes
A4: A.5.29-23 | B4: Ensure That Personnel With Security | C4: The organisation shall ensure that personnel with security responsibilities are available during disruption events. Disruptions frequently occur outside business hours and may prevent normal access to the workplace.
A5: A.5.29-24 | B5: Key Security Roles | C5: Key security roles shall have designated backups documented in a succession plan.
A6: A.5.29-25 | B6: Contact Information For Security | C6: Contact information for security personnel shall be maintained offline — printed contact lists and/or encrypted USB — accessible when email, intranet, and other digital systems are unavailable.
A7: A.5.29-26 | B7: Cross-Training | C7: Cross-training shall ensure that at least two individuals can perform each critical security function (break-glass activation, log review, emergency access revocation, security posture assessment).
A8: A.5.29-27 | B8: On-Call Rotation | C8: On-call rotation shall be established for 24/7 coverage when the organisation operates at Elevated, Degraded, or Emergency posture levels.

Sheet Post-Disruption Sec Validation
A1: Post-Disruption Sec Validation — Compliance Checklist
A2: ISO/IEC 27001:2022 — Control A.5.29: Information Security During Disruption
A3: Req # | B3: Section | C3: Requirement | D3: Status | E3: Evidence | F3: Owner | G3: Due Date | H3: Notes
A4: A.5.29-28 | B4: Before Returning To Normal Posture Level | C4: Before returning to Normal posture level, the organisation shall validate that full security controls have been restored. The recovery-to-normal transition is not complete until security validation is signed off by the CISO.
A5: A.5.29-29 | B5: Security Relaxations Approved During A | C5: All security relaxations approved during a disruption shall be tracked in the Security Debt Register until fully remediated.
A6: A.5.29-30 | B6: Security Debt Older Than 30 Days | C6: Security debt older than 30 days shall be escalated to the CISO with a remediation plan and revised target date.
A7: A.5.29-31 | B7: Security Debt Older Than 90 Days | C7: Security debt older than 90 days shall be escalated to Executive Management for a decision: either approve accelerated remediation with additional resources, or formally accept the residual risk with documented risk acceptance.
A8: A.5.29-32 | B8: Security Debt That Cannot Be Remediated | C8: Security debt that cannot be remediated shall be converted to a permanent risk entry in the Risk Register with compensating controls and annual review.
