Workbook

Sheet Executive Summary
A1: PRIV-CHK-A.3.17-19 — Privacy Awareness, NDAs and Clear Desk Compliance Checklist
A3: DOCUMENT INFORMATION
A4: Document ID | B4: PRIV-CHK-A.3.17-19
A5: Source Policy | B5: PRIV-POL-A.3.17-19
A6: ISO Controls | B6: Privacy Awareness, NDAs and Clear Desk
A7: Generated | B7: 30.09.2026
A8: Prepared By
A9: Organisation
A10: Review Cycle | B10: Annual
A12: OVERALL COMPLIANCE STATUS
A13: Overall Compliance | B13: ='Dashboard'!G7
A14: Status | B14: =IF(Dashboard!H7>0,"INCOMPLETE",IF(Dashboard!G7="N/A","NOT ASSESSED",IF(ISNUMBER(VALUE(SUBSTITUTE(Dashboard!G7,"%",""))),IF(VALUE(SUBSTITUTE(Dashboard!G7,"%",""))>=90,"GREEN",IF(VALUE(SUBSTITUTE(Dashboard!G7,"%",""))>=70,"AMBER","RED")),"NOT ASSESSED")))
A16: KEY METRICS
A17: Total Requirements | B17: ='Dashboard'!B7
A18: Compliant | B18: ='Dashboard'!C7
A19: Partial | B19: ='Dashboard'!D7
A20: Non-Compliant | B20: ='Dashboard'!E7
A21: Not Applicable | B21: ='Dashboard'!F7
A22: Unanswered | B22: ='Dashboard'!H7
A23: Owner Coverage | B23: =IF(Dashboard!B7=0,"N/A",ROUND((COUNTA('Privacy Awareness and Training'!F4:F8)+COUNTA('Confidentiality and NDA Requirements'!F4:F8)+COUNTA('Clear Desk and Clear Screen'!F4:F7))/Dashboard!B7*100,0)&"%")
A25: DOMAIN STATUS SUMMARY
A26: Domain | B26: Compliance % | C26: Compliant | D26: Gaps | E26: Status
A27: Privacy Awareness and Training | B27: ='Dashboard'!G4 | C27: ='Dashboard'!C4 | D27: ='Dashboard'!E4 | E27: =IF(Dashboard!H4>0,"INCOMPLETE",IF(Dashboard!G4="N/A","--",IF(ISNUMBER(VALUE(SUBSTITUTE(Dashboard!G4,"%",""))),IF(VALUE(SUBSTITUTE(Dashboard!G4,"%",""))>=90,"PASS",IF(VALUE(SUBSTITUTE(Dashboard!G4,"%",""))>=70,"REVIEW","FAIL")),"--")))
A28: Confidentiality and NDA Requirements | B28: ='Dashboard'!G5 | C28: ='Dashboard'!C5 | D28: ='Dashboard'!E5 | E28: =IF(Dashboard!H5>0,"INCOMPLETE",IF(Dashboard!G5="N/A","--",IF(ISNUMBER(VALUE(SUBSTITUTE(Dashboard!G5,"%",""))),IF(VALUE(SUBSTITUTE(Dashboard!G5,"%",""))>=90,"PASS",IF(VALUE(SUBSTITUTE(Dashboard!G5,"%",""))>=70,"REVIEW","FAIL")),"--")))
A29: Clear Desk and Clear Screen | B29: ='Dashboard'!G6 | C29: ='Dashboard'!C6 | D29: ='Dashboard'!E6 | E29: =IF(Dashboard!H6>0,"INCOMPLETE",IF(Dashboard!G6="N/A","--",IF(ISNUMBER(VALUE(SUBSTITUTE(Dashboard!G6,"%",""))),IF(VALUE(SUBSTITUTE(Dashboard!G6,"%",""))>=90,"PASS",IF(VALUE(SUBSTITUTE(Dashboard!G6,"%",""))>=70,"REVIEW","FAIL")),"--")))
A31: CRITICAL ISSUES
A32: # | B32: Issue Description | C32: Domain | D32: Owner | E32: Due Date
A33: 1
A34: 2
A35: 3
A36: 4
A37: 5
A39: MANAGEMENT COMMENTARY
A40: [Enter management commentary on privacy awareness, ndas and clear desk posture]
A44: APPROVAL
A45: Assessed By
A46: Name:
A47: Date:
A48: Signature:
A49: Decision:
...

Sheet Dashboard
A1: Privacy Awareness, NDAs and Clear Desk — Compliance Dashboard
A3: Domain | B3: Total Reqs | C3: Compliant | D3: Partial | E3: Non-Compliant | F3: N/A | G3: Compliance % | H3: Unassessed
A4: Privacy Awareness and Training | B4: =COUNTA('Privacy Awareness and Training'!A4:A8) | C4: =COUNTIF('Privacy Awareness and Training'!D4:D8,"Compliant") | D4: =COUNTIF('Privacy Awareness and Training'!D4:D8,"Partial") | E4: =COUNTIF('Privacy Awareness and Training'!D4:D8,"Non-Compliant") | F4: =COUNTIF('Privacy Awareness and Training'!D4:D8,"N/A") | G4: =IF((B4-F4)=0,"N/A",ROUND(C4/(B4-F4)*100,1)&"%") | H4: =B4-(C4+D4+E4+F4)
A5: Confidentiality and NDA Requirements | B5: =COUNTA('Confidentiality and NDA Requirements'!A4:A8) | C5: =COUNTIF('Confidentiality and NDA Requirements'!D4:D8,"Compliant") | D5: =COUNTIF('Confidentiality and NDA Requirements'!D4:D8,"Partial") | E5: =COUNTIF('Confidentiality and NDA Requirements'!D4:D8,"Non-Compliant") | F5: =COUNTIF('Confidentiality and NDA Requirements'!D4:D8,"N/A") | G5: =IF((B5-F5)=0,"N/A",ROUND(C5/(B5-F5)*100,1)&"%") | H5: =B5-(C5+D5+E5+F5)
A6: Clear Desk and Clear Screen | B6: =COUNTA('Clear Desk and Clear Screen'!A4:A7) | C6: =COUNTIF('Clear Desk and Clear Screen'!D4:D7,"Compliant") | D6: =COUNTIF('Clear Desk and Clear Screen'!D4:D7,"Partial") | E6: =COUNTIF('Clear Desk and Clear Screen'!D4:D7,"Non-Compliant") | F6: =COUNTIF('Clear Desk and Clear Screen'!D4:D7,"N/A") | G6: =IF((B6-F6)=0,"N/A",ROUND(C6/(B6-F6)*100,1)&"%") | H6: =B6-(C6+D6+E6+F6)
A7: TOTAL | B7: =SUM(B4:B6) | C7: =SUM(C4:C6) | D7: =SUM(D4:D6) | E7: =SUM(E4:E6) | F7: =SUM(F4:F6) | G7: =IF((B7-F7)=0,"N/A",ROUND(C7/(B7-F7)*100,1)&"%") | H7: =SUM(H4:H6)
A9: COMPLIANCE BY STATUS
A10: Compliant | B10: =C7 | C10: =IF(B7=0,"",ROUND(B10/B7*100,1)&"%")
A11: Partial | B11: =D7 | C11: =IF(B7=0,"",ROUND(B11/B7*100,1)&"%")
A12: Non-Compliant | B12: =E7 | C12: =IF(B7=0,"",ROUND(B12/B7*100,1)&"%")
A13: N/A | B13: =F7 | C13: =IF(B7=0,"",ROUND(B13/B7*100,1)&"%")
A15: TOP GAPS (Manual Entry)
A16: Priority | B16: Domain | C16: Requirement | D16: Owner | E16: Due Date | F16: Status
A28: COMPLIANCE TREND (Manual Entry)
A29: Assessment Date | B29: Overall % | C29: Compliant | D29: Gaps | E29: Assessor | F29: Notes

Sheet Privacy Awareness and Training
A1: Privacy Awareness and Training — Compliance Checklist
A2: ISO/IEC 27701:2025 — Controls A.3.17-19: Privacy Awareness, NDAs and Clear Desk
A3: Req # | B3: Section | C3: Requirement | D3: Status | E3: Evidence | F3: Owner | G3: Due Date | H3: Notes
A4: A.3.17-01 | B4: Training Applicability | C4: The organisation shall provide appropriate privacy awareness, education, and training relevant to each personnel category: all personnel receive general privacy awareness annually; personnel with PII access receive PII handling training on engagement plus annual refresher; personnel with elevated PII responsibility receive role-specific training on appointment plus annually; contractors receive minimum general privacy awareness before PII access is granted.
A5: A.3.17-02 | B5: Privacy Awareness Content | C5: General privacy awareness content shall address at minimum: what PII is and the heightened sensitivity of special categories; the organisation's legal obligations under GDPR and CH FADP; the individual's role in protecting PII; how to recognise a PII incident and how to report it; data subject rights and how to escalate requests; and consequences of PII handling failures (regulatory and disciplinary).
A6: A.3.17-03 | B6: Policy Update Notifications | C6: When a PIMS policy is substantially revised or a new policy is issued, affected personnel shall be notified of the change and its content relevant to their role, required to acknowledge the updated policy before its effective date, and provided with summary guidance where the policy change is material. Acknowledgment records shall be maintained per the Personnel Privacy Training and Acknowledgment Register.
A7: A.3.17-04 | B7: Training Records | C7: Training completion records shall be maintained per individual, including training module and version completed, date of completion, outcome, and next required refresher date. Training records shall be retained for the duration of employment plus 3 years.
A8: A.3.17-05 | B8: DPO Professional Development | C8: The DPO and privacy function shall receive ongoing professional development, including updates on regulatory developments, supervisory authority guidance, and changes to applicable privacy standards. Professional development activities and attendance shall be documented.

Sheet Confidentiality and NDA Requirements
A1: Confidentiality and NDA Requirements — Compliance Checklist
A2: ISO/IEC 27701:2025 — Controls A.3.17-19: Privacy Awareness, NDAs and Clear Desk
A3: Req # | B3: Section | C3: Requirement | D3: Status | E3: Evidence | F3: Owner | G3: Due Date | H3: Notes
A4: A.3.18-01 | B4: Who Must Sign | C4: The following persons and parties shall be bound by a signed confidentiality or non-disclosure obligation covering PII before access to PII is granted: employees (employment contract clause or separate NDA); contractors and consultants (contractor agreement clause or standalone NDA); temporary workers (staffing agency agreement or standalone NDA); PII processors (processor agreement per GDPR Article 28); professional advisors with PII access (engagement letter or NDA).
A5: A.3.18-02 | B5: Minimum PII Content in Agreements | C5: Confidentiality or non-disclosure agreements covering PII shall address: the obligation to process PII only for authorised purposes and under instruction; prohibition on disclosure of PII to unauthorised parties; obligation to protect PII using at least the organisation's required security measures; obligation to report suspected PII incidents without undue delay; survival of confidentiality obligations post-engagement; and consequences of breach.
A6: A.3.18-03 | B6: Confidentiality Agreement Register | C6: The DPO shall maintain a Confidentiality Agreement Register recording: party identity, agreement type, date signed, PII scope covered, and next review date. No PII access shall be granted without a register entry confirming a current, signed agreement is in place.
A7: A.3.18-04 | B7: Agreement Review | C7: Agreements covering PII shall be reviewed at minimum every 3 years or upon: regulatory change affecting the obligations; significant change to the processing activities covered; material change to an individual's role. Agreements that are out of date shall be refreshed before continued PII access is permitted.
A8: A.3.18-05 | B8: DPO Professional Secrecy | C8: The DPO is bound by professional secrecy (GDPR Article 38(5)) with respect to the performance of their tasks. This obligation is in addition to and does not replace the general confidentiality obligations applicable to all personnel.

Sheet Clear Desk and Clear Screen
A1: Clear Desk and Clear Screen — Compliance Checklist
A2: ISO/IEC 27701:2025 — Controls A.3.17-19: Privacy Awareness, NDAs and Clear Desk
A3: Req # | B3: Section | C3: Requirement | D3: Status | E3: Evidence | F3: Owner | G3: Due Date | H3: Notes
A4: A.3.19-01 | B4: Clear Desk Rules for PII | C4: PII documents shall not be left unattended on desks or in open areas; they shall be secured (in locked drawers, cabinets, or document safes) when a workspace is unoccupied. Special category PII documents require locked storage when unattended. PII documents awaiting destruction shall be placed in secure cross-cut shredding receptacles immediately upon completion of use — not in standard waste bins. In shared and hot-desk environments, PII documents must be cleared before vacating without exception.
A5: A.3.19-02 | B5: Clear Screen Rules for PII | C5: Workstations accessing PII shall lock automatically after a maximum idle period (configured per PRIV-IMP-A.3.17-19-TG). Personnel shall manually lock their screen before leaving a workstation unattended, even briefly. Screens displaying PII shall be positioned to minimise visibility to unauthorised persons; privacy screens shall be used in open-plan, public-facing, or shared environments where PII is routinely displayed.
A6: A.3.19-03 | B6: Meeting Room and Shared Display Controls | C6: PII shall not be projected or displayed in meeting rooms or on shared screens unless all attendees are authorised to view the PII. PII shall be closed or screened before external participants join a meeting. Shared display environments (screens, projectors) shall not cache or retain PII between sessions.
A7: A.3.19-04 | B7: Remote Working | C7: Clear desk and clear screen rules apply to remote working environments as fully as to office environments. PII documents used in remote working contexts shall be stored securely and not left visible to household members or others not authorised to access the PII. Personnel shall acknowledge remote working clear desk obligations, with acknowledgment records maintained.
