Workbook

Sheet Instructions & Legend
A1: ISMS-IMP-A.6.6.3 - NDA Review and Compliance ISO/IEC 27001:2022 - Control A.6.6: Confidentiality or Non-Disclosure Agreements
A3: Document Information
A4: Document ID | B4: ISMS-IMP-A.6.6.3
A5: Workbook Title | B5: NDA Review and Compliance
A6: Control Reference | B6: ISO/IEC 27001:2022 - Control A.6.6: Confidentiality or Non-Disclosure Agreements
A7: Version | B7: 1.0
A8: Assessment Date
A9: Completed By
A10: Organisation
A12: Instructions
A13: 1. Complete Periodic Review — document scheduled reviews of all NDA templates and executed agreements.
A14: 2. Complete Template Adequacy — assess whether templates remain adequate for current legal requirements.
A15: 3. Complete Coverage Analysis — verify all personnel and third parties requiring NDAs have signed.
A16: 4. Complete Compliance Check — identify any gaps in NDA coverage or non-compliant agreements.
A17: 5. Complete Gap Register — document missing NDAs and non-compliances with remediation plans.
A18: 6. Maintain the Evidence Register with review reports and remediation evidence.
A19: 7. Obtain final approval and sign-off in the Approval Sign-Off sheet.
A21: Status Legend
A22: Symbol | B22: Status | C22: Description
A23: ✓ | B23: Compliant / Complete | C23: Requirement fully met
A24: ⚠ | B24: Partial / In Progress | C24: Partially met or in progress
A25: ✗ | B25: Non-Compliant / Not Started | C25: Requirement not met
A26: — | B26: Not Applicable | C26: Not applicable to this assessment

Sheet Periodic Review
A1: PERIODIC REVIEW SCHEDULE AND TRACKING
A2: ISO/IEC 27001:2022 - Control A.6.6: Confidentiality or Non-Disclosure Agreements
A3: Review ID | B3: Review Type | C3: Review Scope | D3: Planned Date | E3: Actual Date | F3: Reviewer | G3: Findings Count | H3: Gaps Identified | I3: Status | J3: Next Review | K3: Notes
A4: REV-001 | B4: Annual Full Review | C4: [All NDAs] | D4: [DD.MM.YYYY] | E4: [DD.MM.YYYY] | F4: [Name] | G4: 0 | H4: 0 | I4: Scheduled | J4: [DD.MM.YYYY]

Sheet Template Adequacy
A1: NDA TEMPLATE ADEQUACY ASSESSMENT
A2: ISO/IEC 27001:2022 - Control A.6.6: Confidentiality or Non-Disclosure Agreements
A3: Template ID | B3: Template Name | C3: Last Legal Review | D3: Regulatory Current | E3: Covers All Info Types | F3: Post Term Adequate | G3: Remedies Adequate | H3: Jurisdiction Correct | I3: Overall Adequacy | J3: Score | K3: Action Required | L3: Notes
A4: TMPL-001 | B4: [Employment NDA] | C4: [DD.MM.YYYY] | D4: Adequate | E4: Adequate | F4: Adequate | G4: Adequate | H4: Adequate | I4: Adequate | J4: 5/5

Sheet Coverage Analysis
A1: NDA COVERAGE ANALYSIS
A2: ISO/IEC 27001:2022 - Control A.6.6: Confidentiality or Non-Disclosure Agreements
A3: Employees | B3: Total Count | C3: NDA Required | D3: NDA Signed | E3: Coverage Rate | F3: Expired NDAs | G3: Missing NDAs | H3: Gap Status | I3: Remediation Owner | J3: Notes
A4: Contractors
A5: Consultants
A6: Vendors
A7: Suppliers
A8: Partners
A9: Customers
A10: Board Members
A11: Visitors
A12: Other

Sheet Compliance Check
A1: NDA COMPLIANCE VERIFICATION
A2: ISO/IEC 27001:2022 - Control A.6.6: Confidentiality or Non-Disclosure Agreements
A3: NDA ID | B3: Counterparty | C3: Correctly Executed | D3: Within Validity | E3: Appropriate Template | F3: All Parties Signed | G3: Securely Stored | H3: Overall Compliance | I3: Issues Found | J3: Action Required | K3: Status
A4: NDA-001 | B4: [Counterparty Name] | C4: Yes | D4: Yes | E4: Yes | F4: Yes | G4: Yes | H4: Compliant | K4: No Action Needed

Sheet Gap Register
A1: NDA GAP REGISTER
A2: ISO/IEC 27001:2022 - Control A.6.6: Confidentiality or Non-Disclosure Agreements
A3: Gap ID | B3: Gap Type | C3: Description | D3: Affected Area | E3: Severity | F3: Identified Date | G3: Owner | H3: Remediation Action | I3: Target Date | J3: Status | K3: Closure Date | L3: Notes
A4: GAP-001 | B4: Missing NDA | C4: [Description] | D4: [Department] | E4: High | F4: [DD.MM.YYYY] | G4: [Name] | H4: [Obtain signed NDA] | I4: [DD.MM.YYYY] | J4: Open

Sheet Evidence Register
A1: EVIDENCE REGISTER
A2: ISO/IEC 27001:2022 - Control A.6.6: Confidentiality or Non-Disclosure Agreements
A4: Evidence ID | B4: Evidence Type | C4: Description | D4: Source / Location | E4: Collected By | F4: Collection Date | G4: Retention Date | H4: Notes
A5: EV-001 | B5: Policy Document | C5: [Description of evidence] | D5: [SharePoint/path] | E5: [Name] | F5: [DD.MM.YYYY] | G5: [DD.MM.YYYY]

Sheet Summary Dashboard
A1: NDA REVIEW AND COMPLIANCE — SUMMARY DASHBOARD
A2: ISO/IEC 27001:2022 — Control A.6.6: Confidentiality or Non-Disclosure Agreements
A4: TABLE 1: ASSESSMENT AREA COMPLIANCE OVERVIEW
A5: Assessment Area | B5: Total Items | C5: Compliant | D5: Partial | E5: Non-Compliant | F5: N/A | G5: Compliance %
A6: Periodic Review | B6: =COUNTA('Periodic Review'!I5:I54) | C6: =COUNTIF('Periodic Review'!I5:I54,"Completed") | D6: =COUNTIF('Periodic Review'!I5:I54,"In Progress")+COUNTIF('Periodic Review'!I5:I54,"Scheduled") | E6: =COUNTIF('Periodic Review'!I5:I54,"Overdue") | F6: =COUNTIF('Periodic Review'!I5:I54,"Cancelled") | G6: =IF((B6-F6)=0,0,C6/(B6-F6))
A7: Template Adequacy | B7: =COUNTA('Template Adequacy'!I5:I54) | C7: =COUNTIF('Template Adequacy'!I5:I54,"Adequate") | D7: =COUNTIF('Template Adequacy'!I5:I54,"Partially Adequate") | E7: =COUNTIF('Template Adequacy'!I5:I54,"Inadequate") | F7: =COUNTIF('Template Adequacy'!I5:I54,"Not Assessed") | G7: =IF((B7-F7)=0,0,C7/(B7-F7))
A8: Compliance Check | B8: =COUNTA('Compliance Check'!H5:H54) | C8: =COUNTIF('Compliance Check'!H5:H54,"Compliant") | D8: =COUNTIF('Compliance Check'!H5:H54,"Partially Compliant") | E8: =COUNTIF('Compliance Check'!H5:H54,"Non-Compliant") | F8: 0 | G8: =IF((B8-F8)=0,0,C8/(B8-F8))
A9: Gap Register | B9: =COUNTA('Gap Register'!J5:J54) | C9: =COUNTIF('Gap Register'!J5:J54,"Remediated")+COUNTIF('Gap Register'!J5:J54,"Verified Closed")+COUNTIF('Gap Register'!J5:J54,"Risk Accepted") | D9: =COUNTIF('Gap Register'!J5:J54,"In Progress") | E9: =COUNTIF('Gap Register'!J5:J54,"Open") | F9: 0 | G9: =IF((B9-F9)=0,0,C9/(B9-F9))
A10: TOTAL | B10: =SUM(B6:B9) | C10: =SUM(C6:C9) | D10: =SUM(D6:D9) | E10: =SUM(E6:E9) | F10: =SUM(F6:F9) | G10: =IF((B10-F10)=0,0,C10/(B10-F10))
A12: TABLE 2: KEY METRICS
A13: Metric | B13: Value
A14: Total Reviews Conducted | B14: =COUNTA('Periodic Review'!A5:A54)
A15: Reviews Completed | B15: =COUNTIF('Periodic Review'!I5:I54,"Completed")
A16: Reviews In Progress | B16: =COUNTIF('Periodic Review'!I5:I54,"In Progress")
A17: Overdue Reviews | B17: =COUNTIF('Periodic Review'!I5:I54,"Overdue")
A18: Annual Full Reviews | B18: =COUNTIF('Periodic Review'!B5:B54,"Annual Full Review")
A19: Templates Assessed for Adequacy | B19: =COUNTA('Template Adequacy'!A5:A54)
A20: Templates Adequate | B20: =COUNTIF('Template Adequacy'!I5:I54,"Adequate")
A21: Templates Partially Adequate | B21: =COUNTIF('Template Adequacy'!I5:I54,"Partially Adequate")
A22: Templates Inadequate | B22: =COUNTIF('Template Adequacy'!I5:I54,"Inadequate")
A23: NDAs Compliance Checked | B23: =COUNTA('Compliance Check'!A5:A54)
A24: NDAs Fully Compliant | B24: =COUNTIF('Compliance Check'!H5:H54,"Compliant")
A25: NDAs Partially Compliant | B25: =COUNTIF('Compliance Check'!H5:H54,"Partially Compliant")
A26: NDAs Non-Compliant | B26: =COUNTIF('Compliance Check'!H5:H54,"Non-Compliant")
A27: Total Gaps Identified | B27: =COUNTA('Gap Register'!A5:A54)
A28: Open Gaps | B28: =COUNTIF('Gap Register'!J5:J54,"Open")
A29: Gaps In Progress | B29: =COUNTIF('Gap Register'!J5:J54,"In Progress")
A30: Gaps Remediated | B30: =COUNTIF('Gap Register'!J5:J54,"Remediated")+COUNTIF('Gap Register'!J5:J54,"Verified Closed")
A31: Critical Gaps | B31: =COUNTIF('Gap Register'!E5:E54,"Critical")
A32: High Severity Gaps | B32: =COUNTIF('Gap Register'!E5:E54,"High")
A33: Gaps — Missing NDA Type | B33: =COUNTIF('Gap Register'!B5:B54,"Missing NDA")
A37: TABLE 3: CRITICAL FINDINGS REQUIRING IMMEDIATE ATTENTION
A38: Category | B38: Finding | C38: Count | D38: Severity | E38: Action Required
A39: Compliance | B39: Non-compliant NDAs identified | C39: =COUNTIF('Compliance Check'!H5:H54,"Non-Compliant") | D39: Critical | E39: Immediate
A40: Gap Management | B40: Critical severity gaps open | C40: =COUNTIF('Gap Register'!E5:E54,"Critical") | D40: Critical | E40: Immediate
A41: Gap Management | B41: Missing NDA gaps | C41: =COUNTIF('Gap Register'!B5:B54,"Missing NDA") | D41: Critical | E41: Immediate
A42: Gap Management | B42: High severity gaps open | C42: =COUNTIF('Gap Register'!E5:E54,"High") | D42: High | E42: Urgent
A43: Review Compliance | B43: Overdue NDA reviews | C43: =COUNTIF('Periodic Review'!I5:I54,"Overdue") | D43: High | E43: Urgent
A44: Template Adequacy | B44: Inadequate NDA templates | C44: =COUNTIF('Template Adequacy'!I5:I54,"Inadequate") | D44: High | E44: Urgent
A45: Compliance | B45: Partially compliant NDAs | C45: =COUNTIF('Compliance Check'!H5:H54,"Partially Compliant") | D45: Medium | E45: Plan
...

Sheet Approval Sign-Off
A1: ASSESSMENT APPROVAL AND SIGN-OFF
A2: ISO/IEC 27001:2022 - Control A.6.6: Confidentiality or Non-Disclosure Agreements
A3: ASSESSMENT SUMMARY
A4: Document: | B4: ISMS-IMP-A.6.6.3 - NDA Review and Compliance
A5: Assessment Period:
A6: Overall Compliance Rating: | B6: =IFERROR(AVERAGE('Summary Dashboard'!G6:G9),"")
A7: Assessment Status:
A8: Assessed By:
A11: COMPLETED BY (ASSESSOR)
A12: Name:
A13: Title:
A14: Date:
A15: Signature:
A16: Comments:
A18: REVIEWED BY (INFORMATION SECURITY OFFICER)
A19: Name:
A20: Title:
A21: Date:
... A38: Special Considerations:
