Workbook

Sheet Executive Summary
A1: PRIV-CHK-A.3.11-12 — Privacy Incident Management Compliance Checklist
A3: DOCUMENT INFORMATION
A4: Document ID | B4: PRIV-CHK-A.3.11-12
A5: Source Policy | B5: PRIV-POL-A.3.11-12
A6: ISO Controls | B6: Privacy Incident Management
A7: Generated | B7: 10.03.2026
A8: Prepared By
A9: Organisation
A10: Review Cycle | B10: Annual
A12: OVERALL COMPLIANCE STATUS
A13: Overall Compliance | B13: ='Dashboard'!G7
A14: Status | B14: =IF(Dashboard!G7="N/A","NOT ASSESSED",IF(ISNUMBER(VALUE(SUBSTITUTE(Dashboard!G7,"%",""))),IF(VALUE(SUBSTITUTE(Dashboard!G7,"%",""))>=90,"GREEN",IF(VALUE(SUBSTITUTE(Dashboard!G7,"%",""))>=70,"AMBER","RED")),"NOT ASSESSED"))
A16: KEY METRICS
A17: Total Requirements | B17: ='Dashboard'!B7
A18: Compliant | B18: ='Dashboard'!C7
A19: Partial | B19: ='Dashboard'!D7
A20: Non-Compliant | B20: ='Dashboard'!E7
A21: Not Applicable | B21: ='Dashboard'!F7
A22: Owner Coverage | B22: =IF(Dashboard!B7=0,"N/A",ROUND((COUNTA('Privacy Incident Response Planning'!F4:F8)+COUNTA('Privacy Incident Detection and Assessment'!F4:F7)+COUNTA('Breach Notification and Reporting'!F4:F8))/Dashboard!B7*100,0)&"%")
A24: DOMAIN STATUS SUMMARY
A25: Domain | B25: Compliance % | C25: Compliant | D25: Gaps | E25: Status
A26: Privacy Incident Response Planning | B26: ='Dashboard'!G4 | C26: ='Dashboard'!C4 | D26: ='Dashboard'!E4 | E26: =IF(Dashboard!G4="N/A","--",IF(ISNUMBER(VALUE(SUBSTITUTE(Dashboard!G4,"%",""))),IF(VALUE(SUBSTITUTE(Dashboard!G4,"%",""))>=90,"PASS",IF(VALUE(SUBSTITUTE(Dashboard!G4,"%",""))>=70,"REVIEW","FAIL")),"--"))
A27: Privacy Incident Detection and Assessment | B27: ='Dashboard'!G5 | C27: ='Dashboard'!C5 | D27: ='Dashboard'!E5 | E27: =IF(Dashboard!G5="N/A","--",IF(ISNUMBER(VALUE(SUBSTITUTE(Dashboard!G5,"%",""))),IF(VALUE(SUBSTITUTE(Dashboard!G5,"%",""))>=90,"PASS",IF(VALUE(SUBSTITUTE(Dashboard!G5,"%",""))>=70,"REVIEW","FAIL")),"--"))
A28: Breach Notification and Reporting | B28: ='Dashboard'!G6 | C28: ='Dashboard'!C6 | D28: ='Dashboard'!E6 | E28: =IF(Dashboard!G6="N/A","--",IF(ISNUMBER(VALUE(SUBSTITUTE(Dashboard!G6,"%",""))),IF(VALUE(SUBSTITUTE(Dashboard!G6,"%",""))>=90,"PASS",IF(VALUE(SUBSTITUTE(Dashboard!G6,"%",""))>=70,"REVIEW","FAIL")),"--"))
A30: CRITICAL ISSUES
A31: # | B31: Issue Description | C31: Domain | D31: Owner | E31: Due Date
A32: 1
A33: 2
A34: 3
A35: 4
A36: 5
A38: MANAGEMENT COMMENTARY
A39: [Enter management commentary on privacy incident management posture]
A43: APPROVAL
A44: Assessed By
A45: Name:
A46: Date:
A47: Signature:
A48: Decision:
A50: Reviewed By (DPO)
...

Sheet Dashboard
A1: Privacy Incident Management — Compliance Dashboard
A3: Domain | B3: Total Reqs | C3: Compliant | D3: Partial | E3: Non-Compliant | F3: N/A | G3: Compliance %
A4: Privacy Incident Response Planning | B4: =COUNTA('Privacy Incident Response Planning'!D4:D8) | C4: =COUNTIF('Privacy Incident Response Planning'!D4:D8,"Compliant") | D4: =COUNTIF('Privacy Incident Response Planning'!D4:D8,"Partial") | E4: =COUNTIF('Privacy Incident Response Planning'!D4:D8,"Non-Compliant") | F4: =COUNTIF('Privacy Incident Response Planning'!D4:D8,"N/A") | G4: =IF((B4-F4)=0,"N/A",ROUND(C4/(B4-F4)*100,1)&"%")
A5: Privacy Incident Detection and Assessment | B5: =COUNTA('Privacy Incident Detection and Assessment'!D4:D7) | C5: =COUNTIF('Privacy Incident Detection and Assessment'!D4:D7,"Compliant") | D5: =COUNTIF('Privacy Incident Detection and Assessment'!D4:D7,"Partial") | E5: =COUNTIF('Privacy Incident Detection and Assessment'!D4:D7,"Non-Compliant") | F5: =COUNTIF('Privacy Incident Detection and Assessment'!D4:D7,"N/A") | G5: =IF((B5-F5)=0,"N/A",ROUND(C5/(B5-F5)*100,1)&"%")
A6: Breach Notification and Reporting | B6: =COUNTA('Breach Notification and Reporting'!D4:D8) | C6: =COUNTIF('Breach Notification and Reporting'!D4:D8,"Compliant") | D6: =COUNTIF('Breach Notification and Reporting'!D4:D8,"Partial") | E6: =COUNTIF('Breach Notification and Reporting'!D4:D8,"Non-Compliant") | F6: =COUNTIF('Breach Notification and Reporting'!D4:D8,"N/A") | G6: =IF((B6-F6)=0,"N/A",ROUND(C6/(B6-F6)*100,1)&"%")
A7: TOTAL | B7: =SUM(B4:B6) | C7: =SUM(C4:C6) | D7: =SUM(D4:D6) | E7: =SUM(E4:E6) | F7: =SUM(F4:F6) | G7: =IF((B7-F7)=0,"N/A",ROUND(C7/(B7-F7)*100,1)&"%")
A9: COMPLIANCE BY STATUS
A10: Compliant | B10: =C7 | C10: =IF(B7=0,"",ROUND(B10/B7*100,1)&"%")
A11: Partial | B11: =D7 | C11: =IF(B7=0,"",ROUND(B11/B7*100,1)&"%")
A12: Non-Compliant | B12: =E7 | C12: =IF(B7=0,"",ROUND(B12/B7*100,1)&"%")
A13: N/A | B13: =F7 | C13: =IF(B7=0,"",ROUND(B13/B7*100,1)&"%")
A15: TOP GAPS (Manual Entry)
A16: Priority | B16: Domain | C16: Requirement | D16: Owner | E16: Due Date | F16: Status
A28: COMPLIANCE TREND (Manual Entry)
A29: Assessment Date | B29: Overall % | C29: Compliant | D29: Gaps | E29: Assessor | F29: Notes

Sheet Privacy Incident Response Planning
A1: Privacy Incident Response Planning — Compliance Checklist
A2: ISO/IEC 27701:2025 — Controls A.3.11-12: Privacy Incident Management
A3: Req # | B3: Section | C3: Requirement | D3: Status | E3: Evidence | F3: Owner | G3: Due Date | H3: Notes
A4: A.3.11-01 | B4: Privacy Incident Response Plan | C4: The organisation shall maintain a documented Privacy Incident Response Plan (PIRP) that defines: the definition of a privacy incident; roles and responsibilities during an incident; the incident lifecycle (detect, contain, assess, notify, remediate, review); escalation paths; and communication protocols for supervisory authorities and data subjects.
A5: A.3.11-02 | B5: Severity Classification | C5: The PIRP shall define incident severity tiers. At minimum: Critical (large-scale RESTRICTED PII breach, likely significant harm to data subjects — e.g., medical data of 1,000+ individuals, financial fraud enabling data); High (RESTRICTED PII of any scale or CONFIDENTIAL PII of significant scale, likely harm to individuals); Medium (CONFIDENTIAL PII, limited scope, low individual harm risk); Low (internal breach, no external exposure, negligible individual harm risk). Severity tier determines response timeline and notification obligations.
A6: A.3.11-03 | B6: Breach Register | C6: The DPO shall maintain a Privacy Breach Register logging all confirmed privacy incidents, regardless of severity. Register entries shall include: incident date, detection date, nature of PII compromised, number of data subjects affected, categories of PII, cause, containment actions, notification status, and remediation outcome. The register shall be retained for minimum 5 years.
A7: A.3.11-04 | B7: Incident Response Team | C7: A Privacy Incident Response Team (PIRT) shall be designated, comprising at minimum: DPO (incident coordinator), CISO (technical lead), Legal/Compliance (notification and regulatory obligations), Communications (where data subject notification is required). PIRT members shall be familiar with the PIRP and trained in their incident roles.
A8: A.3.11-05 | B8: Reporting Obligation | C8: All personnel shall be trained and aware of their obligation to report suspected PII incidents immediately to the DPO (or Privacy Champion for first-line escalation). Personnel shall not attempt to independently resolve or conceal a suspected PII incident. Initial reports shall be made without undue delay upon suspicion — the 72-hour regulatory clock starts at the point the organisation becomes aware, not at confirmed breach.

Sheet Privacy Incident Detection and Assessment
A1: Privacy Incident Detection and Assessment — Compliance Checklist
A2: ISO/IEC 27701:2025 — Controls A.3.11-12: Privacy Incident Management
A3: Req # | B3: Section | C3: Requirement | D3: Status | E3: Evidence | F3: Owner | G3: Due Date | H3: Notes
A4: A.3.12-01 | B4: Incident Assessment | C4: Upon receipt of a privacy incident report, the DPO shall conduct an initial assessment within 24 hours to determine: whether a personal data breach (as defined by GDPR Article 4(12)) has occurred; the severity tier per PIRP criteria; whether notification obligations are triggered; and immediate containment actions required. Assessment shall be documented.
A5: A.3.12-02 | B5: Containment Actions | C5: Immediate containment actions shall be initiated upon confirmation of a privacy incident, proportionate to severity: access revocation for compromised accounts; isolation of affected systems; cessation of the processing activity causing the breach; notification to processors or sub-processors if the incident originates in their systems. Containment actions and timelines shall be documented.
A6: A.3.12-03 | B6: Root Cause Analysis | C6: Following containment, a root cause analysis (RCA) shall be conducted for all High and Critical incidents, and for any incident resulting in supervisory authority notification. The RCA shall identify the technical and procedural causes and propose remediation measures to prevent recurrence. RCA documentation shall be retained for 5 years.
A7: A.3.12-04 | B7: Post-Incident Review | C7: A post-incident review shall be conducted after closure of all High and Critical incidents. The review shall assess: effectiveness of the response; adequacy of the PIRP; lessons learned; and whether PIMS controls require updating. Review outcomes shall be presented to Executive Management and shall feed into the PIMS continual improvement programme.

Sheet Breach Notification and Reporting
A1: Breach Notification and Reporting — Compliance Checklist
A2: ISO/IEC 27701:2025 — Controls A.3.11-12: Privacy Incident Management
A3: Req # | B3: Section | C3: Requirement | D3: Status | E3: Evidence | F3: Owner | G3: Due Date | H3: Notes
A4: A.3.12-05 | B4: Supervisory Authority Notification | C4: Where a personal data breach is likely to result in a risk to the rights and freedoms of natural persons, the supervisory authority shall be notified without undue delay and within 72 hours of the organisation becoming aware of the breach (GDPR Article 33). Notification shall include the information required by Article 33(3): nature of breach, categories and approximate numbers of data subjects and records affected, DPO contact, likely consequences, and measures taken or proposed.
A5: A.3.12-06 | B5: Late Notification | C5: Where notification to the supervisory authority cannot be made within 72 hours, the notification shall be accompanied by reasons for the delay. The DPO shall document the reason for delay in the Breach Register. Late notification does not avoid the notification obligation — it must still be made as soon as practicable after the 72-hour window.
A6: A.3.12-07 | B6: Data Subject Notification | C6: Where a personal data breach is likely to result in a high risk to the rights and freedoms of natural persons, affected data subjects shall be notified without undue delay (GDPR Article 34). Notification shall use clear and plain language and shall describe: the nature of the breach; name and contact details of the DPO; likely consequences; and measures taken or proposed to address the breach and mitigate its effects.
A7: A.3.12-08 | B7: Processor Notification to Controller | C7: Where the organisation acts as a PII processor and becomes aware of a breach involving customer PII, the organisation shall notify the customer (PII controller) without undue delay and in the timeframe required by the processor agreement (typically within 24 hours of confirmed breach). Processor notification obligations do not replace the controller's own regulatory notification obligations.
A8: A.3.12-09 | B8: Notification Records | C8: All notifications made to supervisory authorities, data subjects, and customers (as controller or processor) shall be documented in the Breach Register, including: notification date and time, content of notification, recipient, and any responses received. Notification records shall be retained for minimum 5 years.
