Workbook

Sheet Executive Summary
A1: ISMS-OP-CHK-A.8.30 — Outsourced Development Compliance Checklist
A3: DOCUMENT INFORMATION
A4: Document ID | B4: ISMS-OP-CHK-A.8.30
A5: Source Policy | B5: ISMS-OP-POL-A.8.30
A6: ISO Controls | B6: Outsourced Development
A7: Generated | B7: 30.09.2026
A8: Prepared By
A9: Organisation
A10: Review Cycle | B10: Annual
A12: OVERALL COMPLIANCE STATUS
A13: Overall Compliance | B13: ='Dashboard'!G13
A14: Status | B14: =IF(Dashboard!H13>0,"INCOMPLETE",IF(Dashboard!G13="N/A","NOT ASSESSED",IF(ISNUMBER(VALUE(SUBSTITUTE(Dashboard!G13,"%",""))),IF(VALUE(SUBSTITUTE(Dashboard!G13,"%",""))>=90,"GREEN",IF(VALUE(SUBSTITUTE(Dashboard!G13,"%",""))>=70,"AMBER","RED")),"NOT ASSESSED")))
A16: KEY METRICS
A17: Total Requirements | B17: ='Dashboard'!B13
A18: Compliant | B18: ='Dashboard'!C13
A19: Partial | B19: ='Dashboard'!D13
A20: Non-Compliant | B20: ='Dashboard'!E13
A21: Not Applicable | B21: ='Dashboard'!F13
A22: Unanswered | B22: ='Dashboard'!H13
A23: Owner Coverage | B23: =IF(Dashboard!B13=0,"N/A",ROUND((COUNTA('Vendor Security Assessment'!F4:F8)+COUNTA('Contractual Security Reqs'!F4:F4)+COUNTA('Secure Dev Reqs for Vendors'!F4:F11)+COUNTA('Code Review and Sec Testing'!F4:F10)+COUNTA('Acceptance Criteria'!F4:F5)+COUNTA('IP Property and Code Escrow'!F4:F8)+COUNTA('Ongoing Monitoring'!F4:F5)+COUNTA('Vendor Sec Incident Response'!F4:F4)+COUNTA('Data Protection Requirements'!F4:F14))/Dashboard!B13*100,0)&"%")
A25: DOMAIN STATUS SUMMARY
A26: Domain | B26: Compliance % | C26: Compliant | D26: Gaps | E26: Status
A27: Vendor Security Assessment | B27: ='Dashboard'!G4 | C27: ='Dashboard'!C4 | D27: ='Dashboard'!E4 | E27: =IF(Dashboard!H4>0,"INCOMPLETE",IF(Dashboard!G4="N/A","--",IF(ISNUMBER(VALUE(SUBSTITUTE(Dashboard!G4,"%",""))),IF(VALUE(SUBSTITUTE(Dashboard!G4,"%",""))>=90,"PASS",IF(VALUE(SUBSTITUTE(Dashboard!G4,"%",""))>=70,"REVIEW","FAIL")),"--")))
A28: Contractual Security Reqs | B28: ='Dashboard'!G5 | C28: ='Dashboard'!C5 | D28: ='Dashboard'!E5 | E28: =IF(Dashboard!H5>0,"INCOMPLETE",IF(Dashboard!G5="N/A","--",IF(ISNUMBER(VALUE(SUBSTITUTE(Dashboard!G5,"%",""))),IF(VALUE(SUBSTITUTE(Dashboard!G5,"%",""))>=90,"PASS",IF(VALUE(SUBSTITUTE(Dashboard!G5,"%",""))>=70,"REVIEW","FAIL")),"--")))
A29: Secure Dev Reqs for Vendors | B29: ='Dashboard'!G6 | C29: ='Dashboard'!C6 | D29: ='Dashboard'!E6 | E29: =IF(Dashboard!H6>0,"INCOMPLETE",IF(Dashboard!G6="N/A","--",IF(ISNUMBER(VALUE(SUBSTITUTE(Dashboard!G6,"%",""))),IF(VALUE(SUBSTITUTE(Dashboard!G6,"%",""))>=90,"PASS",IF(VALUE(SUBSTITUTE(Dashboard!G6,"%",""))>=70,"REVIEW","FAIL")),"--")))
A30: Code Review and Sec Testing | B30: ='Dashboard'!G7 | C30: ='Dashboard'!C7 | D30: ='Dashboard'!E7 | E30: =IF(Dashboard!H7>0,"INCOMPLETE",IF(Dashboard!G7="N/A","--",IF(ISNUMBER(VALUE(SUBSTITUTE(Dashboard!G7,"%",""))),IF(VALUE(SUBSTITUTE(Dashboard!G7,"%",""))>=90,"PASS",IF(VALUE(SUBSTITUTE(Dashboard!G7,"%",""))>=70,"REVIEW","FAIL")),"--")))
A31: Acceptance Criteria | B31: ='Dashboard'!G8 | C31: ='Dashboard'!C8 | D31: ='Dashboard'!E8 | E31: =IF(Dashboard!H8>0,"INCOMPLETE",IF(Dashboard!G8="N/A","--",IF(ISNUMBER(VALUE(SUBSTITUTE(Dashboard!G8,"%",""))),IF(VALUE(SUBSTITUTE(Dashboard!G8,"%",""))>=90,"PASS",IF(VALUE(SUBSTITUTE(Dashboard!G8,"%",""))>=70,"REVIEW","FAIL")),"--")))
A32: IP Property and Code Escrow | B32: ='Dashboard'!G9 | C32: ='Dashboard'!C9 | D32: ='Dashboard'!E9 | E32: =IF(Dashboard!H9>0,"INCOMPLETE",IF(Dashboard!G9="N/A","--",IF(ISNUMBER(VALUE(SUBSTITUTE(Dashboard!G9,"%",""))),IF(VALUE(SUBSTITUTE(Dashboard!G9,"%",""))>=90,"PASS",IF(VALUE(SUBSTITUTE(Dashboard!G9,"%",""))>=70,"REVIEW","FAIL")),"--")))
A33: Ongoing Monitoring | B33: ='Dashboard'!G10 | C33: ='Dashboard'!C10 | D33: ='Dashboard'!E10 | E33: =IF(Dashboard!H10>0,"INCOMPLETE",IF(Dashboard!G10="N/A","--",IF(ISNUMBER(VALUE(SUBSTITUTE(Dashboard!G10,"%",""))),IF(VALUE(SUBSTITUTE(Dashboard!G10,"%",""))>=90,"PASS",IF(VALUE(SUBSTITUTE(Dashboard!G10,"%",""))>=70,"REVIEW","FAIL")),"--")))
A34: Vendor Sec Incident Response | B34: ='Dashboard'!G11 | C34: ='Dashboard'!C11 | D34: ='Dashboard'!E11 | E34: =IF(Dashboard!H11>0,"INCOMPLETE",IF(Dashboard!G11="N/A","--",IF(ISNUMBER(VALUE(SUBSTITUTE(Dashboard!G11,"%",""))),IF(VALUE(SUBSTITUTE(Dashboard!G11,"%",""))>=90,"PASS",IF(VALUE(SUBSTITUTE(Dashboard!G11,"%",""))>=70,"REVIEW","FAIL")),"--")))
A35: Data Protection Requirements | B35: ='Dashboard'!G12 | C35: ='Dashboard'!C12 | D35: ='Dashboard'!E12 | E35: =IF(Dashboard!H12>0,"INCOMPLETE",IF(Dashboard!G12="N/A","--",IF(ISNUMBER(VALUE(SUBSTITUTE(Dashboard!G12,"%",""))),IF(VALUE(SUBSTITUTE(Dashboard!G12,"%",""))>=90,"PASS",IF(VALUE(SUBSTITUTE(Dashboard!G12,"%",""))>=70,"REVIEW","FAIL")),"--")))
A37: CRITICAL ISSUES
A38: # | B38: Issue Description | C38: Domain | D38: Owner | E38: Due Date
A39: 1
A40: 2
A41: 3
A42: 4
A43: 5
A45: MANAGEMENT COMMENTARY
A46: [Enter management commentary on outsourced development posture]
...

Sheet Dashboard
A1: Outsourced Development — Compliance Dashboard
A3: Domain | B3: Total Reqs | C3: Compliant | D3: Partial | E3: Non-Compliant | F3: N/A | G3: Compliance % | H3: Unassessed
A4: Vendor Security Assessment | B4: =COUNTA('Vendor Security Assessment'!A4:A8) | C4: =COUNTIF('Vendor Security Assessment'!D4:D8,"Compliant") | D4: =COUNTIF('Vendor Security Assessment'!D4:D8,"Partial") | E4: =COUNTIF('Vendor Security Assessment'!D4:D8,"Non-Compliant") | F4: =COUNTIF('Vendor Security Assessment'!D4:D8,"N/A") | G4: =IF((B4-F4)=0,"N/A",ROUND(C4/(B4-F4)*100,1)&"%") | H4: =B4-(C4+D4+E4+F4)
A5: Contractual Security Reqs | B5: =COUNTA('Contractual Security Reqs'!A4:A4) | C5: =COUNTIF('Contractual Security Reqs'!D4:D4,"Compliant") | D5: =COUNTIF('Contractual Security Reqs'!D4:D4,"Partial") | E5: =COUNTIF('Contractual Security Reqs'!D4:D4,"Non-Compliant") | F5: =COUNTIF('Contractual Security Reqs'!D4:D4,"N/A") | G5: =IF((B5-F5)=0,"N/A",ROUND(C5/(B5-F5)*100,1)&"%") | H5: =B5-(C5+D5+E5+F5)
A6: Secure Dev Reqs for Vendors | B6: =COUNTA('Secure Dev Reqs for Vendors'!A4:A11) | C6: =COUNTIF('Secure Dev Reqs for Vendors'!D4:D11,"Compliant") | D6: =COUNTIF('Secure Dev Reqs for Vendors'!D4:D11,"Partial") | E6: =COUNTIF('Secure Dev Reqs for Vendors'!D4:D11,"Non-Compliant") | F6: =COUNTIF('Secure Dev Reqs for Vendors'!D4:D11,"N/A") | G6: =IF((B6-F6)=0,"N/A",ROUND(C6/(B6-F6)*100,1)&"%") | H6: =B6-(C6+D6+E6+F6)
A7: Code Review and Sec Testing | B7: =COUNTA('Code Review and Sec Testing'!A4:A10) | C7: =COUNTIF('Code Review and Sec Testing'!D4:D10,"Compliant") | D7: =COUNTIF('Code Review and Sec Testing'!D4:D10,"Partial") | E7: =COUNTIF('Code Review and Sec Testing'!D4:D10,"Non-Compliant") | F7: =COUNTIF('Code Review and Sec Testing'!D4:D10,"N/A") | G7: =IF((B7-F7)=0,"N/A",ROUND(C7/(B7-F7)*100,1)&"%") | H7: =B7-(C7+D7+E7+F7)
A8: Acceptance Criteria | B8: =COUNTA('Acceptance Criteria'!A4:A5) | C8: =COUNTIF('Acceptance Criteria'!D4:D5,"Compliant") | D8: =COUNTIF('Acceptance Criteria'!D4:D5,"Partial") | E8: =COUNTIF('Acceptance Criteria'!D4:D5,"Non-Compliant") | F8: =COUNTIF('Acceptance Criteria'!D4:D5,"N/A") | G8: =IF((B8-F8)=0,"N/A",ROUND(C8/(B8-F8)*100,1)&"%") | H8: =B8-(C8+D8+E8+F8)
A9: IP Property and Code Escrow | B9: =COUNTA('IP Property and Code Escrow'!A4:A8) | C9: =COUNTIF('IP Property and Code Escrow'!D4:D8,"Compliant") | D9: =COUNTIF('IP Property and Code Escrow'!D4:D8,"Partial") | E9: =COUNTIF('IP Property and Code Escrow'!D4:D8,"Non-Compliant") | F9: =COUNTIF('IP Property and Code Escrow'!D4:D8,"N/A") | G9: =IF((B9-F9)=0,"N/A",ROUND(C9/(B9-F9)*100,1)&"%") | H9: =B9-(C9+D9+E9+F9)
A10: Ongoing Monitoring | B10: =COUNTA('Ongoing Monitoring'!A4:A5) | C10: =COUNTIF('Ongoing Monitoring'!D4:D5,"Compliant") | D10: =COUNTIF('Ongoing Monitoring'!D4:D5,"Partial") | E10: =COUNTIF('Ongoing Monitoring'!D4:D5,"Non-Compliant") | F10: =COUNTIF('Ongoing Monitoring'!D4:D5,"N/A") | G10: =IF((B10-F10)=0,"N/A",ROUND(C10/(B10-F10)*100,1)&"%") | H10: =B10-(C10+D10+E10+F10)
A11: Vendor Sec Incident Response | B11: =COUNTA('Vendor Sec Incident Response'!A4:A4) | C11: =COUNTIF('Vendor Sec Incident Response'!D4:D4,"Compliant") | D11: =COUNTIF('Vendor Sec Incident Response'!D4:D4,"Partial") | E11: =COUNTIF('Vendor Sec Incident Response'!D4:D4,"Non-Compliant") | F11: =COUNTIF('Vendor Sec Incident Response'!D4:D4,"N/A") | G11: =IF((B11-F11)=0,"N/A",ROUND(C11/(B11-F11)*100,1)&"%") | H11: =B11-(C11+D11+E11+F11)
A12: Data Protection Requirements | B12: =COUNTA('Data Protection Requirements'!A4:A14) | C12: =COUNTIF('Data Protection Requirements'!D4:D14,"Compliant") | D12: =COUNTIF('Data Protection Requirements'!D4:D14,"Partial") | E12: =COUNTIF('Data Protection Requirements'!D4:D14,"Non-Compliant") | F12: =COUNTIF('Data Protection Requirements'!D4:D14,"N/A") | G12: =IF((B12-F12)=0,"N/A",ROUND(C12/(B12-F12)*100,1)&"%") | H12: =B12-(C12+D12+E12+F12)
A13: TOTAL | B13: =SUM(B4:B12) | C13: =SUM(C4:C12) | D13: =SUM(D4:D12) | E13: =SUM(E4:E12) | F13: =SUM(F4:F12) | G13: =IF((B13-F13)=0,"N/A",ROUND(C13/(B13-F13)*100,1)&"%") | H13: =SUM(H4:H12)
A15: COMPLIANCE BY STATUS
A16: Compliant | B16: =C13 | C16: =IF(B13=0,"",ROUND(B16/B13*100,1)&"%")
A17: Partial | B17: =D13 | C17: =IF(B13=0,"",ROUND(B17/B13*100,1)&"%")
A18: Non-Compliant | B18: =E13 | C18: =IF(B13=0,"",ROUND(B18/B13*100,1)&"%")
A19: N/A | B19: =F13 | C19: =IF(B13=0,"",ROUND(B19/B13*100,1)&"%")
A21: TOP GAPS (Manual Entry)
A22: Priority | B22: Domain | C22: Requirement | D22: Owner | E22: Due Date | F22: Status
A34: COMPLIANCE TREND (Manual Entry)
A35: Assessment Date | B35: Overall % | C35: Compliant | D35: Gaps | E35: Assessor | F35: Notes

Sheet Vendor Security Assessment
A1: Vendor Security Assessment — Compliance Checklist
A2: ISO/IEC 27001:2022 — Control A.8.30: Outsourced Development
A3: Req # | B3: Section | C3: Requirement | D3: Status | E3: Evidence | F3: Owner | G3: Due Date | H3: Notes
A4: A.8.30-01 | B4: Before Engaging An External Development | C4: Before engaging an external development partner, the organisation shall conduct a security assessment to confirm the vendor's ability to meet information security requirements.
A5: A.8.30-02 | B5: Be Classified Based On The Highest | C5: Vendors shall be classified based on the highest risk factor present:.
A6: A.8.30-03 | B6: Tier Determination | C6: Tier determination shall be documented in the vendor security assessment record and reviewed upon scope changes.
A7: A.8.30-04 | B7: Assessment Results | C7: Assessment results shall be documented and retained for the duration of the vendor relationship plus 3 years.
A8: A.8.30-05 | B8: Vendors That Fail The Security | C8: Vendors that fail the security assessment shall not be engaged until identified deficiencies are remediated and verified.

Sheet Contractual Security Reqs
A1: Contractual Security Reqs — Compliance Checklist
A2: ISO/IEC 27001:2022 — Control A.8.30: Outsourced Development
A3: Req # | B3: Section | C3: Requirement | D3: Status | E3: Evidence | F3: Owner | G3: Due Date | H3: Notes
A4: A.8.30-06 | B4: Outsourced Development Agreements | C4: All outsourced development agreements shall include security requirements as contractual obligations.

Sheet Secure Dev Reqs for Vendors
A1: Secure Dev Reqs for Vendors — Compliance Checklist
A2: ISO/IEC 27001:2022 — Control A.8.30: Outsourced Development
A3: Req # | B3: Section | C3: Requirement | D3: Status | E3: Evidence | F3: Owner | G3: Due Date | H3: Notes
A4: A.8.30-07 | B4: The Organisation'S Secure Development | C4: The organisation's secure development standards shall be communicated to vendors at the start of every engagement.
A5: A.8.30-08 | B5: Provide Each Vendor With | C5: The organisation shall provide each vendor with:.
A6: A.8.30-09 | B6: Implement Controls To Mitigate Software | C6: Vendors shall implement controls to mitigate software supply chain risks in accordance with OWASP Top 10:2025 A03 (Software Supply Chain Failures):.
A7: A.8.30-10 | B7: Third-Party Dependencies | C7: All third-party dependencies shall be inventoried and tracked in an SBOM (CycloneDX or SPDX format).
A8: A.8.30-11 | B8: Be Pinned To Specific Versions And | C8: Dependencies shall be pinned to specific versions and sourced from trusted registries.
A9: A.8.30-12 | B9: Transitive Dependencies | C9: Transitive dependencies shall be included in vulnerability scanning.
A10: A.8.30-13 | B10: Monitor Dependencies Against | C10: Vendors shall monitor dependencies against vulnerability databases (NVD, OSV, GitHub Advisory Database) and remediate identified vulnerabilities within the agreed SLAs.
A11: A.8.30-14 | B11: Use Of Unmaintained Or End-Of-Life | C11: Use of unmaintained or end-of-life components shall require documented risk acceptance from the organisation.

Sheet Code Review and Sec Testing
A1: Code Review and Sec Testing — Compliance Checklist
A2: ISO/IEC 27001:2022 — Control A.8.30: Outsourced Development
A3: Req # | B3: Section | C3: Requirement | D3: Status | E3: Evidence | F3: Owner | G3: Due Date | H3: Notes
A4: A.8.30-15 | B4: Outsourced Code | C4: All outsourced code shall undergo independent security validation by the organisation before acceptance.
A5: A.8.30-16 | B5: Vendor-Side Test Results | C5: Vendor-side test results shall be shared with the organisation at agreed intervals (minimum: per milestone or sprint delivery).
A6: A.8.30-17 | B6: Minimum Testing Baseline*: All Security | C6: Minimum testing baseline*: All security testing shall, at a minimum, cover the OWASP Top 10:2025 categories.
A7: A.8.30-18 | B7: Penetration Testing | C7: All penetration testing shall be conducted by an independent external specialist company meeting at least one of:.
A8: A.8.30-19 | B8: Penetration Test Provider | C8: Penetration test provider shall not be the same entity as the development vendor to ensure independence.
A9: A.8.30-20 | B9: Vulnerabilities Identified During | C9: Vulnerabilities identified during testing shall be remediated by the vendor at the vendor's cost before the organisation accepts the deliverable. Critical and High vulnerabilities shall block acceptance.
A10: A.8.30-21 | B10: Vulnerabilities Identified In Vendor | C10: All vulnerabilities identified in vendor deliverables shall be tracked through resolution:.

Sheet Acceptance Criteria
A1: Acceptance Criteria — Compliance Checklist
A2: ISO/IEC 27001:2022 — Control A.8.30: Outsourced Development
A3: Req # | B3: Section | C3: Requirement | D3: Status | E3: Evidence | F3: Owner | G3: Due Date | H3: Notes
A4: A.8.30-22 | B4: Outsourced Deliverables | C4: Outsourced deliverables shall not be accepted or deployed to production until all acceptance criteria are satisfied.
A5: A.8.30-23 | B5: Acceptance Records | C5: Acceptance records shall be retained for the duration of the application lifecycle plus 3 years.

Sheet IP Property and Code Escrow
A1: IP Property and Code Escrow — Compliance Checklist
A2: ISO/IEC 27001:2022 — Control A.8.30: Outsourced Development
A3: Req # | B3: Section | C3: Requirement | D3: Status | E3: Evidence | F3: Owner | G3: Due Date | H3: Notes
A4: A.8.30-24 | B4: The Development Agreement | C4: The development agreement shall clearly define ownership of all work products, including source code, documentation, designs, and related intellectual property.
A5: A.8.30-25 | B5: The Default Position | C5: Where the organisation commissions bespoke development, the default position shall be that the organisation owns all intellectual property rights in the deliverables upon final payment or upon delivery if payment-on-delivery, whichever occurs first. Any deviation from full ownership shall be documented, approved by Legal and the CISO, and justified by business need.
A6: A.8.30-26 | B6: Vendor Retains Rights To Pre-Existing | C6: Where full ownership transfer is not possible (e.g., vendor retains rights to pre-existing components or frameworks), the agreement shall specify:.
A7: A.8.30-27 | B7: For Tier 1 Vendor Engagements Where | C7: For Tier 1 vendor engagements where the organisation does not hold the source code directly, the organisation shall establish a code escrow arrangement with an independent escrow agent (e.g., Escode, Codekeeper, or equivalent).
A8: A.8.30-28 | B8: Code Escrow Is Not Required, But | C8: Where the organisation holds source code directly in its own repositories, code escrow is not required, but the organisation shall maintain its own verified backups.

Sheet Ongoing Monitoring
A1: Ongoing Monitoring — Compliance Checklist
A2: ISO/IEC 27001:2022 — Control A.8.30: Outsourced Development
A3: Req # | B3: Section | C3: Requirement | D3: Status | E3: Evidence | F3: Owner | G3: Due Date | H3: Notes
A4: A.8.30-29 | B4: Continuously Monitor Outsourced | C4: The organisation shall continuously monitor outsourced development activities throughout the engagement lifecycle.
A5: A.8.30-30 | B5: Vendor Performance Scorecard | C5: Vendor performance scorecard shall be maintained quarterly, tracking: security testing compliance, SLA adherence, incident count, and audit findings. Results shall be reported to management annually.

Sheet Vendor Sec Incident Response
A1: Vendor Sec Incident Response — Compliance Checklist
A2: ISO/IEC 27001:2022 — Control A.8.30: Outsourced Development
A3: Req # | B3: Section | C3: Requirement | D3: Status | E3: Evidence | F3: Owner | G3: Due Date | H3: Notes
A4: A.8.30-31 | B4: Notify Executive Management Within 24 | C4: CISO shall notify Executive Management within 24 hours of any vendor incident affecting organisational data or systems.

Sheet Data Protection Requirements
A1: Data Protection Requirements — Compliance Checklist
A2: ISO/IEC 27001:2022 — Control A.8.30: Outsourced Development
A3: Req # | B3: Section | C3: Requirement | D3: Status | E3: Evidence | F3: Owner | G3: Due Date | H3: Notes
A4: A.8.30-32 | B4: Additional Data Protection Requirements | C4: Where outsourced development involves access to personal data or systems processing personal data, additional data protection requirements shall apply.
A5: A.8.30-33 | B5: In Accordance With Swiss Nfadp Art | C5: In accordance with Swiss nFADP Art. 9, the organisation shall execute a DPA with the development vendor that addresses:.
A6: A.8.30-34 | B6: A Transfer Impact Assessment | C6: A transfer impact assessment shall be completed per Swiss nFADP requirements.
A7: A.8.30-35 | B7: Appropriate Safeguards | C7: Appropriate safeguards shall be in place (e.g., Standard Contractual Clauses, adequacy decisions by the Federal Council, or binding corporate rules).
A8: A.8.30-36 | B8: Gdpr Chapter V Transfer Requirements | C8: Where the vendor processes data of EU/EEA individuals, GDPR Chapter V transfer requirements shall also be met.
A9: A.8.30-37 | B9: Not Receive Production Personal Data For | C9: Vendors shall not receive production personal data for development or testing purposes.
A10: A.8.30-38 | B10: Sanitised, Anonymised, Or Pseudonymised | C10: Where realistic data is required, sanitised, anonymised, or pseudonymised data shall be used.
A11: A.8.30-39 | B11: Any Use Of Transformed Personal Data | C11: Any use of transformed personal data shall be documented and approved by the Data Protection Officer or CISO.
A12: A.8.30-40 | B12: Rare Edge Cases), Data | C12: Where absolutely necessary to use production data (complex data relationships, rare edge cases), data shall be:.
A13: A.8.30-41 | B13: The Organisation | C13: Where a vendor security incident results in high risk to data subjects (nFADP Art. 24), the organisation shall notify the FDPIC without undue delay. High risk indicators include:.
A14: A.8.30-42 | B14: Vendor Dpa | C14: Vendor DPA shall require vendor to provide all information necessary for FDPIC notification within 48 hours of incident discovery.
