Workbook

Sheet Instructions & Legend
A1: ISMS-IMP-A.8.10.1 - Retention & Deletion Triggers Assessment ISO/IEC 27001:2022 - Control A.8.10: Information Deletion
A3: Document Information
A4: Document ID | B4: ISMS-IMP-A.8.10.1
A5: Workbook Title | B5: Retention & Deletion Triggers Assessment
A6: Control Reference | B6: ISO/IEC 27001:2022 - Control A.8.10: Information Deletion
A7: Version | B7: 1.0
A8: Assessment Date
A9: Completed By
A10: Organisation
A12: Instructions
A13: 1. Complete assessment sheets 2–6 in order, filling in all yellow-highlighted cells.
A14: 2. Use dropdown menus where provided for consistency.
A15: 3. Link supporting evidence to the Evidence Register using Column N.
A16: 4. Mark checklist items as compliant or non-compliant.
A17: 5. Review the Summary Dashboard for overall compliance status.
A18: 6. Document any gaps with remediation plans and target completion dates.
A19: 7. Obtain approval using the Approval Sign-Off sheet.
A20: 8. Review and update this assessment annually or when significant changes occur.
A22: Status Legend
A23: Symbol | B23: Status | C23: Description
A24: ✓ | B24: Compliant / Complete | C24: Requirement fully met
A25: ⚠ | B25: Partial / In Progress | C25: Partially met or in progress
A26: ✗ | B26: Non-Compliant / Not Started | C26: Requirement not met
A27: — | B27: Not Applicable | C27: Not applicable to this assessment

Sheet 2. Data Category Registry
A1: SHEET 2: DATA CATEGORY REGISTRY
A2: Policy Reference: ISMS-POL-A.8.10-S2.1, Section 2.1.1
A4: ASSESSMENT QUESTION: Have we identified and documented ALL data categories we process, including their characteristics, ownership, and storage locations?
A7: Complete the yellow-highlighted cells below. Use dropdowns where provided. Link evidence in Column N to Evidence Register sheet.
A9: Data Category / System Name | B9: Data Classification | C9: Business Owner | D9: Retention Period | E9: Legal/Regulatory Basis | F9: Status | G9: Implementation Date | H9: Last Review Date | I9: Next Review Date | J9: Gap Identified | K9: Remediation Plan | L9: Target Completion | M9: Risk Level | N9: Evidence Reference | O9: Notes / Comments | P9: Remediation Owner | Q9: Budget Required | R9: Primary Storage Location | S9: Volume/Records | T9: Contains PII/SPI
A25: COMPLIANCE CHECKLIST - Mark ✅ or ❌
A26: 1. | B26: All business units have been consulted for data categories
A27: 2. | B27: Data inventory includes operational, HR, financial, and customer data
A28: 3. | B28: Each data category has a designated Business Owner
A29: 4. | B29: Storage locations (on-premise, cloud, third-party) are documented
A30: 5. | B30: PII and SPI data categories are specifically identified
A31: 6. | B31: Volume/scale of data is estimated for each category
A32: 7. | B32: Data classification levels are assigned per organisational policy
A33: 8. | B33: Temporary/ephemeral data categories are included
A34: 9. | B34: Legacy systems and archived data are included in inventory
A35: 10. | B35: Cross-border data transfers are noted (if applicable)
A36: 11. | B36: Data category registry is reviewed at least annually
A37: 12. | B37: New business processes trigger data category reassessment
... A40: 15. | B40: Data categories align with Records Retention Schedule
A42: Common Data Categories
A43: Category Example | B43: Typical Retention | C43: Common Legal Basis
A44: Employee Personnel Files | B44: 10 years post-employment | C44: Swiss OR, Tax Law
A45: Customer Contracts | B45: 10 years post-termination | C45: Swiss OR (Art. 127)
A46: Financial Records | B46: 10 years | C46: Swiss Tax Law
A47: Marketing Consent Records | B47: Until consent withdrawn + 1 year | C47: GDPR, FADP
A48: Access Logs | B48: 1 year | C48: Security requirement
A49: Email Communications | B49: 1-7 years (varies) | C49: Business need
A50: Customer Support Tickets | B50: 3 years post-resolution | C50: Contractual
A51: Product Telemetry | B51: 90 days - 2 years | C51: Legitimate interest
A52: CCTV Footage | B52: 30-90 days | C52: Security/legal requirement
A53: Website Analytics | B53: 26 months (GDPR default) | C53: Consent/Legitimate interest
A54: Backup Data | B54: Aligned with active retention | C54: Same as source data
... A58: Health & Safety Records | B58: 10 years | C58: Legal obligation
A60: Storage Location Implications
A61: Location Type | B61: Deletion Complexity | C61: Key Considerations
A62: On-Premise | B62: Medium | C62: Full control, hardware lifecycle
A63: Cloud (IaaS) | B63: Medium-High | C63: Snapshot management, API deletion
A64: Cloud (PaaS) | B64: High | C64: Platform-specific deletion methods
A65: Cloud (SaaS) | B65: Very High | C65: Vendor-dependent, see A.8.10.3
A66: Hybrid | B66: Very High | C66: Coordination across environments
...

Sheet 3. Retention Sched. Compliance
A1: SHEET 3: RETENTION SCHEDULE COMPLIANCE
A2: Policy Reference: ISMS-POL-A.8.10-S2.1, Section 2.1.2
A4: ASSESSMENT QUESTION: Does each data category have a documented retention period with a valid legal or business justification?
A7: Complete the yellow-highlighted cells below. Use dropdowns where provided. Link evidence in Column N to Evidence Register sheet.
A9: Data Category / System Name | B9: Data Classification | C9: Business Owner | D9: Retention Period | E9: Legal/Regulatory Basis | F9: Status | G9: Implementation Date | H9: Last Review Date | I9: Next Review Date | J9: Gap Identified | K9: Remediation Plan | L9: Target Completion | M9: Risk Level | N9: Evidence Reference | O9: Notes / Comments | P9: Remediation Owner | Q9: Budget Required | R9: Retention Calculation Method | S9: Event Trigger Description | T9: Backup Retention Aligned
A25: COMPLIANCE CHECKLIST - Mark ✅ or ❌
A26: 1. | B26: Every data category has a defined retention period
A27: 2. | B27: Retention periods have documented legal/regulatory basis
A28: 3. | B28: Swiss FADP compliance verified for all PII categories
A29: 4. | B29: GDPR compliance verified where applicable
A30: 5. | B30: Retention periods do not exceed legal maximums
A31: 6. | B31: Retention periods meet legal minimums (e.g., tax records)
A32: 7. | B32: Event-based retention triggers are clearly defined
A33: 8. | B33: Business justification documented for non-regulatory retention
A34: 9. | B34: Conflicting retention requirements are resolved and documented
A35: 10. | B35: Retention schedule approved by Legal/Compliance team
A36: 11. | B36: Backup retention aligns with active data retention
A37: 12. | B37: 'Permanent' retention is justified and approved
... A40: 15. | B40: Data subjects are informed of retention periods (GDPR/FADP)
A42: Swiss Legal Retention Requirements
A43: Data Type | B43: Minimum Retention | C43: Legal Basis | D43: Maximum Deletion
A44: Accounting Records | B44: 10 years | C44: Swiss OR Art. 958f | D44: After 10 years
A45: Tax Records | B45: 10 years | C45: Swiss Tax Law | D45: After 10 years
A46: Employee Records | B46: 10 years | C46: Swiss OR Art. 127 | D46: After 10 years (FADP)
A47: Contracts | B47: 10 years | C47: Swiss OR Art. 127 | D47: After 10 years
A48: Payroll Records | B48: 10 years | C48: Swiss Tax/Social Law | D48: After 10 years
A49: Corporate Minutes | B49: Permanent | C49: Swiss OR Art. 695 | D49: N/A
A50: Share Register | B50: Permanent | C50: Swiss OR Art. 686 | D50: N/A
A51: Correspondence | B51: No minimum | C51: Business need | D51: FADP: when no longer needed
A52: Marketing Data | B52: No minimum | C52: Consent-based | D52: FADP: consent withdrawal
A53: CCTV Footage | B53: No minimum | C53: Proportionality | D53: FADP: typically 30-90 days
A55: Retention Calculation Methods
A56: Method | B56: Definition | C56: Example
A57: Fixed Period | B57: Set duration from creation/collection | C57: 7 years from date of invoice
A58: Event-Based | B58: Duration starts at specific event | C58: 10 years from contract termination
A59: Hybrid | B59: Combination of fixed + event | C59: 3 years OR until litigation resolved
A60: Indefinite (Permanent) | B60: No planned deletion | C60: Corporate charter documents
A61: Until Consent Withdrawn | B61: Active until user action | C61: Marketing email list
A63: EXCEPTIONS / DEVIATIONS
A64: Document any exceptions or deviations from requirements here (e.g., data categories excluded from assessment, pending reviews, disputed retention periods):

Sheet 4. Deletion Trigger Config.
A1: SHEET 4: DELETION TRIGGER CONFIGURATION
A2: Policy Reference: ISMS-POL-A.8.10-S2.1, Section 2.1.3
A4: ASSESSMENT QUESTION: Do we have effective and reliable deletion triggers that ensure data is deleted when retention periods expire?
A7: Complete the yellow-highlighted cells below. Use dropdowns where provided. Link evidence in Column N to Evidence Register sheet.
A9: Data Category / System Name | B9: Data Classification | C9: Business Owner | D9: Retention Period | E9: Legal/Regulatory Basis | F9: Status | G9: Implementation Date | H9: Last Review Date | I9: Next Review Date | J9: Gap Identified | K9: Remediation Plan | L9: Target Completion | M9: Risk Level | N9: Evidence Reference | O9: Notes / Comments | P9: Remediation Owner | Q9: Budget Required | R9: Trigger Type | S9: Trigger Frequency | T9: Legal Hold Check Integrated
A25: COMPLIANCE CHECKLIST - Mark ✅ or ❌
A26: 1. | B26: Automated deletion triggers implemented for high-volume data
A27: 2. | B27: Manual deletion procedures documented for low-volume data
A28: 3. | B28: Trigger execution is logged and auditable
A29: 4. | B29: Failed deletion attempts are alerted and investigated
A30: 5. | B30: Legal hold checks are integrated into trigger logic
A31: 6. | B31: Backup deletion triggers aligned with active data triggers
A32: 7. | B32: Cloud/SaaS deletion triggers verified (see A.8.10.3)
A33: 8. | B33: Event-based triggers are monitored for event occurrence
A34: 9. | B34: Deletion triggers tested at least annually
A35: 10. | B35: Trigger failures have defined escalation procedures
A36: 11. | B36: Business Owner approval required for manual triggers (if policy requires)
A37: 12. | B37: Deletion triggers respect data dependencies (referential integrity)
... A40: 15. | B40: Trigger configuration changes follow change management
A42: Trigger Types and Use Cases
A43: Trigger Type | B43: Best For | C43: Advantages | D43: Disadvantages
A44: Automatic | B44: High-volume, structured data | C44: Consistent, no human error | D44: Requires robust testing
A45: Manual | B45: Low-volume, sensitive data | C45: Controlled, deliberate | D45: Human error risk, slower
A46: Semi-Automatic | B46: Medium volume, needs approval | C46: Balance control and efficiency | D46: Workflow complexity
A47: Event-Based | B47: Contract-dependent data | C47: Precise, legally aligned | D47: Requires event tracking
A49: Common Deletion Trigger Patterns
A50: Pattern | B50: Description | C50: Example Implementation
A51: Time-Based Cron | B51: Scheduled deletion job | C51: Daily at 02:00 UTC, delete records > 7 years
A52: Database TTL | B52: Built-in expiration | C52: MongoDB TTL index, Redis EXPIRE
A53: Lifecycle Policy | B53: Cloud-native deletion | C53: AWS S3 Lifecycle, Azure Blob Lifecycle
A54: Workflow Approval | B54: Human-in-the-loop | C54: Jira ticket → approval → script execution
A55: Event Listener | B55: Reactive deletion | C55: Contract.status = terminated → 90-day timer → delete
A56: Batch Processing | B56: Periodic bulk deletion | C56: Monthly job: identify + delete expired records
A58: EXCEPTIONS / DEVIATIONS
A59: Document any exceptions or deviations from requirements here (e.g., data categories excluded from assessment, pending reviews, disputed retention periods):

Sheet 5. Legal Hold Management
A1: SHEET 5: LEGAL HOLD MANAGEMENT
A2: Policy Reference: ISMS-POL-A.8.10-S2.1, Section 2.1.4
A4: ASSESSMENT QUESTION: Do we have robust processes to identify, communicate, and manage legal holds to prevent premature deletion of data under hold?
A7: Complete the yellow-highlighted cells below. Use dropdowns where provided. Link evidence in Column N to Evidence Register sheet.
A9: Data Category / System Name | B9: Data Classification | C9: Business Owner | D9: Retention Period | E9: Legal/Regulatory Basis | F9: Status | G9: Implementation Date | H9: Last Review Date | I9: Next Review Date | J9: Gap Identified | K9: Remediation Plan | L9: Target Completion | M9: Risk Level | N9: Evidence Reference | O9: Notes / Comments | P9: Remediation Owner | Q9: Budget Required | R9: Active Legal Holds | S9: Legal Hold Notification Process | T9: Hold Review Frequency
A25: COMPLIANCE CHECKLIST - Mark ✅ or ❌
A26: 1. | B26: Legal hold procedures are documented and approved
A27: 2. | B27: Legal/Compliance team has authority to initiate holds
A28: 3. | B28: IT/Data teams receive timely notification of holds
A29: 4. | B29: Hold notification includes specific data categories and date ranges
A30: 5. | B30: Automated deletion triggers check for active holds
A31: 6. | B31: Legal hold data is segregated or flagged in systems
A32: 7. | B32: Legal hold registry is maintained (who, what, when, why)
A33: 8. | B33: Business Owners are notified when their data is under hold
A34: 9. | B34: Periodic review of active holds (at least quarterly)
A35: 10. | B35: Hold release procedures are documented
A36: 11. | B36: Post-hold deletion is executed per normal retention schedule
A37: 12. | B37: Legal hold training provided to relevant staf
... A40: 15. | B40: Legal hold process tested at least annually
A42: Legal Hold Triggers
A43: Trigger Event | B43: Typical Response Time | C43: Hold Scope
A44: Litigation Notice | B44: Within 24 hours | C44: All relevant data for case
A45: Regulatory Investigation | B45: Within 48 hours | C45: Specified data types/periods
A46: Internal Investigation | B46: Within 72 hours | C46: Specific employees/systems
A47: M&A Due Diligence | B47: Within 1 week | C47: All corporate records
A48: Employment Dispute | B48: Within 48 hours | C48: Employee records + communications
A49: IP Dispute | B49: Within 72 hours | C49: Development records, communications
A50: Data Breach Investigation | B50: Immediate | C50: Affected systems/logs
A51: Audit Notification | B51: Within 1 week | C51: Records relevant to audit scope
A53: Hold Management Best Practices
A54: Practice | B54: Purpose | C54: Implementation
A55: Centralised Hold Registry | B55: Single source of truth | C55: Legal hold database/system
A56: Automated Flagging | B56: Prevent accidental deletion | C56: System flags or separate storage
A57: Regular Hold Reviews | B57: Release unnecessary holds | C57: Quarterly review meetings
A58: Clear Release Process | B58: Controlled return to normal deletion | C58: Legal approval required
A59: Documentation Requirements | B59: Audit trail | C59: Who, what, when, why, how long
A60: Scope Definition | B60: Avoid over-preservation | C60: Specific data types, date ranges
A61: Cost Tracking | B61: Understand hold impact | C61: Storage costs, resource time
A63: EXCEPTIONS / DEVIATIONS
A64: Document any exceptions or deviations from requirements here (e.g., data categories excluded from assessment, pending reviews, disputed retention periods):

Sheet 6. Data Subject Requests
A1: SHEET 6: DATA SUBJECT REQUESTS (GDPR/FADP)
A2: Policy Reference: ISMS-POL-A.8.10-S2.1, Section 2.1.5
A4: ASSESSMENT QUESTION: Can we effectively identify, validate, and execute deletion requests from data subjects within required timeframes?
A7: Complete the yellow-highlighted cells below. Use dropdowns where provided. Link evidence in Column N to Evidence Register sheet.
A9: Data Category / System Name | B9: Data Classification | C9: Business Owner | D9: Retention Period | E9: Legal/Regulatory Basis | F9: Status | G9: Implementation Date | H9: Last Review Date | I9: Next Review Date | J9: Gap Identified | K9: Remediation Plan | L9: Target Completion | M9: Risk Level | N9: Evidence Reference | O9: Notes / Comments | P9: Remediation Owner | Q9: Budget Required | R9: Average Response Time (Days) | S9: GDPR/FADP Applicable | T9: Request Volume (Last 12 Months)
A25: COMPLIANCE CHECKLIST - Mark ✅ or ❌
A26: 1. | B26: Data subject request procedure is documented
A27: 2. | B27: Request intake channel is clearly communicated (e.g., privacy@company.ch)
A28: 3. | B28: Identity verification process prevents fraudulent requests
A29: 4. | B29: Request acknowledgment within 5 business days (GDPR/FADP)
A30: 5. | B30: Requests fulfilled within 30 days (extendable to 60 days with justification)
A31: 6. | B31: Search capability across all systems holding personal data
A32: 7. | B32: Ability to distinguish between deletion obligations and exceptions
A33: 8. | B33: Third-party/cloud systems included in deletion scope (see A.8.10.3)
A34: 9. | B34: Backup deletion addressed in response (or timeline communicated)
A35: 10. | B35: Request tracking system in place (ticket system, CRM, etc.)
A36: 11. | B36: Responses documented (what was deleted, what was retained, why)
A37: 12. | B37: Data subjects informed of retention exceptions (e.g., legal obligations)
... A40: 15. | B40: Request metrics tracked and reported to DPO/Privacy Officer
A42: GDPR Article 17 Deletion Obligations
A43: Condition for Deletion | B43: Organisation Must Delete If... | C43: Example
A44: No longer necessary | B44: Data no longer needed for original purpose | C44: Marketing data after consent withdrawn
A45: Consent withdrawn | B45: Individual withdraws consent (no other legal basis) | C45: Newsletter subscription cancellation
A46: Objection to processing | B46: Individual objects + no overriding legitimate grounds | C46: Profiling/direct marketing objection
A47: Unlawful processing | B47: Data was processed illegally | C47: Processing without valid legal basis
A48: Legal obligation | B48: Law requires deletion | C48: Court order, regulatory requirement
A49: Child's data | B49: Data collected from child w/o proper consent | C49: Social media account created under age 13
A51: GDPR Article 17 Deletion Exceptions
A52: Exception | B52: Organisation Can Retain If... | C52: Example
A53: Freedom of expression | B53: Exercise of freedom of expression/information | C53: Journalistic/academic/artistic purposes
A54: Legal obligation | B54: Processing necessary for legal compliance | C54: Tax records (10-year retention)
A55: Public interest | B55: Public health, scientific research (safeguarded) | C55: Anonymized medical research data
A56: Legal claims | B56: Establishment, exercise, defence of legal claims | C56: Litigation hold, contract disputes
A57: Archiving in public interest | B57: Historical, statistical, scientific research (safeguarded) | C57: National archives, public health studies
A59: Request Response Workflow
A60: Step | B60: Action | C60: Timeframe | D60: Responsible Role
A61: 1. Receive | B61: Log request in tracking system | C61: Day 0 | D61: Privacy Team
A62: 2. Acknowledge | B62: Send acknowledgment to data subject | C62: Within 5 business days | D62: Privacy Team
A63: 3. Verify Identity | B63: Validate requestor identity | C63: Within 7 days | D63: Privacy Team
A64: 4. Assess Scope | B64: Identify all systems with data subject's data | C64: Within 10 days | D64: IT + Business Owners
...

Sheet Evidence Register
A1: EVIDENCE REGISTER
A2: List all evidence files/documents referenced in this assessment (audit traceability).
A4: Evidence ID | B4: Category | C4: Description | D4: Source Document | E4: Date Collected | F4: Collected By | G4: Status | H4: Notes
A5: EV-001
A6: EV-002
A7: EV-003
A8: EV-004
A9: EV-005
A10: EV-006
A11: EV-007
A12: EV-008
A13: EV-009
A14: EV-010
A15: EV-011
A16: EV-012
... A104: EV-100

Sheet Summary Dashboard
A1: Retention & Deletion Triggers Assessment — SUMMARY DASHBOARD
A2: Summary Dashboard | Retention & Deletion Triggers Assessment | Generated: 20260301
A4: TABLE 1 – COMPLIANCE ASSESSMENT SUMMARY
A5: Assessment Area | B5: Total Items | C5: Compliant | D5: Partial | E5: Non-Compliant | F5: N/A | G5: Compliance %
A6: Data Category Registry | B6: =C6+D6+E6+F6 | C6: =COUNTIF('2. Data Category Registry'!F10:F100,"✅ Compliant") | D6: =COUNTIF('2. Data Category Registry'!F10:F100,"⚠️ Partial") | E6: =COUNTIF('2. Data Category Registry'!F10:F100,"❌ Non-Compliant") | F6: =COUNTIF('2. Data Category Registry'!F10:F100,"N/A") | G6: =IF((B6-F6)=0,0,C6/(B6-F6))
A7: Retention Schedule Compliance | B7: =C7+D7+E7+F7 | C7: =COUNTIF('3. Retention Sched. Compliance'!F10:F100,"✅ Compliant") | D7: =COUNTIF('3. Retention Sched. Compliance'!F10:F100,"⚠️ Partial") | E7: =COUNTIF('3. Retention Sched. Compliance'!F10:F100,"❌ Non-Compliant") | F7: =COUNTIF('3. Retention Sched. Compliance'!F10:F100,"N/A") | G7: =IF((B7-F7)=0,0,C7/(B7-F7))
A8: Deletion Trigger Config. | B8: =C8+D8+E8+F8 | C8: =COUNTIF('4. Deletion Trigger Config.'!F10:F100,"✅ Compliant") | D8: =COUNTIF('4. Deletion Trigger Config.'!F10:F100,"⚠️ Partial") | E8: =COUNTIF('4. Deletion Trigger Config.'!F10:F100,"❌ Non-Compliant") | F8: =COUNTIF('4. Deletion Trigger Config.'!F10:F100,"N/A") | G8: =IF((B8-F8)=0,0,C8/(B8-F8))
A9: Legal Hold Management | B9: =C9+D9+E9+F9 | C9: =COUNTIF('5. Legal Hold Management'!F10:F100,"✅ Compliant") | D9: =COUNTIF('5. Legal Hold Management'!F10:F100,"⚠️ Partial") | E9: =COUNTIF('5. Legal Hold Management'!F10:F100,"❌ Non-Compliant") | F9: =COUNTIF('5. Legal Hold Management'!F10:F100,"N/A") | G9: =IF((B9-F9)=0,0,C9/(B9-F9))
A10: Data Subject Requests | B10: =C10+D10+E10+F10 | C10: =COUNTIF('6. Data Subject Requests'!F10:F100,"✅ Compliant") | D10: =COUNTIF('6. Data Subject Requests'!F10:F100,"⚠️ Partial") | E10: =COUNTIF('6. Data Subject Requests'!F10:F100,"❌ Non-Compliant") | F10: =COUNTIF('6. Data Subject Requests'!F10:F100,"N/A") | G10: =IF((B10-F10)=0,0,C10/(B10-F10))
A11: TOTAL | B11: =SUM(B6:B10) | C11: =SUM(C6:C10) | D11: =SUM(D6:D10) | E11: =SUM(E6:E10) | F11: =SUM(F6:F10) | G11: =IF((B11-F11)=0,0,C11/(B11-F11))
A13: TABLE 2 – KEY METRICS
A14: Metric | B14: Value | C14: Target
A15: Overall Compliance Rate | B15: =IFERROR(G11,"N/A") | C15: ≥ 80%
A16: Data Categories with Defined Retention Schedule | B16: =IFERROR(COUNTIF('3. Retention Sched. Compliance'!F10:F100,"✅ Compliant"),0) | C16: 100%
A17: Deletion Triggers Configured | B17: =IFERROR(COUNTIF('4. Deletion Trigger Config.'!F10:F100,"✅ Compliant"),0) | C17: 100%
A18: Legal Hold Management Controls Compliant | B18: =IFERROR(COUNTIF('5. Legal Hold Management'!F10:F100,"✅ Compliant"),0) | C18: 100%
A19: Data Subject Request Workflows Compliant | B19: =IFERROR(COUNTIF('6. Data Subject Requests'!F10:F100,"✅ Compliant"),0) | C19: 100%
A20: Non-Compliant Items Requiring Remediation | B20: =IFERROR(SUM(E6:E10),0) | C20: 0
A22: TABLE 3 – KEY FINDINGS & RECOMMENDATIONS
A23: # | B23: Finding | C23: Impact | D23: Recommendation | E23: Priority | F23: Status | G23: Notes
A24: 1 | B24: Retention schedules may not cover all data categories | C24: High | D24: Complete data category inventory and assign retention periods to all items | E24: P1 | F24: Open
A25: 2 | B25: Deletion trigger automation may be incomplete | C25: High | D25: Implement automated deletion triggers for all high-volume data categories | E25: P1 | F25: Open
A26: 3 | B26: Legal hold integration with deletion systems requires verification | C26: Medium | D26: Test legal hold suspension across all automated deletion trigger systems | E26: P2 | F26: Open
A27: 4 | B27: Data subject erasure request response times need monitoring | C27: Medium | D27: Establish SLA tracking and escalation for GDPR/FADP erasure requests | E27: P2 | F27: Open

Sheet Approval Sign-Off
A1: ASSESSMENT APPROVAL AND SIGN-OFF
A2: ISMS-IMP-A.8.10.1 - Retention & Deletion Triggers Assessment
A3: ASSESSMENT SUMMARY
A4: Document: | B4: ISMS-IMP-A.8.10.1 - Retention & Deletion Triggers Assessment
A5: Assessment Period:
A6: Overall Compliance: | B6: =IFERROR(AVERAGE('Summary Dashboard'!G6:G10),"")
A7: Assessment Status:
A10: COMPLETED BY (DATA PROTECTION)
A11: Name:
A12: Title:
A13: Date:
A14: Signature:
A15: Comments:
A17: REVIEWED BY (COMPLIANCE)
A18: Name:
A19: Title:
A20: Date:
A21: Signature:
... A37: Special Considerations:
