Workbook

Sheet Executive Summary
A1: ISMS-OP-CHK-A.8.25-26-29 — Secure Development Lifecycle Compliance Checklist
A3: DOCUMENT INFORMATION
A4: Document ID | B4: ISMS-OP-CHK-A.8.25-26-29
A5: Source Policy | B5: ISMS-OP-POL-A.8.25-26-29
A6: ISO Controls | B6: Secure Development Lifecycle
A7: Generated | B7: 30.09.2026
A8: Prepared By
A9: Organisation
A10: Review Cycle | B10: Annual
A12: OVERALL COMPLIANCE STATUS
A13: Overall Compliance | B13: ='Dashboard'!G18
A14: Status | B14: =IF(Dashboard!H18>0,"INCOMPLETE",IF(Dashboard!G18="N/A","NOT ASSESSED",IF(ISNUMBER(VALUE(SUBSTITUTE(Dashboard!G18,"%",""))),IF(VALUE(SUBSTITUTE(Dashboard!G18,"%",""))>=90,"GREEN",IF(VALUE(SUBSTITUTE(Dashboard!G18,"%",""))>=70,"AMBER","RED")),"NOT ASSESSED")))
A16: KEY METRICS
A17: Total Requirements | B17: ='Dashboard'!B18
A18: Compliant | B18: ='Dashboard'!C18
A19: Partial | B19: ='Dashboard'!D18
A20: Non-Compliant | B20: ='Dashboard'!E18
A21: Not Applicable | B21: ='Dashboard'!F18
A22: Unanswered | B22: ='Dashboard'!H18
A23: Owner Coverage | B23: =IF(Dashboard!B18=0,"N/A",ROUND((COUNTA('Development Security Toolchain'!F4:F5)+COUNTA('Environment Segregation'!F4:F8)+COUNTA('Application Risk Classification'!F4:F6)+COUNTA('Security Requirements'!F4:F10)+COUNTA('Secure Coding Guidelines'!F4:F8)+COUNTA('Code Repositories & Version'!F4:F11)+COUNTA('Code Review'!F4:F8)+COUNTA('CI CD Pipeline Security Gates'!F4:F5)+COUNTA('Security Testing Requirements'!F4:F19)+COUNTA('Vulnerability Remediation'!F4:F8)+COUNTA('Test Data Protection'!F4:F9)+COUNTA('Promoting Code to Production'!F4:F10)+COUNTA('Outsourced Development'!F4:F8)+COUNTA('Developer Security Training'!F4:F8))/Dashboard!B18*100,0)&"%")
A25: DOMAIN STATUS SUMMARY
A26: Domain | B26: Compliance % | C26: Compliant | D26: Gaps | E26: Status
A27: Development Security Toolchain | B27: ='Dashboard'!G4 | C27: ='Dashboard'!C4 | D27: ='Dashboard'!E4 | E27: =IF(Dashboard!H4>0,"INCOMPLETE",IF(Dashboard!G4="N/A","--",IF(ISNUMBER(VALUE(SUBSTITUTE(Dashboard!G4,"%",""))),IF(VALUE(SUBSTITUTE(Dashboard!G4,"%",""))>=90,"PASS",IF(VALUE(SUBSTITUTE(Dashboard!G4,"%",""))>=70,"REVIEW","FAIL")),"--")))
A28: Environment Segregation | B28: ='Dashboard'!G5 | C28: ='Dashboard'!C5 | D28: ='Dashboard'!E5 | E28: =IF(Dashboard!H5>0,"INCOMPLETE",IF(Dashboard!G5="N/A","--",IF(ISNUMBER(VALUE(SUBSTITUTE(Dashboard!G5,"%",""))),IF(VALUE(SUBSTITUTE(Dashboard!G5,"%",""))>=90,"PASS",IF(VALUE(SUBSTITUTE(Dashboard!G5,"%",""))>=70,"REVIEW","FAIL")),"--")))
A29: Application Risk Classification | B29: ='Dashboard'!G6 | C29: ='Dashboard'!C6 | D29: ='Dashboard'!E6 | E29: =IF(Dashboard!H6>0,"INCOMPLETE",IF(Dashboard!G6="N/A","--",IF(ISNUMBER(VALUE(SUBSTITUTE(Dashboard!G6,"%",""))),IF(VALUE(SUBSTITUTE(Dashboard!G6,"%",""))>=90,"PASS",IF(VALUE(SUBSTITUTE(Dashboard!G6,"%",""))>=70,"REVIEW","FAIL")),"--")))
A30: Security Requirements | B30: ='Dashboard'!G7 | C30: ='Dashboard'!C7 | D30: ='Dashboard'!E7 | E30: =IF(Dashboard!H7>0,"INCOMPLETE",IF(Dashboard!G7="N/A","--",IF(ISNUMBER(VALUE(SUBSTITUTE(Dashboard!G7,"%",""))),IF(VALUE(SUBSTITUTE(Dashboard!G7,"%",""))>=90,"PASS",IF(VALUE(SUBSTITUTE(Dashboard!G7,"%",""))>=70,"REVIEW","FAIL")),"--")))
A31: Secure Coding Guidelines | B31: ='Dashboard'!G8 | C31: ='Dashboard'!C8 | D31: ='Dashboard'!E8 | E31: =IF(Dashboard!H8>0,"INCOMPLETE",IF(Dashboard!G8="N/A","--",IF(ISNUMBER(VALUE(SUBSTITUTE(Dashboard!G8,"%",""))),IF(VALUE(SUBSTITUTE(Dashboard!G8,"%",""))>=90,"PASS",IF(VALUE(SUBSTITUTE(Dashboard!G8,"%",""))>=70,"REVIEW","FAIL")),"--")))
A32: Code Repositories & Version | B32: ='Dashboard'!G9 | C32: ='Dashboard'!C9 | D32: ='Dashboard'!E9 | E32: =IF(Dashboard!H9>0,"INCOMPLETE",IF(Dashboard!G9="N/A","--",IF(ISNUMBER(VALUE(SUBSTITUTE(Dashboard!G9,"%",""))),IF(VALUE(SUBSTITUTE(Dashboard!G9,"%",""))>=90,"PASS",IF(VALUE(SUBSTITUTE(Dashboard!G9,"%",""))>=70,"REVIEW","FAIL")),"--")))
A33: Code Review | B33: ='Dashboard'!G10 | C33: ='Dashboard'!C10 | D33: ='Dashboard'!E10 | E33: =IF(Dashboard!H10>0,"INCOMPLETE",IF(Dashboard!G10="N/A","--",IF(ISNUMBER(VALUE(SUBSTITUTE(Dashboard!G10,"%",""))),IF(VALUE(SUBSTITUTE(Dashboard!G10,"%",""))>=90,"PASS",IF(VALUE(SUBSTITUTE(Dashboard!G10,"%",""))>=70,"REVIEW","FAIL")),"--")))
A34: CI CD Pipeline Security Gates | B34: ='Dashboard'!G11 | C34: ='Dashboard'!C11 | D34: ='Dashboard'!E11 | E34: =IF(Dashboard!H11>0,"INCOMPLETE",IF(Dashboard!G11="N/A","--",IF(ISNUMBER(VALUE(SUBSTITUTE(Dashboard!G11,"%",""))),IF(VALUE(SUBSTITUTE(Dashboard!G11,"%",""))>=90,"PASS",IF(VALUE(SUBSTITUTE(Dashboard!G11,"%",""))>=70,"REVIEW","FAIL")),"--")))
A35: Security Testing Requirements | B35: ='Dashboard'!G12 | C35: ='Dashboard'!C12 | D35: ='Dashboard'!E12 | E35: =IF(Dashboard!H12>0,"INCOMPLETE",IF(Dashboard!G12="N/A","--",IF(ISNUMBER(VALUE(SUBSTITUTE(Dashboard!G12,"%",""))),IF(VALUE(SUBSTITUTE(Dashboard!G12,"%",""))>=90,"PASS",IF(VALUE(SUBSTITUTE(Dashboard!G12,"%",""))>=70,"REVIEW","FAIL")),"--")))
A36: Vulnerability Remediation | B36: ='Dashboard'!G13 | C36: ='Dashboard'!C13 | D36: ='Dashboard'!E13 | E36: =IF(Dashboard!H13>0,"INCOMPLETE",IF(Dashboard!G13="N/A","--",IF(ISNUMBER(VALUE(SUBSTITUTE(Dashboard!G13,"%",""))),IF(VALUE(SUBSTITUTE(Dashboard!G13,"%",""))>=90,"PASS",IF(VALUE(SUBSTITUTE(Dashboard!G13,"%",""))>=70,"REVIEW","FAIL")),"--")))
A37: Test Data Protection | B37: ='Dashboard'!G14 | C37: ='Dashboard'!C14 | D37: ='Dashboard'!E14 | E37: =IF(Dashboard!H14>0,"INCOMPLETE",IF(Dashboard!G14="N/A","--",IF(ISNUMBER(VALUE(SUBSTITUTE(Dashboard!G14,"%",""))),IF(VALUE(SUBSTITUTE(Dashboard!G14,"%",""))>=90,"PASS",IF(VALUE(SUBSTITUTE(Dashboard!G14,"%",""))>=70,"REVIEW","FAIL")),"--")))
A38: Promoting Code to Production | B38: ='Dashboard'!G15 | C38: ='Dashboard'!C15 | D38: ='Dashboard'!E15 | E38: =IF(Dashboard!H15>0,"INCOMPLETE",IF(Dashboard!G15="N/A","--",IF(ISNUMBER(VALUE(SUBSTITUTE(Dashboard!G15,"%",""))),IF(VALUE(SUBSTITUTE(Dashboard!G15,"%",""))>=90,"PASS",IF(VALUE(SUBSTITUTE(Dashboard!G15,"%",""))>=70,"REVIEW","FAIL")),"--")))
... A40: Developer Security Training | B40: ='Dashboard'!G17 | C40: ='Dashboard'!C17 | D40: ='Dashboard'!E17 | E40: =IF(Dashboard!H17>0,"INCOMPLETE",IF(Dashboard!G17="N/A","--",IF(ISNUMBER(VALUE(SUBSTITUTE(Dashboard!G17,"%",""))),IF(VALUE(SUBSTITUTE(Dashboard!G17,"%",""))>=90,"PASS",IF(VALUE(SUBSTITUTE(Dashboard!G17,"%",""))>=70,"REVIEW","FAIL")),"--")))
A42: CRITICAL ISSUES
A43: # | B43: Issue Description | C43: Domain | D43: Owner | E43: Due Date
A44: 1
A45: 2
A46: 3
...

Sheet Dashboard
A1: Secure Development Lifecycle — Compliance Dashboard
A3: Domain | B3: Total Reqs | C3: Compliant | D3: Partial | E3: Non-Compliant | F3: N/A | G3: Compliance % | H3: Unassessed
A4: Development Security Toolchain | B4: =COUNTA('Development Security Toolchain'!A4:A5) | C4: =COUNTIF('Development Security Toolchain'!D4:D5,"Compliant") | D4: =COUNTIF('Development Security Toolchain'!D4:D5,"Partial") | E4: =COUNTIF('Development Security Toolchain'!D4:D5,"Non-Compliant") | F4: =COUNTIF('Development Security Toolchain'!D4:D5,"N/A") | G4: =IF((B4-F4)=0,"N/A",ROUND(C4/(B4-F4)*100,1)&"%") | H4: =B4-(C4+D4+E4+F4)
A5: Environment Segregation | B5: =COUNTA('Environment Segregation'!A4:A8) | C5: =COUNTIF('Environment Segregation'!D4:D8,"Compliant") | D5: =COUNTIF('Environment Segregation'!D4:D8,"Partial") | E5: =COUNTIF('Environment Segregation'!D4:D8,"Non-Compliant") | F5: =COUNTIF('Environment Segregation'!D4:D8,"N/A") | G5: =IF((B5-F5)=0,"N/A",ROUND(C5/(B5-F5)*100,1)&"%") | H5: =B5-(C5+D5+E5+F5)
A6: Application Risk Classification | B6: =COUNTA('Application Risk Classification'!A4:A6) | C6: =COUNTIF('Application Risk Classification'!D4:D6,"Compliant") | D6: =COUNTIF('Application Risk Classification'!D4:D6,"Partial") | E6: =COUNTIF('Application Risk Classification'!D4:D6,"Non-Compliant") | F6: =COUNTIF('Application Risk Classification'!D4:D6,"N/A") | G6: =IF((B6-F6)=0,"N/A",ROUND(C6/(B6-F6)*100,1)&"%") | H6: =B6-(C6+D6+E6+F6)
A7: Security Requirements | B7: =COUNTA('Security Requirements'!A4:A10) | C7: =COUNTIF('Security Requirements'!D4:D10,"Compliant") | D7: =COUNTIF('Security Requirements'!D4:D10,"Partial") | E7: =COUNTIF('Security Requirements'!D4:D10,"Non-Compliant") | F7: =COUNTIF('Security Requirements'!D4:D10,"N/A") | G7: =IF((B7-F7)=0,"N/A",ROUND(C7/(B7-F7)*100,1)&"%") | H7: =B7-(C7+D7+E7+F7)
A8: Secure Coding Guidelines | B8: =COUNTA('Secure Coding Guidelines'!A4:A8) | C8: =COUNTIF('Secure Coding Guidelines'!D4:D8,"Compliant") | D8: =COUNTIF('Secure Coding Guidelines'!D4:D8,"Partial") | E8: =COUNTIF('Secure Coding Guidelines'!D4:D8,"Non-Compliant") | F8: =COUNTIF('Secure Coding Guidelines'!D4:D8,"N/A") | G8: =IF((B8-F8)=0,"N/A",ROUND(C8/(B8-F8)*100,1)&"%") | H8: =B8-(C8+D8+E8+F8)
A9: Code Repositories & Version | B9: =COUNTA('Code Repositories & Version'!A4:A11) | C9: =COUNTIF('Code Repositories & Version'!D4:D11,"Compliant") | D9: =COUNTIF('Code Repositories & Version'!D4:D11,"Partial") | E9: =COUNTIF('Code Repositories & Version'!D4:D11,"Non-Compliant") | F9: =COUNTIF('Code Repositories & Version'!D4:D11,"N/A") | G9: =IF((B9-F9)=0,"N/A",ROUND(C9/(B9-F9)*100,1)&"%") | H9: =B9-(C9+D9+E9+F9)
A10: Code Review | B10: =COUNTA('Code Review'!A4:A8) | C10: =COUNTIF('Code Review'!D4:D8,"Compliant") | D10: =COUNTIF('Code Review'!D4:D8,"Partial") | E10: =COUNTIF('Code Review'!D4:D8,"Non-Compliant") | F10: =COUNTIF('Code Review'!D4:D8,"N/A") | G10: =IF((B10-F10)=0,"N/A",ROUND(C10/(B10-F10)*100,1)&"%") | H10: =B10-(C10+D10+E10+F10)
A11: CI CD Pipeline Security Gates | B11: =COUNTA('CI CD Pipeline Security Gates'!A4:A5) | C11: =COUNTIF('CI CD Pipeline Security Gates'!D4:D5,"Compliant") | D11: =COUNTIF('CI CD Pipeline Security Gates'!D4:D5,"Partial") | E11: =COUNTIF('CI CD Pipeline Security Gates'!D4:D5,"Non-Compliant") | F11: =COUNTIF('CI CD Pipeline Security Gates'!D4:D5,"N/A") | G11: =IF((B11-F11)=0,"N/A",ROUND(C11/(B11-F11)*100,1)&"%") | H11: =B11-(C11+D11+E11+F11)
A12: Security Testing Requirements | B12: =COUNTA('Security Testing Requirements'!A4:A19) | C12: =COUNTIF('Security Testing Requirements'!D4:D19,"Compliant") | D12: =COUNTIF('Security Testing Requirements'!D4:D19,"Partial") | E12: =COUNTIF('Security Testing Requirements'!D4:D19,"Non-Compliant") | F12: =COUNTIF('Security Testing Requirements'!D4:D19,"N/A") | G12: =IF((B12-F12)=0,"N/A",ROUND(C12/(B12-F12)*100,1)&"%") | H12: =B12-(C12+D12+E12+F12)
A13: Vulnerability Remediation | B13: =COUNTA('Vulnerability Remediation'!A4:A8) | C13: =COUNTIF('Vulnerability Remediation'!D4:D8,"Compliant") | D13: =COUNTIF('Vulnerability Remediation'!D4:D8,"Partial") | E13: =COUNTIF('Vulnerability Remediation'!D4:D8,"Non-Compliant") | F13: =COUNTIF('Vulnerability Remediation'!D4:D8,"N/A") | G13: =IF((B13-F13)=0,"N/A",ROUND(C13/(B13-F13)*100,1)&"%") | H13: =B13-(C13+D13+E13+F13)
A14: Test Data Protection | B14: =COUNTA('Test Data Protection'!A4:A9) | C14: =COUNTIF('Test Data Protection'!D4:D9,"Compliant") | D14: =COUNTIF('Test Data Protection'!D4:D9,"Partial") | E14: =COUNTIF('Test Data Protection'!D4:D9,"Non-Compliant") | F14: =COUNTIF('Test Data Protection'!D4:D9,"N/A") | G14: =IF((B14-F14)=0,"N/A",ROUND(C14/(B14-F14)*100,1)&"%") | H14: =B14-(C14+D14+E14+F14)
A15: Promoting Code to Production | B15: =COUNTA('Promoting Code to Production'!A4:A10) | C15: =COUNTIF('Promoting Code to Production'!D4:D10,"Compliant") | D15: =COUNTIF('Promoting Code to Production'!D4:D10,"Partial") | E15: =COUNTIF('Promoting Code to Production'!D4:D10,"Non-Compliant") | F15: =COUNTIF('Promoting Code to Production'!D4:D10,"N/A") | G15: =IF((B15-F15)=0,"N/A",ROUND(C15/(B15-F15)*100,1)&"%") | H15: =B15-(C15+D15+E15+F15)
A16: Outsourced Development | B16: =COUNTA('Outsourced Development'!A4:A8) | C16: =COUNTIF('Outsourced Development'!D4:D8,"Compliant") | D16: =COUNTIF('Outsourced Development'!D4:D8,"Partial") | E16: =COUNTIF('Outsourced Development'!D4:D8,"Non-Compliant") | F16: =COUNTIF('Outsourced Development'!D4:D8,"N/A") | G16: =IF((B16-F16)=0,"N/A",ROUND(C16/(B16-F16)*100,1)&"%") | H16: =B16-(C16+D16+E16+F16)
A17: Developer Security Training | B17: =COUNTA('Developer Security Training'!A4:A8) | C17: =COUNTIF('Developer Security Training'!D4:D8,"Compliant") | D17: =COUNTIF('Developer Security Training'!D4:D8,"Partial") | E17: =COUNTIF('Developer Security Training'!D4:D8,"Non-Compliant") | F17: =COUNTIF('Developer Security Training'!D4:D8,"N/A") | G17: =IF((B17-F17)=0,"N/A",ROUND(C17/(B17-F17)*100,1)&"%") | H17: =B17-(C17+D17+E17+F17)
A18: TOTAL | B18: =SUM(B4:B17) | C18: =SUM(C4:C17) | D18: =SUM(D4:D17) | E18: =SUM(E4:E17) | F18: =SUM(F4:F17) | G18: =IF((B18-F18)=0,"N/A",ROUND(C18/(B18-F18)*100,1)&"%") | H18: =SUM(H4:H17)
A20: COMPLIANCE BY STATUS
A21: Compliant | B21: =C18 | C21: =IF(B18=0,"",ROUND(B21/B18*100,1)&"%")
A22: Partial | B22: =D18 | C22: =IF(B18=0,"",ROUND(B22/B18*100,1)&"%")
A23: Non-Compliant | B23: =E18 | C23: =IF(B18=0,"",ROUND(B23/B18*100,1)&"%")
A24: N/A | B24: =F18 | C24: =IF(B18=0,"",ROUND(B24/B18*100,1)&"%")
A26: TOP GAPS (Manual Entry)
A27: Priority | B27: Domain | C27: Requirement | D27: Owner | E27: Due Date | F27: Status
A39: COMPLIANCE TREND (Manual Entry)
A40: Assessment Date | B40: Overall % | C40: Compliant | D40: Gaps | E40: Assessor | F40: Notes

Sheet Development Security Toolchain
A1: Development Security Toolchain — Compliance Checklist
A2: ISO/IEC 27001:2022 — Controls A.8.25-26-29: Secure Development Lifecycle
A3: Req # | B3: Section | C3: Requirement | D3: Status | E3: Evidence | F3: Owner | G3: Due Date | H3: Notes
A4: A.8.25-26-29-01 | B4: Maintain An Approved Security Toolchain | C4: The organisation shall maintain an approved security toolchain integrated into the development lifecycle.
A5: A.8.25-26-29-02 | B5: The Toolchain | C5: The toolchain shall be reviewed annually by the Development Manager and CISO. Tool changes shall follow the change management process. All tools shall be maintained at current supported versions.

Sheet Environment Segregation
A1: Environment Segregation — Compliance Checklist
A2: ISO/IEC 27001:2022 — Controls A.8.25-26-29: Secure Development Lifecycle
A3: Req # | B3: Section | C3: Requirement | D3: Status | E3: Evidence | F3: Owner | G3: Due Date | H3: Notes
A4: A.8.25-26-29-03 | B4: Development, Test, And Production | C4: Development, test, and production environments shall be separated and shall not share common components, databases, or storage.
A5: A.8.25-26-29-04 | B5: Development, Test, And Production | C5: Development, test, and production environments shall be on separate networks or network segments.
A6: A.8.25-26-29-05 | B6: Be A Segregation Of Administrative | C6: There shall be a segregation of administrative duties between development/test and production environments. Personnel with write access to development repositories shall not have direct administrative access to production systems without separate authorisation.
A7: A.8.25-26-29-06 | B7: Not Flow From Production To Development | C7: Data shall not flow from production to development or test environments without explicit approval and appropriate sanitisation (see Test Data Protection section).
A8: A.8.25-26-29-07 | B8: Configuration Of Environment Segregation | C8: Configuration of environment segregation shall be documented, and compliance shall be verified at least annually.

Sheet Application Risk Classification
A1: Application Risk Classification — Compliance Checklist
A2: ISO/IEC 27001:2022 — Controls A.8.25-26-29: Secure Development Lifecycle
A3: Req # | B3: Section | C3: Requirement | D3: Status | E3: Evidence | F3: Owner | G3: Due Date | H3: Notes
A4: A.8.25-26-29-08 | B4: Be Classified By Risk Level To | C4: All applications shall be classified by risk level to determine the appropriate security requirements.
A5: A.8.25-26-29-09 | B5: Application Risk Classifications | C5: Application risk classifications shall be reviewed annually by the Development Manager and CISO.
A6: A.8.25-26-29-10 | B6: The Classification | C6: The classification shall be recorded in the application risk classification register.

Sheet Security Requirements
A1: Security Requirements — Compliance Checklist
A2: ISO/IEC 27001:2022 — Controls A.8.25-26-29: Secure Development Lifecycle
A3: Req # | B3: Section | C3: Requirement | D3: Status | E3: Evidence | F3: Owner | G3: Due Date | H3: Notes
A4: A.8.25-26-29-11 | B4: Security Requirements | C4: Security requirements shall be specified for all applications based on risk classification.
A5: A.8.25-26-29-12 | B5: Recommended For Medium-Risk), The | C5: Where threat modelling is required (mandatory for High-Risk, recommended for Medium-Risk), the following process shall be followed:.
A6: A.8.25-26-29-13 | B6: Threat Models | C6: Threat models shall be reviewed and updated: at each major release; when the application architecture changes significantly; when new threat intelligence relevant to the application is identified; and at least annually for High-Risk applications.
A7: A.8.25-26-29-14 | B7: Security Requirements | C7: Security requirements shall address the following areas as a minimum*:.
A8: A.8.25-26-29-15 | B8: For Applications That Provide | C8: For applications that provide transactional services between the organisation and external parties, additional requirements shall address identity trust levels, integrity of exchanged information, non-repudiation, and confidentiality of transactions.
A9: A.8.25-26-29-16 | B9: Security Requirements Specifications | C9: Security requirements specifications shall follow a standardised template covering the following sections:.
A10: A.8.25-26-29-17 | B10: Security Requirements | C10: Security requirements shall be approved by the CISO (High-Risk) or Development Manager (Medium/Low-Risk) before development begins.

Sheet Secure Coding Guidelines
A1: Secure Coding Guidelines — Compliance Checklist
A2: ISO/IEC 27001:2022 — Controls A.8.25-26-29: Secure Development Lifecycle
A3: Req # | B3: Section | C3: Requirement | D3: Status | E3: Evidence | F3: Owner | G3: Due Date | H3: Notes
A4: A.8.25-26-29-18 | B4: Be Designed And Developed Based On | C4: Software shall be designed and developed based on industry-recognised secure coding guidelines, including:.
A5: A.8.25-26-29-19 | B5: Language-Specific Secure Coding | C5: Language-specific secure coding standards shall be documented and maintained for each programming language in active use. These shall cover, at a minimum:.
A6: A.8.25-26-29-20 | B6: Example — Python Secure Coding Standard* | C6: Example — Python Secure Coding Standard* (illustrative; each language shall have equivalent documentation):.
A7: A.8.25-26-29-21 | B7: Language-Specific Standards | C7: Language-specific standards shall be stored in the code repository (e.g., docs/secure-coding/ or equivalent), reviewed annually, and updated when new vulnerabilities or patterns emerge.
A8: A.8.25-26-29-22 | B8: Complete Secure Coding Training Before | C8: All developers shall complete secure coding training before being granted access to write production code (see Developer Security Training section).

Sheet Code Repositories & Version
A1: Code Repositories & Version — Compliance Checklist
A2: ISO/IEC 27001:2022 — Controls A.8.25-26-29: Secure Development Lifecycle
A3: Req # | B3: Section | C3: Requirement | D3: Status | E3: Evidence | F3: Owner | G3: Due Date | H3: Notes
A4: A.8.25-26-29-23 | B4: Development Code | C4: Development code shall be stored in a secure code repository that enforces and meets the requirements of the Access Control Policy and segregation of duty.
A5: A.8.25-26-29-24 | B5: Repository Access | C5: Repository access shall follow the principle of least privilege:.
A6: A.8.25-26-29-25 | B6: Be Granted Based On Project Assignment | C6: Access shall be granted based on project assignment and role.
A7: A.8.25-26-29-26 | B7: Repository Access | C7: Repository access shall be reviewed at least annually, aligned with identity and access management reviews.
A8: A.8.25-26-29-27 | B8: Former Team Members | C8: Former team members shall have access revoked within the same business day of departure.
A9: A.8.25-26-29-28 | B9: Code Repositories | C9: Code repositories shall enforce:.
A10: A.8.25-26-29-29 | B10: Secret Scanning | C10: Secret scanning shall detect, at a minimum: API keys, access tokens, private keys, database connection strings, cloud provider credentials, and webhook URLs.
A11: A.8.25-26-29-30 | B11: Hardcoded Secrets In Source Code Are | C11: Hardcoded secrets in source code are prohibited. Secret scanning results shall be reviewed weekly by the Development Manager.

Sheet Code Review
A1: Code Review — Compliance Checklist
A2: ISO/IEC 27001:2022 — Controls A.8.25-26-29: Secure Development Lifecycle
A3: Req # | B3: Section | C3: Requirement | D3: Status | E3: Evidence | F3: Owner | G3: Due Date | H3: Notes
A4: A.8.25-26-29-31 | B4: Be Reviewed Prior To Release By | C4: All code shall be reviewed prior to release by skilled personnel other than the code author or developer.
A5: A.8.25-26-29-32 | B5: Be Reviewed Against The Secure Coding | C5: Code shall be reviewed against the secure coding guidelines documented by the organisation.
A6: A.8.25-26-29-33 | B6: Code Reviews | C6: Code reviews shall employ both manual and automated techniques:.
A7: A.8.25-26-29-34 | B7: Code Review Findings | C7: Code review findings shall be documented and tracked to resolution before code is approved for promotion.
A8: A.8.25-26-29-35 | B8: Be Approved Before Being Promoted Into | C8: Code shall be approved before being promoted into test or production environments.

Sheet CI CD Pipeline Security Gates
A1: CI CD Pipeline Security Gates — Compliance Checklist
A2: ISO/IEC 27001:2022 — Controls A.8.25-26-29: Secure Development Lifecycle
A3: Req # | B3: Section | C3: Requirement | D3: Status | E3: Evidence | F3: Owner | G3: Due Date | H3: Notes
A4: A.8.25-26-29-36 | B4: Security Checks | C4: Security checks shall be automated within the CI/CD pipeline at defined gates.
A5: A.8.25-26-29-37 | B5: Pipeline Security Gate Results | C5: Pipeline security gate results shall be reported to the Development Manager weekly and the CISO monthly.

Sheet Security Testing Requirements
A1: Security Testing Requirements — Compliance Checklist
A2: ISO/IEC 27001:2022 — Controls A.8.25-26-29: Secure Development Lifecycle
A3: Req # | B3: Section | C3: Requirement | D3: Status | E3: Evidence | F3: Owner | G3: Due Date | H3: Notes
A4: A.8.25-26-29-38 | B4: Security Testing Processes | C4: Security testing processes shall be defined and implemented in the development lifecycle. Testing shall validate that security requirements have been met before deployment to production.
A5: A.8.25-26-29-39 | B5: Application Security Testing | C5: All application security testing shall, at a minimum, test for the OWASP Top 10:2025 categories: Broken Access Control, Security Misconfiguration, Software Supply Chain Failures, Cryptographic Failures, Injection, Insecure Design, Authentication Failures, Software or Data Integrity Failures, Security Logging and Alerting Failures, and Mishandling of Exceptional Conditions.
A6: A.8.25-26-29-40 | B6: Pre-Production Testing | C6: All pre-production testing shall occur in a test environment that mirrors the production environment as closely as possible.
A7: A.8.25-26-29-41 | B7: Environment Verification*: Environment | C7: Environment verification*: Environment parity shall be verified before major security tests (penetration testing, DAST). Verification shall be documented and signed off by the DevOps / Platform Team.
A8: A.8.25-26-29-42 | B8: Test Environment Security*: Test | C8: Test environment security*: Test environments shall be subject to the same access controls as production environments. Test environments shall not be accessible from the internet unless required for DAST testing (with time-limited firewall rules).
A9: A.8.25-26-29-43 | B9: Penetration Testing | C9: All penetration testing shall be conducted by an external specialist company.
A10: A.8.25-26-29-44 | B10: Public-Facing Web Applications | C10: All public-facing web applications shall be tested using manual or automated vulnerability security tools at least annually or after a significant change.
A11: A.8.25-26-29-45 | B11: Testing Standards*: Penetration Tests | C11: Testing standards*: Penetration tests shall follow OWASP Testing Guide v4.2 and/or PTES (Penetration Testing Execution Standard). Test reports shall include: executive summary, methodology, findings with CVSS scoring, evidence (screenshots, request/response), remediation recommendations, and re-test verification.
A12: A.8.25-26-29-46 | B12: Vendor Selection Criteria*: Penetration | C12: Vendor selection criteria*: Penetration testing vendors shall hold relevant certifications (e.g., CREST, OSCP, CEH) and provide evidence of professional indemnity insurance. Vendor engagements shall include signed rules of engagement and NDA.
A13: A.8.25-26-29-47 | B13: High-Risk Applications | C13: High-Risk applications shall maintain an SBOM in CycloneDX or SPDX format.
A14: A.8.25-26-29-48 | B14: Be Generated Automatically During The | C14: SBOMs shall be generated automatically during the build process (every build for High-Risk; weekly for Medium-Risk).
A15: A.8.25-26-29-49 | B15: Be Updated Upon Dependency Changes And | C15: SBOMs shall be updated upon dependency changes and reviewed quarterly for known vulnerabilities.
... A19: A.8.25-26-29-53 | B19: Test Results | C19: Test results, including penetration testing reports, shall be reported to the Management Review Team.

Sheet Vulnerability Remediation
A1: Vulnerability Remediation — Compliance Checklist
A2: ISO/IEC 27001:2022 — Controls A.8.25-26-29: Secure Development Lifecycle
A3: Req # | B3: Section | C3: Requirement | D3: Status | E3: Evidence | F3: Owner | G3: Due Date | H3: Notes
A4: A.8.25-26-29-54 | B4: Security Vulnerabilities Identified | C4: Security vulnerabilities identified during development and testing shall be remediated within defined timeframes based on severity.
A5: A.8.25-26-29-55 | B5: Vulnerabilities Identified As Part Of | C5: All vulnerabilities identified as part of the testing phase, including penetration testing, shall be corrected prior to promotion to production or managed via the risk management and exception process.
A6: A.8.25-26-29-56 | B6: Vulnerabilities Exceeding The | C6: Vulnerabilities exceeding the remediation SLA shall be escalated to the CISO and Application Owner.
A7: A.8.25-26-29-57 | B7: Critical And High Vulnerabilities | C7: Critical and High vulnerabilities overdue beyond the SLA shall block subsequent deployments until remediated or an exception is approved with compensating controls.
A8: A.8.25-26-29-58 | B8: Vulnerability Remediation Status | C8: Vulnerability remediation status shall be reviewed monthly and reported quarterly to the Management Review Team.

Sheet Test Data Protection
A1: Test Data Protection — Compliance Checklist
A2: ISO/IEC 27001:2022 — Controls A.8.25-26-29: Secure Development Lifecycle
A3: Req # | B3: Section | C3: Requirement | D3: Status | E3: Evidence | F3: Owner | G3: Due Date | H3: Notes
A4: A.8.25-26-29-59 | B4: Production Data | C4: Production data shall not be used for testing or development.
A5: A.8.25-26-29-60 | B5: Personal Data (As Defined By Swiss | C5: Personal data (as defined by Swiss nFADP Art. 5) shall not be used for testing or development.
A6: A.8.25-26-29-61 | B6: Be | C6: If sensitive information is required as part of the testing process, it shall be:.
A7: A.8.25-26-29-62 | B7: Synthetic Data* (Artificially Generated | C7: Synthetic data* (artificially generated data with no connection to real individuals) is the preferred approach and shall be used where feasible.
A8: A.8.25-26-29-63 | B8: The Creation And Use Of Test | C8: The creation and use of test data sets shall be documented and approved by the data owner. Test data sets containing transformed personal data shall be treated as Internal classification at a minimum.
A9: A.8.25-26-29-64 | B9: Test Data | C9: Test data shall be securely deleted when no longer required.

Sheet Promoting Code to Production
A1: Promoting Code to Production — Compliance Checklist
A2: ISO/IEC 27001:2022 — Controls A.8.25-26-29: Secure Development Lifecycle
A3: Req # | B3: Section | C3: Requirement | D3: Status | E3: Evidence | F3: Owner | G3: Due Date | H3: Notes
A4: A.8.25-26-29-65 | B4: Be Promoted To Production By Approved | C4: Code shall be promoted to production by approved personnel only and shall be subject to the documented change management process.
A5: A.8.25-26-29-66 | B5: Required Security Gates | C5: All required security gates shall be passed (security testing, code review, vulnerability remediation).
A6: A.8.25-26-29-67 | B6: The Production Environment | C6: The production environment shall be backed up to facilitate rollback in the event of a failed change.
A7: A.8.25-26-29-68 | B7: Test Data | C7: Test data shall be removed from the application.
A8: A.8.25-26-29-69 | B8: No Development Files, Debug | C8: No development files, debug configurations, test accounts, or test data shall be present in the production environment.
A9: A.8.25-26-29-70 | B9: For High-Risk Applications, The Ciso Or | C9: For High-Risk applications, the CISO or designated security authority shall provide explicit sign-off.
A10: A.8.25-26-29-71 | B10: Promotion Records | C10: Promotion records shall include the change ticket reference, approver, security gate status, and deployment timestamp.

Sheet Outsourced Development
A1: Outsourced Development — Compliance Checklist
A2: ISO/IEC 27001:2022 — Controls A.8.25-26-29: Secure Development Lifecycle
A3: Req # | B3: Section | C3: Requirement | D3: Status | E3: Evidence | F3: Owner | G3: Due Date | H3: Notes
A4: A.8.25-26-29-72 | B4: The Organisation'S Secure Development | C4: Where software development is outsourced to third-party contractors or development partners, the organisation's secure development requirements shall apply.
A5: A.8.25-26-29-73 | B5: Contractual Requirements | C5: Contractual requirements shall include*:.
A6: A.8.25-26-29-74 | B6: Submit Security Testing Reports | C6: Contractors shall submit security testing reports (SAST/DAST/SCA results, remediation status) at agreed intervals.
A7: A.8.25-26-29-75 | B7: High-Risk Outsourced Projects | C7: High-Risk outsourced projects shall undergo security review by the organisation's security-qualified personnel at major milestones (design approval, pre-production).
A8: A.8.25-26-29-76 | B8: Code Delivered By Contractors | C8: Code delivered by contractors shall undergo the same code review and security testing process as internally developed code before acceptance.

Sheet Developer Security Training
A1: Developer Security Training — Compliance Checklist
A2: ISO/IEC 27001:2022 — Controls A.8.25-26-29: Secure Development Lifecycle
A3: Req # | B3: Section | C3: Requirement | D3: Status | E3: Evidence | F3: Owner | G3: Due Date | H3: Notes
A4: A.8.25-26-29-77 | B4: Complete Security Training Appropriate | C4: All developers shall complete security training appropriate to their role and responsibilities.
A5: A.8.25-26-29-78 | B5: Cover, At A Minimum | C5: Training shall cover, at a minimum:.
A6: A.8.25-26-29-79 | B6: Training Completion | C6: Training completion shall be recorded and verified before granting production code access. Training records shall be retained for the duration of employment plus 3 years.
A7: A.8.25-26-29-80 | B7: Selection Criteria*: Security Champions | C7: Selection criteria*: Security Champions shall be nominated from development teams based on: demonstrated interest in security, minimum 2 years development experience, willingness to commit approximately 10% of working time to security activities, and team lead endorsement.
A8: A.8.25-26-29-81 | B8: Incentives*: Security Champion | C8: Incentives*: Security Champion contributions shall be recognised in performance reviews. The organisation should consider conference attendance, certification sponsorship, or similar professional development opportunities.
