Workbook

Sheet Executive Summary
A1: ISMS-OP-CHK-A.5.1-2-6.1-2 — ISMS Governance and Secure Employment Compliance Checklist
A3: DOCUMENT INFORMATION
A4: Document ID | B4: ISMS-OP-CHK-A.5.1-2-6.1-2
A5: Source Policy | B5: ISMS-OP-POL-A.5.1-2-6.1-2
A6: ISO Controls | B6: ISMS Governance and Secure Employment
A7: Generated | B7: 08.02.2026
A8: Prepared By
A9: Organisation
A10: Review Cycle | B10: Annual
A12: OVERALL COMPLIANCE STATUS
A13: Overall Compliance | B13: ='Dashboard'!G9
A14: Status | B14: =IF(Dashboard!G9="N/A","NOT ASSESSED",IF(ISNUMBER(VALUE(SUBSTITUTE(Dashboard!G9,"%",""))),IF(VALUE(SUBSTITUTE(Dashboard!G9,"%",""))>=90,"GREEN",IF(VALUE(SUBSTITUTE(Dashboard!G9,"%",""))>=70,"AMBER","RED")),"NOT ASSESSED"))
A16: KEY METRICS
A17: Total Requirements | B17: ='Dashboard'!B9
A18: Compliant | B18: ='Dashboard'!C9
A19: Partial | B19: ='Dashboard'!D9
A20: Non-Compliant | B20: ='Dashboard'!E9
A21: Not Applicable | B21: ='Dashboard'!F9
A22: Owner Coverage | B22: =IF(Dashboard!B9=0,"N/A",ROUND((COUNTA('Info Security Policy Framework'!F4:F19)+COUNTA('Personnel Screening'!F4:F14)+COUNTA('Terms and Conditions of Employ'!F4:F9)+COUNTA('Monitoring'!F4:F4)+COUNTA('Legal and Reg Obligations'!F4:F4))/Dashboard!B9*100,0)&"%")
A24: DOMAIN STATUS SUMMARY
A25: Domain | B25: Compliance % | C25: Compliant | D25: Gaps | E25: Status
A26: Info Security Policy Framework | B26: ='Dashboard'!G4 | C26: ='Dashboard'!C4 | D26: ='Dashboard'!E4 | E26: =IF(Dashboard!G4="N/A","--",IF(ISNUMBER(VALUE(SUBSTITUTE(Dashboard!G4,"%",""))),IF(VALUE(SUBSTITUTE(Dashboard!G4,"%",""))>=90,"PASS",IF(VALUE(SUBSTITUTE(Dashboard!G4,"%",""))>=70,"REVIEW","FAIL")),"--"))
A27: Personnel Screening | B27: ='Dashboard'!G5 | C27: ='Dashboard'!C5 | D27: ='Dashboard'!E5 | E27: =IF(Dashboard!G5="N/A","--",IF(ISNUMBER(VALUE(SUBSTITUTE(Dashboard!G5,"%",""))),IF(VALUE(SUBSTITUTE(Dashboard!G5,"%",""))>=90,"PASS",IF(VALUE(SUBSTITUTE(Dashboard!G5,"%",""))>=70,"REVIEW","FAIL")),"--"))
A28: Terms and Conditions of Employ | B28: ='Dashboard'!G6 | C28: ='Dashboard'!C6 | D28: ='Dashboard'!E6 | E28: =IF(Dashboard!G6="N/A","--",IF(ISNUMBER(VALUE(SUBSTITUTE(Dashboard!G6,"%",""))),IF(VALUE(SUBSTITUTE(Dashboard!G6,"%",""))>=90,"PASS",IF(VALUE(SUBSTITUTE(Dashboard!G6,"%",""))>=70,"REVIEW","FAIL")),"--"))
A29: Monitoring | B29: ='Dashboard'!G7 | C29: ='Dashboard'!C7 | D29: ='Dashboard'!E7 | E29: =IF(Dashboard!G7="N/A","--",IF(ISNUMBER(VALUE(SUBSTITUTE(Dashboard!G7,"%",""))),IF(VALUE(SUBSTITUTE(Dashboard!G7,"%",""))>=90,"PASS",IF(VALUE(SUBSTITUTE(Dashboard!G7,"%",""))>=70,"REVIEW","FAIL")),"--"))
A30: Legal and Reg Obligations | B30: ='Dashboard'!G8 | C30: ='Dashboard'!C8 | D30: ='Dashboard'!E8 | E30: =IF(Dashboard!G8="N/A","--",IF(ISNUMBER(VALUE(SUBSTITUTE(Dashboard!G8,"%",""))),IF(VALUE(SUBSTITUTE(Dashboard!G8,"%",""))>=90,"PASS",IF(VALUE(SUBSTITUTE(Dashboard!G8,"%",""))>=70,"REVIEW","FAIL")),"--"))
A32: CRITICAL ISSUES
A33: # | B33: Issue Description | C33: Domain | D33: Owner | E33: Due Date
A34: 1
A35: 2
A36: 3
A37: 4
A38: 5
A40: MANAGEMENT COMMENTARY
A41: [Enter management commentary on isms governance and secure employment posture]
A45: APPROVAL
A46: Assessed By
A47: Name:
A48: Date:
A49: Signature:
...

Sheet Dashboard
A1: ISMS Governance and Secure Employment — Compliance Dashboard
A3: Domain | B3: Total Reqs | C3: Compliant | D3: Partial | E3: Non-Compliant | F3: N/A | G3: Compliance %
A4: Info Security Policy Framework | B4: =COUNTA('Info Security Policy Framework'!D4:D19) | C4: =COUNTIF('Info Security Policy Framework'!D4:D19,"Compliant") | D4: =COUNTIF('Info Security Policy Framework'!D4:D19,"Partial") | E4: =COUNTIF('Info Security Policy Framework'!D4:D19,"Non-Compliant") | F4: =COUNTIF('Info Security Policy Framework'!D4:D19,"N/A") | G4: =IF((B4-F4)=0,"N/A",ROUND(C4/(B4-F4)*100,1)&"%")
A5: Personnel Screening | B5: =COUNTA('Personnel Screening'!D4:D14) | C5: =COUNTIF('Personnel Screening'!D4:D14,"Compliant") | D5: =COUNTIF('Personnel Screening'!D4:D14,"Partial") | E5: =COUNTIF('Personnel Screening'!D4:D14,"Non-Compliant") | F5: =COUNTIF('Personnel Screening'!D4:D14,"N/A") | G5: =IF((B5-F5)=0,"N/A",ROUND(C5/(B5-F5)*100,1)&"%")
A6: Terms and Conditions of Employ | B6: =COUNTA('Terms and Conditions of Employ'!D4:D9) | C6: =COUNTIF('Terms and Conditions of Employ'!D4:D9,"Compliant") | D6: =COUNTIF('Terms and Conditions of Employ'!D4:D9,"Partial") | E6: =COUNTIF('Terms and Conditions of Employ'!D4:D9,"Non-Compliant") | F6: =COUNTIF('Terms and Conditions of Employ'!D4:D9,"N/A") | G6: =IF((B6-F6)=0,"N/A",ROUND(C6/(B6-F6)*100,1)&"%")
A7: Monitoring | B7: =COUNTA('Monitoring'!D4:D4) | C7: =COUNTIF('Monitoring'!D4:D4,"Compliant") | D7: =COUNTIF('Monitoring'!D4:D4,"Partial") | E7: =COUNTIF('Monitoring'!D4:D4,"Non-Compliant") | F7: =COUNTIF('Monitoring'!D4:D4,"N/A") | G7: =IF((B7-F7)=0,"N/A",ROUND(C7/(B7-F7)*100,1)&"%")
A8: Legal and Reg Obligations | B8: =COUNTA('Legal and Reg Obligations'!D4:D4) | C8: =COUNTIF('Legal and Reg Obligations'!D4:D4,"Compliant") | D8: =COUNTIF('Legal and Reg Obligations'!D4:D4,"Partial") | E8: =COUNTIF('Legal and Reg Obligations'!D4:D4,"Non-Compliant") | F8: =COUNTIF('Legal and Reg Obligations'!D4:D4,"N/A") | G8: =IF((B8-F8)=0,"N/A",ROUND(C8/(B8-F8)*100,1)&"%")
A9: TOTAL | B9: =SUM(B4:B8) | C9: =SUM(C4:C8) | D9: =SUM(D4:D8) | E9: =SUM(E4:E8) | F9: =SUM(F4:F8) | G9: =IF((B9-F9)=0,"N/A",ROUND(C9/(B9-F9)*100,1)&"%")
A11: COMPLIANCE BY STATUS
A12: Compliant | B12: =C9 | C12: =IF(B9=0,"",ROUND(B12/B9*100,1)&"%")
A13: Partial | B13: =D9 | C13: =IF(B9=0,"",ROUND(B13/B9*100,1)&"%")
A14: Non-Compliant | B14: =E9 | C14: =IF(B9=0,"",ROUND(B14/B9*100,1)&"%")
A15: N/A | B15: =F9 | C15: =IF(B9=0,"",ROUND(B15/B9*100,1)&"%")
A17: TOP GAPS (Manual Entry)
A18: Priority | B18: Domain | C18: Requirement | D18: Owner | E18: Due Date | F18: Status
A30: COMPLIANCE TREND (Manual Entry)
A31: Assessment Date | B31: Overall % | C31: Compliant | D31: Gaps | E31: Assessor | F31: Notes

Sheet Info Security Policy Framework
A1: Info Security Policy Framework — Compliance Checklist
A2: ISO/IEC 27001:2022 — Controls A.5.1-2-6.1-2: ISMS Governance and Secure Employment
A3: Req # | B3: Section | C3: Requirement | D3: Status | E3: Evidence | F3: Owner | G3: Due Date | H3: Notes
A4: A.5.1-2-6.1-2-01 | B4: Higher-Tier Policies Set Requirements; | C4: Higher-tier policies set requirements; lower-tier documents provide operational detail. Lower-tier documents shall not contradict higher-tier policies.
A5: A.5.1-2-6.1-2-02 | B5: Information Security Policies | C5: Information security policies shall be managed through defined lifecycle stages:.
A6: A.5.1-2-6.1-2-03 | B6: Creation*: Policies | C6: Creation*: Policies shall be developed using the organisational template, with input from stakeholders including Legal, HR, IT, and affected business units.
A7: A.5.1-2-6.1-2-04 | B7: Approval*: Policies | C7: Approval*: Policies shall be approved by the appropriate authority per tier before publication. Policy approval shall be performed by a different individual than the policy author. Tier 2 policies authored by the Security Team shall be approved by the CISO. The Master Policy authored by the CISO shall be approved by the CEO.
A8: A.5.1-2-6.1-2-05 | B8: Publication*: Approved Policies | C8: Publication*: Approved policies shall be published to the organisational policy repository (e.g., SharePoint, Confluence, or equivalent) with version control.
A9: A.5.1-2-6.1-2-06 | B9: Communication*: Policies | C9: Communication*: Policies shall be communicated to all affected personnel. Supplemental training shall be provided when: (a) >30% of users are affected, (b) a new technical control requires user action (e.g., MFA enrolment), or (c) a regulatory deadline is <90 days. Training formats: webinar, e-learning module, or annotated policy guide.
A10: A.5.1-2-6.1-2-07 | B10: Acknowledgment*: Critical Policies | C10: Acknowledgment*: Critical policies (Master Information Security Policy, Acceptable Use Policy, Code of Conduct) shall require formal acknowledgment from all personnel annually. Acknowledgments shall be collected via [electronic signature portal / HR system attestation] and tracked in the Personnel Training and Acknowledgment Register maintained by HR.
A11: A.5.1-2-6.1-2-08 | B11: Review*: Policies | C11: Review*: Policies shall be reviewed at planned intervals (minimum annually) and upon:.
A12: A.5.1-2-6.1-2-09 | B12: Change Management*: Policy Changes | C12: Change management*: Policy changes shall follow the change management process: change request logged in [GRC Tool / Change Management System], impact assessment performed (affected systems, users, controls), approval obtained per policy tier, change communicated to affected personnel, change implementation tracked (old version archived, new version published), and post-implementation review within 30 days to verify acknowledgments collected and no unintended impacts.
A13: A.5.1-2-6.1-2-10 | B13: Retirement*: Retired Policies | C13: Retirement*: Retired policies shall be archived with audit trail retained for a minimum of 3 years.
A14: A.5.1-2-6.1-2-11 | B14: Topic-Specific Policies (Tier 2) | C14: All topic-specific policies (Tier 2) shall include:.
A15: A.5.1-2-6.1-2-12 | B15: Exceptions To Any Information Security | C15: Exceptions to any information security policy shall be:.
... A19: A.5.1-2-6.1-2-16 | B19: Violations (Critical, High, Medium) | C19: All violations (Critical, High, Medium) shall be logged in the Security Incident Register with investigation findings, remediation actions, and closure date. Violations shall be analysed quarterly for trends and policy effectiveness improvement.

Sheet Personnel Screening
A1: Personnel Screening — Compliance Checklist
A2: ISO/IEC 27001:2022 — Controls A.5.1-2-6.1-2: ISMS Governance and Secure Employment
A3: Req # | B3: Section | C3: Requirement | D3: Status | E3: Evidence | F3: Owner | G3: Due Date | H3: Notes
A4: A.5.1-2-6.1-2-17 | B4: Conduct Background Verification Checks | C4: The organisation shall conduct background verification checks based on:.
A5: A.5.1-2-6.1-2-18 | B5: Proportionality*: Screening Intensity | C5: Proportionality*: Screening intensity shall be proportional to the sensitivity of information accessed, the criticality of the role, the level of system access and privileges, and regulatory requirements.
A6: A.5.1-2-6.1-2-19 | B6: Legality*: All Screening | C6: Legality*: All screening shall comply with Swiss Code of Obligations (OR) Art. 328 and 328b, Swiss nFADP (revDSG), and local employment law. Under Swiss law, employers may only collect information relevant to the role. Written consent from the candidate shall be obtained before conducting background checks. Criminal record checks may cover up to seven years in Switzerland.
A7: A.5.1-2-6.1-2-20 | B7: Fairness*: Screening | C7: Fairness*: Screening shall be conducted transparently. Candidates shall be informed before screening is conducted, consent shall be obtained where required, criteria shall be non-discriminatory and job-relevant, and candidates shall have the opportunity to clarify adverse findings.
A8: A.5.1-2-6.1-2-21 | B8: Confidentiality*: Screening Results | C8: Confidentiality*: Screening results shall be accessed only by HR and authorised hiring personnel, stored securely in [HR System] with access controls, retained for the duration of employment plus 2 years (for defence of employment decisions), and securely destroyed per the data deletion procedure thereafter.
A9: A.5.1-2-6.1-2-22 | B9: Classify Roles By Sensitivity And Apply | C9: The organisation shall classify roles by sensitivity and apply appropriate screening:.
A10: A.5.1-2-6.1-2-23 | B10: The Role-To-Screening-Level Mapping | C10: The role-to-screening-level mapping shall be documented and maintained by HR in consultation with the CISO. Assignments shall be reviewed annually and upon organisational restructure. Changes require CISO approval and HR execution.
A11: A.5.1-2-6.1-2-24 | B11: Pre-Employment*: Screening | C11: Pre-employment*: Screening shall be completed before granting organisational access.
A12: A.5.1-2-6.1-2-25 | B12: Re-Screening | C12: Re-screening shall be conducted only where: (a) contractually agreed in employment terms, (b) required by regulation (e.g., FINMA for financial sector roles), or (c) triggered by security incident or role change requiring elevated access.
A13: A.5.1-2-6.1-2-26 | B13: Adverse Findings | C13: Adverse findings shall be discussed with the candidate to allow clarification, assessed for relevance, recency, and severity, documented with a decision rationale, and handled consistently and non-discriminatorily.
A14: A.5.1-2-6.1-2-27 | B14: Third-Party Personnel Screening | C14: Third-party personnel screening shall be specified in contracts (minimum screening requirements equivalent to the access granted), attested by the vendor, and spot-checked by the organisation (sample verification per the third-party spot-checking process).

Sheet Terms and Conditions of Employ
A1: Terms and Conditions of Employ — Compliance Checklist
A2: ISO/IEC 27001:2022 — Controls A.5.1-2-6.1-2: ISMS Governance and Secure Employment
A3: Req # | B3: Section | C3: Requirement | D3: Status | E3: Evidence | F3: Owner | G3: Due Date | H3: Notes
A4: A.5.1-2-6.1-2-28 | B4: Information Security Obligations | C4: Information security obligations shall be included in all employment-related contracts:.
A5: A.5.1-2-6.1-2-29 | B5: Employment Contracts | C5: All employment contracts shall include the following information security clauses:.
A6: A.5.1-2-6.1-2-30 | B6: New Hire Training | C6: New hire training shall cover: Acceptable Use Policy key requirements (authorised use, prohibited activities), information classification and handling rules, incident identification and reporting procedure, password and authentication requirements, physical security (badge use, visitor management, clean desk), and data protection obligations (confidentiality, nFADP/GDPR basics). Training delivered via [LMS platform] with completion tracked by HR. Certification required to provision system access.
A7: A.5.1-2-6.1-2-31 | B7: Upon Employee Termination (Voluntary Or | C7: Upon employee termination (voluntary or involuntary), the Line Manager shall initiate the termination workflow in [HR System] immediately. HR notifies IT Service Desk on the same business day. IT Service Desk:.
A8: A.5.1-2-6.1-2-32 | B8: Be Signed Before Access Is Granted | C8: Contracts shall be signed before access is granted:.
A9: A.5.1-2-6.1-2-33 | B9: Acknowledgments (Nda, Aup, Training | C9: All acknowledgments (NDA, AUP, training completion) shall be collected with signature (physical or electronic), tracked in [HR System], and re-collected annually for critical policies. Acknowledgment compliance shall be reported quarterly to the ISMS Committee. Personnel who do not acknowledge critical policies within 30 days of communication shall have system access suspended until acknowledgment is completed. Line managers shall be notified at 21 days.

Sheet Monitoring
A1: Monitoring — Compliance Checklist
A2: ISO/IEC 27001:2022 — Controls A.5.1-2-6.1-2: ISMS Governance and Secure Employment
A3: Req # | B3: Section | C3: Requirement | D3: Status | E3: Evidence | F3: Owner | G3: Due Date | H3: Notes
A4: A.5.1-2-6.1-2-34 | B4: Compliance With The Policies And | C4: Compliance with the policies and procedures of the information security management system shall be monitored via the Management Review Team, together with independent reviews by both internal and external audit on a periodic basis.

Sheet Legal and Reg Obligations
A1: Legal and Reg Obligations — Compliance Checklist
A2: ISO/IEC 27001:2022 — Controls A.5.1-2-6.1-2: ISMS Governance and Secure Employment
A3: Req # | B3: Section | C3: Requirement | D3: Status | E3: Evidence | F3: Owner | G3: Due Date | H3: Notes
A4: A.5.1-2-6.1-2-35 | B4: The Organisation Takes Its Legal And | C4: The organisation takes its legal and regulatory obligations seriously. Requirements arising from Swiss nFADP (revDSG), the Swiss Code of Obligations, and other applicable regulations are recorded in the Legal and Contractual Requirements Register. This register shall be reviewed at least annually and updated when new regulations apply or existing regulations change materially.
