Workbook

Sheet Executive Summary
A1: ISMS-OP-CHK-A.7.6-7-14 — Secure Areas and Media Handling Compliance Checklist
A3: DOCUMENT INFORMATION
A4: Document ID | B4: ISMS-OP-CHK-A.7.6-7-14
A5: Source Policy | B5: ISMS-OP-POL-A.7.6-7-14
A6: ISO Controls | B6: Secure Areas and Media Handling
A7: Generated | B7: 30.09.2026
A8: Prepared By
A9: Organisation
A10: Review Cycle | B10: Annual
A12: OVERALL COMPLIANCE STATUS
A13: Overall Compliance | B13: ='Dashboard'!G9
A14: Status | B14: =IF(Dashboard!H9>0,"INCOMPLETE",IF(Dashboard!G9="N/A","NOT ASSESSED",IF(ISNUMBER(VALUE(SUBSTITUTE(Dashboard!G9,"%",""))),IF(VALUE(SUBSTITUTE(Dashboard!G9,"%",""))>=90,"GREEN",IF(VALUE(SUBSTITUTE(Dashboard!G9,"%",""))>=70,"AMBER","RED")),"NOT ASSESSED")))
A16: KEY METRICS
A17: Total Requirements | B17: ='Dashboard'!B9
A18: Compliant | B18: ='Dashboard'!C9
A19: Partial | B19: ='Dashboard'!D9
A20: Non-Compliant | B20: ='Dashboard'!E9
A21: Not Applicable | B21: ='Dashboard'!F9
A22: Unanswered | B22: ='Dashboard'!H9
A23: Owner Coverage | B23: =IF(Dashboard!B9=0,"N/A",ROUND((COUNTA('Working in Secure Areas'!F4:F19)+COUNTA('Clear Desk and Clear Screen'!F4:F25)+COUNTA('Secure Disposal or Re-Use'!F4:F32)+COUNTA('SOC 2 Considerations'!F4:F5)+COUNTA('Optional Payment Card Data'!F4:F6))/Dashboard!B9*100,0)&"%")
A25: DOMAIN STATUS SUMMARY
A26: Domain | B26: Compliance % | C26: Compliant | D26: Gaps | E26: Status
A27: Working in Secure Areas | B27: ='Dashboard'!G4 | C27: ='Dashboard'!C4 | D27: ='Dashboard'!E4 | E27: =IF(Dashboard!H4>0,"INCOMPLETE",IF(Dashboard!G4="N/A","--",IF(ISNUMBER(VALUE(SUBSTITUTE(Dashboard!G4,"%",""))),IF(VALUE(SUBSTITUTE(Dashboard!G4,"%",""))>=90,"PASS",IF(VALUE(SUBSTITUTE(Dashboard!G4,"%",""))>=70,"REVIEW","FAIL")),"--")))
A28: Clear Desk and Clear Screen | B28: ='Dashboard'!G5 | C28: ='Dashboard'!C5 | D28: ='Dashboard'!E5 | E28: =IF(Dashboard!H5>0,"INCOMPLETE",IF(Dashboard!G5="N/A","--",IF(ISNUMBER(VALUE(SUBSTITUTE(Dashboard!G5,"%",""))),IF(VALUE(SUBSTITUTE(Dashboard!G5,"%",""))>=90,"PASS",IF(VALUE(SUBSTITUTE(Dashboard!G5,"%",""))>=70,"REVIEW","FAIL")),"--")))
A29: Secure Disposal or Re-Use | B29: ='Dashboard'!G6 | C29: ='Dashboard'!C6 | D29: ='Dashboard'!E6 | E29: =IF(Dashboard!H6>0,"INCOMPLETE",IF(Dashboard!G6="N/A","--",IF(ISNUMBER(VALUE(SUBSTITUTE(Dashboard!G6,"%",""))),IF(VALUE(SUBSTITUTE(Dashboard!G6,"%",""))>=90,"PASS",IF(VALUE(SUBSTITUTE(Dashboard!G6,"%",""))>=70,"REVIEW","FAIL")),"--")))
A30: SOC 2 Considerations | B30: ='Dashboard'!G7 | C30: ='Dashboard'!C7 | D30: ='Dashboard'!E7 | E30: =IF(Dashboard!H7>0,"INCOMPLETE",IF(Dashboard!G7="N/A","--",IF(ISNUMBER(VALUE(SUBSTITUTE(Dashboard!G7,"%",""))),IF(VALUE(SUBSTITUTE(Dashboard!G7,"%",""))>=90,"PASS",IF(VALUE(SUBSTITUTE(Dashboard!G7,"%",""))>=70,"REVIEW","FAIL")),"--")))
A31: Optional Payment Card Data | B31: ='Dashboard'!G8 | C31: ='Dashboard'!C8 | D31: ='Dashboard'!E8 | E31: =IF(Dashboard!H8>0,"INCOMPLETE",IF(Dashboard!G8="N/A","--",IF(ISNUMBER(VALUE(SUBSTITUTE(Dashboard!G8,"%",""))),IF(VALUE(SUBSTITUTE(Dashboard!G8,"%",""))>=90,"PASS",IF(VALUE(SUBSTITUTE(Dashboard!G8,"%",""))>=70,"REVIEW","FAIL")),"--")))
A33: CRITICAL ISSUES
A34: # | B34: Issue Description | C34: Domain | D34: Owner | E34: Due Date
A35: 1
A36: 2
A37: 3
A38: 4
A39: 5
A41: MANAGEMENT COMMENTARY
A42: [Enter management commentary on secure areas and media handling posture]
A46: APPROVAL
A47: Assessed By
A48: Name:
A49: Date:
...

Sheet Dashboard
A1: Secure Areas and Media Handling — Compliance Dashboard
A3: Domain | B3: Total Reqs | C3: Compliant | D3: Partial | E3: Non-Compliant | F3: N/A | G3: Compliance % | H3: Unassessed
A4: Working in Secure Areas | B4: =COUNTA('Working in Secure Areas'!A4:A19) | C4: =COUNTIF('Working in Secure Areas'!D4:D19,"Compliant") | D4: =COUNTIF('Working in Secure Areas'!D4:D19,"Partial") | E4: =COUNTIF('Working in Secure Areas'!D4:D19,"Non-Compliant") | F4: =COUNTIF('Working in Secure Areas'!D4:D19,"N/A") | G4: =IF((B4-F4)=0,"N/A",ROUND(C4/(B4-F4)*100,1)&"%") | H4: =B4-(C4+D4+E4+F4)
A5: Clear Desk and Clear Screen | B5: =COUNTA('Clear Desk and Clear Screen'!A4:A25) | C5: =COUNTIF('Clear Desk and Clear Screen'!D4:D25,"Compliant") | D5: =COUNTIF('Clear Desk and Clear Screen'!D4:D25,"Partial") | E5: =COUNTIF('Clear Desk and Clear Screen'!D4:D25,"Non-Compliant") | F5: =COUNTIF('Clear Desk and Clear Screen'!D4:D25,"N/A") | G5: =IF((B5-F5)=0,"N/A",ROUND(C5/(B5-F5)*100,1)&"%") | H5: =B5-(C5+D5+E5+F5)
A6: Secure Disposal or Re-Use | B6: =COUNTA('Secure Disposal or Re-Use'!A4:A32) | C6: =COUNTIF('Secure Disposal or Re-Use'!D4:D32,"Compliant") | D6: =COUNTIF('Secure Disposal or Re-Use'!D4:D32,"Partial") | E6: =COUNTIF('Secure Disposal or Re-Use'!D4:D32,"Non-Compliant") | F6: =COUNTIF('Secure Disposal or Re-Use'!D4:D32,"N/A") | G6: =IF((B6-F6)=0,"N/A",ROUND(C6/(B6-F6)*100,1)&"%") | H6: =B6-(C6+D6+E6+F6)
A7: SOC 2 Considerations | B7: =COUNTA('SOC 2 Considerations'!A4:A5) | C7: =COUNTIF('SOC 2 Considerations'!D4:D5,"Compliant") | D7: =COUNTIF('SOC 2 Considerations'!D4:D5,"Partial") | E7: =COUNTIF('SOC 2 Considerations'!D4:D5,"Non-Compliant") | F7: =COUNTIF('SOC 2 Considerations'!D4:D5,"N/A") | G7: =IF((B7-F7)=0,"N/A",ROUND(C7/(B7-F7)*100,1)&"%") | H7: =B7-(C7+D7+E7+F7)
A8: Optional Payment Card Data | B8: =COUNTA('Optional Payment Card Data'!A4:A6) | C8: =COUNTIF('Optional Payment Card Data'!D4:D6,"Compliant") | D8: =COUNTIF('Optional Payment Card Data'!D4:D6,"Partial") | E8: =COUNTIF('Optional Payment Card Data'!D4:D6,"Non-Compliant") | F8: =COUNTIF('Optional Payment Card Data'!D4:D6,"N/A") | G8: =IF((B8-F8)=0,"N/A",ROUND(C8/(B8-F8)*100,1)&"%") | H8: =B8-(C8+D8+E8+F8)
A9: TOTAL | B9: =SUM(B4:B8) | C9: =SUM(C4:C8) | D9: =SUM(D4:D8) | E9: =SUM(E4:E8) | F9: =SUM(F4:F8) | G9: =IF((B9-F9)=0,"N/A",ROUND(C9/(B9-F9)*100,1)&"%") | H9: =SUM(H4:H8)
A11: COMPLIANCE BY STATUS
A12: Compliant | B12: =C9 | C12: =IF(B9=0,"",ROUND(B12/B9*100,1)&"%")
A13: Partial | B13: =D9 | C13: =IF(B9=0,"",ROUND(B13/B9*100,1)&"%")
A14: Non-Compliant | B14: =E9 | C14: =IF(B9=0,"",ROUND(B14/B9*100,1)&"%")
A15: N/A | B15: =F9 | C15: =IF(B9=0,"",ROUND(B15/B9*100,1)&"%")
A17: TOP GAPS (Manual Entry)
A18: Priority | B18: Domain | C18: Requirement | D18: Owner | E18: Due Date | F18: Status
A30: COMPLIANCE TREND (Manual Entry)
A31: Assessment Date | B31: Overall % | C31: Compliant | D31: Gaps | E31: Assessor | F31: Notes

Sheet Working in Secure Areas
A1: Working in Secure Areas — Compliance Checklist
A2: ISO/IEC 27001:2022 — Controls A.7.6-7-14: Secure Areas and Media Handling
A3: Req # | B3: Section | C3: Requirement | D3: Status | E3: Evidence | F3: Owner | G3: Due Date | H3: Notes
A4: A.7.6-7-14-01 | B4: Personnel Working In Secure Areas | C4: Personnel working in secure areas shall follow these requirements:.
A5: A.7.6-7-14-02 | B5: Access To Secure Areas | C5: Access to secure areas shall be granted only to authorised personnel based on job role and need-to-know principle.
A6: A.7.6-7-14-03 | B6: Only Be Made Aware Of Activities | C6: Personnel shall only be made aware of activities within secure areas on a need-to-know basis.
A7: A.7.6-7-14-04 | B7: Not Work Alone In Secure Areas | C7: Personnel shall not work alone in secure areas outside normal business hours unless an approved exception exists with compensating controls in place (e.g., check-in procedure with reception or colleague, CCTV monitoring, or buddy system).
A8: A.7.6-7-14-05 | B8: Empty Secure Areas | C8: Empty secure areas shall be physically locked and periodically checked.
A9: A.7.6-7-14-06 | B9: Photography, Video, Audio, Or Other | C9: Photography, video, audio, or other recording in secure areas shall be prohibited unless specifically authorised in writing by the Secure Area Owner.
A10: A.7.6-7-14-07 | B10: Mobile Phones, Cameras, And | C10: Mobile phones, cameras, and recording-capable devices shall not be brought into high-security areas (e.g., server rooms) unless authorised.
A11: A.7.6-7-14-08 | B11: Third Parties (Contractors, Vendors, | C11: Third parties (contractors, vendors, visitors) shall be escorted at all times within secure areas.
A12: A.7.6-7-14-09 | B12: Third-Party Access | C12: Third-party access shall be logged with entry and exit times and shall be time-limited to the duration of the specific task.
A13: A.7.6-7-14-10 | B13: Third Parties | C13: Third parties shall sign a confidentiality or non-disclosure agreement before entering secure areas.
A14: A.7.6-7-14-11 | B14: Third-Party Equipment | C14: Third-party equipment shall not be brought into secure areas unless authorised by the Secure Area Owner or Security Team.
A15: A.7.6-7-14-12 | B15: Sensitive Information | C15: Sensitive information shall not be discussed where it may be overheard by unauthorised persons.
... A19: A.7.6-7-14-16 | B19: This Register | C19: This register shall be reviewed annually or when organisational changes affect secure area designations.

Sheet Clear Desk and Clear Screen
A1: Clear Desk and Clear Screen — Compliance Checklist
A2: ISO/IEC 27001:2022 — Controls A.7.6-7-14: Secure Areas and Media Handling
A3: Req # | B3: Section | C3: Requirement | D3: Status | E3: Evidence | F3: Owner | G3: Due Date | H3: Notes
A4: A.7.6-7-14-17 | B4: Sensitive Documents | C4: Sensitive documents shall be stored in locked drawers or cabinets when not in immediate active use.
A5: A.7.6-7-14-18 | B5: Documents Awaiting Printing | C5: Documents awaiting printing shall be collected immediately using secure print release where available.
A6: A.7.6-7-14-19 | B6: Only Documents Actively Being Worked On | C6: Only documents actively being worked on shall be on desks. Accumulation of classified documents on desks is not permitted.
A7: A.7.6-7-14-20 | B7: Sensitive Documents | C7: All sensitive documents shall be locked in drawers, cabinets, or safes.
A8: A.7.6-7-14-21 | B8: Removable Storage Media (Usb Drives, | C8: Removable storage media (USB drives, external drives, SD cards) shall be secured in locked storage.
A9: A.7.6-7-14-22 | B9: Access Cards, Keys, And Tokens | C9: Access cards, keys, and tokens shall not be left unattended on desks.
A10: A.7.6-7-14-23 | B10: Notebooks And Sticky Notes | C10: Notebooks and sticky notes containing passwords, PINs, or sensitive information shall be secured or destroyed.
A11: A.7.6-7-14-24 | B11: Removable Media | C11: Removable media containing classified information shall be locked away when not in use, regardless of classification level.
A12: A.7.6-7-14-25 | B12: Unmarked Documents | C12: Unmarked documents shall be treated as INTERNAL by default.
A13: A.7.6-7-14-26 | B13: Confidential Waste Bins | C13: Confidential waste bins shall be provided at workstations or in accessible locations for immediate disposal of sensitive paper documents.
A14: A.7.6-7-14-27 | B14: Screen Lock Timeout | C14: Screen lock timeout shall be enforced via [Endpoint Management Tool] (Group Policy, MDM, or equivalent) with the following tiered policy:.
A15: A.7.6-7-14-28 | B15: Manually Lock Screens When Leaving Their | C15: Users shall manually lock screens when leaving their workstation, even briefly, using keyboard shortcuts (Win+L on Windows, Ctrl+Cmd+Q on macOS).
... A25: A.7.6-7-14-38 | B25: Audit Results | C25: Audit results shall be reported as part of the ISMS management review.

Sheet Secure Disposal or Re-Use
A1: Secure Disposal or Re-Use — Compliance Checklist
A2: ISO/IEC 27001:2022 — Controls A.7.6-7-14: Secure Areas and Media Handling
A3: Req # | B3: Section | C3: Requirement | D3: Status | E3: Evidence | F3: Owner | G3: Due Date | H3: Notes
A4: A.7.6-7-14-39 | B4: Before Any Equipment Is Disposed Of | C4: Before any equipment is disposed of or re-used, the following assessment shall be completed:.
A5: A.7.6-7-14-40 | B5: Licensed Software Audit — Identify And | C5: Licensed software audit — Identify and decommission licensed software per licensing terms. Licence keys shall be recovered or transferred where applicable.
A6: A.7.6-7-14-41 | B6: Personal Data Check — Where Equipment | C6: Personal data check — Where equipment may have contained personal data, disposal shall comply with nFADP Art. 8 requirements for rendering data unrecoverable.
A7: A.7.6-7-14-42 | B7: Ssd And Flash Media — Cryptographic | C7: SSD and flash media — cryptographic erasure verification*: Traditional overwrite methods are unreliable for SSDs due to wear-levelling, over-provisioning, and write amplification. Cryptographic erasure on self-encrypting drives (SEDs) is only effective if: (a) the drive was configured with encryption enabled throughout its lifecycle (verified via asset record), and (b) erasure command completion is verified. The following verification procedure shall be applied:.
A8: A.7.6-7-14-43 | B8: Mobile Device Disposal — Encryption | C8: Mobile device disposal — encryption pre-requisite*: Device encryption shall be mandatory from day of deployment for all mobile devices handling INTERNAL or CONFIDENTIAL data (enforced via [MDM] policy, documented in device enrolment record). If a device was deployed without encryption (legacy, non-compliant): default to physical destruction regardless of data classification, and conduct root cause analysis for MDM policy remediation.
A9: A.7.6-7-14-44 | B9: Virtual And Cloud Storage*: Major Cloud | C9: Virtual and cloud storage*: Major cloud providers (AWS, Azure, GCP) do not issue individual destruction certificates for virtual storage. The organisation relies on provider SOC 2 Type II / ISO 27001 certification and data deletion attestations. Risk acceptance for reliance on provider deletion processes shall be documented annually in Management Review. For highest-sensitivity data: client-side encryption before uploading (organisation controls keys in on-premises HSM or separate KMS); upon disposal, delete organisation-managed keys and then delete cloud data; document key deletion with HSM/KMS audit log.
A10: A.7.6-7-14-45 | B10: Iot And Embedded Devices*: Devices With | C10: IoT and embedded devices*: Devices with embedded storage that cannot be sanitised using standard tools (e.g., IoT sensors, building management controllers, medical devices) shall be physically destroyed if they have stored CONFIDENTIAL or INTERNAL data. Where physical destruction is not feasible, the organisation shall obtain vendor guidance on sanitisation and document the method and any residual risk.
A11: A.7.6-7-14-46 | B11: As A Pre-Requisite For Disposal, The | C11: As a pre-requisite for disposal, the organisation shall maintain an inventory of IoT and embedded devices with storage:.
A12: A.7.6-7-14-47 | B12: Inventory Maintained By Facilities + It | C12: Inventory maintained by Facilities + IT Operations, reviewed annually. Unknown devices found during facility changes shall be escalated to CISO for assessment; default assumption: may contain CONFIDENTIAL data → physical destruction.
A13: A.7.6-7-14-48 | B13: Be Securely Erased Using An Approved | C13: All data shall be securely erased using an approved method appropriate to the previous data classification before reassignment.
A14: A.7.6-7-14-49 | B14: Licensed Software | C14: Licensed software shall be transferred or removed per licensing terms.
A15: A.7.6-7-14-50 | B15: [Asset Management System] | C15: [Asset Management System] shall be updated with the new assignee, date, and sanitisation record.
... A32: A.7.6-7-14-67 | B32: Only Use Destruction Vendors Who | C32: The organisation shall only use destruction vendors who:.

Sheet SOC 2 Considerations
A1: SOC 2 Considerations — Compliance Checklist
A2: ISO/IEC 27001:2022 — Controls A.7.6-7-14: Secure Areas and Media Handling
A3: Req # | B3: Section | C3: Requirement | D3: Status | E3: Evidence | F3: Owner | G3: Due Date | H3: Notes
A4: A.7.6-7-14-68 | B4: Systems And Devices That Processed | C4: Systems and devices that processed customer data (CRM, application servers, databases, customer support laptops) shall be flagged in [Asset Management System] with a 'Customer Data' attribute at deployment. At disposal:.
A5: A.7.6-7-14-69 | B5: Roles With Disposal Responsibilities (It | C5: Roles with disposal responsibilities (IT Operations, Facilities personnel authorised for holding area access) shall be subject to background screening per A.6.1 requirements (minimum Standard level screening). Additional requirement for CONFIDENTIAL equipment disposal: Enhanced screening level (see A.6.1 screening levels table). Documented in role-to-screening-level mapping (maintained by HR + CISO).

Sheet Optional Payment Card Data
A1: Optional Payment Card Data — Compliance Checklist
A2: ISO/IEC 27001:2022 — Controls A.7.6-7-14: Secure Areas and Media Handling
A3: Req # | B3: Section | C3: Requirement | D3: Status | E3: Evidence | F3: Owner | G3: Due Date | H3: Notes
A4: A.7.6-7-14-70 | B4: Media | C4: Media containing cardholder data shall be physically destroyed when no longer needed for business or legal reasons (PCI DSS Requirement 9.4).
A5: A.7.6-7-14-71 | B5: An Inventory Of Media | C5: An inventory of media containing cardholder data shall be maintained and reconciled at least annually.
A6: A.7.6-7-14-72 | B6: Secure Disposal Of Cardholder Data Media | C6: Secure disposal of cardholder data media shall be documented with destruction certificates retained per PCI DSS Requirement 9.4.7.
