Workbook

Sheet Executive Summary
A1: AI-CHK-A.4.2-6 — AI System Resources Compliance Checklist
A3: DOCUMENT INFORMATION
A4: Document ID | B4: AI-CHK-A.4.2-6
A5: Source Policy | B5: AI-POL-A.4.2-6
A6: ISO Controls | B6: AI System Resources
A7: Generated | B7: 15.04.2026
A8: Prepared By
A9: Organisation
A10: Review Cycle | B10: Annual
A12: OVERALL COMPLIANCE STATUS
A13: Overall Compliance | B13: ='Dashboard'!G9
A14: Status | B14: =IF(Dashboard!G9="N/A","NOT ASSESSED",IF(ISNUMBER(VALUE(SUBSTITUTE(Dashboard!G9,"%",""))),IF(VALUE(SUBSTITUTE(Dashboard!G9,"%",""))>=90,"GREEN",IF(VALUE(SUBSTITUTE(Dashboard!G9,"%",""))>=70,"AMBER","RED")),"NOT ASSESSED"))
A16: KEY METRICS
A17: Total Requirements | B17: ='Dashboard'!B9
A18: Compliant | B18: ='Dashboard'!C9
A19: Partial | B19: ='Dashboard'!D9
A20: Non-Compliant | B20: ='Dashboard'!E9
A21: Not Applicable | B21: ='Dashboard'!F9
A22: Owner Coverage | B22: =IF(Dashboard!B9=0,"N/A",ROUND((COUNTA('Computing Resources'!F4:F8)+COUNTA('Data Resources'!F4:F7)+COUNTA('Tooling'!F4:F7)+COUNTA('System Architecture'!F4:F7)+COUNTA('Human Resources'!F4:F7))/Dashboard!B9*100,0)&"%")
A24: DOMAIN STATUS SUMMARY
A25: Domain | B25: Compliance % | C25: Compliant | D25: Gaps | E25: Status
A26: Computing Resources | B26: ='Dashboard'!G4 | C26: ='Dashboard'!C4 | D26: ='Dashboard'!E4 | E26: =IF(Dashboard!G4="N/A","--",IF(ISNUMBER(VALUE(SUBSTITUTE(Dashboard!G4,"%",""))),IF(VALUE(SUBSTITUTE(Dashboard!G4,"%",""))>=90,"PASS",IF(VALUE(SUBSTITUTE(Dashboard!G4,"%",""))>=70,"REVIEW","FAIL")),"--"))
A27: Data Resources | B27: ='Dashboard'!G5 | C27: ='Dashboard'!C5 | D27: ='Dashboard'!E5 | E27: =IF(Dashboard!G5="N/A","--",IF(ISNUMBER(VALUE(SUBSTITUTE(Dashboard!G5,"%",""))),IF(VALUE(SUBSTITUTE(Dashboard!G5,"%",""))>=90,"PASS",IF(VALUE(SUBSTITUTE(Dashboard!G5,"%",""))>=70,"REVIEW","FAIL")),"--"))
A28: Tooling | B28: ='Dashboard'!G6 | C28: ='Dashboard'!C6 | D28: ='Dashboard'!E6 | E28: =IF(Dashboard!G6="N/A","--",IF(ISNUMBER(VALUE(SUBSTITUTE(Dashboard!G6,"%",""))),IF(VALUE(SUBSTITUTE(Dashboard!G6,"%",""))>=90,"PASS",IF(VALUE(SUBSTITUTE(Dashboard!G6,"%",""))>=70,"REVIEW","FAIL")),"--"))
A29: System Architecture | B29: ='Dashboard'!G7 | C29: ='Dashboard'!C7 | D29: ='Dashboard'!E7 | E29: =IF(Dashboard!G7="N/A","--",IF(ISNUMBER(VALUE(SUBSTITUTE(Dashboard!G7,"%",""))),IF(VALUE(SUBSTITUTE(Dashboard!G7,"%",""))>=90,"PASS",IF(VALUE(SUBSTITUTE(Dashboard!G7,"%",""))>=70,"REVIEW","FAIL")),"--"))
A30: Human Resources | B30: ='Dashboard'!G8 | C30: ='Dashboard'!C8 | D30: ='Dashboard'!E8 | E30: =IF(Dashboard!G8="N/A","--",IF(ISNUMBER(VALUE(SUBSTITUTE(Dashboard!G8,"%",""))),IF(VALUE(SUBSTITUTE(Dashboard!G8,"%",""))>=90,"PASS",IF(VALUE(SUBSTITUTE(Dashboard!G8,"%",""))>=70,"REVIEW","FAIL")),"--"))
A32: CRITICAL ISSUES
A33: # | B33: Issue Description | C33: Domain | D33: Owner | E33: Due Date
A34: 1
A35: 2
A36: 3
A37: 4
A38: 5
A40: MANAGEMENT COMMENTARY
A41: [Enter management commentary on ai system resources posture]
A45: APPROVAL
A46: Assessed By (AI System Owner)
A47: Name:
A48: Date:
A49: Signature:
...

Sheet Dashboard
A1: AI System Resources — Compliance Dashboard
A3: Domain | B3: Total Reqs | C3: Compliant | D3: Partial | E3: Non-Compliant | F3: N/A | G3: Compliance %
A4: Computing Resources | B4: =COUNTA('Computing Resources'!D4:D8) | C4: =COUNTIF('Computing Resources'!D4:D8,"Compliant") | D4: =COUNTIF('Computing Resources'!D4:D8,"Partial") | E4: =COUNTIF('Computing Resources'!D4:D8,"Non-Compliant") | F4: =COUNTIF('Computing Resources'!D4:D8,"N/A") | G4: =IF((B4-F4)=0,"N/A",ROUND(C4/(B4-F4)*100,1)&"%")
A5: Data Resources | B5: =COUNTA('Data Resources'!D4:D7) | C5: =COUNTIF('Data Resources'!D4:D7,"Compliant") | D5: =COUNTIF('Data Resources'!D4:D7,"Partial") | E5: =COUNTIF('Data Resources'!D4:D7,"Non-Compliant") | F5: =COUNTIF('Data Resources'!D4:D7,"N/A") | G5: =IF((B5-F5)=0,"N/A",ROUND(C5/(B5-F5)*100,1)&"%")
A6: Tooling | B6: =COUNTA('Tooling'!D4:D7) | C6: =COUNTIF('Tooling'!D4:D7,"Compliant") | D6: =COUNTIF('Tooling'!D4:D7,"Partial") | E6: =COUNTIF('Tooling'!D4:D7,"Non-Compliant") | F6: =COUNTIF('Tooling'!D4:D7,"N/A") | G6: =IF((B6-F6)=0,"N/A",ROUND(C6/(B6-F6)*100,1)&"%")
A7: System Architecture | B7: =COUNTA('System Architecture'!D4:D7) | C7: =COUNTIF('System Architecture'!D4:D7,"Compliant") | D7: =COUNTIF('System Architecture'!D4:D7,"Partial") | E7: =COUNTIF('System Architecture'!D4:D7,"Non-Compliant") | F7: =COUNTIF('System Architecture'!D4:D7,"N/A") | G7: =IF((B7-F7)=0,"N/A",ROUND(C7/(B7-F7)*100,1)&"%")
A8: Human Resources | B8: =COUNTA('Human Resources'!D4:D7) | C8: =COUNTIF('Human Resources'!D4:D7,"Compliant") | D8: =COUNTIF('Human Resources'!D4:D7,"Partial") | E8: =COUNTIF('Human Resources'!D4:D7,"Non-Compliant") | F8: =COUNTIF('Human Resources'!D4:D7,"N/A") | G8: =IF((B8-F8)=0,"N/A",ROUND(C8/(B8-F8)*100,1)&"%")
A9: TOTAL | B9: =SUM(B4:B8) | C9: =SUM(C4:C8) | D9: =SUM(D4:D8) | E9: =SUM(E4:E8) | F9: =SUM(F4:F8) | G9: =IF((B9-F9)=0,"N/A",ROUND(C9/(B9-F9)*100,1)&"%")
A11: COMPLIANCE BY STATUS
A12: Compliant | B12: =C9 | C12: =IF(B9=0,"",ROUND(B12/B9*100,1)&"%")
A13: Partial | B13: =D9 | C13: =IF(B9=0,"",ROUND(B13/B9*100,1)&"%")
A14: Non-Compliant | B14: =E9 | C14: =IF(B9=0,"",ROUND(B14/B9*100,1)&"%")
A15: N/A | B15: =F9 | C15: =IF(B9=0,"",ROUND(B15/B9*100,1)&"%")
A17: TOP GAPS (Manual Entry)
A18: Priority | B18: Domain | C18: Requirement | D18: Owner | E18: Due Date | F18: Status
A30: COMPLIANCE TREND (Manual Entry)
A31: Assessment Date | B31: Overall % | C31: Compliant | D31: Gaps | E31: Assessor | F31: Notes

Sheet Computing Resources
A1: Computing Resources — Compliance Checklist
A2: ISO/IEC 42001:2023 — Controls A.4.2-6: AI System Resources
A3: Req # | B3: Section | C3: Requirement | D3: Status | E3: Evidence | F3: Owner | G3: Due Date | H3: Notes
A4: A.4.2-01 | B4: Resource Register | C4: The organisation shall maintain an AI System Resource Register documenting all in-scope AI systems and their associated resources. The Register shall be current and reviewed at minimum annually.
A5: A.4.2-02 | B5: Infrastructure Documentation | C5: For each AI system, the organisation shall document the computing infrastructure on which the system runs, including infrastructure type, provider, and geographic location of data processing.
A6: A.4.2-03 | B6: Supplier Dependencies | C6: The organisation shall identify and document single-vendor dependencies in AI system infrastructure. Systems with critical third-party AI API dependencies shall be assessed for supply chain risk.
A7: A.4.2-04 | B7: Continuity Planning | C7: Computing resource dependencies shall be referenced in business continuity and disaster recovery plans for AI systems rated as critical or High-impact.
A8: A.4.2-05 | B8: Register Currency | C8: The AI System Resource Register shall be updated when any new AI system enters the AIMS scope, when material changes occur, and when systems are decommissioned.

Sheet Data Resources
A1: Data Resources — Compliance Checklist
A2: ISO/IEC 42001:2023 — Controls A.4.2-6: AI System Resources
A3: Req # | B3: Section | C3: Requirement | D3: Status | E3: Evidence | F3: Owner | G3: Due Date | H3: Notes
A4: A.4.3-01 | B4: Data Resource Documentation | C4: The organisation shall document, for each AI system, the training datasets used and the operational data processed at inference time, including source category and data governance record references.
A5: A.4.3-02 | B5: Personal Data Flag | C5: For each AI system's data resources, the organisation shall document whether personal data is involved in training or operational use and shall confirm that a documented legal basis exists where personal data is processed.
A6: A.4.3-03 | B6: Data Records Linkage | C6: Data resource entries in the AI System Resource Register shall link to the full data governance records maintained per AI-POL-A.7.2-6 (Data for AI Systems).
A7: A.4.3-04 | B7: Prohibited Data | C7: The organisation shall document and enforce prohibitions on data sources that may not be used without explicit approval — including data with unknown provenance, unlicensed data, and personal data without a legal basis.

Sheet Tooling
A1: Tooling — Compliance Checklist
A2: ISO/IEC 42001:2023 — Controls A.4.2-6: AI System Resources
A3: Req # | B3: Section | C3: Requirement | D3: Status | E3: Evidence | F3: Owner | G3: Due Date | H3: Notes
A4: A.4.4-01 | B4: Tooling Documentation | C4: The organisation shall document, for each AI system, the key tooling used in development and operation — including MLOps platforms, model registries, monitoring tools, and logging infrastructure.
A5: A.4.4-02 | B5: Foundation Model Documentation | C5: Where AI systems use third-party foundation models or AI APIs, these shall be documented in the AI System Resource Register including provider, model name, and version.
A6: A.4.4-03 | B6: Open Source Licences | C6: Open-source AI libraries and pre-trained models used in AI systems shall have their licence reviewed by Legal before use in commercial or customer-facing applications.
A7: A.4.4-04 | B7: Vulnerability Management | C7: The organisation shall implement a process for tracking and addressing CVEs in AI-specific libraries and dependencies used in production AI systems.

Sheet System Architecture
A1: System Architecture — Compliance Checklist
A2: ISO/IEC 42001:2023 — Controls A.4.2-6: AI System Resources
A3: Req # | B3: Section | C3: Requirement | D3: Status | E3: Evidence | F3: Owner | G3: Due Date | H3: Notes
A4: A.4.5-01 | B4: Architecture Documentation | C4: The organisation shall maintain architecture documentation for each AI system showing key components, data flows, integration points, and the human oversight mechanism.
A5: A.4.5-02 | B5: Integration Dependencies | C5: The organisation shall document all systems that provide input to or receive output from each AI system, enabling accurate impact assessment and incident response.
A6: A.4.5-03 | B6: Version Control | C6: Model artefacts, training code, inference code, and deployment configuration for each AI system shall be stored in version-controlled repositories with linkage between code versions and model versions.
A7: A.4.5-04 | B7: Model Registry | C7: The organisation shall maintain a model registry recording all deployed model versions with metadata including training dataset, V&V record reference, AISIA reference, and deployment status.

Sheet Human Resources
A1: Human Resources — Compliance Checklist
A2: ISO/IEC 42001:2023 — Controls A.4.2-6: AI System Resources
A3: Req # | B3: Section | C3: Requirement | D3: Status | E3: Evidence | F3: Owner | G3: Due Date | H3: Notes
A4: A.4.6-01 | B4: Competency Documentation | C4: For each AI system, the AI System Owner shall document the competency requirements for persons operating or using the system, including required domain expertise and AI governance knowledge.
A5: A.4.6-02 | B5: Training Completion | C5: The organisation shall maintain records of training completion for all persons operating AI systems, and shall ensure training is refreshed when systems change materially.
A6: A.4.6-03 | B6: Competency Gaps | C6: Where competency gaps are identified for AI system operators, the AI System Owner shall document and escalate the gap and shall implement a remediation plan.
A7: A.4.6-04 | B7: New System Onboarding | C7: Before a new AI system enters operational use, all users shall have completed the required training and the AI System Owner shall confirm training completion as part of the deployment gate.
