Workbook

Sheet Executive Summary
A1: CLD-CHK-A.12 — Privacy Compliance Compliance Checklist
A3: DOCUMENT INFORMATION
A4: Document ID | B4: CLD-CHK-A.12
A5: Source Policy | B5: CLD-POL-A.12
A6: ISO Controls | B6: Privacy Compliance
A7: Generated | B7: 10.03.2026
A8: Prepared By
A9: Organisation
A10: Review Cycle | B10: Annual
A12: OVERALL COMPLIANCE STATUS
A13: Overall Compliance | B13: ='Dashboard'!G6
A14: Status | B14: =IF(Dashboard!G6="N/A","NOT ASSESSED",IF(ISNUMBER(VALUE(SUBSTITUTE(Dashboard!G6,"%",""))),IF(VALUE(SUBSTITUTE(Dashboard!G6,"%",""))>=90,"GREEN",IF(VALUE(SUBSTITUTE(Dashboard!G6,"%",""))>=70,"AMBER","RED")),"NOT ASSESSED"))
A16: KEY METRICS
A17: Total Requirements | B17: ='Dashboard'!B6
A18: Compliant | B18: ='Dashboard'!C6
A19: Partial | B19: ='Dashboard'!D6
A20: Non-Compliant | B20: ='Dashboard'!E6
A21: Not Applicable | B21: ='Dashboard'!F6
A22: Owner Coverage | B22: =IF(Dashboard!B6=0,"N/A",ROUND((COUNTA('Geographical Location of PII'!F4:F8)+COUNTA('Transfer Destinations and Mechanisms'!F4:F7))/Dashboard!B6*100,0)&"%")
A24: DOMAIN STATUS SUMMARY
A25: Domain | B25: Compliance % | C25: Compliant | D25: Gaps | E25: Status
A26: Geographical Location of PII | B26: ='Dashboard'!G4 | C26: ='Dashboard'!C4 | D26: ='Dashboard'!E4 | E26: =IF(Dashboard!G4="N/A","--",IF(ISNUMBER(VALUE(SUBSTITUTE(Dashboard!G4,"%",""))),IF(VALUE(SUBSTITUTE(Dashboard!G4,"%",""))>=90,"PASS",IF(VALUE(SUBSTITUTE(Dashboard!G4,"%",""))>=70,"REVIEW","FAIL")),"--"))
A27: Transfer Destinations and Mechanisms | B27: ='Dashboard'!G5 | C27: ='Dashboard'!C5 | D27: ='Dashboard'!E5 | E27: =IF(Dashboard!G5="N/A","--",IF(ISNUMBER(VALUE(SUBSTITUTE(Dashboard!G5,"%",""))),IF(VALUE(SUBSTITUTE(Dashboard!G5,"%",""))>=90,"PASS",IF(VALUE(SUBSTITUTE(Dashboard!G5,"%",""))>=70,"REVIEW","FAIL")),"--"))
A29: CRITICAL ISSUES
A30: # | B30: Issue Description | C30: Domain | D30: Owner | E30: Due Date
A31: 1
A32: 2
A33: 3
A34: 4
A35: 5
A37: MANAGEMENT COMMENTARY
A38: [Enter management commentary on privacy compliance posture]
A42: APPROVAL
A43: Assessed By
A44: Name:
A45: Date:
A46: Signature:
A47: Decision:
A49: Reviewed By (DPO)
A50: Name:
...

Sheet Dashboard
A1: Privacy Compliance — Compliance Dashboard
A3: Domain | B3: Total Reqs | C3: Compliant | D3: Partial | E3: Non-Compliant | F3: N/A | G3: Compliance %
A4: Geographical Location of PII | B4: =COUNTA('Geographical Location of PII'!D4:D8) | C4: =COUNTIF('Geographical Location of PII'!D4:D8,"Compliant") | D4: =COUNTIF('Geographical Location of PII'!D4:D8,"Partial") | E4: =COUNTIF('Geographical Location of PII'!D4:D8,"Non-Compliant") | F4: =COUNTIF('Geographical Location of PII'!D4:D8,"N/A") | G4: =IF((B4-F4)=0,"N/A",ROUND(C4/(B4-F4)*100,1)&"%")
A5: Transfer Destinations and Mechanisms | B5: =COUNTA('Transfer Destinations and Mechanisms'!D4:D7) | C5: =COUNTIF('Transfer Destinations and Mechanisms'!D4:D7,"Compliant") | D5: =COUNTIF('Transfer Destinations and Mechanisms'!D4:D7,"Partial") | E5: =COUNTIF('Transfer Destinations and Mechanisms'!D4:D7,"Non-Compliant") | F5: =COUNTIF('Transfer Destinations and Mechanisms'!D4:D7,"N/A") | G5: =IF((B5-F5)=0,"N/A",ROUND(C5/(B5-F5)*100,1)&"%")
A6: TOTAL | B6: =SUM(B4:B5) | C6: =SUM(C4:C5) | D6: =SUM(D4:D5) | E6: =SUM(E4:E5) | F6: =SUM(F4:F5) | G6: =IF((B6-F6)=0,"N/A",ROUND(C6/(B6-F6)*100,1)&"%")
A8: COMPLIANCE BY STATUS
A9: Compliant | B9: =C6 | C9: =IF(B6=0,"",ROUND(B9/B6*100,1)&"%")
A10: Partial | B10: =D6 | C10: =IF(B6=0,"",ROUND(B10/B6*100,1)&"%")
A11: Non-Compliant | B11: =E6 | C11: =IF(B6=0,"",ROUND(B11/B6*100,1)&"%")
A12: N/A | B12: =F6 | C12: =IF(B6=0,"",ROUND(B12/B6*100,1)&"%")
A14: TOP GAPS (Manual Entry)
A15: Priority | B15: Domain | C15: Requirement | D15: Owner | E15: Due Date | F15: Status
A27: COMPLIANCE TREND (Manual Entry)
A28: Assessment Date | B28: Overall % | C28: Compliant | D28: Gaps | E28: Assessor | F28: Notes

Sheet Geographical Location of PII
A1: Geographical Location of PII — Compliance Checklist
A2: ISO/IEC 27018:2025 — Controls A.12.1-2: Privacy Compliance
A3: Req # | B3: Section | C3: Requirement | D3: Status | E3: Evidence | F3: Owner | G3: Due Date | H3: Notes
A4: A.12.1-01 | B4: PII Processing Locations Register | C4: The organisation shall maintain a PII Processing Locations Register documenting all countries and regions in which PII is stored, processed, or transits as part of cloud service delivery. The register shall cover: primary storage locations (data centres and cloud regions where PII at rest resides); processing locations (compute regions where PII is actively processed); transit routes (regions through which PII may pass during replication, backup, or delivery); and sub-processor locations (all geographic locations of engaged sub-processors).
A5: A.12.1-02 | B5: Register Availability | C5: The PII Processing Locations Register shall be made available to PII controllers upon request and shall be publicly accessible for controllers operating under general authorisation (e.g., linked from the organisation's trust portal or DPA annex). The register shall be consistent with the Sub-Processor Register maintained under CLD-POL-A.8.1.
A6: A.12.1-03 | B6: Data Residency Enforcement | C6: Where a PII controller specifies data residency requirements in the service agreement (e.g., 'EU-only storage', 'Switzerland only'), the organisation shall technically enforce the residency constraint through infrastructure configuration (regional restrictions, geo-fencing, storage policy rules); document the technical mechanism used and make this documentation available to the controller upon request; and audit residency compliance at least annually and upon significant infrastructure changes, confirming that no PII has been stored or processed outside the agreed regions.
A7: A.12.1-04 | B7: Location Change Notification | C7: Before changing the geographic location of PII processing — including opening a new service region, adding a sub-processor in a new jurisdiction, or relocating backup storage — the organisation shall notify the relevant PII controller a minimum of 30 days in advance (unless the service agreement specifies a longer period); identify the new location and explain the operational reason; obtain prior consent from controllers whose agreements require specific consent for location changes; and update the PII Processing Locations Register within 5 business days of the change taking effect.
A8: A.12.1-05 | B8: Emergency Location Changes | C8: Emergency location changes (e.g., due to data centre failure or force majeure) shall be notified to affected PII controllers without undue delay, with retroactive documentation of the change and its justification. Emergency changes shall be formally recorded in the PII Processing Locations Register within 5 business days of the change. Records of location change notifications shall be retained for 5 years.

Sheet Transfer Destinations and Mechanisms
A1: Transfer Destinations and Mechanisms — Compliance Checklist
A2: ISO/IEC 27018:2025 — Controls A.12.1-2: Privacy Compliance
A3: Req # | B3: Section | C3: Requirement | D3: Status | E3: Evidence | F3: Owner | G3: Due Date | H3: Notes
A4: A.12.2-01 | B4: Transfer Destination Documentation | C4: The organisation shall maintain documented records of all intended destinations to which PII may be transferred as part of cloud service delivery, including cross-border flows to sub-processors, backup and disaster recovery sites in third countries, cloud infrastructure in jurisdictions outside the controller's home country, and support or operations personnel accessing PII remotely from outside the processing region. For each destination the organisation shall document: the destination country or region; transfer purpose; applicable transfer mechanism and legal basis; safeguards in place; and controller notification status.
A5: A.12.2-02 | B5: Approved Transfer Mechanisms | C5: For transfers of PII to countries outside the EEA or Switzerland that lack an adequacy decision, the organisation shall implement one of the following approved transfer mechanisms: EC-approved Standard Contractual Clauses (2021 set); UK International Data Transfer Agreement (IDTA) for transfers to or from the United Kingdom; Swiss Standard Data Protection Clauses for transfers subject to CH FADP; adequacy decision (where in force at the time of transfer); or Binding Corporate Rules (where applicable for intra-group transfers). The organisation shall not transfer PII to a third country without a documented, applicable mechanism.
A6: A.12.2-03 | B6: Adequacy Status Monitoring | C6: The organisation shall monitor the adequacy status of all destination countries to which PII is transferred. Where the adequacy status of a destination country changes (e.g., adequacy decision revoked or suspended), the organisation shall review affected transfers and implement alternative transfer mechanisms within 30 days of the change taking effect, and notify affected PII controllers of the change and the alternative mechanism adopted.
A7: A.12.2-04 | B7: Controller Transfer Information | C7: The organisation shall provide PII controllers with transfer documentation upon request to support the controller's own Article 30 RoPA obligations or transfer impact assessments. Documentation shall include: the complete list of transfer destinations for the controller's PII; the transfer mechanism and relevant legal instrument reference for each destination; and a summary of supplementary technical safeguards applied for transfers to high-risk jurisdictions. Transfer mechanism instruments (SCCs, IDTAs, BCRs, adequacy decision citations) shall be retained for the duration of the engagement plus 5 years.
