Workbook

Sheet Executive Summary
A1: CLD-PII-CHK-A.4 — Collection Limitation Compliance Checklist
A3: DOCUMENT INFORMATION
A4: Document ID | B4: CLD-PII-CHK-A.4
A5: Source Policy | B5: CLD-PII-POL-A.4
A6: ISO Controls | B6: Collection Limitation
A7: Generated | B7: 30.09.2026
A8: Prepared By
A9: Organisation
A10: Review Cycle | B10: Annual
A12: OVERALL COMPLIANCE STATUS
A13: Overall Compliance | B13: ='Dashboard'!G6
A14: Status | B14: =IF(Dashboard!H6>0,"INCOMPLETE",IF(Dashboard!G6="N/A","NOT ASSESSED",IF(ISNUMBER(VALUE(SUBSTITUTE(Dashboard!G6,"%",""))),IF(VALUE(SUBSTITUTE(Dashboard!G6,"%",""))>=90,"GREEN",IF(VALUE(SUBSTITUTE(Dashboard!G6,"%",""))>=70,"AMBER","RED")),"NOT ASSESSED")))
A16: KEY METRICS
A17: Total Requirements | B17: ='Dashboard'!B6
A18: Compliant | B18: ='Dashboard'!C6
A19: Partial | B19: ='Dashboard'!D6
A20: Non-Compliant | B20: ='Dashboard'!E6
A21: Not Applicable | B21: ='Dashboard'!F6
A22: Unanswered | B22: ='Dashboard'!H6
A23: Owner Coverage | B23: =IF(Dashboard!B6=0,"N/A",ROUND((COUNTA('Minimum Necessary Collection'!F4:F7)+COUNTA('Excess PII and Development Environments'!F4:F6))/Dashboard!B6*100,0)&"%")
A25: DOMAIN STATUS SUMMARY
A26: Domain | B26: Compliance % | C26: Compliant | D26: Gaps | E26: Status
A27: Minimum Necessary Collection | B27: ='Dashboard'!G4 | C27: ='Dashboard'!C4 | D27: ='Dashboard'!E4 | E27: =IF(Dashboard!H4>0,"INCOMPLETE",IF(Dashboard!G4="N/A","--",IF(ISNUMBER(VALUE(SUBSTITUTE(Dashboard!G4,"%",""))),IF(VALUE(SUBSTITUTE(Dashboard!G4,"%",""))>=90,"PASS",IF(VALUE(SUBSTITUTE(Dashboard!G4,"%",""))>=70,"REVIEW","FAIL")),"--")))
A28: Excess PII and Development Environments | B28: ='Dashboard'!G5 | C28: ='Dashboard'!C5 | D28: ='Dashboard'!E5 | E28: =IF(Dashboard!H5>0,"INCOMPLETE",IF(Dashboard!G5="N/A","--",IF(ISNUMBER(VALUE(SUBSTITUTE(Dashboard!G5,"%",""))),IF(VALUE(SUBSTITUTE(Dashboard!G5,"%",""))>=90,"PASS",IF(VALUE(SUBSTITUTE(Dashboard!G5,"%",""))>=70,"REVIEW","FAIL")),"--")))
A30: CRITICAL ISSUES
A31: # | B31: Issue Description | C31: Domain | D31: Owner | E31: Due Date
A32: 1
A33: 2
A34: 3
A35: 4
A36: 5
A38: MANAGEMENT COMMENTARY
A39: [Enter management commentary on collection limitation posture]
A43: APPROVAL
A44: Assessed By
A45: Name:
A46: Date:
A47: Signature:
A48: Decision:
A50: Reviewed By (DPO)
...

Sheet Dashboard
A1: Collection Limitation — Compliance Dashboard
A3: Domain | B3: Total Reqs | C3: Compliant | D3: Partial | E3: Non-Compliant | F3: N/A | G3: Compliance % | H3: Unassessed
A4: Minimum Necessary Collection | B4: =COUNTA('Minimum Necessary Collection'!A4:A7) | C4: =COUNTIF('Minimum Necessary Collection'!D4:D7,"Compliant") | D4: =COUNTIF('Minimum Necessary Collection'!D4:D7,"Partial") | E4: =COUNTIF('Minimum Necessary Collection'!D4:D7,"Non-Compliant") | F4: =COUNTIF('Minimum Necessary Collection'!D4:D7,"N/A") | G4: =IF((B4-F4)=0,"N/A",ROUND(C4/(B4-F4)*100,1)&"%") | H4: =B4-(C4+D4+E4+F4)
A5: Excess PII and Development Environments | B5: =COUNTA('Excess PII and Development Environments'!A4:A6) | C5: =COUNTIF('Excess PII and Development Environments'!D4:D6,"Compliant") | D5: =COUNTIF('Excess PII and Development Environments'!D4:D6,"Partial") | E5: =COUNTIF('Excess PII and Development Environments'!D4:D6,"Non-Compliant") | F5: =COUNTIF('Excess PII and Development Environments'!D4:D6,"N/A") | G5: =IF((B5-F5)=0,"N/A",ROUND(C5/(B5-F5)*100,1)&"%") | H5: =B5-(C5+D5+E5+F5)
A6: TOTAL | B6: =SUM(B4:B5) | C6: =SUM(C4:C5) | D6: =SUM(D4:D5) | E6: =SUM(E4:E5) | F6: =SUM(F4:F5) | G6: =IF((B6-F6)=0,"N/A",ROUND(C6/(B6-F6)*100,1)&"%") | H6: =SUM(H4:H5)
A8: COMPLIANCE BY STATUS
A9: Compliant | B9: =C6 | C9: =IF(B6=0,"",ROUND(B9/B6*100,1)&"%")
A10: Partial | B10: =D6 | C10: =IF(B6=0,"",ROUND(B10/B6*100,1)&"%")
A11: Non-Compliant | B11: =E6 | C11: =IF(B6=0,"",ROUND(B11/B6*100,1)&"%")
A12: N/A | B12: =F6 | C12: =IF(B6=0,"",ROUND(B12/B6*100,1)&"%")
A14: TOP GAPS (Manual Entry)
A15: Priority | B15: Domain | C15: Requirement | D15: Owner | E15: Due Date | F15: Status
A27: COMPLIANCE TREND (Manual Entry)
A28: Assessment Date | B28: Overall % | C28: Compliant | D28: Gaps | E28: Assessor | F28: Notes

Sheet Minimum Necessary Collection
A1: Minimum Necessary Collection — Compliance Checklist
A2: ISO/IEC 27018:2025 — Controls A.4: Collection Limitation
A3: Req # | B3: Section | C3: Requirement | D3: Status | E3: Evidence | F3: Owner | G3: Due Date | H3: Notes
A4: A.4-01 | B4: Minimum PII Collection | C4: The organisation shall collect, retain, or otherwise process only the minimum PII necessary to deliver the contracted cloud service. The organisation shall not request or accept PII categories from the PII controller beyond what is required for service delivery; store PII in system components, logs, or operational databases beyond operational necessity; or replicate PII across environments without explicit controller authorisation.
A5: A.4-02 | B5: Collection Practice Documentation | C5: The organisation shall document PII collection practices for each cloud service, including: categories of PII collected or received during service delivery; the operational justification for each PII category; the system components, logs, and storage locations where PII may be present; and retention periods applicable to each collection type. Documentation shall be reviewed annually and upon material changes to service architecture.
A6: A.4-03 | B6: Annual Collection Review | C6: Collection practice documentation shall be reviewed and signed off at minimum annually by the CISO or DPO. The review shall confirm that no PII categories are being collected beyond those necessary for contracted service delivery. Review records shall be retained for 3 years.
A7: A.4-04 | B7: Controller Instruction Primacy | C7: The scope of PII that may be collected or processed is defined by the PII controller's instructions and the service agreement. Where the organisation identifies ambiguity in what PII may be collected, written clarification shall be obtained from the controller before collection commences. Ambiguity does not authorise broader collection.

Sheet Excess PII and Development Environments
A1: Excess PII and Development Environments — Compliance Checklist
A2: ISO/IEC 27018:2025 — Controls A.4: Collection Limitation
A3: Req # | B3: Section | C3: Requirement | D3: Status | E3: Evidence | F3: Owner | G3: Due Date | H3: Notes
A4: A.4-05 | B4: Excess PII Handling | C4: Where the organisation determines that PII has been collected that exceeds the scope of the contracted service, the organisation shall: notify the PII controller of the excess PII without undue delay; agree with the controller whether the excess PII is to be returned or securely deleted; complete the agreed action within the agreed timeframe; and document the event and outcome. Excess PII event records shall be retained for the duration of the contract plus 3 years.
A5: A.4-06 | B5: Development and Test Environment Restriction | C5: PII from production environments shall not be used in development, testing, or staging environments without explicit written authorisation from the PII controller. Where controller authorisation is obtained, the minimum necessary PII shall be used and the same security controls applicable in production shall apply. Development/test PII authorisation records shall be retained for the duration of use plus 3 years.
A6: A.4-07 | B6: Post-Test Deletion | C6: Where PII is used in a development or test environment under controller authorisation, the PII shall be deleted immediately after the specific test or development activity concludes. Deletion shall be confirmed and documented. Authorisation does not constitute permission for indefinite retention of production PII in non-production environments.
