Workbook

Sheet Executive Summary
A1: ISMS-OP-CHK-A.7.12-13 — Cabling Security and Equipment Maintenance Compliance Checklist
A3: DOCUMENT INFORMATION
A4: Document ID | B4: ISMS-OP-CHK-A.7.12-13
A5: Source Policy | B5: ISMS-OP-POL-A.7.12-13
A6: ISO Controls | B6: Cabling Security and Equipment Maintenance
A7: Generated | B7: 08.02.2026
A8: Prepared By
A9: Organisation
A10: Review Cycle | B10: Annual
A12: OVERALL COMPLIANCE STATUS
A13: Overall Compliance | B13: ='Dashboard'!G20
A14: Status | B14: =IF(Dashboard!G20="N/A","NOT ASSESSED",IF(ISNUMBER(VALUE(SUBSTITUTE(Dashboard!G20,"%",""))),IF(VALUE(SUBSTITUTE(Dashboard!G20,"%",""))>=90,"GREEN",IF(VALUE(SUBSTITUTE(Dashboard!G20,"%",""))>=70,"AMBER","RED")),"NOT ASSESSED"))
A16: KEY METRICS
A17: Total Requirements | B17: ='Dashboard'!B20
A18: Compliant | B18: ='Dashboard'!C20
A19: Partial | B19: ='Dashboard'!D20
A20: Non-Compliant | B20: ='Dashboard'!E20
A21: Not Applicable | B21: ='Dashboard'!F20
A22: Owner Coverage | B22: =IF(Dashboard!B20=0,"N/A",ROUND((COUNTA('Cable Protection Standards'!F4:F13)+COUNTA('Cable Segregation'!F4:F9)+COUNTA('Cable Documentation & Labelling'!F4:F17)+COUNTA('Fibre Optic Requirements'!F4:F6)+COUNTA('Inspection and Cable Maint'!F4:F9)+COUNTA('Maintenance Programme'!F4:F9)+COUNTA('Avail and Service Continuity'!F4:F20)+COUNTA('Maint Personnel Authorisation'!F4:F12)+COUNTA('Third-Party Maint Provider Mgmt'!F4:F6)+COUNTA('Security During Maintenance'!F4:F13)+COUNTA('Remote Maintenance'!F4:F10)+COUNTA('Equipment Removal and Return'!F4:F8)+COUNTA('Infra Failure Incident Response'!F4:F5)+COUNTA('Maintenance Records'!F4:F10)+COUNTA('Infrastructure Performance Mon'!F4:F5)+COUNTA('Compliance Measurement'!F4:F4))/Dashboard!B20*100,0)&"%")
A24: DOMAIN STATUS SUMMARY
A25: Domain | B25: Compliance % | C25: Compliant | D25: Gaps | E25: Status
A26: Cable Protection Standards | B26: ='Dashboard'!G4 | C26: ='Dashboard'!C4 | D26: ='Dashboard'!E4 | E26: =IF(Dashboard!G4="N/A","--",IF(ISNUMBER(VALUE(SUBSTITUTE(Dashboard!G4,"%",""))),IF(VALUE(SUBSTITUTE(Dashboard!G4,"%",""))>=90,"PASS",IF(VALUE(SUBSTITUTE(Dashboard!G4,"%",""))>=70,"REVIEW","FAIL")),"--"))
A27: Cable Segregation | B27: ='Dashboard'!G5 | C27: ='Dashboard'!C5 | D27: ='Dashboard'!E5 | E27: =IF(Dashboard!G5="N/A","--",IF(ISNUMBER(VALUE(SUBSTITUTE(Dashboard!G5,"%",""))),IF(VALUE(SUBSTITUTE(Dashboard!G5,"%",""))>=90,"PASS",IF(VALUE(SUBSTITUTE(Dashboard!G5,"%",""))>=70,"REVIEW","FAIL")),"--"))
A28: Cable Documentation & Labelling | B28: ='Dashboard'!G6 | C28: ='Dashboard'!C6 | D28: ='Dashboard'!E6 | E28: =IF(Dashboard!G6="N/A","--",IF(ISNUMBER(VALUE(SUBSTITUTE(Dashboard!G6,"%",""))),IF(VALUE(SUBSTITUTE(Dashboard!G6,"%",""))>=90,"PASS",IF(VALUE(SUBSTITUTE(Dashboard!G6,"%",""))>=70,"REVIEW","FAIL")),"--"))
A29: Fibre Optic Requirements | B29: ='Dashboard'!G7 | C29: ='Dashboard'!C7 | D29: ='Dashboard'!E7 | E29: =IF(Dashboard!G7="N/A","--",IF(ISNUMBER(VALUE(SUBSTITUTE(Dashboard!G7,"%",""))),IF(VALUE(SUBSTITUTE(Dashboard!G7,"%",""))>=90,"PASS",IF(VALUE(SUBSTITUTE(Dashboard!G7,"%",""))>=70,"REVIEW","FAIL")),"--"))
A30: Inspection and Cable Maint | B30: ='Dashboard'!G8 | C30: ='Dashboard'!C8 | D30: ='Dashboard'!E8 | E30: =IF(Dashboard!G8="N/A","--",IF(ISNUMBER(VALUE(SUBSTITUTE(Dashboard!G8,"%",""))),IF(VALUE(SUBSTITUTE(Dashboard!G8,"%",""))>=90,"PASS",IF(VALUE(SUBSTITUTE(Dashboard!G8,"%",""))>=70,"REVIEW","FAIL")),"--"))
A31: Maintenance Programme | B31: ='Dashboard'!G9 | C31: ='Dashboard'!C9 | D31: ='Dashboard'!E9 | E31: =IF(Dashboard!G9="N/A","--",IF(ISNUMBER(VALUE(SUBSTITUTE(Dashboard!G9,"%",""))),IF(VALUE(SUBSTITUTE(Dashboard!G9,"%",""))>=90,"PASS",IF(VALUE(SUBSTITUTE(Dashboard!G9,"%",""))>=70,"REVIEW","FAIL")),"--"))
A32: Avail and Service Continuity | B32: ='Dashboard'!G10 | C32: ='Dashboard'!C10 | D32: ='Dashboard'!E10 | E32: =IF(Dashboard!G10="N/A","--",IF(ISNUMBER(VALUE(SUBSTITUTE(Dashboard!G10,"%",""))),IF(VALUE(SUBSTITUTE(Dashboard!G10,"%",""))>=90,"PASS",IF(VALUE(SUBSTITUTE(Dashboard!G10,"%",""))>=70,"REVIEW","FAIL")),"--"))
A33: Maint Personnel Authorisation | B33: ='Dashboard'!G11 | C33: ='Dashboard'!C11 | D33: ='Dashboard'!E11 | E33: =IF(Dashboard!G11="N/A","--",IF(ISNUMBER(VALUE(SUBSTITUTE(Dashboard!G11,"%",""))),IF(VALUE(SUBSTITUTE(Dashboard!G11,"%",""))>=90,"PASS",IF(VALUE(SUBSTITUTE(Dashboard!G11,"%",""))>=70,"REVIEW","FAIL")),"--"))
A34: Third-Party Maint Provider Mgmt | B34: ='Dashboard'!G12 | C34: ='Dashboard'!C12 | D34: ='Dashboard'!E12 | E34: =IF(Dashboard!G12="N/A","--",IF(ISNUMBER(VALUE(SUBSTITUTE(Dashboard!G12,"%",""))),IF(VALUE(SUBSTITUTE(Dashboard!G12,"%",""))>=90,"PASS",IF(VALUE(SUBSTITUTE(Dashboard!G12,"%",""))>=70,"REVIEW","FAIL")),"--"))
A35: Security During Maintenance | B35: ='Dashboard'!G13 | C35: ='Dashboard'!C13 | D35: ='Dashboard'!E13 | E35: =IF(Dashboard!G13="N/A","--",IF(ISNUMBER(VALUE(SUBSTITUTE(Dashboard!G13,"%",""))),IF(VALUE(SUBSTITUTE(Dashboard!G13,"%",""))>=90,"PASS",IF(VALUE(SUBSTITUTE(Dashboard!G13,"%",""))>=70,"REVIEW","FAIL")),"--"))
A36: Remote Maintenance | B36: ='Dashboard'!G14 | C36: ='Dashboard'!C14 | D36: ='Dashboard'!E14 | E36: =IF(Dashboard!G14="N/A","--",IF(ISNUMBER(VALUE(SUBSTITUTE(Dashboard!G14,"%",""))),IF(VALUE(SUBSTITUTE(Dashboard!G14,"%",""))>=90,"PASS",IF(VALUE(SUBSTITUTE(Dashboard!G14,"%",""))>=70,"REVIEW","FAIL")),"--"))
A37: Equipment Removal and Return | B37: ='Dashboard'!G15 | C37: ='Dashboard'!C15 | D37: ='Dashboard'!E15 | E37: =IF(Dashboard!G15="N/A","--",IF(ISNUMBER(VALUE(SUBSTITUTE(Dashboard!G15,"%",""))),IF(VALUE(SUBSTITUTE(Dashboard!G15,"%",""))>=90,"PASS",IF(VALUE(SUBSTITUTE(Dashboard!G15,"%",""))>=70,"REVIEW","FAIL")),"--"))
... A41: Compliance Measurement | B41: ='Dashboard'!G19 | C41: ='Dashboard'!C19 | D41: ='Dashboard'!E19 | E41: =IF(Dashboard!G19="N/A","--",IF(ISNUMBER(VALUE(SUBSTITUTE(Dashboard!G19,"%",""))),IF(VALUE(SUBSTITUTE(Dashboard!G19,"%",""))>=90,"PASS",IF(VALUE(SUBSTITUTE(Dashboard!G19,"%",""))>=70,"REVIEW","FAIL")),"--"))
A43: CRITICAL ISSUES
A44: # | B44: Issue Description | C44: Domain | D44: Owner | E44: Due Date
A45: 1
A46: 2
A47: 3
A48: 4
...

Sheet Dashboard
A1: Cabling Security and Equipment Maintenance — Compliance Dashboard
A3: Domain | B3: Total Reqs | C3: Compliant | D3: Partial | E3: Non-Compliant | F3: N/A | G3: Compliance %
A4: Cable Protection Standards | B4: =COUNTA('Cable Protection Standards'!D4:D13) | C4: =COUNTIF('Cable Protection Standards'!D4:D13,"Compliant") | D4: =COUNTIF('Cable Protection Standards'!D4:D13,"Partial") | E4: =COUNTIF('Cable Protection Standards'!D4:D13,"Non-Compliant") | F4: =COUNTIF('Cable Protection Standards'!D4:D13,"N/A") | G4: =IF((B4-F4)=0,"N/A",ROUND(C4/(B4-F4)*100,1)&"%")
A5: Cable Segregation | B5: =COUNTA('Cable Segregation'!D4:D9) | C5: =COUNTIF('Cable Segregation'!D4:D9,"Compliant") | D5: =COUNTIF('Cable Segregation'!D4:D9,"Partial") | E5: =COUNTIF('Cable Segregation'!D4:D9,"Non-Compliant") | F5: =COUNTIF('Cable Segregation'!D4:D9,"N/A") | G5: =IF((B5-F5)=0,"N/A",ROUND(C5/(B5-F5)*100,1)&"%")
A6: Cable Documentation & Labelling | B6: =COUNTA('Cable Documentation & Labelling'!D4:D17) | C6: =COUNTIF('Cable Documentation & Labelling'!D4:D17,"Compliant") | D6: =COUNTIF('Cable Documentation & Labelling'!D4:D17,"Partial") | E6: =COUNTIF('Cable Documentation & Labelling'!D4:D17,"Non-Compliant") | F6: =COUNTIF('Cable Documentation & Labelling'!D4:D17,"N/A") | G6: =IF((B6-F6)=0,"N/A",ROUND(C6/(B6-F6)*100,1)&"%")
A7: Fibre Optic Requirements | B7: =COUNTA('Fibre Optic Requirements'!D4:D6) | C7: =COUNTIF('Fibre Optic Requirements'!D4:D6,"Compliant") | D7: =COUNTIF('Fibre Optic Requirements'!D4:D6,"Partial") | E7: =COUNTIF('Fibre Optic Requirements'!D4:D6,"Non-Compliant") | F7: =COUNTIF('Fibre Optic Requirements'!D4:D6,"N/A") | G7: =IF((B7-F7)=0,"N/A",ROUND(C7/(B7-F7)*100,1)&"%")
A8: Inspection and Cable Maint | B8: =COUNTA('Inspection and Cable Maint'!D4:D9) | C8: =COUNTIF('Inspection and Cable Maint'!D4:D9,"Compliant") | D8: =COUNTIF('Inspection and Cable Maint'!D4:D9,"Partial") | E8: =COUNTIF('Inspection and Cable Maint'!D4:D9,"Non-Compliant") | F8: =COUNTIF('Inspection and Cable Maint'!D4:D9,"N/A") | G8: =IF((B8-F8)=0,"N/A",ROUND(C8/(B8-F8)*100,1)&"%")
A9: Maintenance Programme | B9: =COUNTA('Maintenance Programme'!D4:D9) | C9: =COUNTIF('Maintenance Programme'!D4:D9,"Compliant") | D9: =COUNTIF('Maintenance Programme'!D4:D9,"Partial") | E9: =COUNTIF('Maintenance Programme'!D4:D9,"Non-Compliant") | F9: =COUNTIF('Maintenance Programme'!D4:D9,"N/A") | G9: =IF((B9-F9)=0,"N/A",ROUND(C9/(B9-F9)*100,1)&"%")
A10: Avail and Service Continuity | B10: =COUNTA('Avail and Service Continuity'!D4:D20) | C10: =COUNTIF('Avail and Service Continuity'!D4:D20,"Compliant") | D10: =COUNTIF('Avail and Service Continuity'!D4:D20,"Partial") | E10: =COUNTIF('Avail and Service Continuity'!D4:D20,"Non-Compliant") | F10: =COUNTIF('Avail and Service Continuity'!D4:D20,"N/A") | G10: =IF((B10-F10)=0,"N/A",ROUND(C10/(B10-F10)*100,1)&"%")
A11: Maint Personnel Authorisation | B11: =COUNTA('Maint Personnel Authorisation'!D4:D12) | C11: =COUNTIF('Maint Personnel Authorisation'!D4:D12,"Compliant") | D11: =COUNTIF('Maint Personnel Authorisation'!D4:D12,"Partial") | E11: =COUNTIF('Maint Personnel Authorisation'!D4:D12,"Non-Compliant") | F11: =COUNTIF('Maint Personnel Authorisation'!D4:D12,"N/A") | G11: =IF((B11-F11)=0,"N/A",ROUND(C11/(B11-F11)*100,1)&"%")
A12: Third-Party Maint Provider Mgmt | B12: =COUNTA('Third-Party Maint Provider Mgmt'!D4:D6) | C12: =COUNTIF('Third-Party Maint Provider Mgmt'!D4:D6,"Compliant") | D12: =COUNTIF('Third-Party Maint Provider Mgmt'!D4:D6,"Partial") | E12: =COUNTIF('Third-Party Maint Provider Mgmt'!D4:D6,"Non-Compliant") | F12: =COUNTIF('Third-Party Maint Provider Mgmt'!D4:D6,"N/A") | G12: =IF((B12-F12)=0,"N/A",ROUND(C12/(B12-F12)*100,1)&"%")
A13: Security During Maintenance | B13: =COUNTA('Security During Maintenance'!D4:D13) | C13: =COUNTIF('Security During Maintenance'!D4:D13,"Compliant") | D13: =COUNTIF('Security During Maintenance'!D4:D13,"Partial") | E13: =COUNTIF('Security During Maintenance'!D4:D13,"Non-Compliant") | F13: =COUNTIF('Security During Maintenance'!D4:D13,"N/A") | G13: =IF((B13-F13)=0,"N/A",ROUND(C13/(B13-F13)*100,1)&"%")
A14: Remote Maintenance | B14: =COUNTA('Remote Maintenance'!D4:D10) | C14: =COUNTIF('Remote Maintenance'!D4:D10,"Compliant") | D14: =COUNTIF('Remote Maintenance'!D4:D10,"Partial") | E14: =COUNTIF('Remote Maintenance'!D4:D10,"Non-Compliant") | F14: =COUNTIF('Remote Maintenance'!D4:D10,"N/A") | G14: =IF((B14-F14)=0,"N/A",ROUND(C14/(B14-F14)*100,1)&"%")
A15: Equipment Removal and Return | B15: =COUNTA('Equipment Removal and Return'!D4:D8) | C15: =COUNTIF('Equipment Removal and Return'!D4:D8,"Compliant") | D15: =COUNTIF('Equipment Removal and Return'!D4:D8,"Partial") | E15: =COUNTIF('Equipment Removal and Return'!D4:D8,"Non-Compliant") | F15: =COUNTIF('Equipment Removal and Return'!D4:D8,"N/A") | G15: =IF((B15-F15)=0,"N/A",ROUND(C15/(B15-F15)*100,1)&"%")
A16: Infra Failure Incident Response | B16: =COUNTA('Infra Failure Incident Response'!D4:D5) | C16: =COUNTIF('Infra Failure Incident Response'!D4:D5,"Compliant") | D16: =COUNTIF('Infra Failure Incident Response'!D4:D5,"Partial") | E16: =COUNTIF('Infra Failure Incident Response'!D4:D5,"Non-Compliant") | F16: =COUNTIF('Infra Failure Incident Response'!D4:D5,"N/A") | G16: =IF((B16-F16)=0,"N/A",ROUND(C16/(B16-F16)*100,1)&"%")
A17: Maintenance Records | B17: =COUNTA('Maintenance Records'!D4:D10) | C17: =COUNTIF('Maintenance Records'!D4:D10,"Compliant") | D17: =COUNTIF('Maintenance Records'!D4:D10,"Partial") | E17: =COUNTIF('Maintenance Records'!D4:D10,"Non-Compliant") | F17: =COUNTIF('Maintenance Records'!D4:D10,"N/A") | G17: =IF((B17-F17)=0,"N/A",ROUND(C17/(B17-F17)*100,1)&"%")
A18: Infrastructure Performance Mon | B18: =COUNTA('Infrastructure Performance Mon'!D4:D5) | C18: =COUNTIF('Infrastructure Performance Mon'!D4:D5,"Compliant") | D18: =COUNTIF('Infrastructure Performance Mon'!D4:D5,"Partial") | E18: =COUNTIF('Infrastructure Performance Mon'!D4:D5,"Non-Compliant") | F18: =COUNTIF('Infrastructure Performance Mon'!D4:D5,"N/A") | G18: =IF((B18-F18)=0,"N/A",ROUND(C18/(B18-F18)*100,1)&"%")
A19: Compliance Measurement | B19: =COUNTA('Compliance Measurement'!D4:D4) | C19: =COUNTIF('Compliance Measurement'!D4:D4,"Compliant") | D19: =COUNTIF('Compliance Measurement'!D4:D4,"Partial") | E19: =COUNTIF('Compliance Measurement'!D4:D4,"Non-Compliant") | F19: =COUNTIF('Compliance Measurement'!D4:D4,"N/A") | G19: =IF((B19-F19)=0,"N/A",ROUND(C19/(B19-F19)*100,1)&"%")
A20: TOTAL | B20: =SUM(B4:B19) | C20: =SUM(C4:C19) | D20: =SUM(D4:D19) | E20: =SUM(E4:E19) | F20: =SUM(F4:F19) | G20: =IF((B20-F20)=0,"N/A",ROUND(C20/(B20-F20)*100,1)&"%")
A22: COMPLIANCE BY STATUS
A23: Compliant | B23: =C20 | C23: =IF(B20=0,"",ROUND(B23/B20*100,1)&"%")
A24: Partial | B24: =D20 | C24: =IF(B20=0,"",ROUND(B24/B20*100,1)&"%")
A25: Non-Compliant | B25: =E20 | C25: =IF(B20=0,"",ROUND(B25/B20*100,1)&"%")
A26: N/A | B26: =F20 | C26: =IF(B20=0,"",ROUND(B26/B20*100,1)&"%")
A28: TOP GAPS (Manual Entry)
A29: Priority | B29: Domain | C29: Requirement | D29: Owner | E29: Due Date | F29: Status
A41: COMPLIANCE TREND (Manual Entry)
A42: Assessment Date | B42: Overall % | C42: Compliant | D42: Gaps | E42: Assessor | F42: Notes

Sheet Cable Protection Standards
A1: Cable Protection Standards — Compliance Checklist
A2: ISO/IEC 27001:2022 — Controls A.7.12-13: Cabling Security and Equipment Maintenance
A3: Req # | B3: Section | C3: Requirement | D3: Status | E3: Evidence | F3: Owner | G3: Due Date | H3: Notes
A4: A.7.12-13-01 | B4: Cables Carrying Power, Data, Or | C4: All cables carrying power, data, or supporting information services shall be physically protected:.
A5: A.7.12-13-02 | B5: Be Routed Through Protected Pathways — | C5: Cables shall be routed through protected pathways — conduits, cable trays, raised floors, or ceiling voids — not exposed across open areas.
A6: A.7.12-13-03 | B6: Underground Cabling | C6: Underground cabling shall be protected against accidental damage using armoured conduits or duct systems. Route markers shall identify buried cable paths.
A7: A.7.12-13-04 | B7: Be Protected From Environmental Hazards | C7: Cables shall be protected from environmental hazards including water ingress, heat sources, chemical exposure, and physical impact. Cable routes shall avoid areas with high risk of damage.
A8: A.7.12-13-05 | B8: Suitable Protection | C8: Where cables traverse between buildings, suitable protection shall be applied (armoured cable, sealed duct, or direct-buried conduit).
A9: A.7.12-13-06 | B9: Wiring Closets, Telecommunications | C9: Wiring closets, telecommunications rooms, and cable distribution frames shall be physically secured. These areas shall be locked when unoccupied and access restricted to authorised personnel.
A10: A.7.12-13-07 | B10: Manhole And Duct Access Points | C10: Manhole and duct access points shall be secured and access logged.
A11: A.7.12-13-08 | B11: Be Protected From Electromagnetic | C11: Cables shall be protected from electromagnetic interference (EMI) through appropriate shielding, separation from interference sources, and selection of cable type suited to the environment.
A12: A.7.12-13-09 | B12: In Environments With High | C12: In environments with high electromagnetic interference (e.g., near heavy electrical equipment, industrial machinery, or radio transmission), shielded cable (STP/FTP) or fibre optic cable shall be used.
A13: A.7.12-13-10 | B13: Cable Installations | C13: Cable installations shall comply with the organisation's adopted structured cabling standard (IEC 11801 / EN 50173 / TIA-568 as applicable) for shielding and separation requirements.

Sheet Cable Segregation
A1: Cable Segregation — Compliance Checklist
A2: ISO/IEC 27001:2022 — Controls A.7.12-13: Cabling Security and Equipment Maintenance
A3: Req # | B3: Section | C3: Requirement | D3: Status | E3: Evidence | F3: Owner | G3: Due Date | H3: Notes
A4: A.7.12-13-11 | B4: Power Cables And Communications Cables | C4: Power cables and communications cables shall be segregated to prevent electromagnetic interference:.
A5: A.7.12-13-12 | B5: Minimum Separation Distances | C5: Minimum separation distances shall follow the structured cabling standard adopted by the organisation. As a baseline: minimum 200 mm separation between unshielded data cables and power cables running in parallel. Where crossing is unavoidable, cables shall cross at right angles.
A6: A.7.12-13-13 | B6: Power And Data Cables | C6: Power and data cables shall use separate conduits, cable trays, or pathways. Shared pathways are not permitted for unshielded data cables and power cables.
A7: A.7.12-13-14 | B7: Separation Requirements | C7: Separation requirements shall be documented in the organisation's cabling standard and applied consistently across all installations.
A8: A.7.12-13-15 | B8: Cables Carrying Traffic Of Different | C8: Cables carrying traffic of different security classifications shall be physically separated where feasible, or clearly identified using colour coding or labelling to prevent cross-connection.
A9: A.7.12-13-16 | B9: High-Security Network Cables (E.G., | C9: High-security network cables (e.g., management networks, financial systems, security systems) shall be identifiable through consistent colour coding or labelling convention defined by the organisation.

Sheet Cable Documentation & Labelling
A1: Cable Documentation & Labelling — Compliance Checklist
A2: ISO/IEC 27001:2022 — Controls A.7.12-13: Cabling Security and Equipment Maintenance
A3: Req # | B3: Section | C3: Requirement | D3: Status | E3: Evidence | F3: Owner | G3: Due Date | H3: Notes
A4: A.7.12-13-17 | B4: Cable Infrastructure | C4: Cable infrastructure shall be documented and maintained:.
A5: A.7.12-13-18 | B5: A Cable Register Or Cable Management | C5: A cable register or cable management database shall record all structured cabling installations, including cable type, endpoints, route, installation date, and classification.
A6: A.7.12-13-19 | B6: As-Built Cabling Diagrams | C6: As-built cabling diagrams shall be maintained for all facilities. Diagrams shall show cable routes, patch panel locations, distribution frames, and interconnections.
A7: A.7.12-13-20 | B7: Cable Documentation | C7: Cable documentation shall be kept current. All cabling changes shall be reflected in documentation within 5 business days of completion.
A8: A.7.12-13-21 | B8: Cable Documentation | C8: Cable documentation shall be secured and access-controlled. Only authorised personnel shall have access to detailed cabling diagrams (these reveal network topology and physical routes).
A9: A.7.12-13-22 | B9: Be Labelled At Both Ends With | C9: All cables shall be labelled at both ends with a unique identifier that maps to the cable register.
A10: A.7.12-13-23 | B10: Patch Panels, Distribution Frames, And | C10: Patch panels, distribution frames, and telecommunications outlets shall be clearly labelled.
A11: A.7.12-13-24 | B11: Be Durable, Legible, And Enable | C11: Labels shall be durable, legible, and enable identification without requiring reference to detailed documentation for routine operations.
A12: A.7.12-13-25 | B12: Define And Document A Consistent | C12: The organisation shall define and document a consistent labelling convention (e.g., building-floor-room-rack-port).
A13: A.7.12-13-26 | B13: Cabling Installations, Modifications, | C13: All cabling installations, modifications, and removals shall follow the organisation's change management process (A.8.32) with the following specific requirements:.
A14: A.7.12-13-27 | B14: Cabling Change Requests | C14: Cabling change requests shall include:.
A15: A.7.12-13-28 | B15: Cabling Changes | C15: All cabling changes shall include post-implementation testing:.
... A17: A.7.12-13-30 | B17: Quarterly Physical Walkthroughs | C17: Quarterly physical walkthroughs shall be conducted to identify unauthorised additions, modifications, or damage. Findings shall be reconciled against as-built diagrams and change records, with results documented and signed off by the Facilities Manager.

Sheet Fibre Optic Requirements
A1: Fibre Optic Requirements — Compliance Checklist
A2: ISO/IEC 27001:2022 — Controls A.7.12-13: Cabling Security and Equipment Maintenance
A3: Req # | B3: Section | C3: Requirement | D3: Status | E3: Evidence | F3: Owner | G3: Due Date | H3: Notes
A4: A.7.12-13-31 | B4: Fibre Optic Cable | C4: Fibre optic cable shall be used in preference to copper for data transmission in the following circumstances:.
A5: A.7.12-13-32 | B5: Fusion Splicing | C5: Where fibre optic is deployed, fusion splicing shall be used for permanent connections (not mechanical splicing) in secure areas. Fibre patch panels shall be housed in locked enclosures.
A6: A.7.12-13-33 | B6: Shielded Cable (Stp/Ftp) | C6: Where copper cable is used in areas with interception risk, shielded cable (STP/FTP) shall be specified and cable routes shall be physically secured.

Sheet Inspection and Cable Maint
A1: Inspection and Cable Maint — Compliance Checklist
A2: ISO/IEC 27001:2022 — Controls A.7.12-13: Cabling Security and Equipment Maintenance
A3: Req # | B3: Section | C3: Requirement | D3: Status | E3: Evidence | F3: Owner | G3: Due Date | H3: Notes
A4: A.7.12-13-34 | B4: Regular Inspection And Maintenance Of | C4: Regular inspection and maintenance of cabling infrastructure shall be performed:.
A5: A.7.12-13-35 | B5: Cable Infrastructure | C5: Cable infrastructure shall be included in the organisation's maintenance programme with defined inspection intervals.
A6: A.7.12-13-36 | B6: Visual Inspections | C6: Visual inspections shall be conducted quarterly for accessible cable routes, checking for damage, unauthorised modifications, labelling integrity, and pathway obstructions.
A7: A.7.12-13-37 | B7: Formal Cable Testing (Continuity, | C7: Formal cable testing (continuity, performance) shall be conducted annually or following any reported issues.
A8: A.7.12-13-38 | B8: Damaged Cables | C8: Damaged cables shall be repaired or replaced promptly. Temporary repairs shall be documented and permanent repair scheduled within 30 calendar days.
A9: A.7.12-13-39 | B9: Inspection Findings | C9: Inspection findings shall be documented and retained for a minimum of 3 years.

Sheet Maintenance Programme
A1: Maintenance Programme — Compliance Checklist
A2: ISO/IEC 27001:2022 — Controls A.7.12-13: Cabling Security and Equipment Maintenance
A3: Req # | B3: Section | C3: Requirement | D3: Status | E3: Evidence | F3: Owner | G3: Due Date | H3: Notes
A4: A.7.12-13-40 | B4: Establish And Maintain A Maintenance | C4: The organisation shall establish and maintain a maintenance programme covering all equipment that processes, stores, or supports the processing of information:.
A5: A.7.12-13-41 | B5: In-Scope Equipment Recorded In The Asset | C5: All in-scope equipment recorded in the asset inventory (per A.5.9) shall be included in the maintenance programme. The asset inventory is the authoritative source for programme completeness.
A6: A.7.12-13-42 | B6: Quarterly Reconciliation | C6: Quarterly reconciliation shall verify that all inventoried equipment has maintenance coverage. Reconciliation results and sign-off shall be retained as evidence.
A7: A.7.12-13-43 | B7: Maintenance Schedules | C7: Maintenance schedules shall follow manufacturer recommendations as minimums. Deviations require documented risk acceptance via the exception register.
A8: A.7.12-13-44 | B8: The Maintenance Programme | C8: The maintenance programme shall be managed through [CMMS] or equivalent maintenance tracking system. Where a dedicated CMMS is not deployed, a controlled spreadsheet or register shall be used.
A9: A.7.12-13-45 | B9: Maintenance Schedules | C9: Maintenance schedules shall be adjusted based on equipment age, environmental conditions, manufacturer advisories, and incident history. Equipment approaching end-of-life shall have maintenance frequency increased or be scheduled for replacement.

Sheet Avail and Service Continuity
A1: Avail and Service Continuity — Compliance Checklist
A2: ISO/IEC 27001:2022 — Controls A.7.12-13: Cabling Security and Equipment Maintenance
A3: Req # | B3: Section | C3: Requirement | D3: Status | E3: Evidence | F3: Owner | G3: Due Date | H3: Notes
A4: A.7.12-13-46 | B4: Cabling And Equipment Infrastructure | C4: Cabling and equipment infrastructure directly supports the organisation's service availability commitments to customers. Maintenance activities shall be planned and executed to minimise service disruption.
A5: A.7.12-13-47 | B5: Maintenance Activities | C5: All maintenance activities shall be assessed for potential service impact before scheduling:.
A6: A.7.12-13-48 | B6: Non-Emergency Maintenance That May | C6: All non-emergency maintenance that may impact services shall be scheduled during approved maintenance windows.
A7: A.7.12-13-49 | B7: Infrastructure Maintenance Programme | C7: Infrastructure maintenance programme shall support the organisation's availability commitments:.
A8: A.7.12-13-50 | B8: Preventive Maintenance Scheduling | C8: Preventive maintenance scheduling constraint*: Total planned downtime for infrastructure maintenance shall not exceed 50% of the annual allowable downtime budget, reserving capacity for unplanned failures.
A9: A.7.12-13-51 | B9: Equipment Maintenance Programme | C9: Equipment maintenance programme shall account for redundancy design:.
A10: A.7.12-13-52 | B10: Single Points Of Failure: Equipment With | C10: Single points of failure: Equipment with no redundancy shall have maintenance scheduled during low-usage periods with advance customer notification.
A11: A.7.12-13-53 | B11: Redundant Systems: Where N+1 Or 2N | C11: Redundant systems: Where N+1 or 2N redundancy exists, maintenance shall be staggered to maintain at least N capacity at all times.
A12: A.7.12-13-54 | B12: Critical Path Equipment (Ups, Network | C12: Critical path equipment (UPS, network core, primary servers): Maintenance shall include pre-maintenance verification of redundancy status and post-maintenance failover testing.
A13: A.7.12-13-55 | B13: Remaining Capacity | C13: When redundant equipment is taken offline for maintenance, remaining capacity shall be verified sufficient for current load plus 20% buffer:.
A14: A.7.12-13-56 | B14: Be Rescheduled Or Additional Temporary | C14: If capacity would fall below buffer threshold, maintenance shall be rescheduled or additional temporary capacity provisioned.
A15: A.7.12-13-57 | B15: Load Testing After Maintenance | C15: Load testing after maintenance shall verify full redundancy restored before marking equipment 'in service'.
... A20: A.7.12-13-62 | B20: Dr Test Findings That Reveal | C20: DR test findings that reveal infrastructure gaps shall trigger maintenance programme updates.

Sheet Maint Personnel Authorisation
A1: Maint Personnel Authorisation — Compliance Checklist
A2: ISO/IEC 27001:2022 — Controls A.7.12-13: Cabling Security and Equipment Maintenance
A3: Req # | B3: Section | C3: Requirement | D3: Status | E3: Evidence | F3: Owner | G3: Due Date | H3: Notes
A4: A.7.12-13-63 | B4: Only Personnel With Documented | C4: Only personnel with documented authorisation shall perform maintenance on information processing equipment.
A5: A.7.12-13-64 | B5: Maintenance Authorisation | C5: Maintenance authorisation shall specify which equipment categories and which maintenance activities the individual is qualified to perform.
A6: A.7.12-13-65 | B6: Authorisation Records | C6: Authorisation records shall be maintained and reviewed annually.
A7: A.7.12-13-66 | B7: Third-Party Maintenance | C7: Third-party maintenance shall be performed only by contracted and approved providers. Maintenance contracts shall include confidentiality obligations and security requirements.
A8: A.7.12-13-67 | B8: Third-Party Maintenance Personnel | C8: Third-party maintenance personnel shall be identified and verified (government-issued identification) before being granted access to equipment.
A9: A.7.12-13-68 | B9: Maintain A Register Of Approved | C9: The organisation shall maintain a register of approved third-party maintenance providers, reviewed annually.
A10: A.7.12-13-69 | B10: Third-Party Maintenance Personnel | C10: Third-party maintenance personnel shall be supervised when accessing equipment that processes or stores sensitive or confidential information, unless a documented risk assessment concludes that unsupervised access is acceptable (e.g., dedicated maintenance contract with background-checked personnel, isolated equipment).
A11: A.7.12-13-70 | B11: Unsupervised Third-Party Maintenance | C11: Unsupervised third-party maintenance access shall be logged with individual identification, time in/out, and equipment accessed.
A12: A.7.12-13-71 | B12: Supervision Records | C12: Supervision records shall be maintained as evidence.

Sheet Third-Party Maint Provider Mgmt
A1: Third-Party Maint Provider Mgmt — Compliance Checklist
A2: ISO/IEC 27001:2022 — Controls A.7.12-13: Cabling Security and Equipment Maintenance
A3: Req # | B3: Section | C3: Requirement | D3: Status | E3: Evidence | F3: Owner | G3: Due Date | H3: Notes
A4: A.7.12-13-72 | B4: Maintenance Contracts With Third-Party | C4: Maintenance contracts with third-party providers shall include:.
A5: A.7.12-13-73 | B5: Maintenance Provider Performance | C5: Maintenance provider performance shall be tracked and reviewed:.
A6: A.7.12-13-74 | B6: Maintenance Provider | C6: Each maintenance provider shall receive an annual review covering:.

Sheet Security During Maintenance
A1: Security During Maintenance — Compliance Checklist
A2: ISO/IEC 27001:2022 — Controls A.7.12-13: Cabling Security and Equipment Maintenance
A3: Req # | B3: Section | C3: Requirement | D3: Status | E3: Evidence | F3: Owner | G3: Due Date | H3: Notes
A4: A.7.12-13-75 | B4: Sensitive Data | C4: Sensitive data shall be protected during all maintenance activities. Maintenance personnel shall not have access to data stored on equipment unless specifically required and authorised.
A5: A.7.12-13-76 | B5: Equipment | C5: Equipment containing data shall not be removed from premises for maintenance where on-site repair is feasible.
A6: A.7.12-13-77 | B6: Be Securely Erased From The Equipment | C6: If off-site maintenance is required, data shall be securely erased from the equipment before removal (per A.7.14 secure disposal procedures), or the storage media shall be removed and retained by the organisation.
A7: A.7.12-13-78 | B7: For Equipment Where Data Erasure Is | C7: For equipment where data erasure is not feasible before removal (e.g., fault prevents access), a documented risk assessment shall be completed and the maintenance provider's data handling obligations confirmed in writing.
A8: A.7.12-13-79 | B8: After Maintenance, Equipment | C8: After maintenance, equipment shall be physically inspected before being returned to service to verify that no unauthorised modifications have been made.
A9: A.7.12-13-80 | B9: Tools And Equipment Brought On-Site By | C9: All tools and equipment brought on-site by maintenance personnel shall be accounted for before and after maintenance.
A10: A.7.12-13-81 | B10: Firmware And Software Versions | C10: Firmware and software versions shall be verified after maintenance to confirm no unauthorised changes.
A11: A.7.12-13-82 | B11: Maintenance Access | C11: Maintenance access shall be time-limited. Access windows shall be agreed in advance and documented.
A12: A.7.12-13-83 | B12: Maintenance Access | C12: All maintenance access shall be logged: who performed the work, when, what equipment was accessed, and what work was performed.
A13: A.7.12-13-84 | B13: Maintenance Personnel | C13: Maintenance personnel shall be issued temporary access credentials (badges, system access) that expire at the end of the maintenance window.

Sheet Remote Maintenance
A1: Remote Maintenance — Compliance Checklist
A2: ISO/IEC 27001:2022 — Controls A.7.12-13: Cabling Security and Equipment Maintenance
A3: Req # | B3: Section | C3: Requirement | D3: Status | E3: Evidence | F3: Owner | G3: Due Date | H3: Notes
A4: A.7.12-13-85 | B4: Remote Maintenance Introduces Additional | C4: Remote maintenance introduces additional risk. The following controls shall apply:.
A5: A.7.12-13-86 | B5: Remote Maintenance | C5: Remote maintenance shall be explicitly authorised before each session. Standing authorisation for remote access is not permitted.
A6: A.7.12-13-87 | B6: Remote Maintenance Sessions | C6: Remote maintenance sessions shall use encrypted connections (VPN, SSH, or equivalent secure protocol). Unencrypted remote access is not permitted.
A7: A.7.12-13-88 | B7: Remote Maintenance Sessions | C7: Remote maintenance sessions shall be logged, including session start/end times, individual identity, and actions performed. Session recording is recommended for critical equipment.
A8: A.7.12-13-89 | B8: Remote Access | C8: Remote access shall be disabled when not actively in use. Persistent remote access connections for maintenance purposes shall not remain open.
A9: A.7.12-13-90 | B9: Remote Maintenance Of Equipment | C9: Remote maintenance of equipment containing sensitive data shall require the same authorisation as physical access to that equipment.
A10: A.7.12-13-91 | B10: A Dedicated Jump Host Or Bastion | C10: Where the maintenance provider requires remote access to internal systems, a dedicated jump host or bastion server with multi-factor authentication shall be used.

Sheet Equipment Removal and Return
A1: Equipment Removal and Return — Compliance Checklist
A2: ISO/IEC 27001:2022 — Controls A.7.12-13: Cabling Security and Equipment Maintenance
A3: Req # | B3: Section | C3: Requirement | D3: Status | E3: Evidence | F3: Owner | G3: Due Date | H3: Notes
A4: A.7.12-13-92 | B4: Authorisation: Removal | C4: Authorisation: Removal shall be authorised in writing by the equipment owner or designated delegate.
A5: A.7.12-13-93 | B5: Data Protection: Data | C5: Data protection: Data shall be securely erased before removal. If erasure is not possible, storage media shall be removed and retained by the organisation. The data protection approach shall be documented.
A6: A.7.12-13-94 | B6: Chain Of Custody: A Chain Of | C6: Chain of custody: A chain of custody record shall be created documenting: equipment identification, condition at removal, removal date/time, authorised by, carrier/transporter, destination, expected return date.
A7: A.7.12-13-95 | B7: Equipment Return Inspection: Upon | C7: Equipment return inspection: Upon return, the equipment shall be inspected for tampering, unauthorised modifications, and correct configuration. Firmware and software versions shall be verified.
A8: A.7.12-13-96 | B8: Asset Register Update: Equipment Return | C8: Asset register update: Equipment return shall be logged in [Asset Management System] with maintenance summary and inspection results.

Sheet Infra Failure Incident Response
A1: Infra Failure Incident Response — Compliance Checklist
A2: ISO/IEC 27001:2022 — Controls A.7.12-13: Cabling Security and Equipment Maintenance
A3: Req # | B3: Section | C3: Requirement | D3: Status | E3: Evidence | F3: Owner | G3: Due Date | H3: Notes
A4: A.7.12-13-97 | B4: Infrastructure Failures (Cable Damage, | C4: Infrastructure failures (cable damage, equipment malfunction) that impact or may impact services shall be managed through the organisation's incident management process.
A5: A.7.12-13-98 | B5: Infrastructure Incidents | C5: Infrastructure incidents shall document:.

Sheet Maintenance Records
A1: Maintenance Records — Compliance Checklist
A2: ISO/IEC 27001:2022 — Controls A.7.12-13: Cabling Security and Equipment Maintenance
A3: Req # | B3: Section | C3: Requirement | D3: Status | E3: Evidence | F3: Owner | G3: Due Date | H3: Notes
A4: A.7.12-13-99 | B4: Maintenance — Preventive And Corrective | C4: All maintenance — preventive and corrective — shall be documented:.
A5: A.7.12-13-100 | B5: Maintenance Records | C5: Maintenance records shall be retained for a minimum of 3 years or the lifecycle of the equipment, whichever is longer.
A6: A.7.12-13-101 | B6: Be Available For Audit At All | C6: Records shall be available for audit at all times.
A7: A.7.12-13-102 | B7: Be Stored In [Cmms] Or Equivalent | C7: Records shall be stored in [CMMS] or equivalent controlled register.
A8: A.7.12-13-103 | B8: Maintenance Records | C8: Maintenance records shall be reviewed quarterly for trends: recurring faults, equipment approaching end-of-life, increasing failure frequency, or maintenance SLA breaches.
A9: A.7.12-13-104 | B9: Trend Analysis | C9: Trend analysis shall inform equipment replacement planning and maintenance programme adjustments.
A10: A.7.12-13-105 | B10: Quarterly Trend Reports | C10: Quarterly trend reports shall be provided to the IT Operations Manager and CISO.

Sheet Infrastructure Performance Mon
A1: Infrastructure Performance Mon — Compliance Checklist
A2: ISO/IEC 27001:2022 — Controls A.7.12-13: Cabling Security and Equipment Maintenance
A3: Req # | B3: Section | C3: Requirement | D3: Status | E3: Evidence | F3: Owner | G3: Due Date | H3: Notes
A4: A.7.12-13-106 | B4: Beyond Maintenance Completion Metrics, | C4: Beyond maintenance completion metrics, the organisation shall monitor infrastructure health indicators to enable predictive maintenance and demonstrate availability effectiveness.
A5: A.7.12-13-107 | B5: Health Monitoring | C5: Health monitoring shall trigger early maintenance actions before failure:.

Sheet Compliance Measurement
A1: Compliance Measurement — Compliance Checklist
A2: ISO/IEC 27001:2022 — Controls A.7.12-13: Cabling Security and Equipment Maintenance
A3: Req # | B3: Section | C3: Requirement | D3: Status | E3: Evidence | F3: Owner | G3: Due Date | H3: Notes
A4: A.7.12-13-108 | B4: The Following Metrics | C4: The following metrics shall be tracked and reported to the CISO quarterly:.
