Workbook

Sheet Executive Summary
A1: ISMS-OP-CHK-A.5.19-23 — Cloud Services and Supplier Security Compliance Checklist
A3: DOCUMENT INFORMATION
A4: Document ID | B4: ISMS-OP-CHK-A.5.19-23
A5: Source Policy | B5: ISMS-OP-POL-A.5.19-23
A6: ISO Controls | B6: ISO/IEC 27001:2022 — Controls A.5.19-23: Cloud Services and Supplier Security
A7: Generated | B7: 07.02.2026
A8: Prepared By
A9: Organisation
A10: Review Cycle | B10: Annual
A12: OVERALL COMPLIANCE STATUS
A13: Overall Compliance | B13: ='Dashboard'!G10
A14: Status | B14: =IF(Dashboard!G10="N/A","NOT ASSESSED",IF(ISNUMBER(VALUE(SUBSTITUTE(Dashboard!G10,"%",""))),IF(VALUE(SUBSTITUTE(Dashboard!G10,"%",""))>=90,"GREEN",IF(VALUE(SUBSTITUTE(Dashboard!G10,"%",""))>=70,"AMBER","RED")),"NOT ASSESSED"))
A16: KEY METRICS
A17: Total Requirements | B17: ='Dashboard'!B10
A18: Compliant | B18: ='Dashboard'!C10
A19: Partial | B19: ='Dashboard'!D10
A20: Non-Compliant | B20: ='Dashboard'!E10
A21: Not Applicable | B21: ='Dashboard'!F10
A22: Owner Coverage | B22: =IF(Dashboard!B10=0,"N/A",ROUND((COUNTA('Register & Classification'!F4:F11)+COUNTA('Due Diligence & Selection'!F4:F9)+COUNTA('Contracts & Data Processing'!F4:F11)+COUNTA('Cross-Border & Compliance'!F4:F8)+COUNTA('Monitoring & Incidents'!F4:F11)+COUNTA('Exit & Continuity'!F4:F10))/Dashboard!B10*100,0)&"%")
A24: DOMAIN STATUS SUMMARY
A25: Domain | B25: Compliance % | C25: Compliant | D25: Gaps | E25: Status
A26: Register & Classification | B26: ='Dashboard'!G4 | C26: ='Dashboard'!C4 | D26: ='Dashboard'!E4 | E26: =IF(Dashboard!G4="N/A","--",IF(ISNUMBER(VALUE(SUBSTITUTE(Dashboard!G4,"%",""))),IF(VALUE(SUBSTITUTE(Dashboard!G4,"%",""))>=90,"PASS",IF(VALUE(SUBSTITUTE(Dashboard!G4,"%",""))>=70,"REVIEW","FAIL")),"--"))
A27: Due Diligence & Selection | B27: ='Dashboard'!G5 | C27: ='Dashboard'!C5 | D27: ='Dashboard'!E5 | E27: =IF(Dashboard!G5="N/A","--",IF(ISNUMBER(VALUE(SUBSTITUTE(Dashboard!G5,"%",""))),IF(VALUE(SUBSTITUTE(Dashboard!G5,"%",""))>=90,"PASS",IF(VALUE(SUBSTITUTE(Dashboard!G5,"%",""))>=70,"REVIEW","FAIL")),"--"))
A28: Contracts & Data Processing | B28: ='Dashboard'!G6 | C28: ='Dashboard'!C6 | D28: ='Dashboard'!E6 | E28: =IF(Dashboard!G6="N/A","--",IF(ISNUMBER(VALUE(SUBSTITUTE(Dashboard!G6,"%",""))),IF(VALUE(SUBSTITUTE(Dashboard!G6,"%",""))>=90,"PASS",IF(VALUE(SUBSTITUTE(Dashboard!G6,"%",""))>=70,"REVIEW","FAIL")),"--"))
A29: Cross-Border & Compliance | B29: ='Dashboard'!G7 | C29: ='Dashboard'!C7 | D29: ='Dashboard'!E7 | E29: =IF(Dashboard!G7="N/A","--",IF(ISNUMBER(VALUE(SUBSTITUTE(Dashboard!G7,"%",""))),IF(VALUE(SUBSTITUTE(Dashboard!G7,"%",""))>=90,"PASS",IF(VALUE(SUBSTITUTE(Dashboard!G7,"%",""))>=70,"REVIEW","FAIL")),"--"))
A30: Monitoring & Incidents | B30: ='Dashboard'!G8 | C30: ='Dashboard'!C8 | D30: ='Dashboard'!E8 | E30: =IF(Dashboard!G8="N/A","--",IF(ISNUMBER(VALUE(SUBSTITUTE(Dashboard!G8,"%",""))),IF(VALUE(SUBSTITUTE(Dashboard!G8,"%",""))>=90,"PASS",IF(VALUE(SUBSTITUTE(Dashboard!G8,"%",""))>=70,"REVIEW","FAIL")),"--"))
A31: Exit & Continuity | B31: ='Dashboard'!G9 | C31: ='Dashboard'!C9 | D31: ='Dashboard'!E9 | E31: =IF(Dashboard!G9="N/A","--",IF(ISNUMBER(VALUE(SUBSTITUTE(Dashboard!G9,"%",""))),IF(VALUE(SUBSTITUTE(Dashboard!G9,"%",""))>=90,"PASS",IF(VALUE(SUBSTITUTE(Dashboard!G9,"%",""))>=70,"REVIEW","FAIL")),"--"))
A33: CRITICAL ISSUES
A34: # | B34: Issue Description | C34: Domain | D34: Owner | E34: Due Date
A35: 1
A36: 2
A37: 3
A38: 4
A39: 5
A41: MANAGEMENT COMMENTARY
A42: [Enter management commentary on supplier and cloud service security posture]
A46: APPROVAL
A47: Assessed By
A48: Name:
A49: Date:
...

Sheet Dashboard
A1: Cloud Services and Supplier Security — Compliance Dashboard
A3: Domain | B3: Total Reqs | C3: Compliant | D3: Partial | E3: Non-Compliant | F3: N/A | G3: Compliance %
A4: Register & Classification | B4: =COUNTA('Register & Classification'!D4:D11) | C4: =COUNTIF('Register & Classification'!D4:D11,"Compliant") | D4: =COUNTIF('Register & Classification'!D4:D11,"Partial") | E4: =COUNTIF('Register & Classification'!D4:D11,"Non-Compliant") | F4: =COUNTIF('Register & Classification'!D4:D11,"N/A") | G4: =IF((B4-F4)=0,"N/A",ROUND(C4/(B4-F4)*100,1)&"%")
A5: Due Diligence & Selection | B5: =COUNTA('Due Diligence & Selection'!D4:D9) | C5: =COUNTIF('Due Diligence & Selection'!D4:D9,"Compliant") | D5: =COUNTIF('Due Diligence & Selection'!D4:D9,"Partial") | E5: =COUNTIF('Due Diligence & Selection'!D4:D9,"Non-Compliant") | F5: =COUNTIF('Due Diligence & Selection'!D4:D9,"N/A") | G5: =IF((B5-F5)=0,"N/A",ROUND(C5/(B5-F5)*100,1)&"%")
A6: Contracts & Data Processing | B6: =COUNTA('Contracts & Data Processing'!D4:D11) | C6: =COUNTIF('Contracts & Data Processing'!D4:D11,"Compliant") | D6: =COUNTIF('Contracts & Data Processing'!D4:D11,"Partial") | E6: =COUNTIF('Contracts & Data Processing'!D4:D11,"Non-Compliant") | F6: =COUNTIF('Contracts & Data Processing'!D4:D11,"N/A") | G6: =IF((B6-F6)=0,"N/A",ROUND(C6/(B6-F6)*100,1)&"%")
A7: Cross-Border & Compliance | B7: =COUNTA('Cross-Border & Compliance'!D4:D8) | C7: =COUNTIF('Cross-Border & Compliance'!D4:D8,"Compliant") | D7: =COUNTIF('Cross-Border & Compliance'!D4:D8,"Partial") | E7: =COUNTIF('Cross-Border & Compliance'!D4:D8,"Non-Compliant") | F7: =COUNTIF('Cross-Border & Compliance'!D4:D8,"N/A") | G7: =IF((B7-F7)=0,"N/A",ROUND(C7/(B7-F7)*100,1)&"%")
A8: Monitoring & Incidents | B8: =COUNTA('Monitoring & Incidents'!D4:D11) | C8: =COUNTIF('Monitoring & Incidents'!D4:D11,"Compliant") | D8: =COUNTIF('Monitoring & Incidents'!D4:D11,"Partial") | E8: =COUNTIF('Monitoring & Incidents'!D4:D11,"Non-Compliant") | F8: =COUNTIF('Monitoring & Incidents'!D4:D11,"N/A") | G8: =IF((B8-F8)=0,"N/A",ROUND(C8/(B8-F8)*100,1)&"%")
A9: Exit & Continuity | B9: =COUNTA('Exit & Continuity'!D4:D10) | C9: =COUNTIF('Exit & Continuity'!D4:D10,"Compliant") | D9: =COUNTIF('Exit & Continuity'!D4:D10,"Partial") | E9: =COUNTIF('Exit & Continuity'!D4:D10,"Non-Compliant") | F9: =COUNTIF('Exit & Continuity'!D4:D10,"N/A") | G9: =IF((B9-F9)=0,"N/A",ROUND(C9/(B9-F9)*100,1)&"%")
A10: TOTAL | B10: =SUM(B4:B9) | C10: =SUM(C4:C9) | D10: =SUM(D4:D9) | E10: =SUM(E4:E9) | F10: =SUM(F4:F9) | G10: =IF((B10-F10)=0,"N/A",ROUND(C10/(B10-F10)*100,1)&"%")
A12: COMPLIANCE BY STATUS
A13: Compliant | B13: =C10 | C13: =IF(B10=0,"",ROUND(B13/B10*100,1)&"%")
A14: Partial | B14: =D10 | C14: =IF(B10=0,"",ROUND(B14/B10*100,1)&"%")
A15: Non-Compliant | B15: =E10 | C15: =IF(B10=0,"",ROUND(B15/B10*100,1)&"%")
A16: N/A | B16: =F10 | C16: =IF(B10=0,"",ROUND(B16/B10*100,1)&"%")
A18: TOP GAPS (Manual Entry)
A19: Priority | B19: Domain | C19: Requirement | D19: Owner | E19: Due Date | F19: Status
A31: COMPLIANCE TREND (Manual Entry)
A32: Assessment Date | B32: Overall % | C32: Compliant | D32: Gaps | E32: Assessor | F32: Notes

Sheet Register & Classification
A1: Register & Classification — Compliance Checklist
A2: ISO/IEC 27001:2022 — Controls A.5.19-23: Cloud Services and Supplier Security
A3: Req # | B3: Section | C3: Requirement | D3: Status | E3: Evidence | F3: Owner | G3: Due Date | H3: Notes
A4: A.5.19-01 | B4: Supplier Register | C4: All third-party suppliers and cloud services shall be registered and recorded in the Supplier and Cloud Service Register.
A5: A.5.19-02 | B5: Register Review | C5: The register shall be reviewed and updated at least quarterly or upon any new supplier engagement, contract change, or supplier exit.
A6: A.5.19-03 | B6: Criticality Assessment | C6: Suppliers and cloud services shall be assessed for criticality to the business (Critical / Important / Standard).
A7: A.5.19-04 | B7: Data Classification | C7: Suppliers and cloud services shall be classified based on the data processed, stored, or transmitted and their criticality to business operations.
A8: A.5.19-05 | B8: Register Minimum Data | C8: The register shall capture as a minimum: supplier name/contacts, service description, data processed, data classification, contract status, security assurance, data locations, contract/review dates, and sub-processors.
A9: A.5.23-01 | B9: Shared Responsibility Model | C9: The organisation shall understand and document the shared responsibility model for each cloud service; areas of shared responsibility shall be explicitly documented and reviewed.
A10: A.5.23-02 | B10: Shared Responsibility Review | C10: Shared responsibility models shall be documented for each Critical cloud service and reviewed annually.
A11: A.5.23-03 | B11: Non-Negotiable Terms Assessment | C11: Where cloud service agreements are non-negotiable, the organisation shall assess whether the provider's standard terms meet its security requirements and document any residual risks.

Sheet Due Diligence & Selection
A1: Due Diligence & Selection — Compliance Checklist
A2: ISO/IEC 27001:2022 — Controls A.5.19-23: Cloud Services and Supplier Security
A3: Req # | B3: Section | C3: Requirement | D3: Status | E3: Evidence | F3: Owner | G3: Due Date | H3: Notes
A4: A.5.19-06 | B4: Selection Criteria | C4: Suppliers and cloud services shall be selected based on their ability to meet the needs of the business.
A5: A.5.19-07 | B5: Pre-Engagement Due Diligence | C5: Before engaging a supplier or cloud service provider, data security due diligence shall be carried out including: security level, references, certifications, contracts, legal compliance, data residency, terms assessment, and exit feasibility.
A6: A.5.19-08 | B6: Uncertified Supplier Risk Assessment | C6: Where a supplier cannot provide recognised certification (ISO 27001, SOC 2 Type II), the organisation shall conduct a documented risk assessment and implement compensating controls with risk acceptance from the Information Security Manager.
A7: A.5.22-01 | B7: Annual Audit Report Review | C7: The organisation shall obtain and review the most current independent audit reports (within 12 months) for each Critical cloud service annually.
A8: A.5.22-02 | B8: No Reports — CISO Approval | C8: Where a cloud provider does not provide independent third-party reports, the service shall not be used for Confidential or Restricted data without CISO approval and documented residual risk acceptance.
A9: A.5.23-04 | B9: Compensating Controls | C9: Where provider terms do not meet requirements, compensating controls shall be identified or an alternative provider shall be evaluated.

Sheet Contracts & Data Processing
A1: Contracts & Data Processing — Compliance Checklist
A2: ISO/IEC 27001:2022 — Controls A.5.19-23: Cloud Services and Supplier Security
A3: Req # | B3: Section | C3: Requirement | D3: Status | E3: Evidence | F3: Owner | G3: Due Date | H3: Notes
A4: A.5.20-01 | B4: Contract Before Engagement | C4: An appropriate contract, agreement, and/or Data Processing Agreement shall be in place and enforceable before engaging any supplier or cloud service provider to process, store, or transmit confidential or personal information.
A5: A.5.20-02 | B5: Contract Minimum Terms | C5: Contracts and agreements shall address at a minimum: data description, security obligations, incident notification, audit rights, sub-processor disclosure, data destruction, SLAs, and exit provisions.
A6: A.5.20-03 | B6: DPA for Personal Data | C6: All suppliers processing personal data on behalf of the organisation shall have a Data Processing Agreement meeting nFADP Art. 9 and, where applicable, GDPR Art. 28 requirements.
A7: A.5.20-04 | B7: DPA Minimum Content | C7: The DPA shall address: subject/duration, nature/purpose, data types/subjects, controller rights, sub-processor approval, security measures, data subject rights assistance, data return/deletion, and audit rights.
A8: A.5.21-01 | B8: Sub-Processor Approval | C8: The use by suppliers of sub-contractors or sub-processors shall be approved by the Information Security Manager.
A9: A.5.21-02 | B9: Sub-Processor Disclosure | C9: Cloud service providers shall disclose their sub-processor list.
A10: A.5.21-03 | B10: Sub-Processor Change Notification | C10: The organisation shall be notified of changes to sub-processors at least 30 days in advance and shall retain the right to object where contractually achievable.
A11: A.5.21-04 | B11: Residual Risk Documentation | C11: Where objection rights cannot be obtained, this limitation shall be documented in the risk register as residual risk with compensating controls (encryption, access monitoring).

Sheet Cross-Border & Compliance
A1: Cross-Border & Compliance — Compliance Checklist
A2: ISO/IEC 27001:2022 — Controls A.5.19-23: Cloud Services and Supplier Security
A3: Req # | B3: Section | C3: Requirement | D3: Status | E3: Evidence | F3: Owner | G3: Due Date | H3: Notes
A4: A.5.20-05 | B4: Adequacy Verification | C4: Where suppliers process or store personal data outside Switzerland, the organisation shall verify that adequate data protection exists per the Swiss Federal Council's adequacy list.
A5: A.5.20-06 | B5: Transfer Safeguards | C5: For transfers to countries not on the adequacy list, appropriate safeguards shall be in place: Standard Contractual Clauses (SCCs), Binding Corporate Rules (BCRs), or other recognised transfer mechanisms.
A6: A.5.20-07 | B6: Swiss-U.S. DPF Verification | C6: For transfers to the United States, the organisation shall verify that the receiving organisation is certified under the Swiss-U.S. Data Privacy Framework.
A7: A.5.20-08 | B7: US CLOUD Act Assessment | C7: Where the provider is US-headquartered and subject to the US CLOUD Act, a jurisdictional risk assessment shall be documented, including encryption, key management, and legal challenge commitments.
A8: A.5.19-09 | B8: Risk Register Entry | C8: Every supplier handling confidential or personal data shall be entered onto the Risk Register and managed via the organisation's risk management process.

Sheet Monitoring & Incidents
A1: Monitoring & Incidents — Compliance Checklist
A2: ISO/IEC 27001:2022 — Controls A.5.19-23: Cloud Services and Supplier Security
A3: Req # | B3: Section | C3: Requirement | D3: Status | E3: Evidence | F3: Owner | G3: Due Date | H3: Notes
A4: A.5.22-03 | B4: Supplier Incident Process | C4: Suppliers and cloud service providers shall have a security incident management process in place.
A5: A.5.22-04 | B5: Incident Notification Timelines | C5: Supplier security incidents impacting confidential or personal information shall be reported: Critical suppliers within 12 hours, Important within 24 hours, Standard within 72 hours.
A6: A.5.22-05 | B6: Non-12h Timeline Documentation | C6: Where a supplier cannot commit to the 12-hour timeline, this shall be documented as a residual risk with compensating controls.
A7: A.5.22-06 | B7: Notification Minimum Content | C7: The incident notification shall include at a minimum: description, affected systems/data, containment measures, and estimated impact/resolution timeline.
A8: A.5.22-07 | B8: Integrated Incident Management | C8: Supplier and cloud service security incidents shall be managed as part of the organisation's incident management process.
A9: A.5.22-08 | B9: Breach Notification Assessment | C9: Where a supplier incident involves a personal data breach, the organisation shall assess notification obligations under nFADP and, where applicable, GDPR Art. 33.
A10: A.5.19-10 | B10: Concentration Risk | C10: Where a single provider hosts >50% of critical services or >75% of Confidential data, this shall be flagged in the risk register with a mitigation plan or accepted residual risk.
A11: A.5.22-09 | B11: Cloud Service Audit Approach | C11: Where major cloud providers do not permit direct audit, independent third-party attestation (SOC 2, ISO 27001, CSA STAR) shall be obtained and reviewed as alternative assurance.

Sheet Exit & Continuity
A1: Exit & Continuity — Compliance Checklist
A2: ISO/IEC 27001:2022 — Controls A.5.19-23: Cloud Services and Supplier Security
A3: Req # | B3: Section | C3: Requirement | D3: Status | E3: Evidence | F3: Owner | G3: Due Date | H3: Notes
A4: A.5.20-09 | B4: Data Destruction Confirmation | C4: At end of contract, the supplier shall confirm in writing that it has met obligations for destruction of organisation confidential and personal information.
A5: A.5.20-10 | B5: Exit Completion Requirements | C5: Upon contract end: all data returned or destroyed, written destruction confirmation provided, all access revoked, all assets returned, certificates of destruction obtained for Confidential/Restricted data.
A6: A.5.23-05 | B6: CEO Approval for Changes | C6: Changes to a cloud service supplier require the formal, written, documented approval of the CEO or delegated authority.
A7: A.5.23-06 | B7: Change Management Integration | C7: Changes to cloud suppliers shall follow the Change Management Policy and shall be treated as a project with appropriate resources, risk management, and stakeholder communication.
A8: A.5.23-07 | B8: Exit Strategy Maintenance | C8: The organisation shall maintain an exit strategy for each Critical cloud service including: data export capability, transition timeline, alternative providers, transition costs, dependencies, and exit testing.
A9: A.5.23-08 | B9: Exit Strategy Review | C9: Exit strategies shall be reviewed annually or upon contract renewal.
A10: A.5.23-09 | B10: Exit Testing | C10: Verification that data export works shall be performed annually for Critical services.
