Workbook

Sheet Instructions & Legend
A1: ISMS-IMP-A.5.37.1 - Procedure Inventory Assessment ISO/IEC 27001:2022 - Control A.5.37: Documented Operating Procedures
A3: Document Information
A4: Document ID | B4: ISMS-IMP-A.5.37.1
A5: Workbook Title | B5: Procedure Inventory Assessment
A6: Control Reference | B6: ISO/IEC 27001:2022 - Control A.5.37: Documented Operating Procedures
A7: Version | B7: 1.0
A8: Assessment Date
A9: Completed By
A10: Organisation
A12: Instructions
A13: 1. Complete the Procedure Inventory — list all operating procedures for information processing facilities.
A14: 2. For each procedure, document owner, version, review date, and location.
A15: 3. Complete the Required Procedures sheet — verify all ISO 27001:2022 A.5.37 mandatory procedures exist.
A16: 4. Complete the Accessibility Matrix — confirm each procedure is accessible to personnel who need it.
A17: 5. Complete the Gap Analysis — identify missing, outdated, or inaccessible procedures.
A18: 6. Maintain the Evidence Register with procedure documents and accessibility confirmations.
A19: 7. Obtain final approval and sign-off in the Approval Sign-Off sheet.
A21: Status Legend
A22: Symbol | B22: Status | C22: Description
A23: ✓ | B23: Compliant / Complete | C23: Requirement fully met
A24: ⚠ | B24: Partial / In Progress | C24: Partially met or in progress
A25: ✗ | B25: Non-Compliant / Not Started | C25: Requirement not met
A26: — | B26: Not Applicable | C26: Not applicable to this assessment

Sheet Procedure Inventory
A1: PROCEDURE INVENTORY
A2: Master catalogue of all documented operating procedures — record each procedure, its owner, location, approval status and review dates
A3: Procedure ID | B3: Procedure Name | C3: Category | D3: Process Owner | E3: Department | F3: Document Location | G3: Last Review Date | H3: Next Review Due | I3: Review Cycle Days | J3: Version | K3: Approval Status | L3: Approver | M3: Approval Date | N3: Related Controls | O3: Criticality | P3: Notes
A4: PROC-001 | B4: Server Backup and Recovery Procedure | C4: System Operations | D4: IT Operations Manager | E4: IT Department | F4: /policies/ops/backup-recovery.pdf | G4: 01.01.2026 | H4: =IF(G4<>"",G4+I4,"") | I4: 365 | J4: v1.2 | K4: Approved | L4: CTO | M4: 15.01.2026 | N4: A.8.13 | O4: Critical | P4: Annual review required
H5: =IF(G5<>"",G5+I5,"") | I5: 365
H6: =IF(G6<>"",G6+I6,"") | I6: 365
H7: =IF(G7<>"",G7+I7,"") | I7: 365
H8: =IF(G8<>"",G8+I8,"") | I8: 365
H9: =IF(G9<>"",G9+I9,"") | I9: 365
H10: =IF(G10<>"",G10+I10,"") | I10: 365
H11: =IF(G11<>"",G11+I11,"") | I11: 365
H12: =IF(G12<>"",G12+I12,"") | I12: 365
H13: =IF(G13<>"",G13+I13,"") | I13: 365
H14: =IF(G14<>"",G14+I14,"") | I14: 365
H15: =IF(G15<>"",G15+I15,"") | I15: 365
H16: =IF(G16<>"",G16+I16,"") | I16: 365
... H54: =IF(G54<>"",G54+I54,"") | I54: 365

Sheet Required Procedures
A1: REQUIRED PROCEDURES
A2: ISO 27001:2022 required procedure reference list — map existing procedures to required ones and record gaps
A3: Reference ID | B3: Required Procedure | C3: ISO Control | D3: Category | E3: Priority | F3: Current Status | G3: Mapped Procedure ID | H3: Gap Notes
A4: REQ-001 | B4: Information Security Incident Response Procedure | C4: A.5.24-28 | D4: Security Operations | E4: High
A5: REQ-002 | B5: Access Control Management Procedure | C5: A.5.15-18 | D5: User Management | E5: High
A6: REQ-003 | B6: Change Management Procedure | C6: A.8.32 | D6: Change Management | E6: High
A7: REQ-004 | B7: Backup and Recovery Procedure | C7: A.8.13 | D7: System Operations | E7: Critical
A8: REQ-005 | B8: Business Continuity Activation Procedure | C8: A.5.29-30 | D8: Recovery Operations | E8: Critical
A9: REQ-006 | B9: User Onboarding/Offboarding Procedure | C9: A.6.1-5 | D9: User Management | E9: High
A10: REQ-007 | B10: Vulnerability Management Procedure | C10: A.8.8 | D10: Security Operations | E10: High
A11: REQ-008 | B11: Logging and Monitoring Procedure | C11: A.8.15-16 | D11: System Operations | E11: High
A12: REQ-009 | B12: Physical Access Control Procedure | C12: A.7.1-4 | D12: Facility Operations | E12: High

Sheet Accessibility Matrix
A1: ACCESSIBILITY MATRIX
A2: Role-based procedure access mapping — verify that all relevant staff can access the procedures they need
A3: Procedure ID | B3: IT Operations | C3: Security Team | D3: Facilities | E3: Help Desk | F3: Management | G3: Access Method | H3: Verified Date
A4: PROC-001 | B4: Yes | C4: Yes | D4: No | E4: Yes | F4: Yes | G4: SharePoint: /IT/Procedures/ | H4: 15.01.2026

Sheet Gap Analysis
A1: GAP ANALYSIS
A2: Track missing, incomplete, outdated or unapproved procedures — assign remediation owners and target dates
A3: Gap ID | B3: Gap Type | C3: Procedure Reference | D3: Severity | E3: Identified Date | F3: Remediation Owner | G3: Target Date | H3: Status | I3: Completion Date | J3: Evidence
A4: GAP-001 | B4: Missing | C4: Patch Management Procedure | D4: High | E4: 01.02.2026 | F4: IT Security Manager | G4: 01.04.2026 | H4: Open | J4: /evidence/gap-001-assessment.pdf

Sheet Evidence Register
A1: EVIDENCE REGISTER
A2: Document all evidence collected during this assessment
A4: Evidence ID | B4: Assessment Area | C4: Evidence Type | D4: Description | E4: Location / Path | F4: Date Collected | G4: Collected By | H4: Verification Status
A5: EV-001 | B5: Procedure Inventory | C5: Policy Document | D5: Example evidence description | E5: \\fileserver\policies\document.pdf | F5: 15.01.2026 | G5: Assessor Name | H5: Verified

Sheet Summary Dashboard
A1: PROCEDURE INVENTORY ASSESSMENT — SUMMARY DASHBOARD
A2: ISO/IEC 27001:2022 — Control A.5.37: Documented Operating Procedures
A4: TABLE 1: ASSESSMENT AREA COMPLIANCE OVERVIEW
A5: Assessment Area | B5: Total Items | C5: Compliant | D5: Partial | E5: Non-Compliant | F5: N/A | G5: Compliance %
A6: Procedure Inventory | B6: =COUNTA('Procedure Inventory'!B5:B54) | C6: =COUNTIF('Procedure Inventory'!K5:K54,"Approved") | D6: =COUNTIF('Procedure Inventory'!K5:K54,"Draft")+COUNTIF('Procedure Inventory'!K5:K54,"Pending Approval")+COUNTIF('Procedure Inventory'!K5:K54,"Under Review") | E6: =COUNTIF('Procedure Inventory'!K5:K54,"Expired") | F6: =0 | G6: =IFERROR(IF((B6-F6)=0,0,C6/(B6-F6)),"")
A7: Required Procedures | B7: =COUNTA('Required Procedures'!B5:B63) | C7: =COUNTIF('Required Procedures'!F5:F63,"Exists") | D7: =COUNTIF('Required Procedures'!F5:F63,"Partial") | E7: =COUNTIF('Required Procedures'!F5:F63,"Missing") | F7: =0 | G7: =IFERROR(IF((B7-F7)=0,0,C7/(B7-F7)),"")
A8: Accessibility Matrix | B8: =COUNTA('Accessibility Matrix'!A5:A54) | C8: =COUNTA('Accessibility Matrix'!G5:G54) | D8: =0 | E8: =B8-C8 | F8: =0 | G8: =IFERROR(IF((B8-F8)=0,0,C8/(B8-F8)),"")
A9: Gap Analysis | B9: =COUNTA('Gap Analysis'!A5:A54) | C9: =COUNTIF('Gap Analysis'!H5:H54,"Closed") | D9: =COUNTIF('Gap Analysis'!H5:H54,"In Progress") | E9: =COUNTIF('Gap Analysis'!H5:H54,"Open") | F9: =0 | G9: =IFERROR(IF((B9-F9)=0,0,C9/(B9-F9)),"")
A10: TOTAL | B10: =SUM(B6:B9) | C10: =SUM(C6:C9) | D10: =SUM(D6:D9) | E10: =SUM(E6:E9) | F10: =SUM(F6:F9) | G10: =IFERROR(IF((B10-F10)=0,0,C10/(B10-F10)),"")
A12: TABLE 2: KEY METRICS
A13: Metric | B13: Value
A14: Total Procedures Inventoried | B14: =COUNTA('Procedure Inventory'!B5:B54)
A15: Approved Procedures | B15: =COUNTIF('Procedure Inventory'!K5:K54,"Approved")
A16: Expired Procedures (Require Renewal) | B16: =COUNTIF('Procedure Inventory'!K5:K54,"Expired")
A17: Critical Procedures | B17: =COUNTIF('Procedure Inventory'!O5:O54,"Critical")
A18: High Criticality Procedures | B18: =COUNTIF('Procedure Inventory'!O5:O54,"High")
A19: Security Operations Procedures | B19: =COUNTIF('Procedure Inventory'!C5:C54,"Security Operations")
A20: System Operations Procedures | B20: =COUNTIF('Procedure Inventory'!C5:C54,"System Operations")
A21: Recovery Operations Procedures | B21: =COUNTIF('Procedure Inventory'!C5:C54,"Recovery Operations")
A22: Required Procedures Identified | B22: =COUNTA('Required Procedures'!B5:B63)
A23: Procedures Fully Existing | B23: =COUNTIF('Required Procedures'!F5:F63,"Exists")
A24: Procedures Partially Covered | B24: =COUNTIF('Required Procedures'!F5:F63,"Partial")
A25: Procedures Missing | B25: =COUNTIF('Required Procedures'!F5:F63,"Missing")
A26: Critical Priority Requirements | B26: =COUNTIF('Required Procedures'!E5:E63,"Critical")
A27: Total Gap Items Identified | B27: =COUNTA('Gap Analysis'!A5:A54)
A28: Critical Severity Gaps | B28: =COUNTIF('Gap Analysis'!D5:D54,"Critical")
A29: High Severity Gaps | B29: =COUNTIF('Gap Analysis'!D5:D54,"High")
A30: Open Gaps (Unresolved) | B30: =COUNTIF('Gap Analysis'!H5:H54,"Open")
A31: Missing Procedures (Gap Type) | B31: =COUNTIF('Gap Analysis'!B5:B54,"Missing")
A32: Outdated Procedures | B32: =COUNTIF('Gap Analysis'!B5:B54,"Outdated")
A33: Procedures with Verified Access | B33: =COUNTA('Accessibility Matrix'!H5:H54)
A37: TABLE 3: CRITICAL FINDINGS REQUIRING IMMEDIATE ATTENTION
A38: Category | B38: Finding | C38: Count | D38: Severity | E38: Action Required
A39: Required Procedures | B39: Missing required ISO procedures | C39: =COUNTIF('Required Procedures'!F5:F63,"Missing") | D39: Critical | E39: Immediate
A40: Required Procedures | B40: Critical priority procedures missing | C40: =COUNTIFS('Required Procedures'!E5:E63,"Critical",'Required Procedures'!F5:F63,"Missing") | D40: Critical | E40: Immediate
A41: Procedure Inventory | B41: Expired procedures not renewed | C41: =COUNTIF('Procedure Inventory'!K5:K54,"Expired") | D41: Critical | E41: Immediate
A42: Procedure Inventory | B42: Critical procedures not yet approved (Draft) | C42: =COUNTIFS('Procedure Inventory'!O5:O54,"Critical",'Procedure Inventory'!K5:K54,"Draft") | D42: Critical | E42: Immediate
A43: Gap Analysis | B43: Open critical severity gaps | C43: =COUNTIFS('Gap Analysis'!D5:D54,"Critical",'Gap Analysis'!H5:H54,"Open") | D43: Critical | E43: Immediate
A44: Gap Analysis | B44: Open high severity gaps | C44: =COUNTIFS('Gap Analysis'!D5:D54,"High",'Gap Analysis'!H5:H54,"Open") | D44: High | E44: Urgent
A45: Gap Analysis | B45: Missing procedure gaps (no procedure exists) | C45: =COUNTIF('Gap Analysis'!B5:B54,"Missing") | D45: High | E45: Urgent
...

Sheet Approval Sign-Off
A1: ASSESSMENT APPROVAL AND SIGN-OFF
A2: ISO/IEC 27001:2022 - Control A.5.37: Documented Operating Procedures
A3: ASSESSMENT SUMMARY
A4: Document: | B4: ISMS-IMP-A.5.37.1 - Procedure Inventory Assessment
A5: Assessment Period:
A6: Overall Compliance Rating: | B6: =IFERROR(AVERAGE('Summary Dashboard'!G6:G9),"")
A7: Assessment Status:
A8: Assessed By:
A11: COMPLETED BY (ASSESSOR)
A12: Name:
A13: Title:
A14: Date:
A15: Signature:
A16: Comments:
A18: REVIEWED BY (IT SECURITY MANAGER)
A19: Name:
A20: Title:
A21: Date:
... A36: Review Owner:
