Workbook

Sheet Instructions & Legend
A1: ISMS-IMP-A.5.37.2 - Procedure Quality Assessment ISO/IEC 27001:2022 - Control A.5.37: Documented Operating Procedures
A3: Document Information
A4: Document ID | B4: ISMS-IMP-A.5.37.2
A5: Workbook Title | B5: Procedure Quality Assessment
A6: Control Reference | B6: ISO/IEC 27001:2022 - Control A.5.37: Documented Operating Procedures
A7: Version | B7: 1.0
A8: Assessment Date
A9: Completed By
A10: Organisation
A12: Instructions
A13: 1. Review this Instructions & Legend sheet before starting the assessment.
A14: 2. Complete all yellow (FFFFCC) input cells with your assessment data.
A15: 3. Grey (F2F2F2) rows are sample rows — do not edit them.
A16: 4. Complete the Evidence Register with supporting documentation references.
A17: 5. Obtain sign-off in the Approval Sign-Off sheet when the assessment is complete.
A19: Status Legend
A20: Symbol | B20: Status | C20: Description
A21: ✓ | B21: Compliant / Complete | C21: Requirement fully met
A22: ⚠ | B22: Partial / In Progress | C22: Partially met or in progress
A23: ✗ | B23: Non-Compliant / Not Started | C23: Requirement not met
A24: — | B24: Not Applicable | C24: Not applicable to this assessment

Sheet Quality Assessment
A1: QUALITY ASSESSMENT
A2: Score each procedure 0-5 on five quality dimensions — overall score and rating are auto-calculated
A3: Procedure ID | B3: Procedure Name | C3: Assessment Date | D3: Assessor | E3: Clarity Score | F3: Completeness Score | G3: Accuracy Score | H3: Usability Score | I3: Maintainability Score | J3: Overall Score | K3: Quality Rating | L3: Priority Improvements | M3: Findings | N3: Next Review
A4: PROC-001 | B4: Server Backup and Recovery Procedure | C4: 01.02.2026 | D4: IT Assessor | E4: 4 | F4: 5 | G4: 4 | H4: 3 | I4: 4 | J4: =IF(E4<>"",ROUND((E4*0.2)+(F4*0.2)+(G4*0.2)+(H4*0.2)+(I4*0.2),2),"") | K4: =IF(J4="","",IF(J4>=4.5,"Excellent",IF(J4>=3.5,"Good",IF(J4>=2.5,"Adequate",IF(J4>=1.5,"Needs Improvement","Poor"))))) | N4: =IF(K4="Excellent",C4+365,IF(K4="Good",C4+180,IF(K4="Adequate",C4+90,IF(K4<>"",C4+30,""))))
J5: =IF(E5<>"",ROUND((E5*0.2)+(F5*0.2)+(G5*0.2)+(H5*0.2)+(I5*0.2),2),"") | K5: =IF(J5="","",IF(J5>=4.5,"Excellent",IF(J5>=3.5,"Good",IF(J5>=2.5,"Adequate",IF(J5>=1.5,"Needs Improvement","Poor"))))) | N5: =IF(K5="Excellent",C5+365,IF(K5="Good",C5+180,IF(K5="Adequate",C5+90,IF(K5<>"",C5+30,""))))
J6: =IF(E6<>"",ROUND((E6*0.2)+(F6*0.2)+(G6*0.2)+(H6*0.2)+(I6*0.2),2),"") | K6: =IF(J6="","",IF(J6>=4.5,"Excellent",IF(J6>=3.5,"Good",IF(J6>=2.5,"Adequate",IF(J6>=1.5,"Needs Improvement","Poor"))))) | N6: =IF(K6="Excellent",C6+365,IF(K6="Good",C6+180,IF(K6="Adequate",C6+90,IF(K6<>"",C6+30,""))))
J7: =IF(E7<>"",ROUND((E7*0.2)+(F7*0.2)+(G7*0.2)+(H7*0.2)+(I7*0.2),2),"") | K7: =IF(J7="","",IF(J7>=4.5,"Excellent",IF(J7>=3.5,"Good",IF(J7>=2.5,"Adequate",IF(J7>=1.5,"Needs Improvement","Poor"))))) | N7: =IF(K7="Excellent",C7+365,IF(K7="Good",C7+180,IF(K7="Adequate",C7+90,IF(K7<>"",C7+30,""))))
J8: =IF(E8<>"",ROUND((E8*0.2)+(F8*0.2)+(G8*0.2)+(H8*0.2)+(I8*0.2),2),"") | K8: =IF(J8="","",IF(J8>=4.5,"Excellent",IF(J8>=3.5,"Good",IF(J8>=2.5,"Adequate",IF(J8>=1.5,"Needs Improvement","Poor"))))) | N8: =IF(K8="Excellent",C8+365,IF(K8="Good",C8+180,IF(K8="Adequate",C8+90,IF(K8<>"",C8+30,""))))
J9: =IF(E9<>"",ROUND((E9*0.2)+(F9*0.2)+(G9*0.2)+(H9*0.2)+(I9*0.2),2),"") | K9: =IF(J9="","",IF(J9>=4.5,"Excellent",IF(J9>=3.5,"Good",IF(J9>=2.5,"Adequate",IF(J9>=1.5,"Needs Improvement","Poor"))))) | N9: =IF(K9="Excellent",C9+365,IF(K9="Good",C9+180,IF(K9="Adequate",C9+90,IF(K9<>"",C9+30,""))))
J10: =IF(E10<>"",ROUND((E10*0.2)+(F10*0.2)+(G10*0.2)+(H10*0.2)+(I10*0.2),2),"") | K10: =IF(J10="","",IF(J10>=4.5,"Excellent",IF(J10>=3.5,"Good",IF(J10>=2.5,"Adequate",IF(J10>=1.5,"Needs Improvement","Poor"))))) | N10: =IF(K10="Excellent",C10+365,IF(K10="Good",C10+180,IF(K10="Adequate",C10+90,IF(K10<>"",C10+30,""))))
J11: =IF(E11<>"",ROUND((E11*0.2)+(F11*0.2)+(G11*0.2)+(H11*0.2)+(I11*0.2),2),"") | K11: =IF(J11="","",IF(J11>=4.5,"Excellent",IF(J11>=3.5,"Good",IF(J11>=2.5,"Adequate",IF(J11>=1.5,"Needs Improvement","Poor"))))) | N11: =IF(K11="Excellent",C11+365,IF(K11="Good",C11+180,IF(K11="Adequate",C11+90,IF(K11<>"",C11+30,""))))
J12: =IF(E12<>"",ROUND((E12*0.2)+(F12*0.2)+(G12*0.2)+(H12*0.2)+(I12*0.2),2),"") | K12: =IF(J12="","",IF(J12>=4.5,"Excellent",IF(J12>=3.5,"Good",IF(J12>=2.5,"Adequate",IF(J12>=1.5,"Needs Improvement","Poor"))))) | N12: =IF(K12="Excellent",C12+365,IF(K12="Good",C12+180,IF(K12="Adequate",C12+90,IF(K12<>"",C12+30,""))))
J13: =IF(E13<>"",ROUND((E13*0.2)+(F13*0.2)+(G13*0.2)+(H13*0.2)+(I13*0.2),2),"") | K13: =IF(J13="","",IF(J13>=4.5,"Excellent",IF(J13>=3.5,"Good",IF(J13>=2.5,"Adequate",IF(J13>=1.5,"Needs Improvement","Poor"))))) | N13: =IF(K13="Excellent",C13+365,IF(K13="Good",C13+180,IF(K13="Adequate",C13+90,IF(K13<>"",C13+30,""))))
J14: =IF(E14<>"",ROUND((E14*0.2)+(F14*0.2)+(G14*0.2)+(H14*0.2)+(I14*0.2),2),"") | K14: =IF(J14="","",IF(J14>=4.5,"Excellent",IF(J14>=3.5,"Good",IF(J14>=2.5,"Adequate",IF(J14>=1.5,"Needs Improvement","Poor"))))) | N14: =IF(K14="Excellent",C14+365,IF(K14="Good",C14+180,IF(K14="Adequate",C14+90,IF(K14<>"",C14+30,""))))
J15: =IF(E15<>"",ROUND((E15*0.2)+(F15*0.2)+(G15*0.2)+(H15*0.2)+(I15*0.2),2),"") | K15: =IF(J15="","",IF(J15>=4.5,"Excellent",IF(J15>=3.5,"Good",IF(J15>=2.5,"Adequate",IF(J15>=1.5,"Needs Improvement","Poor"))))) | N15: =IF(K15="Excellent",C15+365,IF(K15="Good",C15+180,IF(K15="Adequate",C15+90,IF(K15<>"",C15+30,""))))
J16: =IF(E16<>"",ROUND((E16*0.2)+(F16*0.2)+(G16*0.2)+(H16*0.2)+(I16*0.2),2),"") | K16: =IF(J16="","",IF(J16>=4.5,"Excellent",IF(J16>=3.5,"Good",IF(J16>=2.5,"Adequate",IF(J16>=1.5,"Needs Improvement","Poor"))))) | N16: =IF(K16="Excellent",C16+365,IF(K16="Good",C16+180,IF(K16="Adequate",C16+90,IF(K16<>"",C16+30,""))))
... J54: =IF(E54<>"",ROUND((E54*0.2)+(F54*0.2)+(G54*0.2)+(H54*0.2)+(I54*0.2),2),"") | K54: =IF(J54="","",IF(J54>=4.5,"Excellent",IF(J54>=3.5,"Good",IF(J54>=2.5,"Adequate",IF(J54>=1.5,"Needs Improvement","Poor"))))) | N54: =IF(K54="Excellent",C54+365,IF(K54="Good",C54+180,IF(K54="Adequate",C54+90,IF(K54<>"",C54+30,""))))

Sheet Quality Checklist
A1: QUALITY CHECKLIST
A2: Systematic checklist for procedure quality — assess each item against a specific procedure and record findings
A3: Procedure ID | B3: Check Category | C3: Check Item | D3: Status | E3: Finding | F3: Recommendation
B4: Document Structure | C4: Document ID and title present
B5: Document Structure | C5: Version control information
B6: Document Structure | C6: Owner and approver identified
B7: Document Structure | C7: Last review date documented
B8: Document Structure | C8: Scope clearly defined
B9: Document Structure | C9: Prerequisites listed
B10: Document Structure | C10: Related documents referenced
B11: Content Quality | C11: Purpose statement clear
B12: Content Quality | C12: Step-by-step instructions
B13: Content Quality | C13: Decision trees/flowcharts where needed
B14: Content Quality | C14: Screenshots/diagrams included
B15: Content Quality | C15: Error handling documented
... B26: Operational Elements | C26: Resource requirements listed

Sheet Improvement Actions
A1: IMPROVEMENT ACTIONS
A2: Track improvement actions identified during quality assessments — assign owners, priorities and target dates
A3: Action ID | B3: Procedure ID | C3: Dimension | D3: Issue Description | E3: Action Required | F3: Owner | G3: Priority | H3: Target Date | I3: Status | J3: Completion Date | K3: Verification
A4: ACT-001 | B4: PROC-001 | C4: Completeness | D4: Rollback procedure not documented | E4: Add rollback steps to section 4 | F4: IT Operations Manager | G4: High | H4: 01.03.2026 | I4: Open

Sheet Trend Analysis
A1: TREND ANALYSIS
A2: Track quality score trends over time — record period averages to identify improvement or decline patterns
A3: Period | B3: Procedures Assessed | C3: Avg Clarity | D3: Avg Completeness | E3: Avg Accuracy | F3: Avg Usability | G3: Avg Maintainability | H3: Overall Avg | I3: Excellent Count | J3: Poor Count | K3: Improvement %
A4: Q1 2026 | B4: 15 | C4: 3.8 | D4: 4.1 | E4: 3.9 | F4: 3.5 | G4: 3.7 | H4: 3.8 | I4: 4 | J4: 1 | K4: 12%

Sheet Evidence Register
A1: EVIDENCE REGISTER
A2: Document all evidence collected during this assessment
A4: Evidence ID | B4: Assessment Area | C4: Evidence Type | D4: Description | E4: Location / Path | F4: Date Collected | G4: Collected By | H4: Verification Status
A5: EV-001 | B5: Quality Assessment | C5: Policy Document | D5: Example evidence description | E5: \\fileserver\policies\document.pdf | F5: 15.01.2026 | G5: Assessor Name | H5: Verified

Sheet Summary Dashboard
A1: PROCEDURE QUALITY ASSESSMENT — SUMMARY DASHBOARD
A2: ISO/IEC 27001:2022 — Control A.5.37: Documented Operating Procedures
A4: TABLE 1: ASSESSMENT AREA COMPLIANCE OVERVIEW
A5: Assessment Area | B5: Total Items | C5: Compliant | D5: Partial | E5: Non-Compliant | F5: N/A | G5: Compliance %
A6: Quality Assessment | B6: =COUNTA('Quality Assessment'!B5:B54) | C6: =COUNTIF('Quality Assessment'!K5:K54,"Excellent")+COUNTIF('Quality Assessment'!K5:K54,"Good") | D6: =COUNTIF('Quality Assessment'!K5:K54,"Adequate")+COUNTIF('Quality Assessment'!K5:K54,"Needs Improvement") | E6: =COUNTIF('Quality Assessment'!K5:K54,"Poor") | F6: =0 | G6: =IFERROR(IF((B6-F6)=0,0,C6/(B6-F6)),"")
A7: Quality Checklist | B7: =COUNTA('Quality Checklist'!C5:C76) | C7: =COUNTIF('Quality Checklist'!D5:D76,"Pass") | D7: =COUNTIF('Quality Checklist'!D5:D76,"Partial") | E7: =COUNTIF('Quality Checklist'!D5:D76,"Fail") | F7: =COUNTIF('Quality Checklist'!D5:D76,"N/A") | G7: =IFERROR(IF((B7-F7)=0,0,C7/(B7-F7)),"")
A8: Improvement Actions | B8: =COUNTA('Improvement Actions'!B5:B54) | C8: =COUNTIF('Improvement Actions'!I5:I54,"Completed") | D8: =COUNTIF('Improvement Actions'!I5:I54,"In Progress") | E8: =COUNTIF('Improvement Actions'!I5:I54,"Open") | F8: =COUNTIF('Improvement Actions'!I5:I54,"Cancelled") | G8: =IFERROR(IF((B8-F8)=0,0,C8/(B8-F8)),"")
A9: Trend Analysis | B9: =COUNTA('Trend Analysis'!A5:A24) | C9: =0 | D9: =0 | E9: =0 | F9: =0 | G9: =IFERROR(IF((B9-F9)=0,0,C9/(B9-F9)),"")
A10: TOTAL | B10: =SUM(B6:B9) | C10: =SUM(C6:C9) | D10: =SUM(D6:D9) | E10: =SUM(E6:E9) | F10: =SUM(F6:F9) | G10: =IFERROR(IF((B10-F10)=0,0,C10/(B10-F10)),"")
A12: TABLE 2: KEY METRICS
A13: Metric | B13: Value
A14: Total Procedures Assessed | B14: =COUNTA('Quality Assessment'!B5:B54)
A15: Excellent Quality Procedures | B15: =COUNTIF('Quality Assessment'!K5:K54,"Excellent")
A16: Good Quality Procedures | B16: =COUNTIF('Quality Assessment'!K5:K54,"Good")
A17: Adequate Quality Procedures | B17: =COUNTIF('Quality Assessment'!K5:K54,"Adequate")
A18: Needs Improvement Procedures | B18: =COUNTIF('Quality Assessment'!K5:K54,"Needs Improvement")
A19: Poor Quality Procedures (Immediate Rework) | B19: =COUNTIF('Quality Assessment'!K5:K54,"Poor")
A20: Average Clarity Score (0-5) | B20: =IFERROR(ROUND(AVERAGE('Quality Assessment'!E5:E54),2),"")
A21: Average Completeness Score (0-5) | B21: =IFERROR(ROUND(AVERAGE('Quality Assessment'!F5:F54),2),"")
A22: Average Accuracy Score (0-5) | B22: =IFERROR(ROUND(AVERAGE('Quality Assessment'!G5:G54),2),"")
A23: Average Usability Score (0-5) | B23: =IFERROR(ROUND(AVERAGE('Quality Assessment'!H5:H54),2),"")
A24: Average Maintainability Score (0-5) | B24: =IFERROR(ROUND(AVERAGE('Quality Assessment'!I5:I54),2),"")
A25: Total Improvement Actions | B25: =COUNTA('Improvement Actions'!B5:B54)
A26: Critical Priority Actions | B26: =COUNTIF('Improvement Actions'!G5:G54,"Critical")
A27: High Priority Actions | B27: =COUNTIF('Improvement Actions'!G5:G54,"High")
A28: Open Improvement Actions | B28: =COUNTIF('Improvement Actions'!I5:I54,"Open")
A29: Completed Improvement Actions | B29: =COUNTIF('Improvement Actions'!I5:I54,"Completed")
A30: Clarity Improvement Actions | B30: =COUNTIF('Improvement Actions'!C5:C54,"Clarity")
A31: Completeness Improvement Actions | B31: =COUNTIF('Improvement Actions'!C5:C54,"Completeness")
A32: Total Checklist Items | B32: =COUNTA('Quality Checklist'!C5:C76)
A33: Checklist Items Passed | B33: =COUNTIF('Quality Checklist'!D5:D76,"Pass")
A34: Checklist Items Failed | B34: =COUNTIF('Quality Checklist'!D5:D76,"Fail")
A35: Checklist Items N/A | B35: =COUNTIF('Quality Checklist'!D5:D76,"N/A")
A39: TABLE 3: CRITICAL FINDINGS REQUIRING IMMEDIATE ATTENTION
A40: Category | B40: Finding | C40: Count | D40: Severity | E40: Action Required
A41: Quality Assessment | B41: Poor quality procedures requiring immediate rework | C41: =COUNTIF('Quality Assessment'!K5:K54,"Poor") | D41: Critical | E41: Immediate
A42: Improvement Actions | B42: Critical priority improvement actions open | C42: =COUNTIFS('Improvement Actions'!G5:G54,"Critical",'Improvement Actions'!I5:I54,"Open") | D42: Critical | E42: Immediate
A43: Improvement Actions | B43: High priority open improvement actions | C43: =COUNTIFS('Improvement Actions'!G5:G54,"High",'Improvement Actions'!I5:I54,"Open") | D43: High | E43: Urgent
A44: Quality Checklist | B44: Failed checklist items (non-compliant elements) | C44: =COUNTIF('Quality Checklist'!D5:D76,"Fail") | D44: High | E44: Urgent
A45: Quality Assessment | B45: Procedures rated Needs Improvement | C45: =COUNTIF('Quality Assessment'!K5:K54,"Needs Improvement") | D45: Medium | E45: Plan
...

Sheet Approval Sign-Off
A1: ASSESSMENT APPROVAL AND SIGN-OFF
A2: ISO/IEC 27001:2022 - Control A.5.37: Documented Operating Procedures
A3: ASSESSMENT SUMMARY
A4: Document: | B4: ISMS-IMP-A.5.37.2 - Procedure Quality Assessment
A5: Assessment Period:
A6: Overall Compliance Rating: | B6: =IFERROR(AVERAGE('Summary Dashboard'!G6:G9),"")
A7: Assessment Status:
A8: Assessed By:
A11: COMPLETED BY (ASSESSOR)
A12: Name:
A13: Title:
A14: Date:
A15: Signature:
A16: Comments:
A18: REVIEWED BY (IT SECURITY MANAGER)
A19: Name:
A20: Title:
A21: Date:
... A36: Review Owner:
