Workbook

Sheet Executive Summary
A1: ISMS-OP-CHK-A.8.17 — Clock Synchronisation Compliance Checklist
A3: DOCUMENT INFORMATION
A4: Document ID | B4: ISMS-OP-CHK-A.8.17
A5: Source Policy | B5: ISMS-OP-POL-A.8.17
A6: ISO Controls | B6: Clock Synchronisation
A7: Generated | B7: 08.02.2026
A8: Prepared By
A9: Organisation
A10: Review Cycle | B10: Annual
A12: OVERALL COMPLIANCE STATUS
A13: Overall Compliance | B13: ='Dashboard'!G11
A14: Status | B14: =IF(Dashboard!G11="N/A","NOT ASSESSED",IF(ISNUMBER(VALUE(SUBSTITUTE(Dashboard!G11,"%",""))),IF(VALUE(SUBSTITUTE(Dashboard!G11,"%",""))>=90,"GREEN",IF(VALUE(SUBSTITUTE(Dashboard!G11,"%",""))>=70,"AMBER","RED")),"NOT ASSESSED"))
A16: KEY METRICS
A17: Total Requirements | B17: ='Dashboard'!B11
A18: Compliant | B18: ='Dashboard'!C11
A19: Partial | B19: ='Dashboard'!D11
A20: Non-Compliant | B20: ='Dashboard'!E11
A21: Not Applicable | B21: ='Dashboard'!F11
A22: Owner Coverage | B22: =IF(Dashboard!B11=0,"N/A",ROUND((COUNTA('Authoritative Time Sources'!F4:F6)+COUNTA('Synchronisation Protocol'!F4:F6)+COUNTA('Timestamp Format'!F4:F7)+COUNTA('Clock Drift Tolerances'!F4:F7)+COUNTA('Cloud Service Time'!F4:F4)+COUNTA('Leap Second Handling'!F4:F4)+COUNTA('NTP Security'!F4:F7))/Dashboard!B11*100,0)&"%")
A24: DOMAIN STATUS SUMMARY
A25: Domain | B25: Compliance % | C25: Compliant | D25: Gaps | E25: Status
A26: Authoritative Time Sources | B26: ='Dashboard'!G4 | C26: ='Dashboard'!C4 | D26: ='Dashboard'!E4 | E26: =IF(Dashboard!G4="N/A","--",IF(ISNUMBER(VALUE(SUBSTITUTE(Dashboard!G4,"%",""))),IF(VALUE(SUBSTITUTE(Dashboard!G4,"%",""))>=90,"PASS",IF(VALUE(SUBSTITUTE(Dashboard!G4,"%",""))>=70,"REVIEW","FAIL")),"--"))
A27: Synchronisation Protocol | B27: ='Dashboard'!G5 | C27: ='Dashboard'!C5 | D27: ='Dashboard'!E5 | E27: =IF(Dashboard!G5="N/A","--",IF(ISNUMBER(VALUE(SUBSTITUTE(Dashboard!G5,"%",""))),IF(VALUE(SUBSTITUTE(Dashboard!G5,"%",""))>=90,"PASS",IF(VALUE(SUBSTITUTE(Dashboard!G5,"%",""))>=70,"REVIEW","FAIL")),"--"))
A28: Timestamp Format | B28: ='Dashboard'!G6 | C28: ='Dashboard'!C6 | D28: ='Dashboard'!E6 | E28: =IF(Dashboard!G6="N/A","--",IF(ISNUMBER(VALUE(SUBSTITUTE(Dashboard!G6,"%",""))),IF(VALUE(SUBSTITUTE(Dashboard!G6,"%",""))>=90,"PASS",IF(VALUE(SUBSTITUTE(Dashboard!G6,"%",""))>=70,"REVIEW","FAIL")),"--"))
A29: Clock Drift Tolerances | B29: ='Dashboard'!G7 | C29: ='Dashboard'!C7 | D29: ='Dashboard'!E7 | E29: =IF(Dashboard!G7="N/A","--",IF(ISNUMBER(VALUE(SUBSTITUTE(Dashboard!G7,"%",""))),IF(VALUE(SUBSTITUTE(Dashboard!G7,"%",""))>=90,"PASS",IF(VALUE(SUBSTITUTE(Dashboard!G7,"%",""))>=70,"REVIEW","FAIL")),"--"))
A30: Cloud Service Time | B30: ='Dashboard'!G8 | C30: ='Dashboard'!C8 | D30: ='Dashboard'!E8 | E30: =IF(Dashboard!G8="N/A","--",IF(ISNUMBER(VALUE(SUBSTITUTE(Dashboard!G8,"%",""))),IF(VALUE(SUBSTITUTE(Dashboard!G8,"%",""))>=90,"PASS",IF(VALUE(SUBSTITUTE(Dashboard!G8,"%",""))>=70,"REVIEW","FAIL")),"--"))
A31: Leap Second Handling | B31: ='Dashboard'!G9 | C31: ='Dashboard'!C9 | D31: ='Dashboard'!E9 | E31: =IF(Dashboard!G9="N/A","--",IF(ISNUMBER(VALUE(SUBSTITUTE(Dashboard!G9,"%",""))),IF(VALUE(SUBSTITUTE(Dashboard!G9,"%",""))>=90,"PASS",IF(VALUE(SUBSTITUTE(Dashboard!G9,"%",""))>=70,"REVIEW","FAIL")),"--"))
A32: NTP Security | B32: ='Dashboard'!G10 | C32: ='Dashboard'!C10 | D32: ='Dashboard'!E10 | E32: =IF(Dashboard!G10="N/A","--",IF(ISNUMBER(VALUE(SUBSTITUTE(Dashboard!G10,"%",""))),IF(VALUE(SUBSTITUTE(Dashboard!G10,"%",""))>=90,"PASS",IF(VALUE(SUBSTITUTE(Dashboard!G10,"%",""))>=70,"REVIEW","FAIL")),"--"))
A34: CRITICAL ISSUES
A35: # | B35: Issue Description | C35: Domain | D35: Owner | E35: Due Date
A36: 1
A37: 2
A38: 3
A39: 4
A40: 5
A42: MANAGEMENT COMMENTARY
A43: [Enter management commentary on clock synchronisation posture]
A47: APPROVAL
A48: Assessed By
A49: Name:
...

Sheet Dashboard
A1: Clock Synchronisation — Compliance Dashboard
A3: Domain | B3: Total Reqs | C3: Compliant | D3: Partial | E3: Non-Compliant | F3: N/A | G3: Compliance %
A4: Authoritative Time Sources | B4: =COUNTA('Authoritative Time Sources'!D4:D6) | C4: =COUNTIF('Authoritative Time Sources'!D4:D6,"Compliant") | D4: =COUNTIF('Authoritative Time Sources'!D4:D6,"Partial") | E4: =COUNTIF('Authoritative Time Sources'!D4:D6,"Non-Compliant") | F4: =COUNTIF('Authoritative Time Sources'!D4:D6,"N/A") | G4: =IF((B4-F4)=0,"N/A",ROUND(C4/(B4-F4)*100,1)&"%")
A5: Synchronisation Protocol | B5: =COUNTA('Synchronisation Protocol'!D4:D6) | C5: =COUNTIF('Synchronisation Protocol'!D4:D6,"Compliant") | D5: =COUNTIF('Synchronisation Protocol'!D4:D6,"Partial") | E5: =COUNTIF('Synchronisation Protocol'!D4:D6,"Non-Compliant") | F5: =COUNTIF('Synchronisation Protocol'!D4:D6,"N/A") | G5: =IF((B5-F5)=0,"N/A",ROUND(C5/(B5-F5)*100,1)&"%")
A6: Timestamp Format | B6: =COUNTA('Timestamp Format'!D4:D7) | C6: =COUNTIF('Timestamp Format'!D4:D7,"Compliant") | D6: =COUNTIF('Timestamp Format'!D4:D7,"Partial") | E6: =COUNTIF('Timestamp Format'!D4:D7,"Non-Compliant") | F6: =COUNTIF('Timestamp Format'!D4:D7,"N/A") | G6: =IF((B6-F6)=0,"N/A",ROUND(C6/(B6-F6)*100,1)&"%")
A7: Clock Drift Tolerances | B7: =COUNTA('Clock Drift Tolerances'!D4:D7) | C7: =COUNTIF('Clock Drift Tolerances'!D4:D7,"Compliant") | D7: =COUNTIF('Clock Drift Tolerances'!D4:D7,"Partial") | E7: =COUNTIF('Clock Drift Tolerances'!D4:D7,"Non-Compliant") | F7: =COUNTIF('Clock Drift Tolerances'!D4:D7,"N/A") | G7: =IF((B7-F7)=0,"N/A",ROUND(C7/(B7-F7)*100,1)&"%")
A8: Cloud Service Time | B8: =COUNTA('Cloud Service Time'!D4:D4) | C8: =COUNTIF('Cloud Service Time'!D4:D4,"Compliant") | D8: =COUNTIF('Cloud Service Time'!D4:D4,"Partial") | E8: =COUNTIF('Cloud Service Time'!D4:D4,"Non-Compliant") | F8: =COUNTIF('Cloud Service Time'!D4:D4,"N/A") | G8: =IF((B8-F8)=0,"N/A",ROUND(C8/(B8-F8)*100,1)&"%")
A9: Leap Second Handling | B9: =COUNTA('Leap Second Handling'!D4:D4) | C9: =COUNTIF('Leap Second Handling'!D4:D4,"Compliant") | D9: =COUNTIF('Leap Second Handling'!D4:D4,"Partial") | E9: =COUNTIF('Leap Second Handling'!D4:D4,"Non-Compliant") | F9: =COUNTIF('Leap Second Handling'!D4:D4,"N/A") | G9: =IF((B9-F9)=0,"N/A",ROUND(C9/(B9-F9)*100,1)&"%")
A10: NTP Security | B10: =COUNTA('NTP Security'!D4:D7) | C10: =COUNTIF('NTP Security'!D4:D7,"Compliant") | D10: =COUNTIF('NTP Security'!D4:D7,"Partial") | E10: =COUNTIF('NTP Security'!D4:D7,"Non-Compliant") | F10: =COUNTIF('NTP Security'!D4:D7,"N/A") | G10: =IF((B10-F10)=0,"N/A",ROUND(C10/(B10-F10)*100,1)&"%")
A11: TOTAL | B11: =SUM(B4:B10) | C11: =SUM(C4:C10) | D11: =SUM(D4:D10) | E11: =SUM(E4:E10) | F11: =SUM(F4:F10) | G11: =IF((B11-F11)=0,"N/A",ROUND(C11/(B11-F11)*100,1)&"%")
A13: COMPLIANCE BY STATUS
A14: Compliant | B14: =C11 | C14: =IF(B11=0,"",ROUND(B14/B11*100,1)&"%")
A15: Partial | B15: =D11 | C15: =IF(B11=0,"",ROUND(B15/B11*100,1)&"%")
A16: Non-Compliant | B16: =E11 | C16: =IF(B11=0,"",ROUND(B16/B11*100,1)&"%")
A17: N/A | B17: =F11 | C17: =IF(B11=0,"",ROUND(B17/B11*100,1)&"%")
A19: TOP GAPS (Manual Entry)
A20: Priority | B20: Domain | C20: Requirement | D20: Owner | E20: Due Date | F20: Status
A32: COMPLIANCE TREND (Manual Entry)
A33: Assessment Date | B33: Overall % | C33: Compliant | D33: Gaps | E33: Assessor | F33: Notes

Sheet Authoritative Time Sources
A1: Authoritative Time Sources — Compliance Checklist
A2: ISO/IEC 27001:2022 — Control A.8.17: Clock Synchronisation
A3: Req # | B3: Section | C3: Requirement | D3: Status | E3: Evidence | F3: Owner | G3: Due Date | H3: Notes
A4: A.8.17-01 | B4: Designate A Primary Authoritative Time | C4: The organisation shall designate a primary authoritative time source:.
A5: A.8.17-02 | B5: Deploy Internal Ntp Servers In A | C5: The organisation shall deploy internal NTP servers in a tiered architecture:.
A6: A.8.17-03 | B6: Air-Gapped Networks), These | C6: Where the organisation operates GPS-disciplined oscillators (GPSDOs) for Stratum 0/1 independence (e.g., air-gapped networks), these shall be documented and maintained per manufacturer specifications.

Sheet Synchronisation Protocol
A1: Synchronisation Protocol — Compliance Checklist
A2: ISO/IEC 27001:2022 — Control A.8.17: Clock Synchronisation
A3: Req # | B3: Section | C3: Requirement | D3: Status | E3: Evidence | F3: Owner | G3: Due Date | H3: Notes
A4: A.8.17-04 | B4: Network Time Protocol (Ntp) | C4: Network Time Protocol (NTP) shall be used for time synchronisation across all standard enterprise systems.
A5: A.8.17-05 | B5: Financial Trading, Industrial Control, | C5: Where sub-microsecond accuracy is required (e.g., financial trading, industrial control, high-frequency data processing), IEEE 1588 Precision Time Protocol (PTPv2) shall be deployed:.
A6: A.8.17-06 | B6: A Ptp Grandmaster Clock | C6: A PTP grandmaster clock (GPS-disciplined) shall be deployed.

Sheet Timestamp Format
A1: Timestamp Format — Compliance Checklist
A2: ISO/IEC 27001:2022 — Control A.8.17: Clock Synchronisation
A3: Req # | B3: Section | C3: Requirement | D3: Status | E3: Evidence | F3: Owner | G3: Due Date | H3: Notes
A4: A.8.17-07 | B4: Record Timestamps In One Of The | C4: All systems shall record timestamps in one of the following formats:.
A5: A.8.17-08 | B5: Iso 8601 / Rfc 3339 Format | C5: ISO 8601 / RFC 3339 format shall be used for all machine-generated timestamps.
A6: A.8.17-09 | B6: Named Timezone Abbreviations | C6: Named timezone abbreviations shall not be used in log timestamps.
A7: A.8.17-10 | B7: Use Utc Or Explicit Offset To | C7: All systems shall use UTC or explicit offset to prevent DST-related timestamp ambiguity.

Sheet Clock Drift Tolerances
A1: Clock Drift Tolerances — Compliance Checklist
A2: ISO/IEC 27001:2022 — Control A.8.17: Clock Synchronisation
A3: Req # | B3: Section | C3: Requirement | D3: Status | E3: Evidence | F3: Owner | G3: Due Date | H3: Notes
A4: A.8.17-11 | B4: Maintain Clock Accuracy Within The | C4: Systems shall maintain clock accuracy within the following tolerances:.
A5: A.8.17-12 | B5: Clock Drift | C5: Clock drift shall be monitored continuously using system monitoring tools (e.g., Prometheus, Nagios, CloudWatch, or equivalent):.
A6: A.8.17-13 | B6: Ntp Offset, Jitter, And Stratum Metrics | C6: NTP offset, jitter, and stratum metrics shall be collected from all monitored systems.
A7: A.8.17-14 | B7: Clock Drift Alerts | C7: Clock drift alerts shall be forwarded to the centralised monitoring platform.

Sheet Cloud Service Time
A1: Cloud Service Time — Compliance Checklist
A2: ISO/IEC 27001:2022 — Control A.8.17: Clock Synchronisation
A3: Req # | B3: Section | C3: Requirement | D3: Status | E3: Evidence | F3: Owner | G3: Due Date | H3: Notes
A4: A.8.17-15 | B4: The Provider'S Time Synchronisation | C4: Where systems run in cloud environments, the provider's time synchronisation service shall be used:.

Sheet Leap Second Handling
A1: Leap Second Handling — Compliance Checklist
A2: ISO/IEC 27001:2022 — Control A.8.17: Clock Synchronisation
A3: Req # | B3: Section | C3: Requirement | D3: Status | E3: Evidence | F3: Owner | G3: Due Date | H3: Notes
A4: A.8.17-16 | B4: Adopt A Single, Consistent Leap Second | C4: The organisation shall adopt a single, consistent leap second handling strategy across all environments:.

Sheet NTP Security
A1: NTP Security — Compliance Checklist
A2: ISO/IEC 27001:2022 — Control A.8.17: Clock Synchronisation
A3: Req # | B3: Section | C3: Requirement | D3: Status | E3: Evidence | F3: Owner | G3: Due Date | H3: Notes
A4: A.8.17-17 | B4: Ntp Infrastructure | C4: NTP infrastructure shall be protected against spoofing, replay, and denial-of-service attacks:.
A5: A.8.17-18 | B5: Ntp Configuration Files | C5: NTP configuration files shall be protected from unauthorised modification (file permissions, integrity monitoring).
A6: A.8.17-19 | B6: Changes To Ntp Configuration | C6: Changes to NTP configuration shall follow the change management process.
A7: A.8.17-20 | B7: Ntp Service Status | C7: NTP service status shall be monitored; service failure shall generate an alert.
