Workbook

Sheet Executive Summary
A1: ISMS-OP-CHK-A.5.7 — Threat Intelligence Compliance Checklist
A3: DOCUMENT INFORMATION
A4: Document ID | B4: ISMS-OP-CHK-A.5.7
A5: Source Policy | B5: ISMS-OP-POL-A.5.7
A6: ISO Controls | B6: Threat Intelligence
A7: Generated | B7: 30.09.2026
A8: Prepared By
A9: Organisation
A10: Review Cycle | B10: Annual
A12: OVERALL COMPLIANCE STATUS
A13: Overall Compliance | B13: ='Dashboard'!G18
A14: Status | B14: =IF(Dashboard!H18>0,"INCOMPLETE",IF(Dashboard!G18="N/A","NOT ASSESSED",IF(ISNUMBER(VALUE(SUBSTITUTE(Dashboard!G18,"%",""))),IF(VALUE(SUBSTITUTE(Dashboard!G18,"%",""))>=90,"GREEN",IF(VALUE(SUBSTITUTE(Dashboard!G18,"%",""))>=70,"AMBER","RED")),"NOT ASSESSED")))
A16: KEY METRICS
A17: Total Requirements | B17: ='Dashboard'!B18
A18: Compliant | B18: ='Dashboard'!C18
A19: Partial | B19: ='Dashboard'!D18
A20: Non-Compliant | B20: ='Dashboard'!E18
A21: Not Applicable | B21: ='Dashboard'!F18
A22: Unanswered | B22: ='Dashboard'!H18
A23: Owner Coverage | B23: =IF(Dashboard!B18=0,"N/A",ROUND((COUNTA('Intelligence Types and Layers'!F4:F9)+COUNTA('Source Categories'!F4:F6)+COUNTA('Vendor-Provided Intelligence'!F4:F6)+COUNTA('Collection and Analysis'!F4:F12)+COUNTA('Intelligence Data Lifecycle'!F4:F5)+COUNTA('Dissemination and Sharing'!F4:F11)+COUNTA('Risk Assessment Integration'!F4:F16)+COUNTA('Incident Management Integration'!F4:F12)+COUNTA('Security Monitoring Integration'!F4:F10)+COUNTA('Avail & Business Cont'!F4:F10)+COUNTA('Effectiveness Measurement'!F4:F6)+COUNTA('Testing and Validation'!F4:F5)+COUNTA('Customer Threat Intelligence'!F4:F5)+COUNTA('Compliance Measurement'!F4:F5))/Dashboard!B18*100,0)&"%")
A25: DOMAIN STATUS SUMMARY
A26: Domain | B26: Compliance % | C26: Compliant | D26: Gaps | E26: Status
A27: Intelligence Types and Layers | B27: ='Dashboard'!G4 | C27: ='Dashboard'!C4 | D27: ='Dashboard'!E4 | E27: =IF(Dashboard!H4>0,"INCOMPLETE",IF(Dashboard!G4="N/A","--",IF(ISNUMBER(VALUE(SUBSTITUTE(Dashboard!G4,"%",""))),IF(VALUE(SUBSTITUTE(Dashboard!G4,"%",""))>=90,"PASS",IF(VALUE(SUBSTITUTE(Dashboard!G4,"%",""))>=70,"REVIEW","FAIL")),"--")))
A28: Source Categories | B28: ='Dashboard'!G5 | C28: ='Dashboard'!C5 | D28: ='Dashboard'!E5 | E28: =IF(Dashboard!H5>0,"INCOMPLETE",IF(Dashboard!G5="N/A","--",IF(ISNUMBER(VALUE(SUBSTITUTE(Dashboard!G5,"%",""))),IF(VALUE(SUBSTITUTE(Dashboard!G5,"%",""))>=90,"PASS",IF(VALUE(SUBSTITUTE(Dashboard!G5,"%",""))>=70,"REVIEW","FAIL")),"--")))
A29: Vendor-Provided Intelligence | B29: ='Dashboard'!G6 | C29: ='Dashboard'!C6 | D29: ='Dashboard'!E6 | E29: =IF(Dashboard!H6>0,"INCOMPLETE",IF(Dashboard!G6="N/A","--",IF(ISNUMBER(VALUE(SUBSTITUTE(Dashboard!G6,"%",""))),IF(VALUE(SUBSTITUTE(Dashboard!G6,"%",""))>=90,"PASS",IF(VALUE(SUBSTITUTE(Dashboard!G6,"%",""))>=70,"REVIEW","FAIL")),"--")))
A30: Collection and Analysis | B30: ='Dashboard'!G7 | C30: ='Dashboard'!C7 | D30: ='Dashboard'!E7 | E30: =IF(Dashboard!H7>0,"INCOMPLETE",IF(Dashboard!G7="N/A","--",IF(ISNUMBER(VALUE(SUBSTITUTE(Dashboard!G7,"%",""))),IF(VALUE(SUBSTITUTE(Dashboard!G7,"%",""))>=90,"PASS",IF(VALUE(SUBSTITUTE(Dashboard!G7,"%",""))>=70,"REVIEW","FAIL")),"--")))
A31: Intelligence Data Lifecycle | B31: ='Dashboard'!G8 | C31: ='Dashboard'!C8 | D31: ='Dashboard'!E8 | E31: =IF(Dashboard!H8>0,"INCOMPLETE",IF(Dashboard!G8="N/A","--",IF(ISNUMBER(VALUE(SUBSTITUTE(Dashboard!G8,"%",""))),IF(VALUE(SUBSTITUTE(Dashboard!G8,"%",""))>=90,"PASS",IF(VALUE(SUBSTITUTE(Dashboard!G8,"%",""))>=70,"REVIEW","FAIL")),"--")))
A32: Dissemination and Sharing | B32: ='Dashboard'!G9 | C32: ='Dashboard'!C9 | D32: ='Dashboard'!E9 | E32: =IF(Dashboard!H9>0,"INCOMPLETE",IF(Dashboard!G9="N/A","--",IF(ISNUMBER(VALUE(SUBSTITUTE(Dashboard!G9,"%",""))),IF(VALUE(SUBSTITUTE(Dashboard!G9,"%",""))>=90,"PASS",IF(VALUE(SUBSTITUTE(Dashboard!G9,"%",""))>=70,"REVIEW","FAIL")),"--")))
A33: Risk Assessment Integration | B33: ='Dashboard'!G10 | C33: ='Dashboard'!C10 | D33: ='Dashboard'!E10 | E33: =IF(Dashboard!H10>0,"INCOMPLETE",IF(Dashboard!G10="N/A","--",IF(ISNUMBER(VALUE(SUBSTITUTE(Dashboard!G10,"%",""))),IF(VALUE(SUBSTITUTE(Dashboard!G10,"%",""))>=90,"PASS",IF(VALUE(SUBSTITUTE(Dashboard!G10,"%",""))>=70,"REVIEW","FAIL")),"--")))
A34: Incident Management Integration | B34: ='Dashboard'!G11 | C34: ='Dashboard'!C11 | D34: ='Dashboard'!E11 | E34: =IF(Dashboard!H11>0,"INCOMPLETE",IF(Dashboard!G11="N/A","--",IF(ISNUMBER(VALUE(SUBSTITUTE(Dashboard!G11,"%",""))),IF(VALUE(SUBSTITUTE(Dashboard!G11,"%",""))>=90,"PASS",IF(VALUE(SUBSTITUTE(Dashboard!G11,"%",""))>=70,"REVIEW","FAIL")),"--")))
A35: Security Monitoring Integration | B35: ='Dashboard'!G12 | C35: ='Dashboard'!C12 | D35: ='Dashboard'!E12 | E35: =IF(Dashboard!H12>0,"INCOMPLETE",IF(Dashboard!G12="N/A","--",IF(ISNUMBER(VALUE(SUBSTITUTE(Dashboard!G12,"%",""))),IF(VALUE(SUBSTITUTE(Dashboard!G12,"%",""))>=90,"PASS",IF(VALUE(SUBSTITUTE(Dashboard!G12,"%",""))>=70,"REVIEW","FAIL")),"--")))
A36: Avail & Business Cont | B36: ='Dashboard'!G13 | C36: ='Dashboard'!C13 | D36: ='Dashboard'!E13 | E36: =IF(Dashboard!H13>0,"INCOMPLETE",IF(Dashboard!G13="N/A","--",IF(ISNUMBER(VALUE(SUBSTITUTE(Dashboard!G13,"%",""))),IF(VALUE(SUBSTITUTE(Dashboard!G13,"%",""))>=90,"PASS",IF(VALUE(SUBSTITUTE(Dashboard!G13,"%",""))>=70,"REVIEW","FAIL")),"--")))
A37: Effectiveness Measurement | B37: ='Dashboard'!G14 | C37: ='Dashboard'!C14 | D37: ='Dashboard'!E14 | E37: =IF(Dashboard!H14>0,"INCOMPLETE",IF(Dashboard!G14="N/A","--",IF(ISNUMBER(VALUE(SUBSTITUTE(Dashboard!G14,"%",""))),IF(VALUE(SUBSTITUTE(Dashboard!G14,"%",""))>=90,"PASS",IF(VALUE(SUBSTITUTE(Dashboard!G14,"%",""))>=70,"REVIEW","FAIL")),"--")))
A38: Testing and Validation | B38: ='Dashboard'!G15 | C38: ='Dashboard'!C15 | D38: ='Dashboard'!E15 | E38: =IF(Dashboard!H15>0,"INCOMPLETE",IF(Dashboard!G15="N/A","--",IF(ISNUMBER(VALUE(SUBSTITUTE(Dashboard!G15,"%",""))),IF(VALUE(SUBSTITUTE(Dashboard!G15,"%",""))>=90,"PASS",IF(VALUE(SUBSTITUTE(Dashboard!G15,"%",""))>=70,"REVIEW","FAIL")),"--")))
... A40: Compliance Measurement | B40: ='Dashboard'!G17 | C40: ='Dashboard'!C17 | D40: ='Dashboard'!E17 | E40: =IF(Dashboard!H17>0,"INCOMPLETE",IF(Dashboard!G17="N/A","--",IF(ISNUMBER(VALUE(SUBSTITUTE(Dashboard!G17,"%",""))),IF(VALUE(SUBSTITUTE(Dashboard!G17,"%",""))>=90,"PASS",IF(VALUE(SUBSTITUTE(Dashboard!G17,"%",""))>=70,"REVIEW","FAIL")),"--")))
A42: CRITICAL ISSUES
A43: # | B43: Issue Description | C43: Domain | D43: Owner | E43: Due Date
A44: 1
A45: 2
A46: 3
...

Sheet Dashboard
A1: Threat Intelligence — Compliance Dashboard
A3: Domain | B3: Total Reqs | C3: Compliant | D3: Partial | E3: Non-Compliant | F3: N/A | G3: Compliance % | H3: Unassessed
A4: Intelligence Types and Layers | B4: =COUNTA('Intelligence Types and Layers'!A4:A9) | C4: =COUNTIF('Intelligence Types and Layers'!D4:D9,"Compliant") | D4: =COUNTIF('Intelligence Types and Layers'!D4:D9,"Partial") | E4: =COUNTIF('Intelligence Types and Layers'!D4:D9,"Non-Compliant") | F4: =COUNTIF('Intelligence Types and Layers'!D4:D9,"N/A") | G4: =IF((B4-F4)=0,"N/A",ROUND(C4/(B4-F4)*100,1)&"%") | H4: =B4-(C4+D4+E4+F4)
A5: Source Categories | B5: =COUNTA('Source Categories'!A4:A6) | C5: =COUNTIF('Source Categories'!D4:D6,"Compliant") | D5: =COUNTIF('Source Categories'!D4:D6,"Partial") | E5: =COUNTIF('Source Categories'!D4:D6,"Non-Compliant") | F5: =COUNTIF('Source Categories'!D4:D6,"N/A") | G5: =IF((B5-F5)=0,"N/A",ROUND(C5/(B5-F5)*100,1)&"%") | H5: =B5-(C5+D5+E5+F5)
A6: Vendor-Provided Intelligence | B6: =COUNTA('Vendor-Provided Intelligence'!A4:A6) | C6: =COUNTIF('Vendor-Provided Intelligence'!D4:D6,"Compliant") | D6: =COUNTIF('Vendor-Provided Intelligence'!D4:D6,"Partial") | E6: =COUNTIF('Vendor-Provided Intelligence'!D4:D6,"Non-Compliant") | F6: =COUNTIF('Vendor-Provided Intelligence'!D4:D6,"N/A") | G6: =IF((B6-F6)=0,"N/A",ROUND(C6/(B6-F6)*100,1)&"%") | H6: =B6-(C6+D6+E6+F6)
A7: Collection and Analysis | B7: =COUNTA('Collection and Analysis'!A4:A12) | C7: =COUNTIF('Collection and Analysis'!D4:D12,"Compliant") | D7: =COUNTIF('Collection and Analysis'!D4:D12,"Partial") | E7: =COUNTIF('Collection and Analysis'!D4:D12,"Non-Compliant") | F7: =COUNTIF('Collection and Analysis'!D4:D12,"N/A") | G7: =IF((B7-F7)=0,"N/A",ROUND(C7/(B7-F7)*100,1)&"%") | H7: =B7-(C7+D7+E7+F7)
A8: Intelligence Data Lifecycle | B8: =COUNTA('Intelligence Data Lifecycle'!A4:A5) | C8: =COUNTIF('Intelligence Data Lifecycle'!D4:D5,"Compliant") | D8: =COUNTIF('Intelligence Data Lifecycle'!D4:D5,"Partial") | E8: =COUNTIF('Intelligence Data Lifecycle'!D4:D5,"Non-Compliant") | F8: =COUNTIF('Intelligence Data Lifecycle'!D4:D5,"N/A") | G8: =IF((B8-F8)=0,"N/A",ROUND(C8/(B8-F8)*100,1)&"%") | H8: =B8-(C8+D8+E8+F8)
A9: Dissemination and Sharing | B9: =COUNTA('Dissemination and Sharing'!A4:A11) | C9: =COUNTIF('Dissemination and Sharing'!D4:D11,"Compliant") | D9: =COUNTIF('Dissemination and Sharing'!D4:D11,"Partial") | E9: =COUNTIF('Dissemination and Sharing'!D4:D11,"Non-Compliant") | F9: =COUNTIF('Dissemination and Sharing'!D4:D11,"N/A") | G9: =IF((B9-F9)=0,"N/A",ROUND(C9/(B9-F9)*100,1)&"%") | H9: =B9-(C9+D9+E9+F9)
A10: Risk Assessment Integration | B10: =COUNTA('Risk Assessment Integration'!A4:A16) | C10: =COUNTIF('Risk Assessment Integration'!D4:D16,"Compliant") | D10: =COUNTIF('Risk Assessment Integration'!D4:D16,"Partial") | E10: =COUNTIF('Risk Assessment Integration'!D4:D16,"Non-Compliant") | F10: =COUNTIF('Risk Assessment Integration'!D4:D16,"N/A") | G10: =IF((B10-F10)=0,"N/A",ROUND(C10/(B10-F10)*100,1)&"%") | H10: =B10-(C10+D10+E10+F10)
A11: Incident Management Integration | B11: =COUNTA('Incident Management Integration'!A4:A12) | C11: =COUNTIF('Incident Management Integration'!D4:D12,"Compliant") | D11: =COUNTIF('Incident Management Integration'!D4:D12,"Partial") | E11: =COUNTIF('Incident Management Integration'!D4:D12,"Non-Compliant") | F11: =COUNTIF('Incident Management Integration'!D4:D12,"N/A") | G11: =IF((B11-F11)=0,"N/A",ROUND(C11/(B11-F11)*100,1)&"%") | H11: =B11-(C11+D11+E11+F11)
A12: Security Monitoring Integration | B12: =COUNTA('Security Monitoring Integration'!A4:A10) | C12: =COUNTIF('Security Monitoring Integration'!D4:D10,"Compliant") | D12: =COUNTIF('Security Monitoring Integration'!D4:D10,"Partial") | E12: =COUNTIF('Security Monitoring Integration'!D4:D10,"Non-Compliant") | F12: =COUNTIF('Security Monitoring Integration'!D4:D10,"N/A") | G12: =IF((B12-F12)=0,"N/A",ROUND(C12/(B12-F12)*100,1)&"%") | H12: =B12-(C12+D12+E12+F12)
A13: Avail & Business Cont | B13: =COUNTA('Avail & Business Cont'!A4:A10) | C13: =COUNTIF('Avail & Business Cont'!D4:D10,"Compliant") | D13: =COUNTIF('Avail & Business Cont'!D4:D10,"Partial") | E13: =COUNTIF('Avail & Business Cont'!D4:D10,"Non-Compliant") | F13: =COUNTIF('Avail & Business Cont'!D4:D10,"N/A") | G13: =IF((B13-F13)=0,"N/A",ROUND(C13/(B13-F13)*100,1)&"%") | H13: =B13-(C13+D13+E13+F13)
A14: Effectiveness Measurement | B14: =COUNTA('Effectiveness Measurement'!A4:A6) | C14: =COUNTIF('Effectiveness Measurement'!D4:D6,"Compliant") | D14: =COUNTIF('Effectiveness Measurement'!D4:D6,"Partial") | E14: =COUNTIF('Effectiveness Measurement'!D4:D6,"Non-Compliant") | F14: =COUNTIF('Effectiveness Measurement'!D4:D6,"N/A") | G14: =IF((B14-F14)=0,"N/A",ROUND(C14/(B14-F14)*100,1)&"%") | H14: =B14-(C14+D14+E14+F14)
A15: Testing and Validation | B15: =COUNTA('Testing and Validation'!A4:A5) | C15: =COUNTIF('Testing and Validation'!D4:D5,"Compliant") | D15: =COUNTIF('Testing and Validation'!D4:D5,"Partial") | E15: =COUNTIF('Testing and Validation'!D4:D5,"Non-Compliant") | F15: =COUNTIF('Testing and Validation'!D4:D5,"N/A") | G15: =IF((B15-F15)=0,"N/A",ROUND(C15/(B15-F15)*100,1)&"%") | H15: =B15-(C15+D15+E15+F15)
A16: Customer Threat Intelligence | B16: =COUNTA('Customer Threat Intelligence'!A4:A5) | C16: =COUNTIF('Customer Threat Intelligence'!D4:D5,"Compliant") | D16: =COUNTIF('Customer Threat Intelligence'!D4:D5,"Partial") | E16: =COUNTIF('Customer Threat Intelligence'!D4:D5,"Non-Compliant") | F16: =COUNTIF('Customer Threat Intelligence'!D4:D5,"N/A") | G16: =IF((B16-F16)=0,"N/A",ROUND(C16/(B16-F16)*100,1)&"%") | H16: =B16-(C16+D16+E16+F16)
A17: Compliance Measurement | B17: =COUNTA('Compliance Measurement'!A4:A5) | C17: =COUNTIF('Compliance Measurement'!D4:D5,"Compliant") | D17: =COUNTIF('Compliance Measurement'!D4:D5,"Partial") | E17: =COUNTIF('Compliance Measurement'!D4:D5,"Non-Compliant") | F17: =COUNTIF('Compliance Measurement'!D4:D5,"N/A") | G17: =IF((B17-F17)=0,"N/A",ROUND(C17/(B17-F17)*100,1)&"%") | H17: =B17-(C17+D17+E17+F17)
A18: TOTAL | B18: =SUM(B4:B17) | C18: =SUM(C4:C17) | D18: =SUM(D4:D17) | E18: =SUM(E4:E17) | F18: =SUM(F4:F17) | G18: =IF((B18-F18)=0,"N/A",ROUND(C18/(B18-F18)*100,1)&"%") | H18: =SUM(H4:H17)
A20: COMPLIANCE BY STATUS
A21: Compliant | B21: =C18 | C21: =IF(B18=0,"",ROUND(B21/B18*100,1)&"%")
A22: Partial | B22: =D18 | C22: =IF(B18=0,"",ROUND(B22/B18*100,1)&"%")
A23: Non-Compliant | B23: =E18 | C23: =IF(B18=0,"",ROUND(B23/B18*100,1)&"%")
A24: N/A | B24: =F18 | C24: =IF(B18=0,"",ROUND(B24/B18*100,1)&"%")
A26: TOP GAPS (Manual Entry)
A27: Priority | B27: Domain | C27: Requirement | D27: Owner | E27: Due Date | F27: Status
A39: COMPLIANCE TREND (Manual Entry)
A40: Assessment Date | B40: Overall % | C40: Compliant | D40: Gaps | E40: Assessor | F40: Notes

Sheet Intelligence Types and Layers
A1: Intelligence Types and Layers — Compliance Checklist
A2: ISO/IEC 27001:2022 — Control A.5.7: Threat Intelligence
A3: Req # | B3: Section | C3: Requirement | D3: Status | E3: Evidence | F3: Owner | G3: Due Date | H3: Notes
A4: A.5.7-01 | B4: Produce Or Consume Threat Intelligence | C4: The organisation shall produce or consume threat intelligence at three layers, each serving a distinct audience and purpose. Not all organisations will produce intelligence at every layer internally; consumption from external sources is acceptable where internal production capacity is limited.
A5: A.5.7-02 | B5: Strategic Intelligence | C5: Strategic intelligence shall address:.
A6: A.5.7-03 | B6: Production Frequency*: Quarterly At | C6: Production frequency*: Quarterly at minimum, or triggered by significant threat landscape changes. Where the organisation does not produce strategic intelligence internally, it shall subscribe to or access at least one source of sector-relevant strategic threat reporting (e.g., Swiss NCSC semi-annual reports, CERT advisories, or commercial strategic intelligence services).
A7: A.5.7-04 | B7: Tactical Intelligence | C7: Tactical intelligence shall address:.
A8: A.5.7-05 | B8: Production Frequency*: Monthly At | C8: Production frequency*: Monthly at minimum, or triggered by emerging threats. Where internal analysis capacity is limited, the organisation shall consume tactical intelligence from at least one structured source (e.g., MITRE ATT&CK, Swiss NCSC advisories, CERT feeds, or commercial threat reports).
A9: A.5.7-06 | B9: Operational Intelligence | C9: Operational intelligence shall include:.

Sheet Source Categories
A1: Source Categories — Compliance Checklist
A2: ISO/IEC 27001:2022 — Control A.5.7: Threat Intelligence
A3: Req # | B3: Section | C3: Requirement | D3: Status | E3: Evidence | F3: Owner | G3: Due Date | H3: Notes
A4: A.5.7-07 | B4: Maintain Threat Intelligence Sources | C4: The organisation shall maintain threat intelligence sources across multiple categories to avoid single-source dependency and ensure comprehensive coverage. The number and depth of sources shall be proportionate to organisational size and risk exposure.
A5: A.5.7-08 | B5: Threat Intelligence Sources | C5: All threat intelligence sources shall be evaluated before operationalisation and periodically thereafter. Evaluation shall consider:.
A6: A.5.7-09 | B6: Sources That Consistently Provide | C6: Sources that consistently provide inaccurate, irrelevant, or excessively noisy information shall be replaced or deprioritised. Source performance shall be reviewed at least annually.

Sheet Vendor-Provided Intelligence
A1: Vendor-Provided Intelligence — Compliance Checklist
A2: ISO/IEC 27001:2022 — Control A.5.7: Threat Intelligence
A3: Req # | B3: Section | C3: Requirement | D3: Status | E3: Evidence | F3: Owner | G3: Due Date | H3: Notes
A4: A.5.7-10 | B4: Commercial Threat Intelligence Vendors | C4: Commercial threat intelligence vendors shall be evaluated against:.
A5: A.5.7-11 | B5: Contracts With Commercial Threat | C5: Contracts with commercial threat intelligence vendors shall include:.
A6: A.5.7-12 | B6: Commercial Intelligence Vendors | C6: Commercial intelligence vendors shall be reviewed annually covering:.

Sheet Collection and Analysis
A1: Collection and Analysis — Compliance Checklist
A2: ISO/IEC 27001:2022 — Control A.5.7: Threat Intelligence
A3: Req # | B3: Section | C3: Requirement | D3: Status | E3: Evidence | F3: Owner | G3: Due Date | H3: Notes
A4: A.5.7-13 | B4: Implement A Documented Process For | C4: The organisation shall implement a documented process for collecting threat intelligence that includes:.
A5: A.5.7-14 | B5: Automated Collection: Threat Feeds | C5: Automated collection: Threat feeds shall be ingested automatically where feasible, using standard protocols (STIX/TAXII where supported) or vendor-specific APIs. Automated feeds shall be directed to [SIEM] or [Threat Intelligence Platform] for centralised processing.
A6: A.5.7-15 | B6: Manual Collection: Security Personnel | C6: Manual collection: Security personnel shall review advisory sources, security news, and community forums on a defined schedule. Manual collection findings shall be documented and entered into the threat intelligence register.
A7: A.5.7-16 | B7: Internal Collection: Security Events, | C7: Internal collection: Security events, incident findings, and forensic analysis results shall be captured as internal threat intelligence. Post-incident reviews shall explicitly identify and record IOCs and TTPs encountered.
A8: A.5.7-17 | B8: Data Protection: All Collected | C8: Data protection: All collected intelligence shall comply with applicable data protection requirements. Personal data included in threat intelligence (e.g., email addresses in phishing indicators) shall be processed only for the legitimate interest of information security and retained only as long as the indicator remains operationally relevant.
A9: A.5.7-18 | B9: Raw Threat Data | C9: Raw threat data shall be analysed before dissemination to ensure quality and relevance. Analysis shall:.
A10: A.5.7-19 | B10: Analysis Responsibilities | C10: Where the organisation does not have dedicated threat intelligence analysts, analysis responsibilities shall be assigned to the CISO or designated security personnel. Analysis need not be a full-time function for smaller organisations, but it shall be a documented, recurring activity with clear ownership.
A11: A.5.7-20 | B11: Threat Intelligence — Whether Produced | C11: All threat intelligence — whether produced internally or consumed from external sources — shall meet the following quality criteria before being acted upon:.
A12: A.5.7-21 | B12: Intelligence That Does Not Meet These | C12: Intelligence that does not meet these criteria shall be flagged, investigated, or discarded. Source evaluation records shall document quality issues.

Sheet Intelligence Data Lifecycle
A1: Intelligence Data Lifecycle — Compliance Checklist
A2: ISO/IEC 27001:2022 — Control A.5.7: Threat Intelligence
A3: Req # | B3: Section | C3: Requirement | D3: Status | E3: Evidence | F3: Owner | G3: Due Date | H3: Notes
A4: A.5.7-22 | B4: Threat Intelligence Data | C4: Threat intelligence data shall be retained according to operational and regulatory requirements:.
A5: A.5.7-23 | B5: Indicators Of Compromise Deployed To | C5: Indicators of compromise deployed to detection systems shall be managed through a lifecycle process:.

Sheet Dissemination and Sharing
A1: Dissemination and Sharing — Compliance Checklist
A2: ISO/IEC 27001:2022 — Control A.5.7: Threat Intelligence
A3: Req # | B3: Section | C3: Requirement | D3: Status | E3: Evidence | F3: Owner | G3: Due Date | H3: Notes
A4: A.5.7-24 | B4: Threat Intelligence | C4: Threat intelligence shall be distributed to the appropriate audience based on intelligence type:.
A5: A.5.7-25 | B5: Tlp Classification: All Shared | C5: TLP classification: All shared intelligence shall be classified using Traffic Light Protocol v2.0 (TLP:RED, TLP:AMBER+STRICT, TLP:AMBER, TLP:GREEN, TLP:CLEAR). Sharing shall not exceed the TLP designation assigned by the originator.
A6: A.5.7-26 | B6: Sharing Agreements: Formal Agreements | C6: Sharing agreements: Formal agreements (NDA, information sharing agreement, or membership terms) shall be in place before sharing with external parties.
A7: A.5.7-27 | B7: Data Protection: Shared Intelligence | C7: Data protection: Shared intelligence shall not include personal data beyond what is necessary for threat detection (e.g., IOCs). Where personal data is shared, a lawful basis under nFADP shall be established.
A8: A.5.7-28 | B8: Regulatory Reporting: Where Swiss Ncsc | C8: Regulatory reporting: Where Swiss NCSC mandatory reporting obligations apply (critical infrastructure operators — ISG Art. 74b), the organisation shall report relevant cyber incidents to the NCSC within 24 hours per applicable requirements.
A9: A.5.7-29 | B9: Respect Tlp Markings: Intelligence | C9: Respect TLP markings: Intelligence received with TLP designations shall not be shared beyond the permitted boundaries.
A10: A.5.7-30 | B10: Validate Before Acting: Externally | C10: Validate before acting: Externally received IOCs shall be validated against the organisation's environment before deployment to blocking or detection systems to minimise false positives.
A11: A.5.7-31 | B11: Acknowledge Receipt: Where Sharing Is | C11: Acknowledge receipt: Where sharing is bidirectional, the organisation shall acknowledge receipt and provide feedback on intelligence utility when requested.

Sheet Risk Assessment Integration
A1: Risk Assessment Integration — Compliance Checklist
A2: ISO/IEC 27001:2022 — Control A.5.7: Threat Intelligence
A3: Req # | B3: Section | C3: Requirement | D3: Status | E3: Evidence | F3: Owner | G3: Due Date | H3: Notes
A4: A.5.7-32 | B4: Threat Intelligence | C4: Threat intelligence shall inform the organisation's risk assessment process per ISO 27001:2022 Clause 6.1. This integration is mandatory — threat intelligence that does not influence risk decisions provides limited value.
A5: A.5.7-33 | B5: Likelihood Assessment: Threat | C5: Likelihood assessment: Threat intelligence on active campaigns, exploitation activity, and threat actor targeting shall inform the likelihood estimates assigned to identified risks.
A6: A.5.7-34 | B6: Impact Assessment: Intelligence On | C6: Impact assessment: Intelligence on attack techniques and observed consequences in peer organisations shall inform impact assessments.
A7: A.5.7-35 | B7: Risk Register Updates: When Threat | C7: Risk register updates: When threat intelligence identifies new threats or changes to existing threats, the risk register shall be updated accordingly. Each update shall reference the supporting threat intelligence source.
A8: A.5.7-36 | B8: Control Effectiveness: Threat | C8: Control effectiveness: Threat intelligence on bypassed or ineffective controls observed in the wild shall trigger re-evaluation of the organisation's control effectiveness.
A9: A.5.7-37 | B9: The Ciso Or Designated Security | C9: The CISO or designated security personnel shall review strategic and tactical threat intelligence outputs at least quarterly against the current risk register.
A10: A.5.7-38 | B10: New Threats Identified Through | C10: New threats identified through intelligence analysis shall be submitted to Risk Management for formal risk assessment.
A11: A.5.7-39 | B11: Changes To Threat Likelihood Or Impact | C11: Changes to threat likelihood or impact based on intelligence shall be documented with traceable references to supporting intelligence reports.
A12: A.5.7-40 | B12: Risk Treatment Decisions Influenced By | C12: Risk treatment decisions influenced by threat intelligence shall be recorded in the risk register.
A13: A.5.7-41 | B13: Threat Intelligence | C13: Where the organisation processes personal data subject to nFADP or GDPR, threat intelligence shall specifically address threats to data confidentiality and privacy:.
A14: A.5.7-42 | B14: Risks Related To Personal Data | C14: Risks related to personal data processing (e.g., “R-DATA-01: Unauthorised access to customer personal data”) shall be reviewed quarterly against threat intelligence findings.
A15: A.5.7-43 | B15: Threat Intelligence Indicating Increased | C15: Threat intelligence indicating increased targeting of data controllers in the organisation’s sector shall trigger re-assessment of data protection control adequacy.
A16: A.5.7-44 | B16: Detection Rules For Data Exfiltration | C16: Detection rules for data exfiltration attempts shall be updated based on observed attacker techniques.

Sheet Incident Management Integration
A1: Incident Management Integration — Compliance Checklist
A2: ISO/IEC 27001:2022 — Control A.5.7: Threat Intelligence
A3: Req # | B3: Section | C3: Requirement | D3: Status | E3: Evidence | F3: Owner | G3: Due Date | H3: Notes
A4: A.5.7-45 | B4: Threat Intelligence | C4: Threat intelligence shall enhance incident detection, investigation, and response per Controls A.5.24-28.
A5: A.5.7-46 | B5: Iocs From Threat Intelligence Sources | C5: IOCs from threat intelligence sources shall be deployed to detection systems ([SIEM], [EDR], email gateway, web filter) to enable automated alerting.
A6: A.5.7-47 | B6: Threat Actor Ttps From Tactical | C6: Threat actor TTPs from tactical intelligence shall be translated into detection rules or monitoring use cases where feasible.
A7: A.5.7-48 | B7: Detection Rule Effectiveness | C7: Detection rule effectiveness shall be reviewed periodically and rules updated based on evolving intelligence.
A8: A.5.7-49 | B8: Available Threat Intelligence | C8: When a security incident occurs, available threat intelligence shall be queried for related indicators, known threat actor profiles, and attack pattern context.
A9: A.5.7-50 | B9: Threat Intelligence Context | C9: Threat intelligence context shall be included in incident investigation records to support root cause analysis and attribution assessment.
A10: A.5.7-51 | B10: Incident Findings — | C10: Incident findings — including newly discovered IOCs, observed TTPs, and attack infrastructure — shall be captured as internal threat intelligence.
A11: A.5.7-52 | B11: Post-Incident Reviews | C11: Post-incident reviews shall assess whether existing threat intelligence sources provided adequate warning and whether detection rules performed as expected.
A12: A.5.7-53 | B12: Lessons Learned | C12: Lessons learned shall feed back into source evaluation, detection rule tuning, and risk assessment updates.

Sheet Security Monitoring Integration
A1: Security Monitoring Integration — Compliance Checklist
A2: ISO/IEC 27001:2022 — Control A.5.7: Threat Intelligence
A3: Req # | B3: Section | C3: Requirement | D3: Status | E3: Evidence | F3: Owner | G3: Due Date | H3: Notes
A4: A.5.7-54 | B4: Threat Intelligence | C4: Threat intelligence shall be integrated with security monitoring capabilities to enhance detection effectiveness.
A5: A.5.7-55 | B5: [Siem] Integration: Operational Iocs | C5: [SIEM] integration: Operational IOCs shall be ingested into the [SIEM] for correlation with internal security events. Where automated ingestion is not feasible, manual IOC entry shall be performed on a defined schedule.
A6: A.5.7-56 | B6: Endpoint Detection: Where [Edr] Or | C6: Endpoint detection: Where [EDR] or endpoint protection platforms support threat intelligence feed integration, relevant IOCs shall be deployed to endpoint detection systems.
A7: A.5.7-57 | B7: Email Security: Known Phishing Domains, | C7: Email security: Known phishing domains, malicious sender addresses, and attachment hashes shall be deployed to email gateway filtering rules.
A8: A.5.7-58 | B8: Web Filtering: Malicious Domains And | C8: Web filtering: Malicious domains and URLs from threat intelligence shall be deployed to web filtering or DNS security systems.
A9: A.5.7-59 | B9: Firewall Rules: Known Malicious Ip | C9: Firewall rules: Known malicious IP addresses and network indicators shall be deployed to perimeter and internal firewall blocklists, subject to false positive validation.
A10: A.5.7-60 | B10: Track The Following To Assess | C10: The organisation shall track the following to assess integration effectiveness:.

Sheet Avail & Business Cont
A1: Avail & Business Cont — Compliance Checklist
A2: ISO/IEC 27001:2022 — Control A.5.7: Threat Intelligence
A3: Req # | B3: Section | C3: Requirement | D3: Status | E3: Evidence | F3: Owner | G3: Due Date | H3: Notes
A4: A.5.7-61 | B4: Threat Intelligence | C4: Threat intelligence shall inform business continuity planning and service availability protection per Controls A.5.29-30.
A5: A.5.7-62 | B5: The Following Threat Categories | C5: The following threat categories shall be prioritised for detection and response due to their potential impact on service availability:.
A6: A.5.7-63 | B6: Threat Intelligence | C6: Threat intelligence shall provide the following inputs to business continuity and disaster recovery planning:.
A7: A.5.7-64 | B7: Threat Scenarios — Annual Review Of | C7: Threat scenarios — Annual review of plausible threat scenarios (ransomware, DDoS, data destruction) based on observed industry incidents shall inform business impact analysis (BIA) and recovery strategies.
A8: A.5.7-65 | B8: Recovery Time Objectives (Rto) | C8: Recovery time objectives (RTO) validation — Observed attack speeds in the wild (e.g., ransomware encryption time, DDoS attack duration) shall be compared against RTO assumptions to validate recovery feasibility.
A9: A.5.7-66 | B9: Third-Party Dependency Risks — | C9: Third-party dependency risks — Intelligence on supply chain attacks or cloud service provider incidents shall trigger reviews of vendor contingency plans and alternative provider readiness.
A10: A.5.7-67 | B10: Tabletop Exercise Scenarios — Annual | C10: Tabletop exercise scenarios — Annual business continuity exercises shall incorporate realistic threat scenarios derived from current threat intelligence.

Sheet Effectiveness Measurement
A1: Effectiveness Measurement — Compliance Checklist
A2: ISO/IEC 27001:2022 — Control A.5.7: Threat Intelligence
A3: Req # | B3: Section | C3: Requirement | D3: Status | E3: Evidence | F3: Owner | G3: Due Date | H3: Notes
A4: A.5.7-68 | B4: Measure Threat Intelligence Programme | C4: The organisation shall measure threat intelligence programme effectiveness to justify investment, identify improvement opportunities, and demonstrate value to stakeholders.
A5: A.5.7-69 | B5: The Following Metrics | C5: The following metrics shall be tracked and reported to the CISO quarterly:.
A6: A.5.7-70 | B6: The Ciso | C6: The CISO shall conduct an annual review of the threat intelligence programme covering:.

Sheet Testing and Validation
A1: Testing and Validation — Compliance Checklist
A2: ISO/IEC 27001:2022 — Control A.5.7: Threat Intelligence
A3: Req # | B3: Section | C3: Requirement | D3: Status | E3: Evidence | F3: Owner | G3: Due Date | H3: Notes
A4: A.5.7-71 | B4: Test Threat Intelligence Effectiveness | C4: The organisation shall test threat intelligence effectiveness to validate that intelligence sources and detection integrations perform as intended.
A5: A.5.7-72 | B5: Testing Activities | C5: All testing activities shall be documented with:.

Sheet Customer Threat Intelligence
A1: Customer Threat Intelligence — Compliance Checklist
A2: ISO/IEC 27001:2022 — Control A.5.7: Threat Intelligence
A3: Req # | B3: Section | C3: Requirement | D3: Status | E3: Evidence | F3: Owner | G3: Due Date | H3: Notes
A4: A.5.7-73 | B4: For Customers With Dedicated Service | C4: For customers with dedicated service agreements, the organisation shall:.
A5: A.5.7-74 | B5: Be Invited To Provide Feedback On | C5: Customers shall be invited to provide feedback on intelligence utility and relevance.

Sheet Compliance Measurement
A1: Compliance Measurement — Compliance Checklist
A2: ISO/IEC 27001:2022 — Control A.5.7: Threat Intelligence
A3: Req # | B3: Section | C3: Requirement | D3: Status | E3: Evidence | F3: Owner | G3: Due Date | H3: Notes
A4: A.5.7-75 | B4: The Following Metrics | C4: The following metrics shall be tracked and reported to the CISO quarterly:.
A5: A.5.7-76 | B5: Metrics Breaching Red Thresholds | C5: Metrics breaching red thresholds shall be escalated to the CISO for immediate attention and reported at the next Management Review.
