Workbook

Sheet 1. Instructions & Legend
A1: ISMS-IMP-A.5.34.1 - PII Identification and Classification Assessment
A4: Purpose: | B4: This workbook supports systematic identification and classification of all PII processed by the organization.
A6: Regulatory Compliance: | B6: - GDPR Article 30 (Record of Processing Activities - ROPA)
B7: - Swiss FADP Articles 5, 6, 8 (Data protection principles, PII categories)
B8: - ISO/IEC 27001:2022 Control A.5.34 (Privacy and Protection of PII)
A10: Assessment Scope: | B10: All systems, processes, and activities that collect, process, store, or transmit personal data.
A12: Completion Instructions:
B13: 1. Complete Sheet 2 (PII System Inventory) - identify all PII-containing systems
B14: 2. Complete Sheet 3 (Data Flow Mapping) - map PII flows including cross-border transfers
B15: 3. Complete Sheet 4 (ROPA) - create GDPR-compliant processing activity records
B16: 4. Complete Sheet 5 (Gaps) - document non-compliant processing and remediation plans
B17: 5. Complete Sheet 6 (Evidence) - link supporting evidence for audit trail
B18: 6. Review Sheet 7 (Dashboard) - validate compliance metrics
B19: 7. Obtain approvals in Sheet 8 (Sign-Off)
A21: Key Definitions:
A23: Personal Data / PII: | B23: Any information relating to an identified or identifiable natural person (GDPR Art. 4(1), FADP Art. 5(a))
A25: PII Classifications:
A26: Basic PII: | B26: Standard personal data requiring baseline protection (names, emails, addresses, financial data)
A27: Sensitive PII: | B27: Special category data per GDPR Art. 9 / FADP Art. 5(c) requiring enhanced protection:
B28: • Health data, genetic data, biometric data (for unique identification)
B29: • Racial/ethnic origin, political opinions, religious/philosophical beliefs
B30: • Trade union membership, sex life/sexual orientation, private sphere (FADP)
A31: Criminal Offense Data: | B31: Data relating to criminal convictions, offenses, or related security measures (GDPR Art. 10)
A33: Legal Bases (GDPR Art. 6):
B34: Every processing activity MUST have a valid legal basis:
A35: Consent: | B35: Data subject gave explicit consent for specific purpose (freely given, specific, informed, unambiguous, withdrawable)
A36: Contract: | B36: Processing necessary to perform contract with data subject
A37: Legal Obligation: | B37: Processing required by EU/Member State law
A38: Vital Interests: | B38: Processing necessary to protect life/physical integrity (emergency only)
A39: Public Task: | B39: Processing for task in public interest (typically public authorities only)
A40: Legitimate Interests: | B40: Processing necessary for legitimate interests of controller/third party (requires LIA)
A42: Cross-Border Transfers: | B42: Personal data transferred outside EU/Switzerland requires safeguards:
A43: Adequacy Decision: | B43: EU/CH recognizes destination country as providing adequate protection
A44: SCCs: | B44: Standard Contractual Clauses (EU Commission approved contract terms)
A45: BCRs: | B45: Binding Corporate Rules (intra-group transfer mechanism)
A46: Derogations: | B46: Specific exceptions per GDPR Art. 49 / FADP Art. 17 (consent, contract, legal claims)
A48: Record of Processing Activities (ROPA): | B48: GDPR Article 30 mandates controllers maintain ROPA documenting:
B49: • Purposes of processing
B50: • Categories of data subjects and personal data
B51: • Categories of recipients (including international transfers)
...

Sheet 2. PII System Inventory
A1: RowID | B1: Status | C1: System Name | D1: System Owner | E1: System Type | F1: PII Processing Role | G1: PII Data Subjects | H1: PII Categories | I1: PII Classification | J1: Sensitive PII Types (if applicable) | K1: Data Volume (approx. records) | L1: Hosting Location | M1: Access Level (who/how many) | N1: Discovery Method | O1: Discovery Date | P1: Last Updated | Q1: Updated By | R1: Notes | S1: Evidence Reference | T1: Review Comments
A2: =TEXT(ROW()-1,"SYS-000") | O2: =TODAY() | P2: =TODAY()

Sheet 3. PII Data Flow Mapping
A1: RowID | B1: Status | C1: Source System | D1: Destination System | E1: PII Categories Transferred | F1: Transfer Method | G1: Transfer Frequency | H1: Purpose of Transfer | I1: Legal Basis (Art. 6) | J1: Recipient Type | K1: Recipient Name (if external) | L1: Cross-Border Transfer? | M1: Destination Country | N1: Transfer Mechanism | O1: SCC Date (if applicable) | P1: TIA Completed? (if cross-border) | Q1: Security Measures | R1: Last Updated | S1: Updated By | T1: Notes | U1: Evidence Reference | V1: Review Comments
A2: =TEXT(ROW()-1,"FLOW-000") | R2: =TODAY()

Sheet 4. ROPA (Record of Processing)
A1: RowID | B1: Status | C1: Processing Activity Name | D1: Purpose of Processing | E1: Legal Basis (Art. 6) | F1: Legal Basis (Art. 9 if special category) | G1: Legal Basis Justification | H1: Categories of Data Subjects | I1: Categories of Personal Data | J1: Contains Special Category Data? | K1: Specific Special Category Types | L1: Categories of Recipients (Internal) | M1: Categories of Recipients (Processors) | N1: Categories of Recipients (Third Parties) | O1: Categories of Recipients (Public Authorities) | P1: Transfers to Third Countries? | Q1: Third Countries | R1: Transfer Safeguards | S1: Retention Period | T1: Retention Justification | U1: Deletion Method | V1: Technical Security Measures | W1: Organizational Security Measures | X1: Data Sources | Y1: Data Subject Rights Supported | Z1: DPIA Completed? | AA1: DPIA Reference | AB1: LIA Completed? (if Leg. Interest) | AC1: LIA Reference | AD1: Last Updated | AE1: Updated By | AF1: Notes | AG1: Evidence Reference | AH1: Review Comments
A2: =TEXT(ROW()-1,"ROPA-000") | AD2: =TODAY()

Sheet 5. PII Discovery Gaps
A1: GapID | B1: Status | C1: Gap Type | D1: Gap Description | E1: System/Activity Affected | F1: Risk Level | G1: Risk Justification | H1: Remediation Action | I1: Remediation Owner | J1: Target Completion Date | K1: Actual Completion Date | L1: Date Identified | M1: Identified By | N1: Last Updated | O1: Updated By | P1: Notes | Q1: Evidence Reference | R1: Review Comments
A2: =TEXT(YEAR(TODAY()),"0000")&"-GAP-"&TEXT(ROW()-1,"000") | L2: =TODAY() | N2: =TODAY()

Sheet 6. Evidence Register
A1: EvidenceID | B1: Evidence Type | C1: Evidence Description | D1: Related System/Activity | E1: Related Sheet Reference | F1: Date Collected | G1: Collected By | H1: File Location/URL | I1: File Name | J1: Retention Period | K1: Confidentiality Level | L1: Last Updated | M1: Updated By | N1: Notes | O1: Review Comments
A2: ="EVID-A534.1-"&TEXT(ROW()-1,"000") | F2: =TODAY() | L2: =TODAY()

Sheet 7. Dashboard
A1: PII Identification & Classification Dashboard
A4: Assessment Date: | B4: =TEXT(TODAY(),"DD.MM.YYYY")
A6: SYSTEM INVENTORY METRICS:
A7: Total Systems Assessed: | B7: =COUNTA('2. PII System Inventory'!C2:C1000)
A8: Systems with Basic PII: | B8: =COUNTIF('2. PII System Inventory'!I2:I1000,"Basic PII")
A9: Systems with Sensitive PII: | B9: =COUNTIF('2. PII System Inventory'!I2:I1000,"*Sensitive*")
A10: Systems with Criminal Data: | B10: =COUNTIF('2. PII System Inventory'!I2:I1000,"*Criminal*")
A11: Systems Status - Not Started: | B11: =COUNTIF('2. PII System Inventory'!B2:B1000,"Not Started")
A12: Systems Status - In Progress: | B12: =COUNTIF('2. PII System Inventory'!B2:B1000,"In Progress")
A13: Systems Status - Complete: | B13: =COUNTIF('2. PII System Inventory'!B2:B1000,"Complete")
A14: Systems Status - Validated: | B14: =COUNTIF('2. PII System Inventory'!B2:B1000,"Validated")
A16: DATA FLOW METRICS:
A17: Total Data Flows Mapped: | B17: =COUNTA('3. PII Data Flow Mapping'!C2:C1000)
A18: Cross-Border Transfers: | B18: =COUNTIF('3. PII Data Flow Mapping'!L2:L1000,"Yes")
A19: Flows Missing Transfer Mechanism: | B19: =SUMPRODUCT(('3. PII Data Flow Mapping'!L2:L1000="Yes")*('3. PII Data Flow Mapping'!N2:N1000=""))
A21: ROPA METRICS:
A22: Total Processing Activities: | B22: =COUNTA('4. ROPA (Record of Processing)'!C2:C1000)
A23: Activities with Special Category Data: | B23: =COUNTIF('4. ROPA (Record of Processing)'!J2:J1000,"Yes")
A24: Activities Missing Legal Basis: | B24: =SUMPRODUCT(('4. ROPA (Record of Processing)'!B2:B1000<>"Not Started")*('4. ROPA (Record of Processing)'!E2:E1000=""))
A25: Activities with Cross-Border Transfers: | B25: =COUNTIF('4. ROPA (Record of Processing)'!P2:P1000,"Yes")
A27: GAP ANALYSIS:
A28: Total Gaps Identified: | B28: =COUNTA('5. PII Discovery Gaps'!A2:A1000)
A29: Gaps - Critical Risk: | B29: =COUNTIF('5. PII Discovery Gaps'!F2:F1000,"Critical")
A30: Gaps - High Risk: | B30: =COUNTIF('5. PII Discovery Gaps'!F2:F1000,"High")
A31: Gaps - Medium Risk: | B31: =COUNTIF('5. PII Discovery Gaps'!F2:F1000,"Medium")
A32: Gaps - Low Risk: | B32: =COUNTIF('5. PII Discovery Gaps'!F2:F1000,"Low")
A33: Gaps - Open: | B33: =COUNTIF('5. PII Discovery Gaps'!B2:B1000,"Open")
A34: Gaps - In Progress: | B34: =COUNTIF('5. PII Discovery Gaps'!B2:B1000,"In Progress")
A35: Gaps - Completed: | B35: =COUNTIF('5. PII Discovery Gaps'!B2:B1000,"Completed")
A36: Gaps - Overdue: | B36: =SUMPRODUCT(('5. PII Discovery Gaps'!J2:J1000<TODAY())*('5. PII Discovery Gaps'!B2:B1000<>"Completed"))
A38: EVIDENCE METRICS:
A39: Total Evidence Items Collected: | B39: =COUNTA('6. Evidence Register'!A2:A1000)
A41: COMPLIANCE STATUS:
A42: Assessment Completion Rate: | B42: =IFERROR(TEXT(COUNTIF('2. PII System Inventory'!B2:B1000,"Validated")/COUNTA('2. PII System Inventory'!C2:C1000),"0%"),"0%")
A43: Critical/High Risk Gaps: | B43: =COUNTIF('5. PII Discovery Gaps'!F2:F1000,"Critical")+COUNTIF('5. PII Discovery Gaps'!F2:F1000,"High")
A45: NEXT ACTIONS:
B46: 1. Review and remediate Critical/High risk gaps
B47: 2. Validate all systems marked 'Complete' → 'Validated'
B48: 3. Complete missing legal basis documentation
B49: 4. Obtain Standard Contractual Clauses for cross-border transfers without safeguards
...

Sheet 8. Approval & Sign-Off
A1: Assessment Approval & Sign-Off
A3: Signatory Role | B3: Signatory Name | C3: Signature / Electronic Approval | D3: Signature Date | E3: Approval Scope | F3: Comments | G3: Contact Email
A4: Assessment Lead (DPO / Privacy Officer) | E4: Assessment methodology, completeness, ROPA compliance
A5: Chief Information Security Officer (CISO) | E5: Technical accuracy, security measures documentation
A6: Legal / Compliance Officer | E6: Legal bases validity, regulatory compliance
A7: Executive Sponsor | E7: Final approval, gap remediation support
