Workbook

Sheet Instructions & Legend
A1: ISMS-IMP-A.7.9.S2 - Off-Premises Asset Security ISO/IEC 27001:2022 - Control A.7.9: Security of Assets Off-Premises
A3: Document Information
A4: Document ID | B4: ISMS-IMP-A.7.9.S2
A5: Workbook Title | B5: Off-Premises Asset Security
A6: Control Reference | B6: ISO/IEC 27001:2022 - Control A.7.9: Security of Assets Off-Premises
A7: Version | B7: 1.0
A8: Assessment Date
A9: Completed By
A10: Organisation
A12: Instructions
A13: 1. Complete Sheet 2 (Equipment Inventory) — categories of off-premises equipment.
A14: 2. Complete Sheet 3 (Authorisation & Tracking) — removal processes.
A15: 3. Complete Sheet 4 (Protection Measures) — security controls.
A16: 4. Complete Sheet 5 (Remote Working) — remote work scenarios.
A17: 5. Complete Sheet 6 (Permanent Off-Site) — fixed installations.
A18: 6. Document incidents in Sheet 7 (Incidents).
A19: 7. Document evidence in Sheet 8 (Evidence Register).
A20: 8. Review Sheet 9 (Summary Dashboard) for compliance scores.
... A23: Status Legend
A24: Symbol | B24: Status | C24: Description
A25: ✓ | B25: Compliant / Complete | C25: Requirement fully met
A26: ⚠ | B26: Partial / In Progress | C26: Partially met or in progress
A27: ✗ | B27: Non-Compliant / Not Started | C27: Requirement not met
A28: — | B28: Not Applicable | C28: Not applicable to this assessment

Sheet Equipment Inventory
A1: EQUIPMENT INVENTORY FOR OFF-PREMISES USE Policy Requirement: Off-site assets should be protected
A2: ISO/IEC 27001:2022 - Control A.7.9: Security of Assets Off-Premises
A3: Category ID | B3: Equipment Category | C3: Equipment Type | D3: Total Count | E3: Off-Premises Count | F3: Primary Use Case | G3: MDM Managed | H3: Encryption Enabled | I3: Remote Wipe Capable | J3: GPS Tracking | K3: Last Compliance Check | L3: Compliance Status | M3: Notes
A4: Sample — delete before use

Sheet Authorisation
A1: AUTHORISATION & TRACKING PROCESSES Policy Requirement: Equipment removal should be authorised and tracked
A2: ISO/IEC 27001:2022 - Control A.7.9: Security of Assets Off-Premises
A3: Category ID | B3: Equipment Category | C3: Authorisation Required | D3: Authorisation Method | E3: Tracking System | F3: Chain of Custody | G3: Return Verification | H3: Overdue Alert | I3: Current Overdue | J3: Last Process Review | K3: Compliance Status | L3: Notes
A4: Sample — delete before use

Sheet Protection Measures
A1: PROTECTION MEASURES FOR OFF-PREMISES EQUIPMENT Policy Requirement: Equipment should be protected when off-premises
A2: ISO/IEC 27001:2022 - Control A.7.9: Security of Assets Off-Premises
A3: Category ID | B3: Equipment Category | C3: Physical Security | D3: Transport Guidelines | E3: Public Place Rules | F3: Storage When Not In Use | G3: Environmental Protection | H3: Privacy Screen Required | I3: VPN Required | J3: Screen Lock Timeout | K3: Compliance Status | L3: Notes
A4: Sample — delete before use

Sheet Remote Working
A1: REMOTE WORKING SECURITY ASSESSMENT Policy Requirement: Remote work environments should be secured
A2: ISO/IEC 27001:2022 - Control A.7.9: Security of Assets Off-Premises
A3: Scenario ID | B3: Work Scenario | C3: Data Sensitivity | D3: VPN Requirement | E3: Privacy Screen | F3: WiFi Security | G3: Physical Security | H3: Visitor Access | I3: Bluetooth/Wireless | J3: Worker Count | K3: Last Review | L3: Compliance Status | M3: Notes
A4: Sample — delete before use

Sheet Permanent Off-Site
A1: PERMANENT OFF-SITE INSTALLATIONS Policy Requirement: Permanently off-site equipment requires enhanced protection
A2: ISO/IEC 27001:2022 - Control A.7.9: Security of Assets Off-Premises
A3: Installation ID | B3: Installation Name | C3: Installation Type | D3: Location Count | E3: Physical Security | F3: Environmental Monitoring | G3: Remote Management | H3: Inspection Schedule | I3: Last Inspection | J3: Incident Response | K3: Compliance Status | L3: Notes
A4: Sample — delete before use

Sheet Incidents
A1: EQUIPMENT SECURITY INCIDENTS Policy Requirement: Track and learn from equipment security incidents
A2: ISO/IEC 27001:2022 - Control A.7.9: Security of Assets Off-Premises
A3: Incident ID | B3: Incident Date | C3: Equipment Category | D3: Incident Type | E3: Location | F3: Data at Risk | G3: Remote Wipe Executed | H3: Time to Report (hrs) | I3: Recovery Status | J3: Root Cause | K3: Corrective Action | L3: Notes
A4: Sample — delete before use

Sheet Evidence Register
A1: EVIDENCE REGISTER
A2: Document all evidence collected during this assessment
A4: Evidence ID | B4: Evidence Type | C4: Description | D4: Related Sheet/Item | E4: Collection Date | F4: Collected By | G4: Retention Period | H4: Notes
A5: EV-001 | B5: Screenshot | C5: Sample — delete before use

Sheet Summary Dashboard
A1: OFF-PREMISES ASSET SECURITY — SUMMARY DASHBOARD
A2: ISO/IEC 27001:2022 — Control A.7.9: Security of Assets Off-Premises
A4: TABLE 1: ASSESSMENT AREA COMPLIANCE OVERVIEW
A5: Assessment Area | B5: Total Items | C5: Compliant | D5: Partial | E5: Non-Compliant | F5: N/A | G5: Compliance %
A6: Equipment Inventory | B6: =COUNTA('Equipment Inventory'!B5:B54) | C6: =COUNTIF('Equipment Inventory'!L5:L54,"✅*") | D6: =COUNTIF('Equipment Inventory'!L5:L54,"⚠*") | E6: =COUNTIF('Equipment Inventory'!L5:L54,"❌*") | F6: =B6-(C6+D6+E6) | G6: =IF((B6-F6)=0,0,C6/(B6-F6))
A7: Authorisation | B7: =COUNTA('Authorisation'!B5:B54) | C7: =COUNTIF('Authorisation'!K5:K54,"✅*") | D7: =COUNTIF('Authorisation'!K5:K54,"⚠*") | E7: =COUNTIF('Authorisation'!K5:K54,"❌*") | F7: =B7-(C7+D7+E7) | G7: =IF((B7-F7)=0,0,C7/(B7-F7))
A8: Protection Measures | B8: =COUNTA('Protection Measures'!B5:B54) | C8: =COUNTIF('Protection Measures'!K5:K54,"✅*") | D8: =COUNTIF('Protection Measures'!K5:K54,"⚠*") | E8: =COUNTIF('Protection Measures'!K5:K54,"❌*") | F8: =B8-(C8+D8+E8) | G8: =IF((B8-F8)=0,0,C8/(B8-F8))
A9: Remote Working | B9: =COUNTA('Remote Working'!B5:B54) | C9: =COUNTIF('Remote Working'!L5:L54,"✅*") | D9: =COUNTIF('Remote Working'!L5:L54,"⚠*") | E9: =COUNTIF('Remote Working'!L5:L54,"❌*") | F9: =B9-(C9+D9+E9) | G9: =IF((B9-F9)=0,0,C9/(B9-F9))
A10: Permanent Off-Site | B10: =COUNTA('Permanent Off-Site'!B5:B54) | C10: =COUNTIF('Permanent Off-Site'!K5:K54,"✅*") | D10: =COUNTIF('Permanent Off-Site'!K5:K54,"⚠*") | E10: =COUNTIF('Permanent Off-Site'!K5:K54,"❌*") | F10: =B10-(C10+D10+E10) | G10: =IF((B10-F10)=0,0,C10/(B10-F10))
A11: TOTAL | B11: =SUM(B6:B10) | C11: =SUM(C6:C10) | D11: =SUM(D6:D10) | E11: =SUM(E6:E10) | F11: =SUM(F6:F10) | G11: =IF((B11-F11)=0,0,C11/(B11-F11))
A13: TABLE 2: KEY METRICS
A14: Metric | B14: Value
A15: Total Off-Premises Devices Tracked | B15: =COUNTA('Equipment Inventory'!B5:B54)
A16: Devices with Full Encryption (100%) | B16: =COUNTIF('Equipment Inventory'!H5:H54,"Yes - 100%")
A17: Devices with No Encryption | B17: =COUNTIF('Equipment Inventory'!H5:H54,"No")
A18: Devices with No MDM Enrollment | B18: =COUNTIF('Equipment Inventory'!G5:G54,"No")
A19: Devices with Remote Wipe (Tested) | B19: =COUNTIF('Equipment Inventory'!I5:I54,"Yes - Tested")
A20: Devices with No Remote Wipe Capability | B20: =COUNTIF('Equipment Inventory'!I5:I54,"No")
A21: Assets Without Formal Authorisation | B21: =COUNTIF('Authorisation'!C5:C54,"No approval required")
A22: Assets with No Custody Record | B22: =COUNTIF('Authorisation'!F5:F54,"No")
A23: Assets with No Return Verification | B23: =COUNTIF('Authorisation'!G5:G54,"No verification")
A24: Assets with No VPN Requirement | B24: =COUNTIF('Protection Measures'!I5:I54,"No requirement")
A25: Remote Workers with No VPN Requirement | B25: =COUNTIF('Remote Working'!D5:D54,"Not required")
A26: Permanent Off-Site with No Remote Management | B26: =COUNTIF('Permanent Off-Site'!G5:G54,"No")
A27: Total Security Incidents (This Period) | B27: =COUNTA('Incidents'!B5:B54)
A28: Devices Lost or Stolen | B28: =COUNTIF('Incidents'!D5:D54,"Lost")+COUNTIF('Incidents'!D5:D54,"Stolen")
A29: Incidents with High Data Exposure | B29: =COUNTIF('Incidents'!F5:F54,"High (PII, Financial)")
A30: Successful Remote Wipes (Incidents) | B30: =COUNTIF('Incidents'!G5:G54,"Yes - Successful")
A31: Devices Not Recovered | B31: =COUNTIF('Incidents'!H5:H54,"Not recovered")
A35: TABLE 3: CRITICAL FINDINGS REQUIRING IMMEDIATE ATTENTION
A36: Category | B36: Finding | C36: Count | D36: Severity | E36: Action Required
A37: Equipment Inventory | B37: Devices with no encryption | C37: =COUNTIF('Equipment Inventory'!H5:H54,"No") | D37: Critical | E37: Immediate
A38: Equipment Inventory | B38: Devices with no MDM enrollment | C38: =COUNTIF('Equipment Inventory'!G5:G54,"No") | D38: Critical | E38: Immediate
A39: Equipment Inventory | B39: Devices with no remote wipe capability | C39: =COUNTIF('Equipment Inventory'!I5:I54,"No") | D39: Critical | E39: Immediate
A40: Authorisation | B40: Assets with no custody record | C40: =COUNTIF('Authorisation'!F5:F54,"No") | D40: Critical | E40: Immediate
A41: Authorisation | B41: Assets with no return verification | C41: =COUNTIF('Authorisation'!G5:G54,"No verification") | D41: High | E41: Urgent
A42: Protection Measures | B42: Assets with no VPN requirement | C42: =COUNTIF('Protection Measures'!I5:I54,"No requirement") | D42: High | E42: Urgent
A43: Remote Working | B43: Workers with no VPN requirement | C43: =COUNTIF('Remote Working'!D5:D54,"Not required") | D43: High | E43: Urgent
A44: Incidents | B44: Devices lost or stolen | C44: =COUNTIF('Incidents'!D5:D54,"Lost")+COUNTIF('Incidents'!D5:D54,"Stolen") | D44: Critical | E44: Immediate
A45: Incidents | B45: Incidents with high data exposure (PII/Financial) | C45: =COUNTIF('Incidents'!F5:F54,"High (PII, Financial)") | D45: Critical | E45: Immediate
...

Sheet Approval Sign-Off
A1: ASSESSMENT APPROVAL AND SIGN-OFF
A2: ISO/IEC 27001:2022 - Control A.7.9: Security of Assets Off-Premises
A3: ASSESSMENT SUMMARY
A4: Document: | B4: ISMS-IMP-A.7.9.S2 - Off-Premises Asset Security
A5: Assessment Period:
A6: Overall Compliance Rating: | B6: =IFERROR(AVERAGE('Summary Dashboard'!G6:G10),"")
A7: Assessment Status:
A8: Assessed By:
A10: COMPLETED BY (ASSESSOR)
A11: Name:
A12: Title:
A13: Date:
A14: Signature:
A15: Comments:
A17: REVIEWED BY (INFORMATION SECURITY OFFICER)
A18: Name:
A19: Title:
A20: Date:
... A37: Special Considerations:
