Workbook

Sheet Instructions
A1: ISMS-IMP-A.8.9.4 - Security Hardening Assessment ISO/IEC 27001:2022 - Control A.8.9: Configuration Management
A4: Document ID: | B4: ISMS-IMP-A.8.9.4
A5: Assessment: | B5: Security Hardening Assessment
A6: Version: | B6: 1.0
A7: Generated: | B7: 08.02.2026 11:50
A9: PURPOSE
B10: This workbook assesses [Organization]'s compliance with security hardening standards across all in-scope information assets. Security hardening represents the systematic reduction of attack surface through implementation of security-focused configuration controls.
B12: Assessment objectives:
B13: • Identify which hardening standards apply to which assets
B14: • Assess implementation of required hardening controls
B15: • Identify gaps where controls are not implemented
B16: • Prioritize remediation based on risk
B17: • Document and track approved exceptions
B18: • Monitor progress on closing hardening gaps
A20: KEY CONCEPTS
B21: Security Hardening: Systematic reduction of attack surface through security-focused configuration controls
B23: Hardening Standard: Documented set of security configuration requirements (e.g., CIS Benchmark, DISA STIG, vendor baseline)
B25: Hardening Control: Individual security configuration requirement within a standard
B27: Implementation Status:
B28: • Implemented: Control fully implemented and verified
B29: • Partial: Control partially implemented (60-99% of requirement)
B30: • Not Implemented: Control not implemented, gap exists
B31: • Not Applicable: Control does not apply (with justification)
B33: Exception: Documented deviation from hardening requirement with formal risk acceptance
A35: ASSESSMENT WORKFLOW
B36: 1. Define applicable hardening standards in Hardening_Standard_Register
B37: 2. Map standards to asset types in Asset_Type_Hardening_Matrix
B38: 3. Assess asset-level compliance in Asset_Hardening_Assessment
B39: 4. Document control-level detail in Control_Compliance_Detail
B40: 5. Manage exceptions in Exception_Management
B41: 6. Track remediation in Remediation_Tracking
B42: 7. Review Compliance_Dashboard for overall posture
B43: 8. Use Gap_Prioritization to sequence remediation
B44: 9. Document evidence in Evidence_Register
B45: 10. Obtain approvals in Approval_Sign_Off
A47: HARDENING STANDARD SELECTION
B48: Determine applicable standards through risk assessment. Common categories:
B50: • Industry Benchmarks: CIS Benchmarks, DISA STIGs, NIST 800-53
B51: • Regulatory Requirements: PCI-DSS, HIPAA Technical Safeguards, GDPR controls
B52: • Vendor Baselines: Manufacturer recommended security practices
...

Sheet Hardening_Standard_Register
A1: Standard_ID | B1: Standard_Name | C1: Standard_Category | D1: Standard_Version | E1: Issuing_Authority | F1: Applicability_Scope | G1: Compliance_Level | H1: Mandatory_Optional | I1: Regulatory_Driver | J1: Control_Count | K1: Implementation_Target | L1: Review_Frequency | M1: Last_Review_Date | N1: Next_Review_Date | O1: Standard_Owner | P1: Documentation_Location | Q1: Notes | R1: Status
A2: =IF(B2<>"", "HS-"&TEXT(ROW()-1,"000"), "") | H2: Mandatory | K2: 0.95 | L2: Quarterly | R2: Active
A3: =IF(B3<>"", "HS-"&TEXT(ROW()-1,"000"), "") | H3: Mandatory | K3: 0.95 | L3: Quarterly | R3: Active
A4: =IF(B4<>"", "HS-"&TEXT(ROW()-1,"000"), "") | H4: Mandatory | K4: 0.95 | L4: Quarterly | R4: Active
A5: =IF(B5<>"", "HS-"&TEXT(ROW()-1,"000"), "") | H5: Mandatory | K5: 0.95 | L5: Quarterly | R5: Active
A6: =IF(B6<>"", "HS-"&TEXT(ROW()-1,"000"), "") | H6: Mandatory | K6: 0.95 | L6: Quarterly | R6: Active
A7: =IF(B7<>"", "HS-"&TEXT(ROW()-1,"000"), "") | H7: Mandatory | K7: 0.95 | L7: Quarterly | R7: Active
A8: =IF(B8<>"", "HS-"&TEXT(ROW()-1,"000"), "") | H8: Mandatory | K8: 0.95 | L8: Quarterly | R8: Active
A9: =IF(B9<>"", "HS-"&TEXT(ROW()-1,"000"), "") | H9: Mandatory | K9: 0.95 | L9: Quarterly | R9: Active
A10: =IF(B10<>"", "HS-"&TEXT(ROW()-1,"000"), "") | H10: Mandatory | K10: 0.95 | L10: Quarterly | R10: Active
A11: =IF(B11<>"", "HS-"&TEXT(ROW()-1,"000"), "") | H11: Mandatory | K11: 0.95 | L11: Quarterly | R11: Active
A12: =IF(B12<>"", "HS-"&TEXT(ROW()-1,"000"), "") | H12: Mandatory | K12: 0.95 | L12: Quarterly | R12: Active
A13: =IF(B13<>"", "HS-"&TEXT(ROW()-1,"000"), "") | H13: Mandatory | K13: 0.95 | L13: Quarterly | R13: Active
... A31: =IF(B31<>"", "HS-"&TEXT(ROW()-1,"000"), "") | H31: Mandatory | K31: 0.95 | L31: Quarterly | R31: Active

Sheet Asset_Type_Hardening_Matrix
A1: Asset Type | B1: =IF(Hardening_Standard_Register!A2<>"", Hardening_Standard_Register!A2&": "&LEFT(Hardening_Standard_Register!B2,20), "") | C1: =IF(Hardening_Standard_Register!A3<>"", Hardening_Standard_Register!A3&": "&LEFT(Hardening_Standard_Register!B3,20), "") | D1: =IF(Hardening_Standard_Register!A4<>"", Hardening_Standard_Register!A4&": "&LEFT(Hardening_Standard_Register!B4,20), "") | E1: =IF(Hardening_Standard_Register!A5<>"", Hardening_Standard_Register!A5&": "&LEFT(Hardening_Standard_Register!B5,20), "") | F1: =IF(Hardening_Standard_Register!A6<>"", Hardening_Standard_Register!A6&": "&LEFT(Hardening_Standard_Register!B6,20), "") | G1: =IF(Hardening_Standard_Register!A7<>"", Hardening_Standard_Register!A7&": "&LEFT(Hardening_Standard_Register!B7,20), "") | H1: =IF(Hardening_Standard_Register!A8<>"", Hardening_Standard_Register!A8&": "&LEFT(Hardening_Standard_Register!B8,20), "") | I1: =IF(Hardening_Standard_Register!A9<>"", Hardening_Standard_Register!A9&": "&LEFT(Hardening_Standard_Register!B9,20), "") | J1: =IF(Hardening_Standard_Register!A10<>"", Hardening_Standard_Register!A10&": "&LEFT(Hardening_Standard_Register!B10,20), "") | K1: =IF(Hardening_Standard_Register!A11<>"", Hardening_Standard_Register!A11&": "&LEFT(Hardening_Standard_Register!B11,20), "") | L1: =IF(Hardening_Standard_Register!A12<>"", Hardening_Standard_Register!A12&": "&LEFT(Hardening_Standard_Register!B12,20), "") | M1: =IF(Hardening_Standard_Register!A13<>"", Hardening_Standard_Register!A13&": "&LEFT(Hardening_Standard_Register!B13,20), "") | N1: =IF(Hardening_Standard_Register!A14<>"", Hardening_Standard_Register!A14&": "&LEFT(Hardening_Standard_Register!B14,20), "") | O1: =IF(Hardening_Standard_Register!A15<>"", Hardening_Standard_Register!A15&": "&LEFT(Hardening_Standard_Register!B15,20), "") | P1: =IF(Hardening_Standard_Register!A16<>"", Hardening_Standard_Register!A16&": "&LEFT(Hardening_Standard_Register!B16,20), "") | Q1: =IF(Hardening_Standard_Register!A17<>"", Hardening_Standard_Register!A17&": "&LEFT(Hardening_Standard_Register!B17,20), "") | R1: =IF(Hardening_Standard_Register!A18<>"", Hardening_Standard_Register!A18&": "&LEFT(Hardening_Standard_Register!B18,20), "") | S1: =IF(Hardening_Standard_Register!A19<>"", Hardening_Standard_Register!A19&": "&LEFT(Hardening_Standard_Register!B19,20), "") | T1: =IF(Hardening_Standard_Register!A20<>"", Hardening_Standard_Register!A20&": "&LEFT(Hardening_Standard_Register!B20,20), "") | U1: =IF(Hardening_Standard_Register!A21<>"", Hardening_Standard_Register!A21&": "&LEFT(Hardening_Standard_Register!B21,20), "") | V1: =IF(Hardening_Standard_Register!A22<>"", Hardening_Standard_Register!A22&": "&LEFT(Hardening_Standard_Register!B22,20), "") | W1: =IF(Hardening_Standard_Register!A23<>"", Hardening_Standard_Register!A23&": "&LEFT(Hardening_Standard_Register!B23,20), "") | X1: =IF(Hardening_Standard_Register!A24<>"", Hardening_Standard_Register!A24&": "&LEFT(Hardening_Standard_Register!B24,20), "") | Y1: =IF(Hardening_Standard_Register!A25<>"", Hardening_Standard_Register!A25&": "&LEFT(Hardening_Standard_Register!B25,20), "") | Z1: =IF(Hardening_Standard_Register!A26<>"", Hardening_Standard_Register!A26&": "&LEFT(Hardening_Standard_Register!B26,20), "") | AA1: =IF(Hardening_Standard_Register!A27<>"", Hardening_Standard_Register!A27&": "&LEFT(Hardening_Standard_Register!B27,20), "") | AB1: =IF(Hardening_Standard_Register!A28<>"", Hardening_Standard_Register!A28&": "&LEFT(Hardening_Standard_Register!B28,20), "") | AC1: =IF(Hardening_Standard_Register!A29<>"", Hardening_Standard_Register!A29&": "&LEFT(Hardening_Standard_Register!B29,20), "") | AD1: =IF(Hardening_Standard_Register!A30<>"", Hardening_Standard_Register!A30&": "&LEFT(Hardening_Standard_Register!B30,20), "") | AE1: =IF(Hardening_Standard_Register!A31<>"", Hardening_Standard_Register!A31&": "&LEFT(Hardening_Standard_Register!B31,20), "") | AF1: Required_Standards_Count | AG1: Recommended_Standards_Count | AH1: Total_Applicable_Standards | AI1: High_Hardening_Burden
A2: --- INFRASTRUCTURE ---
A3: Physical Server | AF3: =COUNTIF(B3:AE3,"Required") | AG3: =COUNTIF(B3:AE3,"Recommended") | AH3: =AF3+AG3 | AI3: =IF(AF3>5,"Yes","")
A4: Virtual Server (VM) | AF4: =COUNTIF(B4:AE4,"Required") | AG4: =COUNTIF(B4:AE4,"Recommended") | AH4: =AF4+AG4 | AI4: =IF(AF4>5,"Yes","")
A5: Hypervisor/VM Host | AF5: =COUNTIF(B5:AE5,"Required") | AG5: =COUNTIF(B5:AE5,"Recommended") | AH5: =AF5+AG5 | AI5: =IF(AF5>5,"Yes","")
A6: Container Host | AF6: =COUNTIF(B6:AE6,"Required") | AG6: =COUNTIF(B6:AE6,"Recommended") | AH6: =AF6+AG6 | AI6: =IF(AF6>5,"Yes","")
A7: Storage Array | AF7: =COUNTIF(B7:AE7,"Required") | AG7: =COUNTIF(B7:AE7,"Recommended") | AH7: =AF7+AG7 | AI7: =IF(AF7>5,"Yes","")
A8: Backup Appliance | AF8: =COUNTIF(B8:AE8,"Required") | AG8: =COUNTIF(B8:AE8,"Recommended") | AH8: =AF8+AG8 | AI8: =IF(AF8>5,"Yes","")
A9: Database Server | AF9: =COUNTIF(B9:AE9,"Required") | AG9: =COUNTIF(B9:AE9,"Recommended") | AH9: =AF9+AG9 | AI9: =IF(AF9>5,"Yes","")
A10: Application Server | AF10: =COUNTIF(B10:AE10,"Required") | AG10: =COUNTIF(B10:AE10,"Recommended") | AH10: =AF10+AG10 | AI10: =IF(AF10>5,"Yes","")
A11: Legacy System | AF11: =COUNTIF(B11:AE11,"Required") | AG11: =COUNTIF(B11:AE11,"Recommended") | AH11: =AF11+AG11 | AI11: =IF(AF11>5,"Yes","")
A12: --- ENDPOINT ---
A13: Corporate Workstation | AF13: =COUNTIF(B13:AE13,"Required") | AG13: =COUNTIF(B13:AE13,"Recommended") | AH13: =AF13+AG13 | AI13: =IF(AF13>5,"Yes","")
A14: Corporate Laptop | AF14: =COUNTIF(B14:AE14,"Required") | AG14: =COUNTIF(B14:AE14,"Recommended") | AH14: =AF14+AG14 | AI14: =IF(AF14>5,"Yes","")
A15: Executive Device | AF15: =COUNTIF(B15:AE15,"Required") | AG15: =COUNTIF(B15:AE15,"Recommended") | AH15: =AF15+AG15 | AI15: =IF(AF15>5,"Yes","")
A16: Mobile Device (Corporate) | AF16: =COUNTIF(B16:AE16,"Required") | AG16: =COUNTIF(B16:AE16,"Recommended") | AH16: =AF16+AG16 | AI16: =IF(AF16>5,"Yes","")
A17: Mobile Device (BYOD) | AF17: =COUNTIF(B17:AE17,"Required") | AG17: =COUNTIF(B17:AE17,"Recommended") | AH17: =AF17+AG17 | AI17: =IF(AF17>5,"Yes","")
A18: Thin Client | AF18: =COUNTIF(B18:AE18,"Required") | AG18: =COUNTIF(B18:AE18,"Recommended") | AH18: =AF18+AG18 | AI18: =IF(AF18>5,"Yes","")
A19: Kiosk/Shared Terminal | AF19: =COUNTIF(B19:AE19,"Required") | AG19: =COUNTIF(B19:AE19,"Recommended") | AH19: =AF19+AG19 | AI19: =IF(AF19>5,"Yes","")
A20: --- NETWORK SERVICES ---
A21: Core Router | AF21: =COUNTIF(B21:AE21,"Required") | AG21: =COUNTIF(B21:AE21,"Recommended") | AH21: =AF21+AG21 | AI21: =IF(AF21>5,"Yes","")
A22: Edge Router | AF22: =COUNTIF(B22:AE22,"Required") | AG22: =COUNTIF(B22:AE22,"Recommended") | AH22: =AF22+AG22 | AI22: =IF(AF22>5,"Yes","")
A23: L2/L3 Switch | AF23: =COUNTIF(B23:AE23,"Required") | AG23: =COUNTIF(B23:AE23,"Recommended") | AH23: =AF23+AG23 | AI23: =IF(AF23>5,"Yes","")
A24: Wireless Access Point | AF24: =COUNTIF(B24:AE24,"Required") | AG24: =COUNTIF(B24:AE24,"Recommended") | AH24: =AF24+AG24 | AI24: =IF(AF24>5,"Yes","")
A25: Firewall | AF25: =COUNTIF(B25:AE25,"Required") | AG25: =COUNTIF(B25:AE25,"Recommended") | AH25: =AF25+AG25 | AI25: =IF(AF25>5,"Yes","")
A26: IDS/IPS Appliance | AF26: =COUNTIF(B26:AE26,"Required") | AG26: =COUNTIF(B26:AE26,"Recommended") | AH26: =AF26+AG26 | AI26: =IF(AF26>5,"Yes","")
A27: Load Balancer | AF27: =COUNTIF(B27:AE27,"Required") | AG27: =COUNTIF(B27:AE27,"Recommended") | AH27: =AF27+AG27 | AI27: =IF(AF27>5,"Yes","")
A28: VPN Concentrator | AF28: =COUNTIF(B28:AE28,"Required") | AG28: =COUNTIF(B28:AE28,"Recommended") | AH28: =AF28+AG28 | AI28: =IF(AF28>5,"Yes","")
A29: --- APPLICATIONS ---
A30: Web Application | AF30: =COUNTIF(B30:AE30,"Required") | AG30: =COUNTIF(B30:AE30,"Recommended") | AH30: =AF30+AG30 | AI30: =IF(AF30>5,"Yes","")
A31: API Service | AF31: =COUNTIF(B31:AE31,"Required") | AG31: =COUNTIF(B31:AE31,"Recommended") | AH31: =AF31+AG31 | AI31: =IF(AF31>5,"Yes","")
A32: Database Management System | AF32: =COUNTIF(B32:AE32,"Required") | AG32: =COUNTIF(B32:AE32,"Recommended") | AH32: =AF32+AG32 | AI32: =IF(AF32>5,"Yes","")
A33: File Server/NAS | AF33: =COUNTIF(B33:AE33,"Required") | AG33: =COUNTIF(B33:AE33,"Recommended") | AH33: =AF33+AG33 | AI33: =IF(AF33>5,"Yes","")
A34: Email System | AF34: =COUNTIF(B34:AE34,"Required") | AG34: =COUNTIF(B34:AE34,"Recommended") | AH34: =AF34+AG34 | AI34: =IF(AF34>5,"Yes","")
A35: Authentication Service (IAM) | AF35: =COUNTIF(B35:AE35,"Required") | AG35: =COUNTIF(B35:AE35,"Recommended") | AH35: =AF35+AG35 | AI35: =IF(AF35>5,"Yes","")
A36: Monitoring/Logging System | AF36: =COUNTIF(B36:AE36,"Required") | AG36: =COUNTIF(B36:AE36,"Recommended") | AH36: =AF36+AG36 | AI36: =IF(AF36>5,"Yes","")
A37: --- CLOUD & VIRTUAL ---
A38: IaaS Instance | AF38: =COUNTIF(B38:AE38,"Required") | AG38: =COUNTIF(B38:AE38,"Recommended") | AH38: =AF38+AG38 | AI38: =IF(AF38>5,"Yes","")
A39: PaaS Application | AF39: =COUNTIF(B39:AE39,"Required") | AG39: =COUNTIF(B39:AE39,"Recommended") | AH39: =AF39+AG39 | AI39: =IF(AF39>5,"Yes","")
A40: SaaS Application Configuration | AF40: =COUNTIF(B40:AE40,"Required") | AG40: =COUNTIF(B40:AE40,"Recommended") | AH40: =AF40+AG40 | AI40: =IF(AF40>5,"Yes","")
...

Sheet Asset_Hardening_Assessment
A1: Asset_ID | B1: Asset_Name | C1: Asset_Type | D1: Asset_Tier | E1: Asset_Owner | F1: Location | G1: Operating_System | H1: Applicable_Standards | I1: Standards_Count | J1: Total_Controls | K1: Implemented_Controls | L1: Partial_Controls | M1: Not_Implemented_Controls | N1: Not_Applicable_Controls | O1: Compliance_Percentage | P1: High_Risk_Gaps | Q1: Medium_Risk_Gaps | R1: Low_Risk_Gaps | S1: Active_Exceptions | T1: Compensating_Controls | U1: Compliance_Status | V1: Last_Assessment_Date | W1: Next_Assessment_Date | X1: Assessor | Y1: Evidence_Reference | Z1: Remediation_Status | AA1: Target_Compliance_Date | AB1: Notes
O2: =IF(AND(J2>0,(J2-N2)>0), (K2+(L2*0.5))/(J2-N2), "") | U2: =IF(O2="","", IF(AND(O2=1, P2=0), "Fully Compliant", IF(AND(O2>=0.95, P2=0), "Compliant", IF(O2>=0.9, "Substantially Compliant", IF(O2>=0.8, "Partially Compliant", "Non-Compliant"))))) | W2: =IF(V2<>"", V2+90, "") | X2: [Security Analyst] | Z2: Not Started
O3: =IF(AND(J3>0,(J3-N3)>0), (K3+(L3*0.5))/(J3-N3), "") | U3: =IF(O3="","", IF(AND(O3=1, P3=0), "Fully Compliant", IF(AND(O3>=0.95, P3=0), "Compliant", IF(O3>=0.9, "Substantially Compliant", IF(O3>=0.8, "Partially Compliant", "Non-Compliant"))))) | W3: =IF(V3<>"", V3+90, "") | X3: [Security Analyst] | Z3: Not Started
O4: =IF(AND(J4>0,(J4-N4)>0), (K4+(L4*0.5))/(J4-N4), "") | U4: =IF(O4="","", IF(AND(O4=1, P4=0), "Fully Compliant", IF(AND(O4>=0.95, P4=0), "Compliant", IF(O4>=0.9, "Substantially Compliant", IF(O4>=0.8, "Partially Compliant", "Non-Compliant"))))) | W4: =IF(V4<>"", V4+90, "") | X4: [Security Analyst] | Z4: Not Started
O5: =IF(AND(J5>0,(J5-N5)>0), (K5+(L5*0.5))/(J5-N5), "") | U5: =IF(O5="","", IF(AND(O5=1, P5=0), "Fully Compliant", IF(AND(O5>=0.95, P5=0), "Compliant", IF(O5>=0.9, "Substantially Compliant", IF(O5>=0.8, "Partially Compliant", "Non-Compliant"))))) | W5: =IF(V5<>"", V5+90, "") | X5: [Security Analyst] | Z5: Not Started
O6: =IF(AND(J6>0,(J6-N6)>0), (K6+(L6*0.5))/(J6-N6), "") | U6: =IF(O6="","", IF(AND(O6=1, P6=0), "Fully Compliant", IF(AND(O6>=0.95, P6=0), "Compliant", IF(O6>=0.9, "Substantially Compliant", IF(O6>=0.8, "Partially Compliant", "Non-Compliant"))))) | W6: =IF(V6<>"", V6+90, "") | X6: [Security Analyst] | Z6: Not Started
O7: =IF(AND(J7>0,(J7-N7)>0), (K7+(L7*0.5))/(J7-N7), "") | U7: =IF(O7="","", IF(AND(O7=1, P7=0), "Fully Compliant", IF(AND(O7>=0.95, P7=0), "Compliant", IF(O7>=0.9, "Substantially Compliant", IF(O7>=0.8, "Partially Compliant", "Non-Compliant"))))) | W7: =IF(V7<>"", V7+90, "") | X7: [Security Analyst] | Z7: Not Started
O8: =IF(AND(J8>0,(J8-N8)>0), (K8+(L8*0.5))/(J8-N8), "") | U8: =IF(O8="","", IF(AND(O8=1, P8=0), "Fully Compliant", IF(AND(O8>=0.95, P8=0), "Compliant", IF(O8>=0.9, "Substantially Compliant", IF(O8>=0.8, "Partially Compliant", "Non-Compliant"))))) | W8: =IF(V8<>"", V8+90, "") | X8: [Security Analyst] | Z8: Not Started
O9: =IF(AND(J9>0,(J9-N9)>0), (K9+(L9*0.5))/(J9-N9), "") | U9: =IF(O9="","", IF(AND(O9=1, P9=0), "Fully Compliant", IF(AND(O9>=0.95, P9=0), "Compliant", IF(O9>=0.9, "Substantially Compliant", IF(O9>=0.8, "Partially Compliant", "Non-Compliant"))))) | W9: =IF(V9<>"", V9+90, "") | X9: [Security Analyst] | Z9: Not Started
O10: =IF(AND(J10>0,(J10-N10)>0), (K10+(L10*0.5))/(J10-N10), "") | U10: =IF(O10="","", IF(AND(O10=1, P10=0), "Fully Compliant", IF(AND(O10>=0.95, P10=0), "Compliant", IF(O10>=0.9, "Substantially Compliant", IF(O10>=0.8, "Partially Compliant", "Non-Compliant"))))) | W10: =IF(V10<>"", V10+90, "") | X10: [Security Analyst] | Z10: Not Started
O11: =IF(AND(J11>0,(J11-N11)>0), (K11+(L11*0.5))/(J11-N11), "") | U11: =IF(O11="","", IF(AND(O11=1, P11=0), "Fully Compliant", IF(AND(O11>=0.95, P11=0), "Compliant", IF(O11>=0.9, "Substantially Compliant", IF(O11>=0.8, "Partially Compliant", "Non-Compliant"))))) | W11: =IF(V11<>"", V11+90, "") | X11: [Security Analyst] | Z11: Not Started
O12: =IF(AND(J12>0,(J12-N12)>0), (K12+(L12*0.5))/(J12-N12), "") | U12: =IF(O12="","", IF(AND(O12=1, P12=0), "Fully Compliant", IF(AND(O12>=0.95, P12=0), "Compliant", IF(O12>=0.9, "Substantially Compliant", IF(O12>=0.8, "Partially Compliant", "Non-Compliant"))))) | W12: =IF(V12<>"", V12+90, "") | X12: [Security Analyst] | Z12: Not Started
O13: =IF(AND(J13>0,(J13-N13)>0), (K13+(L13*0.5))/(J13-N13), "") | U13: =IF(O13="","", IF(AND(O13=1, P13=0), "Fully Compliant", IF(AND(O13>=0.95, P13=0), "Compliant", IF(O13>=0.9, "Substantially Compliant", IF(O13>=0.8, "Partially Compliant", "Non-Compliant"))))) | W13: =IF(V13<>"", V13+90, "") | X13: [Security Analyst] | Z13: Not Started
... O101: =IF(AND(J101>0,(J101-N101)>0), (K101+(L101*0.5))/(J101-N101), "") | U101: =IF(O101="","", IF(AND(O101=1, P101=0), "Fully Compliant", IF(AND(O101>=0.95, P101=0), "Compliant", IF(O101>=0.9, "Substantially Compliant", IF(O101>=0.8, "Partially Compliant", "Non-Compliant"))))) | W101: =IF(V101<>"", V101+90, "") | X101: [Security Analyst] | Z101: Not Started

Sheet Control_Compliance_Detail
A1: Control_ID | B1: Asset_ID | C1: Asset_Name | D1: Standard_ID | E1: Standard_Name | F1: Control_Number | G1: Control_Title | H1: Control_Description | I1: Control_Category | J1: Control_Severity | K1: Implementation_Status | L1: Implementation_Method | M1: Implementation_Evidence | N1: Configuration_Setting | O1: Expected_Value | P1: Actual_Value | Q1: Compliance_Status | R1: Gap_Description | S1: Gap_Risk_Rating | T1: Remediation_Required | U1: Remediation_Plan | V1: Remediation_Owner | W1: Target_Remediation_Date | X1: Exception_Status | Y1: Exception_ID | Z1: Compensating_Control | AA1: Last_Verified_Date | AB1: Verified_By | AC1: Evidence_Reference | AD1: Verification_Method | AE1: Next_Verification_Date | AF1: Notes
A2: =IF(B2<>"", "HC-"&TEXT(ROW()-1,"00000"), "") | Q2: =IF(K2="", "", IF(K2="Implemented", "Pass", IF(K2="Partial", "Partial", IF(K2="Not Applicable", "N/A", "Fail")))) | T2: =IF(Q2="", "", IF(OR(Q2="Fail", Q2="Partial"), "Yes", "No")) | X2: No | AB2: [Security Analyst] | AE2: =IF(AA2<>"", AA2+90, "")
A3: =IF(B3<>"", "HC-"&TEXT(ROW()-1,"00000"), "") | Q3: =IF(K3="", "", IF(K3="Implemented", "Pass", IF(K3="Partial", "Partial", IF(K3="Not Applicable", "N/A", "Fail")))) | T3: =IF(Q3="", "", IF(OR(Q3="Fail", Q3="Partial"), "Yes", "No")) | X3: No | AB3: [Security Analyst] | AE3: =IF(AA3<>"", AA3+90, "")
A4: =IF(B4<>"", "HC-"&TEXT(ROW()-1,"00000"), "") | Q4: =IF(K4="", "", IF(K4="Implemented", "Pass", IF(K4="Partial", "Partial", IF(K4="Not Applicable", "N/A", "Fail")))) | T4: =IF(Q4="", "", IF(OR(Q4="Fail", Q4="Partial"), "Yes", "No")) | X4: No | AB4: [Security Analyst] | AE4: =IF(AA4<>"", AA4+90, "")
A5: =IF(B5<>"", "HC-"&TEXT(ROW()-1,"00000"), "") | Q5: =IF(K5="", "", IF(K5="Implemented", "Pass", IF(K5="Partial", "Partial", IF(K5="Not Applicable", "N/A", "Fail")))) | T5: =IF(Q5="", "", IF(OR(Q5="Fail", Q5="Partial"), "Yes", "No")) | X5: No | AB5: [Security Analyst] | AE5: =IF(AA5<>"", AA5+90, "")
A6: =IF(B6<>"", "HC-"&TEXT(ROW()-1,"00000"), "") | Q6: =IF(K6="", "", IF(K6="Implemented", "Pass", IF(K6="Partial", "Partial", IF(K6="Not Applicable", "N/A", "Fail")))) | T6: =IF(Q6="", "", IF(OR(Q6="Fail", Q6="Partial"), "Yes", "No")) | X6: No | AB6: [Security Analyst] | AE6: =IF(AA6<>"", AA6+90, "")
A7: =IF(B7<>"", "HC-"&TEXT(ROW()-1,"00000"), "") | Q7: =IF(K7="", "", IF(K7="Implemented", "Pass", IF(K7="Partial", "Partial", IF(K7="Not Applicable", "N/A", "Fail")))) | T7: =IF(Q7="", "", IF(OR(Q7="Fail", Q7="Partial"), "Yes", "No")) | X7: No | AB7: [Security Analyst] | AE7: =IF(AA7<>"", AA7+90, "")
A8: =IF(B8<>"", "HC-"&TEXT(ROW()-1,"00000"), "") | Q8: =IF(K8="", "", IF(K8="Implemented", "Pass", IF(K8="Partial", "Partial", IF(K8="Not Applicable", "N/A", "Fail")))) | T8: =IF(Q8="", "", IF(OR(Q8="Fail", Q8="Partial"), "Yes", "No")) | X8: No | AB8: [Security Analyst] | AE8: =IF(AA8<>"", AA8+90, "")
A9: =IF(B9<>"", "HC-"&TEXT(ROW()-1,"00000"), "") | Q9: =IF(K9="", "", IF(K9="Implemented", "Pass", IF(K9="Partial", "Partial", IF(K9="Not Applicable", "N/A", "Fail")))) | T9: =IF(Q9="", "", IF(OR(Q9="Fail", Q9="Partial"), "Yes", "No")) | X9: No | AB9: [Security Analyst] | AE9: =IF(AA9<>"", AA9+90, "")
A10: =IF(B10<>"", "HC-"&TEXT(ROW()-1,"00000"), "") | Q10: =IF(K10="", "", IF(K10="Implemented", "Pass", IF(K10="Partial", "Partial", IF(K10="Not Applicable", "N/A", "Fail")))) | T10: =IF(Q10="", "", IF(OR(Q10="Fail", Q10="Partial"), "Yes", "No")) | X10: No | AB10: [Security Analyst] | AE10: =IF(AA10<>"", AA10+90, "")
A11: =IF(B11<>"", "HC-"&TEXT(ROW()-1,"00000"), "") | Q11: =IF(K11="", "", IF(K11="Implemented", "Pass", IF(K11="Partial", "Partial", IF(K11="Not Applicable", "N/A", "Fail")))) | T11: =IF(Q11="", "", IF(OR(Q11="Fail", Q11="Partial"), "Yes", "No")) | X11: No | AB11: [Security Analyst] | AE11: =IF(AA11<>"", AA11+90, "")
A12: =IF(B12<>"", "HC-"&TEXT(ROW()-1,"00000"), "") | Q12: =IF(K12="", "", IF(K12="Implemented", "Pass", IF(K12="Partial", "Partial", IF(K12="Not Applicable", "N/A", "Fail")))) | T12: =IF(Q12="", "", IF(OR(Q12="Fail", Q12="Partial"), "Yes", "No")) | X12: No | AB12: [Security Analyst] | AE12: =IF(AA12<>"", AA12+90, "")
A13: =IF(B13<>"", "HC-"&TEXT(ROW()-1,"00000"), "") | Q13: =IF(K13="", "", IF(K13="Implemented", "Pass", IF(K13="Partial", "Partial", IF(K13="Not Applicable", "N/A", "Fail")))) | T13: =IF(Q13="", "", IF(OR(Q13="Fail", Q13="Partial"), "Yes", "No")) | X13: No | AB13: [Security Analyst] | AE13: =IF(AA13<>"", AA13+90, "")
... A501: =IF(B501<>"", "HC-"&TEXT(ROW()-1,"00000"), "") | Q501: =IF(K501="", "", IF(K501="Implemented", "Pass", IF(K501="Partial", "Partial", IF(K501="Not Applicable", "N/A", "Fail")))) | T501: =IF(Q501="", "", IF(OR(Q501="Fail", Q501="Partial"), "Yes", "No")) | X501: No | AB501: [Security Analyst] | AE501: =IF(AA501<>"", AA501+90, "")

Sheet Exception_Management
A1: Exception_ID | B1: Control_ID | C1: Asset_ID | D1: Asset_Name | E1: Standard_ID | F1: Control_Number | G1: Control_Title | H1: Control_Severity | I1: Exception_Type | J1: Exception_Reason | K1: Business_Justification | L1: Risk_Assessment | M1: Residual_Risk_Rating | N1: Compensating_Control_Required | O1: Compensating_Control_Description | P1: Compensating_Control_Effectiveness | Q1: Requested_By | R1: Request_Date | S1: Reviewed_By | T1: Review_Date | U1: Approved_By | V1: Approval_Date | W1: Exception_Status | X1: Exception_Duration | Y1: Valid_From_Date | Z1: Valid_Until_Date | AA1: Days_Until_Expiry | AB1: Review_Required | AC1: Last_Review_Date | AD1: Next_Review_Date | AE1: Audit_Trail | AF1: Monitoring_Required | AG1: Monitoring_Description | AH1: Re_Assessment_Trigger | AI1: Exception_Closure_Plan | AJ1: Documentation_Reference | AK1: Notes
A2: =IF(B2<>"", "EXC-"&TEXT(ROW()-1,"000"), "") | N2: Yes | W2: Pending Review | Z2: =IF(AND(Y2<>"", X2<>""), IF(X2="3 Months", Y2+90, IF(X2="6 Months", Y2+180, IF(X2="12 Months", Y2+365, IF(X2="24 Months", Y2+730, Y2+365)))), "") | AA2: =IF(Z2<>"", Z2-TODAY(), "") | AB2: =IF(AA2="", "", IF(AA2<30, "Yes - Expiring Soon", IF(AD2<TODAY()+30, "Yes - Periodic Review Due", "No"))) | AD2: =IF(AND(Y2<>"", Z2<>""), Y2+((Z2-Y2)/2), "") | AF2: Yes
A3: =IF(B3<>"", "EXC-"&TEXT(ROW()-1,"000"), "") | N3: Yes | W3: Pending Review | Z3: =IF(AND(Y3<>"", X3<>""), IF(X3="3 Months", Y3+90, IF(X3="6 Months", Y3+180, IF(X3="12 Months", Y3+365, IF(X3="24 Months", Y3+730, Y3+365)))), "") | AA3: =IF(Z3<>"", Z3-TODAY(), "") | AB3: =IF(AA3="", "", IF(AA3<30, "Yes - Expiring Soon", IF(AD3<TODAY()+30, "Yes - Periodic Review Due", "No"))) | AD3: =IF(AND(Y3<>"", Z3<>""), Y3+((Z3-Y3)/2), "") | AF3: Yes
A4: =IF(B4<>"", "EXC-"&TEXT(ROW()-1,"000"), "") | N4: Yes | W4: Pending Review | Z4: =IF(AND(Y4<>"", X4<>""), IF(X4="3 Months", Y4+90, IF(X4="6 Months", Y4+180, IF(X4="12 Months", Y4+365, IF(X4="24 Months", Y4+730, Y4+365)))), "") | AA4: =IF(Z4<>"", Z4-TODAY(), "") | AB4: =IF(AA4="", "", IF(AA4<30, "Yes - Expiring Soon", IF(AD4<TODAY()+30, "Yes - Periodic Review Due", "No"))) | AD4: =IF(AND(Y4<>"", Z4<>""), Y4+((Z4-Y4)/2), "") | AF4: Yes
A5: =IF(B5<>"", "EXC-"&TEXT(ROW()-1,"000"), "") | N5: Yes | W5: Pending Review | Z5: =IF(AND(Y5<>"", X5<>""), IF(X5="3 Months", Y5+90, IF(X5="6 Months", Y5+180, IF(X5="12 Months", Y5+365, IF(X5="24 Months", Y5+730, Y5+365)))), "") | AA5: =IF(Z5<>"", Z5-TODAY(), "") | AB5: =IF(AA5="", "", IF(AA5<30, "Yes - Expiring Soon", IF(AD5<TODAY()+30, "Yes - Periodic Review Due", "No"))) | AD5: =IF(AND(Y5<>"", Z5<>""), Y5+((Z5-Y5)/2), "") | AF5: Yes
A6: =IF(B6<>"", "EXC-"&TEXT(ROW()-1,"000"), "") | N6: Yes | W6: Pending Review | Z6: =IF(AND(Y6<>"", X6<>""), IF(X6="3 Months", Y6+90, IF(X6="6 Months", Y6+180, IF(X6="12 Months", Y6+365, IF(X6="24 Months", Y6+730, Y6+365)))), "") | AA6: =IF(Z6<>"", Z6-TODAY(), "") | AB6: =IF(AA6="", "", IF(AA6<30, "Yes - Expiring Soon", IF(AD6<TODAY()+30, "Yes - Periodic Review Due", "No"))) | AD6: =IF(AND(Y6<>"", Z6<>""), Y6+((Z6-Y6)/2), "") | AF6: Yes
A7: =IF(B7<>"", "EXC-"&TEXT(ROW()-1,"000"), "") | N7: Yes | W7: Pending Review | Z7: =IF(AND(Y7<>"", X7<>""), IF(X7="3 Months", Y7+90, IF(X7="6 Months", Y7+180, IF(X7="12 Months", Y7+365, IF(X7="24 Months", Y7+730, Y7+365)))), "") | AA7: =IF(Z7<>"", Z7-TODAY(), "") | AB7: =IF(AA7="", "", IF(AA7<30, "Yes - Expiring Soon", IF(AD7<TODAY()+30, "Yes - Periodic Review Due", "No"))) | AD7: =IF(AND(Y7<>"", Z7<>""), Y7+((Z7-Y7)/2), "") | AF7: Yes
A8: =IF(B8<>"", "EXC-"&TEXT(ROW()-1,"000"), "") | N8: Yes | W8: Pending Review | Z8: =IF(AND(Y8<>"", X8<>""), IF(X8="3 Months", Y8+90, IF(X8="6 Months", Y8+180, IF(X8="12 Months", Y8+365, IF(X8="24 Months", Y8+730, Y8+365)))), "") | AA8: =IF(Z8<>"", Z8-TODAY(), "") | AB8: =IF(AA8="", "", IF(AA8<30, "Yes - Expiring Soon", IF(AD8<TODAY()+30, "Yes - Periodic Review Due", "No"))) | AD8: =IF(AND(Y8<>"", Z8<>""), Y8+((Z8-Y8)/2), "") | AF8: Yes
A9: =IF(B9<>"", "EXC-"&TEXT(ROW()-1,"000"), "") | N9: Yes | W9: Pending Review | Z9: =IF(AND(Y9<>"", X9<>""), IF(X9="3 Months", Y9+90, IF(X9="6 Months", Y9+180, IF(X9="12 Months", Y9+365, IF(X9="24 Months", Y9+730, Y9+365)))), "") | AA9: =IF(Z9<>"", Z9-TODAY(), "") | AB9: =IF(AA9="", "", IF(AA9<30, "Yes - Expiring Soon", IF(AD9<TODAY()+30, "Yes - Periodic Review Due", "No"))) | AD9: =IF(AND(Y9<>"", Z9<>""), Y9+((Z9-Y9)/2), "") | AF9: Yes
A10: =IF(B10<>"", "EXC-"&TEXT(ROW()-1,"000"), "") | N10: Yes | W10: Pending Review | Z10: =IF(AND(Y10<>"", X10<>""), IF(X10="3 Months", Y10+90, IF(X10="6 Months", Y10+180, IF(X10="12 Months", Y10+365, IF(X10="24 Months", Y10+730, Y10+365)))), "") | AA10: =IF(Z10<>"", Z10-TODAY(), "") | AB10: =IF(AA10="", "", IF(AA10<30, "Yes - Expiring Soon", IF(AD10<TODAY()+30, "Yes - Periodic Review Due", "No"))) | AD10: =IF(AND(Y10<>"", Z10<>""), Y10+((Z10-Y10)/2), "") | AF10: Yes
A11: =IF(B11<>"", "EXC-"&TEXT(ROW()-1,"000"), "") | N11: Yes | W11: Pending Review | Z11: =IF(AND(Y11<>"", X11<>""), IF(X11="3 Months", Y11+90, IF(X11="6 Months", Y11+180, IF(X11="12 Months", Y11+365, IF(X11="24 Months", Y11+730, Y11+365)))), "") | AA11: =IF(Z11<>"", Z11-TODAY(), "") | AB11: =IF(AA11="", "", IF(AA11<30, "Yes - Expiring Soon", IF(AD11<TODAY()+30, "Yes - Periodic Review Due", "No"))) | AD11: =IF(AND(Y11<>"", Z11<>""), Y11+((Z11-Y11)/2), "") | AF11: Yes
A12: =IF(B12<>"", "EXC-"&TEXT(ROW()-1,"000"), "") | N12: Yes | W12: Pending Review | Z12: =IF(AND(Y12<>"", X12<>""), IF(X12="3 Months", Y12+90, IF(X12="6 Months", Y12+180, IF(X12="12 Months", Y12+365, IF(X12="24 Months", Y12+730, Y12+365)))), "") | AA12: =IF(Z12<>"", Z12-TODAY(), "") | AB12: =IF(AA12="", "", IF(AA12<30, "Yes - Expiring Soon", IF(AD12<TODAY()+30, "Yes - Periodic Review Due", "No"))) | AD12: =IF(AND(Y12<>"", Z12<>""), Y12+((Z12-Y12)/2), "") | AF12: Yes
A13: =IF(B13<>"", "EXC-"&TEXT(ROW()-1,"000"), "") | N13: Yes | W13: Pending Review | Z13: =IF(AND(Y13<>"", X13<>""), IF(X13="3 Months", Y13+90, IF(X13="6 Months", Y13+180, IF(X13="12 Months", Y13+365, IF(X13="24 Months", Y13+730, Y13+365)))), "") | AA13: =IF(Z13<>"", Z13-TODAY(), "") | AB13: =IF(AA13="", "", IF(AA13<30, "Yes - Expiring Soon", IF(AD13<TODAY()+30, "Yes - Periodic Review Due", "No"))) | AD13: =IF(AND(Y13<>"", Z13<>""), Y13+((Z13-Y13)/2), "") | AF13: Yes
... A51: =IF(B51<>"", "EXC-"&TEXT(ROW()-1,"000"), "") | N51: Yes | W51: Pending Review | Z51: =IF(AND(Y51<>"", X51<>""), IF(X51="3 Months", Y51+90, IF(X51="6 Months", Y51+180, IF(X51="12 Months", Y51+365, IF(X51="24 Months", Y51+730, Y51+365)))), "") | AA51: =IF(Z51<>"", Z51-TODAY(), "") | AB51: =IF(AA51="", "", IF(AA51<30, "Yes - Expiring Soon", IF(AD51<TODAY()+30, "Yes - Periodic Review Due", "No"))) | AD51: =IF(AND(Y51<>"", Z51<>""), Y51+((Z51-Y51)/2), "") | AF51: Yes

Sheet Remediation_Tracking
A1: Remediation_ID | B1: Gap_Type | C1: Control_ID | D1: Asset_ID | E1: Asset_Name | F1: Asset_Tier | G1: Standard_ID | H1: Control_Number | I1: Control_Title | J1: Control_Severity | K1: Gap_Description | L1: Gap_Risk_Rating | M1: Impact_Assessment | N1: Discovery_Date | O1: Discovery_Method | P1: Remediation_Required | Q1: Remediation_Strategy | R1: Remediation_Description | S1: Remediation_Owner | T1: Remediation_Team | U1: Estimated_Effort | V1: Estimated_Cost | W1: Dependencies | X1: Remediation_Priority | Y1: Target_Start_Date | Z1: Target_Completion_Date | AA1: Actual_Start_Date | AB1: Actual_Completion_Date | AC1: Days_To_Remediate | AD1: Days_Overdue | AE1: Status | AF1: Status_Notes | AG1: Completion_Percentage | AH1: Blocker_Description | AI1: Verification_Required | AJ1: Verification_Method | AK1: Verified_By | AL1: Verification_Date | AM1: Verification_Result | AN1: Re_Test_Required | AO1: Change_Request_ID | AP1: Risk_Acceptance_ID | AQ1: Evidence_Reference | AR1: Lessons_Learned | AS1: Preventive_Action | AT1: Closure_Date | AU1: Approved_By | AV1: Notes
A2: =IF(B2<>"", "REM-"&TEXT(ROW()-1,"000"), "") | P2: Yes | X2: =IF(L2="", "", IF(L2="Critical", "Critical", IF(AND(L2="High", F2="Critical"), "Critical", IF(L2="High", "High", IF(L2="Medium", "Medium", "Low"))))) | Z2: =IF(AND(N2<>"", X2<>""), IF(X2="Critical", N2+3, IF(X2="High", N2+7, IF(X2="Medium", N2+30, N2+90))), "") | AC2: =IF(AND(AA2<>"", AB2<>""), AB2-AA2, "") | AD2: =IF(AE2="", "", IF(OR(AE2="Completed", AE2="Closed - Fixed", AE2="Closed - Exception"), 0, IF(AND(Z2<>"", TODAY()>Z2), TODAY()-Z2, 0))) | AE2: Identified | AG2: 0 | AI2: Yes | AN2: No
A3: =IF(B3<>"", "REM-"&TEXT(ROW()-1,"000"), "") | P3: Yes | X3: =IF(L3="", "", IF(L3="Critical", "Critical", IF(AND(L3="High", F3="Critical"), "Critical", IF(L3="High", "High", IF(L3="Medium", "Medium", "Low"))))) | Z3: =IF(AND(N3<>"", X3<>""), IF(X3="Critical", N3+3, IF(X3="High", N3+7, IF(X3="Medium", N3+30, N3+90))), "") | AC3: =IF(AND(AA3<>"", AB3<>""), AB3-AA3, "") | AD3: =IF(AE3="", "", IF(OR(AE3="Completed", AE3="Closed - Fixed", AE3="Closed - Exception"), 0, IF(AND(Z3<>"", TODAY()>Z3), TODAY()-Z3, 0))) | AE3: Identified | AG3: 0 | AI3: Yes | AN3: No
A4: =IF(B4<>"", "REM-"&TEXT(ROW()-1,"000"), "") | P4: Yes | X4: =IF(L4="", "", IF(L4="Critical", "Critical", IF(AND(L4="High", F4="Critical"), "Critical", IF(L4="High", "High", IF(L4="Medium", "Medium", "Low"))))) | Z4: =IF(AND(N4<>"", X4<>""), IF(X4="Critical", N4+3, IF(X4="High", N4+7, IF(X4="Medium", N4+30, N4+90))), "") | AC4: =IF(AND(AA4<>"", AB4<>""), AB4-AA4, "") | AD4: =IF(AE4="", "", IF(OR(AE4="Completed", AE4="Closed - Fixed", AE4="Closed - Exception"), 0, IF(AND(Z4<>"", TODAY()>Z4), TODAY()-Z4, 0))) | AE4: Identified | AG4: 0 | AI4: Yes | AN4: No
A5: =IF(B5<>"", "REM-"&TEXT(ROW()-1,"000"), "") | P5: Yes | X5: =IF(L5="", "", IF(L5="Critical", "Critical", IF(AND(L5="High", F5="Critical"), "Critical", IF(L5="High", "High", IF(L5="Medium", "Medium", "Low"))))) | Z5: =IF(AND(N5<>"", X5<>""), IF(X5="Critical", N5+3, IF(X5="High", N5+7, IF(X5="Medium", N5+30, N5+90))), "") | AC5: =IF(AND(AA5<>"", AB5<>""), AB5-AA5, "") | AD5: =IF(AE5="", "", IF(OR(AE5="Completed", AE5="Closed - Fixed", AE5="Closed - Exception"), 0, IF(AND(Z5<>"", TODAY()>Z5), TODAY()-Z5, 0))) | AE5: Identified | AG5: 0 | AI5: Yes | AN5: No
A6: =IF(B6<>"", "REM-"&TEXT(ROW()-1,"000"), "") | P6: Yes | X6: =IF(L6="", "", IF(L6="Critical", "Critical", IF(AND(L6="High", F6="Critical"), "Critical", IF(L6="High", "High", IF(L6="Medium", "Medium", "Low"))))) | Z6: =IF(AND(N6<>"", X6<>""), IF(X6="Critical", N6+3, IF(X6="High", N6+7, IF(X6="Medium", N6+30, N6+90))), "") | AC6: =IF(AND(AA6<>"", AB6<>""), AB6-AA6, "") | AD6: =IF(AE6="", "", IF(OR(AE6="Completed", AE6="Closed - Fixed", AE6="Closed - Exception"), 0, IF(AND(Z6<>"", TODAY()>Z6), TODAY()-Z6, 0))) | AE6: Identified | AG6: 0 | AI6: Yes | AN6: No
A7: =IF(B7<>"", "REM-"&TEXT(ROW()-1,"000"), "") | P7: Yes | X7: =IF(L7="", "", IF(L7="Critical", "Critical", IF(AND(L7="High", F7="Critical"), "Critical", IF(L7="High", "High", IF(L7="Medium", "Medium", "Low"))))) | Z7: =IF(AND(N7<>"", X7<>""), IF(X7="Critical", N7+3, IF(X7="High", N7+7, IF(X7="Medium", N7+30, N7+90))), "") | AC7: =IF(AND(AA7<>"", AB7<>""), AB7-AA7, "") | AD7: =IF(AE7="", "", IF(OR(AE7="Completed", AE7="Closed - Fixed", AE7="Closed - Exception"), 0, IF(AND(Z7<>"", TODAY()>Z7), TODAY()-Z7, 0))) | AE7: Identified | AG7: 0 | AI7: Yes | AN7: No
A8: =IF(B8<>"", "REM-"&TEXT(ROW()-1,"000"), "") | P8: Yes | X8: =IF(L8="", "", IF(L8="Critical", "Critical", IF(AND(L8="High", F8="Critical"), "Critical", IF(L8="High", "High", IF(L8="Medium", "Medium", "Low"))))) | Z8: =IF(AND(N8<>"", X8<>""), IF(X8="Critical", N8+3, IF(X8="High", N8+7, IF(X8="Medium", N8+30, N8+90))), "") | AC8: =IF(AND(AA8<>"", AB8<>""), AB8-AA8, "") | AD8: =IF(AE8="", "", IF(OR(AE8="Completed", AE8="Closed - Fixed", AE8="Closed - Exception"), 0, IF(AND(Z8<>"", TODAY()>Z8), TODAY()-Z8, 0))) | AE8: Identified | AG8: 0 | AI8: Yes | AN8: No
A9: =IF(B9<>"", "REM-"&TEXT(ROW()-1,"000"), "") | P9: Yes | X9: =IF(L9="", "", IF(L9="Critical", "Critical", IF(AND(L9="High", F9="Critical"), "Critical", IF(L9="High", "High", IF(L9="Medium", "Medium", "Low"))))) | Z9: =IF(AND(N9<>"", X9<>""), IF(X9="Critical", N9+3, IF(X9="High", N9+7, IF(X9="Medium", N9+30, N9+90))), "") | AC9: =IF(AND(AA9<>"", AB9<>""), AB9-AA9, "") | AD9: =IF(AE9="", "", IF(OR(AE9="Completed", AE9="Closed - Fixed", AE9="Closed - Exception"), 0, IF(AND(Z9<>"", TODAY()>Z9), TODAY()-Z9, 0))) | AE9: Identified | AG9: 0 | AI9: Yes | AN9: No
A10: =IF(B10<>"", "REM-"&TEXT(ROW()-1,"000"), "") | P10: Yes | X10: =IF(L10="", "", IF(L10="Critical", "Critical", IF(AND(L10="High", F10="Critical"), "Critical", IF(L10="High", "High", IF(L10="Medium", "Medium", "Low"))))) | Z10: =IF(AND(N10<>"", X10<>""), IF(X10="Critical", N10+3, IF(X10="High", N10+7, IF(X10="Medium", N10+30, N10+90))), "") | AC10: =IF(AND(AA10<>"", AB10<>""), AB10-AA10, "") | AD10: =IF(AE10="", "", IF(OR(AE10="Completed", AE10="Closed - Fixed", AE10="Closed - Exception"), 0, IF(AND(Z10<>"", TODAY()>Z10), TODAY()-Z10, 0))) | AE10: Identified | AG10: 0 | AI10: Yes | AN10: No
A11: =IF(B11<>"", "REM-"&TEXT(ROW()-1,"000"), "") | P11: Yes | X11: =IF(L11="", "", IF(L11="Critical", "Critical", IF(AND(L11="High", F11="Critical"), "Critical", IF(L11="High", "High", IF(L11="Medium", "Medium", "Low"))))) | Z11: =IF(AND(N11<>"", X11<>""), IF(X11="Critical", N11+3, IF(X11="High", N11+7, IF(X11="Medium", N11+30, N11+90))), "") | AC11: =IF(AND(AA11<>"", AB11<>""), AB11-AA11, "") | AD11: =IF(AE11="", "", IF(OR(AE11="Completed", AE11="Closed - Fixed", AE11="Closed - Exception"), 0, IF(AND(Z11<>"", TODAY()>Z11), TODAY()-Z11, 0))) | AE11: Identified | AG11: 0 | AI11: Yes | AN11: No
A12: =IF(B12<>"", "REM-"&TEXT(ROW()-1,"000"), "") | P12: Yes | X12: =IF(L12="", "", IF(L12="Critical", "Critical", IF(AND(L12="High", F12="Critical"), "Critical", IF(L12="High", "High", IF(L12="Medium", "Medium", "Low"))))) | Z12: =IF(AND(N12<>"", X12<>""), IF(X12="Critical", N12+3, IF(X12="High", N12+7, IF(X12="Medium", N12+30, N12+90))), "") | AC12: =IF(AND(AA12<>"", AB12<>""), AB12-AA12, "") | AD12: =IF(AE12="", "", IF(OR(AE12="Completed", AE12="Closed - Fixed", AE12="Closed - Exception"), 0, IF(AND(Z12<>"", TODAY()>Z12), TODAY()-Z12, 0))) | AE12: Identified | AG12: 0 | AI12: Yes | AN12: No
A13: =IF(B13<>"", "REM-"&TEXT(ROW()-1,"000"), "") | P13: Yes | X13: =IF(L13="", "", IF(L13="Critical", "Critical", IF(AND(L13="High", F13="Critical"), "Critical", IF(L13="High", "High", IF(L13="Medium", "Medium", "Low"))))) | Z13: =IF(AND(N13<>"", X13<>""), IF(X13="Critical", N13+3, IF(X13="High", N13+7, IF(X13="Medium", N13+30, N13+90))), "") | AC13: =IF(AND(AA13<>"", AB13<>""), AB13-AA13, "") | AD13: =IF(AE13="", "", IF(OR(AE13="Completed", AE13="Closed - Fixed", AE13="Closed - Exception"), 0, IF(AND(Z13<>"", TODAY()>Z13), TODAY()-Z13, 0))) | AE13: Identified | AG13: 0 | AI13: Yes | AN13: No
... A101: =IF(B101<>"", "REM-"&TEXT(ROW()-1,"000"), "") | P101: Yes | X101: =IF(L101="", "", IF(L101="Critical", "Critical", IF(AND(L101="High", F101="Critical"), "Critical", IF(L101="High", "High", IF(L101="Medium", "Medium", "Low"))))) | Z101: =IF(AND(N101<>"", X101<>""), IF(X101="Critical", N101+3, IF(X101="High", N101+7, IF(X101="Medium", N101+30, N101+90))), "") | AC101: =IF(AND(AA101<>"", AB101<>""), AB101-AA101, "") | AD101: =IF(AE101="", "", IF(OR(AE101="Completed", AE101="Closed - Fixed", AE101="Closed - Exception"), 0, IF(AND(Z101<>"", TODAY()>Z101), TODAY()-Z101, 0))) | AE101: Identified | AG101: 0 | AI101: Yes | AN101: No

Sheet Compliance_Dashboard
A1: Security Hardening Compliance Dashboard
A2: Assessment Date: 08.02.2026
A4: OVERALL COMPLIANCE SUMMARY
A5: Overall Compliance Percentage | B5: =AVERAGE(Asset_Hardening_Assessment!O:O) | C5: Target | D5: 95%
A6: Total Assets Assessed | B6: =COUNTA(Asset_Hardening_Assessment!A:A)-1
A7: Fully Compliant Assets | B7: =COUNTIF(Asset_Hardening_Assessment!U:U,"Fully Compliant") | C7: Percentage | D7: =B7/B6
A8: Non-Compliant Assets | B8: =COUNTIF(Asset_Hardening_Assessment!U:U,"Non-Compliant") | C8: Target | D8: 0
A9: Total Applicable Controls | B9: =SUM(Asset_Hardening_Assessment!J:J)
A10: Implemented Controls | B10: =SUM(Asset_Hardening_Assessment!K:K)
A11: Total Gaps (Not Implemented) | B11: =SUM(Asset_Hardening_Assessment!M:M) | C11: Target | D11: 0
A12: High-Risk Gaps | B12: =SUM(Asset_Hardening_Assessment!P:P) | C12: Target | D12: 0
A13: Active Exceptions | B13: =COUNTIF(Exception_Management!W:W,"Approved") | C13: Target | D13: =B5*0.05
A14: Open Remediation Items | B14: =COUNTIFS(Remediation_Tracking!AE:AE,"<>Completed",Remediation_Tracking!AE:AE,"<>Closed - Fixed",Remediation_Tracking!AE:AE,"<>Closed - Exception")
A16: COMPLIANCE BY ASSET TIER
A17: Asset Tier | B17: Asset Count | C17: Avg Compliance % | D17: Status
A18: Critical | B18: =COUNTIF(Asset_Hardening_Assessment!D:D,"Critical") | C18: =AVERAGEIF(Asset_Hardening_Assessment!D:D,"Critical",Asset_Hardening_Assessment!O:O) | D18: =IF(C18="", "", IF(AND(C18>=1.0, COUNTIFS(Asset_Hardening_Assessment!D:D,"Critical",Asset_Hardening_Assessment!U:U,"Non-Compliant")=0), "Green", IF(C18>=0.9, "Yellow", "Red")))
A19: High | B19: =COUNTIF(Asset_Hardening_Assessment!D:D,"High") | C19: =AVERAGEIF(Asset_Hardening_Assessment!D:D,"High",Asset_Hardening_Assessment!O:O) | D19: =IF(C19="", "", IF(AND(C19>=0.98, COUNTIFS(Asset_Hardening_Assessment!D:D,"High",Asset_Hardening_Assessment!U:U,"Non-Compliant")=0), "Green", IF(C19>=0.9, "Yellow", "Red")))
A20: Medium | B20: =COUNTIF(Asset_Hardening_Assessment!D:D,"Medium") | C20: =AVERAGEIF(Asset_Hardening_Assessment!D:D,"Medium",Asset_Hardening_Assessment!O:O) | D20: =IF(C20="", "", IF(AND(C20>=0.95, COUNTIFS(Asset_Hardening_Assessment!D:D,"Medium",Asset_Hardening_Assessment!U:U,"Non-Compliant")=0), "Green", IF(C20>=0.9, "Yellow", "Red")))
A21: Low | B21: =COUNTIF(Asset_Hardening_Assessment!D:D,"Low") | C21: =AVERAGEIF(Asset_Hardening_Assessment!D:D,"Low",Asset_Hardening_Assessment!O:O) | D21: =IF(C21="", "", IF(AND(C21>=0.9, COUNTIFS(Asset_Hardening_Assessment!D:D,"Low",Asset_Hardening_Assessment!U:U,"Non-Compliant")=0), "Green", IF(C21>=0.9, "Yellow", "Red")))
A23: REMEDIATION PROGRESS
A24: Total Gaps Identified | B24: =COUNTA(Remediation_Tracking!A:A)-1
A25: Gaps Closed | B25: =COUNTIFS(Remediation_Tracking!AE:AE,"Completed")+COUNTIF(Remediation_Tracking!AE:AE,"Closed - Fixed")
A26: Gap Closure Rate | B26: =IF(B24>0, B25/B24, "") | C26: Target | D26: ≥80%
A27: Mean Time to Remediate (MTTR) | B27: =AVERAGE(Remediation_Tracking!AC:AC) | C27: Target | D27: ≤14 days
A28: Overdue Remediations | B28: =COUNTIF(Remediation_Tracking!AD:AD,">0") | C28: Target | D28: 0
A29: Blocked Remediations | B29: =COUNTIF(Remediation_Tracking!AE:AE,"Blocked") | C29: Target | D29: 0
A30: Critical Gaps (Open) | B30: =COUNTIFS(Remediation_Tracking!L:L,"Critical",Remediation_Tracking!AE:AE,"<>Completed") | C30: Target | D30: 0
A31: High Gaps (Open) | B31: =COUNTIFS(Remediation_Tracking!L:L,"High",Remediation_Tracking!AE:AE,"<>Completed") | C31: Target | D31: ≤3
A33: EXCEPTION ANALYSIS
A34: Total Active Exceptions | B34: =COUNTIF(Exception_Management!W:W,"Approved")
A35: Exceptions Without Compensating Controls | B35: =COUNTIFS(Exception_Management!N:N,"No",Exception_Management!W:W,"Approved") | C35: Target | D35: 0
A36: Exceptions Expiring <30 Days | B36: =COUNTIFS(Exception_Management!AA:AA,"<30",Exception_Management!AA:AA,">=0")
A37: Expired Exceptions | B37: =COUNTIF(Exception_Management!AA:AA,"<0") | C37: Target | D37: 0
A38: High-Risk Exceptions (Residual Risk High/Critical) | B38: =COUNTIFS(Exception_Management!M:M,"High",Exception_Management!W:W,"Approved")+COUNTIFS(Exception_Management!M:M,"Critical",Exception_Management!W:W,"Approved") | C38: Target | D38: 0
A40: EVIDENCE COMPLETENESS
A41: Total Implemented Controls | B41: =COUNTIF(Control_Compliance_Detail!K:K,"Implemented")
A42: Controls With Evidence | B42: =COUNTIFS(Control_Compliance_Detail!K:K,"Implemented",Control_Compliance_Detail!AC:AC,"<>")
A43: Evidence Completeness % | B43: =IF(B41>0, B42/B41, "") | C43: Target | D43: ≥95%
A44: Missing Evidence (Critical Assets) | B44: =COUNTIFS(Control_Compliance_Detail!K:K,"Implemented",Asset_Hardening_Assessment!D:D,"Critical",Control_Compliance_Detail!AC:AC,"") | C44: Target | D44: 0
A46: NOTE: Trend analysis requires 3+ assessment cycles. Maintain historical data for meaningful insights.

Sheet Gap_Prioritization
A1: Priority_Rank | B1: Remediation_ID | C1: Asset_ID | D1: Asset_Name | E1: Asset_Tier | F1: Control_ID | G1: Control_Number | H1: Control_Title | I1: Standard_ID | J1: Control_Severity | K1: Gap_Risk_Rating | L1: Gap_Description | M1: Exploitation_Likelihood | N1: Impact_Assessment | O1: Risk_Score | P1: Priority_Category | Q1: Remediation_Owner | R1: Estimated_Effort | S1: Target_Completion_Date | T1: Days_Until_Target | U1: Status | V1: Dependencies | W1: Quick_Win | X1: Related_Gaps | Y1: Batch_Opportunity
A2: =IF(B2<>"", ROW()-1, "") | B2: =Remediation_Tracking!A2 | C2: =Remediation_Tracking!D2 | D2: =Remediation_Tracking!E2 | E2: =Remediation_Tracking!F2 | F2: =Remediation_Tracking!C2 | G2: =Remediation_Tracking!H2 | H2: =Remediation_Tracking!I2 | I2: =Remediation_Tracking!G2 | J2: =Remediation_Tracking!J2 | K2: =Remediation_Tracking!L2 | L2: =Remediation_Tracking!K2 | M2: Medium | N2: =Remediation_Tracking!M2 | O2: =IF(E2="", "", (IF(E2="Critical",5,IF(E2="High",4,IF(E2="Medium",3,2)))*10) + (IF(J2="Critical",5,IF(J2="High",4,IF(J2="Medium",3,2)))*8) + (IF(M2="Very High",5,IF(M2="High",4,IF(M2="Medium",3,IF(M2="Low",2,1))))*6) + (IF(T2<0, ABS(T2)/7*2, 0))) | P2: =IF(O2="", "", IF(AND(E2="Critical", OR(K2="Critical",K2="High"), T2<0), "P0 - Critical & Urgent", IF(AND(E2="Critical", OR(K2="Critical",K2="High")), "P1 - Critical", IF(OR(AND(E2="High",K2="High"),AND(E2="Critical",K2="Medium")), "P2 - High Priority", IF(OR(AND(E2="Medium",K2="High"),AND(E2="High",K2="Medium")), "P3 - Medium Priority", "P4 - Low Priority"))))) | Q2: =Remediation_Tracking!S2 | R2: =Remediation_Tracking!U2 | S2: =Remediation_Tracking!Z2 | T2: =IF(S2<>"", S2-TODAY(), "") | U2: =Remediation_Tracking!AE2 | V2: =Remediation_Tracking!W2 | W2: =IF(AND(OR(R2="<1 hour",R2="1-4 hours",R2="1 day"), OR(K2="Medium",K2="High",K2="Critical")), "Yes - Quick Win", "No")
A3: =IF(B3<>"", ROW()-1, "") | B3: =Remediation_Tracking!A3 | C3: =Remediation_Tracking!D3 | D3: =Remediation_Tracking!E3 | E3: =Remediation_Tracking!F3 | F3: =Remediation_Tracking!C3 | G3: =Remediation_Tracking!H3 | H3: =Remediation_Tracking!I3 | I3: =Remediation_Tracking!G3 | J3: =Remediation_Tracking!J3 | K3: =Remediation_Tracking!L3 | L3: =Remediation_Tracking!K3 | M3: Medium | N3: =Remediation_Tracking!M3 | O3: =IF(E3="", "", (IF(E3="Critical",5,IF(E3="High",4,IF(E3="Medium",3,2)))*10) + (IF(J3="Critical",5,IF(J3="High",4,IF(J3="Medium",3,2)))*8) + (IF(M3="Very High",5,IF(M3="High",4,IF(M3="Medium",3,IF(M3="Low",2,1))))*6) + (IF(T3<0, ABS(T3)/7*2, 0))) | P3: =IF(O3="", "", IF(AND(E3="Critical", OR(K3="Critical",K3="High"), T3<0), "P0 - Critical & Urgent", IF(AND(E3="Critical", OR(K3="Critical",K3="High")), "P1 - Critical", IF(OR(AND(E3="High",K3="High"),AND(E3="Critical",K3="Medium")), "P2 - High Priority", IF(OR(AND(E3="Medium",K3="High"),AND(E3="High",K3="Medium")), "P3 - Medium Priority", "P4 - Low Priority"))))) | Q3: =Remediation_Tracking!S3 | R3: =Remediation_Tracking!U3 | S3: =Remediation_Tracking!Z3 | T3: =IF(S3<>"", S3-TODAY(), "") | U3: =Remediation_Tracking!AE3 | V3: =Remediation_Tracking!W3 | W3: =IF(AND(OR(R3="<1 hour",R3="1-4 hours",R3="1 day"), OR(K3="Medium",K3="High",K3="Critical")), "Yes - Quick Win", "No")
A4: =IF(B4<>"", ROW()-1, "") | B4: =Remediation_Tracking!A4 | C4: =Remediation_Tracking!D4 | D4: =Remediation_Tracking!E4 | E4: =Remediation_Tracking!F4 | F4: =Remediation_Tracking!C4 | G4: =Remediation_Tracking!H4 | H4: =Remediation_Tracking!I4 | I4: =Remediation_Tracking!G4 | J4: =Remediation_Tracking!J4 | K4: =Remediation_Tracking!L4 | L4: =Remediation_Tracking!K4 | M4: Medium | N4: =Remediation_Tracking!M4 | O4: =IF(E4="", "", (IF(E4="Critical",5,IF(E4="High",4,IF(E4="Medium",3,2)))*10) + (IF(J4="Critical",5,IF(J4="High",4,IF(J4="Medium",3,2)))*8) + (IF(M4="Very High",5,IF(M4="High",4,IF(M4="Medium",3,IF(M4="Low",2,1))))*6) + (IF(T4<0, ABS(T4)/7*2, 0))) | P4: =IF(O4="", "", IF(AND(E4="Critical", OR(K4="Critical",K4="High"), T4<0), "P0 - Critical & Urgent", IF(AND(E4="Critical", OR(K4="Critical",K4="High")), "P1 - Critical", IF(OR(AND(E4="High",K4="High"),AND(E4="Critical",K4="Medium")), "P2 - High Priority", IF(OR(AND(E4="Medium",K4="High"),AND(E4="High",K4="Medium")), "P3 - Medium Priority", "P4 - Low Priority"))))) | Q4: =Remediation_Tracking!S4 | R4: =Remediation_Tracking!U4 | S4: =Remediation_Tracking!Z4 | T4: =IF(S4<>"", S4-TODAY(), "") | U4: =Remediation_Tracking!AE4 | V4: =Remediation_Tracking!W4 | W4: =IF(AND(OR(R4="<1 hour",R4="1-4 hours",R4="1 day"), OR(K4="Medium",K4="High",K4="Critical")), "Yes - Quick Win", "No")
A5: =IF(B5<>"", ROW()-1, "") | B5: =Remediation_Tracking!A5 | C5: =Remediation_Tracking!D5 | D5: =Remediation_Tracking!E5 | E5: =Remediation_Tracking!F5 | F5: =Remediation_Tracking!C5 | G5: =Remediation_Tracking!H5 | H5: =Remediation_Tracking!I5 | I5: =Remediation_Tracking!G5 | J5: =Remediation_Tracking!J5 | K5: =Remediation_Tracking!L5 | L5: =Remediation_Tracking!K5 | M5: Medium | N5: =Remediation_Tracking!M5 | O5: =IF(E5="", "", (IF(E5="Critical",5,IF(E5="High",4,IF(E5="Medium",3,2)))*10) + (IF(J5="Critical",5,IF(J5="High",4,IF(J5="Medium",3,2)))*8) + (IF(M5="Very High",5,IF(M5="High",4,IF(M5="Medium",3,IF(M5="Low",2,1))))*6) + (IF(T5<0, ABS(T5)/7*2, 0))) | P5: =IF(O5="", "", IF(AND(E5="Critical", OR(K5="Critical",K5="High"), T5<0), "P0 - Critical & Urgent", IF(AND(E5="Critical", OR(K5="Critical",K5="High")), "P1 - Critical", IF(OR(AND(E5="High",K5="High"),AND(E5="Critical",K5="Medium")), "P2 - High Priority", IF(OR(AND(E5="Medium",K5="High"),AND(E5="High",K5="Medium")), "P3 - Medium Priority", "P4 - Low Priority"))))) | Q5: =Remediation_Tracking!S5 | R5: =Remediation_Tracking!U5 | S5: =Remediation_Tracking!Z5 | T5: =IF(S5<>"", S5-TODAY(), "") | U5: =Remediation_Tracking!AE5 | V5: =Remediation_Tracking!W5 | W5: =IF(AND(OR(R5="<1 hour",R5="1-4 hours",R5="1 day"), OR(K5="Medium",K5="High",K5="Critical")), "Yes - Quick Win", "No")
A6: =IF(B6<>"", ROW()-1, "") | B6: =Remediation_Tracking!A6 | C6: =Remediation_Tracking!D6 | D6: =Remediation_Tracking!E6 | E6: =Remediation_Tracking!F6 | F6: =Remediation_Tracking!C6 | G6: =Remediation_Tracking!H6 | H6: =Remediation_Tracking!I6 | I6: =Remediation_Tracking!G6 | J6: =Remediation_Tracking!J6 | K6: =Remediation_Tracking!L6 | L6: =Remediation_Tracking!K6 | M6: Medium | N6: =Remediation_Tracking!M6 | O6: =IF(E6="", "", (IF(E6="Critical",5,IF(E6="High",4,IF(E6="Medium",3,2)))*10) + (IF(J6="Critical",5,IF(J6="High",4,IF(J6="Medium",3,2)))*8) + (IF(M6="Very High",5,IF(M6="High",4,IF(M6="Medium",3,IF(M6="Low",2,1))))*6) + (IF(T6<0, ABS(T6)/7*2, 0))) | P6: =IF(O6="", "", IF(AND(E6="Critical", OR(K6="Critical",K6="High"), T6<0), "P0 - Critical & Urgent", IF(AND(E6="Critical", OR(K6="Critical",K6="High")), "P1 - Critical", IF(OR(AND(E6="High",K6="High"),AND(E6="Critical",K6="Medium")), "P2 - High Priority", IF(OR(AND(E6="Medium",K6="High"),AND(E6="High",K6="Medium")), "P3 - Medium Priority", "P4 - Low Priority"))))) | Q6: =Remediation_Tracking!S6 | R6: =Remediation_Tracking!U6 | S6: =Remediation_Tracking!Z6 | T6: =IF(S6<>"", S6-TODAY(), "") | U6: =Remediation_Tracking!AE6 | V6: =Remediation_Tracking!W6 | W6: =IF(AND(OR(R6="<1 hour",R6="1-4 hours",R6="1 day"), OR(K6="Medium",K6="High",K6="Critical")), "Yes - Quick Win", "No")
A7: =IF(B7<>"", ROW()-1, "") | B7: =Remediation_Tracking!A7 | C7: =Remediation_Tracking!D7 | D7: =Remediation_Tracking!E7 | E7: =Remediation_Tracking!F7 | F7: =Remediation_Tracking!C7 | G7: =Remediation_Tracking!H7 | H7: =Remediation_Tracking!I7 | I7: =Remediation_Tracking!G7 | J7: =Remediation_Tracking!J7 | K7: =Remediation_Tracking!L7 | L7: =Remediation_Tracking!K7 | M7: Medium | N7: =Remediation_Tracking!M7 | O7: =IF(E7="", "", (IF(E7="Critical",5,IF(E7="High",4,IF(E7="Medium",3,2)))*10) + (IF(J7="Critical",5,IF(J7="High",4,IF(J7="Medium",3,2)))*8) + (IF(M7="Very High",5,IF(M7="High",4,IF(M7="Medium",3,IF(M7="Low",2,1))))*6) + (IF(T7<0, ABS(T7)/7*2, 0))) | P7: =IF(O7="", "", IF(AND(E7="Critical", OR(K7="Critical",K7="High"), T7<0), "P0 - Critical & Urgent", IF(AND(E7="Critical", OR(K7="Critical",K7="High")), "P1 - Critical", IF(OR(AND(E7="High",K7="High"),AND(E7="Critical",K7="Medium")), "P2 - High Priority", IF(OR(AND(E7="Medium",K7="High"),AND(E7="High",K7="Medium")), "P3 - Medium Priority", "P4 - Low Priority"))))) | Q7: =Remediation_Tracking!S7 | R7: =Remediation_Tracking!U7 | S7: =Remediation_Tracking!Z7 | T7: =IF(S7<>"", S7-TODAY(), "") | U7: =Remediation_Tracking!AE7 | V7: =Remediation_Tracking!W7 | W7: =IF(AND(OR(R7="<1 hour",R7="1-4 hours",R7="1 day"), OR(K7="Medium",K7="High",K7="Critical")), "Yes - Quick Win", "No")
A8: =IF(B8<>"", ROW()-1, "") | B8: =Remediation_Tracking!A8 | C8: =Remediation_Tracking!D8 | D8: =Remediation_Tracking!E8 | E8: =Remediation_Tracking!F8 | F8: =Remediation_Tracking!C8 | G8: =Remediation_Tracking!H8 | H8: =Remediation_Tracking!I8 | I8: =Remediation_Tracking!G8 | J8: =Remediation_Tracking!J8 | K8: =Remediation_Tracking!L8 | L8: =Remediation_Tracking!K8 | M8: Medium | N8: =Remediation_Tracking!M8 | O8: =IF(E8="", "", (IF(E8="Critical",5,IF(E8="High",4,IF(E8="Medium",3,2)))*10) + (IF(J8="Critical",5,IF(J8="High",4,IF(J8="Medium",3,2)))*8) + (IF(M8="Very High",5,IF(M8="High",4,IF(M8="Medium",3,IF(M8="Low",2,1))))*6) + (IF(T8<0, ABS(T8)/7*2, 0))) | P8: =IF(O8="", "", IF(AND(E8="Critical", OR(K8="Critical",K8="High"), T8<0), "P0 - Critical & Urgent", IF(AND(E8="Critical", OR(K8="Critical",K8="High")), "P1 - Critical", IF(OR(AND(E8="High",K8="High"),AND(E8="Critical",K8="Medium")), "P2 - High Priority", IF(OR(AND(E8="Medium",K8="High"),AND(E8="High",K8="Medium")), "P3 - Medium Priority", "P4 - Low Priority"))))) | Q8: =Remediation_Tracking!S8 | R8: =Remediation_Tracking!U8 | S8: =Remediation_Tracking!Z8 | T8: =IF(S8<>"", S8-TODAY(), "") | U8: =Remediation_Tracking!AE8 | V8: =Remediation_Tracking!W8 | W8: =IF(AND(OR(R8="<1 hour",R8="1-4 hours",R8="1 day"), OR(K8="Medium",K8="High",K8="Critical")), "Yes - Quick Win", "No")
A9: =IF(B9<>"", ROW()-1, "") | B9: =Remediation_Tracking!A9 | C9: =Remediation_Tracking!D9 | D9: =Remediation_Tracking!E9 | E9: =Remediation_Tracking!F9 | F9: =Remediation_Tracking!C9 | G9: =Remediation_Tracking!H9 | H9: =Remediation_Tracking!I9 | I9: =Remediation_Tracking!G9 | J9: =Remediation_Tracking!J9 | K9: =Remediation_Tracking!L9 | L9: =Remediation_Tracking!K9 | M9: Medium | N9: =Remediation_Tracking!M9 | O9: =IF(E9="", "", (IF(E9="Critical",5,IF(E9="High",4,IF(E9="Medium",3,2)))*10) + (IF(J9="Critical",5,IF(J9="High",4,IF(J9="Medium",3,2)))*8) + (IF(M9="Very High",5,IF(M9="High",4,IF(M9="Medium",3,IF(M9="Low",2,1))))*6) + (IF(T9<0, ABS(T9)/7*2, 0))) | P9: =IF(O9="", "", IF(AND(E9="Critical", OR(K9="Critical",K9="High"), T9<0), "P0 - Critical & Urgent", IF(AND(E9="Critical", OR(K9="Critical",K9="High")), "P1 - Critical", IF(OR(AND(E9="High",K9="High"),AND(E9="Critical",K9="Medium")), "P2 - High Priority", IF(OR(AND(E9="Medium",K9="High"),AND(E9="High",K9="Medium")), "P3 - Medium Priority", "P4 - Low Priority"))))) | Q9: =Remediation_Tracking!S9 | R9: =Remediation_Tracking!U9 | S9: =Remediation_Tracking!Z9 | T9: =IF(S9<>"", S9-TODAY(), "") | U9: =Remediation_Tracking!AE9 | V9: =Remediation_Tracking!W9 | W9: =IF(AND(OR(R9="<1 hour",R9="1-4 hours",R9="1 day"), OR(K9="Medium",K9="High",K9="Critical")), "Yes - Quick Win", "No")
A10: =IF(B10<>"", ROW()-1, "") | B10: =Remediation_Tracking!A10 | C10: =Remediation_Tracking!D10 | D10: =Remediation_Tracking!E10 | E10: =Remediation_Tracking!F10 | F10: =Remediation_Tracking!C10 | G10: =Remediation_Tracking!H10 | H10: =Remediation_Tracking!I10 | I10: =Remediation_Tracking!G10 | J10: =Remediation_Tracking!J10 | K10: =Remediation_Tracking!L10 | L10: =Remediation_Tracking!K10 | M10: Medium | N10: =Remediation_Tracking!M10 | O10: =IF(E10="", "", (IF(E10="Critical",5,IF(E10="High",4,IF(E10="Medium",3,2)))*10) + (IF(J10="Critical",5,IF(J10="High",4,IF(J10="Medium",3,2)))*8) + (IF(M10="Very High",5,IF(M10="High",4,IF(M10="Medium",3,IF(M10="Low",2,1))))*6) + (IF(T10<0, ABS(T10)/7*2, 0))) | P10: =IF(O10="", "", IF(AND(E10="Critical", OR(K10="Critical",K10="High"), T10<0), "P0 - Critical & Urgent", IF(AND(E10="Critical", OR(K10="Critical",K10="High")), "P1 - Critical", IF(OR(AND(E10="High",K10="High"),AND(E10="Critical",K10="Medium")), "P2 - High Priority", IF(OR(AND(E10="Medium",K10="High"),AND(E10="High",K10="Medium")), "P3 - Medium Priority", "P4 - Low Priority"))))) | Q10: =Remediation_Tracking!S10 | R10: =Remediation_Tracking!U10 | S10: =Remediation_Tracking!Z10 | T10: =IF(S10<>"", S10-TODAY(), "") | U10: =Remediation_Tracking!AE10 | V10: =Remediation_Tracking!W10 | W10: =IF(AND(OR(R10="<1 hour",R10="1-4 hours",R10="1 day"), OR(K10="Medium",K10="High",K10="Critical")), "Yes - Quick Win", "No")
A11: =IF(B11<>"", ROW()-1, "") | B11: =Remediation_Tracking!A11 | C11: =Remediation_Tracking!D11 | D11: =Remediation_Tracking!E11 | E11: =Remediation_Tracking!F11 | F11: =Remediation_Tracking!C11 | G11: =Remediation_Tracking!H11 | H11: =Remediation_Tracking!I11 | I11: =Remediation_Tracking!G11 | J11: =Remediation_Tracking!J11 | K11: =Remediation_Tracking!L11 | L11: =Remediation_Tracking!K11 | M11: Medium | N11: =Remediation_Tracking!M11 | O11: =IF(E11="", "", (IF(E11="Critical",5,IF(E11="High",4,IF(E11="Medium",3,2)))*10) + (IF(J11="Critical",5,IF(J11="High",4,IF(J11="Medium",3,2)))*8) + (IF(M11="Very High",5,IF(M11="High",4,IF(M11="Medium",3,IF(M11="Low",2,1))))*6) + (IF(T11<0, ABS(T11)/7*2, 0))) | P11: =IF(O11="", "", IF(AND(E11="Critical", OR(K11="Critical",K11="High"), T11<0), "P0 - Critical & Urgent", IF(AND(E11="Critical", OR(K11="Critical",K11="High")), "P1 - Critical", IF(OR(AND(E11="High",K11="High"),AND(E11="Critical",K11="Medium")), "P2 - High Priority", IF(OR(AND(E11="Medium",K11="High"),AND(E11="High",K11="Medium")), "P3 - Medium Priority", "P4 - Low Priority"))))) | Q11: =Remediation_Tracking!S11 | R11: =Remediation_Tracking!U11 | S11: =Remediation_Tracking!Z11 | T11: =IF(S11<>"", S11-TODAY(), "") | U11: =Remediation_Tracking!AE11 | V11: =Remediation_Tracking!W11 | W11: =IF(AND(OR(R11="<1 hour",R11="1-4 hours",R11="1 day"), OR(K11="Medium",K11="High",K11="Critical")), "Yes - Quick Win", "No")
A12: =IF(B12<>"", ROW()-1, "") | B12: =Remediation_Tracking!A12 | C12: =Remediation_Tracking!D12 | D12: =Remediation_Tracking!E12 | E12: =Remediation_Tracking!F12 | F12: =Remediation_Tracking!C12 | G12: =Remediation_Tracking!H12 | H12: =Remediation_Tracking!I12 | I12: =Remediation_Tracking!G12 | J12: =Remediation_Tracking!J12 | K12: =Remediation_Tracking!L12 | L12: =Remediation_Tracking!K12 | M12: Medium | N12: =Remediation_Tracking!M12 | O12: =IF(E12="", "", (IF(E12="Critical",5,IF(E12="High",4,IF(E12="Medium",3,2)))*10) + (IF(J12="Critical",5,IF(J12="High",4,IF(J12="Medium",3,2)))*8) + (IF(M12="Very High",5,IF(M12="High",4,IF(M12="Medium",3,IF(M12="Low",2,1))))*6) + (IF(T12<0, ABS(T12)/7*2, 0))) | P12: =IF(O12="", "", IF(AND(E12="Critical", OR(K12="Critical",K12="High"), T12<0), "P0 - Critical & Urgent", IF(AND(E12="Critical", OR(K12="Critical",K12="High")), "P1 - Critical", IF(OR(AND(E12="High",K12="High"),AND(E12="Critical",K12="Medium")), "P2 - High Priority", IF(OR(AND(E12="Medium",K12="High"),AND(E12="High",K12="Medium")), "P3 - Medium Priority", "P4 - Low Priority"))))) | Q12: =Remediation_Tracking!S12 | R12: =Remediation_Tracking!U12 | S12: =Remediation_Tracking!Z12 | T12: =IF(S12<>"", S12-TODAY(), "") | U12: =Remediation_Tracking!AE12 | V12: =Remediation_Tracking!W12 | W12: =IF(AND(OR(R12="<1 hour",R12="1-4 hours",R12="1 day"), OR(K12="Medium",K12="High",K12="Critical")), "Yes - Quick Win", "No")
