Workbook

Sheet Instructions
A1: ISMS Control A.8.9.5
A2: Compliance Dashboard - Configuration Management
A4: PURPOSE
B5: This dashboard consolidates compliance data from all four A.8.9 domain assessments into a single executive-level view of overall configuration management posture.
B7: Dashboard aggregates:
B8: • A.8.9.1 - Baseline Configuration Assessment
B9: • A.8.9.2 - Change Control Assessment
B10: • A.8.9.3 - Configuration Monitoring Assessment
B11: • A.8.9.4 - Security Hardening Assessment
A13: KEY CONCEPTS
B14: External Workbook Linking: Dashboard formulas reference other Excel files in the same directory using formulas like ='[ISMS-IMP-A.8.9.1.xlsx]Sheet'!Cell
B16: Normalized Filenames: Source files must have date-free names (ISMS-IMP-A.8.9.X.xlsx) created by running normalize_assessment_files_a89.py
B18: Overall Compliance: Weighted average across 5 domains:
B19: • Baseline Configuration: 20%
B20: • Change Control: 25%
B21: • Configuration Monitoring: 20%
B22: • Security Hardening: 25%
B23: • Process Maturity: 10%
B25: Target: ≥95% overall compliance
A27: SETUP WORKFLOW
B28: 1. Complete all 4 domain assessments (A.8.9.1 through A.8.9.4)
B29: 2. Generate assessment workbooks with Python scripts
B30: 3. Run normalization: python3 normalize_assessment_files_a89.py
B31: 4. Verify normalized files exist in Dashboard_Sources directory:
B32: • ISMS-IMP-A.8.9.1.xlsx
B33: • ISMS-IMP-A.8.9.2.xlsx
B34: • ISMS-IMP-A.8.9.3.xlsx
B35: • ISMS-IMP-A.8.9.4.xlsx
B36: 5. Place this dashboard in same directory as normalized files
B37: 6. Open dashboard and click 'Update Links' when Excel prompts
B38: 7. Verify Workbook_Integration_Settings shows all 4 workbooks linked
A40: USING THE DASHBOARD
B41: Overall_Compliance_Dashboard: Primary executive view, single-page summary
B43: Asset_Compliance_Summary: Per-asset view across all domains
B45: Gap_Prioritization: Consolidated gap list with risk ranking
B47: Trend_Analysis: Historical compliance tracking (requires multiple cycles)
B49: Evidence_Register: Links to domain-specific evidence
B51: Approval_Sign_Off: Executive approval and governance
A53: EXTERNAL WORKBOOK LINKING
B54: How it works:
...

Sheet Workbook_Integration_Settings
A1: Workbook Integration Settings
A3: SOURCE WORKBOOK CONFIGURATION
A4: Domain | B4: Document ID | C4: Expected Filename | D4: Status | E4: Last Modified | F4: Link Status
A5: Baseline Configuration | B5: ISMS-IMP-A.8.9.1 | C5: ISMS-IMP-A.8.9.1.xlsx | D5: =IF(ISERROR('[ISMS-IMP-A.8.9.1.xlsx]Instructions'!A1),"Not Found",IF(ISREF('[ISMS-IMP-A.8.9.1.xlsx]Instructions'!A1),"Linked","Error")) | E5: N/A | F5: =IF(D5="Linked","✅ Linked and current",IF(D5="Not Found","⚠️ Workbook not found","❌ Link broken"))
A6: Change Control | B6: ISMS-IMP-A.8.9.2 | C6: ISMS-IMP-A.8.9.2.xlsx | D6: =IF(ISERROR('[ISMS-IMP-A.8.9.2.xlsx]Instructions'!A1),"Not Found",IF(ISREF('[ISMS-IMP-A.8.9.2.xlsx]Instructions'!A1),"Linked","Error")) | E6: N/A | F6: =IF(D6="Linked","✅ Linked and current",IF(D6="Not Found","⚠️ Workbook not found","❌ Link broken"))
A7: Configuration Monitoring | B7: ISMS-IMP-A.8.9.3 | C7: ISMS-IMP-A.8.9.3.xlsx | D7: =IF(ISERROR('[ISMS-IMP-A.8.9.3.xlsx]Instructions'!A1),"Not Found",IF(ISREF('[ISMS-IMP-A.8.9.3.xlsx]Instructions'!A1),"Linked","Error")) | E7: N/A | F7: =IF(D7="Linked","✅ Linked and current",IF(D7="Not Found","⚠️ Workbook not found","❌ Link broken"))
A8: Security Hardening | B8: ISMS-IMP-A.8.9.4 | C8: ISMS-IMP-A.8.9.4.xlsx | D8: =IF(ISERROR('[ISMS-IMP-A.8.9.4.xlsx]Instructions'!A1),"Not Found",IF(ISREF('[ISMS-IMP-A.8.9.4.xlsx]Instructions'!A1),"Linked","Error")) | E8: N/A | F8: =IF(D8="Linked","✅ Linked and current",IF(D8="Not Found","⚠️ Workbook not found","❌ Link broken"))
A10: LINK VALIDATION SUMMARY
A11: Total Source Workbooks Expected | B11: 4
A12: Workbooks Successfully Linked | B12: =COUNTIF(D5:D8,"Linked") | C12: =IF(B11<4,"Red","Green")
A13: Workbooks Missing | B13: =COUNTIF(D5:D8,"Not Found") | C13: =IF(B11>0,"Red","Green")
A14: Dashboard Link Health | B14: =B10/B9 | C14: =IF(B11=1,"Green",IF(B11>=0.75,"Yellow","Red"))
A16: DATA PULL TEST
A17: Source | B17: Test Cell | C17: Expected Value Type | D17: Actual Value | E17: Test Result
A18: ISMS-IMP-A.8.9.1 | B18: Compliance_Dashboard!B5 | C18: Percentage | D18: ='[ISMS-IMP-A.8.9.1.xlsx]Compliance_Dashboard'!B5 | E18: =IF(ISERROR(D18),"Fail - Link Broken",IF(AND(D18>=0,D18<=1),"Pass","Fail - Invalid Data"))
A19: ISMS-IMP-A.8.9.2 | B19: Change_Summary!B10 | C19: Percentage | D19: ='[ISMS-IMP-A.8.9.2.xlsx]Change_Summary'!B10 | E19: =IF(ISERROR(D19),"Fail - Link Broken",IF(AND(D19>=0,D19<=1),"Pass","Fail - Invalid Data"))
A20: ISMS-IMP-A.8.9.3 | B20: Compliance_Dashboard!B8 | C20: Percentage | D20: ='[ISMS-IMP-A.8.9.3.xlsx]Compliance_Dashboard'!B8 | E20: =IF(ISERROR(D20),"Fail - Link Broken",IF(AND(D20>=0,D20<=1),"Pass","Fail - Invalid Data"))
A21: ISMS-IMP-A.8.9.4 | B21: Compliance_Dashboard!B5 | C21: Percentage | D21: ='[ISMS-IMP-A.8.9.4.xlsx]Compliance_Dashboard'!B5 | E21: =IF(ISERROR(D21),"Fail - Link Broken",IF(AND(D21>=0,D21<=1),"Pass","Fail - Invalid Data"))

Sheet Overall_Compliance_Dashboard
A1: Control A.8.9 - Configuration Management
A2: COMPLIANCE DASHBOARD
A3: Assessment Date: 08.02.2026
A5: OVERALL COMPLIANCE
A6: Overall Compliance Percentage: | B6: =('[ISMS-IMP-A.8.9.1.xlsx]Compliance_Dashboard'!B5*0.2+'[ISMS-IMP-A.8.9.2.xlsx]Change_Summary'!B10*0.25+'[ISMS-IMP-A.8.9.3.xlsx]Compliance_Dashboard'!B8*0.2+'[ISMS-IMP-A.8.9.4.xlsx]Compliance_Dashboard'!B5*0.25+=AVERAGE('[ISMS-IMP-A.8.9.1.xlsx]Compliance_Dashboard'!B5,'[ISMS-IMP-A.8.9.2.xlsx]Change_Summary'!B10,'[ISMS-IMP-A.8.9.3.xlsx]Compliance_Dashboard'!B8,'[ISMS-IMP-A.8.9.4.xlsx]Compliance_Dashboard'!B5)*0.1) | D6: Target: | E6: ≥95%
A7: Compliance Status: | B7: =IF(AND(B6>=0.95,='[ISMS-IMP-A.8.9.1.xlsx]Compliance_Dashboard'!B15+'[ISMS-IMP-A.8.9.2.xlsx]Change_Summary'!B22+'[ISMS-IMP-A.8.9.3.xlsx]Compliance_Dashboard'!B24+'[ISMS-IMP-A.8.9.4.xlsx]Compliance_Dashboard'!B14=0),"Compliant",IF(B6>=0.9,"Substantially Compliant",IF(B6>=0.8,"At Risk","Non-Compliant")))
A9: DOMAIN COMPLIANCE BREAKDOWN
A10: Domain | B10: Weight | C10: Compliance % | D10: Target | E10: Status | F10: Critical Gaps
A11: Baseline Configuration | B11: 0.2 | C11: ='[ISMS-IMP-A.8.9.1.xlsx]Compliance_Dashboard'!B5 | D11: ≥90% | E11: =IF(C11>=0.9,"Green","Red") | F11: ='[ISMS-IMP-A.8.9.1.xlsx]Compliance_Dashboard'!B15
A12: Change Control | B12: 0.25 | C12: ='[ISMS-IMP-A.8.9.2.xlsx]Change_Summary'!B10 | D12: ≥90% | E12: =IF(C12>=0.9,"Green","Red") | F12: ='[ISMS-IMP-A.8.9.2.xlsx]Change_Summary'!B22
A13: Configuration Monitoring | B13: 0.2 | C13: ='[ISMS-IMP-A.8.9.3.xlsx]Compliance_Dashboard'!B8 | D13: ≥90% | E13: =IF(C13>=0.9,"Green","Red") | F13: ='[ISMS-IMP-A.8.9.3.xlsx]Compliance_Dashboard'!B24
A14: Security Hardening | B14: 0.25 | C14: ='[ISMS-IMP-A.8.9.4.xlsx]Compliance_Dashboard'!B5 | D14: ≥90% | E14: =IF(C14>=0.9,"Green","Red") | F14: ='[ISMS-IMP-A.8.9.4.xlsx]Compliance_Dashboard'!B14
A15: Process Maturity | B15: 0.1 | C15: ==AVERAGE('[ISMS-IMP-A.8.9.1.xlsx]Compliance_Dashboard'!B5,'[ISMS-IMP-A.8.9.2.xlsx]Change_Summary'!B10,'[ISMS-IMP-A.8.9.3.xlsx]Compliance_Dashboard'!B8,'[ISMS-IMP-A.8.9.4.xlsx]Compliance_Dashboard'!B5) | D15: ≥90% | E15: =IF(C15>=0.9,"Green","Red") | F15: 0
A17: KEY PERFORMANCE INDICATORS
A18: KPI | B18: Current | C18: Target | D18: Status
A19: Overall Compliance % | B19: =B6 | C19: ≥95% | D19: Manual Review
A20: Domains Compliant (≥90%) | B20: =COUNTIF(E11:E15,"Green") | C20: 5/5 | D20: Manual Review
A21: Total Critical Gaps | B21: ='[ISMS-IMP-A.8.9.1.xlsx]Compliance_Dashboard'!B15+'[ISMS-IMP-A.8.9.2.xlsx]Change_Summary'!B22+'[ISMS-IMP-A.8.9.3.xlsx]Compliance_Dashboard'!B24+'[ISMS-IMP-A.8.9.4.xlsx]Compliance_Dashboard'!B14 | C21: 0 | D21: Manual Review
A22: Evidence Completeness | B22: 85% | C22: ≥95% | D22: Manual Review

Sheet Asset_Compliance_Summary
A1: Asset_ID | B1: Asset_Name | C1: Asset_Type | D1: Asset_Tier | E1: Asset_Owner | F1: Baseline_Documented | G1: Baseline_Current | H1: Change_Compliance | I1: Emergency_Changes_30d | J1: Monitoring_Coverage | K1: Critical_Drift | L1: Hardening_Compliance | M1: High_Risk_Gaps | N1: Overall_Compliance | O1: Status | P1: Critical_Issues | Q1: Primary_Gap_Domain | R1: Priority | S1: Notes
A2: ='[ISMS-IMP-A.8.9.1.xlsx]Asset_Inventory'!A2 | B2: ='[ISMS-IMP-A.8.9.1.xlsx]Asset_Inventory'!B2 | C2: ='[ISMS-IMP-A.8.9.1.xlsx]Asset_Inventory'!C2 | D2: ='[ISMS-IMP-A.8.9.1.xlsx]Asset_Inventory'!D2 | E2: ='[ISMS-IMP-A.8.9.1.xlsx]Asset_Inventory'!E2 | F2: ='[ISMS-IMP-A.8.9.1.xlsx]Asset_Inventory'!K2 | G2: ='[ISMS-IMP-A.8.9.1.xlsx]Asset_Inventory'!L2 | H2: Manual | I2: 0 | J2: Manual | K2: 0 | L2: Manual | M2: 0 | N2: =IF(A2="","",((IF(AND(F2="Yes",G2="Yes"),100,IF(OR(F2="Yes",G2="Yes"),50,0))*0.2)+(IF(ISNUMBER(H2),H2,0)*0.25)+(IF(AND(J2="Yes",K2=0),100,IF(J2="Yes",50,0))*0.2)+(IF(ISNUMBER(L2),L2,0)*0.25)+(IF(I2<=2,100,100-(I2-2)*10)*0.1))/100) | O2: =IF(A2="","",IF(AND(N2>=0.95,P2=0),"Fully Compliant",IF(N2>=0.9,"Compliant",IF(N2>=0.8,"Substantially Compliant",IF(N2>=0.7,"Partially Compliant","Non-Compliant"))))) | P2: =IF(A2="","",(IF(F2="No",1,0))+(IF(K2>0,1,0))+(IF(M2>0,1,0))+(IF(I2>5,1,0))) | Q2: =IF(A2="","","Manual Analysis Required") | R2: =IF(A2="","",IF(AND(D2="Critical",P2>0),"P0",IF(P2>0,"P1",IF(N2<0.9,"P2","P3"))))
A3: ='[ISMS-IMP-A.8.9.1.xlsx]Asset_Inventory'!A3 | B3: ='[ISMS-IMP-A.8.9.1.xlsx]Asset_Inventory'!B3 | C3: ='[ISMS-IMP-A.8.9.1.xlsx]Asset_Inventory'!C3 | D3: ='[ISMS-IMP-A.8.9.1.xlsx]Asset_Inventory'!D3 | E3: ='[ISMS-IMP-A.8.9.1.xlsx]Asset_Inventory'!E3 | F3: ='[ISMS-IMP-A.8.9.1.xlsx]Asset_Inventory'!K3 | G3: ='[ISMS-IMP-A.8.9.1.xlsx]Asset_Inventory'!L3 | H3: Manual | I3: 0 | J3: Manual | K3: 0 | L3: Manual | M3: 0 | N3: =IF(A3="","",((IF(AND(F3="Yes",G3="Yes"),100,IF(OR(F3="Yes",G3="Yes"),50,0))*0.2)+(IF(ISNUMBER(H3),H3,0)*0.25)+(IF(AND(J3="Yes",K3=0),100,IF(J3="Yes",50,0))*0.2)+(IF(ISNUMBER(L3),L3,0)*0.25)+(IF(I3<=2,100,100-(I3-2)*10)*0.1))/100) | O3: =IF(A3="","",IF(AND(N3>=0.95,P3=0),"Fully Compliant",IF(N3>=0.9,"Compliant",IF(N3>=0.8,"Substantially Compliant",IF(N3>=0.7,"Partially Compliant","Non-Compliant"))))) | P3: =IF(A3="","",(IF(F3="No",1,0))+(IF(K3>0,1,0))+(IF(M3>0,1,0))+(IF(I3>5,1,0))) | Q3: =IF(A3="","","Manual Analysis Required") | R3: =IF(A3="","",IF(AND(D3="Critical",P3>0),"P0",IF(P3>0,"P1",IF(N3<0.9,"P2","P3"))))
A4: ='[ISMS-IMP-A.8.9.1.xlsx]Asset_Inventory'!A4 | B4: ='[ISMS-IMP-A.8.9.1.xlsx]Asset_Inventory'!B4 | C4: ='[ISMS-IMP-A.8.9.1.xlsx]Asset_Inventory'!C4 | D4: ='[ISMS-IMP-A.8.9.1.xlsx]Asset_Inventory'!D4 | E4: ='[ISMS-IMP-A.8.9.1.xlsx]Asset_Inventory'!E4 | F4: ='[ISMS-IMP-A.8.9.1.xlsx]Asset_Inventory'!K4 | G4: ='[ISMS-IMP-A.8.9.1.xlsx]Asset_Inventory'!L4 | H4: Manual | I4: 0 | J4: Manual | K4: 0 | L4: Manual | M4: 0 | N4: =IF(A4="","",((IF(AND(F4="Yes",G4="Yes"),100,IF(OR(F4="Yes",G4="Yes"),50,0))*0.2)+(IF(ISNUMBER(H4),H4,0)*0.25)+(IF(AND(J4="Yes",K4=0),100,IF(J4="Yes",50,0))*0.2)+(IF(ISNUMBER(L4),L4,0)*0.25)+(IF(I4<=2,100,100-(I4-2)*10)*0.1))/100) | O4: =IF(A4="","",IF(AND(N4>=0.95,P4=0),"Fully Compliant",IF(N4>=0.9,"Compliant",IF(N4>=0.8,"Substantially Compliant",IF(N4>=0.7,"Partially Compliant","Non-Compliant"))))) | P4: =IF(A4="","",(IF(F4="No",1,0))+(IF(K4>0,1,0))+(IF(M4>0,1,0))+(IF(I4>5,1,0))) | Q4: =IF(A4="","","Manual Analysis Required") | R4: =IF(A4="","",IF(AND(D4="Critical",P4>0),"P0",IF(P4>0,"P1",IF(N4<0.9,"P2","P3"))))
A5: ='[ISMS-IMP-A.8.9.1.xlsx]Asset_Inventory'!A5 | B5: ='[ISMS-IMP-A.8.9.1.xlsx]Asset_Inventory'!B5 | C5: ='[ISMS-IMP-A.8.9.1.xlsx]Asset_Inventory'!C5 | D5: ='[ISMS-IMP-A.8.9.1.xlsx]Asset_Inventory'!D5 | E5: ='[ISMS-IMP-A.8.9.1.xlsx]Asset_Inventory'!E5 | F5: ='[ISMS-IMP-A.8.9.1.xlsx]Asset_Inventory'!K5 | G5: ='[ISMS-IMP-A.8.9.1.xlsx]Asset_Inventory'!L5 | H5: Manual | I5: 0 | J5: Manual | K5: 0 | L5: Manual | M5: 0 | N5: =IF(A5="","",((IF(AND(F5="Yes",G5="Yes"),100,IF(OR(F5="Yes",G5="Yes"),50,0))*0.2)+(IF(ISNUMBER(H5),H5,0)*0.25)+(IF(AND(J5="Yes",K5=0),100,IF(J5="Yes",50,0))*0.2)+(IF(ISNUMBER(L5),L5,0)*0.25)+(IF(I5<=2,100,100-(I5-2)*10)*0.1))/100) | O5: =IF(A5="","",IF(AND(N5>=0.95,P5=0),"Fully Compliant",IF(N5>=0.9,"Compliant",IF(N5>=0.8,"Substantially Compliant",IF(N5>=0.7,"Partially Compliant","Non-Compliant"))))) | P5: =IF(A5="","",(IF(F5="No",1,0))+(IF(K5>0,1,0))+(IF(M5>0,1,0))+(IF(I5>5,1,0))) | Q5: =IF(A5="","","Manual Analysis Required") | R5: =IF(A5="","",IF(AND(D5="Critical",P5>0),"P0",IF(P5>0,"P1",IF(N5<0.9,"P2","P3"))))
A6: ='[ISMS-IMP-A.8.9.1.xlsx]Asset_Inventory'!A6 | B6: ='[ISMS-IMP-A.8.9.1.xlsx]Asset_Inventory'!B6 | C6: ='[ISMS-IMP-A.8.9.1.xlsx]Asset_Inventory'!C6 | D6: ='[ISMS-IMP-A.8.9.1.xlsx]Asset_Inventory'!D6 | E6: ='[ISMS-IMP-A.8.9.1.xlsx]Asset_Inventory'!E6 | F6: ='[ISMS-IMP-A.8.9.1.xlsx]Asset_Inventory'!K6 | G6: ='[ISMS-IMP-A.8.9.1.xlsx]Asset_Inventory'!L6 | H6: Manual | I6: 0 | J6: Manual | K6: 0 | L6: Manual | M6: 0 | N6: =IF(A6="","",((IF(AND(F6="Yes",G6="Yes"),100,IF(OR(F6="Yes",G6="Yes"),50,0))*0.2)+(IF(ISNUMBER(H6),H6,0)*0.25)+(IF(AND(J6="Yes",K6=0),100,IF(J6="Yes",50,0))*0.2)+(IF(ISNUMBER(L6),L6,0)*0.25)+(IF(I6<=2,100,100-(I6-2)*10)*0.1))/100) | O6: =IF(A6="","",IF(AND(N6>=0.95,P6=0),"Fully Compliant",IF(N6>=0.9,"Compliant",IF(N6>=0.8,"Substantially Compliant",IF(N6>=0.7,"Partially Compliant","Non-Compliant"))))) | P6: =IF(A6="","",(IF(F6="No",1,0))+(IF(K6>0,1,0))+(IF(M6>0,1,0))+(IF(I6>5,1,0))) | Q6: =IF(A6="","","Manual Analysis Required") | R6: =IF(A6="","",IF(AND(D6="Critical",P6>0),"P0",IF(P6>0,"P1",IF(N6<0.9,"P2","P3"))))
A7: ='[ISMS-IMP-A.8.9.1.xlsx]Asset_Inventory'!A7 | B7: ='[ISMS-IMP-A.8.9.1.xlsx]Asset_Inventory'!B7 | C7: ='[ISMS-IMP-A.8.9.1.xlsx]Asset_Inventory'!C7 | D7: ='[ISMS-IMP-A.8.9.1.xlsx]Asset_Inventory'!D7 | E7: ='[ISMS-IMP-A.8.9.1.xlsx]Asset_Inventory'!E7 | F7: ='[ISMS-IMP-A.8.9.1.xlsx]Asset_Inventory'!K7 | G7: ='[ISMS-IMP-A.8.9.1.xlsx]Asset_Inventory'!L7 | H7: Manual | I7: 0 | J7: Manual | K7: 0 | L7: Manual | M7: 0 | N7: =IF(A7="","",((IF(AND(F7="Yes",G7="Yes"),100,IF(OR(F7="Yes",G7="Yes"),50,0))*0.2)+(IF(ISNUMBER(H7),H7,0)*0.25)+(IF(AND(J7="Yes",K7=0),100,IF(J7="Yes",50,0))*0.2)+(IF(ISNUMBER(L7),L7,0)*0.25)+(IF(I7<=2,100,100-(I7-2)*10)*0.1))/100) | O7: =IF(A7="","",IF(AND(N7>=0.95,P7=0),"Fully Compliant",IF(N7>=0.9,"Compliant",IF(N7>=0.8,"Substantially Compliant",IF(N7>=0.7,"Partially Compliant","Non-Compliant"))))) | P7: =IF(A7="","",(IF(F7="No",1,0))+(IF(K7>0,1,0))+(IF(M7>0,1,0))+(IF(I7>5,1,0))) | Q7: =IF(A7="","","Manual Analysis Required") | R7: =IF(A7="","",IF(AND(D7="Critical",P7>0),"P0",IF(P7>0,"P1",IF(N7<0.9,"P2","P3"))))
A8: ='[ISMS-IMP-A.8.9.1.xlsx]Asset_Inventory'!A8 | B8: ='[ISMS-IMP-A.8.9.1.xlsx]Asset_Inventory'!B8 | C8: ='[ISMS-IMP-A.8.9.1.xlsx]Asset_Inventory'!C8 | D8: ='[ISMS-IMP-A.8.9.1.xlsx]Asset_Inventory'!D8 | E8: ='[ISMS-IMP-A.8.9.1.xlsx]Asset_Inventory'!E8 | F8: ='[ISMS-IMP-A.8.9.1.xlsx]Asset_Inventory'!K8 | G8: ='[ISMS-IMP-A.8.9.1.xlsx]Asset_Inventory'!L8 | H8: Manual | I8: 0 | J8: Manual | K8: 0 | L8: Manual | M8: 0 | N8: =IF(A8="","",((IF(AND(F8="Yes",G8="Yes"),100,IF(OR(F8="Yes",G8="Yes"),50,0))*0.2)+(IF(ISNUMBER(H8),H8,0)*0.25)+(IF(AND(J8="Yes",K8=0),100,IF(J8="Yes",50,0))*0.2)+(IF(ISNUMBER(L8),L8,0)*0.25)+(IF(I8<=2,100,100-(I8-2)*10)*0.1))/100) | O8: =IF(A8="","",IF(AND(N8>=0.95,P8=0),"Fully Compliant",IF(N8>=0.9,"Compliant",IF(N8>=0.8,"Substantially Compliant",IF(N8>=0.7,"Partially Compliant","Non-Compliant"))))) | P8: =IF(A8="","",(IF(F8="No",1,0))+(IF(K8>0,1,0))+(IF(M8>0,1,0))+(IF(I8>5,1,0))) | Q8: =IF(A8="","","Manual Analysis Required") | R8: =IF(A8="","",IF(AND(D8="Critical",P8>0),"P0",IF(P8>0,"P1",IF(N8<0.9,"P2","P3"))))
A9: ='[ISMS-IMP-A.8.9.1.xlsx]Asset_Inventory'!A9 | B9: ='[ISMS-IMP-A.8.9.1.xlsx]Asset_Inventory'!B9 | C9: ='[ISMS-IMP-A.8.9.1.xlsx]Asset_Inventory'!C9 | D9: ='[ISMS-IMP-A.8.9.1.xlsx]Asset_Inventory'!D9 | E9: ='[ISMS-IMP-A.8.9.1.xlsx]Asset_Inventory'!E9 | F9: ='[ISMS-IMP-A.8.9.1.xlsx]Asset_Inventory'!K9 | G9: ='[ISMS-IMP-A.8.9.1.xlsx]Asset_Inventory'!L9 | H9: Manual | I9: 0 | J9: Manual | K9: 0 | L9: Manual | M9: 0 | N9: =IF(A9="","",((IF(AND(F9="Yes",G9="Yes"),100,IF(OR(F9="Yes",G9="Yes"),50,0))*0.2)+(IF(ISNUMBER(H9),H9,0)*0.25)+(IF(AND(J9="Yes",K9=0),100,IF(J9="Yes",50,0))*0.2)+(IF(ISNUMBER(L9),L9,0)*0.25)+(IF(I9<=2,100,100-(I9-2)*10)*0.1))/100) | O9: =IF(A9="","",IF(AND(N9>=0.95,P9=0),"Fully Compliant",IF(N9>=0.9,"Compliant",IF(N9>=0.8,"Substantially Compliant",IF(N9>=0.7,"Partially Compliant","Non-Compliant"))))) | P9: =IF(A9="","",(IF(F9="No",1,0))+(IF(K9>0,1,0))+(IF(M9>0,1,0))+(IF(I9>5,1,0))) | Q9: =IF(A9="","","Manual Analysis Required") | R9: =IF(A9="","",IF(AND(D9="Critical",P9>0),"P0",IF(P9>0,"P1",IF(N9<0.9,"P2","P3"))))
A10: ='[ISMS-IMP-A.8.9.1.xlsx]Asset_Inventory'!A10 | B10: ='[ISMS-IMP-A.8.9.1.xlsx]Asset_Inventory'!B10 | C10: ='[ISMS-IMP-A.8.9.1.xlsx]Asset_Inventory'!C10 | D10: ='[ISMS-IMP-A.8.9.1.xlsx]Asset_Inventory'!D10 | E10: ='[ISMS-IMP-A.8.9.1.xlsx]Asset_Inventory'!E10 | F10: ='[ISMS-IMP-A.8.9.1.xlsx]Asset_Inventory'!K10 | G10: ='[ISMS-IMP-A.8.9.1.xlsx]Asset_Inventory'!L10 | H10: Manual | I10: 0 | J10: Manual | K10: 0 | L10: Manual | M10: 0 | N10: =IF(A10="","",((IF(AND(F10="Yes",G10="Yes"),100,IF(OR(F10="Yes",G10="Yes"),50,0))*0.2)+(IF(ISNUMBER(H10),H10,0)*0.25)+(IF(AND(J10="Yes",K10=0),100,IF(J10="Yes",50,0))*0.2)+(IF(ISNUMBER(L10),L10,0)*0.25)+(IF(I10<=2,100,100-(I10-2)*10)*0.1))/100) | O10: =IF(A10="","",IF(AND(N10>=0.95,P10=0),"Fully Compliant",IF(N10>=0.9,"Compliant",IF(N10>=0.8,"Substantially Compliant",IF(N10>=0.7,"Partially Compliant","Non-Compliant"))))) | P10: =IF(A10="","",(IF(F10="No",1,0))+(IF(K10>0,1,0))+(IF(M10>0,1,0))+(IF(I10>5,1,0))) | Q10: =IF(A10="","","Manual Analysis Required") | R10: =IF(A10="","",IF(AND(D10="Critical",P10>0),"P0",IF(P10>0,"P1",IF(N10<0.9,"P2","P3"))))
A11: ='[ISMS-IMP-A.8.9.1.xlsx]Asset_Inventory'!A11 | B11: ='[ISMS-IMP-A.8.9.1.xlsx]Asset_Inventory'!B11 | C11: ='[ISMS-IMP-A.8.9.1.xlsx]Asset_Inventory'!C11 | D11: ='[ISMS-IMP-A.8.9.1.xlsx]Asset_Inventory'!D11 | E11: ='[ISMS-IMP-A.8.9.1.xlsx]Asset_Inventory'!E11 | F11: ='[ISMS-IMP-A.8.9.1.xlsx]Asset_Inventory'!K11 | G11: ='[ISMS-IMP-A.8.9.1.xlsx]Asset_Inventory'!L11 | H11: Manual | I11: 0 | J11: Manual | K11: 0 | L11: Manual | M11: 0 | N11: =IF(A11="","",((IF(AND(F11="Yes",G11="Yes"),100,IF(OR(F11="Yes",G11="Yes"),50,0))*0.2)+(IF(ISNUMBER(H11),H11,0)*0.25)+(IF(AND(J11="Yes",K11=0),100,IF(J11="Yes",50,0))*0.2)+(IF(ISNUMBER(L11),L11,0)*0.25)+(IF(I11<=2,100,100-(I11-2)*10)*0.1))/100) | O11: =IF(A11="","",IF(AND(N11>=0.95,P11=0),"Fully Compliant",IF(N11>=0.9,"Compliant",IF(N11>=0.8,"Substantially Compliant",IF(N11>=0.7,"Partially Compliant","Non-Compliant"))))) | P11: =IF(A11="","",(IF(F11="No",1,0))+(IF(K11>0,1,0))+(IF(M11>0,1,0))+(IF(I11>5,1,0))) | Q11: =IF(A11="","","Manual Analysis Required") | R11: =IF(A11="","",IF(AND(D11="Critical",P11>0),"P0",IF(P11>0,"P1",IF(N11<0.9,"P2","P3"))))
A12: ='[ISMS-IMP-A.8.9.1.xlsx]Asset_Inventory'!A12 | B12: ='[ISMS-IMP-A.8.9.1.xlsx]Asset_Inventory'!B12 | C12: ='[ISMS-IMP-A.8.9.1.xlsx]Asset_Inventory'!C12 | D12: ='[ISMS-IMP-A.8.9.1.xlsx]Asset_Inventory'!D12 | E12: ='[ISMS-IMP-A.8.9.1.xlsx]Asset_Inventory'!E12 | F12: ='[ISMS-IMP-A.8.9.1.xlsx]Asset_Inventory'!K12 | G12: ='[ISMS-IMP-A.8.9.1.xlsx]Asset_Inventory'!L12 | H12: Manual | I12: 0 | J12: Manual | K12: 0 | L12: Manual | M12: 0 | N12: =IF(A12="","",((IF(AND(F12="Yes",G12="Yes"),100,IF(OR(F12="Yes",G12="Yes"),50,0))*0.2)+(IF(ISNUMBER(H12),H12,0)*0.25)+(IF(AND(J12="Yes",K12=0),100,IF(J12="Yes",50,0))*0.2)+(IF(ISNUMBER(L12),L12,0)*0.25)+(IF(I12<=2,100,100-(I12-2)*10)*0.1))/100) | O12: =IF(A12="","",IF(AND(N12>=0.95,P12=0),"Fully Compliant",IF(N12>=0.9,"Compliant",IF(N12>=0.8,"Substantially Compliant",IF(N12>=0.7,"Partially Compliant","Non-Compliant"))))) | P12: =IF(A12="","",(IF(F12="No",1,0))+(IF(K12>0,1,0))+(IF(M12>0,1,0))+(IF(I12>5,1,0))) | Q12: =IF(A12="","","Manual Analysis Required") | R12: =IF(A12="","",IF(AND(D12="Critical",P12>0),"P0",IF(P12>0,"P1",IF(N12<0.9,"P2","P3"))))
A13: ='[ISMS-IMP-A.8.9.1.xlsx]Asset_Inventory'!A13 | B13: ='[ISMS-IMP-A.8.9.1.xlsx]Asset_Inventory'!B13 | C13: ='[ISMS-IMP-A.8.9.1.xlsx]Asset_Inventory'!C13 | D13: ='[ISMS-IMP-A.8.9.1.xlsx]Asset_Inventory'!D13 | E13: ='[ISMS-IMP-A.8.9.1.xlsx]Asset_Inventory'!E13 | F13: ='[ISMS-IMP-A.8.9.1.xlsx]Asset_Inventory'!K13 | G13: ='[ISMS-IMP-A.8.9.1.xlsx]Asset_Inventory'!L13 | H13: Manual | I13: 0 | J13: Manual | K13: 0 | L13: Manual | M13: 0 | N13: =IF(A13="","",((IF(AND(F13="Yes",G13="Yes"),100,IF(OR(F13="Yes",G13="Yes"),50,0))*0.2)+(IF(ISNUMBER(H13),H13,0)*0.25)+(IF(AND(J13="Yes",K13=0),100,IF(J13="Yes",50,0))*0.2)+(IF(ISNUMBER(L13),L13,0)*0.25)+(IF(I13<=2,100,100-(I13-2)*10)*0.1))/100) | O13: =IF(A13="","",IF(AND(N13>=0.95,P13=0),"Fully Compliant",IF(N13>=0.9,"Compliant",IF(N13>=0.8,"Substantially Compliant",IF(N13>=0.7,"Partially Compliant","Non-Compliant"))))) | P13: =IF(A13="","",(IF(F13="No",1,0))+(IF(K13>0,1,0))+(IF(M13>0,1,0))+(IF(I13>5,1,0))) | Q13: =IF(A13="","","Manual Analysis Required") | R13: =IF(A13="","",IF(AND(D13="Critical",P13>0),"P0",IF(P13>0,"P1",IF(N13<0.9,"P2","P3"))))
... A101: ='[ISMS-IMP-A.8.9.1.xlsx]Asset_Inventory'!A101 | B101: ='[ISMS-IMP-A.8.9.1.xlsx]Asset_Inventory'!B101 | C101: ='[ISMS-IMP-A.8.9.1.xlsx]Asset_Inventory'!C101 | D101: ='[ISMS-IMP-A.8.9.1.xlsx]Asset_Inventory'!D101 | E101: ='[ISMS-IMP-A.8.9.1.xlsx]Asset_Inventory'!E101 | F101: ='[ISMS-IMP-A.8.9.1.xlsx]Asset_Inventory'!K101 | G101: ='[ISMS-IMP-A.8.9.1.xlsx]Asset_Inventory'!L101 | H101: Manual | I101: 0 | J101: Manual | K101: 0 | L101: Manual | M101: 0 | N101: =IF(A101="","",((IF(AND(F101="Yes",G101="Yes"),100,IF(OR(F101="Yes",G101="Yes"),50,0))*0.2)+(IF(ISNUMBER(H101),H101,0)*0.25)+(IF(AND(J101="Yes",K101=0),100,IF(J101="Yes",50,0))*0.2)+(IF(ISNUMBER(L101),L101,0)*0.25)+(IF(I101<=2,100,100-(I101-2)*10)*0.1))/100) | O101: =IF(A101="","",IF(AND(N101>=0.95,P101=0),"Fully Compliant",IF(N101>=0.9,"Compliant",IF(N101>=0.8,"Substantially Compliant",IF(N101>=0.7,"Partially Compliant","Non-Compliant"))))) | P101: =IF(A101="","",(IF(F101="No",1,0))+(IF(K101>0,1,0))+(IF(M101>0,1,0))+(IF(I101>5,1,0))) | Q101: =IF(A101="","","Manual Analysis Required") | R101: =IF(A101="","",IF(AND(D101="Critical",P101>0),"P0",IF(P101>0,"P1",IF(N101<0.9,"P2","P3"))))

Sheet Gap_Prioritization
A1: Gap_ID | B1: Priority_Rank | C1: Source_Domain | D1: Asset_ID | E1: Asset_Name | F1: Asset_Tier | G1: Gap_Category | H1: Gap_Description | I1: Gap_Risk_Rating | J1: Impact | K1: Exploitation_Likelihood | L1: Risk_Score | M1: Owner | N1: Strategy | O1: Target_Date | P1: Days_Until | Q1: Status | R1: Quick_Win | S1: Cross_Domain | T1: Notes
A2: =IF(C2<>"","GAP-"&TEXT(ROW()-1,"000"),"") | B2: =IF(L2<>"",RANK(L2,L:L,0),"") | L2: =IF(C2="","",((IF(F2="Critical",5,IF(F2="High",4,IF(F2="Medium",3,2)))*10)+(IF(I2="Critical",5,IF(I2="High",4,IF(I2="Medium",3,2)))*8)+(IF(K2="Very High",5,IF(K2="High",4,IF(K2="Medium",3,IF(K2="Low",2,1))))*6)+(IF(P2<0,ABS(P2)/7*2,0)))) | P2: =IF(O2<>"",O2-TODAY(),"") | R2: =IF(AND(OR(I2="Medium",I2="High",I2="Critical"),OR(N2="Configuration Change",N2="Policy Update",P2<=7)),"Yes","No")
A3: =IF(C3<>"","GAP-"&TEXT(ROW()-1,"000"),"") | B3: =IF(L3<>"",RANK(L3,L:L,0),"") | L3: =IF(C3="","",((IF(F3="Critical",5,IF(F3="High",4,IF(F3="Medium",3,2)))*10)+(IF(I3="Critical",5,IF(I3="High",4,IF(I3="Medium",3,2)))*8)+(IF(K3="Very High",5,IF(K3="High",4,IF(K3="Medium",3,IF(K3="Low",2,1))))*6)+(IF(P3<0,ABS(P3)/7*2,0)))) | P3: =IF(O3<>"",O3-TODAY(),"") | R3: =IF(AND(OR(I3="Medium",I3="High",I3="Critical"),OR(N3="Configuration Change",N3="Policy Update",P3<=7)),"Yes","No")
A4: =IF(C4<>"","GAP-"&TEXT(ROW()-1,"000"),"") | B4: =IF(L4<>"",RANK(L4,L:L,0),"") | L4: =IF(C4="","",((IF(F4="Critical",5,IF(F4="High",4,IF(F4="Medium",3,2)))*10)+(IF(I4="Critical",5,IF(I4="High",4,IF(I4="Medium",3,2)))*8)+(IF(K4="Very High",5,IF(K4="High",4,IF(K4="Medium",3,IF(K4="Low",2,1))))*6)+(IF(P4<0,ABS(P4)/7*2,0)))) | P4: =IF(O4<>"",O4-TODAY(),"") | R4: =IF(AND(OR(I4="Medium",I4="High",I4="Critical"),OR(N4="Configuration Change",N4="Policy Update",P4<=7)),"Yes","No")
A5: =IF(C5<>"","GAP-"&TEXT(ROW()-1,"000"),"") | B5: =IF(L5<>"",RANK(L5,L:L,0),"") | L5: =IF(C5="","",((IF(F5="Critical",5,IF(F5="High",4,IF(F5="Medium",3,2)))*10)+(IF(I5="Critical",5,IF(I5="High",4,IF(I5="Medium",3,2)))*8)+(IF(K5="Very High",5,IF(K5="High",4,IF(K5="Medium",3,IF(K5="Low",2,1))))*6)+(IF(P5<0,ABS(P5)/7*2,0)))) | P5: =IF(O5<>"",O5-TODAY(),"") | R5: =IF(AND(OR(I5="Medium",I5="High",I5="Critical"),OR(N5="Configuration Change",N5="Policy Update",P5<=7)),"Yes","No")
A6: =IF(C6<>"","GAP-"&TEXT(ROW()-1,"000"),"") | B6: =IF(L6<>"",RANK(L6,L:L,0),"") | L6: =IF(C6="","",((IF(F6="Critical",5,IF(F6="High",4,IF(F6="Medium",3,2)))*10)+(IF(I6="Critical",5,IF(I6="High",4,IF(I6="Medium",3,2)))*8)+(IF(K6="Very High",5,IF(K6="High",4,IF(K6="Medium",3,IF(K6="Low",2,1))))*6)+(IF(P6<0,ABS(P6)/7*2,0)))) | P6: =IF(O6<>"",O6-TODAY(),"") | R6: =IF(AND(OR(I6="Medium",I6="High",I6="Critical"),OR(N6="Configuration Change",N6="Policy Update",P6<=7)),"Yes","No")
A7: =IF(C7<>"","GAP-"&TEXT(ROW()-1,"000"),"") | B7: =IF(L7<>"",RANK(L7,L:L,0),"") | L7: =IF(C7="","",((IF(F7="Critical",5,IF(F7="High",4,IF(F7="Medium",3,2)))*10)+(IF(I7="Critical",5,IF(I7="High",4,IF(I7="Medium",3,2)))*8)+(IF(K7="Very High",5,IF(K7="High",4,IF(K7="Medium",3,IF(K7="Low",2,1))))*6)+(IF(P7<0,ABS(P7)/7*2,0)))) | P7: =IF(O7<>"",O7-TODAY(),"") | R7: =IF(AND(OR(I7="Medium",I7="High",I7="Critical"),OR(N7="Configuration Change",N7="Policy Update",P7<=7)),"Yes","No")
A8: =IF(C8<>"","GAP-"&TEXT(ROW()-1,"000"),"") | B8: =IF(L8<>"",RANK(L8,L:L,0),"") | L8: =IF(C8="","",((IF(F8="Critical",5,IF(F8="High",4,IF(F8="Medium",3,2)))*10)+(IF(I8="Critical",5,IF(I8="High",4,IF(I8="Medium",3,2)))*8)+(IF(K8="Very High",5,IF(K8="High",4,IF(K8="Medium",3,IF(K8="Low",2,1))))*6)+(IF(P8<0,ABS(P8)/7*2,0)))) | P8: =IF(O8<>"",O8-TODAY(),"") | R8: =IF(AND(OR(I8="Medium",I8="High",I8="Critical"),OR(N8="Configuration Change",N8="Policy Update",P8<=7)),"Yes","No")
A9: =IF(C9<>"","GAP-"&TEXT(ROW()-1,"000"),"") | B9: =IF(L9<>"",RANK(L9,L:L,0),"") | L9: =IF(C9="","",((IF(F9="Critical",5,IF(F9="High",4,IF(F9="Medium",3,2)))*10)+(IF(I9="Critical",5,IF(I9="High",4,IF(I9="Medium",3,2)))*8)+(IF(K9="Very High",5,IF(K9="High",4,IF(K9="Medium",3,IF(K9="Low",2,1))))*6)+(IF(P9<0,ABS(P9)/7*2,0)))) | P9: =IF(O9<>"",O9-TODAY(),"") | R9: =IF(AND(OR(I9="Medium",I9="High",I9="Critical"),OR(N9="Configuration Change",N9="Policy Update",P9<=7)),"Yes","No")
A10: =IF(C10<>"","GAP-"&TEXT(ROW()-1,"000"),"") | B10: =IF(L10<>"",RANK(L10,L:L,0),"") | L10: =IF(C10="","",((IF(F10="Critical",5,IF(F10="High",4,IF(F10="Medium",3,2)))*10)+(IF(I10="Critical",5,IF(I10="High",4,IF(I10="Medium",3,2)))*8)+(IF(K10="Very High",5,IF(K10="High",4,IF(K10="Medium",3,IF(K10="Low",2,1))))*6)+(IF(P10<0,ABS(P10)/7*2,0)))) | P10: =IF(O10<>"",O10-TODAY(),"") | R10: =IF(AND(OR(I10="Medium",I10="High",I10="Critical"),OR(N10="Configuration Change",N10="Policy Update",P10<=7)),"Yes","No")
A11: =IF(C11<>"","GAP-"&TEXT(ROW()-1,"000"),"") | B11: =IF(L11<>"",RANK(L11,L:L,0),"") | L11: =IF(C11="","",((IF(F11="Critical",5,IF(F11="High",4,IF(F11="Medium",3,2)))*10)+(IF(I11="Critical",5,IF(I11="High",4,IF(I11="Medium",3,2)))*8)+(IF(K11="Very High",5,IF(K11="High",4,IF(K11="Medium",3,IF(K11="Low",2,1))))*6)+(IF(P11<0,ABS(P11)/7*2,0)))) | P11: =IF(O11<>"",O11-TODAY(),"") | R11: =IF(AND(OR(I11="Medium",I11="High",I11="Critical"),OR(N11="Configuration Change",N11="Policy Update",P11<=7)),"Yes","No")
A12: =IF(C12<>"","GAP-"&TEXT(ROW()-1,"000"),"") | B12: =IF(L12<>"",RANK(L12,L:L,0),"") | L12: =IF(C12="","",((IF(F12="Critical",5,IF(F12="High",4,IF(F12="Medium",3,2)))*10)+(IF(I12="Critical",5,IF(I12="High",4,IF(I12="Medium",3,2)))*8)+(IF(K12="Very High",5,IF(K12="High",4,IF(K12="Medium",3,IF(K12="Low",2,1))))*6)+(IF(P12<0,ABS(P12)/7*2,0)))) | P12: =IF(O12<>"",O12-TODAY(),"") | R12: =IF(AND(OR(I12="Medium",I12="High",I12="Critical"),OR(N12="Configuration Change",N12="Policy Update",P12<=7)),"Yes","No")
A13: =IF(C13<>"","GAP-"&TEXT(ROW()-1,"000"),"") | B13: =IF(L13<>"",RANK(L13,L:L,0),"") | L13: =IF(C13="","",((IF(F13="Critical",5,IF(F13="High",4,IF(F13="Medium",3,2)))*10)+(IF(I13="Critical",5,IF(I13="High",4,IF(I13="Medium",3,2)))*8)+(IF(K13="Very High",5,IF(K13="High",4,IF(K13="Medium",3,IF(K13="Low",2,1))))*6)+(IF(P13<0,ABS(P13)/7*2,0)))) | P13: =IF(O13<>"",O13-TODAY(),"") | R13: =IF(AND(OR(I13="Medium",I13="High",I13="Critical"),OR(N13="Configuration Change",N13="Policy Update",P13<=7)),"Yes","No")
... A151: =IF(C151<>"","GAP-"&TEXT(ROW()-1,"000"),"") | B151: =IF(L151<>"",RANK(L151,L:L,0),"") | L151: =IF(C151="","",((IF(F151="Critical",5,IF(F151="High",4,IF(F151="Medium",3,2)))*10)+(IF(I151="Critical",5,IF(I151="High",4,IF(I151="Medium",3,2)))*8)+(IF(K151="Very High",5,IF(K151="High",4,IF(K151="Medium",3,IF(K151="Low",2,1))))*6)+(IF(P151<0,ABS(P151)/7*2,0)))) | P151: =IF(O151<>"",O151-TODAY(),"") | R151: =IF(AND(OR(I151="Medium",I151="High",I151="Critical"),OR(N151="Configuration Change",N151="Policy Update",P151<=7)),"Yes","No")

Sheet Trend_Analysis
A1: Configuration Management Compliance Trend Analysis
A3: ASSESSMENT HISTORY
A4: Cycle | B4: Date | C4: Baseline % | D4: Change % | E4: Monitor % | F4: Harden % | G4: Process % | H4: Overall %
A5: 1
A6: 2
A7: 3
A8: 4
A9: 5
A10: 6
A11: 7
A12: 8
A13: 9
A14: 10
A15: 11
A16: 12
... A24: 20
A26: TREND INDICATORS
A27: Domain | B27: Current % | C27: Previous % | D27: Change | E27: Trend | F27: Status
A28: Baseline Configuration | B28: =INDEX(C:C,MATCH(MAX(B:B),B:B,0)) | C28: =INDEX(C:C,MATCH(MAX(B:B),B:B,0)-1) | D28: =IF(C28<>"",B28-C28,"") | E28: =IF(D28="","",IF(D28>0.02,"↑ Improving",IF(D28<-0.02,"↓ Declining","→ Stable"))) | F28: =IF(B28="","",IF(AND(B28>=0.9,OR(E28="↑ Improving",E28="→ Stable")),"Green",IF(OR(B28<0.8,D28<-0.05),"Red","Yellow")))
A29: Change Control | B29: =INDEX(D:D,MATCH(MAX(B:B),B:B,0)) | C29: =INDEX(D:D,MATCH(MAX(B:B),B:B,0)-1) | D29: =IF(C29<>"",B29-C29,"") | E29: =IF(D29="","",IF(D29>0.02,"↑ Improving",IF(D29<-0.02,"↓ Declining","→ Stable"))) | F29: =IF(B29="","",IF(AND(B29>=0.9,OR(E29="↑ Improving",E29="→ Stable")),"Green",IF(OR(B29<0.8,D29<-0.05),"Red","Yellow")))
A30: Configuration Monitoring | B30: =INDEX(E:E,MATCH(MAX(B:B),B:B,0)) | C30: =INDEX(E:E,MATCH(MAX(B:B),B:B,0)-1) | D30: =IF(C30<>"",B30-C30,"") | E30: =IF(D30="","",IF(D30>0.02,"↑ Improving",IF(D30<-0.02,"↓ Declining","→ Stable"))) | F30: =IF(B30="","",IF(AND(B30>=0.9,OR(E30="↑ Improving",E30="→ Stable")),"Green",IF(OR(B30<0.8,D30<-0.05),"Red","Yellow")))
A31: Security Hardening | B31: =INDEX(F:F,MATCH(MAX(B:B),B:B,0)) | C31: =INDEX(F:F,MATCH(MAX(B:B),B:B,0)-1) | D31: =IF(C31<>"",B31-C31,"") | E31: =IF(D31="","",IF(D31>0.02,"↑ Improving",IF(D31<-0.02,"↓ Declining","→ Stable"))) | F31: =IF(B31="","",IF(AND(B31>=0.9,OR(E31="↑ Improving",E31="→ Stable")),"Green",IF(OR(B31<0.8,D31<-0.05),"Red","Yellow")))
A32: Process Maturity | B32: =INDEX(G:G,MATCH(MAX(B:B),B:B,0)) | C32: =INDEX(G:G,MATCH(MAX(B:B),B:B,0)-1) | D32: =IF(C32<>"",B32-C32,"") | E32: =IF(D32="","",IF(D32>0.02,"↑ Improving",IF(D32<-0.02,"↓ Declining","→ Stable"))) | F32: =IF(B32="","",IF(AND(B32>=0.9,OR(E32="↑ Improving",E32="→ Stable")),"Green",IF(OR(B32<0.8,D32<-0.05),"Red","Yellow")))
A33: OVERALL COMPLIANCE | B33: =INDEX(H:H,MATCH(MAX(B:B),B:B,0)) | C33: =INDEX(H:H,MATCH(MAX(B:B),B:B,0)-1) | D33: =IF(C33<>"",B33-C33,"") | E33: =IF(D33="","",IF(D33>0.02,"↑ Improving",IF(D33<-0.02,"↓ Declining","→ Stable"))) | F33: =IF(B33="","",IF(AND(B33>=0.9,OR(E33="↑ Improving",E33="→ Stable")),"Green",IF(OR(B33<0.8,D33<-0.05),"Red","Yellow")))
A35: GAP TREND ANALYSIS
A36: Cycle | B36: Total Gaps | C36: Critical | D36: High | E36: Closed | F36: Opened | G36: Net Change
A37: 1
A38: 2 | G38: =IF(AND(E38<>"",F38<>""),E38-F38,"")
A39: 3 | G39: =IF(AND(E39<>"",F39<>""),E39-F39,"")
A40: 4 | G40: =IF(AND(E40<>"",F40<>""),E40-F40,"")
A41: 5 | G41: =IF(AND(E41<>"",F41<>""),E41-F41,"")
A42: 6 | G42: =IF(AND(E42<>"",F42<>""),E42-F42,"")
A43: 7 | G43: =IF(AND(E43<>"",F43<>""),E43-F43,"")
A44: 8 | G44: =IF(AND(E44<>"",F44<>""),E44-F44,"")
A45: 9 | G45: =IF(AND(E45<>"",F45<>""),E45-F45,"")
A46: 10 | G46: =IF(AND(E46<>"",F46<>""),E46-F46,"")
A48: FIRST ASSESSMENT GUIDANCE
A49: This is your baseline assessment. Trend analysis requires 3+ assessment cycles.
A51: Next Steps:
A52: 1. Schedule next assessment (recommend quarterly)
...

Sheet Evidence_Register
A1: Evidence_ID | B1: Source_Domain | C1: Source_Document | D1: Source_Evidence_ID | E1: Evidence_Type | F1: Evidence_Description | G1: Related_Control_Area | H1: Collection_Date | I1: Evidence_Location | J1: Evidence_Status | K1: Verification_Status | L1: Audit_Reference | M1: Notes
A2: =IF(B2<>"","EVD-"&TEXT(ROW()-1,"000"),"") | J2: Active | K2: Pending
A3: =IF(B3<>"","EVD-"&TEXT(ROW()-1,"000"),"") | J3: Active | K3: Pending
A4: =IF(B4<>"","EVD-"&TEXT(ROW()-1,"000"),"") | J4: Active | K4: Pending
A5: =IF(B5<>"","EVD-"&TEXT(ROW()-1,"000"),"") | J5: Active | K5: Pending
A6: =IF(B6<>"","EVD-"&TEXT(ROW()-1,"000"),"") | J6: Active | K6: Pending
A7: =IF(B7<>"","EVD-"&TEXT(ROW()-1,"000"),"") | J7: Active | K7: Pending
A8: =IF(B8<>"","EVD-"&TEXT(ROW()-1,"000"),"") | J8: Active | K8: Pending
A9: =IF(B9<>"","EVD-"&TEXT(ROW()-1,"000"),"") | J9: Active | K9: Pending
A10: =IF(B10<>"","EVD-"&TEXT(ROW()-1,"000"),"") | J10: Active | K10: Pending
A11: =IF(B11<>"","EVD-"&TEXT(ROW()-1,"000"),"") | J11: Active | K11: Pending
A12: =IF(B12<>"","EVD-"&TEXT(ROW()-1,"000"),"") | J12: Active | K12: Pending
A13: =IF(B13<>"","EVD-"&TEXT(ROW()-1,"000"),"") | J13: Active | K13: Pending
... A101: =IF(B101<>"","EVD-"&TEXT(ROW()-1,"000"),"") | J101: Active | K101: Pending

Sheet Approval_Sign_Off
A1: Configuration Management Compliance
A2: Approval & Sign-Off
A4: DASHBOARD SUMMARY
A5: Assessment Period | B5: 08.02.2026
A6: Overall Compliance | B6: =Overall_Compliance_Dashboard!B6
A7: Compliance Status | B7: =Overall_Compliance_Dashboard!B7
A8: Total Critical Gaps | B8: =SUM(Overall_Compliance_Dashboard!F12:F16)
A9: Domains Compliant | B9: =Overall_Compliance_Dashboard!B19&"/5"
A11: EXECUTIVE SUMMARY
A12: Summary:
A13: [Provide narrative summary including: • Overall compliance status and trajectory • Key achievements since last review • Critical gaps requiring attention • Resource requirements • Recommended actions]
A15: APPROVAL SIGN-OFF
A16: Tier 1 - Operational Review
A17: Role | B17: Name | C17: Date | D17: Comments
A18: Dashboard Owner | B18: [ISMS Manager]
A19: ISMS Manager | B19: [Name]
A21: Tier 2 - Management Review
A22: Role | B22: Name | C22: Date | D22: Comments
A23: IT Manager | B23: [Name]
A24: Security Manager | B24: [Name]
A26: Tier 3 - Executive Acceptance
A27: Role | B27: Name | C27: Date | D27: Comments
A28: CISO / CIO | B28: [Name]
