Workbook

Sheet Executive Summary
A1: ISMS-OP-CHK-A.8.2-3-5 — Authentication and Privileged Access Compliance Checklist
A3: DOCUMENT INFORMATION
A4: Document ID | B4: ISMS-OP-CHK-A.8.2-3-5
A5: Source Policy | B5: ISMS-OP-POL-A.8.2-3-5
A6: ISO Controls | B6: Authentication and Privileged Access
A7: Generated | B7: 08.02.2026
A8: Prepared By
A9: Organisation
A10: Review Cycle | B10: Annual
A12: OVERALL COMPLIANCE STATUS
A13: Overall Compliance | B13: ='Dashboard'!G9
A14: Status | B14: =IF(Dashboard!G9="N/A","NOT ASSESSED",IF(ISNUMBER(VALUE(SUBSTITUTE(Dashboard!G9,"%",""))),IF(VALUE(SUBSTITUTE(Dashboard!G9,"%",""))>=90,"GREEN",IF(VALUE(SUBSTITUTE(Dashboard!G9,"%",""))>=70,"AMBER","RED")),"NOT ASSESSED"))
A16: KEY METRICS
A17: Total Requirements | B17: ='Dashboard'!B9
A18: Compliant | B18: ='Dashboard'!C9
A19: Partial | B19: ='Dashboard'!D9
A20: Non-Compliant | B20: ='Dashboard'!E9
A21: Not Applicable | B21: ='Dashboard'!F9
A22: Owner Coverage | B22: =IF(Dashboard!B9=0,"N/A",ROUND((COUNTA('Identity and Access Mgmt Infra'!F4:F4)+COUNTA('Authentication Requirements'!F4:F16)+COUNTA('Privileged Access Management'!F4:F21)+COUNTA('Access Restriction'!F4:F10)+COUNTA('Key Performance Indicators'!F4:F5))/Dashboard!B9*100,0)&"%")
A24: DOMAIN STATUS SUMMARY
A25: Domain | B25: Compliance % | C25: Compliant | D25: Gaps | E25: Status
A26: Identity and Access Mgmt Infra | B26: ='Dashboard'!G4 | C26: ='Dashboard'!C4 | D26: ='Dashboard'!E4 | E26: =IF(Dashboard!G4="N/A","--",IF(ISNUMBER(VALUE(SUBSTITUTE(Dashboard!G4,"%",""))),IF(VALUE(SUBSTITUTE(Dashboard!G4,"%",""))>=90,"PASS",IF(VALUE(SUBSTITUTE(Dashboard!G4,"%",""))>=70,"REVIEW","FAIL")),"--"))
A27: Authentication Requirements | B27: ='Dashboard'!G5 | C27: ='Dashboard'!C5 | D27: ='Dashboard'!E5 | E27: =IF(Dashboard!G5="N/A","--",IF(ISNUMBER(VALUE(SUBSTITUTE(Dashboard!G5,"%",""))),IF(VALUE(SUBSTITUTE(Dashboard!G5,"%",""))>=90,"PASS",IF(VALUE(SUBSTITUTE(Dashboard!G5,"%",""))>=70,"REVIEW","FAIL")),"--"))
A28: Privileged Access Management | B28: ='Dashboard'!G6 | C28: ='Dashboard'!C6 | D28: ='Dashboard'!E6 | E28: =IF(Dashboard!G6="N/A","--",IF(ISNUMBER(VALUE(SUBSTITUTE(Dashboard!G6,"%",""))),IF(VALUE(SUBSTITUTE(Dashboard!G6,"%",""))>=90,"PASS",IF(VALUE(SUBSTITUTE(Dashboard!G6,"%",""))>=70,"REVIEW","FAIL")),"--"))
A29: Access Restriction | B29: ='Dashboard'!G7 | C29: ='Dashboard'!C7 | D29: ='Dashboard'!E7 | E29: =IF(Dashboard!G7="N/A","--",IF(ISNUMBER(VALUE(SUBSTITUTE(Dashboard!G7,"%",""))),IF(VALUE(SUBSTITUTE(Dashboard!G7,"%",""))>=90,"PASS",IF(VALUE(SUBSTITUTE(Dashboard!G7,"%",""))>=70,"REVIEW","FAIL")),"--"))
A30: Key Performance Indicators | B30: ='Dashboard'!G8 | C30: ='Dashboard'!C8 | D30: ='Dashboard'!E8 | E30: =IF(Dashboard!G8="N/A","--",IF(ISNUMBER(VALUE(SUBSTITUTE(Dashboard!G8,"%",""))),IF(VALUE(SUBSTITUTE(Dashboard!G8,"%",""))>=90,"PASS",IF(VALUE(SUBSTITUTE(Dashboard!G8,"%",""))>=70,"REVIEW","FAIL")),"--"))
A32: CRITICAL ISSUES
A33: # | B33: Issue Description | C33: Domain | D33: Owner | E33: Due Date
A34: 1
A35: 2
A36: 3
A37: 4
A38: 5
A40: MANAGEMENT COMMENTARY
A41: [Enter management commentary on authentication and privileged access posture]
A45: APPROVAL
A46: Assessed By
A47: Name:
A48: Date:
A49: Signature:
...

Sheet Dashboard
A1: Authentication and Privileged Access — Compliance Dashboard
A3: Domain | B3: Total Reqs | C3: Compliant | D3: Partial | E3: Non-Compliant | F3: N/A | G3: Compliance %
A4: Identity and Access Mgmt Infra | B4: =COUNTA('Identity and Access Mgmt Infra'!D4:D4) | C4: =COUNTIF('Identity and Access Mgmt Infra'!D4:D4,"Compliant") | D4: =COUNTIF('Identity and Access Mgmt Infra'!D4:D4,"Partial") | E4: =COUNTIF('Identity and Access Mgmt Infra'!D4:D4,"Non-Compliant") | F4: =COUNTIF('Identity and Access Mgmt Infra'!D4:D4,"N/A") | G4: =IF((B4-F4)=0,"N/A",ROUND(C4/(B4-F4)*100,1)&"%")
A5: Authentication Requirements | B5: =COUNTA('Authentication Requirements'!D4:D16) | C5: =COUNTIF('Authentication Requirements'!D4:D16,"Compliant") | D5: =COUNTIF('Authentication Requirements'!D4:D16,"Partial") | E5: =COUNTIF('Authentication Requirements'!D4:D16,"Non-Compliant") | F5: =COUNTIF('Authentication Requirements'!D4:D16,"N/A") | G5: =IF((B5-F5)=0,"N/A",ROUND(C5/(B5-F5)*100,1)&"%")
A6: Privileged Access Management | B6: =COUNTA('Privileged Access Management'!D4:D21) | C6: =COUNTIF('Privileged Access Management'!D4:D21,"Compliant") | D6: =COUNTIF('Privileged Access Management'!D4:D21,"Partial") | E6: =COUNTIF('Privileged Access Management'!D4:D21,"Non-Compliant") | F6: =COUNTIF('Privileged Access Management'!D4:D21,"N/A") | G6: =IF((B6-F6)=0,"N/A",ROUND(C6/(B6-F6)*100,1)&"%")
A7: Access Restriction | B7: =COUNTA('Access Restriction'!D4:D10) | C7: =COUNTIF('Access Restriction'!D4:D10,"Compliant") | D7: =COUNTIF('Access Restriction'!D4:D10,"Partial") | E7: =COUNTIF('Access Restriction'!D4:D10,"Non-Compliant") | F7: =COUNTIF('Access Restriction'!D4:D10,"N/A") | G7: =IF((B7-F7)=0,"N/A",ROUND(C7/(B7-F7)*100,1)&"%")
A8: Key Performance Indicators | B8: =COUNTA('Key Performance Indicators'!D4:D5) | C8: =COUNTIF('Key Performance Indicators'!D4:D5,"Compliant") | D8: =COUNTIF('Key Performance Indicators'!D4:D5,"Partial") | E8: =COUNTIF('Key Performance Indicators'!D4:D5,"Non-Compliant") | F8: =COUNTIF('Key Performance Indicators'!D4:D5,"N/A") | G8: =IF((B8-F8)=0,"N/A",ROUND(C8/(B8-F8)*100,1)&"%")
A9: TOTAL | B9: =SUM(B4:B8) | C9: =SUM(C4:C8) | D9: =SUM(D4:D8) | E9: =SUM(E4:E8) | F9: =SUM(F4:F8) | G9: =IF((B9-F9)=0,"N/A",ROUND(C9/(B9-F9)*100,1)&"%")
A11: COMPLIANCE BY STATUS
A12: Compliant | B12: =C9 | C12: =IF(B9=0,"",ROUND(B12/B9*100,1)&"%")
A13: Partial | B13: =D9 | C13: =IF(B9=0,"",ROUND(B13/B9*100,1)&"%")
A14: Non-Compliant | B14: =E9 | C14: =IF(B9=0,"",ROUND(B14/B9*100,1)&"%")
A15: N/A | B15: =F9 | C15: =IF(B9=0,"",ROUND(B15/B9*100,1)&"%")
A17: TOP GAPS (Manual Entry)
A18: Priority | B18: Domain | C18: Requirement | D18: Owner | E18: Due Date | F18: Status
A30: COMPLIANCE TREND (Manual Entry)
A31: Assessment Date | B31: Overall % | C31: Compliant | D31: Gaps | E31: Assessor | F31: Notes

Sheet Identity and Access Mgmt Infra
A1: Identity and Access Mgmt Infra — Compliance Checklist
A2: ISO/IEC 27001:2022 — Controls A.8.2-3-5: Authentication and Privileged Access
A3: Req # | B3: Section | C3: Requirement | D3: Status | E3: Evidence | F3: Owner | G3: Due Date | H3: Notes
A4: A.8.2-3-5-01 | B4: Integration Points*: Idp | C4: Integration points*: IdP shall integrate with HR system for joiner/mover/leaver automation. PAM, IdP, and SIEM shall be integrated for centralised monitoring. MFA shall be enforced via IdP conditional access policies. Session recording logs shall forward to SIEM.

Sheet Authentication Requirements
A1: Authentication Requirements — Compliance Checklist
A2: ISO/IEC 27001:2022 — Controls A.8.2-3-5: Authentication and Privileged Access
A3: Req # | B3: Section | C3: Requirement | D3: Status | E3: Evidence | F3: Owner | G3: Due Date | H3: Notes
A4: A.8.2-3-5-02 | B4: Access To Systems And Information Is | C4: Access to systems and information is authenticated by passwords or stronger mechanisms. The organisation shall enforce the following password standards, aligned with NIST SP 800-63B:.
A5: A.8.2-3-5-03 | B5: Passwords Found In Breach Databases | C5: Passwords found in breach databases shall be rejected at set/change and force-changed if detected during monthly scans. Screening coverage metric: percentage of password set/change events validated against breach databases (target: 100%).
A6: A.8.2-3-5-04 | B6: Multi-Factor Authentication | C6: Multi-factor authentication shall be required for:.
A7: A.8.2-3-5-05 | B7: Sms-Based Otp Should Be Phased Out | C7: SMS-based OTP should be phased out where possible due to known vulnerabilities (SIM swapping, interception). Systems relying solely on SMS-based MFA shall be documented in the risk register with a migration plan.
A8: A.8.2-3-5-06 | B8: Systems Unable To Support Mfa | C8: Systems unable to support MFA shall be documented in the risk register with technical justification, compensating controls (e.g., network segmentation, enhanced monitoring, IP restriction), and CISO-approved risk acceptance reviewed annually.
A9: A.8.2-3-5-07 | B9: Implement Centralised Sso Via The | C9: The organisation shall implement centralised SSO via the identity provider using SAML 2.0 or OIDC with the following targets:.
A10: A.8.2-3-5-08 | B10: An Sso Integration Inventory | C10: An SSO integration inventory shall be maintained listing each application, its SSO status (integrated / in progress / exception), priority tier, and target date. The inventory shall be reviewed quarterly.
A11: A.8.2-3-5-09 | B11: Authentication Events | C11: All authentication events shall be logged and forwarded to the centralised logging system SIEM:.
A12: A.8.2-3-5-10 | B12: Authentication Logs | C12: Authentication logs shall be retained for a minimum of 12 months.
A13: A.8.2-3-5-11 | B13: Approved Geographic Locations*: | C13: Approved geographic locations*: Switzerland, [additional countries per business operations]. Logins from unapproved countries shall trigger alerts per table above.
A14: A.8.2-3-5-12 | B14: Alert Rules | C14: Alert rules shall be reviewed and tuned quarterly to reduce false positive rates. Investigation workflow: receive alert → validate (true/false positive) → enrich with context → escalate if confirmed → document outcome.
A15: A.8.2-3-5-13 | B15: The Main Access Authentication System | C15: The main access authentication system shall:.
A16: A.8.2-3-5-14 | B16: Validate The Log-On Information Only On | C16: Validate the log-on information only on completion of all input data. If an error condition arises, the system shall not indicate which part of the data is correct or incorrect.

Sheet Privileged Access Management
A1: Privileged Access Management — Compliance Checklist
A2: ISO/IEC 27001:2022 — Controls A.8.2-3-5: Authentication and Privileged Access
A3: Req # | B3: Section | C3: Requirement | D3: Status | E3: Evidence | F3: Owner | G3: Due Date | H3: Notes
A4: A.8.2-3-5-15 | B4: Privileged Access | C4: Privileged access shall be restricted based on:.
A5: A.8.2-3-5-16 | B5: Implement Tiered Administration To Limit | C5: The organisation shall implement tiered administration to limit the impact of compromised credentials:.
A6: A.8.2-3-5-17 | B6: Tier 0 Accounts | C6: Tier 0 accounts shall never authenticate to Tier 1 or Tier 2 systems.
A7: A.8.2-3-5-18 | B7: Tier 1 Accounts | C7: Tier 1 accounts shall never authenticate to Tier 2 systems.
A8: A.8.2-3-5-19 | B8: Separate Credentials | C8: Separate credentials shall be used per tier (e.g., j.smith.t0, j.smith.t1).
A9: A.8.2-3-5-20 | B9: Daily Work Activities (Email, Web | C9: Daily work activities (email, web browsing) shall not be performed on dedicated admin workstations.
A10: A.8.2-3-5-21 | B10: Technical Controls | C10: Technical controls shall enforce tier boundaries. The following are implementation options depending on the organisation's identity platform:.
A11: A.8.2-3-5-22 | B11: Phased Deployment*: Phase 1 (Year 1) | C11: Phased deployment*: Phase 1 (Year 1): Tier 0 PAWs deployed. Phase 2 (Year 2): Tier 1 PAWs deployed. Compensating controls shall be documented for any period where PAWs are not yet in place (e.g., enhanced monitoring, dedicated VMs, restricted admin accounts on standard workstations).
A12: A.8.2-3-5-23 | B12: Deployment Status Tracking*: The Current | C12: Deployment status tracking*: The current deployment phase (planning, pilot, partial enforcement, full enforcement) shall be documented for each tier with compensating controls for non-enforced tiers and target completion dates.
A13: A.8.2-3-5-24 | B13: Privileged Accounts | C13: All privileged accounts shall be:.
A14: A.8.2-3-5-25 | B14: Implement Privileged Access Controls, | C14: The organisation shall implement privileged access controls, which may include a dedicated PAM solution PAM solution (see IAM Infrastructure table) or equivalent manual controls:.
A15: A.8.2-3-5-26 | B15: Compensating Controls | C15: Where a dedicated PAM solution is not yet deployed, compensating controls shall be documented (e.g., manual credential rotation, shared password manager with audit trail, alternative session logging via SIEM).
... A21: A.8.2-3-5-32 | B21: Test Records | C21: Test records shall document the date, tester, successful authentication confirmation, and post-test credential rotation.

Sheet Access Restriction
A1: Access Restriction — Compliance Checklist
A2: ISO/IEC 27001:2022 — Controls A.8.2-3-5: Authentication and Privileged Access
A3: Req # | B3: Section | C3: Requirement | D3: Status | E3: Evidence | F3: Owner | G3: Due Date | H3: Notes
A4: A.8.2-3-5-33 | B4: Access To Information And Other | C4: Access to information and other associated assets shall be restricted in accordance with this policy and the Identity and Access Management Policy:.
A5: A.8.2-3-5-34 | B5: System Sessions | C5: System sessions shall enforce the following timeout periods:.
A6: A.8.2-3-5-35 | B6: Network Segmentation | C6: Network segmentation shall separate trust zones to support access restriction (detailed in the Network Security Policy).
A7: A.8.2-3-5-36 | B7: Firewall Rules | C7: Firewall rules shall enforce access boundaries between network segments.
A8: A.8.2-3-5-37 | B8: Network Access Control (Nac) Or | C8: Network access control (NAC) or equivalent shall verify endpoint compliance before granting access where feasible.
A9: A.8.2-3-5-38 | B9: The Organisation Masks Data In Line | C9: The organisation masks data in line with legal and regulatory obligations, including Swiss nFADP and GDPR requirements where applicable. Data masking shall be applied to:.
A10: A.8.2-3-5-39 | B10: Verify Access Controls Through | C10: The organisation shall verify access controls through:.

Sheet Key Performance Indicators
A1: Key Performance Indicators — Compliance Checklist
A2: ISO/IEC 27001:2022 — Controls A.8.2-3-5: Authentication and Privileged Access
A3: Req # | B3: Section | C3: Requirement | D3: Status | E3: Evidence | F3: Owner | G3: Due Date | H3: Notes
A4: A.8.2-3-5-40 | B4: The Following Metrics | C4: The following metrics shall be tracked to measure the effectiveness of authentication and privileged access controls:.
A5: A.8.2-3-5-41 | B5: Be Reported To The Ciso Quarterly | C5: Metrics shall be reported to the CISO quarterly. Metrics falling below target shall include a remediation plan with owner and target date.
