Workbook

Sheet Executive Summary
A1: CLD-PII-CHK-A.7 — Accuracy and Quality Compliance Checklist
A3: DOCUMENT INFORMATION
A4: Document ID | B4: CLD-PII-CHK-A.7
A5: Source Policy | B5: CLD-PII-POL-A.7
A6: ISO Controls | B6: Accuracy and Quality
A7: Generated | B7: 30.09.2026
A8: Prepared By
A9: Organisation
A10: Review Cycle | B10: Annual
A12: OVERALL COMPLIANCE STATUS
A13: Overall Compliance | B13: ='Dashboard'!G6
A14: Status | B14: =IF(Dashboard!H6>0,"INCOMPLETE",IF(Dashboard!G6="N/A","NOT ASSESSED",IF(ISNUMBER(VALUE(SUBSTITUTE(Dashboard!G6,"%",""))),IF(VALUE(SUBSTITUTE(Dashboard!G6,"%",""))>=90,"GREEN",IF(VALUE(SUBSTITUTE(Dashboard!G6,"%",""))>=70,"AMBER","RED")),"NOT ASSESSED")))
A16: KEY METRICS
A17: Total Requirements | B17: ='Dashboard'!B6
A18: Compliant | B18: ='Dashboard'!C6
A19: Partial | B19: ='Dashboard'!D6
A20: Non-Compliant | B20: ='Dashboard'!E6
A21: Not Applicable | B21: ='Dashboard'!F6
A22: Unanswered | B22: ='Dashboard'!H6
A23: Owner Coverage | B23: =IF(Dashboard!B6=0,"N/A",ROUND((COUNTA('Data Integrity Preservation'!F4:F7)+COUNTA('Controller Correction Mechanisms and Quality Checks'!F4:F7))/Dashboard!B6*100,0)&"%")
A25: DOMAIN STATUS SUMMARY
A26: Domain | B26: Compliance % | C26: Compliant | D26: Gaps | E26: Status
A27: Data Integrity Preservation | B27: ='Dashboard'!G4 | C27: ='Dashboard'!C4 | D27: ='Dashboard'!E4 | E27: =IF(Dashboard!H4>0,"INCOMPLETE",IF(Dashboard!G4="N/A","--",IF(ISNUMBER(VALUE(SUBSTITUTE(Dashboard!G4,"%",""))),IF(VALUE(SUBSTITUTE(Dashboard!G4,"%",""))>=90,"PASS",IF(VALUE(SUBSTITUTE(Dashboard!G4,"%",""))>=70,"REVIEW","FAIL")),"--")))
A28: Controller Correction Mechanisms and Quality Checks | B28: ='Dashboard'!G5 | C28: ='Dashboard'!C5 | D28: ='Dashboard'!E5 | E28: =IF(Dashboard!H5>0,"INCOMPLETE",IF(Dashboard!G5="N/A","--",IF(ISNUMBER(VALUE(SUBSTITUTE(Dashboard!G5,"%",""))),IF(VALUE(SUBSTITUTE(Dashboard!G5,"%",""))>=90,"PASS",IF(VALUE(SUBSTITUTE(Dashboard!G5,"%",""))>=70,"REVIEW","FAIL")),"--")))
A30: CRITICAL ISSUES
A31: # | B31: Issue Description | C31: Domain | D31: Owner | E31: Due Date
A32: 1
A33: 2
A34: 3
A35: 4
A36: 5
A38: MANAGEMENT COMMENTARY
A39: [Enter management commentary on accuracy and quality posture]
A43: APPROVAL
A44: Assessed By
A45: Name:
A46: Date:
A47: Signature:
A48: Decision:
A50: Reviewed By (DPO)
...

Sheet Dashboard
A1: Accuracy and Quality — Compliance Dashboard
A3: Domain | B3: Total Reqs | C3: Compliant | D3: Partial | E3: Non-Compliant | F3: N/A | G3: Compliance % | H3: Unassessed
A4: Data Integrity Preservation | B4: =COUNTA('Data Integrity Preservation'!A4:A7) | C4: =COUNTIF('Data Integrity Preservation'!D4:D7,"Compliant") | D4: =COUNTIF('Data Integrity Preservation'!D4:D7,"Partial") | E4: =COUNTIF('Data Integrity Preservation'!D4:D7,"Non-Compliant") | F4: =COUNTIF('Data Integrity Preservation'!D4:D7,"N/A") | G4: =IF((B4-F4)=0,"N/A",ROUND(C4/(B4-F4)*100,1)&"%") | H4: =B4-(C4+D4+E4+F4)
A5: Controller Correction Mechanisms and Quality Checks | B5: =COUNTA('Controller Correction Mechanisms and Quality Checks'!A4:A7) | C5: =COUNTIF('Controller Correction Mechanisms and Quality Checks'!D4:D7,"Compliant") | D5: =COUNTIF('Controller Correction Mechanisms and Quality Checks'!D4:D7,"Partial") | E5: =COUNTIF('Controller Correction Mechanisms and Quality Checks'!D4:D7,"Non-Compliant") | F5: =COUNTIF('Controller Correction Mechanisms and Quality Checks'!D4:D7,"N/A") | G5: =IF((B5-F5)=0,"N/A",ROUND(C5/(B5-F5)*100,1)&"%") | H5: =B5-(C5+D5+E5+F5)
A6: TOTAL | B6: =SUM(B4:B5) | C6: =SUM(C4:C5) | D6: =SUM(D4:D5) | E6: =SUM(E4:E5) | F6: =SUM(F4:F5) | G6: =IF((B6-F6)=0,"N/A",ROUND(C6/(B6-F6)*100,1)&"%") | H6: =SUM(H4:H5)
A8: COMPLIANCE BY STATUS
A9: Compliant | B9: =C6 | C9: =IF(B6=0,"",ROUND(B9/B6*100,1)&"%")
A10: Partial | B10: =D6 | C10: =IF(B6=0,"",ROUND(B10/B6*100,1)&"%")
A11: Non-Compliant | B11: =E6 | C11: =IF(B6=0,"",ROUND(B11/B6*100,1)&"%")
A12: N/A | B12: =F6 | C12: =IF(B6=0,"",ROUND(B12/B6*100,1)&"%")
A14: TOP GAPS (Manual Entry)
A15: Priority | B15: Domain | C15: Requirement | D15: Owner | E15: Due Date | F15: Status
A27: COMPLIANCE TREND (Manual Entry)
A28: Assessment Date | B28: Overall % | C28: Compliant | D28: Gaps | E28: Assessor | F28: Notes

Sheet Data Integrity Preservation
A1: Data Integrity Preservation — Compliance Checklist
A2: ISO/IEC 27018:2025 — Controls A.7: Accuracy and Quality
A3: Req # | B3: Section | C3: Requirement | D3: Status | E3: Evidence | F3: Owner | G3: Due Date | H3: Notes
A4: A.7-01 | B4: Integrity Controls | C4: The organisation shall implement technical controls ensuring that PII stored in cloud systems is not degraded, corrupted, or altered through processing operations except as authorised by the PII controller. Storage systems shall implement integrity checking (e.g., checksums, cryptographic hashes) for PII data stores to detect unauthorised or accidental modification.
A5: A.7-02 | B5: Transformation Logging | C5: Transformation operations performed on PII during processing shall be reversible or logged, ensuring the original data can be verified or restored. Backup and replication operations shall preserve PII accuracy and completeness without data loss.
A6: A.7-03 | B6: Processing-Induced Inaccuracy | C6: Where the organisation performs data transformation, enrichment, or processing operations on PII on behalf of a controller, the organisation shall: document the transformation logic and its effect on PII accuracy; obtain controller authorisation for any transformation that modifies PII attributes; and alert the controller if a processing operation produces results that indicate potential inaccuracy in the source data.
A7: A.7-04 | B7: Integrity Check Configuration Records | C7: Technical documentation of integrity checking mechanisms implemented for PII data stores shall be maintained as evidence, including the mechanism type, scope of data stores covered, and verification frequency. Records shall be retained for the duration of the service plus 3 years.

Sheet Controller Correction Mechanisms and Quality Checks
A1: Controller Correction Mechanisms and Quality Checks — Compliance Checklist
A2: ISO/IEC 27018:2025 — Controls A.7: Accuracy and Quality
A3: Req # | B3: Section | C3: Requirement | D3: Status | E3: Evidence | F3: Owner | G3: Due Date | H3: Notes
A4: A.7-05 | B4: Controller Correction Capabilities | C4: The organisation shall provide PII controllers with technical capabilities to correct, update, and delete PII within cloud storage. These mechanisms shall allow field-level correction or full record update for structured PII data stores, and shall propagate corrections to replicated copies (backups, read replicas, caches) within a reasonable timeframe enabling the controller to fulfil data subject rights obligations.
A5: A.7-06 | B5: Correction Confirmation Records | C5: The organisation shall generate a confirmation record when PII corrections are completed, including which records were modified and the timestamp. Correction confirmation records shall be provided to the controller on request and retained for the duration of the service plus 3 years.
A6: A.7-07 | B6: Quality Checks | C6: The organisation shall implement the following quality controls for PII data stores: data completeness checks (identify and flag records with missing mandatory fields that may indicate data corruption or incomplete transfer); data consistency checks (verify PII consistency across replicated or distributed data stores to detect replication errors); and backup integrity verification (periodically restore and verify backup PII data to confirm backup integrity).
A7: A.7-08 | B7: Quality Check Review and Reporting | C7: Quality check results shall be logged and reviewed quarterly by the Cloud Engineering team. Material data quality issues shall be reported to the PII controller without undue delay. Data quality incident records shall be retained for the duration of the service plus 3 years.
