Workbook

Sheet Instructions & Legend
A1: ISMS-IMP-A.5.30.S3 - RPO RTO Compliance ISO/IEC 27001:2022 - Control A.5.30: Information Backup
A3: Document Information
A4: Document ID | B4: ISMS-IMP-A.5.30.S3
A5: Workbook Title | B5: RPO RTO Compliance
A6: Control Reference | B6: ISO/IEC 27001:2022 - Control A.5.30: Information Backup
A7: Version | B7: 1.0
A8: Assessment Date
A9: Completed By
A10: Organisation
A12: Instructions
A13: 1. Populate the System Inventory worksheet from Business Impact Analysis (BIA) results.
A14: 2. Populate the Capability Assessment worksheet with TESTED technical recovery capabilities.
A15: 3. Review the Compliance Matrix (formulas automatically compare requirements vs capabilities).
A16: 4. Document identified gaps in the Gap Analysis worksheet with remediation plans.
A17: 5. Collect evidence in the Evidence Register (minimum 5 items required for audit).
A18: 6. Review the Summary Dashboard for overall compliance metrics.
A19: 7. Complete the Approval Sign-Off worksheet to obtain formal sign-off.
A20: 8. Re-assess quarterly to track improvement and maintain compliance.
A22: Status Legend
A23: Symbol | B23: Status | C23: Description
A24: ✓ | B24: Compliant / Complete | C24: Requirement fully met
A25: ⚠ | B25: Partial / In Progress | C25: Partially met or in progress
A26: ✗ | B26: Non-Compliant / Not Started | C26: Requirement not met
A27: — | B27: Not Applicable | C27: Not applicable to this assessment
A29: Acceptable Evidence (examples)
A30: ✓ Business Impact Analysis (BIA) report with RPO/RTO requirements for each system
A31: ✓ Backup restore test records with date, system, and actual restore time
A32: ✓ Failover test records with date, system, and actual failover time
A33: ✓ Gap analysis report showing RPO/RTO gaps and risk scores
A34: ✓ Remediation plans for identified gaps with target dates
A35: ✓ System criticality register from BIA process
A36: ✓ Testing schedules and historical test logs
A37: ✓ Compliance calculation worksheets and summary reports

Sheet System Inventory
A1: SYSTEM INVENTORY - BIA RESULTS
A2: Source: Business Impact Analysis (BIA) - RPO/RTO requirements from business stakeholders
A4: System Name | B4: Business Process | C4: Criticality Tier | D4: MTPD (hours) | E4: RPO Requirement (hours) | F4: RTO Requirement (hours) | G4: Business Justification
A15: Example: Application Server | B15: Online Services | C15: Tier 1 - Critical | D15: 4 | E15: 1 | F15: 2 | G15: Enter business justification for RPO/RTO requirements here
A67: DATA SOURCE: Business Impact Analysis (BIA) - Requirements are business-driven, not IT-driven
A68: MTPD = Maximum Tolerable Period of Disruption | RPO = Recovery Point Objective | RTO = Recovery Time Objective

Sheet Capability Assessment
A1: CAPABILITY ASSESSMENT - TESTED TECHNICAL CAPABILITIES
A2: Source: Testing Results - Actual measured recovery times (restore tests, failover tests)
A4: System Name | B4: Backup Frequency (hours) | C4: Restore Time Tested (hours) | D4: Failover Time Tested (hours) | E4: RPO Capability (hours) | F4: RTO Capability (hours) | G4: Test Notes / Observations
E5: =IF(ISNUMBER(B5),B5,"") | F5: =IF(AND(ISNUMBER(C5),ISNUMBER(D5)),MIN(C5,D5),IF(ISNUMBER(C5),C5,IF(ISNUMBER(D5),D5,"")))
E6: =IF(ISNUMBER(B6),B6,"") | F6: =IF(AND(ISNUMBER(C6),ISNUMBER(D6)),MIN(C6,D6),IF(ISNUMBER(C6),C6,IF(ISNUMBER(D6),D6,"")))
E7: =IF(ISNUMBER(B7),B7,"") | F7: =IF(AND(ISNUMBER(C7),ISNUMBER(D7)),MIN(C7,D7),IF(ISNUMBER(C7),C7,IF(ISNUMBER(D7),D7,"")))
E8: =IF(ISNUMBER(B8),B8,"") | F8: =IF(AND(ISNUMBER(C8),ISNUMBER(D8)),MIN(C8,D8),IF(ISNUMBER(C8),C8,IF(ISNUMBER(D8),D8,"")))
E9: =IF(ISNUMBER(B9),B9,"") | F9: =IF(AND(ISNUMBER(C9),ISNUMBER(D9)),MIN(C9,D9),IF(ISNUMBER(C9),C9,IF(ISNUMBER(D9),D9,"")))
E10: =IF(ISNUMBER(B10),B10,"") | F10: =IF(AND(ISNUMBER(C10),ISNUMBER(D10)),MIN(C10,D10),IF(ISNUMBER(C10),C10,IF(ISNUMBER(D10),D10,"")))
E11: =IF(ISNUMBER(B11),B11,"") | F11: =IF(AND(ISNUMBER(C11),ISNUMBER(D11)),MIN(C11,D11),IF(ISNUMBER(C11),C11,IF(ISNUMBER(D11),D11,"")))
E12: =IF(ISNUMBER(B12),B12,"") | F12: =IF(AND(ISNUMBER(C12),ISNUMBER(D12)),MIN(C12,D12),IF(ISNUMBER(C12),C12,IF(ISNUMBER(D12),D12,"")))
E13: =IF(ISNUMBER(B13),B13,"") | F13: =IF(AND(ISNUMBER(C13),ISNUMBER(D13)),MIN(C13,D13),IF(ISNUMBER(C13),C13,IF(ISNUMBER(D13),D13,"")))
E14: =IF(ISNUMBER(B14),B14,"") | F14: =IF(AND(ISNUMBER(C14),ISNUMBER(D14)),MIN(C14,D14),IF(ISNUMBER(C14),C14,IF(ISNUMBER(D14),D14,"")))
A15: Example: Application Server | B15: 1 | C15: 4 | E15: =IF(ISNUMBER(B15),B15,"") | F15: =IF(AND(ISNUMBER(C15),ISNUMBER(D15)),MIN(C15,D15),IF(ISNUMBER(C15),C15,IF(ISNUMBER(D15),D15,""))) | G15: Enter tested recovery times and observations
E16: =IF(ISNUMBER(B16),B16,"") | F16: =IF(AND(ISNUMBER(C16),ISNUMBER(D16)),MIN(C16,D16),IF(ISNUMBER(C16),C16,IF(ISNUMBER(D16),D16,"")))
E17: =IF(ISNUMBER(B17),B17,"") | F17: =IF(AND(ISNUMBER(C17),ISNUMBER(D17)),MIN(C17,D17),IF(ISNUMBER(C17),C17,IF(ISNUMBER(D17),D17,"")))
E18: =IF(ISNUMBER(B18),B18,"") | F18: =IF(AND(ISNUMBER(C18),ISNUMBER(D18)),MIN(C18,D18),IF(ISNUMBER(C18),C18,IF(ISNUMBER(D18),D18,"")))
E19: =IF(ISNUMBER(B19),B19,"") | F19: =IF(AND(ISNUMBER(C19),ISNUMBER(D19)),MIN(C19,D19),IF(ISNUMBER(C19),C19,IF(ISNUMBER(D19),D19,"")))
E20: =IF(ISNUMBER(B20),B20,"") | F20: =IF(AND(ISNUMBER(C20),ISNUMBER(D20)),MIN(C20,D20),IF(ISNUMBER(C20),C20,IF(ISNUMBER(D20),D20,"")))
E21: =IF(ISNUMBER(B21),B21,"") | F21: =IF(AND(ISNUMBER(C21),ISNUMBER(D21)),MIN(C21,D21),IF(ISNUMBER(C21),C21,IF(ISNUMBER(D21),D21,"")))
E22: =IF(ISNUMBER(B22),B22,"") | F22: =IF(AND(ISNUMBER(C22),ISNUMBER(D22)),MIN(C22,D22),IF(ISNUMBER(C22),C22,IF(ISNUMBER(D22),D22,"")))
E23: =IF(ISNUMBER(B23),B23,"") | F23: =IF(AND(ISNUMBER(C23),ISNUMBER(D23)),MIN(C23,D23),IF(ISNUMBER(C23),C23,IF(ISNUMBER(D23),D23,"")))
E24: =IF(ISNUMBER(B24),B24,"") | F24: =IF(AND(ISNUMBER(C24),ISNUMBER(D24)),MIN(C24,D24),IF(ISNUMBER(C24),C24,IF(ISNUMBER(D24),D24,"")))
E25: =IF(ISNUMBER(B25),B25,"") | F25: =IF(AND(ISNUMBER(C25),ISNUMBER(D25)),MIN(C25,D25),IF(ISNUMBER(C25),C25,IF(ISNUMBER(D25),D25,"")))
E26: =IF(ISNUMBER(B26),B26,"") | F26: =IF(AND(ISNUMBER(C26),ISNUMBER(D26)),MIN(C26,D26),IF(ISNUMBER(C26),C26,IF(ISNUMBER(D26),D26,"")))
E27: =IF(ISNUMBER(B27),B27,"") | F27: =IF(AND(ISNUMBER(C27),ISNUMBER(D27)),MIN(C27,D27),IF(ISNUMBER(C27),C27,IF(ISNUMBER(D27),D27,"")))
... E65: =IF(ISNUMBER(B65),B65,"") | F65: =IF(AND(ISNUMBER(C65),ISNUMBER(D65)),MIN(C65,D65),IF(ISNUMBER(C65),C65,IF(ISNUMBER(D65),D65,"")))
A67: DATA SOURCE: Testing Results - CRITICAL: Capabilities must be TESTED, not assumed. Untested = Unknown compliance.
A68: RPO Capability = Backup Frequency | RTO Capability = MIN(Restore Time, Failover Time) - formulas auto-calculate

Sheet Compliance Matrix
A1: RPO/RTO COMPLIANCE MATRIX
A2: Automatic comparison: Business Requirements (System Inventory) vs Technical Capabilities (Capability Assessment)
A4: System Name | B4: Criticality | C4: RPO: Req vs Cap | D4: RTO: Req vs Cap | E4: Overall Compliance | F4: Priority | G4: Gap Summary | H4: Next Action Required
A5: ='System Inventory'!A5 | B5: ='System Inventory'!C5 | C5: =IF(A5="","",IF(OR('System Inventory'!E5="",'Capability Assessment'!E5=""),"❓ Unknown",IF('Capability Assessment'!E5<='System Inventory'!E5,"✅ Compliant","❌ Non-Compliant"))) | D5: =IF(A5="","",IF(OR('System Inventory'!F5="",'Capability Assessment'!F5=""),"❓ Unknown",IF('Capability Assessment'!F5<='System Inventory'!F5,"✅ Compliant","❌ Non-Compliant"))) | E5: =IF(A5="","",IF(OR(C5="❓ Unknown",D5="❓ Unknown"),"❓ Unknown",IF(AND(C5="✅ Compliant",D5="✅ Compliant"),"✅ Full Compliance",IF(OR(C5="✅ Compliant",D5="✅ Compliant"),"⚠ Partial Compliance","❌ Non-Compliant")))) | F5: =IF(A5="","",IF(AND(B5="Tier 1 - Critical",E5="❌ Non-Compliant"),"[!] Critical",IF(B5="Tier 1 - Critical","[~] High",IF(E5="❌ Non-Compliant","[~] High",IF(E5="⚠ Partial Compliance","[.] Medium","[ ] Low"))))) | G5: =IF(A5="","",IF(C5="❌ Non-Compliant",IF(D5="❌ Non-Compliant","Both RPO & RTO gaps","RPO gap only"),IF(D5="❌ Non-Compliant","RTO gap only",IF(E5="❓ Unknown","Testing required","No gaps")))) | H5: Monitor continuously, maintain current state
A6: ='System Inventory'!A6 | B6: ='System Inventory'!C6 | C6: =IF(A6="","",IF(OR('System Inventory'!E6="",'Capability Assessment'!E6=""),"❓ Unknown",IF('Capability Assessment'!E6<='System Inventory'!E6,"✅ Compliant","❌ Non-Compliant"))) | D6: =IF(A6="","",IF(OR('System Inventory'!F6="",'Capability Assessment'!F6=""),"❓ Unknown",IF('Capability Assessment'!F6<='System Inventory'!F6,"✅ Compliant","❌ Non-Compliant"))) | E6: =IF(A6="","",IF(OR(C6="❓ Unknown",D6="❓ Unknown"),"❓ Unknown",IF(AND(C6="✅ Compliant",D6="✅ Compliant"),"✅ Full Compliance",IF(OR(C6="✅ Compliant",D6="✅ Compliant"),"⚠ Partial Compliance","❌ Non-Compliant")))) | F6: =IF(A6="","",IF(AND(B6="Tier 1 - Critical",E6="❌ Non-Compliant"),"[!] Critical",IF(B6="Tier 1 - Critical","[~] High",IF(E6="❌ Non-Compliant","[~] High",IF(E6="⚠ Partial Compliance","[.] Medium","[ ] Low"))))) | G6: =IF(A6="","",IF(C6="❌ Non-Compliant",IF(D6="❌ Non-Compliant","Both RPO & RTO gaps","RPO gap only"),IF(D6="❌ Non-Compliant","RTO gap only",IF(E6="❓ Unknown","Testing required","No gaps")))) | H6: Monitor continuously, critical system
A7: ='System Inventory'!A7 | B7: ='System Inventory'!C7 | C7: =IF(A7="","",IF(OR('System Inventory'!E7="",'Capability Assessment'!E7=""),"❓ Unknown",IF('Capability Assessment'!E7<='System Inventory'!E7,"✅ Compliant","❌ Non-Compliant"))) | D7: =IF(A7="","",IF(OR('System Inventory'!F7="",'Capability Assessment'!F7=""),"❓ Unknown",IF('Capability Assessment'!F7<='System Inventory'!F7,"✅ Compliant","❌ Non-Compliant"))) | E7: =IF(A7="","",IF(OR(C7="❓ Unknown",D7="❓ Unknown"),"❓ Unknown",IF(AND(C7="✅ Compliant",D7="✅ Compliant"),"✅ Full Compliance",IF(OR(C7="✅ Compliant",D7="✅ Compliant"),"⚠ Partial Compliance","❌ Non-Compliant")))) | F7: =IF(A7="","",IF(AND(B7="Tier 1 - Critical",E7="❌ Non-Compliant"),"[!] Critical",IF(B7="Tier 1 - Critical","[~] High",IF(E7="❌ Non-Compliant","[~] High",IF(E7="⚠ Partial Compliance","[.] Medium","[ ] Low"))))) | G7: =IF(A7="","",IF(C7="❌ Non-Compliant",IF(D7="❌ Non-Compliant","Both RPO & RTO gaps","RPO gap only"),IF(D7="❌ Non-Compliant","RTO gap only",IF(E7="❓ Unknown","Testing required","No gaps")))) | H7: Consider more frequent backups (currently 4hr, need 4hr RTO)
A8: ='System Inventory'!A8 | B8: ='System Inventory'!C8 | C8: =IF(A8="","",IF(OR('System Inventory'!E8="",'Capability Assessment'!E8=""),"❓ Unknown",IF('Capability Assessment'!E8<='System Inventory'!E8,"✅ Compliant","❌ Non-Compliant"))) | D8: =IF(A8="","",IF(OR('System Inventory'!F8="",'Capability Assessment'!F8=""),"❓ Unknown",IF('Capability Assessment'!F8<='System Inventory'!F8,"✅ Compliant","❌ Non-Compliant"))) | E8: =IF(A8="","",IF(OR(C8="❓ Unknown",D8="❓ Unknown"),"❓ Unknown",IF(AND(C8="✅ Compliant",D8="✅ Compliant"),"✅ Full Compliance",IF(OR(C8="✅ Compliant",D8="✅ Compliant"),"⚠ Partial Compliance","❌ Non-Compliant")))) | F8: =IF(A8="","",IF(AND(B8="Tier 1 - Critical",E8="❌ Non-Compliant"),"[!] Critical",IF(B8="Tier 1 - Critical","[~] High",IF(E8="❌ Non-Compliant","[~] High",IF(E8="⚠ Partial Compliance","[.] Medium","[ ] Low"))))) | G8: =IF(A8="","",IF(C8="❌ Non-Compliant",IF(D8="❌ Non-Compliant","Both RPO & RTO gaps","RPO gap only"),IF(D8="❌ Non-Compliant","RTO gap only",IF(E8="❓ Unknown","Testing required","No gaps")))) | H8: Implement hot standby for faster recovery
A9: ='System Inventory'!A9 | B9: ='System Inventory'!C9 | C9: =IF(A9="","",IF(OR('System Inventory'!E9="",'Capability Assessment'!E9=""),"❓ Unknown",IF('Capability Assessment'!E9<='System Inventory'!E9,"✅ Compliant","❌ Non-Compliant"))) | D9: =IF(A9="","",IF(OR('System Inventory'!F9="",'Capability Assessment'!F9=""),"❓ Unknown",IF('Capability Assessment'!F9<='System Inventory'!F9,"✅ Compliant","❌ Non-Compliant"))) | E9: =IF(A9="","",IF(OR(C9="❓ Unknown",D9="❓ Unknown"),"❓ Unknown",IF(AND(C9="✅ Compliant",D9="✅ Compliant"),"✅ Full Compliance",IF(OR(C9="✅ Compliant",D9="✅ Compliant"),"⚠ Partial Compliance","❌ Non-Compliant")))) | F9: =IF(A9="","",IF(AND(B9="Tier 1 - Critical",E9="❌ Non-Compliant"),"[!] Critical",IF(B9="Tier 1 - Critical","[~] High",IF(E9="❌ Non-Compliant","[~] High",IF(E9="⚠ Partial Compliance","[.] Medium","[ ] Low"))))) | G9: =IF(A9="","",IF(C9="❌ Non-Compliant",IF(D9="❌ Non-Compliant","Both RPO & RTO gaps","RPO gap only"),IF(D9="❌ Non-Compliant","RTO gap only",IF(E9="❓ Unknown","Testing required","No gaps")))) | H9: Acceptable compliance, monitor quarterly
A10: ='System Inventory'!A10 | B10: ='System Inventory'!C10 | C10: =IF(A10="","",IF(OR('System Inventory'!E10="",'Capability Assessment'!E10=""),"❓ Unknown",IF('Capability Assessment'!E10<='System Inventory'!E10,"✅ Compliant","❌ Non-Compliant"))) | D10: =IF(A10="","",IF(OR('System Inventory'!F10="",'Capability Assessment'!F10=""),"❓ Unknown",IF('Capability Assessment'!F10<='System Inventory'!F10,"✅ Compliant","❌ Non-Compliant"))) | E10: =IF(A10="","",IF(OR(C10="❓ Unknown",D10="❓ Unknown"),"❓ Unknown",IF(AND(C10="✅ Compliant",D10="✅ Compliant"),"✅ Full Compliance",IF(OR(C10="✅ Compliant",D10="✅ Compliant"),"⚠ Partial Compliance","❌ Non-Compliant")))) | F10: =IF(A10="","",IF(AND(B10="Tier 1 - Critical",E10="❌ Non-Compliant"),"[!] Critical",IF(B10="Tier 1 - Critical","[~] High",IF(E10="❌ Non-Compliant","[~] High",IF(E10="⚠ Partial Compliance","[.] Medium","[ ] Low"))))) | G10: =IF(A10="","",IF(C10="❌ Non-Compliant",IF(D10="❌ Non-Compliant","Both RPO & RTO gaps","RPO gap only"),IF(D10="❌ Non-Compliant","RTO gap only",IF(E10="❓ Unknown","Testing required","No gaps")))) | H10: Acceptable compliance, monitor quarterly
A11: ='System Inventory'!A11 | B11: ='System Inventory'!C11 | C11: =IF(A11="","",IF(OR('System Inventory'!E11="",'Capability Assessment'!E11=""),"❓ Unknown",IF('Capability Assessment'!E11<='System Inventory'!E11,"✅ Compliant","❌ Non-Compliant"))) | D11: =IF(A11="","",IF(OR('System Inventory'!F11="",'Capability Assessment'!F11=""),"❓ Unknown",IF('Capability Assessment'!F11<='System Inventory'!F11,"✅ Compliant","❌ Non-Compliant"))) | E11: =IF(A11="","",IF(OR(C11="❓ Unknown",D11="❓ Unknown"),"❓ Unknown",IF(AND(C11="✅ Compliant",D11="✅ Compliant"),"✅ Full Compliance",IF(OR(C11="✅ Compliant",D11="✅ Compliant"),"⚠ Partial Compliance","❌ Non-Compliant")))) | F11: =IF(A11="","",IF(AND(B11="Tier 1 - Critical",E11="❌ Non-Compliant"),"[!] Critical",IF(B11="Tier 1 - Critical","[~] High",IF(E11="❌ Non-Compliant","[~] High",IF(E11="⚠ Partial Compliance","[.] Medium","[ ] Low"))))) | G11: =IF(A11="","",IF(C11="❌ Non-Compliant",IF(D11="❌ Non-Compliant","Both RPO & RTO gaps","RPO gap only"),IF(D11="❌ Non-Compliant","RTO gap only",IF(E11="❓ Unknown","Testing required","No gaps")))) | H11: Acceptable for Tier 3, no action required
A12: ='System Inventory'!A12 | B12: ='System Inventory'!C12 | C12: =IF(A12="","",IF(OR('System Inventory'!E12="",'Capability Assessment'!E12=""),"❓ Unknown",IF('Capability Assessment'!E12<='System Inventory'!E12,"✅ Compliant","❌ Non-Compliant"))) | D12: =IF(A12="","",IF(OR('System Inventory'!F12="",'Capability Assessment'!F12=""),"❓ Unknown",IF('Capability Assessment'!F12<='System Inventory'!F12,"✅ Compliant","❌ Non-Compliant"))) | E12: =IF(A12="","",IF(OR(C12="❓ Unknown",D12="❓ Unknown"),"❓ Unknown",IF(AND(C12="✅ Compliant",D12="✅ Compliant"),"✅ Full Compliance",IF(OR(C12="✅ Compliant",D12="✅ Compliant"),"⚠ Partial Compliance","❌ Non-Compliant")))) | F12: =IF(A12="","",IF(AND(B12="Tier 1 - Critical",E12="❌ Non-Compliant"),"[!] Critical",IF(B12="Tier 1 - Critical","[~] High",IF(E12="❌ Non-Compliant","[~] High",IF(E12="⚠ Partial Compliance","[.] Medium","[ ] Low"))))) | G12: =IF(A12="","",IF(C12="❌ Non-Compliant",IF(D12="❌ Non-Compliant","Both RPO & RTO gaps","RPO gap only"),IF(D12="❌ Non-Compliant","RTO gap only",IF(E12="❓ Unknown","Testing required","No gaps")))) | H12: Acceptable for Tier 3, no action required
A13: ='System Inventory'!A13 | B13: ='System Inventory'!C13 | C13: =IF(A13="","",IF(OR('System Inventory'!E13="",'Capability Assessment'!E13=""),"❓ Unknown",IF('Capability Assessment'!E13<='System Inventory'!E13,"✅ Compliant","❌ Non-Compliant"))) | D13: =IF(A13="","",IF(OR('System Inventory'!F13="",'Capability Assessment'!F13=""),"❓ Unknown",IF('Capability Assessment'!F13<='System Inventory'!F13,"✅ Compliant","❌ Non-Compliant"))) | E13: =IF(A13="","",IF(OR(C13="❓ Unknown",D13="❓ Unknown"),"❓ Unknown",IF(AND(C13="✅ Compliant",D13="✅ Compliant"),"✅ Full Compliance",IF(OR(C13="✅ Compliant",D13="✅ Compliant"),"⚠ Partial Compliance","❌ Non-Compliant")))) | F13: =IF(A13="","",IF(AND(B13="Tier 1 - Critical",E13="❌ Non-Compliant"),"[!] Critical",IF(B13="Tier 1 - Critical","[~] High",IF(E13="❌ Non-Compliant","[~] High",IF(E13="⚠ Partial Compliance","[.] Medium","[ ] Low"))))) | G13: =IF(A13="","",IF(C13="❌ Non-Compliant",IF(D13="❌ Non-Compliant","Both RPO & RTO gaps","RPO gap only"),IF(D13="❌ Non-Compliant","RTO gap only",IF(E13="❓ Unknown","Testing required","No gaps")))) | H13: Acceptable for Tier 4, no action required
A14: ='System Inventory'!A14 | B14: ='System Inventory'!C14 | C14: =IF(A14="","",IF(OR('System Inventory'!E14="",'Capability Assessment'!E14=""),"❓ Unknown",IF('Capability Assessment'!E14<='System Inventory'!E14,"✅ Compliant","❌ Non-Compliant"))) | D14: =IF(A14="","",IF(OR('System Inventory'!F14="",'Capability Assessment'!F14=""),"❓ Unknown",IF('Capability Assessment'!F14<='System Inventory'!F14,"✅ Compliant","❌ Non-Compliant"))) | E14: =IF(A14="","",IF(OR(C14="❓ Unknown",D14="❓ Unknown"),"❓ Unknown",IF(AND(C14="✅ Compliant",D14="✅ Compliant"),"✅ Full Compliance",IF(OR(C14="✅ Compliant",D14="✅ Compliant"),"⚠ Partial Compliance","❌ Non-Compliant")))) | F14: =IF(A14="","",IF(AND(B14="Tier 1 - Critical",E14="❌ Non-Compliant"),"[!] Critical",IF(B14="Tier 1 - Critical","[~] High",IF(E14="❌ Non-Compliant","[~] High",IF(E14="⚠ Partial Compliance","[.] Medium","[ ] Low"))))) | G14: =IF(A14="","",IF(C14="❌ Non-Compliant",IF(D14="❌ Non-Compliant","Both RPO & RTO gaps","RPO gap only"),IF(D14="❌ Non-Compliant","RTO gap only",IF(E14="❓ Unknown","Testing required","No gaps")))) | H14: Acceptable for Tier 4, no action required
A15: ='System Inventory'!A15 | B15: ='System Inventory'!C15 | C15: =IF(A15="","",IF(OR('System Inventory'!E15="",'Capability Assessment'!E15=""),"❓ Unknown",IF('Capability Assessment'!E15<='System Inventory'!E15,"✅ Compliant","❌ Non-Compliant"))) | D15: =IF(A15="","",IF(OR('System Inventory'!F15="",'Capability Assessment'!F15=""),"❓ Unknown",IF('Capability Assessment'!F15<='System Inventory'!F15,"✅ Compliant","❌ Non-Compliant"))) | E15: =IF(A15="","",IF(OR(C15="❓ Unknown",D15="❓ Unknown"),"❓ Unknown",IF(AND(C15="✅ Compliant",D15="✅ Compliant"),"✅ Full Compliance",IF(OR(C15="✅ Compliant",D15="✅ Compliant"),"⚠ Partial Compliance","❌ Non-Compliant")))) | F15: =IF(A15="","",IF(AND(B15="Tier 1 - Critical",E15="❌ Non-Compliant"),"[!] Critical",IF(B15="Tier 1 - Critical","[~] High",IF(E15="❌ Non-Compliant","[~] High",IF(E15="⚠ Partial Compliance","[.] Medium","[ ] Low"))))) | G15: =IF(A15="","",IF(C15="❌ Non-Compliant",IF(D15="❌ Non-Compliant","Both RPO & RTO gaps","RPO gap only"),IF(D15="❌ Non-Compliant","RTO gap only",IF(E15="❓ Unknown","Testing required","No gaps")))) | H15: Sample — enter next remediation action here
A16: ='System Inventory'!A16 | B16: ='System Inventory'!C16 | C16: =IF(A16="","",IF(OR('System Inventory'!E16="",'Capability Assessment'!E16=""),"❓ Unknown",IF('Capability Assessment'!E16<='System Inventory'!E16,"✅ Compliant","❌ Non-Compliant"))) | D16: =IF(A16="","",IF(OR('System Inventory'!F16="",'Capability Assessment'!F16=""),"❓ Unknown",IF('Capability Assessment'!F16<='System Inventory'!F16,"✅ Compliant","❌ Non-Compliant"))) | E16: =IF(A16="","",IF(OR(C16="❓ Unknown",D16="❓ Unknown"),"❓ Unknown",IF(AND(C16="✅ Compliant",D16="✅ Compliant"),"✅ Full Compliance",IF(OR(C16="✅ Compliant",D16="✅ Compliant"),"⚠ Partial Compliance","❌ Non-Compliant")))) | F16: =IF(A16="","",IF(AND(B16="Tier 1 - Critical",E16="❌ Non-Compliant"),"[!] Critical",IF(B16="Tier 1 - Critical","[~] High",IF(E16="❌ Non-Compliant","[~] High",IF(E16="⚠ Partial Compliance","[.] Medium","[ ] Low"))))) | G16: =IF(A16="","",IF(C16="❌ Non-Compliant",IF(D16="❌ Non-Compliant","Both RPO & RTO gaps","RPO gap only"),IF(D16="❌ Non-Compliant","RTO gap only",IF(E16="❓ Unknown","Testing required","No gaps"))))
A17: ='System Inventory'!A17 | B17: ='System Inventory'!C17 | C17: =IF(A17="","",IF(OR('System Inventory'!E17="",'Capability Assessment'!E17=""),"❓ Unknown",IF('Capability Assessment'!E17<='System Inventory'!E17,"✅ Compliant","❌ Non-Compliant"))) | D17: =IF(A17="","",IF(OR('System Inventory'!F17="",'Capability Assessment'!F17=""),"❓ Unknown",IF('Capability Assessment'!F17<='System Inventory'!F17,"✅ Compliant","❌ Non-Compliant"))) | E17: =IF(A17="","",IF(OR(C17="❓ Unknown",D17="❓ Unknown"),"❓ Unknown",IF(AND(C17="✅ Compliant",D17="✅ Compliant"),"✅ Full Compliance",IF(OR(C17="✅ Compliant",D17="✅ Compliant"),"⚠ Partial Compliance","❌ Non-Compliant")))) | F17: =IF(A17="","",IF(AND(B17="Tier 1 - Critical",E17="❌ Non-Compliant"),"[!] Critical",IF(B17="Tier 1 - Critical","[~] High",IF(E17="❌ Non-Compliant","[~] High",IF(E17="⚠ Partial Compliance","[.] Medium","[ ] Low"))))) | G17: =IF(A17="","",IF(C17="❌ Non-Compliant",IF(D17="❌ Non-Compliant","Both RPO & RTO gaps","RPO gap only"),IF(D17="❌ Non-Compliant","RTO gap only",IF(E17="❓ Unknown","Testing required","No gaps"))))
A18: ='System Inventory'!A18 | B18: ='System Inventory'!C18 | C18: =IF(A18="","",IF(OR('System Inventory'!E18="",'Capability Assessment'!E18=""),"❓ Unknown",IF('Capability Assessment'!E18<='System Inventory'!E18,"✅ Compliant","❌ Non-Compliant"))) | D18: =IF(A18="","",IF(OR('System Inventory'!F18="",'Capability Assessment'!F18=""),"❓ Unknown",IF('Capability Assessment'!F18<='System Inventory'!F18,"✅ Compliant","❌ Non-Compliant"))) | E18: =IF(A18="","",IF(OR(C18="❓ Unknown",D18="❓ Unknown"),"❓ Unknown",IF(AND(C18="✅ Compliant",D18="✅ Compliant"),"✅ Full Compliance",IF(OR(C18="✅ Compliant",D18="✅ Compliant"),"⚠ Partial Compliance","❌ Non-Compliant")))) | F18: =IF(A18="","",IF(AND(B18="Tier 1 - Critical",E18="❌ Non-Compliant"),"[!] Critical",IF(B18="Tier 1 - Critical","[~] High",IF(E18="❌ Non-Compliant","[~] High",IF(E18="⚠ Partial Compliance","[.] Medium","[ ] Low"))))) | G18: =IF(A18="","",IF(C18="❌ Non-Compliant",IF(D18="❌ Non-Compliant","Both RPO & RTO gaps","RPO gap only"),IF(D18="❌ Non-Compliant","RTO gap only",IF(E18="❓ Unknown","Testing required","No gaps"))))
A19: ='System Inventory'!A19 | B19: ='System Inventory'!C19 | C19: =IF(A19="","",IF(OR('System Inventory'!E19="",'Capability Assessment'!E19=""),"❓ Unknown",IF('Capability Assessment'!E19<='System Inventory'!E19,"✅ Compliant","❌ Non-Compliant"))) | D19: =IF(A19="","",IF(OR('System Inventory'!F19="",'Capability Assessment'!F19=""),"❓ Unknown",IF('Capability Assessment'!F19<='System Inventory'!F19,"✅ Compliant","❌ Non-Compliant"))) | E19: =IF(A19="","",IF(OR(C19="❓ Unknown",D19="❓ Unknown"),"❓ Unknown",IF(AND(C19="✅ Compliant",D19="✅ Compliant"),"✅ Full Compliance",IF(OR(C19="✅ Compliant",D19="✅ Compliant"),"⚠ Partial Compliance","❌ Non-Compliant")))) | F19: =IF(A19="","",IF(AND(B19="Tier 1 - Critical",E19="❌ Non-Compliant"),"[!] Critical",IF(B19="Tier 1 - Critical","[~] High",IF(E19="❌ Non-Compliant","[~] High",IF(E19="⚠ Partial Compliance","[.] Medium","[ ] Low"))))) | G19: =IF(A19="","",IF(C19="❌ Non-Compliant",IF(D19="❌ Non-Compliant","Both RPO & RTO gaps","RPO gap only"),IF(D19="❌ Non-Compliant","RTO gap only",IF(E19="❓ Unknown","Testing required","No gaps"))))
A20: ='System Inventory'!A20 | B20: ='System Inventory'!C20 | C20: =IF(A20="","",IF(OR('System Inventory'!E20="",'Capability Assessment'!E20=""),"❓ Unknown",IF('Capability Assessment'!E20<='System Inventory'!E20,"✅ Compliant","❌ Non-Compliant"))) | D20: =IF(A20="","",IF(OR('System Inventory'!F20="",'Capability Assessment'!F20=""),"❓ Unknown",IF('Capability Assessment'!F20<='System Inventory'!F20,"✅ Compliant","❌ Non-Compliant"))) | E20: =IF(A20="","",IF(OR(C20="❓ Unknown",D20="❓ Unknown"),"❓ Unknown",IF(AND(C20="✅ Compliant",D20="✅ Compliant"),"✅ Full Compliance",IF(OR(C20="✅ Compliant",D20="✅ Compliant"),"⚠ Partial Compliance","❌ Non-Compliant")))) | F20: =IF(A20="","",IF(AND(B20="Tier 1 - Critical",E20="❌ Non-Compliant"),"[!] Critical",IF(B20="Tier 1 - Critical","[~] High",IF(E20="❌ Non-Compliant","[~] High",IF(E20="⚠ Partial Compliance","[.] Medium","[ ] Low"))))) | G20: =IF(A20="","",IF(C20="❌ Non-Compliant",IF(D20="❌ Non-Compliant","Both RPO & RTO gaps","RPO gap only"),IF(D20="❌ Non-Compliant","RTO gap only",IF(E20="❓ Unknown","Testing required","No gaps"))))
A21: ='System Inventory'!A21 | B21: ='System Inventory'!C21 | C21: =IF(A21="","",IF(OR('System Inventory'!E21="",'Capability Assessment'!E21=""),"❓ Unknown",IF('Capability Assessment'!E21<='System Inventory'!E21,"✅ Compliant","❌ Non-Compliant"))) | D21: =IF(A21="","",IF(OR('System Inventory'!F21="",'Capability Assessment'!F21=""),"❓ Unknown",IF('Capability Assessment'!F21<='System Inventory'!F21,"✅ Compliant","❌ Non-Compliant"))) | E21: =IF(A21="","",IF(OR(C21="❓ Unknown",D21="❓ Unknown"),"❓ Unknown",IF(AND(C21="✅ Compliant",D21="✅ Compliant"),"✅ Full Compliance",IF(OR(C21="✅ Compliant",D21="✅ Compliant"),"⚠ Partial Compliance","❌ Non-Compliant")))) | F21: =IF(A21="","",IF(AND(B21="Tier 1 - Critical",E21="❌ Non-Compliant"),"[!] Critical",IF(B21="Tier 1 - Critical","[~] High",IF(E21="❌ Non-Compliant","[~] High",IF(E21="⚠ Partial Compliance","[.] Medium","[ ] Low"))))) | G21: =IF(A21="","",IF(C21="❌ Non-Compliant",IF(D21="❌ Non-Compliant","Both RPO & RTO gaps","RPO gap only"),IF(D21="❌ Non-Compliant","RTO gap only",IF(E21="❓ Unknown","Testing required","No gaps"))))
A22: ='System Inventory'!A22 | B22: ='System Inventory'!C22 | C22: =IF(A22="","",IF(OR('System Inventory'!E22="",'Capability Assessment'!E22=""),"❓ Unknown",IF('Capability Assessment'!E22<='System Inventory'!E22,"✅ Compliant","❌ Non-Compliant"))) | D22: =IF(A22="","",IF(OR('System Inventory'!F22="",'Capability Assessment'!F22=""),"❓ Unknown",IF('Capability Assessment'!F22<='System Inventory'!F22,"✅ Compliant","❌ Non-Compliant"))) | E22: =IF(A22="","",IF(OR(C22="❓ Unknown",D22="❓ Unknown"),"❓ Unknown",IF(AND(C22="✅ Compliant",D22="✅ Compliant"),"✅ Full Compliance",IF(OR(C22="✅ Compliant",D22="✅ Compliant"),"⚠ Partial Compliance","❌ Non-Compliant")))) | F22: =IF(A22="","",IF(AND(B22="Tier 1 - Critical",E22="❌ Non-Compliant"),"[!] Critical",IF(B22="Tier 1 - Critical","[~] High",IF(E22="❌ Non-Compliant","[~] High",IF(E22="⚠ Partial Compliance","[.] Medium","[ ] Low"))))) | G22: =IF(A22="","",IF(C22="❌ Non-Compliant",IF(D22="❌ Non-Compliant","Both RPO & RTO gaps","RPO gap only"),IF(D22="❌ Non-Compliant","RTO gap only",IF(E22="❓ Unknown","Testing required","No gaps"))))
A23: ='System Inventory'!A23 | B23: ='System Inventory'!C23 | C23: =IF(A23="","",IF(OR('System Inventory'!E23="",'Capability Assessment'!E23=""),"❓ Unknown",IF('Capability Assessment'!E23<='System Inventory'!E23,"✅ Compliant","❌ Non-Compliant"))) | D23: =IF(A23="","",IF(OR('System Inventory'!F23="",'Capability Assessment'!F23=""),"❓ Unknown",IF('Capability Assessment'!F23<='System Inventory'!F23,"✅ Compliant","❌ Non-Compliant"))) | E23: =IF(A23="","",IF(OR(C23="❓ Unknown",D23="❓ Unknown"),"❓ Unknown",IF(AND(C23="✅ Compliant",D23="✅ Compliant"),"✅ Full Compliance",IF(OR(C23="✅ Compliant",D23="✅ Compliant"),"⚠ Partial Compliance","❌ Non-Compliant")))) | F23: =IF(A23="","",IF(AND(B23="Tier 1 - Critical",E23="❌ Non-Compliant"),"[!] Critical",IF(B23="Tier 1 - Critical","[~] High",IF(E23="❌ Non-Compliant","[~] High",IF(E23="⚠ Partial Compliance","[.] Medium","[ ] Low"))))) | G23: =IF(A23="","",IF(C23="❌ Non-Compliant",IF(D23="❌ Non-Compliant","Both RPO & RTO gaps","RPO gap only"),IF(D23="❌ Non-Compliant","RTO gap only",IF(E23="❓ Unknown","Testing required","No gaps"))))
A24: ='System Inventory'!A24 | B24: ='System Inventory'!C24 | C24: =IF(A24="","",IF(OR('System Inventory'!E24="",'Capability Assessment'!E24=""),"❓ Unknown",IF('Capability Assessment'!E24<='System Inventory'!E24,"✅ Compliant","❌ Non-Compliant"))) | D24: =IF(A24="","",IF(OR('System Inventory'!F24="",'Capability Assessment'!F24=""),"❓ Unknown",IF('Capability Assessment'!F24<='System Inventory'!F24,"✅ Compliant","❌ Non-Compliant"))) | E24: =IF(A24="","",IF(OR(C24="❓ Unknown",D24="❓ Unknown"),"❓ Unknown",IF(AND(C24="✅ Compliant",D24="✅ Compliant"),"✅ Full Compliance",IF(OR(C24="✅ Compliant",D24="✅ Compliant"),"⚠ Partial Compliance","❌ Non-Compliant")))) | F24: =IF(A24="","",IF(AND(B24="Tier 1 - Critical",E24="❌ Non-Compliant"),"[!] Critical",IF(B24="Tier 1 - Critical","[~] High",IF(E24="❌ Non-Compliant","[~] High",IF(E24="⚠ Partial Compliance","[.] Medium","[ ] Low"))))) | G24: =IF(A24="","",IF(C24="❌ Non-Compliant",IF(D24="❌ Non-Compliant","Both RPO & RTO gaps","RPO gap only"),IF(D24="❌ Non-Compliant","RTO gap only",IF(E24="❓ Unknown","Testing required","No gaps"))))
A25: ='System Inventory'!A25 | B25: ='System Inventory'!C25 | C25: =IF(A25="","",IF(OR('System Inventory'!E25="",'Capability Assessment'!E25=""),"❓ Unknown",IF('Capability Assessment'!E25<='System Inventory'!E25,"✅ Compliant","❌ Non-Compliant"))) | D25: =IF(A25="","",IF(OR('System Inventory'!F25="",'Capability Assessment'!F25=""),"❓ Unknown",IF('Capability Assessment'!F25<='System Inventory'!F25,"✅ Compliant","❌ Non-Compliant"))) | E25: =IF(A25="","",IF(OR(C25="❓ Unknown",D25="❓ Unknown"),"❓ Unknown",IF(AND(C25="✅ Compliant",D25="✅ Compliant"),"✅ Full Compliance",IF(OR(C25="✅ Compliant",D25="✅ Compliant"),"⚠ Partial Compliance","❌ Non-Compliant")))) | F25: =IF(A25="","",IF(AND(B25="Tier 1 - Critical",E25="❌ Non-Compliant"),"[!] Critical",IF(B25="Tier 1 - Critical","[~] High",IF(E25="❌ Non-Compliant","[~] High",IF(E25="⚠ Partial Compliance","[.] Medium","[ ] Low"))))) | G25: =IF(A25="","",IF(C25="❌ Non-Compliant",IF(D25="❌ Non-Compliant","Both RPO & RTO gaps","RPO gap only"),IF(D25="❌ Non-Compliant","RTO gap only",IF(E25="❓ Unknown","Testing required","No gaps"))))
A26: ='System Inventory'!A26 | B26: ='System Inventory'!C26 | C26: =IF(A26="","",IF(OR('System Inventory'!E26="",'Capability Assessment'!E26=""),"❓ Unknown",IF('Capability Assessment'!E26<='System Inventory'!E26,"✅ Compliant","❌ Non-Compliant"))) | D26: =IF(A26="","",IF(OR('System Inventory'!F26="",'Capability Assessment'!F26=""),"❓ Unknown",IF('Capability Assessment'!F26<='System Inventory'!F26,"✅ Compliant","❌ Non-Compliant"))) | E26: =IF(A26="","",IF(OR(C26="❓ Unknown",D26="❓ Unknown"),"❓ Unknown",IF(AND(C26="✅ Compliant",D26="✅ Compliant"),"✅ Full Compliance",IF(OR(C26="✅ Compliant",D26="✅ Compliant"),"⚠ Partial Compliance","❌ Non-Compliant")))) | F26: =IF(A26="","",IF(AND(B26="Tier 1 - Critical",E26="❌ Non-Compliant"),"[!] Critical",IF(B26="Tier 1 - Critical","[~] High",IF(E26="❌ Non-Compliant","[~] High",IF(E26="⚠ Partial Compliance","[.] Medium","[ ] Low"))))) | G26: =IF(A26="","",IF(C26="❌ Non-Compliant",IF(D26="❌ Non-Compliant","Both RPO & RTO gaps","RPO gap only"),IF(D26="❌ Non-Compliant","RTO gap only",IF(E26="❓ Unknown","Testing required","No gaps"))))
A27: ='System Inventory'!A27 | B27: ='System Inventory'!C27 | C27: =IF(A27="","",IF(OR('System Inventory'!E27="",'Capability Assessment'!E27=""),"❓ Unknown",IF('Capability Assessment'!E27<='System Inventory'!E27,"✅ Compliant","❌ Non-Compliant"))) | D27: =IF(A27="","",IF(OR('System Inventory'!F27="",'Capability Assessment'!F27=""),"❓ Unknown",IF('Capability Assessment'!F27<='System Inventory'!F27,"✅ Compliant","❌ Non-Compliant"))) | E27: =IF(A27="","",IF(OR(C27="❓ Unknown",D27="❓ Unknown"),"❓ Unknown",IF(AND(C27="✅ Compliant",D27="✅ Compliant"),"✅ Full Compliance",IF(OR(C27="✅ Compliant",D27="✅ Compliant"),"⚠ Partial Compliance","❌ Non-Compliant")))) | F27: =IF(A27="","",IF(AND(B27="Tier 1 - Critical",E27="❌ Non-Compliant"),"[!] Critical",IF(B27="Tier 1 - Critical","[~] High",IF(E27="❌ Non-Compliant","[~] High",IF(E27="⚠ Partial Compliance","[.] Medium","[ ] Low"))))) | G27: =IF(A27="","",IF(C27="❌ Non-Compliant",IF(D27="❌ Non-Compliant","Both RPO & RTO gaps","RPO gap only"),IF(D27="❌ Non-Compliant","RTO gap only",IF(E27="❓ Unknown","Testing required","No gaps"))))
... A65: ='System Inventory'!A65 | B65: ='System Inventory'!C65 | C65: =IF(A65="","",IF(OR('System Inventory'!E65="",'Capability Assessment'!E65=""),"❓ Unknown",IF('Capability Assessment'!E65<='System Inventory'!E65,"✅ Compliant","❌ Non-Compliant"))) | D65: =IF(A65="","",IF(OR('System Inventory'!F65="",'Capability Assessment'!F65=""),"❓ Unknown",IF('Capability Assessment'!F65<='System Inventory'!F65,"✅ Compliant","❌ Non-Compliant"))) | E65: =IF(A65="","",IF(OR(C65="❓ Unknown",D65="❓ Unknown"),"❓ Unknown",IF(AND(C65="✅ Compliant",D65="✅ Compliant"),"✅ Full Compliance",IF(OR(C65="✅ Compliant",D65="✅ Compliant"),"⚠ Partial Compliance","❌ Non-Compliant")))) | F65: =IF(A65="","",IF(AND(B65="Tier 1 - Critical",E65="❌ Non-Compliant"),"[!] Critical",IF(B65="Tier 1 - Critical","[~] High",IF(E65="❌ Non-Compliant","[~] High",IF(E65="⚠ Partial Compliance","[.] Medium","[ ] Low"))))) | G65: =IF(A65="","",IF(C65="❌ Non-Compliant",IF(D65="❌ Non-Compliant","Both RPO & RTO gaps","RPO gap only"),IF(D65="❌ Non-Compliant","RTO gap only",IF(E65="❓ Unknown","Testing required","No gaps"))))
A68: COMPLIANCE SUMMARY METRICS
A69: Total Systems: | B69: =COUNTA(A6:A65)
A70: Full Compliance (✅): | B70: =COUNTIF(E6:E65,"✅*")
A71: Partial Compliance (⚠️): | B71: =COUNTIF(E6:E65,"⚠*")
A72: Non-Compliant (❌): | B72: =COUNTIF(E6:E65,"❌*")
A73: Unknown (❓): | B73: =COUNTIF(E6:E65,"❓*")
A74: Overall Compliance Rate: | B74: =IF(B69>0,B70/B69,0)

Sheet Gap Analysis
A1: GAP ANALYSIS & REMEDIATION TRACKING
A2: Document identified gaps with risk scoring and remediation plans
A4: Gap ID | B4: System | C4: Gap Type | D4: Gap Description | E4: Risk Score (1-10) | F4: Priority | G4: Remediation Plan | H4: Status
A15: GAP-NNN | B15: System Name | C15: RTO Gap | D15: Gap description — actual vs required RPO/RTO | E15: 7 | F15: [~] High | G15: Remediation plan and target timeline | H15: In Progress
A67: GAP SUMMARY METRICS
A68: Total Gaps Identified: | B68: =COUNTA(B5:B65)
A69: [!] Critical Priority: | B69: =COUNTIF(F5:F65,"[!]*")
A70: [~] High Priority: | B70: =COUNTIF(F5:F65,"[~]*")
A71: [.] Medium Priority: | B71: =COUNTIF(F5:F65,"[.]*")
A72: [ ] Low Priority: | B72: =COUNTIF(F5:F65,"[ ]*")
A74: Open Gaps: | B74: =COUNTIF(H5:H65,"Open*")
A75: In Progress: | B75: =COUNTIF(H5:H65,"In Progress*")
A76: ✅ Closed Gaps: | B76: =COUNTIF(H5:H65,"✅*")
A77: Risk Accepted: | B77: =COUNTIF(H5:H65,"Risk Accepted*")
A79: Average Risk Score: | B79: =IFERROR(AVERAGE(E5:E114),0)
A80: Max Risk Score: | B80: =IFERROR(MAX(E5:E114),0)

Sheet Evidence Register
A1: EVIDENCE REGISTER
A2: Document all evidence collected during this assessment (minimum 5 items required for audit compliance)
A4: Evidence ID | B4: Assessment Area | C4: Evidence Type | D4: Description | E4: Location / Path | F4: Date Collected | G4: Collected By | H4: Verification Status
A5: EV-001 | B5: Compliance Matrix | C5: BIA Report | D5: Business Impact Analysis report with RPO/RTO requirements for all systems | E5: /evidence/bia/BIA_Report_Q1_2024.pdf | F5: 10.03.2026 | G5: BC/DR Coordinator | H5: ✅ Verified

Sheet Summary Dashboard
A1: RPO/RTO COMPLIANCE — SUMMARY DASHBOARD
A2: Assessment ID: ISMS-IMP-A.5.30.S3 | Assessment Date: [enter date]
A4: OVERALL RPO/RTO COMPLIANCE
A5: Total Systems Assessed: | B5: =COUNTA('System Inventory'!A16:A65)
A6: Systems with Full Compliance (RPO & RTO): | B6: =COUNTIF('Compliance Matrix'!E16:E65,"✅*")
A7: Systems with Partial Compliance: | B7: =COUNTIF('Compliance Matrix'!E16:E65,"⚠*")
A8: Non-Compliant Systems: | B8: =COUNTIF('Compliance Matrix'!E16:E65,"❌*")
A9: Unknown Status (Not Tested): | B9: =COUNTIF('Compliance Matrix'!E16:E65,"❓*")
A10: Overall Compliance Rate: | B10: =IF(B5>0,B6/B5,0)
A12: COMPLIANCE BY CRITICALITY TIER
A13: Tier 1 - Critical Systems: | B13: =COUNTIF('System Inventory'!C16:C65,"Tier 1*")
A14: Tier 1 - Full Compliance: | B14: =SUMPRODUCT(('System Inventory'!C16:C65="Tier 1 - Critical")*('Compliance Matrix'!E16:E65="✅ Full Compliance"))
A15: Tier 1 - Compliance Rate: | B15: =IF(B13>0,B14/B13,0)
A17: Tier 2 - Important Systems: | B17: =COUNTIF('System Inventory'!C16:C65,"Tier 2*")
A18: Tier 2 - Full Compliance: | B18: =SUMPRODUCT(('System Inventory'!C16:C65="Tier 2 - Important")*('Compliance Matrix'!E16:E65="✅ Full Compliance"))
A19: Tier 2 - Compliance Rate: | B19: =IF(B17>0,B18/B17,0)
A21: GAP ANALYSIS SUMMARY
A22: Total Gaps Identified: | B22: =COUNTA('Gap Analysis'!A16:A65)
A23: [!] Critical Priority Gaps: | B23: =COUNTIF('Gap Analysis'!F16:F65,"[!]*")
A24: [~] High Priority Gaps: | B24: =COUNTIF('Gap Analysis'!F16:F65,"[~]*")
A25: [.] Medium Priority Gaps: | B25: =COUNTIF('Gap Analysis'!F16:F65,"[.]*")
A26: [ ] Low Priority Gaps: | B26: =COUNTIF('Gap Analysis'!F16:F65,"[ ]*")
A28: Open Gaps: | B28: =COUNTIF('Gap Analysis'!H16:H65,"Open*")
A29: In Progress Gaps: | B29: =COUNTIF('Gap Analysis'!H16:H65,"In Progress*")
A30: Closed Gaps: | B30: =COUNTIF('Gap Analysis'!H16:H65,"✅*")
A32: Average Risk Score: | B32: =IFERROR(AVERAGE('Gap Analysis'!E16:E65),0)
A34: EVIDENCE & APPROVAL STATUS
A35: Evidence Items Collected: | B35: =COUNTA('Evidence Register'!A6:A105)
A36: Verified Evidence: | B36: =COUNTIF('Evidence Register'!H6:H105,"✅*")
A37: Minimum Evidence Required: | B37: 5
A38: Evidence Compliance: | B38: =IF(B40>=B42,"✅ Sufficient","❌ Insufficient")
A40: Assessment Status: | B40: ='Approval Sign-Off'!B7
A41: Level 1 - Assessor Completed: | B41: =IF('Approval Sign-Off'!B11<>"","✅ Complete","Pending")
A42: Level 2 - ISO Review: | B42: =IF('Approval Sign-Off'!B18<>"","✅ Complete","Pending")
A43: Level 3 - CISO Approval: | B43: =IF('Approval Sign-Off'!B25<>"","✅ Complete","Pending")
A45: PRIORITY ACTIONS
A46: 1. Address all [!] Critical priority gaps immediately (target: 90 days)
A47: 2. Test all systems marked unknown (capability assessment needed)
A48: 3. Focus on Tier 1 systems first (business-critical)
A49: 4. Close RPO gaps: Increase backup frequency OR implement replication
...

Sheet Approval Sign-Off
A1: ASSESSMENT APPROVAL AND SIGN-OFF
A2: ISMS-IMP-A.5.30.S3 | ISO/IEC 27001:2022 - Control A.5.30 (ICT Readiness for Business Continuity)
A3: ASSESSMENT SUMMARY
A4: Document: | B4: ISMS-IMP-A.5.30.S3 - RPO/RTO Compliance Matrix
A5: Assessment Period:
A6: Overall RPO/RTO Compliance Rate: | B6: ='Summary Dashboard'!B10
A7: Assessment Status:
A8: Assessed By:
A11: COMPLETED BY (ASSESSOR)
A12: Name:
A13: Title:
A14: Date:
A15: Signature:
A16: Comments:
A18: REVIEWED BY (INFORMATION SECURITY OFFICER)
A19: Name:
A20: Title:
A21: Date:
... A38: Special Considerations:
