Workbook

Sheet Instructions & Legend
A1: ISMS-IMP-A.5.30.S4 - Testing Results ISO/IEC 27001:2022 - Control A.5.30: Information Backup
A3: Document Information
A4: Document ID | B4: ISMS-IMP-A.5.30.S4
A5: Workbook Title | B5: Testing Results
A6: Control Reference | B6: ISO/IEC 27001:2022 - Control A.5.30: Information Backup
A7: Version | B7: 1.0
A8: Assessment Date
A9: Completed By
A10: Organisation
A12: Instructions
A13: 1. Plan tests in the Test Schedule worksheet (define annual test plan).
A14: 2. Execute tests according to schedule and document actual execution.
A15: 3. Log results in the Test Results Log worksheet (document every test performed).
A16: 4. Document issues in the Issue Remediation worksheet (problems discovered during testing).
A17: 5. Track remediation of issues to closure.
A18: 6. Review Testing Compliance worksheet (annual compliance assessment).
A19: 7. Collect evidence in the Evidence Register (minimum 5 items required for audit).
A20: 8. Review the Summary Dashboard for overall testing compliance metrics.
... A24: Status Legend
A25: Symbol | B25: Status | C25: Description
A26: ✓ | B26: Compliant / Complete | C26: Requirement fully met
A27: ⚠ | B27: Partial / In Progress | C27: Partially met or in progress
A28: ✗ | B28: Non-Compliant / Not Started | C28: Requirement not met
A29: — | B29: Not Applicable | C29: Not applicable to this assessment
A31: Acceptable Evidence (examples)
A32: ✓ Test reports with date, system name, test type, outcome, and actual duration
A33: ✓ Screenshots of backup restore test completion (data integrity verified)
A34: ✓ Failover test logs showing actual switchover time
A35: ✓ Full DR scenario exercise reports with stakeholder attendance
A36: ✓ Issue tracking records (Jira tickets, remediation plans) from test failures
A37: ✓ Testing schedule demonstrating regular cadence aligned to criticality tiers
A38: ✓ Video recordings or observer notes from tabletop exercises
A39: ✓ Management sign-off on annual testing programme

Sheet Test Schedule
A1: BC/DR TEST SCHEDULE
A2: Define annual test plan - what tests to perform when (schedule all required tests)
A4: Test ID | B4: System Name | C4: Test Type | D4: Criticality | E4: Required Frequency | F4: Scheduled Date | G4: Test Owner | H4: Notes / Prerequisites
A15: TEST-NNN | B15: System Name | C15: Backup Restore | D15: Tier 1 - Critical | E15: Quarterly | F15: DD.MM.YYYY | G15: Owner Name | H15: Prerequisites and notes here
A67: TEST SCHEDULE SUMMARY
A68: Total Tests Scheduled: | B68: =COUNTA(B5:B65)
A69: Backup Restore Tests: | B69: =COUNTIF(C5:C65,"Backup*")
A70: Failover Tests: | B70: =COUNTIF(C5:C65,"Failover*")
A71: Full DR Scenarios: | B71: =COUNTIF(C5:C65,"Full DR*")
A72: Tier 1 System Tests: | B72: =COUNTIF(D5:D65,"Tier 1*")
A73: Quarterly Tests: | B73: =COUNTIF(E5:E65,"Quarterly")

Sheet Test Results Log
A1: BC/DR TEST RESULTS LOG
A2: Document all test executions - actual test results (log every test performed)
A4: Result ID | B4: Test ID (Schedule) | C4: System Name | D4: Test Type | E4: Test Date | F4: Result | G4: Actual Duration (hrs) | H4: Tested By | I4: Issues Found | J4: Detailed Notes
A5: RES-001
A6: RES-002
A7: RES-003
A8: RES-004
A9: RES-005
A10: RES-006
A11: RES-007
A12: RES-008
A13: RES-009
A14: RES-010
A15: RES-EXX | B15: TEST-EX | C15: New System (Example) | D15: Backup Restore | F15: ✅ Success | G15: 2.5 | H15: IT Operations Team | I15: None | J15: Sample — enter actual test outcome and notes here
A67: TEST RESULTS SUMMARY
A68: Total Tests Executed: | B68: =COUNTA(C5:C65)
A69: ✅ Successful Tests: | B69: =COUNTIF(F5:F65,"✅*")
A70: ⚠ Partial Success: | B70: =COUNTIF(F5:F65,"⚠*")
A71: ❌ Failed Tests: | B71: =COUNTIF(F5:F65,"❌*")
A72: Success Rate: | B72: =IF(B68>0,(B69+B70*0.5)/B68,0)
A73: Average Test Duration (hrs): | B73: =IFERROR(AVERAGE(G5:G65),0)

Sheet Issue Remediation
A1: ISSUE REMEDIATION TRACKER
A2: Track issues discovered during testing to closure
A4: Issue ID | B4: Related Test (Result ID) | C4: Issue Description | D4: Root Cause | E4: Severity | F4: Status | G4: Remediation Plan | H4: Target Resolution Date
A5: ISS-001
A6: ISS-002
A7: ISS-003
A8: ISS-004
A9: ISS-005
A10: ISS-006
A11: ISS-007
A12: ISS-008
A13: ISS-009
A14: ISS-010
A15: ISS-EXX | B15: RES-EX | C15: Sample issue description — enter details here | D15: Root cause not yet identified | E15: [.] Medium | F15: Open | G15: Sample — enter remediation plan here
A67: ISSUE REMEDIATION SUMMARY
A68: Total Issues: | B68: =COUNTA(C5:C65)
A69: [!] Critical Issues: | B69: =COUNTIF(E5:E65,"[!]*")
A70: [~] High Severity: | B70: =COUNTIF(E5:E65,"[~]*")
A71: [.] Medium Severity: | B71: =COUNTIF(E5:E65,"[.]*")
A73: Open Issues: | B73: =COUNTIF(F5:F65,"Open*")
A74: In Progress: | B74: =COUNTIF(F5:F65,"In Progress*")
A75: ✅ Closed Issues: | B75: =COUNTIF(F5:F65,"✅*")
A76: Issue Closure Rate: | B76: =IF(B68>0,B75/B68,0)

Sheet Testing Compliance
A1: TESTING COMPLIANCE ASSESSMENT
A2: Annual compliance assessment - are systems being tested according to requirements?
A4: System Name | B4: Test Type | C4: Criticality | D4: Required Frequency | E4: Last Test Date | F4: Days Since Last Test | G4: Compliance Status | H4: Next Test Due
F5: =IF(E5="","",TODAY()-E5) | G5: =IF(A5="","",IF(E5="","❓ Unknown",IF(D5="Quarterly",IF(F5<=90,"✅ Compliant",IF(F5<=105,"⚠ Overdue","❌ Non-Compliant")),IF(D5="Semi-Annual",IF(F5<=180,"✅ Compliant",IF(F5<=200,"⚠ Overdue","❌ Non-Compliant")),IF(D5="Annual",IF(F5<=365,"✅ Compliant",IF(F5<=400,"⚠ Overdue","❌ Non-Compliant")),"✅ Compliant"))))) | H5: =IF(E5="","",IF(D5="Quarterly",E5+90,IF(D5="Semi-Annual",E5+180,IF(D5="Annual",E5+365,E5))))
F6: =IF(E6="","",TODAY()-E6) | G6: =IF(A6="","",IF(E6="","❓ Unknown",IF(D6="Quarterly",IF(F6<=90,"✅ Compliant",IF(F6<=105,"⚠ Overdue","❌ Non-Compliant")),IF(D6="Semi-Annual",IF(F6<=180,"✅ Compliant",IF(F6<=200,"⚠ Overdue","❌ Non-Compliant")),IF(D6="Annual",IF(F6<=365,"✅ Compliant",IF(F6<=400,"⚠ Overdue","❌ Non-Compliant")),"✅ Compliant"))))) | H6: =IF(E6="","",IF(D6="Quarterly",E6+90,IF(D6="Semi-Annual",E6+180,IF(D6="Annual",E6+365,E6))))
F7: =IF(E7="","",TODAY()-E7) | G7: =IF(A7="","",IF(E7="","❓ Unknown",IF(D7="Quarterly",IF(F7<=90,"✅ Compliant",IF(F7<=105,"⚠ Overdue","❌ Non-Compliant")),IF(D7="Semi-Annual",IF(F7<=180,"✅ Compliant",IF(F7<=200,"⚠ Overdue","❌ Non-Compliant")),IF(D7="Annual",IF(F7<=365,"✅ Compliant",IF(F7<=400,"⚠ Overdue","❌ Non-Compliant")),"✅ Compliant"))))) | H7: =IF(E7="","",IF(D7="Quarterly",E7+90,IF(D7="Semi-Annual",E7+180,IF(D7="Annual",E7+365,E7))))
F8: =IF(E8="","",TODAY()-E8) | G8: =IF(A8="","",IF(E8="","❓ Unknown",IF(D8="Quarterly",IF(F8<=90,"✅ Compliant",IF(F8<=105,"⚠ Overdue","❌ Non-Compliant")),IF(D8="Semi-Annual",IF(F8<=180,"✅ Compliant",IF(F8<=200,"⚠ Overdue","❌ Non-Compliant")),IF(D8="Annual",IF(F8<=365,"✅ Compliant",IF(F8<=400,"⚠ Overdue","❌ Non-Compliant")),"✅ Compliant"))))) | H8: =IF(E8="","",IF(D8="Quarterly",E8+90,IF(D8="Semi-Annual",E8+180,IF(D8="Annual",E8+365,E8))))
F9: =IF(E9="","",TODAY()-E9) | G9: =IF(A9="","",IF(E9="","❓ Unknown",IF(D9="Quarterly",IF(F9<=90,"✅ Compliant",IF(F9<=105,"⚠ Overdue","❌ Non-Compliant")),IF(D9="Semi-Annual",IF(F9<=180,"✅ Compliant",IF(F9<=200,"⚠ Overdue","❌ Non-Compliant")),IF(D9="Annual",IF(F9<=365,"✅ Compliant",IF(F9<=400,"⚠ Overdue","❌ Non-Compliant")),"✅ Compliant"))))) | H9: =IF(E9="","",IF(D9="Quarterly",E9+90,IF(D9="Semi-Annual",E9+180,IF(D9="Annual",E9+365,E9))))
F10: =IF(E10="","",TODAY()-E10) | G10: =IF(A10="","",IF(E10="","❓ Unknown",IF(D10="Quarterly",IF(F10<=90,"✅ Compliant",IF(F10<=105,"⚠ Overdue","❌ Non-Compliant")),IF(D10="Semi-Annual",IF(F10<=180,"✅ Compliant",IF(F10<=200,"⚠ Overdue","❌ Non-Compliant")),IF(D10="Annual",IF(F10<=365,"✅ Compliant",IF(F10<=400,"⚠ Overdue","❌ Non-Compliant")),"✅ Compliant"))))) | H10: =IF(E10="","",IF(D10="Quarterly",E10+90,IF(D10="Semi-Annual",E10+180,IF(D10="Annual",E10+365,E10))))
F11: =IF(E11="","",TODAY()-E11) | G11: =IF(A11="","",IF(E11="","❓ Unknown",IF(D11="Quarterly",IF(F11<=90,"✅ Compliant",IF(F11<=105,"⚠ Overdue","❌ Non-Compliant")),IF(D11="Semi-Annual",IF(F11<=180,"✅ Compliant",IF(F11<=200,"⚠ Overdue","❌ Non-Compliant")),IF(D11="Annual",IF(F11<=365,"✅ Compliant",IF(F11<=400,"⚠ Overdue","❌ Non-Compliant")),"✅ Compliant"))))) | H11: =IF(E11="","",IF(D11="Quarterly",E11+90,IF(D11="Semi-Annual",E11+180,IF(D11="Annual",E11+365,E11))))
F12: =IF(E12="","",TODAY()-E12) | G12: =IF(A12="","",IF(E12="","❓ Unknown",IF(D12="Quarterly",IF(F12<=90,"✅ Compliant",IF(F12<=105,"⚠ Overdue","❌ Non-Compliant")),IF(D12="Semi-Annual",IF(F12<=180,"✅ Compliant",IF(F12<=200,"⚠ Overdue","❌ Non-Compliant")),IF(D12="Annual",IF(F12<=365,"✅ Compliant",IF(F12<=400,"⚠ Overdue","❌ Non-Compliant")),"✅ Compliant"))))) | H12: =IF(E12="","",IF(D12="Quarterly",E12+90,IF(D12="Semi-Annual",E12+180,IF(D12="Annual",E12+365,E12))))
F13: =IF(E13="","",TODAY()-E13) | G13: =IF(A13="","",IF(E13="","❓ Unknown",IF(D13="Quarterly",IF(F13<=90,"✅ Compliant",IF(F13<=105,"⚠ Overdue","❌ Non-Compliant")),IF(D13="Semi-Annual",IF(F13<=180,"✅ Compliant",IF(F13<=200,"⚠ Overdue","❌ Non-Compliant")),IF(D13="Annual",IF(F13<=365,"✅ Compliant",IF(F13<=400,"⚠ Overdue","❌ Non-Compliant")),"✅ Compliant"))))) | H13: =IF(E13="","",IF(D13="Quarterly",E13+90,IF(D13="Semi-Annual",E13+180,IF(D13="Annual",E13+365,E13))))
F14: =IF(E14="","",TODAY()-E14) | G14: =IF(A14="","",IF(E14="","❓ Unknown",IF(D14="Quarterly",IF(F14<=90,"✅ Compliant",IF(F14<=105,"⚠ Overdue","❌ Non-Compliant")),IF(D14="Semi-Annual",IF(F14<=180,"✅ Compliant",IF(F14<=200,"⚠ Overdue","❌ Non-Compliant")),IF(D14="Annual",IF(F14<=365,"✅ Compliant",IF(F14<=400,"⚠ Overdue","❌ Non-Compliant")),"✅ Compliant"))))) | H14: =IF(E14="","",IF(D14="Quarterly",E14+90,IF(D14="Semi-Annual",E14+180,IF(D14="Annual",E14+365,E14))))
A15: Example: Application Server | B15: Failover Test | C15: Tier 1 - Critical | D15: Annual | F15: =IF(E15="","",TODAY()-E15) | G15: =IF(A15="","",IF(E15="","❓ Unknown",IF(D15="Quarterly",IF(F15<=90,"✅ Compliant",IF(F15<=105,"⚠ Overdue","❌ Non-Compliant")),IF(D15="Semi-Annual",IF(F15<=180,"✅ Compliant",IF(F15<=200,"⚠ Overdue","❌ Non-Compliant")),IF(D15="Annual",IF(F15<=365,"✅ Compliant",IF(F15<=400,"⚠ Overdue","❌ Non-Compliant")),"✅ Compliant"))))) | H15: =IF(E15="","",IF(D15="Quarterly",E15+90,IF(D15="Semi-Annual",E15+180,IF(D15="Annual",E15+365,E15))))
F16: =IF(E16="","",TODAY()-E16) | G16: =IF(A16="","",IF(E16="","❓ Unknown",IF(D16="Quarterly",IF(F16<=90,"✅ Compliant",IF(F16<=105,"⚠ Overdue","❌ Non-Compliant")),IF(D16="Semi-Annual",IF(F16<=180,"✅ Compliant",IF(F16<=200,"⚠ Overdue","❌ Non-Compliant")),IF(D16="Annual",IF(F16<=365,"✅ Compliant",IF(F16<=400,"⚠ Overdue","❌ Non-Compliant")),"✅ Compliant"))))) | H16: =IF(E16="","",IF(D16="Quarterly",E16+90,IF(D16="Semi-Annual",E16+180,IF(D16="Annual",E16+365,E16))))
F17: =IF(E17="","",TODAY()-E17) | G17: =IF(A17="","",IF(E17="","❓ Unknown",IF(D17="Quarterly",IF(F17<=90,"✅ Compliant",IF(F17<=105,"⚠ Overdue","❌ Non-Compliant")),IF(D17="Semi-Annual",IF(F17<=180,"✅ Compliant",IF(F17<=200,"⚠ Overdue","❌ Non-Compliant")),IF(D17="Annual",IF(F17<=365,"✅ Compliant",IF(F17<=400,"⚠ Overdue","❌ Non-Compliant")),"✅ Compliant"))))) | H17: =IF(E17="","",IF(D17="Quarterly",E17+90,IF(D17="Semi-Annual",E17+180,IF(D17="Annual",E17+365,E17))))
F18: =IF(E18="","",TODAY()-E18) | G18: =IF(A18="","",IF(E18="","❓ Unknown",IF(D18="Quarterly",IF(F18<=90,"✅ Compliant",IF(F18<=105,"⚠ Overdue","❌ Non-Compliant")),IF(D18="Semi-Annual",IF(F18<=180,"✅ Compliant",IF(F18<=200,"⚠ Overdue","❌ Non-Compliant")),IF(D18="Annual",IF(F18<=365,"✅ Compliant",IF(F18<=400,"⚠ Overdue","❌ Non-Compliant")),"✅ Compliant"))))) | H18: =IF(E18="","",IF(D18="Quarterly",E18+90,IF(D18="Semi-Annual",E18+180,IF(D18="Annual",E18+365,E18))))
F19: =IF(E19="","",TODAY()-E19) | G19: =IF(A19="","",IF(E19="","❓ Unknown",IF(D19="Quarterly",IF(F19<=90,"✅ Compliant",IF(F19<=105,"⚠ Overdue","❌ Non-Compliant")),IF(D19="Semi-Annual",IF(F19<=180,"✅ Compliant",IF(F19<=200,"⚠ Overdue","❌ Non-Compliant")),IF(D19="Annual",IF(F19<=365,"✅ Compliant",IF(F19<=400,"⚠ Overdue","❌ Non-Compliant")),"✅ Compliant"))))) | H19: =IF(E19="","",IF(D19="Quarterly",E19+90,IF(D19="Semi-Annual",E19+180,IF(D19="Annual",E19+365,E19))))
F20: =IF(E20="","",TODAY()-E20) | G20: =IF(A20="","",IF(E20="","❓ Unknown",IF(D20="Quarterly",IF(F20<=90,"✅ Compliant",IF(F20<=105,"⚠ Overdue","❌ Non-Compliant")),IF(D20="Semi-Annual",IF(F20<=180,"✅ Compliant",IF(F20<=200,"⚠ Overdue","❌ Non-Compliant")),IF(D20="Annual",IF(F20<=365,"✅ Compliant",IF(F20<=400,"⚠ Overdue","❌ Non-Compliant")),"✅ Compliant"))))) | H20: =IF(E20="","",IF(D20="Quarterly",E20+90,IF(D20="Semi-Annual",E20+180,IF(D20="Annual",E20+365,E20))))
F21: =IF(E21="","",TODAY()-E21) | G21: =IF(A21="","",IF(E21="","❓ Unknown",IF(D21="Quarterly",IF(F21<=90,"✅ Compliant",IF(F21<=105,"⚠ Overdue","❌ Non-Compliant")),IF(D21="Semi-Annual",IF(F21<=180,"✅ Compliant",IF(F21<=200,"⚠ Overdue","❌ Non-Compliant")),IF(D21="Annual",IF(F21<=365,"✅ Compliant",IF(F21<=400,"⚠ Overdue","❌ Non-Compliant")),"✅ Compliant"))))) | H21: =IF(E21="","",IF(D21="Quarterly",E21+90,IF(D21="Semi-Annual",E21+180,IF(D21="Annual",E21+365,E21))))
F22: =IF(E22="","",TODAY()-E22) | G22: =IF(A22="","",IF(E22="","❓ Unknown",IF(D22="Quarterly",IF(F22<=90,"✅ Compliant",IF(F22<=105,"⚠ Overdue","❌ Non-Compliant")),IF(D22="Semi-Annual",IF(F22<=180,"✅ Compliant",IF(F22<=200,"⚠ Overdue","❌ Non-Compliant")),IF(D22="Annual",IF(F22<=365,"✅ Compliant",IF(F22<=400,"⚠ Overdue","❌ Non-Compliant")),"✅ Compliant"))))) | H22: =IF(E22="","",IF(D22="Quarterly",E22+90,IF(D22="Semi-Annual",E22+180,IF(D22="Annual",E22+365,E22))))
F23: =IF(E23="","",TODAY()-E23) | G23: =IF(A23="","",IF(E23="","❓ Unknown",IF(D23="Quarterly",IF(F23<=90,"✅ Compliant",IF(F23<=105,"⚠ Overdue","❌ Non-Compliant")),IF(D23="Semi-Annual",IF(F23<=180,"✅ Compliant",IF(F23<=200,"⚠ Overdue","❌ Non-Compliant")),IF(D23="Annual",IF(F23<=365,"✅ Compliant",IF(F23<=400,"⚠ Overdue","❌ Non-Compliant")),"✅ Compliant"))))) | H23: =IF(E23="","",IF(D23="Quarterly",E23+90,IF(D23="Semi-Annual",E23+180,IF(D23="Annual",E23+365,E23))))
F24: =IF(E24="","",TODAY()-E24) | G24: =IF(A24="","",IF(E24="","❓ Unknown",IF(D24="Quarterly",IF(F24<=90,"✅ Compliant",IF(F24<=105,"⚠ Overdue","❌ Non-Compliant")),IF(D24="Semi-Annual",IF(F24<=180,"✅ Compliant",IF(F24<=200,"⚠ Overdue","❌ Non-Compliant")),IF(D24="Annual",IF(F24<=365,"✅ Compliant",IF(F24<=400,"⚠ Overdue","❌ Non-Compliant")),"✅ Compliant"))))) | H24: =IF(E24="","",IF(D24="Quarterly",E24+90,IF(D24="Semi-Annual",E24+180,IF(D24="Annual",E24+365,E24))))
F25: =IF(E25="","",TODAY()-E25) | G25: =IF(A25="","",IF(E25="","❓ Unknown",IF(D25="Quarterly",IF(F25<=90,"✅ Compliant",IF(F25<=105,"⚠ Overdue","❌ Non-Compliant")),IF(D25="Semi-Annual",IF(F25<=180,"✅ Compliant",IF(F25<=200,"⚠ Overdue","❌ Non-Compliant")),IF(D25="Annual",IF(F25<=365,"✅ Compliant",IF(F25<=400,"⚠ Overdue","❌ Non-Compliant")),"✅ Compliant"))))) | H25: =IF(E25="","",IF(D25="Quarterly",E25+90,IF(D25="Semi-Annual",E25+180,IF(D25="Annual",E25+365,E25))))
F26: =IF(E26="","",TODAY()-E26) | G26: =IF(A26="","",IF(E26="","❓ Unknown",IF(D26="Quarterly",IF(F26<=90,"✅ Compliant",IF(F26<=105,"⚠ Overdue","❌ Non-Compliant")),IF(D26="Semi-Annual",IF(F26<=180,"✅ Compliant",IF(F26<=200,"⚠ Overdue","❌ Non-Compliant")),IF(D26="Annual",IF(F26<=365,"✅ Compliant",IF(F26<=400,"⚠ Overdue","❌ Non-Compliant")),"✅ Compliant"))))) | H26: =IF(E26="","",IF(D26="Quarterly",E26+90,IF(D26="Semi-Annual",E26+180,IF(D26="Annual",E26+365,E26))))
F27: =IF(E27="","",TODAY()-E27) | G27: =IF(A27="","",IF(E27="","❓ Unknown",IF(D27="Quarterly",IF(F27<=90,"✅ Compliant",IF(F27<=105,"⚠ Overdue","❌ Non-Compliant")),IF(D27="Semi-Annual",IF(F27<=180,"✅ Compliant",IF(F27<=200,"⚠ Overdue","❌ Non-Compliant")),IF(D27="Annual",IF(F27<=365,"✅ Compliant",IF(F27<=400,"⚠ Overdue","❌ Non-Compliant")),"✅ Compliant"))))) | H27: =IF(E27="","",IF(D27="Quarterly",E27+90,IF(D27="Semi-Annual",E27+180,IF(D27="Annual",E27+365,E27))))
... F65: =IF(E65="","",TODAY()-E65) | G65: =IF(A65="","",IF(E65="","❓ Unknown",IF(D65="Quarterly",IF(F65<=90,"✅ Compliant",IF(F65<=105,"⚠ Overdue","❌ Non-Compliant")),IF(D65="Semi-Annual",IF(F65<=180,"✅ Compliant",IF(F65<=200,"⚠ Overdue","❌ Non-Compliant")),IF(D65="Annual",IF(F65<=365,"✅ Compliant",IF(F65<=400,"⚠ Overdue","❌ Non-Compliant")),"✅ Compliant"))))) | H65: =IF(E65="","",IF(D65="Quarterly",E65+90,IF(D65="Semi-Annual",E65+180,IF(D65="Annual",E65+365,E65))))
A68: TESTING COMPLIANCE SUMMARY
A69: Total Systems Tracked: | B69: =COUNTA(A6:A65)
A70: ✅ Compliant: | B70: =COUNTIF(G6:G65,"✅*")
A71: ⚠ Overdue: | B71: =COUNTIF(G6:G65,"⚠*")
A72: ❌ Non-Compliant: | B72: =COUNTIF(G6:G65,"❌*")
A73: ❓ Unknown (Never Tested): | B73: =COUNTIF(G6:G65,"❓*")
A75: Overall Compliance Rate: | B75: =IF(B69>0,B70/B69,0)
A76: Tests Overdue/Non-Compliant: | B76: =B71+B72

Sheet Evidence Register
A1: EVIDENCE REGISTER
A2: Document all evidence supporting this assessment (ISMS-IMP-A.5.30.S4 | MINIMUM 5 items required for audit compliance)
A4: Evidence ID | B4: Evidence Type | C4: Description | D4: Related Sheet / Row | E4: Location / Path | F4: Date Collected | G4: Collected By | H4: Verification Status
A5: EV-001 | B5: Test Report | C5: E-Commerce backup restore test report — Q1 | D5: Test Results Log!A5 (RES-001) | E5: /evidence/testing/ecommerce_restore_Q1.pdf | F5: 10.03.2026 | G5: Infrastructure Team | H5: ✅ Verified

Sheet Summary Dashboard
A1: TESTING RESULTS — SUMMARY DASHBOARD
A2: Assessment ID: ISMS-IMP-A.5.30.S4 | Assessment Date: [enter date]
A4: TESTING ACTIVITY SUMMARY
A5: Total Tests Scheduled: | B5: =COUNTA('Test Schedule'!A16:A65)
A6: Tests Completed: | B6: =COUNTIF('Test Results Log'!F16:F65,"✅*")
A7: Tests Partial Success: | B7: =COUNTIF('Test Results Log'!F16:F65,"⚠*")
A8: Tests Failed: | B8: =COUNTIF('Test Results Log'!F16:F65,"❌*")
A9: Tests In Progress: | B9: =COUNTIF('Test Results Log'!F16:F65,"In Progress*")
A10: Tests Not Started: | B10: =COUNTIF('Test Results Log'!F16:F65,"Not Started*")
A12: Test Success Rate: | B12: =IF(B5>0,(B6+B7*0.5)/B5,0)
A14: TESTING COMPLIANCE BY CRITICALITY
A15: Tier 1 - Critical Systems: | B15: =COUNTIF('Testing Compliance'!C16:C65,"Tier 1*")
A16: Tier 1 - Compliant: | B16: =SUMPRODUCT(('Testing Compliance'!C16:C65="Tier 1 - Critical")*('Testing Compliance'!G16:G65="✅ Compliant"))
A17: Tier 1 - Compliance Rate: | B17: =IF(B15>0,B16/B15,0)
A19: Tier 2 - Important Systems: | B19: =COUNTIF('Testing Compliance'!C16:C65,"Tier 2*")
A20: Tier 2 - Compliant: | B20: =SUMPRODUCT(('Testing Compliance'!C16:C65="Tier 2 - Important")*('Testing Compliance'!G16:G65="✅ Compliant"))
A21: Tier 2 - Compliance Rate: | B21: =IF(B19>0,B20/B19,0)
A23: ISSUE SUMMARY
A24: Total Issues Identified: | B24: =COUNTA('Issue Remediation'!A16:A65)
A25: [!] Critical Issues: | B25: =COUNTIF('Issue Remediation'!E16:E65,"[!]*")
A26: [~] High Severity Issues: | B26: =COUNTIF('Issue Remediation'!E16:E65,"[~]*")
A27: [.] Medium Severity Issues: | B27: =COUNTIF('Issue Remediation'!E16:E65,"[.]*")
A28: [ ] Low Severity Issues: | B28: =COUNTIF('Issue Remediation'!E16:E65,"[ ]*")
A30: Open Issues: | B30: =COUNTIF('Issue Remediation'!F16:F65,"Open*")
A31: In Progress: | B31: =COUNTIF('Issue Remediation'!F16:F65,"In Progress*")
A32: Closed Issues: | B32: =COUNTIF('Issue Remediation'!F16:F65,"✅*")
A34: EVIDENCE & APPROVAL STATUS
A35: Evidence Items Collected: | B35: =COUNTA('Evidence Register'!A6:A105)
A36: Verified Evidence: | B36: =COUNTIF('Evidence Register'!H6:H105,"✅*")
A37: Minimum Evidence Required: | B37: 5
A38: Evidence Compliance: | B38: =IF(B39>=B41,"✅ Sufficient","❌ Insufficient")
A40: Assessment Status: | B40: ='Approval Sign-Off'!B7
A41: Level 1 - Assessor Completed: | B41: =IF('Approval Sign-Off'!B11<>"","✅ Complete","Pending")
A42: Level 2 - ISO Review: | B42: =IF('Approval Sign-Off'!B18<>"","✅ Complete","Pending")
A43: Level 3 - CISO Approval: | B43: =IF('Approval Sign-Off'!B25<>"","✅ Complete","Pending")
A45: PRIORITY ACTIONS
A46: 1. Address all [!] Critical issues discovered during testing
A47: 2. Complete all overdue tests (Overdue in Testing Compliance)
A48: 3. Schedule quarterly tests for Tier 1 systems
A49: 4. Remediate test failures (Failed tests in Test Results Log)
...

Sheet Approval Sign-Off
A1: ASSESSMENT APPROVAL AND SIGN-OFF
A2: ISMS-IMP-A.5.30.S4 | ISO/IEC 27001:2022 - Control A.5.30 (BC/DR Testing)
A3: ASSESSMENT SUMMARY
A4: Document: | B4: ISMS-IMP-A.5.30.S4 - BC/DR Testing Results Tracker
A5: Assessment Period:
A6: Overall Test Pass Rate: | B6: ='Summary Dashboard'!B13
A7: Assessment Status:
A8: Assessed By:
A11: COMPLETED BY (ASSESSOR)
A12: Name:
A13: Title:
A14: Date:
A15: Signature:
A16: Comments:
A18: REVIEWED BY (INFORMATION SECURITY OFFICER)
A19: Name:
A20: Title:
A21: Date:
... A38: Special Considerations:
