Workbook

Sheet Executive Summary
A1: AI-CHK-A.7.2-6 — Data for AI Systems Compliance Checklist
A3: DOCUMENT INFORMATION
A4: Document ID | B4: AI-CHK-A.7.2-6
A5: Source Policy | B5: AI-POL-A.7.2-6
A6: ISO Controls | B6: Data for AI Systems
A7: Generated | B7: 15.04.2026
A8: Prepared By
A9: Organisation
A10: Review Cycle | B10: Annual
A12: OVERALL COMPLIANCE STATUS
A13: Overall Compliance | B13: ='Dashboard'!G9
A14: Status | B14: =IF(Dashboard!G9="N/A","NOT ASSESSED",IF(ISNUMBER(VALUE(SUBSTITUTE(Dashboard!G9,"%",""))),IF(VALUE(SUBSTITUTE(Dashboard!G9,"%",""))>=90,"GREEN",IF(VALUE(SUBSTITUTE(Dashboard!G9,"%",""))>=70,"AMBER","RED")),"NOT ASSESSED"))
A16: KEY METRICS
A17: Total Requirements | B17: ='Dashboard'!B9
A18: Compliant | B18: ='Dashboard'!C9
A19: Partial | B19: ='Dashboard'!D9
A20: Non-Compliant | B20: ='Dashboard'!E9
A21: Not Applicable | B21: ='Dashboard'!F9
A22: Owner Coverage | B22: =IF(Dashboard!B9=0,"N/A",ROUND((COUNTA('Data Management'!F4:F8)+COUNTA('Data Acquisition'!F4:F8)+COUNTA('Data Quality'!F4:F8)+COUNTA('Data Provenance'!F4:F7)+COUNTA('Data Preparation'!F4:F7))/Dashboard!B9*100,0)&"%")
A24: DOMAIN STATUS SUMMARY
A25: Domain | B25: Compliance % | C25: Compliant | D25: Gaps | E25: Status
A26: Data Management | B26: ='Dashboard'!G4 | C26: ='Dashboard'!C4 | D26: ='Dashboard'!E4 | E26: =IF(Dashboard!G4="N/A","--",IF(ISNUMBER(VALUE(SUBSTITUTE(Dashboard!G4,"%",""))),IF(VALUE(SUBSTITUTE(Dashboard!G4,"%",""))>=90,"PASS",IF(VALUE(SUBSTITUTE(Dashboard!G4,"%",""))>=70,"REVIEW","FAIL")),"--"))
A27: Data Acquisition | B27: ='Dashboard'!G5 | C27: ='Dashboard'!C5 | D27: ='Dashboard'!E5 | E27: =IF(Dashboard!G5="N/A","--",IF(ISNUMBER(VALUE(SUBSTITUTE(Dashboard!G5,"%",""))),IF(VALUE(SUBSTITUTE(Dashboard!G5,"%",""))>=90,"PASS",IF(VALUE(SUBSTITUTE(Dashboard!G5,"%",""))>=70,"REVIEW","FAIL")),"--"))
A28: Data Quality | B28: ='Dashboard'!G6 | C28: ='Dashboard'!C6 | D28: ='Dashboard'!E6 | E28: =IF(Dashboard!G6="N/A","--",IF(ISNUMBER(VALUE(SUBSTITUTE(Dashboard!G6,"%",""))),IF(VALUE(SUBSTITUTE(Dashboard!G6,"%",""))>=90,"PASS",IF(VALUE(SUBSTITUTE(Dashboard!G6,"%",""))>=70,"REVIEW","FAIL")),"--"))
A29: Data Provenance | B29: ='Dashboard'!G7 | C29: ='Dashboard'!C7 | D29: ='Dashboard'!E7 | E29: =IF(Dashboard!G7="N/A","--",IF(ISNUMBER(VALUE(SUBSTITUTE(Dashboard!G7,"%",""))),IF(VALUE(SUBSTITUTE(Dashboard!G7,"%",""))>=90,"PASS",IF(VALUE(SUBSTITUTE(Dashboard!G7,"%",""))>=70,"REVIEW","FAIL")),"--"))
A30: Data Preparation | B30: ='Dashboard'!G8 | C30: ='Dashboard'!C8 | D30: ='Dashboard'!E8 | E30: =IF(Dashboard!G8="N/A","--",IF(ISNUMBER(VALUE(SUBSTITUTE(Dashboard!G8,"%",""))),IF(VALUE(SUBSTITUTE(Dashboard!G8,"%",""))>=90,"PASS",IF(VALUE(SUBSTITUTE(Dashboard!G8,"%",""))>=70,"REVIEW","FAIL")),"--"))
A32: CRITICAL ISSUES
A33: # | B33: Issue Description | C33: Domain | D33: Owner | E33: Due Date
A34: 1
A35: 2
A36: 3
A37: 4
A38: 5
A40: MANAGEMENT COMMENTARY
A41: [Enter management commentary on data for ai systems posture]
A45: APPROVAL
A46: Assessed By (AI System Owner)
A47: Name:
A48: Date:
A49: Signature:
...

Sheet Dashboard
A1: Data for AI Systems — Compliance Dashboard
A3: Domain | B3: Total Reqs | C3: Compliant | D3: Partial | E3: Non-Compliant | F3: N/A | G3: Compliance %
A4: Data Management | B4: =COUNTA('Data Management'!D4:D8) | C4: =COUNTIF('Data Management'!D4:D8,"Compliant") | D4: =COUNTIF('Data Management'!D4:D8,"Partial") | E4: =COUNTIF('Data Management'!D4:D8,"Non-Compliant") | F4: =COUNTIF('Data Management'!D4:D8,"N/A") | G4: =IF((B4-F4)=0,"N/A",ROUND(C4/(B4-F4)*100,1)&"%")
A5: Data Acquisition | B5: =COUNTA('Data Acquisition'!D4:D8) | C5: =COUNTIF('Data Acquisition'!D4:D8,"Compliant") | D5: =COUNTIF('Data Acquisition'!D4:D8,"Partial") | E5: =COUNTIF('Data Acquisition'!D4:D8,"Non-Compliant") | F5: =COUNTIF('Data Acquisition'!D4:D8,"N/A") | G5: =IF((B5-F5)=0,"N/A",ROUND(C5/(B5-F5)*100,1)&"%")
A6: Data Quality | B6: =COUNTA('Data Quality'!D4:D8) | C6: =COUNTIF('Data Quality'!D4:D8,"Compliant") | D6: =COUNTIF('Data Quality'!D4:D8,"Partial") | E6: =COUNTIF('Data Quality'!D4:D8,"Non-Compliant") | F6: =COUNTIF('Data Quality'!D4:D8,"N/A") | G6: =IF((B6-F6)=0,"N/A",ROUND(C6/(B6-F6)*100,1)&"%")
A7: Data Provenance | B7: =COUNTA('Data Provenance'!D4:D7) | C7: =COUNTIF('Data Provenance'!D4:D7,"Compliant") | D7: =COUNTIF('Data Provenance'!D4:D7,"Partial") | E7: =COUNTIF('Data Provenance'!D4:D7,"Non-Compliant") | F7: =COUNTIF('Data Provenance'!D4:D7,"N/A") | G7: =IF((B7-F7)=0,"N/A",ROUND(C7/(B7-F7)*100,1)&"%")
A8: Data Preparation | B8: =COUNTA('Data Preparation'!D4:D7) | C8: =COUNTIF('Data Preparation'!D4:D7,"Compliant") | D8: =COUNTIF('Data Preparation'!D4:D7,"Partial") | E8: =COUNTIF('Data Preparation'!D4:D7,"Non-Compliant") | F8: =COUNTIF('Data Preparation'!D4:D7,"N/A") | G8: =IF((B8-F8)=0,"N/A",ROUND(C8/(B8-F8)*100,1)&"%")
A9: TOTAL | B9: =SUM(B4:B8) | C9: =SUM(C4:C8) | D9: =SUM(D4:D8) | E9: =SUM(E4:E8) | F9: =SUM(F4:F8) | G9: =IF((B9-F9)=0,"N/A",ROUND(C9/(B9-F9)*100,1)&"%")
A11: COMPLIANCE BY STATUS
A12: Compliant | B12: =C9 | C12: =IF(B9=0,"",ROUND(B12/B9*100,1)&"%")
A13: Partial | B13: =D9 | C13: =IF(B9=0,"",ROUND(B13/B9*100,1)&"%")
A14: Non-Compliant | B14: =E9 | C14: =IF(B9=0,"",ROUND(B14/B9*100,1)&"%")
A15: N/A | B15: =F9 | C15: =IF(B9=0,"",ROUND(B15/B9*100,1)&"%")
A17: TOP GAPS (Manual Entry)
A18: Priority | B18: Domain | C18: Requirement | D18: Owner | E18: Due Date | F18: Status
A30: COMPLIANCE TREND (Manual Entry)
A31: Assessment Date | B31: Overall % | C31: Compliant | D31: Gaps | E31: Assessor | F31: Notes

Sheet Data Management
A1: Data Management — Compliance Checklist
A2: ISO/IEC 42001:2023 — Controls A.7.2-6: Data for AI Systems
A3: Req # | B3: Section | C3: Requirement | D3: Status | E3: Evidence | F3: Owner | G3: Due Date | H3: Notes
A4: A.7.2-01 | B4: Data Governance Framework | C4: The organisation shall establish a data governance framework for AI systems covering: data acquisition controls, quality requirements, provenance tracking, preparation documentation, and data retention and deletion. The framework shall be documented and implemented.
A5: A.7.2-02 | B5: Data Register | C5: The organisation shall maintain a register of all datasets used across in-scope AI systems. The register shall identify each dataset, its source category, whether it contains personal data, its current governance status, and the AI systems that use it.
A6: A.7.2-03 | B6: Personal Data Controls | C6: Where AI system data resources include personal data, the organisation shall confirm a documented legal basis for each processing activity, apply data minimisation, and maintain linkage between the AI system and the relevant GDPR or equivalent records.
A7: A.7.2-04 | B7: Prohibited Data Policy | C7: The organisation shall document and communicate a list of data sources that are prohibited from use in AI systems without explicit written approval — including data with unknown provenance, unlicensed third-party data, and personal data without a legal basis.
A8: A.7.2-05 | B8: Data Lifecycle | C8: The organisation shall define and implement data retention and deletion schedules for AI system datasets. Schedules shall be proportionate to legal requirements and the operational life of the AI system. Deletion events shall be recorded.

Sheet Data Acquisition
A1: Data Acquisition — Compliance Checklist
A2: ISO/IEC 42001:2023 — Controls A.7.2-6: Data for AI Systems
A3: Req # | B3: Section | C3: Requirement | D3: Status | E3: Evidence | F3: Owner | G3: Due Date | H3: Notes
A4: A.7.3-01 | B4: Acquisition Record | C4: For every dataset used in training or fine-tuning an AI system, the organisation shall complete a Data Acquisition Record per the template in AI-IMP-A.7.2-6-TG. No dataset shall enter production use without a completed Acquisition Record.
A5: A.7.3-02 | B5: Licence and Rights | C5: Before acquiring a dataset, the organisation shall verify and document: the data licence or terms of use, any restrictions on commercial use, any restrictions on use in AI training, and the confirmation that use falls within the licence scope.
A6: A.7.3-03 | B6: Source Category Documentation | C6: The Data Acquisition Record shall document the data source category: first-party data, licensed third-party data, open dataset, synthetic data, or web-scraped data. For each category, applicable governance controls shall be confirmed.
A7: A.7.3-04 | B7: Personal Data Legal Basis | C7: Where a dataset contains personal data, the Data Acquisition Record shall document the legal basis for processing and reference the relevant GDPR Article 6 or Article 9 basis. Datasets with personal data and no documented legal basis shall not be used.
A8: A.7.3-05 | B8: Third-Party AI API Data | C8: Where the organisation sends data to a third-party AI API for inference or fine-tuning, the organisation shall document what data is sent, confirm there is no prohibited data in the inputs, and confirm the contractual data processing terms with the provider.

Sheet Data Quality
A1: Data Quality — Compliance Checklist
A2: ISO/IEC 42001:2023 — Controls A.7.2-6: Data for AI Systems
A3: Req # | B3: Section | C3: Requirement | D3: Status | E3: Evidence | F3: Owner | G3: Due Date | H3: Notes
A4: A.7.4-01 | B4: Quality Gate | C4: All training datasets shall pass a documented data quality gate before use in model development. The quality gate shall evaluate accuracy, completeness, consistency, timeliness, and representativeness at a minimum.
A5: A.7.4-02 | B5: Quality Record | C5: The organisation shall complete a Data Quality Record per the template in AI-IMP-A.7.2-6-TG for each training dataset. The record shall document quality dimensions assessed, threshold values, actual results, and pass/fail determination.
A6: A.7.4-03 | B6: Representativeness Assessment | C6: The quality assessment shall include a representativeness assessment: whether the dataset adequately represents the populations the AI system will be applied to, and whether underrepresented groups are identified and documented.
A7: A.7.4-04 | B7: Quality Gate Failure Handling | C7: Where a dataset fails the quality gate, the organisation shall document the failure and either: remediate the quality issues and re-run assessment; acquire an alternative dataset; or escalate to the AI Governance Officer with justification if deployment is still being considered.
A8: A.7.4-05 | B8: Operational Data Quality | C8: The organisation shall implement monitoring of operational data quality for deployed AI systems — detecting degradation in data completeness, consistency, or representativeness that could affect system performance. Quality alerts shall feed into the AI system monitoring plan.

Sheet Data Provenance
A1: Data Provenance — Compliance Checklist
A2: ISO/IEC 42001:2023 — Controls A.7.2-6: Data for AI Systems
A3: Req # | B3: Section | C3: Requirement | D3: Status | E3: Evidence | F3: Owner | G3: Due Date | H3: Notes
A4: A.7.5-01 | B4: Provenance Tracking | C4: The organisation shall maintain data provenance records that trace each dataset used in an AI system from acquisition through all transformation steps to the model training run. Provenance shall be sufficient to support audit, incident investigation, and data deletion requests.
A5: A.7.5-02 | B5: Transformation History | C5: Every material transformation applied to a dataset — including cleaning, normalisation, augmentation, and filtering — shall be recorded with: the transformation applied, the tool/script used, the operator, and the date. Transformations shall be reproducible.
A6: A.7.5-03 | B6: Deletion Request Support | C6: Data provenance records shall be sufficient to identify and action deletion requests — including GDPR right to erasure requests. Where an erasure request cannot be actioned without retraining or withdrawing a model, the AI System Owner shall escalate to the AI Governance Officer.
A7: A.7.5-04 | B7: Provenance Record Retention | C7: Data provenance records shall be retained for the operational life of the AI system plus a minimum of 5 years after decommissioning. Provenance records shall be available to auditors and regulatory authorities on request.

Sheet Data Preparation
A1: Data Preparation — Compliance Checklist
A2: ISO/IEC 42001:2023 — Controls A.7.2-6: Data for AI Systems
A3: Req # | B3: Section | C3: Requirement | D3: Status | E3: Evidence | F3: Owner | G3: Due Date | H3: Notes
A4: A.7.6-01 | B4: Preparation Documentation | C4: All data preparation activities — including feature engineering, train/test/validation splitting, data augmentation, and class balancing — shall be documented in a Data Preparation Documentation record per the template in AI-IMP-A.7.2-6-TG.
A5: A.7.6-02 | B5: Bias-Aware Preparation | C5: Data preparation steps shall be assessed for their potential to introduce or amplify bias — including oversampling, undersampling, feature selection, and proxy variable inclusion. Bias risks identified during preparation shall be flagged in the bias assessment.
A6: A.7.6-03 | B6: Test Set Integrity | C6: Test and validation datasets shall be kept strictly separate from training data. Data leakage between training and test sets shall be prevented and verified. The separation method shall be documented in the Data Preparation Documentation record.
A7: A.7.6-04 | B7: Synthetic Data Controls | C7: Where synthetic data is generated for training or testing, the organisation shall document: the generation method, the source data used to train the generator, quality validation performed on synthetic outputs, and any privacy-preserving properties claimed.
