Workbook

Sheet Executive Summary
A1: AI-CHK-A.8.2-5 — Information for Interested Parties Compliance Checklist
A3: DOCUMENT INFORMATION
A4: Document ID | B4: AI-CHK-A.8.2-5
A5: Source Policy | B5: AI-POL-A.8.2-5
A6: ISO Controls | B6: Information for Interested Parties
A7: Generated | B7: 15.04.2026
A8: Prepared By
A9: Organisation
A10: Review Cycle | B10: Annual
A12: OVERALL COMPLIANCE STATUS
A13: Overall Compliance | B13: ='Dashboard'!G8
A14: Status | B14: =IF(Dashboard!G8="N/A","NOT ASSESSED",IF(ISNUMBER(VALUE(SUBSTITUTE(Dashboard!G8,"%",""))),IF(VALUE(SUBSTITUTE(Dashboard!G8,"%",""))>=90,"GREEN",IF(VALUE(SUBSTITUTE(Dashboard!G8,"%",""))>=70,"AMBER","RED")),"NOT ASSESSED"))
A16: KEY METRICS
A17: Total Requirements | B17: ='Dashboard'!B8
A18: Compliant | B18: ='Dashboard'!C8
A19: Partial | B19: ='Dashboard'!D8
A20: Non-Compliant | B20: ='Dashboard'!E8
A21: Not Applicable | B21: ='Dashboard'!F8
A22: Owner Coverage | B22: =IF(Dashboard!B8=0,"N/A",ROUND((COUNTA('User Documentation'!F4:F8)+COUNTA('Transparency to Affected Parties'!F4:F8)+COUNTA('External Reporting'!F4:F7)+COUNTA('Incident Communication'!F4:F7))/Dashboard!B8*100,0)&"%")
A24: DOMAIN STATUS SUMMARY
A25: Domain | B25: Compliance % | C25: Compliant | D25: Gaps | E25: Status
A26: User Documentation | B26: ='Dashboard'!G4 | C26: ='Dashboard'!C4 | D26: ='Dashboard'!E4 | E26: =IF(Dashboard!G4="N/A","--",IF(ISNUMBER(VALUE(SUBSTITUTE(Dashboard!G4,"%",""))),IF(VALUE(SUBSTITUTE(Dashboard!G4,"%",""))>=90,"PASS",IF(VALUE(SUBSTITUTE(Dashboard!G4,"%",""))>=70,"REVIEW","FAIL")),"--"))
A27: Transparency to Affected Parties | B27: ='Dashboard'!G5 | C27: ='Dashboard'!C5 | D27: ='Dashboard'!E5 | E27: =IF(Dashboard!G5="N/A","--",IF(ISNUMBER(VALUE(SUBSTITUTE(Dashboard!G5,"%",""))),IF(VALUE(SUBSTITUTE(Dashboard!G5,"%",""))>=90,"PASS",IF(VALUE(SUBSTITUTE(Dashboard!G5,"%",""))>=70,"REVIEW","FAIL")),"--"))
A28: External Reporting | B28: ='Dashboard'!G6 | C28: ='Dashboard'!C6 | D28: ='Dashboard'!E6 | E28: =IF(Dashboard!G6="N/A","--",IF(ISNUMBER(VALUE(SUBSTITUTE(Dashboard!G6,"%",""))),IF(VALUE(SUBSTITUTE(Dashboard!G6,"%",""))>=90,"PASS",IF(VALUE(SUBSTITUTE(Dashboard!G6,"%",""))>=70,"REVIEW","FAIL")),"--"))
A29: Incident Communication | B29: ='Dashboard'!G7 | C29: ='Dashboard'!C7 | D29: ='Dashboard'!E7 | E29: =IF(Dashboard!G7="N/A","--",IF(ISNUMBER(VALUE(SUBSTITUTE(Dashboard!G7,"%",""))),IF(VALUE(SUBSTITUTE(Dashboard!G7,"%",""))>=90,"PASS",IF(VALUE(SUBSTITUTE(Dashboard!G7,"%",""))>=70,"REVIEW","FAIL")),"--"))
A31: CRITICAL ISSUES
A32: # | B32: Issue Description | C32: Domain | D32: Owner | E32: Due Date
A33: 1
A34: 2
A35: 3
A36: 4
A37: 5
A39: MANAGEMENT COMMENTARY
A40: [Enter management commentary on information for interested parties posture]
A44: APPROVAL
A45: Assessed By (AI System Owner)
A46: Name:
A47: Date:
A48: Signature:
A49: Decision:
...

Sheet Dashboard
A1: Information for Interested Parties — Compliance Dashboard
A3: Domain | B3: Total Reqs | C3: Compliant | D3: Partial | E3: Non-Compliant | F3: N/A | G3: Compliance %
A4: User Documentation | B4: =COUNTA('User Documentation'!D4:D8) | C4: =COUNTIF('User Documentation'!D4:D8,"Compliant") | D4: =COUNTIF('User Documentation'!D4:D8,"Partial") | E4: =COUNTIF('User Documentation'!D4:D8,"Non-Compliant") | F4: =COUNTIF('User Documentation'!D4:D8,"N/A") | G4: =IF((B4-F4)=0,"N/A",ROUND(C4/(B4-F4)*100,1)&"%")
A5: Transparency to Affected Parties | B5: =COUNTA('Transparency to Affected Parties'!D4:D8) | C5: =COUNTIF('Transparency to Affected Parties'!D4:D8,"Compliant") | D5: =COUNTIF('Transparency to Affected Parties'!D4:D8,"Partial") | E5: =COUNTIF('Transparency to Affected Parties'!D4:D8,"Non-Compliant") | F5: =COUNTIF('Transparency to Affected Parties'!D4:D8,"N/A") | G5: =IF((B5-F5)=0,"N/A",ROUND(C5/(B5-F5)*100,1)&"%")
A6: External Reporting | B6: =COUNTA('External Reporting'!D4:D7) | C6: =COUNTIF('External Reporting'!D4:D7,"Compliant") | D6: =COUNTIF('External Reporting'!D4:D7,"Partial") | E6: =COUNTIF('External Reporting'!D4:D7,"Non-Compliant") | F6: =COUNTIF('External Reporting'!D4:D7,"N/A") | G6: =IF((B6-F6)=0,"N/A",ROUND(C6/(B6-F6)*100,1)&"%")
A7: Incident Communication | B7: =COUNTA('Incident Communication'!D4:D7) | C7: =COUNTIF('Incident Communication'!D4:D7,"Compliant") | D7: =COUNTIF('Incident Communication'!D4:D7,"Partial") | E7: =COUNTIF('Incident Communication'!D4:D7,"Non-Compliant") | F7: =COUNTIF('Incident Communication'!D4:D7,"N/A") | G7: =IF((B7-F7)=0,"N/A",ROUND(C7/(B7-F7)*100,1)&"%")
A8: TOTAL | B8: =SUM(B4:B7) | C8: =SUM(C4:C7) | D8: =SUM(D4:D7) | E8: =SUM(E4:E7) | F8: =SUM(F4:F7) | G8: =IF((B8-F8)=0,"N/A",ROUND(C8/(B8-F8)*100,1)&"%")
A10: COMPLIANCE BY STATUS
A11: Compliant | B11: =C8 | C11: =IF(B8=0,"",ROUND(B11/B8*100,1)&"%")
A12: Partial | B12: =D8 | C12: =IF(B8=0,"",ROUND(B12/B8*100,1)&"%")
A13: Non-Compliant | B13: =E8 | C13: =IF(B8=0,"",ROUND(B13/B8*100,1)&"%")
A14: N/A | B14: =F8 | C14: =IF(B8=0,"",ROUND(B14/B8*100,1)&"%")
A16: TOP GAPS (Manual Entry)
A17: Priority | B17: Domain | C17: Requirement | D17: Owner | E17: Due Date | F17: Status
A29: COMPLIANCE TREND (Manual Entry)
A30: Assessment Date | B30: Overall % | C30: Compliant | D30: Gaps | E30: Assessor | F30: Notes

Sheet User Documentation
A1: User Documentation — Compliance Checklist
A2: ISO/IEC 42001:2023 — Controls A.8.2-5: Information for Interested Parties
A3: Req # | B3: Section | C3: Requirement | D3: Status | E3: Evidence | F3: Owner | G3: Due Date | H3: Notes
A4: A.8.2-01 | B4: User Documentation Existence | C4: Every in-scope AI system made available to users shall have current user documentation per the template in AI-IMP-A.8.2-5-TG. Documentation shall be available before or at the point of system access, not retrospectively.
A5: A.8.2-02 | B5: Required Documentation Content | C5: User documentation shall include at minimum: system description and purpose; intended use and use restrictions; inputs required and outputs produced; human oversight and override instructions; known limitations; support and escalation contacts.
A6: A.8.2-03 | B6: Accuracy of Claimed Capabilities | C6: User documentation shall accurately represent the AI system's capabilities and limitations. Claims of accuracy, reliability, or fairness shall be supported by V&V evidence. No documentation shall overstate system capabilities.
A7: A.8.2-04 | B7: Documentation Accessibility | C7: User documentation shall be written in plain language accessible to the intended audience. Where the AI system is deployed in multiple languages, documentation shall be available in all languages supported by the system.
A8: A.8.2-05 | B8: Documentation Currency | C8: User documentation shall be updated whenever a material change is made to the AI system. Outdated documentation shall not remain current. The AI System Owner is responsible for documentation currency.

Sheet Transparency to Affected Parties
A1: Transparency to Affected Parties — Compliance Checklist
A2: ISO/IEC 42001:2023 — Controls A.8.2-5: Information for Interested Parties
A3: Req # | B3: Section | C3: Requirement | D3: Status | E3: Evidence | F3: Owner | G3: Due Date | H3: Notes
A4: A.8.3-01 | B4: AI Disclosure to Users | C4: The organisation shall disclose to users that they are interacting with an AI system, unless the context makes this self-evident. Disclosure shall be clear, prominent, and provided before the first substantive AI interaction.
A5: A.8.3-02 | B5: Transparency Notice | C5: For AI systems that process personal data or make or support consequential decisions affecting individuals, the organisation shall publish a Transparency Notice per the template in AI-IMP-A.8.2-5-TG covering: AI system identity, purpose, data used, and recourse options.
A6: A.8.3-03 | B6: Recourse Information | C6: Where an AI system produces outputs that affect individuals' rights or interests, the organisation shall provide information on how affected individuals can seek human review, raise objections, or access support.
A7: A.8.3-04 | B7: EU AI Act Article 50 Compliance | C7: For AI systems in scope of EU AI Act Article 50 transparency requirements (deepfakes, emotion recognition, biometric categorisation, chatbots), the organisation shall implement the applicable disclosure obligations and document compliance.
A8: A.8.3-05 | B8: Transparency Register | C8: The AI Governance Officer shall maintain an Interested Party Information Register tracking what information has been provided to which categories of interested party, through which channels, and when.

Sheet External Reporting
A1: External Reporting — Compliance Checklist
A2: ISO/IEC 42001:2023 — Controls A.8.2-5: Information for Interested Parties
A3: Req # | B3: Section | C3: Requirement | D3: Status | E3: Evidence | F3: Owner | G3: Due Date | H3: Notes
A4: A.8.4-01 | B4: Regulatory Reporting Obligations | C4: The organisation shall identify all regulatory reporting obligations applicable to its AI systems — including EU AI Act Article 73 serious incident reporting, national AI regulatory requirements, and sector-specific obligations. Obligations shall be documented.
A5: A.8.4-02 | B5: Serious Incident Definition | C5: The organisation shall define what constitutes a serious incident for reporting purposes, aligned with EU AI Act Article 3(49) definition: risk to health/safety, fundamental rights violation, or significant disruption to critical services.
A6: A.8.4-03 | B6: External Reporting Process | C6: The organisation shall implement a documented process for external incident reporting, covering: detection and classification, decision on reportability, notification to regulatory authority within required timeframe, and documentation of report and response.
A7: A.8.4-04 | B7: Market Surveillance Cooperation | C7: The organisation shall implement a process for cooperating with market surveillance authorities — providing information, access, and documentation on request within required timeframes. The process shall be owned by the AI Governance Officer with Legal involvement.

Sheet Incident Communication
A1: Incident Communication — Compliance Checklist
A2: ISO/IEC 42001:2023 — Controls A.8.2-5: Information for Interested Parties
A3: Req # | B3: Section | C3: Requirement | D3: Status | E3: Evidence | F3: Owner | G3: Due Date | H3: Notes
A4: A.8.5-01 | B4: Internal Incident Communication | C4: When an AI incident is declared, the AI System Owner shall notify the AI Governance Officer within 24 hours. Notification shall include: system affected, nature of incident, initial impact assessment, and immediate containment actions taken.
A5: A.8.5-02 | B5: Affected Party Notification | C5: Where an AI incident directly affects individuals' rights or interests, the organisation shall notify affected parties of the incident, the impact on them, and the remediation actions taken, within a timeframe proportionate to severity.
A6: A.8.5-03 | B6: Notification Template | C6: External incident notifications shall use the template in AI-IMP-A.8.2-5-TG. Notifications shall be reviewed by Legal before transmission to regulatory authorities or large-scale affected populations.
A7: A.8.5-04 | B7: Communication Record | C7: All incident communications — internal notifications, external reports, and affected party notifications — shall be logged in the AI Incident Register with timestamps, recipients, and content. Communication records shall be retained for a minimum of 5 years.
