Workbook

Sheet Instructions & Legend
A1: BASELINE & DETECTION RULES ASSESSMENT
A2: ISO/IEC 27001:2022 - Control A.8.16: Monitoring Activities
A4: DOCUMENT INFORMATION
A5: Document ID: | B5: ISMS-IMP-A.8.16.2
A6: Assessment Area: | B6: Baseline & Detection Rules
A7: Related Policy: | B7: ISMS-POL-A.8.16-S2.2
A8: Version: | B8: 1.0
A9: Assessment Date: | B9: [USER INPUT - DD.MM.YYYY]
A10: Completed By: | B10: [USER INPUT]
A11: Organization: | B11: [USER INPUT]
A12: Review Cycle: | B12: Quarterly
A13: Next Review Date: | B13: =IF(B8<>"","=B8+90","")
A16: HOW TO USE THIS WORKBOOK
A17: 1. Complete each worksheet tab in sequence (1-5)
A18: 2. Document ALL baselines established for monitoring
A19: 3. Inventory ALL active detection/correlation rules
A20: 4. Map detection rules to MITRE ATT&CK framework
A21: 5. Assess rule performance (false positives, true positives)
A22: 6. Document testing and validation activities
A23: 7. Review Summary Dashboard for coverage gaps
A24: 8. Gather evidence and list in Evidence Register
A25: 9. Obtain approvals via Approval Sign-Off sheet
A28: STATUS LEGEND
A29: Symbol | B29: Meaning | C29: When to Use
A30: ✅ Active/Covered | B30: Baseline/rule active and effective | C30: Working as intended
A31: ⚠️ Partial/Stale | B31: Needs attention or update | C31: Requires tuning or refresh
A32: ❌ Missing/Not Covered | B32: Gap identified | C32: Critical gap to address
A33: 🔄 In Development/Planned | B33: Work in progress | C33: Future implementation
A36: KEY DEFINITIONS
A37: Term | B37: Definition
A38: Baseline | B38: Normal behavior pattern established through observation and statistical analysis
A39: Anomaly Detection | B39: Identification of deviations from established baseline behavior
A40: Correlation Rule | B40: Logic combining multiple events/conditions to detect complex attack patterns
A41: True Positive (TP) | B41: Alert correctly identifying actual security incident
A42: False Positive (FP) | B42: Alert incorrectly flagging benign activity as malicious
A43: True Negative (TN) | B43: Benign activity correctly not triggering alert
A44: False Negative (FN) | B44: Malicious activity failing to trigger alert (detection miss)
A45: MITRE ATT&CK | B45: Framework of adversary tactics, techniques, and procedures (TTPs)
A46: Detection Rate | B46: Percentage of actual incidents correctly detected (TP / (TP + FN))
A47: Precision | B47: Percentage of alerts that are true positives (TP / (TP + FP))
...

Sheet 1. Baseline Inventory
A1: 1. BASELINE INVENTORY & MAINTENANCE
A2: Policy Reference: ISMS-POL-A.8.16-S2.2.1 - Establish and maintain behavioral baselines
A3: Are baselines established for critical systems, users, and network traffic to enable anomaly detection?
A4: Overall Baseline Status:
A6: Baseline Name/ID | B6: Baseline Type | C6: Scope/Target | D6: Data Source | E6: Baseline Period | F6: Established Date | G6: Last Updated | H6: Update Frequency | I6: Anomaly Detection Method | J6: Threshold/Criteria | K6: Alert Rules Linked | L6: Baseline Status | M6: Days Since Update | N6: Compliance Status | O6: Issues/Gaps | P6: Owner | Q6: Priority
A7: BL-USER-001 | B7: User Activity | C7: Executive users | D7: Windows Event Logs | E7: 30 days | F7: 15.11.2024 | G7: 05.01.2025 | H7: Monthly | I7: Automated | J7: 3 std dev from mean | K7: RULE-105, RULE-203 | L7: ✅ Active | M7: 2 | N7: ✅ Compliant | O7: None | P7: SOC Team | Q7: High
M8: =IF(G8<>"",TODAY()-G8,"")
M9: =IF(G9<>"",TODAY()-G9,"")
M10: =IF(G10<>"",TODAY()-G10,"")
M11: =IF(G11<>"",TODAY()-G11,"")
M12: =IF(G12<>"",TODAY()-G12,"")
M13: =IF(G13<>"",TODAY()-G13,"")
M14: =IF(G14<>"",TODAY()-G14,"")
M15: =IF(G15<>"",TODAY()-G15,"")
M16: =IF(G16<>"",TODAY()-G16,"")
M17: =IF(G17<>"",TODAY()-G17,"")
M18: =IF(G18<>"",TODAY()-G18,"")
M19: =IF(G19<>"",TODAY()-G19,"")
... M37: =IF(G37<>"",TODAY()-G37,"")
A40: BASELINE STATISTICS
A41: Metric
A42: Total Baselines Defined
A43: Active Baselines
A44: Stale Baselines (>90 days)
A45: Baselines by Type: User Activity
A46: Baselines by Type: System Activity
A47: Baselines by Type: Network Traffic
A48: Automated Anomaly Detection
A49: Baselines with Linked Rules
A52: BASELINE COMPLIANCE CHECKLIST
A53: # | B53: Requirement
A54: 1 | B54: Baselines established for Tier 1 (critical) systems
A55: 2 | B55: Baselines established for Tier 2 (high) systems
A56: 3 | B56: Baselines established for privileged user accounts
A57: 4 | B57: Baselines established for network traffic patterns
A58: 5 | B58: Baselines established for application behavior
A59: 6 | B59: Baseline establishment period adequate (min 30 days)
A60: 7 | B60: Baseline update frequency defined and documented
A61: 8 | B61: Baselines reviewed and updated regularly (max 90 days)
A62: 9 | B62: Anomaly detection methods documented
...

Sheet 2. Detection Rules
A1: 2. DETECTION RULES INVENTORY
A2: Policy Reference: ISMS-POL-A.8.16-S2.2.2 - Detection rule coverage and effectiveness
A3: Are detection/correlation rules comprehensively covering security threats and regularly tuned for effectiveness?
A6: Rule ID/Name | B6: Rule Type | C6: Description | D6: Severity | E6: Data Source(s) | F6: Rule Logic Summary | G6: MITRE Tactic | H6: MITRE Technique | I6: Created Date | J6: Last Modified | K6: Last Triggered | L6: Trigger Count (30d) | M6: True Positives (30d) | N6: False Positives (30d) | O6: Precision % | P6: Rule Status | Q6: Tuning Status | R6: Owner | S6: Compliance Status | T6: Issues/Notes | U6: Priority
A7: RULE-105 | B7: Correlation | C7: Detect privilege escalation via Kerberos | D7: High | E7: Windows Event Logs | F7: 4768 + 4769 + 4672 within 5 min | G7: Privilege Escalation | H7: T1078 - Valid Accounts | I7: 10.08.2024 | J7: 15.12.2024 | K7: 05.01.2025 | L7: 12 | M7: 10 | N7: 2 | O7: 83% | P7: ✅ Active | Q7: Optimized | R7: SOC Team | S7: ✅ Compliant | T7: None | U7: High
O8: =IF(AND(M8<>"",N8<>""),ROUND(M8/(M8+N8)*100,1)&"%","")
O9: =IF(AND(M9<>"",N9<>""),ROUND(M9/(M9+N9)*100,1)&"%","")
O10: =IF(AND(M10<>"",N10<>""),ROUND(M10/(M10+N10)*100,1)&"%","")
O11: =IF(AND(M11<>"",N11<>""),ROUND(M11/(M11+N11)*100,1)&"%","")
O12: =IF(AND(M12<>"",N12<>""),ROUND(M12/(M12+N12)*100,1)&"%","")
O13: =IF(AND(M13<>"",N13<>""),ROUND(M13/(M13+N13)*100,1)&"%","")
O14: =IF(AND(M14<>"",N14<>""),ROUND(M14/(M14+N14)*100,1)&"%","")
O15: =IF(AND(M15<>"",N15<>""),ROUND(M15/(M15+N15)*100,1)&"%","")
O16: =IF(AND(M16<>"",N16<>""),ROUND(M16/(M16+N16)*100,1)&"%","")
O17: =IF(AND(M17<>"",N17<>""),ROUND(M17/(M17+N17)*100,1)&"%","")
O18: =IF(AND(M18<>"",N18<>""),ROUND(M18/(M18+N18)*100,1)&"%","")
O19: =IF(AND(M19<>"",N19<>""),ROUND(M19/(M19+N19)*100,1)&"%","")
... O57: =IF(AND(M57<>"",N57<>""),ROUND(M57/(M57+N57)*100,1)&"%","")
A60: DETECTION RULE STATISTICS
A61: Metric
A62: Total Active Rules
A63: Rules by Severity: Critical
A64: Rules by Severity: High
A65: Rules Triggered (30d)
A66: Average Precision %
A67: Rules Needing Tuning
A68: Rules Not Triggered (30d)
A69: Rules Updated (30d)
A72: DETECTION RULE COMPLIANCE CHECKLIST
A73: # | B73: Requirement
A74: 1 | B74: Detection rules cover critical threats (malware, ransomware, data exfil)
A75: 2 | B75: Rules aligned with MITRE ATT&CK framework
A76: 3 | B76: Rules cover all MITRE tactics (Initial Access → Impact)
A77: 4 | B77: Rule logic documented and peer-reviewed
A78: 5 | B78: Rules tested before production deployment
A79: 6 | B79: Rule performance tracked (TP, FP, precision)
A80: 7 | B80: False positive rate acceptable (<30%)
A81: 8 | B81: Rules tuned regularly (quarterly minimum)
A82: 9 | B82: Inactive rules (not triggered 90+ days) reviewed
A83: 10 | B83: Critical/High severity rules prioritized
...

Sheet 3. MITRE ATT&CK Coverage
A1: 3. MITRE ATT&CK FRAMEWORK COVERAGE
A2: Policy Reference: ISMS-POL-A.8.16-S2.2.3 - Detection coverage mapped to threat framework
A3: Are detection capabilities mapped to MITRE ATT&CK framework with adequate coverage across all tactics?
A6: MITRE Tactic | B6: MITRE Technique ID | C6: Technique Name | D6: Technique Description | E6: Risk Level | F6: Detection Rules | G6: Rule Count | H6: Data Sources Available | I6: Coverage Status | J6: Detection Quality | K6: Last Tested | L6: Test Result | M6: Notes/Gaps | N6: Priority
A7: Initial Access | B7: T1078 | C7: Valid Accounts | D7: Adversaries use valid accounts | E7: High | F7: RULE-105, RULE-112 | G7: 2 | H7: AD Logs, VPN Logs | I7: ✅ Covered | J7: Good | K7: 20.12.2024 | L7: Pass | M7: Working well | N7: High
A8: Execution | B8: T1059 | C8: Command and Scripting Interpreter | D8: Execute commands via scripts | E8: High | F8: RULE-203, RULE-204 | G8: 2 | H8: Process Logs, EDR | I8: ✅ Covered | J8: Excellent | K8: 18.12.2024 | L8: Pass | M8: None | N8: High
A9: Persistence | B9: T1547 | C9: Boot or Logon Autostart | D9: Persist via autostart | E9: Medium | F9: RULE-301 | G9: 1 | H9: Registry, File System | I9: ⚠️ Partial | J9: Fair | K9: 10.12.2024 | L9: Partial | M9: Needs more coverage | N9: Medium
G10: =IF(F10<>"",LEN(F10)-LEN(SUBSTITUTE(F10,",",""))+1,0)
G11: =IF(F11<>"",LEN(F11)-LEN(SUBSTITUTE(F11,",",""))+1,0)
G12: =IF(F12<>"",LEN(F12)-LEN(SUBSTITUTE(F12,",",""))+1,0)
G13: =IF(F13<>"",LEN(F13)-LEN(SUBSTITUTE(F13,",",""))+1,0)
G14: =IF(F14<>"",LEN(F14)-LEN(SUBSTITUTE(F14,",",""))+1,0)
G15: =IF(F15<>"",LEN(F15)-LEN(SUBSTITUTE(F15,",",""))+1,0)
G16: =IF(F16<>"",LEN(F16)-LEN(SUBSTITUTE(F16,",",""))+1,0)
G17: =IF(F17<>"",LEN(F17)-LEN(SUBSTITUTE(F17,",",""))+1,0)
G18: =IF(F18<>"",LEN(F18)-LEN(SUBSTITUTE(F18,",",""))+1,0)
G19: =IF(F19<>"",LEN(F19)-LEN(SUBSTITUTE(F19,",",""))+1,0)
G20: =IF(F20<>"",LEN(F20)-LEN(SUBSTITUTE(F20,",",""))+1,0)
G21: =IF(F21<>"",LEN(F21)-LEN(SUBSTITUTE(F21,",",""))+1,0)
... G59: =IF(F59<>"",LEN(F59)-LEN(SUBSTITUTE(F59,",",""))+1,0)
A62: MITRE ATT&CK TACTICS COVERAGE SUMMARY
A63: Tactic | B63: Techniques Documented
A64: Reconnaissance | B64: =COUNTIF(A$10:A$59,"Reconnaissance")
A65: Resource Development | B65: =COUNTIF(A$10:A$59,"Resource Development")
A66: Initial Access | B66: =COUNTIF(A$10:A$59,"Initial Access")
A67: Execution | B67: =COUNTIF(A$10:A$59,"Execution")
A68: Persistence | B68: =COUNTIF(A$10:A$59,"Persistence")
A69: Privilege Escalation | B69: =COUNTIF(A$10:A$59,"Privilege Escalation")
A70: Defense Evasion | B70: =COUNTIF(A$10:A$59,"Defense Evasion")
A71: Credential Access | B71: =COUNTIF(A$10:A$59,"Credential Access")
A72: Discovery | B72: =COUNTIF(A$10:A$59,"Discovery")
A73: Lateral Movement | B73: =COUNTIF(A$10:A$59,"Lateral Movement")
A74: Collection | B74: =COUNTIF(A$10:A$59,"Collection")
A75: Command and Control | B75: =COUNTIF(A$10:A$59,"Command and Control")
A76: Exfiltration | B76: =COUNTIF(A$10:A$59,"Exfiltration")
A77: Impact | B77: =COUNTIF(A$10:A$59,"Impact")
A79: OVERALL COVERAGE | B79: =SUM(B64:B77)
A82: MITRE ATT&CK COVERAGE CHECKLIST
A83: # | B83: Requirement
A84: 1 | B84: Detection rules mapped to MITRE ATT&CK framework
...

Sheet 4. Rule Performance
A1: 4. RULE PERFORMANCE & TUNING TRACKING
A2: Policy Reference: ISMS-POL-A.8.16-S2.2.4 - Rule performance monitoring and optimization
A3: Are detection rules monitored for performance and regularly tuned to maintain effectiveness?
A5: RULE PERFORMANCE METRICS (Last 30 Days)
A6: Rule ID/Name | B6: Total Triggers | C6: True Positives | D6: False Positives | E6: False Negatives | F6: Precision % | G6: Recall % | H6: F1 Score | I6: MTTD (minutes) | J6: Tuning Actions | K6: Last Tuned | L6: Tuning Status | M6: Performance Trend | N6: Owner | O6: Issues | P6: Priority
A7: RULE-105 | B7: 12 | C7: 10 | D7: 2 | E7: 1 | F7: 83% | G7: 91% | H7: 0.87 | I7: 8 | J7: Adjusted threshold | K7: 15.12.2024 | L7: Optimized | M7: Improving | N7: SOC Team | O7: None | P7: Medium
F8: =IF(AND(C8<>"",D8<>""),ROUND(C8/(C8+D8)*100,1)&"%","") | G8: =IF(AND(C8<>"",E8<>""),ROUND(C8/(C8+E8)*100,1)&"%","") | H8: =IF(AND(F8<>"",G8<>""),ROUND(2*(VALUE(LEFT(F8,LEN(F8)-1))/100)*(VALUE(LEFT(G8,LEN(G8)-1))/100)/((VALUE(LEFT(F8,LEN(F8)-1))/100)+(VALUE(LEFT(G8,LEN(G8)-1))/100)),2),"")
F9: =IF(AND(C9<>"",D9<>""),ROUND(C9/(C9+D9)*100,1)&"%","") | G9: =IF(AND(C9<>"",E9<>""),ROUND(C9/(C9+E9)*100,1)&"%","") | H9: =IF(AND(F9<>"",G9<>""),ROUND(2*(VALUE(LEFT(F9,LEN(F9)-1))/100)*(VALUE(LEFT(G9,LEN(G9)-1))/100)/((VALUE(LEFT(F9,LEN(F9)-1))/100)+(VALUE(LEFT(G9,LEN(G9)-1))/100)),2),"")
F10: =IF(AND(C10<>"",D10<>""),ROUND(C10/(C10+D10)*100,1)&"%","") | G10: =IF(AND(C10<>"",E10<>""),ROUND(C10/(C10+E10)*100,1)&"%","") | H10: =IF(AND(F10<>"",G10<>""),ROUND(2*(VALUE(LEFT(F10,LEN(F10)-1))/100)*(VALUE(LEFT(G10,LEN(G10)-1))/100)/((VALUE(LEFT(F10,LEN(F10)-1))/100)+(VALUE(LEFT(G10,LEN(G10)-1))/100)),2),"")
F11: =IF(AND(C11<>"",D11<>""),ROUND(C11/(C11+D11)*100,1)&"%","") | G11: =IF(AND(C11<>"",E11<>""),ROUND(C11/(C11+E11)*100,1)&"%","") | H11: =IF(AND(F11<>"",G11<>""),ROUND(2*(VALUE(LEFT(F11,LEN(F11)-1))/100)*(VALUE(LEFT(G11,LEN(G11)-1))/100)/((VALUE(LEFT(F11,LEN(F11)-1))/100)+(VALUE(LEFT(G11,LEN(G11)-1))/100)),2),"")
F12: =IF(AND(C12<>"",D12<>""),ROUND(C12/(C12+D12)*100,1)&"%","") | G12: =IF(AND(C12<>"",E12<>""),ROUND(C12/(C12+E12)*100,1)&"%","") | H12: =IF(AND(F12<>"",G12<>""),ROUND(2*(VALUE(LEFT(F12,LEN(F12)-1))/100)*(VALUE(LEFT(G12,LEN(G12)-1))/100)/((VALUE(LEFT(F12,LEN(F12)-1))/100)+(VALUE(LEFT(G12,LEN(G12)-1))/100)),2),"")
F13: =IF(AND(C13<>"",D13<>""),ROUND(C13/(C13+D13)*100,1)&"%","") | G13: =IF(AND(C13<>"",E13<>""),ROUND(C13/(C13+E13)*100,1)&"%","") | H13: =IF(AND(F13<>"",G13<>""),ROUND(2*(VALUE(LEFT(F13,LEN(F13)-1))/100)*(VALUE(LEFT(G13,LEN(G13)-1))/100)/((VALUE(LEFT(F13,LEN(F13)-1))/100)+(VALUE(LEFT(G13,LEN(G13)-1))/100)),2),"")
F14: =IF(AND(C14<>"",D14<>""),ROUND(C14/(C14+D14)*100,1)&"%","") | G14: =IF(AND(C14<>"",E14<>""),ROUND(C14/(C14+E14)*100,1)&"%","") | H14: =IF(AND(F14<>"",G14<>""),ROUND(2*(VALUE(LEFT(F14,LEN(F14)-1))/100)*(VALUE(LEFT(G14,LEN(G14)-1))/100)/((VALUE(LEFT(F14,LEN(F14)-1))/100)+(VALUE(LEFT(G14,LEN(G14)-1))/100)),2),"")
F15: =IF(AND(C15<>"",D15<>""),ROUND(C15/(C15+D15)*100,1)&"%","") | G15: =IF(AND(C15<>"",E15<>""),ROUND(C15/(C15+E15)*100,1)&"%","") | H15: =IF(AND(F15<>"",G15<>""),ROUND(2*(VALUE(LEFT(F15,LEN(F15)-1))/100)*(VALUE(LEFT(G15,LEN(G15)-1))/100)/((VALUE(LEFT(F15,LEN(F15)-1))/100)+(VALUE(LEFT(G15,LEN(G15)-1))/100)),2),"")
F16: =IF(AND(C16<>"",D16<>""),ROUND(C16/(C16+D16)*100,1)&"%","") | G16: =IF(AND(C16<>"",E16<>""),ROUND(C16/(C16+E16)*100,1)&"%","") | H16: =IF(AND(F16<>"",G16<>""),ROUND(2*(VALUE(LEFT(F16,LEN(F16)-1))/100)*(VALUE(LEFT(G16,LEN(G16)-1))/100)/((VALUE(LEFT(F16,LEN(F16)-1))/100)+(VALUE(LEFT(G16,LEN(G16)-1))/100)),2),"")
F17: =IF(AND(C17<>"",D17<>""),ROUND(C17/(C17+D17)*100,1)&"%","") | G17: =IF(AND(C17<>"",E17<>""),ROUND(C17/(C17+E17)*100,1)&"%","") | H17: =IF(AND(F17<>"",G17<>""),ROUND(2*(VALUE(LEFT(F17,LEN(F17)-1))/100)*(VALUE(LEFT(G17,LEN(G17)-1))/100)/((VALUE(LEFT(F17,LEN(F17)-1))/100)+(VALUE(LEFT(G17,LEN(G17)-1))/100)),2),"")
F18: =IF(AND(C18<>"",D18<>""),ROUND(C18/(C18+D18)*100,1)&"%","") | G18: =IF(AND(C18<>"",E18<>""),ROUND(C18/(C18+E18)*100,1)&"%","") | H18: =IF(AND(F18<>"",G18<>""),ROUND(2*(VALUE(LEFT(F18,LEN(F18)-1))/100)*(VALUE(LEFT(G18,LEN(G18)-1))/100)/((VALUE(LEFT(F18,LEN(F18)-1))/100)+(VALUE(LEFT(G18,LEN(G18)-1))/100)),2),"")
F19: =IF(AND(C19<>"",D19<>""),ROUND(C19/(C19+D19)*100,1)&"%","") | G19: =IF(AND(C19<>"",E19<>""),ROUND(C19/(C19+E19)*100,1)&"%","") | H19: =IF(AND(F19<>"",G19<>""),ROUND(2*(VALUE(LEFT(F19,LEN(F19)-1))/100)*(VALUE(LEFT(G19,LEN(G19)-1))/100)/((VALUE(LEFT(F19,LEN(F19)-1))/100)+(VALUE(LEFT(G19,LEN(G19)-1))/100)),2),"")
... F37: =IF(AND(C37<>"",D37<>""),ROUND(C37/(C37+D37)*100,1)&"%","") | G37: =IF(AND(C37<>"",E37<>""),ROUND(C37/(C37+E37)*100,1)&"%","") | H37: =IF(AND(F37<>"",G37<>""),ROUND(2*(VALUE(LEFT(F37,LEN(F37)-1))/100)*(VALUE(LEFT(G37,LEN(G37)-1))/100)/((VALUE(LEFT(F37,LEN(F37)-1))/100)+(VALUE(LEFT(G37,LEN(G37)-1))/100)),2),"")
A40: PERFORMANCE STATISTICS
A41: Metric
A42: Average Precision across all rules
A43: Average Recall across all rules
A44: Average F1 Score
A45: Rules with Precision <70%
A46: Rules with high FP rate (>30%)
A47: Rules requiring tuning
A48: Rules tuned in last 30 days
A49: Average MTTD (minutes)
A52: RECENT TUNING ACTIONS LOG
A53: Date | B53: Rule ID | C53: Action Taken | D53: Reason | E53: Before Precision | F53: After Precision | G53: Performed By
A66: RULE PERFORMANCE & TUNING CHECKLIST
A67: # | B67: Requirement
A68: 1 | B68: Rule performance metrics collected (TP, FP, FN)
A69: 2 | B69: Precision calculated for all active rules
A70: 3 | B70: Recall calculated for all active rules
A71: 4 | B71: F1 Score tracked to balance precision and recall
A72: 5 | B72: MTTD tracked for critical/high severity rules
A73: 6 | B73: Rules with precision <70% identified for tuning
A74: 7 | B74: False positive rate acceptable (<30%)
...

Sheet 5. Testing Validation
A1: 5. DETECTION TESTING & VALIDATION
A2: Policy Reference: ISMS-POL-A.8.16-S2.2.5 - Detection rule testing and validation
A3: Are detection rules tested and validated to ensure they detect intended threats?
A6: Test ID | B6: Rule ID/Name | C6: Test Date | D6: Test Type | E6: Test Scenario | F6: Expected Result | G6: Actual Result | H6: Test Result | I6: Detection Time | J6: Issues Identified | K6: Remediation Action | L6: Retested | M6: Tested By | N6: Notes
A7: TEST-001 | B7: RULE-105 | C7: 20.12.2024 | D7: Attack Simulation | E7: Kerberos Golden Ticket attack | F7: Alert triggered within 5 min | G7: Alert triggered in 3 min | H7: Pass | I7: 3 min | J7: None | K7: N/A | L7: Yes | M7: SOC Team | N7: Working as expected
A8: ="TEST-"&TEXT(ROW()-7,"000")
A9: ="TEST-"&TEXT(ROW()-7,"000")
A10: ="TEST-"&TEXT(ROW()-7,"000")
A11: ="TEST-"&TEXT(ROW()-7,"000")
A12: ="TEST-"&TEXT(ROW()-7,"000")
A13: ="TEST-"&TEXT(ROW()-7,"000")
A14: ="TEST-"&TEXT(ROW()-7,"000")
A15: ="TEST-"&TEXT(ROW()-7,"000")
A16: ="TEST-"&TEXT(ROW()-7,"000")
A17: ="TEST-"&TEXT(ROW()-7,"000")
A18: ="TEST-"&TEXT(ROW()-7,"000")
A19: ="TEST-"&TEXT(ROW()-7,"000")
... A37: ="TEST-"&TEXT(ROW()-7,"000")
A40: TESTING STATISTICS
A41: Metric
A42: Total Tests Performed
A43: Tests Passed
A44: Tests Failed
A45: Tests Partial
A46: Pass Rate %
A47: Average Detection Time
A48: Tests Requiring Retest
A49: Rules Not Tested (90+ days)
A52: TESTING & VALIDATION CHECKLIST
A53: # | B53: Requirement
A54: 1 | B54: All critical/high severity rules tested before production
A55: 2 | B55: Testing performed using realistic attack scenarios
A56: 3 | B56: Attack simulations (Purple Team exercises) conducted
A57: 4 | B57: Detection time measured and within acceptable range
A58: 5 | B58: Unit tests performed for individual rule logic
A59: 6 | B59: Integration tests performed for multi-event correlation
A60: 7 | B60: Regression testing after rule modifications
A61: 8 | B61: Test results documented with evidence
A62: 9 | B62: Failed tests result in rule improvement
A63: 10 | B63: Rules tested quarterly minimum
...

Sheet Summary Dashboard
A1: BASELINE & DETECTION - SUMMARY DASHBOARD
A2: Consolidated Assessment Overview - ISMS-IMP-A.8.16.2
A4: OVERALL ASSESSMENT STATUS
A6: Assessment Area | B6: Compliant | C6: Partial | D6: Non-Compliant | E6: N/A | F6: Total Items | G6: Compliance % | H6: Status
A7: 1. Baseline Inventory & Maintenance | B7: =COUNTIF('1. Baseline Inventory'!Q54:Q68,"✅ Compliant") | C7: =COUNTIF('1. Baseline Inventory'!Q54:Q68,"⚠️ Partial") | D7: =COUNTIF('1. Baseline Inventory'!Q54:Q68,"❌ Non-Compliant") | E7: =COUNTIF('1. Baseline Inventory'!Q54:Q68,"N/A") | F7: 15 | G7: =IF(F7>0,ROUND(B7/(F7-E7)*100,1)&"%","N/A") | H7: =IF(G7="N/A","N/A",IF(VALUE(LEFT(G7,LEN(G7)-1))>=80,"✅ Good",IF(VALUE(LEFT(G7,LEN(G7)-1))>=60,"⚠️ Needs Work","❌ Critical")))
A8: 2. Detection Rules Inventory | B8: =COUNTIF('2. Detection Rules'!U74:U88,"✅ Compliant") | C8: =COUNTIF('2. Detection Rules'!U74:U88,"⚠️ Partial") | D8: =COUNTIF('2. Detection Rules'!U74:U88,"❌ Non-Compliant") | E8: =COUNTIF('2. Detection Rules'!U74:U88,"N/A") | F8: 15 | G8: =IF(F8>0,ROUND(B8/(F8-E8)*100,1)&"%","N/A") | H8: =IF(G8="N/A","N/A",IF(VALUE(LEFT(G8,LEN(G8)-1))>=80,"✅ Good",IF(VALUE(LEFT(G8,LEN(G8)-1))>=60,"⚠️ Needs Work","❌ Critical")))
A9: 3. MITRE ATT&CK Coverage | B9: =COUNTIF('3. MITRE ATT&CK Coverage'!N84:N98,"✅ Compliant") | C9: =COUNTIF('3. MITRE ATT&CK Coverage'!N84:N98,"⚠️ Partial") | D9: =COUNTIF('3. MITRE ATT&CK Coverage'!N84:N98,"❌ Non-Compliant") | E9: =COUNTIF('3. MITRE ATT&CK Coverage'!N84:N98,"N/A") | F9: 15 | G9: =IF(F9>0,ROUND(B9/(F9-E9)*100,1)&"%","N/A") | H9: =IF(G9="N/A","N/A",IF(VALUE(LEFT(G9,LEN(G9)-1))>=80,"✅ Good",IF(VALUE(LEFT(G9,LEN(G9)-1))>=60,"⚠️ Needs Work","❌ Critical")))
A10: 4. Rule Performance & Tuning | B10: =COUNTIF('4. Rule Performance'!P68:P82,"✅ Compliant") | C10: =COUNTIF('4. Rule Performance'!P68:P82,"⚠️ Partial") | D10: =COUNTIF('4. Rule Performance'!P68:P82,"❌ Non-Compliant") | E10: =COUNTIF('4. Rule Performance'!P68:P82,"N/A") | F10: 15 | G10: =IF(F10>0,ROUND(B10/(F10-E10)*100,1)&"%","N/A") | H10: =IF(G10="N/A","N/A",IF(VALUE(LEFT(G10,LEN(G10)-1))>=80,"✅ Good",IF(VALUE(LEFT(G10,LEN(G10)-1))>=60,"⚠️ Needs Work","❌ Critical")))
A11: 5. Testing & Validation | B11: =COUNTIF('5. Testing Validation'!N54:N68,"✅ Compliant") | C11: =COUNTIF('5. Testing Validation'!N54:N68,"⚠️ Partial") | D11: =COUNTIF('5. Testing Validation'!N54:N68,"❌ Non-Compliant") | E11: =COUNTIF('5. Testing Validation'!N54:N68,"N/A") | F11: 15 | G11: =IF(F11>0,ROUND(B11/(F11-E11)*100,1)&"%","N/A") | H11: =IF(G11="N/A","N/A",IF(VALUE(LEFT(G11,LEN(G11)-1))>=80,"✅ Good",IF(VALUE(LEFT(G11,LEN(G11)-1))>=60,"⚠️ Needs Work","❌ Critical")))
A13: OVERALL TOTAL | B13: =SUM(B7:B11) | C13: =SUM(C7:C11) | D13: =SUM(D7:D11) | E13: =SUM(E7:E11) | F13: =SUM(F7:F11) | G13: =IF(F13>0,ROUND(B13/(F13-E13)*100,1)&"%","N/A") | H13: =IF(G13="N/A","N/A",IF(VALUE(LEFT(G13,LEN(G13)-1))>=80,"✅ Good",IF(VALUE(LEFT(G13,LEN(G13)-1))>=60,"⚠️ Needs Work","❌ Critical")))
A16: KEY METRICS SUMMARY
A17: Metric
A18: Total Baselines Established
A19: Stale Baselines (>90 days)
A20: Total Active Detection Rules
A21: Rules Requiring Tuning
A22: MITRE ATT&CK Coverage %
A23: Average Rule Precision %
A24: Test Pass Rate %

Sheet Evidence Register

Sheet Approval Sign-Off
