Workbook

Sheet Instructions & Legend
A1: MONITORING COVERAGE ASSESSMENT
A2: ISO/IEC 27001:2022 - Control A.8.16: Monitoring Activities
A4: DOCUMENT INFORMATION
A5: Document ID: | B5: ISMS-IMP-A.8.16.3
A6: Assessment Area: | B6: Monitoring Coverage
A7: Related Policy: | B7: ISMS-POL-A.8.16-S2.1.1, S2.1.2
A8: Version: | B8: 1.0
A9: Assessment Date: | B9: [USER INPUT - DD.MM.YYYY]
A10: Completed By: | B10: [USER INPUT]
A11: Organization: | B11: [USER INPUT]
A12: Review Cycle: | B12: Quarterly
A13: Next Review Date: | B13: =IF(B8<>"","=B8+90","")
A16: HOW TO USE THIS WORKBOOK
A17: 1. Complete comprehensive asset inventory (Sheet 1)
A18: 2. Document all network segments and coverage (Sheet 2)
A19: 3. Assess user and identity system monitoring (Sheet 3)
A20: 4. Inventory application monitoring coverage (Sheet 4)
A21: 5. Identify and document all coverage gaps (Sheet 5)
A22: 6. Review Summary Dashboard for overall coverage status
A23: 7. Prioritize gaps by criticality and regulatory requirements
A24: 8. Document evidence in Evidence Register
A25: 9. Obtain approvals via Approval Sign-Off sheet
A28: KEY PRINCIPLE: You Can't Protect What You Can't See

Sheet 1. Asset Coverage
A1: 1. ASSET INVENTORY & MONITORING COVERAGE
A2: Policy Reference: ISMS-POL-A.8.16-S2.1.1 - Assess asset coverage
A3: Are all organizational assets inventoried and appropriate assets monitored?
A6: Asset ID | B6: Asset Name | C6: Asset Type | D6: Operating System | E6: Location | F6: Business Unit | G6: Asset Owner | H6: Data Classification | I6: Criticality | J6: Regulatory Scope | K6: Monitoring Required | L6: Currently Monitored | M6: Log Types Collected | N6: Monitoring Platform | O6: Baseline Established | P6: Detection Rules Active | Q6: Last Log Verified | R6: Coverage Status | S6: Gap Reason | T6: Exception Approved | U6: Target Coverage Date | V6: Responsible Party | W6: Notes
A7: SRV-001 | B7: DC01-Primary | C7: Server | D7: Windows Server 2022 | E7: DataCenter-1 | F7: IT Operations | G7: J. Smith | H7: Confidential | I7: Critical | J7: Multiple | K7: Mandatory | L7: Yes | M7: Security, System, Application | N7: Splunk | O7: Yes | P7: 15 | Q7: 05.01.2025 | R7: ✅ Full Coverage | S7: None | T7: N/A | U7: N/A | V7: SOC Team | W7: Production DC
A53: ASSET COVERAGE COMPLIANCE CHECKLIST
A54: # | B54: Requirement
A55: 1 | B55: Complete asset inventory maintained
A56: 2 | B56: Asset inventory updated at least quarterly
A57: 3 | B57: All assets classified by criticality
A58: 4 | B58: All Critical assets monitored (100%)
A59: 5 | B59: >80% of High priority assets monitored
A60: 6 | B60: >60% of Medium priority assets monitored
A61: 7 | B61: All PCI-DSS scope systems monitored
A62: 8 | B62: All HIPAA scope systems monitored
A63: 9 | B63: All systems handling confidential data monitored
A64: 10 | B64: Monitoring coverage gaps documented
A65: 11 | B65: Exceptions formally approved
A66: 12 | B66: Gap remediation plans exist
... A69: 15 | B69: New assets onboarded to monitoring within 30 days
A70: SCORE: | B70: =COUNTIF(W55:W69,"✅ Compliant")&" / 15"

Sheet 2. Network Coverage
A1: 2. NETWORK SEGMENT COVERAGE ASSESSMENT
A2: Policy Reference: ISMS-POL-A.8.16-S2.1.1 - Assess network coverage
A6: Network Segment/Zone | B6: Segment Type | C6: IP Range/CIDR | D6: VLAN ID | E6: Number of Assets | F6: Criticality | G6: Data Classification | H6: Perimeter Monitoring | I6: Flow Monitoring | J6: DNS Monitoring | K6: Endpoint Monitoring | L6: Log Collection Active | M6: Network Tap/SPAN | N6: Isolation Status | O6: Coverage Status | P6: Gaps Identified | Q6: Exception Approved | R6: Target Date | S6: Responsible Party | T6: Notes
A35: NETWORK COVERAGE CHECKLIST
A36: # | B36: Requirement
A37: 1 | B37: All network segments inventoried
A38: 2 | B38: All production segments monitored
A39: 3 | B39: All DMZ segments monitored
A40: 4 | B40: Critical segments have redundant monitoring
A41: 5 | B41: Perimeter traffic monitored (firewall + IDS/IPS)
A42: 6 | B42: Internal traffic monitored (flow data)
A43: 7 | B43: DNS queries monitored
A44: 8 | B44: Endpoints monitored (EDR/AV integration)
A45: 9 | B45: East-west traffic visibility (lateral movement detection)
A46: 10 | B46: Cloud network segments included
A47: SCORE: | B47: =COUNTIF(T37:T46,"✅ Compliant")&" / 10"

Sheet 3. User Identity Coverage
A1: 3. USER & IDENTITY MONITORING COVERAGE
A2: Policy Reference: ISMS-POL-A.8.16-S2.1.2 - Assess user monitoring
A6: Identity System | B6: System Type | C6: User Count | D6: Privileged Account Count | E6: Service Account Count | F6: Authentication Logs Collected | G6: Authorization Logs Collected | H6: Password Change Logs | I6: Privilege Escalation Logs | J6: MFA Events Logged | K6: SSO Events Logged | L6: Failed Login Monitoring | M6: After-Hours Access Monitoring | N6: Geographic Anomaly Detection | O6: User Behavior Analytics | P6: Privileged Access Monitoring | Q6: Coverage Status | R6: Gaps/Issues | S6: Priority
A25: USER & IDENTITY COVERAGE CHECKLIST
A26: # | B26: Requirement
A27: 1 | B27: Primary identity system (AD/Azure AD) monitored
A28: 2 | B28: All authentication events logged
A29: 3 | B29: Failed login attempts monitored and alerted
A30: 4 | B30: Privileged account usage monitored
A31: 5 | B31: Service account usage monitored
A32: 6 | B32: Password changes logged
A33: 7 | B33: Privilege escalation logged
A34: 8 | B34: MFA events logged (if MFA deployed)
A35: 9 | B35: SSO events logged (if SSO deployed)
A36: 10 | B36: After-hours access monitored
A37: 11 | B37: Geographic anomalies detected
A38: 12 | B38: User behavior baselines established
... A41: 15 | B41: Identity correlation across systems
A42: SCORE: | B42: =COUNTIF(S27:S41,"✅ Compliant")&" / 15"

Sheet 4. Application Coverage
A1: 4. APPLICATION & SERVICE MONITORING COVERAGE
A2: Policy Reference: ISMS-POL-A.8.16-S2.1.2 - Assess application coverage
A6: Application/Service Name | B6: Application Type | C6: Business Unit | D6: Application Owner | E6: Data Classification | F6: Criticality | G6: User Base | H6: Application Logs Collected | I6: API Logs Collected | J6: Database Logs Collected | K6: Error/Exception Logging | L6: Transaction Logging | M6: Access Control Logs | N6: Data Export Monitoring | O6: Performance Monitoring | P6: WAF Integration | Q6: APM Integration | R6: Coverage Status | S6: Gaps | T6: Target Date | U6: Priority
A7: Customer Portal | B7: Web Application | C7: Sales | D7: M. Johnson | E7: Confidential | F7: High | G7: 5000 users | H7: Yes | I7: Yes | J7: Yes | K7: Yes | L7: Yes | M7: Yes | N7: Yes | O7: Yes | P7: Yes | Q7: Yes | R7: ✅ Compliant | S7: None | T7: N/A | U7: High
A35: APPLICATION COVERAGE CHECKLIST
A36: # | B36: Requirement
A37: 1 | B37: All critical applications monitored
A38: 2 | B38: >80% of high-priority applications monitored
A39: 3 | B39: Application error/exception logs collected
A40: 4 | B40: API calls logged (if API-based)
A41: 5 | B41: Database queries logged (if database-backed)
A42: 6 | B42: User access logged
A43: 7 | B43: Data exports/downloads monitored
A44: 8 | B44: File uploads monitored
A45: 9 | B45: Configuration changes logged
A46: 10 | B46: WAF deployed for internet-facing apps
A47: 11 | B47: APM integrated for performance visibility
A48: 12 | B48: Cloud application logs collected (SaaS)
... A51: 15 | B51: Application security events forwarded to SIEM
A52: SCORE: | B52: =COUNTIF(U37:U51,"✅ Compliant")&" / 15"

Sheet 5. Gap Analysis
A1: 5. COVERAGE GAP ANALYSIS
A2: Policy Reference: ISMS-POL-A.8.16-S2.1 - Document and remediate coverage gaps
A3: Are all monitoring coverage gaps identified, documented, and tracked to remediation?
A6: Gap ID | B6: Gap Category | C6: Affected Asset/System | D6: Gap Description | E6: Business Impact | F6: Risk Level | G6: Root Cause | H6: Exception Approved | I6: Exception ID | J6: Compensating Controls | K6: Remediation Plan | L6: Remediation Owner | M6: Target Date | N6: Budget Required | O6: Status | P6: Status Date | Q6: Verification Method | R6: Notes
A7: GAP-001 | B7: Asset Not Monitored | C7: Legacy File Server | D7: No log collection configured | E7: Medium - non-critical legacy system | F7: Medium | G7: End-of-life system, no agent support | H7: Yes | I7: EXC-2024-015 | J7: Network-level monitoring via firewall | K7: Migrate to new storage platform | L7: Infrastructure Team | M7: 31.03.2025 | N7: Yes | O7: In Progress | P7: 15.12.2024 | Q7: Post-migration verification | R7: Budget approved Q1
A8: ="GAP-"&TEXT(ROW()-7,"000")
A9: ="GAP-"&TEXT(ROW()-7,"000")
A10: ="GAP-"&TEXT(ROW()-7,"000")
A11: ="GAP-"&TEXT(ROW()-7,"000")
A12: ="GAP-"&TEXT(ROW()-7,"000")
A13: ="GAP-"&TEXT(ROW()-7,"000")
A14: ="GAP-"&TEXT(ROW()-7,"000")
A15: ="GAP-"&TEXT(ROW()-7,"000")
A16: ="GAP-"&TEXT(ROW()-7,"000")
A17: ="GAP-"&TEXT(ROW()-7,"000")
A18: ="GAP-"&TEXT(ROW()-7,"000")
A19: ="GAP-"&TEXT(ROW()-7,"000")
... A47: ="GAP-"&TEXT(ROW()-7,"000")
A50: GAP SUMMARY STATISTICS
A51: Metric
A52: Total Gaps Identified
A53: Critical Gaps
A54: High Gaps
A55: Open Gaps
A56: In Progress
A57: Resolved Gaps
A58: Accepted Risks
A59: Overdue (Past Target Date)
A62: GAP MANAGEMENT CHECKLIST
A63: # | B63: Requirement
A64: 1 | B64: All coverage gaps identified
A65: 2 | B65: Gaps categorized by type
A66: 3 | B66: Risk level assessed for each gap
A67: 4 | B67: Root cause analysis conducted
A68: 5 | B68: Critical gaps remediated within 30 days
A69: 6 | B69: High gaps remediated within 90 days
A70: 7 | B70: Exceptions formally approved
A71: 8 | B71: Compensating controls documented
A72: 9 | B72: Remediation plans documented
A73: 10 | B73: Gap remediation tracked
...

Sheet Summary Dashboard
A1: MONITORING COVERAGE - SUMMARY DASHBOARD
A2: Consolidated Coverage Assessment - ISMS-IMP-A.8.16.3
A4: OVERALL COVERAGE SUMMARY
A5: Metric
A6: Total Assets in Inventory
A7: Assets Monitored
A8: % Asset Coverage
A9: Critical Assets - 100% Monitored
A10: High Assets - % Monitored
A11: Network Segments Monitored
A12: Identity Systems Monitored
A13: Applications Monitored
... A20: COMPLIANCE SUMMARY BY ASSESSMENT AREA
A21: Assessment Area | B21: Compliant | C21: Partial | D21: Non-Compliant | E21: N/A | F21: Total Items | G21: Compliance % | H21: Status
A22: 1. Asset Coverage | B22: =COUNTIF('1. Asset Coverage'!W55:W69,"✅ Compliant") | C22: =COUNTIF('1. Asset Coverage'!W55:W69,"⚠️ Partial") | D22: =COUNTIF('1. Asset Coverage'!W55:W69,"❌ Non-Compliant") | E22: =COUNTIF('1. Asset Coverage'!W55:W69,"N/A") | F22: 15 | G22: =IF(F22>0,ROUND(B22/(F22-E22)*100,1)&"%","N/A") | H22: =IF(G22="N/A","N/A",IF(VALUE(LEFT(G22,LEN(G22)-1))>=80,"✅ Good",IF(VALUE(LEFT(G22,LEN(G22)-1))>=60,"⚠️ Needs Work","❌ Critical")))
A23: 2. Network Coverage | B23: =COUNTIF('2. Network Coverage'!T37:T46,"✅ Compliant") | C23: =COUNTIF('2. Network Coverage'!T37:T46,"⚠️ Partial") | D23: =COUNTIF('2. Network Coverage'!T37:T46,"❌ Non-Compliant") | E23: =COUNTIF('2. Network Coverage'!T37:T46,"N/A") | F23: 10 | G23: =IF(F23>0,ROUND(B23/(F23-E23)*100,1)&"%","N/A") | H23: =IF(G23="N/A","N/A",IF(VALUE(LEFT(G23,LEN(G23)-1))>=80,"✅ Good",IF(VALUE(LEFT(G23,LEN(G23)-1))>=60,"⚠️ Needs Work","❌ Critical")))
A24: 3. User/Identity Coverage | B24: =COUNTIF('3. User Identity Coverage'!S27:S41,"✅ Compliant") | C24: =COUNTIF('3. User Identity Coverage'!S27:S41,"⚠️ Partial") | D24: =COUNTIF('3. User Identity Coverage'!S27:S41,"❌ Non-Compliant") | E24: =COUNTIF('3. User Identity Coverage'!S27:S41,"N/A") | F24: 15 | G24: =IF(F24>0,ROUND(B24/(F24-E24)*100,1)&"%","N/A") | H24: =IF(G24="N/A","N/A",IF(VALUE(LEFT(G24,LEN(G24)-1))>=80,"✅ Good",IF(VALUE(LEFT(G24,LEN(G24)-1))>=60,"⚠️ Needs Work","❌ Critical")))
A25: 4. Application Coverage | B25: =COUNTIF('4. Application Coverage'!U37:U51,"✅ Compliant") | C25: =COUNTIF('4. Application Coverage'!U37:U51,"⚠️ Partial") | D25: =COUNTIF('4. Application Coverage'!U37:U51,"❌ Non-Compliant") | E25: =COUNTIF('4. Application Coverage'!U37:U51,"N/A") | F25: 15 | G25: =IF(F25>0,ROUND(B25/(F25-E25)*100,1)&"%","N/A") | H25: =IF(G25="N/A","N/A",IF(VALUE(LEFT(G25,LEN(G25)-1))>=80,"✅ Good",IF(VALUE(LEFT(G25,LEN(G25)-1))>=60,"⚠️ Needs Work","❌ Critical")))
A26: 5. Gap Management | B26: =COUNTIF('5. Gap Analysis'!R64:R78,"✅ Compliant") | C26: =COUNTIF('5. Gap Analysis'!R64:R78,"⚠️ Partial") | D26: =COUNTIF('5. Gap Analysis'!R64:R78,"❌ Non-Compliant") | E26: =COUNTIF('5. Gap Analysis'!R64:R78,"N/A") | F26: 15 | G26: =IF(F26>0,ROUND(B26/(F26-E26)*100,1)&"%","N/A") | H26: =IF(G26="N/A","N/A",IF(VALUE(LEFT(G26,LEN(G26)-1))>=80,"✅ Good",IF(VALUE(LEFT(G26,LEN(G26)-1))>=60,"⚠️ Needs Work","❌ Critical")))
A28: OVERALL TOTAL | B28: =SUM(B22:B26) | C28: =SUM(C22:C26) | D28: =SUM(D22:D26) | E28: =SUM(E22:E26) | F28: =SUM(F22:F26) | G28: =IF(F28>0,ROUND(B28/(F28-E28)*100,1)&"%","N/A") | H28: =IF(G28="N/A","N/A",IF(VALUE(LEFT(G28,LEN(G28)-1))>=80,"✅ Good",IF(VALUE(LEFT(G28,LEN(G28)-1))>=60,"⚠️ Needs Work","❌ Critical")))

Sheet Evidence Register

Sheet Approval Sign-Off
