Workbook

Sheet Executive Dashboard
A1: ISMS-IMP-A.8.28.5 – Secure Coding Compliance Summary Dashboard ISO/IEC 27001:2022 - Control A.8.28: Secure Coding - Executive Overview
A3: Document Information
A4: Document ID | B4: ISMS-IMP-A.8.28.5
A5: Report Type | B5: Compliance Summary Dashboard
A6: Related Policy | B6: ISMS-POL-A.8.28 (Secure Coding)
A7: Version | B7: 1.0
A8: Report Date
A9: Reporting Period
A10: Prepared By
A11: Organisation
A12: Review Cycle | B12: Quarterly
A13: Last Updated | B13: =TODAY()
A16: OVERALL CRYPTOGRAPHY COMPLIANCE STATUS
A17: Metric | B17: Score | C17: Target | D17: Status
A18: Overall Compliance Rate | B18: =AVERAGE(C25:C28) | C18: ≥95%
A19: Critical Gaps | B19: =COUNTIFS('Gap Analysis'!I8:I207,"Critical",'Gap Analysis'!R8:R207,"<>Closed") | C19: 0
A20: High-Risk Items | B20: =COUNTIFS('Risk Register'!N20:N119,">=15",'Risk Register'!Q20:Q119,"<>Closed") | C20: ≤5
A21: Remediation Progress | B21: =COUNTIF('Remediation Roadmap'!H37:H236,"Completed")/COUNTA('Remediation Roadmap'!H37:H236)*100&"%" | C21: ≥80%
A24: COMPLIANCE BY ASSESSMENT AREA
A25: Assessment Area | B25: Source Document | C25: Overall Compliance % | D25: Total Items | E25: Compliant | F25: Partial | G25: Non-Compliant | H25: Trend
A26: SDLC Assessment | B26: ISMS-IMP-A.8.28.1.xlsx | C26: =[ISMS-IMP-A.8.28.1.xlsx]'Summary Dashboard'!G8 | D26: =[ISMS-IMP-A.8.28.1.xlsx]'Summary Dashboard'!B8 | E26: =[ISMS-IMP-A.8.28.1.xlsx]'Summary Dashboard'!C8 | F26: =[ISMS-IMP-A.8.28.1.xlsx]'Summary Dashboard'!D8 | G26: =[ISMS-IMP-A.8.28.1.xlsx]'Summary Dashboard'!E8
A27: Standards & Tools Assessment | B27: ISMS-IMP-A.8.28.2.xlsx | C27: =[ISMS-IMP-A.8.28.2.xlsx]'Summary Dashboard'!G8 | D27: =[ISMS-IMP-A.8.28.2.xlsx]'Summary Dashboard'!B8 | E27: =[ISMS-IMP-A.8.28.2.xlsx]'Summary Dashboard'!C8 | F27: =[ISMS-IMP-A.8.28.2.xlsx]'Summary Dashboard'!D8 | G27: =[ISMS-IMP-A.8.28.2.xlsx]'Summary Dashboard'!E8
A28: Code Review & Testing Assessment | B28: ISMS-IMP-A.8.28.3.xlsx | C28: =[ISMS-IMP-A.8.28.3.xlsx]'Summary Dashboard'!G8 | D28: =[ISMS-IMP-A.8.28.3.xlsx]'Summary Dashboard'!B8 | E28: =[ISMS-IMP-A.8.28.3.xlsx]'Summary Dashboard'!C8 | F28: =[ISMS-IMP-A.8.28.3.xlsx]'Summary Dashboard'!D8 | G28: =[ISMS-IMP-A.8.28.3.xlsx]'Summary Dashboard'!E8
A29: Third-Party & OSS Assessment | B29: ISMS-IMP-A.8.28.4.xlsx | C29: =[ISMS-IMP-A.8.28.4.xlsx]'Summary Dashboard'!G8 | D29: =[ISMS-IMP-A.8.28.4.xlsx]'Summary Dashboard'!B8 | E29: =[ISMS-IMP-A.8.28.4.xlsx]'Summary Dashboard'!C8 | F29: =[ISMS-IMP-A.8.28.4.xlsx]'Summary Dashboard'!D8 | G29: =[ISMS-IMP-A.8.28.4.xlsx]'Summary Dashboard'!E8
A30: TOTAL | B30: (Aggregated) | C30: =AVERAGE(C26:C29) | D30: =SUM(D26:D29) | E30: =SUM(E26:E29) | F30: =SUM(F26:F29) | G30: =SUM(G26:G29)
A33: KEY PERFORMANCE INDICATORS (KPIs)
A34: KPI | B34: Current Value | C34: Target | D34: Status | E34: Last Quarter | F34: Change
A35: Cryptographic Controls Implemented | C35: [Target]
A36: Systems with Encryption at Rest | C36: 100%
A37: Systems with Encryption in Transit | C37: 100%
A38: MFA Coverage (All Users) | C38: 100%
A39: MFA Coverage (Admins) | C39: 100%
A40: Certificate Expiry Compliance | C40: 100%
A41: Key Rotation Compliance | C41: ≥95%
A42: Password Hashing Compliance | C42: 100%
A43: SSO Coverage | C43: ≥80%
A44: Open Critical Gaps | B44: =COUNTIFS('Gap Analysis'!I8:I207,"Critical",'Gap Analysis'!R8:R207,"<>Closed") | C44: 0
A47: TOP 5 CRITICAL SECURITY GAPS
A48: Rank | B48: Issue Description | C48: Assessment Area | D48: Risk Level | E48: Systems Affected | F48: Target Date | G48: Owner | H48: Status
A49: 1
...

Sheet Gap Analysis
A1: COMPREHENSIVE GAP ANALYSIS - CRYPTOGRAPHIC CONTROLS Consolidated view of all compliance gaps across assessment areas
A3: Gap Summary Statistics
A4: Assessment Area | B4: Total Gaps | C4: Critical | D4: High | E4: Medium | F4: Low | G4: Compliance % | H4: Risk Score
A5: Data Transmission | B5: =COUNTIF(B12:B211,"Data Transmission") | C5: =COUNTIFS(B12:B211,"Data Transmission",I12:I211,"Critical") | D5: =COUNTIFS(B12:B211,"Data Transmission",I12:I211,"High") | E5: =COUNTIFS(B12:B211,"Data Transmission",I12:I211,"Medium") | F5: =COUNTIFS(B12:B211,"Data Transmission",I12:I211,"Low") | H5: =IF(B5=0,0,(C5*10+D5*7+E5*4+F5*1)/B5)
A6: Data Storage | B6: =COUNTIF(B12:B211,"Data Storage") | C6: =COUNTIFS(B12:B211,"Data Storage",I12:I211,"Critical") | D6: =COUNTIFS(B12:B211,"Data Storage",I12:I211,"High") | E6: =COUNTIFS(B12:B211,"Data Storage",I12:I211,"Medium") | F6: =COUNTIFS(B12:B211,"Data Storage",I12:I211,"Low") | H6: =IF(B6=0,0,(C6*10+D6*7+E6*4+F6*1)/B6)
A7: Authentication | B7: =COUNTIF(B12:B211,"Authentication") | C7: =COUNTIFS(B12:B211,"Authentication",I12:I211,"Critical") | D7: =COUNTIFS(B12:B211,"Authentication",I12:I211,"High") | E7: =COUNTIFS(B12:B211,"Authentication",I12:I211,"Medium") | F7: =COUNTIFS(B12:B211,"Authentication",I12:I211,"Low") | H7: =IF(B7=0,0,(C7*10+D7*7+E7*4+F7*1)/B7)
A8: Key Management | B8: =COUNTIF(B12:B211,"Key Management") | C8: =COUNTIFS(B12:B211,"Key Management",I12:I211,"Critical") | D8: =COUNTIFS(B12:B211,"Key Management",I12:I211,"High") | E8: =COUNTIFS(B12:B211,"Key Management",I12:I211,"Medium") | F8: =COUNTIFS(B12:B211,"Key Management",I12:I211,"Low") | H8: =IF(B8=0,0,(C8*10+D8*7+E8*4+F8*1)/B8)
A9: TOTAL | B9: =SUM(B5:B8) | C9: =SUM(C5:C8) | D9: =SUM(D5:D8) | E9: =SUM(E5:E8) | F9: =SUM(F5:F8) | G9: =SUM(G5:G8) | H9: =AVERAGE(H5:H8)
A12: DETAILED GAP REGISTER
A13: Gap ID | B13: Assessment Area | C13: Source Document | D13: System/Application | E13: Gap Description | F13: Policy Reference | G13: Current State | H13: Required State | I13: Risk Level | J13: Impact | K13: Likelihood | L13: Risk Score | M13: Data Classification | N13: Systems Affected | O13: Users Impacted | P13: Business Impact | Q13: Compensating Controls | R13: Status | S13: Exception ID | T13: Risk ID
A14: GAP-001 | L14: =IF(OR(ISBLANK(J14),ISBLANK(K14)),"",IF(AND(J14="Critical",K14="Very High"),25,IF(AND(J14="Critical",K14="High"),20,IF(AND(J14="High",K14="Very High"),20,IF(AND(J14="High",K14="High"),16,IF(AND(J14="Critical",K14="Medium"),15,IF(AND(J14="Medium",K14="High"),12,IF(AND(J14="High",K14="Medium"),12,10))))))))
A15: GAP-002 | L15: =IF(OR(ISBLANK(J15),ISBLANK(K15)),"",IF(AND(J15="Critical",K15="Very High"),25,IF(AND(J15="Critical",K15="High"),20,IF(AND(J15="High",K15="Very High"),20,IF(AND(J15="High",K15="High"),16,IF(AND(J15="Critical",K15="Medium"),15,IF(AND(J15="Medium",K15="High"),12,IF(AND(J15="High",K15="Medium"),12,10))))))))
A16: GAP-003 | L16: =IF(OR(ISBLANK(J16),ISBLANK(K16)),"",IF(AND(J16="Critical",K16="Very High"),25,IF(AND(J16="Critical",K16="High"),20,IF(AND(J16="High",K16="Very High"),20,IF(AND(J16="High",K16="High"),16,IF(AND(J16="Critical",K16="Medium"),15,IF(AND(J16="Medium",K16="High"),12,IF(AND(J16="High",K16="Medium"),12,10))))))))
A17: GAP-004 | L17: =IF(OR(ISBLANK(J17),ISBLANK(K17)),"",IF(AND(J17="Critical",K17="Very High"),25,IF(AND(J17="Critical",K17="High"),20,IF(AND(J17="High",K17="Very High"),20,IF(AND(J17="High",K17="High"),16,IF(AND(J17="Critical",K17="Medium"),15,IF(AND(J17="Medium",K17="High"),12,IF(AND(J17="High",K17="Medium"),12,10))))))))
A18: GAP-005 | L18: =IF(OR(ISBLANK(J18),ISBLANK(K18)),"",IF(AND(J18="Critical",K18="Very High"),25,IF(AND(J18="Critical",K18="High"),20,IF(AND(J18="High",K18="Very High"),20,IF(AND(J18="High",K18="High"),16,IF(AND(J18="Critical",K18="Medium"),15,IF(AND(J18="Medium",K18="High"),12,IF(AND(J18="High",K18="Medium"),12,10))))))))
A19: GAP-006 | L19: =IF(OR(ISBLANK(J19),ISBLANK(K19)),"",IF(AND(J19="Critical",K19="Very High"),25,IF(AND(J19="Critical",K19="High"),20,IF(AND(J19="High",K19="Very High"),20,IF(AND(J19="High",K19="High"),16,IF(AND(J19="Critical",K19="Medium"),15,IF(AND(J19="Medium",K19="High"),12,IF(AND(J19="High",K19="Medium"),12,10))))))))
A20: GAP-007 | L20: =IF(OR(ISBLANK(J20),ISBLANK(K20)),"",IF(AND(J20="Critical",K20="Very High"),25,IF(AND(J20="Critical",K20="High"),20,IF(AND(J20="High",K20="Very High"),20,IF(AND(J20="High",K20="High"),16,IF(AND(J20="Critical",K20="Medium"),15,IF(AND(J20="Medium",K20="High"),12,IF(AND(J20="High",K20="Medium"),12,10))))))))
A21: GAP-008 | L21: =IF(OR(ISBLANK(J21),ISBLANK(K21)),"",IF(AND(J21="Critical",K21="Very High"),25,IF(AND(J21="Critical",K21="High"),20,IF(AND(J21="High",K21="Very High"),20,IF(AND(J21="High",K21="High"),16,IF(AND(J21="Critical",K21="Medium"),15,IF(AND(J21="Medium",K21="High"),12,IF(AND(J21="High",K21="Medium"),12,10))))))))
A22: GAP-009 | L22: =IF(OR(ISBLANK(J22),ISBLANK(K22)),"",IF(AND(J22="Critical",K22="Very High"),25,IF(AND(J22="Critical",K22="High"),20,IF(AND(J22="High",K22="Very High"),20,IF(AND(J22="High",K22="High"),16,IF(AND(J22="Critical",K22="Medium"),15,IF(AND(J22="Medium",K22="High"),12,IF(AND(J22="High",K22="Medium"),12,10))))))))
A23: GAP-010 | L23: =IF(OR(ISBLANK(J23),ISBLANK(K23)),"",IF(AND(J23="Critical",K23="Very High"),25,IF(AND(J23="Critical",K23="High"),20,IF(AND(J23="High",K23="Very High"),20,IF(AND(J23="High",K23="High"),16,IF(AND(J23="Critical",K23="Medium"),15,IF(AND(J23="Medium",K23="High"),12,IF(AND(J23="High",K23="Medium"),12,10))))))))
A24: GAP-011 | L24: =IF(OR(ISBLANK(J24),ISBLANK(K24)),"",IF(AND(J24="Critical",K24="Very High"),25,IF(AND(J24="Critical",K24="High"),20,IF(AND(J24="High",K24="Very High"),20,IF(AND(J24="High",K24="High"),16,IF(AND(J24="Critical",K24="Medium"),15,IF(AND(J24="Medium",K24="High"),12,IF(AND(J24="High",K24="Medium"),12,10))))))))
A25: GAP-012 | L25: =IF(OR(ISBLANK(J25),ISBLANK(K25)),"",IF(AND(J25="Critical",K25="Very High"),25,IF(AND(J25="Critical",K25="High"),20,IF(AND(J25="High",K25="Very High"),20,IF(AND(J25="High",K25="High"),16,IF(AND(J25="Critical",K25="Medium"),15,IF(AND(J25="Medium",K25="High"),12,IF(AND(J25="High",K25="Medium"),12,10))))))))
... A213: GAP-200 | L213: =IF(OR(ISBLANK(J213),ISBLANK(K213)),"",IF(AND(J213="Critical",K213="Very High"),25,IF(AND(J213="Critical",K213="High"),20,IF(AND(J213="High",K213="Very High"),20,IF(AND(J213="High",K213="High"),16,IF(AND(J213="Critical",K213="Medium"),15,IF(AND(J213="Medium",K213="High"),12,IF(AND(J213="High",K213="Medium"),12,10))))))))

Sheet Risk Register
A1: CRYPTOGRAPHY RISK REGISTER Consolidated risk assessment for cryptographic control failures
A3: Risk Summary Dashboard
A4: Risk Distribution
A5: Risk Category | B5: Count | C5: Percentage | D5: Risk Exposure
A6: Critical | B6: =COUNTIF(N20:N119,">=20") | C6: =IF(B9=0,"0%",B6/B9*100&"%") | D6: =SUMIF(N20:N119,">=20",N20:N119)
A7: High | B7: =COUNTIF(N20:N119,">=15") | C7: =IF(B9=0,"0%",B7/B9*100&"%") | D7: =SUMIF(N20:N119,">=15",N20:N119)
A8: Medium | B8: =COUNTIF(N20:N119,">=10") | C8: =IF(B9=0,"0%",B8/B9*100&"%") | D8: =SUMIF(N20:N119,">=10",N20:N119)
A9: Low | B9: =COUNTIF(N20:N119,">=0") | C9: =IF(B9=0,"0%",B9/B9*100&"%") | D9: =SUMIF(N20:N119,">=0",N20:N119)
A10: TOTAL | B10: =SUM(B6:B9) | C10: 100% | D10: =SUM(D6:D9)
A12: Risk By Assessment Area
A13: Assessment Area | B13: Critical | C13: High | D13: Medium | E13: Low | F13: Total Risk Exposure | G13: Avg Risk Score
A14: Data Transmission | F14: =B14*25+C14*20+D14*15+E14*10 | G14: =IF(SUM(B14:E14)=0,0,F14/SUM(B14:E14))
A15: Data Storage | F15: =B15*25+C15*20+D15*15+E15*10 | G15: =IF(SUM(B15:E15)=0,0,F15/SUM(B15:E15))
A16: Authentication | F16: =B16*25+C16*20+D16*15+E16*10 | G16: =IF(SUM(B16:E16)=0,0,F16/SUM(B16:E16))
A17: Key Management | F17: =B17*25+C17*20+D17*15+E17*10 | G17: =IF(SUM(B17:E17)=0,0,F17/SUM(B17:E17))
A20: DETAILED RISK REGISTER
A21: Risk ID | B21: Gap ID (Link) | C21: Risk Category | D21: Risk Description | E21: Threat Source | F21: Vulnerability | G21: Existing Controls | H21: Control Effectiveness | I21: Inherent Likelihood | J21: Inherent Impact | K21: Inherent Risk Score | L21: Residual Likelihood | M21: Residual Impact | N21: Residual Risk Score | O21: Risk Response | P21: Risk Owner | Q21: Risk Status | R21: Target Risk Score | S21: Review Date | T21: Last Review Date | U21: Next Review Due
A22: RISK-001 | K22: =IF(OR(ISBLANK(I22),ISBLANK(J22)),"",IF(AND(J22="Critical",I22="Very High"),25,IF(AND(J22="Critical",I22="High"),20,IF(AND(J22="High",I22="Very High"),20,IF(AND(J22="High",I22="High"),16,10))))) | N22: =IF(OR(ISBLANK(L22),ISBLANK(M22)),"",IF(AND(M22="Critical",L22="Very High"),25,IF(AND(M22="Critical",L22="High"),20,IF(AND(M22="High",L22="Very High"),20,IF(AND(M22="High",L22="High"),16,10))))) | U22: =IF(ISBLANK(S22),"",S22+90)
A23: RISK-002 | K23: =IF(OR(ISBLANK(I23),ISBLANK(J23)),"",IF(AND(J23="Critical",I23="Very High"),25,IF(AND(J23="Critical",I23="High"),20,IF(AND(J23="High",I23="Very High"),20,IF(AND(J23="High",I23="High"),16,10))))) | N23: =IF(OR(ISBLANK(L23),ISBLANK(M23)),"",IF(AND(M23="Critical",L23="Very High"),25,IF(AND(M23="Critical",L23="High"),20,IF(AND(M23="High",L23="Very High"),20,IF(AND(M23="High",L23="High"),16,10))))) | U23: =IF(ISBLANK(S23),"",S23+90)
A24: RISK-003 | K24: =IF(OR(ISBLANK(I24),ISBLANK(J24)),"",IF(AND(J24="Critical",I24="Very High"),25,IF(AND(J24="Critical",I24="High"),20,IF(AND(J24="High",I24="Very High"),20,IF(AND(J24="High",I24="High"),16,10))))) | N24: =IF(OR(ISBLANK(L24),ISBLANK(M24)),"",IF(AND(M24="Critical",L24="Very High"),25,IF(AND(M24="Critical",L24="High"),20,IF(AND(M24="High",L24="Very High"),20,IF(AND(M24="High",L24="High"),16,10))))) | U24: =IF(ISBLANK(S24),"",S24+90)
A25: RISK-004 | K25: =IF(OR(ISBLANK(I25),ISBLANK(J25)),"",IF(AND(J25="Critical",I25="Very High"),25,IF(AND(J25="Critical",I25="High"),20,IF(AND(J25="High",I25="Very High"),20,IF(AND(J25="High",I25="High"),16,10))))) | N25: =IF(OR(ISBLANK(L25),ISBLANK(M25)),"",IF(AND(M25="Critical",L25="Very High"),25,IF(AND(M25="Critical",L25="High"),20,IF(AND(M25="High",L25="Very High"),20,IF(AND(M25="High",L25="High"),16,10))))) | U25: =IF(ISBLANK(S25),"",S25+90)
A26: RISK-005 | K26: =IF(OR(ISBLANK(I26),ISBLANK(J26)),"",IF(AND(J26="Critical",I26="Very High"),25,IF(AND(J26="Critical",I26="High"),20,IF(AND(J26="High",I26="Very High"),20,IF(AND(J26="High",I26="High"),16,10))))) | N26: =IF(OR(ISBLANK(L26),ISBLANK(M26)),"",IF(AND(M26="Critical",L26="Very High"),25,IF(AND(M26="Critical",L26="High"),20,IF(AND(M26="High",L26="Very High"),20,IF(AND(M26="High",L26="High"),16,10))))) | U26: =IF(ISBLANK(S26),"",S26+90)
A27: RISK-006 | K27: =IF(OR(ISBLANK(I27),ISBLANK(J27)),"",IF(AND(J27="Critical",I27="Very High"),25,IF(AND(J27="Critical",I27="High"),20,IF(AND(J27="High",I27="Very High"),20,IF(AND(J27="High",I27="High"),16,10))))) | N27: =IF(OR(ISBLANK(L27),ISBLANK(M27)),"",IF(AND(M27="Critical",L27="Very High"),25,IF(AND(M27="Critical",L27="High"),20,IF(AND(M27="High",L27="Very High"),20,IF(AND(M27="High",L27="High"),16,10))))) | U27: =IF(ISBLANK(S27),"",S27+90)
A28: RISK-007 | K28: =IF(OR(ISBLANK(I28),ISBLANK(J28)),"",IF(AND(J28="Critical",I28="Very High"),25,IF(AND(J28="Critical",I28="High"),20,IF(AND(J28="High",I28="Very High"),20,IF(AND(J28="High",I28="High"),16,10))))) | N28: =IF(OR(ISBLANK(L28),ISBLANK(M28)),"",IF(AND(M28="Critical",L28="Very High"),25,IF(AND(M28="Critical",L28="High"),20,IF(AND(M28="High",L28="Very High"),20,IF(AND(M28="High",L28="High"),16,10))))) | U28: =IF(ISBLANK(S28),"",S28+90)
A29: RISK-008 | K29: =IF(OR(ISBLANK(I29),ISBLANK(J29)),"",IF(AND(J29="Critical",I29="Very High"),25,IF(AND(J29="Critical",I29="High"),20,IF(AND(J29="High",I29="Very High"),20,IF(AND(J29="High",I29="High"),16,10))))) | N29: =IF(OR(ISBLANK(L29),ISBLANK(M29)),"",IF(AND(M29="Critical",L29="Very High"),25,IF(AND(M29="Critical",L29="High"),20,IF(AND(M29="High",L29="Very High"),20,IF(AND(M29="High",L29="High"),16,10))))) | U29: =IF(ISBLANK(S29),"",S29+90)
A30: RISK-009 | K30: =IF(OR(ISBLANK(I30),ISBLANK(J30)),"",IF(AND(J30="Critical",I30="Very High"),25,IF(AND(J30="Critical",I30="High"),20,IF(AND(J30="High",I30="Very High"),20,IF(AND(J30="High",I30="High"),16,10))))) | N30: =IF(OR(ISBLANK(L30),ISBLANK(M30)),"",IF(AND(M30="Critical",L30="Very High"),25,IF(AND(M30="Critical",L30="High"),20,IF(AND(M30="High",L30="Very High"),20,IF(AND(M30="High",L30="High"),16,10))))) | U30: =IF(ISBLANK(S30),"",S30+90)
A31: RISK-010 | K31: =IF(OR(ISBLANK(I31),ISBLANK(J31)),"",IF(AND(J31="Critical",I31="Very High"),25,IF(AND(J31="Critical",I31="High"),20,IF(AND(J31="High",I31="Very High"),20,IF(AND(J31="High",I31="High"),16,10))))) | N31: =IF(OR(ISBLANK(L31),ISBLANK(M31)),"",IF(AND(M31="Critical",L31="Very High"),25,IF(AND(M31="Critical",L31="High"),20,IF(AND(M31="High",L31="Very High"),20,IF(AND(M31="High",L31="High"),16,10))))) | U31: =IF(ISBLANK(S31),"",S31+90)
A32: RISK-011 | K32: =IF(OR(ISBLANK(I32),ISBLANK(J32)),"",IF(AND(J32="Critical",I32="Very High"),25,IF(AND(J32="Critical",I32="High"),20,IF(AND(J32="High",I32="Very High"),20,IF(AND(J32="High",I32="High"),16,10))))) | N32: =IF(OR(ISBLANK(L32),ISBLANK(M32)),"",IF(AND(M32="Critical",L32="Very High"),25,IF(AND(M32="Critical",L32="High"),20,IF(AND(M32="High",L32="Very High"),20,IF(AND(M32="High",L32="High"),16,10))))) | U32: =IF(ISBLANK(S32),"",S32+90)
A33: RISK-012 | K33: =IF(OR(ISBLANK(I33),ISBLANK(J33)),"",IF(AND(J33="Critical",I33="Very High"),25,IF(AND(J33="Critical",I33="High"),20,IF(AND(J33="High",I33="Very High"),20,IF(AND(J33="High",I33="High"),16,10))))) | N33: =IF(OR(ISBLANK(L33),ISBLANK(M33)),"",IF(AND(M33="Critical",L33="Very High"),25,IF(AND(M33="Critical",L33="High"),20,IF(AND(M33="High",L33="Very High"),20,IF(AND(M33="High",L33="High"),16,10))))) | U33: =IF(ISBLANK(S33),"",S33+90)
... A121: RISK-100 | K121: =IF(OR(ISBLANK(I121),ISBLANK(J121)),"",IF(AND(J121="Critical",I121="Very High"),25,IF(AND(J121="Critical",I121="High"),20,IF(AND(J121="High",I121="Very High"),20,IF(AND(J121="High",I121="High"),16,10))))) | N121: =IF(OR(ISBLANK(L121),ISBLANK(M121)),"",IF(AND(M121="Critical",L121="Very High"),25,IF(AND(M121="Critical",L121="High"),20,IF(AND(M121="High",L121="Very High"),20,IF(AND(M121="High",L121="High"),16,10))))) | U121: =IF(ISBLANK(S121),"",S121+90)

Sheet Remediation Roadmap
A1: CRYPTOGRAPHY REMEDIATION ROADMAP Action plan for closing identified gaps and reducing risk
A3: Roadmap Summary - Overall Progress
A4: Metric | B4: Value | C4: Target | D4: Status
A5: Total Remediation Items | B5: =COUNTA(E37:E236) | C5: N/A
A6: Completed | B6: =COUNTIF(H37:H236,"Completed") | C6: -
A7: In Progress | B7: =COUNTIF(H37:H236,"In Progress") | C7: -
A8: Not Started | B8: =COUNTIF(H37:H236,"Not Started") | C8: -
A9: Overdue | B9: =COUNTIFS(M37:M236,"<"&TODAY(),H37:H236,"<>Completed") | C9: 0
A10: On Schedule | B10: =COUNTIFS(M37:M236,">="&TODAY(),H37:H236,"<>Completed") | C10: 100%
A11: Total Budget Required | B11: =SUM(R37:R236) | C11: -
A12: Budget Allocated | C12: -
A13: Budget Utilised | B13: =SUM(T37:T236) | C13: -
A16: Progress by Assessment Area
A17: Assessment Area | B17: Total Items | C17: Completed | D17: In Progress | E17: Not Started | F17: % Complete | G17: On-Time %
A18: Data Transmission | B18: =COUNTIF(D37:D236,"Data Transmission") | C18: =COUNTIFS(D37:D236,"Data Transmission",H37:H236,"Completed") | D18: =COUNTIFS(D37:D236,"Data Transmission",H37:H236,"In Progress") | E18: =COUNTIFS(D37:D236,"Data Transmission",H37:H236,"Not Started") | F18: =IF(B18=0,"0%",C18/B18*100&"%")
A19: Data Storage | B19: =COUNTIF(D37:D236,"Data Storage") | C19: =COUNTIFS(D37:D236,"Data Storage",H37:H236,"Completed") | D19: =COUNTIFS(D37:D236,"Data Storage",H37:H236,"In Progress") | E19: =COUNTIFS(D37:D236,"Data Storage",H37:H236,"Not Started") | F19: =IF(B19=0,"0%",C19/B19*100&"%")
A20: Authentication | B20: =COUNTIF(D37:D236,"Authentication") | C20: =COUNTIFS(D37:D236,"Authentication",H37:H236,"Completed") | D20: =COUNTIFS(D37:D236,"Authentication",H37:H236,"In Progress") | E20: =COUNTIFS(D37:D236,"Authentication",H37:H236,"Not Started") | F20: =IF(B20=0,"0%",C20/B20*100&"%")
A21: Key Management | B21: =COUNTIF(D37:D236,"Key Management") | C21: =COUNTIFS(D37:D236,"Key Management",H37:H236,"Completed") | D21: =COUNTIFS(D37:D236,"Key Management",H37:H236,"In Progress") | E21: =COUNTIFS(D37:D236,"Key Management",H37:H236,"Not Started") | F21: =IF(B21=0,"0%",C21/B21*100&"%")
A24: REMEDIATION TIMELINE BY QUARTER
A25: (Gantt chart visualization - use conditional formatting or insert chart manually)
A28: DETAILED REMEDIATION REGISTER
A29: Remediation ID | B29: Gap ID (Link) | C29: Risk ID (Link) | D29: Assessment Area | E29: Remediation Action | F29: Action Type | G29: Priority | H29: Current Status | I29: % Complete | J29: Responsible Person | K29: Supporting Team | L29: Start Date | M29: Target Date | N29: Actual Completion | O29: Days Remaining | P29: On Schedule | Q29: Dependencies | R29: Budget Required | S29: Budget Approved | T29: Actual Cost | U29: Vendor/Resource | V29: Success Criteria | W29: Verification Method | X29: Completion Evidence | Y29: Notes/Comments | Z29: Last Updated
A30: REM-001 | O30: =IF(H30="Completed",0,IF(ISBLANK(M30),"",M30-TODAY())) | P30: =IF(H30="Completed","Completed",IF(ISBLANK(O30),"",IF(O30<0,"Overdue",IF(O30<30,"At Risk","On Track")))) | Z30: =TODAY()
A31: REM-002 | O31: =IF(H31="Completed",0,IF(ISBLANK(M31),"",M31-TODAY())) | P31: =IF(H31="Completed","Completed",IF(ISBLANK(O31),"",IF(O31<0,"Overdue",IF(O31<30,"At Risk","On Track")))) | Z31: =TODAY()
A32: REM-003 | O32: =IF(H32="Completed",0,IF(ISBLANK(M32),"",M32-TODAY())) | P32: =IF(H32="Completed","Completed",IF(ISBLANK(O32),"",IF(O32<0,"Overdue",IF(O32<30,"At Risk","On Track")))) | Z32: =TODAY()
A33: REM-004 | O33: =IF(H33="Completed",0,IF(ISBLANK(M33),"",M33-TODAY())) | P33: =IF(H33="Completed","Completed",IF(ISBLANK(O33),"",IF(O33<0,"Overdue",IF(O33<30,"At Risk","On Track")))) | Z33: =TODAY()
A34: REM-005 | O34: =IF(H34="Completed",0,IF(ISBLANK(M34),"",M34-TODAY())) | P34: =IF(H34="Completed","Completed",IF(ISBLANK(O34),"",IF(O34<0,"Overdue",IF(O34<30,"At Risk","On Track")))) | Z34: =TODAY()
A35: REM-006 | O35: =IF(H35="Completed",0,IF(ISBLANK(M35),"",M35-TODAY())) | P35: =IF(H35="Completed","Completed",IF(ISBLANK(O35),"",IF(O35<0,"Overdue",IF(O35<30,"At Risk","On Track")))) | Z35: =TODAY()
A36: REM-007 | O36: =IF(H36="Completed",0,IF(ISBLANK(M36),"",M36-TODAY())) | P36: =IF(H36="Completed","Completed",IF(ISBLANK(O36),"",IF(O36<0,"Overdue",IF(O36<30,"At Risk","On Track")))) | Z36: =TODAY()
A37: REM-008 | O37: =IF(H37="Completed",0,IF(ISBLANK(M37),"",M37-TODAY())) | P37: =IF(H37="Completed","Completed",IF(ISBLANK(O37),"",IF(O37<0,"Overdue",IF(O37<30,"At Risk","On Track")))) | Z37: =TODAY()
A38: REM-009 | O38: =IF(H38="Completed",0,IF(ISBLANK(M38),"",M38-TODAY())) | P38: =IF(H38="Completed","Completed",IF(ISBLANK(O38),"",IF(O38<0,"Overdue",IF(O38<30,"At Risk","On Track")))) | Z38: =TODAY()
A39: REM-010 | O39: =IF(H39="Completed",0,IF(ISBLANK(M39),"",M39-TODAY())) | P39: =IF(H39="Completed","Completed",IF(ISBLANK(O39),"",IF(O39<0,"Overdue",IF(O39<30,"At Risk","On Track")))) | Z39: =TODAY()
A40: REM-011 | O40: =IF(H40="Completed",0,IF(ISBLANK(M40),"",M40-TODAY())) | P40: =IF(H40="Completed","Completed",IF(ISBLANK(O40),"",IF(O40<0,"Overdue",IF(O40<30,"At Risk","On Track")))) | Z40: =TODAY()
A41: REM-012 | O41: =IF(H41="Completed",0,IF(ISBLANK(M41),"",M41-TODAY())) | P41: =IF(H41="Completed","Completed",IF(ISBLANK(O41),"",IF(O41<0,"Overdue",IF(O41<30,"At Risk","On Track")))) | Z41: =TODAY()
... A229: REM-200 | O229: =IF(H229="Completed",0,IF(ISBLANK(M229),"",M229-TODAY())) | P229: =IF(H229="Completed","Completed",IF(ISBLANK(O229),"",IF(O229<0,"Overdue",IF(O229<30,"At Risk","On Track")))) | Z229: =TODAY()

Sheet KPIs & Metrics
A1: KEY PERFORMANCE INDICATORS & METRICS Secure Coding program effectiveness measurement
A3: COMPLIANCE METRICS
A4: KPI | B4: Current Value | C4: Target | D4: Threshold | E4: Status | F4: Trend | G4: Last Quarter | H4: YoY Change
A5: Overall Secure Coding Compliance Rate | B5: ='Executive Dashboard'!C29 | C5: ≥95% | D5: 90%
A6: Data Transmission Encryption Coverage | C6: 100% | D6: 95%
A7: Data at Rest Encryption Coverage | C7: 100% | D7: 95%
A8: Strong Authentication Coverage | C8: ≥90% | D8: 80%
A9: Key Management Compliance | C9: ≥95% | D9: 90%
A10: Algorithm Compliance Rate | C10: 100% | D10: 98%
A11: Certificate Validity Compliance | C11: 100% | D11: 95%
A12: Password Hashing Compliance | C12: 100% | D12: 100%
A13: Service Account Security | C13: ≥90% | D13: 85%
A14: SSO Coverage | C14: ≥80% | D14: 70%
A15: MFA Enrollment - All Users | C15: 100% | D15: 95%
A16: MFA Enrollment - Administrators | C16: 100% | D16: 100%
A17: Policy Compliance Score | C17: ≥95% | D17: 90%
... A19: Compliance Exceptions | C19: ≤5 | D19: ≤10
A21: RISK METRICS
A22: KPI | B22: Current Value | C22: Target | D22: Threshold | E22: Status | F22: Trend | G22: Last Quarter | H22: YoY Change
A23: Critical Risks - Open | B23: =COUNTIFS('Risk Register'!N20:N119,">=20",'Risk Register'!Q20:Q119,"<>Closed") | C23: 0 | D23: 0
A24: High Risks - Open | B24: =COUNTIFS('Risk Register'!N20:N119,">=15",'Risk Register'!Q20:Q119,"<>Closed") | C24: ≤5 | D24: ≤10
A25: Average Risk Score | B25: =AVERAGE('Risk Register'!N20:N119) | C25: <10 | D25: <15
A26: Risk Reduction Rate | C26: ≥20% per Q | D26: ≥10%
A27: Residual Risk Exposure | B27: =SUM('Risk Register'!N20:N119) | C27: <100 | D27: <200
A28: Risks Accepted (No Remediation) | B28: =COUNTIF('Risk Register'!Q20:Q119,"Accepted") | C28: ≤5 | D28: ≤10
A29: Risks Transferred | C29: - | D29: -
A30: Time to Risk Identification (Avg Days) | C30: ≤7 | D30: ≤14
A31: Time to Risk Remediation (Avg Days) | C31: ≤90 | D31: ≤120
A32: Overdue Risks | C32: 0 | D32: ≤2
A34: REMEDIATION METRICS
A35: KPI | B35: Current Value | C35: Target | D35: Threshold | E35: Status | F35: Trend | G35: Last Quarter | H35: YoY Change
A36: Total Open Gaps | B36: =COUNTIF('Gap Analysis'!R12:R211,"<>Closed") | C36: ≤10 | D36: ≤20
A37: Critical Gaps - Open | B37: =COUNTIFS('Gap Analysis'!I12:I211,"Critical",'Gap Analysis'!R12:R211,"<>Closed") | C37: 0 | D37: 0
A38: High Priority Gaps - Open | B38: =COUNTIFS('Gap Analysis'!I12:I211,"High",'Gap Analysis'!R12:R211,"<>Closed") | C38: ≤5 | D38: ≤10
A39: Gaps Closed This Quarter | C39: ≥10 | D39: ≥5
A40: Gap Closure Rate | B40: =COUNTIF('Gap Analysis'!R12:R211,"Closed")/COUNTA('Gap Analysis'!R12:R211)*100&"%" | C40: ≥80% | D40: ≥70%
A41: Remediation On-Time % | C41: ≥90% | D41: ≥80%
A42: Overdue Remediation Items | B42: =COUNTIFS('Remediation Roadmap'!M37:M236,"<"&TODAY(),'Remediation Roadmap'!H37:H236,"<>Completed") | C42: 0 | D42: ≤3
A43: Average Time to Remediation (Days) | C43: ≤90 | D43: ≤120
A44: Budget Utilization Rate | C44: 90-100% | D44: 80-110%
...

Sheet Evidence Register
A1: CONSOLIDATED EVIDENCE REGISTER Central repository for all cryptography compliance evidence
A3: Evidence Summary Statistics
A4: Assessment Area | B4: Total Evidence Items | C4: Verified | D4: Pending Verification | E4: Not Verified | F4: Verification %
A5: Data Transmission | B5: =COUNTIF(B17:B516,"Data Transmission") | C5: =COUNTIFS(B17:B516,"Data Transmission",K17:K516,"Verified") | D5: =COUNTIFS(B17:B516,"Data Transmission",K17:K516,"Pending Verification") | E5: =COUNTIFS(B17:B516,"Data Transmission",K17:K516,"Not Verified") | F5: =IF(B5=0,"0%",C5/B5*100&"%")
A6: Data Storage | B6: =COUNTIF(B17:B516,"Data Storage") | C6: =COUNTIFS(B17:B516,"Data Storage",K17:K516,"Verified") | D6: =COUNTIFS(B17:B516,"Data Storage",K17:K516,"Pending Verification") | E6: =COUNTIFS(B17:B516,"Data Storage",K17:K516,"Not Verified") | F6: =IF(B6=0,"0%",C6/B6*100&"%")
A7: Authentication | B7: =COUNTIF(B17:B516,"Authentication") | C7: =COUNTIFS(B17:B516,"Authentication",K17:K516,"Verified") | D7: =COUNTIFS(B17:B516,"Authentication",K17:K516,"Pending Verification") | E7: =COUNTIFS(B17:B516,"Authentication",K17:K516,"Not Verified") | F7: =IF(B7=0,"0%",C7/B7*100&"%")
A8: Key Management | B8: =COUNTIF(B17:B516,"Key Management") | C8: =COUNTIFS(B17:B516,"Key Management",K17:K516,"Verified") | D8: =COUNTIFS(B17:B516,"Key Management",K17:K516,"Pending Verification") | E8: =COUNTIFS(B17:B516,"Key Management",K17:K516,"Not Verified") | F8: =IF(B8=0,"0%",C8/B8*100&"%")
A9: TOTAL | B9: =SUM(B5:B8) | C9: =SUM(C5:C8) | D9: =SUM(D5:D8) | E9: =SUM(E5:E8) | F9: =SUM(F5:F8)
A12: DETAILED EVIDENCE REGISTER
A13: Evidence ID | B13: Assessment Area | C13: Source Document | D13: Gap ID (Link) | E13: Control Reference | F13: Evidence Type | G13: Evidence Description | H13: Evidence Location/Path | I13: Date Collected | J13: Collected By | K13: Verification Status | L13: Verified By | M13: Verification Date | N13: Retention Period | O13: Destruction Date | P13: Classification | Q13: Accessibility | R13: Related Risk ID | S13: Related Remediation ID | T13: Audit Reference | U13: Notes/Comments | V13: Last Updated
A14: EV-001 | O14: =IF(OR(ISBLANK(I14),ISBLANK(N14)),"",EDATE(I14,IF(N14="1 year",12,IF(N14="3 years",36,IF(N14="5 years",60,IF(N14="7 years",84,600)))))) | V14: =TODAY()
A15: EV-002 | O15: =IF(OR(ISBLANK(I15),ISBLANK(N15)),"",EDATE(I15,IF(N15="1 year",12,IF(N15="3 years",36,IF(N15="5 years",60,IF(N15="7 years",84,600)))))) | V15: =TODAY()
A16: EV-003 | O16: =IF(OR(ISBLANK(I16),ISBLANK(N16)),"",EDATE(I16,IF(N16="1 year",12,IF(N16="3 years",36,IF(N16="5 years",60,IF(N16="7 years",84,600)))))) | V16: =TODAY()
A17: EV-004 | O17: =IF(OR(ISBLANK(I17),ISBLANK(N17)),"",EDATE(I17,IF(N17="1 year",12,IF(N17="3 years",36,IF(N17="5 years",60,IF(N17="7 years",84,600)))))) | V17: =TODAY()
A18: EV-005 | O18: =IF(OR(ISBLANK(I18),ISBLANK(N18)),"",EDATE(I18,IF(N18="1 year",12,IF(N18="3 years",36,IF(N18="5 years",60,IF(N18="7 years",84,600)))))) | V18: =TODAY()
A19: EV-006 | O19: =IF(OR(ISBLANK(I19),ISBLANK(N19)),"",EDATE(I19,IF(N19="1 year",12,IF(N19="3 years",36,IF(N19="5 years",60,IF(N19="7 years",84,600)))))) | V19: =TODAY()
A20: EV-007 | O20: =IF(OR(ISBLANK(I20),ISBLANK(N20)),"",EDATE(I20,IF(N20="1 year",12,IF(N20="3 years",36,IF(N20="5 years",60,IF(N20="7 years",84,600)))))) | V20: =TODAY()
A21: EV-008 | O21: =IF(OR(ISBLANK(I21),ISBLANK(N21)),"",EDATE(I21,IF(N21="1 year",12,IF(N21="3 years",36,IF(N21="5 years",60,IF(N21="7 years",84,600)))))) | V21: =TODAY()
A22: EV-009 | O22: =IF(OR(ISBLANK(I22),ISBLANK(N22)),"",EDATE(I22,IF(N22="1 year",12,IF(N22="3 years",36,IF(N22="5 years",60,IF(N22="7 years",84,600)))))) | V22: =TODAY()
A23: EV-010 | O23: =IF(OR(ISBLANK(I23),ISBLANK(N23)),"",EDATE(I23,IF(N23="1 year",12,IF(N23="3 years",36,IF(N23="5 years",60,IF(N23="7 years",84,600)))))) | V23: =TODAY()
A24: EV-011 | O24: =IF(OR(ISBLANK(I24),ISBLANK(N24)),"",EDATE(I24,IF(N24="1 year",12,IF(N24="3 years",36,IF(N24="5 years",60,IF(N24="7 years",84,600)))))) | V24: =TODAY()
A25: EV-012 | O25: =IF(OR(ISBLANK(I25),ISBLANK(N25)),"",EDATE(I25,IF(N25="1 year",12,IF(N25="3 years",36,IF(N25="5 years",60,IF(N25="7 years",84,600)))))) | V25: =TODAY()
... A513: EV-500 | O513: =IF(OR(ISBLANK(I513),ISBLANK(N513)),"",EDATE(I513,IF(N513="1 year",12,IF(N513="3 years",36,IF(N513="5 years",60,IF(N513="7 years",84,600)))))) | V513: =TODAY()

Sheet Action Items & Follow-up
A1: ACTION ITEMS & FOLLOW-UP TRACKER Centralised tracking of all outstanding actions
A3: Action Summary Dashboard
A4: Current Status
A5: Status | B5: Count | C5: Percentage | D5: Overdue Count
A6: Not Started | B6: =COUNTIF(G22:G221,"Not Started") | C6: =IF(B10=0,"0%",B6/B10*100&"%") | D6: =COUNTIFS(G22:G221,"Not Started",K22:K221,"<"&TODAY())
A7: In Progress | B7: =COUNTIF(G22:G221,"In Progress") | C7: =IF(B10=0,"0%",B7/B10*100&"%") | D7: =COUNTIFS(G22:G221,"In Progress",K22:K221,"<"&TODAY())
A8: Blocked | B8: =COUNTIF(G22:G221,"Blocked") | C8: =IF(B10=0,"0%",B8/B10*100&"%") | D8: =COUNTIFS(G22:G221,"Blocked",K22:K221,"<"&TODAY())
A9: Pending Review | B9: =COUNTIF(G22:G221,"Pending Review") | C9: =IF(B10=0,"0%",B9/B10*100&"%") | D9: =COUNTIFS(G22:G221,"Pending Review",K22:K221,"<"&TODAY())
A10: Completed | B10: =COUNTIF(G22:G221,"Completed") | C10: =IF(B10=0,"0%",B10/B10*100&"%") | D10: N/A
A11: TOTAL | B11: =SUM(B6:B10) | C11: 100% | D11: =SUM(D6:D10)
A13: By Priority
A14: Priority | B14: Open Actions | C14: Overdue | D14: % Complete | E14: Avg Days Open
A15: Critical | B15: =COUNTIFS(F22:F221,"Critical",G22:G221,"<>Completed") | C15: =COUNTIFS(F22:F221,"Critical",K22:K221,"<"&TODAY(),G22:G221,"<>Completed")
A16: High | B16: =COUNTIFS(F22:F221,"High",G22:G221,"<>Completed") | C16: =COUNTIFS(F22:F221,"High",K22:K221,"<"&TODAY(),G22:G221,"<>Completed")
A17: Medium | B17: =COUNTIFS(F22:F221,"Medium",G22:G221,"<>Completed") | C17: =COUNTIFS(F22:F221,"Medium",K22:K221,"<"&TODAY(),G22:G221,"<>Completed")
A18: Low | B18: =COUNTIFS(F22:F221,"Low",G22:G221,"<>Completed") | C18: =COUNTIFS(F22:F221,"Low",K22:K221,"<"&TODAY(),G22:G221,"<>Completed")
A21: DETAILED ACTION REGISTER
A22: Action ID | B22: Source | C22: Source ID | D22: Action Description | E22: Action Type | F22: Priority | G22: Status | H22: Owner | I22: Supporting Team | J22: Created Date | K22: Due Date | L22: Completed Date | M22: Days Open | N22: Days Remaining | O22: On Time Status | P22: Blocking Issue | Q22: Dependencies | R22: Progress % | S22: Last Update Date | T22: Last Update By | U22: Update Notes | V22: Escalation Required | W22: Escalated To | X22: Escalation Date
A23: ACT-001 | M23: =IF(G23="Completed",IF(ISBLANK(L23),"",L23-J23),IF(ISBLANK(J23),"",TODAY()-J23)) | N23: =IF(G23="Completed",0,IF(ISBLANK(K23),"",K23-TODAY())) | O23: =IF(G23="Completed","Completed",IF(ISBLANK(N23),"",IF(N23<0,"Overdue",IF(N23<7,"At Risk","On Time"))))
A24: ACT-002 | M24: =IF(G24="Completed",IF(ISBLANK(L24),"",L24-J24),IF(ISBLANK(J24),"",TODAY()-J24)) | N24: =IF(G24="Completed",0,IF(ISBLANK(K24),"",K24-TODAY())) | O24: =IF(G24="Completed","Completed",IF(ISBLANK(N24),"",IF(N24<0,"Overdue",IF(N24<7,"At Risk","On Time"))))
A25: ACT-003 | M25: =IF(G25="Completed",IF(ISBLANK(L25),"",L25-J25),IF(ISBLANK(J25),"",TODAY()-J25)) | N25: =IF(G25="Completed",0,IF(ISBLANK(K25),"",K25-TODAY())) | O25: =IF(G25="Completed","Completed",IF(ISBLANK(N25),"",IF(N25<0,"Overdue",IF(N25<7,"At Risk","On Time"))))
A26: ACT-004 | M26: =IF(G26="Completed",IF(ISBLANK(L26),"",L26-J26),IF(ISBLANK(J26),"",TODAY()-J26)) | N26: =IF(G26="Completed",0,IF(ISBLANK(K26),"",K26-TODAY())) | O26: =IF(G26="Completed","Completed",IF(ISBLANK(N26),"",IF(N26<0,"Overdue",IF(N26<7,"At Risk","On Time"))))
A27: ACT-005 | M27: =IF(G27="Completed",IF(ISBLANK(L27),"",L27-J27),IF(ISBLANK(J27),"",TODAY()-J27)) | N27: =IF(G27="Completed",0,IF(ISBLANK(K27),"",K27-TODAY())) | O27: =IF(G27="Completed","Completed",IF(ISBLANK(N27),"",IF(N27<0,"Overdue",IF(N27<7,"At Risk","On Time"))))
A28: ACT-006 | M28: =IF(G28="Completed",IF(ISBLANK(L28),"",L28-J28),IF(ISBLANK(J28),"",TODAY()-J28)) | N28: =IF(G28="Completed",0,IF(ISBLANK(K28),"",K28-TODAY())) | O28: =IF(G28="Completed","Completed",IF(ISBLANK(N28),"",IF(N28<0,"Overdue",IF(N28<7,"At Risk","On Time"))))
A29: ACT-007 | M29: =IF(G29="Completed",IF(ISBLANK(L29),"",L29-J29),IF(ISBLANK(J29),"",TODAY()-J29)) | N29: =IF(G29="Completed",0,IF(ISBLANK(K29),"",K29-TODAY())) | O29: =IF(G29="Completed","Completed",IF(ISBLANK(N29),"",IF(N29<0,"Overdue",IF(N29<7,"At Risk","On Time"))))
A30: ACT-008 | M30: =IF(G30="Completed",IF(ISBLANK(L30),"",L30-J30),IF(ISBLANK(J30),"",TODAY()-J30)) | N30: =IF(G30="Completed",0,IF(ISBLANK(K30),"",K30-TODAY())) | O30: =IF(G30="Completed","Completed",IF(ISBLANK(N30),"",IF(N30<0,"Overdue",IF(N30<7,"At Risk","On Time"))))
A31: ACT-009 | M31: =IF(G31="Completed",IF(ISBLANK(L31),"",L31-J31),IF(ISBLANK(J31),"",TODAY()-J31)) | N31: =IF(G31="Completed",0,IF(ISBLANK(K31),"",K31-TODAY())) | O31: =IF(G31="Completed","Completed",IF(ISBLANK(N31),"",IF(N31<0,"Overdue",IF(N31<7,"At Risk","On Time"))))
A32: ACT-010 | M32: =IF(G32="Completed",IF(ISBLANK(L32),"",L32-J32),IF(ISBLANK(J32),"",TODAY()-J32)) | N32: =IF(G32="Completed",0,IF(ISBLANK(K32),"",K32-TODAY())) | O32: =IF(G32="Completed","Completed",IF(ISBLANK(N32),"",IF(N32<0,"Overdue",IF(N32<7,"At Risk","On Time"))))
A33: ACT-011 | M33: =IF(G33="Completed",IF(ISBLANK(L33),"",L33-J33),IF(ISBLANK(J33),"",TODAY()-J33)) | N33: =IF(G33="Completed",0,IF(ISBLANK(K33),"",K33-TODAY())) | O33: =IF(G33="Completed","Completed",IF(ISBLANK(N33),"",IF(N33<0,"Overdue",IF(N33<7,"At Risk","On Time"))))
A34: ACT-012 | M34: =IF(G34="Completed",IF(ISBLANK(L34),"",L34-J34),IF(ISBLANK(J34),"",TODAY()-J34)) | N34: =IF(G34="Completed",0,IF(ISBLANK(K34),"",K34-TODAY())) | O34: =IF(G34="Completed","Completed",IF(ISBLANK(N34),"",IF(N34<0,"Overdue",IF(N34<7,"At Risk","On Time"))))
... A222: ACT-200 | M222: =IF(G222="Completed",IF(ISBLANK(L222),"",L222-J222),IF(ISBLANK(J222),"",TODAY()-J222)) | N222: =IF(G222="Completed",0,IF(ISBLANK(K222),"",K222-TODAY())) | O222: =IF(G222="Completed","Completed",IF(ISBLANK(N222),"",IF(N222<0,"Overdue",IF(N222<7,"At Risk","On Time"))))

Sheet Audit & Compliance Log
A1: AUDIT & COMPLIANCE LOG Record of all audits, assessments, and compliance reviews
A3: Audit Summary
A4: Audit Type | B4: Total Audits | C4: Open Findings | D4: Closed Findings | E4: Avg Time to Close | F4: Compliance Rate
A5: Internal Audit | B5: =COUNTIF(B19:B118,"Internal Audit")
A6: External Audit | B6: =COUNTIF(B19:B118,"External Audit")
A7: Self-Assessment | B7: =COUNTIF(B19:B118,"Self-Assessment")
A8: Vendor Audit | B8: =COUNTIF(B19:B118,"Vendor Audit")
A9: Regulatory Inspection | B9: =COUNTIF(B19:B118,"Regulatory Inspection")
A10: TOTAL | B10: =SUM(B5:B9) | C10: =SUM(C5:C9) | D10: =SUM(D5:D9) | E10: =AVERAGE(E5:E9) | F10: =AVERAGE(F5:F9)
A13: AUDIT REGISTER
A14: Audit ID | B14: Audit Type | C14: Audit Scope | D14: Assessment Area | E14: Auditor/Assessor | F14: Audit Date | G14: Audit Report Date | H14: Total Findings | I14: Critical Findings | J14: High Findings | K14: Medium Findings | L14: Low Findings | M14: Open Findings | N14: Closed Findings | O14: Compliance Score | P14: Report Location | Q14: Follow-up Required | R14: Follow-up Date | S14: Status | T14: Notes
A15: AUD-001
A16: AUD-002
A17: AUD-003
A18: AUD-004
A19: AUD-005
A20: AUD-006
A21: AUD-007
A22: AUD-008
A23: AUD-009
A24: AUD-010
A25: AUD-011
A26: AUD-012
... A114: AUD-100

Sheet Approval Sign-Off
A1: ASSESSMENT APPROVAL AND SIGN-OFF
A3: Dashboard Summary
A4: Assessment Document | B4: ISMS-IMP-A.8.28.5 - Compliance Summary Dashboard
A5: Assessment Period
A6: Portfolio Compliance (Average) | B6: ='Executive Dashboard'!C29
A7: Dashboard Status
A10: ASSESSMENT COMPLETED BY
A11: Name:
A12: Role/Title:
A13: Department:
A14: Email:
A15: Date:
A18: REVIEWED BY (INFORMATION SECURITY OFFICER)
A19: Name:
A20: Date:
A21: Review Notes:
A24: APPROVED BY (CISO)
... A34: Special Considerations:
