Workbook

Sheet Instructions
A1: ISMS-IMP-A.8.28.1 – SDLC Assessment
A2: ISO/IEC 27001:2022 - Control A.8.28: Secure Coding (SDLC)
A4: DOCUMENT INFORMATION
A5: Document ID: | B5: ISMS-IMP-A.8.28.1
A6: Assessment Area: | B6: Secure Software Development Lifecycle
A7: Related Policy: | B7: ISMS-POL-A.8.28-S2.1 (SDLC Requirements)
A8: Version: | B8: 1.0
A9: Assessment Date: | B9: [USER INPUT - Enter assessment date]
A10: Completed By: | B10: [USER INPUT - Enter assessor name]
A11: Organisation: | B11: [USER INPUT - Enter organisation name]
A12: Review Cycle: | B12: Quarterly or when SDLC processes change
A15: HOW TO USE THIS WORKBOOK
A16: 1. Complete each assessment domain sheet sequentially (Security Requirements → Development Environment → Build Pipeline → Security Testing → Release Management)
A17: 2. For each requirement, select Implementation Status from dropdown menu
A18: 3. Provide Evidence Reference - document WHERE the evidence can be found (URL, file path, system name)
A19: 4. Add Comments explaining implementation details, exceptions, or context
A20: 5. Review the Summary Dashboard to see overall compliance metrics
A21: 6. Document all gaps in the Gap Analysis sheet with remediation plans
A22: 7. Maintain the Evidence Register for comprehensive audit trail
A23: 8. Obtain required approvals on the Approval Sign-Off sheet
A25: ⚠️ IMPORTANT: This is a TECHNICAL assessment. Focus on what is ACTUALLY implemented, not what is planned or documented.
A26: As Feynman said: 'The first principle is that you must not fool yourself—and you are the easiest person to fool.'
A29: ASSESSMENT DOMAINS
A30: Domain | B30: Focus Area | C30: Requirements
A31: 1. Security Requirements & Design | B31: Threat modeling, security requirements, design reviews
A32: 2. Development Environment & Tooling | B32: Developer workstations, IDE plugins, repository security
A33: 3. Build & Deployment Pipeline | B33: CI/CD security, SAST/SCA/DAST, artifact signing
A34: 4. Security Testing Integration | B34: Unit/integration/API testing, pentest, bug bounty
A35: 5. Release & Change Management | B35: Release approval, patching, post-deployment verification
C36: 90 Total
A39: IMPLEMENTATION STATUS LEGEND
A40: Status | B40: Symbol | C40: Description | D40: When to Use
A41: Implemented | B41: ✅ | C41: Requirement fully implemented and operational
A42: Partially Implemented | B42: ⚠️ | C42: Requirement partially met or limited coverage
A43: Not Implemented | B43: ❌ | C43: Requirement not implemented
A44: N/A | B44: N/A | C44: Not applicable to this environment
A47: ACCEPTABLE EVIDENCE (Examples)
A48: ✓ SDLC documentation (process flows, procedures, developer guides)
A49: ✓ Tool configurations (CI/CD pipelines, security scanner settings)
A50: ✓ Scan results (SAST/SCA/DAST reports with timestamps)
...

Sheet Security Requirements Design
A1: SDLC Assessment: Security Requirements & Design
A2: ID | B2: Requirement | C2: Implementation Status | D2: Evidence Reference | E2: Comments | F2: Compliance
A3: ▶ Requirements Definition
A4: 1.1 | B4: Security requirements are documented for all new development projects | D4: Requirements documents, user stories with security acceptance criteria, requirements management system records | F4: =IF(C4="Implemented","✅",IF(C4="Partially Implemented","⚠️",IF(C4="Not Implemented","❌",IF(C4="N/A","N/A",""))))
A5: 1.2 | B5: Threat modeling is performed for high-risk applications before implementation | D5: Threat model documents, STRIDE analysis, attack trees, threat modeling session notes | F5: =IF(C5="Implemented","✅",IF(C5="Partially Implemented","⚠️",IF(C5="Not Implemented","❌",IF(C5="N/A","N/A",""))))
A6: ▶ Design Review
A7: 1.3 | B7: Security design reviews are conducted before implementation begins | D7: Architecture review meeting notes, approved design documents, security sign-off records | F7: =IF(C7="Implemented","✅",IF(C7="Partially Implemented","⚠️",IF(C7="Not Implemented","❌",IF(C7="N/A","N/A",""))))
A8: ▶ Requirements Definition
A9: 1.4 | B9: Authentication and authorization requirements are defined upfront for all applications | D9: Security specifications, access control matrices, identity management requirements | F9: =IF(C9="Implemented","✅",IF(C9="Partially Implemented","⚠️",IF(C9="Not Implemented","❌",IF(C9="N/A","N/A",""))))
A10: 1.5 | B10: Data classification is performed for all data handled by applications | D10: Data classification register, data flow diagrams, data handling requirements | F10: =IF(C10="Implemented","✅",IF(C10="Partially Implemented","⚠️",IF(C10="Not Implemented","❌",IF(C10="N/A","N/A",""))))
A11: 1.6 | B11: Cryptographic requirements are specified when sensitive data is involved | D11: Crypto standards documentation, algorithm approval records, key management specs | F11: =IF(C11="Implemented","✅",IF(C11="Partially Implemented","⚠️",IF(C11="Not Implemented","❌",IF(C11="N/A","N/A",""))))
A12: ▶ Requirements Management
A13: 1.7 | B13: Security requirements are tracked throughout the entire SDLC | D13: Requirement traceability matrix, ticket system reports, requirements coverage metrics | F13: =IF(C13="Implemented","✅",IF(C13="Partially Implemented","⚠️",IF(C13="Not Implemented","❌",IF(C13="N/A","N/A",""))))
A14: ▶ Requirements Definition
A15: 1.8 | B15: Privacy requirements (GDPR, CCPA, etc.) are incorporated into design phase | D15: Privacy impact assessments, data protection by design documentation, consent mechanisms | F15: =IF(C15="Implemented","✅",IF(C15="Partially Implemented","⚠️",IF(C15="Not Implemented","❌",IF(C15="N/A","N/A",""))))
A16: ▶ Design Review
A17: 1.9 | B17: Secure coding standards are referenced in all project documentation | D17: Project wikis, coding guidelines links, onboarding documentation | F17: =IF(C17="Implemented","✅",IF(C17="Partially Implemented","⚠️",IF(C17="Not Implemented","❌",IF(C17="N/A","N/A",""))))
A18: ▶ Requirements Definition
A19: 1.10 | B19: Security acceptance criteria are defined for all user stories and features | D19: JIRA/Azure DevOps stories with security DoD, acceptance criteria templates | F19: =IF(C19="Implemented","✅",IF(C19="Partially Implemented","⚠️",IF(C19="Not Implemented","❌",IF(C19="N/A","N/A",""))))
A20: 1.11 | B20: API security requirements are documented for all APIs (internal and external) | D20: API security specifications, OpenAPI security schemes, API gateway policies | F20: =IF(C20="Implemented","✅",IF(C20="Partially Implemented","⚠️",IF(C20="Not Implemented","❌",IF(C20="N/A","N/A",""))))
A21: ▶ Design Review
A22: 1.12 | B22: Third-party integration security is assessed during design phase | D22: Vendor security assessments, integration security reviews, API security analysis | F22: =IF(C22="Implemented","✅",IF(C22="Partially Implemented","⚠️",IF(C22="Not Implemented","❌",IF(C22="N/A","N/A",""))))
A23: 1.13 | B23: Error handling and logging requirements are specified in design | D23: Logging standards, error handling patterns documentation, log retention policies | F23: =IF(C23="Implemented","✅",IF(C23="Partially Implemented","⚠️",IF(C23="Not Implemented","❌",IF(C23="N/A","N/A",""))))
A24: ▶ Requirements Definition
A25: 1.14 | B25: Security testing requirements are defined before development starts | D25: Test plans, security test case specifications, testing strategy documents | F25: =IF(C25="Implemented","✅",IF(C25="Partially Implemented","⚠️",IF(C25="Not Implemented","❌",IF(C25="N/A","N/A",""))))
A26: 1.15 | B26: Compliance requirements are mapped to technical controls in design | D26: Compliance mapping documents, control implementation matrix, regulatory requirements docs | F26: =IF(C26="Implemented","✅",IF(C26="Partially Implemented","⚠️",IF(C26="Not Implemented","❌",IF(C26="N/A","N/A",""))))
A27: ▶ Design Review
A28: 1.16 | B28: Security Champions are involved in requirements and design review | D28: Review meeting attendance, Security Champion feedback records, design review checklists | F28: =IF(C28="Implemented","✅",IF(C28="Partially Implemented","⚠️",IF(C28="Not Implemented","❌",IF(C28="N/A","N/A",""))))
A29: 1.17 | B29: Secure design patterns are documented and promoted for common scenarios | D29: Design pattern library, secure architecture templates, reference architectures | F29: =IF(C29="Implemented","✅",IF(C29="Partially Implemented","⚠️",IF(C29="Not Implemented","❌",IF(C29="N/A","N/A",""))))
A30: ▶ Requirements Definition
A31: 1.18 | B31: Security requirements are risk-based and proportional to data sensitivity | D31: Risk assessment documentation, security control selection justification | F31: =IF(C31="Implemented","✅",IF(C31="Partially Implemented","⚠️",IF(C31="Not Implemented","❌",IF(C31="N/A","N/A",""))))

Sheet Development Environment
A1: SDLC Assessment: Development Environment & Tooling
A2: ID | B2: Requirement | C2: Implementation Status | D2: Evidence Reference | E2: Comments | F2: Compliance
A3: ▶ Environment Security
A4: 2.1 | B4: Development environments are logically isolated from production systems | D4: Network diagrams, firewall rules, network segmentation documentation | F4: =IF(C4="Implemented","✅",IF(C4="Partially Implemented","⚠️",IF(C4="Not Implemented","❌",IF(C4="N/A","N/A",""))))
A5: ▶ Workstation Security
A6: 2.2 | B6: Developer workstations have mandatory security tooling installed (EDR, DLP, etc.) | D6: EDR deployment reports, endpoint security compliance dashboards, security agent status | F6: =IF(C6="Implemented","✅",IF(C6="Partially Implemented","⚠️",IF(C6="Not Implemented","❌",IF(C6="N/A","N/A",""))))
A7: ▶ Development Tools
A8: 2.3 | B8: IDE security plugins are available and promoted to all developers | D8: IDE plugin catalog, installation instructions, adoption metrics | F8: =IF(C8="Implemented","✅",IF(C8="Partially Implemented","⚠️",IF(C8="Not Implemented","❌",IF(C8="N/A","N/A",""))))
A9: 2.4 | B9: Pre-commit hooks prevent secret commits to version control | D9: Git hooks configuration, secret scanner setup (git-secrets, detect-secrets), violation reports | F9: =IF(C9="Implemented","✅",IF(C9="Partially Implemented","⚠️",IF(C9="Not Implemented","❌",IF(C9="N/A","N/A",""))))
A10: ▶ Repository Security
A11: 2.5 | B11: Code repositories require authentication and authorization (SSO/MFA) | D11: GitHub/GitLab access logs, SSO configuration, MFA enforcement policies | F11: =IF(C11="Implemented","✅",IF(C11="Partially Implemented","⚠️",IF(C11="Not Implemented","❌",IF(C11="N/A","N/A",""))))
A12: 2.6 | B12: Branch protection rules enforce mandatory peer review for production branches | D12: Repository settings screenshots, branch protection rules configuration, merge policies | F12: =IF(C12="Implemented","✅",IF(C12="Partially Implemented","⚠️",IF(C12="Not Implemented","❌",IF(C12="N/A","N/A",""))))
A13: ▶ Environment Security
A14: 2.7 | B14: Development and testing use anonymized or synthetic data (not production data) | D14: Data masking procedures, test data generation tools, data usage policies | F14: =IF(C14="Implemented","✅",IF(C14="Partially Implemented","⚠️",IF(C14="Not Implemented","❌",IF(C14="N/A","N/A",""))))
A15: ▶ Development Tools
A16: 2.8 | B16: Secrets management solution is available and documented for developers | D16: Vault/secrets manager documentation, developer usage guidelines, secrets rotation policies | F16: =IF(C16="Implemented","✅",IF(C16="Partially Implemented","⚠️",IF(C16="Not Implemented","❌",IF(C16="N/A","N/A",""))))
A17: ▶ Environment Security
A18: 2.9 | B18: Local development environments use HTTPS/TLS where applicable | D18: Development proxy configs, local cert management, TLS enforcement policies | F18: =IF(C18="Implemented","✅",IF(C18="Partially Implemented","⚠️",IF(C18="Not Implemented","❌",IF(C18="N/A","N/A",""))))
A19: ▶ Development Tools
A20: 2.10 | B20: Dependency management tools scan for vulnerabilities in developer environments | D20: npm audit, pip-audit, Dependabot integration, vulnerability scan results | F20: =IF(C20="Implemented","✅",IF(C20="Partially Implemented","⚠️",IF(C20="Not Implemented","❌",IF(C20="N/A","N/A",""))))
A21: ▶ Workstation Security
A22: 2.11 | B22: Development environment hardening guidelines exist and are enforced | D22: Developer workstation security baseline, configuration management records | F22: =IF(C22="Implemented","✅",IF(C22="Partially Implemented","⚠️",IF(C22="Not Implemented","❌",IF(C22="N/A","N/A",""))))
A23: ▶ Repository Security
A24: 2.12 | B24: Multi-factor authentication (MFA) is enforced for all code repository access | D24: MFA enforcement policies, authentication logs, MFA adoption metrics | F24: =IF(C24="Implemented","✅",IF(C24="Partially Implemented","⚠️",IF(C24="Not Implemented","❌",IF(C24="N/A","N/A",""))))
A25: ▶ Development Tools
A26: 2.13 | B26: Development tools and IDEs are kept up-to-date with security patches | D26: Tool version inventory, patch management records, software update policies | F26: =IF(C26="Implemented","✅",IF(C26="Partially Implemented","⚠️",IF(C26="Not Implemented","❌",IF(C26="N/A","N/A",""))))
A27: ▶ Training & Awareness
A28: 2.14 | B28: Secure coding training resources are accessible to all developers | D28: Training portal links, OWASP resources, internal wiki, training completion records | F28: =IF(C28="Implemented","✅",IF(C28="Partially Implemented","⚠️",IF(C28="Not Implemented","❌",IF(C28="N/A","N/A",""))))
A29: ▶ Environment Security
A30: 2.15 | B30: Development containers/VMs use secure, hardened base images | D30: Approved image catalog, image scanning results, base image security standards | F30: =IF(C30="Implemented","✅",IF(C30="Partially Implemented","⚠️",IF(C30="Not Implemented","❌",IF(C30="N/A","N/A",""))))
A31: ▶ Repository Security
A32: 2.16 | B32: Code repository activity is logged and monitored for anomalies | D32: Repository audit logs, SIEM integration, anomaly detection alerts | F32: =IF(C32="Implemented","✅",IF(C32="Partially Implemented","⚠️",IF(C32="Not Implemented","❌",IF(C32="N/A","N/A",""))))
A33: ▶ Development Tools
A34: 2.17 | B34: Personal access tokens and API keys have expiration policies | D34: Token lifecycle policies, key rotation procedures, token expiration reports | F34: =IF(C34="Implemented","✅",IF(C34="Partially Implemented","⚠️",IF(C34="Not Implemented","❌",IF(C34="N/A","N/A",""))))
A35: ▶ Training & Awareness
A36: 2.18 | B36: Developers have access to security documentation and secure code examples | D36: Internal security wiki, code example repository, secure coding cheat sheets | F36: =IF(C36="Implemented","✅",IF(C36="Partially Implemented","⚠️",IF(C36="Not Implemented","❌",IF(C36="N/A","N/A",""))))

Sheet Build Deployment Pipeline
A1: SDLC Assessment: Build & Deployment Pipeline
A2: ID | B2: Requirement | C2: Implementation Status | D2: Evidence Reference | E2: Comments | F2: Compliance
A3: ▶ Pipeline Security
A4: 3.1 | B4: CI/CD pipelines enforce automated security checks on every build | D4: Pipeline configuration files (Jenkinsfile, .gitlab-ci.yml), build logs showing security scans | F4: =IF(C4="Implemented","✅",IF(C4="Partially Implemented","⚠️",IF(C4="Not Implemented","❌",IF(C4="N/A","N/A",""))))
A5: ▶ Security Scanning
A6: 3.2 | B6: SAST (Static Application Security Testing) tools are integrated into build pipeline | D6: SAST scan results, tool integration config (SonarQube, Semgrep, Checkmarx) | F6: =IF(C6="Implemented","✅",IF(C6="Partially Implemented","⚠️",IF(C6="Not Implemented","❌",IF(C6="N/A","N/A",""))))
A7: 3.3 | B7: SCA (Software Composition Analysis) tools scan dependencies during every build | D7: SCA scan reports (Snyk, WhiteSource, Dependency-Check), vulnerability alerts | F7: =IF(C7="Implemented","✅",IF(C7="Partially Implemented","⚠️",IF(C7="Not Implemented","❌",IF(C7="N/A","N/A",""))))
A8: 3.4 | B8: Secret scanning runs automatically on every commit | D8: Secret scanner logs (TruffleHog, GitGuardian), detected secret alerts, remediation records | F8: =IF(C8="Implemented","✅",IF(C8="Partially Implemented","⚠️",IF(C8="Not Implemented","❌",IF(C8="N/A","N/A",""))))
A9: ▶ Artifact Security
A10: 3.5 | B10: Build artifacts are signed and signature verification is enforced | D10: Code signing certificates, artifact signatures, signature verification logs | F10: =IF(C10="Implemented","✅",IF(C10="Partially Implemented","⚠️",IF(C10="Not Implemented","❌",IF(C10="N/A","N/A",""))))
A11: ▶ Security Scanning
A12: 3.6 | B12: Container images are scanned for vulnerabilities before deployment | D12: Trivy/Clair/Anchore scan results, image vulnerability reports, scan policies | F12: =IF(C12="Implemented","✅",IF(C12="Partially Implemented","⚠️",IF(C12="Not Implemented","❌",IF(C12="N/A","N/A",""))))
A13: 3.7 | B13: Infrastructure-as-Code (IaC) is scanned for security misconfigurations | D13: Checkov/tfsec/Terrascan results, IaC security scan reports, policy violations | F13: =IF(C13="Implemented","✅",IF(C13="Partially Implemented","⚠️",IF(C13="Not Implemented","❌",IF(C13="N/A","N/A",""))))
A14: ▶ Pipeline Security
A15: 3.8 | B15: Build pipelines fail on critical or high severity vulnerabilities | D15: Pipeline failure logs, quality gate configuration, vulnerability threshold policies | F15: =IF(C15="Implemented","✅",IF(C15="Partially Implemented","⚠️",IF(C15="Not Implemented","❌",IF(C15="N/A","N/A",""))))
A16: ▶ Deployment Controls
A17: 3.9 | B17: Deployment to production requires explicit approval | D17: Approval workflows, deployment gate records, approval audit logs | F17: =IF(C17="Implemented","✅",IF(C17="Partially Implemented","⚠️",IF(C17="Not Implemented","❌",IF(C17="N/A","N/A",""))))
A18: ▶ Pipeline Security
A19: 3.10 | B19: Pipeline service accounts use least-privilege access principles | D19: Service account permissions, IAM policies, privilege reviews | F19: =IF(C19="Implemented","✅",IF(C19="Partially Implemented","⚠️",IF(C19="Not Implemented","❌",IF(C19="N/A","N/A",""))))
A20: 3.11 | B20: Build environments are ephemeral and disposable (not persistent) | D20: Build agent lifecycle documentation, container/VM configs, environment refresh logs | F20: =IF(C20="Implemented","✅",IF(C20="Partially Implemented","⚠️",IF(C20="Not Implemented","❌",IF(C20="N/A","N/A",""))))
A21: 3.12 | B21: Pipeline configurations are version-controlled and peer-reviewed | D21: CI/CD config files in git, change history, pipeline review records | F21: =IF(C21="Implemented","✅",IF(C21="Partially Implemented","⚠️",IF(C21="Not Implemented","❌",IF(C21="N/A","N/A",""))))
A22: ▶ Security Scanning
A23: 3.13 | B23: Security scan results are archived and historically trackable | D23: Scan result storage, historical trend reports, vulnerability tracking database | F23: =IF(C23="Implemented","✅",IF(C23="Partially Implemented","⚠️",IF(C23="Not Implemented","❌",IF(C23="N/A","N/A",""))))
A24: ▶ Deployment Controls
A25: 3.14 | B25: Rollback procedures are tested and documented | D25: Rollback runbooks, rollback test results, disaster recovery procedures | F25: =IF(C25="Implemented","✅",IF(C25="Partially Implemented","⚠️",IF(C25="Not Implemented","❌",IF(C25="N/A","N/A",""))))
A26: 3.15 | B26: Deployment logs are sent to centralised logging/SIEM | D26: SIEM integration, deployment audit logs, log retention policies | F26: =IF(C26="Implemented","✅",IF(C26="Partially Implemented","⚠️",IF(C26="Not Implemented","❌",IF(C26="N/A","N/A",""))))
A27: ▶ Pipeline Security
A28: 3.16 | B28: Pipeline secrets are managed securely (not hardcoded in configs) | D28: Secrets management integration, vault usage, secret rotation logs | F28: =IF(C28="Implemented","✅",IF(C28="Partially Implemented","⚠️",IF(C28="Not Implemented","❌",IF(C28="N/A","N/A",""))))
A29: ▶ Artifact Security
A30: 3.17 | B30: Build reproducibility is ensured (deterministic builds where possible) | D30: Build reproducibility documentation, dependency pinning, lockfiles | F30: =IF(C30="Implemented","✅",IF(C30="Partially Implemented","⚠️",IF(C30="Not Implemented","❌",IF(C30="N/A","N/A",""))))
A31: ▶ Security Scanning
A32: 3.18 | B32: Failed security scans trigger notifications to security team | D32: Alert configuration, notification logs, incident escalation procedures | F32: =IF(C32="Implemented","✅",IF(C32="Partially Implemented","⚠️",IF(C32="Not Implemented","❌",IF(C32="N/A","N/A",""))))

Sheet Security Testing Integration
A1: SDLC Assessment: Security Testing Integration
A2: ID | B2: Requirement | C2: Implementation Status | D2: Evidence Reference | E2: Comments | F2: Compliance
A3: ▶ Test Planning
A4: 4.1 | B4: Security test cases are written for all critical functionality | D4: Security test suite, test case repository, test coverage reports | F4: =IF(C4="Implemented","✅",IF(C4="Partially Implemented","⚠️",IF(C4="Not Implemented","❌",IF(C4="N/A","N/A",""))))
A5: ▶ Unit Testing
A6: 4.2 | B6: Unit tests include security-focused test cases (input validation, etc.) | D6: Unit test suites with security tests, code coverage reports | F6: =IF(C6="Implemented","✅",IF(C6="Partially Implemented","⚠️",IF(C6="Not Implemented","❌",IF(C6="N/A","N/A",""))))
A7: ▶ Integration Testing
A8: 4.3 | B8: Integration tests validate authentication and authorization mechanisms | D8: Integration test suites, auth test results, test scenarios | F8: =IF(C8="Implemented","✅",IF(C8="Partially Implemented","⚠️",IF(C8="Not Implemented","❌",IF(C8="N/A","N/A",""))))
A9: ▶ Dynamic Testing
A10: 4.4 | B10: DAST (Dynamic Application Security Testing) runs against staging environments | D10: DAST scan reports (OWASP ZAP, Burp Suite, Acunetix), vulnerability findings | F10: =IF(C10="Implemented","✅",IF(C10="Partially Implemented","⚠️",IF(C10="Not Implemented","❌",IF(C10="N/A","N/A",""))))
A11: ▶ API Testing
A12: 4.5 | B12: API security testing is performed (fuzzing, schema validation, injection tests) | D12: API test results, fuzzing reports, Postman/REST Assured test suites | F12: =IF(C12="Implemented","✅",IF(C12="Partially Implemented","⚠️",IF(C12="Not Implemented","❌",IF(C12="N/A","N/A",""))))
A13: ▶ Penetration Testing
A14: 4.6 | B14: Penetration testing is conducted for high-risk applications annually | D14: Pentest reports, findings tracking, remediation validation | F14: =IF(C14="Implemented","✅",IF(C14="Partially Implemented","⚠️",IF(C14="Not Implemented","❌",IF(C14="N/A","N/A",""))))
A15: ▶ Regression Testing
A16: 4.7 | B16: Security regression tests prevent reintroduction of known vulnerabilities | D16: Regression test suite, vulnerability fix validation tests | F16: =IF(C16="Implemented","✅",IF(C16="Partially Implemented","⚠️",IF(C16="Not Implemented","❌",IF(C16="N/A","N/A",""))))
A17: ▶ Test Environment
A18: 4.8 | B18: Test environments mirror production security configurations | D18: Environment parity documentation, configuration comparisons | F18: =IF(C18="Implemented","✅",IF(C18="Partially Implemented","⚠️",IF(C18="Not Implemented","❌",IF(C18="N/A","N/A",""))))
A19: ▶ Test Automation
A20: 4.9 | B20: Automated security tests run in CI/CD pipeline on every build | D20: Pipeline test execution logs, automated test results | F20: =IF(C20="Implemented","✅",IF(C20="Partially Implemented","⚠️",IF(C20="Not Implemented","❌",IF(C20="N/A","N/A",""))))
A21: ▶ Test Planning
A22: 4.10 | B22: Security testing results are reviewed before release approval | D22: Release gate checklists, security sign-off records, test result reviews | F22: =IF(C22="Implemented","✅",IF(C22="Partially Implemented","⚠️",IF(C22="Not Implemented","❌",IF(C22="N/A","N/A",""))))
A23: ▶ Performance Testing
A24: 4.11 | B24: Performance testing includes assessment of security control overhead | D24: Load test results with security controls enabled, performance baselines | F24: =IF(C24="Implemented","✅",IF(C24="Partially Implemented","⚠️",IF(C24="Not Implemented","❌",IF(C24="N/A","N/A",""))))
A25: ▶ External Testing
A26: 4.12 | B26: Bug bounty or responsible disclosure program provides external testing | D26: Bug bounty platform reports (HackerOne, Bugcrowd), vulnerability submissions | F26: =IF(C26="Implemented","✅",IF(C26="Partially Implemented","⚠️",IF(C26="Not Implemented","❌",IF(C26="N/A","N/A",""))))
A27: ▶ Test Planning
A28: 4.13 | B28: Security Champions participate in test planning and review | D28: Test planning meeting notes, Security Champion involvement records | F28: =IF(C28="Implemented","✅",IF(C28="Partially Implemented","⚠️",IF(C28="Not Implemented","❌",IF(C28="N/A","N/A",""))))
A29: ▶ Test Automation
A30: 4.14 | B30: Failed security tests block deployment to production | D30: Quality gate configuration, blocked deployment logs, override procedures | F30: =IF(C30="Implemented","✅",IF(C30="Partially Implemented","⚠️",IF(C30="Not Implemented","❌",IF(C30="N/A","N/A",""))))
A31: ▶ Test Planning
A32: 4.15 | B32: Security test coverage is measured and tracked over time | D32: Coverage metrics, security test inventory, trend analysis | F32: =IF(C32="Implemented","✅",IF(C32="Partially Implemented","⚠️",IF(C32="Not Implemented","❌",IF(C32="N/A","N/A",""))))
A33: ▶ Integration Testing
A34: 4.16 | B34: Authentication and session management are thoroughly tested | D34: Auth test scenarios, session security tests, credential handling tests | F34: =IF(C34="Implemented","✅",IF(C34="Partially Implemented","⚠️",IF(C34="Not Implemented","❌",IF(C34="N/A","N/A",""))))
A35: ▶ API Testing
A36: 4.17 | B36: Input validation testing covers all user input vectors | D36: Input validation test cases, injection testing results, fuzzing outputs | F36: =IF(C36="Implemented","✅",IF(C36="Partially Implemented","⚠️",IF(C36="Not Implemented","❌",IF(C36="N/A","N/A",""))))
A37: ▶ Test Environment
A38: 4.18 | B38: Security test data is maintained separately from production data | D38: Test data management procedures, synthetic data generation tools | F38: =IF(C38="Implemented","✅",IF(C38="Partially Implemented","⚠️",IF(C38="Not Implemented","❌",IF(C38="N/A","N/A",""))))

Sheet Release Change Management
A1: SDLC Assessment: Release & Change Management
A2: ID | B2: Requirement | C2: Implementation Status | D2: Evidence Reference | E2: Comments | F2: Compliance
A3: ▶ Release Process
A4: 5.1 | B4: Security review is mandatory for all production releases | D4: Release checklists with security sign-off, security review records | F4: =IF(C4="Implemented","✅",IF(C4="Partially Implemented","⚠️",IF(C4="Not Implemented","❌",IF(C4="N/A","N/A",""))))
A5: ▶ Release Documentation
A6: 5.2 | B6: Release notes document all security-relevant changes | D6: Release notes, change logs with security tags, security update notifications | F6: =IF(C6="Implemented","✅",IF(C6="Partially Implemented","⚠️",IF(C6="Not Implemented","❌",IF(C6="N/A","N/A",""))))
A7: ▶ Change Management
A8: 5.3 | B8: Emergency hotfix process includes security assessment | D8: Hotfix procedures, emergency change records, security review logs | F8: =IF(C8="Implemented","✅",IF(C8="Partially Implemented","⚠️",IF(C8="Not Implemented","❌",IF(C8="N/A","N/A",""))))
A9: ▶ Release Process
A10: 5.4 | B10: Rollback plans are prepared and tested for all production releases | D10: Rollback procedures, rollback test results, disaster recovery plans | F10: =IF(C10="Implemented","✅",IF(C10="Partially Implemented","⚠️",IF(C10="Not Implemented","❌",IF(C10="N/A","N/A",""))))
A11: 5.5 | B11: Post-deployment verification includes security checks | D11: Smoke test results, security validation logs, post-deployment checklists | F11: =IF(C11="Implemented","✅",IF(C11="Partially Implemented","⚠️",IF(C11="Not Implemented","❌",IF(C11="N/A","N/A",""))))
A12: ▶ Patch Management
A13: 5.6 | B13: Security patches are prioritised and tracked with defined SLAs | D13: Security patch SLA, vulnerability remediation tracker, patching metrics | F13: =IF(C13="Implemented","✅",IF(C13="Partially Implemented","⚠️",IF(C13="Not Implemented","❌",IF(C13="N/A","N/A",""))))
A14: ▶ Change Management
A15: 5.7 | B15: Configuration changes follow formal change management process | D15: Change requests, CAB approval records, configuration change logs | F15: =IF(C15="Implemented","✅",IF(C15="Partially Implemented","⚠️",IF(C15="Not Implemented","❌",IF(C15="N/A","N/A",""))))
A16: ▶ Access Control
A17: 5.8 | B17: Production access is logged, monitored, and reviewed | D17: Production access logs, privileged access monitoring, access reviews | F17: =IF(C17="Implemented","✅",IF(C17="Partially Implemented","⚠️",IF(C17="Not Implemented","❌",IF(C17="N/A","N/A",""))))
A18: ▶ Release Process
A19: 5.9 | B19: Feature flags enable controlled rollout of security features | D19: Feature flag configurations, gradual rollout plans, feature toggle logs | F19: =IF(C19="Implemented","✅",IF(C19="Partially Implemented","⚠️",IF(C19="Not Implemented","❌",IF(C19="N/A","N/A",""))))
A20: ▶ Release Documentation
A21: 5.10 | B21: Security metrics are collected and reviewed post-release | D21: Post-release security reports, incident metrics, security KPI dashboards | F21: =IF(C21="Implemented","✅",IF(C21="Partially Implemented","⚠️",IF(C21="Not Implemented","❌",IF(C21="N/A","N/A",""))))
A22: 5.11 | B22: Communication plan exists for security-relevant releases | D22: Communication templates, stakeholder notification logs, security bulletins | F22: =IF(C22="Implemented","✅",IF(C22="Partially Implemented","⚠️",IF(C22="Not Implemented","❌",IF(C22="N/A","N/A",""))))
A23: ▶ Release Process
A24: 5.12 | B24: Release frequency balances security needs with business velocity | D24: Release calendar, security vs. feature delivery metrics, deployment frequency | F24: =IF(C24="Implemented","✅",IF(C24="Partially Implemented","⚠️",IF(C24="Not Implemented","❌",IF(C24="N/A","N/A",""))))
A25: ▶ Patch Management
A26: 5.13 | B26: Post-incident releases are tracked and undergo enhanced scrutiny | D26: Incident-driven release logs, security fix tracking, post-incident reviews | F26: =IF(C26="Implemented","✅",IF(C26="Partially Implemented","⚠️",IF(C26="Not Implemented","❌",IF(C26="N/A","N/A",""))))
A27: ▶ Release Documentation
A28: 5.14 | B28: Compliance artifacts are updated with each relevant release | D28: Compliance documentation updates, attestation records, audit trail | F28: =IF(C28="Implemented","✅",IF(C28="Partially Implemented","⚠️",IF(C28="Not Implemented","❌",IF(C28="N/A","N/A",""))))
A29: ▶ Continuous Improvement
A30: 5.15 | B30: Lessons learned from security issues feed into process improvements | D30: Retrospective notes, security improvement backlog, process change records | F30: =IF(C30="Implemented","✅",IF(C30="Partially Implemented","⚠️",IF(C30="Not Implemented","❌",IF(C30="N/A","N/A",""))))
A31: ▶ Release Process
A32: 5.16 | B32: Release approvals require sign-off from security stakeholders | D32: Approval workflow records, security sign-off documentation | F32: =IF(C32="Implemented","✅",IF(C32="Partially Implemented","⚠️",IF(C32="Not Implemented","❌",IF(C32="N/A","N/A",""))))
A33: ▶ Release Documentation
A34: 5.17 | B34: Version control and release tags are properly maintained | D34: Git tags, release versioning records, artifact version tracking | F34: =IF(C34="Implemented","✅",IF(C34="Partially Implemented","⚠️",IF(C34="Not Implemented","❌",IF(C34="N/A","N/A",""))))
A35: 5.18 | B35: Security scan results are archived with release artifacts | D35: Scan result archives, release documentation bundles, compliance packages | F35: =IF(C35="Implemented","✅",IF(C35="Partially Implemented","⚠️",IF(C35="Not Implemented","❌",IF(C35="N/A","N/A",""))))

Sheet Summary Dashboard
A1: SDLC Assessment - Summary Dashboard
A3: Assessment Date: | B3: =Instructions!B8
A4: Assessor: | B4: =Instructions!B9
A5: Organisation: | B5: =Instructions!B10
A7: Overall SDLC Compliance Score: | C7: =(COUNTIF('Security Requirements Design'!C:C,"Implemented")+ COUNTIF('Development Environment'!C:C,"Implemented")+ COUNTIF('Build Deployment Pipeline'!C:C,"Implemented")+ COUNTIF('Security Testing Integration'!C:C,"Implemented")+ COUNTIF('Release Change Management'!C:C,"Implemented"))/ (COUNTA('Security Requirements Design'!C:C)+ COUNTA('Development Environment'!C:C)+ COUNTA('Build Deployment Pipeline'!C:C)+ COUNTA('Security Testing Integration'!C:C)+ COUNTA('Release Change Management'!C:C)-5- COUNTIF('Security Requirements Design'!C:C,"N/A")- COUNTIF('Development Environment'!C:C,"N/A")- COUNTIF('Build Deployment Pipeline'!C:C,"N/A")- COUNTIF('Security Testing Integration'!C:C,"N/A")- COUNTIF('Release Change Management'!C:C,"N/A")) | D7: =IF(C7>=0.8,"🟢 Compliant",IF(C7>=0.6,"🟡 Needs Improvement","🔴 Non-Compliant"))
A10: Domain Compliance Breakdown
A11: Domain | B11: Compliance % | C11: Status | D11: Not Implemented | E11: Partially Implemented
A12: 1. Security Requirements & Design | B12: =COUNTIF('Security Requirements Design'!C:C,"Implemented")/(COUNTA('Security Requirements Design'!C:C)-1-COUNTIF('Security Requirements Design'!C:C,"N/A")) | C12: =IF(B12>=0.8,"🟢",IF(B12>=0.6,"🟡","🔴")) | D12: =COUNTIF('Security Requirements Design'!C:C,"Not Implemented") | E12: =COUNTIF('Security Requirements Design'!C:C,"Partially Implemented")
A13: 2. Development Environment & Tooling | B13: =COUNTIF('Development Environment'!C:C,"Implemented")/(COUNTA('Development Environment'!C:C)-1-COUNTIF('Development Environment'!C:C,"N/A")) | C13: =IF(B13>=0.8,"🟢",IF(B13>=0.6,"🟡","🔴")) | D13: =COUNTIF('Development Environment'!C:C,"Not Implemented") | E13: =COUNTIF('Development Environment'!C:C,"Partially Implemented")
A14: 3. Build & Deployment Pipeline | B14: =COUNTIF('Build Deployment Pipeline'!C:C,"Implemented")/(COUNTA('Build Deployment Pipeline'!C:C)-1-COUNTIF('Build Deployment Pipeline'!C:C,"N/A")) | C14: =IF(B14>=0.8,"🟢",IF(B14>=0.6,"🟡","🔴")) | D14: =COUNTIF('Build Deployment Pipeline'!C:C,"Not Implemented") | E14: =COUNTIF('Build Deployment Pipeline'!C:C,"Partially Implemented")
A15: 4. Security Testing Integration | B15: =COUNTIF('Security Testing Integration'!C:C,"Implemented")/(COUNTA('Security Testing Integration'!C:C)-1-COUNTIF('Security Testing Integration'!C:C,"N/A")) | C15: =IF(B15>=0.8,"🟢",IF(B15>=0.6,"🟡","🔴")) | D15: =COUNTIF('Security Testing Integration'!C:C,"Not Implemented") | E15: =COUNTIF('Security Testing Integration'!C:C,"Partially Implemented")
A16: 5. Release & Change Management | B16: =COUNTIF('Release Change Management'!C:C,"Implemented")/(COUNTA('Release Change Management'!C:C)-1-COUNTIF('Release Change Management'!C:C,"N/A")) | C16: =IF(B16>=0.8,"🟢",IF(B16>=0.6,"🟡","🔴")) | D16: =COUNTIF('Release Change Management'!C:C,"Not Implemented") | E16: =COUNTIF('Release Change Management'!C:C,"Partially Implemented")
A18: Summary Statistics
A19: Total Requirements Assessed: | B19: =COUNTA('Security Requirements Design'!C:C)+COUNTA('Development Environment'!C:C)+COUNTA('Build Deployment Pipeline'!C:C)+COUNTA('Security Testing Integration'!C:C)+COUNTA('Release Change Management'!C:C)-5
A20: Implemented: | B20: =COUNTIF('Security Requirements Design'!C:C,"Implemented")+COUNTIF('Development Environment'!C:C,"Implemented")+COUNTIF('Build Deployment Pipeline'!C:C,"Implemented")+COUNTIF('Security Testing Integration'!C:C,"Implemented")+COUNTIF('Release Change Management'!C:C,"Implemented")
A21: Partially Implemented: | B21: =COUNTIF('Security Requirements Design'!C:C,"Partially Implemented")+COUNTIF('Development Environment'!C:C,"Partially Implemented")+COUNTIF('Build Deployment Pipeline'!C:C,"Partially Implemented")+COUNTIF('Security Testing Integration'!C:C,"Partially Implemented")+COUNTIF('Release Change Management'!C:C,"Partially Implemented")
A22: Not Implemented: | B22: =COUNTIF('Security Requirements Design'!C:C,"Not Implemented")+COUNTIF('Development Environment'!C:C,"Not Implemented")+COUNTIF('Build Deployment Pipeline'!C:C,"Not Implemented")+COUNTIF('Security Testing Integration'!C:C,"Not Implemented")+COUNTIF('Release Change Management'!C:C,"Not Implemented")
A23: Not Applicable (N/A): | B23: =COUNTIF('Security Requirements Design'!C:C,"N/A")+COUNTIF('Development Environment'!C:C,"N/A")+COUNTIF('Build Deployment Pipeline'!C:C,"N/A")+COUNTIF('Security Testing Integration'!C:C,"N/A")+COUNTIF('Release Change Management'!C:C,"N/A")
A25: Recommendations
A26: • Focus remediation efforts on 'Not Implemented' items first, then 'Partially Implemented'
A27: • Prioritize gaps in Build & Deployment Pipeline - these provide automated security controls
A28: • Document all evidence thoroughly - lack of evidence ≠ lack of implementation
A29: • Review 'N/A' items carefully - are they genuinely not applicable or just difficult?
A30: • Set target dates for all gaps in the Gap Analysis sheet
A31: • Schedule quarterly re-assessments to track improvement

Sheet Evidence Register
A1: Evidence Register
A2: Document all evidence supporting your SDLC assessment. Each requirement should have traceable evidence.
A3: Evidence ID | B3: Related Requirement | C3: Evidence Type | D3: Description | E3: Location/Link | F3: Collection Date | G3: Collected By
A4: E001 | B4: 1.1 - Security Requirements | C4: Document | D4: SDLC Process Documentation | E4: https://wiki.company.com/sdlc | F4: 01.01.2025 | G4: Security Team
A5: E002 | B5: 3.2 - SAST Integration | C5: Screenshot | D5: SonarQube Pipeline Configuration | E5: file://evidence/sonarqube_config.png | F5: 05.01.2025 | G5: DevOps Lead
A6: E003 | B6: 4.4 - DAST Scanning | C6: Report | D6: OWASP ZAP Scan Results | E6: https://security-portal.company.com/reports/zap/ | F6: 06.01.2025 | G6: Security Analyst

Sheet Gap Analysis
A1: Gap Analysis & Remediation Plan
A2: Document all 'Not Implemented' and 'Partially Implemented' requirements. Assign owners, set target dates, and track remediation progress.
A3: Gap ID | B3: Domain | C3: Requirement ID | D3: Requirement Description | E3: Current State | F3: Target State | G3: Priority | H3: Owner | I3: Target Date | J3: Status
A4: GAP-001 | B4: Development Environment | C4: 2.4 | D4: Pre-commit hooks prevent secret commits | E4: No pre-commit hooks configured | F4: Git-secrets installed on all dev workstations | G4: High | H4: DevOps Lead | I4: 31.01.2025 | J4: In Progress
A5: GAP-002 | B5: Build Pipeline | C5: 3.2 | D5: SAST tools integrated into build pipeline | E5: SAST runs manually, not in pipeline | F5: SonarQube integrated with automated quality gates | G5: Critical | H5: CI/CD Engineer | I5: 15.02.2025 | J5: Open
A6: GAP-003 | B6: Security Testing | C6: 4.4 | D6: DAST runs against staging | E6: No DAST scanning performed | F6: OWASP ZAP automated scans before production | G6: High | H6: Security Team | I6: 28.02.2025 | J6: Open
A8: Priority Guidance:
A9: Critical: Exploitable vulnerability or compliance blocker - fix immediately
A10: High: Significant security risk or major compliance gap - fix within 30 days
A11: Medium: Moderate security risk or minor compliance gap - fix within 90 days
A12: Low: Low security risk or improvement opportunity - fix when resources available

Sheet Approval Sign-Off
A1: SDLC Assessment - Approval Sign-Off
A2: Formal approval workflow for assessment completion
A4: ASSESSMENT SUMMARY
A6: Assessment Date: | B6: =Instructions!B8
A7: Assessor Name: | B7: =Instructions!B9
A8: Organisation: | B8: =Instructions!B10
A9: Overall Compliance Score: | B9: ='Summary Dashboard'!C7
A10: Compliance Status: | B10: ='Summary Dashboard'!D7
A13: KEY FINDINGS
A15: Total Requirements: | B15: ='Summary Dashboard'!B19
A16: Implemented: | B16: ='Summary Dashboard'!B20
A17: Partially Implemented: | B17: ='Summary Dashboard'!B21
A18: Not Implemented: | B18: ='Summary Dashboard'!B22
A19: Not Applicable: | B19: ='Summary Dashboard'!B23
A22: APPROVAL WORKFLOW
A23: Role | B23: Name | C23: Signature | D23: Date
A24: Assessment Completer
A25: Application Security Lead
A26: Development Manager / Engineering Lead
A27: CISO / Security Director
A29: APPROVAL NOTES / CONDITIONS
A30: Enter any conditions, exceptions, or notes related to this approval:
A37: APPROVAL CRITERIA
A38: ✓ All assessment domains have been completed
A39: ✓ Evidence references are provided for all 'Implemented' claims
A40: ✓ Gap Analysis sheet documents all 'Not Implemented' items
A41: ✓ Remediation plans include owners and target dates
A42: ✓ Assessment findings are accurate and verifiable
A43: ✓ Summary Dashboard reflects true compliance posture
