Workbook

Sheet Executive Summary
A1: ISMS-OP-CHK-A.6.4-5 — Disciplinary Process and Employment Exit Compliance Checklist
A3: DOCUMENT INFORMATION
A4: Document ID | B4: ISMS-OP-CHK-A.6.4-5
A5: Source Policy | B5: ISMS-OP-POL-A.6.4-5
A6: ISO Controls | B6: Disciplinary Process and Employment Exit
A7: Generated | B7: 30.09.2026
A8: Prepared By
A9: Organisation
A10: Review Cycle | B10: Annual
A12: OVERALL COMPLIANCE STATUS
A13: Overall Compliance | B13: ='Dashboard'!G7
A14: Status | B14: =IF(Dashboard!H7>0,"INCOMPLETE",IF(Dashboard!G7="N/A","NOT ASSESSED",IF(ISNUMBER(VALUE(SUBSTITUTE(Dashboard!G7,"%",""))),IF(VALUE(SUBSTITUTE(Dashboard!G7,"%",""))>=90,"GREEN",IF(VALUE(SUBSTITUTE(Dashboard!G7,"%",""))>=70,"AMBER","RED")),"NOT ASSESSED")))
A16: KEY METRICS
A17: Total Requirements | B17: ='Dashboard'!B7
A18: Compliant | B18: ='Dashboard'!C7
A19: Partial | B19: ='Dashboard'!D7
A20: Non-Compliant | B20: ='Dashboard'!E7
A21: Not Applicable | B21: ='Dashboard'!F7
A22: Unanswered | B22: ='Dashboard'!H7
A23: Owner Coverage | B23: =IF(Dashboard!B7=0,"N/A",ROUND((COUNTA('Disciplinary Framework'!F4:F17)+COUNTA('Employment Exit'!F4:F17)+COUNTA('Compliance Measurement'!F4:F4))/Dashboard!B7*100,0)&"%")
A25: DOMAIN STATUS SUMMARY
A26: Domain | B26: Compliance % | C26: Compliant | D26: Gaps | E26: Status
A27: Disciplinary Framework | B27: ='Dashboard'!G4 | C27: ='Dashboard'!C4 | D27: ='Dashboard'!E4 | E27: =IF(Dashboard!H4>0,"INCOMPLETE",IF(Dashboard!G4="N/A","--",IF(ISNUMBER(VALUE(SUBSTITUTE(Dashboard!G4,"%",""))),IF(VALUE(SUBSTITUTE(Dashboard!G4,"%",""))>=90,"PASS",IF(VALUE(SUBSTITUTE(Dashboard!G4,"%",""))>=70,"REVIEW","FAIL")),"--")))
A28: Employment Exit | B28: ='Dashboard'!G5 | C28: ='Dashboard'!C5 | D28: ='Dashboard'!E5 | E28: =IF(Dashboard!H5>0,"INCOMPLETE",IF(Dashboard!G5="N/A","--",IF(ISNUMBER(VALUE(SUBSTITUTE(Dashboard!G5,"%",""))),IF(VALUE(SUBSTITUTE(Dashboard!G5,"%",""))>=90,"PASS",IF(VALUE(SUBSTITUTE(Dashboard!G5,"%",""))>=70,"REVIEW","FAIL")),"--")))
A29: Compliance Measurement | B29: ='Dashboard'!G6 | C29: ='Dashboard'!C6 | D29: ='Dashboard'!E6 | E29: =IF(Dashboard!H6>0,"INCOMPLETE",IF(Dashboard!G6="N/A","--",IF(ISNUMBER(VALUE(SUBSTITUTE(Dashboard!G6,"%",""))),IF(VALUE(SUBSTITUTE(Dashboard!G6,"%",""))>=90,"PASS",IF(VALUE(SUBSTITUTE(Dashboard!G6,"%",""))>=70,"REVIEW","FAIL")),"--")))
A31: CRITICAL ISSUES
A32: # | B32: Issue Description | C32: Domain | D32: Owner | E32: Due Date
A33: 1
A34: 2
A35: 3
A36: 4
A37: 5
A39: MANAGEMENT COMMENTARY
A40: [Enter management commentary on disciplinary process and employment exit posture]
A44: APPROVAL
A45: Assessed By
A46: Name:
A47: Date:
A48: Signature:
A49: Decision:
...

Sheet Dashboard
A1: Disciplinary Process and Employment Exit — Compliance Dashboard
A3: Domain | B3: Total Reqs | C3: Compliant | D3: Partial | E3: Non-Compliant | F3: N/A | G3: Compliance % | H3: Unassessed
A4: Disciplinary Framework | B4: =COUNTA('Disciplinary Framework'!A4:A17) | C4: =COUNTIF('Disciplinary Framework'!D4:D17,"Compliant") | D4: =COUNTIF('Disciplinary Framework'!D4:D17,"Partial") | E4: =COUNTIF('Disciplinary Framework'!D4:D17,"Non-Compliant") | F4: =COUNTIF('Disciplinary Framework'!D4:D17,"N/A") | G4: =IF((B4-F4)=0,"N/A",ROUND(C4/(B4-F4)*100,1)&"%") | H4: =B4-(C4+D4+E4+F4)
A5: Employment Exit | B5: =COUNTA('Employment Exit'!A4:A17) | C5: =COUNTIF('Employment Exit'!D4:D17,"Compliant") | D5: =COUNTIF('Employment Exit'!D4:D17,"Partial") | E5: =COUNTIF('Employment Exit'!D4:D17,"Non-Compliant") | F5: =COUNTIF('Employment Exit'!D4:D17,"N/A") | G5: =IF((B5-F5)=0,"N/A",ROUND(C5/(B5-F5)*100,1)&"%") | H5: =B5-(C5+D5+E5+F5)
A6: Compliance Measurement | B6: =COUNTA('Compliance Measurement'!A4:A4) | C6: =COUNTIF('Compliance Measurement'!D4:D4,"Compliant") | D6: =COUNTIF('Compliance Measurement'!D4:D4,"Partial") | E6: =COUNTIF('Compliance Measurement'!D4:D4,"Non-Compliant") | F6: =COUNTIF('Compliance Measurement'!D4:D4,"N/A") | G6: =IF((B6-F6)=0,"N/A",ROUND(C6/(B6-F6)*100,1)&"%") | H6: =B6-(C6+D6+E6+F6)
A7: TOTAL | B7: =SUM(B4:B6) | C7: =SUM(C4:C6) | D7: =SUM(D4:D6) | E7: =SUM(E4:E6) | F7: =SUM(F4:F6) | G7: =IF((B7-F7)=0,"N/A",ROUND(C7/(B7-F7)*100,1)&"%") | H7: =SUM(H4:H6)
A9: COMPLIANCE BY STATUS
A10: Compliant | B10: =C7 | C10: =IF(B7=0,"",ROUND(B10/B7*100,1)&"%")
A11: Partial | B11: =D7 | C11: =IF(B7=0,"",ROUND(B11/B7*100,1)&"%")
A12: Non-Compliant | B12: =E7 | C12: =IF(B7=0,"",ROUND(B12/B7*100,1)&"%")
A13: N/A | B13: =F7 | C13: =IF(B7=0,"",ROUND(B13/B7*100,1)&"%")
A15: TOP GAPS (Manual Entry)
A16: Priority | B16: Domain | C16: Requirement | D16: Owner | E16: Due Date | F16: Status
A28: COMPLIANCE TREND (Manual Entry)
A29: Assessment Date | B29: Overall % | C29: Compliant | D29: Gaps | E29: Assessor | F29: Notes

Sheet Disciplinary Framework
A1: Disciplinary Framework — Compliance Checklist
A2: ISO/IEC 27001:2022 — Controls A.6.4-5: Disciplinary Process and Employment Exit
A3: Req # | B3: Section | C3: Requirement | D3: Status | E3: Evidence | F3: Owner | G3: Due Date | H3: Notes
A4: A.6.4-5-01 | B4: The Disciplinary Process | C4: The disciplinary process shall be:.
A5: A.6.4-5-02 | B5: Proportionate — The Response | C5: Proportionate — the response shall match the severity of the violation and its consequences.
A6: A.6.4-5-03 | B6: The Following Five-Step Procedure | C6: The following five-step procedure shall be followed for all information security violations:.
A7: A.6.4-5-04 | B7: Be Collected In A Manner That | C7: Evidence shall be collected in a manner that respects the individual's rights under Swiss CO Art. 328 and nFADP. The chain of custody shall be documented.
A8: A.6.4-5-05 | B8: Step 4 — Investigation*: A Formal | C8: Step 4 — Investigation*: A formal investigation is conducted, including interviews with the individual concerned, witnesses, and relevant managers. The individual shall be informed of the nature of the allegations and given the opportunity to respond. For serious or gross misconduct cases, Legal Counsel shall be consulted.
A9: A.6.4-5-06 | B9: The Following Due Process Requirements | C9: The following due process requirements shall be observed in all disciplinary proceedings, in compliance with Swiss CO Art. 328 (employer's duty of care):.
A10: A.6.4-5-07 | B10: The Individual | C10: The individual shall be informed of the specific allegations in writing before any disciplinary hearing.
A11: A.6.4-5-08 | B11: The Individual | C11: The individual shall be given a reasonable opportunity to respond to the allegations, including time to prepare.
A12: A.6.4-5-09 | B12: The Individual | C12: The individual shall have the right to representation at disciplinary meetings (e.g., a colleague, trade union representative, or legal advisor, as permitted under applicable employment law).
A13: A.6.4-5-10 | B13: An Appeals Process | C13: An appeals process shall be available:.
A14: A.6.4-5-11 | B14: Be Maintained Confidentially, With | C14: All documentation shall be maintained confidentially, with access restricted to those with a legitimate need to know.
A15: A.6.4-5-12 | B15: The Individual'S Personal Data Processed | C15: The individual's personal data processed during the investigation shall be handled in accordance with nFADP and the organisation's Privacy and Protection of PII Policy.
... A17: A.6.4-5-14 | B17: Regulatory Notification*: Where A | C17: Regulatory notification*: Where a disciplinary matter involves a confirmed or suspected personal data breach, the organisation shall assess notification obligations:.

Sheet Employment Exit
A1: Employment Exit — Compliance Checklist
A2: ISO/IEC 27001:2022 — Controls A.6.4-5: Disciplinary Process and Employment Exit
A3: Req # | B3: Section | C3: Requirement | D3: Status | E3: Evidence | F3: Owner | G3: Due Date | H3: Notes
A4: A.6.4-5-15 | B4: Be Revoked According To The Following | C4: Access shall be revoked according to the following timelines based on termination type:.
A5: A.6.4-5-16 | B5: Before Executing Immediate Dismissal, | C5: Before executing immediate dismissal, the following procedural safeguards shall be observed:.
A6: A.6.4-5-17 | B6: Compensating Controls When Sla Cannot Be | C6: Compensating controls when SLA cannot be met: If full revocation across all systems cannot be completed within the SLA, the following compensating controls shall be applied immediately* while full revocation is completed:.
A7: A.6.4-5-18 | B7: A Nonconformity Or Exception Record | C7: A nonconformity or exception record shall be created for any SLA breach, with root cause analysis and remediation tracked to closure per the corrective action process.
A8: A.6.4-5-19 | B8: Access Types | C8: All access types shall be addressed during the offboarding process:.
A9: A.6.4-5-20 | B9: Follow This Priority Order | C9: Where the departing individual holds privileged access, revocation shall follow this priority order:.
A10: A.6.4-5-21 | B10: Recover All Organisational Assets Upon | C10: The organisation shall recover all organisational assets upon termination or change of employment.
A11: A.6.4-5-22 | B11: Continuing Obligations | C11: Continuing obligations shall be communicated to the departing individual in writing before or on the last working day:.
A12: A.6.4-5-23 | B12: Organisational Information In The | C12: All organisational information in the individual's possession shall be returned or certified as destroyed.
A13: A.6.4-5-24 | B13: The Individual | C13: The individual shall confirm in writing that no organisational data has been retained on personal devices, personal cloud storage, or personal email accounts.
A14: A.6.4-5-25 | B14: Verification Of Data Return Or Deletion | C14: Verification of data return or deletion shall use the following lawful, risk-proportionate methods:.
A15: A.6.4-5-26 | B15: No Forced Inspection Of Personal Devices | C15: No forced inspection of personal devices: The organisation shall not compel inspection of personal devices without the individual's consent. Where consent is refused and risk is assessed as high, Legal Counsel shall advise on available remedies under Swiss law.
... A17: A.6.4-5-28 | B17: Exit Interviews | C17: Exit interviews shall be conducted by HR with input from the Information Security Team where the departing individual had access to Confidential or Restricted data, held privileged system access, or is departing under disciplinary circumstances.

Sheet Compliance Measurement
A1: Compliance Measurement — Compliance Checklist
A2: ISO/IEC 27001:2022 — Controls A.6.4-5: Disciplinary Process and Employment Exit
A3: Req # | B3: Section | C3: Requirement | D3: Status | E3: Evidence | F3: Owner | G3: Due Date | H3: Notes
A4: A.6.4-5-29 | B4: Be Reported To The Ciso Monthly | C4: Metrics shall be reported to the CISO monthly and to the Management Review Team quarterly.
