Workbook

Sheet Executive Summary
A1: ISMS-OP-CHK-A.8.9 — Configuration Management Compliance Checklist
A3: DOCUMENT INFORMATION
A4: Document ID | B4: ISMS-OP-CHK-A.8.9
A5: Source Policy | B5: ISMS-OP-POL-A.8.9
A6: ISO Controls | B6: Configuration Management
A7: Generated | B7: 30.09.2026
A8: Prepared By
A9: Organisation
A10: Review Cycle | B10: Annual
A12: OVERALL COMPLIANCE STATUS
A13: Overall Compliance | B13: ='Dashboard'!G11
A14: Status | B14: =IF(Dashboard!H11>0,"INCOMPLETE",IF(Dashboard!G11="N/A","NOT ASSESSED",IF(ISNUMBER(VALUE(SUBSTITUTE(Dashboard!G11,"%",""))),IF(VALUE(SUBSTITUTE(Dashboard!G11,"%",""))>=90,"GREEN",IF(VALUE(SUBSTITUTE(Dashboard!G11,"%",""))>=70,"AMBER","RED")),"NOT ASSESSED")))
A16: KEY METRICS
A17: Total Requirements | B17: ='Dashboard'!B11
A18: Compliant | B18: ='Dashboard'!C11
A19: Partial | B19: ='Dashboard'!D11
A20: Non-Compliant | B20: ='Dashboard'!E11
A21: Not Applicable | B21: ='Dashboard'!F11
A22: Unanswered | B22: ='Dashboard'!H11
A23: Owner Coverage | B23: =IF(Dashboard!B11=0,"N/A",ROUND((COUNTA('Configuration Baselines'!F4:F14)+COUNTA('Standard Builds & Golden Images'!F4:F6)+COUNTA('Configuration Change Control'!F4:F9)+COUNTA('Config Drift Detection and Mon'!F4:F11)+COUNTA('Security Hardening Standards'!F4:F13)+COUNTA('Configuration Audit'!F4:F6)+COUNTA('Emergency Configuration Changes'!F4:F8))/Dashboard!B11*100,0)&"%")
A25: DOMAIN STATUS SUMMARY
A26: Domain | B26: Compliance % | C26: Compliant | D26: Gaps | E26: Status
A27: Configuration Baselines | B27: ='Dashboard'!G4 | C27: ='Dashboard'!C4 | D27: ='Dashboard'!E4 | E27: =IF(Dashboard!H4>0,"INCOMPLETE",IF(Dashboard!G4="N/A","--",IF(ISNUMBER(VALUE(SUBSTITUTE(Dashboard!G4,"%",""))),IF(VALUE(SUBSTITUTE(Dashboard!G4,"%",""))>=90,"PASS",IF(VALUE(SUBSTITUTE(Dashboard!G4,"%",""))>=70,"REVIEW","FAIL")),"--")))
A28: Standard Builds & Golden Images | B28: ='Dashboard'!G5 | C28: ='Dashboard'!C5 | D28: ='Dashboard'!E5 | E28: =IF(Dashboard!H5>0,"INCOMPLETE",IF(Dashboard!G5="N/A","--",IF(ISNUMBER(VALUE(SUBSTITUTE(Dashboard!G5,"%",""))),IF(VALUE(SUBSTITUTE(Dashboard!G5,"%",""))>=90,"PASS",IF(VALUE(SUBSTITUTE(Dashboard!G5,"%",""))>=70,"REVIEW","FAIL")),"--")))
A29: Configuration Change Control | B29: ='Dashboard'!G6 | C29: ='Dashboard'!C6 | D29: ='Dashboard'!E6 | E29: =IF(Dashboard!H6>0,"INCOMPLETE",IF(Dashboard!G6="N/A","--",IF(ISNUMBER(VALUE(SUBSTITUTE(Dashboard!G6,"%",""))),IF(VALUE(SUBSTITUTE(Dashboard!G6,"%",""))>=90,"PASS",IF(VALUE(SUBSTITUTE(Dashboard!G6,"%",""))>=70,"REVIEW","FAIL")),"--")))
A30: Config Drift Detection and Mon | B30: ='Dashboard'!G7 | C30: ='Dashboard'!C7 | D30: ='Dashboard'!E7 | E30: =IF(Dashboard!H7>0,"INCOMPLETE",IF(Dashboard!G7="N/A","--",IF(ISNUMBER(VALUE(SUBSTITUTE(Dashboard!G7,"%",""))),IF(VALUE(SUBSTITUTE(Dashboard!G7,"%",""))>=90,"PASS",IF(VALUE(SUBSTITUTE(Dashboard!G7,"%",""))>=70,"REVIEW","FAIL")),"--")))
A31: Security Hardening Standards | B31: ='Dashboard'!G8 | C31: ='Dashboard'!C8 | D31: ='Dashboard'!E8 | E31: =IF(Dashboard!H8>0,"INCOMPLETE",IF(Dashboard!G8="N/A","--",IF(ISNUMBER(VALUE(SUBSTITUTE(Dashboard!G8,"%",""))),IF(VALUE(SUBSTITUTE(Dashboard!G8,"%",""))>=90,"PASS",IF(VALUE(SUBSTITUTE(Dashboard!G8,"%",""))>=70,"REVIEW","FAIL")),"--")))
A32: Configuration Audit | B32: ='Dashboard'!G9 | C32: ='Dashboard'!C9 | D32: ='Dashboard'!E9 | E32: =IF(Dashboard!H9>0,"INCOMPLETE",IF(Dashboard!G9="N/A","--",IF(ISNUMBER(VALUE(SUBSTITUTE(Dashboard!G9,"%",""))),IF(VALUE(SUBSTITUTE(Dashboard!G9,"%",""))>=90,"PASS",IF(VALUE(SUBSTITUTE(Dashboard!G9,"%",""))>=70,"REVIEW","FAIL")),"--")))
A33: Emergency Configuration Changes | B33: ='Dashboard'!G10 | C33: ='Dashboard'!C10 | D33: ='Dashboard'!E10 | E33: =IF(Dashboard!H10>0,"INCOMPLETE",IF(Dashboard!G10="N/A","--",IF(ISNUMBER(VALUE(SUBSTITUTE(Dashboard!G10,"%",""))),IF(VALUE(SUBSTITUTE(Dashboard!G10,"%",""))>=90,"PASS",IF(VALUE(SUBSTITUTE(Dashboard!G10,"%",""))>=70,"REVIEW","FAIL")),"--")))
A35: CRITICAL ISSUES
A36: # | B36: Issue Description | C36: Domain | D36: Owner | E36: Due Date
A37: 1
A38: 2
A39: 3
A40: 4
A41: 5
A43: MANAGEMENT COMMENTARY
A44: [Enter management commentary on configuration management posture]
A48: APPROVAL
A49: Assessed By
...

Sheet Dashboard
A1: Configuration Management — Compliance Dashboard
A3: Domain | B3: Total Reqs | C3: Compliant | D3: Partial | E3: Non-Compliant | F3: N/A | G3: Compliance % | H3: Unassessed
A4: Configuration Baselines | B4: =COUNTA('Configuration Baselines'!A4:A14) | C4: =COUNTIF('Configuration Baselines'!D4:D14,"Compliant") | D4: =COUNTIF('Configuration Baselines'!D4:D14,"Partial") | E4: =COUNTIF('Configuration Baselines'!D4:D14,"Non-Compliant") | F4: =COUNTIF('Configuration Baselines'!D4:D14,"N/A") | G4: =IF((B4-F4)=0,"N/A",ROUND(C4/(B4-F4)*100,1)&"%") | H4: =B4-(C4+D4+E4+F4)
A5: Standard Builds & Golden Images | B5: =COUNTA('Standard Builds & Golden Images'!A4:A6) | C5: =COUNTIF('Standard Builds & Golden Images'!D4:D6,"Compliant") | D5: =COUNTIF('Standard Builds & Golden Images'!D4:D6,"Partial") | E5: =COUNTIF('Standard Builds & Golden Images'!D4:D6,"Non-Compliant") | F5: =COUNTIF('Standard Builds & Golden Images'!D4:D6,"N/A") | G5: =IF((B5-F5)=0,"N/A",ROUND(C5/(B5-F5)*100,1)&"%") | H5: =B5-(C5+D5+E5+F5)
A6: Configuration Change Control | B6: =COUNTA('Configuration Change Control'!A4:A9) | C6: =COUNTIF('Configuration Change Control'!D4:D9,"Compliant") | D6: =COUNTIF('Configuration Change Control'!D4:D9,"Partial") | E6: =COUNTIF('Configuration Change Control'!D4:D9,"Non-Compliant") | F6: =COUNTIF('Configuration Change Control'!D4:D9,"N/A") | G6: =IF((B6-F6)=0,"N/A",ROUND(C6/(B6-F6)*100,1)&"%") | H6: =B6-(C6+D6+E6+F6)
A7: Config Drift Detection and Mon | B7: =COUNTA('Config Drift Detection and Mon'!A4:A11) | C7: =COUNTIF('Config Drift Detection and Mon'!D4:D11,"Compliant") | D7: =COUNTIF('Config Drift Detection and Mon'!D4:D11,"Partial") | E7: =COUNTIF('Config Drift Detection and Mon'!D4:D11,"Non-Compliant") | F7: =COUNTIF('Config Drift Detection and Mon'!D4:D11,"N/A") | G7: =IF((B7-F7)=0,"N/A",ROUND(C7/(B7-F7)*100,1)&"%") | H7: =B7-(C7+D7+E7+F7)
A8: Security Hardening Standards | B8: =COUNTA('Security Hardening Standards'!A4:A13) | C8: =COUNTIF('Security Hardening Standards'!D4:D13,"Compliant") | D8: =COUNTIF('Security Hardening Standards'!D4:D13,"Partial") | E8: =COUNTIF('Security Hardening Standards'!D4:D13,"Non-Compliant") | F8: =COUNTIF('Security Hardening Standards'!D4:D13,"N/A") | G8: =IF((B8-F8)=0,"N/A",ROUND(C8/(B8-F8)*100,1)&"%") | H8: =B8-(C8+D8+E8+F8)
A9: Configuration Audit | B9: =COUNTA('Configuration Audit'!A4:A6) | C9: =COUNTIF('Configuration Audit'!D4:D6,"Compliant") | D9: =COUNTIF('Configuration Audit'!D4:D6,"Partial") | E9: =COUNTIF('Configuration Audit'!D4:D6,"Non-Compliant") | F9: =COUNTIF('Configuration Audit'!D4:D6,"N/A") | G9: =IF((B9-F9)=0,"N/A",ROUND(C9/(B9-F9)*100,1)&"%") | H9: =B9-(C9+D9+E9+F9)
A10: Emergency Configuration Changes | B10: =COUNTA('Emergency Configuration Changes'!A4:A8) | C10: =COUNTIF('Emergency Configuration Changes'!D4:D8,"Compliant") | D10: =COUNTIF('Emergency Configuration Changes'!D4:D8,"Partial") | E10: =COUNTIF('Emergency Configuration Changes'!D4:D8,"Non-Compliant") | F10: =COUNTIF('Emergency Configuration Changes'!D4:D8,"N/A") | G10: =IF((B10-F10)=0,"N/A",ROUND(C10/(B10-F10)*100,1)&"%") | H10: =B10-(C10+D10+E10+F10)
A11: TOTAL | B11: =SUM(B4:B10) | C11: =SUM(C4:C10) | D11: =SUM(D4:D10) | E11: =SUM(E4:E10) | F11: =SUM(F4:F10) | G11: =IF((B11-F11)=0,"N/A",ROUND(C11/(B11-F11)*100,1)&"%") | H11: =SUM(H4:H10)
A13: COMPLIANCE BY STATUS
A14: Compliant | B14: =C11 | C14: =IF(B11=0,"",ROUND(B14/B11*100,1)&"%")
A15: Partial | B15: =D11 | C15: =IF(B11=0,"",ROUND(B15/B11*100,1)&"%")
A16: Non-Compliant | B16: =E11 | C16: =IF(B11=0,"",ROUND(B16/B11*100,1)&"%")
A17: N/A | B17: =F11 | C17: =IF(B11=0,"",ROUND(B17/B11*100,1)&"%")
A19: TOP GAPS (Manual Entry)
A20: Priority | B20: Domain | C20: Requirement | D20: Owner | E20: Due Date | F20: Status
A32: COMPLIANCE TREND (Manual Entry)
A33: Assessment Date | B33: Overall % | C33: Compliant | D33: Gaps | E33: Assessor | F33: Notes

Sheet Configuration Baselines
A1: Configuration Baselines — Compliance Checklist
A2: ISO/IEC 27001:2022 — Control A.8.9: Configuration Management
A3: Req # | B3: Section | C3: Requirement | D3: Status | E3: Evidence | F3: Owner | G3: Due Date | H3: Notes
A4: A.8.9-01 | B4: Define And Maintain Secure Configuration | C4: The organisation shall define and maintain secure configuration baselines at the asset-type level (e.g., 'Windows Server 2022 — Domain Controller', 'Ubuntu 24.04 — Application Server', 'Cisco IOS-XE — Core Switch'), not at the individual asset level.
A5: A.8.9-02 | B5: Be Defined For All Asset Types | C5: Baselines shall be defined for all asset types in active production use.
A6: A.8.9-03 | B6: Be Measured By | C6: Coverage shall be measured by:.
A7: A.8.9-04 | B7: Tier 1/2 Assets Without Baselines: | C7: Tier 1/2 assets without baselines: Deployment to production shall be blocked until a baseline is created (enforced via change approval).
A8: A.8.9-05 | B8: Document | C8: Each baseline shall document:.
A9: A.8.9-06 | B9: New Baselines And Baseline Updates | C9: New baselines and baseline updates shall follow a defined approval workflow:.
A10: A.8.9-07 | B10: Be Reviewed And Updated | C10: Baselines shall be reviewed and updated:.
A11: A.8.9-08 | B11: The Baseline | C11: The baseline shall be marked 'DEPRECATED' with an effective date.
A12: A.8.9-09 | B12: The Baseline | C12: The baseline shall be retained in the repository for 3 years for historical reference.
A13: A.8.9-10 | B13: The Baseline | C13: The baseline shall be removed from active compliance monitoring.
A14: A.8.9-11 | B14: A Replacement Baseline (If Applicable) | C14: A replacement baseline (if applicable) shall be linked in the repository.

Sheet Standard Builds & Golden Images
A1: Standard Builds & Golden Images — Compliance Checklist
A2: ISO/IEC 27001:2022 — Control A.8.9: Configuration Management
A3: Req # | B3: Section | C3: Requirement | D3: Status | E3: Evidence | F3: Owner | G3: Due Date | H3: Notes
A4: A.8.9-12 | B4: Golden Images | C4: Golden images shall:.
A5: A.8.9-13 | B5: Image Age Tracking*: [Asset Management | C5: Image age tracking*: [Asset Management System] shall record image creation date per deployed instance; report monthly on 'stale deployments' (instances from images older than 30 days).
A6: A.8.9-14 | B6: Golden Image Creation | C6: Golden image creation shall be restricted to authorised personnel (system administrators or DevOps engineers). New or updated golden images shall be validated by the security team before approval.

Sheet Configuration Change Control
A1: Configuration Change Control — Compliance Checklist
A2: ISO/IEC 27001:2022 — Control A.8.9: Configuration Management
A3: Req # | B3: Section | C3: Requirement | D3: Status | E3: Evidence | F3: Owner | G3: Due Date | H3: Notes
A4: A.8.9-15 | B4: Changes To System Configurations | C4: All changes to system configurations shall follow the organisation's change management process (see Change Management Policy — A.8.32). This section addresses configuration-specific requirements that complement change management.
A5: A.8.9-16 | B5: Configuration Changes | C5: Configuration changes shall be classified according to risk and impact:.
A6: A.8.9-17 | B6: Documentation: Standard Change Catalogue | C6: Documentation: Standard change catalogue shall be maintained in [Change Management System] with pre-approved procedures and risk assessments.
A7: A.8.9-18 | B7: Following Any Approved Configuration | C7: Following any approved configuration change, the following shall be updated within 5 business days:.
A8: A.8.9-19 | B8: Configuration Changes Made Outside The | C8: Configuration changes made outside the approved change management process shall be treated as security events:.
A9: A.8.9-20 | B9: The Affected System | C9: The affected system shall be remediated to the approved baseline or a new baseline formally approved through the standard process.

Sheet Config Drift Detection and Mon
A1: Config Drift Detection and Mon — Compliance Checklist
A2: ISO/IEC 27001:2022 — Control A.8.9: Configuration Management
A3: Req # | B3: Section | C3: Requirement | D3: Status | E3: Evidence | F3: Owner | G3: Due Date | H3: Notes
A4: A.8.9-21 | B4: Implement Configuration Monitoring To | C4: The organisation shall implement configuration monitoring to detect deviations from approved baselines.
A5: A.8.9-22 | B5: Monitoring Tools | C5: Monitoring tools shall:.
A6: A.8.9-23 | B6: Tool Selection*: The Organisation | C6: Tool selection*: The organisation shall select configuration monitoring tools appropriate to its technical environment. Tools shall support baseline comparison and drift detection. Examples include: file integrity monitoring (FIM) tools, cloud configuration assessment tools (e.g., AWS Config, Azure Policy, GCP Security Command Center), endpoint management platforms, and configuration compliance scanners.
A7: A.8.9-24 | B7: Asset Types Not Yet Under Automated | C7: Asset types not yet under automated monitoring shall be documented with a planned deployment date and interim manual controls (e.g., quarterly manual audits). Coverage gaps shall be risk-accepted by the CISO and recorded in the risk register.
A8: A.8.9-25 | B8: Risk Acceptance Does Not Waive Interim | C8: Risk acceptance does not waive interim controls — manual audits shall continue.
A9: A.8.9-26 | B9: Be Classified By Severity And Responded | C9: When configuration drift is detected, it shall be classified by severity and responded to within defined timelines:.
A10: A.8.9-27 | B10: Drift Remediation | C10: Drift remediation shall follow a structured workflow:.
A11: A.8.9-28 | B11: Recurring Drift On The Same System | C11: Recurring drift on the same system or asset type shall trigger a root cause analysis. If the root cause is a baseline that is impractical to maintain, the baseline shall be reviewed and updated through the standard approval process rather than repeatedly accepting exceptions.

Sheet Security Hardening Standards
A1: Security Hardening Standards — Compliance Checklist
A2: ISO/IEC 27001:2022 — Control A.8.9: Configuration Management
A3: Req # | B3: Section | C3: Requirement | D3: Status | E3: Evidence | F3: Owner | G3: Due Date | H3: Notes
A4: A.8.9-29 | B4: Select And Apply Recognised Security | C4: The organisation shall select and apply recognised security hardening standards for all production asset types.
A5: A.8.9-30 | B5: The Organisation | C5: Where multiple standards exist for an asset type, the organisation shall select the standard most appropriate to its risk profile and document the selection rationale.
A6: A.8.9-31 | B6: Production Systems | C6: All production systems shall be hardened before deployment. Hardening shall include, at minimum:.
A7: A.8.9-32 | B7: Hardening Compliance | C7: Hardening compliance shall be verified through periodic scanning:.
A8: A.8.9-33 | B8: Scan Results And Compliance Reports | C8: Scan results and compliance reports shall be retained for a minimum of 3 years for audit purposes.
A9: A.8.9-34 | B9: Hardening Gaps Identified Through | C9: Hardening gaps identified through verification shall be remediated according to risk:.
A10: A.8.9-35 | B10: Gaps That Cannot Be Remediated Due | C10: Gaps that cannot be remediated due to technical constraints or business requirements shall be documented as exceptions with compensating controls (see Exception Management below).
A11: A.8.9-36 | B11: Reduce Risk To An Acceptable Level | C11: Controls shall reduce risk to an acceptable level (CISO determination).
A12: A.8.9-37 | B12: Be Verifiable And Auditable (Not Merely | C12: Controls shall be verifiable and auditable (not merely 'we will be careful').
A13: A.8.9-38 | B13: Expiry: 12 Months Maximum | C13: Expiry: 12 months maximum; shall be re-justified if still needed.

Sheet Configuration Audit
A1: Configuration Audit — Compliance Checklist
A2: ISO/IEC 27001:2022 — Control A.8.9: Configuration Management
A3: Req # | B3: Section | C3: Requirement | D3: Status | E3: Evidence | F3: Owner | G3: Due Date | H3: Notes
A4: A.8.9-39 | B4: Conduct Periodic Configuration Audits To | C4: The organisation shall conduct periodic configuration audits to verify that:.
A5: A.8.9-40 | B5: Configuration Audits | C5: Configuration audits shall produce documented evidence including:.
A6: A.8.9-41 | B6: Audit Results | C6: Audit results shall be reported to the CISO and included in the management review process.

Sheet Emergency Configuration Changes
A1: Emergency Configuration Changes — Compliance Checklist
A2: ISO/IEC 27001:2022 — Control A.8.9: Configuration Management
A3: Req # | B3: Section | C3: Requirement | D3: Status | E3: Evidence | F3: Owner | G3: Due Date | H3: Notes
A4: A.8.9-42 | B4: The System | C4: The system shall be restored to a documented, known-good configuration state as quickly as possible.
A5: A.8.9-43 | B5: The Baseline | C5: If the emergency change results in a new configuration state (not a return to baseline), the baseline shall be updated through the standard approval process within 5 business days.
A6: A.8.9-44 | B6: Emergency Configuration Changes | C6: All emergency configuration changes shall be logged with: the specific configuration parameters changed, the previous values, the new values, the person who made the change, and the business justification.
A7: A.8.9-45 | B7: Retrospective Review By The Ciso Or | C7: Retrospective review by the CISO or delegate shall occur within 48 hours.
A8: A.8.9-46 | B8: Emergency Configuration Changes | C8: Emergency configuration changes shall not exceed 10% of all configuration changes in any calendar month. Exceeding this threshold triggers a process review.
