Workbook

Sheet Executive Summary
A1: PRIV-CHK-A.3.3-4 — Privacy Policy and Roles Compliance Checklist
A3: DOCUMENT INFORMATION
A4: Document ID | B4: PRIV-CHK-A.3.3-4
A5: Source Policy | B5: PRIV-POL-A.3.3-4
A6: ISO Controls | B6: Privacy Policy and Roles
A7: Generated | B7: 10.03.2026
A8: Prepared By
A9: Organisation
A10: Review Cycle | B10: Annual
A12: OVERALL COMPLIANCE STATUS
A13: Overall Compliance | B13: ='Dashboard'!G7
A14: Status | B14: =IF(Dashboard!G7="N/A","NOT ASSESSED",IF(ISNUMBER(VALUE(SUBSTITUTE(Dashboard!G7,"%",""))),IF(VALUE(SUBSTITUTE(Dashboard!G7,"%",""))>=90,"GREEN",IF(VALUE(SUBSTITUTE(Dashboard!G7,"%",""))>=70,"AMBER","RED")),"NOT ASSESSED"))
A16: KEY METRICS
A17: Total Requirements | B17: ='Dashboard'!B7
A18: Compliant | B18: ='Dashboard'!C7
A19: Partial | B19: ='Dashboard'!D7
A20: Non-Compliant | B20: ='Dashboard'!E7
A21: Not Applicable | B21: ='Dashboard'!F7
A22: Owner Coverage | B22: =IF(Dashboard!B7=0,"N/A",ROUND((COUNTA('PIMS Policy Framework'!F4:F8)+COUNTA('Privacy Roles — Appointment and Accountability'!F4:F9)+COUNTA('Segregation and Independence'!F4:F7))/Dashboard!B7*100,0)&"%")
A24: DOMAIN STATUS SUMMARY
A25: Domain | B25: Compliance % | C25: Compliant | D25: Gaps | E25: Status
A26: PIMS Policy Framework | B26: ='Dashboard'!G4 | C26: ='Dashboard'!C4 | D26: ='Dashboard'!E4 | E26: =IF(Dashboard!G4="N/A","--",IF(ISNUMBER(VALUE(SUBSTITUTE(Dashboard!G4,"%",""))),IF(VALUE(SUBSTITUTE(Dashboard!G4,"%",""))>=90,"PASS",IF(VALUE(SUBSTITUTE(Dashboard!G4,"%",""))>=70,"REVIEW","FAIL")),"--"))
A27: Privacy Roles — Appointment and Accountability | B27: ='Dashboard'!G5 | C27: ='Dashboard'!C5 | D27: ='Dashboard'!E5 | E27: =IF(Dashboard!G5="N/A","--",IF(ISNUMBER(VALUE(SUBSTITUTE(Dashboard!G5,"%",""))),IF(VALUE(SUBSTITUTE(Dashboard!G5,"%",""))>=90,"PASS",IF(VALUE(SUBSTITUTE(Dashboard!G5,"%",""))>=70,"REVIEW","FAIL")),"--"))
A28: Segregation and Independence | B28: ='Dashboard'!G6 | C28: ='Dashboard'!C6 | D28: ='Dashboard'!E6 | E28: =IF(Dashboard!G6="N/A","--",IF(ISNUMBER(VALUE(SUBSTITUTE(Dashboard!G6,"%",""))),IF(VALUE(SUBSTITUTE(Dashboard!G6,"%",""))>=90,"PASS",IF(VALUE(SUBSTITUTE(Dashboard!G6,"%",""))>=70,"REVIEW","FAIL")),"--"))
A30: CRITICAL ISSUES
A31: # | B31: Issue Description | C31: Domain | D31: Owner | E31: Due Date
A32: 1
A33: 2
A34: 3
A35: 4
A36: 5
A38: MANAGEMENT COMMENTARY
A39: [Enter management commentary on privacy policy and roles posture]
A43: APPROVAL
A44: Assessed By
A45: Name:
A46: Date:
A47: Signature:
A48: Decision:
A50: Reviewed By (DPO)
...

Sheet Dashboard
A1: Privacy Policy and Roles — Compliance Dashboard
A3: Domain | B3: Total Reqs | C3: Compliant | D3: Partial | E3: Non-Compliant | F3: N/A | G3: Compliance %
A4: PIMS Policy Framework | B4: =COUNTA('PIMS Policy Framework'!D4:D8) | C4: =COUNTIF('PIMS Policy Framework'!D4:D8,"Compliant") | D4: =COUNTIF('PIMS Policy Framework'!D4:D8,"Partial") | E4: =COUNTIF('PIMS Policy Framework'!D4:D8,"Non-Compliant") | F4: =COUNTIF('PIMS Policy Framework'!D4:D8,"N/A") | G4: =IF((B4-F4)=0,"N/A",ROUND(C4/(B4-F4)*100,1)&"%")
A5: Privacy Roles — Appointment and Accountability | B5: =COUNTA('Privacy Roles — Appointment and Accountability'!D4:D9) | C5: =COUNTIF('Privacy Roles — Appointment and Accountability'!D4:D9,"Compliant") | D5: =COUNTIF('Privacy Roles — Appointment and Accountability'!D4:D9,"Partial") | E5: =COUNTIF('Privacy Roles — Appointment and Accountability'!D4:D9,"Non-Compliant") | F5: =COUNTIF('Privacy Roles — Appointment and Accountability'!D4:D9,"N/A") | G5: =IF((B5-F5)=0,"N/A",ROUND(C5/(B5-F5)*100,1)&"%")
A6: Segregation and Independence | B6: =COUNTA('Segregation and Independence'!D4:D7) | C6: =COUNTIF('Segregation and Independence'!D4:D7,"Compliant") | D6: =COUNTIF('Segregation and Independence'!D4:D7,"Partial") | E6: =COUNTIF('Segregation and Independence'!D4:D7,"Non-Compliant") | F6: =COUNTIF('Segregation and Independence'!D4:D7,"N/A") | G6: =IF((B6-F6)=0,"N/A",ROUND(C6/(B6-F6)*100,1)&"%")
A7: TOTAL | B7: =SUM(B4:B6) | C7: =SUM(C4:C6) | D7: =SUM(D4:D6) | E7: =SUM(E4:E6) | F7: =SUM(F4:F6) | G7: =IF((B7-F7)=0,"N/A",ROUND(C7/(B7-F7)*100,1)&"%")
A9: COMPLIANCE BY STATUS
A10: Compliant | B10: =C7 | C10: =IF(B7=0,"",ROUND(B10/B7*100,1)&"%")
A11: Partial | B11: =D7 | C11: =IF(B7=0,"",ROUND(B11/B7*100,1)&"%")
A12: Non-Compliant | B12: =E7 | C12: =IF(B7=0,"",ROUND(B12/B7*100,1)&"%")
A13: N/A | B13: =F7 | C13: =IF(B7=0,"",ROUND(B13/B7*100,1)&"%")
A15: TOP GAPS (Manual Entry)
A16: Priority | B16: Domain | C16: Requirement | D16: Owner | E16: Due Date | F16: Status
A28: COMPLIANCE TREND (Manual Entry)
A29: Assessment Date | B29: Overall % | C29: Compliant | D29: Gaps | E29: Assessor | F29: Notes

Sheet PIMS Policy Framework
A1: PIMS Policy Framework — Compliance Checklist
A2: ISO/IEC 27701:2025 — Controls A.3.3-4: Privacy Policy and Roles
A3: Req # | B3: Section | C3: Requirement | D3: Status | E3: Evidence | F3: Owner | G3: Due Date | H3: Notes
A4: A.3.3-01 | B4: PIMS Policy Suite | C4: The organisation shall maintain a suite of information security policies covering all aspects of PII processing. The PIMS policy suite shall address all 21 control groups within the PIMS scope and shall be approved by Executive Management.
A5: A.3.3-02 | B5: Policy Owner and Review | C5: Each PIMS policy shall have a designated owner (the DPO for privacy-specific policies) and shall be reviewed at minimum annually and upon significant regulatory or organisational change. Out-of-date policies (unreviewd for more than 12 months) shall be treated as a compliance gap.
A6: A.3.3-03 | B6: Policy Communication | C6: All PIMS policies shall be communicated to all personnel and relevant interested parties. Personnel shall be required to acknowledge policies applicable to their role before accessing PII. Acknowledgment records shall be maintained per PRIV-POL-A.3.17-19.
A7: A.3.3-04 | B7: Policy Hierarchy | C7: The PIMS policy framework shall operate within a defined hierarchy: PRIV-POL-00 (Regulatory Applicability Framework) and PRIV-POL-01 (Governance Framework) sit above control-specific policies (PRIV-POL-A.x.x). Where policies conflict, the more restrictive requirement shall prevail.
A8: A.3.3-05 | B8: Privacy Registers | C8: The DPO shall maintain the core PIMS registers required to demonstrate compliance: Privacy Legal Requirements Register (PLRR), Confidentiality Agreement Register, Personnel Privacy Training and Acknowledgment Register, and any registers required by individual PIMS policies. Register templates and maintenance procedures are defined in PRIV-IMP-A.3.3-4-UG.

Sheet Privacy Roles — Appointment and Accountability
A1: Privacy Roles — Appointment and Accountability — Compliance Checklist
A2: ISO/IEC 27701:2025 — Controls A.3.3-4: Privacy Policy and Roles
A3: Req # | B3: Section | C3: Requirement | D3: Status | E3: Evidence | F3: Owner | G3: Due Date | H3: Notes
A4: A.3.4-01 | B4: DPO Appointment | C4: The organisation shall appoint a Data Protection Officer (DPO) with sufficient authority, resources, and independence to fulfil the role. The DPO appointment shall be documented and communicated internally and, where required by GDPR Article 37, notified to the supervisory authority. The DPO shall report directly to Executive Management.
A5: A.3.4-02 | B5: DPO Responsibilities | C5: The DPO shall be responsible for: informing and advising on data protection obligations; monitoring PIMS policy compliance; conducting privacy impact assessments; cooperating with supervisory authorities; and acting as first contact for data subjects and supervisory authorities. DPO responsibilities shall not create a conflict of interest with any other role held.
A6: A.3.4-03 | B6: Privacy Champions | C6: The organisation shall appoint Privacy Champions in each material business unit or function that processes PII. Privacy Champions serve as the DPO's operational contact point within their unit, assist with PIMS awareness, identify PII risks, and escalate privacy concerns to the DPO. Privacy Champion appointments shall be documented.
A7: A.3.4-04 | B7: Data Owners | C7: A Data Owner shall be assigned for each PII dataset or processing activity in the Record of Processing Activities (RoPA). Data Owners are accountable for the PII within their domain: defining access rights, approving PII use cases, and ensuring the dataset remains within policy bounds. Data Owner assignments shall be documented and reviewed at minimum annually.
A8: A.3.4-05 | B8: PIMS Internal Auditor | C8: The organisation shall designate a PIMS Internal Auditor role responsible for conducting independent reviews of PIMS implementation per PRIV-POL-A.3.13-16. The PIMS Internal Auditor shall be independent of the operational functions they audit and shall have sufficient competence to assess privacy controls.
A9: A.3.4-06 | B9: Security Roles with PII Responsibility | C9: The CISO and IT Security Team hold information security responsibilities that include PII-specific obligations. These roles shall implement and maintain technical controls for PII processing environments as specified in this policy series. Their PII responsibilities shall be documented in role descriptions and included in the PIMS governance framework.

Sheet Segregation and Independence
A1: Segregation and Independence — Compliance Checklist
A2: ISO/IEC 27701:2025 — Controls A.3.3-4: Privacy Policy and Roles
A3: Req # | B3: Section | C3: Requirement | D3: Status | E3: Evidence | F3: Owner | G3: Due Date | H3: Notes
A4: A.3.4-07 | B4: DPO Independence | C4: The DPO shall not receive instructions from the organisation regarding the exercise of their data protection tasks. The DPO shall not be dismissed or penalised for performing their duties. Roles that would create a conflict of interest (such as determining purposes and means of PII processing) shall not be held concurrently with the DPO role.
A5: A.3.4-08 | B5: Segregation of Duties | C5: The organisation shall apply segregation of duties for sensitive PII processing operations, including: authorisation of new processing activities, approval of access rights, conduct of privacy impact assessments, and handling of data subject rights requests. No single individual shall be able to authorise and execute a sensitive PII operation without a second authorised party.
A6: A.3.4-09 | B6: Role Reviews | C6: All privacy role assignments (DPO, Privacy Champions, Data Owners, PIMS Internal Auditor) shall be reviewed at minimum annually to confirm: the role holder remains competent; the scope of the role remains current; no new conflicts of interest have arisen. Reviews shall be documented.
A7: A.3.4-10 | B7: Succession and Continuity | C7: The organisation shall have documented succession arrangements for the DPO role to ensure continuity of privacy governance in the event of absence or role change. At minimum, a named deputy DPO or temporary arrangement shall be identified and approved by Executive Management.
