Workbook

Sheet Executive Summary
A1: ISMS-OP-CHK-A.8.11 — Data Masking Compliance Checklist
A3: DOCUMENT INFORMATION
A4: Document ID | B4: ISMS-OP-CHK-A.8.11
A5: Source Policy | B5: ISMS-OP-POL-A.8.11
A6: ISO Controls | B6: Data Masking
A7: Generated | B7: 30.09.2026
A8: Prepared By
A9: Organisation
A10: Review Cycle | B10: Annual
A12: OVERALL COMPLIANCE STATUS
A13: Overall Compliance | B13: ='Dashboard'!G13
A14: Status | B14: =IF(Dashboard!H13>0,"INCOMPLETE",IF(Dashboard!G13="N/A","NOT ASSESSED",IF(ISNUMBER(VALUE(SUBSTITUTE(Dashboard!G13,"%",""))),IF(VALUE(SUBSTITUTE(Dashboard!G13,"%",""))>=90,"GREEN",IF(VALUE(SUBSTITUTE(Dashboard!G13,"%",""))>=70,"AMBER","RED")),"NOT ASSESSED")))
A16: KEY METRICS
A17: Total Requirements | B17: ='Dashboard'!B13
A18: Compliant | B18: ='Dashboard'!C13
A19: Partial | B19: ='Dashboard'!D13
A20: Non-Compliant | B20: ='Dashboard'!E13
A21: Not Applicable | B21: ='Dashboard'!F13
A22: Unanswered | B22: ='Dashboard'!H13
A23: Owner Coverage | B23: =IF(Dashboard!B13=0,"N/A",ROUND((COUNTA('Data Class and Masking Reqs'!F4:F5)+COUNTA('Approved Masking Techniques'!F4:F12)+COUNTA('Environment Coverage Reqs'!F4:F26)+COUNTA('Testing and Validation'!F4:F6)+COUNTA('Logging and Monitoring'!F4:F8)+COUNTA('Incident Response Masking'!F4:F5)+COUNTA('Exception Management'!F4:F4)+COUNTA('Optional Payment Card Data'!F4:F7)+COUNTA('Third-Party Data Sharing Reqs'!F4:F6))/Dashboard!B13*100,0)&"%")
A25: DOMAIN STATUS SUMMARY
A26: Domain | B26: Compliance % | C26: Compliant | D26: Gaps | E26: Status
A27: Data Class and Masking Reqs | B27: ='Dashboard'!G4 | C27: ='Dashboard'!C4 | D27: ='Dashboard'!E4 | E27: =IF(Dashboard!H4>0,"INCOMPLETE",IF(Dashboard!G4="N/A","--",IF(ISNUMBER(VALUE(SUBSTITUTE(Dashboard!G4,"%",""))),IF(VALUE(SUBSTITUTE(Dashboard!G4,"%",""))>=90,"PASS",IF(VALUE(SUBSTITUTE(Dashboard!G4,"%",""))>=70,"REVIEW","FAIL")),"--")))
A28: Approved Masking Techniques | B28: ='Dashboard'!G5 | C28: ='Dashboard'!C5 | D28: ='Dashboard'!E5 | E28: =IF(Dashboard!H5>0,"INCOMPLETE",IF(Dashboard!G5="N/A","--",IF(ISNUMBER(VALUE(SUBSTITUTE(Dashboard!G5,"%",""))),IF(VALUE(SUBSTITUTE(Dashboard!G5,"%",""))>=90,"PASS",IF(VALUE(SUBSTITUTE(Dashboard!G5,"%",""))>=70,"REVIEW","FAIL")),"--")))
A29: Environment Coverage Reqs | B29: ='Dashboard'!G6 | C29: ='Dashboard'!C6 | D29: ='Dashboard'!E6 | E29: =IF(Dashboard!H6>0,"INCOMPLETE",IF(Dashboard!G6="N/A","--",IF(ISNUMBER(VALUE(SUBSTITUTE(Dashboard!G6,"%",""))),IF(VALUE(SUBSTITUTE(Dashboard!G6,"%",""))>=90,"PASS",IF(VALUE(SUBSTITUTE(Dashboard!G6,"%",""))>=70,"REVIEW","FAIL")),"--")))
A30: Testing and Validation | B30: ='Dashboard'!G7 | C30: ='Dashboard'!C7 | D30: ='Dashboard'!E7 | E30: =IF(Dashboard!H7>0,"INCOMPLETE",IF(Dashboard!G7="N/A","--",IF(ISNUMBER(VALUE(SUBSTITUTE(Dashboard!G7,"%",""))),IF(VALUE(SUBSTITUTE(Dashboard!G7,"%",""))>=90,"PASS",IF(VALUE(SUBSTITUTE(Dashboard!G7,"%",""))>=70,"REVIEW","FAIL")),"--")))
A31: Logging and Monitoring | B31: ='Dashboard'!G8 | C31: ='Dashboard'!C8 | D31: ='Dashboard'!E8 | E31: =IF(Dashboard!H8>0,"INCOMPLETE",IF(Dashboard!G8="N/A","--",IF(ISNUMBER(VALUE(SUBSTITUTE(Dashboard!G8,"%",""))),IF(VALUE(SUBSTITUTE(Dashboard!G8,"%",""))>=90,"PASS",IF(VALUE(SUBSTITUTE(Dashboard!G8,"%",""))>=70,"REVIEW","FAIL")),"--")))
A32: Incident Response Masking | B32: ='Dashboard'!G9 | C32: ='Dashboard'!C9 | D32: ='Dashboard'!E9 | E32: =IF(Dashboard!H9>0,"INCOMPLETE",IF(Dashboard!G9="N/A","--",IF(ISNUMBER(VALUE(SUBSTITUTE(Dashboard!G9,"%",""))),IF(VALUE(SUBSTITUTE(Dashboard!G9,"%",""))>=90,"PASS",IF(VALUE(SUBSTITUTE(Dashboard!G9,"%",""))>=70,"REVIEW","FAIL")),"--")))
A33: Exception Management | B33: ='Dashboard'!G10 | C33: ='Dashboard'!C10 | D33: ='Dashboard'!E10 | E33: =IF(Dashboard!H10>0,"INCOMPLETE",IF(Dashboard!G10="N/A","--",IF(ISNUMBER(VALUE(SUBSTITUTE(Dashboard!G10,"%",""))),IF(VALUE(SUBSTITUTE(Dashboard!G10,"%",""))>=90,"PASS",IF(VALUE(SUBSTITUTE(Dashboard!G10,"%",""))>=70,"REVIEW","FAIL")),"--")))
A34: Optional Payment Card Data | B34: ='Dashboard'!G11 | C34: ='Dashboard'!C11 | D34: ='Dashboard'!E11 | E34: =IF(Dashboard!H11>0,"INCOMPLETE",IF(Dashboard!G11="N/A","--",IF(ISNUMBER(VALUE(SUBSTITUTE(Dashboard!G11,"%",""))),IF(VALUE(SUBSTITUTE(Dashboard!G11,"%",""))>=90,"PASS",IF(VALUE(SUBSTITUTE(Dashboard!G11,"%",""))>=70,"REVIEW","FAIL")),"--")))
A35: Third-Party Data Sharing Reqs | B35: ='Dashboard'!G12 | C35: ='Dashboard'!C12 | D35: ='Dashboard'!E12 | E35: =IF(Dashboard!H12>0,"INCOMPLETE",IF(Dashboard!G12="N/A","--",IF(ISNUMBER(VALUE(SUBSTITUTE(Dashboard!G12,"%",""))),IF(VALUE(SUBSTITUTE(Dashboard!G12,"%",""))>=90,"PASS",IF(VALUE(SUBSTITUTE(Dashboard!G12,"%",""))>=70,"REVIEW","FAIL")),"--")))
A37: CRITICAL ISSUES
A38: # | B38: Issue Description | C38: Domain | D38: Owner | E38: Due Date
A39: 1
A40: 2
A41: 3
A42: 4
A43: 5
A45: MANAGEMENT COMMENTARY
A46: [Enter management commentary on data masking posture]
...

Sheet Dashboard
A1: Data Masking — Compliance Dashboard
A3: Domain | B3: Total Reqs | C3: Compliant | D3: Partial | E3: Non-Compliant | F3: N/A | G3: Compliance % | H3: Unassessed
A4: Data Class and Masking Reqs | B4: =COUNTA('Data Class and Masking Reqs'!A4:A5) | C4: =COUNTIF('Data Class and Masking Reqs'!D4:D5,"Compliant") | D4: =COUNTIF('Data Class and Masking Reqs'!D4:D5,"Partial") | E4: =COUNTIF('Data Class and Masking Reqs'!D4:D5,"Non-Compliant") | F4: =COUNTIF('Data Class and Masking Reqs'!D4:D5,"N/A") | G4: =IF((B4-F4)=0,"N/A",ROUND(C4/(B4-F4)*100,1)&"%") | H4: =B4-(C4+D4+E4+F4)
A5: Approved Masking Techniques | B5: =COUNTA('Approved Masking Techniques'!A4:A12) | C5: =COUNTIF('Approved Masking Techniques'!D4:D12,"Compliant") | D5: =COUNTIF('Approved Masking Techniques'!D4:D12,"Partial") | E5: =COUNTIF('Approved Masking Techniques'!D4:D12,"Non-Compliant") | F5: =COUNTIF('Approved Masking Techniques'!D4:D12,"N/A") | G5: =IF((B5-F5)=0,"N/A",ROUND(C5/(B5-F5)*100,1)&"%") | H5: =B5-(C5+D5+E5+F5)
A6: Environment Coverage Reqs | B6: =COUNTA('Environment Coverage Reqs'!A4:A26) | C6: =COUNTIF('Environment Coverage Reqs'!D4:D26,"Compliant") | D6: =COUNTIF('Environment Coverage Reqs'!D4:D26,"Partial") | E6: =COUNTIF('Environment Coverage Reqs'!D4:D26,"Non-Compliant") | F6: =COUNTIF('Environment Coverage Reqs'!D4:D26,"N/A") | G6: =IF((B6-F6)=0,"N/A",ROUND(C6/(B6-F6)*100,1)&"%") | H6: =B6-(C6+D6+E6+F6)
A7: Testing and Validation | B7: =COUNTA('Testing and Validation'!A4:A6) | C7: =COUNTIF('Testing and Validation'!D4:D6,"Compliant") | D7: =COUNTIF('Testing and Validation'!D4:D6,"Partial") | E7: =COUNTIF('Testing and Validation'!D4:D6,"Non-Compliant") | F7: =COUNTIF('Testing and Validation'!D4:D6,"N/A") | G7: =IF((B7-F7)=0,"N/A",ROUND(C7/(B7-F7)*100,1)&"%") | H7: =B7-(C7+D7+E7+F7)
A8: Logging and Monitoring | B8: =COUNTA('Logging and Monitoring'!A4:A8) | C8: =COUNTIF('Logging and Monitoring'!D4:D8,"Compliant") | D8: =COUNTIF('Logging and Monitoring'!D4:D8,"Partial") | E8: =COUNTIF('Logging and Monitoring'!D4:D8,"Non-Compliant") | F8: =COUNTIF('Logging and Monitoring'!D4:D8,"N/A") | G8: =IF((B8-F8)=0,"N/A",ROUND(C8/(B8-F8)*100,1)&"%") | H8: =B8-(C8+D8+E8+F8)
A9: Incident Response Masking | B9: =COUNTA('Incident Response Masking'!A4:A5) | C9: =COUNTIF('Incident Response Masking'!D4:D5,"Compliant") | D9: =COUNTIF('Incident Response Masking'!D4:D5,"Partial") | E9: =COUNTIF('Incident Response Masking'!D4:D5,"Non-Compliant") | F9: =COUNTIF('Incident Response Masking'!D4:D5,"N/A") | G9: =IF((B9-F9)=0,"N/A",ROUND(C9/(B9-F9)*100,1)&"%") | H9: =B9-(C9+D9+E9+F9)
A10: Exception Management | B10: =COUNTA('Exception Management'!A4:A4) | C10: =COUNTIF('Exception Management'!D4:D4,"Compliant") | D10: =COUNTIF('Exception Management'!D4:D4,"Partial") | E10: =COUNTIF('Exception Management'!D4:D4,"Non-Compliant") | F10: =COUNTIF('Exception Management'!D4:D4,"N/A") | G10: =IF((B10-F10)=0,"N/A",ROUND(C10/(B10-F10)*100,1)&"%") | H10: =B10-(C10+D10+E10+F10)
A11: Optional Payment Card Data | B11: =COUNTA('Optional Payment Card Data'!A4:A7) | C11: =COUNTIF('Optional Payment Card Data'!D4:D7,"Compliant") | D11: =COUNTIF('Optional Payment Card Data'!D4:D7,"Partial") | E11: =COUNTIF('Optional Payment Card Data'!D4:D7,"Non-Compliant") | F11: =COUNTIF('Optional Payment Card Data'!D4:D7,"N/A") | G11: =IF((B11-F11)=0,"N/A",ROUND(C11/(B11-F11)*100,1)&"%") | H11: =B11-(C11+D11+E11+F11)
A12: Third-Party Data Sharing Reqs | B12: =COUNTA('Third-Party Data Sharing Reqs'!A4:A6) | C12: =COUNTIF('Third-Party Data Sharing Reqs'!D4:D6,"Compliant") | D12: =COUNTIF('Third-Party Data Sharing Reqs'!D4:D6,"Partial") | E12: =COUNTIF('Third-Party Data Sharing Reqs'!D4:D6,"Non-Compliant") | F12: =COUNTIF('Third-Party Data Sharing Reqs'!D4:D6,"N/A") | G12: =IF((B12-F12)=0,"N/A",ROUND(C12/(B12-F12)*100,1)&"%") | H12: =B12-(C12+D12+E12+F12)
A13: TOTAL | B13: =SUM(B4:B12) | C13: =SUM(C4:C12) | D13: =SUM(D4:D12) | E13: =SUM(E4:E12) | F13: =SUM(F4:F12) | G13: =IF((B13-F13)=0,"N/A",ROUND(C13/(B13-F13)*100,1)&"%") | H13: =SUM(H4:H12)
A15: COMPLIANCE BY STATUS
A16: Compliant | B16: =C13 | C16: =IF(B13=0,"",ROUND(B16/B13*100,1)&"%")
A17: Partial | B17: =D13 | C17: =IF(B13=0,"",ROUND(B17/B13*100,1)&"%")
A18: Non-Compliant | B18: =E13 | C18: =IF(B13=0,"",ROUND(B18/B13*100,1)&"%")
A19: N/A | B19: =F13 | C19: =IF(B13=0,"",ROUND(B19/B13*100,1)&"%")
A21: TOP GAPS (Manual Entry)
A22: Priority | B22: Domain | C22: Requirement | D22: Owner | E22: Due Date | F22: Status
A34: COMPLIANCE TREND (Manual Entry)
A35: Assessment Date | B35: Overall % | C35: Compliant | D35: Gaps | E35: Assessor | F35: Notes

Sheet Data Class and Masking Reqs
A1: Data Class and Masking Reqs — Compliance Checklist
A2: ISO/IEC 27001:2022 — Control A.8.11: Data Masking
A3: Req # | B3: Section | C3: Requirement | D3: Status | E3: Evidence | F3: Owner | G3: Due Date | H3: Notes
A4: A.8.11-01 | B4: Maintain An Inventory Of Sensitive Data | C4: The organisation shall maintain an inventory of sensitive data requiring masking, including:.
A5: A.8.11-02 | B5: Data Discovery | C5: Data discovery shall be automated for all environments containing Restricted or Confidential data, using [Data Discovery Tool] or equivalent. Automated discovery shall scan for known sensitive data patterns (PII patterns, credit card numbers, AHV/SSN formats, health identifiers) on at least a quarterly basis. Manual inventory is acceptable for organisations with limited data estates and no Restricted data, but shall be supplemented by automated discovery as the data estate grows.

Sheet Approved Masking Techniques
A1: Approved Masking Techniques — Compliance Checklist
A2: ISO/IEC 27001:2022 — Control A.8.11: Data Masking
A3: Req # | B3: Section | C3: Requirement | D3: Status | E3: Evidence | F3: Owner | G3: Due Date | H3: Notes
A4: A.8.11-03 | B4: The Following Factors | C4: When selecting a masking technique, the following factors shall be considered:.
A5: A.8.11-04 | B5: New Masking Techniques Or Significant | C5: New masking techniques or significant modifications to approved techniques shall be proposed to the Security Team, undergo security review and testing, and be approved by the CISO before use.
A6: A.8.11-05 | B6: Under Both Gdpr And Nfadp, Pseudonymised | C6: Under both GDPR and nFADP, pseudonymised data remains personal data because re-identification is possible with the separately held key. Anonymised data — where re-identification is no longer reasonably possible — falls outside the scope of data protection regulation. The organisation shall ensure the correct technique is applied based on whether the data must remain within data protection scope (pseudonymisation) or can be removed from scope entirely (anonymisation).
A7: A.8.11-06 | B7: Anonymisation Data Utility Assessment*: | C7: Anonymisation data utility assessment*: Before applying anonymisation, the Data Owner shall assess whether the anonymised data retains sufficient business utility for its intended purpose. The assessment shall consider:.
A8: A.8.11-07 | B8: Pseudonymisation Keys | C8: Pseudonymisation keys shall be stored separately from the pseudonymised data, with the following separation requirements:.
A9: A.8.11-08 | B9: Physical Or Logical Separation: Keys | C9: Physical or logical separation: Keys shall be stored in a different system, database, or security domain from the pseudonymised data. Co-locating keys and data on the same server or in the same database is prohibited.
A10: A.8.11-09 | B10: Access Separation: Personnel With Access | C10: Access separation: Personnel with access to pseudonymised data shall not have access to re-identification keys unless specifically authorised for a documented purpose. Dual-control (two-person authorisation) shall be required for re-identification of Restricted data.
A11: A.8.11-10 | B11: Re-Identification Logging: All | C11: Re-identification logging: All re-identification events shall be logged with requestor identity, justification, data scope, and approval reference.
A12: A.8.11-11 | B12: Key Management | C12: Key management shall follow the Use of Cryptography Policy (A.8.24).

Sheet Environment Coverage Reqs
A1: Environment Coverage Reqs — Compliance Checklist
A2: ISO/IEC 27001:2022 — Control A.8.11: Data Masking
A3: Req # | B3: Section | C3: Requirement | D3: Status | E3: Evidence | F3: Owner | G3: Due Date | H3: Notes
A4: A.8.11-12 | B4: Sensitive Data | C4: Sensitive data shall be masked in environments where full data visibility is not required for legitimate business operations.
A5: A.8.11-13 | B5: Be Applied Before Data Leaves The | C5: SDM shall be applied BEFORE data leaves the production environment.
A6: A.8.11-14 | B6: Maintain Referential Integrity Across | C6: SDM shall maintain referential integrity across related tables. Where multi-table relationships exist, masking shall be applied consistently using the same masking key or mapping to preserve foreign key relationships, join integrity, and cross-table business rules. Referential integrity shall be validated through automated testing after each masking cycle.
A7: A.8.11-15 | B7: Preserve Data Format For Application | C7: SDM shall preserve data format for application compatibility. Note: format preservation may reduce the masking entropy (number of possible masked values), which increases re-identification risk. For Restricted data, the organisation shall assess whether format-preserving masking provides sufficient security or whether non-format-preserving techniques with application-layer adaptation are required.
A8: A.8.11-16 | B8: Masked Data | C8: Masked data shall be realistic enough for application testing.
A9: A.8.11-17 | B9: Masked Data Refresh: Non-Production | C9: Masked data refresh: Non-production environments using SDM shall be refreshed with newly masked data at a defined frequency — at minimum quarterly for active development environments and semi-annually for less active environments. Refresh frequency shall account for production data changes that may affect test validity and for reducing the risk of masking circumvention through accumulated knowledge of stale masked datasets.
A10: A.8.11-18 | B10: Be Enforced At The Database Or | C10: DDM shall be enforced at the database or application layer — not client-side.
A11: A.8.11-19 | B11: Ddm Rules | C11: DDM rules shall be based on documented user roles and least privilege.
A12: A.8.11-20 | B12: Not Be Bypassable By Users Without | C12: DDM shall not be bypassable by users without appropriate authorisation. Bypass prevention controls shall include:.
A13: A.8.11-21 | B13: Direct Database Access (Bypassing The | C13: Direct database access (bypassing the application layer) shall be restricted to authorised database administrators.
A14: A.8.11-22 | B14: Ddm Rules | C14: DDM rules shall be enforced at the database engine level where supported, not solely at the application layer.
A15: A.8.11-23 | B15: Attempts To Query Underlying Unmasked | C15: Attempts to query underlying unmasked data through views, stored procedures, or alternate access paths shall be blocked or logged and alerted.
... A26: A.8.11-34 | B26: Vault Key Management | C26: Vault key management shall follow the Use of Cryptography Policy (A.8.24).

Sheet Testing and Validation
A1: Testing and Validation — Compliance Checklist
A2: ISO/IEC 27001:2022 — Control A.8.11: Data Masking
A3: Req # | B3: Section | C3: Requirement | D3: Status | E3: Evidence | F3: Owner | G3: Due Date | H3: Notes
A4: A.8.11-35 | B4: Masking Implementations | C4: Masking implementations shall be tested before deployment and after any changes to masking configuration.
A5: A.8.11-36 | B5: Data Utility | C5: Where k-anonymity thresholds cannot be met, data utility shall be assessed against the risk of re-identification, and alternative techniques (generalisation, suppression, noise addition) shall be applied to achieve the target threshold.
A6: A.8.11-37 | B6: Be Corrected Before Production Use, Root | C6: When testing identifies failures, implementation shall be corrected before production use, root cause documented, and re-testing performed.

Sheet Logging and Monitoring
A1: Logging and Monitoring — Compliance Checklist
A2: ISO/IEC 27001:2022 — Control A.8.11: Data Masking
A3: Req # | B3: Section | C3: Requirement | D3: Status | E3: Evidence | F3: Owner | G3: Due Date | H3: Notes
A4: A.8.11-38 | B4: The Following Masking-Related Events | C4: The following masking-related events shall be logged where technically feasible:.
A5: A.8.11-39 | B5: Masking Configuration Changes (Technique | C5: Masking configuration changes (technique changes, rule updates). Configuration changes shall follow the organisation's change management process: requested by authorised personnel, reviewed by the Security Team, tested in a non-production environment, approved by the Data Owner and Security Team Lead before production deployment, and logged with before/after configuration states.
A6: A.8.11-40 | B6: Monitor For Masking Process Failures, | C6: The organisation shall monitor for masking process failures, repeated bypass attempts, unauthorised configuration changes, and DDM performance degradation. Alerts shall be integrated with the organisation's security monitoring programme.
A7: A.8.11-41 | B7: Re-Identification Attempt Detection*: | C7: Re-identification attempt detection*: The organisation shall implement monitoring to detect potential re-identification attempts, including:.
A8: A.8.11-42 | B8: Detected Re-Identification Attempts | C8: Detected re-identification attempts shall be treated as High-severity security incidents and investigated immediately.

Sheet Incident Response Masking
A1: Incident Response Masking — Compliance Checklist
A2: ISO/IEC 27001:2022 — Control A.8.11: Data Masking
A3: Req # | B3: Section | C3: Requirement | D3: Status | E3: Evidence | F3: Owner | G3: Due Date | H3: Notes
A4: A.8.11-43 | B4: Data Exposure Incidents | C4: Data exposure incidents shall be assessed for breach notification requirements:.
A5: A.8.11-44 | B5: The Dpo And Legal/Compliance | C5: The DPO and Legal/Compliance shall be involved in all breach notification decisions.

Sheet Exception Management
A1: Exception Management — Compliance Checklist
A2: ISO/IEC 27001:2022 — Control A.8.11: Data Masking
A3: Req # | B3: Section | C3: Requirement | D3: Status | E3: Evidence | F3: Owner | G3: Due Date | H3: Notes
A4: A.8.11-45 | B4: Active Exceptions | C4: Active exceptions shall be reviewed quarterly, revoked if business justification changes, and automatically expired at end of approved duration (no implicit renewal).

Sheet Optional Payment Card Data
A1: Optional Payment Card Data — Compliance Checklist
A2: ISO/IEC 27001:2022 — Control A.8.11: Data Masking
A3: Req # | B3: Section | C3: Requirement | D3: Status | E3: Evidence | F3: Owner | G3: Due Date | H3: Notes
A4: A.8.11-46 | B4: Primary Account Numbers (Pans) | C4: Primary Account Numbers (PANs) shall be rendered unreadable anywhere they are stored, per PCI DSS Req. 3.4 (tokenisation, truncation, hashing, or strong encryption).
A5: A.8.11-47 | B5: Show At Most The First Six | C5: When PANs are displayed, masking shall show at most the first six and last four digits, per PCI DSS Req. 3.5.1.
A6: A.8.11-48 | B6: Full Pans | C6: Full PANs shall not be present in non-production environments unless the non-production environment meets all applicable PCI DSS controls. SDM or tokenisation shall be applied before data leaves the cardholder data environment.
A7: A.8.11-49 | B7: Non-Production Use Of Payment Card Data | C7: Non-production use of payment card data shall be governed by a documented data usage policy per PCI DSS Req. 12.3.

Sheet Third-Party Data Sharing Reqs
A1: Third-Party Data Sharing Reqs — Compliance Checklist
A2: ISO/IEC 27001:2022 — Control A.8.11: Data Masking
A3: Req # | B3: Section | C3: Requirement | D3: Status | E3: Evidence | F3: Owner | G3: Due Date | H3: Notes
A4: A.8.11-50 | B4: Contractual Requirements: Data Sharing | C4: Contractual requirements: Data sharing agreements shall specify:.
A5: A.8.11-51 | B5: Risk Assessment: A Data Sharing Risk | C5: Risk assessment: A data sharing risk assessment shall be performed before initial sharing, evaluating re-identification risk, the third party's data handling maturity, and regulatory implications.
A6: A.8.11-52 | B6: Ongoing Monitoring: Data Sharing | C6: Ongoing monitoring: Data sharing arrangements shall be reviewed annually and upon material changes to the third party's environment or the shared data scope.
