Workbook

Sheet Executive Summary
A1: PRIV-CHK-A.1.3.2-4 — Transparency and Information Provision Compliance Checklist
A3: DOCUMENT INFORMATION
A4: Document ID | B4: PRIV-CHK-A.1.3.2-4
A5: Source Policy | B5: PRIV-POL-A.1.3.2-4
A6: ISO Controls | B6: Transparency and Information Provision
A7: Generated | B7: 30.09.2026
A8: Prepared By
A9: Organisation
A10: Review Cycle | B10: Annual
A12: OVERALL COMPLIANCE STATUS
A13: Overall Compliance | B13: ='Dashboard'!G7
A14: Status | B14: =IF(Dashboard!H7>0,"INCOMPLETE",IF(Dashboard!G7="N/A","NOT ASSESSED",IF(ISNUMBER(VALUE(SUBSTITUTE(Dashboard!G7,"%",""))),IF(VALUE(SUBSTITUTE(Dashboard!G7,"%",""))>=90,"GREEN",IF(VALUE(SUBSTITUTE(Dashboard!G7,"%",""))>=70,"AMBER","RED")),"NOT ASSESSED")))
A16: KEY METRICS
A17: Total Requirements | B17: ='Dashboard'!B7
A18: Compliant | B18: ='Dashboard'!C7
A19: Partial | B19: ='Dashboard'!D7
A20: Non-Compliant | B20: ='Dashboard'!E7
A21: Not Applicable | B21: ='Dashboard'!F7
A22: Unanswered | B22: ='Dashboard'!H7
A23: Owner Coverage | B23: =IF(Dashboard!B7=0,"N/A",ROUND((COUNTA('Obligations Identification'!F4:F7)+COUNTA('Information Content Determination'!F4:F8)+COUNTA('Information Provision'!F4:F8))/Dashboard!B7*100,0)&"%")
A25: DOMAIN STATUS SUMMARY
A26: Domain | B26: Compliance % | C26: Compliant | D26: Gaps | E26: Status
A27: Obligations Identification | B27: ='Dashboard'!G4 | C27: ='Dashboard'!C4 | D27: ='Dashboard'!E4 | E27: =IF(Dashboard!H4>0,"INCOMPLETE",IF(Dashboard!G4="N/A","--",IF(ISNUMBER(VALUE(SUBSTITUTE(Dashboard!G4,"%",""))),IF(VALUE(SUBSTITUTE(Dashboard!G4,"%",""))>=90,"PASS",IF(VALUE(SUBSTITUTE(Dashboard!G4,"%",""))>=70,"REVIEW","FAIL")),"--")))
A28: Information Content Determination | B28: ='Dashboard'!G5 | C28: ='Dashboard'!C5 | D28: ='Dashboard'!E5 | E28: =IF(Dashboard!H5>0,"INCOMPLETE",IF(Dashboard!G5="N/A","--",IF(ISNUMBER(VALUE(SUBSTITUTE(Dashboard!G5,"%",""))),IF(VALUE(SUBSTITUTE(Dashboard!G5,"%",""))>=90,"PASS",IF(VALUE(SUBSTITUTE(Dashboard!G5,"%",""))>=70,"REVIEW","FAIL")),"--")))
A29: Information Provision | B29: ='Dashboard'!G6 | C29: ='Dashboard'!C6 | D29: ='Dashboard'!E6 | E29: =IF(Dashboard!H6>0,"INCOMPLETE",IF(Dashboard!G6="N/A","--",IF(ISNUMBER(VALUE(SUBSTITUTE(Dashboard!G6,"%",""))),IF(VALUE(SUBSTITUTE(Dashboard!G6,"%",""))>=90,"PASS",IF(VALUE(SUBSTITUTE(Dashboard!G6,"%",""))>=70,"REVIEW","FAIL")),"--")))
A31: CRITICAL ISSUES
A32: # | B32: Issue Description | C32: Domain | D32: Owner | E32: Due Date
A33: 1
A34: 2
A35: 3
A36: 4
A37: 5
A39: MANAGEMENT COMMENTARY
A40: [Enter management commentary on transparency and information provision posture]
A44: APPROVAL
A45: Assessed By
A46: Name:
A47: Date:
A48: Signature:
A49: Decision:
...

Sheet Dashboard
A1: Transparency and Information Provision — Compliance Dashboard
A3: Domain | B3: Total Reqs | C3: Compliant | D3: Partial | E3: Non-Compliant | F3: N/A | G3: Compliance % | H3: Unassessed
A4: Obligations Identification | B4: =COUNTA('Obligations Identification'!A4:A7) | C4: =COUNTIF('Obligations Identification'!D4:D7,"Compliant") | D4: =COUNTIF('Obligations Identification'!D4:D7,"Partial") | E4: =COUNTIF('Obligations Identification'!D4:D7,"Non-Compliant") | F4: =COUNTIF('Obligations Identification'!D4:D7,"N/A") | G4: =IF((B4-F4)=0,"N/A",ROUND(C4/(B4-F4)*100,1)&"%") | H4: =B4-(C4+D4+E4+F4)
A5: Information Content Determination | B5: =COUNTA('Information Content Determination'!A4:A8) | C5: =COUNTIF('Information Content Determination'!D4:D8,"Compliant") | D5: =COUNTIF('Information Content Determination'!D4:D8,"Partial") | E5: =COUNTIF('Information Content Determination'!D4:D8,"Non-Compliant") | F5: =COUNTIF('Information Content Determination'!D4:D8,"N/A") | G5: =IF((B5-F5)=0,"N/A",ROUND(C5/(B5-F5)*100,1)&"%") | H5: =B5-(C5+D5+E5+F5)
A6: Information Provision | B6: =COUNTA('Information Provision'!A4:A8) | C6: =COUNTIF('Information Provision'!D4:D8,"Compliant") | D6: =COUNTIF('Information Provision'!D4:D8,"Partial") | E6: =COUNTIF('Information Provision'!D4:D8,"Non-Compliant") | F6: =COUNTIF('Information Provision'!D4:D8,"N/A") | G6: =IF((B6-F6)=0,"N/A",ROUND(C6/(B6-F6)*100,1)&"%") | H6: =B6-(C6+D6+E6+F6)
A7: TOTAL | B7: =SUM(B4:B6) | C7: =SUM(C4:C6) | D7: =SUM(D4:D6) | E7: =SUM(E4:E6) | F7: =SUM(F4:F6) | G7: =IF((B7-F7)=0,"N/A",ROUND(C7/(B7-F7)*100,1)&"%") | H7: =SUM(H4:H6)
A9: COMPLIANCE BY STATUS
A10: Compliant | B10: =C7 | C10: =IF(B7=0,"",ROUND(B10/B7*100,1)&"%")
A11: Partial | B11: =D7 | C11: =IF(B7=0,"",ROUND(B11/B7*100,1)&"%")
A12: Non-Compliant | B12: =E7 | C12: =IF(B7=0,"",ROUND(B12/B7*100,1)&"%")
A13: N/A | B13: =F7 | C13: =IF(B7=0,"",ROUND(B13/B7*100,1)&"%")
A15: TOP GAPS (Manual Entry)
A16: Priority | B16: Domain | C16: Requirement | D16: Owner | E16: Due Date | F16: Status
A28: COMPLIANCE TREND (Manual Entry)
A29: Assessment Date | B29: Overall % | C29: Compliant | D29: Gaps | E29: Assessor | F29: Notes

Sheet Obligations Identification
A1: Obligations Identification — Compliance Checklist
A2: ISO/IEC 27701:2025 — Controls A.1.3.2-4: Transparency and Information Provision
A3: Req # | B3: Section | C3: Requirement | D3: Status | E3: Evidence | F3: Owner | G3: Due Date | H3: Notes
A4: A.1.3.2-01 | B4: Obligation Documentation | C4: The organisation shall determine and document its legal, regulatory, and business obligations to PII principals for each processing activity, including transparency obligations, rights obligations, breach notification obligations, and jurisdiction-specific obligations.
A5: A.1.3.2-02 | B5: Obligations Register | C5: The DPO shall maintain a PII Principal Obligations Register (part of the PLRR per PRIV-POL-A.3.13-16) that maps each applicable obligation to the relevant processing activities and describes how the organisation meets each obligation.
A6: A.1.3.2-03 | B6: Means to Meet Obligations | C6: The organisation shall provide the means to meet its obligations to PII principals, including operational processes for responding to data subject rights requests and providing required information at the point of collection.
A7: A.1.3.2-04 | B7: Obligations Review | C7: The PII Principal Obligations Register shall be reviewed at minimum annually, upon regulatory change, and when new processing activities commence, to ensure all applicable obligations are captured and met.

Sheet Information Content Determination
A1: Information Content Determination — Compliance Checklist
A2: ISO/IEC 27701:2025 — Controls A.1.3.2-4: Transparency and Information Provision
A3: Req # | B3: Section | C3: Requirement | D3: Status | E3: Evidence | F3: Owner | G3: Due Date | H3: Notes
A4: A.1.3.3-01 | B4: Mandatory Information Elements — Direct Collection | C4: For PII collected directly from data subjects (GDPR Article 13), the organisation shall determine and document the mandatory elements to be provided at or before the time of collection, including: controller identity; DPO contact; purposes and legal basis; legitimate interests; recipients; third-country transfers and safeguards; retention period; data subject rights; right to withdraw consent; right to lodge a complaint; and automated decision-making information.
A5: A.1.3.3-02 | B5: Mandatory Information Elements — Indirect Collection | C5: For PII obtained indirectly (GDPR Article 14), the organisation shall determine the same information elements as direct collection, plus the source of the PII and whether it came from publicly available sources. This information shall be provided within 1 month of obtaining the PII, or at first communication with the data subject, or at time of disclosure — whichever is earliest.
A6: A.1.3.3-03 | B6: Timing Documentation | C6: The timing of information provision for each processing activity shall be documented. The organisation shall demonstrate that information is provided before or at the point of collection for direct collection activities.
A7: A.1.3.3-04 | B7: Content Review | C7: Privacy notice content shall be reviewed at minimum annually, when a processing activity changes, upon regulatory change affecting required information elements, and when supervisory authority guidance materially changes expectations.
A8: A.1.3.3-05 | B8: Version Control | C8: Privacy notices shall be version-controlled with effective dates maintained. Previous versions shall be retained for 3 years after version retirement to support demonstrability obligations.

Sheet Information Provision
A1: Information Provision — Compliance Checklist
A2: ISO/IEC 27701:2025 — Controls A.1.3.2-4: Transparency and Information Provision
A3: Req # | B3: Section | C3: Requirement | D3: Status | E3: Evidence | F3: Owner | G3: Due Date | H3: Notes
A4: A.1.3.4-01 | B4: Format Requirements | C4: Information provided to PII principals shall be concise, transparent, intelligible, and easily accessible. It shall be provided free of charge and in plain language appropriate to the audience, including simpler language for children's processing.
A5: A.1.3.4-02 | B5: Accessibility | C5: Privacy information shall be published where data subjects will reasonably find it: privacy notice link on the website; in-app privacy information; and printed notice with physical collection. The full privacy notice shall be accessible at all times.
A6: A.1.3.4-03 | B6: Layered Notice | C6: The organisation shall maintain a full privacy notice accessible at all times (via website and on request), supplemented by shorter contextual notices at key data collection points that direct users to the full notice for complete details.
A7: A.1.3.4-04 | B7: Timing of Provision | C7: For online/digital direct collection, privacy information shall be provided at or before the point of collection. For physical collection, at time of collection. For employee PII, at commencement of employment. For indirect collection, within 1 month of obtaining the PII or at first communication — whichever is earliest.
A8: A.1.3.4-05 | B8: Collection Point Evidence | C8: The organisation shall maintain evidence of where and how privacy information is provided at each collection point, demonstrating timely provision to supervisory authorities on request.
