Workbook

Sheet Executive Summary
A1: CLD-PII-CHK-A.8 — Openness, Transparency and Notice Compliance Checklist
A3: DOCUMENT INFORMATION
A4: Document ID | B4: CLD-PII-CHK-A.8
A5: Source Policy | B5: CLD-PII-POL-A.8
A6: ISO Controls | B6: Openness, Transparency and Notice
A7: Generated | B7: 30.09.2026
A8: Prepared By
A9: Organisation
A10: Review Cycle | B10: Annual
A12: OVERALL COMPLIANCE STATUS
A13: Overall Compliance | B13: ='Dashboard'!G6
A14: Status | B14: =IF(Dashboard!H6>0,"INCOMPLETE",IF(Dashboard!G6="N/A","NOT ASSESSED",IF(ISNUMBER(VALUE(SUBSTITUTE(Dashboard!G6,"%",""))),IF(VALUE(SUBSTITUTE(Dashboard!G6,"%",""))>=90,"GREEN",IF(VALUE(SUBSTITUTE(Dashboard!G6,"%",""))>=70,"AMBER","RED")),"NOT ASSESSED")))
A16: KEY METRICS
A17: Total Requirements | B17: ='Dashboard'!B6
A18: Compliant | B18: ='Dashboard'!C6
A19: Partial | B19: ='Dashboard'!D6
A20: Non-Compliant | B20: ='Dashboard'!E6
A21: Not Applicable | B21: ='Dashboard'!F6
A22: Unanswered | B22: ='Dashboard'!H6
A23: Owner Coverage | B23: =IF(Dashboard!B6=0,"N/A",ROUND((COUNTA('Sub-processor Register and Disclosure'!F4:F7)+COUNTA('Change Management and Objection Handling'!F4:F8))/Dashboard!B6*100,0)&"%")
A25: DOMAIN STATUS SUMMARY
A26: Domain | B26: Compliance % | C26: Compliant | D26: Gaps | E26: Status
A27: Sub-processor Register and Disclosure | B27: ='Dashboard'!G4 | C27: ='Dashboard'!C4 | D27: ='Dashboard'!E4 | E27: =IF(Dashboard!H4>0,"INCOMPLETE",IF(Dashboard!G4="N/A","--",IF(ISNUMBER(VALUE(SUBSTITUTE(Dashboard!G4,"%",""))),IF(VALUE(SUBSTITUTE(Dashboard!G4,"%",""))>=90,"PASS",IF(VALUE(SUBSTITUTE(Dashboard!G4,"%",""))>=70,"REVIEW","FAIL")),"--")))
A28: Change Management and Objection Handling | B28: ='Dashboard'!G5 | C28: ='Dashboard'!C5 | D28: ='Dashboard'!E5 | E28: =IF(Dashboard!H5>0,"INCOMPLETE",IF(Dashboard!G5="N/A","--",IF(ISNUMBER(VALUE(SUBSTITUTE(Dashboard!G5,"%",""))),IF(VALUE(SUBSTITUTE(Dashboard!G5,"%",""))>=90,"PASS",IF(VALUE(SUBSTITUTE(Dashboard!G5,"%",""))>=70,"REVIEW","FAIL")),"--")))
A30: CRITICAL ISSUES
A31: # | B31: Issue Description | C31: Domain | D31: Owner | E31: Due Date
A32: 1
A33: 2
A34: 3
A35: 4
A36: 5
A38: MANAGEMENT COMMENTARY
A39: [Enter management commentary on openness, transparency and notice posture]
A43: APPROVAL
A44: Assessed By
A45: Name:
A46: Date:
A47: Signature:
A48: Decision:
A50: Reviewed By (DPO)
...

Sheet Dashboard
A1: Openness, Transparency and Notice — Compliance Dashboard
A3: Domain | B3: Total Reqs | C3: Compliant | D3: Partial | E3: Non-Compliant | F3: N/A | G3: Compliance % | H3: Unassessed
A4: Sub-processor Register and Disclosure | B4: =COUNTA('Sub-processor Register and Disclosure'!A4:A7) | C4: =COUNTIF('Sub-processor Register and Disclosure'!D4:D7,"Compliant") | D4: =COUNTIF('Sub-processor Register and Disclosure'!D4:D7,"Partial") | E4: =COUNTIF('Sub-processor Register and Disclosure'!D4:D7,"Non-Compliant") | F4: =COUNTIF('Sub-processor Register and Disclosure'!D4:D7,"N/A") | G4: =IF((B4-F4)=0,"N/A",ROUND(C4/(B4-F4)*100,1)&"%") | H4: =B4-(C4+D4+E4+F4)
A5: Change Management and Objection Handling | B5: =COUNTA('Change Management and Objection Handling'!A4:A8) | C5: =COUNTIF('Change Management and Objection Handling'!D4:D8,"Compliant") | D5: =COUNTIF('Change Management and Objection Handling'!D4:D8,"Partial") | E5: =COUNTIF('Change Management and Objection Handling'!D4:D8,"Non-Compliant") | F5: =COUNTIF('Change Management and Objection Handling'!D4:D8,"N/A") | G5: =IF((B5-F5)=0,"N/A",ROUND(C5/(B5-F5)*100,1)&"%") | H5: =B5-(C5+D5+E5+F5)
A6: TOTAL | B6: =SUM(B4:B5) | C6: =SUM(C4:C5) | D6: =SUM(D4:D5) | E6: =SUM(E4:E5) | F6: =SUM(F4:F5) | G6: =IF((B6-F6)=0,"N/A",ROUND(C6/(B6-F6)*100,1)&"%") | H6: =SUM(H4:H5)
A8: COMPLIANCE BY STATUS
A9: Compliant | B9: =C6 | C9: =IF(B6=0,"",ROUND(B9/B6*100,1)&"%")
A10: Partial | B10: =D6 | C10: =IF(B6=0,"",ROUND(B10/B6*100,1)&"%")
A11: Non-Compliant | B11: =E6 | C11: =IF(B6=0,"",ROUND(B11/B6*100,1)&"%")
A12: N/A | B12: =F6 | C12: =IF(B6=0,"",ROUND(B12/B6*100,1)&"%")
A14: TOP GAPS (Manual Entry)
A15: Priority | B15: Domain | C15: Requirement | D15: Owner | E15: Due Date | F15: Status
A27: COMPLIANCE TREND (Manual Entry)
A28: Assessment Date | B28: Overall % | C28: Compliant | D28: Gaps | E28: Assessor | F28: Notes

Sheet Sub-processor Register and Disclosure
A1: Sub-processor Register and Disclosure — Compliance Checklist
A2: ISO/IEC 27018:2025 — Controls A.8 / A.8.1: Openness, Transparency and Notice
A3: Req # | B3: Section | C3: Requirement | D3: Status | E3: Evidence | F3: Owner | G3: Due Date | H3: Notes
A4: A.8.1-01 | B4: Sub-processor Register | C4: The organisation shall maintain a Sub-processor Register listing all sub-processors engaged to process PII on the organisation's behalf. For each sub-processor the register shall include: legal entity name; services provided (specific processing operations); PII categories accessed; processing location(s) by country or region; contract reference; controller consent status with date; and date added and last reviewed.
A5: A.8.1-02 | B5: Register Availability | C5: The Sub-processor Register shall be maintained by the DPO and made available to all PII controllers upon request. The organisation shall also publish a current Sub-Processor List on its website or trust portal for controllers operating under general authorisation. The published list shall be consistent with the internal register.
A6: A.8.1-03 | B6: Controller Consent Status | C6: Before any sub-processor is engaged to process PII, documented controller consent shall be obtained — either specific written consent for the individual sub-processor or a general authorisation from the controller to engage sub-processors of the type described, subject to advance notice. No sub-processor shall process PII without a documented consent record in the Sub-processor Register.
A7: A.8.1-04 | B7: Register Currency | C7: The Sub-processor Register shall be updated within 5 business days of any sub-processor change (addition, replacement, material scope change, or termination). Previous versions of the register shall be retained for 5 years to support retrospective audit.

Sheet Change Management and Objection Handling
A1: Change Management and Objection Handling — Compliance Checklist
A2: ISO/IEC 27018:2025 — Controls A.8 / A.8.1: Openness, Transparency and Notice
A3: Req # | B3: Section | C3: Requirement | D3: Status | E3: Evidence | F3: Owner | G3: Due Date | H3: Notes
A4: A.8.1-05 | B4: Advance Notice of Sub-processor Changes | C4: The organisation shall provide advance notice to PII controllers before implementing any intended change to sub-processor arrangements, including engagement of a new sub-processor, replacement of an existing sub-processor, or material change to the scope or location of an existing sub-processor's processing. Unless a service agreement specifies a longer period, the minimum advance notice period is 30 days.
A5: A.8.1-06 | B5: Notice Delivery | C5: Sub-processor change notices shall be delivered via the notification channel specified in the service agreement (e.g., email to the designated data protection contact, trust portal notification, or published change log with subscriber alerts). The notice shall include the identity of the new or changed sub-processor, the nature of processing, and the effective date.
A6: A.8.1-07 | B6: Controller Objection Right | C6: PII controllers operating under general sub-processor authorisation shall have the right to object to any intended sub-processor change during the advance notice period. The organisation's objection handling procedure shall include: acknowledging the objection within 3 business days; engaging with the controller on the grounds; and if the objection cannot be accommodated, allowing contract termination on reasonable terms without penalty.
A7: A.8.1-08 | B7: Emergency Sub-processor Changes | C7: Where the organisation must engage a replacement sub-processor urgently (e.g., due to sub-processor insolvency or security incident), the organisation shall notify affected PII controllers without undue delay, provide written justification for the emergency change, implement equivalent security and privacy controls on the replacement before PII transfer, and formally update the Sub-processor Register within 5 business days.
A8: A.8.1-09 | B8: Objection and Change Records | C8: All controller advance notices, controller objections received, and resolution outcomes shall be documented and retained for 5 years. Timestamped copies of the publicly available sub-processor list at each version shall also be retained for 5 years.
