Workbook

Sheet Instructions & Legend
A1: ISMS-IMP-A.5.7.1 - Threat Intelligence Sources Assessment ISO/IEC 27001:2022 - Control A.5.7: Threat Intelligence
A3: Document Information
A4: Document ID | B4: ISMS-IMP-A.5.7.1
A5: Workbook Title | B5: Threat Intelligence Sources Assessment
A6: Control Reference | B6: ISO/IEC 27001:2022 - Control A.5.7: Threat Intelligence
A7: Version | B7: 1.0
A8: Assessment Date
A9: Completed By
A10: Organisation
A12: Instructions
A13: 1. Document all threat intelligence sources used by your organisation in the Source Inventory sheet (commercial feeds, ISACs, open-source, vendor advisories).
A14: 2. Evaluate each source for reliability, timeliness, accuracy, and relevance in the Source Evaluation sheet using the scoring criteria provided.
A15: 3. Classify sources by intelligence type (strategic, tactical, operational, technical) and threat category in the Source Classification sheet.
A16: 4. Review and record subscription and licensing details for each paid source — including contract start/end dates, renewal status, and contact information.
A17: 5. Use the dropdown menus for standardised ratings: source type, reliability score, and integration status.
A18: 6. Flag sources scoring below acceptable thresholds or with lapsed contracts for review and potential replacement.
A19: 7. Maintain the Evidence Register with subscription agreements, evaluation reports, sample feed outputs, and ISAC membership certificates.
A20: 8. Obtain final sign-off from the Threat Intelligence Lead, Information Security Manager, and CISO.
A22: Status Legend
A23: Symbol | B23: Status | C23: Description
A24: ✓ | B24: Compliant / Complete | C24: Requirement fully met
A25: ⚠ | B25: Partial / In Progress | C25: Partially met or in progress
A26: ✗ | B26: Non-Compliant / Not Started | C26: Requirement not met
A27: — | B27: Not Applicable | C27: Not applicable to this assessment
A29: Acceptable Evidence (examples)
A30: ✓ Threat intelligence feed subscription agreements and service-level agreements
A31: ✓ Source reliability and evaluation reports with scoring rationale
A32: ✓ Sample intelligence feed outputs (sanitised — no classified data)
A33: ✓ ISAC / ISAO membership certificates and access documentation
A34: ✓ Source classification records and periodic review decisions

Sheet Source Inventory
A1: THREAT INTELLIGENCE SOURCE INVENTORY (WITH CVSS CAPABILITY TRACKING)
A2: Document all threat intelligence sources. NEW: Track CVSS v4.0/3.1 support for vulnerability intelligence integration with Control 8.8.
A4: Source ID | B4: Source Name | C4: Source Type | D4: Source Category | E4: Provider | F4: Contact Email | G4: Contract Start | H4: Contract End | I4: Auto Renew | J4: Status | K4: CVSS Support | L4: Primary Owner | M4: Backup Owner | N4: Last Review Date | O4: Next Review Date | P4: Notes
A5: SRC-001 | B5: MISP Community Feed | C5: OSINT | D5: Threat Feed | E5: CIRCL Luxembourg | F5: info@circl.lu | G5: 01.01.2025 | H5: 31.12.2025 | I5: No | J5: Active | K5: Full | L5: CISO | M5: Security Manager | N5: 01.01.2025 | O5: 01.04.2025 | P5: Open-source threat intelligence — primary OSINT feed
O6: =IF(N6<>"", N6+90, "")
O7: =IF(N7<>"", N7+90, "")
O8: =IF(N8<>"", N8+90, "")
O9: =IF(N9<>"", N9+90, "")
O10: =IF(N10<>"", N10+90, "")
O11: =IF(N11<>"", N11+90, "")
O12: =IF(N12<>"", N12+90, "")
O13: =IF(N13<>"", N13+90, "")
O14: =IF(N14<>"", N14+90, "")
O15: =IF(N15<>"", N15+90, "")
O16: =IF(N16<>"", N16+90, "")
O17: =IF(N17<>"", N17+90, "")
... O55: =IF(N55<>"", N55+90, "")

Sheet Source Evaluation
A1: THREAT INTELLIGENCE SOURCE EVALUATION (QUALITY + CVSS ACCURACY ASSESSMENT)
A2: Assess source reliability using Admiralty Code. NEW: Track CVSS accuracy rate per ISMS-POL-A.5.7-S4 Section 4.4.3 (target: ≥90%).
A4: Source ID | B4: Source Name | C4: Evaluation Date | D4: Evaluator | E4: Reliability Rating | F4: Reliability Justification | G4: Credibility Rating | H4: Credibility Justification | I4: Timeliness Score | J4: Timeliness Notes | K4: Relevance Score | L4: Relevance Notes | M4: Actionability Score | N4: Actionability Notes | O4: Overall Quality Score | P4: Quality Rating | Q4: False Positive Rate | R4: CVSS Accuracy Rate | S4: CVSS Sample Size | T4: CVSS Validation Date | U4: Evidence Link | V4: Recommendation | W4: Next Evaluation
A5: SRC-001 | B5: MISP Community Feed | C5: 15.01.2025 | D5: Jane Smith | E5: B | F5: Reliable — consistent accuracy over 12 months | G5: 2 | H5: Independently corroborated by CERT-EU | I5: 4 | J5: Feeds updated daily, occasional 2h delays | K5: 4 | L5: Covers EU threats; limited Asia-Pacific | M5: 4 | N5: High actionability for network-based indicators | O5: =IF(AND(I5<>"",K5<>"",M5<>""),AVERAGE(I5,K5,M5),"") | P5: =IF(O5="","",IF(O5>=4.5,"Excellent",IF(O5>=3.5,"Good",IF(O5>=2.5,"Fair","Poor")))) | Q5: Low | R5: 0.91 | S5: 47 | T5: 10.01.2025 | U5: /evidence/a57/source-eval-2025-01.pdf | V5: Continue | W5: =IF(C5<>"",C5+90,"")
B6: =IF(A6="","",IFERROR(VLOOKUP(A6,'Source Inventory'!$A$6:$P$55,2,FALSE),"[Source Not Found]")) | C6: =IF(A6<>"",TODAY(),"") | O6: =IF(AND(I6<>"",K6<>"",M6<>""),AVERAGE(I6,K6,M6),"") | P6: =IF(O6="","",IF(O6>=4.5,"Excellent",IF(O6>=3.5,"Good",IF(O6>=2.5,"Fair","Poor")))) | W6: =IF(C6<>"",C6+90,"")
B7: =IF(A7="","",IFERROR(VLOOKUP(A7,'Source Inventory'!$A$6:$P$55,2,FALSE),"[Source Not Found]")) | C7: =IF(A7<>"",TODAY(),"") | O7: =IF(AND(I7<>"",K7<>"",M7<>""),AVERAGE(I7,K7,M7),"") | P7: =IF(O7="","",IF(O7>=4.5,"Excellent",IF(O7>=3.5,"Good",IF(O7>=2.5,"Fair","Poor")))) | W7: =IF(C7<>"",C7+90,"")
B8: =IF(A8="","",IFERROR(VLOOKUP(A8,'Source Inventory'!$A$6:$P$55,2,FALSE),"[Source Not Found]")) | C8: =IF(A8<>"",TODAY(),"") | O8: =IF(AND(I8<>"",K8<>"",M8<>""),AVERAGE(I8,K8,M8),"") | P8: =IF(O8="","",IF(O8>=4.5,"Excellent",IF(O8>=3.5,"Good",IF(O8>=2.5,"Fair","Poor")))) | W8: =IF(C8<>"",C8+90,"")
B9: =IF(A9="","",IFERROR(VLOOKUP(A9,'Source Inventory'!$A$6:$P$55,2,FALSE),"[Source Not Found]")) | C9: =IF(A9<>"",TODAY(),"") | O9: =IF(AND(I9<>"",K9<>"",M9<>""),AVERAGE(I9,K9,M9),"") | P9: =IF(O9="","",IF(O9>=4.5,"Excellent",IF(O9>=3.5,"Good",IF(O9>=2.5,"Fair","Poor")))) | W9: =IF(C9<>"",C9+90,"")
B10: =IF(A10="","",IFERROR(VLOOKUP(A10,'Source Inventory'!$A$6:$P$55,2,FALSE),"[Source Not Found]")) | C10: =IF(A10<>"",TODAY(),"") | O10: =IF(AND(I10<>"",K10<>"",M10<>""),AVERAGE(I10,K10,M10),"") | P10: =IF(O10="","",IF(O10>=4.5,"Excellent",IF(O10>=3.5,"Good",IF(O10>=2.5,"Fair","Poor")))) | W10: =IF(C10<>"",C10+90,"")
B11: =IF(A11="","",IFERROR(VLOOKUP(A11,'Source Inventory'!$A$6:$P$55,2,FALSE),"[Source Not Found]")) | C11: =IF(A11<>"",TODAY(),"") | O11: =IF(AND(I11<>"",K11<>"",M11<>""),AVERAGE(I11,K11,M11),"") | P11: =IF(O11="","",IF(O11>=4.5,"Excellent",IF(O11>=3.5,"Good",IF(O11>=2.5,"Fair","Poor")))) | W11: =IF(C11<>"",C11+90,"")
B12: =IF(A12="","",IFERROR(VLOOKUP(A12,'Source Inventory'!$A$6:$P$55,2,FALSE),"[Source Not Found]")) | C12: =IF(A12<>"",TODAY(),"") | O12: =IF(AND(I12<>"",K12<>"",M12<>""),AVERAGE(I12,K12,M12),"") | P12: =IF(O12="","",IF(O12>=4.5,"Excellent",IF(O12>=3.5,"Good",IF(O12>=2.5,"Fair","Poor")))) | W12: =IF(C12<>"",C12+90,"")
B13: =IF(A13="","",IFERROR(VLOOKUP(A13,'Source Inventory'!$A$6:$P$55,2,FALSE),"[Source Not Found]")) | C13: =IF(A13<>"",TODAY(),"") | O13: =IF(AND(I13<>"",K13<>"",M13<>""),AVERAGE(I13,K13,M13),"") | P13: =IF(O13="","",IF(O13>=4.5,"Excellent",IF(O13>=3.5,"Good",IF(O13>=2.5,"Fair","Poor")))) | W13: =IF(C13<>"",C13+90,"")
B14: =IF(A14="","",IFERROR(VLOOKUP(A14,'Source Inventory'!$A$6:$P$55,2,FALSE),"[Source Not Found]")) | C14: =IF(A14<>"",TODAY(),"") | O14: =IF(AND(I14<>"",K14<>"",M14<>""),AVERAGE(I14,K14,M14),"") | P14: =IF(O14="","",IF(O14>=4.5,"Excellent",IF(O14>=3.5,"Good",IF(O14>=2.5,"Fair","Poor")))) | W14: =IF(C14<>"",C14+90,"")
B15: =IF(A15="","",IFERROR(VLOOKUP(A15,'Source Inventory'!$A$6:$P$55,2,FALSE),"[Source Not Found]")) | C15: =IF(A15<>"",TODAY(),"") | O15: =IF(AND(I15<>"",K15<>"",M15<>""),AVERAGE(I15,K15,M15),"") | P15: =IF(O15="","",IF(O15>=4.5,"Excellent",IF(O15>=3.5,"Good",IF(O15>=2.5,"Fair","Poor")))) | W15: =IF(C15<>"",C15+90,"")
B16: =IF(A16="","",IFERROR(VLOOKUP(A16,'Source Inventory'!$A$6:$P$55,2,FALSE),"[Source Not Found]")) | C16: =IF(A16<>"",TODAY(),"") | O16: =IF(AND(I16<>"",K16<>"",M16<>""),AVERAGE(I16,K16,M16),"") | P16: =IF(O16="","",IF(O16>=4.5,"Excellent",IF(O16>=3.5,"Good",IF(O16>=2.5,"Fair","Poor")))) | W16: =IF(C16<>"",C16+90,"")
B17: =IF(A17="","",IFERROR(VLOOKUP(A17,'Source Inventory'!$A$6:$P$55,2,FALSE),"[Source Not Found]")) | C17: =IF(A17<>"",TODAY(),"") | O17: =IF(AND(I17<>"",K17<>"",M17<>""),AVERAGE(I17,K17,M17),"") | P17: =IF(O17="","",IF(O17>=4.5,"Excellent",IF(O17>=3.5,"Good",IF(O17>=2.5,"Fair","Poor")))) | W17: =IF(C17<>"",C17+90,"")
... B55: =IF(A55="","",IFERROR(VLOOKUP(A55,'Source Inventory'!$A$6:$P$55,2,FALSE),"[Source Not Found]")) | C55: =IF(A55<>"",TODAY(),"") | O55: =IF(AND(I55<>"",K55<>"",M55<>""),AVERAGE(I55,K55,M55),"") | P55: =IF(O55="","",IF(O55>=4.5,"Excellent",IF(O55>=3.5,"Good",IF(O55>=2.5,"Fair","Poor")))) | W55: =IF(C55<>"",C55+90,"")

Sheet Coverage Matrix
A1: THREAT INTELLIGENCE COVERAGE MATRIX
A2: Map sources to coverage dimensions to identify gaps. Minimum 2 sources recommended per critical category.
A4: GEOGRAPHIC COVERAGE
A5: Source ID | B5: Source Name | C5: Global | D5: North America | E5: Europe | F5: Asia Pacific | G5: Middle East | H5: Latin America | I5: Africa
B6: =IFERROR(VLOOKUP(A6,'Source Inventory'!A:B,2,FALSE),"")
B7: =IFERROR(VLOOKUP(A7,'Source Inventory'!A:B,2,FALSE),"")
B8: =IFERROR(VLOOKUP(A8,'Source Inventory'!A:B,2,FALSE),"")
B9: =IFERROR(VLOOKUP(A9,'Source Inventory'!A:B,2,FALSE),"")
B10: =IFERROR(VLOOKUP(A10,'Source Inventory'!A:B,2,FALSE),"")
B11: =IFERROR(VLOOKUP(A11,'Source Inventory'!A:B,2,FALSE),"")
B12: =IFERROR(VLOOKUP(A12,'Source Inventory'!A:B,2,FALSE),"")
B13: =IFERROR(VLOOKUP(A13,'Source Inventory'!A:B,2,FALSE),"")
B14: =IFERROR(VLOOKUP(A14,'Source Inventory'!A:B,2,FALSE),"")
B15: =IFERROR(VLOOKUP(A15,'Source Inventory'!A:B,2,FALSE),"")
B16: =IFERROR(VLOOKUP(A16,'Source Inventory'!A:B,2,FALSE),"")
B17: =IFERROR(VLOOKUP(A17,'Source Inventory'!A:B,2,FALSE),"")
... B25: =IFERROR(VLOOKUP(A25,'Source Inventory'!A:B,2,FALSE),"")
A26: Sources per Region: | C26: =COUNTIF(C6:C25,"Yes") | D26: =COUNTIF(D6:D25,"Yes") | E26: =COUNTIF(E6:E25,"Yes") | F26: =COUNTIF(F6:F25,"Yes") | G26: =COUNTIF(G6:G25,"Yes") | H26: =COUNTIF(H6:H25,"Yes") | I26: =COUNTIF(I6:I25,"Yes")
A28: SECTOR COVERAGE
A29: Source ID | B29: Source Name | C29: Financial | D29: Healthcare | E29: Government | F29: Critical Infra | G29: Technology | H29: Education | I29: Retail | J29: Manufacturing | K29: All Sectors
B30: =IFERROR(VLOOKUP(A30,'Source Inventory'!A:B,2,FALSE),"")
B31: =IFERROR(VLOOKUP(A31,'Source Inventory'!A:B,2,FALSE),"")
B32: =IFERROR(VLOOKUP(A32,'Source Inventory'!A:B,2,FALSE),"")
B33: =IFERROR(VLOOKUP(A33,'Source Inventory'!A:B,2,FALSE),"")
B34: =IFERROR(VLOOKUP(A34,'Source Inventory'!A:B,2,FALSE),"")
B35: =IFERROR(VLOOKUP(A35,'Source Inventory'!A:B,2,FALSE),"")
B36: =IFERROR(VLOOKUP(A36,'Source Inventory'!A:B,2,FALSE),"")
B37: =IFERROR(VLOOKUP(A37,'Source Inventory'!A:B,2,FALSE),"")
B38: =IFERROR(VLOOKUP(A38,'Source Inventory'!A:B,2,FALSE),"")
B39: =IFERROR(VLOOKUP(A39,'Source Inventory'!A:B,2,FALSE),"")
B40: =IFERROR(VLOOKUP(A40,'Source Inventory'!A:B,2,FALSE),"")
B41: =IFERROR(VLOOKUP(A41,'Source Inventory'!A:B,2,FALSE),"")
... B49: =IFERROR(VLOOKUP(A49,'Source Inventory'!A:B,2,FALSE),"")
A50: Sources per Sector: | C50: =COUNTIF(C30:C49,"Yes") | D50: =COUNTIF(D30:D49,"Yes") | E50: =COUNTIF(E30:E49,"Yes") | F50: =COUNTIF(F30:F49,"Yes") | G50: =COUNTIF(G30:G49,"Yes") | H50: =COUNTIF(H30:H49,"Yes") | I50: =COUNTIF(I30:I49,"Yes") | J50: =COUNTIF(J30:J49,"Yes")
A52: THREAT TYPE COVERAGE
A53: Source ID | B53: Source Name | C53: Malware | D53: Phishing | E53: Ransomware | F53: Data Breach | G53: DDoS | H53: Insider | I53: Supply Chain | J53: Zero Day | K53: APT | L53: Vulnerabilities
B54: =IFERROR(VLOOKUP(A54,'Source Inventory'!A:B,2,FALSE),"")
B55: =IFERROR(VLOOKUP(A55,'Source Inventory'!A:B,2,FALSE),"")
B56: =IFERROR(VLOOKUP(A56,'Source Inventory'!A:B,2,FALSE),"")
B57: =IFERROR(VLOOKUP(A57,'Source Inventory'!A:B,2,FALSE),"")
...

Sheet Cost Analysis
A1: THREAT INTELLIGENCE COST & ROI ANALYSIS
A2: Track costs, analyse ROI, and manage budget for all threat intelligence sources. Include subscription fees, implementation, and operational costs.
A4: Source ID | B4: Source Name | C4: Annual Cost CHF | D4: Implementation Cost | E4: Operational Cost Annual | F4: Total Cost | G4: Alerts Per Month | H4: Cost Per Alert | I4: Actionable Alerts Pct | J4: Value Rating | K4: ROI Assessment | L4: Budget Next Year | M4: Renewal Date | N4: Notes
A5: SRC-001 | B5: MISP Community Feed | C5: 0 | D5: 2500 | E5: 1200 | F5: =IF(AND(C5="",D5="",E5=""),"",SUM(C5:E5)) | G5: 450 | H5: =IF(OR(F5="",G5="",G5=0),"",F5/(G5*12)) | I5: 85 | J5: Good | K5: Good_Value | L5: 0 | M5: 31.12.2025 | N5: Free OSINT feed; implementation cost for API integration
B6: =IFERROR(VLOOKUP(A6,'Source Inventory'!$A$6:$P$55,2,FALSE),"") | F6: =IF(AND(C6="",D6="",E6=""),"",SUM(C6:E6)) | H6: =IF(OR(F6="",G6="",G6=0),"",F6/(G6*12))
B7: =IFERROR(VLOOKUP(A7,'Source Inventory'!$A$6:$P$55,2,FALSE),"") | F7: =IF(AND(C7="",D7="",E7=""),"",SUM(C7:E7)) | H7: =IF(OR(F7="",G7="",G7=0),"",F7/(G7*12))
B8: =IFERROR(VLOOKUP(A8,'Source Inventory'!$A$6:$P$55,2,FALSE),"") | F8: =IF(AND(C8="",D8="",E8=""),"",SUM(C8:E8)) | H8: =IF(OR(F8="",G8="",G8=0),"",F8/(G8*12))
B9: =IFERROR(VLOOKUP(A9,'Source Inventory'!$A$6:$P$55,2,FALSE),"") | F9: =IF(AND(C9="",D9="",E9=""),"",SUM(C9:E9)) | H9: =IF(OR(F9="",G9="",G9=0),"",F9/(G9*12))
B10: =IFERROR(VLOOKUP(A10,'Source Inventory'!$A$6:$P$55,2,FALSE),"") | F10: =IF(AND(C10="",D10="",E10=""),"",SUM(C10:E10)) | H10: =IF(OR(F10="",G10="",G10=0),"",F10/(G10*12))
B11: =IFERROR(VLOOKUP(A11,'Source Inventory'!$A$6:$P$55,2,FALSE),"") | F11: =IF(AND(C11="",D11="",E11=""),"",SUM(C11:E11)) | H11: =IF(OR(F11="",G11="",G11=0),"",F11/(G11*12))
B12: =IFERROR(VLOOKUP(A12,'Source Inventory'!$A$6:$P$55,2,FALSE),"") | F12: =IF(AND(C12="",D12="",E12=""),"",SUM(C12:E12)) | H12: =IF(OR(F12="",G12="",G12=0),"",F12/(G12*12))
B13: =IFERROR(VLOOKUP(A13,'Source Inventory'!$A$6:$P$55,2,FALSE),"") | F13: =IF(AND(C13="",D13="",E13=""),"",SUM(C13:E13)) | H13: =IF(OR(F13="",G13="",G13=0),"",F13/(G13*12))
B14: =IFERROR(VLOOKUP(A14,'Source Inventory'!$A$6:$P$55,2,FALSE),"") | F14: =IF(AND(C14="",D14="",E14=""),"",SUM(C14:E14)) | H14: =IF(OR(F14="",G14="",G14=0),"",F14/(G14*12))
B15: =IFERROR(VLOOKUP(A15,'Source Inventory'!$A$6:$P$55,2,FALSE),"") | F15: =IF(AND(C15="",D15="",E15=""),"",SUM(C15:E15)) | H15: =IF(OR(F15="",G15="",G15=0),"",F15/(G15*12))
B16: =IFERROR(VLOOKUP(A16,'Source Inventory'!$A$6:$P$55,2,FALSE),"") | F16: =IF(AND(C16="",D16="",E16=""),"",SUM(C16:E16)) | H16: =IF(OR(F16="",G16="",G16=0),"",F16/(G16*12))
B17: =IFERROR(VLOOKUP(A17,'Source Inventory'!$A$6:$P$55,2,FALSE),"") | F17: =IF(AND(C17="",D17="",E17=""),"",SUM(C17:E17)) | H17: =IF(OR(F17="",G17="",G17=0),"",F17/(G17*12))
... B55: =IFERROR(VLOOKUP(A55,'Source Inventory'!$A$6:$P$55,2,FALSE),"") | F55: =IF(AND(C55="",D55="",E55=""),"",SUM(C55:E55)) | H55: =IF(OR(F55="",G55="",G55=0),"",F55/(G55*12))
A57: COST SUMMARY
A58: Total Annual Spend: | B58: =SUM(C6:C55)
A59: Total Implementation: | B59: =SUM(D6:D55)
A60: Total Operational: | B60: =SUM(E6:E55)
A61: Grand Total: | B61: =SUM(F6:F55)
A62: Next Year Budget: | B62: =SUM(L6:L55)
A64: Average Cost Per Alert: | B64: =AVERAGE(H6:H55)

Sheet Compliance Check
A1: THREAT INTELLIGENCE COMPLIANCE VERIFICATION
A2: Verify compliance with GDPR, FADP, data processing agreements, and organisational policies for all TI sources handling personal data.
A4: Source ID | B4: Source Name | C4: Handles PII | D4: GDPR Applicable | E4: FADP Applicable | F4: DPA In Place | G4: DPA Signed Date | H4: DPA Review Date | I4: SCC Required | J4: SCC In Place | K4: Compliance Status | L4: Notes
A5: SRC-001 | B5: MISP Community Feed | C5: No | D5: No | E5: No | F5: No | H5: =IF(G5="","",G5+365) | I5: No | J5: No | K5: ✅ Compliant | L5: OSINT feed; no PII processed
B6: =IFERROR(VLOOKUP(A6,'Source Inventory'!A:B,2,FALSE),"") | H6: =IF(G6="","",G6+365)
B7: =IFERROR(VLOOKUP(A7,'Source Inventory'!A:B,2,FALSE),"") | H7: =IF(G7="","",G7+365)
B8: =IFERROR(VLOOKUP(A8,'Source Inventory'!A:B,2,FALSE),"") | H8: =IF(G8="","",G8+365)
B9: =IFERROR(VLOOKUP(A9,'Source Inventory'!A:B,2,FALSE),"") | H9: =IF(G9="","",G9+365)
B10: =IFERROR(VLOOKUP(A10,'Source Inventory'!A:B,2,FALSE),"") | H10: =IF(G10="","",G10+365)
B11: =IFERROR(VLOOKUP(A11,'Source Inventory'!A:B,2,FALSE),"") | H11: =IF(G11="","",G11+365)
B12: =IFERROR(VLOOKUP(A12,'Source Inventory'!A:B,2,FALSE),"") | H12: =IF(G12="","",G12+365)
B13: =IFERROR(VLOOKUP(A13,'Source Inventory'!A:B,2,FALSE),"") | H13: =IF(G13="","",G13+365)
B14: =IFERROR(VLOOKUP(A14,'Source Inventory'!A:B,2,FALSE),"") | H14: =IF(G14="","",G14+365)
B15: =IFERROR(VLOOKUP(A15,'Source Inventory'!A:B,2,FALSE),"") | H15: =IF(G15="","",G15+365)
B16: =IFERROR(VLOOKUP(A16,'Source Inventory'!A:B,2,FALSE),"") | H16: =IF(G16="","",G16+365)
B17: =IFERROR(VLOOKUP(A17,'Source Inventory'!A:B,2,FALSE),"") | H17: =IF(G17="","",G17+365)
... B55: =IFERROR(VLOOKUP(A55,'Source Inventory'!A:B,2,FALSE),"") | H55: =IF(G55="","",G55+365)
A57: COMPLIANCE SUMMARY
A58: Sources Handling PII: | B58: =COUNTIF(C6:C55,"Yes")
A59: DPAs in Place: | B59: =COUNTIF(F6:F55,"Yes")
A60: DPAs Missing: | B60: =COUNTIFS(C6:C55,"Yes",F6:F55,"No")
A61: Compliant Sources: | B61: =COUNTIF(K6:K55,"Compliant")
A62: Non-Compliant: | B62: =COUNTIF(K6:K55,"Non_Compliant")
A63: Under Review: | B63: =COUNTIF(K6:K55,"Under_Review")

Sheet Action Items
A1: ACTION ITEMS - REMEDIATION AND IMPROVEMENT TASKS
A2: ISO/IEC 27001:2022 | Control A.5.7 | Track remediation tasks and improvements for all threat intelligence source issues
A4: Action ID | B4: Source ID | C4: Issue Type | D4: Issue Description | E4: Detected In Sheet | F4: Priority | G4: Assigned To | H4: Due Date | I4: Status | J4: Status Notes | K4: Resolution Date | L4: Evidence Link | M4: Created Date | N4: Created By | O4: Last Updated
A5: ACT-NNN | B5: SRC-001 | C5: Quality | D5: CVSS accuracy dropped below 85% threshold — source requires re-evaluation | E5: Source Evaluation | F5: High | G5: Security Analyst | H5: 31.03.2025 | I5: Open | J5: Vendor notified — awaiting corrected feed | L5: /evidence/act_src001_quality.pdf | M5: 15.01.2025 | N5: CISO | O5: 15.01.2025

Sheet Metadata
A1: WORKBOOK METADATA AND VERSION CONTROL
A4: Workbook_Version | B4: 2.0
A5: Total_Sheets | B5: 15
A6: Generation_Date | B6: 07.03.2026 12:27:43
A7: Generator_Script | B7: generate_a57_1_sources.py
A8: Script_Version | B8: 2.0.0
A9: Python_Version | B9: 3.12+
A10: openpyxl_Version | B10: 3.1+
A11: Related_Policy | B11: ISMS-POL-A.5.7
A12: Related_IMP_Spec | B12: ISMS-IMP-A.5.7.1 v1.0
A14: V1.0_Changes
A15: CVSS_Support_Added | B15: Sheet 2 - Column K
A16: CVSS_Accuracy_Added | B16: Sheet 3 - Columns R, S, T
A17: Vendor_Mgmt_Added | B17: Sheets 9-13 (Integration, SLAs, Contacts, API)
A18: Audit_Evidence_Added | B18: Sheets 14-15 (Validation, Continuity)
A19: Sheet_14_CRITICAL | B19: Source_Performance_Validation (Quarterly validation per POL Section 4.4.3)
A20: Sheet_15_CRITICAL | B20: Business_Continuity_Plan (Annual testing per POL Section 4.4.6)

Sheet Update Frequency
A1: UPDATE FREQUENCY - SLA COMPLIANCE TRACKING
A2: ISO/IEC 27001:2022 | Control A.5.7 | Track update SLA compliance and timeliness for all threat intelligence sources
A4: Source ID | B4: Source Name | C4: Contractual Frequency | D4: Actual Avg Frequency | E4: Last Update Received | F4: Update Count Last 30 Days | G4: Expected Update Count | H4: Update Variance | I4: SLA Met | J4: SLA Met Justification | K4: Outage Count Last Quarter | L4: Longest Outage Duration | M4: Average Outage Duration | N4: Timeliness Score | O4: Timeliness Trend | P4: Last SLA Review | Q4: Next SLA Review | R4: Notes
A5: SRC-001 | B5: MISP Community Feed | C5: Daily | D5: Daily | E5: 15.02.2025 | F5: 28 | G5: 28 | H5: 0 | I5: Yes | J5: All updates received within SLA window | K5: 0 | L5: N/A | M5: N/A | N5: 98 | O5: Stable | P5: 01.01.2025 | Q5: 01.04.2025 | R5: Highly reliable feed — no issues this quarter
B6: =IFERROR(VLOOKUP(A6,'Source Inventory'!$A$6:$P$55,2,FALSE),"") | Q6: =IF(P6<>"",P6+90,"")
B7: =IFERROR(VLOOKUP(A7,'Source Inventory'!$A$6:$P$55,2,FALSE),"") | Q7: =IF(P7<>"",P7+90,"")
B8: =IFERROR(VLOOKUP(A8,'Source Inventory'!$A$6:$P$55,2,FALSE),"") | Q8: =IF(P8<>"",P8+90,"")
B9: =IFERROR(VLOOKUP(A9,'Source Inventory'!$A$6:$P$55,2,FALSE),"") | Q9: =IF(P9<>"",P9+90,"")
B10: =IFERROR(VLOOKUP(A10,'Source Inventory'!$A$6:$P$55,2,FALSE),"") | Q10: =IF(P10<>"",P10+90,"")
B11: =IFERROR(VLOOKUP(A11,'Source Inventory'!$A$6:$P$55,2,FALSE),"") | Q11: =IF(P11<>"",P11+90,"")
B12: =IFERROR(VLOOKUP(A12,'Source Inventory'!$A$6:$P$55,2,FALSE),"") | Q12: =IF(P12<>"",P12+90,"")
B13: =IFERROR(VLOOKUP(A13,'Source Inventory'!$A$6:$P$55,2,FALSE),"") | Q13: =IF(P13<>"",P13+90,"")
B14: =IFERROR(VLOOKUP(A14,'Source Inventory'!$A$6:$P$55,2,FALSE),"") | Q14: =IF(P14<>"",P14+90,"")
B15: =IFERROR(VLOOKUP(A15,'Source Inventory'!$A$6:$P$55,2,FALSE),"") | Q15: =IF(P15<>"",P15+90,"")
B16: =IFERROR(VLOOKUP(A16,'Source Inventory'!$A$6:$P$55,2,FALSE),"") | Q16: =IF(P16<>"",P16+90,"")
B17: =IFERROR(VLOOKUP(A17,'Source Inventory'!$A$6:$P$55,2,FALSE),"") | Q17: =IF(P17<>"",P17+90,"")
... B55: =IFERROR(VLOOKUP(A55,'Source Inventory'!$A$6:$P$55,2,FALSE),"") | Q55: =IF(P55<>"",P55+90,"")

Sheet Source Contacts
A1: SOURCE CONTACTS - VENDOR ESCALATION AND SUPPORT
A2: ISO/IEC 27001:2022 | Control A.5.7 | Vendor escalation contacts and support channels for all threat intelligence sources
A4: Source ID | B4: Source Name | C4: Contact Type | D4: Contact Name | E4: Contact Title | F4: Contact Email | G4: Contact Phone | H4: Contact Region | I4: Availability | J4: Escalation Path | K4: Preferred Contact Method | L4: Language Supported | M4: Last Contact Date | N4: Last Contact Reason | O4: Response Quality | P4: Response Time | Q4: Contact Status | R4: Replacement Contact | S4: Last Verified | T4: Next Verification | U4: Notes
A5: SRC-001 | B5: MISP Community Feed | C5: Technical Support | D5: Jean-Marc Leroux | E5: Senior Threat Analyst | F5: jm.leroux@circl.lu | G5: +352 621 000001 | H5: Europe | I5: Business Hours CET | J5: Email → Phone → Escalation Manager | K5: Email | L5: English, French | M5: 10.01.2025 | N5: API integration query | O5: Excellent | P5: < 4 hours | Q5: Active | S5: 01.01.2025 | T5: 01.07.2025 | U5: Primary technical contact for API issues
B6: =IFERROR(VLOOKUP(A6,'Source Inventory'!$A$6:$P$55,2,FALSE),"") | T6: =IF(S6<>"",S6+180,"")
B7: =IFERROR(VLOOKUP(A7,'Source Inventory'!$A$6:$P$55,2,FALSE),"") | T7: =IF(S7<>"",S7+180,"")
B8: =IFERROR(VLOOKUP(A8,'Source Inventory'!$A$6:$P$55,2,FALSE),"") | T8: =IF(S8<>"",S8+180,"")
B9: =IFERROR(VLOOKUP(A9,'Source Inventory'!$A$6:$P$55,2,FALSE),"") | T9: =IF(S9<>"",S9+180,"")
B10: =IFERROR(VLOOKUP(A10,'Source Inventory'!$A$6:$P$55,2,FALSE),"") | T10: =IF(S10<>"",S10+180,"")
B11: =IFERROR(VLOOKUP(A11,'Source Inventory'!$A$6:$P$55,2,FALSE),"") | T11: =IF(S11<>"",S11+180,"")
B12: =IFERROR(VLOOKUP(A12,'Source Inventory'!$A$6:$P$55,2,FALSE),"") | T12: =IF(S12<>"",S12+180,"")
B13: =IFERROR(VLOOKUP(A13,'Source Inventory'!$A$6:$P$55,2,FALSE),"") | T13: =IF(S13<>"",S13+180,"")
B14: =IFERROR(VLOOKUP(A14,'Source Inventory'!$A$6:$P$55,2,FALSE),"") | T14: =IF(S14<>"",S14+180,"")
B15: =IFERROR(VLOOKUP(A15,'Source Inventory'!$A$6:$P$55,2,FALSE),"") | T15: =IF(S15<>"",S15+180,"")
B16: =IFERROR(VLOOKUP(A16,'Source Inventory'!$A$6:$P$55,2,FALSE),"") | T16: =IF(S16<>"",S16+180,"")
B17: =IFERROR(VLOOKUP(A17,'Source Inventory'!$A$6:$P$55,2,FALSE),"") | T17: =IF(S17<>"",S17+180,"")
... B55: =IFERROR(VLOOKUP(A55,'Source Inventory'!$A$6:$P$55,2,FALSE),"") | T55: =IF(S55<>"",S55+180,"")

Sheet Vendor SLAs
A1: VENDOR SLAS - PERFORMANCE VS. CONTRACTUAL COMMITMENTS
A2: ISO/IEC 27001:2022 | Control A.5.7 | Track SLA performance vs. contractual commitments for all threat intelligence sources
A4: SLA Record ID | B4: Source ID | C4: Source Name | D4: SLA Metric | E4: Contractual Target | F4: Contractual Target Numeric | G4: Actual Performance | H4: Actual Performance Numeric | I4: Performance Variance | J4: Measurement Period | K4: Measurement Start Date | L4: Measurement End Date | M4: SLA Status | N4: SLA Breach Count | O4: Penalty Clause | P4: Penalty Amount | Q4: Penalty Applied | R4: Penalty Application Date | S4: Credit Received | T4: Escalated To Vendor | U4: Escalation Date | V4: Vendor Response | W4: Last Review Date | X4: Next Review Date | Y4: Reviewer | Z4: Notes
A5: SLA-001 | B5: SRC-001 | C5: MISP Community Feed | D5: Update Frequency | E5: Daily | F5: 1 | G5: Daily | H5: 1 | I5: 0 | J5: Q1 2025 | K5: 01.01.2025 | L5: 31.03.2025 | M5: Met | N5: 0 | O5: No | Q5: No | T5: No | W5: 01.04.2025 | X5: 01.07.2025 | Y5: Security Manager | Z5: All SLAs met for Q1 2025
C6: =IFERROR(VLOOKUP(B6,'Source Inventory'!$A$6:$P$55,2,FALSE),"") | I6: =IF(AND(H6<>"",F6<>""),H6-F6,"")
C7: =IFERROR(VLOOKUP(B7,'Source Inventory'!$A$6:$P$55,2,FALSE),"") | I7: =IF(AND(H7<>"",F7<>""),H7-F7,"")
C8: =IFERROR(VLOOKUP(B8,'Source Inventory'!$A$6:$P$55,2,FALSE),"") | I8: =IF(AND(H8<>"",F8<>""),H8-F8,"")
C9: =IFERROR(VLOOKUP(B9,'Source Inventory'!$A$6:$P$55,2,FALSE),"") | I9: =IF(AND(H9<>"",F9<>""),H9-F9,"")
C10: =IFERROR(VLOOKUP(B10,'Source Inventory'!$A$6:$P$55,2,FALSE),"") | I10: =IF(AND(H10<>"",F10<>""),H10-F10,"")
C11: =IFERROR(VLOOKUP(B11,'Source Inventory'!$A$6:$P$55,2,FALSE),"") | I11: =IF(AND(H11<>"",F11<>""),H11-F11,"")
C12: =IFERROR(VLOOKUP(B12,'Source Inventory'!$A$6:$P$55,2,FALSE),"") | I12: =IF(AND(H12<>"",F12<>""),H12-F12,"")
C13: =IFERROR(VLOOKUP(B13,'Source Inventory'!$A$6:$P$55,2,FALSE),"") | I13: =IF(AND(H13<>"",F13<>""),H13-F13,"")
C14: =IFERROR(VLOOKUP(B14,'Source Inventory'!$A$6:$P$55,2,FALSE),"") | I14: =IF(AND(H14<>"",F14<>""),H14-F14,"")
C15: =IFERROR(VLOOKUP(B15,'Source Inventory'!$A$6:$P$55,2,FALSE),"") | I15: =IF(AND(H15<>"",F15<>""),H15-F15,"")
C16: =IFERROR(VLOOKUP(B16,'Source Inventory'!$A$6:$P$55,2,FALSE),"") | I16: =IF(AND(H16<>"",F16<>""),H16-F16,"")
C17: =IFERROR(VLOOKUP(B17,'Source Inventory'!$A$6:$P$55,2,FALSE),"") | I17: =IF(AND(H17<>"",F17<>""),H17-F17,"")
... C55: =IFERROR(VLOOKUP(B55,'Source Inventory'!$A$6:$P$55,2,FALSE),"") | I55: =IF(AND(H55<>"",F55<>""),H55-F55,"")

Sheet Source Performance Validation
A1: SOURCE PERFORMANCE VALIDATION - QUARTERLY ACCURACY ASSESSMENT (AUDIT CRITICAL)
A2: QUARTERLY REQUIREMENT per ISMS-POL-A.5.7-S4 Section 4.4.3: Validate source accuracy. Sample ≥10 IOCs + ≥10 CVEs per source. Target: ≥85% overall, ≥90% CVSS. Evidence required for audit.
A4: Validation ID | B4: Source ID | C4: Source Name | D4: Validation Quarter | E4: Validation Date | F4: Validator | G4: Validation Method | H4: Total Sample Size | I4: IOC Sample Size | J4: IOC True Positives | K4: IOC False Positives | L4: IOC Accuracy | M4: CVE Sample Size | N4: CVE Accurate | O4: CVE Inaccurate | P4: CVE Accuracy | Q4: CVSS Accurate Count | R4: CVSS Inaccurate Count | S4: CVSS Accuracy Rate | T4: CVSS Accuracy Method | U4: Overall Accuracy Rate | V4: Admiralty Code Source | W4: Admiralty Code Info | X4: Admiralty Combined | Y4: Validation Pass | Z4: Pass Criteria Met | AA4: Action Required | AB4: Action Notes | AC4: Action Item Created | AD4: Action Item ID | AE4: Evidence Location | AF4: Reviewed By | AG4: Review Date | AH4: Next Validation Date
A5: VAL-NNN | B5: SRC-001 | C5: =IFERROR(VLOOKUP(B5,'Source Inventory'!$A$6:$P$55,2,FALSE),"[Not Found]") | D5: Q1 2025 | E5: 15.01.2025 | F5: Jane Smith | G5: Random sampling of IOCs and CVEs from 30-day feed capture | H5: 25 | I5: 12 | J5: 11 | K5: 1 | L5: =IFERROR((J5/I5)*100,"") | M5: 13 | N5: 12 | O5: 1 | P5: =IFERROR((N5/M5)*100,"") | Q5: 12 | R5: 1 | S5: =IFERROR((Q5/M5)*100,"") | T5: Direct comparison with NVD CVSS scores | U5: =IFERROR(((J5+N5)/H5)*100,"") | V5: A | W5: 1 | X5: =IF(AND(V5<>"",W5<>""),CONCATENATE(V5,W5),"") | Y5: =IF(AND(U5>=85,S5>=90),"Pass",IF(AND(U5>=80,S5>=85),"Conditional_Pass","Fail")) | Z5: =IF(U5>=85,"Overall >=85% [OK]","Overall <85% [X]") & ", " & IF(S5>=90,"CVSS >=90% [OK]","CVSS <90% [X]") | AA5: =IF(Y5="Pass","None",IF(Y5="Conditional_Pass","Review",IF(OR(V5="A",V5="B"),"Improve","Deprecate"))) | AB5: High quality source — continue monitoring | AC5: No | AE5: /evidence/a57/val-q1-2025-src001.pdf | AF5: John Doe | AG5: 30.01.2025 | AH5: =IF(E5<>"",E5+90,"")
C6: =IFERROR(VLOOKUP(B6,'Source Inventory'!$A$6:$P$55,2,FALSE),"[Not Found]") | L6: =IFERROR((J6/I6)*100,"") | P6: =IFERROR((N6/M6)*100,"") | S6: =IFERROR((Q6/M6)*100,"") | U6: =IFERROR(((J6+N6)/H6)*100,"") | X6: =IF(AND(V6<>"",W6<>""),CONCATENATE(V6,W6),"") | Y6: =IF(AND(U6>=85,S6>=90),"Pass",IF(AND(U6>=80,S6>=85),"Conditional_Pass","Fail")) | Z6: =IF(U6>=85,"Overall >=85% [OK]","Overall <85% [X]") & ", " & IF(S6>=90,"CVSS >=90% [OK]","CVSS <90% [X]") | AA6: =IF(Y6="Pass","None",IF(Y6="Conditional_Pass","Review",IF(OR(V6="A",V6="B"),"Improve","Deprecate"))) | AH6: =IF(E6<>"",E6+90,"")
C7: =IFERROR(VLOOKUP(B7,'Source Inventory'!$A$6:$P$55,2,FALSE),"[Not Found]") | L7: =IFERROR((J7/I7)*100,"") | P7: =IFERROR((N7/M7)*100,"") | S7: =IFERROR((Q7/M7)*100,"") | U7: =IFERROR(((J7+N7)/H7)*100,"") | X7: =IF(AND(V7<>"",W7<>""),CONCATENATE(V7,W7),"") | Y7: =IF(AND(U7>=85,S7>=90),"Pass",IF(AND(U7>=80,S7>=85),"Conditional_Pass","Fail")) | Z7: =IF(U7>=85,"Overall >=85% [OK]","Overall <85% [X]") & ", " & IF(S7>=90,"CVSS >=90% [OK]","CVSS <90% [X]") | AA7: =IF(Y7="Pass","None",IF(Y7="Conditional_Pass","Review",IF(OR(V7="A",V7="B"),"Improve","Deprecate"))) | AH7: =IF(E7<>"",E7+90,"")
C8: =IFERROR(VLOOKUP(B8,'Source Inventory'!$A$6:$P$55,2,FALSE),"[Not Found]") | L8: =IFERROR((J8/I8)*100,"") | P8: =IFERROR((N8/M8)*100,"") | S8: =IFERROR((Q8/M8)*100,"") | U8: =IFERROR(((J8+N8)/H8)*100,"") | X8: =IF(AND(V8<>"",W8<>""),CONCATENATE(V8,W8),"") | Y8: =IF(AND(U8>=85,S8>=90),"Pass",IF(AND(U8>=80,S8>=85),"Conditional_Pass","Fail")) | Z8: =IF(U8>=85,"Overall >=85% [OK]","Overall <85% [X]") & ", " & IF(S8>=90,"CVSS >=90% [OK]","CVSS <90% [X]") | AA8: =IF(Y8="Pass","None",IF(Y8="Conditional_Pass","Review",IF(OR(V8="A",V8="B"),"Improve","Deprecate"))) | AH8: =IF(E8<>"",E8+90,"")
C9: =IFERROR(VLOOKUP(B9,'Source Inventory'!$A$6:$P$55,2,FALSE),"[Not Found]") | L9: =IFERROR((J9/I9)*100,"") | P9: =IFERROR((N9/M9)*100,"") | S9: =IFERROR((Q9/M9)*100,"") | U9: =IFERROR(((J9+N9)/H9)*100,"") | X9: =IF(AND(V9<>"",W9<>""),CONCATENATE(V9,W9),"") | Y9: =IF(AND(U9>=85,S9>=90),"Pass",IF(AND(U9>=80,S9>=85),"Conditional_Pass","Fail")) | Z9: =IF(U9>=85,"Overall >=85% [OK]","Overall <85% [X]") & ", " & IF(S9>=90,"CVSS >=90% [OK]","CVSS <90% [X]") | AA9: =IF(Y9="Pass","None",IF(Y9="Conditional_Pass","Review",IF(OR(V9="A",V9="B"),"Improve","Deprecate"))) | AH9: =IF(E9<>"",E9+90,"")
C10: =IFERROR(VLOOKUP(B10,'Source Inventory'!$A$6:$P$55,2,FALSE),"[Not Found]") | L10: =IFERROR((J10/I10)*100,"") | P10: =IFERROR((N10/M10)*100,"") | S10: =IFERROR((Q10/M10)*100,"") | U10: =IFERROR(((J10+N10)/H10)*100,"") | X10: =IF(AND(V10<>"",W10<>""),CONCATENATE(V10,W10),"") | Y10: =IF(AND(U10>=85,S10>=90),"Pass",IF(AND(U10>=80,S10>=85),"Conditional_Pass","Fail")) | Z10: =IF(U10>=85,"Overall >=85% [OK]","Overall <85% [X]") & ", " & IF(S10>=90,"CVSS >=90% [OK]","CVSS <90% [X]") | AA10: =IF(Y10="Pass","None",IF(Y10="Conditional_Pass","Review",IF(OR(V10="A",V10="B"),"Improve","Deprecate"))) | AH10: =IF(E10<>"",E10+90,"")
C11: =IFERROR(VLOOKUP(B11,'Source Inventory'!$A$6:$P$55,2,FALSE),"[Not Found]") | L11: =IFERROR((J11/I11)*100,"") | P11: =IFERROR((N11/M11)*100,"") | S11: =IFERROR((Q11/M11)*100,"") | U11: =IFERROR(((J11+N11)/H11)*100,"") | X11: =IF(AND(V11<>"",W11<>""),CONCATENATE(V11,W11),"") | Y11: =IF(AND(U11>=85,S11>=90),"Pass",IF(AND(U11>=80,S11>=85),"Conditional_Pass","Fail")) | Z11: =IF(U11>=85,"Overall >=85% [OK]","Overall <85% [X]") & ", " & IF(S11>=90,"CVSS >=90% [OK]","CVSS <90% [X]") | AA11: =IF(Y11="Pass","None",IF(Y11="Conditional_Pass","Review",IF(OR(V11="A",V11="B"),"Improve","Deprecate"))) | AH11: =IF(E11<>"",E11+90,"")
C12: =IFERROR(VLOOKUP(B12,'Source Inventory'!$A$6:$P$55,2,FALSE),"[Not Found]") | L12: =IFERROR((J12/I12)*100,"") | P12: =IFERROR((N12/M12)*100,"") | S12: =IFERROR((Q12/M12)*100,"") | U12: =IFERROR(((J12+N12)/H12)*100,"") | X12: =IF(AND(V12<>"",W12<>""),CONCATENATE(V12,W12),"") | Y12: =IF(AND(U12>=85,S12>=90),"Pass",IF(AND(U12>=80,S12>=85),"Conditional_Pass","Fail")) | Z12: =IF(U12>=85,"Overall >=85% [OK]","Overall <85% [X]") & ", " & IF(S12>=90,"CVSS >=90% [OK]","CVSS <90% [X]") | AA12: =IF(Y12="Pass","None",IF(Y12="Conditional_Pass","Review",IF(OR(V12="A",V12="B"),"Improve","Deprecate"))) | AH12: =IF(E12<>"",E12+90,"")
C13: =IFERROR(VLOOKUP(B13,'Source Inventory'!$A$6:$P$55,2,FALSE),"[Not Found]") | L13: =IFERROR((J13/I13)*100,"") | P13: =IFERROR((N13/M13)*100,"") | S13: =IFERROR((Q13/M13)*100,"") | U13: =IFERROR(((J13+N13)/H13)*100,"") | X13: =IF(AND(V13<>"",W13<>""),CONCATENATE(V13,W13),"") | Y13: =IF(AND(U13>=85,S13>=90),"Pass",IF(AND(U13>=80,S13>=85),"Conditional_Pass","Fail")) | Z13: =IF(U13>=85,"Overall >=85% [OK]","Overall <85% [X]") & ", " & IF(S13>=90,"CVSS >=90% [OK]","CVSS <90% [X]") | AA13: =IF(Y13="Pass","None",IF(Y13="Conditional_Pass","Review",IF(OR(V13="A",V13="B"),"Improve","Deprecate"))) | AH13: =IF(E13<>"",E13+90,"")
C14: =IFERROR(VLOOKUP(B14,'Source Inventory'!$A$6:$P$55,2,FALSE),"[Not Found]") | L14: =IFERROR((J14/I14)*100,"") | P14: =IFERROR((N14/M14)*100,"") | S14: =IFERROR((Q14/M14)*100,"") | U14: =IFERROR(((J14+N14)/H14)*100,"") | X14: =IF(AND(V14<>"",W14<>""),CONCATENATE(V14,W14),"") | Y14: =IF(AND(U14>=85,S14>=90),"Pass",IF(AND(U14>=80,S14>=85),"Conditional_Pass","Fail")) | Z14: =IF(U14>=85,"Overall >=85% [OK]","Overall <85% [X]") & ", " & IF(S14>=90,"CVSS >=90% [OK]","CVSS <90% [X]") | AA14: =IF(Y14="Pass","None",IF(Y14="Conditional_Pass","Review",IF(OR(V14="A",V14="B"),"Improve","Deprecate"))) | AH14: =IF(E14<>"",E14+90,"")
C15: =IFERROR(VLOOKUP(B15,'Source Inventory'!$A$6:$P$55,2,FALSE),"[Not Found]") | L15: =IFERROR((J15/I15)*100,"") | P15: =IFERROR((N15/M15)*100,"") | S15: =IFERROR((Q15/M15)*100,"") | U15: =IFERROR(((J15+N15)/H15)*100,"") | X15: =IF(AND(V15<>"",W15<>""),CONCATENATE(V15,W15),"") | Y15: =IF(AND(U15>=85,S15>=90),"Pass",IF(AND(U15>=80,S15>=85),"Conditional_Pass","Fail")) | Z15: =IF(U15>=85,"Overall >=85% [OK]","Overall <85% [X]") & ", " & IF(S15>=90,"CVSS >=90% [OK]","CVSS <90% [X]") | AA15: =IF(Y15="Pass","None",IF(Y15="Conditional_Pass","Review",IF(OR(V15="A",V15="B"),"Improve","Deprecate"))) | AH15: =IF(E15<>"",E15+90,"")
C16: =IFERROR(VLOOKUP(B16,'Source Inventory'!$A$6:$P$55,2,FALSE),"[Not Found]") | L16: =IFERROR((J16/I16)*100,"") | P16: =IFERROR((N16/M16)*100,"") | S16: =IFERROR((Q16/M16)*100,"") | U16: =IFERROR(((J16+N16)/H16)*100,"") | X16: =IF(AND(V16<>"",W16<>""),CONCATENATE(V16,W16),"") | Y16: =IF(AND(U16>=85,S16>=90),"Pass",IF(AND(U16>=80,S16>=85),"Conditional_Pass","Fail")) | Z16: =IF(U16>=85,"Overall >=85% [OK]","Overall <85% [X]") & ", " & IF(S16>=90,"CVSS >=90% [OK]","CVSS <90% [X]") | AA16: =IF(Y16="Pass","None",IF(Y16="Conditional_Pass","Review",IF(OR(V16="A",V16="B"),"Improve","Deprecate"))) | AH16: =IF(E16<>"",E16+90,"")
C17: =IFERROR(VLOOKUP(B17,'Source Inventory'!$A$6:$P$55,2,FALSE),"[Not Found]") | L17: =IFERROR((J17/I17)*100,"") | P17: =IFERROR((N17/M17)*100,"") | S17: =IFERROR((Q17/M17)*100,"") | U17: =IFERROR(((J17+N17)/H17)*100,"") | X17: =IF(AND(V17<>"",W17<>""),CONCATENATE(V17,W17),"") | Y17: =IF(AND(U17>=85,S17>=90),"Pass",IF(AND(U17>=80,S17>=85),"Conditional_Pass","Fail")) | Z17: =IF(U17>=85,"Overall >=85% [OK]","Overall <85% [X]") & ", " & IF(S17>=90,"CVSS >=90% [OK]","CVSS <90% [X]") | AA17: =IF(Y17="Pass","None",IF(Y17="Conditional_Pass","Review",IF(OR(V17="A",V17="B"),"Improve","Deprecate"))) | AH17: =IF(E17<>"",E17+90,"")
... C55: =IFERROR(VLOOKUP(B55,'Source Inventory'!$A$6:$P$55,2,FALSE),"[Not Found]") | L55: =IFERROR((J55/I55)*100,"") | P55: =IFERROR((N55/M55)*100,"") | S55: =IFERROR((Q55/M55)*100,"") | U55: =IFERROR(((J55+N55)/H55)*100,"") | X55: =IF(AND(V55<>"",W55<>""),CONCATENATE(V55,W55),"") | Y55: =IF(AND(U55>=85,S55>=90),"Pass",IF(AND(U55>=80,S55>=85),"Conditional_Pass","Fail")) | Z55: =IF(U55>=85,"Overall >=85% [OK]","Overall <85% [X]") & ", " & IF(S55>=90,"CVSS >=90% [OK]","CVSS <90% [X]") | AA55: =IF(Y55="Pass","None",IF(Y55="Conditional_Pass","Review",IF(OR(V55="A",V55="B"),"Improve","Deprecate"))) | AH55: =IF(E55<>"",E55+90,"")

Sheet Evidence Register
A1: EVIDENCE REGISTER
A2: ISMS-IMP-A.5.7.1 | ISO/IEC 27001:2022 - Control A.5.7: Threat Intelligence
A4: Evidence ID | B4: Assessment Area | C4: Evidence Type | D4: Description | E4: Location / Path | F4: Date Collected | G4: Collected By | H4: Verification Status
A5: EV-001 | B5: Threat Intelligence Sources | C5: Screenshot | D5: MISP Community Feed configuration showing active subscription and API integration | E5: /evidence/a57/misp-feed-config-2025-01-15.png | F5: 07.03.2026 | G5: Security Manager | H5: ✅ Verified

Sheet Summary Dashboard
A1: ISMS-IMP-A.5.7.1 — THREAT INTELLIGENCE SOURCES ASSESSMENT — SUMMARY DASHBOARD
A2: ISO/IEC 27001:2022 | Control A.5.7 | Source health, compliance status, and open actions
A4: TABLE 1: STATUS DISTRIBUTION
A5: Section A: Source Inventory Status ('Source Inventory' — Column J, rows 6:55)
A6: Status | B6: Count | C6: % of Total
A7: Active | B7: =COUNTIF('Source Inventory'!J6:J55,"Active") | C7: =IF($B$12=0,"—",TEXT(B7/$B$12,"0.0%"))
A8: Inactive | B8: =COUNTIF('Source Inventory'!J6:J55,"Inactive") | C8: =IF($B$12=0,"—",TEXT(B8/$B$12,"0.0%"))
A9: Trial | B9: =COUNTIF('Source Inventory'!J6:J55,"Trial") | C9: =IF($B$12=0,"—",TEXT(B9/$B$12,"0.0%"))
A10: Pending_Renewal | B10: =COUNTIF('Source Inventory'!J6:J55,"Pending_Renewal") | C10: =IF($B$12=0,"—",TEXT(B10/$B$12,"0.0%"))
A11: Cancelled | B11: =COUNTIF('Source Inventory'!J6:J55,"Cancelled") | C11: =IF($B$12=0,"—",TEXT(B11/$B$12,"0.0%"))
A12: TOTAL | B12: =SUM(B7:B11) | C12: —
A13: Section B: Compliance Check Status ('Compliance Check' — Column K, rows 6:55)
A14: Status | B14: Count | C14: % of Total
A15: ✅ Compliant | B15: =COUNTIF('Compliance Check'!K6:K55,"✅ Compliant") | C15: =IF($B$19=0,"—",TEXT(B15/$B$19,"0.0%"))
A16: ❌ Non_Compliant | B16: =COUNTIF('Compliance Check'!K6:K55,"❌ Non_Compliant") | C16: =IF($B$19=0,"—",TEXT(B16/$B$19,"0.0%"))
A17: ⚠ Under_Review | B17: =COUNTIF('Compliance Check'!K6:K55,"⚠ Under_Review") | C17: =IF($B$19=0,"—",TEXT(B17/$B$19,"0.0%"))
A18: — Not_Applicable | B18: =COUNTIF('Compliance Check'!K6:K55,"— Not_Applicable") | C18: =IF($B$19=0,"—",TEXT(B18/$B$19,"0.0%"))
A19: TOTAL | B19: =SUM(B15:B18) | C19: —
A21: TABLE 2: KEY PERFORMANCE INDICATORS
A22: KPI Metric | B22: Value | C22: Notes
A23: Total Sources in Inventory | B23: =COUNTA('Source Inventory'!A6:A55) | C23: All sources tracked in Source Inventory
A24: Active Sources | B24: =COUNTIF('Source Inventory'!J6:J55,"Active") | C24: Sources with status = Active
A25: Compliant Sources | B25: =COUNTIF('Compliance Check'!K6:K55,"✅ Compliant") | C25: Sources meeting compliance requirements
A26: Non-Compliant Sources | B26: =COUNTIF('Compliance Check'!K6:K55,"❌ Non_Compliant") | C26: Sources failing compliance check — requires action
A27: Open Action Items | B27: =COUNTIF('Action Items'!I6:I55,"Open") | C27: Action Items with status = Open
A28: Blocked Action Items | B28: =COUNTIF('Action Items'!I6:I55,"Blocked") | C28: Action Items blocked — requires escalation
A30: TABLE 3: CRITICAL FINDINGS
A31: Finding | B31: Count | C31: Action Required
A32: Non-Compliant Sources | B32: =COUNTIF('Compliance Check'!K6:K55,"❌ Non_Compliant") | C32: Review and remediate all non-compliant sources immediately
A33: Inactive or Cancelled Sources | B33: =COUNTIF('Source Inventory'!J6:J55,"Inactive")+COUNTIF('Source Inventory'!J6:J55,"Cancelled") | C33: Confirm inactive sources are intentional; archive or remove cancelled
A34: Blocked Action Items | B34: =COUNTIF('Action Items'!I6:I55,"Blocked") | C34: Escalate blocked actions — identify dependency and unblock

Sheet Approval Sign-Off
A1: ASSESSMENT APPROVAL AND SIGN-OFF
A2: ISMS-IMP-A.5.7.1 | ISO/IEC 27001:2022 - Control A.5.7: Threat Intelligence
A3: ASSESSMENT SUMMARY
A4: Document: | B4: ISMS-IMP-A.5.7.1 - Threat Intelligence Sources Assessment
A5: Assessment Period:
A6: Overall Compliance Rate: | B6: =IFERROR('Summary Dashboard'!B15/'Summary Dashboard'!B19,"")
A7: Assessment Status:
A8: Assessed By:
A11: COMPLETED BY (ASSESSOR)
A12: Name:
A13: Title:
A14: Date:
A15: Signature:
A16: Comments:
A18: REVIEWED BY (INFORMATION SECURITY OFFICER)
A19: Name:
A20: Title:
A21: Date:
... A38: Special Considerations:
