Workbook

Sheet Executive Summary
A1: ISMS-OP-CHK-A.7.1-2-3 — Physical Access Control Compliance Checklist
A3: DOCUMENT INFORMATION
A4: Document ID | B4: ISMS-OP-CHK-A.7.1-2-3
A5: Source Policy | B5: ISMS-OP-POL-A.7.1-2-3
A6: ISO Controls | B6: Physical Access Control
A7: Generated | B7: 08.02.2026
A8: Prepared By
A9: Organisation
A10: Review Cycle | B10: Annual
A12: OVERALL COMPLIANCE STATUS
A13: Overall Compliance | B13: ='Dashboard'!G8
A14: Status | B14: =IF(Dashboard!G8="N/A","NOT ASSESSED",IF(ISNUMBER(VALUE(SUBSTITUTE(Dashboard!G8,"%",""))),IF(VALUE(SUBSTITUTE(Dashboard!G8,"%",""))>=90,"GREEN",IF(VALUE(SUBSTITUTE(Dashboard!G8,"%",""))>=70,"AMBER","RED")),"NOT ASSESSED"))
A16: KEY METRICS
A17: Total Requirements | B17: ='Dashboard'!B8
A18: Compliant | B18: ='Dashboard'!C8
A19: Partial | B19: ='Dashboard'!D8
A20: Non-Compliant | B20: ='Dashboard'!E8
A21: Not Applicable | B21: ='Dashboard'!F8
A22: Owner Coverage | B22: =IF(Dashboard!B8=0,"N/A",ROUND((COUNTA('Physical Security Perimeters'!F4:F25)+COUNTA('Physical Entry Controls'!F4:F48)+COUNTA('Securing Offices, Rooms'!F4:F30)+COUNTA('Compliance Measurement'!F4:F4))/Dashboard!B8*100,0)&"%")
A24: DOMAIN STATUS SUMMARY
A25: Domain | B25: Compliance % | C25: Compliant | D25: Gaps | E25: Status
A26: Physical Security Perimeters | B26: ='Dashboard'!G4 | C26: ='Dashboard'!C4 | D26: ='Dashboard'!E4 | E26: =IF(Dashboard!G4="N/A","--",IF(ISNUMBER(VALUE(SUBSTITUTE(Dashboard!G4,"%",""))),IF(VALUE(SUBSTITUTE(Dashboard!G4,"%",""))>=90,"PASS",IF(VALUE(SUBSTITUTE(Dashboard!G4,"%",""))>=70,"REVIEW","FAIL")),"--"))
A27: Physical Entry Controls | B27: ='Dashboard'!G5 | C27: ='Dashboard'!C5 | D27: ='Dashboard'!E5 | E27: =IF(Dashboard!G5="N/A","--",IF(ISNUMBER(VALUE(SUBSTITUTE(Dashboard!G5,"%",""))),IF(VALUE(SUBSTITUTE(Dashboard!G5,"%",""))>=90,"PASS",IF(VALUE(SUBSTITUTE(Dashboard!G5,"%",""))>=70,"REVIEW","FAIL")),"--"))
A28: Securing Offices, Rooms | B28: ='Dashboard'!G6 | C28: ='Dashboard'!C6 | D28: ='Dashboard'!E6 | E28: =IF(Dashboard!G6="N/A","--",IF(ISNUMBER(VALUE(SUBSTITUTE(Dashboard!G6,"%",""))),IF(VALUE(SUBSTITUTE(Dashboard!G6,"%",""))>=90,"PASS",IF(VALUE(SUBSTITUTE(Dashboard!G6,"%",""))>=70,"REVIEW","FAIL")),"--"))
A29: Compliance Measurement | B29: ='Dashboard'!G7 | C29: ='Dashboard'!C7 | D29: ='Dashboard'!E7 | E29: =IF(Dashboard!G7="N/A","--",IF(ISNUMBER(VALUE(SUBSTITUTE(Dashboard!G7,"%",""))),IF(VALUE(SUBSTITUTE(Dashboard!G7,"%",""))>=90,"PASS",IF(VALUE(SUBSTITUTE(Dashboard!G7,"%",""))>=70,"REVIEW","FAIL")),"--"))
A31: CRITICAL ISSUES
A32: # | B32: Issue Description | C32: Domain | D32: Owner | E32: Due Date
A33: 1
A34: 2
A35: 3
A36: 4
A37: 5
A39: MANAGEMENT COMMENTARY
A40: [Enter management commentary on physical access control posture]
A44: APPROVAL
A45: Assessed By
A46: Name:
A47: Date:
A48: Signature:
A49: Decision:
...

Sheet Dashboard
A1: Physical Access Control — Compliance Dashboard
A3: Domain | B3: Total Reqs | C3: Compliant | D3: Partial | E3: Non-Compliant | F3: N/A | G3: Compliance %
A4: Physical Security Perimeters | B4: =COUNTA('Physical Security Perimeters'!D4:D25) | C4: =COUNTIF('Physical Security Perimeters'!D4:D25,"Compliant") | D4: =COUNTIF('Physical Security Perimeters'!D4:D25,"Partial") | E4: =COUNTIF('Physical Security Perimeters'!D4:D25,"Non-Compliant") | F4: =COUNTIF('Physical Security Perimeters'!D4:D25,"N/A") | G4: =IF((B4-F4)=0,"N/A",ROUND(C4/(B4-F4)*100,1)&"%")
A5: Physical Entry Controls | B5: =COUNTA('Physical Entry Controls'!D4:D48) | C5: =COUNTIF('Physical Entry Controls'!D4:D48,"Compliant") | D5: =COUNTIF('Physical Entry Controls'!D4:D48,"Partial") | E5: =COUNTIF('Physical Entry Controls'!D4:D48,"Non-Compliant") | F5: =COUNTIF('Physical Entry Controls'!D4:D48,"N/A") | G5: =IF((B5-F5)=0,"N/A",ROUND(C5/(B5-F5)*100,1)&"%")
A6: Securing Offices, Rooms | B6: =COUNTA('Securing Offices, Rooms'!D4:D30) | C6: =COUNTIF('Securing Offices, Rooms'!D4:D30,"Compliant") | D6: =COUNTIF('Securing Offices, Rooms'!D4:D30,"Partial") | E6: =COUNTIF('Securing Offices, Rooms'!D4:D30,"Non-Compliant") | F6: =COUNTIF('Securing Offices, Rooms'!D4:D30,"N/A") | G6: =IF((B6-F6)=0,"N/A",ROUND(C6/(B6-F6)*100,1)&"%")
A7: Compliance Measurement | B7: =COUNTA('Compliance Measurement'!D4:D4) | C7: =COUNTIF('Compliance Measurement'!D4:D4,"Compliant") | D7: =COUNTIF('Compliance Measurement'!D4:D4,"Partial") | E7: =COUNTIF('Compliance Measurement'!D4:D4,"Non-Compliant") | F7: =COUNTIF('Compliance Measurement'!D4:D4,"N/A") | G7: =IF((B7-F7)=0,"N/A",ROUND(C7/(B7-F7)*100,1)&"%")
A8: TOTAL | B8: =SUM(B4:B7) | C8: =SUM(C4:C7) | D8: =SUM(D4:D7) | E8: =SUM(E4:E7) | F8: =SUM(F4:F7) | G8: =IF((B8-F8)=0,"N/A",ROUND(C8/(B8-F8)*100,1)&"%")
A10: COMPLIANCE BY STATUS
A11: Compliant | B11: =C8 | C11: =IF(B8=0,"",ROUND(B11/B8*100,1)&"%")
A12: Partial | B12: =D8 | C12: =IF(B8=0,"",ROUND(B12/B8*100,1)&"%")
A13: Non-Compliant | B13: =E8 | C13: =IF(B8=0,"",ROUND(B13/B8*100,1)&"%")
A14: N/A | B14: =F8 | C14: =IF(B8=0,"",ROUND(B14/B8*100,1)&"%")
A16: TOP GAPS (Manual Entry)
A17: Priority | B17: Domain | C17: Requirement | D17: Owner | E17: Due Date | F17: Status
A29: COMPLIANCE TREND (Manual Entry)
A30: Assessment Date | B30: Overall % | C30: Compliant | D30: Gaps | E30: Assessor | F30: Notes

Sheet Physical Security Perimeters
A1: Physical Security Perimeters — Compliance Checklist
A2: ISO/IEC 27001:2022 — Controls A.7.1-2-3: Physical Access Control
A3: Req # | B3: Section | C3: Requirement | D3: Status | E3: Evidence | F3: Owner | G3: Due Date | H3: Notes
A4: A.7.1-2-3-01 | B4: Define And Document Security Zones Using | C4: The organisation shall define and document security zones using the following classification:.
A5: A.7.1-2-3-02 | B5: Be Documented On Floor Plans With | C5: Each zone shall be documented on floor plans with clearly marked boundaries, entry points, and the access control mechanisms in use.
A6: A.7.1-2-3-03 | B6: External Walls, Roofs, And Floors | C6: External walls, roofs, and floors shall be of solid construction appropriate to the risk.
A7: A.7.1-2-3-04 | B7: External Doors | C7: External doors shall be secured with locks and access control mechanisms (e.g., [Access Control System] badge readers, electronic locks).
A8: A.7.1-2-3-05 | B8: Be Secured, Particularly At Ground Level | C8: Windows shall be secured, particularly at ground level; ground-floor windows in proximity to Restricted or High-Security Zones shall be reinforced or fitted with security glazing.
A9: A.7.1-2-3-06 | B9: Emergency Exits | C9: Emergency exits shall be alarmed and monitored; emergency exits shall not be usable for routine entry from outside.
A10: A.7.1-2-3-07 | B10: Fire Doors On A Security Perimeter | C10: All fire doors on a security perimeter shall be alarmed, monitored, and tested in conjunction with the walls to establish the required level of resistance. Fire doors shall operate in accordance with Swiss fire safety regulations in a failsafe manner.
A11: A.7.1-2-3-08 | B11: Ventilation Points And Service Openings | C11: Ventilation points and service openings shall not provide a bypass route into secured areas.
A12: A.7.1-2-3-09 | B12: Suitable Intrusion Detection Systems | C12: Suitable intrusion detection systems shall be installed in accordance with applicable national or international standards (e.g., EN 50131).
A13: A.7.1-2-3-10 | B13: Partitions Between Controlled, | C13: Partitions between Controlled, Restricted, and High-Security Zones shall extend floor-to-ceiling, including above suspended ceilings and below raised floors.
A14: A.7.1-2-3-11 | B14: Access Points Between Zones | C14: Access points between zones shall have appropriate access controls matching the destination zone.
A15: A.7.1-2-3-12 | B15: Walls Of Restricted And High-Security | C15: Walls of Restricted and High-Security Zones shall prevent visual and audio eavesdropping where the risk assessment requires it.
... A25: A.7.1-2-3-22 | B25: Information Processing Facilities | C25: Information processing facilities separation*: Information processing facilities managed by the organisation shall be physically separated from those managed by external parties sharing the same building or floor.

Sheet Physical Entry Controls
A1: Physical Entry Controls — Compliance Checklist
A2: ISO/IEC 27001:2022 — Controls A.7.1-2-3: Physical Access Control
A3: Req # | B3: Section | C3: Requirement | D3: Status | E3: Evidence | F3: Owner | G3: Due Date | H3: Notes
A4: A.7.1-2-3-23 | B4: Entry Points To Secured Areas | C4: All entry points to secured areas shall be protected:.
A5: A.7.1-2-3-24 | B5: A Staffed Reception Desk Or Equivalent | C5: A staffed reception desk or equivalent control (intercom, video entry) shall operate during business hours.
A6: A.7.1-2-3-25 | B6: An Access Control System ([Access | C6: An access control system ([Access Control System] — e.g., Verkada, Genetec, Honeywell, Lenel, ASSA ABLOY/Salto, or equivalent RFID badge readers, mobile credentials, or biometric readers) shall authenticate all personnel entering beyond the Public Zone. Where systems are in selection, the interim approach and target deployment date shall be documented.
A7: A.7.1-2-3-26 | B7: Anti-Tailgating Measures | C7: Anti-tailgating measures shall be implemented at entry points to Restricted and High-Security Zones:.
A8: A.7.1-2-3-27 | B8: After-Hours Access | C8: After-hours access shall require additional authentication and shall generate alerts to security personnel or the on-call team.
A9: A.7.1-2-3-28 | B9: Side Doors And Secondary Entrances | C9: Side doors and secondary entrances shall have access controls equivalent to the main entrance for the corresponding zone.
A10: A.7.1-2-3-29 | B10: Fire Doors And Emergency Exits | C10: Fire doors and emergency exits shall be alarmed and monitored. Emergency exits shall open outward (per fire regulations) but shall not be openable from outside without authorisation.
A11: A.7.1-2-3-30 | B11: Roof Access Doors And Service Hatches | C11: Roof access doors and service hatches shall be locked and alarmed.
A12: A.7.1-2-3-31 | B12: The Access Control System | C12: The access control system shall log all access events (granted and denied) with identity, timestamp, and entry point.
A13: A.7.1-2-3-32 | B13: Access Rights | C13: Access rights shall be role-based and granted on a need-to-know/need-to-access basis.
A14: A.7.1-2-3-33 | B14: Access Rights | C14: Access rights shall be reviewed quarterly (at minimum); Restricted and High-Security Zone access shall be re-confirmed by the authorising manager.
A15: A.7.1-2-3-34 | B15: Terminated Employee Physical Access | C15: Terminated employee physical access shall be revoked the same day as employment termination, coordinated with HR.
... A48: A.7.1-2-3-67 | B48: Incoming Materials | C48: Incoming materials shall be inspected for hazardous substances where the risk assessment warrants it (context-dependent: chemical, biological, or explosive risks).

Sheet Securing Offices, Rooms
A1: Securing Offices, Rooms — Compliance Checklist
A2: ISO/IEC 27001:2022 — Controls A.7.1-2-3: Physical Access Control
A3: Req # | B3: Section | C3: Requirement | D3: Status | E3: Evidence | F3: Owner | G3: Due Date | H3: Notes
A4: A.7.1-2-3-68 | B4: Be Locked When Unoccupied Outside | C4: Offices shall be locked when unoccupied outside business hours.
A5: A.7.1-2-3-69 | B5: The Clean Desk Policy | C5: The clean desk policy shall be enforced — sensitive documents secured in locked storage when not in active use.
A6: A.7.1-2-3-70 | B6: Be Positioned To Prevent Shoulder | C6: Screens shall be positioned to prevent shoulder surfing by visitors or passers-by.
A7: A.7.1-2-3-71 | B7: Storage Facilities (Cabinets, Safes, | C7: Storage facilities (cabinets, safes, locked drawers) shall be provided for securing classified documents and portable media.
A8: A.7.1-2-3-72 | B8: Areas Processing Confidential Or | C8: Areas processing Confidential or Restricted information (e.g., HR, finance, legal, executive offices) shall have:.
A9: A.7.1-2-3-73 | B9: Be Limited To Authorised It Personnel | C9: Access shall be limited to authorised IT personnel only, with named access lists maintained.
A10: A.7.1-2-3-74 | B10: Multi-Factor Authentication | C10: Multi-factor authentication shall be required (badge + PIN + biometric, or dual-person control).
A11: A.7.1-2-3-75 | B11: Be Logged With Identity And Timestamp | C11: All access shall be logged with identity and timestamp.
A12: A.7.1-2-3-76 | B12: Visitors And Contractors In Server Rooms | C12: Visitors and contractors in server rooms shall be escorted at all times.
A13: A.7.1-2-3-77 | B13: Equivalent Protections | C13: Equivalent protections shall be assured through supplier assurance (ISO 27001 certificate, SOC 2 Type II report) and contractual security requirements.
A14: A.7.1-2-3-78 | B14: Documented Risk Treatment With | C14: Where exact equivalence is not feasible, documented risk treatment with compensating controls shall be recorded.
A15: A.7.1-2-3-79 | B15: Meeting Rooms | C15: Meeting rooms shall be checked for recording devices or materials left behind before sensitive discussions.
... A30: A.7.1-2-3-94 | B30: Checklist: A Standardised Walkthrough | C30: Checklist: A standardised walkthrough checklist shall be maintained and used for all inspections.

Sheet Compliance Measurement
A1: Compliance Measurement — Compliance Checklist
A2: ISO/IEC 27001:2022 — Controls A.7.1-2-3: Physical Access Control
A3: Req # | B3: Section | C3: Requirement | D3: Status | E3: Evidence | F3: Owner | G3: Due Date | H3: Notes
A4: A.7.1-2-3-95 | B4: Metrics Breaching Targets | C4: Metrics breaching targets shall be escalated to CISO immediately and include remediation plan with owner and target date.
