Workbook

Sheet Overview
A1: ISMS-IMP-A.8.8.12 – Vulnerability Management Metrics & KPIs Dashboard
A2: ISO/IEC 27001:2022 - Control A.8.8: Technical Vulnerability Management
A4: Field | B4: Value
A5: Document ID | B5: ISMS-IMP-A.8.8.12
A6: Workbook Title | B6: Vulnerability Management Metrics & KPIs Dashboard
A7: Version | B7: 1.0
A8: Date Created | B8: 31.01.2026
A9: Last Updated | B9: =TODAY()
A10: Classification | B10: Internal
A11: Owner | B11: Vulnerability Management Coordinator
A12: Prepared By | B12: [Name]
A13: Review Cycle | B13: Monthly
A14: Next Review Date | B14: [DD.MM.YYYY]
A15: Approved By | B15: [CISO Name]
A16: Approval Date | B16: [DD.MM.YYYY]
A17: Integration Status | B17: Green
A18: Total Source Workbooks | B18: 11
A19: Linked Workbooks | B19: [Count]
A20: Last Refresh | B20: =NOW()
A22: 📋 USAGE INSTRUCTIONS
A24: 1. PREREQUISITES:
A25: • All 11 source workbooks (IMP-1 through IMP-11) completed
A26: • Document IDs present in Overview/Metadata sheets
A27: • Workbooks normalized using normalize_assessment_files_a88.py
A29: 2. OPENING DASHBOARD:
A30: • Place in same directory as normalized workbooks
A31: • Open in Excel 2016+
A32: • Click 'Update Links' when prompted
A34: 3. REFRESHING DATA:
A35: • Data → Refresh All (or Ctrl+Alt+F5)
A36: • Wait 5-10 seconds for recalculation
... A46: 🔍 QUICK NAVIGATION
A47: → Metric_Definitions | B47: All 80 metrics
A48: → Lifecycle_Metrics | B48: Discovery to closure
A49: → SLA_Performance | B49: SLA tracking
A50: → Success_Rates | B50: Effectiveness
A51: → Risk_Metrics | B51: Risk posture
A52: → Monthly_Trends | B52: 12-month trends
A53: → Quarterly_Aggregations | B53: Board reporting
A54: → Executive_KPI_Dashboard | B54: CISO summary
...

Sheet Metric_Definitions
A1: COMPLETE METRIC DEFINITIONS - ALL 80 METRICS
A4: Metric_ID | B4: Metric_Name | C4: Category | D4: Source_IMP | E4: Source_Workbook | F4: Source_Sheet | G4: Source_Cell_Range | H4: Formula | I4: Unit | J4: Target_Value | K4: Warning_Value | L4: Critical_Value | M4: Calculation_Frequency | N4: Data_Owner | O4: Audit_Relevance | P4: Current_Value | Q4: Status | R4: Notes
A5: M001 | B5: Total Active Vulnerabilities | C5: Discovery | D5: 5 | E5: ISMS-IMP-A.8.8.5.xlsx | F5: Vulnerability_Inventory | G5: A:A | H5: =COUNTA('[ISMS-IMP-A.8.8.5.xlsx]Vulnerability_Inventory'!A:A)-1 | I5: Count | J5: <500 | K5: 500-1000 | L5: >1000 | M5: Daily | N5: VM Coordinator | O5: High | P5: =H5 | Q5: =IF(P5="","",IF(P5<=IFERROR(VALUE(J5),J5),"Green",IF(P5<=IFERROR(VALUE(K5),K5),"Yellow","Red"))) | R5: Master vulnerability count from IMP-5
A6: M002 | B6: New Vulnerabilities (Last 7 Days) | C6: Discovery | D6: 5 | E6: ISMS-IMP-A.8.8.5.xlsx | F6: Vulnerability_Inventory | G6: D:D | H6: =COUNTIF('[ISMS-IMP-A.8.8.5.xlsx]Vulnerability_Inventory'!D:D,">="&TODAY()-7) | I6: Count | J6: <50 | K6: 50-100 | L6: >100 | M6: Daily | N6: VM Coordinator | O6: Medium | P6: =H6 | Q6: =IF(P6="","",IF(P6<=IFERROR(VALUE(J6),J6),"Green",IF(P6<=IFERROR(VALUE(K6),K6),"Yellow","Red"))) | R6: Recent discoveries
A7: M003 | B7: New Vulnerabilities (Last 30 Days) | C7: Discovery | D7: 5 | E7: ISMS-IMP-A.8.8.5.xlsx | F7: Vulnerability_Inventory | G7: D:D | H7: =COUNTIF('[ISMS-IMP-A.8.8.5.xlsx]Vulnerability_Inventory'!D:D,">="&TODAY()-30) | I7: Count | J7: <200 | K7: 200-400 | L7: >400 | M7: Weekly | N7: VM Coordinator | O7: High | P7: =H7 | Q7: =IF(P7="","",IF(P7<=IFERROR(VALUE(J7),J7),"Green",IF(P7<=IFERROR(VALUE(K7),K7),"Yellow","Red"))) | R7: Monthly discovery trend
A8: M004 | B8: Critical CVSS Score Count (≥9.0) | C8: Discovery | D8: 5 | E8: ISMS-IMP-A.8.8.5.xlsx | F8: Vulnerability_Inventory | G8: K:K | H8: =COUNTIF('[ISMS-IMP-A.8.8.5.xlsx]Vulnerability_Inventory'!K:K,">=9.0") | I8: Count | J8: <10 | K8: 10-20 | L8: >20 | M8: Daily | N8: VM Coordinator | O8: Critical | P8: =H8 | Q8: =IF(P8="","",IF(P8<=IFERROR(VALUE(J8),J8),"Green",IF(P8<=IFERROR(VALUE(K8),K8),"Yellow","Red"))) | R8: CVSS ≥9.0 severity
A9: M005 | B9: High CVSS Score Count (7.0-8.9) | C9: Discovery | D9: 5 | E9: ISMS-IMP-A.8.8.5.xlsx | F9: Vulnerability_Inventory | G9: K:K | H9: =COUNTIFS('[ISMS-IMP-A.8.8.5.xlsx]Vulnerability_Inventory'!K:K,">=7.0",'[ISMS-IMP-A.8.8.5.xlsx]Vulnerability_Inventory'!K:K,"<9.0") | I9: Count | J9: <50 | K9: 50-100 | L9: >100 | M9: Daily | N9: VM Coordinator | O9: High | P9: =H9 | Q9: =IF(P9="","",IF(P9<=IFERROR(VALUE(J9),J9),"Green",IF(P9<=IFERROR(VALUE(K9),K9),"Yellow","Red"))) | R9: CVSS 7.0-8.9 severity
A10: M006 | B10: Scanner Uptime Percentage | C10: Discovery | D10: 1 | E10: ISMS-IMP-A.8.8.1.xlsx | F10: Overview | G10: B7 | H10: '[ISMS-IMP-A.8.8.1.xlsx]Overview'!B7 | I10: Percentage | J10: >99% | K10: 95-99% | L10: <95% | M10: Daily | N10: Infrastructure Team | O10: High | P10: =H10 | Q10: =IF(P10="","",IF(P10>=IFERROR(VALUE(LEFT(J10,FIND("%",J10)-1))/100,J10),"Green",IF(P10>=IFERROR(VALUE(LEFT(K10,FIND("%",K10)-1))/100,K10),"Yellow","Red"))) | R10: Scanner availability from IMP-1
A11: M007 | B11: Scan Completion Rate | C11: Discovery | D11: 1 | E11: ISMS-IMP-A.8.8.1.xlsx | F11: Overview | G11: B10 | H11: '[ISMS-IMP-A.8.8.1.xlsx]Overview'!B10 | I11: Percentage | J11: >95% | K11: 90-95% | L11: <90% | M11: Daily | N11: VM Coordinator | O11: High | P11: =H11 | Q11: =IF(P11="","",IF(P11>=IFERROR(VALUE(LEFT(J11,FIND("%",J11)-1))/100,J11),"Green",IF(P11>=IFERROR(VALUE(LEFT(K11,FIND("%",K11)-1))/100,K11),"Yellow","Red"))) | R11: Successful scan execution rate
A12: M008 | B12: Network Coverage Percentage | C12: Discovery | D12: 2 | E12: ISMS-IMP-A.8.8.2.xlsx | F12: Overview | G12: B8 | H12: '[ISMS-IMP-A.8.8.2.xlsx]Overview'!B8 | I12: Percentage | J12: 100% | K12: 95-99% | L12: <95% | M12: Weekly | N12: Network Team | O12: Critical | P12: =H12 | Q12: =IF(P12="","",IF(P12>=IFERROR(VALUE(LEFT(J12,FIND("%",J12)-1))/100,J12),"Green",IF(P12>=IFERROR(VALUE(LEFT(K12,FIND("%",K12)-1))/100,K12),"Yellow","Red"))) | R12: Network segments covered by scanning
A13: M009 | B13: Critical Coverage Gaps | C13: Discovery | D13: 2 | E13: ISMS-IMP-A.8.8.2.xlsx | F13: Overview | G13: B10 | H13: '[ISMS-IMP-A.8.8.2.xlsx]Overview'!B10 | I13: Count | J13: 0 | K13: 1-2 | L13: >2 | M13: Weekly | N13: Network Team | O13: Critical | P13: =H13 | Q13: =IF(P13="","",IF(P13<=IFERROR(VALUE(J13),J13),"Green",IF(P13<=IFERROR(VALUE(K13),K13),"Yellow","Red"))) | R13: Uncovered critical network segments
A14: M010 | B14: Average Vulnerability Age (Days) | C14: Discovery | D14: 5 | E14: ISMS-IMP-A.8.8.5.xlsx | F14: Vulnerability_Inventory | G14: D:D | H14: =AVERAGE(TODAY()-'[ISMS-IMP-A.8.8.5.xlsx]Vulnerability_Inventory'!D:D) | I14: Days | J14: <30 | K14: 30-60 | L14: >60 | M14: Weekly | N14: VM Coordinator | O14: Medium | P14: =H14 | Q14: =IF(P14="","",IF(P14<=IFERROR(VALUE(J14),J14),"Green",IF(P14<=IFERROR(VALUE(K14),K14),"Yellow","Red"))) | R14: Mean age of all active vulnerabilities
A15: M011 | B15: Oldest Vulnerability (Days) | C15: Discovery | D15: 5 | E15: ISMS-IMP-A.8.8.5.xlsx | F15: Vulnerability_Inventory | G15: D:D | H15: =TODAY()-MIN('[ISMS-IMP-A.8.8.5.xlsx]Vulnerability_Inventory'!D:D) | I15: Days | J15: <90 | K15: 90-180 | L15: >180 | M15: Weekly | N15: VM Coordinator | O15: High | P15: =H15 | Q15: =IF(P15="","",IF(P15<=IFERROR(VALUE(J15),J15),"Green",IF(P15<=IFERROR(VALUE(K15),K15),"Yellow","Red"))) | R15: Maximum age (oldest vulnerability)
A16: M012 | B16: CVSS v4.0 Adoption Rate | C16: Discovery | D16: 5 | E16: ISMS-IMP-A.8.8.5.xlsx | F16: Vulnerability_Inventory | G16: J:J | H16: =COUNTIF('[ISMS-IMP-A.8.8.5.xlsx]Vulnerability_Inventory'!J:J,"v4.0")/COUNTA('[ISMS-IMP-A.8.8.5.xlsx]Vulnerability_Inventory'!J:J) | I16: Percentage | J16: >70% | K16: 50-70% | L16: <50% | M16: Monthly | N16: VM Coordinator | O16: Medium | P16: =H16 | Q16: =IF(P16="","",IF(P16>=IFERROR(VALUE(LEFT(J16,FIND("%",J16)-1))/100,J16),"Green",IF(P16>=IFERROR(VALUE(LEFT(K16,FIND("%",K16)-1))/100,K16),"Yellow","Red"))) | R16: Percentage using CVSS v4.0 scoring
A17: M013 | B17: Dual-Scored Vulnerabilities | C17: Discovery | D17: 5 | E17: ISMS-IMP-A.8.8.5.xlsx | F17: Vulnerability_Inventory | G17: J:J | H17: =COUNTIF('[ISMS-IMP-A.8.8.5.xlsx]Vulnerability_Inventory'!J:J,"Both") | I17: Count | J17: >100 | K17: 50-100 | L17: <50 | M17: Monthly | N17: VM Coordinator | O17: Low | P17: =H17 | Q17: =IF(P17="","",IF(P17<=IFERROR(VALUE(J17),J17),"Green",IF(P17<=IFERROR(VALUE(K17),K17),"Yellow","Red"))) | R17: Both v4.0 and v3.1 scores present
A18: M014 | B18: Failed Scans (Last 7 Days) | C18: Discovery | D18: 1 | E18: ISMS-IMP-A.8.8.1.xlsx | F18: Overview | G18: B12 | H18: '[ISMS-IMP-A.8.8.1.xlsx]Overview'!B12 | I18: Count | J18: <5 | K18: 5-10 | L18: >10 | M18: Daily | N18: Infrastructure Team | O18: Medium | P18: =H18 | Q18: =IF(P18="","",IF(P18<=IFERROR(VALUE(J18),J18),"Green",IF(P18<=IFERROR(VALUE(K18),K18),"Yellow","Red"))) | R18: Recent scan failures from IMP-1
A19: M015 | B19: False Positive Rate | C19: Discovery | D19: 1 | E19: ISMS-IMP-A.8.8.1.xlsx | F19: Overview | G19: B13 | H19: '[ISMS-IMP-A.8.8.1.xlsx]Overview'!B13 | I19: Percentage | J19: <5% | K19: 5-10% | L19: >10% | M19: Weekly | N19: VM Coordinator | O19: Medium | P19: =H19 | Q19: =IF(P19="","",IF(P19>=IFERROR(VALUE(LEFT(J19,FIND("%",J19)-1))/100,J19),"Green",IF(P19>=IFERROR(VALUE(LEFT(K19,FIND("%",K19)-1))/100,K19),"Yellow","Red"))) | R19: Scanner false positive percentage
A20: M016 | B20: Wormable Vulnerabilities (AU=Y) | C20: Assessment | D20: 7 | E20: ISMS-IMP-A.8.8.7.xlsx | F20: Dashboard | G20: B8 | H20: '[ISMS-IMP-A.8.8.7.xlsx]Dashboard'!B8 | I20: Count | J20: 0 | K20: 1-2 | L20: >2 | M20: Daily | N20: VM Coordinator | O20: Critical | P20: =H20 | Q20: =IF(P20="","",IF(P20<=IFERROR(VALUE(J20),J20),"Green",IF(P20<=IFERROR(VALUE(K20),K20),"Yellow","Red"))) | R20: Self-propagating vulnerabilities (CVSS v4.0 AU=Yes)
A21: M017 | B21: Safety-Critical Vulnerabilities (S=P) | C21: Assessment | D21: 5 | E21: ISMS-IMP-A.8.8.5.xlsx | F21: Vulnerability_Inventory | G21: Q:Q,K:K | H21: =COUNTIFS('[ISMS-IMP-A.8.8.5.xlsx]Vulnerability_Inventory'!Q:Q,"P",'[ISMS-IMP-A.8.8.5.xlsx]Vulnerability_Inventory'!K:K,">=7.0") | I21: Count | J21: 0 | K21: 1-3 | L21: >3 | M21: Daily | N21: OT/ICS Team | O21: Critical | P21: =H21 | Q21: =IF(P21="","",IF(P21<=IFERROR(VALUE(J21),J21),"Green",IF(P21<=IFERROR(VALUE(K21),K21),"Yellow","Red"))) | R21: OT/ICS safety-critical (CVSS v4.0 S=Present)
A22: M018 | B22: KEV-Listed Vulnerabilities | C22: Assessment | D22: 4 | E22: ISMS-IMP-A.8.8.4.xlsx | F22: TI_Integration_Dashboard | G22: B6 | H22: '[ISMS-IMP-A.8.8.4.xlsx]TI_Integration_Dashboard'!B6 | I22: Count | J22: 0 | K22: 1-3 | L22: >3 | M22: Daily | N22: TI Analyst | O22: Critical | P22: =H22 | Q22: =IF(P22="","",IF(P22<=IFERROR(VALUE(J22),J22),"Green",IF(P22<=IFERROR(VALUE(K22),K22),"Yellow","Red"))) | R22: CISA Known Exploited Vulnerabilities catalog
A23: M019 | B23: Active Exploitation Flags | C23: Assessment | D23: 4 | E23: ISMS-IMP-A.8.8.4.xlsx | F23: TI_Integration_Dashboard | G23: B7 | H23: '[ISMS-IMP-A.8.8.4.xlsx]TI_Integration_Dashboard'!B7 | I23: Count | J23: 0 | K23: 1-2 | L23: >2 | M23: Daily | N23: TI Analyst | O23: Critical | P23: =H23 | Q23: =IF(P23="","",IF(P23<=IFERROR(VALUE(J23),J23),"Green",IF(P23<=IFERROR(VALUE(K23),K23),"Yellow","Red"))) | R23: In-the-wild exploitation detected
A24: M020 | B24: EPSS Coverage Rate | C24: Assessment | D24: 4 | E24: ISMS-IMP-A.8.8.4.xlsx | F24: TI_Integration_Dashboard | G24: B8 | H24: '[ISMS-IMP-A.8.8.4.xlsx]TI_Integration_Dashboard'!B8 | I24: Percentage | J24: >80% | K24: 60-80% | L24: <60% | M24: Weekly | N24: TI Analyst | O24: Medium | P24: =H24 | Q24: =IF(P24="","",IF(P24>=IFERROR(VALUE(LEFT(J24,FIND("%",J24)-1))/100,J24),"Green",IF(P24>=IFERROR(VALUE(LEFT(K24,FIND("%",K24)-1))/100,K24),"Yellow","Red"))) | R24: Exploit Prediction Scoring System coverage
A25: M021 | B25: Total Risk Score | C25: Assessment | D25: 6 | E25: ISMS-IMP-A.8.8.6.xlsx | F25: Risk_Assessment_Matrix | G25: AP:AP | H25: =SUM('[ISMS-IMP-A.8.8.6.xlsx]Risk_Assessment_Matrix'!AP:AP) | I25: Score | J25: <500 | K25: 500-1000 | L25: >1000 | M25: Weekly | N25: Risk Analyst | O25: High | P25: =H25 | Q25: =IF(P25="","",IF(P25<=IFERROR(VALUE(J25),J25),"Green",IF(P25<=IFERROR(VALUE(K25),K25),"Yellow","Red"))) | R25: Aggregate risk score across all vulnerabilities
A26: M022 | B26: Critical Risk Count | C26: Assessment | D26: 6 | E26: ISMS-IMP-A.8.8.6.xlsx | F26: Risk_Assessment_Matrix | G26: AQ:AQ | H26: =COUNTIF('[ISMS-IMP-A.8.8.6.xlsx]Risk_Assessment_Matrix'!AQ:AQ,"Critical") | I26: Count | J26: <5 | K26: 5-10 | L26: >10 | M26: Daily | N26: Risk Analyst | O26: Critical | P26: =H26 | Q26: =IF(P26="","",IF(P26<=IFERROR(VALUE(J26),J26),"Green",IF(P26<=IFERROR(VALUE(K26),K26),"Yellow","Red"))) | R26: Vulnerabilities with Critical risk rating
A27: M023 | B27: High Risk Count | C27: Assessment | D27: 6 | E27: ISMS-IMP-A.8.8.6.xlsx | F27: Risk_Assessment_Matrix | G27: AQ:AQ | H27: =COUNTIF('[ISMS-IMP-A.8.8.6.xlsx]Risk_Assessment_Matrix'!AQ:AQ,"High") | I27: Count | J27: <20 | K27: 20-50 | L27: >50 | M27: Daily | N27: Risk Analyst | O27: High | P27: =H27 | Q27: =IF(P27="","",IF(P27<=IFERROR(VALUE(J27),J27),"Green",IF(P27<=IFERROR(VALUE(K27),K27),"Yellow","Red"))) | R27: Vulnerabilities with High risk rating
A28: M024 | B28: Financial Exposure (CHF) | C28: Assessment | D28: 6 | E28: ISMS-IMP-A.8.8.6.xlsx | F28: Risk_Assessment_Matrix | G28: Z:Z | H28: =SUM('[ISMS-IMP-A.8.8.6.xlsx]Risk_Assessment_Matrix'!Z:Z) | I28: CHF | J28: <500'000 | K28: 500'000-1'000'000 | L28: >1'000'000 | M28: Weekly | N28: Risk Analyst | O28: High | P28: =H28 | Q28: =IF(P28="","",IF(P28<=IFERROR(VALUE(J28),J28),"Green",IF(P28<=IFERROR(VALUE(K28),K28),"Yellow","Red"))) | R28: Total financial impact exposure
A29: M025 | B29: Time to Initial Risk Assessment (Hours) | C29: Assessment | D29: 6 | E29: ISMS-IMP-A.8.8.6.xlsx | F29: Risk_Assessment_Matrix | G29: E:E,D:D | H29: =AVERAGE(('[ISMS-IMP-A.8.8.6.xlsx]Risk_Assessment_Matrix'!E:E-'[ISMS-IMP-A.8.8.5.xlsx]Vulnerability_Inventory'!D:D)*24) | I29: Hours | J29: <24 | K29: 24-48 | L29: >48 | M29: Weekly | N29: Risk Analyst | O29: High | P29: =H29 | Q29: =IF(P29="","",IF(P29<=IFERROR(VALUE(J29),J29),"Green",IF(P29<=IFERROR(VALUE(K29),K29),"Yellow","Red"))) | R29: Discovery to initial risk assessment time
A30: M026 | B30: P0 Emergency Count | C30: Prioritization | D30: 7 | E30: ISMS-IMP-A.8.8.7.xlsx | F30: Dashboard | G30: B7 | H30: '[ISMS-IMP-A.8.8.7.xlsx]Dashboard'!B7 | I30: Count | J30: <5 | K30: 5-10 | L30: >10 | M30: Daily | N30: VM Coordinator | O30: Critical | P30: =H30 | Q30: =IF(P30="","",IF(P30<=IFERROR(VALUE(J30),J30),"Green",IF(P30<=IFERROR(VALUE(K30),K30),"Yellow","Red"))) | R30: Emergency priority (1-day SLA)
A31: M027 | B31: P1 Critical Count | C31: Prioritization | D31: 7 | E31: ISMS-IMP-A.8.8.7.xlsx | F31: Priority_Matrix | G31: AD:AD | H31: =COUNTIF('[ISMS-IMP-A.8.8.7.xlsx]Priority_Matrix'!AD:AD,"P1") | I31: Count | J31: <50 | K31: 50-100 | L31: >100 | M31: Daily | N31: VM Coordinator | O31: High | P31: =H31 | Q31: =IF(P31="","",IF(P31<=IFERROR(VALUE(J31),J31),"Green",IF(P31<=IFERROR(VALUE(K31),K31),"Yellow","Red"))) | R31: Critical priority (7-day SLA)
A32: M028 | B32: P2 Standard Count | C32: Prioritization | D32: 7 | E32: ISMS-IMP-A.8.8.7.xlsx | F32: Priority_Matrix | G32: AD:AD | H32: =COUNTIF('[ISMS-IMP-A.8.8.7.xlsx]Priority_Matrix'!AD:AD,"P2") | I32: Count | J32: <200 | K32: 200-300 | L32: >300 | M32: Weekly | N32: VM Coordinator | O32: Medium | P32: =H32 | Q32: =IF(P32="","",IF(P32<=IFERROR(VALUE(J32),J32),"Green",IF(P32<=IFERROR(VALUE(K32),K32),"Yellow","Red"))) | R32: Standard priority (30-day SLA)
A33: M029 | B33: P3 Medium Count | C33: Prioritization | D33: 7 | E33: ISMS-IMP-A.8.8.7.xlsx | F33: Priority_Matrix | G33: AD:AD | H33: =COUNTIF('[ISMS-IMP-A.8.8.7.xlsx]Priority_Matrix'!AD:AD,"P3") | I33: Count | J33: <300 | K33: 300-500 | L33: >500 | M33: Weekly | N33: VM Coordinator | O33: Low | P33: =H33 | Q33: =IF(P33="","",IF(P33<=IFERROR(VALUE(J33),J33),"Green",IF(P33<=IFERROR(VALUE(K33),K33),"Yellow","Red"))) | R33: Medium priority (90-day SLA)
A34: M030 | B34: P4 Low Count | C34: Prioritization | D34: 7 | E34: ISMS-IMP-A.8.8.7.xlsx | F34: Priority_Matrix | G34: AD:AD | H34: =COUNTIF('[ISMS-IMP-A.8.8.7.xlsx]Priority_Matrix'!AD:AD,"P4") | I34: Count | J34: Any | K34: N/A | L34: N/A | M34: Weekly | N34: VM Coordinator | O34: Low | P34: =H34 | Q34: =IF(P34="","",IF(P34<=IFERROR(VALUE(J34),J34),"Green",IF(P34<=IFERROR(VALUE(K34),K34),"Yellow","Red"))) | R34: Low priority (best-effort)
A35: M031 | B35: Overall SLA Compliance | C35: Prioritization | D35: 7 | E35: ISMS-IMP-A.8.8.7.xlsx | F35: Dashboard | G35: B9 | H35: '[ISMS-IMP-A.8.8.7.xlsx]Dashboard'!B9 | I35: Percentage | J35: >95% | K35: 90-95% | L35: <90% | M35: Daily | N35: VM Coordinator | O35: Critical | P35: =H35 | Q35: =IF(P35="","",IF(P35>=IFERROR(VALUE(LEFT(J35,FIND("%",J35)-1))/100,J35),"Green",IF(P35>=IFERROR(VALUE(LEFT(K35,FIND("%",K35)-1))/100,K35),"Yellow","Red"))) | R35: Aggregate SLA compliance across all priorities
A36: M032 | B36: Overdue Vulnerabilities | C36: Prioritization | D36: 7 | E36: ISMS-IMP-A.8.8.7.xlsx | F36: Dashboard | G36: B10 | H36: '[ISMS-IMP-A.8.8.7.xlsx]Dashboard'!B10 | I36: Count | J36: 0 | K36: 1-5 | L36: >5 | M36: Daily | N36: VM Coordinator | O36: Critical | P36: =H36 | Q36: =IF(P36="","",IF(P36<=IFERROR(VALUE(J36),J36),"Green",IF(P36<=IFERROR(VALUE(K36),K36),"Yellow","Red"))) | R36: Vulnerabilities past remediation SLA
A37: M033 | B37: P0 SLA Compliance (1 Day) | C37: Prioritization | D37: 7 | E37: ISMS-IMP-A.8.8.7.xlsx | F37: Priority_Matrix | G37: AD:AD,AH:AH | H37: =COUNTIFS('[ISMS-IMP-A.8.8.7.xlsx]Priority_Matrix'!AD:AD,"P0",'[ISMS-IMP-A.8.8.7.xlsx]Priority_Matrix'!AH:AH,"On Track")/COUNTIF('[ISMS-IMP-A.8.8.7.xlsx]Priority_Matrix'!AD:AD,"P0") | I37: Percentage | J37: 100% | K37: 95-100% | L37: <95% | M37: Daily | N37: VM Coordinator | O37: Critical | P37: =H37 | Q37: =IF(P37="","",IF(P37>=IFERROR(VALUE(LEFT(J37,FIND("%",J37)-1))/100,J37),"Green",IF(P37>=IFERROR(VALUE(LEFT(K37,FIND("%",K37)-1))/100,K37),"Yellow","Red"))) | R37: Emergency vulnerabilities within 1-day SLA
A38: M034 | B38: P1 SLA Compliance (7 Days) | C38: Prioritization | D38: 7 | E38: ISMS-IMP-A.8.8.7.xlsx | F38: Priority_Matrix | G38: AD:AD,AH:AH | H38: =COUNTIFS('[ISMS-IMP-A.8.8.7.xlsx]Priority_Matrix'!AD:AD,"P1",'[ISMS-IMP-A.8.8.7.xlsx]Priority_Matrix'!AH:AH,"On Track")/COUNTIF('[ISMS-IMP-A.8.8.7.xlsx]Priority_Matrix'!AD:AD,"P1") | I38: Percentage | J38: >95% | K38: 90-95% | L38: <90% | M38: Daily | N38: VM Coordinator | O38: High | P38: =H38 | Q38: =IF(P38="","",IF(P38>=IFERROR(VALUE(LEFT(J38,FIND("%",J38)-1))/100,J38),"Green",IF(P38>=IFERROR(VALUE(LEFT(K38,FIND("%",K38)-1))/100,K38),"Yellow","Red"))) | R38: Critical vulnerabilities within 7-day SLA
A39: M035 | B39: Manual Priority Overrides | C39: Prioritization | D39: 7 | E39: ISMS-IMP-A.8.8.7.xlsx | F39: Priority_Matrix | G39: AJ:AJ | H39: =COUNTIF('[ISMS-IMP-A.8.8.7.xlsx]Priority_Matrix'!AJ:AJ,"Manual") | I39: Count | J39: <10 | K39: 10-20 | L39: >20 | M39: Weekly | N39: VM Coordinator | O39: Medium | P39: =H39 | Q39: =IF(P39="","",IF(P39<=IFERROR(VALUE(J39),J39),"Green",IF(P39<=IFERROR(VALUE(K39),K39),"Yellow","Red"))) | R39: Priorities manually adjusted from calculated value
A40: M036 | B40: Total Active Remediations | C40: Remediation | D40: 8 | E40: ISMS-IMP-A.8.8.8.xlsx | F40: Metrics_Dashboard | G40: B6 | H40: '[ISMS-IMP-A.8.8.8.xlsx]Metrics_Dashboard'!B6 | I40: Count | J40: <500 | K40: 500-750 | L40: >750 | M40: Daily | N40: Remediation Team | O40: High | P40: =H40 | Q40: =IF(P40="","",IF(P40<=IFERROR(VALUE(J40),J40),"Green",IF(P40<=IFERROR(VALUE(K40),K40),"Yellow","Red"))) | R40: Vulnerabilities in remediation queue
A41: M037 | B41: Remediation SLA Compliance | C41: Remediation | D41: 8 | E41: ISMS-IMP-A.8.8.8.xlsx | F41: Metrics_Dashboard | G41: B7 | H41: '[ISMS-IMP-A.8.8.8.xlsx]Metrics_Dashboard'!B7 | I41: Percentage | J41: >95% | K41: 90-95% | L41: <90% | M41: Daily | N41: Remediation Team | O41: Critical | P41: =H41 | Q41: =IF(P41="","",IF(P41>=IFERROR(VALUE(LEFT(J41,FIND("%",J41)-1))/100,J41),"Green",IF(P41>=IFERROR(VALUE(LEFT(K41,FIND("%",K41)-1))/100,K41),"Yellow","Red"))) | R41: Remediations completed within SLA
A42: M038 | B42: Average Remediation Time (Days) | C42: Remediation | D42: 8 | E42: ISMS-IMP-A.8.8.8.xlsx | F42: Metrics_Dashboard | G42: B8 | H42: '[ISMS-IMP-A.8.8.8.xlsx]Metrics_Dashboard'!B8 | I42: Days | J42: <14 | K42: 14-21 | L42: >21 | M42: Weekly | N42: Remediation Team | O42: High | P42: =H42 | Q42: =IF(P42="","",IF(P42<=IFERROR(VALUE(J42),J42),"Green",IF(P42<=IFERROR(VALUE(K42),K42),"Yellow","Red"))) | R42: Mean time from start to completion
...

Sheet Lifecycle_Metrics
A1: VULNERABILITY LIFECYCLE FUNNEL
A6: 🔍 DISCOVERY | B6: =Metric_Definitions!P1 | C6: Target: <500
A8: 📡 SCANNING | B8: =Metric_Definitions!P8 | C8: Target: 100%
A10: ⚖️ ASSESSMENT | B10: =Metric_Definitions!P22 | C10: Target: <5
A12: 🎯 PRIORITIZATION | B12: =Metric_Definitions!P31 | C12: Target: >95%
A14: 🔧 REMEDIATION | B14: =Metric_Definitions!P37 | C14: Target: >95%
A16: ✅ VERIFICATION | B16: =Metric_Definitions!P53 | C16: Target: >95%
A18: 🎉 CLOSED | B18: =Metric_Definitions!P50 | C18: Target: >200

Sheet SLA_Performance
A1: SLA PERFORMANCE DASHBOARD
A3: SLA Category | B3: Current % | C3: Target % | D3: Status
A4: Overall SLA Compliance | B4: =Metric_Definitions!P31 | C4: >95% | D4: =IF(B4>=C4,"✅ Met","❌ Violated")
A5: P0 Emergency (1 Day) | B5: =Metric_Definitions!P33 | C5: 100% | D5: =IF(B5>=C5,"✅ Met","❌ Violated")
A6: P1 Critical (7 Days) | B6: =Metric_Definitions!P34 | C6: >95% | D6: =IF(B6>=C6,"✅ Met","❌ Violated")
A7: Remediation SLA | B7: =Metric_Definitions!P37 | C7: >95% | D7: =IF(B7>=C7,"✅ Met","❌ Violated")
A8: Verification SLA | B8: =Metric_Definitions!P59 | C8: >95% | D8: =IF(B8>=C8,"✅ Met","❌ Violated")

Sheet Success_Rates
A1: SUCCESS RATE DASHBOARD
A3: Success Metric | B3: Current % | C3: Target % | D3: Gap %
A4: Deployment Success | B4: =Metric_Definitions!P39 | C4: >98% | D4: =B4-VALUE(LEFT(C4,FIND("%",C4)-1))/100
A5: Verification Success | B5: =Metric_Definitions!P53 | C5: >95% | D5: =B5-VALUE(LEFT(C5,FIND("%",C5)-1))/100
A6: Scanner Uptime | B6: =Metric_Definitions!P6 | C6: >99% | D6: =B6-VALUE(LEFT(C6,FIND("%",C6)-1))/100
A7: Scan Completion | B7: =Metric_Definitions!P7 | C7: >95% | D7: =B7-VALUE(LEFT(C7,FIND("%",C7)-1))/100
A8: Network Coverage | B8: =Metric_Definitions!P8 | C8: 100% | D8: =B8-VALUE(LEFT(C8,FIND("%",C8)-1))/100

Sheet Risk_Metrics
A1: RISK METRICS DASHBOARD
A3: Risk Metric | B3: Current | C3: Target | D3: Status
A4: Critical Risk Count | B4: =Metric_Definitions!P22 | C4: <5 | D4: =IF(B4<5,"🟢","🔴")
A5: Total Risk Score | B5: =Metric_Definitions!P21 | C5: <500 | D5: =IF(B5<500,"🟢","🔴")
A6: Critical Residual Risk | B6: =Metric_Definitions!P62 | C6: 0 | D6: =IF(B6=0,"🟢","🔴")
A7: Active Exceptions | B7: =Metric_Definitions!P61 | C7: <30 | D7: =IF(B7<30,"🟢","🔴")
A8: Wormable Vulns (AU=Y) | B8: =Metric_Definitions!P16 | C8: 0 | D8: =IF(B8=0,"🟢","🔴")
A9: KEV Vulns | B9: =Metric_Definitions!P18 | C9: 0 | D9: =IF(B9=0,"🟢","🔴")
A10: Financial Exposure | B10: =Metric_Definitions!P24 | C10: <500000 | D10: =IF(B10<500000,"🟢","🔴")

Sheet Monthly_Trends
A1: MONTHLY TREND ANALYSIS (12 MONTHS)
A4: Metric | B4: M-11 | C4: M-10 | D4: M-9 | E4: M-8 | F4: M-7 | G4: M-6 | H4: M-5 | I4: M-4 | J4: M-3 | K4: M-2 | L4: M-1 | M4: M-0 | N4: Trend
A5: Total Active Vulns (M001) | B5: [Manual] | C5: [Manual] | D5: [Manual] | E5: [Manual] | F5: [Manual] | G5: [Manual] | H5: [Manual] | I5: [Manual] | J5: [Manual] | K5: [Manual] | L5: [Manual] | M5: [Manual]
A6: P0 Count (M026) | B6: [Manual] | C6: [Manual] | D6: [Manual] | E6: [Manual] | F6: [Manual] | G6: [Manual] | H6: [Manual] | I6: [Manual] | J6: [Manual] | K6: [Manual] | L6: [Manual] | M6: [Manual]
A7: SLA Compliance (M031) | B7: [Manual] | C7: [Manual] | D7: [Manual] | E7: [Manual] | F7: [Manual] | G7: [Manual] | H7: [Manual] | I7: [Manual] | J7: [Manual] | K7: [Manual] | L7: [Manual] | M7: [Manual]
A8: Critical Risk (M022) | B8: [Manual] | C8: [Manual] | D8: [Manual] | E8: [Manual] | F8: [Manual] | G8: [Manual] | H8: [Manual] | I8: [Manual] | J8: [Manual] | K8: [Manual] | L8: [Manual] | M8: [Manual]
A9: Deployment Success (M039) | B9: [Manual] | C9: [Manual] | D9: [Manual] | E9: [Manual] | F9: [Manual] | G9: [Manual] | H9: [Manual] | I9: [Manual] | J9: [Manual] | K9: [Manual] | L9: [Manual] | M9: [Manual]
A12: ⚠️ UPDATE MONTHLY: Copy current values from Metric_Definitions column P

Sheet Quarterly_Aggregations
A1: QUARTERLY PERFORMANCE AGGREGATIONS
A3: Metric | B3: Q1 2026 | C3: Q2 2026 | D3: Q3 2026 | E3: Q4 2026 | F3: YoY %
A4: Vulns Discovered (Sum) | B4: [Manual Quarterly Data] | C4: [Manual Quarterly Data] | D4: [Manual Quarterly Data] | E4: [Manual Quarterly Data]
A5: Vulns Closed (Sum) | B5: [Manual Quarterly Data] | C5: [Manual Quarterly Data] | D5: [Manual Quarterly Data] | E5: [Manual Quarterly Data]
A6: SLA Compliance (Avg) | B6: [Manual Quarterly Data] | C6: [Manual Quarterly Data] | D6: [Manual Quarterly Data] | E6: [Manual Quarterly Data]
A7: Deployment Success (Avg) | B7: [Manual Quarterly Data] | C7: [Manual Quarterly Data] | D7: [Manual Quarterly Data] | E7: [Manual Quarterly Data]
A8: Verification Success (Avg) | B8: [Manual Quarterly Data] | C8: [Manual Quarterly Data] | D8: [Manual Quarterly Data] | E8: [Manual Quarterly Data]

Sheet Executive_KPI_Dashboard
A1: VULNERABILITY MANAGEMENT EXECUTIVE DASHBOARD
A2: Period: 31.01.2026 | E2: Program Status: [Green/Yellow/Red]
A4: 🔴 CRITICAL METRICS (IMMEDIATE ATTENTION)
A6: P0 Emergencies | E6: SLA Compliance %
A7: =Metric_Definitions!P26 | E7: =Metric_Definitions!P31
A8: Target: <5 | E8: Target: >95%
A10: Critical Residual Risk | E10: Verification Success %
A11: =Metric_Definitions!P62 | E11: =Metric_Definitions!P53
A12: Target: 0 | E12: Target: >95%
A14: 📊 OPERATIONAL HEALTH (10 KEY METRICS)
A16: Metric | B16: Current | C16: Target | D16: Status
A17: Scanner Uptime % | B17: =Metric_Definitions!P6 | C17: >99% | D17: ✅
A18: Network Coverage % | B18: =Metric_Definitions!P8 | C18: 100% | D18: ✅
A19: Deployment Success % | B19: =Metric_Definitions!P39 | C19: >98% | D19: ✅
A20: Avg Remediation Time | B20: =Metric_Definitions!P38 | C20: <14d | D20: ✅
A21: Active Exceptions | B21: =Metric_Definitions!P61 | C21: <30 | D21: ✅
A22: Wormable Vulns | B22: =Metric_Definitions!P16 | C22: 0 | D22: ✅
A23: KEV Vulns | B23: =Metric_Definitions!P18 | C23: 0 | D23: ✅
A24: Overdue Vulns | B24: =Metric_Definitions!P32 | C24: 0 | D24: ✅
A25: Failed Verifications | B25: =Metric_Definitions!P55 | C25: 0 | D25: ✅
A26: Expired Exceptions | B26: =Metric_Definitions!P65 | C26: 0 | D26: ✅
A28: 💬 EXECUTIVE SUMMARY (MANUAL INPUT)
A29: [Program Status - Update monthly with key achievements, issues, initiatives]
A33: CISO Approval: _______________ | E33: Date: _______________

Sheet Benchmark_Targets
A1: INDUSTRY BENCHMARK COMPARISON
A3: Metric | B3: Industry Benchmark | C3: Our Current | D3: Gap % | E3: Status | F3: Source
A4: SLA Compliance | B4: 93% | C4: =Metric_Definitions!P31 | D4: =IF(ISNUMBER(C{idx}),C{idx}-VALUE(B{idx}),"N/A") | E4: =IF(D4="N/A","Track",IF(D4>=0,"🟢 Exceeding","🔴 Below")) | F4: SANS 2024
A5: Avg Remediation Time | B5: 18 days | C5: =Metric_Definitions!P38 | D5: =IF(ISNUMBER(C{idx}),C{idx}-VALUE(B{idx}),"N/A") | E5: =IF(D5="N/A","Track",IF(D5>=0,"🟢 Exceeding","🔴 Below")) | F5: SANS 2024
A6: Deployment Success | B6: 96% | C6: =Metric_Definitions!P39 | D6: =IF(ISNUMBER(C{idx}),C{idx}-VALUE(B{idx}),"N/A") | E6: =IF(D6="N/A","Track",IF(D6>=0,"🟢 Exceeding","🔴 Below")) | F6: SANS 2024
A7: Verification Success | B7: 92% | C7: =Metric_Definitions!P53 | D7: =IF(ISNUMBER(C{idx}),C{idx}-VALUE(B{idx}),"N/A") | E7: =IF(D7="N/A","Track",IF(D7>=0,"🟢 Exceeding","🔴 Below")) | F7: SANS 2024
A8: Scanner Uptime | B8: 99.5% | C8: =Metric_Definitions!P6 | D8: =IF(ISNUMBER(C{idx}),C{idx}-VALUE(B{idx}),"N/A") | E8: =IF(D8="N/A","Track",IF(D8>=0,"🟢 Exceeding","🔴 Below")) | F8: SANS 2024
A9: Network Coverage | B9: 98% | C9: =Metric_Definitions!P8 | D9: =IF(ISNUMBER(C{idx}),C{idx}-VALUE(B{idx}),"N/A") | E9: =IF(D9="N/A","Track",IF(D9>=0,"🟢 Exceeding","🔴 Below")) | F9: SANS 2024
A10: MTTR (Days) | B10: 21 | C10: =Metric_Definitions!P38 | D10: =IF(ISNUMBER(C{idx}),C{idx}-VALUE(B{idx}),"N/A") | E10: =IF(D10="N/A","Track",IF(D10>=0,"🟢 Exceeding","🔴 Below")) | F10: Ponemon 2024
