Workbook

Sheet Executive Summary
A1: ISMS-OP-CHK-A.5.30-8.13-14 — Business Continuity and Disaster Recovery Compliance Checklist
A3: DOCUMENT INFORMATION
A4: Document ID | B4: ISMS-OP-CHK-A.5.30-8.13-14
A5: Source Policy | B5: ISMS-OP-POL-A.5.30-8.13-14
A6: ISO Controls | B6: Business Continuity and Disaster Recovery
A7: Generated | B7: 30.09.2026
A8: Prepared By
A9: Organisation
A10: Review Cycle | B10: Annual
A12: OVERALL COMPLIANCE STATUS
A13: Overall Compliance | B13: ='Dashboard'!G9
A14: Status | B14: =IF(Dashboard!H9>0,"INCOMPLETE",IF(Dashboard!G9="N/A","NOT ASSESSED",IF(ISNUMBER(VALUE(SUBSTITUTE(Dashboard!G9,"%",""))),IF(VALUE(SUBSTITUTE(Dashboard!G9,"%",""))>=90,"GREEN",IF(VALUE(SUBSTITUTE(Dashboard!G9,"%",""))>=70,"AMBER","RED")),"NOT ASSESSED")))
A16: KEY METRICS
A17: Total Requirements | B17: ='Dashboard'!B9
A18: Compliant | B18: ='Dashboard'!C9
A19: Partial | B19: ='Dashboard'!D9
A20: Non-Compliant | B20: ='Dashboard'!E9
A21: Not Applicable | B21: ='Dashboard'!F9
A22: Unanswered | B22: ='Dashboard'!H9
A23: Owner Coverage | B23: =IF(Dashboard!B9=0,"N/A",ROUND((COUNTA('Business Impact Analysis'!F4:F9)+COUNTA('Information Backup'!F4:F32)+COUNTA('Redundancy Info Process'!F4:F12)+COUNTA('ICT Continuity Planning'!F4:F21)+COUNTA('BC DR Metrics and Reporting'!F4:F5))/Dashboard!B9*100,0)&"%")
A25: DOMAIN STATUS SUMMARY
A26: Domain | B26: Compliance % | C26: Compliant | D26: Gaps | E26: Status
A27: Business Impact Analysis | B27: ='Dashboard'!G4 | C27: ='Dashboard'!C4 | D27: ='Dashboard'!E4 | E27: =IF(Dashboard!H4>0,"INCOMPLETE",IF(Dashboard!G4="N/A","--",IF(ISNUMBER(VALUE(SUBSTITUTE(Dashboard!G4,"%",""))),IF(VALUE(SUBSTITUTE(Dashboard!G4,"%",""))>=90,"PASS",IF(VALUE(SUBSTITUTE(Dashboard!G4,"%",""))>=70,"REVIEW","FAIL")),"--")))
A28: Information Backup | B28: ='Dashboard'!G5 | C28: ='Dashboard'!C5 | D28: ='Dashboard'!E5 | E28: =IF(Dashboard!H5>0,"INCOMPLETE",IF(Dashboard!G5="N/A","--",IF(ISNUMBER(VALUE(SUBSTITUTE(Dashboard!G5,"%",""))),IF(VALUE(SUBSTITUTE(Dashboard!G5,"%",""))>=90,"PASS",IF(VALUE(SUBSTITUTE(Dashboard!G5,"%",""))>=70,"REVIEW","FAIL")),"--")))
A29: Redundancy Info Process | B29: ='Dashboard'!G6 | C29: ='Dashboard'!C6 | D29: ='Dashboard'!E6 | E29: =IF(Dashboard!H6>0,"INCOMPLETE",IF(Dashboard!G6="N/A","--",IF(ISNUMBER(VALUE(SUBSTITUTE(Dashboard!G6,"%",""))),IF(VALUE(SUBSTITUTE(Dashboard!G6,"%",""))>=90,"PASS",IF(VALUE(SUBSTITUTE(Dashboard!G6,"%",""))>=70,"REVIEW","FAIL")),"--")))
A30: ICT Continuity Planning | B30: ='Dashboard'!G7 | C30: ='Dashboard'!C7 | D30: ='Dashboard'!E7 | E30: =IF(Dashboard!H7>0,"INCOMPLETE",IF(Dashboard!G7="N/A","--",IF(ISNUMBER(VALUE(SUBSTITUTE(Dashboard!G7,"%",""))),IF(VALUE(SUBSTITUTE(Dashboard!G7,"%",""))>=90,"PASS",IF(VALUE(SUBSTITUTE(Dashboard!G7,"%",""))>=70,"REVIEW","FAIL")),"--")))
A31: BC DR Metrics and Reporting | B31: ='Dashboard'!G8 | C31: ='Dashboard'!C8 | D31: ='Dashboard'!E8 | E31: =IF(Dashboard!H8>0,"INCOMPLETE",IF(Dashboard!G8="N/A","--",IF(ISNUMBER(VALUE(SUBSTITUTE(Dashboard!G8,"%",""))),IF(VALUE(SUBSTITUTE(Dashboard!G8,"%",""))>=90,"PASS",IF(VALUE(SUBSTITUTE(Dashboard!G8,"%",""))>=70,"REVIEW","FAIL")),"--")))
A33: CRITICAL ISSUES
A34: # | B34: Issue Description | C34: Domain | D34: Owner | E34: Due Date
A35: 1
A36: 2
A37: 3
A38: 4
A39: 5
A41: MANAGEMENT COMMENTARY
A42: [Enter management commentary on business continuity and disaster recovery posture]
A46: APPROVAL
A47: Assessed By
A48: Name:
A49: Date:
...

Sheet Dashboard
A1: Business Continuity and Disaster Recovery — Compliance Dashboard
A3: Domain | B3: Total Reqs | C3: Compliant | D3: Partial | E3: Non-Compliant | F3: N/A | G3: Compliance % | H3: Unassessed
A4: Business Impact Analysis | B4: =COUNTA('Business Impact Analysis'!A4:A9) | C4: =COUNTIF('Business Impact Analysis'!D4:D9,"Compliant") | D4: =COUNTIF('Business Impact Analysis'!D4:D9,"Partial") | E4: =COUNTIF('Business Impact Analysis'!D4:D9,"Non-Compliant") | F4: =COUNTIF('Business Impact Analysis'!D4:D9,"N/A") | G4: =IF((B4-F4)=0,"N/A",ROUND(C4/(B4-F4)*100,1)&"%") | H4: =B4-(C4+D4+E4+F4)
A5: Information Backup | B5: =COUNTA('Information Backup'!A4:A32) | C5: =COUNTIF('Information Backup'!D4:D32,"Compliant") | D5: =COUNTIF('Information Backup'!D4:D32,"Partial") | E5: =COUNTIF('Information Backup'!D4:D32,"Non-Compliant") | F5: =COUNTIF('Information Backup'!D4:D32,"N/A") | G5: =IF((B5-F5)=0,"N/A",ROUND(C5/(B5-F5)*100,1)&"%") | H5: =B5-(C5+D5+E5+F5)
A6: Redundancy Info Process | B6: =COUNTA('Redundancy Info Process'!A4:A12) | C6: =COUNTIF('Redundancy Info Process'!D4:D12,"Compliant") | D6: =COUNTIF('Redundancy Info Process'!D4:D12,"Partial") | E6: =COUNTIF('Redundancy Info Process'!D4:D12,"Non-Compliant") | F6: =COUNTIF('Redundancy Info Process'!D4:D12,"N/A") | G6: =IF((B6-F6)=0,"N/A",ROUND(C6/(B6-F6)*100,1)&"%") | H6: =B6-(C6+D6+E6+F6)
A7: ICT Continuity Planning | B7: =COUNTA('ICT Continuity Planning'!A4:A21) | C7: =COUNTIF('ICT Continuity Planning'!D4:D21,"Compliant") | D7: =COUNTIF('ICT Continuity Planning'!D4:D21,"Partial") | E7: =COUNTIF('ICT Continuity Planning'!D4:D21,"Non-Compliant") | F7: =COUNTIF('ICT Continuity Planning'!D4:D21,"N/A") | G7: =IF((B7-F7)=0,"N/A",ROUND(C7/(B7-F7)*100,1)&"%") | H7: =B7-(C7+D7+E7+F7)
A8: BC DR Metrics and Reporting | B8: =COUNTA('BC DR Metrics and Reporting'!A4:A5) | C8: =COUNTIF('BC DR Metrics and Reporting'!D4:D5,"Compliant") | D8: =COUNTIF('BC DR Metrics and Reporting'!D4:D5,"Partial") | E8: =COUNTIF('BC DR Metrics and Reporting'!D4:D5,"Non-Compliant") | F8: =COUNTIF('BC DR Metrics and Reporting'!D4:D5,"N/A") | G8: =IF((B8-F8)=0,"N/A",ROUND(C8/(B8-F8)*100,1)&"%") | H8: =B8-(C8+D8+E8+F8)
A9: TOTAL | B9: =SUM(B4:B8) | C9: =SUM(C4:C8) | D9: =SUM(D4:D8) | E9: =SUM(E4:E8) | F9: =SUM(F4:F8) | G9: =IF((B9-F9)=0,"N/A",ROUND(C9/(B9-F9)*100,1)&"%") | H9: =SUM(H4:H8)
A11: COMPLIANCE BY STATUS
A12: Compliant | B12: =C9 | C12: =IF(B9=0,"",ROUND(B12/B9*100,1)&"%")
A13: Partial | B13: =D9 | C13: =IF(B9=0,"",ROUND(B13/B9*100,1)&"%")
A14: Non-Compliant | B14: =E9 | C14: =IF(B9=0,"",ROUND(B14/B9*100,1)&"%")
A15: N/A | B15: =F9 | C15: =IF(B9=0,"",ROUND(B15/B9*100,1)&"%")
A17: TOP GAPS (Manual Entry)
A18: Priority | B18: Domain | C18: Requirement | D18: Owner | E18: Due Date | F18: Status
A30: COMPLIANCE TREND (Manual Entry)
A31: Assessment Date | B31: Overall % | C31: Compliant | D31: Gaps | E31: Assessor | F31: Notes

Sheet Business Impact Analysis
A1: Business Impact Analysis — Compliance Checklist
A2: ISO/IEC 27001:2022 — Controls A.5.30-8.13-14: Business Continuity and Disaster Recovery
A3: Req # | B3: Section | C3: Requirement | D3: Status | E3: Evidence | F3: Owner | G3: Due Date | H3: Notes
A4: A.5.30-8.13-14-01 | B4: Business Continuity | C4: Business continuity shall be based on a documented business impact analysis (BIA) and risk assessment. The BIA shall:.
A5: A.5.30-8.13-14-02 | B5: Bia Frequency*: The Bia | C5: BIA frequency*: The BIA shall be conducted initially during ISMS implementation, reviewed annually, and updated upon significant business changes (new services, acquisitions, major system changes) or after major incidents.
A6: A.5.30-8.13-14-03 | B6: Be Classified Into Criticality Tiers | C6: Systems shall be classified into criticality tiers based on BIA results. These tiers drive backup frequency, redundancy requirements, and testing schedules:.
A7: A.5.30-8.13-14-04 | B7: System Owners, In Consultation With The | C7: System owners, in consultation with the BC/DR Coordinator, shall determine the appropriate tier for each system based on the BIA results.
A8: A.5.30-8.13-14-05 | B8: Role Assignment*: Where The Organisation | C8: Role assignment*: Where the organisation does not have a dedicated BC/DR Coordinator, the IT Operations Manager shall assume BC/DR coordination responsibilities. This assignment shall be formally documented in the role description.
A9: A.5.30-8.13-14-06 | B9: Systems Unable To Meet Their Defined | C9: Systems unable to meet their defined RPO or RTO shall follow the exception management process (see Policy Compliance — Exceptions).

Sheet Information Backup
A1: Information Backup — Compliance Checklist
A2: ISO/IEC 27001:2022 — Controls A.5.30-8.13-14: Business Continuity and Disaster Recovery
A3: Req # | B3: Section | C3: Requirement | D3: Status | E3: Evidence | F3: Owner | G3: Due Date | H3: Notes
A4: A.5.30-8.13-14-07 | B4: The Following Categories Of Information | C4: The following categories of information shall be backed up:.
A5: A.5.30-8.13-14-08 | B5: A Backup Schedule, Retention Schedule, | C5: A backup schedule, retention schedule, and testing schedule shall be maintained and made available. Backup frequency shall align with the RPO for each system tier:.
A6: A.5.30-8.13-14-09 | B6: Extended Retention*: Longer Retention | C6: Extended retention*: Longer retention periods may be required by regulation (e.g., financial records 7–10 years), legal hold requests, or contractual obligations. Extended retention shall be justified (regulatory requirement, legal hold, or contractual obligation) to prevent unnecessary data accumulation. Shorter retention periods require CISO approval with documented risk acceptance.
A7: A.5.30-8.13-14-10 | B7: Select Appropriate Backup Strategies | C7: The organisation shall select appropriate backup strategies based on system requirements:.
A8: A.5.30-8.13-14-11 | B8: Implement The 3-2-1 Backup Rule As | C8: The organisation shall implement the 3-2-1 backup rule as a minimum for Tier 1 and Tier 2 systems:.
A9: A.5.30-8.13-14-12 | B9: Immutable Backups*: For Tier 1 And | C9: Immutable backups*: For Tier 1 and Tier 2 systems, at least one backup copy shall be immutable (write-once-read-many) or air-gapped to protect against ransomware and accidental deletion. Technologies include object storage with object lock (e.g., AWS S3 Object Lock, Azure Immutable Blob Storage, or equivalent), WORM tape, or air-gapped offline media.
A10: A.5.30-8.13-14-13 | B10: Conditional*: Organisations Subject To | C10: Conditional*: Organisations subject to DORA (EU financial entities) shall implement immutable backup copies where technically feasible (Art. 12(4)) and offsite backup storage at sufficient geographic distance.
A11: A.5.30-8.13-14-14 | B11: Be Encrypted Both In Transit And | C11: Backups shall be encrypted both in transit and at rest using AES-256 or equivalent, per the Use of Cryptography Policy (A.8.24). The backup solution (e.g., Veeam, Commvault, AWS Backup, Azure Backup, or equivalent) shall support built-in encryption.
A12: A.5.30-8.13-14-15 | B12: Backups Stored In Cloud-Based Solutions | C12: Backups stored in cloud-based solutions shall as a minimum be hosted with an ISO 27001 certified provider.
A13: A.5.30-8.13-14-16 | B13: The Media | C13: The media shall be encrypted.
A14: A.5.30-8.13-14-17 | B14: The Media | C14: The media shall be labelled and stored securely with restricted, authorisation-required access control.
A15: A.5.30-8.13-14-18 | B15: Offsite Transfer | C15: Offsite transfer shall use an approved secure courier or encrypted electronic transfer.
... A32: A.5.30-8.13-14-35 | B32: Cloud Provider Bc/Dr Commitments | C32: Cloud provider BC/DR commitments shall be included in the vendor risk assessment.

Sheet Redundancy Info Process
A1: Redundancy Info Process — Compliance Checklist
A2: ISO/IEC 27001:2022 — Controls A.5.30-8.13-14: Business Continuity and Disaster Recovery
A3: Req # | B3: Section | C3: Requirement | D3: Status | E3: Evidence | F3: Owner | G3: Due Date | H3: Notes
A4: A.5.30-8.13-14-36 | B4: Information Processing Facilities | C4: Information processing facilities shall be implemented with redundancy sufficient to meet availability requirements:.
A5: A.5.30-8.13-14-37 | B5: System Owners | C5: System owners shall conduct SPOF analysis for Tier 1 and Tier 2 systems to identify components whose failure would cause complete system unavailability. Common SPOFs include:.
A6: A.5.30-8.13-14-38 | B6: Spof Remediation*: Identified Spofs For | C6: SPOF remediation*: Identified SPOFs for Tier 1 systems shall be remediated within 90 days or have documented risk acceptance from the CISO. Tier 2 system SPOFs shall be remediated within 180 days or have documented risk acceptance.
A7: A.5.30-8.13-14-39 | B7: Systems With Redundancy | C7: Systems with redundancy shall have their failover mechanisms tested:.
A8: A.5.30-8.13-14-40 | B8: Failover Test | C8: Each failover test shall document: systems tested, failover trigger mechanism, actual failover time vs. RTO target, issues identified, and sign-off.
A9: A.5.30-8.13-14-41 | B9: Failback Testing*: Failover Tests | C9: Failback testing*: Failover tests shall also validate the failback process (returning to primary infrastructure after recovery). Failback procedures shall be documented and tested alongside failover to ensure full recovery cycle capability.
A10: A.5.30-8.13-14-42 | B10: Failed Failover Response*: Tests | C10: Failed failover response*: Tests revealing inability to meet RTO shall trigger immediate remediation and risk assessment per the escalation table in Backup Testing and Verification.
A11: A.5.30-8.13-14-43 | B11: Geographic Redundancy*: For Tier 1 | C11: Geographic redundancy*: For Tier 1 systems, redundancy shall be implemented at sufficient geographic distance to protect against site-wide disasters:.
A12: A.5.30-8.13-14-44 | B12: Cost-Benefit Analysis*: Redundancy | C12: Cost-benefit analysis*: Redundancy decisions shall balance the cost of redundant infrastructure against the business impact of extended outages and regulatory requirements. For many SMEs, cloud-native redundancy (multi-AZ deployment) provides cost-effective geographic redundancy without maintaining separate physical infrastructure.

Sheet ICT Continuity Planning
A1: ICT Continuity Planning — Compliance Checklist
A2: ISO/IEC 27001:2022 — Controls A.5.30-8.13-14: Business Continuity and Disaster Recovery
A3: Req # | B3: Section | C3: Requirement | D3: Status | E3: Evidence | F3: Owner | G3: Due Date | H3: Notes
A4: A.5.30-8.13-14-45 | B4: Maintain Documented Procedures For | C4: The organisation shall maintain documented procedures for responding to a disruptive incident and for continuing or recovering its activities within predetermined timeframes. Business continuity plans shall address the requirements of those who will use them.
A5: A.5.30-8.13-14-46 | B5: Business Continuity Plans | C5: Business continuity plans shall cover*:.
A6: A.5.30-8.13-14-47 | B6: Define*: Purpose And Scope, Objectives, | C6: Each plan shall define*: purpose and scope, objectives, activation criteria and procedures, implementation procedures, roles and authorities, communication requirements, internal and external interdependencies, resource requirements, and information flow and documentation processes.
A7: A.5.30-8.13-14-48 | B7: For Each Tier 1 And Tier | C7: For each Tier 1 and Tier 2 system, the organisation shall maintain ICT recovery plans documenting:.
A8: A.5.30-8.13-14-49 | B8: Recovery Plans | C8: Recovery plans shall be version-controlled, reviewed annually, and updated after testing exercises, major incidents, or significant system changes.
A9: A.5.30-8.13-14-50 | B9: A Disaster | C9: A disaster shall be declared when:.
A10: A.5.30-8.13-14-51 | B10: Activation Notification*: Pre-Approved | C10: Activation notification*: Pre-approved notification templates shall be maintained in the BC/DR plan. Notification shall be issued via primary channel (email, collaboration platform) and backup channel (SMS, phone) simultaneously.
A11: A.5.30-8.13-14-52 | B11: Business Continuity Plans And Technical | C11: Business continuity plans and technical recovery plans shall be tested at least annually and when significant change occurs.
A12: A.5.30-8.13-14-53 | B12: Test Documentation*: Each Test | C12: Test documentation*: Each test shall document: test date, scope, objectives, participants, scenario, results (success/partial/failure), actual vs. target RTO/RPO, issues identified, lessons learned, action items, and sign-off.
A13: A.5.30-8.13-14-54 | B13: Failed Test Response*: Tests Revealing | C13: Failed test response*: Tests revealing inability to meet RTO/RPO shall trigger immediate investigation, gap remediation plan, interim compensating controls, and executive notification for Tier 1 systems.
A14: A.5.30-8.13-14-55 | B14: Conditional*: Organisations Subject To | C14: Conditional*: Organisations subject to DORA shall test BC arrangements at least annually (Art. 11(9)) and test ICT backup and restoration at least annually (Art. 12(6)).
A15: A.5.30-8.13-14-56 | B15: Post-Test Training: Bc/Dr Test Results | C15: Post-test training: BC/DR test results and lessons learned shall be communicated to all participants within 30 days of each test.
... A21: A.5.30-8.13-14-62 | B21: An Incident Management Process | C21: An incident management process shall be in place and followed. Business continuity incidents shall additionally be:.

Sheet BC DR Metrics and Reporting
A1: BC DR Metrics and Reporting — Compliance Checklist
A2: ISO/IEC 27001:2022 — Controls A.5.30-8.13-14: Business Continuity and Disaster Recovery
A3: Req # | B3: Section | C3: Requirement | D3: Status | E3: Evidence | F3: Owner | G3: Due Date | H3: Notes
A4: A.5.30-8.13-14-63 | B4: The Following Metrics | C4: The following metrics shall be tracked to measure BC/DR programme effectiveness:.
A5: A.5.30-8.13-14-64 | B5: Metrics Breaching Targets For Two | C5: Metrics breaching targets for two consecutive reporting periods shall be escalated to the CISO and reported at the next Management Review.
