Workbook

Sheet Executive Summary
A1: PRIV-CHK-A.2.5.2-6 — Transfer and Disclosure (Processor) Compliance Checklist
A3: DOCUMENT INFORMATION
A4: Document ID | B4: PRIV-CHK-A.2.5.2-6
A5: Source Policy | B5: PRIV-POL-A.2.5.2-6
A6: ISO Controls | B6: Transfer and Disclosure (Processor)
A7: Generated | B7: 10.03.2026
A8: Prepared By
A9: Organisation
A10: Review Cycle | B10: Annual
A12: OVERALL COMPLIANCE STATUS
A13: Overall Compliance | B13: ='Dashboard'!G8
A14: Status | B14: =IF(Dashboard!G8="N/A","NOT ASSESSED",IF(ISNUMBER(VALUE(SUBSTITUTE(Dashboard!G8,"%",""))),IF(VALUE(SUBSTITUTE(Dashboard!G8,"%",""))>=90,"GREEN",IF(VALUE(SUBSTITUTE(Dashboard!G8,"%",""))>=70,"AMBER","RED")),"NOT ASSESSED"))
A16: KEY METRICS
A17: Total Requirements | B17: ='Dashboard'!B8
A18: Compliant | B18: ='Dashboard'!C8
A19: Partial | B19: ='Dashboard'!D8
A20: Non-Compliant | B20: ='Dashboard'!E8
A21: Not Applicable | B21: ='Dashboard'!F8
A22: Owner Coverage | B22: =IF(Dashboard!B8=0,"N/A",ROUND((COUNTA('Transfer Basis Notification'!F4:F7)+COUNTA('Transfer Destinations'!F4:F6)+COUNTA('Disclosure Records'!F4:F6)+COUNTA('Disclosure Request Handling'!F4:F8))/Dashboard!B8*100,0)&"%")
A24: DOMAIN STATUS SUMMARY
A25: Domain | B25: Compliance % | C25: Compliant | D25: Gaps | E25: Status
A26: Transfer Basis Notification | B26: ='Dashboard'!G4 | C26: ='Dashboard'!C4 | D26: ='Dashboard'!E4 | E26: =IF(Dashboard!G4="N/A","--",IF(ISNUMBER(VALUE(SUBSTITUTE(Dashboard!G4,"%",""))),IF(VALUE(SUBSTITUTE(Dashboard!G4,"%",""))>=90,"PASS",IF(VALUE(SUBSTITUTE(Dashboard!G4,"%",""))>=70,"REVIEW","FAIL")),"--"))
A27: Transfer Destinations | B27: ='Dashboard'!G5 | C27: ='Dashboard'!C5 | D27: ='Dashboard'!E5 | E27: =IF(Dashboard!G5="N/A","--",IF(ISNUMBER(VALUE(SUBSTITUTE(Dashboard!G5,"%",""))),IF(VALUE(SUBSTITUTE(Dashboard!G5,"%",""))>=90,"PASS",IF(VALUE(SUBSTITUTE(Dashboard!G5,"%",""))>=70,"REVIEW","FAIL")),"--"))
A28: Disclosure Records | B28: ='Dashboard'!G6 | C28: ='Dashboard'!C6 | D28: ='Dashboard'!E6 | E28: =IF(Dashboard!G6="N/A","--",IF(ISNUMBER(VALUE(SUBSTITUTE(Dashboard!G6,"%",""))),IF(VALUE(SUBSTITUTE(Dashboard!G6,"%",""))>=90,"PASS",IF(VALUE(SUBSTITUTE(Dashboard!G6,"%",""))>=70,"REVIEW","FAIL")),"--"))
A29: Disclosure Request Handling | B29: ='Dashboard'!G7 | C29: ='Dashboard'!C7 | D29: ='Dashboard'!E7 | E29: =IF(Dashboard!G7="N/A","--",IF(ISNUMBER(VALUE(SUBSTITUTE(Dashboard!G7,"%",""))),IF(VALUE(SUBSTITUTE(Dashboard!G7,"%",""))>=90,"PASS",IF(VALUE(SUBSTITUTE(Dashboard!G7,"%",""))>=70,"REVIEW","FAIL")),"--"))
A31: CRITICAL ISSUES
A32: # | B32: Issue Description | C32: Domain | D32: Owner | E32: Due Date
A33: 1
A34: 2
A35: 3
A36: 4
A37: 5
A39: MANAGEMENT COMMENTARY
A40: [Enter management commentary on transfer and disclosure (processor) posture]
A44: APPROVAL
A45: Assessed By
A46: Name:
A47: Date:
A48: Signature:
A49: Decision:
...

Sheet Dashboard
A1: Transfer and Disclosure (Processor) — Compliance Dashboard
A3: Domain | B3: Total Reqs | C3: Compliant | D3: Partial | E3: Non-Compliant | F3: N/A | G3: Compliance %
A4: Transfer Basis Notification | B4: =COUNTA('Transfer Basis Notification'!D4:D7) | C4: =COUNTIF('Transfer Basis Notification'!D4:D7,"Compliant") | D4: =COUNTIF('Transfer Basis Notification'!D4:D7,"Partial") | E4: =COUNTIF('Transfer Basis Notification'!D4:D7,"Non-Compliant") | F4: =COUNTIF('Transfer Basis Notification'!D4:D7,"N/A") | G4: =IF((B4-F4)=0,"N/A",ROUND(C4/(B4-F4)*100,1)&"%")
A5: Transfer Destinations | B5: =COUNTA('Transfer Destinations'!D4:D6) | C5: =COUNTIF('Transfer Destinations'!D4:D6,"Compliant") | D5: =COUNTIF('Transfer Destinations'!D4:D6,"Partial") | E5: =COUNTIF('Transfer Destinations'!D4:D6,"Non-Compliant") | F5: =COUNTIF('Transfer Destinations'!D4:D6,"N/A") | G5: =IF((B5-F5)=0,"N/A",ROUND(C5/(B5-F5)*100,1)&"%")
A6: Disclosure Records | B6: =COUNTA('Disclosure Records'!D4:D6) | C6: =COUNTIF('Disclosure Records'!D4:D6,"Compliant") | D6: =COUNTIF('Disclosure Records'!D4:D6,"Partial") | E6: =COUNTIF('Disclosure Records'!D4:D6,"Non-Compliant") | F6: =COUNTIF('Disclosure Records'!D4:D6,"N/A") | G6: =IF((B6-F6)=0,"N/A",ROUND(C6/(B6-F6)*100,1)&"%")
A7: Disclosure Request Handling | B7: =COUNTA('Disclosure Request Handling'!D4:D8) | C7: =COUNTIF('Disclosure Request Handling'!D4:D8,"Compliant") | D7: =COUNTIF('Disclosure Request Handling'!D4:D8,"Partial") | E7: =COUNTIF('Disclosure Request Handling'!D4:D8,"Non-Compliant") | F7: =COUNTIF('Disclosure Request Handling'!D4:D8,"N/A") | G7: =IF((B7-F7)=0,"N/A",ROUND(C7/(B7-F7)*100,1)&"%")
A8: TOTAL | B8: =SUM(B4:B7) | C8: =SUM(C4:C7) | D8: =SUM(D4:D7) | E8: =SUM(E4:E7) | F8: =SUM(F4:F7) | G8: =IF((B8-F8)=0,"N/A",ROUND(C8/(B8-F8)*100,1)&"%")
A10: COMPLIANCE BY STATUS
A11: Compliant | B11: =C8 | C11: =IF(B8=0,"",ROUND(B11/B8*100,1)&"%")
A12: Partial | B12: =D8 | C12: =IF(B8=0,"",ROUND(B12/B8*100,1)&"%")
A13: Non-Compliant | B13: =E8 | C13: =IF(B8=0,"",ROUND(B13/B8*100,1)&"%")
A14: N/A | B14: =F8 | C14: =IF(B8=0,"",ROUND(B14/B8*100,1)&"%")
A16: TOP GAPS (Manual Entry)
A17: Priority | B17: Domain | C17: Requirement | D17: Owner | E17: Due Date | F17: Status
A29: COMPLIANCE TREND (Manual Entry)
A30: Assessment Date | B30: Overall % | C30: Compliant | D30: Gaps | E30: Assessor | F30: Notes

Sheet Transfer Basis Notification
A1: Transfer Basis Notification — Compliance Checklist
A2: ISO/IEC 27701:2025 — Controls A.2.5.2-6: Transfer and Disclosure (Processor)
A3: Req # | B3: Section | C3: Requirement | D3: Status | E3: Evidence | F3: Owner | G3: Due Date | H3: Notes
A4: A.2.5.2-01 | B4: Customer Notification | C4: The organisation shall inform each customer in a timely manner of the legal basis for any PII transfers between jurisdictions carried out on their behalf. The transfer basis (adequacy, SCCs, BCRs) for each transfer destination shall be documented and provided in the processor agreement or associated data processing schedule.
A5: A.2.5.2-02 | B5: Change Notification | C5: Where the organisation intends to change a transfer basis or add a new transfer destination, customers shall be notified in advance with sufficient time to object or terminate the contract. The notification period shall be as specified in the processor agreement (typically minimum 30 days for non-urgent changes).
A6: A.2.5.2-03 | B6: Change Notification Records | C6: Records of customer notifications for transfer basis changes shall be maintained for 3 years, including the nature of the change, date of notification, and customer response (objection or no-objection).
A7: A.2.5.2-04 | B7: Objection Handling | C7: Where a customer objects to a proposed transfer basis change or new destination, the organisation shall have a documented process for handling objections, including implementing alternative measures or allowing termination without penalty.

Sheet Transfer Destinations
A1: Transfer Destinations — Compliance Checklist
A2: ISO/IEC 27701:2025 — Controls A.2.5.2-6: Transfer and Disclosure (Processor)
A3: Req # | B3: Section | C3: Requirement | D3: Status | E3: Evidence | F3: Owner | G3: Due Date | H3: Notes
A4: A.2.5.3-01 | B4: Transfer Destination Register | C4: The DPO shall maintain a Transfer Destination Register listing all countries and international organisations to which customer PII may be transferred in the course of service delivery, including transfer mechanism, legal basis, and applicable PII categories.
A5: A.2.5.3-02 | B5: Customer Availability | C5: The Transfer Destination Register shall be made available to customers in the processor agreement or data processing schedule. Updates to the register require customer notification per A.2.5.2.
A6: A.2.5.3-03 | B6: Register Currency | C6: The Transfer Destination Register shall be updated when new sub-processors or infrastructure require new transfer destinations, when adequacy status changes, and at minimum annually. Customers shall be notified of changes that affect their processing.

Sheet Disclosure Records
A1: Disclosure Records — Compliance Checklist
A2: ISO/IEC 27701:2025 — Controls A.2.5.2-6: Transfer and Disclosure (Processor)
A3: Req # | B3: Section | C3: Requirement | D3: Status | E3: Evidence | F3: Owner | G3: Due Date | H3: Notes
A4: A.2.5.4-01 | B4: Processor Disclosure Register | C4: The organisation shall maintain a Processor Disclosure Register logging each disclosure of customer PII to third parties: date, third party identity, PII categories disclosed, and basis (customer instruction, legal obligation, or contractual obligation). Records shall be retained for minimum 3 years.
A5: A.2.5.4-02 | B5: Customer Availability | C5: Disclosure records shall be made available to customers upon request to support customer demonstrability obligations and data subject access requests (which require identification of PII recipients).
A6: A.2.5.4-03 | B6: Sub-processor Disclosures | C6: Disclosures to sub-processors shall be documented separately per PRIV-POL-A.2.5.7-9 (Sub-processor Register). Sub-processor disclosures are covered by the customer's general sub-processor authorisation.

Sheet Disclosure Request Handling
A1: Disclosure Request Handling — Compliance Checklist
A2: ISO/IEC 27701:2025 — Controls A.2.5.2-6: Transfer and Disclosure (Processor)
A3: Req # | B3: Section | C3: Requirement | D3: Status | E3: Evidence | F3: Owner | G3: Due Date | H3: Notes
A4: A.2.5.5-01 | B4: Legally Binding Request Notification | C4: When the organisation receives a legally binding request for disclosure of customer PII (from law enforcement, court, regulator, or tax authority), it shall notify the customer without undue delay, unless prohibited by law. Notification shall include the nature of the request, PII categories requested, and legal authority cited — to the extent legally permissible.
A5: A.2.5.5-02 | B5: Notification Prohibition Handling | C5: Where notification to the customer is legally prohibited (e.g. by a non-disclosure order), the organisation shall document this constraint, seek legal advice on challenging the prohibition, and notify the customer as soon as the prohibition is lifted.
A6: A.2.5.6-01 | B6: Non-Legally-Binding Request Refusal | C6: The organisation shall reject any requests for disclosure of customer PII that are not legally binding. If uncertain whether a request is legally binding, legal advice shall be sought before responding. Refusals shall be documented.
A7: A.2.5.6-02 | B7: Legally Binding Disclosure Process | C7: The organisation shall consult with the customer before making any disclosure pursuant to a legally binding request — except where law prohibits notification. Where disclosure proceeds, it shall be limited to the minimum PII necessary to comply with the legal obligation. The disclosure shall be documented in the Processor Disclosure Register.
A8: A.2.5.6-03 | B8: Contractually Authorised Disclosures | C8: The organisation may accept and act upon contractually agreed requests for PII disclosures explicitly authorised by the customer (e.g. reporting to specified regulators, sharing with auditors under customer instruction). All such disclosures shall be recorded.
