Workbook

Sheet Instructions & Legend
A1: ISMS-IMP-A.8.31.1 - Environment Architecture Assessment ISO/IEC 27001:2022 - Control A.8.31: Separation of Development, Test and Production Environments
A3: Document Information
A4: Document ID | B4: ISMS-IMP-A.8.31.1
A5: Workbook Title | B5: Environment Architecture Assessment
A6: Control Reference | B6: ISO/IEC 27001:2022 - Control A.8.31: Separation of Development, Test and Production Environments
A7: Version | B7: 1.0
A8: Assessment Date
A9: Completed By
A10: Organisation
A12: Instructions
A13: 1. Complete the Environment Inventory sheet with all your environments (dev, test, staging, production).
A14: 2. Assess Network Separation — verify VLANs, VPCs, firewall rules prevent cross-environment access.
A15: 3. Assess Infrastructure Separation — verify separate servers, cloud accounts, databases.
A16: 4. Assess Data Separation — confirm NO production data in dev/test environments.
A17: 5. Assess Credential Separation — verify unique credentials per environment.
A18: 6. Review Configuration Consistency — check for drift between staging and production.
A19: 7. Complete Gap Analysis — document non-compliance areas and remediation plans.
A20: 8. Maintain Evidence Register for audit traceability.
... A23: Status Legend
A24: Symbol | B24: Status | C24: Description
A25: ✓ | B25: Compliant / Complete | C25: Requirement fully met
A26: ⚠ | B26: Partial / In Progress | C26: Partially met or in progress
A27: ✗ | B27: Non-Compliant / Not Started | C27: Requirement not met
A28: — | B28: Not Applicable | C28: Not applicable to this assessment

Sheet Environment Inventory
A1: ENVIRONMENT INVENTORY
A2: Document all environments in use by [Organisation]
A4: Environment Name | B4: Environment Type | C4: Purpose | D4: Infrastructure Type | E4: Primary Users | F4: Data Type Allowed | G4: Availability Target | H4: Change Control Level | I4: Notes
A5: test-myapp | B5: Testing/QA | C5: QA and UAT | D5: AWS | E5: QA team, Business users | F5: Synthetic/Anonymized ONLY | G5: 95% business hours | H5: Moderate | I5: Test account: 222222222222

Sheet Network Separation
A1: NETWORK SEPARATION ASSESSMENT
A2: Verify network-level isolation between environments
A4: Environment Pair | B4: Network Segment (VLAN/VPC) | C4: Firewall Rules | D4: Cross-Environment Traffic | E4: Separation Status | F4: Test Result | G4: Compliance | H4: Notes/Evidence
A5: Dev → Test | B5: VLAN 100 → VLAN 200 | C5: Default DENY | D5: No traffic allowed | E5: Complete | F5: Ping test FAILED (expected) | G5: Compliant | H5: Firewall rule export: evidence_001.pdf

Sheet Infrastructure Separation
A1: INFRASTRUCTURE SEPARATION ASSESSMENT
A2: Verify separate compute, storage, and database resources per environment
A4: Environment | B4: Compute Resources | C4: Database Instances | D4: Storage/Buckets | E4: Cloud Account/Sub | F4: Shared Resources? | G4: Separation Status | H4: Compliance | I4: Evidence
A5: Development | B5: 3x t3.micro EC2 | C5: dev-db.rds (t3.micro) | D5: s3://myorg-dev-data | E5: AWS: 111111111111 | F5: No | G5: Complete | H5: Compliant | I5: AWS inventory: aws_dev_inventory.xlsx

Sheet Data Separation
A1: DATA SEPARATION ASSESSMENT
A2: ⚠️ CRITICAL: Verify NO production data in development or testing environments
A4: Environment | B4: Data Type Used | C4: Production Data Present? | D4: Anonymization Applied? | E4: Synthetic Data Used? | F4: Data Source | G4: Compliance | H4: Evidence/Notes
A5: Development | B5: Synthetic test data | C5: No | D5: N/A | E5: Yes | F5: Faker library (Python) | G5: Compliant | H5: Data generation script: generate_testdata.py

Sheet Credential Separation
A1: CREDENTIAL & SECRETS SEPARATION ASSESSMENT
A2: Verify unique credentials per environment and production secrets in PAM vault
A4: Credential Type | B4: Development | C4: Testing | D4: Production | E4: Shared Credentials? | F4: Prod in PAM Vault? | G4: Compliance | H4: Evidence
A5: Database Admin Password | B5: dev_admin / [unique-1] | C5: test_admin / [unique-2] | D5: prod_admin / [PAM-vault] | E5: No | F5: Yes | G5: Compliant | H5: CyberArk vault screenshot

Sheet Configuration Consistency
A1: CONFIGURATION CONSISTENCY CHECK
A2: Verify staging mirrors production configuration (drift detection)
A4: Configuration Item | B4: Staging Config | C4: Production Config | D4: Match? | E4: Drift % | F4: Compliance | G4: Notes
A5: Application Version | B5: v2.3.1 | C5: v2.3.1 | D5: Yes | E5: 0% | F5: Compliant | G5: Versions match
A6: Environment Labels in UI/Menus (ISO A.8.31 f) | G6: Verify all UI screens/menus clearly label the active environment (DEV/TEST/PROD)
A7: Security Patch Level Parity (DEV/TEST vs PROD) | G7: Confirm dev and test environments are patched to the same level as production

Sheet Evidence Register
A1: EVIDENCE REGISTER
A2: Record all evidence collected during the assessment. Each row represents one piece of evidence.
A4: Evidence ID | B4: Assessment Area | C4: Evidence Type | D4: Description | E4: Location / Path | F4: Date Collected | G4: Collected By | H4: Verification Status
A5: EV-001 | B5: Environment Architecture | C5: Configuration file | D5: Network diagram showing environment separation | E5: \\fileserver\evidence\network_diagram_20260213.pdf | F5: 13.02.2026 | G5: Network Administrator | H5: Verified

Sheet Gap Analysis
A1: GAP ANALYSIS & REMEDIATION PLAN
A2: Document non-compliance areas and remediation actions
A4: Gap ID | B4: Area | C4: Gap Description | D4: Risk Severity | E4: Current State | F4: Target State | G4: Remediation Action | H4: Owner | I4: Target Date
A5: GAP-001 | B5: Network Separation | C5: VPC peering exists between dev and staging | D5: Medium | E5: Dev VPC peered to Staging VPC | F5: No VPC peering between non-prod envs | G5: Remove VPC peering connection vpc-peer-12345 | H5: Cloud Architect | I5: 2026-02-15

Sheet Summary Dashboard
A1: ENVIRONMENT ARCHITECTURE ASSESSMENT — SUMMARY DASHBOARD
A2: ISO/IEC 27001:2022 - Control A.8.31: Separation of Development, Test and Production Environments
A4: TABLE 1: ASSESSMENT AREA COMPLIANCE OVERVIEW
A5: Assessment Area | B5: Total Items | C5: Compliant | D5: Partial | E5: Non-Compliant | F5: N/A | G5: Compliance %
A6: Environment Inventory | B6: =COUNTA('Environment Inventory'!B6:B55) | C6: =COUNTIF('Environment Inventory'!B6:B55,"Production") | D6: =COUNTIF('Environment Inventory'!B6:B55,"Staging") | E6: =COUNTIF('Environment Inventory'!B6:B55,"Testing/QA")+COUNTIF('Environment Inventory'!B6:B55,"Development") | F6: =COUNTIF('Environment Inventory'!B6:B55,"Sandbox")+COUNTIF('Environment Inventory'!B6:B55,"DR/Backup")+COUNTIF('Environment Inventory'!B6:B55,"Training")+COUNTIF('Environment Inventory'!B6:B55,"Other") | G6: =IF(B6=0,0,C6/B6)
A7: Network Separation | B7: =COUNTA('Network Separation'!G:G) | C7: =COUNTIF('Network Separation'!G6:G55,"Compliant") | D7: =COUNTIF('Network Separation'!G6:G55,"Partial") | E7: =COUNTIF('Network Separation'!G6:G55,"Non-Compliant")+COUNTIF('Network Separation'!G6:G55,"Not Assessed") | F7: =COUNTIF('Network Separation'!G6:G55,"N/A") | G7: =IF((B7-F7)=0,0,C7/(B7-F7))
A8: Infrastructure Separation | B8: =COUNTA('Infrastructure Separation'!H:H) | C8: =COUNTIF('Infrastructure Separation'!H6:H55,"Compliant") | D8: =COUNTIF('Infrastructure Separation'!H6:H55,"Partial") | E8: =COUNTIF('Infrastructure Separation'!H6:H55,"Non-Compliant")+COUNTIF('Infrastructure Separation'!H6:H55,"Not Assessed") | F8: =COUNTIF('Infrastructure Separation'!H6:H55,"N/A") | G8: =IF((B8-F8)=0,0,C8/(B8-F8))
A9: Data Separation | B9: =COUNTA('Data Separation'!G:G) | C9: =COUNTIF('Data Separation'!G6:G55,"Compliant") | D9: =COUNTIF('Data Separation'!G6:G55,"Partial") | E9: =COUNTIF('Data Separation'!G6:G55,"Non-Compliant")+COUNTIF('Data Separation'!G6:G55,"Not Assessed") | F9: =COUNTIF('Data Separation'!G6:G55,"N/A") | G9: =IF((B9-F9)=0,0,C9/(B9-F9))
A10: Credential Separation | B10: =COUNTA('Credential Separation'!G:G) | C10: =COUNTIF('Credential Separation'!G6:G55,"Compliant") | D10: =COUNTIF('Credential Separation'!G6:G55,"Partial") | E10: =COUNTIF('Credential Separation'!G6:G55,"Non-Compliant")+COUNTIF('Credential Separation'!G6:G55,"Not Assessed") | F10: =COUNTIF('Credential Separation'!G6:G55,"N/A") | G10: =IF((B10-F10)=0,0,C10/(B10-F10))
A11: Configuration Consistency | B11: =COUNTA('Configuration Consistency'!F:F) | C11: =COUNTIF('Configuration Consistency'!F6:F55,"Compliant") | D11: =COUNTIF('Configuration Consistency'!F6:F55,"Partial") | E11: =COUNTIF('Configuration Consistency'!F6:F55,"Non-Compliant")+COUNTIF('Configuration Consistency'!F6:F55,"Not Assessed") | F11: =COUNTIF('Configuration Consistency'!F6:F55,"N/A") | G11: =IF((B11-F11)=0,0,C11/(B11-F11))
A12: Gap Analysis | B12: =COUNTA('Gap Analysis'!D6:D55) | C12: =COUNTIF('Gap Analysis'!D6:D55,"Critical") | D12: =COUNTIF('Gap Analysis'!D6:D55,"High") | E12: =COUNTIF('Gap Analysis'!D6:D55,"Medium") | F12: =COUNTIF('Gap Analysis'!D6:D55,"Low")+COUNTIF('Gap Analysis'!D6:D55,"Informational") | G12: =IF(B12=0,0,(C12+D12)/B12)
A13: TOTAL | B13: =SUM(B6:B12) | C13: =SUM(C6:C12) | D13: =SUM(D6:D12) | E13: =SUM(E6:E12) | F13: =SUM(F6:F12) | G13: N/A
A15: TABLE 2: KEY METRICS
A16: Metric | B16: Value
A17: Total Environments | B17: =COUNTA('Environment Inventory'!B6:B55)
A18: Production Environments | B18: =COUNTIF('Environment Inventory'!B6:B55,"Production")
A19: Non-Production Environments | B19: =COUNTIF('Environment Inventory'!B6:B55,"Development")+COUNTIF('Environment Inventory'!B6:B55,"Testing/QA")+COUNTIF('Environment Inventory'!B6:B55,"Staging")
A20: Cloud-Based Environments | B20: =COUNTIF('Environment Inventory'!D6:D55,"AWS")+COUNTIF('Environment Inventory'!D6:D55,"Azure")+COUNTIF('Environment Inventory'!D6:D55,"GCP")
A21: On-Premises Environments | B21: =COUNTIF('Environment Inventory'!D6:D55,"On-Premises")
A22: Network Routes Assessed | B22: =COUNTA('Network Separation'!A6:A55)
A23: Fully Separated (Complete) | B23: =COUNTIF('Network Separation'!E6:E55,"Complete")
A24: Partially Separated | B24: =COUNTIF('Network Separation'!E6:E55,"Partial")
A25: Not Separated | B25: =COUNTIF('Network Separation'!E6:E55,"None")
A26: Infrastructure Components | B26: =COUNTA('Infrastructure Separation'!A6:A55)
A27: Completely Separated Infrastructure | B27: =COUNTIF('Infrastructure Separation'!G6:G55,"Complete")
A28: Shared Infrastructure Items | B28: =COUNTIF('Infrastructure Separation'!G6:G55,"None")+COUNTIF('Infrastructure Separation'!G6:G55,"Partial")
A29: Data Stores Assessed | B29: =COUNTA('Data Separation'!A6:A55)
A30: Fully Separated Data Stores | B30: =COUNTIF('Data Separation'!F6:F55,"Complete")
A31: Partially Separated Data | B31: =COUNTIF('Data Separation'!F6:F55,"Partial")
A32: Shared Data Stores | B32: =COUNTIF('Data Separation'!F6:F55,"None")
A33: Credential Sets Assessed | B33: =COUNTA('Credential Separation'!A6:A55)
A34: Dedicated Credentials | B34: =COUNTIF('Credential Separation'!E6:E55,"Yes")
A35: Shared Credentials (Risk) | B35: =COUNTIF('Credential Separation'!E6:E55,"No")
A36: Configuration Items | B36: =COUNTA('Configuration Consistency'!A6:A55)
A37: Consistent Configs | B37: =COUNTIF('Configuration Consistency'!E6:E55,"Complete")
A38: Inconsistent Configs | B38: =COUNTIF('Configuration Consistency'!E6:E55,"Partial")+COUNTIF('Configuration Consistency'!E6:E55,"None")
A39: Total Gaps Identified | B39: =COUNTA('Gap Analysis'!D6:D55)
A40: Critical Severity Gaps | B40: =COUNTIF('Gap Analysis'!D6:D55,"Critical")
A41: High Severity Gaps | B41: =COUNTIF('Gap Analysis'!D6:D55,"High")
A42: Critical+High Gaps | B42: =COUNTIF('Gap Analysis'!D6:D55,"Critical")+COUNTIF('Gap Analysis'!D6:D55,"High")
...

Sheet Approval Sign-Off
A1: ASSESSMENT APPROVAL AND SIGN-OFF
A2: ISO/IEC 27001:2022 - Control A.8.31: Separation of Development, Test and Production Environments
A4: ASSESSMENT SUMMARY
A5: Document: | B5: ISMS-IMP-A.8.31.1
A6: Overall Compliance Rating: | B6: ='Summary Dashboard'!G13
A7: Assessment Period:
A8: Assessed By:
A9: Assessment Status:
A11: COMPLETED BY — Assessment Lead
A12: Name:
A13: Title:
A14: Date:
A15: Signature:
A16: Comments:
A18: REVIEWED BY — Security Manager
A19: Name:
A20: Title:
... A38: Special Considerations:
