Workbook

Sheet Instructions & Legend
A1: ISMS-IMP-A.8.31.2 - Environment Access Control Assessment ISO/IEC 27001:2022 - Control A.8.31: Separation of Development, Test and Production Environments
A3: Document Information
A4: Document ID | B4: ISMS-IMP-A.8.31.2
A5: Workbook Title | B5: Environment Access Control Assessment
A6: Control Reference | B6: ISO/IEC 27001:2022 - Control A.8.31: Separation of Development, Test and Production Environments
A7: Version | B7: 1.0
A8: Assessment Date
A9: Completed By
A10: Organisation
A12: Instructions
A13: 1. Complete User Environment Access Matrix — document who has access to which environment.
A14: 2. ⚠️ CRITICAL: Complete Developer Production Access — verify ZERO developers have production access.
A15: 3. Audit Production Credential Audit — verify all production credentials in PAM vault.
A16: 4. Review Cross Environment Access Log — check for unauthorised access attempts.
A17: 5. Document Break Glass Access Log — all emergency production access instances.
A18: 6. Verify MFA Enforcement — confirm MFA required for production.
A19: 7. Complete Summary Dashboard — calculate overall compliance.
A20: 8. Maintain Evidence Register for audit traceability.
... A23: Status Legend
A24: Symbol | B24: Status | C24: Description
A25: ✓ | B25: Compliant / Complete | C25: Requirement fully met
A26: ⚠ | B26: Partial / In Progress | C26: Partially met or in progress
A27: ✗ | B27: Non-Compliant / Not Started | C27: Requirement not met
A28: — | B28: Not Applicable | C28: Not applicable to this assessment

Sheet User Environment Access Matrix
A1: USER → ENVIRONMENT ACCESS MATRIX
A2: Document access permissions for each user per environment
A4: User ID / Email | B4: Role | C4: Development Access | D4: Testing Access | E4: Staging Access | F4: Production Access | G4: Compliance Status | H4: Notes
A6: dev2@example.ch | B6: Developer | C6: Full (CRUD) | D6: Read/Write | E6: Read-only | F6: No Access | G6: Compliant | H6: No prod access (expected)

Sheet Developer Production Access
A1: DEVELOPER PRODUCTION ACCESS CHECK (CRITICAL)
A2: TARGET: ZERO developers with production access | Any violations = CRITICAL FINDING
A4: Developer ID | B4: Production Account/Sub | C4: Production Access? | D4: Access Type | E4: Justification | F4: Violation Severity | G4: Remediation Action
A5: dev1@example.ch | B5: AWS Prod Account: 444444444444 | C5: No | D5: N/A | E5: No production access (expected) | F5: Low | G5: N/A - Compliant
A67: If ALL developers show 'No' for Production Access = COMPLIANT
A68: If ANY developer shows 'Yes' for Production Access = CRITICAL VIOLATION

Sheet Production Credential Audit
A1: PRODUCTION CREDENTIAL AUDIT
A2: Verify all production credentials stored in PAM vault and rotated regularly
A4: Credential Type | B4: System/Service | C4: Stored in PAM Vault? | D4: Vault Location | E4: Last Rotated | F4: Rotation Schedule | G4: Compliance | H4: Notes
A6: AWS Root Account | B6: AWS Prod: 444444444444 | C6: Yes | D6: CyberArk/Prod/AWS/Root | E6: 2025-12-15 | F6: Never (not used) | G6: Compliant | H6: MFA enforced, never used

Sheet Cross Environment Access Log
A1: CROSS-ENVIRONMENT ACCESS ATTEMPTS LOG
A2: Log unauthorised cross-environment access attempts (should be blocked)
A4: Date/Time | B4: User ID | C4: Source Environment | D4: Target Environment | E4: Attempted Action | F4: Result | G4: Alert Generated? | H4: Investigation Notes
A6: 2026-01-09 09:15:00 | B6: dev2@example.ch | C6: Development | D6: Production | E6: AWS CLI describe-instances | F6: DENIED | G6: Yes | H6: IAM policy denied (expected)

Sheet Break Glass Access Log
A1: BREAK-GLASS EMERGENCY ACCESS LOG
A2: Document all instances of emergency developer access to production
A4: Incident ID | B4: Date/Time Activated | C4: Developer ID | D4: Approved By | E4: Reason/Justification | F4: Duration (hours) | G4: Date/Time Revoked | H4: Post-Incident Review | I4: Compliance | J4: Notes
A6: INC-2026-001 | B6: 2026-01-05 02:30 | C6: senior-dev@example.ch | D6: ops-manager@example.ch | E6: Critical production outage - database corruption | F6: 4 | G6: 2026-01-05 06:30 | H6: Completed 2026-01-06 | I6: Compliant | J6: Proper procedure followed

Sheet MFA Enforcement
A1: MFA ENFORCEMENT VERIFICATION
A2: Verify MFA required for production access (all users)
A4: User ID | B4: Production Access? | C4: MFA Enabled? | D4: MFA Type | E4: Last MFA Check | F4: Compliance | G4: Evidence
A6: ops2@example.ch | B6: Yes | C6: Yes | D6: Virtual MFA (Google Authenticator) | E6: 2026-01-11 | F6: Compliant | G6: IAM user MFA device ARN: ...mfa/ops2

Sheet Evidence Register
A1: EVIDENCE REGISTER
A2: Record all evidence collected during the assessment. Each row represents one piece of evidence.
A4: Evidence ID | B4: Assessment Area | C4: Evidence Type | D4: Description | E4: Location / Path | F4: Date Collected | G4: Collected By | H4: Verification Status
A5: EV-001 | B5: Environment Access Control | C5: Log extract | D5: Access control logs showing environment separation enforcement | E5: \\fileserver\evidence\access_logs_20260213.csv | F5: 13.02.2026 | G5: Security Administrator | H5: Verified

Sheet Summary Dashboard
A1: ENVIRONMENT ACCESS CONTROL ASSESSMENT — SUMMARY DASHBOARD
A2: ISO/IEC 27001:2022 - Control A.8.31: Separation of Development, Test and Production Environments
A4: TABLE 1: ASSESSMENT AREA COMPLIANCE OVERVIEW
A5: Assessment Area | B5: Total Items | C5: Compliant | D5: Partial | E5: Non-Compliant | F5: N/A | G5: Compliance %
A6: User Environment Access Matrix | B6: =COUNTA('User Environment Access Matrix'!G:G) | C6: =COUNTIF('User Environment Access Matrix'!G7:G56,"Compliant") | D6: =COUNTIF('User Environment Access Matrix'!G7:G56,"Partial") | E6: =COUNTIF('User Environment Access Matrix'!G7:G56,"Non-Compliant")+COUNTIF('User Environment Access Matrix'!G7:G56,"Not Assessed") | F6: 0 | G6: =IF((B6-F6)=0,0,C6/(B6-F6))
A7: Developer Production Access | B7: =COUNTA('Developer Production Access'!C7:C56) | C7: =COUNTIF('Developer Production Access'!C7:C56,"No") | D7: =COUNTIF('Developer Production Access'!C7:C56,"Yes") | E7: =COUNTIF('Developer Production Access'!F7:F56,"Critical")+COUNTIF('Developer Production Access'!F7:F56,"High") | F7: =COUNTIF('Developer Production Access'!F7:F56,"Medium")+COUNTIF('Developer Production Access'!F7:F56,"Low") | G7: =IF(B7=0,0,C7/B7)
A8: Production Credential Audit | B8: =COUNTA('Production Credential Audit'!G:G) | C8: =COUNTIF('Production Credential Audit'!G7:G56,"Compliant") | D8: =COUNTIF('Production Credential Audit'!G7:G56,"Partial") | E8: =COUNTIF('Production Credential Audit'!G7:G56,"Non-Compliant")+COUNTIF('Production Credential Audit'!G7:G56,"Not Assessed") | F8: 0 | G8: =IF((B8-F8)=0,0,C8/(B8-F8))
A9: Cross Environment Access Log | B9: =COUNTA('Cross Environment Access Log'!G7:G56) | C9: =COUNTIF('Cross Environment Access Log'!G7:G56,"Yes") | D9: =COUNTIF('Cross Environment Access Log'!G7:G56,"No") | E9: 0 | F9: 0 | G9: =IF(B9=0,0,C9/B9)
A10: Break Glass Access Log | B10: =COUNTA('Break Glass Access Log'!I:I) | C10: =COUNTIF('Break Glass Access Log'!I7:I56,"Compliant") | D10: =COUNTIF('Break Glass Access Log'!I7:I56,"Partial") | E10: =COUNTIF('Break Glass Access Log'!I7:I56,"Non-Compliant")+COUNTIF('Break Glass Access Log'!I7:I56,"Not Assessed") | F10: 0 | G10: =IF((B10-F10)=0,0,C10/(B10-F10))
A11: MFA Enforcement | B11: =COUNTA('MFA Enforcement'!F:F) | C11: =COUNTIF('MFA Enforcement'!F7:F56,"Compliant") | D11: =COUNTIF('MFA Enforcement'!F7:F56,"Partial") | E11: =COUNTIF('MFA Enforcement'!F7:F56,"Non-Compliant")+COUNTIF('MFA Enforcement'!F7:F56,"Not Assessed") | F11: 0 | G11: =IF((B11-F11)=0,0,C11/(B11-F11))
A12: TOTAL | B12: =SUM(B6:B11) | C12: =SUM(C6:C11) | D12: =SUM(D6:D11) | E12: =SUM(E6:E11) | F12: =SUM(F6:F11) | G12: N/A
A14: TABLE 2: KEY METRICS
A15: Metric | B15: Value
A16: User Roles Assessed | B16: =COUNTA('User Environment Access Matrix'!A7:A56)
A17: Roles with Full Production Access | B17: =COUNTIF('User Environment Access Matrix'!C7:C56,"Full (CRUD)")
A18: Roles with Read-Only Production | B18: =COUNTIF('User Environment Access Matrix'!C7:C56,"Read-only")
A19: Roles with No Production Access | B19: =COUNTIF('User Environment Access Matrix'!C7:C56,"No Access")
A20: Break-Glass Access Roles | B20: =COUNTIF('User Environment Access Matrix'!C7:C56,"Break-Glass Only")
A21: Developers Assessed | B21: =COUNTA('Developer Production Access'!C7:C56)
A22: Developers WITHOUT Prod Access | B22: =COUNTIF('Developer Production Access'!C7:C56,"No")
A23: Developers WITH Prod Access (Risk) | B23: =COUNTIF('Developer Production Access'!C7:C56,"Yes")
A24: High-Risk Developer Access | B24: =COUNTIF('Developer Production Access'!F7:F56,"Critical")+COUNTIF('Developer Production Access'!F7:F56,"High")
A25: % Developers with Prod Access | B25: =IF(COUNTA('Developer Production Access'!C7:C56)=0,"0%",ROUND(COUNTIF('Developer Production Access'!C7:C56,"Yes")/COUNTA('Developer Production Access'!C7:C56)*100,1)&"%")
A26: Production Credentials Assessed | B26: =COUNTA('Production Credential Audit'!A7:A56)
A27: Dedicated Production Credentials | B27: =COUNTIF('Production Credential Audit'!E7:E56,"Yes")
A28: Shared Production Credentials (Risk) | B28: =COUNTIF('Production Credential Audit'!E7:E56,"No")
A29: Cross-Environment Access Events | B29: =COUNTA('Cross Environment Access Log'!G7:G56)
A30: Authorised Cross-Env Access | B30: =COUNTIF('Cross Environment Access Log'!G7:G56,"Yes")
A31: Unauthorised Cross-Env Access (Risk) | B31: =COUNTIF('Cross Environment Access Log'!G7:G56,"No")
A32: % Unauthorised Access | B32: =IF(COUNTA('Cross Environment Access Log'!G7:G56)=0,"0%",ROUND(COUNTIF('Cross Environment Access Log'!G7:G56,"No")/COUNTA('Cross Environment Access Log'!G7:G56)*100,1)&"%")
A33: Break Glass Events | B33: =COUNTA('Break Glass Access Log'!I7:I56)
A34: Approved Break Glass Access | B34: =COUNTIF('Break Glass Access Log'!I7:I56,"Compliant")
A35: Unapproved Break Glass (Risk) | B35: =COUNTIF('Break Glass Access Log'!I7:I56,"Non-Compliant")
A36: MFA Controls Assessed | B36: =COUNTA('MFA Enforcement'!F7:F56)
A37: MFA Fully Enforced | B37: =COUNTIF('MFA Enforcement'!F7:F56,"Compliant")
A38: MFA Partially Enforced | B38: =COUNTIF('MFA Enforcement'!F7:F56,"Partial")
A39: MFA Not Enforced (Risk) | B39: =COUNTIF('MFA Enforcement'!F7:F56,"Non-Compliant")
A40: % MFA Coverage | B40: =IF(COUNTA('MFA Enforcement'!F7:F56)=0,"0%",ROUND(COUNTIF('MFA Enforcement'!F7:F56,"Compliant")/COUNTA('MFA Enforcement'!F7:F56)*100,1)&"%")
A44: TABLE 3: CRITICAL FINDINGS
A45: # | B45: Developer ID | C45: Severity | D45: Production Account | E45: Justification | F45: Remediation Action | G45: Status
...

Sheet Approval Sign-Off
A1: ASSESSMENT APPROVAL AND SIGN-OFF
A2: ISO/IEC 27001:2022 - Control A.8.31: Separation of Development, Test and Production Environments
A4: ASSESSMENT SUMMARY
A5: Document: | B5: ISMS-IMP-A.8.31.2
A6: Overall Compliance Rating: | B6: ='Summary Dashboard'!G13
A7: Assessment Period:
A8: Assessed By:
A9: Assessment Status:
A11: COMPLETED BY — Assessment Lead
A12: Name:
A13: Title:
A14: Date:
A15: Signature:
A16: Comments:
A18: REVIEWED BY — Security Manager
A19: Name:
A20: Title:
... A38: Special Considerations:
