Workbook

Sheet Executive Summary
A1: ISMS-OP-CHK-A.5.15-16-18 — Identity and Access Management Compliance Checklist
A3: DOCUMENT INFORMATION
A4: Document ID | B4: ISMS-OP-CHK-A.5.15-16-18
A5: Source Policy | B5: ISMS-OP-POL-A.5.15-16-18
A6: ISO Controls | B6: Identity and Access Management
A7: Generated | B7: 30.09.2026
A8: Prepared By
A9: Organisation
A10: Review Cycle | B10: Annual
A12: OVERALL COMPLIANCE STATUS
A13: Overall Compliance | B13: ='Dashboard'!G18
A14: Status | B14: =IF(Dashboard!H18>0,"INCOMPLETE",IF(Dashboard!G18="N/A","NOT ASSESSED",IF(ISNUMBER(VALUE(SUBSTITUTE(Dashboard!G18,"%",""))),IF(VALUE(SUBSTITUTE(Dashboard!G18,"%",""))>=90,"GREEN",IF(VALUE(SUBSTITUTE(Dashboard!G18,"%",""))>=70,"AMBER","RED")),"NOT ASSESSED")))
A16: KEY METRICS
A17: Total Requirements | B17: ='Dashboard'!B18
A18: Compliant | B18: ='Dashboard'!C18
A19: Partial | B19: ='Dashboard'!D18
A20: Non-Compliant | B20: ='Dashboard'!E18
A21: Not Applicable | B21: ='Dashboard'!F18
A22: Unanswered | B22: ='Dashboard'!H18
A23: Owner Coverage | B23: =IF(Dashboard!B18=0,"N/A",ROUND((COUNTA('Confidentiality Agreements'!F4:F4)+COUNTA('Role-Based Access'!F4:F4)+COUNTA('Unique Identifier'!F4:F5)+COUNTA('Access Authentication'!F4:F5)+COUNTA('Access Rights Review'!F4:F6)+COUNTA('Privileged Accounts'!F4:F6)+COUNTA('Service Accounts'!F4:F11)+COUNTA('Passwords'!F4:F4)+COUNTA('User Account Provisioning'!F4:F8)+COUNTA('Leavers'!F4:F6)+COUNTA('Authentication'!F4:F5)+COUNTA('Remote Access'!F4:F5)+COUNTA('Third-Party Remote Access'!F4:F6)+COUNTA('Monitoring and Reporting'!F4:F4))/Dashboard!B18*100,0)&"%")
A25: DOMAIN STATUS SUMMARY
A26: Domain | B26: Compliance % | C26: Compliant | D26: Gaps | E26: Status
A27: Confidentiality Agreements | B27: ='Dashboard'!G4 | C27: ='Dashboard'!C4 | D27: ='Dashboard'!E4 | E27: =IF(Dashboard!H4>0,"INCOMPLETE",IF(Dashboard!G4="N/A","--",IF(ISNUMBER(VALUE(SUBSTITUTE(Dashboard!G4,"%",""))),IF(VALUE(SUBSTITUTE(Dashboard!G4,"%",""))>=90,"PASS",IF(VALUE(SUBSTITUTE(Dashboard!G4,"%",""))>=70,"REVIEW","FAIL")),"--")))
A28: Role-Based Access | B28: ='Dashboard'!G5 | C28: ='Dashboard'!C5 | D28: ='Dashboard'!E5 | E28: =IF(Dashboard!H5>0,"INCOMPLETE",IF(Dashboard!G5="N/A","--",IF(ISNUMBER(VALUE(SUBSTITUTE(Dashboard!G5,"%",""))),IF(VALUE(SUBSTITUTE(Dashboard!G5,"%",""))>=90,"PASS",IF(VALUE(SUBSTITUTE(Dashboard!G5,"%",""))>=70,"REVIEW","FAIL")),"--")))
A29: Unique Identifier | B29: ='Dashboard'!G6 | C29: ='Dashboard'!C6 | D29: ='Dashboard'!E6 | E29: =IF(Dashboard!H6>0,"INCOMPLETE",IF(Dashboard!G6="N/A","--",IF(ISNUMBER(VALUE(SUBSTITUTE(Dashboard!G6,"%",""))),IF(VALUE(SUBSTITUTE(Dashboard!G6,"%",""))>=90,"PASS",IF(VALUE(SUBSTITUTE(Dashboard!G6,"%",""))>=70,"REVIEW","FAIL")),"--")))
A30: Access Authentication | B30: ='Dashboard'!G7 | C30: ='Dashboard'!C7 | D30: ='Dashboard'!E7 | E30: =IF(Dashboard!H7>0,"INCOMPLETE",IF(Dashboard!G7="N/A","--",IF(ISNUMBER(VALUE(SUBSTITUTE(Dashboard!G7,"%",""))),IF(VALUE(SUBSTITUTE(Dashboard!G7,"%",""))>=90,"PASS",IF(VALUE(SUBSTITUTE(Dashboard!G7,"%",""))>=70,"REVIEW","FAIL")),"--")))
A31: Access Rights Review | B31: ='Dashboard'!G8 | C31: ='Dashboard'!C8 | D31: ='Dashboard'!E8 | E31: =IF(Dashboard!H8>0,"INCOMPLETE",IF(Dashboard!G8="N/A","--",IF(ISNUMBER(VALUE(SUBSTITUTE(Dashboard!G8,"%",""))),IF(VALUE(SUBSTITUTE(Dashboard!G8,"%",""))>=90,"PASS",IF(VALUE(SUBSTITUTE(Dashboard!G8,"%",""))>=70,"REVIEW","FAIL")),"--")))
A32: Privileged Accounts | B32: ='Dashboard'!G9 | C32: ='Dashboard'!C9 | D32: ='Dashboard'!E9 | E32: =IF(Dashboard!H9>0,"INCOMPLETE",IF(Dashboard!G9="N/A","--",IF(ISNUMBER(VALUE(SUBSTITUTE(Dashboard!G9,"%",""))),IF(VALUE(SUBSTITUTE(Dashboard!G9,"%",""))>=90,"PASS",IF(VALUE(SUBSTITUTE(Dashboard!G9,"%",""))>=70,"REVIEW","FAIL")),"--")))
A33: Service Accounts | B33: ='Dashboard'!G10 | C33: ='Dashboard'!C10 | D33: ='Dashboard'!E10 | E33: =IF(Dashboard!H10>0,"INCOMPLETE",IF(Dashboard!G10="N/A","--",IF(ISNUMBER(VALUE(SUBSTITUTE(Dashboard!G10,"%",""))),IF(VALUE(SUBSTITUTE(Dashboard!G10,"%",""))>=90,"PASS",IF(VALUE(SUBSTITUTE(Dashboard!G10,"%",""))>=70,"REVIEW","FAIL")),"--")))
A34: Passwords | B34: ='Dashboard'!G11 | C34: ='Dashboard'!C11 | D34: ='Dashboard'!E11 | E34: =IF(Dashboard!H11>0,"INCOMPLETE",IF(Dashboard!G11="N/A","--",IF(ISNUMBER(VALUE(SUBSTITUTE(Dashboard!G11,"%",""))),IF(VALUE(SUBSTITUTE(Dashboard!G11,"%",""))>=90,"PASS",IF(VALUE(SUBSTITUTE(Dashboard!G11,"%",""))>=70,"REVIEW","FAIL")),"--")))
A35: User Account Provisioning | B35: ='Dashboard'!G12 | C35: ='Dashboard'!C12 | D35: ='Dashboard'!E12 | E35: =IF(Dashboard!H12>0,"INCOMPLETE",IF(Dashboard!G12="N/A","--",IF(ISNUMBER(VALUE(SUBSTITUTE(Dashboard!G12,"%",""))),IF(VALUE(SUBSTITUTE(Dashboard!G12,"%",""))>=90,"PASS",IF(VALUE(SUBSTITUTE(Dashboard!G12,"%",""))>=70,"REVIEW","FAIL")),"--")))
A36: Leavers | B36: ='Dashboard'!G13 | C36: ='Dashboard'!C13 | D36: ='Dashboard'!E13 | E36: =IF(Dashboard!H13>0,"INCOMPLETE",IF(Dashboard!G13="N/A","--",IF(ISNUMBER(VALUE(SUBSTITUTE(Dashboard!G13,"%",""))),IF(VALUE(SUBSTITUTE(Dashboard!G13,"%",""))>=90,"PASS",IF(VALUE(SUBSTITUTE(Dashboard!G13,"%",""))>=70,"REVIEW","FAIL")),"--")))
A37: Authentication | B37: ='Dashboard'!G14 | C37: ='Dashboard'!C14 | D37: ='Dashboard'!E14 | E37: =IF(Dashboard!H14>0,"INCOMPLETE",IF(Dashboard!G14="N/A","--",IF(ISNUMBER(VALUE(SUBSTITUTE(Dashboard!G14,"%",""))),IF(VALUE(SUBSTITUTE(Dashboard!G14,"%",""))>=90,"PASS",IF(VALUE(SUBSTITUTE(Dashboard!G14,"%",""))>=70,"REVIEW","FAIL")),"--")))
A38: Remote Access | B38: ='Dashboard'!G15 | C38: ='Dashboard'!C15 | D38: ='Dashboard'!E15 | E38: =IF(Dashboard!H15>0,"INCOMPLETE",IF(Dashboard!G15="N/A","--",IF(ISNUMBER(VALUE(SUBSTITUTE(Dashboard!G15,"%",""))),IF(VALUE(SUBSTITUTE(Dashboard!G15,"%",""))>=90,"PASS",IF(VALUE(SUBSTITUTE(Dashboard!G15,"%",""))>=70,"REVIEW","FAIL")),"--")))
... A40: Monitoring and Reporting | B40: ='Dashboard'!G17 | C40: ='Dashboard'!C17 | D40: ='Dashboard'!E17 | E40: =IF(Dashboard!H17>0,"INCOMPLETE",IF(Dashboard!G17="N/A","--",IF(ISNUMBER(VALUE(SUBSTITUTE(Dashboard!G17,"%",""))),IF(VALUE(SUBSTITUTE(Dashboard!G17,"%",""))>=90,"PASS",IF(VALUE(SUBSTITUTE(Dashboard!G17,"%",""))>=70,"REVIEW","FAIL")),"--")))
A42: CRITICAL ISSUES
A43: # | B43: Issue Description | C43: Domain | D43: Owner | E43: Due Date
A44: 1
A45: 2
A46: 3
...

Sheet Dashboard
A1: Identity and Access Management — Compliance Dashboard
A3: Domain | B3: Total Reqs | C3: Compliant | D3: Partial | E3: Non-Compliant | F3: N/A | G3: Compliance % | H3: Unassessed
A4: Confidentiality Agreements | B4: =COUNTA('Confidentiality Agreements'!A4:A4) | C4: =COUNTIF('Confidentiality Agreements'!D4:D4,"Compliant") | D4: =COUNTIF('Confidentiality Agreements'!D4:D4,"Partial") | E4: =COUNTIF('Confidentiality Agreements'!D4:D4,"Non-Compliant") | F4: =COUNTIF('Confidentiality Agreements'!D4:D4,"N/A") | G4: =IF((B4-F4)=0,"N/A",ROUND(C4/(B4-F4)*100,1)&"%") | H4: =B4-(C4+D4+E4+F4)
A5: Role-Based Access | B5: =COUNTA('Role-Based Access'!A4:A4) | C5: =COUNTIF('Role-Based Access'!D4:D4,"Compliant") | D5: =COUNTIF('Role-Based Access'!D4:D4,"Partial") | E5: =COUNTIF('Role-Based Access'!D4:D4,"Non-Compliant") | F5: =COUNTIF('Role-Based Access'!D4:D4,"N/A") | G5: =IF((B5-F5)=0,"N/A",ROUND(C5/(B5-F5)*100,1)&"%") | H5: =B5-(C5+D5+E5+F5)
A6: Unique Identifier | B6: =COUNTA('Unique Identifier'!A4:A5) | C6: =COUNTIF('Unique Identifier'!D4:D5,"Compliant") | D6: =COUNTIF('Unique Identifier'!D4:D5,"Partial") | E6: =COUNTIF('Unique Identifier'!D4:D5,"Non-Compliant") | F6: =COUNTIF('Unique Identifier'!D4:D5,"N/A") | G6: =IF((B6-F6)=0,"N/A",ROUND(C6/(B6-F6)*100,1)&"%") | H6: =B6-(C6+D6+E6+F6)
A7: Access Authentication | B7: =COUNTA('Access Authentication'!A4:A5) | C7: =COUNTIF('Access Authentication'!D4:D5,"Compliant") | D7: =COUNTIF('Access Authentication'!D4:D5,"Partial") | E7: =COUNTIF('Access Authentication'!D4:D5,"Non-Compliant") | F7: =COUNTIF('Access Authentication'!D4:D5,"N/A") | G7: =IF((B7-F7)=0,"N/A",ROUND(C7/(B7-F7)*100,1)&"%") | H7: =B7-(C7+D7+E7+F7)
A8: Access Rights Review | B8: =COUNTA('Access Rights Review'!A4:A6) | C8: =COUNTIF('Access Rights Review'!D4:D6,"Compliant") | D8: =COUNTIF('Access Rights Review'!D4:D6,"Partial") | E8: =COUNTIF('Access Rights Review'!D4:D6,"Non-Compliant") | F8: =COUNTIF('Access Rights Review'!D4:D6,"N/A") | G8: =IF((B8-F8)=0,"N/A",ROUND(C8/(B8-F8)*100,1)&"%") | H8: =B8-(C8+D8+E8+F8)
A9: Privileged Accounts | B9: =COUNTA('Privileged Accounts'!A4:A6) | C9: =COUNTIF('Privileged Accounts'!D4:D6,"Compliant") | D9: =COUNTIF('Privileged Accounts'!D4:D6,"Partial") | E9: =COUNTIF('Privileged Accounts'!D4:D6,"Non-Compliant") | F9: =COUNTIF('Privileged Accounts'!D4:D6,"N/A") | G9: =IF((B9-F9)=0,"N/A",ROUND(C9/(B9-F9)*100,1)&"%") | H9: =B9-(C9+D9+E9+F9)
A10: Service Accounts | B10: =COUNTA('Service Accounts'!A4:A11) | C10: =COUNTIF('Service Accounts'!D4:D11,"Compliant") | D10: =COUNTIF('Service Accounts'!D4:D11,"Partial") | E10: =COUNTIF('Service Accounts'!D4:D11,"Non-Compliant") | F10: =COUNTIF('Service Accounts'!D4:D11,"N/A") | G10: =IF((B10-F10)=0,"N/A",ROUND(C10/(B10-F10)*100,1)&"%") | H10: =B10-(C10+D10+E10+F10)
A11: Passwords | B11: =COUNTA('Passwords'!A4:A4) | C11: =COUNTIF('Passwords'!D4:D4,"Compliant") | D11: =COUNTIF('Passwords'!D4:D4,"Partial") | E11: =COUNTIF('Passwords'!D4:D4,"Non-Compliant") | F11: =COUNTIF('Passwords'!D4:D4,"N/A") | G11: =IF((B11-F11)=0,"N/A",ROUND(C11/(B11-F11)*100,1)&"%") | H11: =B11-(C11+D11+E11+F11)
A12: User Account Provisioning | B12: =COUNTA('User Account Provisioning'!A4:A8) | C12: =COUNTIF('User Account Provisioning'!D4:D8,"Compliant") | D12: =COUNTIF('User Account Provisioning'!D4:D8,"Partial") | E12: =COUNTIF('User Account Provisioning'!D4:D8,"Non-Compliant") | F12: =COUNTIF('User Account Provisioning'!D4:D8,"N/A") | G12: =IF((B12-F12)=0,"N/A",ROUND(C12/(B12-F12)*100,1)&"%") | H12: =B12-(C12+D12+E12+F12)
A13: Leavers | B13: =COUNTA('Leavers'!A4:A6) | C13: =COUNTIF('Leavers'!D4:D6,"Compliant") | D13: =COUNTIF('Leavers'!D4:D6,"Partial") | E13: =COUNTIF('Leavers'!D4:D6,"Non-Compliant") | F13: =COUNTIF('Leavers'!D4:D6,"N/A") | G13: =IF((B13-F13)=0,"N/A",ROUND(C13/(B13-F13)*100,1)&"%") | H13: =B13-(C13+D13+E13+F13)
A14: Authentication | B14: =COUNTA('Authentication'!A4:A5) | C14: =COUNTIF('Authentication'!D4:D5,"Compliant") | D14: =COUNTIF('Authentication'!D4:D5,"Partial") | E14: =COUNTIF('Authentication'!D4:D5,"Non-Compliant") | F14: =COUNTIF('Authentication'!D4:D5,"N/A") | G14: =IF((B14-F14)=0,"N/A",ROUND(C14/(B14-F14)*100,1)&"%") | H14: =B14-(C14+D14+E14+F14)
A15: Remote Access | B15: =COUNTA('Remote Access'!A4:A5) | C15: =COUNTIF('Remote Access'!D4:D5,"Compliant") | D15: =COUNTIF('Remote Access'!D4:D5,"Partial") | E15: =COUNTIF('Remote Access'!D4:D5,"Non-Compliant") | F15: =COUNTIF('Remote Access'!D4:D5,"N/A") | G15: =IF((B15-F15)=0,"N/A",ROUND(C15/(B15-F15)*100,1)&"%") | H15: =B15-(C15+D15+E15+F15)
A16: Third-Party Remote Access | B16: =COUNTA('Third-Party Remote Access'!A4:A6) | C16: =COUNTIF('Third-Party Remote Access'!D4:D6,"Compliant") | D16: =COUNTIF('Third-Party Remote Access'!D4:D6,"Partial") | E16: =COUNTIF('Third-Party Remote Access'!D4:D6,"Non-Compliant") | F16: =COUNTIF('Third-Party Remote Access'!D4:D6,"N/A") | G16: =IF((B16-F16)=0,"N/A",ROUND(C16/(B16-F16)*100,1)&"%") | H16: =B16-(C16+D16+E16+F16)
A17: Monitoring and Reporting | B17: =COUNTA('Monitoring and Reporting'!A4:A4) | C17: =COUNTIF('Monitoring and Reporting'!D4:D4,"Compliant") | D17: =COUNTIF('Monitoring and Reporting'!D4:D4,"Partial") | E17: =COUNTIF('Monitoring and Reporting'!D4:D4,"Non-Compliant") | F17: =COUNTIF('Monitoring and Reporting'!D4:D4,"N/A") | G17: =IF((B17-F17)=0,"N/A",ROUND(C17/(B17-F17)*100,1)&"%") | H17: =B17-(C17+D17+E17+F17)
A18: TOTAL | B18: =SUM(B4:B17) | C18: =SUM(C4:C17) | D18: =SUM(D4:D17) | E18: =SUM(E4:E17) | F18: =SUM(F4:F17) | G18: =IF((B18-F18)=0,"N/A",ROUND(C18/(B18-F18)*100,1)&"%") | H18: =SUM(H4:H17)
A20: COMPLIANCE BY STATUS
A21: Compliant | B21: =C18 | C21: =IF(B18=0,"",ROUND(B21/B18*100,1)&"%")
A22: Partial | B22: =D18 | C22: =IF(B18=0,"",ROUND(B22/B18*100,1)&"%")
A23: Non-Compliant | B23: =E18 | C23: =IF(B18=0,"",ROUND(B23/B18*100,1)&"%")
A24: N/A | B24: =F18 | C24: =IF(B18=0,"",ROUND(B24/B18*100,1)&"%")
A26: TOP GAPS (Manual Entry)
A27: Priority | B27: Domain | C27: Requirement | D27: Owner | E27: Due Date | F27: Status
A39: COMPLIANCE TREND (Manual Entry)
A40: Assessment Date | B40: Overall % | C40: Compliant | D40: Gaps | E40: Assessor | F40: Notes

Sheet Confidentiality Agreements
A1: Confidentiality Agreements — Compliance Checklist
A2: ISO/IEC 27001:2022 — Controls A.5.15-16-18: Identity and Access Management
A3: Req # | B3: Section | C3: Requirement | D3: Status | E3: Evidence | F3: Owner | G3: Due Date | H3: Notes
A4: A.5.15-16-18-01 | B4: Employees And Contractors Who Are Given | C4: All employees and contractors who are given access to confidential information shall sign a confidentiality or non-disclosure agreement prior to being given access to information processing facilities.

Sheet Role-Based Access
A1: Role-Based Access — Compliance Checklist
A2: ISO/IEC 27001:2022 — Controls A.5.15-16-18: Identity and Access Management
A3: Req # | B3: Section | C3: Requirement | D3: Status | E3: Evidence | F3: Owner | G3: Due Date | H3: Notes
A4: A.5.15-16-18-02 | B4: Implement Role-Based Access Control | C4: The organisation shall implement role-based access control (RBAC) as the preferred method for assigning access. Roles shall be documented and reviewed annually by business owners.

Sheet Unique Identifier
A1: Unique Identifier — Compliance Checklist
A2: ISO/IEC 27001:2022 — Controls A.5.15-16-18: Identity and Access Management
A3: Req # | B3: Section | C3: Requirement | D3: Status | E3: Evidence | F3: Owner | G3: Due Date | H3: Notes
A4: A.5.15-16-18-03 | B4: Users Are Assigned A Unique Username | C4: Users are assigned a unique username or identifier on the principle of one user, one ID to ensure individual accountability. Usernames and identifiers shall not be shared between users.
A5: A.5.15-16-18-04 | B5: Shared Accounts Are Prohibited Except | C5: Shared accounts are prohibited except where technically unavoidable (legacy systems, vendor-required accounts). Any exception requires written CISO approval with documented business justification, compensating controls (individual user logging, quarterly review), and formal risk acceptance. Shared accounts shall be included in the privileged account register.

Sheet Access Authentication
A1: Access Authentication — Compliance Checklist
A2: ISO/IEC 27001:2022 — Controls A.5.15-16-18: Identity and Access Management
A3: Req # | B3: Section | C3: Requirement | D3: Status | E3: Evidence | F3: Owner | G3: Due Date | H3: Notes
A4: A.5.15-16-18-05 | B4: Multi-Factor Authentication (Mfa) | C4: Multi-factor authentication (MFA) shall be required for:.
A5: A.5.15-16-18-06 | B5: Systems Unable To Support Mfa | C5: Systems unable to support MFA shall be documented in the risk register with technical justification, compensating controls (e.g., network segmentation, enhanced monitoring), and CISO-approved risk acceptance reviewed annually.

Sheet Access Rights Review
A1: Access Rights Review — Compliance Checklist
A2: ISO/IEC 27001:2022 — Controls A.5.15-16-18: Identity and Access Management
A3: Req # | B3: Section | C3: Requirement | D3: Status | E3: Evidence | F3: Owner | G3: Due Date | H3: Notes
A4: A.5.15-16-18-07 | B4: User Access To Systems | C4: User access to systems shall be reviewed periodically to ensure it is still appropriate and relevant:.
A5: A.5.15-16-18-08 | B5: Inactive And Dormant Accounts | C5: Inactive and dormant accounts shall be investigated. An account is considered inactive if it has not successfully authenticated within the specified period. Accounts inactive for more than 45 days shall be disabled. Accounts inactive for more than 90 days shall be removed unless a documented business justification exists.
A6: A.5.15-16-18-09 | B6: Service Accounts Are Excluded From | C6: Service accounts are excluded from inactivity-based disablement but shall be reviewed quarterly to verify they remain in active use and are still required. Unused service accounts shall be disabled immediately upon discovery.

Sheet Privileged Accounts
A1: Privileged Accounts — Compliance Checklist
A2: ISO/IEC 27001:2022 — Controls A.5.15-16-18: Identity and Access Management
A3: Req # | B3: Section | C3: Requirement | D3: Status | E3: Evidence | F3: Owner | G3: Due Date | H3: Notes
A4: A.5.15-16-18-10 | B4: Administrator Accounts | C4: Administrator accounts shall not be provided to users for standard tasks, including but not limited to laptops and mobile technology.
A5: A.5.15-16-18-11 | B5: Privileged And Administrator Users | C5: Where feasible, privileged and administrator users shall be assigned specific privileged accounts in addition to their normal account, for the specific use of completing privileged and administrator tasks.
A6: A.5.15-16-18-12 | B6: Privileged And Administrator Accounts | C6: Privileged and administrator accounts shall:.

Sheet Service Accounts
A1: Service Accounts — Compliance Checklist
A2: ISO/IEC 27001:2022 — Controls A.5.15-16-18: Identity and Access Management
A3: Req # | B3: Section | C3: Requirement | D3: Status | E3: Evidence | F3: Owner | G3: Due Date | H3: Notes
A4: A.5.15-16-18-13 | B4: Service Accounts (Non-Human Accounts | C4: Service accounts (non-human accounts used by applications, scripts, or automated processes) shall be managed according to the following requirements:.
A5: A.5.15-16-18-14 | B5: Service Account Creation | C5: Service account creation shall be approved by the system owner and CISO.
A6: A.5.15-16-18-15 | B6: Service Accounts | C6: All service accounts shall be documented with purpose, system/application, owner, and review date.
A7: A.5.15-16-18-16 | B7: Service Accounts | C7: Service accounts shall be granted only the minimum permissions required for their function.
A8: A.5.15-16-18-17 | B8: Service Accounts | C8: Service accounts shall not be used for interactive login by personnel.
A9: A.5.15-16-18-18 | B9: Service Account Credentials | C9: Service account credentials shall be stored in an approved secrets management solution, not hard-coded or stored in plaintext.
A10: A.5.15-16-18-19 | B10: Service Account Activity | C10: Service account activity shall be logged and monitored for anomalous behaviour.
A11: A.5.15-16-18-20 | B11: Service Accounts | C11: Service accounts shall be reviewed quarterly per the access review schedule.

Sheet Passwords
A1: Passwords — Compliance Checklist
A2: ISO/IEC 27001:2022 — Controls A.5.15-16-18: Identity and Access Management
A3: Req # | B3: Section | C3: Requirement | D3: Status | E3: Evidence | F3: Owner | G3: Due Date | H3: Notes
A4: A.5.15-16-18-21 | B4: Access To Systems And Information Is | C4: Access to systems and information is authenticated by passwords. The organisation shall enforce the following password standards:.

Sheet User Account Provisioning
A1: User Account Provisioning — Compliance Checklist
A2: ISO/IEC 27001:2022 — Controls A.5.15-16-18: Identity and Access Management
A3: Req # | B3: Section | C3: Requirement | D3: Status | E3: Evidence | F3: Owner | G3: Due Date | H3: Notes
A4: A.5.15-16-18-22 | B4: Account Creation, Modification, And | C4: Account creation, modification, and deletion shall be performed by authorised personnel and fully documented.
A5: A.5.15-16-18-23 | B5: Implement A Joiner-Mover-Leaver (Jml) | C5: The organisation shall implement a Joiner-Mover-Leaver (JML) process:.
A6: A.5.15-16-18-24 | B6: Business, System, Or Information Owners | C6: Business, system, or information owners shall approve access to systems and information. A documented request shall clearly indicate the required access and an authorisation record shall be maintained.
A7: A.5.15-16-18-25 | B7: Emergency Access (Break-Glass) May Be | C7: Emergency access (break-glass) may be granted by IT with CISO verbal approval and shall be formally documented within 1 business day.
A8: A.5.15-16-18-26 | B8: Users Requesting Password Resets Or | C8: All users requesting password resets or changes to authentication credentials shall have their identity verified using at least one of the following methods:.

Sheet Leavers
A1: Leavers — Compliance Checklist
A2: ISO/IEC 27001:2022 — Controls A.5.15-16-18: Identity and Access Management
A3: Req # | B3: Section | C3: Requirement | D3: Status | E3: Evidence | F3: Owner | G3: Due Date | H3: Notes
A4: A.5.15-16-18-27 | B4: Line Managers And Hr | C4: Line managers and HR shall inform the account provisioning team of a user's leave date.
A5: A.5.15-16-18-28 | B5: All Access | C5: When a user leaves the organisation, all access shall be revoked on the same business day, as a minimum to the main authentication technology, and to all systems and data recorded in the role-based access list.
A6: A.5.15-16-18-29 | B6: User Ids, Passwords, And Authentication | C6: User IDs, passwords, and authentication credentials of leavers shall not be reused.

Sheet Authentication
A1: Authentication — Compliance Checklist
A2: ISO/IEC 27001:2022 — Controls A.5.15-16-18: Identity and Access Management
A3: Req # | B3: Section | C3: Requirement | D3: Status | E3: Evidence | F3: Owner | G3: Due Date | H3: Notes
A4: A.5.15-16-18-30 | B4: The Main Access Authentication System | C4: The main access authentication system shall:.
A5: A.5.15-16-18-31 | B5: Validate The Log-On Information Only On | C5: Validate the log-on information only on completion of all input data. If an error condition arises, the system shall not indicate which part of the data is correct or incorrect.

Sheet Remote Access
A1: Remote Access — Compliance Checklist
A2: ISO/IEC 27001:2022 — Controls A.5.15-16-18: Identity and Access Management
A3: Req # | B3: Section | C3: Requirement | D3: Status | E3: Evidence | F3: Owner | G3: Due Date | H3: Notes
A4: A.5.15-16-18-32 | B4: Remote Connections | C4: Remote connections shall be set to disconnect after a defined period of inactivity.
A5: A.5.15-16-18-33 | B5: A List Of Users With Remote | C5: A list of users with remote access to internal network systems shall be maintained and reviewed quarterly.

Sheet Third-Party Remote Access
A1: Third-Party Remote Access — Compliance Checklist
A2: ISO/IEC 27001:2022 — Controls A.5.15-16-18: Identity and Access Management
A3: Req # | B3: Section | C3: Requirement | D3: Status | E3: Evidence | F3: Owner | G3: Due Date | H3: Notes
A4: A.5.15-16-18-34 | B4: Be Granted For A Specific Time | C4: Access shall be granted for a specific time, to a specific system, to a specific individual, and provided on receipt of a formal, valid, authorised access request.
A5: A.5.15-16-18-35 | B5: Be Removed Immediately On Completion Of | C5: Access shall be removed immediately on completion of the requirement or contract end, whichever comes first.
A6: A.5.15-16-18-36 | B6: A List Of Third Parties And | C6: A list of third parties and individuals with access shall be maintained and reviewed quarterly.

Sheet Monitoring and Reporting
A1: Monitoring and Reporting — Compliance Checklist
A2: ISO/IEC 27001:2022 — Controls A.5.15-16-18: Identity and Access Management
A3: Req # | B3: Section | C3: Requirement | D3: Status | E3: Evidence | F3: Owner | G3: Due Date | H3: Notes
A4: A.5.15-16-18-37 | B4: Access To Systems | C4: Access to systems shall be monitored and reported. Actions that directly or indirectly affect or could affect the confidentiality, integrity, or availability of data shall be managed via the Incident Management process.
