Workbook

Sheet Executive Summary
A1: AI-CHK-A.5.2-5 — AI System Impact Assessment Compliance Checklist
A3: DOCUMENT INFORMATION
A4: Document ID | B4: AI-CHK-A.5.2-5
A5: Source Policy | B5: AI-POL-A.5.2-5
A6: ISO Controls | B6: AI System Impact Assessment
A7: Generated | B7: 15.04.2026
A8: Prepared By
A9: Organisation
A10: Review Cycle | B10: Annual
A12: OVERALL COMPLIANCE STATUS
A13: Overall Compliance | B13: ='Dashboard'!G8
A14: Status | B14: =IF(Dashboard!G8="N/A","NOT ASSESSED",IF(ISNUMBER(VALUE(SUBSTITUTE(Dashboard!G8,"%",""))),IF(VALUE(SUBSTITUTE(Dashboard!G8,"%",""))>=90,"GREEN",IF(VALUE(SUBSTITUTE(Dashboard!G8,"%",""))>=70,"AMBER","RED")),"NOT ASSESSED"))
A16: KEY METRICS
A17: Total Requirements | B17: ='Dashboard'!B8
A18: Compliant | B18: ='Dashboard'!C8
A19: Partial | B19: ='Dashboard'!D8
A20: Non-Compliant | B20: ='Dashboard'!E8
A21: Not Applicable | B21: ='Dashboard'!F8
A22: Owner Coverage | B22: =IF(Dashboard!B8=0,"N/A",ROUND((COUNTA('AISIA Process'!F4:F10)+COUNTA('AISIA Documentation'!F4:F8)+COUNTA('Individual Impact Assessment'!F4:F9)+COUNTA('Societal Impact Assessment'!F4:F8))/Dashboard!B8*100,0)&"%")
A24: DOMAIN STATUS SUMMARY
A25: Domain | B25: Compliance % | C25: Compliant | D25: Gaps | E25: Status
A26: AISIA Process | B26: ='Dashboard'!G4 | C26: ='Dashboard'!C4 | D26: ='Dashboard'!E4 | E26: =IF(Dashboard!G4="N/A","--",IF(ISNUMBER(VALUE(SUBSTITUTE(Dashboard!G4,"%",""))),IF(VALUE(SUBSTITUTE(Dashboard!G4,"%",""))>=90,"PASS",IF(VALUE(SUBSTITUTE(Dashboard!G4,"%",""))>=70,"REVIEW","FAIL")),"--"))
A27: AISIA Documentation | B27: ='Dashboard'!G5 | C27: ='Dashboard'!C5 | D27: ='Dashboard'!E5 | E27: =IF(Dashboard!G5="N/A","--",IF(ISNUMBER(VALUE(SUBSTITUTE(Dashboard!G5,"%",""))),IF(VALUE(SUBSTITUTE(Dashboard!G5,"%",""))>=90,"PASS",IF(VALUE(SUBSTITUTE(Dashboard!G5,"%",""))>=70,"REVIEW","FAIL")),"--"))
A28: Individual Impact Assessment | B28: ='Dashboard'!G6 | C28: ='Dashboard'!C6 | D28: ='Dashboard'!E6 | E28: =IF(Dashboard!G6="N/A","--",IF(ISNUMBER(VALUE(SUBSTITUTE(Dashboard!G6,"%",""))),IF(VALUE(SUBSTITUTE(Dashboard!G6,"%",""))>=90,"PASS",IF(VALUE(SUBSTITUTE(Dashboard!G6,"%",""))>=70,"REVIEW","FAIL")),"--"))
A29: Societal Impact Assessment | B29: ='Dashboard'!G7 | C29: ='Dashboard'!C7 | D29: ='Dashboard'!E7 | E29: =IF(Dashboard!G7="N/A","--",IF(ISNUMBER(VALUE(SUBSTITUTE(Dashboard!G7,"%",""))),IF(VALUE(SUBSTITUTE(Dashboard!G7,"%",""))>=90,"PASS",IF(VALUE(SUBSTITUTE(Dashboard!G7,"%",""))>=70,"REVIEW","FAIL")),"--"))
A31: CRITICAL ISSUES
A32: # | B32: Issue Description | C32: Domain | D32: Owner | E32: Due Date
A33: 1
A34: 2
A35: 3
A36: 4
A37: 5
A39: MANAGEMENT COMMENTARY
A40: [Enter management commentary on ai system impact assessment posture]
A44: APPROVAL
A45: Assessed By (AI System Owner)
A46: Name:
A47: Date:
A48: Signature:
A49: Decision:
...

Sheet Dashboard
A1: AI System Impact Assessment — Compliance Dashboard
A3: Domain | B3: Total Reqs | C3: Compliant | D3: Partial | E3: Non-Compliant | F3: N/A | G3: Compliance %
A4: AISIA Process | B4: =COUNTA('AISIA Process'!D4:D10) | C4: =COUNTIF('AISIA Process'!D4:D10,"Compliant") | D4: =COUNTIF('AISIA Process'!D4:D10,"Partial") | E4: =COUNTIF('AISIA Process'!D4:D10,"Non-Compliant") | F4: =COUNTIF('AISIA Process'!D4:D10,"N/A") | G4: =IF((B4-F4)=0,"N/A",ROUND(C4/(B4-F4)*100,1)&"%")
A5: AISIA Documentation | B5: =COUNTA('AISIA Documentation'!D4:D8) | C5: =COUNTIF('AISIA Documentation'!D4:D8,"Compliant") | D5: =COUNTIF('AISIA Documentation'!D4:D8,"Partial") | E5: =COUNTIF('AISIA Documentation'!D4:D8,"Non-Compliant") | F5: =COUNTIF('AISIA Documentation'!D4:D8,"N/A") | G5: =IF((B5-F5)=0,"N/A",ROUND(C5/(B5-F5)*100,1)&"%")
A6: Individual Impact Assessment | B6: =COUNTA('Individual Impact Assessment'!D4:D9) | C6: =COUNTIF('Individual Impact Assessment'!D4:D9,"Compliant") | D6: =COUNTIF('Individual Impact Assessment'!D4:D9,"Partial") | E6: =COUNTIF('Individual Impact Assessment'!D4:D9,"Non-Compliant") | F6: =COUNTIF('Individual Impact Assessment'!D4:D9,"N/A") | G6: =IF((B6-F6)=0,"N/A",ROUND(C6/(B6-F6)*100,1)&"%")
A7: Societal Impact Assessment | B7: =COUNTA('Societal Impact Assessment'!D4:D8) | C7: =COUNTIF('Societal Impact Assessment'!D4:D8,"Compliant") | D7: =COUNTIF('Societal Impact Assessment'!D4:D8,"Partial") | E7: =COUNTIF('Societal Impact Assessment'!D4:D8,"Non-Compliant") | F7: =COUNTIF('Societal Impact Assessment'!D4:D8,"N/A") | G7: =IF((B7-F7)=0,"N/A",ROUND(C7/(B7-F7)*100,1)&"%")
A8: TOTAL | B8: =SUM(B4:B7) | C8: =SUM(C4:C7) | D8: =SUM(D4:D7) | E8: =SUM(E4:E7) | F8: =SUM(F4:F7) | G8: =IF((B8-F8)=0,"N/A",ROUND(C8/(B8-F8)*100,1)&"%")
A10: COMPLIANCE BY STATUS
A11: Compliant | B11: =C8 | C11: =IF(B8=0,"",ROUND(B11/B8*100,1)&"%")
A12: Partial | B12: =D8 | C12: =IF(B8=0,"",ROUND(B12/B8*100,1)&"%")
A13: Non-Compliant | B13: =E8 | C13: =IF(B8=0,"",ROUND(B13/B8*100,1)&"%")
A14: N/A | B14: =F8 | C14: =IF(B8=0,"",ROUND(B14/B8*100,1)&"%")
A16: TOP GAPS (Manual Entry)
A17: Priority | B17: Domain | C17: Requirement | D17: Owner | E17: Due Date | F17: Status
A29: COMPLIANCE TREND (Manual Entry)
A30: Assessment Date | B30: Overall % | C30: Compliant | D30: Gaps | E30: Assessor | F30: Notes

Sheet AISIA Process
A1: AISIA Process — Compliance Checklist
A2: ISO/IEC 42001:2023 — Controls A.5.2-5: AI System Impact Assessment
A3: Req # | B3: Section | C3: Requirement | D3: Status | E3: Evidence | F3: Owner | G3: Due Date | H3: Notes
A4: A.5.2-01 | B4: Process Establishment | C4: The organisation shall establish, document, and implement a process for AI System Impact Assessment (AISIA) that is applied to every in-scope AI system. The process shall follow ISO/IEC 42005:2025 methodology.
A5: A.5.2-02 | B5: Deployment Gate | C5: No AI system shall be deployed in an operational context without a completed and approved AISIA. The AI Governance Officer shall approve the AISIA before deployment authorisation is issued.
A6: A.5.2-03 | B6: Material Change Trigger | C6: A new or updated AISIA shall be completed before any material change to an AI system is deployed — including new use cases, new affected populations, changed deployment context, and significant model updates.
A7: A.5.2-04 | B7: Review Schedule | C7: AISIAs shall be reviewed on a schedule proportionate to impact classification: High-impact every 6 months; Medium-impact annually; Low-impact every 3 years. Overdue AISIAs shall be flagged and escalated.
A8: A.5.2-05 | B8: Post-Incident Review | C8: Following any AI incident where the system's impact on individuals was material, the AISIA for the affected system shall be reviewed and updated if the incident reveals new or underestimated harms.
A9: A.5.2-06 | B9: AISIA Register | C9: The AI Governance Officer shall maintain an AISIA Register listing all in-scope AI systems with their current AISIA version, classification, approval date, and next review date.
A10: A.5.2-07 | B10: FRIA and DPIA Alignment | C10: Where EU AI Act Fundamental Rights Impact Assessments (FRIA) or GDPR Data Protection Impact Assessments (DPIA) are required, the AISIA shall serve as the analytical foundation, with cross-references documented.

Sheet AISIA Documentation
A1: AISIA Documentation — Compliance Checklist
A2: ISO/IEC 42001:2023 — Controls A.5.2-5: AI System Impact Assessment
A3: Req # | B3: Section | C3: Requirement | D3: Status | E3: Evidence | F3: Owner | G3: Due Date | H3: Notes
A4: A.5.3-01 | B4: Structured Record | C4: Each completed AISIA shall be documented as a structured record following the template in AI-IMP-A.5.2-5-TG (built against ISO/IEC 42005:2025 Annex E). Free-form assessments are not acceptable.
A5: A.5.3-02 | B5: Required Content | C5: Every AISIA record shall include: AI system identification; intended and foreseeable uses; technical information; deployment environment; interested party identification; benefits and harms analysis; AI system failures; reasonably foreseeable misuse; impact classification; and approval record.
A6: A.5.3-03 | B6: Approval Record | C6: Every AISIA shall include a signed approval record by the AI Governance Officer with approval date. Deployment authorisation shall not be issued without a signed approval record.
A7: A.5.3-04 | B7: Retention | C7: AISIA records shall be retained for the duration of the AI system's operational life plus 5 years after decommissioning, and shall be available to auditors and regulatory authorities on request.
A8: A.5.3-05 | B8: Version Control | C8: AISIAs shall be version-controlled. Updated AISIAs shall preserve prior versions. The current approved version shall be clearly identified in the AISIA Register.

Sheet Individual Impact Assessment
A1: Individual Impact Assessment — Compliance Checklist
A2: ISO/IEC 42001:2023 — Controls A.5.2-5: AI System Impact Assessment
A3: Req # | B3: Section | C3: Requirement | D3: Status | E3: Evidence | F3: Owner | G3: Due Date | H3: Notes
A4: A.5.4-01 | B4: Individual Impact Scope | C4: For each AI system, the organisation shall identify all categories of individuals whose interests could be affected by AI outputs — including direct users, affected individuals who are not users, and vulnerable groups.
A5: A.5.4-02 | B5: Harm Assessment Dimensions | C5: The individual impact assessment shall evaluate reasonably foreseeable harms and benefits across all required dimensions: Accountability, Transparency, Fairness and discrimination, Privacy, Reliability, Safety, Explainability, and Environmental impact.
A6: A.5.4-03 | B6: Harm Severity Rating | C6: For each identified harm, the organisation shall document severity (Negligible / Minor / Moderate / Serious / Critical), breadth (individual / group / population), and reversibility.
A7: A.5.4-04 | B7: Vulnerable Groups | C7: The individual impact assessment shall specifically identify and assess impacts on vulnerable groups — including children, elderly individuals, persons with disabilities, minority groups, and parties in power-asymmetric relationships.
A8: A.5.4-05 | B8: Human Oversight Assessment | C8: The individual impact assessment shall assess the adequacy of human oversight mechanisms — whether affected individuals have meaningful recourse, and whether human reviewers can exercise independent judgment.
A9: A.5.4-06 | B9: Impact Classification | C9: Based on the individual impact assessment, the AI system shall be assigned an overall impact classification: Low / Medium / High. The classification shall determine control requirements and review frequency.

Sheet Societal Impact Assessment
A1: Societal Impact Assessment — Compliance Checklist
A2: ISO/IEC 42001:2023 — Controls A.5.2-5: AI System Impact Assessment
A3: Req # | B3: Section | C3: Requirement | D3: Status | E3: Evidence | F3: Owner | G3: Due Date | H3: Notes
A4: A.5.5-01 | B4: Societal Impact Scope | C4: For each AI system, the organisation shall assess potential societal impacts — the macro-level effects of AI system deployment on communities, sectors, and society at large — as a distinct assessment from individual impact.
A5: A.5.5-02 | B5: Societal Dimensions | C5: The societal impact assessment shall address: systemic bias at scale, labour and employment impacts, misinformation risk, democratic and civic process impacts, concentration of power, and dependency/resilience risks.
A6: A.5.5-03 | B6: Environmental Impact | C6: The societal impact assessment shall include an assessment of the AI system's environmental impact — energy consumption, carbon footprint, and whether these are proportionate to the value delivered.
A7: A.5.5-04 | B7: Scale Consideration | C7: The societal impact assessment shall explicitly address how individual-level effects aggregate at scale — an AI system with low individual impact may have significant societal impact when deployed broadly.
A8: A.5.5-05 | B8: Mitigation Measures | C8: Where societal impacts are identified, the organisation shall document what measures it can take to mitigate its contribution to those impacts, even where the impact is beyond its direct control.
