Workbook

Sheet Executive Summary
A1: ISMS-OP-CHK-A.5.34 — Privacy and Protection of PII Compliance Checklist
A3: DOCUMENT INFORMATION
A4: Document ID | B4: ISMS-OP-CHK-A.5.34
A5: Source Policy | B5: ISMS-OP-POL-A.5.34
A6: ISO Controls | B6: Privacy and Protection of PII
A7: Generated | B7: 30.09.2026
A8: Prepared By
A9: Organisation
A10: Review Cycle | B10: Annual
A12: OVERALL COMPLIANCE STATUS
A13: Overall Compliance | B13: ='Dashboard'!G18
A14: Status | B14: =IF(Dashboard!H18>0,"INCOMPLETE",IF(Dashboard!G18="N/A","NOT ASSESSED",IF(ISNUMBER(VALUE(SUBSTITUTE(Dashboard!G18,"%",""))),IF(VALUE(SUBSTITUTE(Dashboard!G18,"%",""))>=90,"GREEN",IF(VALUE(SUBSTITUTE(Dashboard!G18,"%",""))>=70,"AMBER","RED")),"NOT ASSESSED")))
A16: KEY METRICS
A17: Total Requirements | B17: ='Dashboard'!B18
A18: Compliant | B18: ='Dashboard'!C18
A19: Partial | B19: ='Dashboard'!D18
A20: Non-Compliant | B20: ='Dashboard'!E18
A21: Not Applicable | B21: ='Dashboard'!F18
A22: Unanswered | B22: ='Dashboard'!H18
A23: Owner Coverage | B23: =IF(Dashboard!B18=0,"N/A",ROUND((COUNTA('Data Prot Policy Statement'!F4:F4)+COUNTA('Legal Basis for Processing'!F4:F5)+COUNTA('Lawfulness and Good Faith'!F4:F11)+COUNTA('Accuracy'!F4:F4)+COUNTA('Storage Period Limitation'!F4:F4)+COUNTA('Security of Processing'!F4:F14)+COUNTA('Cross-Border Data Transfers'!F4:F8)+COUNTA('The Right of Access'!F4:F5)+COUNTA('The Right to Rectification'!F4:F4)+COUNTA('Agreement of Retention Periods'!F4:F4)+COUNTA('Expiry of Retention Period'!F4:F4)+COUNTA('Suspension Record Disposal'!F4:F4)+COUNTA('Children's Data'!F4:F7)+COUNTA('Optional Data Prot Advisor'!F4:F4))/Dashboard!B18*100,0)&"%")
A25: DOMAIN STATUS SUMMARY
A26: Domain | B26: Compliance % | C26: Compliant | D26: Gaps | E26: Status
A27: Data Prot Policy Statement | B27: ='Dashboard'!G4 | C27: ='Dashboard'!C4 | D27: ='Dashboard'!E4 | E27: =IF(Dashboard!H4>0,"INCOMPLETE",IF(Dashboard!G4="N/A","--",IF(ISNUMBER(VALUE(SUBSTITUTE(Dashboard!G4,"%",""))),IF(VALUE(SUBSTITUTE(Dashboard!G4,"%",""))>=90,"PASS",IF(VALUE(SUBSTITUTE(Dashboard!G4,"%",""))>=70,"REVIEW","FAIL")),"--")))
A28: Legal Basis for Processing | B28: ='Dashboard'!G5 | C28: ='Dashboard'!C5 | D28: ='Dashboard'!E5 | E28: =IF(Dashboard!H5>0,"INCOMPLETE",IF(Dashboard!G5="N/A","--",IF(ISNUMBER(VALUE(SUBSTITUTE(Dashboard!G5,"%",""))),IF(VALUE(SUBSTITUTE(Dashboard!G5,"%",""))>=90,"PASS",IF(VALUE(SUBSTITUTE(Dashboard!G5,"%",""))>=70,"REVIEW","FAIL")),"--")))
A29: Lawfulness and Good Faith | B29: ='Dashboard'!G6 | C29: ='Dashboard'!C6 | D29: ='Dashboard'!E6 | E29: =IF(Dashboard!H6>0,"INCOMPLETE",IF(Dashboard!G6="N/A","--",IF(ISNUMBER(VALUE(SUBSTITUTE(Dashboard!G6,"%",""))),IF(VALUE(SUBSTITUTE(Dashboard!G6,"%",""))>=90,"PASS",IF(VALUE(SUBSTITUTE(Dashboard!G6,"%",""))>=70,"REVIEW","FAIL")),"--")))
A30: Accuracy | B30: ='Dashboard'!G7 | C30: ='Dashboard'!C7 | D30: ='Dashboard'!E7 | E30: =IF(Dashboard!H7>0,"INCOMPLETE",IF(Dashboard!G7="N/A","--",IF(ISNUMBER(VALUE(SUBSTITUTE(Dashboard!G7,"%",""))),IF(VALUE(SUBSTITUTE(Dashboard!G7,"%",""))>=90,"PASS",IF(VALUE(SUBSTITUTE(Dashboard!G7,"%",""))>=70,"REVIEW","FAIL")),"--")))
A31: Storage Period Limitation | B31: ='Dashboard'!G8 | C31: ='Dashboard'!C8 | D31: ='Dashboard'!E8 | E31: =IF(Dashboard!H8>0,"INCOMPLETE",IF(Dashboard!G8="N/A","--",IF(ISNUMBER(VALUE(SUBSTITUTE(Dashboard!G8,"%",""))),IF(VALUE(SUBSTITUTE(Dashboard!G8,"%",""))>=90,"PASS",IF(VALUE(SUBSTITUTE(Dashboard!G8,"%",""))>=70,"REVIEW","FAIL")),"--")))
A32: Security of Processing | B32: ='Dashboard'!G9 | C32: ='Dashboard'!C9 | D32: ='Dashboard'!E9 | E32: =IF(Dashboard!H9>0,"INCOMPLETE",IF(Dashboard!G9="N/A","--",IF(ISNUMBER(VALUE(SUBSTITUTE(Dashboard!G9,"%",""))),IF(VALUE(SUBSTITUTE(Dashboard!G9,"%",""))>=90,"PASS",IF(VALUE(SUBSTITUTE(Dashboard!G9,"%",""))>=70,"REVIEW","FAIL")),"--")))
A33: Cross-Border Data Transfers | B33: ='Dashboard'!G10 | C33: ='Dashboard'!C10 | D33: ='Dashboard'!E10 | E33: =IF(Dashboard!H10>0,"INCOMPLETE",IF(Dashboard!G10="N/A","--",IF(ISNUMBER(VALUE(SUBSTITUTE(Dashboard!G10,"%",""))),IF(VALUE(SUBSTITUTE(Dashboard!G10,"%",""))>=90,"PASS",IF(VALUE(SUBSTITUTE(Dashboard!G10,"%",""))>=70,"REVIEW","FAIL")),"--")))
A34: The Right of Access | B34: ='Dashboard'!G11 | C34: ='Dashboard'!C11 | D34: ='Dashboard'!E11 | E34: =IF(Dashboard!H11>0,"INCOMPLETE",IF(Dashboard!G11="N/A","--",IF(ISNUMBER(VALUE(SUBSTITUTE(Dashboard!G11,"%",""))),IF(VALUE(SUBSTITUTE(Dashboard!G11,"%",""))>=90,"PASS",IF(VALUE(SUBSTITUTE(Dashboard!G11,"%",""))>=70,"REVIEW","FAIL")),"--")))
A35: The Right to Rectification | B35: ='Dashboard'!G12 | C35: ='Dashboard'!C12 | D35: ='Dashboard'!E12 | E35: =IF(Dashboard!H12>0,"INCOMPLETE",IF(Dashboard!G12="N/A","--",IF(ISNUMBER(VALUE(SUBSTITUTE(Dashboard!G12,"%",""))),IF(VALUE(SUBSTITUTE(Dashboard!G12,"%",""))>=90,"PASS",IF(VALUE(SUBSTITUTE(Dashboard!G12,"%",""))>=70,"REVIEW","FAIL")),"--")))
A36: Agreement of Retention Periods | B36: ='Dashboard'!G13 | C36: ='Dashboard'!C13 | D36: ='Dashboard'!E13 | E36: =IF(Dashboard!H13>0,"INCOMPLETE",IF(Dashboard!G13="N/A","--",IF(ISNUMBER(VALUE(SUBSTITUTE(Dashboard!G13,"%",""))),IF(VALUE(SUBSTITUTE(Dashboard!G13,"%",""))>=90,"PASS",IF(VALUE(SUBSTITUTE(Dashboard!G13,"%",""))>=70,"REVIEW","FAIL")),"--")))
A37: Expiry of Retention Period | B37: ='Dashboard'!G14 | C37: ='Dashboard'!C14 | D37: ='Dashboard'!E14 | E37: =IF(Dashboard!H14>0,"INCOMPLETE",IF(Dashboard!G14="N/A","--",IF(ISNUMBER(VALUE(SUBSTITUTE(Dashboard!G14,"%",""))),IF(VALUE(SUBSTITUTE(Dashboard!G14,"%",""))>=90,"PASS",IF(VALUE(SUBSTITUTE(Dashboard!G14,"%",""))>=70,"REVIEW","FAIL")),"--")))
A38: Suspension Record Disposal | B38: ='Dashboard'!G15 | C38: ='Dashboard'!C15 | D38: ='Dashboard'!E15 | E38: =IF(Dashboard!H15>0,"INCOMPLETE",IF(Dashboard!G15="N/A","--",IF(ISNUMBER(VALUE(SUBSTITUTE(Dashboard!G15,"%",""))),IF(VALUE(SUBSTITUTE(Dashboard!G15,"%",""))>=90,"PASS",IF(VALUE(SUBSTITUTE(Dashboard!G15,"%",""))>=70,"REVIEW","FAIL")),"--")))
... A40: Optional Data Prot Advisor | B40: ='Dashboard'!G17 | C40: ='Dashboard'!C17 | D40: ='Dashboard'!E17 | E40: =IF(Dashboard!H17>0,"INCOMPLETE",IF(Dashboard!G17="N/A","--",IF(ISNUMBER(VALUE(SUBSTITUTE(Dashboard!G17,"%",""))),IF(VALUE(SUBSTITUTE(Dashboard!G17,"%",""))>=90,"PASS",IF(VALUE(SUBSTITUTE(Dashboard!G17,"%",""))>=70,"REVIEW","FAIL")),"--")))
A42: CRITICAL ISSUES
A43: # | B43: Issue Description | C43: Domain | D43: Owner | E43: Due Date
A44: 1
A45: 2
A46: 3
...

Sheet Dashboard
A1: Privacy and Protection of PII — Compliance Dashboard
A3: Domain | B3: Total Reqs | C3: Compliant | D3: Partial | E3: Non-Compliant | F3: N/A | G3: Compliance % | H3: Unassessed
A4: Data Prot Policy Statement | B4: =COUNTA('Data Prot Policy Statement'!A4:A4) | C4: =COUNTIF('Data Prot Policy Statement'!D4:D4,"Compliant") | D4: =COUNTIF('Data Prot Policy Statement'!D4:D4,"Partial") | E4: =COUNTIF('Data Prot Policy Statement'!D4:D4,"Non-Compliant") | F4: =COUNTIF('Data Prot Policy Statement'!D4:D4,"N/A") | G4: =IF((B4-F4)=0,"N/A",ROUND(C4/(B4-F4)*100,1)&"%") | H4: =B4-(C4+D4+E4+F4)
A5: Legal Basis for Processing | B5: =COUNTA('Legal Basis for Processing'!A4:A5) | C5: =COUNTIF('Legal Basis for Processing'!D4:D5,"Compliant") | D5: =COUNTIF('Legal Basis for Processing'!D4:D5,"Partial") | E5: =COUNTIF('Legal Basis for Processing'!D4:D5,"Non-Compliant") | F5: =COUNTIF('Legal Basis for Processing'!D4:D5,"N/A") | G5: =IF((B5-F5)=0,"N/A",ROUND(C5/(B5-F5)*100,1)&"%") | H5: =B5-(C5+D5+E5+F5)
A6: Lawfulness and Good Faith | B6: =COUNTA('Lawfulness and Good Faith'!A4:A11) | C6: =COUNTIF('Lawfulness and Good Faith'!D4:D11,"Compliant") | D6: =COUNTIF('Lawfulness and Good Faith'!D4:D11,"Partial") | E6: =COUNTIF('Lawfulness and Good Faith'!D4:D11,"Non-Compliant") | F6: =COUNTIF('Lawfulness and Good Faith'!D4:D11,"N/A") | G6: =IF((B6-F6)=0,"N/A",ROUND(C6/(B6-F6)*100,1)&"%") | H6: =B6-(C6+D6+E6+F6)
A7: Accuracy | B7: =COUNTA('Accuracy'!A4:A4) | C7: =COUNTIF('Accuracy'!D4:D4,"Compliant") | D7: =COUNTIF('Accuracy'!D4:D4,"Partial") | E7: =COUNTIF('Accuracy'!D4:D4,"Non-Compliant") | F7: =COUNTIF('Accuracy'!D4:D4,"N/A") | G7: =IF((B7-F7)=0,"N/A",ROUND(C7/(B7-F7)*100,1)&"%") | H7: =B7-(C7+D7+E7+F7)
A8: Storage Period Limitation | B8: =COUNTA('Storage Period Limitation'!A4:A4) | C8: =COUNTIF('Storage Period Limitation'!D4:D4,"Compliant") | D8: =COUNTIF('Storage Period Limitation'!D4:D4,"Partial") | E8: =COUNTIF('Storage Period Limitation'!D4:D4,"Non-Compliant") | F8: =COUNTIF('Storage Period Limitation'!D4:D4,"N/A") | G8: =IF((B8-F8)=0,"N/A",ROUND(C8/(B8-F8)*100,1)&"%") | H8: =B8-(C8+D8+E8+F8)
A9: Security of Processing | B9: =COUNTA('Security of Processing'!A4:A14) | C9: =COUNTIF('Security of Processing'!D4:D14,"Compliant") | D9: =COUNTIF('Security of Processing'!D4:D14,"Partial") | E9: =COUNTIF('Security of Processing'!D4:D14,"Non-Compliant") | F9: =COUNTIF('Security of Processing'!D4:D14,"N/A") | G9: =IF((B9-F9)=0,"N/A",ROUND(C9/(B9-F9)*100,1)&"%") | H9: =B9-(C9+D9+E9+F9)
A10: Cross-Border Data Transfers | B10: =COUNTA('Cross-Border Data Transfers'!A4:A8) | C10: =COUNTIF('Cross-Border Data Transfers'!D4:D8,"Compliant") | D10: =COUNTIF('Cross-Border Data Transfers'!D4:D8,"Partial") | E10: =COUNTIF('Cross-Border Data Transfers'!D4:D8,"Non-Compliant") | F10: =COUNTIF('Cross-Border Data Transfers'!D4:D8,"N/A") | G10: =IF((B10-F10)=0,"N/A",ROUND(C10/(B10-F10)*100,1)&"%") | H10: =B10-(C10+D10+E10+F10)
A11: The Right of Access | B11: =COUNTA('The Right of Access'!A4:A5) | C11: =COUNTIF('The Right of Access'!D4:D5,"Compliant") | D11: =COUNTIF('The Right of Access'!D4:D5,"Partial") | E11: =COUNTIF('The Right of Access'!D4:D5,"Non-Compliant") | F11: =COUNTIF('The Right of Access'!D4:D5,"N/A") | G11: =IF((B11-F11)=0,"N/A",ROUND(C11/(B11-F11)*100,1)&"%") | H11: =B11-(C11+D11+E11+F11)
A12: The Right to Rectification | B12: =COUNTA('The Right to Rectification'!A4:A4) | C12: =COUNTIF('The Right to Rectification'!D4:D4,"Compliant") | D12: =COUNTIF('The Right to Rectification'!D4:D4,"Partial") | E12: =COUNTIF('The Right to Rectification'!D4:D4,"Non-Compliant") | F12: =COUNTIF('The Right to Rectification'!D4:D4,"N/A") | G12: =IF((B12-F12)=0,"N/A",ROUND(C12/(B12-F12)*100,1)&"%") | H12: =B12-(C12+D12+E12+F12)
A13: Agreement of Retention Periods | B13: =COUNTA('Agreement of Retention Periods'!A4:A4) | C13: =COUNTIF('Agreement of Retention Periods'!D4:D4,"Compliant") | D13: =COUNTIF('Agreement of Retention Periods'!D4:D4,"Partial") | E13: =COUNTIF('Agreement of Retention Periods'!D4:D4,"Non-Compliant") | F13: =COUNTIF('Agreement of Retention Periods'!D4:D4,"N/A") | G13: =IF((B13-F13)=0,"N/A",ROUND(C13/(B13-F13)*100,1)&"%") | H13: =B13-(C13+D13+E13+F13)
A14: Expiry of Retention Period | B14: =COUNTA('Expiry of Retention Period'!A4:A4) | C14: =COUNTIF('Expiry of Retention Period'!D4:D4,"Compliant") | D14: =COUNTIF('Expiry of Retention Period'!D4:D4,"Partial") | E14: =COUNTIF('Expiry of Retention Period'!D4:D4,"Non-Compliant") | F14: =COUNTIF('Expiry of Retention Period'!D4:D4,"N/A") | G14: =IF((B14-F14)=0,"N/A",ROUND(C14/(B14-F14)*100,1)&"%") | H14: =B14-(C14+D14+E14+F14)
A15: Suspension Record Disposal | B15: =COUNTA('Suspension Record Disposal'!A4:A4) | C15: =COUNTIF('Suspension Record Disposal'!D4:D4,"Compliant") | D15: =COUNTIF('Suspension Record Disposal'!D4:D4,"Partial") | E15: =COUNTIF('Suspension Record Disposal'!D4:D4,"Non-Compliant") | F15: =COUNTIF('Suspension Record Disposal'!D4:D4,"N/A") | G15: =IF((B15-F15)=0,"N/A",ROUND(C15/(B15-F15)*100,1)&"%") | H15: =B15-(C15+D15+E15+F15)
A16: Children's Data | B16: =COUNTA('Children's Data'!A4:A7) | C16: =COUNTIF('Children's Data'!D4:D7,"Compliant") | D16: =COUNTIF('Children's Data'!D4:D7,"Partial") | E16: =COUNTIF('Children's Data'!D4:D7,"Non-Compliant") | F16: =COUNTIF('Children's Data'!D4:D7,"N/A") | G16: =IF((B16-F16)=0,"N/A",ROUND(C16/(B16-F16)*100,1)&"%") | H16: =B16-(C16+D16+E16+F16)
A17: Optional Data Prot Advisor | B17: =COUNTA('Optional Data Prot Advisor'!A4:A4) | C17: =COUNTIF('Optional Data Prot Advisor'!D4:D4,"Compliant") | D17: =COUNTIF('Optional Data Prot Advisor'!D4:D4,"Partial") | E17: =COUNTIF('Optional Data Prot Advisor'!D4:D4,"Non-Compliant") | F17: =COUNTIF('Optional Data Prot Advisor'!D4:D4,"N/A") | G17: =IF((B17-F17)=0,"N/A",ROUND(C17/(B17-F17)*100,1)&"%") | H17: =B17-(C17+D17+E17+F17)
A18: TOTAL | B18: =SUM(B4:B17) | C18: =SUM(C4:C17) | D18: =SUM(D4:D17) | E18: =SUM(E4:E17) | F18: =SUM(F4:F17) | G18: =IF((B18-F18)=0,"N/A",ROUND(C18/(B18-F18)*100,1)&"%") | H18: =SUM(H4:H17)
A20: COMPLIANCE BY STATUS
A21: Compliant | B21: =C18 | C21: =IF(B18=0,"",ROUND(B21/B18*100,1)&"%")
A22: Partial | B22: =D18 | C22: =IF(B18=0,"",ROUND(B22/B18*100,1)&"%")
A23: Non-Compliant | B23: =E18 | C23: =IF(B18=0,"",ROUND(B23/B18*100,1)&"%")
A24: N/A | B24: =F18 | C24: =IF(B18=0,"",ROUND(B24/B18*100,1)&"%")
A26: TOP GAPS (Manual Entry)
A27: Priority | B27: Domain | C27: Requirement | D27: Owner | E27: Due Date | F27: Status
A39: COMPLIANCE TREND (Manual Entry)
A40: Assessment Date | B40: Overall % | C40: Compliant | D40: Gaps | E40: Assessor | F40: Notes

Sheet Data Prot Policy Statement
A1: Data Prot Policy Statement — Compliance Checklist
A2: ISO/IEC 27001:2022 — Control A.5.34: Privacy and Protection of PII
A3: Req # | B3: Section | C3: Requirement | D3: Status | E3: Evidence | F3: Owner | G3: Due Date | H3: Notes
A4: A.5.34-01 | B4: Determine Its Role As Data Controller | C4: The organisation shall determine its role as Data Controller, Data Processor, or Joint Controller for each processing activity based on the context of its processing activities under the Swiss Federal Act on Data Protection (nFADP/revDSG). This determination shall be documented in the Record of Processing Activities (ROPA) and reflected in contractual arrangements with third parties. This policy confirms our commitment to protect the privacy of the personal information of our customers, clients, employees, and other interested parties. We have engaged in a programme of Information Security Management aligned to the international standard ISO 27001 to ensure that the processing of personal information is conducted using best practice processes.

Sheet Legal Basis for Processing
A1: Legal Basis for Processing — Compliance Checklist
A2: ISO/IEC 27001:2022 — Control A.5.34: Privacy and Protection of PII
A3: Req # | B3: Section | C3: Requirement | D3: Status | E3: Evidence | F3: Owner | G3: Due Date | H3: Notes
A4: A.5.34-02 | B4: A Valid Legal Basis Under Gdpr | C4: Where the organisation processes data of EU/EEA individuals, a valid legal basis under GDPR Article 6 shall be identified and documented for each processing activity in the Record of Processing Activities.
A5: A.5.34-03 | B5: Article 6 Of The Nfadp Requires | C5: Article 6 of the nFADP requires that personal data shall be:.

Sheet Lawfulness and Good Faith
A1: Lawfulness and Good Faith — Compliance Checklist
A2: ISO/IEC 27001:2022 — Control A.5.34: Privacy and Protection of PII
A3: Req # | B3: Section | C3: Requirement | D3: Status | E3: Evidence | F3: Owner | G3: Due Date | H3: Notes
A4: A.5.34-04 | B4: Inform Data Subjects At The Time | C4: The organisation shall inform data subjects at the time of data collection (Art. 19 nFADP). Privacy notices shall be provided covering:.
A5: A.5.34-05 | B5: Privacy Notices | C5: Privacy notices shall be concise, transparent, and written in plain language. They shall be made available at the point of data collection (e.g., on websites, in application forms, in employment contracts, at reception for visitors).
A6: A.5.34-06 | B6: Be Freely Given, Specific, Informed, And | C6: Consent shall be freely given, specific, informed, and unambiguous (Art. 6(6)–(7) nFADP).
A7: A.5.34-07 | B7: Consent For Sensitive Personal Data Or | C7: Consent for sensitive personal data or high-risk profiling shall be explicit (Art. 6(7) nFADP).
A8: A.5.34-08 | B8: Be Recorded With The Date, Method | C8: Consent shall be recorded with the date, method, and scope of consent granted.
A9: A.5.34-09 | B9: Withdrawal Of Consent | C9: Withdrawal of consent shall be as easy as giving consent, and the process shall be communicated to data subjects.
A10: A.5.34-10 | B10: Be Capable Of Recording And Actioning | C10: Systems shall be capable of recording and actioning consent withdrawal without undue delay.
A11: A.5.34-11 | B11: Consent Records | C11: Consent records shall be retained for the duration of processing plus the applicable limitation period.

Sheet Accuracy
A1: Accuracy — Compliance Checklist
A2: ISO/IEC 27001:2022 — Control A.5.34: Privacy and Protection of PII
A3: Req # | B3: Section | C3: Requirement | D3: Status | E3: Evidence | F3: Owner | G3: Due Date | H3: Notes
A4: A.5.34-12 | B4: Accurate And, Where Necessary, Kept Up | C4: Accurate and, where necessary, kept up to date; every reasonable step shall be taken to ensure that personal data that are inaccurate, having regard to the purposes for which they are processed, are erased or rectified without delay.

Sheet Storage Period Limitation
A1: Storage Period Limitation — Compliance Checklist
A2: ISO/IEC 27001:2022 — Control A.5.34: Privacy and Protection of PII
A3: Req # | B3: Section | C3: Requirement | D3: Status | E3: Evidence | F3: Owner | G3: Due Date | H3: Notes
A4: A.5.34-13 | B4: The Organisation Has Implemented A Data | C4: The organisation has implemented a data retention policy and data retention schedule in line with legal, regulatory, and business needs. Personal data shall be destroyed or anonymised once it is no longer needed for the stated processing purpose (Art. 6(4) nFADP).

Sheet Security of Processing
A1: Security of Processing — Compliance Checklist
A2: ISO/IEC 27001:2022 — Control A.5.34: Privacy and Protection of PII
A3: Req # | B3: Section | C3: Requirement | D3: Status | E3: Evidence | F3: Owner | G3: Due Date | H3: Notes
A4: A.5.34-14 | B4: Maintain A Record Of Processing | C4: The organisation shall maintain a Record of Processing Activities documenting all processing operations (DSV Art. 4–5).
A5: A.5.34-15 | B5: Sme Exemption (Dsv Art. 4):* | C5: SME exemption (DSV Art. 4):* Organisations with fewer than 250 employees are exempted from maintaining a ROPA unless they process sensitive personal data on a large scale or conduct high-risk profiling. The organisation shall document its assessment of whether the exemption applies.
A6: A.5.34-16 | B6: Include: Purposes Of Processing, | C6: Where a ROPA is maintained, it shall include: purposes of processing, categories of data subjects and personal data, recipients, cross-border transfers, retention periods, and a description of technical and organisational security measures.
A7: A.5.34-17 | B7: The Ropa | C7: The ROPA shall be reviewed and updated annually, or whenever new processing activities commence, and made available to the FDPIC upon request.
A8: A.5.34-18 | B8: Conduct A Dpia Before Beginning | C8: The organisation shall conduct a DPIA before beginning processing activities that are likely to result in a high risk to the rights of data subjects (Art. 22 nFADP, Art. 35 GDPR where applicable).
A9: A.5.34-19 | B9: Document: A Description Of The | C9: Each DPIA shall document: a description of the processing and its purposes, an assessment of necessity and proportionality, an assessment of risks to data subjects, and measures to address those risks.
A10: A.5.34-20 | B10: They May Approve The Dpia In | C10: Where a qualified Data Protection Advisor has been appointed, they may approve the DPIA in place of consulting the FDPIC (Art. 23(4) nFADP). Where residual risk remains high and no Data Protection Advisor is appointed, the FDPIC shall be consulted.
A11: A.5.34-21 | B11: Dpia Documentation | C11: DPIA documentation shall be retained for at least 2 years after processing ends (DSV Art. 14).
A12: A.5.34-22 | B12: Retention Periods | C12: Retention periods shall be agreed by the relevant data owners in line with legal, regulatory, and business requirements:.
A13: A.5.34-23 | B13: The Information | C13: When the retention target is reached, the information shall be reviewed by the relevant data owner to confirm whether the information is to be further retained or destroyed. It shall be destroyed in line with the Information Classification and Handling Policy if there is no further business, statutory, or historical reason to retain it.
A14: A.5.34-24 | B14: Personal Data Is Transferred In Line | C14: Personal data is transferred in line with the Information Transfer Policy. Employees shall ensure the appropriate level of security in line with the policy and organisation processes.

Sheet Cross-Border Data Transfers
A1: Cross-Border Data Transfers — Compliance Checklist
A2: ISO/IEC 27001:2022 — Control A.5.34: Privacy and Protection of PII
A3: Req # | B3: Section | C3: Requirement | D3: Status | E3: Evidence | F3: Owner | G3: Due Date | H3: Notes
A4: A.5.34-25 | B4: Not Transfer Personal Data To Countries | C4: The organisation shall not transfer personal data to countries outside Switzerland unless:.
A5: A.5.34-26 | B5: European Commission Adequacy Decisions | C5: Where the organisation also processes EU/EEA data, European Commission adequacy decisions and GDPR transfer mechanisms (Art. 44–49) shall be applied as appropriate.
A6: A.5.34-27 | B6: Inform Their Line Manager And/Or A | C6: In the event of a breach of the data protection principles, employees shall inform their line manager and/or a member of the Management Review Team and invoke the Incident Management Process.
A7: A.5.34-28 | B7: Be Reported As Follows | C7: Breaches shall be reported as follows:.
A8: A.5.34-29 | B8: Maintain A Breach Register | C8: The organisation shall maintain a breach register documenting the facts, effects, and remedial actions for all breaches.

Sheet The Right of Access
A1: The Right of Access — Compliance Checklist
A2: ISO/IEC 27001:2022 — Control A.5.34: Privacy and Protection of PII
A3: Req # | B3: Section | C3: Requirement | D3: Status | E3: Evidence | F3: Owner | G3: Due Date | H3: Notes
A4: A.5.34-30 | B4: Provide Information On The Purpose, | C4: The organisation shall provide information on the purpose, categories of data, recipients, retention period, and source.
A5: A.5.34-31 | B5: Be Provided In Writing, Free Of | C5: Information shall be provided in writing, free of charge, within 30 days (Art. 25 nFADP). This period may be extended by a further 30 days where necessary due to complexity, with notification to the data subject.

Sheet The Right to Rectification
A1: The Right to Rectification — Compliance Checklist
A2: ISO/IEC 27001:2022 — Control A.5.34: Privacy and Protection of PII
A3: Req # | B3: Section | C3: Requirement | D3: Status | E3: Evidence | F3: Owner | G3: Due Date | H3: Notes
A4: A.5.34-32 | B4: Respond Within 30 Days | C4: The organisation shall respond within 30 days.

Sheet Agreement of Retention Periods
A1: Agreement of Retention Periods — Compliance Checklist
A2: ISO/IEC 27001:2022 — Control A.5.34: Privacy and Protection of PII
A3: Req # | B3: Section | C3: Requirement | D3: Status | E3: Evidence | F3: Owner | G3: Due Date | H3: Notes
A4: A.5.34-33 | B4: The Relevant Owners Of The Documentation | C4: The relevant owners of the documentation as detailed in the asset register are responsible for agreeing the data retention periods in line with legal, regulatory, and business requirements. Data retention periods shall be approved by legal counsel.

Sheet Expiry of Retention Period
A1: Expiry of Retention Period — Compliance Checklist
A2: ISO/IEC 27001:2022 — Control A.5.34: Privacy and Protection of PII
A3: Req # | B3: Section | C3: Requirement | D3: Status | E3: Evidence | F3: Owner | G3: Due Date | H3: Notes
A4: A.5.34-34 | B4: The Information | C4: When the retention target is reached, the information shall be reviewed by the relevant owners to confirm that the information is to be further retained or destroyed. It shall be destroyed in line with the Information Classification and Handling Policy if there is no further business, statutory, or historical reason to retain it.

Sheet Suspension Record Disposal
A1: Suspension Record Disposal — Compliance Checklist
A2: ISO/IEC 27001:2022 — Control A.5.34: Privacy and Protection of PII
A3: Req # | B3: Section | C3: Requirement | D3: Status | E3: Evidence | F3: Owner | G3: Due Date | H3: Notes
A4: A.5.34-35 | B4: Or The Commencement Of Any Litigation | C4: In the event any employee of the organisation reasonably anticipates or becomes aware of a governmental investigation or audit, or the commencement of any litigation, all further disposal of documents shall be suspended until management, with the advice of legal counsel, determines otherwise. Management shall take such steps as are necessary to promptly inform affected staff of any suspension in the disposal or destruction of documents.

Sheet Children's Data
A1: Children's Data — Compliance Checklist
A2: ISO/IEC 27001:2022 — Control A.5.34: Privacy and Protection of PII
A3: Req # | B3: Section | C3: Requirement | D3: Status | E3: Evidence | F3: Owner | G3: Due Date | H3: Notes
A4: A.5.34-36 | B4: Additional Care | C4: Additional care shall be taken to ensure privacy notices are understandable by the child or their legal representative.
A5: A.5.34-37 | B5: Consent For Online Services Directed At | C5: Consent for online services directed at children shall be obtained from the holder of parental authority where the child is under the applicable age threshold.
A6: A.5.34-38 | B6: Be Limited To What Is Strictly | C6: Processing shall be limited to what is strictly necessary and proportionate.
A7: A.5.34-39 | B7: Be Documented. If Children'S Data Is | C7: Where the organisation does not intentionally process children's data, this shall be documented. If children's data is discovered, it shall be assessed for compliance with applicable requirements.

Sheet Optional Data Prot Advisor
A1: Optional Data Prot Advisor — Compliance Checklist
A2: ISO/IEC 27001:2022 — Control A.5.34: Privacy and Protection of PII
A3: Req # | B3: Section | C3: Requirement | D3: Status | E3: Evidence | F3: Owner | G3: Due Date | H3: Notes
A4: A.5.34-40 | B4: They | C4: If a Data Protection Advisor is appointed, they shall:.
