Workbook

Sheet Executive Summary
A1: ISMS-OP-CHK-A.5.24-28 — Incident Management Compliance Checklist
A3: DOCUMENT INFORMATION
A4: Document ID | B4: ISMS-OP-CHK-A.5.24-28
A5: Source Policy | B5: ISMS-OP-POL-A.5.24-28
A6: ISO Controls | B6: ISO/IEC 27001:2022 — Controls A.5.24-28: Incident Management
A7: Generated | B7: 07.02.2026
A8: Prepared By
A9: Organisation
A10: Review Cycle | B10: Annual
A12: OVERALL COMPLIANCE STATUS
A13: Overall Compliance | B13: ='Dashboard'!G10
A14: Status | B14: =IF(Dashboard!G10="N/A","NOT ASSESSED",IF(ISNUMBER(VALUE(SUBSTITUTE(Dashboard!G10,"%",""))),IF(VALUE(SUBSTITUTE(Dashboard!G10,"%",""))>=90,"GREEN",IF(VALUE(SUBSTITUTE(Dashboard!G10,"%",""))>=70,"AMBER","RED")),"NOT ASSESSED"))
A16: KEY METRICS
A17: Total Requirements | B17: ='Dashboard'!B10
A18: Compliant | B18: ='Dashboard'!C10
A19: Partial | B19: ='Dashboard'!D10
A20: Non-Compliant | B20: ='Dashboard'!E10
A21: Not Applicable | B21: ='Dashboard'!F10
A22: Owner Coverage | B22: =IF(Dashboard!B10=0,"N/A",ROUND((COUNTA('Reporting & Triage'!F4:F10)+COUNTA('Classification & Escalation'!F4:F9)+COUNTA('Incident Response'!F4:F11)+COUNTA('Data Breach Notification'!F4:F11)+COUNTA('Evidence Collection'!F4:F10)+COUNTA('Lessons Learned & Testing'!F4:F10))/Dashboard!B10*100,0)&"%")
A24: DOMAIN STATUS SUMMARY
A25: Domain | B25: Compliance % | C25: Compliant | D25: Gaps | E25: Status
A26: Reporting & Triage | B26: ='Dashboard'!G4 | C26: ='Dashboard'!C4 | D26: ='Dashboard'!E4 | E26: =IF(Dashboard!G4="N/A","--",IF(ISNUMBER(VALUE(SUBSTITUTE(Dashboard!G4,"%",""))),IF(VALUE(SUBSTITUTE(Dashboard!G4,"%",""))>=90,"PASS",IF(VALUE(SUBSTITUTE(Dashboard!G4,"%",""))>=70,"REVIEW","FAIL")),"--"))
A27: Classification & Escalation | B27: ='Dashboard'!G5 | C27: ='Dashboard'!C5 | D27: ='Dashboard'!E5 | E27: =IF(Dashboard!G5="N/A","--",IF(ISNUMBER(VALUE(SUBSTITUTE(Dashboard!G5,"%",""))),IF(VALUE(SUBSTITUTE(Dashboard!G5,"%",""))>=90,"PASS",IF(VALUE(SUBSTITUTE(Dashboard!G5,"%",""))>=70,"REVIEW","FAIL")),"--"))
A28: Incident Response | B28: ='Dashboard'!G6 | C28: ='Dashboard'!C6 | D28: ='Dashboard'!E6 | E28: =IF(Dashboard!G6="N/A","--",IF(ISNUMBER(VALUE(SUBSTITUTE(Dashboard!G6,"%",""))),IF(VALUE(SUBSTITUTE(Dashboard!G6,"%",""))>=90,"PASS",IF(VALUE(SUBSTITUTE(Dashboard!G6,"%",""))>=70,"REVIEW","FAIL")),"--"))
A29: Data Breach Notification | B29: ='Dashboard'!G7 | C29: ='Dashboard'!C7 | D29: ='Dashboard'!E7 | E29: =IF(Dashboard!G7="N/A","--",IF(ISNUMBER(VALUE(SUBSTITUTE(Dashboard!G7,"%",""))),IF(VALUE(SUBSTITUTE(Dashboard!G7,"%",""))>=90,"PASS",IF(VALUE(SUBSTITUTE(Dashboard!G7,"%",""))>=70,"REVIEW","FAIL")),"--"))
A30: Evidence Collection | B30: ='Dashboard'!G8 | C30: ='Dashboard'!C8 | D30: ='Dashboard'!E8 | E30: =IF(Dashboard!G8="N/A","--",IF(ISNUMBER(VALUE(SUBSTITUTE(Dashboard!G8,"%",""))),IF(VALUE(SUBSTITUTE(Dashboard!G8,"%",""))>=90,"PASS",IF(VALUE(SUBSTITUTE(Dashboard!G8,"%",""))>=70,"REVIEW","FAIL")),"--"))
A31: Lessons Learned & Testing | B31: ='Dashboard'!G9 | C31: ='Dashboard'!C9 | D31: ='Dashboard'!E9 | E31: =IF(Dashboard!G9="N/A","--",IF(ISNUMBER(VALUE(SUBSTITUTE(Dashboard!G9,"%",""))),IF(VALUE(SUBSTITUTE(Dashboard!G9,"%",""))>=90,"PASS",IF(VALUE(SUBSTITUTE(Dashboard!G9,"%",""))>=70,"REVIEW","FAIL")),"--"))
A33: CRITICAL ISSUES
A34: # | B34: Issue Description | C34: Domain | D34: Owner | E34: Due Date
A35: 1
A36: 2
A37: 3
A38: 4
A39: 5
A41: MANAGEMENT COMMENTARY
A42: [Enter management commentary on incident management readiness and response capability]
A46: APPROVAL
A47: Assessed By
A48: Name:
A49: Date:
...

Sheet Dashboard
A1: Incident Management — Compliance Dashboard
A3: Domain | B3: Total Reqs | C3: Compliant | D3: Partial | E3: Non-Compliant | F3: N/A | G3: Compliance %
A4: Reporting & Triage | B4: =COUNTA('Reporting & Triage'!D4:D10) | C4: =COUNTIF('Reporting & Triage'!D4:D10,"Compliant") | D4: =COUNTIF('Reporting & Triage'!D4:D10,"Partial") | E4: =COUNTIF('Reporting & Triage'!D4:D10,"Non-Compliant") | F4: =COUNTIF('Reporting & Triage'!D4:D10,"N/A") | G4: =IF((B4-F4)=0,"N/A",ROUND(C4/(B4-F4)*100,1)&"%")
A5: Classification & Escalation | B5: =COUNTA('Classification & Escalation'!D4:D9) | C5: =COUNTIF('Classification & Escalation'!D4:D9,"Compliant") | D5: =COUNTIF('Classification & Escalation'!D4:D9,"Partial") | E5: =COUNTIF('Classification & Escalation'!D4:D9,"Non-Compliant") | F5: =COUNTIF('Classification & Escalation'!D4:D9,"N/A") | G5: =IF((B5-F5)=0,"N/A",ROUND(C5/(B5-F5)*100,1)&"%")
A6: Incident Response | B6: =COUNTA('Incident Response'!D4:D11) | C6: =COUNTIF('Incident Response'!D4:D11,"Compliant") | D6: =COUNTIF('Incident Response'!D4:D11,"Partial") | E6: =COUNTIF('Incident Response'!D4:D11,"Non-Compliant") | F6: =COUNTIF('Incident Response'!D4:D11,"N/A") | G6: =IF((B6-F6)=0,"N/A",ROUND(C6/(B6-F6)*100,1)&"%")
A7: Data Breach Notification | B7: =COUNTA('Data Breach Notification'!D4:D11) | C7: =COUNTIF('Data Breach Notification'!D4:D11,"Compliant") | D7: =COUNTIF('Data Breach Notification'!D4:D11,"Partial") | E7: =COUNTIF('Data Breach Notification'!D4:D11,"Non-Compliant") | F7: =COUNTIF('Data Breach Notification'!D4:D11,"N/A") | G7: =IF((B7-F7)=0,"N/A",ROUND(C7/(B7-F7)*100,1)&"%")
A8: Evidence Collection | B8: =COUNTA('Evidence Collection'!D4:D10) | C8: =COUNTIF('Evidence Collection'!D4:D10,"Compliant") | D8: =COUNTIF('Evidence Collection'!D4:D10,"Partial") | E8: =COUNTIF('Evidence Collection'!D4:D10,"Non-Compliant") | F8: =COUNTIF('Evidence Collection'!D4:D10,"N/A") | G8: =IF((B8-F8)=0,"N/A",ROUND(C8/(B8-F8)*100,1)&"%")
A9: Lessons Learned & Testing | B9: =COUNTA('Lessons Learned & Testing'!D4:D10) | C9: =COUNTIF('Lessons Learned & Testing'!D4:D10,"Compliant") | D9: =COUNTIF('Lessons Learned & Testing'!D4:D10,"Partial") | E9: =COUNTIF('Lessons Learned & Testing'!D4:D10,"Non-Compliant") | F9: =COUNTIF('Lessons Learned & Testing'!D4:D10,"N/A") | G9: =IF((B9-F9)=0,"N/A",ROUND(C9/(B9-F9)*100,1)&"%")
A10: TOTAL | B10: =SUM(B4:B9) | C10: =SUM(C4:C9) | D10: =SUM(D4:D9) | E10: =SUM(E4:E9) | F10: =SUM(F4:F9) | G10: =IF((B10-F10)=0,"N/A",ROUND(C10/(B10-F10)*100,1)&"%")
A12: COMPLIANCE BY STATUS
A13: Compliant | B13: =C10 | C13: =IF(B10=0,"",ROUND(B13/B10*100,1)&"%")
A14: Partial | B14: =D10 | C14: =IF(B10=0,"",ROUND(B14/B10*100,1)&"%")
A15: Non-Compliant | B15: =E10 | C15: =IF(B10=0,"",ROUND(B15/B10*100,1)&"%")
A16: N/A | B16: =F10 | C16: =IF(B10=0,"",ROUND(B16/B10*100,1)&"%")
A18: TOP GAPS (Manual Entry)
A19: Priority | B19: Domain | C19: Requirement | D19: Owner | E19: Due Date | F19: Status
A31: COMPLIANCE TREND (Manual Entry)
A32: Assessment Date | B32: Overall % | C32: Compliant | D32: Gaps | E32: Assessor | F32: Notes

Sheet Reporting & Triage
A1: Reporting & Triage — Compliance Checklist
A2: ISO/IEC 27001:2022 — Controls A.5.24-28: Incident Management
A3: Req # | B3: Section | C3: Requirement | D3: Status | E3: Evidence | F3: Owner | G3: Due Date | H3: Notes
A4: A.5.24-01 | B4: Incident Reporting | C4: All employees and third-party users shall report security events immediately upon discovery to the information security management team through the designated reporting channels.
A5: A.5.24-02 | B5: Reporting Channels | C5: Reporting channels shall be communicated during onboarding and annual awareness training, and published on the organisation intranet.
A6: A.5.24-03 | B6: No Self-Investigation | C6: Employees shall not attempt to investigate or resolve suspected incidents themselves; preservation of evidence takes priority over curiosity.
A7: A.5.25-01 | B7: Event Assessment | C7: The information security management team shall assess all reported security events to determine whether they constitute a security incident.
A8: A.5.25-02 | B8: Event Logging | C8: Events that do not meet the threshold for an incident shall be logged, and trends shall be monitored.
A9: A.5.25-03 | B9: Incident Register | C9: All reported security events and confirmed incidents shall be recorded in the incident register with the required minimum fields (ID, dates, reporter, description, systems affected, classification, severity, status, assigned to, root cause, actions, lessons, closure).
A10: A.5.25-04 | B10: Personal Data Assessment | C10: Assessment shall consider whether personal data is involved (potential data breach) and the potential business, legal, or regulatory impact.

Sheet Classification & Escalation
A1: Classification & Escalation — Compliance Checklist
A2: ISO/IEC 27001:2022 — Controls A.5.24-28: Incident Management
A3: Req # | B3: Section | C3: Requirement | D3: Status | E3: Evidence | F3: Owner | G3: Due Date | H3: Notes
A4: A.5.25-05 | B4: Severity Classification | C4: Confirmed incidents shall be classified by severity (Critical / High / Medium / Low) to determine response priority, escalation, and communication requirements.
A5: A.5.25-06 | B5: Severity Escalation | C5: Severity may be escalated at any point during the incident lifecycle as new information emerges.
A6: A.5.26-01 | B6: Senior Management Escalation | C6: The incident response team leader shall escalate incidents to senior management when: classified Critical/High, involves personal data, may require external notification, exceeds team capability, or not contained within expected timeframe.
A7: A.5.26-02 | B7: Need-to-Know Communication | C7: Incident information shall be shared on a strict need-to-know basis; communication during an active incident shall be coordinated through the incident response team leader.
A8: A.5.26-03 | B8: Status Updates | C8: Internal status updates shall be provided at regular intervals for Critical and High incidents.
A9: A.5.26-04 | B9: External Communication Approval | C9: External communication (media, customers, partners) shall be approved by senior management and reviewed by legal counsel before release.

Sheet Incident Response
A1: Incident Response — Compliance Checklist
A2: ISO/IEC 27001:2022 — Controls A.5.24-28: Incident Management
A3: Req # | B3: Section | C3: Requirement | D3: Status | E3: Evidence | F3: Owner | G3: Due Date | H3: Notes
A4: A.5.26-05 | B4: Containment | C4: Short-term containment actions (e.g., isolating affected systems, disabling compromised accounts) shall be taken immediately; long-term containment strategies shall be planned where eradication cannot be immediate.
A5: A.5.26-06 | B5: Eradication | C5: The root cause of the incident shall be removed, which may include removing malware, closing vulnerabilities, resetting compromised credentials, or rebuilding affected systems.
A6: A.5.26-07 | B6: Recovery Verification | C6: Recovery shall be verified through testing before returning systems to production; monitoring shall be enhanced during the recovery period to detect recurrence.
A7: A.5.26-08 | B7: Response Documentation | C7: All incident response actions shall be documented with timestamps, actions taken, and personnel involved.
A8: A.5.24-04 | B8: IRT Roles | C8: The following incident response team roles shall be assigned and documented: IRT Leader, Technical Lead, Communications Lead, Legal Advisor, Business Liaison; deputies shall be assigned for each role.
A9: A.5.24-05 | B9: Role Review | C9: Role assignments shall be documented, communicated to all team members, and reviewed annually.
A10: A.5.24-06 | B10: Significant Incident Team | C10: In all instances where a situation may lead to an external investigation or legal proceedings, specialist external resources shall be engaged and a Significant Incident Team Leader shall be appointed from senior management.
A11: A.5.24-07 | B11: Stop and Make Safe | C11: For significant incidents, all work on, access to, modification of, or tampering with affected systems shall stop; the only exceptions are preservation of life, health, and safety, or bare minimum triage actions.

Sheet Data Breach Notification
A1: Data Breach Notification — Compliance Checklist
A2: ISO/IEC 27001:2022 — Controls A.5.24-28: Incident Management
A3: Req # | B3: Section | C3: Requirement | D3: Status | E3: Evidence | F3: Owner | G3: Due Date | H3: Notes
A4: A.5.26-09 | B4: FDPIC Notification | C4: Where a data breach is likely to result in a high risk to data subjects, the FDPIC shall be notified as soon as possible after becoming aware of the breach (nFADP Art. 24).
A5: A.5.26-10 | B5: Data Subject Notification | C5: Where notification is necessary for the protection of data subjects or where the FDPIC requests it, data subjects shall be notified as soon as possible.
A6: A.5.26-11 | B6: Processor Notification | C6: Where the organisation acts as processor, the controller shall be notified as soon as possible after discovery of a breach involving the controller's personal data.
A7: A.5.26-12 | B7: GDPR 72-Hour Notification | C7: Where GDPR applies, the supervisory authority shall be notified within 72 hours of becoming aware of a personal data breach; the organisation shall meet the stricter timeline where both nFADP and GDPR apply.
A8: A.5.26-13 | B8: Notification Content | C8: Breach notifications shall include: nature of the breach, consequences and risks, measures taken or planned, and contact point for further information.
A9: A.5.26-14 | B9: Phased Notification | C9: Where full information is not available at the time of notification, it shall be provided in phases without undue delay.
A10: A.5.26-15 | B10: Breach Assessment | C10: The incident response team shall assess whether personal data incidents require notification based on: nature/sensitivity of data, number of subjects, severity/likelihood of consequences, encryption status, and containment status.
A11: A.5.26-16 | B11: Assessment Documentation | C11: The breach assessment and decision (including rationale for not notifying, if applicable) shall be documented.

Sheet Evidence Collection
A1: Evidence Collection — Compliance Checklist
A2: ISO/IEC 27001:2022 — Controls A.5.24-28: Incident Management
A3: Req # | B3: Section | C3: Requirement | D3: Status | E3: Evidence | F3: Owner | G3: Due Date | H3: Notes
A4: A.5.28-01 | B4: Timely Collection | C4: Evidence shall be collected as soon as possible after the incident is identified.
A5: A.5.28-02 | B5: Forensic Copies | C5: Original evidence shall not be accessed, modified, or analysed directly; forensic copies (bit-for-bit images) shall be created using write-blocking tools.
A6: A.5.28-03 | B6: Hash Verification | C6: All evidence shall be verified using cryptographic hash functions (SHA-256 minimum) to confirm integrity.
A7: A.5.28-04 | B7: Chain of Custody | C7: A chain of custody record shall be maintained for all evidence documenting: what was collected, when, by whom, where stored, who accessed it, and any transfers between custodians.
A8: A.5.28-05 | B8: Evidence Storage | C8: Evidence shall be stored in a secure location with restricted access; digital evidence on encrypted media; physical evidence in a locked, tamper-evident container; retained for minimum 12 months from incident closure or longer where required.
A9: A.5.28-06 | B9: External Forensics | C9: For significant incidents, qualified external forensic investigators shall be engaged; the organisation shall identify and pre-approve at least one external forensic provider.
A10: A.5.28-07 | B10: Internal Forensics Restriction | C10: Internal personnel shall not conduct forensic analysis unless trained and qualified to do so.

Sheet Lessons Learned & Testing
A1: Lessons Learned & Testing — Compliance Checklist
A2: ISO/IEC 27001:2022 — Controls A.5.24-28: Incident Management
A3: Req # | B3: Section | C3: Requirement | D3: Status | E3: Evidence | F3: Owner | G3: Due Date | H3: Notes
A4: A.5.27-01 | B4: Post-Incident Review | C4: A post-incident review shall be conducted for all Critical and High severity incidents within 5 business days of incident resolution.
A5: A.5.27-02 | B5: Review Content | C5: The review shall document: timeline (factual chronology), root cause, what worked, what could be improved, and specific measurable action items with owner and deadline.
A6: A.5.27-03 | B6: Action Tracking | C6: Action items from post-incident reviews shall be tracked to completion.
A7: A.5.27-04 | B7: Trend Review | C7: Trends across incidents shall be reviewed quarterly to identify systemic issues.
A8: A.5.27-05 | B8: Blame-Free Reviews | C8: Reviews shall be conducted in a blame-free manner, focusing on system and process improvement rather than individual fault.
A9: A.5.24-08 | B9: Annual Response Testing | C9: The incident response plan shall be tested at least annually through tabletop exercises or simulations to verify roles, communication, escalation, evidence collection, and breach notification timelines.
A10: A.5.24-09 | B10: Incident Metrics | C10: The following metrics shall be reported quarterly: total events, events-to-incidents ratio, incidents by severity, MTTD, MTTR, mean time to resolve, overdue incidents, data breaches reported, and post-incident review completion rate.
