Workbook

Sheet Executive Summary
A1: AI-CHK-A.9.2-4 — Responsible Use of AI Systems Compliance Checklist
A3: DOCUMENT INFORMATION
A4: Document ID | B4: AI-CHK-A.9.2-4
A5: Source Policy | B5: AI-POL-A.9.2-4
A6: ISO Controls | B6: Responsible Use of AI Systems
A7: Generated | B7: 30.09.2026
A8: Prepared By
A9: Organisation
A10: Review Cycle | B10: Annual
A12: OVERALL COMPLIANCE STATUS
A13: Overall Compliance | B13: ='Dashboard'!G7
A14: Status | B14: =IF(Dashboard!H7>0,"INCOMPLETE",IF(Dashboard!G7="N/A","NOT ASSESSED",IF(ISNUMBER(VALUE(SUBSTITUTE(Dashboard!G7,"%",""))),IF(VALUE(SUBSTITUTE(Dashboard!G7,"%",""))>=90,"GREEN",IF(VALUE(SUBSTITUTE(Dashboard!G7,"%",""))>=70,"AMBER","RED")),"NOT ASSESSED")))
A16: KEY METRICS
A17: Total Requirements | B17: ='Dashboard'!B7
A18: Compliant | B18: ='Dashboard'!C7
A19: Partial | B19: ='Dashboard'!D7
A20: Non-Compliant | B20: ='Dashboard'!E7
A21: Not Applicable | B21: ='Dashboard'!F7
A22: Unanswered | B22: ='Dashboard'!H7
A23: Owner Coverage | B23: =IF(Dashboard!B7=0,"N/A",ROUND((COUNTA('Responsible Use Processes'!F4:F9)+COUNTA('Responsible Use Objectives'!F4:F8)+COUNTA('Intended Use Compliance'!F4:F8))/Dashboard!B7*100,0)&"%")
A25: DOMAIN STATUS SUMMARY
A26: Domain | B26: Compliance % | C26: Compliant | D26: Gaps | E26: Status
A27: Responsible Use Processes | B27: ='Dashboard'!G4 | C27: ='Dashboard'!C4 | D27: ='Dashboard'!E4 | E27: =IF(Dashboard!H4>0,"INCOMPLETE",IF(Dashboard!G4="N/A","--",IF(ISNUMBER(VALUE(SUBSTITUTE(Dashboard!G4,"%",""))),IF(VALUE(SUBSTITUTE(Dashboard!G4,"%",""))>=90,"PASS",IF(VALUE(SUBSTITUTE(Dashboard!G4,"%",""))>=70,"REVIEW","FAIL")),"--")))
A28: Responsible Use Objectives | B28: ='Dashboard'!G5 | C28: ='Dashboard'!C5 | D28: ='Dashboard'!E5 | E28: =IF(Dashboard!H5>0,"INCOMPLETE",IF(Dashboard!G5="N/A","--",IF(ISNUMBER(VALUE(SUBSTITUTE(Dashboard!G5,"%",""))),IF(VALUE(SUBSTITUTE(Dashboard!G5,"%",""))>=90,"PASS",IF(VALUE(SUBSTITUTE(Dashboard!G5,"%",""))>=70,"REVIEW","FAIL")),"--")))
A29: Intended Use Compliance | B29: ='Dashboard'!G6 | C29: ='Dashboard'!C6 | D29: ='Dashboard'!E6 | E29: =IF(Dashboard!H6>0,"INCOMPLETE",IF(Dashboard!G6="N/A","--",IF(ISNUMBER(VALUE(SUBSTITUTE(Dashboard!G6,"%",""))),IF(VALUE(SUBSTITUTE(Dashboard!G6,"%",""))>=90,"PASS",IF(VALUE(SUBSTITUTE(Dashboard!G6,"%",""))>=70,"REVIEW","FAIL")),"--")))
A31: CRITICAL ISSUES
A32: # | B32: Issue Description | C32: Domain | D32: Owner | E32: Due Date
A33: 1
A34: 2
A35: 3
A36: 4
A37: 5
A39: MANAGEMENT COMMENTARY
A40: [Enter management commentary on responsible use of ai systems posture]
A44: APPROVAL
A45: Assessed By (AI System Owner)
A46: Name:
A47: Date:
A48: Signature:
A49: Decision:
...

Sheet Dashboard
A1: Responsible Use of AI Systems — Compliance Dashboard
A3: Domain | B3: Total Reqs | C3: Compliant | D3: Partial | E3: Non-Compliant | F3: N/A | G3: Compliance % | H3: Unassessed
A4: Responsible Use Processes | B4: =COUNTA('Responsible Use Processes'!A4:A9) | C4: =COUNTIF('Responsible Use Processes'!D4:D9,"Compliant") | D4: =COUNTIF('Responsible Use Processes'!D4:D9,"Partial") | E4: =COUNTIF('Responsible Use Processes'!D4:D9,"Non-Compliant") | F4: =COUNTIF('Responsible Use Processes'!D4:D9,"N/A") | G4: =IF((B4-F4)=0,"N/A",ROUND(C4/(B4-F4)*100,1)&"%") | H4: =B4-(C4+D4+E4+F4)
A5: Responsible Use Objectives | B5: =COUNTA('Responsible Use Objectives'!A4:A8) | C5: =COUNTIF('Responsible Use Objectives'!D4:D8,"Compliant") | D5: =COUNTIF('Responsible Use Objectives'!D4:D8,"Partial") | E5: =COUNTIF('Responsible Use Objectives'!D4:D8,"Non-Compliant") | F5: =COUNTIF('Responsible Use Objectives'!D4:D8,"N/A") | G5: =IF((B5-F5)=0,"N/A",ROUND(C5/(B5-F5)*100,1)&"%") | H5: =B5-(C5+D5+E5+F5)
A6: Intended Use Compliance | B6: =COUNTA('Intended Use Compliance'!A4:A8) | C6: =COUNTIF('Intended Use Compliance'!D4:D8,"Compliant") | D6: =COUNTIF('Intended Use Compliance'!D4:D8,"Partial") | E6: =COUNTIF('Intended Use Compliance'!D4:D8,"Non-Compliant") | F6: =COUNTIF('Intended Use Compliance'!D4:D8,"N/A") | G6: =IF((B6-F6)=0,"N/A",ROUND(C6/(B6-F6)*100,1)&"%") | H6: =B6-(C6+D6+E6+F6)
A7: TOTAL | B7: =SUM(B4:B6) | C7: =SUM(C4:C6) | D7: =SUM(D4:D6) | E7: =SUM(E4:E6) | F7: =SUM(F4:F6) | G7: =IF((B7-F7)=0,"N/A",ROUND(C7/(B7-F7)*100,1)&"%") | H7: =SUM(H4:H6)
A9: COMPLIANCE BY STATUS
A10: Compliant | B10: =C7 | C10: =IF(B7=0,"",ROUND(B10/B7*100,1)&"%")
A11: Partial | B11: =D7 | C11: =IF(B7=0,"",ROUND(B11/B7*100,1)&"%")
A12: Non-Compliant | B12: =E7 | C12: =IF(B7=0,"",ROUND(B12/B7*100,1)&"%")
A13: N/A | B13: =F7 | C13: =IF(B7=0,"",ROUND(B13/B7*100,1)&"%")
A15: TOP GAPS (Manual Entry)
A16: Priority | B16: Domain | C16: Requirement | D16: Owner | E16: Due Date | F16: Status
A28: COMPLIANCE TREND (Manual Entry)
A29: Assessment Date | B29: Overall % | C29: Compliant | D29: Gaps | E29: Assessor | F29: Notes

Sheet Responsible Use Processes
A1: Responsible Use Processes — Compliance Checklist
A2: ISO/IEC 42001:2023 — Controls A.9.2-4: Responsible Use of AI Systems
A3: Req # | B3: Section | C3: Requirement | D3: Status | E3: Evidence | F3: Owner | G3: Due Date | H3: Notes
A4: A.9.2-01 | B4: Responsible Use Framework | C4: The organisation shall establish and implement a responsible use framework for AI systems in operation. The framework shall define: what constitutes responsible use, the obligations on operators, the process for escalating concerns, and consequences of misuse.
A5: A.9.2-02 | B5: Pre-Use Verification | C5: Before deploying an AI system to a new operational context or user population, the AI System Owner shall complete a pre-use verification confirming: intended use alignment, operator training, human oversight in place, and monitoring active.
A6: A.9.2-03 | B6: Misuse Detection | C6: The AI System Owner shall implement controls to detect when an AI system is being used outside its intended use scope — including monitoring of use patterns, user queries, and downstream decisions. Detected misuse shall be escalated.
A7: A.9.2-04 | B7: Misuse Response | C7: The organisation shall implement a documented misuse response process covering: initial containment, impact assessment, affected party notification if applicable, root cause analysis, and remediation. Response shall be proportionate to misuse severity.
A8: A.9.2-05 | B8: Serious Misuse Escalation | C8: Misuse that results in harm to individuals, breach of applicable law, or reputational risk shall be escalated to the AI Governance Officer and Legal within 24 hours. Where EU AI Act serious incident thresholds are met, regulatory reporting obligations shall be assessed.
A9: A.9.2-06 | B9: Misuse Register | C9: The AI Governance Officer shall maintain a Misuse Event Register. Misuse events shall be recorded, reviewed at AI governance meetings, and used to improve use controls, training, and system design as appropriate.

Sheet Responsible Use Objectives
A1: Responsible Use Objectives — Compliance Checklist
A2: ISO/IEC 42001:2023 — Controls A.9.2-4: Responsible Use of AI Systems
A3: Req # | B3: Section | C3: Requirement | D3: Status | E3: Evidence | F3: Owner | G3: Due Date | H3: Notes
A4: A.9.3-01 | B4: Responsible Use Record | C4: For each AI system, the AI System Owner shall maintain a Responsible Use Record per the template in AI-IMP-A.9.2-4-TG, documenting how the six responsible use properties (human agency, fairness, privacy, reliability, safety, accountability) are operationalised in practice.
A5: A.9.3-02 | B5: Human Agency in Practice | C5: The AI System Owner shall document and maintain the mechanism through which human agency is preserved in practice — including how operators can override or escalate AI outputs, and how affected individuals can seek human review.
A6: A.9.3-03 | B6: Fairness in Operation | C6: The AI System Owner shall implement operational fairness monitoring — tracking whether AI outputs show disparate impact across protected groups in operation, not only at V&V. Monitoring results shall be reviewed at minimum annually.
A7: A.9.3-04 | B7: Safety and Reliability | C7: The AI System Owner shall define operational safety thresholds — the performance levels below which the system shall be suspended or require human review of all outputs — and shall monitor against these thresholds.
A8: A.9.3-05 | B8: Accountability Trail | C8: The organisation shall maintain an accountability trail for consequential AI-assisted decisions — recording the AI output, the human decision made, and the identity of the human decision-maker. The trail shall be auditable and retained per the impact classification retention schedule.

Sheet Intended Use Compliance
A1: Intended Use Compliance — Compliance Checklist
A2: ISO/IEC 42001:2023 — Controls A.9.2-4: Responsible Use of AI Systems
A3: Req # | B3: Section | C3: Requirement | D3: Status | E3: Evidence | F3: Owner | G3: Due Date | H3: Notes
A4: A.9.4-01 | B4: Intended Use Specification | C4: Every in-scope AI system shall have a documented Intended Use Specification per the template in AI-IMP-A.9.2-4-TG, defining: permitted use cases, geographic scope, user roles, input types, output interpretation guidance, and explicitly prohibited uses.
A5: A.9.4-02 | B5: Use Restriction Communication | C5: Use restrictions from the Intended Use Specification shall be communicated to all AI system operators before first use, and reinforced through user documentation and system interface notices where technically feasible.
A6: A.9.4-03 | B6: Scope Creep Prevention | C6: The AI System Owner shall implement a process to identify and respond to scope creep — the gradual expansion of an AI system's use beyond its intended scope. Scope creep shall be treated as a proposed material change requiring AISIA update and re-validation.
A7: A.9.4-04 | B7: High-Risk Use Prohibition | C7: The organisation shall maintain a list of use cases for which AI system use is prohibited or requires specific additional controls — including uses that would constitute prohibited practices under EU AI Act Article 5. This list shall be communicated to all relevant staff.
A8: A.9.4-05 | B8: Intended Use Review | C8: The Intended Use Specification shall be reviewed when: the system's operational context changes materially; new user populations are onboarded; or the AISIA is updated. Reviews shall be documented with outcome and approval record.
