Workbook

Sheet Executive Summary
A1: PRIV-CHK-A.2.2.2-7 — Processor Agreements and Obligations Compliance Checklist
A3: DOCUMENT INFORMATION
A4: Document ID | B4: PRIV-CHK-A.2.2.2-7
A5: Source Policy | B5: PRIV-POL-A.2.2.2-7
A6: ISO Controls | B6: Processor Agreements and Obligations
A7: Generated | B7: 30.09.2026
A8: Prepared By
A9: Organisation
A10: Review Cycle | B10: Annual
A12: OVERALL COMPLIANCE STATUS
A13: Overall Compliance | B13: ='Dashboard'!G10
A14: Status | B14: =IF(Dashboard!H10>0,"INCOMPLETE",IF(Dashboard!G10="N/A","NOT ASSESSED",IF(ISNUMBER(VALUE(SUBSTITUTE(Dashboard!G10,"%",""))),IF(VALUE(SUBSTITUTE(Dashboard!G10,"%",""))>=90,"GREEN",IF(VALUE(SUBSTITUTE(Dashboard!G10,"%",""))>=70,"AMBER","RED")),"NOT ASSESSED")))
A16: KEY METRICS
A17: Total Requirements | B17: ='Dashboard'!B10
A18: Compliant | B18: ='Dashboard'!C10
A19: Partial | B19: ='Dashboard'!D10
A20: Non-Compliant | B20: ='Dashboard'!E10
A21: Not Applicable | B21: ='Dashboard'!F10
A22: Unanswered | B22: ='Dashboard'!H10
A23: Owner Coverage | B23: =IF(Dashboard!B10=0,"N/A",ROUND((COUNTA('Customer Agreement Content'!F4:F7)+COUNTA('Processing on Instructions'!F4:F7)+COUNTA('Marketing and Advertising'!F4:F6)+COUNTA('Infringing Instructions'!F4:F7)+COUNTA('Customer Compliance Support'!F4:F6)+COUNTA('Processor Records'!F4:F7))/Dashboard!B10*100,0)&"%")
A25: DOMAIN STATUS SUMMARY
A26: Domain | B26: Compliance % | C26: Compliant | D26: Gaps | E26: Status
A27: Customer Agreement Content | B27: ='Dashboard'!G4 | C27: ='Dashboard'!C4 | D27: ='Dashboard'!E4 | E27: =IF(Dashboard!H4>0,"INCOMPLETE",IF(Dashboard!G4="N/A","--",IF(ISNUMBER(VALUE(SUBSTITUTE(Dashboard!G4,"%",""))),IF(VALUE(SUBSTITUTE(Dashboard!G4,"%",""))>=90,"PASS",IF(VALUE(SUBSTITUTE(Dashboard!G4,"%",""))>=70,"REVIEW","FAIL")),"--")))
A28: Processing on Instructions | B28: ='Dashboard'!G5 | C28: ='Dashboard'!C5 | D28: ='Dashboard'!E5 | E28: =IF(Dashboard!H5>0,"INCOMPLETE",IF(Dashboard!G5="N/A","--",IF(ISNUMBER(VALUE(SUBSTITUTE(Dashboard!G5,"%",""))),IF(VALUE(SUBSTITUTE(Dashboard!G5,"%",""))>=90,"PASS",IF(VALUE(SUBSTITUTE(Dashboard!G5,"%",""))>=70,"REVIEW","FAIL")),"--")))
A29: Marketing and Advertising | B29: ='Dashboard'!G6 | C29: ='Dashboard'!C6 | D29: ='Dashboard'!E6 | E29: =IF(Dashboard!H6>0,"INCOMPLETE",IF(Dashboard!G6="N/A","--",IF(ISNUMBER(VALUE(SUBSTITUTE(Dashboard!G6,"%",""))),IF(VALUE(SUBSTITUTE(Dashboard!G6,"%",""))>=90,"PASS",IF(VALUE(SUBSTITUTE(Dashboard!G6,"%",""))>=70,"REVIEW","FAIL")),"--")))
A30: Infringing Instructions | B30: ='Dashboard'!G7 | C30: ='Dashboard'!C7 | D30: ='Dashboard'!E7 | E30: =IF(Dashboard!H7>0,"INCOMPLETE",IF(Dashboard!G7="N/A","--",IF(ISNUMBER(VALUE(SUBSTITUTE(Dashboard!G7,"%",""))),IF(VALUE(SUBSTITUTE(Dashboard!G7,"%",""))>=90,"PASS",IF(VALUE(SUBSTITUTE(Dashboard!G7,"%",""))>=70,"REVIEW","FAIL")),"--")))
A31: Customer Compliance Support | B31: ='Dashboard'!G8 | C31: ='Dashboard'!C8 | D31: ='Dashboard'!E8 | E31: =IF(Dashboard!H8>0,"INCOMPLETE",IF(Dashboard!G8="N/A","--",IF(ISNUMBER(VALUE(SUBSTITUTE(Dashboard!G8,"%",""))),IF(VALUE(SUBSTITUTE(Dashboard!G8,"%",""))>=90,"PASS",IF(VALUE(SUBSTITUTE(Dashboard!G8,"%",""))>=70,"REVIEW","FAIL")),"--")))
A32: Processor Records | B32: ='Dashboard'!G9 | C32: ='Dashboard'!C9 | D32: ='Dashboard'!E9 | E32: =IF(Dashboard!H9>0,"INCOMPLETE",IF(Dashboard!G9="N/A","--",IF(ISNUMBER(VALUE(SUBSTITUTE(Dashboard!G9,"%",""))),IF(VALUE(SUBSTITUTE(Dashboard!G9,"%",""))>=90,"PASS",IF(VALUE(SUBSTITUTE(Dashboard!G9,"%",""))>=70,"REVIEW","FAIL")),"--")))
A34: CRITICAL ISSUES
A35: # | B35: Issue Description | C35: Domain | D35: Owner | E35: Due Date
A36: 1
A37: 2
A38: 3
A39: 4
A40: 5
A42: MANAGEMENT COMMENTARY
A43: [Enter management commentary on processor agreements and obligations posture]
A47: APPROVAL
A48: Assessed By
A49: Name:
...

Sheet Dashboard
A1: Processor Agreements and Obligations — Compliance Dashboard
A3: Domain | B3: Total Reqs | C3: Compliant | D3: Partial | E3: Non-Compliant | F3: N/A | G3: Compliance % | H3: Unassessed
A4: Customer Agreement Content | B4: =COUNTA('Customer Agreement Content'!A4:A7) | C4: =COUNTIF('Customer Agreement Content'!D4:D7,"Compliant") | D4: =COUNTIF('Customer Agreement Content'!D4:D7,"Partial") | E4: =COUNTIF('Customer Agreement Content'!D4:D7,"Non-Compliant") | F4: =COUNTIF('Customer Agreement Content'!D4:D7,"N/A") | G4: =IF((B4-F4)=0,"N/A",ROUND(C4/(B4-F4)*100,1)&"%") | H4: =B4-(C4+D4+E4+F4)
A5: Processing on Instructions | B5: =COUNTA('Processing on Instructions'!A4:A7) | C5: =COUNTIF('Processing on Instructions'!D4:D7,"Compliant") | D5: =COUNTIF('Processing on Instructions'!D4:D7,"Partial") | E5: =COUNTIF('Processing on Instructions'!D4:D7,"Non-Compliant") | F5: =COUNTIF('Processing on Instructions'!D4:D7,"N/A") | G5: =IF((B5-F5)=0,"N/A",ROUND(C5/(B5-F5)*100,1)&"%") | H5: =B5-(C5+D5+E5+F5)
A6: Marketing and Advertising | B6: =COUNTA('Marketing and Advertising'!A4:A6) | C6: =COUNTIF('Marketing and Advertising'!D4:D6,"Compliant") | D6: =COUNTIF('Marketing and Advertising'!D4:D6,"Partial") | E6: =COUNTIF('Marketing and Advertising'!D4:D6,"Non-Compliant") | F6: =COUNTIF('Marketing and Advertising'!D4:D6,"N/A") | G6: =IF((B6-F6)=0,"N/A",ROUND(C6/(B6-F6)*100,1)&"%") | H6: =B6-(C6+D6+E6+F6)
A7: Infringing Instructions | B7: =COUNTA('Infringing Instructions'!A4:A7) | C7: =COUNTIF('Infringing Instructions'!D4:D7,"Compliant") | D7: =COUNTIF('Infringing Instructions'!D4:D7,"Partial") | E7: =COUNTIF('Infringing Instructions'!D4:D7,"Non-Compliant") | F7: =COUNTIF('Infringing Instructions'!D4:D7,"N/A") | G7: =IF((B7-F7)=0,"N/A",ROUND(C7/(B7-F7)*100,1)&"%") | H7: =B7-(C7+D7+E7+F7)
A8: Customer Compliance Support | B8: =COUNTA('Customer Compliance Support'!A4:A6) | C8: =COUNTIF('Customer Compliance Support'!D4:D6,"Compliant") | D8: =COUNTIF('Customer Compliance Support'!D4:D6,"Partial") | E8: =COUNTIF('Customer Compliance Support'!D4:D6,"Non-Compliant") | F8: =COUNTIF('Customer Compliance Support'!D4:D6,"N/A") | G8: =IF((B8-F8)=0,"N/A",ROUND(C8/(B8-F8)*100,1)&"%") | H8: =B8-(C8+D8+E8+F8)
A9: Processor Records | B9: =COUNTA('Processor Records'!A4:A7) | C9: =COUNTIF('Processor Records'!D4:D7,"Compliant") | D9: =COUNTIF('Processor Records'!D4:D7,"Partial") | E9: =COUNTIF('Processor Records'!D4:D7,"Non-Compliant") | F9: =COUNTIF('Processor Records'!D4:D7,"N/A") | G9: =IF((B9-F9)=0,"N/A",ROUND(C9/(B9-F9)*100,1)&"%") | H9: =B9-(C9+D9+E9+F9)
A10: TOTAL | B10: =SUM(B4:B9) | C10: =SUM(C4:C9) | D10: =SUM(D4:D9) | E10: =SUM(E4:E9) | F10: =SUM(F4:F9) | G10: =IF((B10-F10)=0,"N/A",ROUND(C10/(B10-F10)*100,1)&"%") | H10: =SUM(H4:H9)
A12: COMPLIANCE BY STATUS
A13: Compliant | B13: =C10 | C13: =IF(B10=0,"",ROUND(B13/B10*100,1)&"%")
A14: Partial | B14: =D10 | C14: =IF(B10=0,"",ROUND(B14/B10*100,1)&"%")
A15: Non-Compliant | B15: =E10 | C15: =IF(B10=0,"",ROUND(B15/B10*100,1)&"%")
A16: N/A | B16: =F10 | C16: =IF(B10=0,"",ROUND(B16/B10*100,1)&"%")
A18: TOP GAPS (Manual Entry)
A19: Priority | B19: Domain | C19: Requirement | D19: Owner | E19: Due Date | F19: Status
A31: COMPLIANCE TREND (Manual Entry)
A32: Assessment Date | B32: Overall % | C32: Compliant | D32: Gaps | E32: Assessor | F32: Notes

Sheet Customer Agreement Content
A1: Customer Agreement Content — Compliance Checklist
A2: ISO/IEC 27701:2025 — Controls A.2.2.2-7: Processor Agreements and Obligations
A3: Req # | B3: Section | C3: Requirement | D3: Status | E3: Evidence | F3: Owner | G3: Due Date | H3: Notes
A4: A.2.2.2-01 | B4: Agreement Content Review | C4: All processor agreements (where the organisation acts as processor) shall be reviewed by the DPO before execution to confirm that obligations relating to assisting with the customer's data protection duties are adequately addressed, taking into account the nature of processing.
A5: A.2.2.2-02 | B5: Assistance Obligations | C5: Processor agreements shall address the organisation's role in: implementing appropriate security measures (Article 32); assisting with data subject rights obligations; assisting with security, breach notification, DPIA, and prior consultation; providing information for customer compliance demonstration; and cooperating with customer or supervisory authority audits.
A6: A.2.2.2-03 | B6: Return or Deletion at End | C6: Processor agreements shall include the obligation to return or delete all customer PII upon service termination, per PRIV-POL-A.2.4.2-4. The default action (return or deletion) shall be specified in the agreement.
A7: A.2.2.2-04 | B7: Processor Agreement Register | C7: The DPO shall maintain a Processor Agreement Register listing all active customer processor agreements with status, review date, and customer contact. No new processor engagement commences without a register entry.

Sheet Processing on Instructions
A1: Processing on Instructions — Compliance Checklist
A2: ISO/IEC 27701:2025 — Controls A.2.2.2-7: Processor Agreements and Obligations
A3: Req # | B3: Section | C3: Requirement | D3: Status | E3: Evidence | F3: Owner | G3: Due Date | H3: Notes
A4: A.2.2.3-01 | B4: Instruction-Only Processing | C4: PII processed on behalf of customers shall be processed only for the purposes expressed in the customer's documented instructions. Processing for the organisation's own purposes is prohibited unless explicitly authorised by the customer in writing.
A5: A.2.2.3-02 | B5: Instruction Traceability | C5: All processing operations applied to customer PII must be traceable to a customer instruction (contract, SLA, or written instruction). Processing operations without a traceable instruction shall not commence.
A6: A.2.2.3-03 | B6: Personnel Instruction Compliance | C6: All personnel processing customer PII shall understand and be able to demonstrate that they are acting on customer instructions only. Unauthorised use of customer PII for internal purposes shall be treated as a security incident.
A7: A.2.2.3-04 | B7: Escalation Requirement | C7: Where personnel seek to use customer PII for a purpose not covered by the contract, they shall escalate to the DPO for assessment before proceeding. The DPO assessment and outcome shall be documented.

Sheet Marketing and Advertising
A1: Marketing and Advertising — Compliance Checklist
A2: ISO/IEC 27701:2025 — Controls A.2.2.2-7: Processor Agreements and Obligations
A3: Req # | B3: Section | C3: Requirement | D3: Status | E3: Evidence | F3: Owner | G3: Due Date | H3: Notes
A4: A.2.2.4-01 | B4: Marketing Prohibition | C4: The organisation shall not use PII processed under a customer contract for marketing or advertising purposes (the organisation's own marketing to the customer's data subjects) unless prior consent from the PII principal has been separately obtained.
A5: A.2.2.4-02 | B5: Consent Requirements | C5: Marketing consent from PII principals shall be separately obtained and not bundled with the service agreement. Providing consent for marketing shall not be a condition of receiving the service.
A6: A.2.2.4-03 | B6: Consent Records | C6: The organisation shall maintain records of any marketing consent obtained from data subjects in the context of processor activities and shall not send marketing to individuals who have not consented.

Sheet Infringing Instructions
A1: Infringing Instructions — Compliance Checklist
A2: ISO/IEC 27701:2025 — Controls A.2.2.2-7: Processor Agreements and Obligations
A3: Req # | B3: Section | C3: Requirement | D3: Status | E3: Evidence | F3: Owner | G3: Due Date | H3: Notes
A4: A.2.2.5-01 | B4: Notification Obligation | C4: If the organisation considers that a customer's processing instruction infringes applicable legal requirements (GDPR, CH FADP, or other applicable law), the organisation shall inform the customer in writing without undue delay.
A5: A.2.2.5-02 | B5: Escalation Process | C5: Processing personnel who identify a potentially infringing instruction shall escalate to the DPO immediately. The DPO shall assess the instruction (with Legal/Compliance input where uncertain), document the assessment, and communicate the concern to the customer in writing.
A6: A.2.2.5-03 | B6: Non-Execution Pending Resolution | C6: The organisation shall not execute an instruction identified as potentially infringing pending resolution with the customer. If the customer insists on proceeding after notification, the organisation shall document its position and may exercise its contractual right to suspend or terminate the engagement.
A7: A.2.2.5-04 | B7: Infringing Instruction Register | C7: All infringing instruction notifications and customer responses shall be documented in the Infringing Instruction Register and retained for 5 years.

Sheet Customer Compliance Support
A1: Customer Compliance Support — Compliance Checklist
A2: ISO/IEC 27701:2025 — Controls A.2.2.2-7: Processor Agreements and Obligations
A3: Req # | B3: Section | C3: Requirement | D3: Status | E3: Evidence | F3: Owner | G3: Due Date | H3: Notes
A4: A.2.2.6-01 | B4: Compliance Information Provision | C4: The organisation shall provide customers with the information necessary to enable them to demonstrate compliance with their obligations as PII Controller. This includes: security documentation (certificates, audit reports, SOC 2); sub-processor lists; and evidence of implemented security measures.
A5: A.2.2.6-02 | B5: Audit Cooperation | C5: The organisation shall cooperate with customer audits and supervisory authority inspections relating to the processing of customer PII, as required by GDPR Article 28(3)(h). The scope and conditions of such cooperation shall be defined in the processor agreement.
A6: A.2.2.6-03 | B6: Customer Compliance Support Register | C6: The DPO shall maintain a Customer Compliance Support Register tracking what security and compliance documentation has been provided to each customer and when.

Sheet Processor Records
A1: Processor Records — Compliance Checklist
A2: ISO/IEC 27701:2025 — Controls A.2.2.2-7: Processor Agreements and Obligations
A3: Req # | B3: Section | C3: Requirement | D3: Status | E3: Evidence | F3: Owner | G3: Due Date | H3: Notes
A4: A.2.2.7-01 | B4: Processor RoPA | C4: The organisation shall maintain a processor-side Record of Processing Activities (RoPA) per GDPR Article 30(2), including for each customer processing activity: name and contact details of the processor and DPO; categories of processing carried out per customer; transfers to third countries and safeguards; and general description of security measures.
A5: A.2.2.7-02 | B5: Supporting Registers | C5: In addition to the processor RoPA, the organisation shall maintain: Processor Agreement Register; Sub-processor Register; Infringing Instruction Register; and Customer Compliance Support Register.
A6: A.2.2.7-03 | B6: Record Availability | C6: Processor records shall be maintained in a secure manner and made available to supervisory authorities on request within the timeframe required by applicable law.
A7: A.2.2.7-04 | B7: Record Review | C7: Processor records shall be reviewed and updated at minimum annually, when new customer engagements commence, when processing activities change materially, and when engagements end.
