Workbook

Sheet Instructions & Legend
A1: ISMS-IMP-A.5.23.S1 - Cloud Service Inventory & Classification ISO/IEC 27001:2022 - Control A.5.23: Information Security for Use of Cloud Services
A3: Document Information
A4: Document ID | B4: ISMS-IMP-A.5.23.S1
A5: Assessment Area | B5: Cloud Service Inventory & Classification
A6: Related Policy | B6: ISMS-POL-A.5.19-23-S1, S5
A7: Version | B7: 1.0
A8: Assessment Date
A9: Completed By
A10: Organisation
A11: Review Cycle | B11: Quarterly
A13: REGULATORY COMPLIANCE
A14: This workbook includes regulatory compliance tracking for:
A15: • DORA (Digital Operational Resilience Act) - EU financial entity requirements
A16: • NIS2 (Network and Information Security Directive 2) - Essential/important entities
A17: • EU AI Act - AI system classification and provider evaluation
A18: • US CLOUD Act - Jurisdictional risk for US-headquartered providers
A20: Regulatory columns (Y-AG) are included in each assessment sheet.
A21: Complete only the regulatory sections applicable to your organisation.
A23: HOW TO USE THIS WORKBOOK
A24: 1. Complete each assessment sheet for all cloud services in your inventory.
A25: 2. Use dropdown menus for standardised entries.
A26: 3. Fill in yellow-highlighted cells with your service-specific information.
... A35: STATUS LEGEND
A36: Symbol | B36: Status | C36: Description
A37: ✅ | B37: Compliant | C37: Service meets all security and classification requirements
A38: ⚠ | B38: Partial | C38: Some requirements met, gaps exist (e.g., missing classification)
A39: ❌ | B39: Non-Compliant | C39: Service does not meet minimum requirements
A40: N/A | B40: Not Applicable | C40: Requirement does not apply to this service
A42: ACCEPTABLE EVIDENCE (examples)
A43: ✓ Cloud service contracts and terms of service
A44: ✓ Data Processing Agreement (DPA) / Addendum
A45: ✓ Service Level Agreement (SLA)
A46: ✓ ISO 27001 / ISO 27017 / ISO 27018 certificate (current)
A47: ✓ SOC 2 Type II report (within last 12 months)
A48: ✓ CSA STAR registration or certification
A49: ✓ GDPR/nFADP compliance attestation
A50: ✓ Data residency and sovereignty documentation
A51: ✓ Cloud service architecture diagrams
A52: ✓ Business impact assessment for each cloud service
A53: ✓ Risk assessment documentation
...

Sheet 2. SaaS Services
A1: SAAS SERVICES INVENTORY All SaaS applications must be documented with data classification (Policy S5 Section 2.1)
A3: Does your organisation use SaaS applications?
A4: Response:
A6: Cloud_Service_Name | B6: Service_Type | C6: Vendor_Name | D6: Service_Criticality | E6: Data_Classification | F6: Data_Residency | G6: Contract_Status | H6: Status | I6: Evidence_Location | J6: Gap_Description | K6: Remediation_Needed | L6: Exception_ID | M6: Risk_ID | N6: Compensating_Controls | O6: Service_Owner | P6: Target_Remediation_Date | Q6: Budget_Impact | R6: Monthly_Cost_CHF | S6: Annual_Contract_Value | T6: Licensed_Users | U6: Integration_Count | V6: Backup_Available | W6: Exit_Feasibility | X6: Last_Review_Date | Y6: Provider_HQ_Jurisdiction | Z6: CLOUD_Act_Exposure | AA6: Data_Processing_Locations | AB6: EU_Data_Boundary | AC6: DORA_In_Scope | AD6: NIS2_In_Scope | AE6: AI_Classification | AF6: Concentration_Risk | AG6: Alternatives_Identified
A8: Example: Microsoft 365 | B8: SaaS | C8: Microsoft | D8: Critical | H8: ✅ Compliant | Y8: United States | Z8: Mitigated (EU Data Boundary) | AC8: Yes | AD8: Yes | AF8: High (Few alternatives)
A53: COMPLIANCE CHECKLIST
A55: Item | B55: Requirement | C55: Status | D55: Evidence
A56: ☐ | B56: All cloud services documented in CMDB | D56: CMDB export
A57: ☐ | B57: Data classification assigned | D57: Data classification matrix
A58: ☐ | B58: Service criticality assessed (BIA) | D58: Business impact analysis
A59: ☐ | B59: Service owner identified | D59: RACI matrix
A60: ☐ | B60: Contract status tracked | D60: Contract management system
A61: ☐ | B61: Monthly costs documented | D61: Finance system
A62: ☐ | B62: User license count verified | D62: License report
A63: ☐ | B63: Integration dependencies mapped | D63: Architecture diagram
A64: ☐ | B64: Backup strategy defined | D64: BC/DR plan
A65: ☐ | B65: Exit feasibility evaluated | D65: Exit strategy document
A66: ☐ | B66: Data residency verified | D66: Vendor DPA
A67: ☐ | B67: Last review date recorded | D67: Review calendar
... A75: ☐ | B75: Alternative providers identified | D75: Market analysis

Sheet 3. IaaS PaaS Services
A1: IAAS/PAAS SERVICES INVENTORY All infrastructure services must maintain security baselines (Policy S5 Section 2.2)
A3: Does your organisation use IaaS or PaaS services?
A4: Response:
A6: Cloud_Service_Name | B6: Service_Type | C6: Vendor_Name | D6: Service_Criticality | E6: Data_Classification | F6: Data_Residency | G6: Contract_Status | H6: Status | I6: Evidence_Location | J6: Gap_Description | K6: Remediation_Needed | L6: Exception_ID | M6: Risk_ID | N6: Compensating_Controls | O6: Service_Owner | P6: Target_Remediation_Date | Q6: Budget_Impact | R6: Monthly_Cost_CHF | S6: Annual_Contract_Value | T6: Licensed_Users | U6: Integration_Count | V6: Backup_Available | W6: Exit_Feasibility | X6: Last_Review_Date | Y6: Provider_HQ_Jurisdiction | Z6: CLOUD_Act_Exposure | AA6: Data_Processing_Locations | AB6: EU_Data_Boundary | AC6: DORA_In_Scope | AD6: NIS2_In_Scope | AE6: AI_Classification | AF6: Concentration_Risk | AG6: Alternatives_Identified
A8: Example: Microsoft 365 | B8: SaaS | C8: Microsoft | D8: Critical | H8: ✅ Compliant | Y8: United States | Z8: Mitigated (EU Data Boundary) | AC8: Yes | AD8: Yes | AF8: High (Few alternatives)
A53: COMPLIANCE CHECKLIST
A55: Item | B55: Requirement | C55: Status | D55: Evidence
A56: ☐ | B56: All cloud services documented in CMDB | D56: CMDB export
A57: ☐ | B57: Data classification assigned | D57: Data classification matrix
A58: ☐ | B58: Service criticality assessed (BIA) | D58: Business impact analysis
A59: ☐ | B59: Service owner identified | D59: RACI matrix
A60: ☐ | B60: Contract status tracked | D60: Contract management system
A61: ☐ | B61: Monthly costs documented | D61: Finance system
A62: ☐ | B62: User license count verified | D62: License report
A63: ☐ | B63: Integration dependencies mapped | D63: Architecture diagram
A64: ☐ | B64: Backup strategy defined | D64: BC/DR plan
A65: ☐ | B65: Exit feasibility evaluated | D65: Exit strategy document
A66: ☐ | B66: Data residency verified | D66: Vendor DPA
A67: ☐ | B67: Last review date recorded | D67: Review calendar
... A75: ☐ | B75: Alternative providers identified | D75: Market analysis

Sheet 4. Cloud Security Services
A1: SHEET 4: EXIT FEASIBILITY & STRATEGY ASSESSMENT
A2: POL-S5 Section 8.1.1: Cloud-to-Cloud (90%+), Hybrid (5-10%), On-Premises (<5% only when justified)
A3: Service Name | B3: Provider | C3: Service Type | D3: Environment | E3: Business Owner | F3: Technical Owner | G3: Data Classification | H3: Criticality | I3: Users | J3: Cost (Annual CHF) | K3: Contract End Date | L3: Primary Region | M3: Backup Region | N3: Integration Count | O3: API Dependency | P3: Compliance Certs | Q3: Current Status | R3: Exit Strategy Type | S3: Alternative Identified | T3: Export Format Available | U3: Export Tested | V3: Data Volume (GB) | W3: Migration Complexity | X3: Lock-In Risk | Y3: Hybrid: Workload Segmentation | Z3: Hybrid: Data Sync Latency | AA3: OnPrem: TCO Analysis Complete | AB3: OnPrem: Infrastructure Available | AC3: OnPrem: Staffing Plan Documented
A105: EXIT STRATEGY COMPLIANCE CHECKLIST (22 items)
A106: 1. ✅ Exit strategy documented for Critical/High services
A107: 2. ✅ Exit triggers defined
A108: 3. ✅ Alternative providers/solutions identified
A109: 4. ✅ Alternative provider assessment completed
A110: 5. ✅ Migration effort estimated
A111: 6. ✅ Data extraction requirements documented
A112: 7. ✅ Application dependencies mapped
A113: 8. ✅ Integration points documented
A114: 9. ✅ Lock-in risks identified and documented
A115: 10. ✅ Exit cost estimate completed
A116: 11. ✅ Exit timeline estimate completed
... A173: • POL-S5 Section 8.1.1.3 (On-Premises)

Sheet 5. Cloud Storage Services
A1: CLOUD STORAGE SERVICES INVENTORY All cloud storage must enforce encryption (Policy S5 Section 2.4)
A3: Does your organisation use cloud storage services?
A4: Response:
A6: Cloud_Service_Name | B6: Service_Type | C6: Vendor_Name | D6: Service_Criticality | E6: Data_Classification | F6: Data_Residency | G6: Contract_Status | H6: Status | I6: Evidence_Location | J6: Gap_Description | K6: Remediation_Needed | L6: Exception_ID | M6: Risk_ID | N6: Compensating_Controls | O6: Service_Owner | P6: Target_Remediation_Date | Q6: Budget_Impact | R6: Monthly_Cost_CHF | S6: Annual_Contract_Value | T6: Licensed_Users | U6: Integration_Count | V6: Backup_Available | W6: Exit_Feasibility | X6: Last_Review_Date | Y6: Provider_HQ_Jurisdiction | Z6: CLOUD_Act_Exposure | AA6: Data_Processing_Locations | AB6: EU_Data_Boundary | AC6: DORA_In_Scope | AD6: NIS2_In_Scope | AE6: AI_Classification | AF6: Concentration_Risk | AG6: Alternatives_Identified
A8: Example: Microsoft 365 | B8: SaaS | C8: Microsoft | D8: Critical | H8: ✅ Compliant | Y8: United States | Z8: Mitigated (EU Data Boundary) | AC8: Yes | AD8: Yes | AF8: High (Few alternatives)
A53: COMPLIANCE CHECKLIST
A55: Item | B55: Requirement | C55: Status | D55: Evidence
A56: ☐ | B56: All cloud services documented in CMDB | D56: CMDB export
A57: ☐ | B57: Data classification assigned | D57: Data classification matrix
A58: ☐ | B58: Service criticality assessed (BIA) | D58: Business impact analysis
A59: ☐ | B59: Service owner identified | D59: RACI matrix
A60: ☐ | B60: Contract status tracked | D60: Contract management system
A61: ☐ | B61: Monthly costs documented | D61: Finance system
A62: ☐ | B62: User license count verified | D62: License report
A63: ☐ | B63: Integration dependencies mapped | D63: Architecture diagram
A64: ☐ | B64: Backup strategy defined | D64: BC/DR plan
A65: ☐ | B65: Exit feasibility evaluated | D65: Exit strategy document
A66: ☐ | B66: Data residency verified | D66: Vendor DPA
A67: ☐ | B67: Last review date recorded | D67: Review calendar
... A75: ☐ | B75: Alternative providers identified | D75: Market analysis

Sheet 6. Data Classification
A1: DATA CLASSIFICATION - CLOUD STORAGE INVENTORY
A2: Classify all data types stored in cloud services. Required for ISO 27001 A.5.12 (Classification), A.5.13 (Labelling), and GDPR Article 30.
A3: Data_ID | B3: Data Category | C3: Description | D3: Classification Level | E3: Primary Cloud Service | F3: Storage Location | G3: Data Owner | H3: Retention Period | I3: Personal Data (GDPR) | J3: Cross-Border Transfer
A4: DC-001
A5: DC-002
A6: DC-003
A7: DC-004
A8: DC-005
A9: DC-006
A10: DC-007
A11: DC-008
A12: DC-009
A13: DC-010
A14: DC-011
A15: DC-012
... A103: DC-100

Sheet 7. Service Criticality
A1: SERVICE CRITICALITY ASSESSMENT
A2: Assess criticality of each cloud service for BIA and exit strategy planning. Required for ISO 27001 A.5.29 (Business Continuity) and DORA Article 28.
A3: Service_ID | B3: Cloud Service Name | C3: Service Category | D3: Business Process Supported | E3: Criticality Level | F3: RTO (Hours) | G3: RPO (Hours) | H3: MTPD (Hours) | I3: Single Point of Failure | J3: Workaround Available | K3: DORA Scope | L3: Exit Priority
A4: SC-001
A5: SC-002
A6: SC-003
A7: SC-004
A8: SC-005
A9: SC-006
A10: SC-007
A11: SC-008
A12: SC-009
A13: SC-010
A14: SC-011
A15: SC-012
... A103: SC-100

Sheet 8. Summary Dashboard
A1: CLOUD SERVICE INVENTORY - COMPLIANCE DASHBOARD
A3: TABLE 1: COMPLIANCE BY SERVICE CATEGORY
A4: Category | B4: Total | C4: ✅ Compliant | D4: ⚠ Partial | E4: ❌ Non-Compliant | F4: N/A | G4: Compliance %
A5: SaaS Services | B5: =COUNTA('2. SaaS Services'!A8:A50) | C5: =COUNTIF('2. SaaS Services'!H8:H50,"✅*") | D5: =COUNTIF('2. SaaS Services'!H8:H50,"⚠*") | E5: =COUNTIF('2. SaaS Services'!H8:H50,"❌*") | F5: =COUNTIF('2. SaaS Services'!H8:H50,"N/A") | G5: =IF((B5-F5)=0,"0%",ROUND(C5/(B5-F5)*100,1)&"%")
A6: IaaS/PaaS | B6: =COUNTA('3. IaaS PaaS Services'!A8:A50) | C6: =COUNTIF('3. IaaS PaaS Services'!H8:H50,"✅*") | D6: =COUNTIF('3. IaaS PaaS Services'!H8:H50,"⚠*") | E6: =COUNTIF('3. IaaS PaaS Services'!H8:H50,"❌*") | F6: =COUNTIF('3. IaaS PaaS Services'!H8:H50,"N/A") | G6: =IF((B6-F6)=0,"0%",ROUND(C6/(B6-F6)*100,1)&"%")
A7: Security Services | B7: =COUNTA('4. Cloud Security Services'!A8:A50) | C7: =COUNTIF('4. Cloud Security Services'!H8:H50,"✅*") | D7: =COUNTIF('4. Cloud Security Services'!H8:H50,"⚠*") | E7: =COUNTIF('4. Cloud Security Services'!H8:H50,"❌*") | F7: =COUNTIF('4. Cloud Security Services'!H8:H50,"N/A") | G7: =IF((B7-F7)=0,"0%",ROUND(C7/(B7-F7)*100,1)&"%")
A8: Storage Services | B8: =COUNTA('5. Cloud Storage Services'!A8:A50) | C8: =COUNTIF('5. Cloud Storage Services'!H8:H50,"✅*") | D8: =COUNTIF('5. Cloud Storage Services'!H8:H50,"⚠*") | E8: =COUNTIF('5. Cloud Storage Services'!H8:H50,"❌*") | F8: =COUNTIF('5. Cloud Storage Services'!H8:H50,"N/A") | G8: =IF((B8-F8)=0,"0%",ROUND(C8/(B8-F8)*100,1)&"%")
A9: TOTAL | B9: =SUM(B5:B8) | C9: =SUM(C5:C8) | D9: =SUM(D5:D8) | E9: =SUM(E5:E8) | F9: =SUM(F5:F8) | G9: =IF(B9-F9>0,ROUND(C9/(B9-F9)*100,1)&"%","N/A")
A12: TABLE 2: REGULATORY COMPLIANCE SUMMARY (DORA / NIS2 / AI Act / CLOUD Act)
A14: Metric | B14: Count | C14: Status
A15: CLOUD Act Potential Exposure | B15: =COUNTIF('2. SaaS Services'!Z:Z,"Potential*")+COUNTIF('3. IaaS PaaS Services'!Z:Z,"Potential*") | C15: =IF(B15>0,"⚠ Review","✅ OK")
A16: DORA In-Scope Services | B16: =COUNTIF('2. SaaS Services'!AC:AC,"Yes")+COUNTIF('3. IaaS PaaS Services'!AC:AC,"Yes") | C16: =IF(B16>0,"⚠ Review","✅ OK")
A17: NIS2 In-Scope Services | B17: =COUNTIF('2. SaaS Services'!AD:AD,"Yes")+COUNTIF('3. IaaS PaaS Services'!AD:AD,"Yes") | C17: =IF(B17>0,"⚠ Review","✅ OK")
A18: High-Risk AI Systems | B18: =COUNTIF('2. SaaS Services'!AE:AE,"High Risk")+COUNTIF('3. IaaS PaaS Services'!AE:AE,"High Risk") | C18: =IF(B18>0,"⚠ Review","✅ OK")
A19: Critical Concentration Risk | B19: =COUNTIF('2. SaaS Services'!AF:AF,"Critical*")+COUNTIF('3. IaaS PaaS Services'!AF:AF,"Critical*") | C19: =IF(B19>0,"⚠ Review","✅ OK")

Sheet 9. Evidence Register
A1: EVIDENCE REGISTER - CLOUD SERVICE INVENTORY
A2: Track all cloud service contracts, certifications, and compliance documentation
A4: Evidence ID | B4: Cloud Service | C4: Evidence Type | D4: Description | E4: File Location | F4: Collection Date | G4: Collected By | H4: Retention | I4: Status
A5: EV-INV-001
A6: EV-INV-002
A7: EV-INV-003
A8: EV-INV-004
A9: EV-INV-005
A10: EV-INV-006
A11: EV-INV-007
A12: EV-INV-008
A13: EV-INV-009
A14: EV-INV-010
A15: EV-INV-011
A16: EV-INV-012
... A104: EV-INV-100

Sheet 10. Approval Sign-Of
A1: APPROVAL SIGN-OFF - CLOUD SERVICE INVENTORY
A3: ASSESSMENT SUMMARY
A4: Document: | B4: ISMS-IMP-A.5.23.S1 - Cloud Service Inventory
A5: Assessment Period:
A6: Total Services: | B6: ='8. Summary Dashboard'!B8
A7: Overall Compliance: | B7: ='8. Summary Dashboard'!G8
A8: Assessment Status:
A11: COMPLETED BY (IT OPERATIONS)
A12: Name:
A13: Title:
A14: Date:
A15: Signature:
A16: Comments:
A18: REVIEWED BY (ISO)
A19: Name:
A20: Title:
A21: Date:
A22: Signature:
... A38: Special Considerations:
