Workbook

Sheet Instructions & Legend
A1: ISMS-IMP-A.5.23.S2 - Vendor Due Diligence & Contracts ISO/IEC 27001:2022 - Control A.5.23: Information Security for Use of Cloud Services
A3: Document Information
A4: Document ID | B4: ISMS-IMP-A.5.23.S2
A5: Assessment Area | B5: Vendor Due Diligence & Contracts
A6: Related Policy | B6: ISMS-POL-A.5.19-23-S1, S2
A7: Version | B7: 1.0
A8: Assessment Date
A9: Completed By
A10: Organisation
A11: Review Cycle | B11: Quarterly
A13: REGULATORY COMPLIANCE
A14: This workbook includes regulatory compliance tracking for:
A15: • DORA (Digital Operational Resilience Act) - Art.30 contract clauses
A16: • NIS2 (Network and Information Security Directive 2) - Supply chain security
A17: • EU AI Act - AI service provider evaluation criteria
A18: • US CLOUD Act - Jurisdictional risk assessment
A20: Sheet 7 (Jurisdictional Risk) helps assess CLOUD Act exposure for US-nexus providers.
A21: Contract Terms checklist now includes DORA Art.30 and NIS2 requirements.
A23: HOW TO USE THIS WORKBOOK
A24: 1. Complete each worksheet tab (2-7) for all cloud service vendors.
A25: 2. Use dropdown menus for standardised entries.
A26: 3. Fill in yellow-highlighted cells with vendor-specific information.
... A35: STATUS LEGEND
A36: Symbol | B36: Status | C36: Description
A37: ✅ | B37: Compliant | C37: Vendor meets all security and contractual requirements
A38: ⚠ | B38: Partial | C38: Some requirements met, gaps exist (e.g., cert pending)
A39: ❌ | B39: Non-Compliant | C39: Vendor does not meet minimum requirements
A40: N/A | B40: Not Applicable | C40: Requirement does not apply to this vendor/service
A42: ACCEPTABLE EVIDENCE (examples)
A43: ✓ Master Service Agreement (MSA)
A44: ✓ Data Processing Agreement (DPA) / Addendum
A45: ✓ Service Level Agreement (SLA)
A46: ✓ ISO 27001 certificate (current, not expired)
A47: ✓ SOC 2 Type II report (within last 12 months)
A48: ✓ FedRAMP authorization letter
A49: ✓ GDPR/nFADP compliance attestation
A50: ✓ Vendor security questionnaire (completed)
A51: ✓ Penetration test results (if available)
A52: ✓ Incident response plan documentation
A53: ✓ Business continuity/disaster recovery plan
...

Sheet 2. Security Certifications
A1: VENDOR SECURITY CERTIFICATIONS Policy Requirement: All cloud vendors must maintain ISO 27001 or equivalent security certification (Policy S2 Section 3.1)
A2: Assessment Question: Do your cloud service vendors hold current security certifications (ISO 27001, SOC 2, FedRAMP, etc.)?
A4: Cloud Service Name | B4: Vendor Name | C4: Service Type | D4: Service Criticality | E4: Data Classification | F4: Contract Type | G4: Contract Start Date | H4: Status | I4: Evidence Location | J4: Gap Description | K4: Remediation Needed | L4: Exception ID | M4: Risk ID | N4: Compensating Controls | O4: Vendor Contact (Legal) | P4: Target Remediation Date | Q4: Contract Owner | R4: ISO 27001 Certified | S4: ISO 27001 Cert Number | T4: ISO 27001 Expiry Date | U4: SOC 2 Type II Report | V4: SOC 2 Report Date | W4: FedRAMP Authorized | X4: Other Certifications
A27: COMPLIANCE CHECKLIST
A28: ☐ | B28: Requirement | C28: Status | D28: Evidence Type
A29: ☐ | B29: All critical/high services have ISO 27001 or SOC 2 Type II | D29: Certification register
A30: ☐ | B30: Certificates verified as current (not expired) | D30: Certificate expiry tracking
A31: ☐ | B31: SOC 2 reports obtained within last 12 months | D31: Vendor portal, NDA required
A32: ☐ | B32: Certificate scope covers services in use | D32: Certificate scope statement
A33: ☐ | B33: Certificate issuing body is accredited (e.g., UKAS, ANAB) | D33: Issuer verification
A34: ☐ | B34: FedRAMP authorization verified for US government workloads | D34: FedRAMP marketplace
A35: ☐ | B35: Industry-specific certs documented (PCI-DSS, HIPAA, etc.) | D35: Compliance attestations
A36: ☐ | B36: Certificate renewal dates tracked in contract management system | D36: CMS reports

Sheet 3. Contract Terms
A1: CONTRACT TERMS ANALYSIS (incl. DORA/NIS2) Policy Requirement: All cloud service contracts must include security clauses, data protection terms, and termination rights (Policy S2 Section 3.2)
A2: Assessment Question: Have all cloud service contracts been reviewed for security, data protection, and regulatory clauses (DORA Art.30, NIS2)?
A4: Cloud Service Name | B4: Vendor Name | C4: Service Type | D4: Service Criticality | E4: Data Classification | F4: Contract Type | G4: Contract Start Date | H4: Status | I4: Evidence Location | J4: Gap Description | K4: Remediation Needed | L4: Exception ID | M4: Risk ID | N4: Compensating Controls | O4: Vendor Contact (Legal) | P4: Target Remediation Date | Q4: Contract Owner | R4: Data Protection Clause | S4: Subprocessor Disclosure | T4: Liability Cap (CHF) | U4: Indemnification Clause | V4: Termination Notice Period | W4: Data Return on Termination | X4: Auto-Renewal Clause | Y4: DORA Art.30 Compliance | Z4: NIS2 Supply Chain Clause
A27: COMPLIANCE CHECKLIST
A28: ☐ | B28: Requirement | C28: Status | D28: Evidence Type
A29: ☐ | B29: Data protection clause references GDPR/nFADP | D29: Contract review
A30: ☐ | B30: Subprocessor list reviewed by Legal | D30: Legal sign-of
A31: ☐ | B31: Liability cap reasonable for service criticality | D31: Risk assessment
A32: ☐ | B32: Termination notice ≤90 days for non-critical services | D32: Contract terms
A33: ☐ | B33: Data return process documented with timeline | D33: Exit annex
A34: ☐ | B34: Insurance requirements verified (cyber liability) | D34: Insurance cert
A35: ☐ | B35: Governing law and jurisdiction acceptable | D35: Legal review
A36: ☐ | B36: DORA Art.30(2)(a): Clear service descriptions | D36: Contract clause
A37: ☐ | B37: DORA Art.30(2)(b): Data processing locations specified | D37: DPA/Contract
A38: ☐ | B38: DORA Art.30(2)(c): Subcontracting conditions defined | D38: Subprocessor annex
A39: ☐ | B39: DORA Art.30(2)(d): Full access and audit rights | D39: Audit clause
A40: ☐ | B40: DORA Art.30(2)(e): Cooperation with regulators | D40: Regulatory clause
... A45: ☐ | B45: NIS2: Vulnerability handling process defined | D45: Security annex

Sheet 4. SLA Performance
A1: SLA REQUIREMENTS & PERFORMANCE TRACKING Policy Requirement: SLAs must define availability, support response times, and performance penalties (Policy S2 Section 3.3)
A2: Assessment Question: Do all cloud services have documented SLAs with performance commitments?
A4: Cloud Service Name | B4: Vendor Name | C4: Service Type | D4: Service Criticality | E4: Data Classification | F4: Contract Type | G4: Contract Start Date | H4: Status | I4: Evidence Location | J4: Gap Description | K4: Remediation Needed | L4: Exception ID | M4: Risk ID | N4: Compensating Controls | O4: Vendor Contact (Legal) | P4: Target Remediation Date | Q4: Contract Owner | R4: SLA Availability % | S4: Actual Availability Q4 | T4: SLA Credits Claimed | U4: Support Response Time | V4: Incident Count Q4 | W4: Mean Time to Resolve | X4: SLA Review Date
A27: COMPLIANCE CHECKLIST
A28: ☐ | B28: Requirement | C28: Status | D28: Evidence Type
A29: ☐ | B29: SLA availability target documented (e.g., 99.9%) | D29: SLA document
A30: ☐ | B30: SLA credits/penalties defined for breaches | D30: SLA terms
A31: ☐ | B31: Support response times defined by severity | D31: Support matrix
A32: ☐ | B32: Incident escalation path documented | D32: Support procedures
A33: ☐ | B33: Planned maintenance notification requirements | D33: SLA terms
A34: ☐ | B34: Performance metrics reporting frequency defined | D34: SLA reporting
A35: ☐ | B35: SLA review cadence established (quarterly/annual) | D35: Contract terms
A36: ☐ | B36: Historical SLA performance reviewed | D36: Vendor reports

Sheet 5. Data Sovereignty
A1: DATA SOVEREIGNTY & COMPLIANCE Policy Requirement: Vendor data processing locations must comply with organisational data residency requirements (Policy S2 Section 3.4)
A2: Assessment Question: Do vendors comply with data sovereignty and regulatory requirements for your data?
A4: Cloud Service Name | B4: Vendor Name | C4: Service Type | D4: Service Criticality | E4: Data Classification | F4: Contract Type | G4: Contract Start Date | H4: Status | I4: Evidence Location | J4: Gap Description | K4: Remediation Needed | L4: Exception ID | M4: Risk ID | N4: Compensating Controls | O4: Vendor Contact (Legal) | P4: Target Remediation Date | Q4: Contract Owner | R4: Data Processing Region | S4: Data Residency Verified | T4: Standard Contractual Clauses | U4: Data Transfer Mechanism | V4: GDPR Compliance | W4: Swiss nFADP Compliance | X4: Regulatory Framework
A27: COMPLIANCE CHECKLIST
A28: ☐ | B28: Requirement | C28: Status | D28: Evidence Type
A29: ☐ | B29: Data processing locations documented | D29: DPA, vendor docs
A30: ☐ | B30: Data residency meets regulatory requirements | D30: Compliance review
A31: ☐ | B31: Standard Contractual Clauses (SCCs) in place | D31: DPA annex
A32: ☐ | B32: Transfer Impact Assessment completed | D32: TIA document
A33: ☐ | B33: GDPR compliance verified | D33: Compliance attestation
A34: ☐ | B34: Swiss nFADP compliance verified | D34: Compliance attestation
A35: ☐ | B35: Restricted data not processed outside approved regions | D35: Data mapping
A36: ☐ | B36: Sub-processor locations reviewed and approved | D36: Sub-processor list

Sheet 6. Forensics & Audit
A1: FORENSICS, AUDIT RIGHTS & INCIDENT RESPONSE Policy Requirement: Vendors must support forensic investigations and grant audit rights (Policy S2 Section 3.5)
A2: Assessment Question: Do vendors provide forensic capabilities, audit rights, and incident response support?
A4: Cloud Service Name | B4: Vendor Name | C4: Service Type | D4: Service Criticality | E4: Data Classification | F4: Contract Type | G4: Contract Start Date | H4: Status | I4: Evidence Location | J4: Gap Description | K4: Remediation Needed | L4: Exception ID | M4: Risk ID | N4: Compensating Controls | O4: Vendor Contact (Legal) | P4: Target Remediation Date | Q4: Contract Owner | R4: Forensics Support | S4: Forensics SLA | T4: Right to Audit | U4: Audit Notice Period | V4: Incident Notification SLA | W4: Breach Notification | X4: IR Playbook Provided
A27: COMPLIANCE CHECKLIST
A28: ☐ | B28: Requirement | C28: Status | D28: Evidence Type
A29: ☐ | B29: Forensics support verified for critical/high services | D29: Vendor capability
A30: ☐ | B30: Forensics SLA documented (log retention, data export) | D30: IR annex
A31: ☐ | B31: Right to audit clause in contract | D31: Contract clause
A32: ☐ | B32: Audit notice period ≤30 days for critical services | D32: Audit terms
A33: ☐ | B33: Incident notification SLA ≤24 hours | D33: Incident SLA
A34: ☐ | B34: Breach notification meets GDPR 72-hour requirement | D34: Breach clause
A35: ☐ | B35: Incident response playbook obtained and reviewed | D35: IR playbook
A36: ☐ | B36: Vendor participates in tabletop exercises (if critical) | D36: Exercise records

Sheet 7. Jurisdictional Risk
A1: JURISDICTIONAL RISK ASSESSMENT CLOUD Act, Data Sovereignty, and Cross-Border Transfer Analysis
A2: Policy Requirement: Assess jurisdictional risks for all cloud providers, particularly US-headquartered providers subject to CLOUD Act (Policy S5 Section 4)
A3: ⚠ US-headquartered providers (or providers with US parent companies) may be compelled to disclose data under CLOUD Act regardless of data location. Assess and document mitigations.
A5: Assessment ID | B5: Cloud Service Name | C5: Provider Name | D5: Provider HQ Country | E5: Provider HQ Jurisdiction | F5: US Parent Company | G5: CLOUD Act Applicability | H5: Data Processing Locations | I5: EU Data Boundary Available | J5: Customer Managed Keys | K5: Legal Challenge Commitment | L5: Adequacy Decision Status | M5: Transfer Mechanism | N5: Risk Level | O5: Risk Accepted By | P5: Risk Acceptance Date | Q5: Compensating Controls | R5: Review Date | S5: Evidence Reference | T5: Notes
A7: JRA-001 | B7: Microsoft 365 | C7: Microsoft Corporation | D7: United States | E7: United States | F7: No | G7: Mitigated (EU Data Boundary) | H7: EU, Switzerland (EU Data Boundary enabled) | I7: Yes | J7: Yes | K7: Yes | L7: Adequacy Decision (Swiss-US DPF) | M7: SCCs | N7: Medium | O7: CISO | P7: 2025-01-15 | Q7: EU Data Boundary + Customer Lockbox | R7: 2025-07-01 | S7: EV-JRA-001 | T7: Example entry - delete or overwrite
A8: JRA-002
A9: JRA-003
A10: JRA-004
A11: JRA-005
A12: JRA-006
A13: JRA-007
A14: JRA-008
A15: JRA-009
A16: JRA-010
A17: JRA-011
A18: JRA-012
A19: JRA-013
... A33: JURISDICTIONAL RISK CHECKLIST
A34: ☐ | B34: Requirement | C34: Status | D34: Evidence Type
A35: ☐ | B35: Provider HQ jurisdiction identified and documented | D35: Vendor documentation
A36: ☐ | B36: US parent company status verified | D36: Corporate structure review
A37: ☐ | B37: CLOUD Act exposure assessed for US-nexus providers | D37: Legal review
A38: ☐ | B38: Data processing locations documented in DPA | D38: DPA review
A39: ☐ | B39: EU Data Boundary availability checked | D39: Vendor announcement/docs
A40: ☐ | B40: Customer-managed encryption keys option evaluated | D40: Technical documentation
A41: ☐ | B41: Legal challenge commitment verified | D41: Contract/Public statement
A42: ☐ | B42: Transfer mechanism documented (SCCs, BCRs, etc.) | D42: DPA
A43: ☐ | B43: Risk acceptance recorded if residual risk remains | D43: Risk register
A44: ☐ | B44: Compensating controls documented for high-risk providers | D44: Control documentation
A47: CLOUD ACT MITIGATION STRATEGIES (Reference)
A48: • Technical: | B48: EU Data Boundary, Customer-managed encryption keys, Confidential Computing
A49: • Contractual: | B49: Legal challenge commitment, Data disclosure notification, SCCs with supplementary measures
A50: • Organisational: | B50: Risk acceptance by CISO/DPO, Documented risk assessment, Regular review cycle
A51: • Alternative: | B51: Consider EU-headquartered alternatives for highest-risk data categories

Sheet 8. Summary Dashboard
A1: VENDOR DUE DILIGENCE - COMPLIANCE SUMMARY DASHBOARD
A3: TABLE 1: COMPLIANCE SUMMARY BY ASSESSMENT AREA
A4: Assessment Area | B4: Total Vendors | C4: ✅ Compliant | D4: ⚠ Partial | E4: ❌ Non-Compliant | F4: N/A | G4: Compliance %
A5: Security Certifications | B5: =COUNTA('2. Security Certifications'!A7:A30)-COUNTBLANK('2. Security Certifications'!B7:B30) | C5: =COUNTIF('2. Security Certifications'!H5:H24,"✅*") | D5: =COUNTIF('2. Security Certifications'!H5:H24,"⚠*") | E5: =COUNTIF('2. Security Certifications'!H5:H24,"❌*") | F5: =COUNTIF('2. Security Certifications'!H5:H24,"N/A") | G5: =IF(B5=0,"N/A",ROUND((C5/(B5-F5))*100,1)&"%")
A6: Contract Terms | B6: =COUNTA('3. Contract Terms'!A7:A30)-COUNTBLANK('3. Contract Terms'!B7:B30) | C6: =COUNTIF('3. Contract Terms'!H5:H24,"✅*") | D6: =COUNTIF('3. Contract Terms'!H5:H24,"⚠*") | E6: =COUNTIF('3. Contract Terms'!H5:H24,"❌*") | F6: =COUNTIF('3. Contract Terms'!H5:H24,"N/A") | G6: =IF(B6=0,"N/A",ROUND((C6/(B6-F6))*100,1)&"%")
A7: SLA Performance | B7: =COUNTA('4. SLA Performance'!A7:A30)-COUNTBLANK('4. SLA Performance'!B7:B30) | C7: =COUNTIF('4. SLA Performance'!H5:H24,"✅*") | D7: =COUNTIF('4. SLA Performance'!H5:H24,"⚠*") | E7: =COUNTIF('4. SLA Performance'!H5:H24,"❌*") | F7: =COUNTIF('4. SLA Performance'!H5:H24,"N/A") | G7: =IF(B7=0,"N/A",ROUND((C7/(B7-F7))*100,1)&"%")
A8: Data Sovereignty | B8: =COUNTA('5. Data Sovereignty'!A7:A30)-COUNTBLANK('5. Data Sovereignty'!B7:B30) | C8: =COUNTIF('5. Data Sovereignty'!H5:H24,"✅*") | D8: =COUNTIF('5. Data Sovereignty'!H5:H24,"⚠*") | E8: =COUNTIF('5. Data Sovereignty'!H5:H24,"❌*") | F8: =COUNTIF('5. Data Sovereignty'!H5:H24,"N/A") | G8: =IF(B8=0,"N/A",ROUND((C8/(B8-F8))*100,1)&"%")
A9: Forensics & Audit | B9: =COUNTA('6. Forensics & Audit'!A7:A30)-COUNTBLANK('6. Forensics & Audit'!B7:B30) | C9: =COUNTIF('6. Forensics & Audit'!H5:H24,"✅*") | D9: =COUNTIF('6. Forensics & Audit'!H5:H24,"⚠*") | E9: =COUNTIF('6. Forensics & Audit'!H5:H24,"❌*") | F9: =COUNTIF('6. Forensics & Audit'!H5:H24,"N/A") | G9: =IF(B9=0,"N/A",ROUND((C9/(B9-F9))*100,1)&"%")
A10: Jurisdictional Risk | B10: =COUNTA('7. Jurisdictional Risk'!A7:A30)-COUNTBLANK('7. Jurisdictional Risk'!B7:B30) | C10: =COUNTIF('7. Jurisdictional Risk'!N7:N30,"Low")+COUNTIF('7. Jurisdictional Risk'!N7:N30,"Medium") | D10: =COUNTIF('7. Jurisdictional Risk'!N7:N30,"High") | E10: =COUNTIF('7. Jurisdictional Risk'!N7:N30,"Critical") | F10: =COUNTIF('7. Jurisdictional Risk'!N5:N24,"N/A") | G10: =IF(B10=0,"N/A",ROUND((C10/(B10-F10))*100,1)&"%")
A11: TOTAL | B11: =SUM(B5:B10) | C11: =SUM(C5:C10) | D11: =SUM(D5:D10) | E11: =SUM(E5:E10) | F11: =SUM(F5:F10) | G11: =IF(B11=0,"N/A",ROUND((C11/(B11-F11))*100,1)&"%")
A14: TABLE 2: JURISDICTIONAL & CLOUD ACT RISK SUMMARY
A16: Metric | B16: Count | C16: Status
A17: US-HQ Providers (CLOUD Act Scope) | B17: =COUNTIF('7. Jurisdictional Risk'!E7:E30,"United States") | C17: =IF(B17>0,"⚠ Review Required","✅ OK")
A18: Providers with US Parent Company | B18: =COUNTIF('7. Jurisdictional Risk'!F7:F30,"Yes") | C18: =IF(B18>0,"⚠ Review Required","✅ OK")
A19: CLOUD Act Potential Exposure (Unmitigated) | B19: =COUNTIF('7. Jurisdictional Risk'!G7:G30,"Potential*") | C19: =IF(B19>0,"⚠ Review Required","✅ OK")
A20: CLOUD Act Mitigated | B20: =COUNTIF('7. Jurisdictional Risk'!G7:G30,"Mitigated*") | C20: =IF(B20>0,"⚠ Review Required","✅ OK")
A21: High/Critical Jurisdictional Risk | B21: =COUNTIF('7. Jurisdictional Risk'!N7:N30,"High")+COUNTIF('7. Jurisdictional Risk'!N7:N30,"Critical") | C21: =IF(B21>0,"⚠ Review Required","✅ OK")
A22: Providers Without EU Data Boundary | B22: =COUNTIF('7. Jurisdictional Risk'!I7:I30,"No") | C22: =IF(B22>0,"⚠ Review Required","✅ OK")
A23: Providers Without Customer-Managed Keys | B23: =COUNTIF('7. Jurisdictional Risk'!J7:J30,"No") | C23: =IF(B23>0,"⚠ Review Required","✅ OK")
A26: TABLE 3: SECURITY CERTIFICATION STATUS
A27: Certification | B27: Yes (Current) | C27: Expired/Pending | D27: No/Unknown
A28: ISO 27001 | B28: =COUNTIF('2. Security Certifications'!R5:R24,"Yes (Current)") | C28: =COUNTIF('2. Security Certifications'!R5:R24,"Yes (Expired)") | D28: =COUNTIF('2. Security Certifications'!R5:R24,"No")+COUNTIF('2. Security Certifications'!R5:R24,"Unknown")
A29: SOC 2 Type II | B29: =COUNTIF('2. Security Certifications'!U5:U24,"Yes*") | C29: =0 | D29: =COUNTIF('2. Security Certifications'!U5:U24,"No")+COUNTIF('2. Security Certifications'!U5:U24,"Unknown")
A30: FedRAMP | B30: =COUNTIF('2. Security Certifications'!W5:W24,"Yes*") | C30: =0 | D30: =COUNTIF('2. Security Certifications'!W5:W24,"No")+COUNTIF('2. Security Certifications'!W5:W24,"N/A")
A33: TABLE 4: DATA SOVEREIGNTY RISKS
A34: Risk | B34: Count | C34: Severity
A35: Restricted Data Outside Switzerland/EU | B35: =COUNTIF('5. Data Sovereignty'!R5:R24,"USA")+COUNTIF('5. Data Sovereignty'!R5:R24,"Asia-Pacific") | C35: Critical
A36: Confidential Data Without SCCs | B36: =COUNTIF('5. Data Sovereignty'!T5:T24,"No") | C36: High
A37: GDPR Compliance Not Verified | B37: =COUNTIF('5. Data Sovereignty'!V5:V24,"No")+COUNTIF('5. Data Sovereignty'!V5:V24,"N/A") | C37: High

Sheet 9. Evidence Register
A1: EVIDENCE REGISTER - VENDOR DUE DILIGENCE & CONTRACTS
A2: Track all vendor contracts, certifications, and compliance documentation
A4: Evidence ID | B4: Vendor Name | C4: Evidence Type | D4: Description | E4: File Location / URL | F4: Document Date | G4: Expiry/Renewal Date | H4: Document Owner | I4: Status | J4: Notes
A5: EV-VDD-001
A6: EV-VDD-002
A7: EV-VDD-003
A8: EV-VDD-004
A9: EV-VDD-005
A10: EV-VDD-006
A11: EV-VDD-007
A12: EV-VDD-008
A13: EV-VDD-009
A14: EV-VDD-010
A15: EV-VDD-011
A16: EV-VDD-012
... A117: ☐ Risk acceptance forms signed for high-risk vendors

Sheet 10. Approval Sign-Of
A1: APPROVAL SIGN-OFF - VENDOR DUE DILIGENCE ASSESSMENT
A3: ASSESSMENT SUMMARY
A4: Assessment Completed By:
A5: Completion Date:
A6: Total Vendors Assessed: | B6: ='8. Summary Dashboard'!B10
A7: Overall Compliance %: | B7: ='8. Summary Dashboard'!G10
A8: Jurisdictional Risks Identified: | B8: ='8. Summary Dashboard'!B20
A9: Critical Issues Identified:
A10: Remediation Plan Attached:
A13: LEGAL REVIEW
A14: Reviewed By (Legal Counsel):
A15: Review Date:
A16: Contract Compliance Status:
A17: Jurisdictional Risk Acceptance:
A18: Legal Comments:
A21: PROCUREMENT REVIEW
A22: Reviewed By (Procurement):
A23: Review Date:
A24: Commercial Terms Status:
... A49: Special Considerations:
