Workbook

Sheet Executive Summary
A1: CLD-CHK-A.3 — Purpose Legitimacy and Specification Compliance Checklist
A3: DOCUMENT INFORMATION
A4: Document ID | B4: CLD-CHK-A.3
A5: Source Policy | B5: CLD-POL-A.3
A6: ISO Controls | B6: Purpose Legitimacy and Specification
A7: Generated | B7: 10.03.2026
A8: Prepared By
A9: Organisation
A10: Review Cycle | B10: Annual
A12: OVERALL COMPLIANCE STATUS
A13: Overall Compliance | B13: ='Dashboard'!G6
A14: Status | B14: =IF(Dashboard!G6="N/A","NOT ASSESSED",IF(ISNUMBER(VALUE(SUBSTITUTE(Dashboard!G6,"%",""))),IF(VALUE(SUBSTITUTE(Dashboard!G6,"%",""))>=90,"GREEN",IF(VALUE(SUBSTITUTE(Dashboard!G6,"%",""))>=70,"AMBER","RED")),"NOT ASSESSED"))
A16: KEY METRICS
A17: Total Requirements | B17: ='Dashboard'!B6
A18: Compliant | B18: ='Dashboard'!C6
A19: Partial | B19: ='Dashboard'!D6
A20: Non-Compliant | B20: ='Dashboard'!E6
A21: Not Applicable | B21: ='Dashboard'!F6
A22: Owner Coverage | B22: =IF(Dashboard!B6=0,"N/A",ROUND((COUNTA('Purpose Restriction'!F4:F7)+COUNTA('Commercial Use Prohibition'!F4:F7))/Dashboard!B6*100,0)&"%")
A24: DOMAIN STATUS SUMMARY
A25: Domain | B25: Compliance % | C25: Compliant | D25: Gaps | E25: Status
A26: Purpose Restriction | B26: ='Dashboard'!G4 | C26: ='Dashboard'!C4 | D26: ='Dashboard'!E4 | E26: =IF(Dashboard!G4="N/A","--",IF(ISNUMBER(VALUE(SUBSTITUTE(Dashboard!G4,"%",""))),IF(VALUE(SUBSTITUTE(Dashboard!G4,"%",""))>=90,"PASS",IF(VALUE(SUBSTITUTE(Dashboard!G4,"%",""))>=70,"REVIEW","FAIL")),"--"))
A27: Commercial Use Prohibition | B27: ='Dashboard'!G5 | C27: ='Dashboard'!C5 | D27: ='Dashboard'!E5 | E27: =IF(Dashboard!G5="N/A","--",IF(ISNUMBER(VALUE(SUBSTITUTE(Dashboard!G5,"%",""))),IF(VALUE(SUBSTITUTE(Dashboard!G5,"%",""))>=90,"PASS",IF(VALUE(SUBSTITUTE(Dashboard!G5,"%",""))>=70,"REVIEW","FAIL")),"--"))
A29: CRITICAL ISSUES
A30: # | B30: Issue Description | C30: Domain | D30: Owner | E30: Due Date
A31: 1
A32: 2
A33: 3
A34: 4
A35: 5
A37: MANAGEMENT COMMENTARY
A38: [Enter management commentary on purpose legitimacy and specification posture]
A42: APPROVAL
A43: Assessed By
A44: Name:
A45: Date:
A46: Signature:
A47: Decision:
A49: Reviewed By (DPO)
A50: Name:
...

Sheet Dashboard
A1: Purpose Legitimacy and Specification — Compliance Dashboard
A3: Domain | B3: Total Reqs | C3: Compliant | D3: Partial | E3: Non-Compliant | F3: N/A | G3: Compliance %
A4: Purpose Restriction | B4: =COUNTA('Purpose Restriction'!D4:D7) | C4: =COUNTIF('Purpose Restriction'!D4:D7,"Compliant") | D4: =COUNTIF('Purpose Restriction'!D4:D7,"Partial") | E4: =COUNTIF('Purpose Restriction'!D4:D7,"Non-Compliant") | F4: =COUNTIF('Purpose Restriction'!D4:D7,"N/A") | G4: =IF((B4-F4)=0,"N/A",ROUND(C4/(B4-F4)*100,1)&"%")
A5: Commercial Use Prohibition | B5: =COUNTA('Commercial Use Prohibition'!D4:D7) | C5: =COUNTIF('Commercial Use Prohibition'!D4:D7,"Compliant") | D5: =COUNTIF('Commercial Use Prohibition'!D4:D7,"Partial") | E5: =COUNTIF('Commercial Use Prohibition'!D4:D7,"Non-Compliant") | F5: =COUNTIF('Commercial Use Prohibition'!D4:D7,"N/A") | G5: =IF((B5-F5)=0,"N/A",ROUND(C5/(B5-F5)*100,1)&"%")
A6: TOTAL | B6: =SUM(B4:B5) | C6: =SUM(C4:C5) | D6: =SUM(D4:D5) | E6: =SUM(E4:E5) | F6: =SUM(F4:F5) | G6: =IF((B6-F6)=0,"N/A",ROUND(C6/(B6-F6)*100,1)&"%")
A8: COMPLIANCE BY STATUS
A9: Compliant | B9: =C6 | C9: =IF(B6=0,"",ROUND(B9/B6*100,1)&"%")
A10: Partial | B10: =D6 | C10: =IF(B6=0,"",ROUND(B10/B6*100,1)&"%")
A11: Non-Compliant | B11: =E6 | C11: =IF(B6=0,"",ROUND(B11/B6*100,1)&"%")
A12: N/A | B12: =F6 | C12: =IF(B6=0,"",ROUND(B12/B6*100,1)&"%")
A14: TOP GAPS (Manual Entry)
A15: Priority | B15: Domain | C15: Requirement | D15: Owner | E15: Due Date | F15: Status
A27: COMPLIANCE TREND (Manual Entry)
A28: Assessment Date | B28: Overall % | C28: Compliant | D28: Gaps | E28: Assessor | F28: Notes

Sheet Purpose Restriction
A1: Purpose Restriction — Compliance Checklist
A2: ISO/IEC 27018:2025 — Controls A.3.1-2: Purpose Legitimacy and Specification
A3: Req # | B3: Section | C3: Requirement | D3: Status | E3: Evidence | F3: Owner | G3: Due Date | H3: Notes
A4: A.3.1-01 | B4: Processing Restricted to Agreed Purposes | C4: The organisation shall process PII only for the purposes explicitly documented in the service agreement or written processing instructions received from the PII controller. Processing shall not be extended to new purposes without prior written controller authorisation.
A5: A.3.1-02 | B5: Processing Description in Agreements | C5: All cloud service agreements with PII controllers shall include a processing description specifying: the categories of PII to be processed; the purposes of processing; the processing operations to be performed; the duration of processing; and any permitted sub-processing arrangements.
A6: A.3.1-03 | B6: New Purpose Authorisation | C6: Where the organisation identifies an operational need to process PII for a purpose not covered by the current agreement, the organisation shall: document the proposed new purpose in writing; obtain written controller authorisation before processing begins; record the authorisation in the Processor Agreement Register; and cease the additional processing if authorisation is withheld or withdrawn.
A7: A.3.1-04 | B7: Operational Telemetry | C7: Service telemetry and operational metadata that incidentally contains PII shall be treated as PII subject to this policy. Telemetry PII retention shall be limited to the minimum period necessary for operational purposes and shall not be used for analytics, product improvement, or commercial purposes without controller authorisation.

Sheet Commercial Use Prohibition
A1: Commercial Use Prohibition — Compliance Checklist
A2: ISO/IEC 27018:2025 — Controls A.3.1-2: Purpose Legitimacy and Specification
A3: Req # | B3: Section | C3: Requirement | D3: Status | E3: Evidence | F3: Owner | G3: Due Date | H3: Notes
A4: A.3.2-01 | B4: Absolute Commercial Use Prohibition | C4: The organisation shall not use PII processed on behalf of a PII controller for any of the organisation's own commercial purposes, including: targeted advertising or ad profiling; sale or licensing of PII or derived datasets to third parties; training or improving machine learning models using PII; competitive intelligence gathering; or market research or customer analytics not directly supporting the contracted service. This prohibition applies regardless of aggregation or pseudonymisation unless DPO has confirmed genuine anonymisation in writing.
A5: A.3.2-02 | B5: Contractual Commitment | C5: Service agreements shall include an explicit clause confirming the commercial use prohibition. Any proposed commercial use arrangement (including arrangements involving genuinely anonymised data) shall be proposed to and agreed by the PII controller in writing before implementation, disclosed in the service agreement, and reviewed by the DPO and Legal/Compliance before execution.
A6: A.3.2-03 | B6: Technical Separation | C6: The organisation shall implement technical access controls separating controller PII from the organisation's internal product and analytics systems. The organisation's marketing and commercial teams shall be prohibited from accessing controller PII without DPO authorisation. The commercial use prohibition shall be included in employee training and confidentiality agreements.
A7: A.3.2-04 | B7: DPO Anonymisation Confirmation | C7: Where the organisation proposes to use data derived from controller PII on the basis that it is genuinely anonymised, a written DPO confirmation that the anonymisation is irreversible and meets the applicable regulatory standard shall be obtained before use. DPO confirmations shall be retained for the duration of use plus 3 years.
