Workbook

Sheet Executive Summary
A1: ISMS-OP-CHK-A.5.4 — Management Responsibilities Compliance Checklist
A3: DOCUMENT INFORMATION
A4: Document ID | B4: ISMS-OP-CHK-A.5.4
A5: Source Policy | B5: ISMS-OP-POL-A.5.4
A6: ISO Controls | B6: Management Responsibilities
A7: Generated | B7: 08.02.2026
A8: Prepared By
A9: Organisation
A10: Review Cycle | B10: Annual
A12: OVERALL COMPLIANCE STATUS
A13: Overall Compliance | B13: ='Dashboard'!G10
A14: Status | B14: =IF(Dashboard!G10="N/A","NOT ASSESSED",IF(ISNUMBER(VALUE(SUBSTITUTE(Dashboard!G10,"%",""))),IF(VALUE(SUBSTITUTE(Dashboard!G10,"%",""))>=90,"GREEN",IF(VALUE(SUBSTITUTE(Dashboard!G10,"%",""))>=70,"AMBER","RED")),"NOT ASSESSED"))
A16: KEY METRICS
A17: Total Requirements | B17: ='Dashboard'!B10
A18: Compliant | B18: ='Dashboard'!C10
A19: Partial | B19: ='Dashboard'!D10
A20: Non-Compliant | B20: ='Dashboard'!E10
A21: Not Applicable | B21: ='Dashboard'!F10
A22: Owner Coverage | B22: =IF(Dashboard!B10=0,"N/A",ROUND((COUNTA('Mgmt Commitment Requirements'!F4:F10)+COUNTA('Security Culture Leadership'!F4:F7)+COUNTA('Personnel Compl Accountability'!F4:F9)+COUNTA('Management Review Participation'!F4:F9)+COUNTA('Mgmt Commitment Assessment'!F4:F5)+COUNTA('Escalation Path'!F4:F4))/Dashboard!B10*100,0)&"%")
A24: DOMAIN STATUS SUMMARY
A25: Domain | B25: Compliance % | C25: Compliant | D25: Gaps | E25: Status
A26: Mgmt Commitment Requirements | B26: ='Dashboard'!G4 | C26: ='Dashboard'!C4 | D26: ='Dashboard'!E4 | E26: =IF(Dashboard!G4="N/A","--",IF(ISNUMBER(VALUE(SUBSTITUTE(Dashboard!G4,"%",""))),IF(VALUE(SUBSTITUTE(Dashboard!G4,"%",""))>=90,"PASS",IF(VALUE(SUBSTITUTE(Dashboard!G4,"%",""))>=70,"REVIEW","FAIL")),"--"))
A27: Security Culture Leadership | B27: ='Dashboard'!G5 | C27: ='Dashboard'!C5 | D27: ='Dashboard'!E5 | E27: =IF(Dashboard!G5="N/A","--",IF(ISNUMBER(VALUE(SUBSTITUTE(Dashboard!G5,"%",""))),IF(VALUE(SUBSTITUTE(Dashboard!G5,"%",""))>=90,"PASS",IF(VALUE(SUBSTITUTE(Dashboard!G5,"%",""))>=70,"REVIEW","FAIL")),"--"))
A28: Personnel Compl Accountability | B28: ='Dashboard'!G6 | C28: ='Dashboard'!C6 | D28: ='Dashboard'!E6 | E28: =IF(Dashboard!G6="N/A","--",IF(ISNUMBER(VALUE(SUBSTITUTE(Dashboard!G6,"%",""))),IF(VALUE(SUBSTITUTE(Dashboard!G6,"%",""))>=90,"PASS",IF(VALUE(SUBSTITUTE(Dashboard!G6,"%",""))>=70,"REVIEW","FAIL")),"--"))
A29: Management Review Participation | B29: ='Dashboard'!G7 | C29: ='Dashboard'!C7 | D29: ='Dashboard'!E7 | E29: =IF(Dashboard!G7="N/A","--",IF(ISNUMBER(VALUE(SUBSTITUTE(Dashboard!G7,"%",""))),IF(VALUE(SUBSTITUTE(Dashboard!G7,"%",""))>=90,"PASS",IF(VALUE(SUBSTITUTE(Dashboard!G7,"%",""))>=70,"REVIEW","FAIL")),"--"))
A30: Mgmt Commitment Assessment | B30: ='Dashboard'!G8 | C30: ='Dashboard'!C8 | D30: ='Dashboard'!E8 | E30: =IF(Dashboard!G8="N/A","--",IF(ISNUMBER(VALUE(SUBSTITUTE(Dashboard!G8,"%",""))),IF(VALUE(SUBSTITUTE(Dashboard!G8,"%",""))>=90,"PASS",IF(VALUE(SUBSTITUTE(Dashboard!G8,"%",""))>=70,"REVIEW","FAIL")),"--"))
A31: Escalation Path | B31: ='Dashboard'!G9 | C31: ='Dashboard'!C9 | D31: ='Dashboard'!E9 | E31: =IF(Dashboard!G9="N/A","--",IF(ISNUMBER(VALUE(SUBSTITUTE(Dashboard!G9,"%",""))),IF(VALUE(SUBSTITUTE(Dashboard!G9,"%",""))>=90,"PASS",IF(VALUE(SUBSTITUTE(Dashboard!G9,"%",""))>=70,"REVIEW","FAIL")),"--"))
A33: CRITICAL ISSUES
A34: # | B34: Issue Description | C34: Domain | D34: Owner | E34: Due Date
A35: 1
A36: 2
A37: 3
A38: 4
A39: 5
A41: MANAGEMENT COMMENTARY
A42: [Enter management commentary on management responsibilities posture]
A46: APPROVAL
A47: Assessed By
A48: Name:
A49: Date:
...

Sheet Dashboard
A1: Management Responsibilities — Compliance Dashboard
A3: Domain | B3: Total Reqs | C3: Compliant | D3: Partial | E3: Non-Compliant | F3: N/A | G3: Compliance %
A4: Mgmt Commitment Requirements | B4: =COUNTA('Mgmt Commitment Requirements'!D4:D10) | C4: =COUNTIF('Mgmt Commitment Requirements'!D4:D10,"Compliant") | D4: =COUNTIF('Mgmt Commitment Requirements'!D4:D10,"Partial") | E4: =COUNTIF('Mgmt Commitment Requirements'!D4:D10,"Non-Compliant") | F4: =COUNTIF('Mgmt Commitment Requirements'!D4:D10,"N/A") | G4: =IF((B4-F4)=0,"N/A",ROUND(C4/(B4-F4)*100,1)&"%")
A5: Security Culture Leadership | B5: =COUNTA('Security Culture Leadership'!D4:D7) | C5: =COUNTIF('Security Culture Leadership'!D4:D7,"Compliant") | D5: =COUNTIF('Security Culture Leadership'!D4:D7,"Partial") | E5: =COUNTIF('Security Culture Leadership'!D4:D7,"Non-Compliant") | F5: =COUNTIF('Security Culture Leadership'!D4:D7,"N/A") | G5: =IF((B5-F5)=0,"N/A",ROUND(C5/(B5-F5)*100,1)&"%")
A6: Personnel Compl Accountability | B6: =COUNTA('Personnel Compl Accountability'!D4:D9) | C6: =COUNTIF('Personnel Compl Accountability'!D4:D9,"Compliant") | D6: =COUNTIF('Personnel Compl Accountability'!D4:D9,"Partial") | E6: =COUNTIF('Personnel Compl Accountability'!D4:D9,"Non-Compliant") | F6: =COUNTIF('Personnel Compl Accountability'!D4:D9,"N/A") | G6: =IF((B6-F6)=0,"N/A",ROUND(C6/(B6-F6)*100,1)&"%")
A7: Management Review Participation | B7: =COUNTA('Management Review Participation'!D4:D9) | C7: =COUNTIF('Management Review Participation'!D4:D9,"Compliant") | D7: =COUNTIF('Management Review Participation'!D4:D9,"Partial") | E7: =COUNTIF('Management Review Participation'!D4:D9,"Non-Compliant") | F7: =COUNTIF('Management Review Participation'!D4:D9,"N/A") | G7: =IF((B7-F7)=0,"N/A",ROUND(C7/(B7-F7)*100,1)&"%")
A8: Mgmt Commitment Assessment | B8: =COUNTA('Mgmt Commitment Assessment'!D4:D5) | C8: =COUNTIF('Mgmt Commitment Assessment'!D4:D5,"Compliant") | D8: =COUNTIF('Mgmt Commitment Assessment'!D4:D5,"Partial") | E8: =COUNTIF('Mgmt Commitment Assessment'!D4:D5,"Non-Compliant") | F8: =COUNTIF('Mgmt Commitment Assessment'!D4:D5,"N/A") | G8: =IF((B8-F8)=0,"N/A",ROUND(C8/(B8-F8)*100,1)&"%")
A9: Escalation Path | B9: =COUNTA('Escalation Path'!D4:D4) | C9: =COUNTIF('Escalation Path'!D4:D4,"Compliant") | D9: =COUNTIF('Escalation Path'!D4:D4,"Partial") | E9: =COUNTIF('Escalation Path'!D4:D4,"Non-Compliant") | F9: =COUNTIF('Escalation Path'!D4:D4,"N/A") | G9: =IF((B9-F9)=0,"N/A",ROUND(C9/(B9-F9)*100,1)&"%")
A10: TOTAL | B10: =SUM(B4:B9) | C10: =SUM(C4:C9) | D10: =SUM(D4:D9) | E10: =SUM(E4:E9) | F10: =SUM(F4:F9) | G10: =IF((B10-F10)=0,"N/A",ROUND(C10/(B10-F10)*100,1)&"%")
A12: COMPLIANCE BY STATUS
A13: Compliant | B13: =C10 | C13: =IF(B10=0,"",ROUND(B13/B10*100,1)&"%")
A14: Partial | B14: =D10 | C14: =IF(B10=0,"",ROUND(B14/B10*100,1)&"%")
A15: Non-Compliant | B15: =E10 | C15: =IF(B10=0,"",ROUND(B15/B10*100,1)&"%")
A16: N/A | B16: =F10 | C16: =IF(B10=0,"",ROUND(B16/B10*100,1)&"%")
A18: TOP GAPS (Manual Entry)
A19: Priority | B19: Domain | C19: Requirement | D19: Owner | E19: Due Date | F19: Status
A31: COMPLIANCE TREND (Manual Entry)
A32: Assessment Date | B32: Overall % | C32: Compliant | D32: Gaps | E32: Assessor | F32: Notes

Sheet Mgmt Commitment Requirements
A1: Mgmt Commitment Requirements — Compliance Checklist
A2: ISO/IEC 27001:2022 — Control A.5.4: Management Responsibilities
A3: Req # | B3: Section | C3: Requirement | D3: Status | E3: Evidence | F3: Owner | G3: Due Date | H3: Notes
A4: A.5.4-01 | B4: Management Personnel | C4: All management personnel shall demonstrate active commitment to information security through:.
A5: A.5.4-02 | B5: Ensure Adequate Resources Are Available | C5: Management shall ensure adequate resources are available for information security:.
A6: A.5.4-03 | B6: Adequacy Criteria* For Resource | C6: Adequacy criteria* for resource allocation decisions shall consider:.
A7: A.5.4-04 | B7: Resource Requests For Approved Security | C7: Resource requests for approved security initiatives shall be processed within 30 calendar days. Disputes over resource adequacy shall be escalated per the escalation path defined in this policy.
A8: A.5.4-05 | B8: Ensure Their Teams Understand And Comply | C8: Management shall ensure their teams understand and comply with applicable security policies:.
A9: A.5.4-06 | B9: Management Commitment | C9: Management commitment shall be assessed annually using objective criteria:.
A10: A.5.4-07 | B10: Assessment Results | C10: Assessment results shall be documented and reviewed by Executive Management. Scores below 70% trigger a mandatory remediation plan (see Remediation for Non-Compliance).

Sheet Security Culture Leadership
A1: Security Culture Leadership — Compliance Checklist
A2: ISO/IEC 27001:2022 — Control A.5.4: Management Responsibilities
A3: Req # | B3: Section | C3: Requirement | D3: Status | E3: Evidence | F3: Owner | G3: Due Date | H3: Notes
A4: A.5.4-08 | B4: Foster A Positive Security Culture | C4: Management shall foster a positive security culture across the organisation through deliberate action and consistent example.
A5: A.5.4-09 | B5: Create An Environment Where Personnel | C5: Management shall create an environment where personnel feel safe reporting security issues:.
A6: A.5.4-10 | B6: Implement A Structured Recognition | C6: Management shall implement a structured recognition programme for security-conscious behaviour:.
A7: A.5.4-11 | B7: An Annual Security Culture Survey | C7: An annual Security Culture Survey shall be conducted to measure the effectiveness of management's security leadership and the organisation's overall security awareness posture.

Sheet Personnel Compl Accountability
A1: Personnel Compl Accountability — Compliance Checklist
A2: ISO/IEC 27001:2022 — Control A.5.4: Management Responsibilities
A3: Req # | B3: Section | C3: Requirement | D3: Status | E3: Evidence | F3: Owner | G3: Due Date | H3: Notes
A4: A.5.4-12 | B4: Ensure All Personnel Under Their | C4: Management shall ensure all personnel under their authority comply with information security requirements throughout the employment lifecycle.
A5: A.5.4-13 | B5: Verify That New Personnel Complete All | C5: Management shall verify that new personnel complete all security onboarding requirements before being granted system access.
A6: A.5.4-14 | B6: Access Gate*: System Access (Beyond | C6: Access gate*: System access (beyond basic email and intranet) shall not be provisioned until items 1-4 are confirmed complete. [Identity Provider] group assignment conditional on [LMS] training completion status.
A7: A.5.4-15 | B7: Maintain Continuous Oversight Of | C7: Management shall maintain continuous oversight of personnel compliance:.
A8: A.5.4-16 | B8: Important*: Security Performance | C8: Important*: Security performance criteria shall be communicated to personnel at the start of each review period. No individual shall be evaluated against criteria they were not informed of in advance.
A9: A.5.4-17 | B9: Ensure Timely And Complete Security | C9: Management shall ensure timely and complete security offboarding for departing personnel.

Sheet Management Review Participation
A1: Management Review Participation — Compliance Checklist
A2: ISO/IEC 27001:2022 — Control A.5.4: Management Responsibilities
A3: Req # | B3: Section | C3: Requirement | D3: Status | E3: Evidence | F3: Owner | G3: Due Date | H3: Notes
A4: A.5.4-18 | B4: Actively Participate In Isms Management | C4: Management shall actively participate in ISMS management review activities as required by ISO 27001:2022 Clause 9.3.
A5: A.5.4-19 | B5: Active Participation Means More Than | C5: Active participation means more than attendance. Management personnel shall:.
A6: A.5.4-20 | B6: Quarterly Management Review | C6: Each quarterly management review shall follow a standardised agenda to ensure consistent coverage and efficient use of executive time:.
A7: A.5.4-21 | B7: Provide The Following Inputs To Isms | C7: Management shall provide the following inputs to ISMS management reviews:.
A8: A.5.4-22 | B8: Within Management Reviews, Management | C8: Within management reviews, management personnel shall exercise their authority to:.
A9: A.5.4-23 | B9: Be Tracked And Reported As Part | C9: Participation shall be tracked and reported as part of the annual management commitment assessment.

Sheet Mgmt Commitment Assessment
A1: Mgmt Commitment Assessment — Compliance Checklist
A2: ISO/IEC 27001:2022 — Control A.5.4: Management Responsibilities
A3: Req # | B3: Section | C3: Requirement | D3: Status | E3: Evidence | F3: Owner | G3: Due Date | H3: Notes
A4: A.5.4-24 | B4: An Annual Management Commitment | C4: An annual Management Commitment Assessment shall be conducted by the CISO to evaluate management's fulfilment of their information security responsibilities. The assessment shall cover:.
A5: A.5.4-25 | B5: Management Responsibility Gaps | C5: All management responsibility gaps shall be recorded in the central ISMS Gap Register maintained in [GRC Tool / SharePoint / Confluence]. The Gap Register is the single source of truth for tracking management commitment findings across all assessment cycles.

Sheet Escalation Path
A1: Escalation Path — Compliance Checklist
A2: ISO/IEC 27001:2022 — Control A.5.4: Management Responsibilities
A3: Req # | B3: Section | C3: Requirement | D3: Status | E3: Evidence | F3: Owner | G3: Due Date | H3: Notes
A4: A.5.4-26 | B4: The Following Escalation Paths | C4: The following escalation paths shall be used for security-related matters:.
