Workbook

Sheet Instructions
A1: ISMS-IMP-A.8.28.2 – Standards & Tools Assessment
A2: ISO/IEC 27001:2022 - Control A.8.28: Secure Coding (Standards & Tools)
A4: DOCUMENT INFORMATION
A5: Document ID: | B5: ISMS-IMP-A.8.28.2
A6: Assessment Area: | B6: Secure Coding Standards & Security Tools
A7: Related Policy: | B7: ISMS-POL-A.8.28-S2.2 (Coding Standards), S2.3 (Code Review)
A8: Version: | B8: 1.0
A9: Assessment Date: | B9: [USER INPUT - Enter assessment date]
A10: Completed By: | B10: [USER INPUT - Enter assessor name]
A11: Organization: | B11: [USER INPUT - Enter organization name]
A12: Review Cycle: | B12: Quarterly or when tools/standards change
A15: HOW TO USE THIS WORKBOOK
A16: 1. Complete each assessment domain: Coding Standards → SAST/SCA → DAST → IDE Plugins → Tool Metrics
A17: 2. Assess DEPLOYMENT (is it there?) and EFFECTIVENESS (does it work?)
A18: 3. For tools: Don't just mark 'Implemented' if the tool exists - assess if it's configured and used properly
A19: 4. Provide specific tool names and versions (not just 'we have SAST')
A20: 5. Reference actual scan results, configuration files, and adoption metrics as evidence
A21: 6. Use Tool Effectiveness Metrics sheet to track measurable outcomes
A22: 7. Document gaps with specific remediation actions (not just 'improve tool')
A23: 8. Obtain approvals from both Security and Development leadership
A25: ⚠️ CRITICAL: Having a tool ≠ using it effectively. Focus on:
A26: • Is it configured with security rules? • Does it run automatically? • Are findings remediated?
A27: • What's the false positive rate? • Do developers actually use it?
A30: ASSESSMENT DOMAINS
A31: Domain | B31: Focus Area | C31: Requirements
A32: 1. Coding Standards Adoption | B32: Standards documentation, training, compliance measurement
A33: 2. SAST & SCA Tools | B33: Static analysis, dependency scanning, vulnerability detection
A34: 3. DAST & Security Testing Tools | B34: Dynamic testing, API testing, container/IaC scanning
A35: 4. IDE Plugins & Linters | B35: Developer tools, pre-commit hooks, real-time feedback
A36: 5. Tool Effectiveness & Metrics | B36: KPIs, coverage, false positives, remediation velocity
C37: 90 Total
A40: IMPLEMENTATION STATUS LEGEND
A41: Status | B41: Symbol | C41: Description | D41: When to Use
A42: Implemented | B42: ✅ | C42: Standard/tool deployed AND effective
A43: Partially Implemented | B43: ⚠️ | C43: Standard/tool exists but gaps in coverage/effectiveness
A44: Not Implemented | B44: ❌ | C44: Standard/tool not deployed
A45: N/A | B45: N/A | C45: Not applicable to environment
A48: ACCEPTABLE EVIDENCE (Examples)
A49: ✓ Secure coding standards documents (wiki links, PDFs, internal guidelines)
A50: ✓ Tool deployment documentation (licenses, access URLs, admin guides)
...

Sheet Coding_Standards_Adoption
A1: Standards & Tools Assessment: Coding Standards Adoption
A2: ID | B2: Requirement | C2: Implementation Status | D2: Evidence Reference | E2: Comments | F2: Compliance
A3: ▶ Standards Documentation
A4: 1.1 | B4: Organization has documented secure coding standards | D4: Secure coding standards document, developer wiki, internal guidelines | F4: =IF(C4="Implemented","✅",IF(C4="Partially Implemented","⚠️",IF(C4="Not Implemented","❌",IF(C4="N/A","N/A",""))))
A5: 1.2 | B5: Coding standards reference OWASP Top 10 and CWE Top 25 | D5: Standards document with OWASP/CWE mappings, policy references | F5: =IF(C5="Implemented","✅",IF(C5="Partially Implemented","⚠️",IF(C5="Not Implemented","❌",IF(C5="N/A","N/A",""))))
A6: 1.3 | B6: Standards cover input validation requirements for all languages used | D6: Language-specific input validation guidelines, code examples | F6: =IF(C6="Implemented","✅",IF(C6="Partially Implemented","⚠️",IF(C6="Not Implemented","❌",IF(C6="N/A","N/A",""))))
A7: 1.4 | B7: Standards cover output encoding/escaping requirements | D7: XSS prevention guidelines, encoding standards documentation | F7: =IF(C7="Implemented","✅",IF(C7="Partially Implemented","⚠️",IF(C7="Not Implemented","❌",IF(C7="N/A","N/A",""))))
A8: 1.5 | B8: Standards cover authentication and session management requirements | D8: Auth standards, session handling guidelines, JWT/token standards | F8: =IF(C8="Implemented","✅",IF(C8="Partially Implemented","⚠️",IF(C8="Not Implemented","❌",IF(C8="N/A","N/A",""))))
A9: 1.6 | B9: Standards cover cryptography requirements (algorithms, key management) | D9: Crypto standards, approved algorithms list, key management policies | F9: =IF(C9="Implemented","✅",IF(C9="Partially Implemented","⚠️",IF(C9="Not Implemented","❌",IF(C9="N/A","N/A",""))))
A10: 1.7 | B10: Standards cover error handling and logging requirements | D10: Logging standards, error handling patterns, log retention policies | F10: =IF(C10="Implemented","✅",IF(C10="Partially Implemented","⚠️",IF(C10="Not Implemented","❌",IF(C10="N/A","N/A",""))))
A11: ▶ Training & Awareness
A12: 1.8 | B12: Developers are trained on secure coding standards | D12: Training completion records, training materials, attendance logs | F12: =IF(C12="Implemented","✅",IF(C12="Partially Implemented","⚠️",IF(C12="Not Implemented","❌",IF(C12="N/A","N/A",""))))
A13: ▶ Accessibility
A14: 1.9 | B14: Secure coding standards are easily accessible to all developers | D14: Internal wiki links, IDE bookmarks, quick reference guides | F14: =IF(C14="Implemented","✅",IF(C14="Partially Implemented","⚠️",IF(C14="Not Implemented","❌",IF(C14="N/A","N/A",""))))
A15: ▶ Standards Maintenance
A16: 1.10 | B16: Standards are reviewed and updated at least annually | D16: Standards review schedule, change logs, version history | F16: =IF(C16="Implemented","✅",IF(C16="Partially Implemented","⚠️",IF(C16="Not Implemented","❌",IF(C16="N/A","N/A",""))))
A17: ▶ Standards Documentation
A18: 1.11 | B18: Language-specific secure coding guides exist for primary languages | D18: Python/Java/JavaScript/etc. specific security guidelines | F18: =IF(C18="Implemented","✅",IF(C18="Partially Implemented","⚠️",IF(C18="Not Implemented","❌",IF(C18="N/A","N/A",""))))
A19: 1.12 | B19: Standards include code examples (secure vs. insecure patterns) | D19: Code example repository, good/bad pattern documentation | F19: =IF(C19="Implemented","✅",IF(C19="Partially Implemented","⚠️",IF(C19="Not Implemented","❌",IF(C19="N/A","N/A",""))))
A20: ▶ Standards Enforcement
A21: 1.13 | B21: Compliance with standards is measured and tracked | D21: Compliance metrics, SAST rule compliance, audit results | F21: =IF(C21="Implemented","✅",IF(C21="Partially Implemented","⚠️",IF(C21="Not Implemented","❌",IF(C21="N/A","N/A",""))))
A22: 1.14 | B22: Standards violations are identified during code review | D22: Code review checklists, review comments, violation tracking | F22: =IF(C22="Implemented","✅",IF(C22="Partially Implemented","⚠️",IF(C22="Not Implemented","❌",IF(C22="N/A","N/A",""))))
A23: ▶ Standards Governance
A24: 1.15 | B24: Developers can request clarifications or exceptions to standards | D24: Exception request process, clarification tickets, security champion reviews | F24: =IF(C24="Implemented","✅",IF(C24="Partially Implemented","⚠️",IF(C24="Not Implemented","❌",IF(C24="N/A","N/A",""))))
A25: ▶ Standards Enforcement
A26: 1.16 | B26: Standards compliance is part of developer performance evaluation | D26: Performance review criteria, security KPIs for developers | F26: =IF(C26="Implemented","✅",IF(C26="Partially Implemented","⚠️",IF(C26="Not Implemented","❌",IF(C26="N/A","N/A",""))))
A27: ▶ Training & Awareness
A28: 1.17 | B28: Secure coding champions help developers apply standards | D28: Security champion program documentation, champion activity logs | F28: =IF(C28="Implemented","✅",IF(C28="Partially Implemented","⚠️",IF(C28="Not Implemented","❌",IF(C28="N/A","N/A",""))))
A29: 1.18 | B29: New hire onboarding includes secure coding standards training | D29: Onboarding checklist, new hire training materials, completion records | F29: =IF(C29="Implemented","✅",IF(C29="Partially Implemented","⚠️",IF(C29="Not Implemented","❌",IF(C29="N/A","N/A",""))))

Sheet SAST_SCA_Tools
A1: Standards & Tools Assessment: SAST & SCA Tools
A2: ID | B2: Requirement | C2: Implementation Status | D2: Evidence Reference | E2: Comments | F2: Compliance
A3: ▶ SAST Deployment
A4: 2.1 | B4: SAST (Static Application Security Testing) tool is deployed | D4: Tool license, deployment documentation, access credentials | F4: =IF(C4="Implemented","✅",IF(C4="Partially Implemented","⚠️",IF(C4="Not Implemented","❌",IF(C4="N/A","N/A",""))))
A5: ▶ SAST Configuration
A6: 2.2 | B6: SAST tool covers all primary programming languages used | D6: Language support documentation, configuration for each language | F6: =IF(C6="Implemented","✅",IF(C6="Partially Implemented","⚠️",IF(C6="Not Implemented","❌",IF(C6="N/A","N/A",""))))
A7: ▶ SAST Integration
A8: 2.3 | B8: SAST scans run automatically on every code commit/PR | D8: CI/CD integration config, pipeline logs showing SAST execution | F8: =IF(C8="Implemented","✅",IF(C8="Partially Implemented","⚠️",IF(C8="Not Implemented","❌",IF(C8="N/A","N/A",""))))
A9: ▶ SAST Configuration
A10: 2.4 | B10: SAST tool is configured with security-focused rulesets | D10: Ruleset configuration, enabled security rules list | F10: =IF(C10="Implemented","✅",IF(C10="Partially Implemented","⚠️",IF(C10="Not Implemented","❌",IF(C10="N/A","N/A",""))))
A11: 2.5 | B11: SAST findings are prioritized by severity (Critical/High/Medium/Low) | D11: Severity classification schema, findings dashboard | F11: =IF(C11="Implemented","✅",IF(C11="Partially Implemented","⚠️",IF(C11="Not Implemented","❌",IF(C11="N/A","N/A",""))))
A12: ▶ SAST Integration
A13: 2.6 | B13: Critical/High SAST findings block code deployment | D13: Quality gate configuration, blocked deployment logs | F13: =IF(C13="Implemented","✅",IF(C13="Partially Implemented","⚠️",IF(C13="Not Implemented","❌",IF(C13="N/A","N/A",""))))
A14: ▶ SAST Configuration
A15: 2.7 | B15: SAST false positives can be suppressed with justification | D15: Suppression process, suppression audit trail, justification records | F15: =IF(C15="Implemented","✅",IF(C15="Partially Implemented","⚠️",IF(C15="Not Implemented","❌",IF(C15="N/A","N/A",""))))
A16: ▶ SAST Remediation
A17: 2.8 | B17: SAST findings are tracked to resolution in ticketing system | D17: JIRA/Azure DevOps integration, vulnerability tracking tickets | F17: =IF(C17="Implemented","✅",IF(C17="Partially Implemented","⚠️",IF(C17="Not Implemented","❌",IF(C17="N/A","N/A",""))))
A18: ▶ SCA Deployment
A19: 2.9 | B19: SCA (Software Composition Analysis) tool is deployed | D19: Tool license, deployment documentation, access credentials | F19: =IF(C19="Implemented","✅",IF(C19="Partially Implemented","⚠️",IF(C19="Not Implemented","❌",IF(C19="N/A","N/A",""))))
A20: ▶ SCA Configuration
A21: 2.10 | B21: SCA tool scans all dependency manifests (package.json, pom.xml, etc.) | D21: Supported manifest files list, scan coverage reports | F21: =IF(C21="Implemented","✅",IF(C21="Partially Implemented","⚠️",IF(C21="Not Implemented","❌",IF(C21="N/A","N/A",""))))
A22: ▶ SCA Integration
A23: 2.11 | B23: SCA scans run automatically on every build | D23: CI/CD integration, build logs showing SCA execution | F23: =IF(C23="Implemented","✅",IF(C23="Partially Implemented","⚠️",IF(C23="Not Implemented","❌",IF(C23="N/A","N/A",""))))
A24: ▶ SCA Configuration
A25: 2.12 | B25: SCA tool checks for known vulnerabilities in dependencies (CVEs) | D25: Vulnerability database updates, CVE detection reports | F25: =IF(C25="Implemented","✅",IF(C25="Partially Implemented","⚠️",IF(C25="Not Implemented","❌",IF(C25="N/A","N/A",""))))
A26: 2.13 | B26: SCA tool checks for license compliance issues | D26: License policy configuration, license violation reports | F26: =IF(C26="Implemented","✅",IF(C26="Partially Implemented","⚠️",IF(C26="Not Implemented","❌",IF(C26="N/A","N/A",""))))
A27: ▶ SCA Integration
A28: 2.14 | B28: Critical/High vulnerability findings block deployment | D28: Quality gate configuration, blocked deployment logs | F28: =IF(C28="Implemented","✅",IF(C28="Partially Implemented","⚠️",IF(C28="Not Implemented","❌",IF(C28="N/A","N/A",""))))
A29: ▶ SCA Remediation
A30: 2.15 | B30: SCA tool provides remediation guidance (upgrade paths) | D30: Remediation recommendations, automated PR generation | F30: =IF(C30="Implemented","✅",IF(C30="Partially Implemented","⚠️",IF(C30="Not Implemented","❌",IF(C30="N/A","N/A",""))))
A31: 2.16 | B31: Dependency vulnerabilities have defined SLAs for remediation | D31: Vulnerability remediation SLA policy, SLA tracking metrics | F31: =IF(C31="Implemented","✅",IF(C31="Partially Implemented","⚠️",IF(C31="Not Implemented","❌",IF(C31="N/A","N/A",""))))
A32: ▶ Tool Governance
A33: 2.17 | B33: SAST and SCA findings are reviewed by security team regularly | D33: Security review meeting notes, findings triage records | F33: =IF(C33="Implemented","✅",IF(C33="Partially Implemented","⚠️",IF(C33="Not Implemented","❌",IF(C33="N/A","N/A",""))))
A34: ▶ Tool Effectiveness
A35: 2.18 | B35: Metrics track SAST/SCA finding trends and remediation velocity | D35: Security metrics dashboard, trend analysis reports | F35: =IF(C35="Implemented","✅",IF(C35="Partially Implemented","⚠️",IF(C35="Not Implemented","❌",IF(C35="N/A","N/A",""))))

Sheet DAST_Security_Testing_Tools
A1: Standards & Tools Assessment: DAST & Security Testing Tools
A2: ID | B2: Requirement | C2: Implementation Status | D2: Evidence Reference | E2: Comments | F2: Compliance
A3: ▶ DAST Deployment
A4: 3.1 | B4: DAST (Dynamic Application Security Testing) tool is deployed | D4: Tool license, deployment documentation, scanning infrastructure | F4: =IF(C4="Implemented","✅",IF(C4="Partially Implemented","⚠️",IF(C4="Not Implemented","❌",IF(C4="N/A","N/A",""))))
A5: ▶ DAST Configuration
A6: 3.2 | B6: DAST scans run against staging/pre-production environments | D6: Scan configuration, target environment documentation | F6: =IF(C6="Implemented","✅",IF(C6="Partially Implemented","⚠️",IF(C6="Not Implemented","❌",IF(C6="N/A","N/A",""))))
A7: ▶ DAST Integration
A8: 3.3 | B8: DAST scans are executed before production releases | D8: Release checklist with DAST requirement, scan reports | F8: =IF(C8="Implemented","✅",IF(C8="Partially Implemented","⚠️",IF(C8="Not Implemented","❌",IF(C8="N/A","N/A",""))))
A9: ▶ DAST Configuration
A10: 3.4 | B10: DAST tool tests for OWASP Top 10 vulnerabilities | D10: Scan policy configuration, OWASP Top 10 test coverage | F10: =IF(C10="Implemented","✅",IF(C10="Partially Implemented","⚠️",IF(C10="Not Implemented","❌",IF(C10="N/A","N/A",""))))
A11: 3.5 | B11: DAST scans include authenticated testing (logged-in scenarios) | D11: Authentication configuration, authenticated scan results | F11: =IF(C11="Implemented","✅",IF(C11="Partially Implemented","⚠️",IF(C11="Not Implemented","❌",IF(C11="N/A","N/A",""))))
A12: 3.6 | B12: DAST findings are classified by severity and risk | D12: Severity schema, risk scoring methodology | F12: =IF(C12="Implemented","✅",IF(C12="Partially Implemented","⚠️",IF(C12="Not Implemented","❌",IF(C12="N/A","N/A",""))))
A13: ▶ DAST Integration
A14: 3.7 | B14: Critical DAST findings block production deployment | D14: Release gate configuration, blocked release records | F14: =IF(C14="Implemented","✅",IF(C14="Partially Implemented","⚠️",IF(C14="Not Implemented","❌",IF(C14="N/A","N/A",""))))
A15: ▶ DAST Remediation
A16: 3.8 | B16: DAST false positives are validated and documented | D16: False positive validation process, validation records | F16: =IF(C16="Implemented","✅",IF(C16="Partially Implemented","⚠️",IF(C16="Not Implemented","❌",IF(C16="N/A","N/A",""))))
A17: ▶ API Testing
A18: 3.9 | B18: API security testing tools are deployed for API testing | D18: API testing tool documentation (Postman, REST Assured, etc.) | F18: =IF(C18="Implemented","✅",IF(C18="Partially Implemented","⚠️",IF(C18="Not Implemented","❌",IF(C18="N/A","N/A",""))))
A19: 3.10 | B19: API tests include authentication and authorization testing | D19: API test scenarios, auth bypass test cases | F19: =IF(C19="Implemented","✅",IF(C19="Partially Implemented","⚠️",IF(C19="Not Implemented","❌",IF(C19="N/A","N/A",""))))
A20: 3.11 | B20: API tests include input validation and injection testing | D20: API fuzzing results, injection test cases | F20: =IF(C20="Implemented","✅",IF(C20="Partially Implemented","⚠️",IF(C20="Not Implemented","❌",IF(C20="N/A","N/A",""))))
A21: ▶ Container Security
A22: 3.12 | B22: Container/image scanning tool is deployed | D22: Tool documentation (Trivy, Clair, Anchore), scan integration | F22: =IF(C22="Implemented","✅",IF(C22="Partially Implemented","⚠️",IF(C22="Not Implemented","❌",IF(C22="N/A","N/A",""))))
A23: 3.13 | B23: Container images are scanned before deployment | D23: Container scan results, vulnerability reports | F23: =IF(C23="Implemented","✅",IF(C23="Partially Implemented","⚠️",IF(C23="Not Implemented","❌",IF(C23="N/A","N/A",""))))
A24: ▶ IaC Security
A25: 3.14 | B25: IaC (Infrastructure-as-Code) scanning tool is deployed | D25: Tool documentation (Checkov, tfsec, Terrascan), scan config | F25: =IF(C25="Implemented","✅",IF(C25="Partially Implemented","⚠️",IF(C25="Not Implemented","❌",IF(C25="N/A","N/A",""))))
A26: 3.15 | B26: IaC is scanned for misconfigurations before deployment | D26: IaC scan results, misconfiguration findings | F26: =IF(C26="Implemented","✅",IF(C26="Partially Implemented","⚠️",IF(C26="Not Implemented","❌",IF(C26="N/A","N/A",""))))
A27: ▶ Testing Governance
A28: 3.16 | B28: Security testing results are archived for audit purposes | D28: Test result storage, historical scan archives | F28: =IF(C28="Implemented","✅",IF(C28="Partially Implemented","⚠️",IF(C28="Not Implemented","❌",IF(C28="N/A","N/A",""))))
A29: ▶ Penetration Testing
A30: 3.17 | B30: Penetration testing is performed annually for critical applications | D30: Pentest reports, remediation tracking, retest results | F30: =IF(C30="Implemented","✅",IF(C30="Partially Implemented","⚠️",IF(C30="Not Implemented","❌",IF(C30="N/A","N/A",""))))
A31: ▶ External Testing
A32: 3.18 | B32: Bug bounty or responsible disclosure program is active | D32: Bug bounty platform (HackerOne, Bugcrowd), submission records | F32: =IF(C32="Implemented","✅",IF(C32="Partially Implemented","⚠️",IF(C32="Not Implemented","❌",IF(C32="N/A","N/A",""))))

Sheet IDE_Plugins_Linters
A1: Standards & Tools Assessment: IDE Plugins & Linters
A2: ID | B2: Requirement | C2: Implementation Status | D2: Evidence Reference | E2: Comments | F2: Compliance
A3: ▶ IDE Plugins
A4: 4.1 | B4: Security-focused IDE plugins are available for developers | D4: Plugin catalog, installation guides, approved plugin list | F4: =IF(C4="Implemented","✅",IF(C4="Partially Implemented","⚠️",IF(C4="Not Implemented","❌",IF(C4="N/A","N/A",""))))
A5: 4.2 | B5: SAST IDE plugins provide real-time security feedback | D5: SonarLint, Snyk IDE plugin, or similar tool documentation | F5: =IF(C5="Implemented","✅",IF(C5="Partially Implemented","⚠️",IF(C5="Not Implemented","❌",IF(C5="N/A","N/A",""))))
A6: ▶ IDE Configuration
A7: 4.3 | B7: IDE plugins are integrated with organizational security policies | D7: Plugin configuration synced with SAST/SCA rules | F7: =IF(C7="Implemented","✅",IF(C7="Partially Implemented","⚠️",IF(C7="Not Implemented","❌",IF(C7="N/A","N/A",""))))
A8: ▶ IDE Adoption
A9: 4.4 | B9: IDE plugin adoption rate is measured and tracked | D9: Plugin telemetry, adoption metrics dashboard | F9: =IF(C9="Implemented","✅",IF(C9="Partially Implemented","⚠️",IF(C9="Not Implemented","❌",IF(C9="N/A","N/A",""))))
A10: ▶ IDE Training
A11: 4.5 | B11: Developers receive training on using IDE security plugins | D11: Plugin training materials, usage documentation | F11: =IF(C11="Implemented","✅",IF(C11="Partially Implemented","⚠️",IF(C11="Not Implemented","❌",IF(C11="N/A","N/A",""))))
A12: ▶ Linting
A13: 4.6 | B13: Code linters are configured with security rules | D13: Linter configuration files (eslint, pylint, rubocop), security rules enabled | F13: =IF(C13="Implemented","✅",IF(C13="Partially Implemented","⚠️",IF(C13="Not Implemented","❌",IF(C13="N/A","N/A",""))))
A14: 4.7 | B14: Linters run automatically in developer IDEs | D14: IDE linter integration, pre-commit hook configuration | F14: =IF(C14="Implemented","✅",IF(C14="Partially Implemented","⚠️",IF(C14="Not Implemented","❌",IF(C14="N/A","N/A",""))))
A15: 4.8 | B15: Linting rules are enforced in CI/CD pipeline | D15: Pipeline linting step, linting failure logs | F15: =IF(C15="Implemented","✅",IF(C15="Partially Implemented","⚠️",IF(C15="Not Implemented","❌",IF(C15="N/A","N/A",""))))
A16: ▶ Secret Prevention
A17: 4.9 | B17: Secret scanning pre-commit hooks are deployed | D17: Git hooks configuration (git-secrets, detect-secrets), hook installation | F17: =IF(C17="Implemented","✅",IF(C17="Partially Implemented","⚠️",IF(C17="Not Implemented","❌",IF(C17="N/A","N/A",""))))
A18: 4.10 | B18: Pre-commit hooks prevent commits containing secrets | D18: Blocked commit logs, secret detection examples | F18: =IF(C18="Implemented","✅",IF(C18="Partially Implemented","⚠️",IF(C18="Not Implemented","❌",IF(C18="N/A","N/A",""))))
A19: 4.11 | B19: Developers can bypass pre-commit hooks only with justification | D19: Bypass process documentation, bypass audit logs | F19: =IF(C19="Implemented","✅",IF(C19="Partially Implemented","⚠️",IF(C19="Not Implemented","❌",IF(C19="N/A","N/A",""))))
A20: ▶ Code Quality
A21: 4.12 | B21: Code formatting tools enforce consistent style | D21: Prettier, Black, gofmt configuration, formatting enforcement | F21: =IF(C21="Implemented","✅",IF(C21="Partially Implemented","⚠️",IF(C21="Not Implemented","❌",IF(C21="N/A","N/A",""))))
A22: 4.13 | B22: Complexity metrics are tracked (cyclomatic complexity, etc.) | D22: SonarQube complexity metrics, code quality dashboards | F22: =IF(C22="Implemented","✅",IF(C22="Partially Implemented","⚠️",IF(C22="Not Implemented","❌",IF(C22="N/A","N/A",""))))
A23: 4.14 | B23: Code coverage metrics are tracked and enforced | D23: Coverage reports, minimum coverage thresholds | F23: =IF(C23="Implemented","✅",IF(C23="Partially Implemented","⚠️",IF(C23="Not Implemented","❌",IF(C23="N/A","N/A",""))))
A24: ▶ Dependency Management
A25: 4.15 | B25: Dependency update tools provide automated update PRs | D25: Dependabot, Renovate Bot configuration, automated PRs | F25: =IF(C25="Implemented","✅",IF(C25="Partially Implemented","⚠️",IF(C25="Not Implemented","❌",IF(C25="N/A","N/A",""))))
A26: ▶ IDE Plugins
A27: 4.16 | B27: IDE plugins provide inline documentation for secure coding | D27: Context-aware security hints, inline documentation | F27: =IF(C27="Implemented","✅",IF(C27="Partially Implemented","⚠️",IF(C27="Not Implemented","❌",IF(C27="N/A","N/A",""))))
A28: ▶ Tool Governance
A29: 4.17 | B29: Developer feedback on tool usability is collected and acted upon | D29: Developer surveys, tool improvement backlog | F29: =IF(C29="Implemented","✅",IF(C29="Partially Implemented","⚠️",IF(C29="Not Implemented","❌",IF(C29="N/A","N/A",""))))
A30: 4.18 | B30: Tool performance impact on developer workflow is monitored | D30: Performance metrics, developer satisfaction scores | F30: =IF(C30="Implemented","✅",IF(C30="Partially Implemented","⚠️",IF(C30="Not Implemented","❌",IF(C30="N/A","N/A",""))))

Sheet Tool_Effectiveness_Metrics
A1: Standards & Tools Assessment: Tool Effectiveness & Metrics
A2: ID | B2: Requirement | C2: Implementation Status | D2: Evidence Reference | E2: Comments | F2: Compliance
A3: ▶ Metrics & Measurement
A4: 5.1 | B4: Security tool effectiveness is measured with KPIs | D4: KPI dashboard, effectiveness metrics definition | F4: =IF(C4="Implemented","✅",IF(C4="Partially Implemented","⚠️",IF(C4="Not Implemented","❌",IF(C4="N/A","N/A",""))))
A5: 5.2 | B5: Vulnerability detection rate is tracked per tool | D5: Detection metrics by tool, true positive rates | F5: =IF(C5="Implemented","✅",IF(C5="Partially Implemented","⚠️",IF(C5="Not Implemented","❌",IF(C5="N/A","N/A",""))))
A6: ▶ Tool Tuning
A7: 5.3 | B7: False positive rate is measured and minimized | D7: False positive metrics, tuning efforts documentation | F7: =IF(C7="Implemented","✅",IF(C7="Partially Implemented","⚠️",IF(C7="Not Implemented","❌",IF(C7="N/A","N/A",""))))
A8: ▶ Metrics & Measurement
A9: 5.4 | B9: Mean time to remediation (MTTR) is tracked for findings | D9: MTTR metrics, remediation velocity dashboard | F9: =IF(C9="Implemented","✅",IF(C9="Partially Implemented","⚠️",IF(C9="Not Implemented","❌",IF(C9="N/A","N/A",""))))
A10: ▶ Tool Coverage
A11: 5.5 | B11: Tool coverage is measured (% of codebase scanned) | D11: Coverage reports, unscanned code identification | F11: =IF(C11="Implemented","✅",IF(C11="Partially Implemented","⚠️",IF(C11="Not Implemented","❌",IF(C11="N/A","N/A",""))))
A12: ▶ Metrics & Measurement
A13: 5.6 | B13: Security tool findings trends are analyzed over time | D13: Trend analysis reports, historical metrics | F13: =IF(C13="Implemented","✅",IF(C13="Partially Implemented","⚠️",IF(C13="Not Implemented","❌",IF(C13="N/A","N/A",""))))
A14: ▶ Tool Governance
A15: 5.7 | B15: Tool costs are tracked and justified by value delivered | D15: Cost-benefit analysis, ROI documentation | F15: =IF(C15="Implemented","✅",IF(C15="Partially Implemented","⚠️",IF(C15="Not Implemented","❌",IF(C15="N/A","N/A",""))))
A16: ▶ Tool Performance
A17: 5.8 | B17: Tool performance (scan time, resource usage) is monitored | D17: Performance monitoring, scan duration metrics | F17: =IF(C17="Implemented","✅",IF(C17="Partially Implemented","⚠️",IF(C17="Not Implemented","❌",IF(C17="N/A","N/A",""))))
A18: ▶ Tool Integration
A19: 5.9 | B19: Duplicate findings across tools are identified and deduplicated | D19: Deduplication process, consolidated findings reports | F19: =IF(C19="Implemented","✅",IF(C19="Partially Implemented","⚠️",IF(C19="Not Implemented","❌",IF(C19="N/A","N/A",""))))
A20: ▶ Metrics & Measurement
A21: 5.10 | B21: Security findings are correlated with production incidents | D21: Incident analysis, finding-to-incident correlation reports | F21: =IF(C21="Implemented","✅",IF(C21="Partially Implemented","⚠️",IF(C21="Not Implemented","❌",IF(C21="N/A","N/A",""))))
A22: ▶ Tool Integration
A23: 5.11 | B23: Tool findings are integrated with vulnerability management system | D23: VM system integration, unified vulnerability tracking | F23: =IF(C23="Implemented","✅",IF(C23="Partially Implemented","⚠️",IF(C23="Not Implemented","❌",IF(C23="N/A","N/A",""))))
A24: ▶ Reporting
A25: 5.12 | B25: Security metrics are reported to management quarterly | D25: Management reports, executive dashboards | F25: =IF(C25="Implemented","✅",IF(C25="Partially Implemented","⚠️",IF(C25="Not Implemented","❌",IF(C25="N/A","N/A",""))))
A26: ▶ Tool Governance
A27: 5.13 | B27: Tool configuration changes are tracked and audited | D27: Configuration change logs, audit trails | F27: =IF(C27="Implemented","✅",IF(C27="Partially Implemented","⚠️",IF(C27="Not Implemented","❌",IF(C27="N/A","N/A",""))))
A28: 5.14 | B28: Tool licenses are managed and renewal dates tracked | D28: License management system, renewal calendar | F28: =IF(C28="Implemented","✅",IF(C28="Partially Implemented","⚠️",IF(C28="Not Implemented","❌",IF(C28="N/A","N/A",""))))
A29: ▶ Tool Selection
A30: 5.15 | B30: New tools are evaluated against security requirements | D30: Tool evaluation framework, POC results | F30: =IF(C30="Implemented","✅",IF(C30="Partially Implemented","⚠️",IF(C30="Not Implemented","❌",IF(C30="N/A","N/A",""))))
A31: ▶ Tool Maintenance
A32: 5.16 | B32: Tools are regularly updated to latest stable versions | D32: Tool version inventory, update schedule | F32: =IF(C32="Implemented","✅",IF(C32="Partially Implemented","⚠️",IF(C32="Not Implemented","❌",IF(C32="N/A","N/A",""))))
A33: ▶ Tool Effectiveness
A34: 5.17 | B34: Tool effectiveness is benchmarked against industry standards | D34: Benchmark comparison reports, industry metrics | F34: =IF(C34="Implemented","✅",IF(C34="Partially Implemented","⚠️",IF(C34="Not Implemented","❌",IF(C34="N/A","N/A",""))))
A35: ▶ Tool Governance
A36: 5.18 | B36: Continuous improvement process exists for tool optimization | D36: Improvement backlog, optimization initiatives | F36: =IF(C36="Implemented","✅",IF(C36="Partially Implemented","⚠️",IF(C36="Not Implemented","❌",IF(C36="N/A","N/A",""))))

Sheet Summary_Dashboard
A1: Standards & Tools Assessment - Summary Dashboard
A3: Assessment Date: | B3: =Instructions!B8
A4: Assessor: | B4: =Instructions!B9
A5: Organization: | B5: =Instructions!B10
A7: Overall Standards & Tools Compliance: | C7: =(COUNTIF(Coding_Standards_Adoption!C:C,"Implemented")+ COUNTIF(SAST_SCA_Tools!C:C,"Implemented")+ COUNTIF(DAST_Security_Testing_Tools!C:C,"Implemented")+ COUNTIF(IDE_Plugins_Linters!C:C,"Implemented")+ COUNTIF(Tool_Effectiveness_Metrics!C:C,"Implemented"))/ (COUNTA(Coding_Standards_Adoption!C:C)+ COUNTA(SAST_SCA_Tools!C:C)+ COUNTA(DAST_Security_Testing_Tools!C:C)+ COUNTA(IDE_Plugins_Linters!C:C)+ COUNTA(Tool_Effectiveness_Metrics!C:C)-5- COUNTIF(Coding_Standards_Adoption!C:C,"N/A")- COUNTIF(SAST_SCA_Tools!C:C,"N/A")- COUNTIF(DAST_Security_Testing_Tools!C:C,"N/A")- COUNTIF(IDE_Plugins_Linters!C:C,"N/A")- COUNTIF(Tool_Effectiveness_Metrics!C:C,"N/A")) | D7: =IF(C7>=0.8,"🟢 Compliant",IF(C7>=0.6,"🟡 Needs Improvement","🔴 Non-Compliant"))
A10: Domain Compliance Breakdown
A11: Domain | B11: Compliance % | C11: Status | D11: Not Implemented | E11: Partially Implemented
A12: 1. Coding Standards Adoption | B12: =COUNTIF(Coding_Standards_Adoption!C:C,"Implemented")/(COUNTA(Coding_Standards_Adoption!C:C)-1-COUNTIF(Coding_Standards_Adoption!C:C,"N/A")) | C12: =IF(B12>=0.8,"🟢",IF(B12>=0.6,"🟡","🔴")) | D12: =COUNTIF(Coding_Standards_Adoption!C:C,"Not Implemented") | E12: =COUNTIF(Coding_Standards_Adoption!C:C,"Partially Implemented")
A13: 2. SAST & SCA Tools | B13: =COUNTIF(SAST_SCA_Tools!C:C,"Implemented")/(COUNTA(SAST_SCA_Tools!C:C)-1-COUNTIF(SAST_SCA_Tools!C:C,"N/A")) | C13: =IF(B13>=0.8,"🟢",IF(B13>=0.6,"🟡","🔴")) | D13: =COUNTIF(SAST_SCA_Tools!C:C,"Not Implemented") | E13: =COUNTIF(SAST_SCA_Tools!C:C,"Partially Implemented")
A14: 3. DAST & Security Testing Tools | B14: =COUNTIF(DAST_Security_Testing_Tools!C:C,"Implemented")/(COUNTA(DAST_Security_Testing_Tools!C:C)-1-COUNTIF(DAST_Security_Testing_Tools!C:C,"N/A")) | C14: =IF(B14>=0.8,"🟢",IF(B14>=0.6,"🟡","🔴")) | D14: =COUNTIF(DAST_Security_Testing_Tools!C:C,"Not Implemented") | E14: =COUNTIF(DAST_Security_Testing_Tools!C:C,"Partially Implemented")
A15: 4. IDE Plugins & Linters | B15: =COUNTIF(IDE_Plugins_Linters!C:C,"Implemented")/(COUNTA(IDE_Plugins_Linters!C:C)-1-COUNTIF(IDE_Plugins_Linters!C:C,"N/A")) | C15: =IF(B15>=0.8,"🟢",IF(B15>=0.6,"🟡","🔴")) | D15: =COUNTIF(IDE_Plugins_Linters!C:C,"Not Implemented") | E15: =COUNTIF(IDE_Plugins_Linters!C:C,"Partially Implemented")
A16: 5. Tool Effectiveness & Metrics | B16: =COUNTIF(Tool_Effectiveness_Metrics!C:C,"Implemented")/(COUNTA(Tool_Effectiveness_Metrics!C:C)-1-COUNTIF(Tool_Effectiveness_Metrics!C:C,"N/A")) | C16: =IF(B16>=0.8,"🟢",IF(B16>=0.6,"🟡","🔴")) | D16: =COUNTIF(Tool_Effectiveness_Metrics!C:C,"Not Implemented") | E16: =COUNTIF(Tool_Effectiveness_Metrics!C:C,"Partially Implemented")

Sheet Evidence_Register
A1: Evidence Register
A2: Document all evidence supporting your Standards & Tools assessment.
A3: Evidence ID | B3: Related Requirement | C3: Evidence Type | D3: Description | E3: Location/Link | F3: Collection Date | G3: Collected By

Sheet Gap_Analysis
A1: Gap Analysis & Remediation Plan
A3: Gap ID | B3: Domain | C3: Requirement ID | D3: Requirement Description | E3: Current State | F3: Target State | G3: Priority | H3: Owner | I3: Target Date | J3: Status

Sheet Approval_Sign_Off
A1: Standards & Tools Assessment - Approval Sign-Off
A6: Assessment Date: | B6: =Instructions!B8
A7: Assessor Name: | B7: =Instructions!B9
A8: Overall Compliance Score: | B8: =Summary_Dashboard!C7
A11: APPROVAL WORKFLOW
A12: Role | B12: Name | C12: Signature | D12: Date
A13: Assessment Completer
A14: Application Security Lead
A15: Development Manager
A16: CISO
