Workbook

Sheet Instructions
A1: ISMS-IMP-A.8.28.3 – Code Review & Testing Assessment
A2: ISO/IEC 27001:2022 - Control A.8.28: Secure Coding (Code Review & Testing)
A4: DOCUMENT INFORMATION
A5: Document ID: | B5: ISMS-IMP-A.8.28.3
A6: Assessment Area: | B6: Secure Code Review & Security Testing
A7: Related Policy: | B7: ISMS-POL-A.8.28-S2.3 (Code Review & Testing)
A8: Version: | B8: 1.0
A9: Assessment Date: | B9: [USER INPUT - Enter assessment date]
A10: Completed By: | B10: [USER INPUT - Enter assessor name]
A11: Organization: | B11: [USER INPUT - Enter organization name]
A12: Review Cycle: | B12: Quarterly or when review/testing processes change
A15: HOW TO USE THIS WORKBOOK
A16: 1. Complete each assessment domain: Review Process → Champion Reviews → Unit/Integration Testing → API Testing → External Testing
A17: 2. Focus on EFFECTIVENESS, not just process existence
A18: 3. Ask: 'Does this review/test actually catch vulnerabilities before production?'
A19: 4. Sample actual code reviews to validate quality (not just process documentation)
A20: 5. Review test cases to ensure they test security-relevant behavior
A21: 6. Analyze metrics: What % of vulnerabilities are caught in review vs. testing vs. production?
A22: 7. Document gaps with specific, actionable remediation plans
A23: 8. Obtain approvals from both Security and Engineering leadership
A25: ⚠️ CRITICAL: Avoid 'Review Theater' and 'Test Theater'
A26: • 'LGTM' without security analysis is not a review
A27: • Tests that always pass don't test security
... A31: ASSESSMENT DOMAINS
A32: Domain | B32: Focus Area | C32: Requirements
A33: 1. Code Review Process & Governance | B33: Mandatory review, qualified reviewers, security checklists
A34: 2. Security Champion Review | B34: Champion program, architecture reviews, threat modeling
A35: 3. Security Testing - Unit & Integration | B35: Security test cases, auth/authz testing, test coverage
A36: 4. API & Application Security Testing | B36: API testing, injection testing, fuzzing, staging tests
A37: 5. External Testing & Continuous Validation | B37: Pentesting, bug bounty, regression tests, metrics
C38: 90 Total
A41: IMPLEMENTATION STATUS LEGEND
A42: Status | B42: Symbol | C42: Description | D42: When to Use
A43: Implemented | B43: ✅ | C43: Review/test is effective at catching vulnerabilities
A44: Partially Implemented | B44: ⚠️ | C44: Process exists but limited effectiveness
A45: Not Implemented | B45: ❌ | C45: Review/test process does not exist
A46: N/A | B46: N/A | C46: Not applicable to environment
A49: ACCEPTABLE EVIDENCE (Examples)
A50: ✓ Code review policy and procedures documentation
A51: ✓ Sample code reviews showing security analysis (not just 'LGTM')
...

Sheet Code_Review_Process
A1: Code Review & Testing Assessment: Code Review Process & Governance
A2: ID | B2: Requirement | C2: Implementation Status | D2: Evidence Reference | E2: Comments | F2: Compliance
A3: ▶ Review Policy
A4: 1.1 | B4: Peer review is mandatory for all production code changes | D4: Repository settings showing branch protection, review approval requirements | F4: =IF(C4="Implemented","✅",IF(C4="Partially Implemented","⚠️",IF(C4="Not Implemented","❌",IF(C4="N/A","N/A",""))))
A5: 1.2 | B5: Code review policy is documented and accessible to all developers | D5: Code review policy document, developer handbook, internal wiki | F5: =IF(C5="Implemented","✅",IF(C5="Partially Implemented","⚠️",IF(C5="Not Implemented","❌",IF(C5="N/A","N/A",""))))
A6: 1.3 | B6: Minimum reviewer qualifications are defined and enforced | D6: Reviewer qualification criteria, approved reviewer list | F6: =IF(C6="Implemented","✅",IF(C6="Partially Implemented","⚠️",IF(C6="Not Implemented","❌",IF(C6="N/A","N/A",""))))
A7: ▶ Reviewer Training
A8: 1.4 | B8: All reviewers are trained on secure code review practices | D8: Training completion records, secure code review training materials | F8: =IF(C8="Implemented","✅",IF(C8="Partially Implemented","⚠️",IF(C8="Not Implemented","❌",IF(C8="N/A","N/A",""))))
A9: ▶ Review Process
A10: 1.5 | B10: Security-focused checklist is used in all code reviews | D10: Code review checklist template, checklist usage in PR comments | F10: =IF(C10="Implemented","✅",IF(C10="Partially Implemented","⚠️",IF(C10="Not Implemented","❌",IF(C10="N/A","N/A",""))))
A11: ▶ Review Tools
A12: 1.6 | B12: Code review tools are integrated into development workflow | D12: GitHub/GitLab/Bitbucket PR process, review tool configuration | F12: =IF(C12="Implemented","✅",IF(C12="Partially Implemented","⚠️",IF(C12="Not Implemented","❌",IF(C12="N/A","N/A",""))))
A13: ▶ Review Enforcement
A14: 1.7 | B14: Review approval is required before code can be merged to production | D14: Branch protection rules, merge approval logs | F14: =IF(C14="Implemented","✅",IF(C14="Partially Implemented","⚠️",IF(C14="Not Implemented","❌",IF(C14="N/A","N/A",""))))
A15: ▶ Review Metrics
A16: 1.8 | B16: Code review coverage is measured and tracked | D16: Review coverage metrics dashboard, coverage reports | F16: =IF(C16="Implemented","✅",IF(C16="Partially Implemented","⚠️",IF(C16="Not Implemented","❌",IF(C16="N/A","N/A",""))))
A17: ▶ Review Quality
A18: 1.9 | B18: Review comments reference secure coding standards and best practices | D18: Sample review comments with standards references | F18: =IF(C18="Implemented","✅",IF(C18="Partially Implemented","⚠️",IF(C18="Not Implemented","❌",IF(C18="N/A","N/A",""))))
A19: ▶ Review Process
A20: 1.10 | B20: High-risk code changes require additional security review scrutiny | D20: Risk-based review policy, high-risk change review records | F20: =IF(C20="Implemented","✅",IF(C20="Partially Implemented","⚠️",IF(C20="Not Implemented","❌",IF(C20="N/A","N/A",""))))
A21: ▶ Review Follow-up
A22: 1.11 | B22: Security findings from code review are tracked to resolution | D22: Finding tracking system (JIRA, GitHub Issues), resolution logs | F22: =IF(C22="Implemented","✅",IF(C22="Partially Implemented","⚠️",IF(C22="Not Implemented","❌",IF(C22="N/A","N/A",""))))
A23: ▶ Review Metrics
A24: 1.12 | B24: Code review metrics are reported to management quarterly | D24: Quarterly review metrics reports, management dashboards | F24: =IF(C24="Implemented","✅",IF(C24="Partially Implemented","⚠️",IF(C24="Not Implemented","❌",IF(C24="N/A","N/A",""))))
A25: ▶ Review Enforcement
A26: 1.13 | B26: Review bypass requires documented approval and justification | D26: Exception request process, bypass approval records | F26: =IF(C26="Implemented","✅",IF(C26="Partially Implemented","⚠️",IF(C26="Not Implemented","❌",IF(C26="N/A","N/A",""))))
A27: ▶ Review Tools
A28: 1.14 | B28: Automated review assistance tools are deployed (PR bots, automated checks) | D28: PR bot integration (Danger, CodeOwners), automated check configuration | F28: =IF(C28="Implemented","✅",IF(C28="Partially Implemented","⚠️",IF(C28="Not Implemented","❌",IF(C28="N/A","N/A",""))))
A29: ▶ Review Quality
A30: 1.15 | B30: Code review quality is audited periodically | D30: Review quality audit results, sample review assessments | F30: =IF(C30="Implemented","✅",IF(C30="Partially Implemented","⚠️",IF(C30="Not Implemented","❌",IF(C30="N/A","N/A",""))))
A31: ▶ Review Policy
A32: 1.16 | B32: Self-review is not permitted for production code | D32: Review policy prohibiting self-approval, enforcement evidence | F32: =IF(C32="Implemented","✅",IF(C32="Partially Implemented","⚠️",IF(C32="Not Implemented","❌",IF(C32="N/A","N/A",""))))
A33: ▶ Review Metrics
A34: 1.17 | B34: Code review turnaround time is measured and within SLA | D34: Review SLA metrics, turnaround time tracking | F34: =IF(C34="Implemented","✅",IF(C34="Partially Implemented","⚠️",IF(C34="Not Implemented","❌",IF(C34="N/A","N/A",""))))
A35: ▶ Continuous Improvement
A36: 1.18 | B36: Code review process is continuously improved based on lessons learned | D36: Process improvement backlog, retrospective notes | F36: =IF(C36="Implemented","✅",IF(C36="Partially Implemented","⚠️",IF(C36="Not Implemented","❌",IF(C36="N/A","N/A",""))))

Sheet Security_Champion_Review
A1: Code Review & Testing Assessment: Security Champion Review & Architecture
A2: ID | B2: Requirement | C2: Implementation Status | D2: Evidence Reference | E2: Comments | F2: Compliance
A3: ▶ Champion Program
A4: 2.1 | B4: Security Champion program is formally established | D4: Program charter, Security Champion roster, program documentation | F4: =IF(C4="Implemented","✅",IF(C4="Partially Implemented","⚠️",IF(C4="Not Implemented","❌",IF(C4="N/A","N/A",""))))
A5: 2.2 | B5: Security Champions are assigned to all development teams | D5: Team assignments, Security Champion coverage matrix | F5: =IF(C5="Implemented","✅",IF(C5="Partially Implemented","⚠️",IF(C5="Not Implemented","❌",IF(C5="N/A","N/A",""))))
A6: ▶ Champion Training
A7: 2.3 | B7: Security Champions are trained on secure development and threat modeling | D7: Training certifications, secure development course completion records | F7: =IF(C7="Implemented","✅",IF(C7="Partially Implemented","⚠️",IF(C7="Not Implemented","❌",IF(C7="N/A","N/A",""))))
A8: ▶ Champion Process
A9: 2.4 | B9: Criteria for Security Champion review are clearly defined | D9: Review trigger criteria documentation (e.g., auth changes, crypto, PII) | F9: =IF(C9="Implemented","✅",IF(C9="Partially Implemented","⚠️",IF(C9="Not Implemented","❌",IF(C9="N/A","N/A",""))))
A10: 2.5 | B10: High-risk code changes are automatically escalated to Security Champions | D10: Escalation logs, Champion review records, automated escalation rules | F10: =IF(C10="Implemented","✅",IF(C10="Partially Implemented","⚠️",IF(C10="Not Implemented","❌",IF(C10="N/A","N/A",""))))
A11: ▶ Architecture Review
A12: 2.6 | B12: Architecture review is required for all new systems and major changes | D12: Architecture review policy, architecture review board meeting notes | F12: =IF(C12="Implemented","✅",IF(C12="Partially Implemented","⚠️",IF(C12="Not Implemented","❌",IF(C12="N/A","N/A",""))))
A13: 2.7 | B13: Security design review is performed before implementation begins | D13: Design review meeting notes, security design sign-off records | F13: =IF(C13="Implemented","✅",IF(C13="Partially Implemented","⚠️",IF(C13="Not Implemented","❌",IF(C13="N/A","N/A",""))))
A14: ▶ Threat Modeling
A15: 2.8 | B15: Threat modeling is performed for security-sensitive features | D15: Threat model documents, STRIDE analysis, attack trees | F15: =IF(C15="Implemented","✅",IF(C15="Partially Implemented","⚠️",IF(C15="Not Implemented","❌",IF(C15="N/A","N/A",""))))
A16: ▶ Champion Performance
A17: 2.9 | B17: Security Champion availability and response time are tracked and meet SLA | D17: Response time SLA metrics, Champion availability data | F17: =IF(C17="Implemented","✅",IF(C17="Partially Implemented","⚠️",IF(C17="Not Implemented","❌",IF(C17="N/A","N/A",""))))
A18: ▶ Champion Follow-up
A19: 2.10 | B19: Security Champion recommendations are tracked to implementation | D19: Recommendation tracking system, implementation verification | F19: =IF(C19="Implemented","✅",IF(C19="Partially Implemented","⚠️",IF(C19="Not Implemented","❌",IF(C19="N/A","N/A",""))))
A20: ▶ Champion Process
A21: 2.11 | B21: Clear escalation path exists from Champions to AppSec team | D21: Escalation procedures, escalation records, contact information | F21: =IF(C21="Implemented","✅",IF(C21="Partially Implemented","⚠️",IF(C21="Not Implemented","❌",IF(C21="N/A","N/A",""))))
A22: ▶ Champion Authority
A23: 2.12 | B23: Security Champions have authority to block releases for security issues | D23: Authority documentation, examples of Champion-blocked releases | F23: =IF(C23="Implemented","✅",IF(C23="Partially Implemented","⚠️",IF(C23="Not Implemented","❌",IF(C23="N/A","N/A",""))))
A24: ▶ Champion Metrics
A25: 2.13 | B25: Security Champion program effectiveness is measured with KPIs | D25: Program metrics dashboard, effectiveness assessment reports | F25: =IF(C25="Implemented","✅",IF(C25="Partially Implemented","⚠️",IF(C25="Not Implemented","❌",IF(C25="N/A","N/A",""))))
A26: ▶ Champion Program
A27: 2.14 | B27: Regular Security Champion sync meetings are held | D27: Meeting schedules, attendance records, meeting notes | F27: =IF(C27="Implemented","✅",IF(C27="Partially Implemented","⚠️",IF(C27="Not Implemented","❌",IF(C27="N/A","N/A",""))))
A28: ▶ Champion Resources
A29: 2.15 | B29: Security Champion knowledge base and playbooks are maintained | D29: Internal wiki, Security Champion playbooks, decision trees | F29: =IF(C29="Implemented","✅",IF(C29="Partially Implemented","⚠️",IF(C29="Not Implemented","❌",IF(C29="N/A","N/A",""))))
A30: ▶ Champion Training
A31: 2.16 | B31: New Security Champions are onboarded with systematic training plan | D31: Champion onboarding checklist, training plan documentation | F31: =IF(C31="Implemented","✅",IF(C31="Partially Implemented","⚠️",IF(C31="Not Implemented","❌",IF(C31="N/A","N/A",""))))
A32: ▶ Champion Program
A33: 2.17 | B33: Security Champion contributions are recognized and rewarded | D33: Recognition program documentation, awards, acknowledgments | F33: =IF(C33="Implemented","✅",IF(C33="Partially Implemented","⚠️",IF(C33="Not Implemented","❌",IF(C33="N/A","N/A",""))))
A34: ▶ Champion Training
A35: 2.18 | B35: Security Champions receive regular updates on emerging threats | D35: Threat intelligence briefings, security newsletters, training sessions | F35: =IF(C35="Implemented","✅",IF(C35="Partially Implemented","⚠️",IF(C35="Not Implemented","❌",IF(C35="N/A","N/A",""))))

Sheet Unit_Integration_Testing
A1: Code Review & Testing Assessment: Security Testing - Unit & Integration
A2: ID | B2: Requirement | C2: Implementation Status | D2: Evidence Reference | E2: Comments | F2: Compliance
A3: ▶ Test Coverage
A4: 3.1 | B4: Security test cases exist for all critical application functionality | D4: Security test suite, test case repository, test documentation | F4: =IF(C4="Implemented","✅",IF(C4="Partially Implemented","⚠️",IF(C4="Not Implemented","❌",IF(C4="N/A","N/A",""))))
A5: ▶ Unit Testing
A6: 3.2 | B6: Input validation is tested at the unit test level | D6: Input validation unit tests, boundary testing, malicious input tests | F6: =IF(C6="Implemented","✅",IF(C6="Partially Implemented","⚠️",IF(C6="Not Implemented","❌",IF(C6="N/A","N/A",""))))
A7: 3.3 | B7: Authentication logic is thoroughly tested with unit tests | D7: Authentication unit test suites, auth failure test cases | F7: =IF(C7="Implemented","✅",IF(C7="Partially Implemented","⚠️",IF(C7="Not Implemented","❌",IF(C7="N/A","N/A",""))))
A8: 3.4 | B8: Authorization checks are tested at unit and integration levels | D8: Authorization test cases, access control test matrices | F8: =IF(C8="Implemented","✅",IF(C8="Partially Implemented","⚠️",IF(C8="Not Implemented","❌",IF(C8="N/A","N/A",""))))
A9: ▶ Integration Testing
A10: 3.5 | B10: Session management security is tested | D10: Session security test cases, timeout testing, session fixation tests | F10: =IF(C10="Implemented","✅",IF(C10="Partially Implemented","⚠️",IF(C10="Not Implemented","❌",IF(C10="N/A","N/A",""))))
A11: ▶ Unit Testing
A12: 3.6 | B12: Cryptographic functions are tested for correct implementation | D12: Cryptography unit tests, key generation tests, encryption/decryption tests | F12: =IF(C12="Implemented","✅",IF(C12="Partially Implemented","⚠️",IF(C12="Not Implemented","❌",IF(C12="N/A","N/A",""))))
A13: 3.7 | B13: Error handling is tested to prevent information disclosure | D13: Error handling test scenarios, exception testing, stack trace prevention tests | F13: =IF(C13="Implemented","✅",IF(C13="Partially Implemented","⚠️",IF(C13="Not Implemented","❌",IF(C13="N/A","N/A",""))))
A14: ▶ Integration Testing
A15: 3.8 | B15: Integration tests validate end-to-end authentication/authorization workflows | D15: Integration test suites, workflow test scenarios | F15: =IF(C15="Implemented","✅",IF(C15="Partially Implemented","⚠️",IF(C15="Not Implemented","❌",IF(C15="N/A","N/A",""))))
A16: ▶ Test Metrics
A17: 3.9 | B17: Security test coverage is measured and tracked | D17: Test coverage metrics for security-critical code, coverage reports | F17: =IF(C17="Implemented","✅",IF(C17="Partially Implemented","⚠️",IF(C17="Not Implemented","❌",IF(C17="N/A","N/A",""))))
A18: ▶ Test Enforcement
A19: 3.10 | B19: Failed security tests block CI/CD pipeline deployment | D19: Pipeline configuration, test failure blocking evidence, failed build logs | F19: =IF(C19="Implemented","✅",IF(C19="Partially Implemented","⚠️",IF(C19="Not Implemented","❌",IF(C19="N/A","N/A",""))))
A20: ▶ Test Automation
A21: 3.11 | B21: Security tests run automatically on every code commit | D21: CI/CD configuration, test execution logs, automated test runs | F21: =IF(C21="Implemented","✅",IF(C21="Partially Implemented","⚠️",IF(C21="Not Implemented","❌",IF(C21="N/A","N/A",""))))
A22: ▶ Test Maintenance
A23: 3.12 | B23: Security test maintenance process exists and tests are kept current | D23: Test maintenance procedures, test update logs, deprecation handling | F23: =IF(C23="Implemented","✅",IF(C23="Partially Implemented","⚠️",IF(C23="Not Implemented","❌",IF(C23="N/A","N/A",""))))
A24: ▶ Test Quality
A25: 3.13 | B25: Security test cases are peer-reviewed like production code | D25: Test code review records, test PR approvals | F25: =IF(C25="Implemented","✅",IF(C25="Partially Implemented","⚠️",IF(C25="Not Implemented","❌",IF(C25="N/A","N/A",""))))
A26: ▶ Unit Testing
A27: 3.14 | B27: Negative test cases are included for security-critical functions | D27: Negative testing examples, failure mode testing | F27: =IF(C27="Implemented","✅",IF(C27="Partially Implemented","⚠️",IF(C27="Not Implemented","❌",IF(C27="N/A","N/A",""))))
A28: 3.15 | B28: Boundary condition testing is performed for input validation | D28: Boundary test cases, edge case testing, overflow testing | F28: =IF(C28="Implemented","✅",IF(C28="Partially Implemented","⚠️",IF(C28="Not Implemented","❌",IF(C28="N/A","N/A",""))))
A29: ▶ Integration Testing
A30: 3.16 | B30: Race condition testing is performed where applicable | D30: Concurrency test cases, threading tests, TOCTOU testing | F30: =IF(C30="Implemented","✅",IF(C30="Partially Implemented","⚠️",IF(C30="Not Implemented","❌",IF(C30="N/A","N/A",""))))
A31: ▶ Test Metrics
A32: 3.17 | B32: Security test results are archived for audit and trend analysis | D32: Test result storage, historical test data, trend reports | F32: =IF(C32="Implemented","✅",IF(C32="Partially Implemented","⚠️",IF(C32="Not Implemented","❌",IF(C32="N/A","N/A",""))))
A33: ▶ Test Environment
A34: 3.18 | B34: Test environment security is validated (no production data) | D34: Test environment security assessment, data handling procedures | F34: =IF(C34="Implemented","✅",IF(C34="Partially Implemented","⚠️",IF(C34="Not Implemented","❌",IF(C34="N/A","N/A",""))))

Sheet API_Application_Testing
A1: Code Review & Testing Assessment: API & Application Security Testing
A2: ID | B2: Requirement | C2: Implementation Status | D2: Evidence Reference | E2: Comments | F2: Compliance
A3: ▶ API Testing
A4: 4.1 | B4: All APIs (REST, GraphQL, gRPC) have dedicated security test suites | D4: API security test documentation, Postman/REST Assured collections | F4: =IF(C4="Implemented","✅",IF(C4="Partially Implemented","⚠️",IF(C4="Not Implemented","❌",IF(C4="N/A","N/A",""))))
A5: 4.2 | B5: API authentication mechanisms are thoroughly tested | D5: Auth testing scenarios (OAuth, JWT, API keys), token validation tests | F5: =IF(C5="Implemented","✅",IF(C5="Partially Implemented","⚠️",IF(C5="Not Implemented","❌",IF(C5="N/A","N/A",""))))
A6: 4.3 | B6: Authorization is tested for all API endpoints and operations | D6: Endpoint authorization test matrix, RBAC testing, privilege escalation tests | F6: =IF(C6="Implemented","✅",IF(C6="Partially Implemented","⚠️",IF(C6="Not Implemented","❌",IF(C6="N/A","N/A",""))))
A7: 4.4 | B7: Input validation is tested for all API parameters | D7: Input validation test cases, parameter fuzzing, type confusion tests | F7: =IF(C7="Implemented","✅",IF(C7="Partially Implemented","⚠️",IF(C7="Not Implemented","❌",IF(C7="N/A","N/A",""))))
A8: ▶ Injection Testing
A9: 4.5 | B9: SQL injection testing is performed on all database-backed APIs | D9: SQL injection test results, parameterized query validation | F9: =IF(C9="Implemented","✅",IF(C9="Partially Implemented","⚠️",IF(C9="Not Implemented","❌",IF(C9="N/A","N/A",""))))
A10: 4.6 | B10: Cross-Site Scripting (XSS) testing is performed | D10: XSS test scenarios, output encoding validation, CSP testing | F10: =IF(C10="Implemented","✅",IF(C10="Partially Implemented","⚠️",IF(C10="Not Implemented","❌",IF(C10="N/A","N/A",""))))
A11: 4.7 | B11: XXE and deserialization vulnerability testing is performed | D11: XXE test cases, unsafe deserialization tests, XML/JSON validation | F11: =IF(C11="Implemented","✅",IF(C11="Partially Implemented","⚠️",IF(C11="Not Implemented","❌",IF(C11="N/A","N/A",""))))
A12: ▶ API Testing
A13: 4.8 | B13: API fuzzing is performed to discover unexpected behavior | D13: Fuzzing tool results (Burp Intruder, ffuf, RESTler), crash reports | F13: =IF(C13="Implemented","✅",IF(C13="Partially Implemented","⚠️",IF(C13="Not Implemented","❌",IF(C13="N/A","N/A",""))))
A14: 4.9 | B14: API rate limiting and abuse prevention are tested | D14: Rate limit test evidence, DoS protection testing, throttling validation | F14: =IF(C14="Implemented","✅",IF(C14="Partially Implemented","⚠️",IF(C14="Not Implemented","❌",IF(C14="N/A","N/A",""))))
A15: 4.10 | B15: CORS configuration is validated for security | D15: CORS test results, origin validation tests, preflight testing | F15: =IF(C15="Implemented","✅",IF(C15="Partially Implemented","⚠️",IF(C15="Not Implemented","❌",IF(C15="N/A","N/A",""))))
A16: ▶ Application Testing
A17: 4.11 | B17: Security headers are validated in API responses | D17: Header validation tests (HSTS, CSP, X-Frame-Options, etc.) | F17: =IF(C17="Implemented","✅",IF(C17="Partially Implemented","⚠️",IF(C17="Not Implemented","❌",IF(C17="N/A","N/A",""))))
A18: ▶ API Testing
A19: 4.12 | B19: API error responses are tested for information disclosure | D19: Error response security tests, stack trace prevention validation | F19: =IF(C19="Implemented","✅",IF(C19="Partially Implemented","⚠️",IF(C19="Not Implemented","❌",IF(C19="N/A","N/A",""))))
A20: ▶ Test Environment
A21: 4.13 | B21: Staging/testing environment mirrors production security configuration | D21: Environment parity documentation, configuration comparison | F21: =IF(C21="Implemented","✅",IF(C21="Partially Implemented","⚠️",IF(C21="Not Implemented","❌",IF(C21="N/A","N/A",""))))
A22: 4.14 | B22: Test data is sanitized and does not include production data | D22: Test data management policy, data anonymization procedures | F22: =IF(C22="Implemented","✅",IF(C22="Partially Implemented","⚠️",IF(C22="Not Implemented","❌",IF(C22="N/A","N/A",""))))
A23: ▶ API Testing
A24: 4.15 | B24: API documentation is security-reviewed for sensitive information disclosure | D24: API documentation review records, Swagger/OpenAPI security review | F24: =IF(C24="Implemented","✅",IF(C24="Partially Implemented","⚠️",IF(C24="Not Implemented","❌",IF(C24="N/A","N/A",""))))
A25: 4.16 | B25: GraphQL-specific security testing is performed (if applicable) | D25: GraphQL introspection testing, query depth limiting, batching abuse tests | F25: =IF(C25="Implemented","✅",IF(C25="Partially Implemented","⚠️",IF(C25="Not Implemented","❌",IF(C25="N/A","N/A",""))))
A26: ▶ Application Testing
A27: 4.17 | B27: WebSocket security is tested (if applicable) | D27: WebSocket test scenarios, connection hijacking tests, message validation | F27: =IF(C27="Implemented","✅",IF(C27="Partially Implemented","⚠️",IF(C27="Not Implemented","❌",IF(C27="N/A","N/A",""))))
A28: ▶ API Testing
A29: 4.18 | B29: API versioning security is validated across versions | D29: Version security tests, deprecated endpoint validation, migration testing | F29: =IF(C29="Implemented","✅",IF(C29="Partially Implemented","⚠️",IF(C29="Not Implemented","❌",IF(C29="N/A","N/A",""))))

Sheet External_Testing_Validation
A1: Code Review & Testing Assessment: External Testing & Continuous Validation
A2: ID | B2: Requirement | C2: Implementation Status | D2: Evidence Reference | E2: Comments | F2: Compliance
A3: ▶ Penetration Testing
A4: 5.1 | B4: Annual penetration testing is performed for critical applications | D4: Penetration test reports from last 12 months, test schedules | F4: =IF(C4="Implemented","✅",IF(C4="Partially Implemented","⚠️",IF(C4="Not Implemented","❌",IF(C4="N/A","N/A",""))))
A5: 5.2 | B5: Penetration test scope covers all critical applications and APIs | D5: Pentest scope documentation, application inventory | F5: =IF(C5="Implemented","✅",IF(C5="Partially Implemented","⚠️",IF(C5="Not Implemented","❌",IF(C5="N/A","N/A",""))))
A6: 5.3 | B6: Penetration test findings are prioritized by risk and severity | D6: Risk-ranked findings list, severity classification methodology | F6: =IF(C6="Implemented","✅",IF(C6="Partially Implemented","⚠️",IF(C6="Not Implemented","❌",IF(C6="N/A","N/A",""))))
A7: ▶ Remediation
A8: 5.4 | B8: Critical pentest findings are remediated within 30 days | D8: Remediation tracking system, SLA compliance metrics | F8: =IF(C8="Implemented","✅",IF(C8="Partially Implemented","⚠️",IF(C8="Not Implemented","❌",IF(C8="N/A","N/A",""))))
A9: ▶ Penetration Testing
A10: 5.5 | B10: Penetration test retest validates that fixes are effective | D10: Retest reports, fix validation evidence | F10: =IF(C10="Implemented","✅",IF(C10="Partially Implemented","⚠️",IF(C10="Not Implemented","❌",IF(C10="N/A","N/A",""))))
A11: ▶ Bug Bounty
A12: 5.6 | B12: Bug bounty or responsible disclosure program is active | D12: Bug bounty platform documentation (HackerOne, Bugcrowd), program page | F12: =IF(C12="Implemented","✅",IF(C12="Partially Implemented","⚠️",IF(C12="Not Implemented","❌",IF(C12="N/A","N/A",""))))
A13: 5.7 | B13: Vulnerability disclosure policy is publicly published | D13: Published security.txt or vulnerability disclosure policy URL | F13: =IF(C13="Implemented","✅",IF(C13="Partially Implemented","⚠️",IF(C13="Not Implemented","❌",IF(C13="N/A","N/A",""))))
A14: 5.8 | B14: External vulnerability submissions are triaged within 48 hours | D14: Triage SLA metrics, response time tracking | F14: =IF(C14="Implemented","✅",IF(C14="Partially Implemented","⚠️",IF(C14="Not Implemented","❌",IF(C14="N/A","N/A",""))))
A15: 5.9 | B15: Security researcher communication is handled professionally | D15: Communication templates, researcher feedback, response examples | F15: =IF(C15="Implemented","✅",IF(C15="Partially Implemented","⚠️",IF(C15="Not Implemented","❌",IF(C15="N/A","N/A",""))))
A16: 5.10 | B16: Bug bounty payments are tracked and processed timely | D16: Payment records, payout tracking, bounty statistics | F16: =IF(C16="Implemented","✅",IF(C16="Partially Implemented","⚠️",IF(C16="Not Implemented","❌",IF(C16="N/A","N/A",""))))
A17: ▶ Regression Testing
A18: 5.11 | B18: Security regression tests exist for all past critical vulnerabilities | D18: Regression test suite, vulnerability-specific tests | F18: =IF(C18="Implemented","✅",IF(C18="Partially Implemented","⚠️",IF(C18="Not Implemented","❌",IF(C18="N/A","N/A",""))))
A19: 5.12 | B19: Security regression tests run automatically in CI/CD | D19: CI/CD regression test execution logs, test automation | F19: =IF(C19="Implemented","✅",IF(C19="Partially Implemented","⚠️",IF(C19="Not Implemented","❌",IF(C19="N/A","N/A",""))))
A20: ▶ Metrics
A21: 5.13 | B21: Security testing metrics are tracked over time | D21: Historical metrics dashboard, trend analysis | F21: =IF(C21="Implemented","✅",IF(C21="Partially Implemented","⚠️",IF(C21="Not Implemented","❌",IF(C21="N/A","N/A",""))))
A22: 5.14 | B22: Vulnerability trends are analyzed to identify patterns | D22: Vulnerability trend analysis reports, root cause analysis | F22: =IF(C22="Implemented","✅",IF(C22="Partially Implemented","⚠️",IF(C22="Not Implemented","❌",IF(C22="N/A","N/A",""))))
A23: 5.15 | B23: Testing effectiveness is measured with KPIs | D23: Testing effectiveness KPIs, detection rate metrics | F23: =IF(C23="Implemented","✅",IF(C23="Partially Implemented","⚠️",IF(C23="Not Implemented","❌",IF(C23="N/A","N/A",""))))
A24: ▶ Continuous Improvement
A25: 5.16 | B25: False negative analysis is performed after security incidents | D25: Post-incident analysis reports, testing gap assessments | F25: =IF(C25="Implemented","✅",IF(C25="Partially Implemented","⚠️",IF(C25="Not Implemented","❌",IF(C25="N/A","N/A",""))))
A26: 5.17 | B26: Testing gaps identified in incidents are addressed systematically | D26: Gap remediation plans, testing enhancement initiatives | F26: =IF(C26="Implemented","✅",IF(C26="Partially Implemented","⚠️",IF(C26="Not Implemented","❌",IF(C26="N/A","N/A",""))))
A27: 5.18 | B27: Continuous improvement process drives testing program evolution | D27: Improvement backlog, testing maturity roadmap | F27: =IF(C27="Implemented","✅",IF(C27="Partially Implemented","⚠️",IF(C27="Not Implemented","❌",IF(C27="N/A","N/A",""))))

Sheet Summary_Dashboard
A1: Code Review & Testing Assessment - Summary Dashboard
A3: Assessment Date: | B3: =Instructions!B8
A4: Assessor: | B4: =Instructions!B9
A5: Organization: | B5: =Instructions!B10
A7: Overall Code Review & Testing Compliance: | C7: =(COUNTIF(Code_Review_Process!C:C,"Implemented")+ COUNTIF(Security_Champion_Review!C:C,"Implemented")+ COUNTIF(Unit_Integration_Testing!C:C,"Implemented")+ COUNTIF(API_Application_Testing!C:C,"Implemented")+ COUNTIF(External_Testing_Validation!C:C,"Implemented"))/ (COUNTA(Code_Review_Process!C:C)+ COUNTA(Security_Champion_Review!C:C)+ COUNTA(Unit_Integration_Testing!C:C)+ COUNTA(API_Application_Testing!C:C)+ COUNTA(External_Testing_Validation!C:C)-5- COUNTIF(Code_Review_Process!C:C,"N/A")- COUNTIF(Security_Champion_Review!C:C,"N/A")- COUNTIF(Unit_Integration_Testing!C:C,"N/A")- COUNTIF(API_Application_Testing!C:C,"N/A")- COUNTIF(External_Testing_Validation!C:C,"N/A")) | D7: =IF(C7>=0.8,"🟢 Compliant",IF(C7>=0.6,"🟡 Needs Improvement","🔴 Non-Compliant"))
A10: Domain Compliance Breakdown
A11: Domain | B11: Compliance % | C11: Status | D11: Not Implemented | E11: Partially Implemented
A12: 1. Code Review Process & Governance | B12: =COUNTIF(Code_Review_Process!C:C,"Implemented")/(COUNTA(Code_Review_Process!C:C)-1-COUNTIF(Code_Review_Process!C:C,"N/A")) | C12: =IF(B12>=0.8,"🟢",IF(B12>=0.6,"🟡","🔴")) | D12: =COUNTIF(Code_Review_Process!C:C,"Not Implemented") | E12: =COUNTIF(Code_Review_Process!C:C,"Partially Implemented")
A13: 2. Security Champion Review & Architecture | B13: =COUNTIF(Security_Champion_Review!C:C,"Implemented")/(COUNTA(Security_Champion_Review!C:C)-1-COUNTIF(Security_Champion_Review!C:C,"N/A")) | C13: =IF(B13>=0.8,"🟢",IF(B13>=0.6,"🟡","🔴")) | D13: =COUNTIF(Security_Champion_Review!C:C,"Not Implemented") | E13: =COUNTIF(Security_Champion_Review!C:C,"Partially Implemented")
A14: 3. Security Testing - Unit & Integration | B14: =COUNTIF(Unit_Integration_Testing!C:C,"Implemented")/(COUNTA(Unit_Integration_Testing!C:C)-1-COUNTIF(Unit_Integration_Testing!C:C,"N/A")) | C14: =IF(B14>=0.8,"🟢",IF(B14>=0.6,"🟡","🔴")) | D14: =COUNTIF(Unit_Integration_Testing!C:C,"Not Implemented") | E14: =COUNTIF(Unit_Integration_Testing!C:C,"Partially Implemented")
A15: 4. API & Application Security Testing | B15: =COUNTIF(API_Application_Testing!C:C,"Implemented")/(COUNTA(API_Application_Testing!C:C)-1-COUNTIF(API_Application_Testing!C:C,"N/A")) | C15: =IF(B15>=0.8,"🟢",IF(B15>=0.6,"🟡","🔴")) | D15: =COUNTIF(API_Application_Testing!C:C,"Not Implemented") | E15: =COUNTIF(API_Application_Testing!C:C,"Partially Implemented")
A16: 5. External Testing & Continuous Validation | B16: =COUNTIF(External_Testing_Validation!C:C,"Implemented")/(COUNTA(External_Testing_Validation!C:C)-1-COUNTIF(External_Testing_Validation!C:C,"N/A")) | C16: =IF(B16>=0.8,"🟢",IF(B16>=0.6,"🟡","🔴")) | D16: =COUNTIF(External_Testing_Validation!C:C,"Not Implemented") | E16: =COUNTIF(External_Testing_Validation!C:C,"Partially Implemented")
A19: Key Assessment Insights
A20: • Focus on EFFECTIVENESS: Do reviews and tests actually catch vulnerabilities?
A21: • Sample actual code reviews to validate quality of security analysis
A22: • Review test cases to ensure they test security-relevant behavior
A23: • Analyze: Where are vulnerabilities found? Review → Testing → Production?
A24: • If pentests find trivial issues, internal testing is failing

Sheet Evidence_Register
A1: Evidence Register
A2: Document all evidence supporting your Code Review & Testing assessment.
A3: Evidence ID | B3: Related Requirement | C3: Evidence Type | D3: Description | E3: Location/Link | F3: Collection Date | G3: Collected By

Sheet Gap_Analysis
A1: Gap Analysis & Remediation Plan
A3: Gap ID | B3: Domain | C3: Requirement ID | D3: Requirement Description | E3: Current State | F3: Target State | G3: Priority | H3: Owner | I3: Target Date | J3: Status

Sheet Approval_Sign_Off
A1: Code Review & Testing Assessment - Approval Sign-Off
A6: Assessment Date: | B6: =Instructions!B8
A7: Assessor Name: | B7: =Instructions!B9
A8: Overall Compliance Score: | B8: =Summary_Dashboard!C7
A11: APPROVAL WORKFLOW
A12: Role | B12: Name | C12: Signature | D12: Date
A13: Assessment Completer
A14: Application Security Lead
A15: Development Manager
A16: QA Manager
A17: CISO
