Workbook

Sheet Executive Summary
A1: ISMS-OP-CHK-A.8.31 — Separation of Development, Test and Production Environments Compliance Checklist
A3: DOCUMENT INFORMATION
A4: Document ID | B4: ISMS-OP-CHK-A.8.31
A5: Source Policy | B5: ISMS-OP-POL-A.8.31
A6: ISO Controls | B6: Separation of Development, Test and Production Environments
A7: Generated | B7: 08.02.2026
A8: Prepared By
A9: Organisation
A10: Review Cycle | B10: Annual
A12: OVERALL COMPLIANCE STATUS
A13: Overall Compliance | B13: ='Dashboard'!G13
A14: Status | B14: =IF(Dashboard!G13="N/A","NOT ASSESSED",IF(ISNUMBER(VALUE(SUBSTITUTE(Dashboard!G13,"%",""))),IF(VALUE(SUBSTITUTE(Dashboard!G13,"%",""))>=90,"GREEN",IF(VALUE(SUBSTITUTE(Dashboard!G13,"%",""))>=70,"AMBER","RED")),"NOT ASSESSED"))
A16: KEY METRICS
A17: Total Requirements | B17: ='Dashboard'!B13
A18: Compliant | B18: ='Dashboard'!C13
A19: Partial | B19: ='Dashboard'!D13
A20: Non-Compliant | B20: ='Dashboard'!E13
A21: Not Applicable | B21: ='Dashboard'!F13
A22: Owner Coverage | B22: =IF(Dashboard!B13=0,"N/A",ROUND((COUNTA('Network Separation'!F4:F16)+COUNTA('Access Control per Environment'!F4:F11)+COUNTA('Data Handling Rules'!F4:F11)+COUNTA('Test Data Management'!F4:F15)+COUNTA('Code Promotion Process'!F4:F18)+COUNTA('Configuration Separation'!F4:F11)+COUNTA('Cloud Environment Separation'!F4:F11)+COUNTA('Env Sep and Incident Response'!F4:F4)+COUNTA('Compliance Measurement'!F4:F5))/Dashboard!B13*100,0)&"%")
A24: DOMAIN STATUS SUMMARY
A25: Domain | B25: Compliance % | C25: Compliant | D25: Gaps | E25: Status
A26: Network Separation | B26: ='Dashboard'!G4 | C26: ='Dashboard'!C4 | D26: ='Dashboard'!E4 | E26: =IF(Dashboard!G4="N/A","--",IF(ISNUMBER(VALUE(SUBSTITUTE(Dashboard!G4,"%",""))),IF(VALUE(SUBSTITUTE(Dashboard!G4,"%",""))>=90,"PASS",IF(VALUE(SUBSTITUTE(Dashboard!G4,"%",""))>=70,"REVIEW","FAIL")),"--"))
A27: Access Control per Environment | B27: ='Dashboard'!G5 | C27: ='Dashboard'!C5 | D27: ='Dashboard'!E5 | E27: =IF(Dashboard!G5="N/A","--",IF(ISNUMBER(VALUE(SUBSTITUTE(Dashboard!G5,"%",""))),IF(VALUE(SUBSTITUTE(Dashboard!G5,"%",""))>=90,"PASS",IF(VALUE(SUBSTITUTE(Dashboard!G5,"%",""))>=70,"REVIEW","FAIL")),"--"))
A28: Data Handling Rules | B28: ='Dashboard'!G6 | C28: ='Dashboard'!C6 | D28: ='Dashboard'!E6 | E28: =IF(Dashboard!G6="N/A","--",IF(ISNUMBER(VALUE(SUBSTITUTE(Dashboard!G6,"%",""))),IF(VALUE(SUBSTITUTE(Dashboard!G6,"%",""))>=90,"PASS",IF(VALUE(SUBSTITUTE(Dashboard!G6,"%",""))>=70,"REVIEW","FAIL")),"--"))
A29: Test Data Management | B29: ='Dashboard'!G7 | C29: ='Dashboard'!C7 | D29: ='Dashboard'!E7 | E29: =IF(Dashboard!G7="N/A","--",IF(ISNUMBER(VALUE(SUBSTITUTE(Dashboard!G7,"%",""))),IF(VALUE(SUBSTITUTE(Dashboard!G7,"%",""))>=90,"PASS",IF(VALUE(SUBSTITUTE(Dashboard!G7,"%",""))>=70,"REVIEW","FAIL")),"--"))
A30: Code Promotion Process | B30: ='Dashboard'!G8 | C30: ='Dashboard'!C8 | D30: ='Dashboard'!E8 | E30: =IF(Dashboard!G8="N/A","--",IF(ISNUMBER(VALUE(SUBSTITUTE(Dashboard!G8,"%",""))),IF(VALUE(SUBSTITUTE(Dashboard!G8,"%",""))>=90,"PASS",IF(VALUE(SUBSTITUTE(Dashboard!G8,"%",""))>=70,"REVIEW","FAIL")),"--"))
A31: Configuration Separation | B31: ='Dashboard'!G9 | C31: ='Dashboard'!C9 | D31: ='Dashboard'!E9 | E31: =IF(Dashboard!G9="N/A","--",IF(ISNUMBER(VALUE(SUBSTITUTE(Dashboard!G9,"%",""))),IF(VALUE(SUBSTITUTE(Dashboard!G9,"%",""))>=90,"PASS",IF(VALUE(SUBSTITUTE(Dashboard!G9,"%",""))>=70,"REVIEW","FAIL")),"--"))
A32: Cloud Environment Separation | B32: ='Dashboard'!G10 | C32: ='Dashboard'!C10 | D32: ='Dashboard'!E10 | E32: =IF(Dashboard!G10="N/A","--",IF(ISNUMBER(VALUE(SUBSTITUTE(Dashboard!G10,"%",""))),IF(VALUE(SUBSTITUTE(Dashboard!G10,"%",""))>=90,"PASS",IF(VALUE(SUBSTITUTE(Dashboard!G10,"%",""))>=70,"REVIEW","FAIL")),"--"))
A33: Env Sep and Incident Response | B33: ='Dashboard'!G11 | C33: ='Dashboard'!C11 | D33: ='Dashboard'!E11 | E33: =IF(Dashboard!G11="N/A","--",IF(ISNUMBER(VALUE(SUBSTITUTE(Dashboard!G11,"%",""))),IF(VALUE(SUBSTITUTE(Dashboard!G11,"%",""))>=90,"PASS",IF(VALUE(SUBSTITUTE(Dashboard!G11,"%",""))>=70,"REVIEW","FAIL")),"--"))
A34: Compliance Measurement | B34: ='Dashboard'!G12 | C34: ='Dashboard'!C12 | D34: ='Dashboard'!E12 | E34: =IF(Dashboard!G12="N/A","--",IF(ISNUMBER(VALUE(SUBSTITUTE(Dashboard!G12,"%",""))),IF(VALUE(SUBSTITUTE(Dashboard!G12,"%",""))>=90,"PASS",IF(VALUE(SUBSTITUTE(Dashboard!G12,"%",""))>=70,"REVIEW","FAIL")),"--"))
A36: CRITICAL ISSUES
A37: # | B37: Issue Description | C37: Domain | D37: Owner | E37: Due Date
A38: 1
A39: 2
A40: 3
A41: 4
A42: 5
A44: MANAGEMENT COMMENTARY
A45: [Enter management commentary on separation of development, test and production environments posture]
A49: APPROVAL
...

Sheet Dashboard
A1: Separation of Development, Test and Production Environments — Compliance Dashboard
A3: Domain | B3: Total Reqs | C3: Compliant | D3: Partial | E3: Non-Compliant | F3: N/A | G3: Compliance %
A4: Network Separation | B4: =COUNTA('Network Separation'!D4:D16) | C4: =COUNTIF('Network Separation'!D4:D16,"Compliant") | D4: =COUNTIF('Network Separation'!D4:D16,"Partial") | E4: =COUNTIF('Network Separation'!D4:D16,"Non-Compliant") | F4: =COUNTIF('Network Separation'!D4:D16,"N/A") | G4: =IF((B4-F4)=0,"N/A",ROUND(C4/(B4-F4)*100,1)&"%")
A5: Access Control per Environment | B5: =COUNTA('Access Control per Environment'!D4:D11) | C5: =COUNTIF('Access Control per Environment'!D4:D11,"Compliant") | D5: =COUNTIF('Access Control per Environment'!D4:D11,"Partial") | E5: =COUNTIF('Access Control per Environment'!D4:D11,"Non-Compliant") | F5: =COUNTIF('Access Control per Environment'!D4:D11,"N/A") | G5: =IF((B5-F5)=0,"N/A",ROUND(C5/(B5-F5)*100,1)&"%")
A6: Data Handling Rules | B6: =COUNTA('Data Handling Rules'!D4:D11) | C6: =COUNTIF('Data Handling Rules'!D4:D11,"Compliant") | D6: =COUNTIF('Data Handling Rules'!D4:D11,"Partial") | E6: =COUNTIF('Data Handling Rules'!D4:D11,"Non-Compliant") | F6: =COUNTIF('Data Handling Rules'!D4:D11,"N/A") | G6: =IF((B6-F6)=0,"N/A",ROUND(C6/(B6-F6)*100,1)&"%")
A7: Test Data Management | B7: =COUNTA('Test Data Management'!D4:D15) | C7: =COUNTIF('Test Data Management'!D4:D15,"Compliant") | D7: =COUNTIF('Test Data Management'!D4:D15,"Partial") | E7: =COUNTIF('Test Data Management'!D4:D15,"Non-Compliant") | F7: =COUNTIF('Test Data Management'!D4:D15,"N/A") | G7: =IF((B7-F7)=0,"N/A",ROUND(C7/(B7-F7)*100,1)&"%")
A8: Code Promotion Process | B8: =COUNTA('Code Promotion Process'!D4:D18) | C8: =COUNTIF('Code Promotion Process'!D4:D18,"Compliant") | D8: =COUNTIF('Code Promotion Process'!D4:D18,"Partial") | E8: =COUNTIF('Code Promotion Process'!D4:D18,"Non-Compliant") | F8: =COUNTIF('Code Promotion Process'!D4:D18,"N/A") | G8: =IF((B8-F8)=0,"N/A",ROUND(C8/(B8-F8)*100,1)&"%")
A9: Configuration Separation | B9: =COUNTA('Configuration Separation'!D4:D11) | C9: =COUNTIF('Configuration Separation'!D4:D11,"Compliant") | D9: =COUNTIF('Configuration Separation'!D4:D11,"Partial") | E9: =COUNTIF('Configuration Separation'!D4:D11,"Non-Compliant") | F9: =COUNTIF('Configuration Separation'!D4:D11,"N/A") | G9: =IF((B9-F9)=0,"N/A",ROUND(C9/(B9-F9)*100,1)&"%")
A10: Cloud Environment Separation | B10: =COUNTA('Cloud Environment Separation'!D4:D11) | C10: =COUNTIF('Cloud Environment Separation'!D4:D11,"Compliant") | D10: =COUNTIF('Cloud Environment Separation'!D4:D11,"Partial") | E10: =COUNTIF('Cloud Environment Separation'!D4:D11,"Non-Compliant") | F10: =COUNTIF('Cloud Environment Separation'!D4:D11,"N/A") | G10: =IF((B10-F10)=0,"N/A",ROUND(C10/(B10-F10)*100,1)&"%")
A11: Env Sep and Incident Response | B11: =COUNTA('Env Sep and Incident Response'!D4:D4) | C11: =COUNTIF('Env Sep and Incident Response'!D4:D4,"Compliant") | D11: =COUNTIF('Env Sep and Incident Response'!D4:D4,"Partial") | E11: =COUNTIF('Env Sep and Incident Response'!D4:D4,"Non-Compliant") | F11: =COUNTIF('Env Sep and Incident Response'!D4:D4,"N/A") | G11: =IF((B11-F11)=0,"N/A",ROUND(C11/(B11-F11)*100,1)&"%")
A12: Compliance Measurement | B12: =COUNTA('Compliance Measurement'!D4:D5) | C12: =COUNTIF('Compliance Measurement'!D4:D5,"Compliant") | D12: =COUNTIF('Compliance Measurement'!D4:D5,"Partial") | E12: =COUNTIF('Compliance Measurement'!D4:D5,"Non-Compliant") | F12: =COUNTIF('Compliance Measurement'!D4:D5,"N/A") | G12: =IF((B12-F12)=0,"N/A",ROUND(C12/(B12-F12)*100,1)&"%")
A13: TOTAL | B13: =SUM(B4:B12) | C13: =SUM(C4:C12) | D13: =SUM(D4:D12) | E13: =SUM(E4:E12) | F13: =SUM(F4:F12) | G13: =IF((B13-F13)=0,"N/A",ROUND(C13/(B13-F13)*100,1)&"%")
A15: COMPLIANCE BY STATUS
A16: Compliant | B16: =C13 | C16: =IF(B13=0,"",ROUND(B16/B13*100,1)&"%")
A17: Partial | B17: =D13 | C17: =IF(B13=0,"",ROUND(B17/B13*100,1)&"%")
A18: Non-Compliant | B18: =E13 | C18: =IF(B13=0,"",ROUND(B18/B13*100,1)&"%")
A19: N/A | B19: =F13 | C19: =IF(B13=0,"",ROUND(B19/B13*100,1)&"%")
A21: TOP GAPS (Manual Entry)
A22: Priority | B22: Domain | C22: Requirement | D22: Owner | E22: Due Date | F22: Status
A34: COMPLIANCE TREND (Manual Entry)
A35: Assessment Date | B35: Overall % | C35: Compliant | D35: Gaps | E35: Assessor | F35: Notes

Sheet Network Separation
A1: Network Separation — Compliance Checklist
A2: ISO/IEC 27001:2022 — Control A.8.31: Separation of Development, Test and Production Environments
A3: Req # | B3: Section | C3: Requirement | D3: Status | E3: Evidence | F3: Owner | G3: Due Date | H3: Notes
A4: A.8.31-01 | B4: Be Isolated Through Network Segmentation | C4: Environments shall be isolated through network segmentation to prevent unintended cross-environment data flows and access.
A5: A.8.31-02 | B5: Environment Separation | C5: Where the organisation uses cloud infrastructure, environment separation shall be implemented using the cloud provider's account or subscription boundary model:.
A6: A.8.31-03 | B6: Be Separated Using | C6: Where the organisation uses container orchestration platforms, environments shall be separated using:.
A7: A.8.31-04 | B7: Production Workloads | C7: Production workloads shall not share a cluster with development or testing workloads.
A8: A.8.31-05 | B8: Container Image Registries | C8: Container image registries shall be separated or access-controlled per environment.
A9: A.8.31-06 | B9: Production Containers | C9: Production containers shall not mount host filesystems except for explicitly approved use cases.
A10: A.8.31-07 | B10: Production Containers | C10: Production containers shall run as non-root users.
A11: A.8.31-08 | B11: Production Container Images | C11: Production container images shall be signed and verified before deployment.
A12: A.8.31-09 | B12: Container Registries | C12: Container registries shall be separated per environment (e.g., prod.registry.example.com vs dev.registry.example.com).
A13: A.8.31-10 | B13: Production Clusters | C13: Production clusters shall use separate control planes and node pools.
A14: A.8.31-11 | B14: Pod Security Standards (Pss) | C14: Pod Security Standards (PSS) shall be enforced at 'Restricted' level for production.
A15: A.8.31-12 | B15: Network Policies | C15: Network policies shall deny-all by default with explicit allow rules.
A16: A.8.31-13 | B16: Service Accounts | C16: Service accounts shall be scoped to minimum required permissions.

Sheet Access Control per Environment
A1: Access Control per Environment — Compliance Checklist
A2: ISO/IEC 27001:2022 — Control A.8.31: Separation of Development, Test and Production Environments
A3: Req # | B3: Section | C3: Requirement | D3: Status | E3: Evidence | F3: Owner | G3: Due Date | H3: Notes
A4: A.8.31-14 | B4: Access To Each Environment | C4: Access to each environment shall follow the principle of least privilege. Access rights shall be defined per role and environment tier.
A5: A.8.31-15 | B5: Not Have Standing Access To Production | C5: Developers shall not have standing access to production infrastructure, databases, or application consoles.
A6: A.8.31-16 | B6: Production Access | C6: All production access shall require multi-factor authentication.
A7: A.8.31-17 | B7: Production Access Sessions | C7: Production access sessions shall be logged, recorded, and monitored.
A8: A.8.31-18 | B8: Privileged Production Access | C8: Privileged production access shall be managed through a Privileged Access Management (PAM) system ([PAM Tool] — e.g., CyberArk, HashiCorp Boundary, AWS SSM Session Manager, or equivalent).
A9: A.8.31-19 | B9: Emergency Developer Access To Production | C9: Emergency developer access to production shall be permitted only during declared incidents where developer expertise is required for resolution. Break-glass access shall:.
A10: A.8.31-20 | B10: Break-Glass Activations | C10: Break-glass activations shall be reviewed monthly by the Information Security Manager and reported in the quarterly CISO dashboard with trend analysis.
A11: A.8.31-21 | B11: Terminated Employee Access | C11: Terminated employee access shall be revoked within the same business day across all environments. Automated deprovisioning via the identity management system is preferred.

Sheet Data Handling Rules
A1: Data Handling Rules — Compliance Checklist
A2: ISO/IEC 27001:2022 — Control A.8.31: Separation of Development, Test and Production Environments
A3: Req # | B3: Section | C3: Requirement | D3: Status | E3: Evidence | F3: Owner | G3: Due Date | H3: Notes
A4: A.8.31-22 | B4: Production Data | C4: Production data shall not be used in development or testing environments. This requirement protects business-critical data from exposure in less-controlled environments and supports nFADP compliance for personal data.
A5: A.8.31-23 | B5: Production Data | C5: Production data shall not be copied, exported, restored, or replicated to development, testing, or staging environments.
A6: A.8.31-24 | B6: Production Database Backups | C6: Production database backups shall not be restored in non-production environments.
A7: A.8.31-25 | B7: Production Credentials, Api Keys, | C7: Production credentials, API keys, connection strings, and secrets shall not be used in non-production environments.
A8: A.8.31-26 | B8: Log Files | C8: Log files containing production personal data shall not be transferred to non-production environments without anonymisation.
A9: A.8.31-27 | B9: Confidential And Restricted Data | C9: Confidential and Restricted data classifications shall be prohibited in development and testing environments.
A10: A.8.31-28 | B10: Automated Scanning | C10: Automated scanning shall be implemented to detect prohibited production data patterns (e.g., real names, national identifiers, financial account numbers) in non-production environments. Scanning shall cover databases, file systems, log files, and container images.
A11: A.8.31-29 | B11: Be Remediated Within 7 Days Of | C11: Violations shall be remediated within 7 days of detection and reported to the Information Security Manager.

Sheet Test Data Management
A1: Test Data Management — Compliance Checklist
A2: ISO/IEC 27001:2022 — Control A.8.31: Separation of Development, Test and Production Environments
A3: Req # | B3: Section | C3: Requirement | D3: Status | E3: Evidence | F3: Owner | G3: Due Date | H3: Notes
A4: A.8.31-30 | B4: Test Data | C4: Test data shall be managed as a controlled asset throughout the software development lifecycle.
A5: A.8.31-31 | B5: Synthetic Data | C5: Synthetic data shall be the default and preferred approach for all testing activities.
A6: A.8.31-32 | B6: Test Data | C6: Test data shall be structurally representative of production data (same schema, data types, relationships, and volume characteristics) without containing real personal or business data.
A7: A.8.31-33 | B7: Test Data Generation | C7: Test data generation shall be automated where practicable using [Test Data Tool] (e.g., Faker, Mockaroo, Tonic.ai, Delphix, or equivalent).
A8: A.8.31-34 | B8: Test Data | C8: Test data shall be versioned and reproducible to support regression testing.
A9: A.8.31-35 | B9: Test Data | C9: Test data shall be purged from non-production environments within 30 days of project completion or test cycle conclusion.
A10: A.8.31-36 | B10: The Anonymisation Process | C10: Where anonymised production data is approved for non-production use, the anonymisation process shall be validated before each use:.
A11: A.8.31-37 | B11: Data Protection Officer | C11: Data Protection Officer shall verify that direct identifiers have been removed or replaced.
A12: A.8.31-38 | B12: Quasi-Identifier Combinations | C12: Quasi-identifier combinations shall be assessed for re-identification risk.
A13: A.8.31-39 | B13: Validation Results | C13: Validation results shall be documented and retained for audit purposes.
A14: A.8.31-40 | B14: Failed Validation | C14: Failed validation shall result in rejection and remediation before data can be used.
A15: A.8.31-41 | B15: Card Holder Data*: Card Holder Data | C15: Card Holder Data*: Card holder data (PAN, CVV, track data) shall never be used in development or testing environments, regardless of anonymisation status. Synthetic card numbers conforming to test ranges shall be used instead.

Sheet Code Promotion Process
A1: Code Promotion Process — Compliance Checklist
A2: ISO/IEC 27001:2022 — Control A.8.31: Separation of Development, Test and Production Environments
A3: Req # | B3: Section | C3: Requirement | D3: Status | E3: Evidence | F3: Owner | G3: Due Date | H3: Notes
A4: A.8.31-42 | B4: Follow A Defined Promotion Path From | C4: Changes shall follow a defined promotion path from development to production. Direct deployment to production shall be prohibited except for approved emergency fixes.
A5: A.8.31-43 | B5: Promotion Step | C5: Each promotion step shall include defined quality and security gates.
A6: A.8.31-44 | B6: The Developer Who Writes The Code | C6: The developer who writes the code shall not be the same person who approves its promotion to production.
A7: A.8.31-45 | B7: The Person Who Promotes Code To | C7: The person who promotes code to staging shall not be the same person who promotes it to production, where team size permits.
A8: A.8.31-46 | B8: Ci/Cd Pipeline Credentials For | C8: CI/CD pipeline credentials for production deployment shall be restricted to the operations team.
A9: A.8.31-47 | B9: Pipeline Definitions | C9: Pipeline definitions shall be version-controlled and subject to code review.
A10: A.8.31-48 | B10: Pipeline Credentials And Secrets | C10: Pipeline credentials and secrets shall be stored in the pipeline platform's secret store — not hardcoded in pipeline definitions.
A11: A.8.31-49 | B11: Have Dedicated Pipeline Credentials With | C11: Each environment shall have dedicated pipeline credentials with minimum required permissions.
A12: A.8.31-50 | B12: Pipeline Execution Logs | C12: Pipeline execution logs shall be retained for audit purposes (minimum 1 year).
A13: A.8.31-51 | B13: Be Built Once And Promoted Through | C13: Artifacts shall be built once and promoted through environments (immutable artifacts) — not rebuilt per environment.
A14: A.8.31-52 | B14: Previous Versions | C14: Previous versions shall be retained to support rollback.
A15: A.8.31-53 | B15: Rollback Procedures | C15: Rollback procedures shall be documented and tested at least quarterly.
... A18: A.8.31-56 | B18: Test Data And Development Artefacts | C18: Test data and development artefacts shall be removed before promotion to production.

Sheet Configuration Separation
A1: Configuration Separation — Compliance Checklist
A2: ISO/IEC 27001:2022 — Control A.8.31: Separation of Development, Test and Production Environments
A3: Req # | B3: Section | C3: Requirement | D3: Status | E3: Evidence | F3: Owner | G3: Due Date | H3: Notes
A4: A.8.31-57 | B4: Environment Configurations | C4: Environment configurations shall be managed to prevent credential leakage, cross-environment contamination, and configuration drift.
A5: A.8.31-58 | B5: Staging Environments | C5: Staging environments shall mirror production configuration as closely as possible (same software versions, same infrastructure sizing within budget constraints, same security controls).
A6: A.8.31-59 | B6: Configuration Drift Between Staging And | C6: Configuration drift between staging and production shall be detected and reported. Drift detection shall be performed at least weekly.
A7: A.8.31-60 | B7: Differences Between Staging And | C7: Differences between staging and production shall be documented, justified, and approved by the IT Operations Manager.
A8: A.8.31-61 | B8: The Following Table | C8: The following table shall be maintained by the IT Operations Manager and reviewed quarterly. Unapproved differences detected through drift detection shall be investigated and resolved.
A9: A.8.31-62 | B9: Display Clear Visual Identification To | C9: Each environment shall display clear visual identification to prevent accidental operations in the wrong environment.
A10: A.8.31-63 | B10: Hostname Prefixes, Console Banners, | C10: Hostname prefixes, console banners, browser tab labels, and colour-coded UI elements shall distinguish environment tiers.
A11: A.8.31-64 | B11: Production Environments | C11: Production environments shall display prominent identification (e.g., red banners, '[PRODUCTION]' labels).

Sheet Cloud Environment Separation
A1: Cloud Environment Separation — Compliance Checklist
A2: ISO/IEC 27001:2022 — Control A.8.31: Separation of Development, Test and Production Environments
A3: Req # | B3: Section | C3: Requirement | D3: Status | E3: Evidence | F3: Owner | G3: Due Date | H3: Notes
A4: A.8.31-65 | B4: Production Workloads | C4: Production workloads shall reside in dedicated cloud accounts, subscriptions, or projects — separate from all non-production workloads.
A5: A.8.31-66 | B5: Iam Policies | C5: IAM policies shall prevent cross-account access except through explicitly defined, audited roles.
A6: A.8.31-67 | B6: Service Control Policies (Scps), Azure | C6: Service control policies (SCPs), Azure Policies, or organisation policies shall enforce environment boundaries at the organisational level.
A7: A.8.31-68 | B7: Be Separated Per Environment To Enable | C7: Billing shall be separated per environment to enable cost attribution and anomaly detection.
A8: A.8.31-69 | B8: Cloud Resources | C8: All cloud resources shall be tagged with environment identification (e.g., env:production, env:staging, env:development) to support:.
A9: A.8.31-70 | B9: Infrastructure Definitions | C9: Infrastructure definitions shall be stored in version-controlled repositories.
A10: A.8.31-71 | B10: Infrastructure Changes | C10: Infrastructure changes shall follow the same promotion workflow as application code (develop, review, test, deploy).
A11: A.8.31-72 | B11: Manual Changes To Production | C11: Manual changes to production infrastructure ('ClickOps') shall be prohibited; all changes shall be applied through the CI/CD pipeline.

Sheet Env Sep and Incident Response
A1: Env Sep and Incident Response — Compliance Checklist
A2: ISO/IEC 27001:2022 — Control A.8.31: Separation of Development, Test and Production Environments
A3: Req # | B3: Section | C3: Requirement | D3: Status | E3: Evidence | F3: Owner | G3: Due Date | H3: Notes
A4: A.8.31-73 | B4: During Incidents Involving Environment | C4: During incidents involving environment boundary violations (unauthorised access across environments, production data discovered in non-production), the Information Security Manager shall:.

Sheet Compliance Measurement
A1: Compliance Measurement — Compliance Checklist
A2: ISO/IEC 27001:2022 — Control A.8.31: Separation of Development, Test and Production Environments
A3: Req # | B3: Section | C3: Requirement | D3: Status | E3: Evidence | F3: Owner | G3: Due Date | H3: Notes
A4: A.8.31-74 | B4: The Information Security Manager | C4: The Information Security Manager shall generate this dashboard quarterly and present it during the management review:.
A5: A.8.31-75 | B5: Items Requiring Attention And Recent | C5: Items requiring attention and recent improvements shall be highlighted in the dashboard report.
