Workbook

Sheet Instructions & Legend
A1: ISMS-IMP-A.8.24.2 – Data Storage Assessment ISO/IEC 27001:2022 - Control A.8.24: Use of Cryptography
A3: Document Information
A4: Document ID | B4: ISMS-IMP-A.8.24.2
A5: Assessment Area | B5: Data Storage Cryptographic Controls
A6: Related Policy | B6: ISMS-POL-A.8.24-S2.3
A7: Version | B7: 1.0
A8: Assessment Date
A9: Completed By
A10: Organization
A11: Review Cycle | B11: Quarterly
A13: HOW TO USE THIS WORKBOOK
A14: 1. Complete each worksheet tab (1–7) for applicable storage systems
A15: 2. Use dropdown menus for standardized entries (Status, Encryption Type, Algorithm, etc.)
A16: 3. Fill in yellow-highlighted cells with your information
A17: 4. If Status = Partial or Non-Compliant, complete the Exception/Deviation section
A18: 5. Document key management details for each encrypted storage system
A19: 6. Provide evidence location/path for each implementation entry
A20: 7. Summary Dashboard auto-calculates compliance statistics per storage type
A21: 8. Maintain the Evidence Register for audit traceability
A22: 9. Obtain final approval and sign-off in the Approval Sign-Off sheet
A24: STATUS LEGEND
A25: Symbol | B25: Status | C25: Description
A26: ✅ | B26: Compliant | C26: Fully meets policy requirements
A27: ⚠️ | B27: Partial | C27: Some requirements met, gaps exist
A28: ❌ | B28: Non-Compliant | C28: Does not meet policy requirements
A29: N/A | B29: Not Applicable | C29: Requirement does not apply
A32: ACCEPTABLE EVIDENCE (examples)
A33: ✓ Encryption configuration screenshots
A34: ✓ BitLocker/FileVault/LUKS status reports
A35: ✓ Database TDE (Transparent Data Encryption) configuration
A36: ✓ Cloud encryption settings documentation
A37: ✓ Key management system inventory
A38: ✓ Backup encryption verification reports
A39: ✓ Mobile device management (MDM) compliance reports
A40: ✓ Storage vendor encryption specifications
A41: ✓ Disk encryption audit logs
A42: ✓ Certificate/key rotation logs
A43: ✓ Hardware Security Module (HSM) integration docs

Sheet 1. Mobile Devices
A1: 1. MOBILE DEVICES - DATA AT REST ENCRYPTION Policy Requirement: Mobile devices storing organizational data MUST use full device encryption (Policy Section 2.3.1)
A3: Does your organization issue or allow mobile devices (smartphones, tablets) that store organizational data?
A4: Response:
A6: Storage System/Device | B6: Data Classification | C6: Encryption Status | D6: Encryption Type | E6: Algorithm & Key Size | F6: Key Management Method | G6: Key Rotation Enabled | H6: Status | I6: Evidence Location | J6: Gap Description | K6: Remediation Needed | L6: Exception ID | M6: Risk ID | N6: Compensating Controls | O6: Responsible Person | P6: Target Date | Q6: Budget Required
A7: Example: Production SQL Server 2019 - FINDB01 | B7: Restricted | C7: Encrypted | D7: Database TDE | E7: AES-256 | F7: HSM | G7: Yes | H7: ✅ Compliant | I7: /evidence/databases/FINDB01-TDE-config.pdf | J7: None | K7: No | L7: N/A | M7: N/A | N7: N/A | O7: N/A | P7: N/A | Q7: No
A8: Corporate iPhones (500 units) | B8: Confidential | C8: iOS FileVault | D8: Hardware-backed | E8: AES-256 | F8: MDM - MobileIron | G8: Yes | H8: ✅ Compliant | I8: MDM compliance report | K8: No
A9: Android Devices (300 units) | B9: Confidential | C9: Android FDE | D9: Hardware-backed | E9: AES-256 | F9: MDM - Workspace ONE | G9: Yes | H9: ✅ Compliant | I9: Workspace ONE dashboard | K9: No
A10: Corporate iPads (200 units) | B10: Confidential | C10: iOS FileVault | D10: Hardware-backed | E10: AES-256 | F10: MDM - Jamf Pro | G10: Yes | H10: ✅ Compliant | I10: Jamf compliance scan | K10: No
A11: Executive iPhones | B11: Restricted | C11: iOS + Container | D11: Hardware + App | E11: AES-256 | F11: MDM + App wrapping | G11: Yes | H11: ✅ Compliant | I11: Executive device audit | K11: No
A12: BYOD iPhones (enrolled) | B12: Internal | C12: Containerization | D12: App-level | E12: AES-256 | F12: MDM container only | G12: Yes | H12: ⚠️ Partial | I12: BYOD policy docs | J12: Increase enrollment | K12: Yes
A13: BYOD Android (enrolled) | B13: Internal | C13: Containerization | D13: App-level | E13: AES-256 | F13: MDM container only | G13: Yes | H13: ⚠️ Partial | I13: BYOD enrollment report | J13: Training needed | K13: Yes
A14: Test Devices (50 units) | B14: Public | C14: Various/None | D14: Mixed/None | E14: Various | F14: No central management | G14: No | H14: ❌ Non-Compliant | I14: Test device inventory | J14: Enroll in MDM or decommission | K14: Yes
A15: Legacy Tablets | B15: Internal | C15: No encryption | D15: None | E15: None | F15: No management | G15: No | H15: ❌ Non-Compliant | I15: Legacy device list | J15: Replace or decommission | K15: Yes
A22: 1. MOBILE DEVICES ENCRYPTION CHECKLIST
A23: ☐ | B23: Requirement | C23: Status
A24: ☐ | B24: iOS devices: FileVault/built-in encryption enabled
A25: ☐ | B25: Android devices: Full device encryption enabled
A26: ☐ | B26: MDM policy enforces encryption
A27: ☐ | B27: Encryption status verified via MDM reporting
A28: ☐ | B28: PIN/password/biometric required for device unlock
A29: ☐ | B29: Remote wipe capability configured
A30: ☐ | B30: Encryption cannot be disabled by user
A31: ☐ | B31: BYOD devices meet encryption requirements
A32: ☐ | B32: Lost/stolen device procedure includes encryption verification
A33: ☐ | B33: Regular compliance audits performed (quarterly minimum)
A34: Checklist Score: | B34: =COUNTIF(C24:C33,"Yes")/COUNTA(C24:C33)*100&"%" -> #DIV/0!
A36: EXCEPTION / DEVIATION DOCUMENTATION (Complete if Status = Partial or Non-Compliant)
A37: Formal exception request submitted:
A38: Exception ID:
A39: Risk acceptance documented:
A40: Risk ID:
A41: Compensating Controls (summary):
A42: ☐ Physical security controls (locked facility, restricted access)
A43: ☐ Network segmentation / air-gapped systems
A44: ☐ Enhanced monitoring / DLP controls
A45: ☐ Restricted user access / privileged access management
A46: ☐ Data minimization / reduced storage scope
A47: ☐ Other (describe):
A49: ADDITIONAL NOTES / COMMENTS

Sheet 2. Laptops & Workstations
A1: 2. LAPTOPS & WORKSTATIONS - DATA AT REST ENCRYPTION Policy Requirement: Laptops and workstations storing sensitive data MUST use full disk encryption (Policy Section 2.3.2)
A3: Does your organization have laptops or workstations that store organizational data locally?
A4: Response:
A6: Storage System/Device | B6: Data Classification | C6: Encryption Status | D6: Encryption Type | E6: Algorithm & Key Size | F6: Key Management Method | G6: Key Rotation Enabled | H6: Status | I6: Evidence Location | J6: Gap Description | K6: Remediation Needed | L6: Exception ID | M6: Risk ID | N6: Compensating Controls | O6: Responsible Person | P6: Target Date | Q6: Budget Required
A7: Example: Production SQL Server 2019 - FINDB01 | B7: Restricted | C7: Encrypted | D7: Database TDE | E7: AES-256 | F7: HSM | G7: Yes | H7: ✅ Compliant | I7: /evidence/databases/FINDB01-TDE-config.pdf | J7: None | K7: No | L7: N/A | M7: N/A | N7: N/A | O7: N/A | P7: N/A | Q7: No
A8: Windows 11 Laptops (800 units) | B8: Confidential | C8: BitLocker | D8: Full Disk | E8: AES-256-XTS | F8: AD + Intune recovery | G8: Annual | H8: ✅ Compliant | I8: BitLocker compliance dashboard | K8: No
A9: MacBook Pro (400 units) | B9: Confidential | C9: FileVault 2 | D9: Full Disk | E9: AES-256-XTS | F9: MDM escrowed keys | G9: Annual | H9: ✅ Compliant | I9: Jamf encryption report | K9: No
A10: MacBook Air (250 units) | B10: Confidential | C10: FileVault 2 | D10: Full Disk | E10: AES-256-XTS | F10: MDM escrowed keys | G10: Annual | H10: ✅ Compliant | I10: Jamf encryption report | K10: No
A11: Linux Workstations (100 units) | B11: Internal | C11: LUKS | D11: Full Disk | E11: AES-256-XTS | F11: Manual key backup | G11: Annual | H11: ⚠️ Partial | I11: Linux asset inventory | J11: Centralize key management | K11: Yes
A12: Executive Laptops | B12: Restricted | C12: BitLocker + TPM 2.0 | D12: Full Disk + TPM | E12: AES-256-XTS | F12: Intune + Hardware TPM | G12: Quarterly | H12: ✅ Compliant | I12: Executive device report | K12: No
A13: Developer MacBooks | B13: Confidential | C13: FileVault 2 | D13: Full Disk | E13: AES-256-XTS | F13: MDM managed | G13: Annual | H13: ✅ Compliant | I13: Dev team device audit | K13: No
A14: Windows 10 Desktops (500 units) | B14: Internal | C14: BitLocker | D14: Full Disk | E14: AES-256 | F14: AD recovery | G14: Annual | H14: ✅ Compliant | I14: SCCM compliance | K14: No
A15: Contractor Laptops (80 units) | B15: Internal | C15: Various/None | D15: Mixed | E15: Various | F15: No enforcement | G15: No | H15: ❌ Non-Compliant | I15: Contractor device list | J15: Enforce encryption policy | K15: Yes
A16: Legacy Desktops (50 units) | B16: Internal | C16: No encryption | D16: None | E16: None | F16: None | G16: No | H16: ❌ Non-Compliant | I16: Legacy hardware list | J16: Upgrade or decommission | K16: Yes
A22: 2. LAPTOPS & WORKSTATIONS ENCRYPTION CHECKLIST
A23: ☐ | B23: Requirement | C23: Status
A24: ☐ | B24: Windows: BitLocker enabled and configured
A25: ☐ | B25: macOS: FileVault 2 enabled
A26: ☐ | B26: Linux: LUKS/dm-crypt configured
A27: ☐ | B27: TPM 2.0 utilized for key storage (where available)
A28: ☐ | B28: Pre-boot authentication required
A29: ☐ | B29: Recovery keys securely escrowed
A30: ☐ | B30: Encryption status monitored centrally
A31: ☐ | B31: Users cannot disable encryption
A32: ☐ | B32: Encryption applied before device deployment
A33: ☐ | B33: Hibernate/sleep mode protected
A34: ☐ | B34: External storage auto-encryption policy enforced
A35: Checklist Score: | B35: =COUNTIF(C24:C34,"Yes")/COUNTA(C24:C34)*100&"%" -> #DIV/0!
A37: EXCEPTION / DEVIATION DOCUMENTATION (Complete if Status = Partial or Non-Compliant)
A38: Formal exception request submitted:
A39: Exception ID:
A40: Risk acceptance documented:
A41: Risk ID:
A42: Compensating Controls (summary):
A43: ☐ Physical security controls (locked facility, restricted access)
A44: ☐ Network segmentation / air-gapped systems
A45: ☐ Enhanced monitoring / DLP controls
A46: ☐ Restricted user access / privileged access management
A47: ☐ Data minimization / reduced storage scope
A48: ☐ Other (describe):
...

Sheet 3. Servers
A1: 3. SERVERS - DATA AT REST ENCRYPTION Policy Requirement: Servers storing sensitive data MUST implement appropriate encryption at rest (Policy Section 2.3.3)
A3: Does your organization operate servers (physical or virtual) that store sensitive organizational data?
A4: Response:
A6: Storage System/Device | B6: Data Classification | C6: Encryption Status | D6: Encryption Type | E6: Algorithm & Key Size | F6: Key Management Method | G6: Key Rotation Enabled | H6: Status | I6: Evidence Location | J6: Gap Description | K6: Remediation Needed | L6: Exception ID | M6: Risk ID | N6: Compensating Controls | O6: Responsible Person | P6: Target Date | Q6: Budget Required
A7: Example: Production SQL Server 2019 - FINDB01 | B7: Restricted | C7: Encrypted | D7: Database TDE | E7: AES-256 | F7: HSM | G7: Yes | H7: ✅ Compliant | I7: /evidence/databases/FINDB01-TDE-config.pdf | J7: None | K7: No | L7: N/A | M7: N/A | N7: N/A | O7: N/A | P7: N/A | Q7: No
A8: Production Linux (150 units) | B8: Restricted | C8: LUKS + dm-crypt | D8: Full Disk | E8: AES-256-XTS | F8: Ansible Vault | G8: Annual | H8: ✅ Compliant | I8: Server encryption audit | K8: No
A9: Production Windows (100 units) | B9: Restricted | C9: BitLocker | D9: Full Disk | E9: AES-256-XTS | F9: MBAM + AD | G9: Annual | H9: ✅ Compliant | I9: BitLocker server status | K9: No
A10: VMware VMs (300 units) | B10: Confidential | C10: VM Encryption | D10: VMDK-level | E10: AES-256-XTS | F10: vCenter + KMS | G10: Annual | H10: ✅ Compliant | I10: vSphere encryption report | K10: No
A11: Hyper-V VMs (150 units) | B11: Confidential | C11: Shielded VMs | D11: VM-level | E11: AES-256 | F11: SCVMM + GuardedHost | G11: Annual | H11: ✅ Compliant | I11: Hyper-V audit | K11: No
A12: Docker Hosts (80 units) | B12: Internal | C12: Host LUKS | D12: Host disk | E12: AES-256 | F12: Ansible managed | G12: Annual | H12: ✅ Compliant | I12: Docker host inventory | K12: No
A13: Kubernetes Nodes (120 units) | B13: Confidential | C13: etcd encryption | D13: etcd + disk | E13: AES-256-GCM | F13: K8s secrets + LUKS | G13: Quarterly | H13: ✅ Compliant | I13: K8s encryption config | K13: No
A14: Development Servers (50 units) | B14: Internal | C14: LUKS | D14: Full Disk | E14: AES-256 | F14: Manual | G14: Annual | H14: ⚠️ Partial | I14: Dev server list | J14: Automate key rotation | K14: Yes
A15: Legacy Unix Servers (20 units) | B15: Internal | C15: No encryption | D15: None | E15: None | F15: None | G15: No | H15: ❌ Non-Compliant | I15: Legacy server inventory | J15: Migrate or decommission | K15: Yes
A22: 3. SERVERS ENCRYPTION CHECKLIST
A23: ☐ | B23: Requirement | C23: Status
A24: ☐ | B24: OS-level encryption enabled (LUKS, BitLocker, etc.)
A25: ☐ | B25: Storage volume/LUN encryption configured
A26: ☐ | B26: Virtual machine disk encryption enabled
A27: ☐ | B27: Key management solution integrated
A28: ☐ | B28: Encryption keys stored separately from encrypted data
A29: ☐ | B29: SAN/NAS encryption enabled (if applicable)
A30: ☐ | B30: Self-encrypting drives (SED) utilized where appropriate
A31: ☐ | B31: Boot volumes encrypted
A32: ☐ | B32: Temporary/swap space encrypted
A33: ☐ | B33: Encryption status monitoring automated
A34: ☐ | B34: Key rotation procedures documented and implemented
A35: ☐ | B35: HSM integration for key protection (production systems)
A36: Checklist Score: | B36: =COUNTIF(C24:C35,"Yes")/COUNTA(C24:C35)*100&"%" -> #DIV/0!
A38: EXCEPTION / DEVIATION DOCUMENTATION (Complete if Status = Partial or Non-Compliant)
A39: Formal exception request submitted:
A40: Exception ID:
A41: Risk acceptance documented:
A42: Risk ID:
A43: Compensating Controls (summary):
A44: ☐ Physical security controls (locked facility, restricted access)
A45: ☐ Network segmentation / air-gapped systems
A46: ☐ Enhanced monitoring / DLP controls
A47: ☐ Restricted user access / privileged access management
A48: ☐ Data minimization / reduced storage scope
A49: ☐ Other (describe):
...

Sheet 4. Databases
A1: 4. DATABASES - DATA AT REST ENCRYPTION Policy Requirement: Databases containing sensitive data MUST implement Transparent Data Encryption or equivalent (Policy Section 2.3.4)
A3: Does your organization operate databases that store sensitive or regulated data?
A4: Response:
A6: Storage System/Device | B6: Data Classification | C6: Encryption Status | D6: Encryption Type | E6: Algorithm & Key Size | F6: Key Management Method | G6: Key Rotation Enabled | H6: Status | I6: Evidence Location | J6: Gap Description | K6: Remediation Needed | L6: Exception ID | M6: Risk ID | N6: Compensating Controls | O6: Responsible Person | P6: Target Date | Q6: Budget Required
A7: Example: Production SQL Server 2019 - FINDB01 | B7: Restricted | C7: Encrypted | D7: Database TDE | E7: AES-256 | F7: HSM | G7: Yes | H7: ✅ Compliant | I7: /evidence/databases/FINDB01-TDE-config.pdf | J7: None | K7: No | L7: N/A | M7: N/A | N7: N/A | O7: N/A | P7: N/A | Q7: No
A8: PostgreSQL Production (10 nodes) | B8: Restricted | C8: TDE - pgcrypto | D8: Transparent | E8: AES-256-GCM | F8: AWS KMS | G8: Yes - Quarterly | H8: ✅ Compliant | I8: PostgreSQL TDE status | K8: No
A9: MySQL Customer DB (12 nodes) | B9: Confidential | C9: InnoDB TDE | D9: Transparent | E9: AES-256-CBC | F9: Azure Key Vault | G9: Yes - Quarterly | H9: ✅ Compliant | I9: MySQL encryption audit | K9: No
A10: SQL Server Finance (8 nodes) | B10: Restricted | C10: TDE + Always Encrypted | D10: Transparent + Column | E10: AES-256 | F10: HSM-backed keys | G10: Yes - Quarterly | H10: ✅ Compliant | I10: SQL Server DMV reports | K10: No
A11: MongoDB Analytics (6 nodes) | B11: Internal | C11: Encrypted Storage Engine | D11: At-rest | E11: AES-256-GCM | F11: Self-managed keyfile | G11: No | H11: ⚠️ Partial | I11: MongoDB config audit | J11: Implement KMS rotation | K11: Yes
A12: Redis Cache Cluster | B12: Internal | C12: RDB/AOF Encryption | D12: Snapshot | E12: AES-256 | F12: Key in config | G12: No | H12: ⚠️ Partial | I12: Redis configuration | J12: Move keys to KMS | K12: Yes
A13: Oracle Enterprise (4 nodes) | B13: Confidential | C13: TDE - Advanced Security | D13: Transparent | E13: AES-192 | F13: Manual key management | G13: No | H13: ⚠️ Partial | I13: Oracle TDE audit | J13: Upgrade to AES-256 + HSM | K13: Yes
A14: Cassandra Cluster (8 nodes) | B14: Confidential | C14: At-rest Encryption | D14: SSTable | E14: AES-256 | F14: JKS keystore | G14: Manual | H14: ⚠️ Partial | I14: Cassandra encryption.yaml | J14: Automate key rotation | K14: Yes
A15: MariaDB Prod (6 nodes) | B15: Confidential | C15: InnoDB TDE | D15: Transparent | E15: AES-256 | F15: File-based keys | G15: Manual | H15: ⚠️ Partial | I15: MariaDB encryption status | J15: Implement KMS | K15: Yes
A16: DynamoDB Tables | B16: Confidential | C16: AWS managed | D16: Server-side | E16: AES-256 | F16: AWS KMS | G16: Yes - Automatic | H16: ✅ Compliant | I16: DynamoDB encryption config | K16: No
A17: Test Databases | B17: Public | C17: None | D17: None | E17: None | F17: None | G17: No | H17: ❌ Non-Compliant | I17: Test DB inventory | J17: Implement encryption | K17: Yes
A22: 4. DATABASES ENCRYPTION CHECKLIST
A23: ☐ | B23: Requirement | C23: Status
A24: ☐ | B24: TDE (Transparent Data Encryption) enabled
A25: ☐ | B25: Encryption at column level for sensitive fields (if applicable)
A26: ☐ | B26: Encryption at tablespace level configured
A27: ☐ | B27: Database backup files encrypted
A28: ☐ | B28: Transaction logs encrypted
A29: ☐ | B29: Encryption keys managed via KMS/HSM
A30: ☐ | B30: Master encryption key rotated per policy
A31: ☐ | B31: Encryption does not significantly impact performance
A32: ☐ | B32: Application-layer encryption for PII/PHI (if TDE unavailable)
A33: ☐ | B33: Encryption status verified in database audit logs
A34: ☐ | B34: Development/test databases use encryption for prod data
A35: ☐ | B35: Database snapshots/clones encrypted
A36: Checklist Score: | B36: =COUNTIF(C24:C35,"Yes")/COUNTA(C24:C35)*100&"%" -> #DIV/0!
A38: Technology-Specific Notes / Examples
A39: SQL Server: | B39: TDE, Always Encrypted
A40: Oracle: | B40: TDE, DBMS_CRYPTO
A41: PostgreSQL: | B41: pgcrypto, LUKS volume encryption
A42: MySQL: | B42: InnoDB encryption, file-level encryption
A43: MongoDB: | B43: Encrypted Storage Engine
A44: Cassandra: | B44: Transparent data encryption
A46: EXCEPTION / DEVIATION DOCUMENTATION (Complete if Status = Partial or Non-Compliant)
A47: Formal exception request submitted:
A48: Exception ID:
...

Sheet 5. Cloud Storage
A1: 5. CLOUD STORAGE - DATA AT REST ENCRYPTION Policy Requirement: Cloud storage MUST use provider encryption with customer-managed keys where available (Policy Section 2.3.5)
A3: Does your organization store data in cloud storage services (object storage, block storage, file storage)?
A4: Response:
A6: Storage System/Device | B6: Data Classification | C6: Encryption Status | D6: Encryption Type | E6: Algorithm & Key Size | F6: Key Management Method | G6: Key Rotation Enabled | H6: Status | I6: Evidence Location | J6: Gap Description | K6: Remediation Needed | L6: Exception ID | M6: Risk ID | N6: Compensating Controls | O6: Responsible Person | P6: Target Date | Q6: Budget Required
A7: Example: Production SQL Server 2019 - FINDB01 | B7: Restricted | C7: Encrypted | D7: Database TDE | E7: AES-256 | F7: HSM | G7: Yes | H7: ✅ Compliant | I7: /evidence/databases/FINDB01-TDE-config.pdf | J7: None | K7: No | L7: N/A | M7: N/A | N7: N/A | O7: N/A | P7: N/A | Q7: No
A8: AWS S3 Production | B8: Confidential | C8: SSE-KMS | D8: Server-side | E8: AES-256-GCM | F8: AWS KMS | G8: Yes - Automatic | H8: ✅ Compliant | I8: S3 bucket encryption audit | K8: No
A9: Azure Blob Storage | B9: Confidential | C9: SSE with Customer Keys | D9: Server-side | E9: AES-256 | F9: Azure Key Vault | G9: Yes - Automatic | H9: ✅ Compliant | I9: Azure Storage encryption | K9: No
A10: GCP Cloud Storage | B10: Confidential | C10: CMEK | D10: Server-side | E10: AES-256-GCM | F10: Cloud KMS | G10: Yes - Automatic | H10: ✅ Compliant | I10: GCS encryption config | K10: No
A11: AWS EBS Volumes | B11: Restricted | C11: EBS Encryption | D11: Block-level | E11: AES-256-XTS | F11: AWS KMS | G11: Yes - Automatic | H11: ✅ Compliant | I11: EBS encryption status | K11: No
A12: Azure Managed Disks | B12: Restricted | C12: SSE + Customer Keys | D12: Disk-level | E12: AES-256-XTS | F12: Azure Key Vault | G12: Yes - Automatic | H12: ✅ Compliant | I12: Managed Disk encryption | K12: No
A13: GCP Persistent Disks | B13: Restricted | C13: CMEK | D13: Disk-level | E13: AES-256-XTS | F13: Cloud KMS | G13: Yes - Automatic | H13: ✅ Compliant | I13: Persistent Disk config | K13: No
A14: AWS EFS File Systems | B14: Confidential | C14: EFS Encryption | D14: File-level | E14: AES-256-GCM | F14: AWS KMS | G14: Yes - Automatic | H14: ✅ Compliant | I14: EFS encryption status | K14: No
A15: OneDrive for Business | B15: Confidential | C15: Microsoft-managed | D15: Server-side | E15: AES-256 | F15: Microsoft managed | G15: Yes - Automatic | H15: ✅ Compliant | I15: OneDrive admin report | K15: No
A16: SharePoint Online | B16: Confidential | C16: Microsoft-managed | D16: Server-side | E16: AES-256 | F16: Microsoft managed | G16: Yes - Automatic | H16: ✅ Compliant | I16: SharePoint encryption | K16: No
A17: Dropbox Business | B17: Internal | C17: Dropbox-managed | D17: Server-side | E17: AES-256 | F17: Dropbox managed | G17: Yes - Automatic | H17: ✅ Compliant | I17: Dropbox admin console | K17: No
A22: 5. CLOUD STORAGE ENCRYPTION CHECKLIST
A23: ☐ | B23: Requirement | C23: Status
A24: ☐ | B24: Server-side encryption (SSE) enabled by default
A25: ☐ | B25: Customer-managed keys (CMK) configured
A26: ☐ | B26: Client-side encryption implemented for highly sensitive data
A27: ☐ | B27: Encryption key location documented (region/jurisdiction)
A28: ☐ | B28: Cloud KMS integrated (AWS KMS, Azure Key Vault, GCP KMS)
A29: ☐ | B29: Automatic key rotation enabled
A30: ☐ | B30: Encryption validated via cloud audit logs
A31: ☐ | B31: Data encrypted before upload (for maximum sensitivity)
A32: ☐ | B32: Bucket/container policies enforce encryption
A33: ☐ | B33: Cross-region replication maintains encryption
A34: ☐ | B34: Cloud backup snapshots encrypted
A35: ☐ | B35: Compliance certifications verified (SOC 2, ISO 27001)
A36: Checklist Score: | B36: =COUNTIF(C24:C35,"Yes")/COUNTA(C24:C35)*100&"%" -> #DIV/0!
A38: Technology-Specific Notes / Examples
A39: AWS: | B39: S3 SSE-KMS, EBS encryption, RDS encryption
A40: Azure: | B40: Storage Service Encryption, Azure Disk Encryption
A41: GCP: | B41: Default encryption at rest, CMEK
A42: Others: | B42: Document specific provider controls
A44: EXCEPTION / DEVIATION DOCUMENTATION (Complete if Status = Partial or Non-Compliant)
A45: Formal exception request submitted:
A46: Exception ID:
A47: Risk acceptance documented:
A48: Risk ID:
...

Sheet 6. Backups
A1: 6. BACKUPS - DATA AT REST ENCRYPTION Policy Requirement: Backup media and backup data MUST be encrypted with strong cryptography (Policy Section 2.3.6)
A3: Does your organization perform backups of systems, databases, or files?
A4: Response:
A6: Storage System/Device | B6: Data Classification | C6: Encryption Status | D6: Encryption Type | E6: Algorithm & Key Size | F6: Key Management Method | G6: Key Rotation Enabled | H6: Status | I6: Evidence Location | J6: Gap Description | K6: Remediation Needed | L6: Exception ID | M6: Risk ID | N6: Compensating Controls | O6: Responsible Person | P6: Target Date | Q6: Budget Required
A7: Example: Production SQL Server 2019 - FINDB01 | B7: Restricted | C7: Encrypted | D7: Database TDE | E7: AES-256 | F7: HSM | G7: Yes | H7: ✅ Compliant | I7: /evidence/databases/FINDB01-TDE-config.pdf | J7: None | K7: No | L7: N/A | M7: N/A | N7: N/A | O7: N/A | P7: N/A | Q7: No
A8: Veeam Backup Production | B8: Restricted | C8: Encrypted backups | D8: Full backup | E8: AES-256 | F8: Veeam password + KMS | G8: Annual | H8: ✅ Compliant | I8: Veeam backup reports | K8: No
A9: Commvault Enterprise | B9: Restricted | C9: Encrypted backups | D9: Full backup | E9: AES-256 | F9: Commvault key manager | G9: Annual | H9: ✅ Compliant | I9: Commvault encryption audit | K9: No
A10: AWS Backup | B10: Confidential | C10: AWS managed encryption | D10: Backup vaults | E10: AES-256-GCM | F10: AWS KMS | G10: Yes - Automatic | H10: ✅ Compliant | I10: AWS Backup config | K10: No
A11: Azure Backup | B11: Confidential | C11: Azure-managed | D11: Recovery vaults | E11: AES-256 | F11: Azure Key Vault | G11: Yes - Automatic | H11: ✅ Compliant | I11: Azure Backup reports | K11: No
A12: Database Backup (SQL) | B12: Restricted | C12: TDE backup encryption | D12: Native backup | E12: AES-256 | F12: SQL certificate | G12: Annual | H12: ✅ Compliant | I12: SQL backup audit | K12: No
A13: File Server Backup | B13: Confidential | C13: Encrypted tapes | D13: Tape backup | E13: AES-256 | F13: Tape library encryption | G13: Annual | H13: ✅ Compliant | I13: Tape library logs | K13: No
A14: Offsite Backup (Iron Mountain) | B14: Restricted | C14: Encrypted media | D14: Physical tapes | E14: AES-256 | F14: Key escrow | G14: Annual | H14: ✅ Compliant | I14: Iron Mountain inventory | K14: No
A15: Personal Backup (Time Machine) | B15: Internal | C15: FileVault encrypted | D15: Disk backup | E15: AES-256 | F15: User-managed | G15: No | H15: ⚠️ Partial | I15: Backup policy | J15: Enforce corporate backup | K15: Yes
A16: Legacy Backup System | B16: Internal | C16: No encryption | D16: None | E16: None | F16: None | G16: No | H16: ❌ Non-Compliant | I16: Legacy backup inventory | J16: Migrate to encrypted solution | K16: Yes
A22: 6. BACKUPS ENCRYPTION CHECKLIST
A23: ☐ | B23: Requirement | C23: Status
A24: ☐ | B24: Full backup encryption enabled
A25: ☐ | B25: Incremental/differential backups encrypted
A26: ☐ | B26: Backup encryption configured before first backup
A27: ☐ | B27: Backup encryption keys managed separately from backup data
A28: ☐ | B28: Offsite/cloud backup storage encrypted in transit AND at rest
A29: ☐ | B29: Tape backups encrypted (if applicable)
A30: ☐ | B30: Virtual machine backups encrypted
A31: ☐ | B31: Database backup encryption independent of TDE
A32: ☐ | B32: Backup restoration tested with encryption
A33: ☐ | B33: Backup encryption key recovery procedure documented
A34: ☐ | B34: Long-term archive backups maintain encryption
A35: ☐ | B35: Backup logs do not expose sensitive data in plaintext
A36: Checklist Score: | B36: =COUNTIF(C24:C35,"Yes")/COUNTA(C24:C35)*100&"%" -> #DIV/0!
A38: Technology-Specific Notes / Examples
A39: Agent-based: | B39: Veeam, Commvault, Veritas
A40: Cloud-native: | B40: AWS Backup, Azure Backup
A41: Database-native: | B41: RMAN (Oracle), SQL Server Backup
A42: File-level: | B42: rsync + GPG, Duplicati
A43: Container: | B43: Velero with encryption
A45: EXCEPTION / DEVIATION DOCUMENTATION (Complete if Status = Partial or Non-Compliant)
A46: Formal exception request submitted:
A47: Exception ID:
A48: Risk acceptance documented:
A49: Risk ID:
...

Sheet 7. Removable Media
A1: 7. REMOVABLE MEDIA - DATA AT REST ENCRYPTION Policy Requirement: Removable media storing organizational data MUST be encrypted (Policy Section 2.3.7)
A3: Does your organization use removable media (USB drives, external disks, optical media) to store or transport data?
A4: Response:
A6: Storage System/Device | B6: Data Classification | C6: Encryption Status | D6: Encryption Type | E6: Algorithm & Key Size | F6: Key Management Method | G6: Key Rotation Enabled | H6: Status | I6: Evidence Location | J6: Gap Description | K6: Remediation Needed | L6: Exception ID | M6: Risk ID | N6: Compensating Controls | O6: Responsible Person | P6: Target Date | Q6: Budget Required
A7: Example: Production SQL Server 2019 - FINDB01 | B7: Restricted | C7: Encrypted | D7: Database TDE | E7: AES-256 | F7: HSM | G7: Yes | H7: ✅ Compliant | I7: /evidence/databases/FINDB01-TDE-config.pdf | J7: None | K7: No | L7: N/A | M7: N/A | N7: N/A | O7: N/A | P7: N/A | Q7: No
A8: Encrypted USB Drives (IronKey) | B8: Confidential | C8: Hardware encrypted | D8: Full device | E8: AES-256 | F8: Hardware-based | G8: N/A | H8: ✅ Compliant | I8: IronKey deployment list | K8: No
A9: Encrypted USB Drives (Kingston) | B9: Confidential | C9: Hardware encrypted | D9: Full device | E9: AES-256 | F9: Hardware keypad | G9: N/A | H9: ✅ Compliant | I9: Kingston inventory | K9: No
A10: BitLocker To Go USB | B10: Internal | C10: BitLocker To Go | D10: Full device | E10: AES-256 | F10: AD recovery | G10: N/A | H10: ✅ Compliant | I10: BitLocker To Go policy | K10: No
A11: External HDDs (encrypted) | B11: Confidential | C11: Hardware encrypted | D11: Full disk | E11: AES-256 | F11: Hardware PIN | G11: N/A | H11: ✅ Compliant | I11: External HDD inventory | K11: No
A12: Corporate SD Cards | B12: Internal | C12: VeraCrypt | D12: Container | E12: AES-256 | F12: User password | G12: N/A | H12: ⚠️ Partial | I12: SD card policy | J12: Enforce hardware encryption | K12: Yes
A13: DVD/CD Media (archived) | B13: Internal | C13: Password-protected | D13: File-level | E13: Various | F13: Document password | G13: N/A | H13: ⚠️ Partial | I13: Optical media inventory | J13: Phase out optical media | K13: Yes
A14: Standard USB Drives | B14: Public | C14: No encryption | D14: None | E14: None | F14: None | G14: N/A | H14: ❌ Non-Compliant | I14: USB policy violation logs | J14: Block standard USB via GPO | K14: Yes
A15: Personal USB Drives | B15: N/A | C15: Blocked by policy | D15: N/A | E15: N/A | F15: N/A | G15: N/A | H15: ✅ Compliant | I15: DLP USB blocking rules | K15: No
A22: 7. REMOVABLE MEDIA ENCRYPTION CHECKLIST
A23: ☐ | B23: Requirement | C23: Status
A24: ☐ | B24: USB drive encryption mandatory via policy
A25: ☐ | B25: External hard drive encryption enforced
A26: ☐ | B26: BitLocker To Go / FileVault / LUKS configured
A27: ☐ | B27: Hardware-encrypted USB drives procured
A28: ☐ | B28: Unencrypted removable media blocked by endpoint policy
A29: ☐ | B29: Media encryption verified before data transfer
A30: ☐ | B30: Encrypted optical media (DVD/CD) procedures documented
A31: ☐ | B31: Lost removable media incident response includes encryption check
A32: ☐ | B32: Media disposal/destruction procedures enforce encryption verification
A33: ☐ | B33: Approved removable media inventory maintained
A34: ☐ | B34: Encryption exceptions require formal approval
A35: ☐ | B35: Regular compliance audits of removable media usage
A36: Checklist Score: | B36: =COUNTIF(C24:C35,"Yes")/COUNTA(C24:C35)*100&"%" -> #DIV/0!
A38: Technology-Specific Notes / Examples
A39: Windows: | B39: BitLocker To Go
A40: macOS: | B40: FileVault encrypted volumes
A41: Linux: | B41: LUKS containers
A42: Cross-platform: | B42: VeraCrypt
A43: Hardware: | B43: IronKey, Kingston Encrypted USB
A44: Enterprise: | B44: Symantec Endpoint Encryption
A46: EXCEPTION / DEVIATION DOCUMENTATION (Complete if Status = Partial or Non-Compliant)
A47: Formal exception request submitted:
A48: Exception ID:
A49: Risk acceptance documented:
A50: Risk ID:
...

Sheet Summary Dashboard
A1: DATA STORAGE ASSESSMENT - COMPLIANCE SUMMARY
A3: Assessment Area | B3: Total Items | C3: Compliant | D3: Partial | E3: Non-Compliant | F3: N/A | G3: Compliance %
A4: 1. Mobile Devices | B4: =COUNTA('1. Mobile Devices'!H8:H20) -> 8 | C4: =COUNTIF('1. Mobile Devices'!H8:H20,"✅*") -> 4 | D4: =COUNTIF('1. Mobile Devices'!H8:H20,"⚠️*") -> 2 | E4: =COUNTIF('1. Mobile Devices'!H8:H20,"❌*") -> 2 | F4: =COUNTIF('1. Mobile Devices'!H8:H20,"N/A") -> 0 | G4: =IF((B4-F4)=0,"0%",ROUND(C4/(B4-F4)*100,1)&"%") -> 50%
A5: 2. Laptops & Workstations | B5: =COUNTA('2. Laptops & Workstations'!H8:H20) -> 9 | C5: =COUNTIF('2. Laptops & Workstations'!H8:H20,"✅*") -> 6 | D5: =COUNTIF('2. Laptops & Workstations'!H8:H20,"⚠️*") -> 1 | E5: =COUNTIF('2. Laptops & Workstations'!H8:H20,"❌*") -> 2 | F5: =COUNTIF('2. Laptops & Workstations'!H8:H20,"N/A") -> 0 | G5: =IF((B5-F5)=0,"0%",ROUND(C5/(B5-F5)*100,1)&"%") -> 66.7%
A6: 3. Servers | B6: =COUNTA('3. Servers'!H8:H20) -> 8 | C6: =COUNTIF('3. Servers'!H8:H20,"✅*") -> 6 | D6: =COUNTIF('3. Servers'!H8:H20,"⚠️*") -> 1 | E6: =COUNTIF('3. Servers'!H8:H20,"❌*") -> 1 | F6: =COUNTIF('3. Servers'!H8:H20,"N/A") -> 0 | G6: =IF((B6-F6)=0,"0%",ROUND(C6/(B6-F6)*100,1)&"%") -> 75%
A7: 4. Databases | B7: =COUNTA('4. Databases'!H8:H20) -> 10 | C7: =COUNTIF('4. Databases'!H8:H20,"✅*") -> 4 | D7: =COUNTIF('4. Databases'!H8:H20,"⚠️*") -> 5 | E7: =COUNTIF('4. Databases'!H8:H20,"❌*") -> 1 | F7: =COUNTIF('4. Databases'!H8:H20,"N/A") -> 0 | G7: =IF((B7-F7)=0,"0%",ROUND(C7/(B7-F7)*100,1)&"%") -> 40%
A8: 5. Cloud Storage | B8: =COUNTA('5. Cloud Storage'!H8:H20) -> 10 | C8: =COUNTIF('5. Cloud Storage'!H8:H20,"✅*") -> 10 | D8: =COUNTIF('5. Cloud Storage'!H8:H20,"⚠️*") -> 0 | E8: =COUNTIF('5. Cloud Storage'!H8:H20,"❌*") -> 0 | F8: =COUNTIF('5. Cloud Storage'!H8:H20,"N/A") -> 0 | G8: =IF((B8-F8)=0,"0%",ROUND(C8/(B8-F8)*100,1)&"%") -> 100%
A9: 6. Backups | B9: =COUNTA('6. Backups'!H8:H20) -> 9 | C9: =COUNTIF('6. Backups'!H8:H20,"✅*") -> 7 | D9: =COUNTIF('6. Backups'!H8:H20,"⚠️*") -> 1 | E9: =COUNTIF('6. Backups'!H8:H20,"❌*") -> 1 | F9: =COUNTIF('6. Backups'!H8:H20,"N/A") -> 0 | G9: =IF((B9-F9)=0,"0%",ROUND(C9/(B9-F9)*100,1)&"%") -> 77.8%
A10: 7. Removable Media | B10: =COUNTA('7. Removable Media'!H8:H20) -> 8 | C10: =COUNTIF('7. Removable Media'!H8:H20,"✅*") -> 5 | D10: =COUNTIF('7. Removable Media'!H8:H20,"⚠️*") -> 2 | E10: =COUNTIF('7. Removable Media'!H8:H20,"❌*") -> 1 | F10: =COUNTIF('7. Removable Media'!H8:H20,"N/A") -> 0 | G10: =IF((B10-F10)=0,"0%",ROUND(C10/(B10-F10)*100,1)&"%") -> 62.5%
A11: TOTAL | B11: =SUM(B4:B10) -> 62 | C11: =SUM(C4:C10) -> 42 | D11: =SUM(D4:D10) -> 12 | E11: =SUM(E4:E10) -> 8 | F11: =SUM(F4:F10) -> 0 | G11: =IF((B11-F11)=0,"0%",ROUND(C11/(B11-F11)*100,1)&"%") -> 67.7%
A14: ENCRYPTION COVERAGE BY DATA CLASSIFICATION
A15: Data Classification | B15: Systems Assessed | C15: Encrypted | D15: Unencrypted | E15: Coverage %
A16: Restricted
A17: Confidential
A18: Internal
A19: Public
A22: KEY MANAGEMENT SUMMARY
A23: Key Management Method | B23: Count | C23: Percentage
A24: HSM | B24: =COUNTIF('1. Mobile Devices'!F8:F20,"HSM")+COUNTIF('2. Laptops & Workstations'!F8:F20,"HSM")+COUNTIF('3. Servers'!F8:F20,"HSM")+COUNTIF('4. Databases'!F8:F20,"HSM")+COUNTIF('5. Cloud Storage'!F8:F20,"HSM")+COUNTIF('6. Backups'!F8:F20,"HSM")+COUNTIF('7. Removable Media'!F8:F20,"HSM") -> 0 | C24: =IF(SUM(B24:B24)=0,"0%",ROUND(B24/SUM(B$24:B$24)*100,1)&"%") -> 0%
A25: Cloud KMS | B25: =COUNTIF('1. Mobile Devices'!F8:F20,"Cloud KMS")+COUNTIF('2. Laptops & Workstations'!F8:F20,"Cloud KMS")+COUNTIF('3. Servers'!F8:F20,"Cloud KMS")+COUNTIF('4. Databases'!F8:F20,"Cloud KMS")+COUNTIF('5. Cloud Storage'!F8:F20,"Cloud KMS")+COUNTIF('6. Backups'!F8:F20,"Cloud KMS")+COUNTIF('7. Removable Media'!F8:F20,"Cloud KMS") -> 2 | C25: =IF(SUM(B24:B25)=0,"0%",ROUND(B25/SUM(B$24:B$25)*100,1)&"%") -> 100%
A26: TPM | B26: =COUNTIF('1. Mobile Devices'!F8:F20,"TPM")+COUNTIF('2. Laptops & Workstations'!F8:F20,"TPM")+COUNTIF('3. Servers'!F8:F20,"TPM")+COUNTIF('4. Databases'!F8:F20,"TPM")+COUNTIF('5. Cloud Storage'!F8:F20,"TPM")+COUNTIF('6. Backups'!F8:F20,"TPM")+COUNTIF('7. Removable Media'!F8:F20,"TPM") -> 0 | C26: =IF(SUM(B24:B26)=0,"0%",ROUND(B26/SUM(B$24:B$26)*100,1)&"%") -> 0%
A27: Software-based | B27: =COUNTIF('1. Mobile Devices'!F8:F20,"Software-based")+COUNTIF('2. Laptops & Workstations'!F8:F20,"Software-based")+COUNTIF('3. Servers'!F8:F20,"Software-based")+COUNTIF('4. Databases'!F8:F20,"Software-based")+COUNTIF('5. Cloud Storage'!F8:F20,"Software-based")+COUNTIF('6. Backups'!F8:F20,"Software-based")+COUNTIF('7. Removable Media'!F8:F20,"Software-based") -> 0 | C27: =IF(SUM(B24:B27)=0,"0%",ROUND(B27/SUM(B$24:B$27)*100,1)&"%") -> 0%
A28: Manual | B28: =COUNTIF('1. Mobile Devices'!F8:F20,"Manual")+COUNTIF('2. Laptops & Workstations'!F8:F20,"Manual")+COUNTIF('3. Servers'!F8:F20,"Manual")+COUNTIF('4. Databases'!F8:F20,"Manual")+COUNTIF('5. Cloud Storage'!F8:F20,"Manual")+COUNTIF('6. Backups'!F8:F20,"Manual")+COUNTIF('7. Removable Media'!F8:F20,"Manual") -> 1 | C28: =IF(SUM(B24:B28)=0,"0%",ROUND(B28/SUM(B$24:B$28)*100,1)&"%") -> 33.3%
A29: Vendor-managed | B29: =COUNTIF('1. Mobile Devices'!F8:F20,"Vendor-managed")+COUNTIF('2. Laptops & Workstations'!F8:F20,"Vendor-managed")+COUNTIF('3. Servers'!F8:F20,"Vendor-managed")+COUNTIF('4. Databases'!F8:F20,"Vendor-managed")+COUNTIF('5. Cloud Storage'!F8:F20,"Vendor-managed")+COUNTIF('6. Backups'!F8:F20,"Vendor-managed")+COUNTIF('7. Removable Media'!F8:F20,"Vendor-managed") -> 0 | C29: =IF(SUM(B24:B29)=0,"0%",ROUND(B29/SUM(B$24:B$29)*100,1)&"%") -> 0%
A32: CRITICAL GAPS REQUIRING IMMEDIATE ATTENTION
A33: Priority | B33: Assessment Area | C33: Gap Description | D33: Responsible Person | E33: Target Date | F33: Status

Sheet Evidence Register
A1: EVIDENCE REGISTER
A2: List all evidence files/documents referenced in this assessment (audit traceability).
A4: Evidence ID | B4: Assessment Area | C4: Evidence Type | D4: Description | E4: Location/Path | F4: Date Collected | G4: Collected By | H4: Verification Status
A5: EV-001
A6: EV-002
A7: EV-003
A8: EV-004
A9: EV-005
A10: EVD-824.2-001 | B10: MDM Compliance Report - Mobile Devices | C10: Compliance Report | D10: 1. Mobile Devices | E10: MobileIron/Reports | F10: 2026-01-10 | G10: IT Admin | H10: 2 years | I10: Current
A11: EVD-824.2-002 | B11: iOS Encryption Policy Configuration | C11: Configuration Doc | D11: 1. Mobile Devices | E11: SharePoint/MDM/iOS | F11: 2026-01-10 | G11: Security Team | H11: 3 years | I11: Current
A12: EVD-824.2-003 | B12: Android Encryption Compliance Scan | C12: Scan Report | D12: 1. Mobile Devices | E12: Workspace ONE/Scans | F12: 2026-01-09 | G12: IT Admin | H12: 1 year | I12: Current
A13: EVD-824.2-004 | B13: BYOD Policy Document v2.1 | C13: Policy | D13: 1. Mobile Devices | E13: SharePoint/Policies/BYOD | F13: 2025-06-01 | G13: HR & Security | H13: 5 years | I13: Current
A14: EVD-824.2-005 | B14: BitLocker Deployment Status Report | C14: Deployment Report | D14: 2. Laptops & Workstations | E14: Intune/Reports | F14: 2026-01-10 | G14: Windows Admin | H14: 2 years | I14: Current
A15: EVD-824.2-006 | B15: FileVault 2 Compliance - Mac Fleet | C15: Compliance Report | D15: 2. Laptops & Workstations | E15: Jamf/Encryption | F15: 2026-01-10 | G15: Mac Admin | H15: 2 years | I15: Current
A16: EVD-824.2-007 | B16: BitLocker Recovery Key Escrow Audit | C16: Audit Report | D16: 2. Laptops & Workstations | E16: AD/BitLocker-Keys | F16: 2025-12-15 | G16: Security Team | H16: 3 years | I16: Current
A17: EVD-824.2-008 | B17: Linux LUKS Encryption Standards | C17: Technical Standard | D17: 2. Laptops & Workstations | E17: SharePoint/Standards | F17: 2025-08-01 | G17: Linux Team | H17: 5 years | I17: Current
A18: EVD-824.2-009 | B18: Server Encryption Audit Q4 2025 | C18: Audit Report | D18: 3. Servers | E18: SharePoint/Audits/Servers | F18: 2025-12-20 | G18: Internal Audit | H18: 7 years | I18: Current
A19: EVD-824.2-010 | B19: VMware VM Encryption Configuration | C19: Config Export | D19: 3. Servers | E19: vCenter/Configs | F19: 2026-01-08 | G19: VMware Admin | H19: 2 years | I19: Current
A20: EVD-824.2-011 | B20: Kubernetes etcd Encryption Config | C20: YAML Config | D20: 3. Servers | E20: Git/k8s/encryption | F20: 2025-11-15 | G20: K8s Admin | H20: 2 years | I20: Current
A21: EVD-824.2-012 | B21: PostgreSQL TDE Implementation Guide | C21: Technical Doc | D21: 4. Databases | E21: Confluence/Database/PG | F21: 2025-09-20 | G21: DBA Team | H21: 3 years | I21: Current
... A37: EVD-824.2-028 | B37: Encrypted USB Vendor Comparison | C37: Analysis Doc | D37: 7. Removable Media | E37: SharePoint/Procurement | F37: 2025-10-10 | G37: IT Procurement | H37: 3 years | I37: Current
A38: EV-034
A39: EV-035
A40: EV-036
A41: EV-037
A42: EV-038
A43: EV-039
A44: EV-040
A45: EV-041
A46: EV-042
A47: EV-043
A48: EV-044
A49: EV-045
... A104: EV-100

Sheet Approval Sign-Off
A1: ASSESSMENT APPROVAL AND SIGN-OFF
A3: Assessment Summary
A4: Assessment Document | B4: ISMS-IMP-A.8.24.2 - Data Storage Assessment
A5: Assessment Period | B5: Emily Rodriguez
A6: Overall Compliance Rate | B6: Security Analyst
A7: Assessment Status | B7: Information Security
B8: emily.rodriguez@company.com
B9: 2026-01-13
A10: ASSESSMENT COMPLETED BY
A11: Name:
A12: Role/Title:
A13: Department:
A14: Email: | B14: David Park
A15: Date: | B15: 2026-01-15
B16: Encryption coverage is comprehensive across storage systems. Legacy database encryption requires attention.
A18: APPROVED BY (CISO)
A19: Name:
A20: Date:
A21: Approval Decision: | B21: Michael Chen
B22: 2026-01-16
B23: Storage encryption controls meet requirements. Priority: Legacy backup system migration.
B28: Jennifer Williams
B29: 2026-01-18
B30: Approved with conditions
B31: Approved pending Q2 2026 completion of MongoDB KMS integration and legacy backup migration.
B36: 2026-04-13
B37: David Park
B38: Q2 2026 reassessment focusing on database encryption standardization
