Workbook

Sheet Instructions & Legend
A1: ISMS-IMP-A.8.24.3 – Authentication Assessment ISO/IEC 27001:2022 - Control A.8.24: Use of Cryptography
A3: Document Information
A4: Document ID | B4: ISMS-IMP-A.8.24.3
A5: Assessment Area | B5: Authentication Cryptographic Controls
A6: Related Policy | B6: ISMS-POL-A.8.24-S2.5
A7: Version | B7: 1.0
A8: Assessment Date
A9: Completed By
A10: Organization
A11: Review Cycle | B11: Quarterly
A13: HOW TO USE THIS WORKBOOK
A14: 1. Complete each worksheet tab (1–5) for applicable authentication methods
A15: 2. Use dropdown menus for standardized entries (Status, Auth Method, Algorithm, etc.)
A16: 3. Fill in yellow-highlighted cells with your information
A17: 4. If Status = Partial or Non-Compliant, complete the Exception/Deviation section
A18: 5. Document password policies, MFA implementations, certificate usage, and SSO configurations
A19: 6. Provide evidence location/path for each implementation entry
A20: 7. Summary Dashboard auto-calculates compliance statistics per authentication area
A21: 8. Maintain the Evidence Register for audit traceability
A22: 9. Obtain final approval and sign-off in the Approval Sign-Off sheet
A24: STATUS LEGEND
A25: Symbol | B25: Status | C25: Description
A26: ✅ | B26: Compliant | C26: Fully meets policy requirements
A27: ⚠️ | B27: Partial | C27: Some requirements met, gaps exist
A28: ❌ | B28: Non-Compliant | C28: Does not meet policy requirements
A29: N/A | B29: Not Applicable | C29: Requirement does not apply
A32: ACCEPTABLE EVIDENCE (examples)
A33: ✓ Password policy documentation
A34: ✓ Active Directory Group Policy Objects (GPO)
A35: ✓ MFA enrollment reports
A36: ✓ Certificate authority configurations
A37: ✓ PKI infrastructure documentation
A38: ✓ SSO/SAML configuration screenshots
A39: ✓ Identity provider (IdP) settings
A40: ✓ Service account inventory
A41: ✓ Authentication logs and audit trails
A42: ✓ Password hash algorithm verification
A43: ✓ Account lockout policy screenshots
... A46: ✓ Privilege access management (PAM) reports

Sheet 1. Password Security
A1: 1. PASSWORD SECURITY - PASSWORD AUTHENTICATION CONTROLS Policy Requirement: Passwords MUST be hashed using approved algorithms (bcrypt, Argon2, PBKDF2, scrypt). Minimum 12 characters, complexity requirements enforced (Policy Section 2.5.1)
A3: Does your organization use password-based authentication for any systems or applications?
A4: Response:
A6: System/Application | B6: Authentication Method | C6: User Type | D6: Data Classification | E6: Cryptographic Algorithm | F6: Hash/Encryption Status | G6: Password Complexity | H6: Status | I6: Evidence Location | J6: Gap Description | K6: Remediation Needed | L6: Exception ID | M6: Risk ID | N6: Compensating Controls | O6: Responsible Person | P6: Target Date | Q6: Budget Required | R6: Min Password Length | S6: Complexity Enforced | T6: Password Expiry | U6: Password History | V6: Account Lockout | W6: Password Strength Meter | X6: Default Passwords
A7: Example: Production HR System - Workday | B7: Password | C7: End User | D7: Confidential | E7: bcrypt | F7: Properly Hashed | G7: Strong (≥14 chars) | H7: ✅ Compliant | I7: /evidence/auth/workday-password-policy.pdf | J7: None | K7: No | L7: N/A | M7: N/A | N7: N/A | O7: N/A | P7: N/A | Q7: No | R7: ≥14 chars | S7: Yes | T7: 90 days | U7: ≥10 passwords | V7: Yes | W7: Yes | X7: Changed
A8: Active Directory | B8: NIST SP 800-63B compliant | C8: Argon2id | D8: 12 characters minimum | E8: Yes - 90 days | F8: GPO enforced | G8: Password policy GPO | H8: ✅ Compliant | I8: AD audit logs | K8: No
A9: Azure AD | B9: NIST compliant + MFA | C9: Azure AD hash | D9: 12 characters + complexity | E9: Yes - Conditional | F9: Conditional Access | G9: Azure AD security | H9: ✅ Compliant | I9: Azure AD logs | K9: No
A10: Linux PAM | B10: NIST compliant | C10: SHA-512 + salt | D10: 14 characters | E10: Yes - 90 days | F10: PAM config | G10: PAM config files | H10: ✅ Compliant | I10: /etc/pam.d/ audit | K10: No
A11: Database Accounts | B11: Application-specific | C11: SCRAM-SHA-256 | D11: 16 characters | E11: Yes - 180 days | F11: DB password policy | G11: DB security audit | H11: ✅ Compliant | I11: DB password logs | K11: No
A12: Application Users | B12: OWASP compliant | C12: bcrypt (cost 12) | D12: 12 characters + 2FA | E12: Yes - 120 days | F12: App password policy | G12: App security config | H12: ✅ Compliant | I12: App audit logs | K12: No
A13: Legacy Applications | B13: Basic requirements | C13: MD5 hash | D13: 8 characters | E13: No expiry | F13: No policy | G13: Legacy app list | H13: ❌ Non-Compliant | I13: Legacy audit | J13: Migrate or decommission | K13: Yes
A14: Service Accounts (AD) | B14: Strong passwords | C14: Kerberos AES-256 | D14: 20+ random chars | E14: No expiry + monitoring | F14: Managed Service Accounts | G14: AD service account policy | H14: ✅ Compliant | I14: AD service logs | K14: No
A15: API Keys | B15: Cryptographically strong | C15: HMAC-SHA-256 | D15: 32+ bytes entropy | E15: Yes - 180 days | F15: Vault rotation | G15: API key management | H15: ✅ Compliant | I15: Vault audit logs | K15: No
A22: 1. PASSWORD SECURITY CHECKLIST
A23: ☐ | B23: Requirement | C23: Status
A24: ☐ | B24: Passwords hashed with approved algorithm (bcrypt, Argon2, PBKDF2, scrypt)
A25: ☐ | B25: Passwords NOT stored in plaintext anywhere
A26: ☐ | B26: Passwords NOT stored with reversible encryption
A27: ☐ | B27: Password hashes salted (unique salt per user)
A28: ☐ | B28: Minimum password length ≥12 characters
A29: ☐ | B29: Recommended password length ≥14 characters
A30: ☐ | B30: Complexity requirements enforced (uppercase, lowercase, numbers, symbols)
A31: ☐ | B31: Password expiration policy: 90 days maximum (or risk-based)
A32: ☐ | B32: Password history enforced (minimum 10 previous passwords)
A33: ☐ | B33: Account lockout after failed attempts (5-10 attempts)
A34: ☐ | B34: Lockout duration or CAPTCHA implemented
A35: ☐ | B35: Common/weak passwords blocked (breach database check)
... A43: ☐ | B43: Privileged accounts require stronger passwords (≥14 characters)
A44: Checklist Score: | B44: =COUNTIF(C24:C43,"Yes")/COUNTA(C24:C43)*100&"%" -> #DIV/0!
A46: APPROVED PASSWORD HASHING ALGORITHMS
A47: Algorithm | B47: Work Factor | C47: Salt Required | D47: Security Level | E47: Use Case
A48: Argon2id | B48: High (configurable) | C48: Yes | D48: Highest | E48: New implementations (recommended)
A49: bcrypt | B49: Medium-High (cost factor 10-12) | C49: Yes | D49: High | E49: Widely supported, proven
A50: PBKDF2-SHA256 | B50: High (100,000+ iterations) | C50: Yes | D50: High | E50: Standards compliance (NIST)
A51: scrypt | B51: High (configurable) | C51: Yes | D51: High | E51: Memory-hard function
A53: PASSWORD COMPLEXITY STANDARDS
A54: Account Type | B54: Min Length | C54: Complexity | D54: Expiry | E54: MFA Required
A55: Standard User | B55: 12 chars | C55: Upper, lower, number, symbol | D55: 90 days | E55: Recommended
A56: Administrator | B56: 14 chars | C56: Upper, lower, number, symbol | D56: 90 days | E56: Required
A57: Service Account | B57: 20 chars | C57: Random generation | D57: No expiry (monitor) | E57: Certificate preferred
...

Sheet 2. Multi-Factor Authentication
A1: 2. MULTI-FACTOR AUTHENTICATION (MFA) - STRONG AUTHENTICATION Policy Requirement: MFA REQUIRED for all administrative access, remote access, and access to Confidential/Restricted data. Approved factors: TOTP, Push notification, Hardware token, Biometric (Policy Section 2.5.2)
A3: Does your organization require multi-factor authentication for any systems or user types?
A4: Response:
A6: System/Application | B6: Authentication Method | C6: User Type | D6: Data Classification | E6: Cryptographic Algorithm | F6: Hash/Encryption Status | G6: Password Complexity | H6: Status | I6: Evidence Location | J6: Gap Description | K6: Remediation Needed | L6: Exception ID | M6: Risk ID | N6: Compensating Controls | O6: Responsible Person | P6: Target Date | Q6: Budget Required | R6: MFA Factor Type | S6: MFA Enrollment Rate | T6: MFA Enforcement | U6: Backup MFA Method | V6: MFA Bypass Allowed | W6: Passwordless Option
A7: Example: AWS Production Account | B7: MFA | C7: Administrator | D7: Restricted | E7: TOTP | F7: Encrypted | G7: N/A | H7: ✅ Compliant | I7: /evidence/auth/aws-mfa-config.pdf | J7: None | K7: No | L7: N/A | M7: N/A | N7: N/A | O7: N/A | P7: N/A | Q7: No | R7: TOTP (Authenticator App) | S7: 100% | T7: Required | U7: Yes | V7: Never | W7: Available
A8: Azure AD MFA | B8: TOTP + Push + FIDO2 | C8: 100% admin, 95% users | D8: Authenticator app | E8: Yes - Conditional Access | F8: Azure AD MFA | G8: Azure MFA report | H8: ✅ Compliant | I8: Azure AD MFA logs | K8: No
A9: VPN Access MFA | B9: TOTP + Push | C9: 100% required | D9: Duo Security | E9: Yes - Always | F9: Duo MFA | G9: Duo admin dashboard | H9: ✅ Compliant | I9: Duo authentication logs | K9: No
A10: SSH Bastion MFA | B10: FIDO2 hardware keys | C10: 100% required | D10: YubiKey 5 | E10: Yes - Always | F10: PAM + Yubikey | G10: SSH bastion config | H10: ✅ Compliant | I10: SSH audit logs | K10: No
A11: Admin Portal MFA | B11: TOTP + Backup codes | C11: 100% required | D11: Google Authenticator | E11: Yes - Always | F11: App-level MFA | G11: Admin portal config | H11: ✅ Compliant | I11: Admin access logs | K11: No
A12: AWS Console MFA | B12: Virtual MFA + U2F | C12: 100% IAM users | D12: AWS MFA | E12: Yes - Always | F12: IAM MFA policies | G12: IAM credential report | H12: ✅ Compliant | I12: CloudTrail MFA events | K12: No
A13: Critical Systems | B13: FIDO2 + Biometric | C13: 100% required | D13: Windows Hello + YubiKey | E13: Yes - Always | F13: Conditional Access | G13: Critical system policy | H13: ✅ Compliant | I13: Access audit logs | K13: No
A14: Developer Systems | B14: TOTP | C14: 85% adoption | D14: Various | E14: Recommended | F14: Not enforced | G14: Dev MFA report | H14: ⚠️ Partial | I14: Dev access logs | J14: Enforce 100% MFA | K14: Yes
A15: Legacy Systems | B15: No MFA | C15: 0% coverage | D15: N/A | E15: Not supported | F15: N/A | G15: Legacy system list | H15: ❌ Non-Compliant | I15: Legacy access logs | J15: Implement MFA proxy | K15: Yes
A22: 2. MULTI CHECKLIST
A23: ☐ | B23: Requirement | C23: Status
A24: ☐ | B24: MFA required for all administrative/privileged access
A25: ☐ | B25: MFA required for remote access (VPN, RDP, SSH)
A26: ☐ | B26: MFA required for access to Confidential/Restricted data
A27: ☐ | B27: MFA required for cloud service access (AWS, Azure, GCP, M365)
A28: ☐ | B28: MFA enrollment mandatory for all users
A29: ☐ | B29: TOTP (time-based one-time password) supported
A30: ☐ | B30: Push notification MFA supported
A31: ☐ | B31: Hardware security keys (FIDO2/WebAuthn) supported
A32: ☐ | B32: SMS-based MFA deprecated or phased out
A33: ☐ | B33: Biometric authentication available (where appropriate)
A34: ☐ | B34: Backup MFA methods configured for each user
A35: ☐ | B35: MFA bypass requests logged and approved
... A42: ☐ | B42: Adaptive/risk-based MFA implemented
A43: Checklist Score: | B43: =COUNTIF(C24:C42,"Yes")/COUNTA(C24:C42)*100&"%" -> #DIV/0!
A45: MFA FACTOR SECURITY COMPARISON
A46: MFA Factor | B46: Security Level | C46: Phishing Resistant | D46: User Convenience | E46: Recommended Use
A47: FIDO2/WebAuthn (Hardware Key) | B47: Highest | C47: Yes | D47: High | E47: Privileged accounts, high-security
A48: Certificate-based | B48: Highest | C48: Yes | D48: Medium | E48: Service accounts, automation
A49: TOTP (Authenticator App) | B49: High | C49: No | D49: High | E49: General users, widely supported
A50: Push Notification | B50: High | C50: Partial | D50: High | E50: General users, mobile-friendly
A51: Biometric (with device trust) | B51: High | C51: Partial | D51: Highest | E51: Endpoints, mobile devices
A52: SMS/Voice | B52: Low | C52: No | D52: Medium | E52: DEPRECATED - legacy only
A54: MFA IMPLEMENTATION PRIORITIES
A55: Priority | B55: Account Type | C55: MFA Requirement | D55: Recommended Factor
A56: Critical | B56: Domain Administrators | C56: Required | D56: Hardware key + Backup TOTP
...

Sheet 3. Certificate-Based Auth
A1: 3. CERTIFICATE-BASED AUTHENTICATION - PKI & DIGITAL CERTIFICATES Policy Requirement: Certificate-based authentication REQUIRED for service accounts, automated processes, and high-security environments. Certificates issued from trusted CA with proper key management (Policy Section 2.5.3)
A3: Does your organization use digital certificates for authentication (client certificates, smart cards, machine authentication)?
A4: Response:
A6: System/Application | B6: Authentication Method | C6: User Type | D6: Data Classification | E6: Cryptographic Algorithm | F6: Hash/Encryption Status | G6: Password Complexity | H6: Status | I6: Evidence Location | J6: Gap Description | K6: Remediation Needed | L6: Exception ID | M6: Risk ID | N6: Compensating Controls | O6: Responsible Person | P6: Target Date | Q6: Budget Required | R6: Certificate Type | S6: Issuing CA | T6: Key Algorithm | U6: Certificate Validity | V6: CRL/OCSP Configured | W6: Smart Card Required | X6: PIV/CAC Compliant
A7: Example: VPN Gateway - Cisco ASA | B7: Certificate | C7: End User | D7: Confidential | E7: RSA-3072 | F7: Encrypted | G7: N/A | H7: ✅ Compliant | I7: /evidence/auth/vpn-cert-config.pdf | J7: None | K7: No | L7: N/A | M7: N/A | N7: N/A | O7: N/A | P7: N/A | Q7: No | R7: Client Certificate | S7: Internal CA | T7: RSA-3072 | U7: ≤1 year | V7: Yes | W7: No | X7: No
A8: Smart Card Logon (PIV) | B8: X.509 certificates | C8: 100% executives | D8: PIV smart cards | E8: Annual cert renewal | F8: AD Certificate Services | G8: PIV deployment docs | H8: ✅ Compliant | I8: Smart card logs | K8: No
A9: Client Certificates (mTLS) | B9: X.509 certificates | C9: 100% API clients | D9: Client certs | E9: Certificate rotation | F9: Internal PKI | G9: mTLS architecture | H9: ✅ Compliant | I9: PKI audit logs | K9: No
A10: Machine Certificates | B10: X.509 certificates | C10: 100% managed devices | D10: MDM-issued | E10: Automatic renewal | F10: MDM PKI integration | G10: MDM certificate policy | H10: ✅ Compliant | I10: MDM cert logs | K10: No
A11: VPN Certificates | B11: X.509 + username | C11: Partner VPN only | D11: Client certificates | E11: Annual renewal | F11: VPN CA | G11: VPN cert config | H11: ✅ Compliant | I11: VPN authentication logs | K11: No
A12: Email Signing (S/MIME) | B12: X.509 certificates | C12: 85% executives | D12: S/MIME certs | E12: Annual renewal | F12: Public CA + Internal | G12: S/MIME deployment | H12: ⚠️ Partial | I12: Certificate store audit | J12: Increase to 100% | K12: Yes
A13: Code Signing | B13: X.509 + HSM | C13: 100% releases | D13: EV code signing | E13: Annual renewal | F13: YubiKey HSM | G13: Code signing procedure | H13: ✅ Compliant | I13: Signing logs | K13: No
A22: 3. CERTIFICATE CHECKLIST
A23: ☐ | B23: Requirement | C23: Status
A24: ☐ | B24: Certificates issued from trusted CA (internal PKI or public CA)
A25: ☐ | B25: Certificate-based auth required for service accounts
A26: ☐ | B26: Certificate-based auth required for automated processes
A27: ☐ | B27: Client certificates used for VPN/remote access
A28: ☐ | B28: Smart cards issued for privileged users
A29: ☐ | B29: Machine/device certificates for endpoint authentication
A30: ☐ | B30: Certificate validity ≤2 years (1 year preferred)
A31: ☐ | B31: Certificate revocation checking enabled (CRL/OCSP)
A32: ☐ | B32: Certificate pinning implemented for critical services
A33: ☐ | B33: Private keys stored in HSM/TPM/smart card
A34: ☐ | B34: Private keys never exported in plaintext
A35: ☐ | B35: Certificate enrollment process documented
... A41: ☐ | B41: Certificate revocation process tested
A42: Checklist Score: | B42: =COUNTIF(C24:C41,"Yes")/COUNTA(C24:C41)*100&"%" -> #DIV/0!
A44: CERTIFICATE AUTHENTICATION USE CASES
A45: Use Case | B45: Certificate Type | C45: Key Algorithm | D45: Validity | E45: Storage
A46: Service Account Auth | B46: Client Certificate | C46: RSA-3072+ | D46: 1 year | E46: HSM/KMS
A47: Smart Card Login | B47: User Certificate (PIV) | C47: RSA-2048+ or ECDSA P-256+ | D47: 1-3 years | E47: Smart Card
A48: VPN Client Auth | B48: Client Certificate | C48: RSA-3072+ or ECDSA P-256+ | D48: 1 year | E48: TPM/Smart Card
A49: Machine/Device Auth | B49: Device Certificate | C49: RSA-2048+ or ECDSA P-256+ | D49: 1-2 years | E49: TPM
A50: Mutual TLS (mTLS) | B50: Client & Server Cert | C50: RSA-3072+ or ECDSA P-256+ | D50: 1 year | E50: HSM/KMS
A51: Code Signing | B51: Code Signing Cert | C51: RSA-3072+ | D51: 1-3 years | E51: Hardware Token
A52: Email Signing (S/MIME) | B52: Email Certificate | C52: RSA-2048+ or ECDSA P-256+ | D52: 1 year | E52: Smart Card/Keystore
A54: PKI INFRASTRUCTURE CHECKLIST
A55: Component | B55: Requirement | C55: Implementation Status
A56: Root CA | B56: Offline, HSM-protected
A57: Issuing CA | B57: Online, HSM-protected
...

Sheet 4. Service Accounts
A1: 4. SERVICE ACCOUNTS - NON-HUMAN AUTHENTICATION Policy Requirement: Service accounts MUST use certificate-based authentication or long random passwords (≥20 characters). Password expiry disabled with monitoring. MFA or certificate preferred (Policy Section 2.5.4)
A3: Does your organization use service accounts for application-to-application or automated process authentication?
A4: Response:
A6: System/Application | B6: Authentication Method | C6: User Type | D6: Data Classification | E6: Cryptographic Algorithm | F6: Hash/Encryption Status | G6: Password Complexity | H6: Status | I6: Evidence Location | J6: Gap Description | K6: Remediation Needed | L6: Exception ID | M6: Risk ID | N6: Compensating Controls | O6: Responsible Person | P6: Target Date | Q6: Budget Required | R6: Service Account Type | S6: Auth Method | T6: Password Rotation | U6: Privileged Account | V6: Account Monitoring | W6: Interactive Login | X6: Least Privilege
A7: Example: Database Service Account - SQL_SVC | B7: Service Account | C7: Service Account | D7: Restricted | E7: Certificate | F7: Encrypted | G7: N/A | H7: ✅ Compliant | I7: /evidence/auth/sqlsvc-cert.pdf | J7: None | K7: No | L7: N/A | M7: N/A | N7: N/A | O7: N/A | P7: N/A | Q7: No | R7: Database Service | S7: Certificate | T7: Never (Monitored) | U7: Yes | V7: Yes | W7: Disabled | X7: Yes
A8: Azure Managed Identities | B8: Azure AD workload identity | C8: 100% Azure resources | D8: Managed Identity | E8: N/A - Automatic | F8: Azure RBAC | G8: Azure MI configuration | H8: ✅ Compliant | I8: Azure activity logs | K8: No
A9: AWS IAM Roles | B9: IAM role assumption | C9: 100% AWS resources | D9: IAM Roles | E9: N/A - Temporary creds | F9: IAM policies | G9: IAM role documentation | H9: ✅ Compliant | I9: CloudTrail AssumeRole | K9: No
A10: GCP Service Accounts | B10: GCP service account | C10: 100% GCP resources | D10: Service Account keys | E10: Key rotation 90 days | F10: GCP IAM | G10: GCP SA inventory | H10: ✅ Compliant | I10: Cloud Audit Logs | K10: No
A11: AD Group Managed Service Accounts | B11: gMSA | C11: 80% Windows services | D11: gMSA | E11: N/A - AD managed | F11: AD gMSA | G11: gMSA deployment | H11: ⚠️ Partial | I11: AD service logs | J11: Migrate remaining services | K11: Yes
A12: Kubernetes Service Accounts | B12: K8s SA + RBAC | C12: 100% pods | D12: JWT tokens | E12: Automatic rotation | F12: K8s RBAC | G12: K8s SA policies | H12: ✅ Compliant | I12: K8s audit logs | K12: No
A13: Database Service Accounts | B13: DB-specific | C13: 100% apps | D13: Strong passwords | E13: 180 days | F13: Secret rotation | G13: DB account inventory | H13: ⚠️ Partial | I13: DB audit logs | J13: Implement secret manager | K13: Yes
A14: Legacy Service Accounts | B14: Hardcoded passwords | C14: Legacy apps | D14: Static passwords | E14: No rotation | F14: No management | G14: Legacy SA list | H14: ❌ Non-Compliant | I14: Legacy app audit | J14: Modernize authentication | K14: Yes
A22: 4. SERVICE ACCOUNTS CHECKLIST
A23: ☐ | B23: Requirement | C23: Status
A24: ☐ | B24: Service account inventory maintained and up to date
A25: ☐ | B25: Certificate-based authentication used (preferred)
A26: ☐ | B26: Managed identities used for cloud services (AWS IAM, Azure MI)
A27: ☐ | B27: Long random passwords (≥20 characters) if certificate not available
A28: ☐ | B28: Password expiry disabled with compensating monitoring
A29: ☐ | B29: Service account passwords stored in secrets vault
A30: ☐ | B30: Service account passwords NEVER hardcoded in code
A31: ☐ | B31: Service account passwords NEVER in configuration files
A32: ☐ | B32: Interactive login disabled for service accounts
A33: ☐ | B33: Service accounts follow least privilege principle
A34: ☐ | B34: Service account usage logged and monitored
A35: ☐ | B35: Service account activity anomaly detection configured
... A42: ☐ | B42: Break-glass procedures for service account failures
A43: Checklist Score: | B43: =COUNTIF(C24:C42,"Yes")/COUNTA(C24:C42)*100&"%" -> #DIV/0!
A45: SERVICE ACCOUNT AUTHENTICATION METHODS
A46: Authentication Method | B46: Security Level | C46: Use Case | D46: Implementation
A47: Managed Identity (Cloud) | B47: Highest | C47: Cloud services (AWS, Azure, GCP) | D47: AWS IAM Roles, Azure Managed Identity
A48: Certificate-based | B48: Highest | C48: On-premises, API integration | D48: Client certificates, mTLS
A49: Secrets Vault (HashiCorp/CyberArk) | B49: High | C49: Dynamic secret generation | D49: Vault dynamic credentials
A50: API Key (Long, Random) | B50: Medium-High | C50: API services, integrations | D50: ≥256-bit entropy, rotated 90 days
A51: Long Password (≥20 chars) | B51: Medium | C51: Legacy systems, compatibility | D51: Random generation, vault storage
A52: Shared Secret | B52: Low | C52: DEPRECATED | D52: Phase out
A54: SERVICE ACCOUNT LIFECYCLE MANAGEMENT
A55: Lifecycle Stage | B55: Actions | C55: Responsible Role | D55: Frequency
A56: Request | B56: Business justification, owner assignment | C56: Service Owner | D56: As needed
A57: Provisioning | B57: Create account, assign permissions, document | C57: IAM Admin | D57: Upon approval
...

Sheet 5. SSO & Federation
A1: 5. SSO & FEDERATION - CENTRALIZED AUTHENTICATION Policy Requirement: SSO/Federation REQUIRED using SAML 2.0, OAuth 2.0/OIDC, or WS-Federation. Identity Provider (IdP) must enforce strong authentication and MFA (Policy Section 2.5.5)
A3: Does your organization use Single Sign-On (SSO) or federated authentication for applications and services?
A4: Response:
A6: System/Application | B6: Authentication Method | C6: User Type | D6: Data Classification | E6: Cryptographic Algorithm | F6: Hash/Encryption Status | G6: Password Complexity | H6: Status | I6: Evidence Location | J6: Gap Description | K6: Remediation Needed | L6: Exception ID | M6: Risk ID | N6: Compensating Controls | O6: Responsible Person | P6: Target Date | Q6: Budget Required | R6: SSO Protocol | S6: Identity Provider | T6: MFA at IdP | U6: Just-In-Time Provisioning | V6: Session Timeout | W6: Certificate Validation | X6: Token Encryption
A7: Example: Office 365 SSO - Azure AD | B7: SSO | C7: End User | D7: Confidential | E7: SHA-256 | F7: Encrypted | G7: N/A | H7: ✅ Compliant | I7: /evidence/auth/o365-sso-config.pdf | J7: None | K7: No | L7: N/A | M7: N/A | N7: N/A | O7: N/A | P7: N/A | Q7: No | R7: SAML 2.0 | S7: Azure AD | T7: Yes | U7: Enabled | V7: ≤1 hour | W7: Yes | X7: Yes
A8: Azure AD SSO | B8: SAML 2.0 + OpenID Connect | C8: 95% SaaS apps | D8: Azure AD | E8: Conditional Access enforced | F8: Azure AD SSO | G8: Azure AD app gallery | H8: ✅ Compliant | I8: Azure AD sign-ins | K8: No
A9: Okta SSO | B9: SAML 2.0 + OAuth 2.0 | C9: 100% federated apps | D9: Okta | E9: MFA + Adaptive Auth | F9: Okta Universal Directory | G9: Okta app integrations | H9: ✅ Compliant | I9: Okta system logs | K9: No
A10: ADFS Federation | B10: WS-Federation + SAML | C10: 100% AD-integrated | D10: ADFS | E10: MFA enforced | F10: ADFS + Azure AD | G10: ADFS architecture | H10: ✅ Compliant | I10: ADFS audit logs | K10: No
A11: Google Workspace SSO | B11: SAML 2.0 | C11: 100% Google apps | D11: Google SSO | E11: Security key enforced | F11: Google Admin | G11: Google SSO config | H11: ✅ Compliant | I11: Google Admin logs | K11: No
A12: AWS SSO (IAM Identity Center) | B12: SAML 2.0 | C12: 100% AWS accounts | D12: AWS SSO | E12: MFA required | F12: AWS Organizations | G12: AWS SSO configuration | H12: ✅ Compliant | I12: CloudTrail SSO events | K12: No
A13: Custom Apps with SSO | B13: SAML 2.0 + OIDC | C13: 80% custom apps | D13: Various IdPs | E13: MFA where supported | F13: App-specific | G13: Custom app inventory | H13: ⚠️ Partial | I13: App authentication logs | J13: Complete SSO integration | K13: Yes
A14: Legacy Apps (No SSO) | B14: Local authentication | C14: 20% legacy apps | D14: N/A | E14: N/A | F14: Local credentials | G14: Legacy app list | H14: ❌ Non-Compliant | I14: Local auth logs | J14: Implement SSO proxy | K14: Yes
A22: 5. SSO & FEDERATION CHECKLIST
A23: ☐ | B23: Requirement | C23: Status
A24: ☐ | B24: SSO implemented for all compatible applications
A25: ☐ | B25: SAML 2.0, OAuth 2.0/OIDC, or WS-Federation protocols used
A26: ☐ | B26: Centralized Identity Provider (IdP) configured
A27: ☐ | B27: MFA enforced at IdP level
A28: ☐ | B28: SAML assertions signed and encrypted
A29: ☐ | B29: Certificate-based trust established (SAML metadata)
A30: ☐ | B30: Token lifetime/expiration configured (≤1 hour access token)
A31: ☐ | B31: Refresh token rotation implemented
A32: ☐ | B32: Just-in-time (JIT) user provisioning configured
A33: ☐ | B33: Attribute/claim mapping documented
A34: ☐ | B34: SSO session timeout configured (≤8 hours)
A35: ☐ | B35: Conditional access policies implemented
... A43: ☐ | B43: Privileged access management (PAM) integrated with SSO
A44: Checklist Score: | B44: =COUNTIF(C24:C43,"Yes")/COUNTA(C24:C43)*100&"%" -> #DIV/0!
A46: SSO PROTOCOL COMPARISON
A47: Protocol | B47: Use Case | C47: Security Features | D47: Token Type | E47: Best For
A48: SAML 2.0 | B48: Enterprise SSO, SaaS | C48: Signed/encrypted assertions, strong binding | D48: XML assertions | E48: Enterprise applications, legacy systems
A49: OAuth 2.0 + OIDC | B49: Modern web/mobile apps, APIs | C49: JWT tokens, PKCE, scopes | D49: JSON Web Tokens (JWT) | E49: Cloud-native apps, mobile, APIs
A50: WS-Federation | B50: Microsoft ecosystems | C50: Encrypted tokens, claims-based | D50: SAML tokens | E50: Active Directory Federation Services (ADFS)
A51: Kerberos | B51: On-premises Windows | C51: Ticket-based, mutual authentication | D51: Kerberos tickets | E51: Internal Windows environments
A53: IDENTITY PROVIDER SECURITY CHECKLIST
A54: Requirement | B54: Implementation Status | C54: Notes
A55: MFA enforcement at IdP | C55: Required for all users
A56: Conditional access policies | C56: Risk-based authentication
A57: Device compliance checking | C57: Managed devices only
A58: Geo-location restrictions | C58: Block suspicious locations
...

Sheet Summary Dashboard
A1: AUTHENTICATION ASSESSMENT - COMPLIANCE SUMMARY
A3: Assessment Area | B3: Total Items | C3: Compliant | D3: Partial | E3: Non-Compliant | F3: N/A | G3: Compliance %
A4: 1. Password Security | B4: =COUNTA('1. Password Security'!H8:H20) -> 8 | C4: =COUNTIF('1. Password Security'!H8:H20,"✅*") -> 7 | D4: =COUNTIF('1. Password Security'!H8:H20,"⚠️*") -> 0 | E4: =COUNTIF('1. Password Security'!H8:H20,"❌*") -> 1 | F4: =COUNTIF('1. Password Security'!H8:H20,"N/A") -> 0 | G4: =IF((B4-F4)=0,"0%",ROUND(C4/(B4-F4)*100,1)&"%") -> 87.5%
A5: 2. Multi-Factor Authentication | B5: =COUNTA('2. Multi-Factor Authentication'!H8:H20) -> 8 | C5: =COUNTIF('2. Multi-Factor Authentication'!H8:H20,"✅*") -> 6 | D5: =COUNTIF('2. Multi-Factor Authentication'!H8:H20,"⚠️*") -> 1 | E5: =COUNTIF('2. Multi-Factor Authentication'!H8:H20,"❌*") -> 1 | F5: =COUNTIF('2. Multi-Factor Authentication'!H8:H20,"N/A") -> 0 | G5: =IF((B5-F5)=0,"0%",ROUND(C5/(B5-F5)*100,1)&"%") -> 75%
A6: 3. Certificate-Based Auth | B6: =COUNTA('3. Certificate-Based Auth'!H8:H20) -> 6 | C6: =COUNTIF('3. Certificate-Based Auth'!H8:H20,"✅*") -> 5 | D6: =COUNTIF('3. Certificate-Based Auth'!H8:H20,"⚠️*") -> 1 | E6: =COUNTIF('3. Certificate-Based Auth'!H8:H20,"❌*") -> 0 | F6: =COUNTIF('3. Certificate-Based Auth'!H8:H20,"N/A") -> 0 | G6: =IF((B6-F6)=0,"0%",ROUND(C6/(B6-F6)*100,1)&"%") -> 83.3%
A7: 4. Service Accounts | B7: =COUNTA('4. Service Accounts'!H8:H20) -> 7 | C7: =COUNTIF('4. Service Accounts'!H8:H20,"✅*") -> 4 | D7: =COUNTIF('4. Service Accounts'!H8:H20,"⚠️*") -> 2 | E7: =COUNTIF('4. Service Accounts'!H8:H20,"❌*") -> 1 | F7: =COUNTIF('4. Service Accounts'!H8:H20,"N/A") -> 0 | G7: =IF((B7-F7)=0,"0%",ROUND(C7/(B7-F7)*100,1)&"%") -> 57.1%
A8: 5. SSO & Federation | B8: =COUNTA('5. SSO & Federation'!H8:H20) -> 7 | C8: =COUNTIF('5. SSO & Federation'!H8:H20,"✅*") -> 5 | D8: =COUNTIF('5. SSO & Federation'!H8:H20,"⚠️*") -> 1 | E8: =COUNTIF('5. SSO & Federation'!H8:H20,"❌*") -> 1 | F8: =COUNTIF('5. SSO & Federation'!H8:H20,"N/A") -> 0 | G8: =IF((B8-F8)=0,"0%",ROUND(C8/(B8-F8)*100,1)&"%") -> 71.4%
A9: TOTAL | B9: =SUM(B4:B8) -> 36 | C9: =SUM(C4:C8) -> 27 | D9: =SUM(D4:D8) -> 5 | E9: =SUM(E4:E8) -> 4 | F9: =SUM(F4:F8) -> 0 | G9: =IF((B9-F9)=0,"0%",ROUND(C9/(B9-F9)*100,1)&"%") -> 75%
A12: AUTHENTICATION METHOD DISTRIBUTION
A13: Authentication Method | B13: Count | C13: Percentage | D13: Security Rating
A14: Password Only | C14: =IF(SUM(B14:B14)=0,"0%",ROUND(B14/SUM(B$14:B$14)*100,1)&"%") -> 0% | D14: LOW RISK ⚠️
A15: Password + MFA | C15: =IF(SUM(B14:B15)=0,"0%",ROUND(B15/SUM(B$14:B$15)*100,1)&"%") -> 0% | D15: Good ✅
A16: Certificate-based | C16: =IF(SUM(B14:B16)=0,"0%",ROUND(B16/SUM(B$14:B$16)*100,1)&"%") -> 0% | D16: Excellent ✅
A17: SSO + MFA | C17: =IF(SUM(B14:B17)=0,"0%",ROUND(B17/SUM(B$14:B$17)*100,1)&"%") -> 0% | D17: Excellent ✅
A18: Biometric + MFA | C18: =IF(SUM(B14:B18)=0,"0%",ROUND(B18/SUM(B$14:B$18)*100,1)&"%") -> 0% | D18: Excellent ✅
A19: Legacy/Weak | C19: =IF(SUM(B14:B19)=0,"0%",ROUND(B19/SUM(B$14:B$19)*100,1)&"%") -> 0% | D19: CRITICAL RISK ❌
A22: MFA ADOPTION METRICS
A23: User Type | B23: Total Users | C23: MFA Enrolled | D23: Enrollment % | E23: MFA Enforcement
A24: Administrators | D24: =IF(B24>0,C24/B24*100&"%","N/A") -> N/A
A25: Remote Users | D25: =IF(B25>0,C25/B25*100&"%","N/A") -> N/A
A26: Internal Users | D26: =IF(B26>0,C26/B26*100&"%","N/A") -> N/A
A27: External Users | D27: =IF(B27>0,C27/B27*100&"%","N/A") -> N/A
A28: Service Accounts | D28: =IF(B28>0,C28/B28*100&"%","N/A") -> N/A
A31: PASSWORD SECURITY METRICS
A32: Password Metric | B32: Count | C32: Percentage | D32: Compliance Status
A33: Hashed with Approved Algorithm | C33: =IF(SUM(B33:B33)=0,"0%",ROUND(B33/SUM(B$33:B$33)*100,1)&"%") -> 0% | D33: ✅ Compliant
A34: Plaintext Storage | C34: =IF(SUM(B33:B34)=0,"0%",ROUND(B34/SUM(B$33:B$34)*100,1)&"%") -> 0% | D34: ❌ CRITICAL
A35: Weak Hashing (MD5/SHA-1) | C35: =IF(SUM(B33:B35)=0,"0%",ROUND(B35/SUM(B$33:B$35)*100,1)&"%") -> 0% | D35: ❌ Non-Compliant
A36: Min Length ≥14 chars | C36: =IF(SUM(B33:B36)=0,"0%",ROUND(B36/SUM(B$33:B$36)*100,1)&"%") -> 0% | D36: ✅ Recommended
A37: Min Length 12-13 chars | C37: =IF(SUM(B33:B37)=0,"0%",ROUND(B37/SUM(B$33:B$37)*100,1)&"%") -> 0% | D37: ⚠️ Adequate
A38: Min Length <12 chars | C38: =IF(SUM(B33:B38)=0,"0%",ROUND(B38/SUM(B$33:B$38)*100,1)&"%") -> 0% | D38: ❌ Weak
A39: Account Lockout Enabled | C39: =IF(SUM(B33:B39)=0,"0%",ROUND(B39/SUM(B$33:B$39)*100,1)&"%") -> 0% | D39: ✅ Required
A40: Password Expiry Configured | C40: =IF(SUM(B33:B40)=0,"0%",ROUND(B40/SUM(B$33:B$40)*100,1)&"%") -> 0% | D40: ✅ Required
A43: SERVICE ACCOUNT SECURITY
A44: Service Account Metric | B44: Count | C44: Status
A45: Total Service Accounts
A46: Certificate-based Auth | C46: ✅
A47: Long Password (≥20 chars) | C47: ✅
A48: Weak Password (<20 chars) | C48: ❌
A49: Interactive Login Disabled | C49: ✅
...

Sheet Evidence Register
A1: EVIDENCE REGISTER
A2: List all evidence files/documents referenced in this assessment (audit traceability).
A4: Evidence ID | B4: Assessment Area | C4: Evidence Type | D4: Description | E4: Location/Path | F4: Date Collected | G4: Collected By | H4: Verification Status
A5: EV-001
A6: EV-002
A7: EV-003
A8: EV-004
A9: EV-005
A10: EVD-824.3-001 | B10: Active Directory Password Policy GPO | C10: GPO Export | D10: 1. Password Security | E10: AD/GPO/Password | F10: 2026-01-10 | G10: Windows Admin | H10: 3 years | I10: Current
A11: EVD-824.3-002 | B11: Azure AD Password Policy Configuration | C11: Screenshot | D11: 1. Password Security | E11: Azure/AAD/Security | F11: 2026-01-10 | G11: Cloud Admin | H11: 2 years | I11: Current
A12: EVD-824.3-003 | B12: Linux PAM Configuration Audit | C12: Config Files | D12: 1. Password Security | E12: Linux/PAM/Config | F12: 2026-01-09 | G12: Linux Admin | H12: 2 years | I12: Current
A13: EVD-824.3-004 | B13: Password Security Standard v3.2 | C13: Standard Document | D13: 1. Password Security | E13: SharePoint/Standards | F13: 2025-08-01 | G13: Security Team | H13: 5 years | I13: Current
A14: EVD-824.3-005 | B14: Azure MFA Adoption Report | C14: Compliance Report | D14: 2. Multi-Factor Authentication | E14: Azure/MFA/Reports | F14: 2026-01-10 | G14: Security Team | H14: 1 year | I14: Current
A15: EVD-824.3-006 | B15: Duo Security Deployment Configuration | C15: Config Export | D15: 2. Multi-Factor Authentication | E15: Duo/Admin/Config | F15: 2026-01-09 | G15: Security Team | H15: 2 years | I15: Current
A16: EVD-824.3-007 | B16: YubiKey Deployment Inventory | C16: Inventory List | D16: 2. Multi-Factor Authentication | E16: SharePoint/Inventory/MFA | F16: 2026-01-08 | G16: IT Admin | H16: 2 years | I16: Current
A17: EVD-824.3-008 | B17: MFA Policy Document v2.5 | C17: Policy | D17: 2. Multi-Factor Authentication | E17: SharePoint/Policies/MFA | F17: 2025-09-01 | G17: Security Team | H17: 5 years | I17: Current
A18: EVD-824.3-009 | B18: PIV Smart Card Deployment Guide | C18: Technical Guide | D18: 3. Certificate-Based Auth | E18: SharePoint/Guides/PIV | F18: 2025-10-15 | G18: Security Team | H18: 3 years | I18: Current
A19: EVD-824.3-010 | B19: PKI Certificate Policy | C19: Policy Document | D19: 3. Certificate-Based Auth | E19: SharePoint/Policies/PKI | F19: 2025-06-01 | G19: Security Team | H19: 5 years | I19: Current
A20: EVD-824.3-011 | B20: mTLS Architecture Documentation | C20: Architecture Doc | D20: 3. Certificate-Based Auth | E20: Confluence/mTLS | F20: 2025-11-01 | G20: Platform Team | H20: 3 years | I20: Current
A21: EVD-824.3-012 | B21: S/MIME Certificate Deployment Report | C21: Deployment Report | D21: 3. Certificate-Based Auth | E21: SharePoint/Certificates | F21: 2026-01-09 | G21: Email Admin | H21: 2 years | I21: Current
... A29: EVD-824.3-020 | B29: SSO Implementation Standard | C29: Standard Document | D29: 5. SSO & Federation | E29: SharePoint/Standards/SSO | F29: 2025-09-01 | G29: Security Team | H29: 5 years | I29: Current
A30: EV-026
A31: EV-027
A32: EV-028
A33: EV-029
A34: EV-030
A35: EV-031
A36: EV-032
A37: EV-033
A38: EV-034
A39: EV-035
A40: EV-036
A41: EV-037
... A104: EV-100

Sheet Approval Sign-Off
A1: ASSESSMENT APPROVAL AND SIGN-OFF
A3: Assessment Summary
A4: Assessment Document | B4: ISMS-IMP-A.8.24.3 - Authentication Assessment
A5: Assessment Period | B5: Alex Thompson
A6: Overall Compliance Rate | B6: Identity & Access Management Engineer
A7: Assessment Status | B7: Information Security
B8: alex.thompson@company.com
B9: 2026-01-13
A10: ASSESSMENT COMPLETED BY
A11: Name:
A12: Role/Title:
A13: Department:
A14: Email: | B14: Lisa Martinez
A15: Date: | B15: 2026-01-15
B16: Reviewed and verified all authentication controls. Legacy system SSO integration needs attention.
A18: REVIEWED BY (INFORMATION SECURITY OFFICER)
A19: Name:
A20: Date:
A21: Review Notes: | B21: Michael Chen
B22: 2026-01-16
B23: MFA coverage excellent. Focus on completing developer MFA enforcement and legacy app modernization.
A24: APPROVED BY (CISO)
A25: Name:
A26: Date:
A27: Approval Decision:
A28: Conditions/Notes: | B28: Jennifer Williams
B29: 2026-01-18
B30: Approved
A31: NEXT REVIEW DETAILS
A32: Next Review Date:
A33: Review Responsible:
A34: Special Considerations:
B36: 2026-04-13
B37: Lisa Martinez
B38: Q2 2026 follow-up on legacy application authentication modernization
