Workbook

Sheet Instructions & Legend
A1: ISMS-IMP-A.8.24.4 – Key Management Assessment ISO/IEC 27001:2022 - Control A.8.24: Use of Cryptography
A3: Document Information
A4: Document ID | B4: ISMS-IMP-A.8.24.4
A5: Assessment Area | B5: Key Management Cryptographic Controls
A6: Related Policy | B6: ISMS-POL-A.8.24-S2.4
A7: Version | B7: 1.0
A8: Assessment Date
A9: Completed By
A10: Organization
A11: Review Cycle | B11: Quarterly
A13: HOW TO USE THIS WORKBOOK
A14: 1. Complete each worksheet tab (1–5) for applicable key management areas
A15: 2. Use dropdown menus for standardized entries (Status, Key Type, Algorithm, Storage Method, etc.)
A16: 3. Fill in yellow-highlighted cells with your information
A17: 4. If Status = Partial or Non-Compliant, complete the Exception/Deviation section
A18: 5. Document key lifecycle details for each cryptographic system
A19: 6. Provide evidence location/path for each implementation entry
A20: 7. Summary Dashboard auto-calculates compliance statistics per key management area
A21: 8. Maintain the Evidence Register for audit traceability
A22: 9. Obtain final approval and sign-off in the Approval Sign-Off sheet
A24: STATUS LEGEND
A25: Symbol | B25: Status | C25: Description
A26: ✅ | B26: Compliant | C26: Fully meets policy requirements
A27: ⚠️ | B27: Partial | C27: Some requirements met, gaps exist
A28: ❌ | B28: Non-Compliant | C28: Does not meet policy requirements
A29: N/A | B29: Not Applicable | C29: Requirement does not apply
A32: ACCEPTABLE EVIDENCE (examples)
A33: ✓ Key generation audit logs
A34: ✓ HSM configuration and initialization records
A35: ✓ KMS architecture diagrams
A36: ✓ Key rotation schedules and logs
A37: ✓ Key backup and recovery procedures
A38: ✓ Key escrow agreements
A39: ✓ Certificate lifecycle management reports
A40: ✓ Certificate Authority (CA) audit reports
A41: ✓ Key ceremony documentation
A42: ✓ Cryptographic module validation certificates (FIPS 140-2/3)
A43: ✓ Key usage and access logs
... A46: ✓ Third-party key management audit reports

Sheet 1. Key Generation
A1: 1. KEY GENERATION - CRYPTOGRAPHIC KEY CREATION Policy Requirement: Cryptographic keys MUST be generated using approved algorithms with cryptographically secure random number generators (Policy Section 2.4.1)
A3: Does your organization generate cryptographic keys for encryption, signing, or authentication purposes?
A4: Response:
A6: System/Service | B6: Key Type | C6: Algorithm | D6: Key Length (bits) | E6: Storage Method | F6: Data Classification | G6: Lifecycle Stage | H6: Status | I6: Evidence Location | J6: Gap Description | K6: Remediation Needed | L6: Exception ID | M6: Risk ID | N6: Compensating Controls | O6: Responsible Person | P6: Target Date | Q6: Budget Required | R6: Random Number Generator | S6: Generation Location | T6: Key Ceremony Performed | U6: Entropy Source Verified | V6: Generation Audit Log
A7: Example: Production Database Encryption - FINDB01 | B7: Data Encryption Key | C7: AES-256 | D7: 256 | E7: HSM | F7: Restricted | G7: Active | H7: ✅ Compliant | I7: /evidence/key-mgmt/FINDB01-key-generation-log.pdf | J7: None | K7: No | L7: N/A | M7: N/A | N7: N/A | O7: N/A | P7: N/A | Q7: No | R7: HSM RNG | S7: HSM | T7: Yes | U7: Yes | V7: Yes
A8: TLS Certificates (Public) | B8: Public-facing services | C8: RSA | D8: 4096 bits | E8: Let's Encrypt / DigiCert | F8: Public | G8: Active | H8: ✅ Compliant | I8: Certificate inventory | K8: No
A9: Database Encryption Keys | B9: Data-at-rest protection | C9: AES | D9: 256 bits | E9: AWS KMS / Azure Key Vault | F9: Restricted | G9: Active | H9: ✅ Compliant | I9: KMS key inventory | K9: No
A10: API Signing Keys (JWT) | B10: API authentication | C10: ECDSA P-256 | D10: 256 bits | E10: HashiCorp Vault | F10: Confidential | G10: Active | H10: ✅ Compliant | I10: Vault key audit | K10: No
A11: SSH Host Keys | B11: Server authentication | C11: Ed25519 | D11: 256 bits | E11: Ansible automated | F11: Internal | G11: Active | H11: ✅ Compliant | I11: SSH key inventory | K11: No
A12: Code Signing Keys | B12: Software release signing | C12: RSA | D12: 4096 bits | E12: YubiKey HSM | F12: Restricted | G12: Active | H12: ✅ Compliant | I12: Code signing logs | K12: No
A13: Symmetric Encryption Keys | B13: Application encryption | C13: AES | D13: 256 bits | E13: Cloud KMS | F13: Confidential | G13: Active | H13: ✅ Compliant | I13: Application key docs | K13: No
A14: Legacy DES Keys | B14: Legacy system (deprecated) | C14: DES | D14: 56 bits | E14: File-based | F14: Confidential | G14: Deprecated | H14: ❌ Non-Compliant | I14: Legacy system docs | J14: Migrate to AES-256 | K14: Yes
A15: Key Encryption Keys (KEK) | B15: Key wrapping | C15: AES | D15: 256 bits | E15: HSM-backed | F15: Restricted | G15: Active | H15: ✅ Compliant | I15: HSM audit logs | K15: No
A16: Master Encryption Keys | B16: Top-level keys | C16: AES | D16: 256 bits | E16: Hardware HSM | F16: Restricted | G16: Active | H16: ✅ Compliant | I16: HSM key ceremony docs | K16: No
A22: 1. KEY GENERATION CHECKLIST
A23: ☐ | B23: Requirement | C23: Status
A24: ☐ | B24: Approved algorithms only (AES-256, RSA ≥3072, Ed25519, ECDSA P-256+)
A25: ☐ | B25: Cryptographically secure random number generator (CSRNG) used
A26: ☐ | B26: FIPS 140-2 Level 2+ validated cryptographic module (production)
A27: ☐ | B27: Key generation performed in secure environment (HSM/KMS/TPM)
A28: ☐ | B28: Weak algorithms prohibited (DES, 3DES, MD5, SHA-1, RSA <2048)
A29: ☐ | B29: Key ceremony documented for master/root keys
A30: ☐ | B30: Dual control/split knowledge for critical key generation
A31: ☐ | B31: Key generation audit logging enabled
A32: ☐ | B32: Generated keys never exposed in plaintext outside secure boundary
A33: ☐ | B33: Entropy source quality verified and tested
A34: ☐ | B34: Key generation procedures documented
A35: ☐ | B35: Key metadata tracked (creation date, purpose, owner, classification)
... A37: ☐ | B37: Default/vendor keys replaced before production use
A38: Checklist Score: | B38: =COUNTIF(C24:C37,"Yes")/COUNTA(C24:C37)*100&"%" -> #DIV/0!
A40: APPROVED ALGORITHMS BY USE CASE
A41: Use Case | B41: Minimum Algorithm | C41: Key Length | D41: Notes
A42: Symmetric Encryption (Data at Rest) | B42: AES | C42: 256 bits | D42: AES-256-GCM preferred
A43: Symmetric Encryption (Data in Transit) | B43: AES, ChaCha20 | C43: 256 bits | D43: ChaCha20-Poly1305 for mobile
A44: Asymmetric Encryption | B44: RSA, ECDH | C44: RSA ≥3072, ECDH P-256+ | D44: RSA-4096 for long-term
A45: Digital Signatures | B45: RSA, Ed25519, ECDSA | C45: RSA ≥3072, Ed25519, ECDSA P-256+ | D45: Ed25519 preferred for new systems
A46: Key Exchange | B46: ECDH, RSA | C46: ECDH P-256+, RSA ≥3072 | D46: Use ephemeral keys for PFS
A47: Hashing | B47: SHA-256, SHA-384, SHA-512 | C47: N/A (output size) | D47: SHA-256 minimum
A48: HMAC | B48: HMAC-SHA256 | C48: ≥256 bits | D48: For message authentication
A50: EXCEPTION / DEVIATION DOCUMENTATION (Complete if Status = Partial or Non-Compliant)
...

Sheet 2. Key Storage
A1: 2. KEY STORAGE - SECURE KEY PROTECTION Policy Requirement: Cryptographic keys MUST be stored in hardware security modules (HSM), cloud KMS, or TPM for production systems. Software keystores permitted only for non-production with documented risk acceptance (Policy Section 2.4.2)
A3: Does your organization store cryptographic keys that require protection?
A4: Response:
A6: System/Service | B6: Key Type | C6: Algorithm | D6: Key Length (bits) | E6: Storage Method | F6: Data Classification | G6: Lifecycle Stage | H6: Status | I6: Evidence Location | J6: Gap Description | K6: Remediation Needed | L6: Exception ID | M6: Risk ID | N6: Compensating Controls | O6: Responsible Person | P6: Target Date | Q6: Budget Required | R6: HSM/KMS Model | S6: FIPS 140 Level | T6: Access Control Method | U6: Encryption at Rest | V6: Physical Security | W6: Key Backup Exists
A7: Example: Azure Key Vault - App1 Keys | B7: Key Encryption Key | C7: RSA-4096 | D7: 4096 | E7: Cloud KMS | F7: Confidential | G7: Active | H7: ✅ Compliant | I7: /evidence/key-mgmt/app1-kv-config.pdf | J7: None | K7: No | L7: N/A | M7: N/A | N7: N/A | O7: N/A | P7: N/A | Q7: No | R7: Azure Key Vault | S7: Level 2 | T7: MFA Required | U7: Yes | V7: Cloud Provider | W7: Yes
A8: Production TLS Keys | B8: TLS private keys | C8: RSA | D8: 4096 bits | E8: AWS ACM / Azure Key Vault | F8: Public | G8: HSM-backed | H8: ✅ Compliant | I8: ACM configuration | K8: No
A9: Database Master Keys | B9: DB encryption keys | C9: AES | D9: 256 bits | E9: Azure Key Vault + HSM | F9: Restricted | G9: HSM-backed | H9: ✅ Compliant | I9: Key Vault access logs | K9: No
A10: Application Secrets | B10: API keys, passwords | C10: Various | D10: 256+ bits | E10: HashiCorp Vault | F10: Confidential | G10: Encrypted at rest | H10: ✅ Compliant | I10: Vault access policies | K10: No
A11: Kubernetes Secrets | B11: K8s application secrets | C11: Various | D11: Varies | E11: etcd encrypted | F11: Internal | G11: etcd encryption | H11: ✅ Compliant | I11: K8s encryption config | K11: No
A12: Code Signing Keys | B12: Software signing | C12: RSA | D12: 4096 bits | E12: YubiKey HSM | F12: Restricted | G12: Hardware device | H12: ✅ Compliant | I12: HSM access logs | K12: No
A13: SSH Private Keys | B13: User authentication | C13: Ed25519 | D13: 256 bits | E13: User ~/.ssh/ | F13: Internal | G13: Filesystem + passphrase | H13: ⚠️ Partial | I13: Endpoint scan results | J13: Enforce passphrase policy | K13: Yes
A14: Service Account Keys | B14: GCP service accounts | C14: RSA | D14: 2048 bits | E14: GCP Secret Manager | F14: Confidential | G14: Encrypted | H14: ✅ Compliant | I14: GCP audit logs | K14: No
A15: Backup Encryption Keys | B15: Backup protection | C15: AES | D15: 256 bits | E15: Key escrow service | F15: Restricted | G15: Secure escrow | H15: ✅ Compliant | I15: Escrow audit trail | K15: No
A16: Development Keys (local) | B16: Dev environment | C16: Various | D16: Varies | E16: Local filesystem | F16: Internal | G16: Unprotected | H16: ❌ Non-Compliant | I16: Dev key audit | J16: Implement Vault for dev | K16: Yes
A22: 2. KEY STORAGE CHECKLIST
A23: ☐ | B23: Requirement | C23: Status
A24: ☐ | B24: Production keys stored in HSM, cloud KMS, or TPM
A25: ☐ | B25: FIPS 140-2 Level 2+ (or FIPS 140-3 equivalent) for production
A26: ☐ | B26: Keys encrypted when stored (key encryption keys protected by HSM)
A27: ☐ | B27: Keys never stored in plaintext files or code repositories
A28: ☐ | B28: Keys never stored in application configuration files
A29: ☐ | B29: Keys never stored in environment variables (production)
A30: ☐ | B30: Keys never stored in databases without encryption
A31: ☐ | B31: Access to keys restricted by role-based access control (RBAC)
A32: ☐ | B32: Multi-factor authentication required for key access
A33: ☐ | B33: Dual control/split knowledge for master keys
A34: ☐ | B34: Key access logged and monitored
A35: ☐ | B35: Keys physically secured (locked facilities, tamper-evident HSMs)
... A40: ☐ | B40: Unused/obsolete keys securely destroyed
A41: Checklist Score: | B41: =COUNTIF(C24:C40,"Yes")/COUNTA(C24:C40)*100&"%" -> #DIV/0!
A43: APPROVED KEY STORAGE SOLUTIONS
A44: Solution Type | B44: Examples | C44: FIPS 140-2 Level | D44: Use Case
A45: Hardware HSM | B45: Thales Luna, Entrust nShield, Utimaco | C45: Level 3/4 | D45: High-security production
A46: Cloud HSM | B46: AWS CloudHSM, Azure Dedicated HSM | C46: Level 3 | D46: Cloud-native high-security
A47: Cloud KMS | B47: AWS KMS, Azure Key Vault, GCP Cloud KMS | C47: Level 2/3 | D47: General cloud workloads
A48: TPM | B48: TPM 2.0 (various vendors) | C48: Level 2 | D48: Endpoint/device keys
A49: Software Vault | B49: HashiCorp Vault, CyberArk | C49: Varies | D49: Non-production acceptable
A51: EXCEPTION / DEVIATION DOCUMENTATION (Complete if Status = Partial or Non-Compliant)
A52: Formal exception request submitted:
A53: Exception ID:
...

Sheet 3. Key Rotation
A1: 3. KEY ROTATION - CRYPTOGRAPHIC KEY LIFECYCLE MANAGEMENT Policy Requirement: Cryptographic keys MUST be rotated according to defined schedules: Encryption keys annually, signing keys biennially, session keys hourly/daily (Policy Section 2.4.3)
A3: Does your organization have a key rotation policy and implementation for cryptographic keys?
A4: Response:
A6: System/Service | B6: Key Type | C6: Algorithm | D6: Key Length (bits) | E6: Storage Method | F6: Data Classification | G6: Lifecycle Stage | H6: Status | I6: Evidence Location | J6: Gap Description | K6: Remediation Needed | L6: Exception ID | M6: Risk ID | N6: Compensating Controls | O6: Responsible Person | P6: Target Date | Q6: Budget Required | R6: Rotation Schedule | S6: Last Rotation Date | T6: Next Rotation Due | U6: Automated Rotation | V6: Rotation Tested | W6: Re-encryption Required
A7: Example: API Signing Keys | B7: Signing Key | C7: RSA-3072 | D7: 3072 | E7: Cloud KMS | F7: Confidential | G7: Active | H7: ✅ Compliant | I7: /evidence/key-mgmt/api-key-rotation.pdf | J7: None | K7: No | L7: N/A | M7: N/A | N7: N/A | O7: N/A | P7: N/A | Q7: No | R7: Quarterly | S7: 2024-10-01 | T7: 2025-01-01 | U7: Yes | V7: Yes | W7: No
A8: TLS Certificates | B8: Public TLS certs | C8: RSA | D8: 4096 bits | E8: Automated (Let's Encrypt) | F8: Public | G8: 90 days | H8: ✅ Compliant | I8: Auto-renewal logs | K8: No
A9: Database Encryption Keys | B9: DB master keys | C9: AES | D9: 256 bits | E9: Manual rotation process | F9: Restricted | G9: 365 days | H9: ⚠️ Partial | I9: KMS rotation schedule | J9: Automate rotation | K9: Yes
A10: API Keys (Customer) | B10: Customer API access | C10: Random | D10: 256 bits | E10: Vault auto-rotation | F10: Confidential | G10: 180 days | H10: ✅ Compliant | I10: Vault rotation logs | K10: No
A11: JWT Signing Keys | B11: Token signing | C11: ECDSA | D11: 256 bits | E11: Automated rotation | F11: Confidential | G11: 180 days | H11: ✅ Compliant | I11: API gateway logs | K11: No
A12: GCP Service Keys | B12: Service account keys | C12: RSA | D12: 2048 bits | E12: Automated | F12: Confidential | G12: 90 days | H12: ✅ Compliant | I12: GCP IAM audit | K12: No
A13: Azure Storage Keys | B13: Storage account access | C13: AES | D13: 256 bits | E13: Manual | F13: Confidential | G13: Never rotated | H13: ❌ Non-Compliant | I13: Azure Storage audit | J13: Enable auto-rotation | K13: Yes
A14: SSH Host Keys | B14: Server host keys | C14: Ed25519 | D14: 256 bits | E14: Manual | F14: Internal | G14: No rotation policy | H14: ⚠️ Partial | I14: SSH key inventory | J14: Implement rotation policy | K14: Yes
A15: Encryption Keys (Apps) | B15: Application-level | C15: AES | D15: 256 bits | E15: Automated via Vault | F15: Confidential | G15: 180 days | H15: ✅ Compliant | I15: Application key logs | K15: No
A22: 3. KEY ROTATION CHECKLIST
A23: ☐ | B23: Requirement | C23: Status
A24: ☐ | B24: Key rotation policy documented and approved
A25: ☐ | B25: Encryption keys (data at rest) rotated annually minimum
A26: ☐ | B26: Signing keys rotated biennially minimum
A27: ☐ | B27: Session keys rotated hourly/daily
A28: ☐ | B28: Master keys rotated every 1-3 years
A29: ☐ | B29: Key rotation automated where possible
A30: ☐ | B30: Key rotation triggers defined (time, usage, compromise)
A31: ☐ | B31: Data re-encryption performed after key rotation
A32: ☐ | B32: Old keys retained for decryption (with restricted access)
A33: ☐ | B33: Key version tracking implemented
A34: ☐ | B34: Rotation procedures tested in non-production
A35: ☐ | B35: Rotation audit logs maintained
... A39: ☐ | B39: Cryptoperiod limits enforced (max key usage duration)
A40: Checklist Score: | B40: =COUNTIF(C24:C39,"Yes")/COUNTA(C24:C39)*100&"%" -> #DIV/0!
A42: ROTATION SCHEDULE BY KEY TYPE
A43: Key Type | B43: Minimum Rotation Frequency | C43: Recommended Frequency | D43: Trigger Events
A44: Master Encryption Key | B44: 1 year | C44: 1 year | D44: Compromise, personnel change
A45: Data Encryption Key | B45: 1 year | C45: 90 days | D45: High volume usage, compromise
A46: Key Encryption Key | B46: 1 year | C46: 1 year | D46: Master key rotation, compromise
A47: Signing Key | B47: 2 years | C47: 1 year | D47: Certificate expiry, compromise
A48: Session Key | B48: 24 hours | C48: 1 hour | D48: Session end, compromise
A49: API Key | B49: 90 days | C49: 30-90 days | D49: Personnel change, compromise
A50: TLS/SSL Certificate Private Key | B50: Certificate validity | C50: Annual | D50: Certificate renewal, compromise
A51: SSH Key | B51: 1 year | C51: 90 days | D51: Personnel change, compromise
A52: Database TDE Key | B52: 1 year | C52: 1 year | D52: Compliance requirement, compromise
...

Sheet 4. Key Backup & Recovery
A1: 4. KEY BACKUP & RECOVERY - BUSINESS CONTINUITY Policy Requirement: Cryptographic keys MUST have documented backup and recovery procedures. Backup keys stored with equal or greater security than production keys (Policy Section 2.4.4)
A3: Does your organization maintain backup and recovery procedures for cryptographic keys?
A4: Response:
A6: System/Service | B6: Key Type | C6: Algorithm | D6: Key Length (bits) | E6: Storage Method | F6: Data Classification | G6: Lifecycle Stage | H6: Status | I6: Evidence Location | J6: Gap Description | K6: Remediation Needed | L6: Exception ID | M6: Risk ID | N6: Compensating Controls | O6: Responsible Person | P6: Target Date | Q6: Budget Required | R6: Backup Method | S6: Backup Encryption | T6: Backup Location | U6: Recovery Tested | V6: Last Recovery Test | W6: RTO (Recovery Time) | X6: Escrow Agreement
A7: Example: Master Encryption Key Backup | B7: Master Key | C7: AES-256 | D7: 256 | E7: HSM | F7: Restricted | G7: Active | H7: ✅ Compliant | I7: /evidence/key-mgmt/master-key-backup.pdf | J7: None | K7: No | L7: N/A | M7: N/A | N7: N/A | O7: N/A | P7: N/A | Q7: No | R7: HSM Backup | S7: Yes | T7: Offsite Secure Vault | U7: Yes | V7: 2024-06-15 | W7: <1 hour | X7: Yes
A8: HSM Master Keys | B8: Hardware HSM keys | C8: AES | D8: 256 bits | E8: M of N key ceremony | F8: Restricted | G8: Secure key ceremony | H8: ✅ Compliant | I8: Key ceremony documentation | K8: No
A9: Database Master Keys | B9: DB encryption keys | C9: AES | D9: 256 bits | E9: KMS backup + escrow | F9: Restricted | G9: Cloud KMS backup | H9: ✅ Compliant | I9: KMS backup policies | K9: No
A10: BitLocker Recovery Keys | B10: Disk encryption recovery | C10: AES | D10: 256 bits | E10: Active Directory escrow | F10: Restricted | G10: AD recovery key store | H10: ✅ Compliant | I10: BitLocker recovery audit | K10: No
A11: FileVault Recovery Keys | B11: Mac disk encryption | C11: AES | D11: 256 bits | E11: MDM escrow | F11: Restricted | G11: Jamf Pro escrow | H11: ✅ Compliant | I11: MDM recovery key audit | K11: No
A12: Backup Encryption Keys | B12: Backup system keys | C12: AES | D12: 256 bits | E12: Secure key escrow service | F12: Restricted | G12: Iron Mountain escrow | H12: ✅ Compliant | I12: Escrow service SLA | K12: No
A13: Code Signing Keys | B13: Software signing | C13: RSA | D13: 4096 bits | E13: HSM + offline backup | F13: Restricted | G13: Secure offline storage | H13: ✅ Compliant | I13: Backup key audit | K13: No
A14: Root CA Keys | B14: PKI root keys | C14: RSA | D14: 4096 bits | E14: Offline HSM + safe | F14: Restricted | G14: Air-gapped HSM | H14: ✅ Compliant | I14: CA key ceremony docs | K14: No
A15: Personal SSH Keys | B15: User SSH keys | C15: Various | D15: Varies | E15: No backup | F15: Internal | G15: User responsibility | H15: ⚠️ Partial | I15: User key management policy | J15: Centralized key management | K15: Yes
A22: 4. KEY BACKUP & RECOVERY CHECKLIST
A23: ☐ | B23: Requirement | C23: Status
A24: ☐ | B24: Key backup and recovery procedures documented
A25: ☐ | B25: All critical keys have backup copies
A26: ☐ | B26: Backup keys encrypted with equal or stronger encryption
A27: ☐ | B27: Backup keys stored separately from production keys
A28: ☐ | B28: Geographic separation of backup keys (offsite/different region)
A29: ☐ | B29: Backup key access restricted (dual control/escrow)
A30: ☐ | B30: Key recovery procedures tested quarterly
A31: ☐ | B31: Recovery time objective (RTO) defined and documented
A32: ☐ | B32: Recovery point objective (RPO) defined and documented
A33: ☐ | B33: Key escrow agreements in place (where required)
A34: ☐ | B34: Split knowledge/dual control for backup key recovery
A35: ☐ | B35: Backup key inventory maintained and audited
... A41: ☐ | B41: HSM backup cards stored in secure facility
A42: Checklist Score: | B42: =COUNTIF(C24:C41,"Yes")/COUNTA(C24:C41)*100&"%" -> #DIV/0!
A44: BACKUP STRATEGIES BY KEY TYPE
A45: Key Type | B45: Recommended Backup Method | C45: Storage Location | D45: Recovery Testing Frequency
A46: Master Keys | B46: HSM backup card + escrow | C46: Offsite secure vault | D46: Annually
A47: Encryption Keys | B47: KMS automated backup | C47: Different region/account | D47: Quarterly
A48: Certificate Private Keys | B48: Encrypted file backup | C48: Secure file storage | D48: Semi-annually
A49: SSH Keys | B49: Encrypted backup + key management system | C49: Secrets vault | D49: Annually
A50: API Keys | B50: Secrets management system | C50: Multi-region vault | D50: Quarterly
A51: Database TDE Keys | B51: Native database backup + KMS | C51: Encrypted backup storage | D51: Quarterly
A53: EXCEPTION / DEVIATION DOCUMENTATION (Complete if Status = Partial or Non-Compliant)
A54: Formal exception request submitted:
A55: Exception ID:
...

Sheet 5. Certificate Management
A1: 5. CERTIFICATE MANAGEMENT - DIGITAL CERTIFICATE LIFECYCLE Policy Requirement: Digital certificates MUST be issued from trusted Certificate Authorities. Certificate lifecycle management includes issuance, renewal, revocation, and expiration monitoring (Policy Section 2.4.5)
A3: Does your organization use digital certificates for TLS/SSL, code signing, email signing, or authentication?
A4: Response:
A6: System/Service | B6: Key Type | C6: Algorithm | D6: Key Length (bits) | E6: Storage Method | F6: Data Classification | G6: Lifecycle Stage | H6: Status | I6: Evidence Location | J6: Gap Description | K6: Remediation Needed | L6: Exception ID | M6: Risk ID | N6: Compensating Controls | O6: Responsible Person | P6: Target Date | Q6: Budget Required | R6: Certificate Type | S6: Issuing CA | T6: Certificate Validity | U6: Expiration Date | V6: Auto-Renewal | W6: Revocation Method | X6: Monitoring Enabled
A7: Example: Production Web Server TLS | B7: Certificate | C7: RSA-2048 | D7: 2048 | E7: TPM | F7: Public | G7: Active | H7: ✅ Compliant | I7: /evidence/key-mgmt/web-tls-cert.pdf | J7: None | K7: No | L7: N/A | M7: N/A | N7: N/A | O7: N/A | P7: N/A | Q7: No | R7: TLS/SSL Server | S7: Let's Encrypt | T7: ≤90 days | U7: 2025-03-15 | V7: Yes | W7: OCSP | X7: Yes
A8: Public TLS Certificates | B8: External services | C8: RSA/ECDSA | D8: 2048-4096 bits | E8: Let's Encrypt + DigiCert | F8: Public | G8: Active | H8: ✅ Compliant | I8: Certificate inventory system | K8: No
A9: Internal PKI Certificates | B9: Internal services | C9: RSA | D9: 2048 bits | E9: Internal CA | F9: Internal | G9: Active | H9: ✅ Compliant | I9: AD Certificate Services | K9: No
A10: Client Authentication Certs | B10: User/device auth | C10: RSA/ECDSA | D10: 2048-4096 bits | E10: Internal PKI + MDM | F10: Internal | G10: Active | H10: ✅ Compliant | I10: PKI audit logs | K10: No
A11: Code Signing Certificates | B11: Software signing | C11: RSA | D11: 4096 bits | E11: DigiCert EV | F11: Restricted | G11: Active | H11: ✅ Compliant | I11: Code signing inventory | K11: No
A12: S/MIME Certificates | B12: Email encryption | C12: RSA | D12: 2048 bits | E12: Public CA + Internal | F12: Internal | G12: Active | H12: ⚠️ Partial | I12: S/MIME deployment report | J12: Increase adoption to 100% | K12: Yes
A13: VPN Certificates | B13: VPN authentication | C13: RSA/ECDSA | D13: 2048-4096 bits | E13: Internal PKI | F13: Internal | G13: Active | H13: ✅ Compliant | I13: VPN certificate audit | K13: No
A14: IoT Device Certificates | B14: IoT authentication | C14: ECDSA | D14: 256 bits | E14: Internal IoT CA | F14: Internal | G14: Active | H14: ✅ Compliant | I14: IoT PKI documentation | K14: No
A15: Certificate Expiry Monitoring | B15: Proactive monitoring | C15: N/A | D15: N/A | E15: Automated monitoring (30/7 days) | F15: N/A | G15: Active | H15: ✅ Compliant | I15: Monitoring dashboard | K15: No
A16: Legacy Self-Signed Certs | B16: Legacy systems | C16: RSA | D16: 1024 bits | E16: Self-signed | F16: Internal | G16: Deprecated | H16: ❌ Non-Compliant | I16: Legacy cert inventory | J16: Replace with proper PKI | K16: Yes
A22: 5. CERTIFICATE MANAGEMENT CHECKLIST
A23: ☐ | B23: Requirement | C23: Status
A24: ☐ | B24: Certificates issued from trusted public CA (for external services)
A25: ☐ | B25: Internal CA infrastructure properly secured (for internal services)
A26: ☐ | B26: Certificate validity ≤397 days (public TLS certificates)
A27: ☐ | B27: Certificate validity ≤90 days preferred (automated renewal)
A28: ☐ | B28: Self-signed certificates NOT used in production
A29: ☐ | B29: Certificate inventory maintained and up to date
A30: ☐ | B30: Certificate expiration monitoring implemented
A31: ☐ | B31: Alerts configured for 30/60/90 days before expiration
A32: ☐ | B32: Automated certificate renewal configured
A33: ☐ | B33: Certificate renewal tested in non-production
A34: ☐ | B34: Certificate revocation procedures documented
A35: ☐ | B35: CRL or OCSP configured for revocation checking
... A43: ☐ | B43: Email certificates (S/MIME) issued per user
A44: Checklist Score: | B44: =COUNTIF(C24:C43,"Yes")/COUNTA(C24:C43)*100&"%" -> #DIV/0!
A46: CERTIFICATE VALIDITY STANDARDS
A47: Certificate Type | B47: Maximum Validity | C47: Recommended Validity | D47: Renewal Process
A48: Public TLS/SSL | B48: 397 days (13 months) | C48: 90 days | D48: ACME/Let's Encrypt automated
A49: Internal TLS/SSL | B49: 2 years | C49: 1 year | D49: Internal CA automated
A50: Code Signing | B50: 3 years | C50: 1 year | D50: Manual with hardware token
A51: Email (S/MIME) | B51: 2 years | C51: 1 year | D51: PKI automated or manual
A52: Client Authentication | B52: 2 years | C52: 1 year | D52: PKI automated
A53: Root CA | B53: 20 years | C53: 10 years | D53: Manual with ceremony
A54: Intermediate CA | B54: 10 years | C54: 5 years | D54: Manual with ceremony
A56: CERTIFICATE LIFECYCLE STAGES
...

Sheet Summary Dashboard
A1: KEY MANAGEMENT ASSESSMENT - COMPLIANCE SUMMARY
A3: Assessment Area | B3: Total Items | C3: Compliant | D3: Partial | E3: Non-Compliant | F3: N/A | G3: Compliance %
A4: 1. Key Generation | B4: =COUNTA('1. Key Generation'!H8:H20) -> 9 | C4: =COUNTIF('1. Key Generation'!H8:H20,"✅*") -> 8 | D4: =COUNTIF('1. Key Generation'!H8:H20,"⚠️*") -> 0 | E4: =COUNTIF('1. Key Generation'!H8:H20,"❌*") -> 1 | F4: =COUNTIF('1. Key Generation'!H8:H20,"N/A") -> 0 | G4: =IF((B4-F4)=0,"0%",ROUND(C4/(B4-F4)*100,1)&"%") -> 88.9%
A5: 2. Key Storage | B5: =COUNTA('2. Key Storage'!H8:H20) -> 9 | C5: =COUNTIF('2. Key Storage'!H8:H20,"✅*") -> 7 | D5: =COUNTIF('2. Key Storage'!H8:H20,"⚠️*") -> 1 | E5: =COUNTIF('2. Key Storage'!H8:H20,"❌*") -> 1 | F5: =COUNTIF('2. Key Storage'!H8:H20,"N/A") -> 0 | G5: =IF((B5-F5)=0,"0%",ROUND(C5/(B5-F5)*100,1)&"%") -> 77.8%
A6: 3. Key Rotation | B6: =COUNTA('3. Key Rotation'!H8:H20) -> 8 | C6: =COUNTIF('3. Key Rotation'!H8:H20,"✅*") -> 5 | D6: =COUNTIF('3. Key Rotation'!H8:H20,"⚠️*") -> 2 | E6: =COUNTIF('3. Key Rotation'!H8:H20,"❌*") -> 1 | F6: =COUNTIF('3. Key Rotation'!H8:H20,"N/A") -> 0 | G6: =IF((B6-F6)=0,"0%",ROUND(C6/(B6-F6)*100,1)&"%") -> 62.5%
A7: 4. Key Backup & Recovery | B7: =COUNTA('4. Key Backup & Recovery'!H8:H20) -> 8 | C7: =COUNTIF('4. Key Backup & Recovery'!H8:H20,"✅*") -> 7 | D7: =COUNTIF('4. Key Backup & Recovery'!H8:H20,"⚠️*") -> 1 | E7: =COUNTIF('4. Key Backup & Recovery'!H8:H20,"❌*") -> 0 | F7: =COUNTIF('4. Key Backup & Recovery'!H8:H20,"N/A") -> 0 | G7: =IF((B7-F7)=0,"0%",ROUND(C7/(B7-F7)*100,1)&"%") -> 87.5%
A8: 5. Certificate Management | B8: =COUNTA('5. Certificate Management'!H8:H20) -> 9 | C8: =COUNTIF('5. Certificate Management'!H8:H20,"✅*") -> 7 | D8: =COUNTIF('5. Certificate Management'!H8:H20,"⚠️*") -> 1 | E8: =COUNTIF('5. Certificate Management'!H8:H20,"❌*") -> 1 | F8: =COUNTIF('5. Certificate Management'!H8:H20,"N/A") -> 0 | G8: =IF((B8-F8)=0,"0%",ROUND(C8/(B8-F8)*100,1)&"%") -> 77.8%
A9: TOTAL | B9: =SUM(B4:B8) -> 43 | C9: =SUM(C4:C8) -> 34 | D9: =SUM(D4:D8) -> 5 | E9: =SUM(E4:E8) -> 4 | F9: =SUM(F4:F8) -> 0 | G9: =IF((B9-F9)=0,"0%",ROUND(C9/(B9-F9)*100,1)&"%") -> 79.1%
A12: KEY MANAGEMENT MATURITY BY AREA
A13: Key Management Area | B13: Checklist Score | C13: Maturity Level
A14: Key Generation | C14: =IF(B14>=90%,"Advanced",IF(B14>=70%,"Intermediate","Basic")) -> Basic
A15: Key Storage | C15: =IF(B15>=90%,"Advanced",IF(B15>=70%,"Intermediate","Basic")) -> Basic
A16: Key Rotation | C16: =IF(B16>=90%,"Advanced",IF(B16>=70%,"Intermediate","Basic")) -> Basic
A17: Key Backup & Recovery | C17: =IF(B17>=90%,"Advanced",IF(B17>=70%,"Intermediate","Basic")) -> Basic
A18: Certificate Management | C18: =IF(B18>=90%,"Advanced",IF(B18>=70%,"Intermediate","Basic")) -> Basic
A21: ALGORITHM DISTRIBUTION ANALYSIS
A22: Algorithm Type | B22: Count | C22: Percentage | D22: Compliance Status
A23: AES-256 | C23: =IF(SUM(B23:B23)=0,"0%",ROUND(B23/SUM(B$23:B$23)*100,1)&"%") -> 0% | D23: Approved
A24: AES-128 | C24: =IF(SUM(B23:B24)=0,"0%",ROUND(B24/SUM(B$23:B$24)*100,1)&"%") -> 0% | D24: Approved
A25: RSA-4096 | C25: =IF(SUM(B23:B25)=0,"0%",ROUND(B25/SUM(B$23:B$25)*100,1)&"%") -> 0% | D25: Approved
A26: RSA-3072 | C26: =IF(SUM(B23:B26)=0,"0%",ROUND(B26/SUM(B$23:B$26)*100,1)&"%") -> 0% | D26: Approved
A27: RSA-2048 | C27: =IF(SUM(B23:B27)=0,"0%",ROUND(B27/SUM(B$23:B$27)*100,1)&"%") -> 0% | D27: Minimum (Legacy)
A28: Ed25519 | C28: =IF(SUM(B23:B28)=0,"0%",ROUND(B28/SUM(B$23:B$28)*100,1)&"%") -> 0% | D28: Approved
A29: ECDSA P-256+ | C29: =IF(SUM(B23:B29)=0,"0%",ROUND(B29/SUM(B$23:B$29)*100,1)&"%") -> 0% | D29: Approved
A30: ChaCha20 | C30: =IF(SUM(B23:B30)=0,"0%",ROUND(B30/SUM(B$23:B$30)*100,1)&"%") -> 0% | D30: Approved
A31: Weak/Legacy | C31: =IF(SUM(B23:B31)=0,"0%",ROUND(B31/SUM(B$23:B$31)*100,1)&"%") -> 0% | D31: NON-COMPLIANT
A34: STORAGE METHOD DISTRIBUTION
A35: Storage Method | B35: Count | C35: Percentage | D35: Security Rating
A36: HSM | C36: =IF(SUM(B36:B36)=0,"0%",ROUND(B36/SUM(B$36:B$36)*100,1)&"%") -> 0% | D36: Highest
A37: Cloud KMS | C37: =IF(SUM(B36:B37)=0,"0%",ROUND(B37/SUM(B$36:B$37)*100,1)&"%") -> 0% | D37: High
A38: TPM | C38: =IF(SUM(B36:B38)=0,"0%",ROUND(B38/SUM(B$36:B$38)*100,1)&"%") -> 0% | D38: High
A39: Software Keystore | C39: =IF(SUM(B36:B39)=0,"0%",ROUND(B39/SUM(B$36:B$39)*100,1)&"%") -> 0% | D39: Medium
A40: Vault | C40: =IF(SUM(B36:B40)=0,"0%",ROUND(B40/SUM(B$36:B$40)*100,1)&"%") -> 0% | D40: Medium
A41: File-based | C41: =IF(SUM(B36:B41)=0,"0%",ROUND(B41/SUM(B$36:B$41)*100,1)&"%") -> 0% | D41: LOW RISK
A42: Database | C42: =IF(SUM(B36:B42)=0,"0%",ROUND(B42/SUM(B$36:B$42)*100,1)&"%") -> 0% | D42: LOW RISK
A45: KEY ROTATION COVERAGE
A46: Rotation Schedule | B46: Count | C46: Percentage | D46: Compliance Status
A47: Automated | D47: Optimal
A48: Manual (Scheduled) | D48: Acceptable
A49: Never / Not Configured | D49: NON-COMPLIANT
...

Sheet Evidence Register
A1: EVIDENCE REGISTER
A2: List all evidence files/documents referenced in this assessment (audit traceability).
A4: Evidence ID | B4: Assessment Area | C4: Evidence Type | D4: Description | E4: Location/Path | F4: Date Collected | G4: Collected By | H4: Verification Status
A5: EV-001
A6: EV-002
A7: EV-003
A8: EV-004
A9: EV-005
A10: EVD-824.4-001 | B10: Key Generation Standard v2.0 | C10: Standard Document | D10: 1. Key Generation | E10: SharePoint/Standards/Keys | F10: 2025-09-01 | G10: Security Team | H10: 5 years | I10: Current
A11: EVD-824.4-002 | B11: AWS KMS Key Policy Documentation | C11: Policy Document | D11: 1. Key Generation | E11: AWS/KMS/Policies | F11: 2026-01-10 | G11: Cloud Team | H11: 3 years | I11: Current
A12: EVD-824.4-003 | B12: HashiCorp Vault Key Audit Report | C12: Audit Report | D12: 1. Key Generation | E12: Vault/Audit/Q4-2025 | F12: 2025-12-20 | G12: Security Team | H12: 3 years | I12: Current
A13: EVD-824.4-004 | B13: Code Signing Key Ceremony Documentation | C13: Ceremony Doc | D13: 1. Key Generation | E13: SharePoint/Ceremonies/Code-Signing | F13: 2025-08-15 | G13: DevOps Team | H13: 7 years | I13: Current
A14: EVD-824.4-005 | B14: YubiKey HSM Deployment Guide | C14: Technical Guide | D14: 1. Key Generation | E14: SharePoint/Guides/HSM | F14: 2025-10-01 | G14: Security Team | H14: 3 years | I14: Current
A15: EVD-824.4-006 | B15: AWS ACM Configuration Screenshot | C15: Screenshot | D15: 2. Key Storage | E15: SharePoint/Evidence/ACM | F15: 2026-01-10 | G15: Cloud Team | H15: 2 years | I15: Current
A16: EVD-824.4-007 | B16: Azure Key Vault Access Policies | C16: Config Export | D16: 2. Key Storage | E16: Azure/KeyVault/Policies | F16: 2026-01-10 | G16: Cloud Team | H16: 3 years | I16: Current
A17: EVD-824.4-008 | B17: Vault Access Control Policies | C17: Policy Document | D17: 2. Key Storage | E17: Vault/Policies | F17: 2025-11-15 | G17: Security Team | H17: 3 years | I17: Current
A18: EVD-824.4-009 | B18: Kubernetes etcd Encryption Configuration | C18: Config File | D18: 2. Key Storage | E18: Git/k8s/etcd-encryption | F18: 2025-11-20 | G18: Platform Team | H18: 2 years | I18: Current
A19: EVD-824.4-010 | B19: SSH Key Passphrase Enforcement Policy | C19: Policy | D19: 2. Key Storage | E19: SharePoint/Policies/SSH | F19: 2025-09-01 | G19: Security Team | H19: 5 years | I19: Current
A20: EVD-824.4-011 | B20: TLS Certificate Auto-Renewal Logs | C20: Log File | D20: 3. Key Rotation | E20: CertBot/Logs/2025 | F20: 2026-01-10 | G20: DevOps | H20: 1 year | I20: Current
A21: EVD-824.4-012 | B21: Key Rotation Schedule Q1 2026 | C21: Schedule Document | D21: 3. Key Rotation | E21: SharePoint/Schedules/Keys | F21: 2026-01-08 | G21: Security Team | H21: 2 years | I21: Current
... A31: EVD-824.4-022 | B31: S/MIME Deployment Status Report | C31: Status Report | D31: 5. Certificate Management | E31: SharePoint/Reports/SMIME | F31: 2026-01-08 | G31: Email Team | H31: 2 years | I31: Current
A32: EV-028
A33: EV-029
A34: EV-030
A35: EV-031
A36: EV-032
A37: EV-033
A38: EV-034
A39: EV-035
A40: EV-036
A41: EV-037
A42: EV-038
A43: EV-039
... A104: EV-100

Sheet Approval Sign-Off
A1: ASSESSMENT APPROVAL AND SIGN-OFF
A3: Assessment Summary
A4: Assessment Document | B4: ISMS-IMP-A.8.24.4 - Key Management Assessment
A5: Assessment Period | B5: Robert Kim
A6: Overall Compliance Rate | B6: Cryptography Specialist
A7: Assessment Status | B7: Information Security
B8: robert.kim@company.com
B9: 2026-01-13
A10: ASSESSMENT COMPLETED BY
A11: Name:
A12: Role/Title:
A13: Department:
A14: Email: | B14: Patricia Lopez
A15: Date: | B15: 2026-01-15
B16: Key management lifecycle controls are comprehensive. Legacy DES keys and Azure storage key rotation require immediate attention.
A18: REVIEWED BY (INFORMATION SECURITY OFFICER)
A19: Name:
A20: Date:
A21: Review Notes: | B21: Michael Chen
B22: 2026-01-16
B23: Strong key management posture. Automated rotation coverage is good. Legacy system migration is priority.
A24: APPROVED BY (CISO)
A25: Name:
A26: Date:
A27: Approval Decision:
A28: Conditions/Notes: | B28: Jennifer Williams
B29: 2026-01-18
B30: Approved with conditions
A31: NEXT REVIEW DETAILS
A32: Next Review Date:
A33: Review Responsible:
A34: Special Considerations:
B36: 2026-04-13
B37: Patricia Lopez
B38: Q2 2026 reassessment focusing on automated key rotation coverage
