Workbook

Sheet Instructions & Legend
A1: ISMS-IMP-A.8.24.1 - Data Transmission Assessment ISO/IEC 27001:2022 - Control A.8.24: Use of Cryptography
A3: Document Information
A4: Document ID | B4: ISMS-IMP-A.8.24.1
A5: Assessment Area | B5: Data Transmission Cryptographic Controls
A6: Related Policy | B6: ISMS-POL-A.8.24-S2.2
A7: Version | B7: 1.0
A8: Assessment Date
A9: Completed By
A10: Organization
A11: Review Cycle | B11: Quarterly
A13: HOW TO USE THIS WORKBOOK
A14: 1. Complete each worksheet tab for applicable systems/services.
A15: 2. Use dropdown menus for standardized entries (Status, Remediation, etc.).
A16: 3. Fill in yellow-highlighted cells with your information.
A17: 4. If Status = Partial or Non-Compliant, complete the Exception/Deviation section.
A18: 5. Check all applicable items in the Compliance Checklist for each section.
A19: 6. Provide evidence location/path for each implementation entry.
A20: 7. Summary Dashboard auto-calculates compliance statistics.
A21: 8. Maintain the Evidence Register for audit traceability.
A22: 9. Obtain final approval and sign-off in the Approval Sign-Off sheet.
A24: STATUS LEGEND
A25: Symbol | B25: Status | C25: Description
A26: ✅ | B26: Compliant | C26: Fully meets policy requirements
A27: ⚠️ | B27: Partial | C27: Some requirements met, gaps exist
A28: ❌ | B28: Non-Compliant | C28: Does not meet policy requirements
A29: N/A | B29: Not Applicable | C29: Requirement does not apply
A32: ACCEPTABLE EVIDENCE (examples)
A33: ✓ Configuration files or screenshots
A34: ✓ Network scan results (e.g., SSL Labs, nmap, testssl.sh)
A35: ✓ System documentation / architecture diagrams
A36: ✓ Vendor specifications / encryption statements
A37: ✓ Certificate inventory / key management records
A38: ✓ Audit logs / SIEM evidence
A39: ✓ Compliance reports / exception approvals

Sheet 1.1 External HTTPS-TLS
A1: 1.1 HTTPS/TLS - External Web Services Policy Requirement: All externally accessible web services MUST use TLS encryption with valid certificates from trusted CAs (Policy Section 2.2.1)
A3: Does your organization have external-facing web services or websites?
A4: Response:
A6: Service Description | B6: Current TLS Version | C6: Certificate Source (CA) | D6: Certificate Validity | E6: Status | F6: Evidence Location | G6: Gap Description | H6: Remediation Needed
A7: Example entry (see markdown spec)
A8: www.company.com | B8: TLS 1.3 | C8: DigiCert SHA-256 | D8: Valid until 2026-12-31 | E8: ✅ Compliant | F8: SSL Labs Report A+ | H8: No
A9: portal.company.com | B9: TLS 1.3 | C9: Let's Encrypt | D9: Valid until 2026-06-15 | E9: ✅ Compliant | F9: Certbot auto-renew logs | H9: No
A10: api.company.com | B10: TLS 1.3 | C10: DigiCert EV SSL | D10: Valid until 2027-03-20 | E10: ✅ Compliant | F10: AWS Certificate Manager | H10: No
A11: mail.company.com | B11: TLS 1.2 | C11: GoDaddy SSL | D11: Expires 2026-02-28 | E11: ⚠️ Partial | F11: Renewal scheduled Q1 | G11: Upgrade to TLS 1.3 | H11: Yes
A12: mobile-api.company.com | B12: TLS 1.3 | C12: DigiCert | D12: Valid until 2026-11-30 | E12: ✅ Compliant | F12: Auto-rotation enabled | H12: No
A13: partners.company.com | B13: TLS 1.3 | C13: GlobalSign | D13: Valid until 2027-01-15 | E13: ✅ Compliant | F13: SAN certificate | H13: No
A14: cdn.company.com | B14: TLS 1.3 | C14: Cloudflare Universal | D14: Valid until 2027-06-01 | E14: ✅ Compliant | F14: Cloudflare managed | H14: No
A15: admin.company.com | B15: TLS 1.3 | C15: DigiCert EV SSL | D15: Valid until 2026-09-15 | E15: ✅ Compliant | F15: EV cert + HSM backup | H15: No
A16: shop.company.com | B16: TLS 1.3 | C16: Sectigo | D16: Valid until 2026-08-20 | E16: ✅ Compliant | F16: E-commerce certificate | H16: No
A17: docs.company.com | B17: TLS 1.3 | C17: Let's Encrypt | D17: Valid until 2026-04-10 | E17: ✅ Compliant | F17: Auto-renew via certbot | H17: No
A18: legacy.company.com | B18: TLS 1.1 | C18: Self-signed | D18: Expired 2024-01-01 | E18: ❌ Non-Compliant | F18: Legacy system logs | G18: URGENT: Decommission or upgrade | H18: Yes
A19: vpn.company.com | B19: TLS 1.2 | C19: Internal CA | D19: Valid until 2025-12-31 | E19: ⚠️ Partial | F19: Internal PKI | G19: Plan TLS 1.3 upgrade | H19: Yes
A20: test.company.com | B20: TLS 1.2 | C20: Self-signed | D20: Valid until 2026-03-01 | E20: ⚠️ Partial | F20: Test environment | G20: Use valid certificate | H20: Yes
A21: blog.company.com | B21: TLS 1.3 | C21: Let's Encrypt | D21: Valid until 2026-07-15 | E21: ✅ Compliant | F21: WordPress auto-SSL | H21: No
A22: status.company.com | B22: TLS 1.3 | C22: DigiCert | D22: Valid until 2026-10-01 | E22: ✅ Compliant | F22: Status page service | H22: No
A32: Additional Details
A33: Number of external web services:
A34: Certificate expiration monitoring configured:
A35: Automated certificate renewal (REQUIRED for public CAs by Mar 2026):
A36: Certificate inventory maintained:
A38: COMPLIANCE CHECKLIST
A39: ☐ | B39: Requirement | C39: Status
A40: ☐ | B40: TLS 1.3 preferred OR TLS 1.2 minimum
A41: ☐ | B41: Valid certificates from trusted public CA
A42: ☐ | B42: Certificate validity: ≤398d (until Mar 2026), ≤200d (Mar 2026+), ≤100d (Mar 2027+), ≤47d (Mar 2029+)
A43: ☐ | B43: Self-signed certificates NOT used in production
A44: ☐ | B44: HTTP automatically redirects to HTTPS
A45: ☐ | B45: HSTS header configured
A46: ☐ | B46: Strong cipher suites configured
A47: ☐ | B47: Weak protocols disabled (TLS 1.1, 1.0, SSL)
A48: ☐ | B48: Perfect Forward Secrecy (PFS) enabled
A49: ☐ | B49: Certificate expiration alerts (≥ 30 days)
A50: ☐ | B50: Automation infrastructure ready for 47-day certificate lifecycle (by Mar 2029)
A51: Checklist Score: | B51: =COUNTIF(C40:C50,"Yes")/COUNTA(C40:C50)*100&"%" -> #DIV/0!
A53: EXCEPTION / DEVIATION DOCUMENTATION (Complete if Status = Partial or Non-Compliant)
...

Sheet 1.2 Internal HTTPS-TLS
A1: 1.2 HTTPS/TLS - Internal Web Services Policy Requirement: Internal web services containing sensitive data (Confidential or Restricted classification) MUST use TLS (Policy Section 2.2.1)
A3: Does your organization have internal web services (intranet, internal portals, internal APIs)?
A4: Response:
A6: Service Description | B6: Data Classification | C6: Current TLS Version | D6: Certificate Type | E6: Status | F6: Evidence Location | G6: Gap Description | H6: Remediation Needed
A7: Example entry (see markdown spec)
A8: intranet.internal | B8: TLS 1.3 | C8: Internal CA | D8: Valid until 2026-12-01 | E8: ✅ Compliant | F8: AD Certificate Services | H8: No
A9: gitlab.internal | B9: TLS 1.3 | C9: Internal CA | D9: Valid until 2026-11-15 | E9: ✅ Compliant | F9: GitLab SSL config | H9: No
A10: jenkins.internal | B10: TLS 1.3 | C10: Internal CA | D10: Valid until 2026-10-20 | E10: ✅ Compliant | F10: Jenkins HTTPS setup | H10: No
A11: grafana.internal | B11: TLS 1.3 | C11: Internal CA | D11: Valid until 2026-09-30 | E11: ✅ Compliant | F11: Grafana SSL logs | H11: No
A12: prometheus.internal | B12: TLS 1.3 | C12: Internal CA | D12: Valid until 2026-09-15 | E12: ✅ Compliant | F12: Prometheus config | H12: No
A13: vault.internal | B13: TLS 1.3 | C13: Internal CA + HSM | D13: Valid until 2027-01-01 | E13: ✅ Compliant | F13: Vault audit logs | H13: No
A14: elasticsearch.internal | B14: TLS 1.3 | C14: Internal CA | D14: Valid until 2026-08-20 | E14: ✅ Compliant | F14: ES cluster config | H14: No
A15: kibana.internal | B15: TLS 1.3 | C15: Internal CA | D15: Valid until 2026-08-20 | E15: ✅ Compliant | F15: Kibana SSL settings | H15: No
A16: confluence.internal | B16: TLS 1.2 | C16: Internal CA | D16: Valid until 2025-12-31 | E16: ⚠️ Partial | F16: Confluence config | G16: Upgrade to TLS 1.3 | H16: Yes
A17: jira.internal | B17: TLS 1.2 | C17: Internal CA | D17: Valid until 2025-12-31 | E17: ⚠️ Partial | F17: Jira SSL config | G17: Upgrade to TLS 1.3 | H17: Yes
A18: monitoring.internal | B18: TLS 1.3 | C18: Internal CA | D18: Valid until 2026-07-01 | E18: ✅ Compliant | F18: Monitoring stack | H18: No
A19: backup.internal | B19: TLS 1.2 | C19: Self-signed | D19: Expired 2025-11-01 | E19: ❌ Non-Compliant | F19: Backup server logs | G19: Replace with valid cert | H19: Yes
A32: Additional Details
A33: Number of internal web services:
A34: Data classification(s) handled:
A35: Internal CA in use:
A36: Certificate management process documented:
A38: COMPLIANCE CHECKLIST
A39: ☐ | B39: Requirement | C39: Status
A40: ☐ | B40: TLS 1.2+ for services with Confidential/Restricted data
A41: ☐ | B41: Valid certificates (internal CA acceptable)
A42: ☐ | B42: Services with non-sensitive data: Risk assessed and documented
A43: ☐ | B43: Certificate inventory maintained
A44: ☐ | B44: Certificate expiration monitoring configured
A45: Checklist Score: | B45: =COUNTIF(C40:C44,"Yes")/COUNTA(C40:C44)*100&"%" -> #DIV/0!
A47: EXCEPTION / DEVIATION DOCUMENTATION (Complete if Status = Partial or Non-Compliant)
A48: Formal exception request submitted:
A49: Exception ID:
A50: Risk acceptance documented:
A51: Risk ID:
A52: Compensating Controls (summary):
A53: ☐ Network segmentation / firewall restrictions
A54: ☐ Enhanced monitoring / alerting
A55: ☐ IP allowlisting / access restrictions
A56: ☐ Other (describe):
...

Sheet 2.1 Email Encryption
A1: 2.1 Email Encryption Policy Requirement: Emails containing classified information (Confidential or Restricted) MUST be encrypted when sent externally (Policy Section 2.2.2)
A3: Does your organization send emails containing classified information to external parties?
A4: Response:
A6: Email System | B6: Encryption Solution | C6: Encryption Method | D6: User Adoption Rate | E6: Status | F6: Evidence Location | G6: Gap Description | H6: Remediation Needed
A7: Example entry (see markdown spec)
A8: Microsoft 365 | B8: TLS 1.3 + S/MIME | C8: DigiCert | D8: 85% user adoption | E8: ⚠️ Partial | F8: M365 Admin Center | G8: Increase S/MIME adoption to 95% | H8: Yes
A9: Gmail Business | B9: TLS 1.3 | C9: Google Trust Services | D9: 100% enforced | E9: ✅ Compliant | F9: Google Workspace Admin | H9: No
A10: Internal Mail Server | B10: TLS 1.2 + PGP | C10: Internal CA | D10: 45% PGP adoption | E10: ⚠️ Partial | F10: Postfix logs | G10: Promote PGP key usage | H10: Yes
A11: Executive Email | B11: TLS 1.3 + S/MIME | C11: DigiCert | D11: 100% mandatory | E11: ✅ Compliant | F11: Certificate store audit | H11: No
A12: Partner Email Gateway | B12: TLS 1.2 | C12: StartTLS | D12: 90% TLS coverage | E12: ✅ Compliant | F12: Mail gateway logs | H12: No
A13: Marketing Automation | B13: TLS 1.3 | C13: SendGrid | D13: 100% | E13: ✅ Compliant | F13: SendGrid dashboard | H13: No
A14: Support Tickets | B14: TLS 1.3 | C14: Zendesk | D14: 100% | E14: ✅ Compliant | F14: Zendesk security | H14: No
A15: Notification System | B15: TLS 1.3 | C15: AWS SES | D15: 100% | E15: ✅ Compliant | F15: SES configuration | H15: No
A32: Additional Details
A33: Encryption solution in use:
A34: PKI infrastructure for email:
A35: User training provided:
A36: Encryption enforced via policy/DLP:
A38: COMPLIANCE CHECKLIST
A39: ☐ | B39: Requirement | C39: Status
A40: ☐ | B40: S/MIME or PGP/GPG encryption available
A41: ☐ | B41: Users trained on when/how to encrypt sensitive emails
A42: ☐ | B42: PKI infrastructure in place for S/MIME
A43: ☐ | B43: Opportunistic TLS enabled for mail server connections
A44: ☐ | B44: STARTTLS enabled for SMTP
A45: Checklist Score: | B45: =COUNTIF(C40:C44,"Yes")/COUNTA(C40:C44)*100&"%" -> #DIV/0!
A47: EXCEPTION / DEVIATION DOCUMENTATION (Complete if Status = Partial or Non-Compliant)
A48: Formal exception request submitted:
A49: Exception ID:
A50: Risk acceptance documented:
A51: Risk ID:
A52: Compensating Controls (summary):
A53: ☐ Network segmentation / firewall restrictions
A54: ☐ Enhanced monitoring / alerting
A55: ☐ IP allowlisting / access restrictions
A56: ☐ Other (describe):
A57: Remediation actions required:
A58: Responsible person:
... A62: ADDITIONAL NOTES / COMMENTS

Sheet 2.2 Digital Signatures
A1: 2.2 Digital Signatures Policy Requirement: Digital signatures RECOMMENDED for all external emails, REQUIRED for legal/financial/official communications (Policy Section 2.2.2)
A3: Does your organization use digital signatures for email?
A4: Response:
A6: Use Case | B6: Signature Method | C6: Certificate Source | D6: Status | E6: Evidence Location | F6: Gap Description | G6: Remediation Needed
A7: Example entry (see markdown spec)
A8: Executive Contracts | B8: RSA-4096 + SHA-256 | C8: DocuSign | D8: 100% signed | E8: ✅ Compliant | F8: DocuSign audit trail | H8: No
A9: Financial Documents | B9: RSA-4096 + SHA-256 | C9: Adobe Sign | D9: 100% required | E9: ✅ Compliant | F9: Adobe audit logs | H9: No
A10: Code Signing | B10: RSA-4096 + SHA-256 | C10: YubiKey HSM | D10: All releases | E10: ✅ Compliant | F10: CI/CD signing logs | H10: No
A11: Internal Approvals | B11: RSA-2048 + SHA-256 | C11: Internal PKI | D11: 80% adoption | E11: ⚠️ Partial | F11: Approval workflow logs | G11: Increase to 95% | H11: Yes
A12: PDF Documents | B12: RSA-4096 + SHA-256 | C12: Adobe Acrobat | D12: All sensitive docs | E12: ✅ Compliant | F12: Document management | H12: No
A13: Email Signatures | B13: RSA-2048 + SHA-256 | C13: S/MIME | D13: Executive only | E13: ⚠️ Partial | F13: Certificate logs | G13: Expand to all users | H13: Yes
A14: Legal Documents | B14: RSA-4096 + SHA-256 | C14: DocuSign + PKI | D14: 100% required | E14: ✅ Compliant | F14: Legal system logs | H14: No
A32: Additional Details
A33: Digital signatures used for:
A34: Certificate source:
A36: COMPLIANCE CHECKLIST
A37: ☐ | B37: Requirement | C37: Status
A38: ☐ | B38: Digital signatures available for required use cases
A39: ☐ | B39: Email certificates issued from trusted CA or internal PKI
A40: ☐ | B40: Certificate validity ≤ 1 year
A41: ☐ | B41: Users trained on digital signature usage
A42: Checklist Score: | B42: =COUNTIF(C38:C41,"Yes")/COUNTA(C38:C41)*100&"%" -> #DIV/0!
A44: EXCEPTION / DEVIATION DOCUMENTATION (Complete if Status = Partial or Non-Compliant)
A45: Formal exception request submitted:
A46: Exception ID:
A47: Risk acceptance documented:
A48: Risk ID:
A49: Compensating Controls (summary):
A50: ☐ Network segmentation / firewall restrictions
A51: ☐ Enhanced monitoring / alerting
A52: ☐ IP allowlisting / access restrictions
A53: ☐ Other (describe):
A54: Remediation actions required:
A55: Responsible person:
... A59: ADDITIONAL NOTES / COMMENTS

Sheet 3.1 File Transfer Protocols
A1: 3.1 Secure File Transfer Policy Requirement: File transfers containing sensitive data MUST use encrypted protocols (SFTP, FTPS, HTTPS). Unencrypted FTP is PROHIBITED (Policy Section 2.2.3)
A3: Does your organization transfer files containing sensitive data to/from external parties or between systems?
A4: Response:
A6: Transfer Method/System | B6: Protocol Used | C6: Authentication Method | D6: Data Classification | E6: Status | F6: Evidence Location | G6: Gap Description | H6: Remediation Needed
A7: Example entry (see markdown spec)
A8: SFTP Production | B8: SSH-2 (RSA-4096) | C8: Key-based | D8: Port 22 | E8: ✅ Compliant | F8: SFTP server logs | H8: No
A9: FTPS Partner Gateway | B9: TLS 1.3 | C9: Certificate-based | D9: Port 990 | E9: ✅ Compliant | F9: FileZilla logs | H9: No
A10: SCP Internal | B10: SSH-2 (Ed25519) | C10: Key-based | D10: Port 22 | E10: ✅ Compliant | F10: SSH audit logs | H10: No
A11: Legacy FTP | B11: FTP (plaintext) | C11: Password | D11: Port 21 | E11: ❌ Non-Compliant | F11: Old FTP logs | G11: URGENT: Migrate to SFTP | H11: Yes
A12: HTTPS File Upload | B12: TLS 1.3 | C12: Certificate | D12: Port 443 | E12: ✅ Compliant | F12: Web server logs | H12: No
A13: rsync Backups | B13: SSH-2 (RSA-4096) | C13: Key-based | D13: Port 22 | E13: ✅ Compliant | F13: Backup logs | H13: No
A14: AWS S3 Transfer | B14: TLS 1.3 | C14: IAM + KMS | D14: Port 443 | E14: ✅ Compliant | F14: CloudTrail logs | H14: No
A15: Azure Files | B15: SMB 3.1.1 + TLS 1.3 | C15: Kerberos + cert | D15: Port 445 | E15: ✅ Compliant | F15: Azure Storage logs | H15: No
A32: Additional Details
A33: Approved protocols in use:
A34: Prohibited protocols detected:
A35: Authentication:
A37: COMPLIANCE CHECKLIST
A38: ☐ | B38: Requirement | C38: Status
A39: ☐ | B39: SFTP, FTPS, or HTTPS used for sensitive file transfers
A40: ☐ | B40: Plain FTP NOT used for sensitive data
A41: ☐ | B41: Strong authentication configured (key-based preferred)
A42: ☐ | B42: MFA required for external file transfer
A43: ☐ | B43: File transfer logging enabled
A44: ☐ | B44: SSH keys rotated annually (if SFTP used)
A45: Checklist Score: | B45: =COUNTIF(C39:C44,"Yes")/COUNTA(C39:C44)*100&"%" -> #DIV/0!
A47: EXCEPTION / DEVIATION DOCUMENTATION (Complete if Status = Partial or Non-Compliant)
A48: Formal exception request submitted:
A49: Exception ID:
A50: Risk acceptance documented:
A51: Risk ID:
A52: Compensating Controls (summary):
A53: ☐ Network segmentation / firewall restrictions
A54: ☐ Enhanced monitoring / alerting
A55: ☐ IP allowlisting / access restrictions
A56: ☐ Other (describe):
A57: Remediation actions required:
A58: Responsible person:
... A62: ADDITIONAL NOTES / COMMENTS

Sheet 4.1 VPN
A1: 4.1 VPN (Virtual Private Network) Policy Requirement: All remote access to organizational networks MUST use encrypted VPN with approved protocols (IPsec, WireGuard, OpenVPN). MFA REQUIRED (Policy Section 2.2.4)
A3: Does your organization provide remote access via VPN?
A4: Response:
A6: VPN Solution | B6: Protocol | C6: Encryption Algorithm | D6: MFA Enabled | E6: Status | F6: Evidence Location | G6: Gap Description | H6: Remediation Needed
A7: Example entry (see markdown spec)
A8: Employee VPN (OpenVPN) | B8: TLS 1.3 | C8: AES-256-GCM + RSA-4096 | D8: MFA required | E8: ✅ Compliant | F8: VPN server logs + MFA logs | H8: No
A9: Site-to-Site VPN (IPSec) | B9: IKEv2 | C9: AES-256-CBC + DH Group 14 | D9: Pre-shared key | E9: ⚠️ Partial | F9: Firewall logs | G9: Add certificate auth + DH 20 | H9: Yes
A10: Executive VPN (WireGuard) | B10: WireGuard | C10: ChaCha20-Poly1305 + Curve25519 | D10: MFA + device cert | E10: ✅ Compliant | F10: WireGuard logs + MDM | H10: No
A11: Partner VPN (SSL) | B11: TLS 1.3 | C11: AES-256-GCM + ECDHE | D11: Certificate + MFA | E11: ✅ Compliant | F11: SSL VPN access logs | H11: No
A12: Contractor VPN (OpenVPN) | B12: TLS 1.2 | C12: AES-128-CBC + RSA-2048 | D12: Password only | E12: ❌ Non-Compliant | F12: Legacy VPN config | G12: Upgrade: TLS 1.3 + MFA + AES-256 | H12: Yes
A13: Remote Admin VPN | B13: TLS 1.3 | C13: AES-256-GCM + RSA-4096 | D13: MFA + FIDO2 | E13: ✅ Compliant | F13: Admin VPN audit logs | H13: No
A14: Vendor VPN (Temporary) | B14: TLS 1.3 | C14: AES-256-GCM | D14: Time-limited certs | E14: ✅ Compliant | F14: Vendor access logs | H14: No
A32: Additional Details
A33: VPN protocol in use:
A34: Encryption algorithm:
A35: Number of VPN users:
A36: MFA solution:
A37: Split-tunneling:
A39: COMPLIANCE CHECKLIST
A40: ☐ | B40: Requirement | C40: Status
A41: ☐ | B41: Approved VPN protocol (IPsec/IKEv2, WireGuard, OpenVPN with TLS 1.2+)
A42: ☐ | B42: AES-256 or ChaCha20 encryption
A43: ☐ | B43: Perfect Forward Secrecy (PFS) enabled
A44: ☐ | B44: MFA required for all VPN connections
A45: ☐ | B45: Certificate-based authentication (preferred) OR strong pre-shared key
A46: ☐ | B46: VPN session timeout configured (≤30 minutes idle)
A47: ☐ | B47: Split-tunneling disabled (or documented exception)
A48: ☐ | B48: VPN access logs retained and reviewed
A49: Checklist Score: | B49: =COUNTIF(C41:C48,"Yes")/COUNTA(C41:C48)*100&"%" -> #DIV/0!
A51: EXCEPTION / DEVIATION DOCUMENTATION (Complete if Status = Partial or Non-Compliant)
A52: Formal exception request submitted:
A53: Exception ID:
A54: Risk acceptance documented:
A55: Risk ID:
A56: Compensating Controls (summary):
A57: ☐ Network segmentation / firewall restrictions
A58: ☐ Enhanced monitoring / alerting
A59: ☐ IP allowlisting / access restrictions
A60: ☐ Other (describe):
A61: Remediation actions required:
...

Sheet 4.2 SSH
A1: 4.2 SSH (Secure Shell) Policy Requirement: SSH REQUIRED for all administrative and remote terminal access. SSH protocol version 2 REQUIRED, password authentication SHOULD be disabled (Policy Section 2.2.4)
A3: Does your organization use SSH for remote system administration?
A4: Response:
A6: System/Service | B6: SSH Version | C6: Authentication Method | D6: Key Algorithm | E6: Status | F6: Evidence Location | G6: Gap Description | H6: Remediation Needed
A7: Example entry (see markdown spec)
A8: Production Servers | B8: SSH-2 (Ed25519) | C8: Key-based + FIDO2 | D8: Bastion required | E8: ✅ Compliant | F8: SSH audit logs + Bastion | H8: No
A9: Development Servers | B9: SSH-2 (RSA-4096) | C9: Key-based | D9: Direct access | E9: ✅ Compliant | F9: Dev SSH logs | H9: No
A10: Database Servers | B10: SSH-2 (Ed25519) | C10: Key + MFA | D10: Bastion + audit | E10: ✅ Compliant | F10: DB SSH logs | H10: No
A11: Network Devices | B11: SSH-2 (RSA-2048) | C11: Password + TACACS+ | D11: Cisco devices | E11: ⚠️ Partial | F11: TACACS+ logs | G11: Migrate to key-based | H11: Yes
A12: IoT Devices | B12: SSH-2 (RSA-2048) | C12: Default passwords | D12: Embedded systems | E12: ❌ Non-Compliant | F12: IoT inventory | G12: Implement key management | H12: Yes
A13: Jump/Bastion Host | B13: SSH-2 (Ed25519) | C13: Key + FIDO2 + session recording | D13: All access logged | E13: ✅ Compliant | F13: Bastion audit logs | H13: No
A14: Git Repository Access | B14: SSH-2 (Ed25519) | C14: Key-based | D14: GitLab/GitHub | E14: ✅ Compliant | F14: Git SSH logs | H14: No
A15: Backup Server Access | B15: SSH-2 (RSA-4096) | C15: Key-based | D15: Restricted IPs | E15: ✅ Compliant | F15: Backup SSH logs | H15: No
A32: Additional Details
A33: SSH protocol version:
A34: Authentication method:
A35: SSH key types in use:
A36: Root login via SSH:
A37: SSH key rotation schedule:
A39: COMPLIANCE CHECKLIST
A40: ☐ | B40: Requirement | C40: Status
A41: ☐ | B41: SSH protocol version 2 only (SSHv1 disabled)
A42: ☐ | B42: Key-based authentication (password auth disabled preferred)
A43: ☐ | B43: Minimum key length: RSA 2048-bit or Ed25519
A44: ☐ | B44: Root login disabled
A45: ☐ | B45: SSH keys rotated annually
A46: ☐ | B46: Unused SSH keys removed
A47: ☐ | B47: Strong algorithms configured (per Policy Appendix A)
A48: ☐ | B48: Weak algorithms disabled (DSA, MD5, SHA-1)
A49: Checklist Score: | B49: =COUNTIF(C41:C48,"Yes")/COUNTA(C41:C48)*100&"%" -> #DIV/0!
A51: EXCEPTION / DEVIATION DOCUMENTATION (Complete if Status = Partial or Non-Compliant)
A52: Formal exception request submitted:
A53: Exception ID:
A54: Risk acceptance documented:
A55: Risk ID:
A56: Compensating Controls (summary):
A57: ☐ Network segmentation / firewall restrictions
A58: ☐ Enhanced monitoring / alerting
A59: ☐ IP allowlisting / access restrictions
A60: ☐ Other (describe):
...

Sheet 4.3 RDP
A1: 4.3 RDP (Remote Desktop Protocol) Policy Requirement: RDP connections MUST be encrypted using TLS. RDP MUST NOT be directly exposed to the Internet (Policy Section 2.2.4)
A3: Does your organization use RDP for remote access?
A4: Response:
A6: System/Environment | B6: RDP Access Method | C6: TLS Encryption | D6: NLA Enabled | E6: Status | F6: Evidence Location | G6: Gap Description | H6: Remediation Needed
A7: Example entry (see markdown spec)
A8: Windows Servers | B8: RDP with NLA + TLS 1.3 | C8: AES-256 | D8: MFA enforced | E8: ✅ Compliant | F8: RDP logs + MFA events | H8: No
A9: Windows Workstations | B9: RDP with NLA + TLS 1.2 | C9: AES-128 | D9: Password only | E9: ⚠️ Partial | F9: Workstation RDP logs | G9: Enforce MFA + TLS 1.3 | H9: Yes
A10: Terminal Servers | B10: RDP with NLA + TLS 1.3 | C10: AES-256 | D10: MFA + smartcard | E10: ✅ Compliant | F10: Terminal server logs | H10: No
A11: Legacy Systems | B11: RDP without NLA | C11: RC4 (weak) | D11: Password | E11: ❌ Non-Compliant | F11: Legacy RDP logs | G11: URGENT: Enable NLA + TLS 1.3 | H11: Yes
A12: Admin Workstations | B12: RDP with NLA + TLS 1.3 | C12: AES-256-GCM | D12: FIDO2 required | E12: ✅ Compliant | F12: Admin RDP audit | H12: No
A13: Jump Server RDP | B13: RDP with NLA + TLS 1.3 | C13: AES-256 + session recording | D13: Certificate + MFA | E13: ✅ Compliant | F13: Jump server logs | H13: No
A32: Additional Details
A33: RDP access method:
A34: Network Level Authentication (NLA):
A35: MFA for RDP:
A36: RDP encryption level:
A38: COMPLIANCE CHECKLIST
A39: ☐ | B39: Requirement | C39: Status
A40: ☐ | B40: RDP accessed through VPN or jump host (NOT directly exposed)
A41: ☐ | B41: TLS encryption configured
A42: ☐ | B42: Network Level Authentication (NLA) enabled
A43: ☐ | B43: RDP encryption level set to 'High'
A44: ☐ | B44: MFA required for production system access
A45: ☐ | B45: RDP session recording (recommended for privileged access)
A46: Checklist Score: | B46: =COUNTIF(C40:C45,"Yes")/COUNTA(C40:C45)*100&"%" -> #DIV/0!
A48: EXCEPTION / DEVIATION DOCUMENTATION (Complete if Status = Partial or Non-Compliant)
A49: Formal exception request submitted:
A50: Exception ID:
A51: Risk acceptance documented:
A52: Risk ID:
A53: Compensating Controls (summary):
A54: ☐ Network segmentation / firewall restrictions
A55: ☐ Enhanced monitoring / alerting
A56: ☐ IP allowlisting / access restrictions
A57: ☐ Other (describe):
A58: Remediation actions required:
A59: Responsible person:
... A63: ADDITIONAL NOTES / COMMENTS

Sheet 5.1 API Security
A1: 5.1 API Security Policy Requirement: API endpoints MUST use HTTPS with TLS 1.2+. API authentication MUST use OAuth 2.0, API keys (256-bit entropy), or mutual TLS (Policy Section 2.2.5)
A3: Does your organization expose APIs (REST, SOAP, GraphQL, etc.)?
A4: Response:
A6: API Name/Service | B6: Authentication Method | C6: TLS Version | D6: API Key Management | E6: Token Expiry | F6: Status | G6: Evidence Location | H6: Gap Description | I6: Remediation Needed
A7: Example entry (see markdown spec)
A8: REST API (Public) | B8: TLS 1.3 | C8: AES-256-GCM + ECDHE | D8: JWT + OAuth 2.0 | E8: ✅ Compliant | F8: API Gateway logs | H8: No
A9: GraphQL API | B9: TLS 1.3 | C9: AES-256-GCM | D9: API Key + JWT | E9: ✅ Compliant | F9: GraphQL server logs | H9: No
A10: Internal Microservices | B10: mTLS (TLS 1.3) | C10: AES-256-GCM | D10: Service mesh certs | E10: ✅ Compliant | F10: Istio/Linkerd logs | H10: No
A11: Partner API | B11: TLS 1.3 | C11: AES-256-GCM | D11: Client certificates | E11: ✅ Compliant | F11: Partner API logs | H11: No
A12: Mobile App API | B12: TLS 1.3 + Certificate Pinning | C12: AES-256-GCM | D12: JWT + refresh tokens | E12: ✅ Compliant | F12: Mobile API logs | H12: No
A13: Legacy SOAP API | B13: TLS 1.2 | C13: AES-128-CBC | D13: WS-Security (username) | E13: ⚠️ Partial | F13: SOAP logs | G13: Upgrade TLS 1.3 + OAuth | H13: Yes
A14: Webhook Endpoints | B14: TLS 1.3 | C14: AES-256-GCM | D14: HMAC signatures | E14: ✅ Compliant | F14: Webhook logs | H14: No
A15: Admin API | B15: TLS 1.3 + mTLS | C15: AES-256-GCM | D15: Client cert + RBAC | E15: ✅ Compliant | F15: Admin API audit | H15: No
A32: Additional Details
A33: Number of APIs:
A34: API authentication:
A35: API key entropy:
A36: API key rotation:
A37: API keys stored in:
A39: COMPLIANCE CHECKLIST
A40: ☐ | B40: Requirement | C40: Status
A41: ☐ | B41: All API endpoints use HTTPS (TLS 1.2+)
A42: ☐ | B42: HTTP endpoints disabled or blocked
A43: ☐ | B43: OAuth 2.0 with PKCE (for user-facing APIs)
A44: ☐ | B44: API keys have ≥256-bit entropy
A45: ☐ | B45: API keys rotate every 90 days
A46: ☐ | B46: API keys stored in secrets manager (NOT in code/config)
A47: ☐ | B47: Access tokens expire within 1 hour
A48: ☐ | B48: Refresh tokens expire within 24 hours
A49: ☐ | B49: Rate limiting implemented per API key
A50: ☐ | B50: API keys NOT passed in URL query parameters
A51: Checklist Score: | B51: =COUNTIF(C41:C50,"Yes")/COUNTA(C41:C50)*100&"%" -> #DIV/0!
A53: EXCEPTION / DEVIATION DOCUMENTATION (Complete if Status = Partial or Non-Compliant)
A54: Formal exception request submitted:
A55: Exception ID:
A56: Risk acceptance documented:
A57: Risk ID:
A58: Compensating Controls (summary):
A59: ☐ Network segmentation / firewall restrictions
A60: ☐ Enhanced monitoring / alerting
...

Sheet 6.1 Database Connections
A1: 6.1 Database Connections Policy Requirement: Database connections MUST use encrypted protocols (TLS for PostgreSQL/MySQL, encrypted connections for MSSQL) (Policy Section 2.2.6)
A3: Does your organization have applications connecting to databases?
A4: Response:
A6: Database System | B6: Connection Encryption | C6: Certificate Validation | D6: Status | E6: Evidence Location | F6: Gap Description | G6: Remediation Needed
A7: Example entry (see markdown spec)
A8: PostgreSQL Production | B8: TLS 1.3 + SCRAM-SHA-256 | C8: AES-256-GCM | D8: Certificate required | E8: ✅ Compliant | F8: PostgreSQL logs | H8: No
A9: MySQL Cluster | B9: TLS 1.3 | C9: AES-256 | D9: Certificate + password | E9: ✅ Compliant | F9: MySQL SSL status | H9: No
A10: SQL Server | B10: TLS 1.3 + Kerberos | C10: AES-256 | D10: Windows Auth | E10: ✅ Compliant | F10: SQL Server DMVs | H10: No
A11: MongoDB | B11: TLS 1.3 + SCRAM | C11: AES-256-GCM | D11: X.509 certificates | E11: ✅ Compliant | F11: MongoDB logs | H11: No
A12: Redis | B12: TLS 1.3 | C12: AES-256-GCM | D12: ACL + password | E12: ✅ Compliant | F12: Redis ACL logs | H12: No
A13: Oracle Database | B13: TLS 1.2 + Oracle Native | C13: AES-192 | D13: Password only | E13: ⚠️ Partial | F13: Oracle audit | G13: Upgrade TLS 1.3 + AES-256 | H13: Yes
A14: Elasticsearch | B14: TLS 1.3 + SAML | C14: AES-256-GCM | D14: Certificate + RBAC | E14: ✅ Compliant | F14: ES security logs | H14: No
A15: Cassandra | B15: TLS 1.3 | C15: AES-256 | D15: Certificate auth | E15: ✅ Compliant | F15: Cassandra audit | H15: No
A16: MariaDB | B16: TLS 1.3 | C16: AES-256 | D16: Certificate required | E16: ✅ Compliant | F16: MariaDB SSL logs | H16: No
A17: DynamoDB | B17: TLS 1.3 + IAM | C17: AES-256-GCM | D17: IAM roles | E17: ✅ Compliant | F17: CloudTrail logs | H17: No
A32: Additional Details
A33: Database systems in use:
A34: Connection encryption enforced:
A36: COMPLIANCE CHECKLIST
A37: ☐ | B37: Requirement | C37: Status
A38: ☐ | B38: Database connections encrypted (TLS/SSL)
A39: ☐ | B39: Certificate validation enabled (not 'trust any certificate')
A40: ☐ | B40: Self-signed certificates only for internal databases (with proper CA)
A41: ☐ | B41: Unencrypted connections disabled or documented exception
A42: Checklist Score: | B42: =COUNTIF(C38:C41,"Yes")/COUNTA(C38:C41)*100&"%" -> #DIV/0!
A44: EXCEPTION / DEVIATION DOCUMENTATION (Complete if Status = Partial or Non-Compliant)
A45: Formal exception request submitted:
A46: Exception ID:
A47: Risk acceptance documented:
A48: Risk ID:
A49: Compensating Controls (summary):
A50: ☐ Network segmentation / firewall restrictions
A51: ☐ Enhanced monitoring / alerting
A52: ☐ IP allowlisting / access restrictions
A53: ☐ Other (describe):
A54: Remediation actions required:
A55: Responsible person:
... A59: ADDITIONAL NOTES / COMMENTS

Sheet 6.2 Wireless Networks
A1: 6.2 Wireless Networks Policy Requirement: Wireless networks MUST use WPA3-Enterprise or WPA2-Enterprise minimum. WEP and WPA (original) PROHIBITED (Policy Section 2.2.6)
A3: Does your organization have wireless networks?
A4: Response:
A6: Network SSID | B6: Encryption Standard | C6: Authentication Method | D6: Status | E6: Evidence Location | F6: Gap Description | G6: Remediation Needed
A7: Example entry (see markdown spec)
A8: Corporate WiFi | B8: WPA3-Enterprise | C8: AES-256 + 802.1X | D8: RADIUS + certificates | E8: ✅ Compliant | F8: RADIUS logs + AP logs | H8: No
A9: Guest WiFi | B9: WPA3-Personal | C9: AES-256 | D9: Captive portal | E9: ✅ Compliant | F9: Guest access logs | H9: No
A10: IoT WiFi | B10: WPA2-Enterprise | C10: AES-256 + 802.1X | D10: Device certificates | E10: ⚠️ Partial | F10: IoT VLAN logs | G10: Migrate to WPA3 | H10: Yes
A11: Executive Floor | B11: WPA3-Enterprise | C11: AES-256 + 802.1X | D11: RADIUS + FIDO2 | E11: ✅ Compliant | F11: Executive AP logs | H11: No
A12: Conference Rooms | B12: WPA3-Personal | C12: AES-256 | D12: Daily rotating PSK | E12: ✅ Compliant | F12: Conference WiFi logs | H12: No
A13: Warehouse WiFi | B13: WPA2-Personal | C13: AES-128 | D13: Shared PSK | E13: ❌ Non-Compliant | F13: Warehouse AP logs | G13: Upgrade WPA3 + 802.1X | H13: Yes
A14: Data Center WiFi | B14: Disabled | C14: N/A | D14: Wired only | E14: ✅ Compliant | F14: DC access policy | H14: No
A32: Additional Details
A33: Corporate WiFi encryption:
A34: Guest WiFi:
A35: 802.1X authentication:
A36: WiFi password strength:
A38: COMPLIANCE CHECKLIST
A39: ☐ | B39: Requirement | C39: Status
A40: ☐ | B40: WPA3-Enterprise or WPA2-Enterprise for corporate networks
A41: ☐ | B41: 802.1X with EAP-TLS (certificate-based) preferred
A42: ☐ | B42: WPA2-Personal only with strong passphrase (≥20 characters)
A43: ☐ | B43: WEP and WPA (original) NOT used
A44: ☐ | B44: Guest wireless isolated from corporate network
A45: ☐ | B45: WiFi passwords rotated quarterly (for PSK networks)
A46: Checklist Score: | B46: =COUNTIF(C40:C45,"Yes")/COUNTA(C40:C45)*100&"%" -> #DIV/0!
A48: EXCEPTION / DEVIATION DOCUMENTATION (Complete if Status = Partial or Non-Compliant)
A49: Formal exception request submitted:
A50: Exception ID:
A51: Risk acceptance documented:
A52: Risk ID:
A53: Compensating Controls (summary):
A54: ☐ Network segmentation / firewall restrictions
A55: ☐ Enhanced monitoring / alerting
A56: ☐ IP allowlisting / access restrictions
A57: ☐ Other (describe):
A58: Remediation actions required:
A59: Responsible person:
... A63: ADDITIONAL NOTES / COMMENTS

Sheet 7.1 Cloud Transmission
A1: 7.1 Cloud Data Transmission Policy Requirement: Connections to cloud provider APIs MUST use TLS 1.2+. Private connectivity options (PrivateLink, Private Link, Private Service Connect) RECOMMENDED for high-volume or sensitive data (Policy Section 2.2.7)
A3: Does your organization use cloud services (AWS, Azure, GCP, SaaS)?
A4: Response:
A6: Cloud Provider/Service | B6: Connection Method | C6: Encryption | D6: Status | E6: Evidence Location | F6: Gap Description | G6: Remediation Needed
A7: Example entry (see markdown spec)
A8: AWS Services | B8: TLS 1.3 | C8: AES-256-GCM | D8: IAM + KMS | E8: ✅ Compliant | F8: CloudTrail + VPC Flow | H8: No
A9: Azure Services | B9: TLS 1.3 | C9: AES-256-GCM | D9: Azure AD + Key Vault | E9: ✅ Compliant | F9: Azure Monitor | H9: No
A10: GCP Services | B10: TLS 1.3 | C10: AES-256-GCM | D10: IAM + Cloud KMS | E10: ✅ Compliant | F10: Cloud Audit Logs | H10: No
A11: AWS VPC Peering | B11: Encrypted in-transit | C11: AES-256-GCM | D11: VPC routing | E11: ✅ Compliant | F11: VPC peering logs | H11: No
A12: Azure ExpressRoute | B12: Private connection + IPsec | C12: AES-256 | D12: MACsec enabled | E12: ✅ Compliant | F12: ExpressRoute metrics | H12: No
A13: GCP Interconnect | B13: Private connection + IPsec | C13: AES-256 | D13: Cloud VPN | E13: ✅ Compliant | F13: Interconnect logs | H13: No
A14: Multi-cloud VPN | B14: TLS 1.3 + IPsec | C14: AES-256-GCM | D14: Site-to-site | E14: ✅ Compliant | F14: Multi-cloud logs | H14: No
A15: CDN (CloudFront) | B15: TLS 1.3 | C15: AES-256-GCM | D15: AWS managed | E15: ✅ Compliant | F15: CloudFront logs | H15: No
A16: CDN (Azure CDN) | B16: TLS 1.3 | C16: AES-256-GCM | D16: Azure managed | E16: ✅ Compliant | F16: CDN analytics | H16: No
A17: SaaS Applications | B17: TLS 1.3 | C17: AES-256 | D17: OAuth + SAML | E17: ✅ Compliant | F17: SSO audit logs | H17: No
A32: Additional Details
A33: Connection type:
A34: Data classification transmitted:
A35: Cloud providers used:
A37: COMPLIANCE CHECKLIST
A38: ☐ | B38: Requirement | C38: Status
A39: ☐ | B39: TLS 1.2+ for all cloud API connections
A40: ☐ | B40: Private connectivity for Confidential/Restricted data (preferred)
A41: ☐ | B41: Cloud provider native encryption enabled
A42: ☐ | B42: Data encrypted in transit to/from cloud
A43: Checklist Score: | B43: =COUNTIF(C39:C42,"Yes")/COUNTA(C39:C42)*100&"%" -> #DIV/0!
A45: EXCEPTION / DEVIATION DOCUMENTATION (Complete if Status = Partial or Non-Compliant)
A46: Formal exception request submitted:
A47: Exception ID:
A48: Risk acceptance documented:
A49: Risk ID:
A50: Compensating Controls (summary):
A51: ☐ Network segmentation / firewall restrictions
A52: ☐ Enhanced monitoring / alerting
A53: ☐ IP allowlisting / access restrictions
A54: ☐ Other (describe):
A55: Remediation actions required:
A56: Responsible person:
... A60: ADDITIONAL NOTES / COMMENTS

Sheet Summary Dashboard
A1: DATA TRANSMISSION ASSESSMENT - COMPLIANCE SUMMARY
A3: Assessment Area | B3: Total Items | C3: Compliant | D3: Partial | E3: Non-Compliant | F3: N/A | G3: Compliance %
A4: 1.1 External HTTPS/TLS | B4: =COUNTA('1.1 External HTTPS-TLS'!E8:E30) -> 15 | C4: =COUNTIF('1.1 External HTTPS-TLS'!E8:E30,"✅*") -> 11 | D4: =COUNTIF('1.1 External HTTPS-TLS'!E8:E30,"⚠️*") -> 3 | E4: =COUNTIF('1.1 External HTTPS-TLS'!E8:E30,"❌*") -> 1 | F4: =COUNTIF('1.1 External HTTPS-TLS'!E8:E30,"N/A") -> 0 | G4: =IF((B4-F4)=0,"0%",ROUND(C4/(B4-F4)*100,1)&"%") -> 73.3%
A5: 1.2 Internal HTTPS/TLS | B5: =COUNTA('1.2 Internal HTTPS-TLS'!E8:E30) -> 12 | C5: =COUNTIF('1.2 Internal HTTPS-TLS'!E8:E30,"✅*") -> 9 | D5: =COUNTIF('1.2 Internal HTTPS-TLS'!E8:E30,"⚠️*") -> 2 | E5: =COUNTIF('1.2 Internal HTTPS-TLS'!E8:E30,"❌*") -> 1 | F5: =COUNTIF('1.2 Internal HTTPS-TLS'!E8:E30,"N/A") -> 0 | G5: =IF((B5-F5)=0,"0%",ROUND(C5/(B5-F5)*100,1)&"%") -> 75%
A6: 2.1 Email Encryption | B6: =COUNTA('2.1 Email Encryption'!E8:E30) -> 8 | C6: =COUNTIF('2.1 Email Encryption'!E8:E30,"✅*") -> 6 | D6: =COUNTIF('2.1 Email Encryption'!E8:E30,"⚠️*") -> 2 | E6: =COUNTIF('2.1 Email Encryption'!E8:E30,"❌*") -> 0 | F6: =COUNTIF('2.1 Email Encryption'!E8:E30,"N/A") -> 0 | G6: =IF((B6-F6)=0,"0%",ROUND(C6/(B6-F6)*100,1)&"%") -> 75%
A7: 2.2 Digital Signatures | B7: =COUNTA('2.2 Digital Signatures'!D8:D30) -> 7 | C7: =COUNTIF('2.2 Digital Signatures'!D8:D30,"✅*") -> 0 | D7: =COUNTIF('2.2 Digital Signatures'!D8:D30,"⚠️*") -> 0 | E7: =COUNTIF('2.2 Digital Signatures'!D8:D30,"❌*") -> 0 | F7: =COUNTIF('2.2 Digital Signatures'!D8:D30,"N/A") -> 0 | G7: =IF((B7-F7)=0,"0%",ROUND(C7/(B7-F7)*100,1)&"%") -> 0%
A8: 3.1 File Transfer | B8: =COUNTA('3.1 File Transfer Protocols'!E8:E30) -> 8 | C8: =COUNTIF('3.1 File Transfer Protocols'!E8:E30,"✅*") -> 7 | D8: =COUNTIF('3.1 File Transfer Protocols'!E8:E30,"⚠️*") -> 0 | E8: =COUNTIF('3.1 File Transfer Protocols'!E8:E30,"❌*") -> 1 | F8: =COUNTIF('3.1 File Transfer Protocols'!E8:E30,"N/A") -> 0 | G8: =IF((B8-F8)=0,"0%",ROUND(C8/(B8-F8)*100,1)&"%") -> 87.5%
A9: 4.1 VPN | B9: =COUNTA('4.1 VPN'!E8:E30) -> 7 | C9: =COUNTIF('4.1 VPN'!E8:E30,"✅*") -> 5 | D9: =COUNTIF('4.1 VPN'!E8:E30,"⚠️*") -> 1 | E9: =COUNTIF('4.1 VPN'!E8:E30,"❌*") -> 1 | F9: =COUNTIF('4.1 VPN'!E8:E30,"N/A") -> 0 | G9: =IF((B9-F9)=0,"0%",ROUND(C9/(B9-F9)*100,1)&"%") -> 71.4%
A10: 4.2 SSH | B10: =COUNTA('4.2 SSH'!E8:E30) -> 8 | C10: =COUNTIF('4.2 SSH'!E8:E30,"✅*") -> 6 | D10: =COUNTIF('4.2 SSH'!E8:E30,"⚠️*") -> 1 | E10: =COUNTIF('4.2 SSH'!E8:E30,"❌*") -> 1 | F10: =COUNTIF('4.2 SSH'!E8:E30,"N/A") -> 0 | G10: =IF((B10-F10)=0,"0%",ROUND(C10/(B10-F10)*100,1)&"%") -> 75%
A11: 4.3 RDP | B11: =COUNTA('4.3 RDP'!E8:E30) -> 6 | C11: =COUNTIF('4.3 RDP'!E8:E30,"✅*") -> 4 | D11: =COUNTIF('4.3 RDP'!E8:E30,"⚠️*") -> 1 | E11: =COUNTIF('4.3 RDP'!E8:E30,"❌*") -> 1 | F11: =COUNTIF('4.3 RDP'!E8:E30,"N/A") -> 0 | G11: =IF((B11-F11)=0,"0%",ROUND(C11/(B11-F11)*100,1)&"%") -> 66.7%
A12: 5.1 API Security | B12: =COUNTA('5.1 API Security'!F8:F30) -> 8 | C12: =COUNTIF('5.1 API Security'!F8:F30,"✅*") -> 0 | D12: =COUNTIF('5.1 API Security'!F8:F30,"⚠️*") -> 0 | E12: =COUNTIF('5.1 API Security'!F8:F30,"❌*") -> 0 | F12: =COUNTIF('5.1 API Security'!F8:F30,"N/A") -> 0 | G12: =IF((B12-F12)=0,"0%",ROUND(C12/(B12-F12)*100,1)&"%") -> 0%
A13: 6.1 Database Connections | B13: =COUNTA('6.1 Database Connections'!D8:D30) -> 10 | C13: =COUNTIF('6.1 Database Connections'!D8:D30,"✅*") -> 0 | D13: =COUNTIF('6.1 Database Connections'!D8:D30,"⚠️*") -> 0 | E13: =COUNTIF('6.1 Database Connections'!D8:D30,"❌*") -> 0 | F13: =COUNTIF('6.1 Database Connections'!D8:D30,"N/A") -> 0 | G13: =IF((B13-F13)=0,"0%",ROUND(C13/(B13-F13)*100,1)&"%") -> 0%
A14: 6.2 Wireless Networks | B14: =COUNTA('6.2 Wireless Networks'!D8:D30) -> 7 | C14: =COUNTIF('6.2 Wireless Networks'!D8:D30,"✅*") -> 0 | D14: =COUNTIF('6.2 Wireless Networks'!D8:D30,"⚠️*") -> 0 | E14: =COUNTIF('6.2 Wireless Networks'!D8:D30,"❌*") -> 0 | F14: =COUNTIF('6.2 Wireless Networks'!D8:D30,"N/A") -> 0 | G14: =IF((B14-F14)=0,"0%",ROUND(C14/(B14-F14)*100,1)&"%") -> 0%
A15: 7.1 Cloud Transmission | B15: =COUNTA('7.1 Cloud Transmission'!D8:D30) -> 10 | C15: =COUNTIF('7.1 Cloud Transmission'!D8:D30,"✅*") -> 0 | D15: =COUNTIF('7.1 Cloud Transmission'!D8:D30,"⚠️*") -> 0 | E15: =COUNTIF('7.1 Cloud Transmission'!D8:D30,"❌*") -> 0 | F15: =COUNTIF('7.1 Cloud Transmission'!D8:D30,"N/A") -> 0 | G15: =IF((B15-F15)=0,"0%",ROUND(C15/(B15-F15)*100,1)&"%") -> 0%
A16: TOTAL | B16: =SUM(B4:B15) -> 106 | C16: =SUM(C4:C15) -> 48 | D16: =SUM(D4:D15) -> 10 | E16: =SUM(E4:E15) -> 6 | F16: =SUM(F4:F15) -> 0 | G16: =IF((B16-F16)=0,"0%",ROUND(C16/(B16-F16)*100,1)&"%") -> 45.3%
A19: CRITICAL GAPS REQUIRING IMMEDIATE ATTENTION
A20: Priority | B20: Assessment Area | C20: Gap Description | D20: Responsible Person | E20: Target Date | F20: Status

Sheet Evidence Register
A1: EVIDENCE REGISTER
A2: List all evidence files/documents referenced in this assessment (audit traceability).
A4: Evidence ID | B4: Assessment Area | C4: Evidence Type | D4: Description | E4: Location/Path | F4: Date Collected | G4: Collected By | H4: Verification Status
A5: EV-001
A6: EV-002
A7: EV-003
A8: EV-004
A9: EV-005
A10: EVD-824.1-001 | B10: SSL Labs Security Report - www.company.com | C10: Technical Report | D10: 1.1 External HTTPS-TLS | E10: SharePoint/Evidence/TLS | F10: 2026-01-10 | G10: Security Team | H10: 3 years | I10: Current
A11: EVD-824.1-002 | B11: Certificate Inventory Export | C11: Spreadsheet | D11: 1.1 External HTTPS-TLS | E11: SharePoint/Evidence/Certificates | F11: 2026-01-10 | G11: Security Team | H11: 3 years | I11: Current
A12: EVD-824.1-003 | B12: Let's Encrypt Auto-Renewal Logs | C12: Log File | D12: 1.1 External HTTPS-TLS | E12: S3/evidence/certbot-logs | F12: 2026-01-10 | G12: DevOps | H12: 1 year | I12: Current
A13: EVD-824.1-004 | B13: AWS ACM Certificate Configuration | C13: Screenshot | D13: 1.1 External HTTPS-TLS | E13: SharePoint/Evidence/AWS | F13: 2026-01-10 | G13: Cloud Team | H13: 2 years | I13: Current
A14: EVD-824.1-005 | B14: Internal PKI Certificate Policy | C14: Policy Document | D14: 1.2 Internal HTTPS-TLS | E14: SharePoint/Policies | F14: 2025-06-01 | G14: Security Team | H14: 5 years | I14: Current
A15: EVD-824.1-006 | B15: AD Certificate Services Audit Report | C15: Audit Report | D15: 1.2 Internal HTTPS-TLS | E15: SharePoint/Audits/2025 | F15: 2025-12-15 | G15: Internal Audit | H15: 7 years | I15: Current
A16: EVD-824.1-007 | B16: M365 Admin Center - S/MIME Adoption Report | C16: Dashboard Export | D16: 2.1 Email Encryption | E16: SharePoint/Evidence/M365 | F16: 2026-01-09 | G16: IT Admin | H16: 1 year | I16: Current
A17: EVD-824.1-008 | B17: Google Workspace Security Settings | C17: Screenshot | D17: 2.1 Email Encryption | E17: SharePoint/Evidence/Google | F17: 2026-01-09 | G17: IT Admin | H17: 2 years | I17: Current
A18: EVD-824.1-009 | B18: Postfix TLS Configuration File | C18: Config File | D18: 2.1 Email Encryption | E18: Git/configs/postfix | F18: 2025-11-20 | G18: Email Admin | H18: 2 years | I18: Current
A19: EVD-824.1-010 | B19: Executive S/MIME Certificate Audit | C19: Audit Report | D19: 2.1 Email Encryption | E19: SharePoint/Audits/Certs | F19: 2025-12-01 | G19: Security Team | H19: 3 years | I19: Current
A20: EVD-824.1-011 | B20: DocuSign Audit Trail Report | C20: Audit Log | D20: 2.2 Digital Signatures | E20: DocuSign/Audit-Trails | F20: 2026-01-08 | G20: Legal Team | H20: 7 years | I20: Current
A21: EVD-824.1-012 | B21: Adobe Sign Security Configuration | C21: Screenshot | D21: 2.2 Digital Signatures | E21: SharePoint/Evidence/Adobe | F21: 2026-01-08 | G21: Legal Team | H21: 3 years | I21: Current
... A49: EVD-824.1-040 | B49: CDN TLS Configuration - CloudFront | C49: Config Screenshot | D49: 7.1 Cloud Transmission | E49: SharePoint/Evidence/CDN | F49: 2026-01-09 | G49: Cloud Team | H49: 2 years | I49: Current
A50: EV-046
A51: EV-047
A52: EV-048
A53: EV-049
A54: EV-050
A55: EV-051
A56: EV-052
A57: EV-053
A58: EV-054
A59: EV-055
A60: EV-056
A61: EV-057
... A104: EV-100

Sheet Approval Sign-Off
A1: ASSESSMENT APPROVAL AND SIGN-OFF
A3: Assessment Summary
A4: Assessment Document | B4: ISMS-IMP-A.8.24.1 - Data Transmission Assessment
A5: Assessment Period | B5: John Smith
A6: Overall Compliance Rate | B6: Senior Security Engineer
A7: Assessment Status | B7: Information Security
B8: john.smith@company.com
B9: 2026-01-13
A10: ASSESSMENT COMPLETED BY
A11: Name:
A12: Role/Title:
A13: Department:
A14: Email: | B14: Sarah Johnson
A15: Date: | B15: 2026-01-15
B16: Reviewed and verified all TLS configurations and certificate validations. Minor gaps identified in legacy systems.
A18: REVIEWED BY (Information Security Officer)
A19: Name:
A20: Date:
A21: Signature: | B21: Michael Chen
B22: 2026-01-16
B23: Security controls are adequate. Priority items: Legacy FTP migration and contractor VPN upgrade.
A24: APPROVED BY (CISO)
A25: Name:
A26: Date:
A27: Approval Decision:
A28: Signature: | B28: Jennifer Williams
B29: 2026-01-18
B30: Approved with conditions
A31: Next Review Date: | B31: Approved pending completion of high-priority remediation items by Q2 2026.
B36: 2026-04-13
B37: Sarah Johnson
B38: Q2 2026 reassessment after remediation of critical gaps
