Workbook

Sheet Instructions & Legend
A1: ISMS-IMP-A.8.16.5 – Monitoring Activities Compliance Dashboard ISO/IEC 27001:2022 - Control A.8.16: Monitoring Activities - Master Compliance Overview
A3: Document Information
A4: Document ID | B4: ISMS-IMP-A.8.16.5
A5: Report Type | B5: Compliance Summary Dashboard
A6: Related Policy | B6: ISMS-POL-A.8.16 (Monitoring Activities)
A7: Version | B7: 1.0
A8: Report Date
A9: Reporting Period
A10: Prepared By
A11: Organization
A12: Review Cycle | B12: Quarterly
A13: Last Updated | B13: =TODAY()
A16: Purpose
A17: This dashboard aggregates compliance data from four assessment workbooks to provide executive oversight of the organization's monitoring activities program per ISO/IEC 27001:2022 Control A.8.16.
A20: Source Assessment Workbooks
A21: ISMS-IMP-A.8.16.1 | B21: Monitoring Infrastructure Assessment | C21: Log sources, SIEM, tools
A22: ISMS-IMP-A.8.16.2 | B22: Baseline & Detection Assessment | C22: Baselines, detection rules
A23: ISMS-IMP-A.8.16.3 | B23: Coverage Assessment | C23: Asset coverage, monitoring scope
A24: ISMS-IMP-A.8.16.4 | B24: Alert Management Assessment | C24: Alerting, response, escalation
A27: How to Use This Dashboard
A28: 1. PREREQUISITE: Run normalization script first:
A29: python3 normalize_assessment_files_a816.py
A31: 2. Place this dashboard in the Dashboard_Sources folder with normalized files
A33: 3. Open dashboard and click 'Update Links' when prompted
A35: 4. Executive Summary will auto-populate with current compliance data
A37: 5. Review compliance metrics and gaps across all assessment areas
A39: 6. Complete manual sections (Gap Remediation, Trend Analysis, Evidence)
A41: 7. Obtain approvals via Evidence & Approvals sheet
A44: LEGEND
A45: Symbol | B45: Status | C45: Meaning | D45: When to Use
A46: ✅ | B46: Compliant | C46: Requirement fully met | D46: All controls implemented and effective
A47: ⚠️ | B47: Partial | C47: Requirement partially met | D47: Some controls in place, gaps remain
A48: ❌ | B48: Non-Compliant | C48: Requirement not met | D48: Controls absent or ineffective
A49: N/A | B49: Not Applicable | C49: Requirement does not apply | D49: Requirement not relevant to environment
A52: Color Coding
A53: Yellow cells | B53: User input required
A54: Gray cells | B54: Auto-calculated (formulas)
A55: Green cells | B55: Compliant status
A56: Yellow cells | B56: Partial/Warning status
A57: Red cells | B57: Non-compliant/Critical status
...

Sheet Executive Summary
A1: MONITORING ACTIVITIES - EXECUTIVE SUMMARY ISO/IEC 27001:2022 Control A.8.16 Compliance Status
A3: Document Information
A4: Dashboard ID | B4: ISMS-IMP-A.8.16.5
A5: Assessment Date
A6: Reporting Period
A7: Next Review
A8: Prepared By
A11: OVERALL MONITORING COMPLIANCE STATUS
A12: Metric | B12: Score | C12: Target | D12: Status
A13: Overall Compliance Rate | B13: =AVERAGE(C17:C20) | C13: ≥95%
A14: Critical Gaps | B14: =COUNTIFS('Compliance Matrix'!I:I,"Critical",'Compliance Matrix'!F:F,"❌ Non-Compliant") | C14: 0
A15: High-Risk Items | B15: =COUNTIFS('Gap Remediation Tracker'!E:E,"High",'Gap Remediation Tracker'!K:K,"<>Resolved") | C15: ≤5
A16: Remediation Progress | B16: ='Gap Remediation Tracker'!L3 | C16: ≥80%
A19: COMPLIANCE BY ASSESSMENT AREA
A20: Assessment | B20: Domain | C20: Compliance % | D20: Status | E20: Trend
A21: IMP-A.8.16.1 | B21: Infrastructure | C21: =[ISMS-IMP-A.8.16.1.xlsx]'Summary Dashboard'!$B$13/($F$13-$E$13)*100 | D21: =IF(C17>=95,"✅ Compliant",IF(C17>=80,"⚠️ Partial","❌ Non-Compliant")) | E21: →
A22: IMP-A.8.16.2 | B22: Baseline & Detection | C22: =[ISMS-IMP-A.8.16.2.xlsx]'Summary Dashboard'!$B$13/($F$13-$E$13)*100 | D22: =IF(C18>=95,"✅ Compliant",IF(C18>=80,"⚠️ Partial","❌ Non-Compliant")) | E22: →
A23: IMP-A.8.16.3 | B23: Coverage | C23: =[ISMS-IMP-A.8.16.3.xlsx]'Summary Dashboard'!$B$13/($F$13-$E$13)*100 | D23: =IF(C19>=95,"✅ Compliant",IF(C19>=80,"⚠️ Partial","❌ Non-Compliant")) | E23: ↑
A24: IMP-A.8.16.4 | B24: Alert Management | C24: =[ISMS-IMP-A.8.16.4.xlsx]'Summary Dashboard'!$B$13/($F$13-$E$13)*100 | D24: =IF(C20>=95,"✅ Compliant",IF(C20>=80,"⚠️ Partial","❌ Non-Compliant")) | E24: ↑
A25: OVERALL | B25: All Domains | C25: =AVERAGE(C17:C20) | D25: =IF(C21>=95,"✅ Compliant",IF(C21>=80,"⚠️ Partial","❌ Non-Compliant")) | E25: →
A28: CRITICAL METRICS SUMMARY
A29: Metric | B29: Current | C29: Target | D29: Status
A30: COVERAGE METRICS
A31: Critical Systems Monitored | C31: 100% | D31: =IF(B28>=100,"✅",IF(B28>=80,"⚠️","❌"))
A32: Overall System Coverage | C32: >80% | D32: =IF(B29>=80,"✅",IF(B29>=60,"⚠️","❌"))
A33: Network Segment Coverage | C33: 100% | D33: =IF(B30>=100,"✅",IF(B30>=80,"⚠️","❌"))
A35: DETECTION METRICS
A36: Baseline Coverage (Critical) | C36: 100% | D36: =IF(B33>=100,"✅",IF(B33>=80,"⚠️","❌"))
A37: Detection Rate | C37: >90% | D37: =IF(B34>=90,"✅",IF(B34>=70,"⚠️","❌"))
A38: False Positive Rate | C38: <25% | D38: =IF(B35<=25,"✅",IF(B35<=40,"⚠️","❌"))
A40: RESPONSE METRICS
A41: MTTD (Critical Alerts) | C41: <5 min | D41: =IF(B38<=5,"✅",IF(B38<=15,"⚠️","❌"))
A42: MTTR (Critical Incidents) | C42: <8 hrs | D42: =IF(B39<=8,"✅",IF(B39<=24,"⚠️","❌"))
A43: SLA Compliance | C43: >95% | D43: =IF(B40>=95,"✅",IF(B40>=85,"⚠️","❌"))
A45: OPERATIONAL METRICS
A46: Log Sources Integrated | C46: Target | D46: =IF(ISNUMBER(B43),IF(B43>=ISNUMBER(C43),"✅","⚠️"),"")
A47: Active Detection Rules | C47: Target | D47: =IF(ISNUMBER(B44),IF(B44>=ISNUMBER(C44),"✅","⚠️"),"")
A48: SOC Analyst Coverage | C48: 24/7 | D48: =IF(B45="24/7","✅","❌")
A51: TOP 5 STRENGTHS
A52: Rank | B52: Strength | C52: Evidence
...

Sheet Compliance Matrix
A1: DETAILED COMPLIANCE MATRIX
A3: Policy Reference | B3: Requirement | C3: Control Type | D3: Assessment Sheet | E3: Evidence Location | F3: Implementation Status | G3: Compliance Status | H3: Gap Description | I3: Risk Level | J3: Remediation Owner | K3: Target Date | L3: Notes
A4: REQ-001
A5: REQ-002
A6: REQ-003
A7: REQ-004
A8: REQ-005
A9: REQ-006
A10: REQ-007
A11: REQ-008
A12: REQ-009
A13: REQ-010
A14: REQ-011
A15: REQ-012
... A108: REQ-105

Sheet KPIs
A1: KEY PERFORMANCE INDICATORS (KPIs)
A3: COVERAGE KPIs
A4: KPI | B4: Current | C4: Target | D4: Baseline | E4: Trend (3mo) | F4: Status
A5: Critical Systems Monitored %
A6: High Priority Systems %
A7: Overall Asset Coverage %
A8: Network Segments Covered %
A9: Log Sources Integrated (Count)
A10: Log Volume (GB/day)
A11: Log Collection Reliability %
A14: DETECTION KPIs
A15: KPI | B15: Current | C15: Target | D15: Baseline | E15: Trend (3mo) | F15: Status
A16: Tier 1 Systems with Baselines %
A17: Tier 2 Systems with Baselines %
A18: Baseline Staleness (Avg Days)
A19: Active Detection Rules (Count)
A20: MITRE ATT&CK Coverage %
A21: Detection Rate (Testing) %
A22: False Positive Rate %
A23: Rules Requiring Tuning (Count)
A26: RESPONSE KPIs
A27: KPI | B27: Current | C27: Target | D27: Baseline | E27: Trend (3mo) | F27: Status
A28: Total Alerts (30d)
A29: True Positive Rate %
A30: MTTA - Critical (minutes)
A31: MTTT - Critical (minutes)
A32: MTTI - Critical (hours)
A33: MTTR - Critical (hours)
A34: SLA Compliance Rate %
A35: Escalation Rate %

Sheet Gap Remediation Tracker
A1: GAP ANALYSIS & REMEDIATION TRACKER
A3: Gap ID | B3: Source Assessment | C3: Gap Category | D3: Description | E3: Risk | F3: Impact | G3: Remediation Plan | H3: Owner | I3: Target Date | J3: Budget | K3: Status | L3: % Complete | M3: Last Updated
A4: GAP-001
A5: GAP-002
A6: GAP-003
A7: GAP-004
A8: GAP-005
A9: GAP-006
A10: GAP-007
A11: GAP-008
A12: GAP-009
A13: GAP-010
A14: GAP-011
A15: GAP-012
... A63: GAP-060

Sheet Trend Analysis
A1: TREND ANALYSIS
A3: MONTHLY COMPLIANCE TREND (12 MONTHS)
A4: Month | B4: Overall % | C4: Infrastructure % | D4: Baseline % | E4: Coverage % | F4: Alert Mgmt %
A5: Jan 2025
A6: Feb 2025
A7: Mar 2025
A8: Apr 2025
A9: May 2025
A10: Jun 2025
A11: Jul 2025
A12: Aug 2025
A13: Sep 2025
A14: Oct 2025
A15: Nov 2025
A16: Dec 2025

Sheet Evidence & Approvals
A1: EVIDENCE REGISTER & APPROVALS
A3: Evidence ID | B3: Evidence Type | C3: Description | D3: Related Requirement | E3: Source Assessment | F3: Date Collected | G3: Collected By | H3: Location/Link | I3: Verification Status | J3: Verified By | K3: Verification Date | L3: Notes
A4: EVD-001
A5: EVD-002
A6: EVD-003
A7: EVD-004
A8: EVD-005
A9: EVD-006
A10: EVD-007
A11: EVD-008
A12: EVD-009
A13: EVD-010
A14: EVD-011
A15: EVD-012
... A127: Date:
