Workbook

Sheet Instructions
A1: ISMS BC/DR Assessment - BC/DR Testing Results Tracker
A3: Document ID: | B3: ISMS-IMP-A.5.30.S4
A4: Assessment: | B4: BC/DR Testing Results
A5: Version: | B5: 1.0
A6: Generated: | B6: 08.02.2026 11:48
A8: PURPOSE
A9: This workbook tracks all BC/DR testing activities, results, issues discovered, and testing compliance.
A10: Use this to demonstrate that backup, failover, and DR capabilities are regularly TESTED, not just assumed.
A12: KEY PRINCIPLE: "Test or it doesn't work" - Untested recovery capability = no recovery capability.
A14: TESTING WORKFLOW
A15: 1. Plan tests in Test_Schedule (define annual test plan)
A16: 2. Execute tests according to schedule
A17: 3. Log results in Test_Results_Log (document actual test execution)
A18: 4. Document issues in Issue_Remediation (problems discovered during testing)
A19: 5. Track remediation of issues to closure
A20: 6. Review Testing_Compliance (annual compliance assessment)
A21: 7. Collect evidence in Evidence_Register (MINIMUM 5 evidence items for audit)
... A26: TEST TYPES EXPLAINED
A27: Backup Restore: | B27: Test restoring data from backup - verify RPO capability (A.5.30)
A28: Failover Test: | B28: Test switching to redundant system - verify RTO capability (A.8.14)
A29: Full DR Scenario: | B29: End-to-end disaster recovery test - complete system recovery (A.5.30)
A30: Tabletop Exercise: | B30: Discussion-based walkthrough of DR procedures (no actual execution)
A31: Component Test: | B31: Test individual component (e.g., database restore only)
A32: Integration Test: | B32: Test multiple components together (e.g., app + database recovery)
A34: WORKSHEET DESCRIPTIONS
A35: Instructions: | B35: This sheet - comprehensive usage guide
A36: Summary: | B36: Executive dashboard with testing compliance metrics
A37: Test_Schedule: | B37: Annual test plan - what tests to perform when (110 rows)
A38: Test_Results_Log: | B38: All test executions - actual test results (110 rows)
A39: Issue_Remediation: | B39: Issues discovered during testing - track to closure (110 rows)
A40: Testing_Compliance: | B40: Annual compliance assessment - are we testing enough? (110 rows)
A41: Evidence_Register: | B41: 100 evidence slots for audit traceability (minimum 5 required)
A42: Approval_Sign_Off: | B42: 3-level approval workflow (Assessor → ISO → CISO)
A44: TESTING FREQUENCY GUIDELINES
A45: TIER 1 - CRITICAL SYSTEMS:
A46: • Backup Restore: Quarterly (every 3 months)
A47: • Failover Test: Quarterly (every 3 months)
A48: • Full DR Scenario: Annual (at least once per year)
A50: TIER 2 - IMPORTANT SYSTEMS:
A51: • Backup Restore: Semi-Annual (every 6 months)
...

Sheet Summary
A1: BC/DR TESTING COMPLIANCE DASHBOARD
A2: Assessment Date: 08.02.2026 | Assessment ID: ISMS-IMP-A.5.30.S4
A4: TESTING ACTIVITY SUMMARY
A5: Total Tests Scheduled: | B5: =COUNTA(Test_Schedule!A5:A114)
A6: Tests Completed (✅ Success): | B6: =COUNTIF(Test_Results_Log!F5:F114,"{CHECK}*")
A7: Tests Partial Success (⚠️): | B7: =COUNTIF(Test_Results_Log!F5:F114,"{WARNING}*")
A8: Tests Failed (❌): | B8: =COUNTIF(Test_Results_Log!F5:F114,"{XMARK}*")
A9: Tests In Progress (⏳): | B9: =COUNTIF(Test_Results_Log!F5:F114,"⏳*")
A10: Tests Not Started (➖): | B10: =COUNTIF(Test_Results_Log!F5:F114,"➖*")
A12: Test Success Rate: | B12: =IF(B5>0,(B6+B7*0.5)/B5,0)
A14: TESTING COMPLIANCE BY CRITICALITY
A15: Tier 1 - Critical Systems: | B15: =COUNTIF(Testing_Compliance!C5:C114,"Tier 1*")
A16: Tier 1 - Compliant: | B16: =SUMPRODUCT((Testing_Compliance!C5:C114="Tier 1 - Critical")*(Testing_Compliance!G5:G114="{CHECK} Compliant"))
A17: Tier 1 - Compliance Rate: | B17: =IF(B15>0,B16/B15,0)
A19: Tier 2 - Important Systems: | B19: =COUNTIF(Testing_Compliance!C5:C114,"Tier 2*")
A20: Tier 2 - Compliant: | B20: =SUMPRODUCT((Testing_Compliance!C5:C114="Tier 2 - Important")*(Testing_Compliance!G5:G114="{CHECK} Compliant"))
A21: Tier 2 - Compliance Rate: | B21: =IF(B19>0,B20/B19,0)
A23: ISSUE SUMMARY
A24: Total Issues Identified: | B24: =COUNTA(Issue_Remediation!A5:A114)
A25: 🔴 Critical Issues: | B25: =COUNTIF(Issue_Remediation!E5:E114,"🔴*")
A26: 🟡 High Severity Issues: | B26: =COUNTIF(Issue_Remediation!E5:E114,"🟡*")
A27: 🟢 Medium Severity Issues: | B27: =COUNTIF(Issue_Remediation!E5:E114,"🟢*")
A28: ⚪ Low Severity Issues: | B28: =COUNTIF(Issue_Remediation!E5:E114,"⚪*")
A30: Open Issues (🔴): | B30: =COUNTIF(Issue_Remediation!F5:F114,"🔴*")
A31: In Progress (⏳): | B31: =COUNTIF(Issue_Remediation!F5:F114,"⏳*")
A32: Closed Issues (✅): | B32: =COUNTIF(Issue_Remediation!F5:F114,"{CHECK}*")
A34: EVIDENCE & APPROVAL STATUS
A35: Evidence Items Collected: | B35: =COUNTA(Evidence_Register!A5:A104)
A36: Verified Evidence: | B36: =COUNTIF(Evidence_Register!H5:H104,"{CHECK}*")
A37: Minimum Evidence Required: | B37: 5
A38: Evidence Compliance: | B38: =IF(B39>=B41,"{CHECK} Sufficient","{XMARK} Insufficient")
A40: Assessment Status: | B40: =Approval_Sign_Off!B14
A41: Level 1 - Assessor Completed: | B41: =IF(Approval_Sign_Off!B26<>"","{CHECK} Complete","⏳ Pending")
A42: Level 2 - ISO Review: | B42: =IF(Approval_Sign_Off!B37<>"","{CHECK} Complete","⏳ Pending")
A43: Level 3 - CISO Approval: | B43: =IF(Approval_Sign_Off!B49<>"","{CHECK} Complete","⏳ Pending")
A45: PRIORITY ACTIONS
A46: 1. Address all 🔴 Critical issues discovered during testing
A47: 2. Complete all overdue tests (⚠️ Overdue in Testing_Compliance)
A48: 3. Schedule quarterly tests for Tier 1 systems
A49: 4. Remediate test failures (❌ Failed tests in Test_Results_Log)
...

Sheet Test_Schedule
A1: BC/DR TEST SCHEDULE (Annual Plan)
A2: Define annual test plan - what tests to perform when (schedule all required tests)
A4: Test ID | B4: System Name | C4: Test Type | D4: Criticality | E4: Required Frequency | F4: Scheduled Date | G4: Test Owner | H4: Notes / Prerequisites
A5: TEST-001 | C5: E-Commerce Website | D5: Backup Restore | E5: Tier 1 - Critical | F5: Quarterly | G5: 23.02.2026 | H5: Infrastructure Team | I5: Restore full website DB, verify data integrity, test 4hr restore time
A6: TEST-002 | C6: E-Commerce Website | D6: Failover Test | E6: Tier 1 - Critical | F6: Quarterly | G6: 25.03.2026 | H6: Infrastructure Team | I6: Test Active-Passive cluster failover, verify <30min RTO
A7: TEST-003 | C7: Payment Gateway | D7: Failover Test | E7: Tier 1 - Critical | F7: Quarterly | G7: 10.03.2026 | H7: Payments Team | I7: Test Active-Active failover, critical system, must coordinate with processor
A8: TEST-004 | C8: Email System | D8: Backup Restore | E8: Tier 1 - Critical | F8: Quarterly | G8: 09.04.2026 | H8: IT Operations | I8: Restore mailbox data, test 12hr restore time, verify user access
A9: TEST-005 | C9: CRM System | D9: Backup Restore | E9: Tier 1 - Critical | F9: Quarterly | G9: 24.04.2026 | H9: App Support Team | I9: Restore CRM DB, verify integrations work, test 8hr restore time
A10: TEST-006 | C10: ERP System | D10: Backup Restore | E10: Tier 2 - Important | F10: Semi-Annual | G10: 09.05.2026 | H10: ERP Team | I10: Restore ERP DB, complex dependencies, test 8hr restore, schedule during low activity
A11: TEST-007 | C11: HR Information System | D11: Backup Restore | E11: Tier 2 - Important | F11: Semi-Annual | G11: 08.06.2026 | H11: HR IT Team | I11: Restore HR DB, sensitive data, coordinate with CISO, test 20hr restore
A12: TEST-008 | C12: All Critical Systems | D12: Full DR Scenario | E12: Tier 1 - Critical | F12: Annual | G12: 07.08.2026 | H12: BC/DR Coordinator | I12: Full DR exercise - simulate datacenter loss, recover all Tier 1 systems
A13: TEST-009 | C13: File Server | D13: Backup Restore | E13: Tier 3 - Standard | F13: Annual | G13: 06.09.2026 | H13: IT Operations | I13: Restore file share, test 24hr restore time, low priority
A14: TEST-010 | C14: BC/DR Team | D14: Tabletop Exercise | E14: Tier 1 - Critical | F14: Annual | G14: 10.03.2026 | H14: BC/DR Coordinator | I14: Walkthrough DR procedures with stakeholders, no actual execution
A15: TEST-011
A16: TEST-012
A17: TEST-013
A18: TEST-014
A19: TEST-015
A20: TEST-016
A21: TEST-017
A22: TEST-018
A23: TEST-019
A24: TEST-020
A25: TEST-021
A26: TEST-022
... A117: TEST SCHEDULE SUMMARY
A118: Total Tests Scheduled: | B118: =COUNTA(B5:B114)
A119: Backup Restore Tests: | B119: =COUNTIF(C5:C114,"Backup*")
A120: Failover Tests: | B120: =COUNTIF(C5:C114,"Failover*")
A121: Full DR Scenarios: | B121: =COUNTIF(C5:C114,"Full DR*")
A122: Tier 1 System Tests: | B122: =COUNTIF(D5:D114,"Tier 1*")
A123: Quarterly Tests: | B123: =COUNTIF(E5:E114,"Quarterly")

Sheet Test_Results_Log
A1: BC/DR TEST RESULTS LOG (Execution History)
A2: Document all test executions - actual test results (log every test performed)
A4: Result ID | B4: Test ID (Schedule) | C4: System Name | D4: Test Type | E4: Test Date | F4: Result | G4: Actual Duration (hrs) | H4: Tested By | I4: Issues Found | J4: Detailed Notes
A5: RES-001 | C5: TEST-001 | D5: E-Commerce Website | E5: Backup Restore | F5: 03.02.2026 | G5: ✅ Success | H5: 3.8 | I5: Infrastructure Team | J5: None | K5: Full restore successful, verified data integrity, 3.8hr restore time
A6: RES-002 | C6: TEST-002 | D6: E-Commerce Website | E6: Failover Test | F6: 24.01.2026 | G6: ⚠ Partial Success | H6: 0.6 | I6: Infrastructure Team | J6: ISS-002, ISS-003 | K6: Failover worked but took 36min (exceeds 30min RTO), found monitoring gaps
A7: RES-003 | C7: TEST-003 | D7: Payment Gateway | E7: Failover Test | F7: 19.01.2026 | G7: ✅ Success | H7: 0.08 | I7: Payments Team | J7: None | K7: Failover successful, ~5min, no transaction loss, excellent result
A8: RES-004 | C8: TEST-004 | D8: Email System | E8: Backup Restore | F8: 09.01.2026 | G8: ❌ Failure | H8: 16 | I8: IT Operations | J8: ISS-001 | K8: Restore failed, backup corrupted, root cause: backup job misconfiguration
A9: RES-005 | C9: TEST-005 | D9: CRM System | E9: Backup Restore | F9: 25.12.2025 | G9: ⚠ Partial Success | H9: 9.5 | I9: App Support Team | J9: ISS-004 | K9: Restore successful but took 9.5hr (exceeds 8hr RTO), integration issues post-restore
A10: RES-006 | C10: TEST-006 | D10: ERP System | E10: Backup Restore | F10: 10.12.2025 | G10: ✅ Success | H10: 7.2 | I10: ERP Team | J10: None | K10: Restore successful, complex dependencies resolved, 7.2hr within 8hr target
A11: RES-007 | C11: TEST-010 | D11: BC/DR Team | E11: Tabletop Exercise | F11: 29.01.2026 | G11: ✅ Success | H11: 2 | I11: BC/DR Coordinator | J11: ISS-005 | K11: Tabletop successful, identified gaps in communication procedures
A12: RES-008 | C12: TEST-008 | D12: All Critical Systems | E12: Full DR Scenario | F12: 10.11.2025 | G12: ⚠ Partial Success | H12: 12 | I12: BC/DR Coordinator | J12: ISS-006, ISS-007, ISS-008 | K12: DR scenario partially successful, 3/5 Tier 1 systems recovered within RTO
A13: RES-009 | C13: TEST-009 | D13: File Server | E13: Backup Restore | F13: 11.10.2025 | G13: ✅ Success | H13: 22 | I13: IT Operations | J13: None | K13: Restore successful, 22hr within 24hr target, Tier 3 system
A14: RES-010 | C14: TEST-007 | D14: HR Information System | E14: Backup Restore | F14: 26.09.2025 | G14: ✅ Success | H14: 18.5 | I14: HR IT Team | J14: None | K14: Restore successful, 18.5hr within 20hr target, sensitive data verified
A15: RES-011
A16: RES-012
A17: RES-013
A18: RES-014
A19: RES-015
A20: RES-016
A21: RES-017
A22: RES-018
A23: RES-019
A24: RES-020
A25: RES-021
A26: RES-022
... A117: TEST RESULTS SUMMARY
A118: Total Tests Executed: | B118: =COUNTA(C5:C114)
A119: ✅ Successful Tests: | B119: =COUNTIF(F5:F114,"✅*")
A120: ⚠ Partial Success: | B120: =COUNTIF(F5:F114,"⚠*")
A121: ❌ Failed Tests: | B121: =COUNTIF(F5:F114,"❌*")
A122: Success Rate: | B122: =IF(B118>0,(B119+B120*0.5)/B118,0)
A123: Average Test Duration (hrs): | B123: =IFERROR(AVERAGE(G5:G114),0)

Sheet Issue_Remediation
A1: ISSUE REMEDIATION TRACKER
A2: Track issues discovered during testing to closure
A4: Issue ID | B4: Related Test (Result ID) | C4: Issue Description | D4: Root Cause | E4: Severity | F4: Status | G4: Remediation Plan | H4: Target Resolution Date
A5: ISS-001 | C5: RES-004 | D5: Email system backup corrupted - restore failed | E5: Backup job misconfigured, missing transaction log backups | F5: 🔴 Critical | G5: ✅ Closed | H5: Reconfigured backup job, added transaction log backups, verified with successful test | I5: 19.01.2026
A6: ISS-002 | C6: RES-002 | D6: E-Commerce failover took 36min (exceeds 30min RTO) | E6: Manual DNS update required, not automated | F6: 🟡 High | G6: ✅ Closed | H6: Automated DNS failover, reduced to <30min, retested successfully | I6: 29.01.2026
A7: ISS-003 | C7: RES-002 | D7: Monitoring did not alert during failover | E7: Monitoring not configured for cluster failover events | F7: 🟢 Medium | G7: ✅ Closed | H7: Configured monitoring for failover events, tested alerts | I7: 31.01.2026
A8: ISS-004 | C8: RES-005 | D8: CRM restore took 9.5hr (exceeds 8hr RTO) | E8: Integration dependencies not documented in restore procedure | F8: 🟡 High | G8: ⏳ In Progress | H8: Update restore runbook with integration steps, optimize restore process | I8: 10.03.2026
A9: ISS-005 | C9: RES-007 | D9: Communication procedures gap identified in tabletop | E9: No clear escalation path defined for DR coordinator | F9: 🟡 High | G9: ✅ Closed | H9: Documented escalation procedures, updated BC/DR plan | I9: 03.02.2026
A10: ISS-006 | C10: RES-008 | D10: Payment Gateway not recovered during DR scenario | E10: Active-Active failover requires manual processor notification | F10: 🔴 Critical | G10: ⏳ In Progress | H10: Automate processor notification, create runbook, retest in next DR scenario | I10: 09.04.2026
A11: ISS-007 | C11: RES-008 | D11: CRM not recovered within RTO during DR scenario | E11: Complex dependencies, restore order not documented | F11: 🟡 High | G11: ⏳ In Progress | H11: Document system dependency tree, define restore order, update runbook | I11: 25.03.2026
A12: ISS-008 | C12: RES-008 | D12: Network connectivity issues during DR scenario | E12: DR site network not pre-configured, manual setup required | F12: 🟡 High | G12: 🔴 Open | H12: Pre-configure DR site network, automate VPN setup, document procedures | I12: 09.05.2026
A13: ISS-009 | C13: [General] | D13: Test documentation inconsistent across teams | E13: No standard template for test documentation | F13: 🟢 Medium | G13: ✅ Closed | H13: Created standard test report template, distributed to all teams | I13: 24.01.2026
A14: ISS-010 | C14: [General] | D14: Lack of training for restore procedures | E14: Staff turnover, new team members not trained on DR procedures | F14: 🟡 High | G14: ⏳ In Progress | H14: Schedule quarterly DR training, create training materials, track completion | I14: 10.03.2026
A15: ISS-011
A16: ISS-012
A17: ISS-013
A18: ISS-014
A19: ISS-015
A20: ISS-016
A21: ISS-017
A22: ISS-018
A23: ISS-019
A24: ISS-020
A25: ISS-021
A26: ISS-022
... A117: ISSUE REMEDIATION SUMMARY
A118: Total Issues: | B118: =COUNTA(C5:C114)
A119: 🔴 Critical Issues: | B119: =COUNTIF(E5:E114,"🔴*")
A120: 🟡 High Severity: | B120: =COUNTIF(E5:E114,"🟡*")
A121: 🟢 Medium Severity: | B121: =COUNTIF(E5:E114,"🟢*")
A123: 🔴 Open Issues: | B123: =COUNTIF(F5:F114,"🔴*")
A124: ⏳ In Progress: | B124: =COUNTIF(F5:F114,"⏳*")
A125: ✅ Closed Issues: | B125: =COUNTIF(F5:F114,"✅*")
A126: Issue Closure Rate: | B126: =IF(B118>0,B125/B118,0)

Sheet Testing_Compliance
A1: TESTING COMPLIANCE ASSESSMENT (Annual Review)
A2: Annual compliance assessment - are systems being tested according to requirements?
A4: System Name | B4: Test Type | C4: Criticality | D4: Required Frequency | E4: Last Test Date | F4: Days Since Last Test | G4: Compliance Status | H4: Next Test Due
A5: E-Commerce Website | B5: Backup Restore | C5: Tier 1 - Critical | D5: Quarterly | E5: 30.11.2025 | F5: =IF(E5="","",TODAY()-E5) | G5: =IF(A5="","",IF(E5="","❓ Unknown",IF(D5="Quarterly",IF(F5<=90,"✅ Compliant",IF(F5<=105,"⚠ Overdue","❌ Non-Compliant")),IF(D5="Semi-Annual",IF(F5<=180,"✅ Compliant",IF(F5<=200,"⚠ Overdue","❌ Non-Compliant")),IF(D5="Annual",IF(F5<=365,"✅ Compliant",IF(F5<=400,"⚠ Overdue","❌ Non-Compliant")),"✅ Compliant"))))) | H5: =IF(E5="","",IF(D5="Quarterly",E5+90,IF(D5="Semi-Annual",E5+180,IF(D5="Annual",E5+365,E5))))
A6: E-Commerce Website | B6: Failover Test | C6: Tier 1 - Critical | D6: Quarterly | E6: 05.11.2025 | F6: =IF(E6="","",TODAY()-E6) | G6: =IF(A6="","",IF(E6="","❓ Unknown",IF(D6="Quarterly",IF(F6<=90,"✅ Compliant",IF(F6<=105,"⚠ Overdue","❌ Non-Compliant")),IF(D6="Semi-Annual",IF(F6<=180,"✅ Compliant",IF(F6<=200,"⚠ Overdue","❌ Non-Compliant")),IF(D6="Annual",IF(F6<=365,"✅ Compliant",IF(F6<=400,"⚠ Overdue","❌ Non-Compliant")),"✅ Compliant"))))) | H6: =IF(E6="","",IF(D6="Quarterly",E6+90,IF(D6="Semi-Annual",E6+180,IF(D6="Annual",E6+365,E6))))
A7: Payment Gateway | B7: Failover Test | C7: Tier 1 - Critical | D7: Quarterly | E7: 10.12.2025 | F7: =IF(E7="","",TODAY()-E7) | G7: =IF(A7="","",IF(E7="","❓ Unknown",IF(D7="Quarterly",IF(F7<=90,"✅ Compliant",IF(F7<=105,"⚠ Overdue","❌ Non-Compliant")),IF(D7="Semi-Annual",IF(F7<=180,"✅ Compliant",IF(F7<=200,"⚠ Overdue","❌ Non-Compliant")),IF(D7="Annual",IF(F7<=365,"✅ Compliant",IF(F7<=400,"⚠ Overdue","❌ Non-Compliant")),"✅ Compliant"))))) | H7: =IF(E7="","",IF(D7="Quarterly",E7+90,IF(D7="Semi-Annual",E7+180,IF(D7="Annual",E7+365,E7))))
A8: Email System | B8: Backup Restore | C8: Tier 1 - Critical | D8: Quarterly | E8: 11.10.2025 | F8: =IF(E8="","",TODAY()-E8) | G8: =IF(A8="","",IF(E8="","❓ Unknown",IF(D8="Quarterly",IF(F8<=90,"✅ Compliant",IF(F8<=105,"⚠ Overdue","❌ Non-Compliant")),IF(D8="Semi-Annual",IF(F8<=180,"✅ Compliant",IF(F8<=200,"⚠ Overdue","❌ Non-Compliant")),IF(D8="Annual",IF(F8<=365,"✅ Compliant",IF(F8<=400,"⚠ Overdue","❌ Non-Compliant")),"✅ Compliant"))))) | H8: =IF(E8="","",IF(D8="Quarterly",E8+90,IF(D8="Semi-Annual",E8+180,IF(D8="Annual",E8+365,E8))))
A9: CRM System | B9: Backup Restore | C9: Tier 1 - Critical | D9: Quarterly | E9: 20.11.2025 | F9: =IF(E9="","",TODAY()-E9) | G9: =IF(A9="","",IF(E9="","❓ Unknown",IF(D9="Quarterly",IF(F9<=90,"✅ Compliant",IF(F9<=105,"⚠ Overdue","❌ Non-Compliant")),IF(D9="Semi-Annual",IF(F9<=180,"✅ Compliant",IF(F9<=200,"⚠ Overdue","❌ Non-Compliant")),IF(D9="Annual",IF(F9<=365,"✅ Compliant",IF(F9<=400,"⚠ Overdue","❌ Non-Compliant")),"✅ Compliant"))))) | H9: =IF(E9="","",IF(D9="Quarterly",E9+90,IF(D9="Semi-Annual",E9+180,IF(D9="Annual",E9+365,E9))))
A10: ERP System | B10: Backup Restore | C10: Tier 2 - Important | D10: Semi-Annual | E10: 01.09.2025 | F10: =IF(E10="","",TODAY()-E10) | G10: =IF(A10="","",IF(E10="","❓ Unknown",IF(D10="Quarterly",IF(F10<=90,"✅ Compliant",IF(F10<=105,"⚠ Overdue","❌ Non-Compliant")),IF(D10="Semi-Annual",IF(F10<=180,"✅ Compliant",IF(F10<=200,"⚠ Overdue","❌ Non-Compliant")),IF(D10="Annual",IF(F10<=365,"✅ Compliant",IF(F10<=400,"⚠ Overdue","❌ Non-Compliant")),"✅ Compliant"))))) | H10: =IF(E10="","",IF(D10="Quarterly",E10+90,IF(D10="Semi-Annual",E10+180,IF(D10="Annual",E10+365,E10))))
A11: HR Information System | B11: Backup Restore | C11: Tier 2 - Important | D11: Semi-Annual | E11: 02.08.2025 | F11: =IF(E11="","",TODAY()-E11) | G11: =IF(A11="","",IF(E11="","❓ Unknown",IF(D11="Quarterly",IF(F11<=90,"✅ Compliant",IF(F11<=105,"⚠ Overdue","❌ Non-Compliant")),IF(D11="Semi-Annual",IF(F11<=180,"✅ Compliant",IF(F11<=200,"⚠ Overdue","❌ Non-Compliant")),IF(D11="Annual",IF(F11<=365,"✅ Compliant",IF(F11<=400,"⚠ Overdue","❌ Non-Compliant")),"✅ Compliant"))))) | H11: =IF(E11="","",IF(D11="Quarterly",E11+90,IF(D11="Semi-Annual",E11+180,IF(D11="Annual",E11+365,E11))))
A12: File Server | B12: Backup Restore | C12: Tier 3 - Standard | D12: Annual | E12: 14.04.2025 | F12: =IF(E12="","",TODAY()-E12) | G12: =IF(A12="","",IF(E12="","❓ Unknown",IF(D12="Quarterly",IF(F12<=90,"✅ Compliant",IF(F12<=105,"⚠ Overdue","❌ Non-Compliant")),IF(D12="Semi-Annual",IF(F12<=180,"✅ Compliant",IF(F12<=200,"⚠ Overdue","❌ Non-Compliant")),IF(D12="Annual",IF(F12<=365,"✅ Compliant",IF(F12<=400,"⚠ Overdue","❌ Non-Compliant")),"✅ Compliant"))))) | H12: =IF(E12="","",IF(D12="Quarterly",E12+90,IF(D12="Semi-Annual",E12+180,IF(D12="Annual",E12+365,E12))))
A13: Document Repository | B13: Backup Restore | C13: Tier 3 - Standard | D13: Annual | E13: 24.01.2025 | F13: =IF(E13="","",TODAY()-E13) | G13: =IF(A13="","",IF(E13="","❓ Unknown",IF(D13="Quarterly",IF(F13<=90,"✅ Compliant",IF(F13<=105,"⚠ Overdue","❌ Non-Compliant")),IF(D13="Semi-Annual",IF(F13<=180,"✅ Compliant",IF(F13<=200,"⚠ Overdue","❌ Non-Compliant")),IF(D13="Annual",IF(F13<=365,"✅ Compliant",IF(F13<=400,"⚠ Overdue","❌ Non-Compliant")),"✅ Compliant"))))) | H13: =IF(E13="","",IF(D13="Quarterly",E13+90,IF(D13="Semi-Annual",E13+180,IF(D13="Annual",E13+365,E13))))
A14: Test Database | B14: Backup Restore | C14: Tier 4 - Low | D14: Ad-Hoc | F14: =IF(E14="","",TODAY()-E14) | G14: =IF(A14="","",IF(E14="","❓ Unknown",IF(D14="Quarterly",IF(F14<=90,"✅ Compliant",IF(F14<=105,"⚠ Overdue","❌ Non-Compliant")),IF(D14="Semi-Annual",IF(F14<=180,"✅ Compliant",IF(F14<=200,"⚠ Overdue","❌ Non-Compliant")),IF(D14="Annual",IF(F14<=365,"✅ Compliant",IF(F14<=400,"⚠ Overdue","❌ Non-Compliant")),"✅ Compliant"))))) | H14: =IF(E14="","",IF(D14="Quarterly",E14+90,IF(D14="Semi-Annual",E14+180,IF(D14="Annual",E14+365,E14))))
F15: =IF(E15="","",TODAY()-E15) | G15: =IF(A15="","",IF(E15="","❓ Unknown",IF(D15="Quarterly",IF(F15<=90,"✅ Compliant",IF(F15<=105,"⚠ Overdue","❌ Non-Compliant")),IF(D15="Semi-Annual",IF(F15<=180,"✅ Compliant",IF(F15<=200,"⚠ Overdue","❌ Non-Compliant")),IF(D15="Annual",IF(F15<=365,"✅ Compliant",IF(F15<=400,"⚠ Overdue","❌ Non-Compliant")),"✅ Compliant"))))) | H15: =IF(E15="","",IF(D15="Quarterly",E15+90,IF(D15="Semi-Annual",E15+180,IF(D15="Annual",E15+365,E15))))
F16: =IF(E16="","",TODAY()-E16) | G16: =IF(A16="","",IF(E16="","❓ Unknown",IF(D16="Quarterly",IF(F16<=90,"✅ Compliant",IF(F16<=105,"⚠ Overdue","❌ Non-Compliant")),IF(D16="Semi-Annual",IF(F16<=180,"✅ Compliant",IF(F16<=200,"⚠ Overdue","❌ Non-Compliant")),IF(D16="Annual",IF(F16<=365,"✅ Compliant",IF(F16<=400,"⚠ Overdue","❌ Non-Compliant")),"✅ Compliant"))))) | H16: =IF(E16="","",IF(D16="Quarterly",E16+90,IF(D16="Semi-Annual",E16+180,IF(D16="Annual",E16+365,E16))))
F17: =IF(E17="","",TODAY()-E17) | G17: =IF(A17="","",IF(E17="","❓ Unknown",IF(D17="Quarterly",IF(F17<=90,"✅ Compliant",IF(F17<=105,"⚠ Overdue","❌ Non-Compliant")),IF(D17="Semi-Annual",IF(F17<=180,"✅ Compliant",IF(F17<=200,"⚠ Overdue","❌ Non-Compliant")),IF(D17="Annual",IF(F17<=365,"✅ Compliant",IF(F17<=400,"⚠ Overdue","❌ Non-Compliant")),"✅ Compliant"))))) | H17: =IF(E17="","",IF(D17="Quarterly",E17+90,IF(D17="Semi-Annual",E17+180,IF(D17="Annual",E17+365,E17))))
F18: =IF(E18="","",TODAY()-E18) | G18: =IF(A18="","",IF(E18="","❓ Unknown",IF(D18="Quarterly",IF(F18<=90,"✅ Compliant",IF(F18<=105,"⚠ Overdue","❌ Non-Compliant")),IF(D18="Semi-Annual",IF(F18<=180,"✅ Compliant",IF(F18<=200,"⚠ Overdue","❌ Non-Compliant")),IF(D18="Annual",IF(F18<=365,"✅ Compliant",IF(F18<=400,"⚠ Overdue","❌ Non-Compliant")),"✅ Compliant"))))) | H18: =IF(E18="","",IF(D18="Quarterly",E18+90,IF(D18="Semi-Annual",E18+180,IF(D18="Annual",E18+365,E18))))
F19: =IF(E19="","",TODAY()-E19) | G19: =IF(A19="","",IF(E19="","❓ Unknown",IF(D19="Quarterly",IF(F19<=90,"✅ Compliant",IF(F19<=105,"⚠ Overdue","❌ Non-Compliant")),IF(D19="Semi-Annual",IF(F19<=180,"✅ Compliant",IF(F19<=200,"⚠ Overdue","❌ Non-Compliant")),IF(D19="Annual",IF(F19<=365,"✅ Compliant",IF(F19<=400,"⚠ Overdue","❌ Non-Compliant")),"✅ Compliant"))))) | H19: =IF(E19="","",IF(D19="Quarterly",E19+90,IF(D19="Semi-Annual",E19+180,IF(D19="Annual",E19+365,E19))))
F20: =IF(E20="","",TODAY()-E20) | G20: =IF(A20="","",IF(E20="","❓ Unknown",IF(D20="Quarterly",IF(F20<=90,"✅ Compliant",IF(F20<=105,"⚠ Overdue","❌ Non-Compliant")),IF(D20="Semi-Annual",IF(F20<=180,"✅ Compliant",IF(F20<=200,"⚠ Overdue","❌ Non-Compliant")),IF(D20="Annual",IF(F20<=365,"✅ Compliant",IF(F20<=400,"⚠ Overdue","❌ Non-Compliant")),"✅ Compliant"))))) | H20: =IF(E20="","",IF(D20="Quarterly",E20+90,IF(D20="Semi-Annual",E20+180,IF(D20="Annual",E20+365,E20))))
F21: =IF(E21="","",TODAY()-E21) | G21: =IF(A21="","",IF(E21="","❓ Unknown",IF(D21="Quarterly",IF(F21<=90,"✅ Compliant",IF(F21<=105,"⚠ Overdue","❌ Non-Compliant")),IF(D21="Semi-Annual",IF(F21<=180,"✅ Compliant",IF(F21<=200,"⚠ Overdue","❌ Non-Compliant")),IF(D21="Annual",IF(F21<=365,"✅ Compliant",IF(F21<=400,"⚠ Overdue","❌ Non-Compliant")),"✅ Compliant"))))) | H21: =IF(E21="","",IF(D21="Quarterly",E21+90,IF(D21="Semi-Annual",E21+180,IF(D21="Annual",E21+365,E21))))
F22: =IF(E22="","",TODAY()-E22) | G22: =IF(A22="","",IF(E22="","❓ Unknown",IF(D22="Quarterly",IF(F22<=90,"✅ Compliant",IF(F22<=105,"⚠ Overdue","❌ Non-Compliant")),IF(D22="Semi-Annual",IF(F22<=180,"✅ Compliant",IF(F22<=200,"⚠ Overdue","❌ Non-Compliant")),IF(D22="Annual",IF(F22<=365,"✅ Compliant",IF(F22<=400,"⚠ Overdue","❌ Non-Compliant")),"✅ Compliant"))))) | H22: =IF(E22="","",IF(D22="Quarterly",E22+90,IF(D22="Semi-Annual",E22+180,IF(D22="Annual",E22+365,E22))))
F23: =IF(E23="","",TODAY()-E23) | G23: =IF(A23="","",IF(E23="","❓ Unknown",IF(D23="Quarterly",IF(F23<=90,"✅ Compliant",IF(F23<=105,"⚠ Overdue","❌ Non-Compliant")),IF(D23="Semi-Annual",IF(F23<=180,"✅ Compliant",IF(F23<=200,"⚠ Overdue","❌ Non-Compliant")),IF(D23="Annual",IF(F23<=365,"✅ Compliant",IF(F23<=400,"⚠ Overdue","❌ Non-Compliant")),"✅ Compliant"))))) | H23: =IF(E23="","",IF(D23="Quarterly",E23+90,IF(D23="Semi-Annual",E23+180,IF(D23="Annual",E23+365,E23))))
F24: =IF(E24="","",TODAY()-E24) | G24: =IF(A24="","",IF(E24="","❓ Unknown",IF(D24="Quarterly",IF(F24<=90,"✅ Compliant",IF(F24<=105,"⚠ Overdue","❌ Non-Compliant")),IF(D24="Semi-Annual",IF(F24<=180,"✅ Compliant",IF(F24<=200,"⚠ Overdue","❌ Non-Compliant")),IF(D24="Annual",IF(F24<=365,"✅ Compliant",IF(F24<=400,"⚠ Overdue","❌ Non-Compliant")),"✅ Compliant"))))) | H24: =IF(E24="","",IF(D24="Quarterly",E24+90,IF(D24="Semi-Annual",E24+180,IF(D24="Annual",E24+365,E24))))
F25: =IF(E25="","",TODAY()-E25) | G25: =IF(A25="","",IF(E25="","❓ Unknown",IF(D25="Quarterly",IF(F25<=90,"✅ Compliant",IF(F25<=105,"⚠ Overdue","❌ Non-Compliant")),IF(D25="Semi-Annual",IF(F25<=180,"✅ Compliant",IF(F25<=200,"⚠ Overdue","❌ Non-Compliant")),IF(D25="Annual",IF(F25<=365,"✅ Compliant",IF(F25<=400,"⚠ Overdue","❌ Non-Compliant")),"✅ Compliant"))))) | H25: =IF(E25="","",IF(D25="Quarterly",E25+90,IF(D25="Semi-Annual",E25+180,IF(D25="Annual",E25+365,E25))))
F26: =IF(E26="","",TODAY()-E26) | G26: =IF(A26="","",IF(E26="","❓ Unknown",IF(D26="Quarterly",IF(F26<=90,"✅ Compliant",IF(F26<=105,"⚠ Overdue","❌ Non-Compliant")),IF(D26="Semi-Annual",IF(F26<=180,"✅ Compliant",IF(F26<=200,"⚠ Overdue","❌ Non-Compliant")),IF(D26="Annual",IF(F26<=365,"✅ Compliant",IF(F26<=400,"⚠ Overdue","❌ Non-Compliant")),"✅ Compliant"))))) | H26: =IF(E26="","",IF(D26="Quarterly",E26+90,IF(D26="Semi-Annual",E26+180,IF(D26="Annual",E26+365,E26))))
... F114: =IF(E114="","",TODAY()-E114) | G114: =IF(A114="","",IF(E114="","❓ Unknown",IF(D114="Quarterly",IF(F114<=90,"✅ Compliant",IF(F114<=105,"⚠ Overdue","❌ Non-Compliant")),IF(D114="Semi-Annual",IF(F114<=180,"✅ Compliant",IF(F114<=200,"⚠ Overdue","❌ Non-Compliant")),IF(D114="Annual",IF(F114<=365,"✅ Compliant",IF(F114<=400,"⚠ Overdue","❌ Non-Compliant")),"✅ Compliant"))))) | H114: =IF(E114="","",IF(D114="Quarterly",E114+90,IF(D114="Semi-Annual",E114+180,IF(D114="Annual",E114+365,E114))))
A117: TESTING COMPLIANCE SUMMARY
A118: Total Systems Tracked: | B118: =COUNTA(A5:A114)
A119: ✅ Compliant: | B119: =COUNTIF(G5:G114,"✅*")
A120: ⚠ Overdue: | B120: =COUNTIF(G5:G114,"⚠*")
A121: ❌ Non-Compliant: | B121: =COUNTIF(G5:G114,"❌*")
A122: ❓ Unknown (Never Tested): | B122: =COUNTIF(G5:G114,"❓*")
A124: Overall Compliance Rate: | B124: =IF(B118>0,B119/B118,0)
A125: Tests Overdue/Non-Compliant: | B125: =B120+B121

Sheet Evidence_Register
A1: EVIDENCE REGISTER
A2: Document all evidence supporting this assessment (MINIMUM 5 evidence items required for audit compliance)
A4: Evidence ID | B4: Evidence Type | C4: Description | D4: Related Sheet/Row | E4: Location/Path | F4: Date Collected | G4: Collected By | H4: Verification Status
A5: EVD-001 | C5: Test Report | D5: E-Commerce backup restore test report - Q1 2024 | E5: Test_Results_Log!A5 (RES-001) | F5: /evidence/testing/ecommerce_restore_Q1_2024.pdf | G5: 03.02.2026 | H5: Infrastructure Team | I5: ✅ Verified
A6: EVD-002 | C6: Test Report | D6: Payment Gateway failover test report with timing data | E6: Test_Results_Log!A7 (RES-003) | F6: /evidence/testing/payment_failover_2024-01-03.pdf | G6: 19.01.2026 | H6: Payments Team | I6: ✅ Verified
A7: EVD-003 | C7: Screenshot | D7: Full DR scenario test dashboard - all system status | E7: Test_Results_Log!A12 (RES-008) | F7: /evidence/testing/dr_scenario_dashboard_2023-10-15.png | G7: 10.11.2025 | H7: BC/DR Coordinator | I7: ✅ Verified
A8: EVD-004 | C8: Video Recording | D8: Tabletop exercise recording - team walkthrough | E8: Test_Results_Log!A11 (RES-007) | F8: /evidence/testing/tabletop_exercise_2024-01-01.mp4 | G8: 29.01.2026 | H8: BC/DR Coordinator | I8: ✅ Verified
A9: EVD-005 | C9: Log File | D9: Email backup job failure logs - ISS-001 root cause | E9: Issue_Remediation!A5 (ISS-001) | F9: /evidence/logs/email_backup_failure_2023-12-10.log | G9: 04.01.2026 | H9: IT Operations | I9: ✅ Verified
A10: EVD-006 | C10: Issue Ticket | D10: Jira ticket ISS-006 - Payment Gateway DR scenario issue | E10: Issue_Remediation!A10 (ISS-006) | F10: /evidence/tickets/JIRA-BCDR-156.pdf | G10: 15.11.2025 | H10: BC/DR Coordinator | I10: ✅ Verified
A11: EVD-007 | C11: Runbook | D11: Updated E-Commerce restore runbook - post-test improvements | E11: Test_Results_Log!A5 | F11: /evidence/runbooks/ecommerce_restore_runbook_v2.2.pdf | G11: 05.02.2026 | H11: Infrastructure Team | I11: ⏳ Pending
A12: EVD-008 | C12: Sign-Of | D12: Annual DR test sign-off from CISO | E12: Test_Results_Log!A12 | F12: /evidence/approvals/annual_dr_test_signoff_2023.pdf | G12: 10.11.2025 | H12: CISO Office | I12: ✅ Verified
A13: EVD-009
A14: EVD-010
A15: EVD-011
A16: EVD-012
A17: EVD-013
A18: EVD-014
A19: EVD-015
A20: EVD-016
A21: EVD-017
A22: EVD-018
A23: EVD-019
A24: EVD-020
... A107: EVIDENCE COLLECTION SUMMARY
A108: Total Evidence Items: | B108: =COUNTA(A5:A104)
A109: ✅ Verified Evidence: | B109: =COUNTIF(H5:H104,"✅*")
A110: ⏳ Pending Verification: | B110: =COUNTIF(H5:H104,"⏳*")
A111: ❌ Not Verified: | B111: =COUNTIF(H5:H104,"❌*")
A113: Minimum Required: | B113: 5
A114: Compliance Status: | B114: =IF(B108>=5,"✅ Sufficient Evidence","❌ Insufficient Evidence")

Sheet Approval_Sign_Off
A1: ASSESSMENT APPROVAL & SIGN-OFF
A3: ASSESSMENT SUMMARY
A4: Assessment Document: | B4: BC/DR Testing Results Tracker
A5: Assessment ID: | B5: ISMS-IMP-A.5.30.S4
A6: ISO 27001:2022 Controls: | B6: A.5.30 (Information Backup)
A7: Assessment Period: | B7: [USER INPUT - e.g., Annual 2024, Q1-Q4 2024]
A8: Total Tests Executed: | B8: =Summary!B5
A9: Test Success Rate: | B9: =Summary!B12
A10: Critical Issues Open: | B10: =Summary!B29
A11: Testing Compliance Rate (Tier 1): | B11: =Summary!B17
A12: Critical Issues Summary: | B12: [USER INPUT - list critical issues from Issue_Remediation]
A13: Evidence Items Collected: | B13: =COUNTA(Evidence_Register!A5:A104)
A14: Assessment Status: | B14: [SELECT FROM DROPDOWN]
A17: LEVEL 1: ASSESSMENT COMPLETED BY
A18: Name:
A19: Role/Title:
A20: Department:
A21: Email:
A22: Date Completed: | B22: =TODAY()
A23: Signature/Initials:
A26: LEVEL 2: REVIEWED BY (INFORMATION SECURITY OFFICER)
A27: Name:
A28: Review Date:
A29: Review Notes:
A32: Recommendation:
A35: LEVEL 3: APPROVED BY (CISO / SECURITY DIRECTOR)
A36: Name:
A37: Approval Date:
A38: Approval Decision:
A39: Conditions/Notes:
A44: NEXT REVIEW DETAILS
A45: Next Annual Assessment: | B45: =TODAY()+365
A46: Review Responsible:
A47: Special Considerations:
A50: APPROVAL WORKFLOW REQUIREMENTS
A51: • All 3 approval levels must be completed for final approval
A52: • Minimum 5 evidence items must be documented in Evidence_Register
A53: • Assessment status must be "Final" before CISO approval
A54: • All 🔴 Critical issues must have remediation plans
A55: • Annual re-assessment required (next assessment due in 365 days)
...
