Workbook

Sheet Executive Summary
A1: ISMS-OP-CHK-A.5.12-13 — Information Classification and Handling Compliance Checklist
A3: DOCUMENT INFORMATION
A4: Document ID | B4: ISMS-OP-CHK-A.5.12-13
A5: Source Policy | B5: ISMS-OP-POL-A.5.12-13
A6: ISO Controls | B6: Information Classification and Handling
A7: Generated | B7: 08.02.2026
A8: Prepared By
A9: Organisation
A10: Review Cycle | B10: Annual
A12: OVERALL COMPLIANCE STATUS
A13: Overall Compliance | B13: ='Dashboard'!G9
A14: Status | B14: =IF(Dashboard!G9="N/A","NOT ASSESSED",IF(ISNUMBER(VALUE(SUBSTITUTE(Dashboard!G9,"%",""))),IF(VALUE(SUBSTITUTE(Dashboard!G9,"%",""))>=90,"GREEN",IF(VALUE(SUBSTITUTE(Dashboard!G9,"%",""))>=70,"AMBER","RED")),"NOT ASSESSED"))
A16: KEY METRICS
A17: Total Requirements | B17: ='Dashboard'!B9
A18: Compliant | B18: ='Dashboard'!C9
A19: Partial | B19: ='Dashboard'!D9
A20: Non-Compliant | B20: ='Dashboard'!E9
A21: Not Applicable | B21: ='Dashboard'!F9
A22: Owner Coverage | B22: =IF(Dashboard!B9=0,"N/A",ROUND((COUNTA('Classification Scheme'!F4:F9)+COUNTA('Information Labelling'!F4:F5)+COUNTA('Information Handling'!F4:F16)+COUNTA('Information Destruction'!F4:F8)+COUNTA('Reclassification'!F4:F5))/Dashboard!B9*100,0)&"%")
A24: DOMAIN STATUS SUMMARY
A25: Domain | B25: Compliance % | C25: Compliant | D25: Gaps | E25: Status
A26: Classification Scheme | B26: ='Dashboard'!G4 | C26: ='Dashboard'!C4 | D26: ='Dashboard'!E4 | E26: =IF(Dashboard!G4="N/A","--",IF(ISNUMBER(VALUE(SUBSTITUTE(Dashboard!G4,"%",""))),IF(VALUE(SUBSTITUTE(Dashboard!G4,"%",""))>=90,"PASS",IF(VALUE(SUBSTITUTE(Dashboard!G4,"%",""))>=70,"REVIEW","FAIL")),"--"))
A27: Information Labelling | B27: ='Dashboard'!G5 | C27: ='Dashboard'!C5 | D27: ='Dashboard'!E5 | E27: =IF(Dashboard!G5="N/A","--",IF(ISNUMBER(VALUE(SUBSTITUTE(Dashboard!G5,"%",""))),IF(VALUE(SUBSTITUTE(Dashboard!G5,"%",""))>=90,"PASS",IF(VALUE(SUBSTITUTE(Dashboard!G5,"%",""))>=70,"REVIEW","FAIL")),"--"))
A28: Information Handling | B28: ='Dashboard'!G6 | C28: ='Dashboard'!C6 | D28: ='Dashboard'!E6 | E28: =IF(Dashboard!G6="N/A","--",IF(ISNUMBER(VALUE(SUBSTITUTE(Dashboard!G6,"%",""))),IF(VALUE(SUBSTITUTE(Dashboard!G6,"%",""))>=90,"PASS",IF(VALUE(SUBSTITUTE(Dashboard!G6,"%",""))>=70,"REVIEW","FAIL")),"--"))
A29: Information Destruction | B29: ='Dashboard'!G7 | C29: ='Dashboard'!C7 | D29: ='Dashboard'!E7 | E29: =IF(Dashboard!G7="N/A","--",IF(ISNUMBER(VALUE(SUBSTITUTE(Dashboard!G7,"%",""))),IF(VALUE(SUBSTITUTE(Dashboard!G7,"%",""))>=90,"PASS",IF(VALUE(SUBSTITUTE(Dashboard!G7,"%",""))>=70,"REVIEW","FAIL")),"--"))
A30: Reclassification | B30: ='Dashboard'!G8 | C30: ='Dashboard'!C8 | D30: ='Dashboard'!E8 | E30: =IF(Dashboard!G8="N/A","--",IF(ISNUMBER(VALUE(SUBSTITUTE(Dashboard!G8,"%",""))),IF(VALUE(SUBSTITUTE(Dashboard!G8,"%",""))>=90,"PASS",IF(VALUE(SUBSTITUTE(Dashboard!G8,"%",""))>=70,"REVIEW","FAIL")),"--"))
A32: CRITICAL ISSUES
A33: # | B33: Issue Description | C33: Domain | D33: Owner | E33: Due Date
A34: 1
A35: 2
A36: 3
A37: 4
A38: 5
A40: MANAGEMENT COMMENTARY
A41: [Enter management commentary on information classification and handling posture]
A45: APPROVAL
A46: Assessed By
A47: Name:
A48: Date:
A49: Signature:
...

Sheet Dashboard
A1: Information Classification and Handling — Compliance Dashboard
A3: Domain | B3: Total Reqs | C3: Compliant | D3: Partial | E3: Non-Compliant | F3: N/A | G3: Compliance %
A4: Classification Scheme | B4: =COUNTA('Classification Scheme'!D4:D9) | C4: =COUNTIF('Classification Scheme'!D4:D9,"Compliant") | D4: =COUNTIF('Classification Scheme'!D4:D9,"Partial") | E4: =COUNTIF('Classification Scheme'!D4:D9,"Non-Compliant") | F4: =COUNTIF('Classification Scheme'!D4:D9,"N/A") | G4: =IF((B4-F4)=0,"N/A",ROUND(C4/(B4-F4)*100,1)&"%")
A5: Information Labelling | B5: =COUNTA('Information Labelling'!D4:D5) | C5: =COUNTIF('Information Labelling'!D4:D5,"Compliant") | D5: =COUNTIF('Information Labelling'!D4:D5,"Partial") | E5: =COUNTIF('Information Labelling'!D4:D5,"Non-Compliant") | F5: =COUNTIF('Information Labelling'!D4:D5,"N/A") | G5: =IF((B5-F5)=0,"N/A",ROUND(C5/(B5-F5)*100,1)&"%")
A6: Information Handling | B6: =COUNTA('Information Handling'!D4:D16) | C6: =COUNTIF('Information Handling'!D4:D16,"Compliant") | D6: =COUNTIF('Information Handling'!D4:D16,"Partial") | E6: =COUNTIF('Information Handling'!D4:D16,"Non-Compliant") | F6: =COUNTIF('Information Handling'!D4:D16,"N/A") | G6: =IF((B6-F6)=0,"N/A",ROUND(C6/(B6-F6)*100,1)&"%")
A7: Information Destruction | B7: =COUNTA('Information Destruction'!D4:D8) | C7: =COUNTIF('Information Destruction'!D4:D8,"Compliant") | D7: =COUNTIF('Information Destruction'!D4:D8,"Partial") | E7: =COUNTIF('Information Destruction'!D4:D8,"Non-Compliant") | F7: =COUNTIF('Information Destruction'!D4:D8,"N/A") | G7: =IF((B7-F7)=0,"N/A",ROUND(C7/(B7-F7)*100,1)&"%")
A8: Reclassification | B8: =COUNTA('Reclassification'!D4:D5) | C8: =COUNTIF('Reclassification'!D4:D5,"Compliant") | D8: =COUNTIF('Reclassification'!D4:D5,"Partial") | E8: =COUNTIF('Reclassification'!D4:D5,"Non-Compliant") | F8: =COUNTIF('Reclassification'!D4:D5,"N/A") | G8: =IF((B8-F8)=0,"N/A",ROUND(C8/(B8-F8)*100,1)&"%")
A9: TOTAL | B9: =SUM(B4:B8) | C9: =SUM(C4:C8) | D9: =SUM(D4:D8) | E9: =SUM(E4:E8) | F9: =SUM(F4:F8) | G9: =IF((B9-F9)=0,"N/A",ROUND(C9/(B9-F9)*100,1)&"%")
A11: COMPLIANCE BY STATUS
A12: Compliant | B12: =C9 | C12: =IF(B9=0,"",ROUND(B12/B9*100,1)&"%")
A13: Partial | B13: =D9 | C13: =IF(B9=0,"",ROUND(B13/B9*100,1)&"%")
A14: Non-Compliant | B14: =E9 | C14: =IF(B9=0,"",ROUND(B14/B9*100,1)&"%")
A15: N/A | B15: =F9 | C15: =IF(B9=0,"",ROUND(B15/B9*100,1)&"%")
A17: TOP GAPS (Manual Entry)
A18: Priority | B18: Domain | C18: Requirement | D18: Owner | E18: Due Date | F18: Status
A30: COMPLIANCE TREND (Manual Entry)
A31: Assessment Date | B31: Overall % | C31: Compliant | D31: Gaps | E31: Assessor | F31: Notes

Sheet Classification Scheme
A1: Classification Scheme — Compliance Checklist
A2: ISO/IEC 27001:2022 — Controls A.5.12-13: Information Classification and Handling
A3: Req # | B3: Section | C3: Requirement | D3: Status | E3: Evidence | F3: Owner | G3: Due Date | H3: Notes
A4: A.5.12-13-01 | B4: Be Classified Into One Of Three | C4: Information shall be classified into one of three levels:.
A5: A.5.12-13-02 | B5: Default Classification: Information That | C5: Default classification: Information that has not been explicitly classified shall be treated as INTERNAL* until classified by its owner.
A6: A.5.12-13-03 | B6: Be Assigned When Information Is Created | C6: Classification shall be assigned when information is created or received.
A7: A.5.12-13-04 | B7: Be Reviewed When Information Is | C7: Classification shall be reviewed when information is significantly modified, shared with new parties, or when business circumstances change.
A8: A.5.12-13-05 | B8: Over-Classification | C8: Over-classification shall be avoided — classifying everything as CONFIDENTIAL dilutes the meaning and wastes resources.
A9: A.5.12-13-06 | B9: Aggregation Risk: Information That Is | C9: Aggregation risk: Information that is individually classified as INTERNAL may require reclassification to CONFIDENTIAL when combined with other datasets, if the aggregation creates a materially higher risk of harm (e.g., combining names with health conditions, or combining individual salary records into a department-wide compensation report). Information owners shall consider aggregation risk when classifying datasets.

Sheet Information Labelling
A1: Information Labelling — Compliance Checklist
A2: ISO/IEC 27001:2022 — Controls A.5.12-13: Information Classification and Handling
A3: Req # | B3: Section | C3: Requirement | D3: Status | E3: Evidence | F3: Owner | G3: Due Date | H3: Notes
A4: A.5.12-13-07 | B4: Be Labelled According To Its | C4: All information shall be labelled according to its classification level:.
A5: A.5.12-13-08 | B5: Unmarked Information | C5: Unmarked information shall be treated as INTERNAL* by default.

Sheet Information Handling
A1: Information Handling — Compliance Checklist
A2: ISO/IEC 27001:2022 — Controls A.5.12-13: Information Classification and Handling
A3: Req # | B3: Section | C3: Requirement | D3: Status | E3: Evidence | F3: Owner | G3: Due Date | H3: Notes
A4: A.5.12-13-09 | B4: Organisation Information | C4: Organisation information shall not be stored on personal equipment, personal email accounts, or personal cloud storage unless approved by the CISO and recorded in an approved register.
A5: A.5.12-13-10 | B5: Organisation Information | C5: Organisation information shall be protected by access controls as defined in the Access Control Policy.
A6: A.5.12-13-11 | B6: Confidential Information | C6: Confidential information shall be encrypted at rest and in transit when stored on or transmitted through any system, in line with the Use of Cryptography Policy.
A7: A.5.12-13-12 | B7: Confidential And Internal Information | C7: Confidential and internal information shall not be stored or processed in development or test environments unless the data has been masked, anonymised, or pseudonymised. Where production data must be used in non-production environments, approval from the information owner and the CISO is required, and the data shall be handled at the same classification level as in production.
A8: A.5.12-13-13 | B8: Dlp Policies | C8: Where the organisation deploys Data Leakage Prevention (DLP) tools, DLP policies shall be aligned with the classification scheme to detect and prevent unauthorised transfer or disclosure of CONFIDENTIAL information (e.g., blocking external email of files labelled CONFIDENTIAL, preventing upload to unsanctioned cloud services).
A9: A.5.12-13-14 | B9: Confidential Information Discussed | C9: Confidential information discussed verbally (in meetings, phone calls, or conversations) shall be handled with appropriate care:.
A10: A.5.12-13-15 | B10: Discussions Of Confidential Information | C10: Discussions of confidential information shall take place in private settings (closed offices, meeting rooms with closed doors) — not in open-plan areas, public spaces, or on public transport.
A11: A.5.12-13-16 | B11: Virtual Meetings Discussing Confidential | C11: Virtual meetings discussing confidential information shall use encrypted platforms with access restricted to authorised participants.
A12: A.5.12-13-17 | B12: Be Reminded Of The Confidential Nature | C12: Participants shall be reminded of the confidential nature of the discussion at the start of the meeting.
A13: A.5.12-13-18 | B13: Notes Or Minutes Of Confidential | C13: Notes or minutes of confidential discussions shall be classified and handled accordingly.
A14: A.5.12-13-19 | B14: Electronic And Paper Media | C14: All electronic and paper media containing confidential information shall be physically secured from unauthorised access by securing in locked drawers, cabinets, or restricted rooms.
A15: A.5.12-13-20 | B15: Removable Media (Usb Drives, External | C15: Removable media (USB drives, external drives, backup tapes) containing confidential data shall be encrypted and registered in the asset inventory, in line with the Asset Management Policy.
A16: A.5.12-13-21 | B16: Organisation Information | C16: Organisation information shall be backed up, retained, and tested in line with the backup schedule. Backups shall be encrypted using strong encryption. All backups shall be stored in secure locations with access restricted to authorised personnel.

Sheet Information Destruction
A1: Information Destruction — Compliance Checklist
A2: ISO/IEC 27001:2022 — Controls A.5.12-13: Information Classification and Handling
A3: Req # | B3: Section | C3: Requirement | D3: Status | E3: Evidence | F3: Owner | G3: Due Date | H3: Notes
A4: A.5.12-13-22 | B4: Be Destroyed Securely According To Its | C4: When information is no longer required and its retention period has expired, it shall be destroyed securely according to its classification level.
A5: A.5.12-13-23 | B5: Logs Of The Wipe | C5: Logs of the wipe shall be maintained where the sanitisation tool supports it.
A6: A.5.12-13-24 | B6: Electronic Media And Devices That Have | C6: Electronic media and devices that have stored confidential or internal information shall be destroyed by approved methods when no longer required:.
A7: A.5.12-13-25 | B7: Destruction Of Confidential Media | C7: Destruction of confidential media shall be performed by approved specialist third-party suppliers where in-house destruction is not feasible. Certificates of destruction shall be obtained and retained as evidence.
A8: A.5.12-13-26 | B8: An Inventory Of Devices | C8: An inventory of devices, including those destroyed, shall be maintained in line with the Asset Management Policy.

Sheet Reclassification
A1: Reclassification — Compliance Checklist
A2: ISO/IEC 27001:2022 — Controls A.5.12-13: Information Classification and Handling
A3: Req # | B3: Section | C3: Requirement | D3: Status | E3: Evidence | F3: Owner | G3: Due Date | H3: Notes
A4: A.5.12-13-27 | B4: Information Classification Is Not | C4: Information classification is not permanent. Information shall be reclassified when:.
A5: A.5.12-13-28 | B5: Be Performed By The Information Owner | C5: Reclassification shall be performed by the information owner and the labelling updated accordingly.
