Workbook

Sheet Instructions & Legend
A1: ISMS-IMP-A.8.20-22.S2 - Network Device Security Assessment ISO/IEC 27001:2022 - Control A.8.20-22: Network Security
A3: Document Information
A4: Document ID | B4: ISMS-IMP-A.8.20-22.S2
A5: Workbook Title | B5: Network Device Security Assessment
A6: Control Reference | B6: ISO/IEC 27001:2022 - Control A.8.20-22: Network Security
A7: Version | B7: 1.0
A8: Assessment Date
A9: Completed By
A10: Organisation
A12: Instructions
A13: 1. Complete the Device Hardening Assessment for each network device type in scope.
A14: 2. Reference the Hardening Baseline Reference for vendor-specific standards (CIS, STIG, NIST).
A15: 3. Use dropdown menus for standardised compliance and risk assessments.
A16: 4. Document gaps in the Gap Analysis sheet with severity and remediation priority.
A17: 5. Review the Compliance Scoring sheet for automated compliance percentage calculations.
A18: 6. Assess device type compliance trends in the Device Type Compliance sheet.
A19: 7. Prioritise top gaps in the Top Gaps Analysis sheet for remediation planning.
A20: 8. Create remediation roadmaps with timelines in the Remediation Roadmap sheet.
... A24: Status Legend
A25: Symbol | B25: Status | C25: Description
A26: ✓ | B26: Compliant / Complete | C26: Requirement fully met
A27: ⚠ | B27: Partial / In Progress | C27: Partially met or in progress
A28: ✗ | B28: Non-Compliant / Not Started | C28: Requirement not met
A29: — | B29: Not Applicable | C29: Not applicable to this assessment

Sheet Device Hardening Assessment
A1: NETWORK DEVICE HARDENING ASSESSMENT - GENERATED 10.03.2026
A2: Assess each device against 15 hardening requirements. Yellow cells are assessment fields (Yes/No/N/A). Compliance score auto-calculates.
A3: Device ID | B3: Device Type | C3: Hostname | D3: Primary IP | E3: Criticality | F3: Default Credentials Disabled | G3: Strong Password Policy | H3: Multi-Factor Authentication (MFA) | I3: Unnecessary Services Disabled | J3: Secure Management (SSH/HTTPS Only) | K3: Logging Enabled | L3: NTP Configured | M3: SNMPv3 Only (v1/v2c Disabled) | N3: Session Timeouts Configured | O3: Banner Messages Configured | P3: Configuration Backups | Q3: Firmware/Software Up-to-Date | R3: Access Control Lists (ACLs) | S3: Encrypted Management Traffic | T3: Least Privilege Access | U3: Compliance Score (%) | V3: Gap Count | W3: Assessment Date | X3: Assessor | Y3: Notes
A4: NET-DEV-001 | B4: Router | C4: core-rtr-01 | D4: 192.168.1.1 | E4: Critical | F4: Yes | G4: Yes | H4: No | I4: Yes | J4: Yes | K4: Yes | L4: Yes | M4: Yes | N4: Yes | O4: Yes | P4: Yes | Q4: No | R4: Yes | S4: Yes | T4: Yes | U4: =IF(COUNTIF(F4:T4,"Yes")+COUNTIF(F4:T4,"No")=0,"",COUNTIF(F4:T4,"Yes")/(COUNTIF(F4:T4,"Yes")+COUNTIF(F4:T4,"No"))*100) | V4: =COUNTIF(F4:T4,"No") | W4: 15.01.2026
U5: =IF(COUNTIF(F5:T5,"Yes")+COUNTIF(F5:T5,"No")=0,"",COUNTIF(F5:T5,"Yes")/(COUNTIF(F5:T5,"Yes")+COUNTIF(F5:T5,"No"))*100) | V5: =COUNTIF(F5:T5,"No")
U6: =IF(COUNTIF(F6:T6,"Yes")+COUNTIF(F6:T6,"No")=0,"",COUNTIF(F6:T6,"Yes")/(COUNTIF(F6:T6,"Yes")+COUNTIF(F6:T6,"No"))*100) | V6: =COUNTIF(F6:T6,"No")
U7: =IF(COUNTIF(F7:T7,"Yes")+COUNTIF(F7:T7,"No")=0,"",COUNTIF(F7:T7,"Yes")/(COUNTIF(F7:T7,"Yes")+COUNTIF(F7:T7,"No"))*100) | V7: =COUNTIF(F7:T7,"No")
U8: =IF(COUNTIF(F8:T8,"Yes")+COUNTIF(F8:T8,"No")=0,"",COUNTIF(F8:T8,"Yes")/(COUNTIF(F8:T8,"Yes")+COUNTIF(F8:T8,"No"))*100) | V8: =COUNTIF(F8:T8,"No")
U9: =IF(COUNTIF(F9:T9,"Yes")+COUNTIF(F9:T9,"No")=0,"",COUNTIF(F9:T9,"Yes")/(COUNTIF(F9:T9,"Yes")+COUNTIF(F9:T9,"No"))*100) | V9: =COUNTIF(F9:T9,"No")
U10: =IF(COUNTIF(F10:T10,"Yes")+COUNTIF(F10:T10,"No")=0,"",COUNTIF(F10:T10,"Yes")/(COUNTIF(F10:T10,"Yes")+COUNTIF(F10:T10,"No"))*100) | V10: =COUNTIF(F10:T10,"No")
U11: =IF(COUNTIF(F11:T11,"Yes")+COUNTIF(F11:T11,"No")=0,"",COUNTIF(F11:T11,"Yes")/(COUNTIF(F11:T11,"Yes")+COUNTIF(F11:T11,"No"))*100) | V11: =COUNTIF(F11:T11,"No")
U12: =IF(COUNTIF(F12:T12,"Yes")+COUNTIF(F12:T12,"No")=0,"",COUNTIF(F12:T12,"Yes")/(COUNTIF(F12:T12,"Yes")+COUNTIF(F12:T12,"No"))*100) | V12: =COUNTIF(F12:T12,"No")
U13: =IF(COUNTIF(F13:T13,"Yes")+COUNTIF(F13:T13,"No")=0,"",COUNTIF(F13:T13,"Yes")/(COUNTIF(F13:T13,"Yes")+COUNTIF(F13:T13,"No"))*100) | V13: =COUNTIF(F13:T13,"No")
U14: =IF(COUNTIF(F14:T14,"Yes")+COUNTIF(F14:T14,"No")=0,"",COUNTIF(F14:T14,"Yes")/(COUNTIF(F14:T14,"Yes")+COUNTIF(F14:T14,"No"))*100) | V14: =COUNTIF(F14:T14,"No")
U15: =IF(COUNTIF(F15:T15,"Yes")+COUNTIF(F15:T15,"No")=0,"",COUNTIF(F15:T15,"Yes")/(COUNTIF(F15:T15,"Yes")+COUNTIF(F15:T15,"No"))*100) | V15: =COUNTIF(F15:T15,"No")
U16: =IF(COUNTIF(F16:T16,"Yes")+COUNTIF(F16:T16,"No")=0,"",COUNTIF(F16:T16,"Yes")/(COUNTIF(F16:T16,"Yes")+COUNTIF(F16:T16,"No"))*100) | V16: =COUNTIF(F16:T16,"No")
... U54: =IF(COUNTIF(F54:T54,"Yes")+COUNTIF(F54:T54,"No")=0,"",COUNTIF(F54:T54,"Yes")/(COUNTIF(F54:T54,"Yes")+COUNTIF(F54:T54,"No"))*100) | V54: =COUNTIF(F54:T54,"No")

Sheet Hardening Baseline Reference
A1: DEVICE HARDENING BASELINE REFERENCE
A2: Reference guide for device hardening based on CIS Benchmarks and vendor security guides
A4: CIS Benchmarks & Industry Standards
A5: Device Type | B5: Benchmark/Guide | C5: Version | D5: URL/Reference
A6: Cisco IOS | B6: CIS Cisco IOS Benchmark | C6: v4.1.0 | D6: https://www.cisecurity.org/benchmark/cisco
A7: Juniper JunOS | B7: CIS Juniper Benchmark | C7: v2.1.0 | D7: https://www.cisecurity.org/benchmark/juniper
A8: Palo Alto | B8: CIS Palo Alto Firewall Benchmark | C8: v1.1.0 | D8: https://www.cisecurity.org/benchmark/palo_alto_networks
A9: Fortinet | B9: CIS Fortinet FortiOS Benchmark | C9: v1.1.0 | D9: https://www.cisecurity.org/benchmark/fortinet
A10: Aruba | B10: Aruba Hardening Guide | C10: Latest | D10: https://www.arubanetworks.com/techdocs/
A11: Generic Network | B11: NIST SP 800-41 (Firewall/Router) | C11: Rev 1 | D11: https://csrc.nist.gov/publications/detail/sp/800-41/rev-1/final
A12: Wireless | B12: CIS Wireless Network Security | C12: v1.0 | D12: https://www.cisecurity.org/
A14: Hardening Requirements - Implementation Guidance
A15: Requirement | B15: Implementation Guidance | C15: Verification Method
A16: Default Credentials Disabled | B16: Change default usernames/passwords (admin/admin, cisco/cisco, etc.). Disable or rename default accounts. | C16: Attempt login with default credentials (should fail). Review user list.
A17: Strong Password Policy | B17: Min 12 chars, complexity (upper/lower/number/special), expiration 90 days, history 5 passwords. | C17: Check password policy config. Test weak password (should be rejected).
A18: Multi-Factor Authentication | B18: Enable MFA for admin access (TACACS+, RADIUS with OTP/tokens). Critical for privileged access. | C18: Verify AAA config, test login (should require 2nd factor).
A19: Unnecessary Services Disabled | B19: Disable unused protocols: HTTP (use HTTPS), Telnet (use SSH), FTP, TFTP, finger, echo, CDP (on edge). | C19: Port scan device, check running services list.
A20: Secure Management (SSH/HTTPS) | B20: Use SSH for CLI (disable Telnet), HTTPS for web (disable HTTP). SSH v2 only. | C20: Telnet to device (should fail). Check SSH version.
A21: Logging Enabled | B21: Enable syslog to centralised server. Log severity: informational or higher. Buffer logging. | C21: Check logging config, verify logs reaching syslog server.
A22: NTP Configured | B22: Configure NTP client, point to internal NTP servers. Enable NTP authentication if possible. | C22: Check NTP config, verify time sync (ntpstat, show ntp status).
A23: SNMPv3 Only | B23: Use SNMPv3 with authentication and encryption. Disable SNMPv1/v2c (community strings). | C23: Check SNMP config, test v2c query (should fail).
A24: Session Timeouts | B24: Configure idle timeout (e.g., 10 minutes for console, 15 min for VTY). Auto-logout inactive sessions. | C24: Check timeout config (exec-timeout, idle-timeout).
A25: Banner Messages | B25: Configure login banner warning unauthorised access is prohibited. MOTD and login banners. | C25: Check banner config, verify displayed on login.
A26: Configuration Backups | B26: Automated nightly config backups to secure location. Use RANCID, Oxidized, or scripts. | C26: Verify backup schedule, check recent backup files exist.
... A30: Least Privilege Access | B30: Role-based access control (RBAC). Users have minimum privileges needed. Privilege levels configured. | C30: Review user privilege levels, test restricted user access.
A32: Device-Specific Hardening Notes
A33: Routers | B33: Disable IP source routing, enable uRPF, implement ACLs, secure routing protocols (MD5 auth).
A34: Switches | B34: Enable port security, DHCP snooping, DAI, disable DTP, change native VLAN, disable unused ports.
A35: Firewalls | B35: Default deny policy, rule cleanup, logging all denied traffic, regular rule review.
A36: Wireless APs | B36: WPA3 or WPA2-Enterprise, disable WPS, hide SSID (optional), MAC filtering, rogue AP detection.
A37: Load Balancers | B37: Strong SSL/TLS ciphers, disable SSLv3/TLS1.0, enable HSTS, session persistence security.

Sheet Gap Analysis
A1: DEVICE HARDENING GAPS - SUMMARY & REMEDIATION TRACKING
A2: Document all "No" responses from Device Hardening Assessment. Track remediation progress and priority.
A3: Gap ID | B3: Device ID | C3: Device Type | D3: Hostname | E3: Hardening Requirement | F3: Current State | G3: Gap Severity | H3: Remediation Plan | I3: Owner | J3: Status | K3: Target Date
A4: HARD-GAP-001 | B4: NET-DEV-001 | C4: Router | D4: core-rtr-01 | E4: Multi-Factor Authentication (MFA) | F4: MFA not configured for admin access | G4: Critical | H4: Configure TACACS+ with MFA within 30 days | I4: Network Security Team | J4: Open | K4: 28.02.2026
A5: =IF(B5<>"","HARD-GAP-" & TEXT(2,"000"),"")
A6: =IF(B6<>"","HARD-GAP-" & TEXT(3,"000"),"")
A7: =IF(B7<>"","HARD-GAP-" & TEXT(4,"000"),"")
A8: =IF(B8<>"","HARD-GAP-" & TEXT(5,"000"),"")
A9: =IF(B9<>"","HARD-GAP-" & TEXT(6,"000"),"")
A10: =IF(B10<>"","HARD-GAP-" & TEXT(7,"000"),"")
A11: =IF(B11<>"","HARD-GAP-" & TEXT(8,"000"),"")
A12: =IF(B12<>"","HARD-GAP-" & TEXT(9,"000"),"")
A13: =IF(B13<>"","HARD-GAP-" & TEXT(10,"000"),"")
A14: =IF(B14<>"","HARD-GAP-" & TEXT(11,"000"),"")
A15: =IF(B15<>"","HARD-GAP-" & TEXT(12,"000"),"")
A16: =IF(B16<>"","HARD-GAP-" & TEXT(13,"000"),"")
A17: =IF(B17<>"","HARD-GAP-" & TEXT(14,"000"),"")
A18: =IF(B18<>"","HARD-GAP-" & TEXT(15,"000"),"")
A19: =IF(B19<>"","HARD-GAP-" & TEXT(16,"000"),"")
A20: =IF(B20<>"","HARD-GAP-" & TEXT(17,"000"),"")
A21: =IF(B21<>"","HARD-GAP-" & TEXT(18,"000"),"")
A22: =IF(B22<>"","HARD-GAP-" & TEXT(19,"000"),"")
A23: =IF(B23<>"","HARD-GAP-" & TEXT(20,"000"),"")
A24: =IF(B24<>"","HARD-GAP-" & TEXT(21,"000"),"")
A25: =IF(B25<>"","HARD-GAP-" & TEXT(22,"000"),"")
A26: =IF(B26<>"","HARD-GAP-" & TEXT(23,"000"),"")
A27: =IF(B27<>"","HARD-GAP-" & TEXT(24,"000"),"")
A28: =IF(B28<>"","HARD-GAP-" & TEXT(25,"000"),"")
A29: =IF(B29<>"","HARD-GAP-" & TEXT(26,"000"),"")
A30: =IF(B30<>"","HARD-GAP-" & TEXT(27,"000"),"")
A31: =IF(B31<>"","HARD-GAP-" & TEXT(28,"000"),"")
A32: =IF(B32<>"","HARD-GAP-" & TEXT(29,"000"),"")
A33: =IF(B33<>"","HARD-GAP-" & TEXT(30,"000"),"")
A34: =IF(B34<>"","HARD-GAP-" & TEXT(31,"000"),"")
A35: =IF(B35<>"","HARD-GAP-" & TEXT(32,"000"),"")
A36: =IF(B36<>"","HARD-GAP-" & TEXT(33,"000"),"")
A37: =IF(B37<>"","HARD-GAP-" & TEXT(34,"000"),"")
A38: =IF(B38<>"","HARD-GAP-" & TEXT(35,"000"),"")
A39: =IF(B39<>"","HARD-GAP-" & TEXT(36,"000"),"")
A40: =IF(B40<>"","HARD-GAP-" & TEXT(37,"000"),"")
...

Sheet Device Type Compliance
A1: COMPLIANCE ANALYSIS BY DEVICE TYPE
A2: Breakdown of hardening compliance scores by device type to identify problem areas
A4: Average Compliance Score by Device Type
A5: Device Type | B5: Device Count | C5: Avg Compliance Score | D5: Min Score | E5: Max Score
A6: Router | B6: =COUNTIF('Device Hardening Assessment'!B5:B54,"Router") | C6: =IFERROR(AVERAGEIF('Device Hardening Assessment'!B5:B54,"Router",'Device Hardening Assessment'!U5:U54),"") | D6: =IFERROR(MINIFS('Device Hardening Assessment'!U5:U54,'Device Hardening Assessment'!B5:B54,"Router"),"") | E6: =IFERROR(MAXIFS('Device Hardening Assessment'!U5:U54,'Device Hardening Assessment'!B5:B54,"Router"),"")
A7: Switch | B7: =COUNTIF('Device Hardening Assessment'!B5:B54,"Switch") | C7: =IFERROR(AVERAGEIF('Device Hardening Assessment'!B5:B54,"Switch",'Device Hardening Assessment'!U5:U54),"") | D7: =IFERROR(MINIFS('Device Hardening Assessment'!U5:U54,'Device Hardening Assessment'!B5:B54,"Switch"),"") | E7: =IFERROR(MAXIFS('Device Hardening Assessment'!U5:U54,'Device Hardening Assessment'!B5:B54,"Switch"),"")
A8: Firewall | B8: =COUNTIF('Device Hardening Assessment'!B5:B54,"Firewall") | C8: =IFERROR(AVERAGEIF('Device Hardening Assessment'!B5:B54,"Firewall",'Device Hardening Assessment'!U5:U54),"") | D8: =IFERROR(MINIFS('Device Hardening Assessment'!U5:U54,'Device Hardening Assessment'!B5:B54,"Firewall"),"") | E8: =IFERROR(MAXIFS('Device Hardening Assessment'!U5:U54,'Device Hardening Assessment'!B5:B54,"Firewall"),"")
A9: Wireless AP | B9: =COUNTIF('Device Hardening Assessment'!B5:B54,"Wireless AP") | C9: =IFERROR(AVERAGEIF('Device Hardening Assessment'!B5:B54,"Wireless AP",'Device Hardening Assessment'!U5:U54),"") | D9: =IFERROR(MINIFS('Device Hardening Assessment'!U5:U54,'Device Hardening Assessment'!B5:B54,"Wireless AP"),"") | E9: =IFERROR(MAXIFS('Device Hardening Assessment'!U5:U54,'Device Hardening Assessment'!B5:B54,"Wireless AP"),"")
A10: Load Balancer | B10: =COUNTIF('Device Hardening Assessment'!B5:B54,"Load Balancer") | C10: =IFERROR(AVERAGEIF('Device Hardening Assessment'!B5:B54,"Load Balancer",'Device Hardening Assessment'!U5:U54),"") | D10: =IFERROR(MINIFS('Device Hardening Assessment'!U5:U54,'Device Hardening Assessment'!B5:B54,"Load Balancer"),"") | E10: =IFERROR(MAXIFS('Device Hardening Assessment'!U5:U54,'Device Hardening Assessment'!B5:B54,"Load Balancer"),"")
A11: VPN Concentrator | B11: =COUNTIF('Device Hardening Assessment'!B5:B54,"VPN Concentrator") | C11: =IFERROR(AVERAGEIF('Device Hardening Assessment'!B5:B54,"VPN Concentrator",'Device Hardening Assessment'!U5:U54),"") | D11: =IFERROR(MINIFS('Device Hardening Assessment'!U5:U54,'Device Hardening Assessment'!B5:B54,"VPN Concentrator"),"") | E11: =IFERROR(MAXIFS('Device Hardening Assessment'!U5:U54,'Device Hardening Assessment'!B5:B54,"VPN Concentrator"),"")
A12: IDS/IPS | B12: =COUNTIF('Device Hardening Assessment'!B5:B54,"IDS/IPS") | C12: =IFERROR(AVERAGEIF('Device Hardening Assessment'!B5:B54,"IDS/IPS",'Device Hardening Assessment'!U5:U54),"") | D12: =IFERROR(MINIFS('Device Hardening Assessment'!U5:U54,'Device Hardening Assessment'!B5:B54,"IDS/IPS"),"") | E12: =IFERROR(MAXIFS('Device Hardening Assessment'!U5:U54,'Device Hardening Assessment'!B5:B54,"IDS/IPS"),"")
A13: Network Management | B13: =COUNTIF('Device Hardening Assessment'!B5:B54,"Network Management") | C13: =IFERROR(AVERAGEIF('Device Hardening Assessment'!B5:B54,"Network Management",'Device Hardening Assessment'!U5:U54),"") | D13: =IFERROR(MINIFS('Device Hardening Assessment'!U5:U54,'Device Hardening Assessment'!B5:B54,"Network Management"),"") | E13: =IFERROR(MAXIFS('Device Hardening Assessment'!U5:U54,'Device Hardening Assessment'!B5:B54,"Network Management"),"")
A14: Other | B14: =COUNTIF('Device Hardening Assessment'!B5:B54,"Other") | C14: =IFERROR(AVERAGEIF('Device Hardening Assessment'!B5:B54,"Other",'Device Hardening Assessment'!U5:U54),"") | D14: =IFERROR(MINIFS('Device Hardening Assessment'!U5:U54,'Device Hardening Assessment'!B5:B54,"Other"),"") | E14: =IFERROR(MAXIFS('Device Hardening Assessment'!U5:U54,'Device Hardening Assessment'!B5:B54,"Other"),"")

Sheet Top Gaps Analysis
A1: TOP HARDENING GAPS - MOST COMMON FAILURES
A2: Identify most frequently failed hardening requirements across all devices
A4: Hardening Requirements Failure Analysis (15 Requirements)
A5: Requirement | B5: Total 'No' Count | C5: Failure Rate % | D5: Priority
A6: Default Credentials Disabled | B6: =COUNTIF('Device Hardening Assessment'!F5:F54,"No") | C6: =IFERROR(B6/COUNTA('Device Hardening Assessment'!F5:F54),"") | D6: =IF(C6>=75,"CRITICAL",IF(C6>=50,"HIGH",IF(C6>=25,"MEDIUM","LOW")))
A7: Strong Password Policy | B7: =COUNTIF('Device Hardening Assessment'!G5:G54,"No") | C7: =IFERROR(B7/COUNTA('Device Hardening Assessment'!G5:G54),"") | D7: =IF(C7>=75,"CRITICAL",IF(C7>=50,"HIGH",IF(C7>=25,"MEDIUM","LOW")))
A8: Multi-Factor Authentication (MFA) | B8: =COUNTIF('Device Hardening Assessment'!H5:H54,"No") | C8: =IFERROR(B8/COUNTA('Device Hardening Assessment'!H5:H54),"") | D8: =IF(C8>=75,"CRITICAL",IF(C8>=50,"HIGH",IF(C8>=25,"MEDIUM","LOW")))
A9: Unnecessary Services Disabled | B9: =COUNTIF('Device Hardening Assessment'!I5:I54,"No") | C9: =IFERROR(B9/COUNTA('Device Hardening Assessment'!I5:I54),"") | D9: =IF(C9>=75,"CRITICAL",IF(C9>=50,"HIGH",IF(C9>=25,"MEDIUM","LOW")))
A10: Secure Management (SSH/HTTPS Only) | B10: =COUNTIF('Device Hardening Assessment'!J5:J54,"No") | C10: =IFERROR(B10/COUNTA('Device Hardening Assessment'!J5:J54),"") | D10: =IF(C10>=75,"CRITICAL",IF(C10>=50,"HIGH",IF(C10>=25,"MEDIUM","LOW")))
A11: Logging Enabled | B11: =COUNTIF('Device Hardening Assessment'!K5:K54,"No") | C11: =IFERROR(B11/COUNTA('Device Hardening Assessment'!K5:K54),"") | D11: =IF(C11>=75,"CRITICAL",IF(C11>=50,"HIGH",IF(C11>=25,"MEDIUM","LOW")))
A12: NTP Configured | B12: =COUNTIF('Device Hardening Assessment'!L5:L54,"No") | C12: =IFERROR(B12/COUNTA('Device Hardening Assessment'!L5:L54),"") | D12: =IF(C12>=75,"CRITICAL",IF(C12>=50,"HIGH",IF(C12>=25,"MEDIUM","LOW")))
A13: SNMPv3 Only (v1/v2c Disabled) | B13: =COUNTIF('Device Hardening Assessment'!M5:M54,"No") | C13: =IFERROR(B13/COUNTA('Device Hardening Assessment'!M5:M54),"") | D13: =IF(C13>=75,"CRITICAL",IF(C13>=50,"HIGH",IF(C13>=25,"MEDIUM","LOW")))
A14: Session Timeouts Configured | B14: =COUNTIF('Device Hardening Assessment'!N5:N54,"No") | C14: =IFERROR(B14/COUNTA('Device Hardening Assessment'!N5:N54),"") | D14: =IF(C14>=75,"CRITICAL",IF(C14>=50,"HIGH",IF(C14>=25,"MEDIUM","LOW")))
A15: Banner Messages Configured | B15: =COUNTIF('Device Hardening Assessment'!O5:O54,"No") | C15: =IFERROR(B15/COUNTA('Device Hardening Assessment'!O5:O54),"") | D15: =IF(C15>=75,"CRITICAL",IF(C15>=50,"HIGH",IF(C15>=25,"MEDIUM","LOW")))
A16: Configuration Backups | B16: =COUNTIF('Device Hardening Assessment'!P5:P54,"No") | C16: =IFERROR(B16/COUNTA('Device Hardening Assessment'!P5:P54),"") | D16: =IF(C16>=75,"CRITICAL",IF(C16>=50,"HIGH",IF(C16>=25,"MEDIUM","LOW")))
A17: Firmware/Software Up-to-Date | B17: =COUNTIF('Device Hardening Assessment'!Q5:Q54,"No") | C17: =IFERROR(B17/COUNTA('Device Hardening Assessment'!Q5:Q54),"") | D17: =IF(C17>=75,"CRITICAL",IF(C17>=50,"HIGH",IF(C17>=25,"MEDIUM","LOW")))
A18: Access Control Lists (ACLs) | B18: =COUNTIF('Device Hardening Assessment'!R5:R54,"No") | C18: =IFERROR(B18/COUNTA('Device Hardening Assessment'!R5:R54),"") | D18: =IF(C18>=75,"CRITICAL",IF(C18>=50,"HIGH",IF(C18>=25,"MEDIUM","LOW")))
A19: Encrypted Management Traffic | B19: =COUNTIF('Device Hardening Assessment'!S5:S54,"No") | C19: =IFERROR(B19/COUNTA('Device Hardening Assessment'!S5:S54),"") | D19: =IF(C19>=75,"CRITICAL",IF(C19>=50,"HIGH",IF(C19>=25,"MEDIUM","LOW")))
A20: Least Privilege Access | B20: =COUNTIF('Device Hardening Assessment'!T5:T54,"No") | C20: =IFERROR(B20/COUNTA('Device Hardening Assessment'!T5:T54),"") | D20: =IF(C20>=75,"CRITICAL",IF(C20>=50,"HIGH",IF(C20>=25,"MEDIUM","LOW")))

Sheet Remediation Roadmap
A1: HARDENING REMEDIATION ROADMAP
A2: Prioritised remediation plan sorted by severity. Focus on Critical/High gaps first.
A3: Priority | B3: Severity | C3: Gap Description | D3: Affected Devices | E3: Remediation Action | F3: Owner | G3: Target Date | H3: Status
A4: 1
A5: 2
A6: 3
A7: 4
A8: 5
A9: 6
A10: 7
A11: 8
A12: 9
A13: 10
A14: 11
A15: 12
... A53: 50
A55: Remediation Approach Guidelines
A56: 1. PRIORITIZE BY SEVERITY: Address Critical gaps immediately, then High, then Medium/Low
A57: 2. CLUSTER BY REQUIREMENT: Remediate same requirement across multiple devices together (efficiency)
A58: 3. LOW-HANGING FRUIT: Quick wins (e.g., enable logging, configure banners) → build momentum
A59: 4. COMPLEX ITEMS: MFA, major config changes require planning, testing, approval
A60: 5. VALIDATE: Test in lab/dev environment before production deployment
A61: 6. DOCUMENT: Maintain change records, configuration backups, validation evidence
A62: 7. RE-ASSESS: After remediation, re-run assessment to confirm compliance improvement

Sheet Evidence Register
A1: EVIDENCE REGISTER
A2: List all evidence files/documents referenced in this assessment (audit traceability).
A4: Evidence ID | B4: Assessment Area | C4: Evidence Type | D4: Description | E4: Location/Path | F4: Date Collected | G4: Collected By | H4: Verification Status
A5: EV-001 | B5: Device Security Assessment | C5: Configuration file | D5: Device hardening assessment results and security configuration exports | E5: /evidence/A.8.20-22/ | F5: 15.01.2026 | G5: Assessor Name | H5: ✅ Verified

Sheet Summary Dashboard
A1: NETWORK DEVICE SECURITY ASSESSMENT — SUMMARY DASHBOARD
A2: ISO/IEC 27001:2022 — Controls A.8.20 · A.8.21 · A.8.22: Network Security, Security of Network Services and Segregation of Networks
A4: TABLE 1: ASSESSMENT AREA COMPLIANCE
A5: Assessment Area | B5: Total | C5: Yes | D5: Partial | E5: No | F5: N-A | G5: Compliance %
A6: Device Hardening Assessment | B6: =COUNTA('Device Hardening Assessment'!B5:B54) | C6: =COUNTIF('Device Hardening Assessment'!U5:U54,">=80") | D6: =COUNTIFS('Device Hardening Assessment'!U5:U54,">=50",'Device Hardening Assessment'!U5:U54,"<80") | E6: =COUNTIFS('Device Hardening Assessment'!U5:U54,">=0",'Device Hardening Assessment'!U5:U54,"<50") | F6: =B6-(C6+D6+E6) | G6: =IF((B6-F6)=0,"0%",ROUND(C6/(B6-F6)*100,1)&"%")
A7: Gap Analysis | B7: =COUNTA('Gap Analysis'!B5:B110) | C7: =COUNTIF('Gap Analysis'!J5:J110,"Completed") | D7: =COUNTIF('Gap Analysis'!J5:J110,"In Progress") | E7: =COUNTIF('Gap Analysis'!J5:J110,"Open") | F7: =B7-(C7+D7+E7) | G7: =IF((B7-F7)=0,"0%",ROUND(C7/(B7-F7)*100,1)&"%")
A8: TOTAL | B8: =SUM(B6:B7) | C8: =SUM(C6:C7) | D8: =SUM(D6:D7) | E8: =SUM(E6:E7) | F8: =SUM(F6:F7) | G8: =IF((B8-F8)=0,"0%",ROUND(C8/(B8-F8)*100,1)&"%")
A10: TABLE 2: KEY METRICS
A11: Metric | B11: Value | C11: What This Shows
A12: Non-Compliant Devices (<80%) | B12: =COUNTIFS('Device Hardening Assessment'!U5:U54,">=0",'Device Hardening Assessment'!U5:U54,"<80") | C12: Devices scoring below 80% hardening baseline (require remediation)
A13: Fully Compliant Devices (≥95%) | B13: =COUNTIF('Device Hardening Assessment'!U5:U54,">=95") | C13: Devices meeting gold-standard hardening (≥95% compliance score)
A14: Partially Compliant Devices (80–94%) | B14: =COUNTIFS('Device Hardening Assessment'!U5:U54,">=80",'Device Hardening Assessment'!U5:U54,"<95") | C14: Near-compliant devices needing minor hardening improvements
A15: Critical Severity Hardening Gaps | B15: =COUNTIF('Gap Analysis'!G5:G110,"Critical") | C15: Critical hardening gaps requiring immediate remediation
A16: Open Gaps | B16: =COUNTIF('Gap Analysis'!J5:J110,"Open") | C16: Outstanding gaps without active remediation plan
A17: High Severity Gaps | B17: =COUNTIF('Gap Analysis'!G5:G110,"High") | C17: High-severity hardening gaps requiring prioritised remediation
A18: Devices Not Assessed | B18: =COUNTBLANK('Device Hardening Assessment'!U5:U54) | C18: Devices in scope with no hardening score (assessment required)
A19: Overall Compliance Rate | B19: =G8 | C19: Overall device hardening compliance percentage (TABLE 1 total)
A21: TABLE 3: CRITICAL FINDINGS
A22: Critical Finding Type | B22: Count | C22: Filter Instructions
A23: Non-Compliant Devices (<80%) | B23: =COUNTIFS('Device Hardening Assessment'!U5:U54,">=0",'Device Hardening Assessment'!U5:U54,"<80") | C23: Filter Device Hardening Assessment: Score < 80
A24: Critical Hardening Gaps | B24: =COUNTIF('Gap Analysis'!G5:G110,"Critical") | C24: Filter Gap Analysis: Severity = "Critical"
A25: Open Gaps | B25: =COUNTIF('Gap Analysis'!J5:J110,"Open") | C25: Filter Gap Analysis: Status = "Open"
A26: High Severity Gaps | B26: =COUNTIF('Gap Analysis'!G5:G110,"High") | C26: Filter Gap Analysis: Severity = "High"
A27: Devices Not Assessed | B27: =COUNTBLANK('Device Hardening Assessment'!U5:U54) | C27: Filter Device Hardening Assessment: Score is empty
A28: TOTAL | B28: =SUM(B23:B27) | C28: Total critical findings requiring immediate remediation

Sheet Approval Sign-Off
A1: ASSESSMENT APPROVAL AND SIGN-OFF
A3: ASSESSMENT SUMMARY
A4: Document: | B4: ISMS-IMP-A.8.20-22.S2 - Network Device Security Assessment
A5: Assessment Period:
A6: Overall Compliance: | B6: =IFERROR(AVERAGE('Summary Dashboard'!G6:G7),"")
A7: Assessment Status:
A10: COMPLETED BY (NETWORK SECURITY)
A11: Name:
A12: Title:
A13: Date:
A14: Signature:
A15: Comments:
A17: REVIEWED BY (ISO)
A18: Name:
A19: Title:
A20: Date:
A21: Signature:
... A37: Special Considerations:
