Workbook

Sheet Instructions & Legend
A1: ISMS-IMP-A.8.20-21-22.S3 - Network Services Catalog & Security Assessment ISO/IEC 27001:2022 - Control A.8.20-21-22: Network Security
A3: Document Information
A4: Document ID | B4: ISMS-IMP-A.8.20-21-22.S3
A5: Workbook Title | B5: Network Services Catalog & Security Assessment
A6: Control Reference | B6: ISO/IEC 27001:2022 - Control A.8.20-21-22: Network Security
A7: Version | B7: 1.0
A8: Assessment Date
A9: Completed By
A10: Organisation
A12: Instructions
A13: 1. Complete the Services Catalog for all network services deployed in your environment.
A14: 2. Assess DNS security controls in the DNS Security Assessment sheet.
A15: 3. Assess DHCP security controls in the DHCP Security Assessment sheet.
A16: 4. Assess NTP security controls in the NTP Security Assessment sheet.
A17: 5. Assess proxy/web gateway security in the Proxy Security Assessment sheet.
A18: 6. Document additional network services (RADIUS, SNMP, etc.) in the Additional Services sheet.
A19: 7. Review compliance scoring in the Service Compliance Summary sheet.
A20: 8. Identify and document gaps in the Gap Analysis sheet with remediation plans.
... A25: Status Legend
A26: Symbol | B26: Status | C26: Description
A27: ✓ | B27: Compliant / Complete | C27: Requirement fully met
A28: ⚠ | B28: Partial / In Progress | C28: Partially met or in progress
A29: ✗ | B29: Non-Compliant / Not Started | C29: Requirement not met
A30: — | B30: Not Applicable | C30: Not applicable to this assessment

Sheet Services Catalog
A1: NETWORK SERVICES CATALOG - GENERATED 01.03.2026
A2: Master catalog of all network services. Yellow cells are input fields. Link to detailed assessments in service-specific sheets.
A3: Service ID | B3: Service Type | C3: Service Name | D3: Purpose | E3: Hosting Location | F3: IP Address | G3: Port(s) | H3: Criticality | I3: Redundancy Level | J3: Monitoring Status | K3: SLA Uptime % | L3: Owner | M3: Last Security Review | N3: Status | O3: Notes | P3: Assessment Link
A4: =IF(B4<>"","SVC-" & TEXT(1,"000"),"")
A5: =IF(B5<>"","SVC-" & TEXT(2,"000"),"")
A6: =IF(B6<>"","SVC-" & TEXT(3,"000"),"")
A7: =IF(B7<>"","SVC-" & TEXT(4,"000"),"")
A8: =IF(B8<>"","SVC-" & TEXT(5,"000"),"")
A9: =IF(B9<>"","SVC-" & TEXT(6,"000"),"")
A10: =IF(B10<>"","SVC-" & TEXT(7,"000"),"")
A11: =IF(B11<>"","SVC-" & TEXT(8,"000"),"")
A12: =IF(B12<>"","SVC-" & TEXT(9,"000"),"")
A13: =IF(B13<>"","SVC-" & TEXT(10,"000"),"")
A14: =IF(B14<>"","SVC-" & TEXT(11,"000"),"")
A15: =IF(B15<>"","SVC-" & TEXT(12,"000"),"")
A16: =IF(B16<>"","SVC-" & TEXT(13,"000"),"")
A17: =IF(B17<>"","SVC-" & TEXT(14,"000"),"")
A18: =IF(B18<>"","SVC-" & TEXT(15,"000"),"")
A19: =IF(B19<>"","SVC-" & TEXT(16,"000"),"")
A20: =IF(B20<>"","SVC-" & TEXT(17,"000"),"")
A21: =IF(B21<>"","SVC-" & TEXT(18,"000"),"")
A22: =IF(B22<>"","SVC-" & TEXT(19,"000"),"")
A23: =IF(B23<>"","SVC-" & TEXT(20,"000"),"")
A24: =IF(B24<>"","SVC-" & TEXT(21,"000"),"")
A25: =IF(B25<>"","SVC-" & TEXT(22,"000"),"")
A26: =IF(B26<>"","SVC-" & TEXT(23,"000"),"")
A27: =IF(B27<>"","SVC-" & TEXT(24,"000"),"")
A28: =IF(B28<>"","SVC-" & TEXT(25,"000"),"")
A29: =IF(B29<>"","SVC-" & TEXT(26,"000"),"")
A30: =IF(B30<>"","SVC-" & TEXT(27,"000"),"")
A31: =IF(B31<>"","SVC-" & TEXT(28,"000"),"")
A32: =IF(B32<>"","SVC-" & TEXT(29,"000"),"")
A33: =IF(B33<>"","SVC-" & TEXT(30,"000"),"")
A34: =IF(B34<>"","SVC-" & TEXT(31,"000"),"")
A35: =IF(B35<>"","SVC-" & TEXT(32,"000"),"")
A36: =IF(B36<>"","SVC-" & TEXT(33,"000"),"")
A37: =IF(B37<>"","SVC-" & TEXT(34,"000"),"")
A38: =IF(B38<>"","SVC-" & TEXT(35,"000"),"")
A39: =IF(B39<>"","SVC-" & TEXT(36,"000"),"")
A40: =IF(B40<>"","SVC-" & TEXT(37,"000"),"")
...

Sheet DNS Security Assessment
A1: DNS SECURITY ASSESSMENT
A2: Assess DNS security controls per IMP-S4 guidance. One row per DNS service instance.
A3: Service ID | B3: DNS Type | C3: DNSSEC Enabled | D3: Split DNS | E3: Rate Limiting | F3: Query Logging | G3: RPZ/Filtering | H3: Recursion Control | I3: Cache Poisoning Protection | J3: Zone Transfer Controls | K3: TSIG/SIG(0) | L3: Compliance Score % | M3: Last Assessed | N3: Notes
A4: DNS-001 | B4: Recursive | C4: Yes | D4: Yes | E4: Yes | F4: Yes | G4: Yes | H4: Yes | I4: Yes | J4: Yes | K4: Yes | L4: =IF(COUNTIF(C4:K4,"Yes")+COUNTIF(C4:K4,"No")=0,"",COUNTIF(C4:K4,"Yes")/(COUNTIF(C4:K4,"Yes")+COUNTIF(C4:K4,"No"))*100) | M4: 15.01.2026
L5: =IF(COUNTIF(C5:K5,"Yes")+COUNTIF(C5:K5,"No")=0,"",COUNTIF(C5:K5,"Yes")/(COUNTIF(C5:K5,"Yes")+COUNTIF(C5:K5,"No"))*100)
L6: =IF(COUNTIF(C6:K6,"Yes")+COUNTIF(C6:K6,"No")=0,"",COUNTIF(C6:K6,"Yes")/(COUNTIF(C6:K6,"Yes")+COUNTIF(C6:K6,"No"))*100)
L7: =IF(COUNTIF(C7:K7,"Yes")+COUNTIF(C7:K7,"No")=0,"",COUNTIF(C7:K7,"Yes")/(COUNTIF(C7:K7,"Yes")+COUNTIF(C7:K7,"No"))*100)
L8: =IF(COUNTIF(C8:K8,"Yes")+COUNTIF(C8:K8,"No")=0,"",COUNTIF(C8:K8,"Yes")/(COUNTIF(C8:K8,"Yes")+COUNTIF(C8:K8,"No"))*100)
L9: =IF(COUNTIF(C9:K9,"Yes")+COUNTIF(C9:K9,"No")=0,"",COUNTIF(C9:K9,"Yes")/(COUNTIF(C9:K9,"Yes")+COUNTIF(C9:K9,"No"))*100)
L10: =IF(COUNTIF(C10:K10,"Yes")+COUNTIF(C10:K10,"No")=0,"",COUNTIF(C10:K10,"Yes")/(COUNTIF(C10:K10,"Yes")+COUNTIF(C10:K10,"No"))*100)
L11: =IF(COUNTIF(C11:K11,"Yes")+COUNTIF(C11:K11,"No")=0,"",COUNTIF(C11:K11,"Yes")/(COUNTIF(C11:K11,"Yes")+COUNTIF(C11:K11,"No"))*100)
L12: =IF(COUNTIF(C12:K12,"Yes")+COUNTIF(C12:K12,"No")=0,"",COUNTIF(C12:K12,"Yes")/(COUNTIF(C12:K12,"Yes")+COUNTIF(C12:K12,"No"))*100)
L13: =IF(COUNTIF(C13:K13,"Yes")+COUNTIF(C13:K13,"No")=0,"",COUNTIF(C13:K13,"Yes")/(COUNTIF(C13:K13,"Yes")+COUNTIF(C13:K13,"No"))*100)
L14: =IF(COUNTIF(C14:K14,"Yes")+COUNTIF(C14:K14,"No")=0,"",COUNTIF(C14:K14,"Yes")/(COUNTIF(C14:K14,"Yes")+COUNTIF(C14:K14,"No"))*100)
L15: =IF(COUNTIF(C15:K15,"Yes")+COUNTIF(C15:K15,"No")=0,"",COUNTIF(C15:K15,"Yes")/(COUNTIF(C15:K15,"Yes")+COUNTIF(C15:K15,"No"))*100)
L16: =IF(COUNTIF(C16:K16,"Yes")+COUNTIF(C16:K16,"No")=0,"",COUNTIF(C16:K16,"Yes")/(COUNTIF(C16:K16,"Yes")+COUNTIF(C16:K16,"No"))*100)
... L54: =IF(COUNTIF(C54:K54,"Yes")+COUNTIF(C54:K54,"No")=0,"",COUNTIF(C54:K54,"Yes")/(COUNTIF(C54:K54,"Yes")+COUNTIF(C54:K54,"No"))*100)
A56: DNS Security Controls - Implementation Reference (per IMP-S4)
A57: Control | B57: Implementation Guidance
A58: DNSSEC | B58: Enable zone signing, publish DS records to parent, configure trust anchors
A59: Split DNS | B59: Internal view for private zones, external view for public zones
A60: Rate Limiting | B60: Configure response rate limiting (RRL) to prevent DDoS amplification
A61: Query Logging | B61: Enable query logging for security monitoring and forensics
A62: RPZ/Filtering | B62: Implement Response Policy Zones for malware/phishing domain blocking
A63: Recursion Control | B63: Disable recursion on authoritative servers, restrict recursive queries by ACL
A64: Cache Poisoning Protection | B64: Enable DNSSEC validation, source port randomization
A65: Zone Transfer Controls | B65: Restrict zone transfers (AXFR) to authorised secondary servers only
A66: TSIG/SIG(0) | B66: Use TSIG for authenticated zone transfers and dynamic updates

Sheet DHCP Security Assessment
A1: DHCP SECURITY ASSESSMENT
A2: Assess DHCP security controls per IMP-S4 guidance. One row per DHCP server/scope.
A3: Service ID | B3: DHCP Scope | C3: DHCP Snooping | D3: Rogue DHCP Detection | E3: Server Hardening | F3: Lease Time Appropriate | G3: Utilization Monitoring | H3: Reservation Management | I3: Logging Enabled | J3: Compliance Score % | K3: Last Assessed | L3: Notes
A4: DHCP-001 | B4: 192.168.1.0/24 | C4: Yes | D4: Yes | E4: Yes | F4: Yes | G4: Yes | H4: Yes | I4: Yes | J4: =IF(COUNTIF(C4:I4,"Yes")+COUNTIF(C4:I4,"No")=0,"",COUNTIF(C4:I4,"Yes")/(COUNTIF(C4:I4,"Yes")+COUNTIF(C4:I4,"No"))*100) | K4: 15.01.2026
J5: =IF(COUNTIF(C5:I5,"Yes")+COUNTIF(C5:I5,"No")=0,"",COUNTIF(C5:I5,"Yes")/(COUNTIF(C5:I5,"Yes")+COUNTIF(C5:I5,"No"))*100)
J6: =IF(COUNTIF(C6:I6,"Yes")+COUNTIF(C6:I6,"No")=0,"",COUNTIF(C6:I6,"Yes")/(COUNTIF(C6:I6,"Yes")+COUNTIF(C6:I6,"No"))*100)
J7: =IF(COUNTIF(C7:I7,"Yes")+COUNTIF(C7:I7,"No")=0,"",COUNTIF(C7:I7,"Yes")/(COUNTIF(C7:I7,"Yes")+COUNTIF(C7:I7,"No"))*100)
J8: =IF(COUNTIF(C8:I8,"Yes")+COUNTIF(C8:I8,"No")=0,"",COUNTIF(C8:I8,"Yes")/(COUNTIF(C8:I8,"Yes")+COUNTIF(C8:I8,"No"))*100)
J9: =IF(COUNTIF(C9:I9,"Yes")+COUNTIF(C9:I9,"No")=0,"",COUNTIF(C9:I9,"Yes")/(COUNTIF(C9:I9,"Yes")+COUNTIF(C9:I9,"No"))*100)
J10: =IF(COUNTIF(C10:I10,"Yes")+COUNTIF(C10:I10,"No")=0,"",COUNTIF(C10:I10,"Yes")/(COUNTIF(C10:I10,"Yes")+COUNTIF(C10:I10,"No"))*100)
J11: =IF(COUNTIF(C11:I11,"Yes")+COUNTIF(C11:I11,"No")=0,"",COUNTIF(C11:I11,"Yes")/(COUNTIF(C11:I11,"Yes")+COUNTIF(C11:I11,"No"))*100)
J12: =IF(COUNTIF(C12:I12,"Yes")+COUNTIF(C12:I12,"No")=0,"",COUNTIF(C12:I12,"Yes")/(COUNTIF(C12:I12,"Yes")+COUNTIF(C12:I12,"No"))*100)
J13: =IF(COUNTIF(C13:I13,"Yes")+COUNTIF(C13:I13,"No")=0,"",COUNTIF(C13:I13,"Yes")/(COUNTIF(C13:I13,"Yes")+COUNTIF(C13:I13,"No"))*100)
J14: =IF(COUNTIF(C14:I14,"Yes")+COUNTIF(C14:I14,"No")=0,"",COUNTIF(C14:I14,"Yes")/(COUNTIF(C14:I14,"Yes")+COUNTIF(C14:I14,"No"))*100)
J15: =IF(COUNTIF(C15:I15,"Yes")+COUNTIF(C15:I15,"No")=0,"",COUNTIF(C15:I15,"Yes")/(COUNTIF(C15:I15,"Yes")+COUNTIF(C15:I15,"No"))*100)
J16: =IF(COUNTIF(C16:I16,"Yes")+COUNTIF(C16:I16,"No")=0,"",COUNTIF(C16:I16,"Yes")/(COUNTIF(C16:I16,"Yes")+COUNTIF(C16:I16,"No"))*100)
... J54: =IF(COUNTIF(C54:I54,"Yes")+COUNTIF(C54:I54,"No")=0,"",COUNTIF(C54:I54,"Yes")/(COUNTIF(C54:I54,"Yes")+COUNTIF(C54:I54,"No"))*100)
A56: DHCP Security Controls - Implementation Reference
A57: Control | B57: Implementation Guidance
A58: DHCP Snooping | B58: Enable on access switches to prevent rogue DHCP servers
A59: Rogue Detection | B59: Active scanning or monitoring for unauthorised DHCP responses
A60: Server Hardening | B60: Apply OS hardening, disable unnecessary services, patch regularly
A61: Lease Time | B61: Appropriate lease time (8 hours workstations, 24 hours servers, 1 hour guest)
A62: Utilization Monitoring | B62: Monitor scope utilization, alert at 80% threshold
A63: Reservation Management | B63: Document static reservations, review regularly
A64: Logging | B64: Enable DHCP server logging for all lease actions

Sheet NTP Security Assessment
A1: NTP SECURITY ASSESSMENT
A2: Assess NTP security controls per IMP-S4 guidance. One row per NTP server/client.
A3: Service ID | B3: NTP Role | C3: Authentication | D3: Access Control | E3: Stratum Appropriate | F3: Source Validation | G3: Monitoring | H3: Compliance Score % | I3: Stratum Level | J3: Last Assessed | K3: Notes
A4: NTP-001 | B4: Server | C4: Yes | D4: Yes | E4: Yes | F4: Yes | G4: Yes | H4: =IF(COUNTIF(C4:G4,"Yes")+COUNTIF(C4:G4,"No")=0,"",COUNTIF(C4:G4,"Yes")/(COUNTIF(C4:G4,"Yes")+COUNTIF(C4:G4,"No"))*100) | I4: 2 | J4: 15.01.2026
H5: =IF(COUNTIF(C5:G5,"Yes")+COUNTIF(C5:G5,"No")=0,"",COUNTIF(C5:G5,"Yes")/(COUNTIF(C5:G5,"Yes")+COUNTIF(C5:G5,"No"))*100)
H6: =IF(COUNTIF(C6:G6,"Yes")+COUNTIF(C6:G6,"No")=0,"",COUNTIF(C6:G6,"Yes")/(COUNTIF(C6:G6,"Yes")+COUNTIF(C6:G6,"No"))*100)
H7: =IF(COUNTIF(C7:G7,"Yes")+COUNTIF(C7:G7,"No")=0,"",COUNTIF(C7:G7,"Yes")/(COUNTIF(C7:G7,"Yes")+COUNTIF(C7:G7,"No"))*100)
H8: =IF(COUNTIF(C8:G8,"Yes")+COUNTIF(C8:G8,"No")=0,"",COUNTIF(C8:G8,"Yes")/(COUNTIF(C8:G8,"Yes")+COUNTIF(C8:G8,"No"))*100)
H9: =IF(COUNTIF(C9:G9,"Yes")+COUNTIF(C9:G9,"No")=0,"",COUNTIF(C9:G9,"Yes")/(COUNTIF(C9:G9,"Yes")+COUNTIF(C9:G9,"No"))*100)
H10: =IF(COUNTIF(C10:G10,"Yes")+COUNTIF(C10:G10,"No")=0,"",COUNTIF(C10:G10,"Yes")/(COUNTIF(C10:G10,"Yes")+COUNTIF(C10:G10,"No"))*100)
H11: =IF(COUNTIF(C11:G11,"Yes")+COUNTIF(C11:G11,"No")=0,"",COUNTIF(C11:G11,"Yes")/(COUNTIF(C11:G11,"Yes")+COUNTIF(C11:G11,"No"))*100)
H12: =IF(COUNTIF(C12:G12,"Yes")+COUNTIF(C12:G12,"No")=0,"",COUNTIF(C12:G12,"Yes")/(COUNTIF(C12:G12,"Yes")+COUNTIF(C12:G12,"No"))*100)
H13: =IF(COUNTIF(C13:G13,"Yes")+COUNTIF(C13:G13,"No")=0,"",COUNTIF(C13:G13,"Yes")/(COUNTIF(C13:G13,"Yes")+COUNTIF(C13:G13,"No"))*100)
H14: =IF(COUNTIF(C14:G14,"Yes")+COUNTIF(C14:G14,"No")=0,"",COUNTIF(C14:G14,"Yes")/(COUNTIF(C14:G14,"Yes")+COUNTIF(C14:G14,"No"))*100)
H15: =IF(COUNTIF(C15:G15,"Yes")+COUNTIF(C15:G15,"No")=0,"",COUNTIF(C15:G15,"Yes")/(COUNTIF(C15:G15,"Yes")+COUNTIF(C15:G15,"No"))*100)
H16: =IF(COUNTIF(C16:G16,"Yes")+COUNTIF(C16:G16,"No")=0,"",COUNTIF(C16:G16,"Yes")/(COUNTIF(C16:G16,"Yes")+COUNTIF(C16:G16,"No"))*100)
... H54: =IF(COUNTIF(C54:G54,"Yes")+COUNTIF(C54:G54,"No")=0,"",COUNTIF(C54:G54,"Yes")/(COUNTIF(C54:G54,"Yes")+COUNTIF(C54:G54,"No"))*100)
A56: NTP Security Controls - Implementation Reference
A57: Control | B57: Implementation Guidance
A58: Authentication | B58: Enable NTP authentication (MD5 keys) between servers
A59: Access Control | B59: Restrict NTP queries and modifications (restrict default kod nomodify notrap)
A60: Stratum Hierarchy | B60: Appropriate stratum levels (Stratum 1/2 for internal servers)
A61: Source Validation | B61: Verify NTP server sources, use multiple reliable sources
A62: Monitoring | B62: Monitor time offset, alert on significant drift (>1 second)

Sheet Proxy Security Assessment
A1: PROXY/WEB FILTER SECURITY ASSESSMENT
A2: Assess Proxy/Web Filtering security controls per IMP-S4 guidance.
A3: Service ID | B3: Proxy Type | C3: Authentication | D3: SSL Inspection | E3: Category Filtering | F3: Malware Scanning | G3: Logging | H3: Bypass Prevention | I3: Redundancy | J3: Compliance Score % | K3: Last Assessed | L3: Filter Categories | M3: Notes
A4: PRXY-001 | B4: Forward | C4: Yes | D4: Yes | E4: Yes | F4: Yes | G4: Yes | H4: Yes | I4: Yes | J4: 100 | K4: 15.01.2026 | L4: Malware, Adult Content
J5: =IF(COUNTIF(C5:I5,"Yes")+COUNTIF(C5:I5,"No")=0,"",COUNTIF(C5:I5,"Yes")/(COUNTIF(C5:I5,"Yes")+COUNTIF(C5:I5,"No"))*100)
J6: =IF(COUNTIF(C6:I6,"Yes")+COUNTIF(C6:I6,"No")=0,"",COUNTIF(C6:I6,"Yes")/(COUNTIF(C6:I6,"Yes")+COUNTIF(C6:I6,"No"))*100)
J7: =IF(COUNTIF(C7:I7,"Yes")+COUNTIF(C7:I7,"No")=0,"",COUNTIF(C7:I7,"Yes")/(COUNTIF(C7:I7,"Yes")+COUNTIF(C7:I7,"No"))*100)
J8: =IF(COUNTIF(C8:I8,"Yes")+COUNTIF(C8:I8,"No")=0,"",COUNTIF(C8:I8,"Yes")/(COUNTIF(C8:I8,"Yes")+COUNTIF(C8:I8,"No"))*100)
J9: =IF(COUNTIF(C9:I9,"Yes")+COUNTIF(C9:I9,"No")=0,"",COUNTIF(C9:I9,"Yes")/(COUNTIF(C9:I9,"Yes")+COUNTIF(C9:I9,"No"))*100)
J10: =IF(COUNTIF(C10:I10,"Yes")+COUNTIF(C10:I10,"No")=0,"",COUNTIF(C10:I10,"Yes")/(COUNTIF(C10:I10,"Yes")+COUNTIF(C10:I10,"No"))*100)
J11: =IF(COUNTIF(C11:I11,"Yes")+COUNTIF(C11:I11,"No")=0,"",COUNTIF(C11:I11,"Yes")/(COUNTIF(C11:I11,"Yes")+COUNTIF(C11:I11,"No"))*100)
J12: =IF(COUNTIF(C12:I12,"Yes")+COUNTIF(C12:I12,"No")=0,"",COUNTIF(C12:I12,"Yes")/(COUNTIF(C12:I12,"Yes")+COUNTIF(C12:I12,"No"))*100)
J13: =IF(COUNTIF(C13:I13,"Yes")+COUNTIF(C13:I13,"No")=0,"",COUNTIF(C13:I13,"Yes")/(COUNTIF(C13:I13,"Yes")+COUNTIF(C13:I13,"No"))*100)
J14: =IF(COUNTIF(C14:I14,"Yes")+COUNTIF(C14:I14,"No")=0,"",COUNTIF(C14:I14,"Yes")/(COUNTIF(C14:I14,"Yes")+COUNTIF(C14:I14,"No"))*100)
J15: =IF(COUNTIF(C15:I15,"Yes")+COUNTIF(C15:I15,"No")=0,"",COUNTIF(C15:I15,"Yes")/(COUNTIF(C15:I15,"Yes")+COUNTIF(C15:I15,"No"))*100)
J16: =IF(COUNTIF(C16:I16,"Yes")+COUNTIF(C16:I16,"No")=0,"",COUNTIF(C16:I16,"Yes")/(COUNTIF(C16:I16,"Yes")+COUNTIF(C16:I16,"No"))*100)
... J54: =IF(COUNTIF(C54:I54,"Yes")+COUNTIF(C54:I54,"No")=0,"",COUNTIF(C54:I54,"Yes")/(COUNTIF(C54:I54,"Yes")+COUNTIF(C54:I54,"No"))*100)
A56: Proxy Security Controls - Implementation Reference
A57: Control | B57: Implementation Guidance
A58: Authentication | B58: LDAP/AD authentication, Kerberos/NTLM for transparent proxy
A59: SSL Inspection | B59: SSL/TLS decryption and inspection (with CA cert deployment)
A60: Category Filtering | B60: Block malicious/inappropriate categories (malware, adult, gambling, etc.)
A61: Malware Scanning | B61: Real-time malware scanning of downloaded content
A62: Logging | B62: Log all requests with user, URL, timestamp, action (allow/block)
A63: Bypass Prevention | B63: Block direct internet access, enforce proxy via firewall rules
A64: Redundancy | B64: High availability configuration (multiple proxy servers)

Sheet Additional Services
A1: ADDITIONAL NETWORK SERVICES ASSESSMENT
A2: Assess other network services: Load Balancers, AAA (RADIUS/TACACS+), SNMP, Syslog, SMTP, FTP, etc.
A3: Service ID | B3: Service Type | C3: Authentication | D3: Encryption | E3: Access Control | F3: Logging | G3: Monitoring | H3: Hardening Applied | I3: Compliance Score % | J3: Last Assessed | K3: Key Controls | L3: Notes
A4: SVC-001 | B4: RADIUS/AAA | C4: Yes | D4: Yes | E4: Yes | F4: Yes | G4: Yes | H4: Yes | I4: 100 | J4: 15.01.2026 | K4: TACACS+, SNMPv3
I5: =IF(COUNTIF(C5:H5,"Yes")+COUNTIF(C5:H5,"No")=0,"",COUNTIF(C5:H5,"Yes")/(COUNTIF(C5:H5,"Yes")+COUNTIF(C5:H5,"No"))*100)
I6: =IF(COUNTIF(C6:H6,"Yes")+COUNTIF(C6:H6,"No")=0,"",COUNTIF(C6:H6,"Yes")/(COUNTIF(C6:H6,"Yes")+COUNTIF(C6:H6,"No"))*100)
I7: =IF(COUNTIF(C7:H7,"Yes")+COUNTIF(C7:H7,"No")=0,"",COUNTIF(C7:H7,"Yes")/(COUNTIF(C7:H7,"Yes")+COUNTIF(C7:H7,"No"))*100)
I8: =IF(COUNTIF(C8:H8,"Yes")+COUNTIF(C8:H8,"No")=0,"",COUNTIF(C8:H8,"Yes")/(COUNTIF(C8:H8,"Yes")+COUNTIF(C8:H8,"No"))*100)
I9: =IF(COUNTIF(C9:H9,"Yes")+COUNTIF(C9:H9,"No")=0,"",COUNTIF(C9:H9,"Yes")/(COUNTIF(C9:H9,"Yes")+COUNTIF(C9:H9,"No"))*100)
I10: =IF(COUNTIF(C10:H10,"Yes")+COUNTIF(C10:H10,"No")=0,"",COUNTIF(C10:H10,"Yes")/(COUNTIF(C10:H10,"Yes")+COUNTIF(C10:H10,"No"))*100)
I11: =IF(COUNTIF(C11:H11,"Yes")+COUNTIF(C11:H11,"No")=0,"",COUNTIF(C11:H11,"Yes")/(COUNTIF(C11:H11,"Yes")+COUNTIF(C11:H11,"No"))*100)
I12: =IF(COUNTIF(C12:H12,"Yes")+COUNTIF(C12:H12,"No")=0,"",COUNTIF(C12:H12,"Yes")/(COUNTIF(C12:H12,"Yes")+COUNTIF(C12:H12,"No"))*100)
I13: =IF(COUNTIF(C13:H13,"Yes")+COUNTIF(C13:H13,"No")=0,"",COUNTIF(C13:H13,"Yes")/(COUNTIF(C13:H13,"Yes")+COUNTIF(C13:H13,"No"))*100)
I14: =IF(COUNTIF(C14:H14,"Yes")+COUNTIF(C14:H14,"No")=0,"",COUNTIF(C14:H14,"Yes")/(COUNTIF(C14:H14,"Yes")+COUNTIF(C14:H14,"No"))*100)
I15: =IF(COUNTIF(C15:H15,"Yes")+COUNTIF(C15:H15,"No")=0,"",COUNTIF(C15:H15,"Yes")/(COUNTIF(C15:H15,"Yes")+COUNTIF(C15:H15,"No"))*100)
I16: =IF(COUNTIF(C16:H16,"Yes")+COUNTIF(C16:H16,"No")=0,"",COUNTIF(C16:H16,"Yes")/(COUNTIF(C16:H16,"Yes")+COUNTIF(C16:H16,"No"))*100)
... I54: =IF(COUNTIF(C54:H54,"Yes")+COUNTIF(C54:H54,"No")=0,"",COUNTIF(C54:H54,"Yes")/(COUNTIF(C54:H54,"Yes")+COUNTIF(C54:H54,"No"))*100)
A56: Service-Specific Security Controls Reference
A57: Service Type | B57: Key Security Controls
A58: Load Balancer | B58: SSL/TLS termination, strong ciphers, health checks, session persistence security, DDoS protection
A59: RADIUS/TACACS+ | B59: Strong authentication, command authorisation (TACACS+), encrypted communication, MFA support, logging
A60: SNMP | B60: SNMPv3 only (v1/v2c disabled), authentication (authPriv), encryption, access control, trap security
A61: Syslog | B61: TLS encryption (rsyslog/syslog-ng), log retention policy, log rotation, integrity protection
A62: SMTP Relay | B62: Authentication required, relay restrictions, SPF/DKIM/DMARC, TLS encryption, rate limiting
A63: FTP/SFTP | B63: Use SFTP (SSH), disable FTP, strong authentication, access control, logging

Sheet Gap Analysis
A1: SERVICE SECURITY GAPS - REMEDIATION TRACKING
A2: Document all service security gaps (missing controls, misconfigurations). Track remediation progress.
A3: Gap ID | B3: Service ID | C3: Service Type | D3: Security Gap | E3: Current State | F3: Severity | G3: Remediation Plan | H3: Owner | I3: Status | J3: Target Date
A4: SVC-GAP-001 | B4: SVC-001 | C4: DNS | D4: No DNSSEC validation on internal resolver | E4: DNS cache poisoning possible on corporate resolver | F4: High | G4: Enable DNSSEC validation on all internal DNS resolvers | H4: Network Team | I4: Open | J4: 28.02.2026
A5: =IF(B5<>"","SVC-GAP-" & TEXT(2,"000"),"")
A6: =IF(B6<>"","SVC-GAP-" & TEXT(3,"000"),"")
A7: =IF(B7<>"","SVC-GAP-" & TEXT(4,"000"),"")
A8: =IF(B8<>"","SVC-GAP-" & TEXT(5,"000"),"")
A9: =IF(B9<>"","SVC-GAP-" & TEXT(6,"000"),"")
A10: =IF(B10<>"","SVC-GAP-" & TEXT(7,"000"),"")
A11: =IF(B11<>"","SVC-GAP-" & TEXT(8,"000"),"")
A12: =IF(B12<>"","SVC-GAP-" & TEXT(9,"000"),"")
A13: =IF(B13<>"","SVC-GAP-" & TEXT(10,"000"),"")
A14: =IF(B14<>"","SVC-GAP-" & TEXT(11,"000"),"")
A15: =IF(B15<>"","SVC-GAP-" & TEXT(12,"000"),"")
A16: =IF(B16<>"","SVC-GAP-" & TEXT(13,"000"),"")
A17: =IF(B17<>"","SVC-GAP-" & TEXT(14,"000"),"")
A18: =IF(B18<>"","SVC-GAP-" & TEXT(15,"000"),"")
A19: =IF(B19<>"","SVC-GAP-" & TEXT(16,"000"),"")
A20: =IF(B20<>"","SVC-GAP-" & TEXT(17,"000"),"")
A21: =IF(B21<>"","SVC-GAP-" & TEXT(18,"000"),"")
A22: =IF(B22<>"","SVC-GAP-" & TEXT(19,"000"),"")
A23: =IF(B23<>"","SVC-GAP-" & TEXT(20,"000"),"")
A24: =IF(B24<>"","SVC-GAP-" & TEXT(21,"000"),"")
A25: =IF(B25<>"","SVC-GAP-" & TEXT(22,"000"),"")
A26: =IF(B26<>"","SVC-GAP-" & TEXT(23,"000"),"")
A27: =IF(B27<>"","SVC-GAP-" & TEXT(24,"000"),"")
A28: =IF(B28<>"","SVC-GAP-" & TEXT(25,"000"),"")
A29: =IF(B29<>"","SVC-GAP-" & TEXT(26,"000"),"")
A30: =IF(B30<>"","SVC-GAP-" & TEXT(27,"000"),"")
A31: =IF(B31<>"","SVC-GAP-" & TEXT(28,"000"),"")
A32: =IF(B32<>"","SVC-GAP-" & TEXT(29,"000"),"")
A33: =IF(B33<>"","SVC-GAP-" & TEXT(30,"000"),"")
A34: =IF(B34<>"","SVC-GAP-" & TEXT(31,"000"),"")
A35: =IF(B35<>"","SVC-GAP-" & TEXT(32,"000"),"")
A36: =IF(B36<>"","SVC-GAP-" & TEXT(33,"000"),"")
A37: =IF(B37<>"","SVC-GAP-" & TEXT(34,"000"),"")
A38: =IF(B38<>"","SVC-GAP-" & TEXT(35,"000"),"")
A39: =IF(B39<>"","SVC-GAP-" & TEXT(36,"000"),"")
A40: =IF(B40<>"","SVC-GAP-" & TEXT(37,"000"),"")
...

Sheet Service Dependencies
A1: SERVICE DEPENDENCIES MAPPING
A2: Map service dependencies to understand impact of service failures.
A3: Service ID | B3: Service Name | C3: Depends On | D3: Required By | E3: Impact of Failure | F3: Notes
A4: SVC-DEP-001 | B4: DNS (Primary) | C4: NTP-001 | D4: Active Directory, Email, Web Apps | E4: High availability — all name resolution fails if DNS fails
A56: Common Service Dependencies - Examples
A57: Service | B57: Typical Dependencies
A58: Active Directory | B58: Depends On: DNS, NTP, DHCP (optional)
A59: Email (Exchange/O365) | B59: Depends On: DNS, Active Directory, Network Connectivity
A60: Web Applications | B60: Depends On: DNS, Load Balancer, Database, Authentication (LDAP/AD)
A61: VPN Access | B61: Depends On: RADIUS/TACACS+, Active Directory, DNS
A62: DHCP | B62: Depends On: Network connectivity (usually no dependencies)
A63: DNS | B63: Depends On: Network connectivity, NTP (for DNSSEC)

Sheet Evidence Register
A1: EVIDENCE REGISTER
A2: List all evidence files/documents referenced in this assessment (audit traceability).
A4: Evidence ID | B4: Assessment Area | C4: Evidence Type | D4: Description | E4: Location/Path | F4: Date Collected | G4: Collected By | H4: Verification Status
A5: EV-001 | B5: Network Services Assessment | C5: Configuration file | D5: DNS/DHCP/NTP service configuration exports and security assessment records | E5: /evidence/A.8.20-22/ | F5: 15.01.2026 | G5: Assessor Name | H5: ✅ Verified

Sheet Summary Dashboard
A1: NETWORK SERVICES CATALOG & SECURITY ASSESSMENT — SUMMARY DASHBOARD
A2: ISO/IEC 27001:2022 — Controls A.8.20 · A.8.21 · A.8.22: Network Security, Security of Network Services and Segregation of Networks
A4: TABLE 1: ASSESSMENT AREA COMPLIANCE
A5: Assessment Area | B5: Total | C5: Yes | D5: Partial | E5: No | F5: N-A | G5: Compliance %
A6: DNS Security Assessment | B6: =COUNTA('DNS Security Assessment'!A5:A54) | C6: =COUNTIF('DNS Security Assessment'!L5:L54,">=80") | D6: =COUNTIFS('DNS Security Assessment'!L5:L54,">=50",'DNS Security Assessment'!L5:L54,"<80") | E6: =COUNTIFS('DNS Security Assessment'!L5:L54,">=0",'DNS Security Assessment'!L5:L54,"<50") | F6: =B6-(C6+D6+E6) | G6: =IF((B6-F6)=0,"0%",ROUND(C6/(B6-F6)*100,1)&"%")
A7: DHCP Security Assessment | B7: =COUNTA('DHCP Security Assessment'!C5:I54) | C7: =COUNTIF('DHCP Security Assessment'!C5:I54,"Yes") | E7: =COUNTIF('DHCP Security Assessment'!C5:I54,"No") | F7: =COUNTIF('DHCP Security Assessment'!C5:I54,"N/A") | G7: =IF((B7-F7)=0,"0%",ROUND(C7/(B7-F7)*100,1)&"%")
A8: NTP Security Assessment | B8: =COUNTA('NTP Security Assessment'!C5:G54) | C8: =COUNTIF('NTP Security Assessment'!C5:G54,"Yes") | E8: =COUNTIF('NTP Security Assessment'!C5:G54,"No") | F8: =COUNTIF('NTP Security Assessment'!C5:G54,"N/A") | G8: =IF((B8-F8)=0,"0%",ROUND(C8/(B8-F8)*100,1)&"%")
A9: Proxy Security Assessment | B9: =COUNTA('Proxy Security Assessment'!C5:I54) | C9: =COUNTIF('Proxy Security Assessment'!C5:I54,"Yes") | E9: =COUNTIF('Proxy Security Assessment'!C5:I54,"No") | F9: =COUNTIF('Proxy Security Assessment'!C5:I54,"N/A") | G9: =IF((B9-F9)=0,"0%",ROUND(C9/(B9-F9)*100,1)&"%")
A10: Additional Services | B10: =COUNTA('Additional Services'!C5:H54) | C10: =COUNTIF('Additional Services'!C5:H54,"Yes") | E10: =COUNTIF('Additional Services'!C5:H54,"No") | F10: =COUNTIF('Additional Services'!C5:H54,"N/A") | G10: =IF((B10-F10)=0,"0%",ROUND(C10/(B10-F10)*100,1)&"%")
A11: Gap Analysis | B11: =COUNTA('Gap Analysis'!B5:B53) | C11: =COUNTIF('Gap Analysis'!I5:I53,"Resolved") | D11: =COUNTIF('Gap Analysis'!I5:I53,"In Progress") | E11: =COUNTIF('Gap Analysis'!I5:I53,"Open") | F11: =B11-(C11+D11+E11) | G11: =IF((B11-F11)=0,"0%",ROUND(C11/(B11-F11)*100,1)&"%")
A12: TOTAL | B12: =SUM(B6:B11) | C12: =SUM(C6:C11) | D12: =SUM(D6:D11) | E12: =SUM(E6:E11) | F12: =SUM(F6:F11) | G12: =IF((B12-F12)=0,"0%",ROUND(C12/(B12-F12)*100,1)&"%")
A14: TABLE 2: KEY METRICS
A15: Metric | B15: Value | C15: What This Shows
A16: DNS Services Below 80% | B16: =COUNTIFS('DNS Security Assessment'!L5:L54,">=0",'DNS Security Assessment'!L5:L54,"<80") | C16: DNS services below 80% compliance (DNSSEC, logging, and filtering gaps)
A17: NTP Services Below Threshold | B17: =COUNTIFS('NTP Security Assessment'!H5:H54,">=0",'NTP Security Assessment'!H5:H54,"<80") | C17: NTP services below 80% (authentication and authorisation gaps)
A18: DHCP Services Below Threshold | B18: =COUNTIFS('DHCP Security Assessment'!J5:J54,">=0",'DHCP Security Assessment'!J5:J54,"<80") | C18: DHCP services below 80% (snooping, rogue DHCP prevention gaps)
A19: Unmonitored Services | B19: =COUNTIF('Services Catalog'!J5:J104,"Not Monitored") | C19: Network services not monitored (blind spots in security posture)
A20: Critical Services Count | B20: =COUNTIF('Services Catalog'!H5:H104,"Critical") | C20: Total critical services requiring priority security attention
A21: Open Service Security Gaps | B21: =COUNTIF('Gap Analysis'!I5:I53,"Open") | C21: Outstanding service security gaps without remediation
A22: Critical Gap Count | B22: =COUNTIF('Gap Analysis'!F5:F53,"Critical") | C22: Critical-severity service security gaps requiring immediate action
A23: Overall Compliance Rate | B23: =G12 | C23: Overall network services security compliance percentage (TABLE 1 total)
A25: TABLE 3: CRITICAL FINDINGS
A26: Critical Finding Type | B26: Count | C26: Filter Instructions
A27: DNS Services Below 80% | B27: =COUNTIFS('DNS Security Assessment'!L5:L54,">=0",'DNS Security Assessment'!L5:L54,"<80") | C27: Filter DNS Security Assessment: Score < 80
A28: Critical Severity Service Gaps | B28: =COUNTIF('Gap Analysis'!F5:F53,"Critical") | C28: Filter Gap Analysis: Severity = "Critical"
A29: Open Service Security Gaps | B29: =COUNTIF('Gap Analysis'!I5:I53,"Open") | C29: Filter Gap Analysis: Status = "Open"
A30: Unmonitored Critical Services | B30: =COUNTIFS('Services Catalog'!H5:H104,"Critical",'Services Catalog'!J5:J104,"Not Monitored") | C30: Filter Services Catalog: Criticality = "Critical" AND Monitoring = "Not Monitored"
A31: NTP/DHCP Services Below Threshold | B31: =COUNTIFS('NTP Security Assessment'!H5:H54,">=0",'NTP Security Assessment'!H5:H54,"<80")+COUNTIFS('DHCP Security Assessment'!J5:J54,">=0",'DHCP Security Assessment'!J5:J54,"<80") | C31: Filter NTP sheet: Score < 80; or filter DHCP sheet: Score < 80
A32: TOTAL | B32: =SUM(B27:B31) | C32: Total critical findings requiring immediate remediation

Sheet Approval Sign-Off
A1: ASSESSMENT APPROVAL AND SIGN-OFF
A3: ASSESSMENT SUMMARY
A4: Document: | B4: ISMS-IMP-A.8.20-21-22.S3 - Network Services Catalog & Security Assessment
A5: Assessment Period:
A6: Overall Compliance: | B6: =IFERROR(AVERAGE('Summary Dashboard'!G6:G11),"")
A7: Assessment Status:
A10: COMPLETED BY (NETWORK ENGINEERING)
A11: Name:
A12: Title:
A13: Date:
A14: Signature:
A15: Comments:
A17: REVIEWED BY (ISO)
A18: Name:
A19: Title:
A20: Date:
A21: Signature:
... A37: Special Considerations:
