Workbook

Sheet Instructions & Legend
A1: ISMS-IMP-A.8.20-22.S1 - Network Infrastructure Inventory ISO/IEC 27001:2022 - Control A.8.20-22: Network Security
A3: Document Information
A4: Document ID | B4: ISMS-IMP-A.8.20-22.S1
A5: Workbook Title | B5: Network Infrastructure Inventory
A6: Control Reference | B6: ISO/IEC 27001:2022 - Control A.8.20-22: Network Security
A7: Version | B7: 1.0
A8: Assessment Date
A9: Completed By
A10: Organisation
A12: Instructions
A13: 1. Complete the Device Inventory sheet for every network device in scope.
A14: 2. Use dropdown menus for standardised assessments (device type, status, criticality).
A15: 3. Assess device criticality using the Device Criticality Matrix framework.
A16: 4. Review the Device Type Summary for coverage statistics across device categories.
A17: 5. Document discovery metadata and methodology in the Discovery Metadata sheet.
A18: 6. Identify and document gaps in the Gap Analysis sheet with remediation plans.
A19: 7. Review the Validation Rules sheet for data quality checks.
A20: 8. Maintain the Evidence Register with all supporting documentation for audit traceability.
... A23: Status Legend
A24: Symbol | B24: Status | C24: Description
A25: ✓ | B25: Compliant / Complete | C25: Requirement fully met
A26: ⚠ | B26: Partial / In Progress | C26: Partially met or in progress
A27: ✗ | B27: Non-Compliant / Not Started | C27: Requirement not met
A28: — | B28: Not Applicable | C28: Not applicable to this assessment

Sheet Device Inventory
A1: NETWORK INFRASTRUCTURE INVENTORY - GENERATED 10.03.2026
A2: Complete inventory for all network devices discovered per IMP-S1. Yellow cells are input fields. Device IDs auto-generate.
A3: Device ID | B3: Device Type | C3: Make/Model | D3: Hostname | E3: Primary IP | F3: Management IP | G3: Location | H3: Security Zone | I3: Purpose | J3: Criticality | K3: Owner | L3: Last Discovered | M3: Discovery Method | N3: Firmware Version | O3: Serial Number | P3: Compliance Status | Q3: Status | R3: Notes
A4: NET-DEV-001 | B4: Router | C4: Cisco ISR 4451 | D4: core-rtr-01 | E4: 192.168.1.1 | F4: 192.168.1.250 | G4: Server Room Rack 1 | H4: Management | I4: Core routing and inter-VLAN routing | J4: Critical | K4: IT Infrastructure Team | L4: 01.01.2026 | M4: Network Scan | N4: 15.3.8a | O4: FTX12345678 | P4: Compliant | Q4: Active
A5: =IF(B5<>"","NET-DEV-" & TEXT(2,"000"),"")
A6: =IF(B6<>"","NET-DEV-" & TEXT(3,"000"),"")
A7: =IF(B7<>"","NET-DEV-" & TEXT(4,"000"),"")
A8: =IF(B8<>"","NET-DEV-" & TEXT(5,"000"),"")
A9: =IF(B9<>"","NET-DEV-" & TEXT(6,"000"),"")
A10: =IF(B10<>"","NET-DEV-" & TEXT(7,"000"),"")
A11: =IF(B11<>"","NET-DEV-" & TEXT(8,"000"),"")
A12: =IF(B12<>"","NET-DEV-" & TEXT(9,"000"),"")
A13: =IF(B13<>"","NET-DEV-" & TEXT(10,"000"),"")
A14: =IF(B14<>"","NET-DEV-" & TEXT(11,"000"),"")
A15: =IF(B15<>"","NET-DEV-" & TEXT(12,"000"),"")
A16: =IF(B16<>"","NET-DEV-" & TEXT(13,"000"),"")
A17: =IF(B17<>"","NET-DEV-" & TEXT(14,"000"),"")
A18: =IF(B18<>"","NET-DEV-" & TEXT(15,"000"),"")
A19: =IF(B19<>"","NET-DEV-" & TEXT(16,"000"),"")
A20: =IF(B20<>"","NET-DEV-" & TEXT(17,"000"),"")
A21: =IF(B21<>"","NET-DEV-" & TEXT(18,"000"),"")
A22: =IF(B22<>"","NET-DEV-" & TEXT(19,"000"),"")
A23: =IF(B23<>"","NET-DEV-" & TEXT(20,"000"),"")
A24: =IF(B24<>"","NET-DEV-" & TEXT(21,"000"),"")
A25: =IF(B25<>"","NET-DEV-" & TEXT(22,"000"),"")
A26: =IF(B26<>"","NET-DEV-" & TEXT(23,"000"),"")
A27: =IF(B27<>"","NET-DEV-" & TEXT(24,"000"),"")
A28: =IF(B28<>"","NET-DEV-" & TEXT(25,"000"),"")
A29: =IF(B29<>"","NET-DEV-" & TEXT(26,"000"),"")
A30: =IF(B30<>"","NET-DEV-" & TEXT(27,"000"),"")
A31: =IF(B31<>"","NET-DEV-" & TEXT(28,"000"),"")
A32: =IF(B32<>"","NET-DEV-" & TEXT(29,"000"),"")
A33: =IF(B33<>"","NET-DEV-" & TEXT(30,"000"),"")
A34: =IF(B34<>"","NET-DEV-" & TEXT(31,"000"),"")
A35: =IF(B35<>"","NET-DEV-" & TEXT(32,"000"),"")
A36: =IF(B36<>"","NET-DEV-" & TEXT(33,"000"),"")
A37: =IF(B37<>"","NET-DEV-" & TEXT(34,"000"),"")
A38: =IF(B38<>"","NET-DEV-" & TEXT(35,"000"),"")
A39: =IF(B39<>"","NET-DEV-" & TEXT(36,"000"),"")
A40: =IF(B40<>"","NET-DEV-" & TEXT(37,"000"),"")
...

Sheet Device Criticality Matrix
A1: DEVICE CRITICALITY ASSESSMENT MATRIX
A2: Use this matrix to assess device criticality based on business impact if device fails
A4: Assessment Criteria
A5: Criticality | B5: Service Impact | C5: Recovery Time | D5: User Impact | E5: Revenue Impact | F5: Redundancy
A6: Critical | B6: Complete outage of critical services | C6: < 1 hour | D6: All users affected | E6: Significant revenue loss | F6: Single point of failure
A7: High | B7: Significant service degradation | C7: < 4 hours | D7: Large user group affected | E7: Notable revenue impact | F7: Limited redundancy
A8: Medium | B8: Localized service impact | C8: < 24 hours | D8: Department/team affected | E8: Minimal revenue impact | F8: Redundant but important
A9: Low | B9: Minimal or no service impact | C9: > 24 hours acceptable | D9: Few users affected | E9: No revenue impact | F9: Fully redundant or non-critical
A11: Device Type - Typical Criticality Mapping (Guidance Only)
A12: Device Type | B12: Typical Criticality | C12: Rationale
A13: Core Router | B13: Critical | C13: Single point of failure for all WAN/Internet traffic
A14: Core Switch | B14: Critical | C14: Aggregates all access layer traffic
A15: Primary Firewall | B15: Critical | C15: Controls all ingress/egress traffic
A16: Datacenter Switch | B16: Critical | C16: Connects production servers
A17: Distribution Switch | B17: High | C17: Aggregates multiple access switches
A18: WAN Router | B18: High | C18: Connects branch to HQ
A19: Secondary Firewall | B19: High | C19: Backup for primary firewall
A20: Access Switch | B20: Medium | C20: Localized impact (single floor/department)
A21: Wireless AP | B21: Medium | C21: Affects wireless users only
A22: Management Device | B22: Medium | C22: Does not forward production traffic
A23: Guest Wi-Fi AP | B23: Low | C23: Non-business critical
A24: Lab Equipment | B24: Low | C24: Test/development only
A26: ⚠️ Important: Criticality assessment must consider YOUR organisation's specific context, not just device type. Always assess based on business impact.

Sheet Device Type Summary
A1: DEVICE TYPE SUMMARY & STATISTICS
A2: Categorise network device types, record counts and compliance status. One row per device category.
A3: Device Type | B3: Total Count | C3: Active | D3: Offline | E3: Critical Count | F3: Compliant Count | G3: Compliance % | H3: Notes
A4: Router | B4: =IF(A4="","",COUNTIF('Device Inventory'!B5:B153,A4)) | C4: =IF(A4="","",COUNTIFS('Device Inventory'!B5:B153,A4,'Device Inventory'!Q5:Q153,"Active")) | D4: =IF(A4="","",COUNTIFS('Device Inventory'!B5:B153,A4,'Device Inventory'!Q5:Q153,"Offline")) | E4: =IF(A4="","",COUNTIFS('Device Inventory'!B5:B153,A4,'Device Inventory'!J5:J153,"Critical")) | F4: =IF(A4="","",COUNTIFS('Device Inventory'!B5:B153,A4,'Device Inventory'!P5:P153,"Compliant")) | G4: =IF(OR(A4="",B4=0),"",F4/B4*100)
B5: =IF(A5="","",COUNTIF('Device Inventory'!B5:B153,A5)) | C5: =IF(A5="","",COUNTIFS('Device Inventory'!B5:B153,A5,'Device Inventory'!Q5:Q153,"Active")) | D5: =IF(A5="","",COUNTIFS('Device Inventory'!B5:B153,A5,'Device Inventory'!Q5:Q153,"Offline")) | E5: =IF(A5="","",COUNTIFS('Device Inventory'!B5:B153,A5,'Device Inventory'!J5:J153,"Critical")) | F5: =IF(A5="","",COUNTIFS('Device Inventory'!B5:B153,A5,'Device Inventory'!P5:P153,"Compliant")) | G5: =IF(OR(A5="",B5=0),"",F5/B5*100)
B6: =IF(A6="","",COUNTIF('Device Inventory'!B5:B153,A6)) | C6: =IF(A6="","",COUNTIFS('Device Inventory'!B5:B153,A6,'Device Inventory'!Q5:Q153,"Active")) | D6: =IF(A6="","",COUNTIFS('Device Inventory'!B5:B153,A6,'Device Inventory'!Q5:Q153,"Offline")) | E6: =IF(A6="","",COUNTIFS('Device Inventory'!B5:B153,A6,'Device Inventory'!J5:J153,"Critical")) | F6: =IF(A6="","",COUNTIFS('Device Inventory'!B5:B153,A6,'Device Inventory'!P5:P153,"Compliant")) | G6: =IF(OR(A6="",B6=0),"",F6/B6*100)
B7: =IF(A7="","",COUNTIF('Device Inventory'!B5:B153,A7)) | C7: =IF(A7="","",COUNTIFS('Device Inventory'!B5:B153,A7,'Device Inventory'!Q5:Q153,"Active")) | D7: =IF(A7="","",COUNTIFS('Device Inventory'!B5:B153,A7,'Device Inventory'!Q5:Q153,"Offline")) | E7: =IF(A7="","",COUNTIFS('Device Inventory'!B5:B153,A7,'Device Inventory'!J5:J153,"Critical")) | F7: =IF(A7="","",COUNTIFS('Device Inventory'!B5:B153,A7,'Device Inventory'!P5:P153,"Compliant")) | G7: =IF(OR(A7="",B7=0),"",F7/B7*100)
B8: =IF(A8="","",COUNTIF('Device Inventory'!B5:B153,A8)) | C8: =IF(A8="","",COUNTIFS('Device Inventory'!B5:B153,A8,'Device Inventory'!Q5:Q153,"Active")) | D8: =IF(A8="","",COUNTIFS('Device Inventory'!B5:B153,A8,'Device Inventory'!Q5:Q153,"Offline")) | E8: =IF(A8="","",COUNTIFS('Device Inventory'!B5:B153,A8,'Device Inventory'!J5:J153,"Critical")) | F8: =IF(A8="","",COUNTIFS('Device Inventory'!B5:B153,A8,'Device Inventory'!P5:P153,"Compliant")) | G8: =IF(OR(A8="",B8=0),"",F8/B8*100)
B9: =IF(A9="","",COUNTIF('Device Inventory'!B5:B153,A9)) | C9: =IF(A9="","",COUNTIFS('Device Inventory'!B5:B153,A9,'Device Inventory'!Q5:Q153,"Active")) | D9: =IF(A9="","",COUNTIFS('Device Inventory'!B5:B153,A9,'Device Inventory'!Q5:Q153,"Offline")) | E9: =IF(A9="","",COUNTIFS('Device Inventory'!B5:B153,A9,'Device Inventory'!J5:J153,"Critical")) | F9: =IF(A9="","",COUNTIFS('Device Inventory'!B5:B153,A9,'Device Inventory'!P5:P153,"Compliant")) | G9: =IF(OR(A9="",B9=0),"",F9/B9*100)
B10: =IF(A10="","",COUNTIF('Device Inventory'!B5:B153,A10)) | C10: =IF(A10="","",COUNTIFS('Device Inventory'!B5:B153,A10,'Device Inventory'!Q5:Q153,"Active")) | D10: =IF(A10="","",COUNTIFS('Device Inventory'!B5:B153,A10,'Device Inventory'!Q5:Q153,"Offline")) | E10: =IF(A10="","",COUNTIFS('Device Inventory'!B5:B153,A10,'Device Inventory'!J5:J153,"Critical")) | F10: =IF(A10="","",COUNTIFS('Device Inventory'!B5:B153,A10,'Device Inventory'!P5:P153,"Compliant")) | G10: =IF(OR(A10="",B10=0),"",F10/B10*100)
B11: =IF(A11="","",COUNTIF('Device Inventory'!B5:B153,A11)) | C11: =IF(A11="","",COUNTIFS('Device Inventory'!B5:B153,A11,'Device Inventory'!Q5:Q153,"Active")) | D11: =IF(A11="","",COUNTIFS('Device Inventory'!B5:B153,A11,'Device Inventory'!Q5:Q153,"Offline")) | E11: =IF(A11="","",COUNTIFS('Device Inventory'!B5:B153,A11,'Device Inventory'!J5:J153,"Critical")) | F11: =IF(A11="","",COUNTIFS('Device Inventory'!B5:B153,A11,'Device Inventory'!P5:P153,"Compliant")) | G11: =IF(OR(A11="",B11=0),"",F11/B11*100)
B12: =IF(A12="","",COUNTIF('Device Inventory'!B5:B153,A12)) | C12: =IF(A12="","",COUNTIFS('Device Inventory'!B5:B153,A12,'Device Inventory'!Q5:Q153,"Active")) | D12: =IF(A12="","",COUNTIFS('Device Inventory'!B5:B153,A12,'Device Inventory'!Q5:Q153,"Offline")) | E12: =IF(A12="","",COUNTIFS('Device Inventory'!B5:B153,A12,'Device Inventory'!J5:J153,"Critical")) | F12: =IF(A12="","",COUNTIFS('Device Inventory'!B5:B153,A12,'Device Inventory'!P5:P153,"Compliant")) | G12: =IF(OR(A12="",B12=0),"",F12/B12*100)
B13: =IF(A13="","",COUNTIF('Device Inventory'!B5:B153,A13)) | C13: =IF(A13="","",COUNTIFS('Device Inventory'!B5:B153,A13,'Device Inventory'!Q5:Q153,"Active")) | D13: =IF(A13="","",COUNTIFS('Device Inventory'!B5:B153,A13,'Device Inventory'!Q5:Q153,"Offline")) | E13: =IF(A13="","",COUNTIFS('Device Inventory'!B5:B153,A13,'Device Inventory'!J5:J153,"Critical")) | F13: =IF(A13="","",COUNTIFS('Device Inventory'!B5:B153,A13,'Device Inventory'!P5:P153,"Compliant")) | G13: =IF(OR(A13="",B13=0),"",F13/B13*100)
B14: =IF(A14="","",COUNTIF('Device Inventory'!B5:B153,A14)) | C14: =IF(A14="","",COUNTIFS('Device Inventory'!B5:B153,A14,'Device Inventory'!Q5:Q153,"Active")) | D14: =IF(A14="","",COUNTIFS('Device Inventory'!B5:B153,A14,'Device Inventory'!Q5:Q153,"Offline")) | E14: =IF(A14="","",COUNTIFS('Device Inventory'!B5:B153,A14,'Device Inventory'!J5:J153,"Critical")) | F14: =IF(A14="","",COUNTIFS('Device Inventory'!B5:B153,A14,'Device Inventory'!P5:P153,"Compliant")) | G14: =IF(OR(A14="",B14=0),"",F14/B14*100)
B15: =IF(A15="","",COUNTIF('Device Inventory'!B5:B153,A15)) | C15: =IF(A15="","",COUNTIFS('Device Inventory'!B5:B153,A15,'Device Inventory'!Q5:Q153,"Active")) | D15: =IF(A15="","",COUNTIFS('Device Inventory'!B5:B153,A15,'Device Inventory'!Q5:Q153,"Offline")) | E15: =IF(A15="","",COUNTIFS('Device Inventory'!B5:B153,A15,'Device Inventory'!J5:J153,"Critical")) | F15: =IF(A15="","",COUNTIFS('Device Inventory'!B5:B153,A15,'Device Inventory'!P5:P153,"Compliant")) | G15: =IF(OR(A15="",B15=0),"",F15/B15*100)
B16: =IF(A16="","",COUNTIF('Device Inventory'!B5:B153,A16)) | C16: =IF(A16="","",COUNTIFS('Device Inventory'!B5:B153,A16,'Device Inventory'!Q5:Q153,"Active")) | D16: =IF(A16="","",COUNTIFS('Device Inventory'!B5:B153,A16,'Device Inventory'!Q5:Q153,"Offline")) | E16: =IF(A16="","",COUNTIFS('Device Inventory'!B5:B153,A16,'Device Inventory'!J5:J153,"Critical")) | F16: =IF(A16="","",COUNTIFS('Device Inventory'!B5:B153,A16,'Device Inventory'!P5:P153,"Compliant")) | G16: =IF(OR(A16="",B16=0),"",F16/B16*100)
B17: =IF(A17="","",COUNTIF('Device Inventory'!B5:B153,A17)) | C17: =IF(A17="","",COUNTIFS('Device Inventory'!B5:B153,A17,'Device Inventory'!Q5:Q153,"Active")) | D17: =IF(A17="","",COUNTIFS('Device Inventory'!B5:B153,A17,'Device Inventory'!Q5:Q153,"Offline")) | E17: =IF(A17="","",COUNTIFS('Device Inventory'!B5:B153,A17,'Device Inventory'!J5:J153,"Critical")) | F17: =IF(A17="","",COUNTIFS('Device Inventory'!B5:B153,A17,'Device Inventory'!P5:P153,"Compliant")) | G17: =IF(OR(A17="",B17=0),"",F17/B17*100)
B18: =IF(A18="","",COUNTIF('Device Inventory'!B5:B153,A18)) | C18: =IF(A18="","",COUNTIFS('Device Inventory'!B5:B153,A18,'Device Inventory'!Q5:Q153,"Active")) | D18: =IF(A18="","",COUNTIFS('Device Inventory'!B5:B153,A18,'Device Inventory'!Q5:Q153,"Offline")) | E18: =IF(A18="","",COUNTIFS('Device Inventory'!B5:B153,A18,'Device Inventory'!J5:J153,"Critical")) | F18: =IF(A18="","",COUNTIFS('Device Inventory'!B5:B153,A18,'Device Inventory'!P5:P153,"Compliant")) | G18: =IF(OR(A18="",B18=0),"",F18/B18*100)
B19: =IF(A19="","",COUNTIF('Device Inventory'!B5:B153,A19)) | C19: =IF(A19="","",COUNTIFS('Device Inventory'!B5:B153,A19,'Device Inventory'!Q5:Q153,"Active")) | D19: =IF(A19="","",COUNTIFS('Device Inventory'!B5:B153,A19,'Device Inventory'!Q5:Q153,"Offline")) | E19: =IF(A19="","",COUNTIFS('Device Inventory'!B5:B153,A19,'Device Inventory'!J5:J153,"Critical")) | F19: =IF(A19="","",COUNTIFS('Device Inventory'!B5:B153,A19,'Device Inventory'!P5:P153,"Compliant")) | G19: =IF(OR(A19="",B19=0),"",F19/B19*100)
B20: =IF(A20="","",COUNTIF('Device Inventory'!B5:B153,A20)) | C20: =IF(A20="","",COUNTIFS('Device Inventory'!B5:B153,A20,'Device Inventory'!Q5:Q153,"Active")) | D20: =IF(A20="","",COUNTIFS('Device Inventory'!B5:B153,A20,'Device Inventory'!Q5:Q153,"Offline")) | E20: =IF(A20="","",COUNTIFS('Device Inventory'!B5:B153,A20,'Device Inventory'!J5:J153,"Critical")) | F20: =IF(A20="","",COUNTIFS('Device Inventory'!B5:B153,A20,'Device Inventory'!P5:P153,"Compliant")) | G20: =IF(OR(A20="",B20=0),"",F20/B20*100)
B21: =IF(A21="","",COUNTIF('Device Inventory'!B5:B153,A21)) | C21: =IF(A21="","",COUNTIFS('Device Inventory'!B5:B153,A21,'Device Inventory'!Q5:Q153,"Active")) | D21: =IF(A21="","",COUNTIFS('Device Inventory'!B5:B153,A21,'Device Inventory'!Q5:Q153,"Offline")) | E21: =IF(A21="","",COUNTIFS('Device Inventory'!B5:B153,A21,'Device Inventory'!J5:J153,"Critical")) | F21: =IF(A21="","",COUNTIFS('Device Inventory'!B5:B153,A21,'Device Inventory'!P5:P153,"Compliant")) | G21: =IF(OR(A21="",B21=0),"",F21/B21*100)
B22: =IF(A22="","",COUNTIF('Device Inventory'!B5:B153,A22)) | C22: =IF(A22="","",COUNTIFS('Device Inventory'!B5:B153,A22,'Device Inventory'!Q5:Q153,"Active")) | D22: =IF(A22="","",COUNTIFS('Device Inventory'!B5:B153,A22,'Device Inventory'!Q5:Q153,"Offline")) | E22: =IF(A22="","",COUNTIFS('Device Inventory'!B5:B153,A22,'Device Inventory'!J5:J153,"Critical")) | F22: =IF(A22="","",COUNTIFS('Device Inventory'!B5:B153,A22,'Device Inventory'!P5:P153,"Compliant")) | G22: =IF(OR(A22="",B22=0),"",F22/B22*100)
B23: =IF(A23="","",COUNTIF('Device Inventory'!B5:B153,A23)) | C23: =IF(A23="","",COUNTIFS('Device Inventory'!B5:B153,A23,'Device Inventory'!Q5:Q153,"Active")) | D23: =IF(A23="","",COUNTIFS('Device Inventory'!B5:B153,A23,'Device Inventory'!Q5:Q153,"Offline")) | E23: =IF(A23="","",COUNTIFS('Device Inventory'!B5:B153,A23,'Device Inventory'!J5:J153,"Critical")) | F23: =IF(A23="","",COUNTIFS('Device Inventory'!B5:B153,A23,'Device Inventory'!P5:P153,"Compliant")) | G23: =IF(OR(A23="",B23=0),"",F23/B23*100)
B24: =IF(A24="","",COUNTIF('Device Inventory'!B5:B153,A24)) | C24: =IF(A24="","",COUNTIFS('Device Inventory'!B5:B153,A24,'Device Inventory'!Q5:Q153,"Active")) | D24: =IF(A24="","",COUNTIFS('Device Inventory'!B5:B153,A24,'Device Inventory'!Q5:Q153,"Offline")) | E24: =IF(A24="","",COUNTIFS('Device Inventory'!B5:B153,A24,'Device Inventory'!J5:J153,"Critical")) | F24: =IF(A24="","",COUNTIFS('Device Inventory'!B5:B153,A24,'Device Inventory'!P5:P153,"Compliant")) | G24: =IF(OR(A24="",B24=0),"",F24/B24*100)
B25: =IF(A25="","",COUNTIF('Device Inventory'!B5:B153,A25)) | C25: =IF(A25="","",COUNTIFS('Device Inventory'!B5:B153,A25,'Device Inventory'!Q5:Q153,"Active")) | D25: =IF(A25="","",COUNTIFS('Device Inventory'!B5:B153,A25,'Device Inventory'!Q5:Q153,"Offline")) | E25: =IF(A25="","",COUNTIFS('Device Inventory'!B5:B153,A25,'Device Inventory'!J5:J153,"Critical")) | F25: =IF(A25="","",COUNTIFS('Device Inventory'!B5:B153,A25,'Device Inventory'!P5:P153,"Compliant")) | G25: =IF(OR(A25="",B25=0),"",F25/B25*100)
B26: =IF(A26="","",COUNTIF('Device Inventory'!B5:B153,A26)) | C26: =IF(A26="","",COUNTIFS('Device Inventory'!B5:B153,A26,'Device Inventory'!Q5:Q153,"Active")) | D26: =IF(A26="","",COUNTIFS('Device Inventory'!B5:B153,A26,'Device Inventory'!Q5:Q153,"Offline")) | E26: =IF(A26="","",COUNTIFS('Device Inventory'!B5:B153,A26,'Device Inventory'!J5:J153,"Critical")) | F26: =IF(A26="","",COUNTIFS('Device Inventory'!B5:B153,A26,'Device Inventory'!P5:P153,"Compliant")) | G26: =IF(OR(A26="",B26=0),"",F26/B26*100)
B27: =IF(A27="","",COUNTIF('Device Inventory'!B5:B153,A27)) | C27: =IF(A27="","",COUNTIFS('Device Inventory'!B5:B153,A27,'Device Inventory'!Q5:Q153,"Active")) | D27: =IF(A27="","",COUNTIFS('Device Inventory'!B5:B153,A27,'Device Inventory'!Q5:Q153,"Offline")) | E27: =IF(A27="","",COUNTIFS('Device Inventory'!B5:B153,A27,'Device Inventory'!J5:J153,"Critical")) | F27: =IF(A27="","",COUNTIFS('Device Inventory'!B5:B153,A27,'Device Inventory'!P5:P153,"Compliant")) | G27: =IF(OR(A27="",B27=0),"",F27/B27*100)
B28: =IF(A28="","",COUNTIF('Device Inventory'!B5:B153,A28)) | C28: =IF(A28="","",COUNTIFS('Device Inventory'!B5:B153,A28,'Device Inventory'!Q5:Q153,"Active")) | D28: =IF(A28="","",COUNTIFS('Device Inventory'!B5:B153,A28,'Device Inventory'!Q5:Q153,"Offline")) | E28: =IF(A28="","",COUNTIFS('Device Inventory'!B5:B153,A28,'Device Inventory'!J5:J153,"Critical")) | F28: =IF(A28="","",COUNTIFS('Device Inventory'!B5:B153,A28,'Device Inventory'!P5:P153,"Compliant")) | G28: =IF(OR(A28="",B28=0),"",F28/B28*100)
B29: =IF(A29="","",COUNTIF('Device Inventory'!B5:B153,A29)) | C29: =IF(A29="","",COUNTIFS('Device Inventory'!B5:B153,A29,'Device Inventory'!Q5:Q153,"Active")) | D29: =IF(A29="","",COUNTIFS('Device Inventory'!B5:B153,A29,'Device Inventory'!Q5:Q153,"Offline")) | E29: =IF(A29="","",COUNTIFS('Device Inventory'!B5:B153,A29,'Device Inventory'!J5:J153,"Critical")) | F29: =IF(A29="","",COUNTIFS('Device Inventory'!B5:B153,A29,'Device Inventory'!P5:P153,"Compliant")) | G29: =IF(OR(A29="",B29=0),"",F29/B29*100)
B30: =IF(A30="","",COUNTIF('Device Inventory'!B5:B153,A30)) | C30: =IF(A30="","",COUNTIFS('Device Inventory'!B5:B153,A30,'Device Inventory'!Q5:Q153,"Active")) | D30: =IF(A30="","",COUNTIFS('Device Inventory'!B5:B153,A30,'Device Inventory'!Q5:Q153,"Offline")) | E30: =IF(A30="","",COUNTIFS('Device Inventory'!B5:B153,A30,'Device Inventory'!J5:J153,"Critical")) | F30: =IF(A30="","",COUNTIFS('Device Inventory'!B5:B153,A30,'Device Inventory'!P5:P153,"Compliant")) | G30: =IF(OR(A30="",B30=0),"",F30/B30*100)
B31: =IF(A31="","",COUNTIF('Device Inventory'!B5:B153,A31)) | C31: =IF(A31="","",COUNTIFS('Device Inventory'!B5:B153,A31,'Device Inventory'!Q5:Q153,"Active")) | D31: =IF(A31="","",COUNTIFS('Device Inventory'!B5:B153,A31,'Device Inventory'!Q5:Q153,"Offline")) | E31: =IF(A31="","",COUNTIFS('Device Inventory'!B5:B153,A31,'Device Inventory'!J5:J153,"Critical")) | F31: =IF(A31="","",COUNTIFS('Device Inventory'!B5:B153,A31,'Device Inventory'!P5:P153,"Compliant")) | G31: =IF(OR(A31="",B31=0),"",F31/B31*100)
B32: =IF(A32="","",COUNTIF('Device Inventory'!B5:B153,A32)) | C32: =IF(A32="","",COUNTIFS('Device Inventory'!B5:B153,A32,'Device Inventory'!Q5:Q153,"Active")) | D32: =IF(A32="","",COUNTIFS('Device Inventory'!B5:B153,A32,'Device Inventory'!Q5:Q153,"Offline")) | E32: =IF(A32="","",COUNTIFS('Device Inventory'!B5:B153,A32,'Device Inventory'!J5:J153,"Critical")) | F32: =IF(A32="","",COUNTIFS('Device Inventory'!B5:B153,A32,'Device Inventory'!P5:P153,"Compliant")) | G32: =IF(OR(A32="",B32=0),"",F32/B32*100)
B33: =IF(A33="","",COUNTIF('Device Inventory'!B5:B153,A33)) | C33: =IF(A33="","",COUNTIFS('Device Inventory'!B5:B153,A33,'Device Inventory'!Q5:Q153,"Active")) | D33: =IF(A33="","",COUNTIFS('Device Inventory'!B5:B153,A33,'Device Inventory'!Q5:Q153,"Offline")) | E33: =IF(A33="","",COUNTIFS('Device Inventory'!B5:B153,A33,'Device Inventory'!J5:J153,"Critical")) | F33: =IF(A33="","",COUNTIFS('Device Inventory'!B5:B153,A33,'Device Inventory'!P5:P153,"Compliant")) | G33: =IF(OR(A33="",B33=0),"",F33/B33*100)
B34: =IF(A34="","",COUNTIF('Device Inventory'!B5:B153,A34)) | C34: =IF(A34="","",COUNTIFS('Device Inventory'!B5:B153,A34,'Device Inventory'!Q5:Q153,"Active")) | D34: =IF(A34="","",COUNTIFS('Device Inventory'!B5:B153,A34,'Device Inventory'!Q5:Q153,"Offline")) | E34: =IF(A34="","",COUNTIFS('Device Inventory'!B5:B153,A34,'Device Inventory'!J5:J153,"Critical")) | F34: =IF(A34="","",COUNTIFS('Device Inventory'!B5:B153,A34,'Device Inventory'!P5:P153,"Compliant")) | G34: =IF(OR(A34="",B34=0),"",F34/B34*100)
B35: =IF(A35="","",COUNTIF('Device Inventory'!B5:B153,A35)) | C35: =IF(A35="","",COUNTIFS('Device Inventory'!B5:B153,A35,'Device Inventory'!Q5:Q153,"Active")) | D35: =IF(A35="","",COUNTIFS('Device Inventory'!B5:B153,A35,'Device Inventory'!Q5:Q153,"Offline")) | E35: =IF(A35="","",COUNTIFS('Device Inventory'!B5:B153,A35,'Device Inventory'!J5:J153,"Critical")) | F35: =IF(A35="","",COUNTIFS('Device Inventory'!B5:B153,A35,'Device Inventory'!P5:P153,"Compliant")) | G35: =IF(OR(A35="",B35=0),"",F35/B35*100)
B36: =IF(A36="","",COUNTIF('Device Inventory'!B5:B153,A36)) | C36: =IF(A36="","",COUNTIFS('Device Inventory'!B5:B153,A36,'Device Inventory'!Q5:Q153,"Active")) | D36: =IF(A36="","",COUNTIFS('Device Inventory'!B5:B153,A36,'Device Inventory'!Q5:Q153,"Offline")) | E36: =IF(A36="","",COUNTIFS('Device Inventory'!B5:B153,A36,'Device Inventory'!J5:J153,"Critical")) | F36: =IF(A36="","",COUNTIFS('Device Inventory'!B5:B153,A36,'Device Inventory'!P5:P153,"Compliant")) | G36: =IF(OR(A36="",B36=0),"",F36/B36*100)
B37: =IF(A37="","",COUNTIF('Device Inventory'!B5:B153,A37)) | C37: =IF(A37="","",COUNTIFS('Device Inventory'!B5:B153,A37,'Device Inventory'!Q5:Q153,"Active")) | D37: =IF(A37="","",COUNTIFS('Device Inventory'!B5:B153,A37,'Device Inventory'!Q5:Q153,"Offline")) | E37: =IF(A37="","",COUNTIFS('Device Inventory'!B5:B153,A37,'Device Inventory'!J5:J153,"Critical")) | F37: =IF(A37="","",COUNTIFS('Device Inventory'!B5:B153,A37,'Device Inventory'!P5:P153,"Compliant")) | G37: =IF(OR(A37="",B37=0),"",F37/B37*100)
B38: =IF(A38="","",COUNTIF('Device Inventory'!B5:B153,A38)) | C38: =IF(A38="","",COUNTIFS('Device Inventory'!B5:B153,A38,'Device Inventory'!Q5:Q153,"Active")) | D38: =IF(A38="","",COUNTIFS('Device Inventory'!B5:B153,A38,'Device Inventory'!Q5:Q153,"Offline")) | E38: =IF(A38="","",COUNTIFS('Device Inventory'!B5:B153,A38,'Device Inventory'!J5:J153,"Critical")) | F38: =IF(A38="","",COUNTIFS('Device Inventory'!B5:B153,A38,'Device Inventory'!P5:P153,"Compliant")) | G38: =IF(OR(A38="",B38=0),"",F38/B38*100)
B39: =IF(A39="","",COUNTIF('Device Inventory'!B5:B153,A39)) | C39: =IF(A39="","",COUNTIFS('Device Inventory'!B5:B153,A39,'Device Inventory'!Q5:Q153,"Active")) | D39: =IF(A39="","",COUNTIFS('Device Inventory'!B5:B153,A39,'Device Inventory'!Q5:Q153,"Offline")) | E39: =IF(A39="","",COUNTIFS('Device Inventory'!B5:B153,A39,'Device Inventory'!J5:J153,"Critical")) | F39: =IF(A39="","",COUNTIFS('Device Inventory'!B5:B153,A39,'Device Inventory'!P5:P153,"Compliant")) | G39: =IF(OR(A39="",B39=0),"",F39/B39*100)
B40: =IF(A40="","",COUNTIF('Device Inventory'!B5:B153,A40)) | C40: =IF(A40="","",COUNTIFS('Device Inventory'!B5:B153,A40,'Device Inventory'!Q5:Q153,"Active")) | D40: =IF(A40="","",COUNTIFS('Device Inventory'!B5:B153,A40,'Device Inventory'!Q5:Q153,"Offline")) | E40: =IF(A40="","",COUNTIFS('Device Inventory'!B5:B153,A40,'Device Inventory'!J5:J153,"Critical")) | F40: =IF(A40="","",COUNTIFS('Device Inventory'!B5:B153,A40,'Device Inventory'!P5:P153,"Compliant")) | G40: =IF(OR(A40="",B40=0),"",F40/B40*100)
...

Sheet Discovery Metadata
A1: NETWORK DISCOVERY PROCESS METADATA
A2: Document the discovery methodology, scope, and tools used to identify all network devices.
A3: Discovery Project Information
A4: Project Name: | B4: [Enter discovery project name]
A5: Start Date: | B5: [DD.MM.YYYY]
A6: Completion Date: | B6: [DD.MM.YYYY]
A7: Lead Assessor: | B7: [Name]
A8: Team Members: | B8: [Names]
A9: Scope: | B9: [Network segments/locations covered]
A11: Discovery Methods Used
A12: Method | B12: Used (Y/N) | C12: Tool/Platform | D12: Coverage | E12: Notes
A13: Nmap Network Scan | C13: nmap
A14: SNMP Walk | C14: SNMPwalk
A15: AWS Discovery | C15: AWS CLI / boto3
A16: Azure Discovery | C16: Azure CLI
A17: GCP Discovery | C17: GCP SDK
A18: NetFlow Analysis
A19: Documentation Review | C19: CMDB / Wiki
A20: Administrator Interviews | C20: N/A
A21: Physical Site Survey | C21: N/A
A22: Other
A24: Discovery Scope
A25: Network Segment/Zone | B25: IP Range | C25: Included (Y/N) | D25: Devices Found | E25: Notes
A47: Discovery Challenges & Limitations
A48: [DOCUMENT ANY CHALLENGES ENCOUNTERED DURING DISCOVERY: - UNREACHABLE NETWORKS - FIREWALL BLOCKING SCANS - MISSING CREDENTIALS - UNDOCUMENTED DEVICES - OTHER LIMITATIONS]

Sheet Gap Analysis
A1: NETWORK DISCOVERY GAP ANALYSIS
A2: Document gaps: undocumented devices, unreachable devices, missing information, or discovery failures
A3: Gap ID | B3: Gap Type | C3: Device/Location | D3: Description | E3: Severity | F3: Impact | G3: Remediation Plan | H3: Owner | I3: Status | J3: Target Date
A4: DISC-GAP-001 | B4: Missing Device | C4: 192.168.10.0/24 subnet | D4: Undocumented switch discovered during network scan — not in inventory | E4: High | F4: Potential unauthorised device accessing internal network | G4: Identify device, classify, assign owner, add to inventory | H4: Network Team | I4: ⭕ Open | J4: 31.03.2026
A5: =IF(B5<>"","DISC-GAP-" & TEXT(2,"000"),"")
A6: =IF(B6<>"","DISC-GAP-" & TEXT(3,"000"),"")
A7: =IF(B7<>"","DISC-GAP-" & TEXT(4,"000"),"")
A8: =IF(B8<>"","DISC-GAP-" & TEXT(5,"000"),"")
A9: =IF(B9<>"","DISC-GAP-" & TEXT(6,"000"),"")
A10: =IF(B10<>"","DISC-GAP-" & TEXT(7,"000"),"")
A11: =IF(B11<>"","DISC-GAP-" & TEXT(8,"000"),"")
A12: =IF(B12<>"","DISC-GAP-" & TEXT(9,"000"),"")
A13: =IF(B13<>"","DISC-GAP-" & TEXT(10,"000"),"")
A14: =IF(B14<>"","DISC-GAP-" & TEXT(11,"000"),"")
A15: =IF(B15<>"","DISC-GAP-" & TEXT(12,"000"),"")
A16: =IF(B16<>"","DISC-GAP-" & TEXT(13,"000"),"")
A17: =IF(B17<>"","DISC-GAP-" & TEXT(14,"000"),"")
A18: =IF(B18<>"","DISC-GAP-" & TEXT(15,"000"),"")
A19: =IF(B19<>"","DISC-GAP-" & TEXT(16,"000"),"")
A20: =IF(B20<>"","DISC-GAP-" & TEXT(17,"000"),"")
A21: =IF(B21<>"","DISC-GAP-" & TEXT(18,"000"),"")
A22: =IF(B22<>"","DISC-GAP-" & TEXT(19,"000"),"")
A23: =IF(B23<>"","DISC-GAP-" & TEXT(20,"000"),"")
A24: =IF(B24<>"","DISC-GAP-" & TEXT(21,"000"),"")
A25: =IF(B25<>"","DISC-GAP-" & TEXT(22,"000"),"")
A26: =IF(B26<>"","DISC-GAP-" & TEXT(23,"000"),"")
A27: =IF(B27<>"","DISC-GAP-" & TEXT(24,"000"),"")
A28: =IF(B28<>"","DISC-GAP-" & TEXT(25,"000"),"")
A29: =IF(B29<>"","DISC-GAP-" & TEXT(26,"000"),"")
A30: =IF(B30<>"","DISC-GAP-" & TEXT(27,"000"),"")
A31: =IF(B31<>"","DISC-GAP-" & TEXT(28,"000"),"")
A32: =IF(B32<>"","DISC-GAP-" & TEXT(29,"000"),"")
A33: =IF(B33<>"","DISC-GAP-" & TEXT(30,"000"),"")
A34: =IF(B34<>"","DISC-GAP-" & TEXT(31,"000"),"")
A35: =IF(B35<>"","DISC-GAP-" & TEXT(32,"000"),"")
A36: =IF(B36<>"","DISC-GAP-" & TEXT(33,"000"),"")
A37: =IF(B37<>"","DISC-GAP-" & TEXT(34,"000"),"")
A38: =IF(B38<>"","DISC-GAP-" & TEXT(35,"000"),"")
A39: =IF(B39<>"","DISC-GAP-" & TEXT(36,"000"),"")
A40: =IF(B40<>"","DISC-GAP-" & TEXT(37,"000"),"")
...

Sheet Validation Rules
A1: DATA VALIDATION RULES & QUALITY CHECKS
A2: This sheet defines data quality rules to ensure inventory completeness and accuracy
A4: Required Field Validation
A5: Field | B5: Required | C5: Validation Rule | D5: Status
A6: Device Type | B6: Yes | C6: Must be selected from dropdown | D6: =IF(COUNTBLANK('Device Inventory'!B5:B153)=149,"✔ All blank (OK)","⚠ Check required")
A7: Hostname | B7: Yes | C7: Must not be blank | D7: =IF(COUNTBLANK('Device Inventory'!D5:D153)=149,"✔ All blank (OK)","⚠ Check required")
A8: Primary IP | B8: Yes | C8: Must not be blank | D8: =IF(COUNTBLANK('Device Inventory'!E5:E153)=149,"✔ All blank (OK)","⚠ Check required")
A9: Location | B9: Yes | C9: Must not be blank | D9: =IF(COUNTBLANK('Device Inventory'!G5:G153)=149,"✔ All blank (OK)","⚠ Check required")
A10: Criticality | B10: Yes | C10: Must be selected from dropdown | D10: =IF(COUNTBLANK('Device Inventory'!J5:J153)=149,"✔ All blank (OK)","⚠ Check required")
A11: Status | B11: Yes | C11: Must be selected from dropdown | D11: =IF(COUNTBLANK('Device Inventory'!Q5:Q153)=149,"✔ All blank (OK)","⚠ Check required")
A13: Data Quality Checks
A14: Check | B14: Description | C14: Status
A15: No Duplicate IPs | B15: Check for duplicate primary IPs | C15: Manual verification required
A16: No Duplicate Hostnames | B16: Check for duplicate hostnames | C16: Manual verification required
A17: Valid IP Format | B17: Verify all IPs follow IPv4 format | C17: Manual verification required
A18: Criticality Assigned | B18: All active devices have criticality | C18: =IF(COUNTIFS('Device Inventory'!Q5:Q153,"Active",'Device Inventory'!J5:J153,"")=0,"✔ OK","⚠ Missing criticality")
A19: Owner Assigned | B19: All critical/high devices have owner | C19: Manual verification required
A20: Recent Discovery | B20: All devices discovered within last 90 days | C20: Manual verification required
A22: Inventory Completeness Metrics
A23: Metric | B23: Target | C23: Actual | D23: Status
A24: Device Type Filled | B24: 100% | C24: =COUNTA('Device Inventory'!B5:B153)/COUNTA('Device Inventory'!B5:B153) | D24: =IF(C24>=1,"✔","⚠ ")
A25: Hostname Filled | B25: 100% | C25: =COUNTA('Device Inventory'!D5:D153)/COUNTA('Device Inventory'!B5:B153) | D25: =IF(C25>=1,"✔","⚠ ")
A26: Criticality Assigned | B26: 100% | C26: =COUNTA('Device Inventory'!J5:J153)/COUNTA('Device Inventory'!B5:B153) | D26: =IF(C26>=1,"✔","⚠ ")
A27: Owner Assigned | B27: ≥80% | C27: =COUNTA('Device Inventory'!K5:K153)/COUNTA('Device Inventory'!B5:B153) | D27: =IF(C27>=0.8,"✔","⚠ ")
A28: Firmware Version | B28: ≥70% | C28: =COUNTA('Device Inventory'!N5:N153)/COUNTA('Device Inventory'!B5:B153) | D28: =IF(C28>=0.7,"✔","⚠ ")

Sheet Evidence Register
A1: EVIDENCE REGISTER
A2: List all evidence files/documents referenced in this assessment (audit traceability).
A4: Evidence ID | B4: Assessment Area | C4: Evidence Type | D4: Description | E4: Location/Path | F4: Date Collected | G4: Collected By | H4: Verification Status
A5: EV-001 | B5: Network Infrastructure Inventory | C5: Network scan | D5: Network device discovery scan results and inventory compliance assessment | E5: /evidence/A.8.20-22/ | F5: 15.01.2026 | G5: Assessor Name | H5: ✅ Verified

Sheet Summary Dashboard
A1: NETWORK INFRASTRUCTURE INVENTORY — SUMMARY DASHBOARD
A2: ISO/IEC 27001:2022 — Controls A.8.20 · A.8.21 · A.8.22: Network Security, Security of Network Services and Segregation of Networks
A4: TABLE 1: ASSESSMENT AREA COMPLIANCE
A5: Assessment Area | B5: Total | C5: Yes | D5: Partial | E5: No | F5: N-A | G5: Compliance %
A6: Device Inventory | B6: =COUNTA('Device Inventory'!B5:B153) | C6: =COUNTIF('Device Inventory'!P5:P153,"Compliant") | D6: =COUNTIF('Device Inventory'!P5:P153,"⚠️ Partial") | E6: =COUNTIF('Device Inventory'!P5:P153,"Non-Compliant") | F6: =B6-(C6+D6+E6) | G6: =IF((B6-F6)=0,"0%",ROUND(C6/(B6-F6)*100,1)&"%")
A7: Gap Analysis | B7: =COUNTA('Gap Analysis'!B5:B53) | C7: =COUNTIF('Gap Analysis'!I5:I53,"Resolved") | D7: =COUNTIF('Gap Analysis'!I5:I53,"In Progress") | E7: =COUNTIF('Gap Analysis'!I5:I53,"⭕ Open") | F7: =B7-(C7+D7+E7) | G7: =IF((B7-F7)=0,"0%",ROUND(C7/(B7-F7)*100,1)&"%")
A8: TOTAL | B8: =SUM(B6:B7) | C8: =SUM(C6:C7) | D8: =SUM(D6:D7) | E8: =SUM(E6:E7) | F8: =SUM(F6:F7) | G8: =IF((B8-F8)=0,"0%",ROUND(C8/(B8-F8)*100,1)&"%")
A10: TABLE 2: KEY METRICS
A11: Metric | B11: Value | C11: What This Shows
A12: Non-Compliant Devices | B12: =COUNTIF('Device Inventory'!P5:P153,"Non-Compliant") | C12: Devices not meeting security requirements (immediate remediation required)
A13: Partial Compliance Devices | B13: =COUNTIF('Device Inventory'!P5:P153,"⚠️ Partial") | C13: Devices partially compliant (incomplete protection)
A14: Undiscovered / Not Assessed | B14: =COUNTIF('Device Inventory'!P5:P153,"❓ Not Assessed") | C14: Devices in scope but not yet assessed (unknown security posture)
A15: Critical Devices Non-Compliant | B15: =COUNTIFS('Device Inventory'!J5:J153,"Critical",'Device Inventory'!P5:P153,"Non-Compliant") | C15: Critical infrastructure with compliance gaps (highest risk)
A16: Offline Devices | B16: =COUNTIF('Device Inventory'!Q5:Q153,"Offline") | C16: Devices not reachable for assessment (potential inventory gaps)
A17: Open Discovery Gaps | B17: =COUNTIF('Gap Analysis'!I5:I53,"⭕ Open") | C17: Outstanding gaps in device discovery (incomplete network inventory)
A18: Critical Severity Gaps | B18: =COUNTIF('Gap Analysis'!E5:E53,"Critical") | C18: Critical-severity discovery gaps requiring immediate attention
A19: Overall Compliance Rate | B19: =G8 | C19: Overall network inventory compliance percentage (TABLE 1 total)
A21: TABLE 3: CRITICAL FINDINGS
A22: Critical Finding Type | B22: Count | C22: Filter Instructions
A23: Non-Compliant Devices | B23: =COUNTIF('Device Inventory'!P5:P153,"Non-Compliant") | C23: Filter Device Inventory: Compliance Status = "Non-Compliant"
A24: Critical Devices Non-Compliant | B24: =COUNTIFS('Device Inventory'!J5:J153,"Critical",'Device Inventory'!P5:P153,"Non-Compliant") | C24: Filter Device Inventory: Criticality = "Critical" AND Compliance = "Non-Compliant"
A25: Open Discovery Gaps | B25: =COUNTIF('Gap Analysis'!I5:I53,"⭕ Open") | C25: Filter Gap Analysis: Status = "⭕ Open"
A26: Critical Severity Gaps | B26: =COUNTIF('Gap Analysis'!E5:E53,"Critical") | C26: Filter Gap Analysis: Severity = "Critical"
A27: Devices Not Assessed | B27: =COUNTIF('Device Inventory'!P5:P153,"❓ Not Assessed") | C27: Filter Device Inventory: Compliance Status = "❓ Not Assessed"
A28: TOTAL | B28: =SUM(B23:B27) | C28: Total critical findings requiring immediate investigation

Sheet Approval Sign-Off
A1: ASSESSMENT APPROVAL AND SIGN-OFF
A3: ASSESSMENT SUMMARY
A4: Document: | B4: ISMS-IMP-A.8.20-22.S1 - Network Infrastructure Inventory
A5: Assessment Period:
A6: Overall Compliance: | B6: =IFERROR(AVERAGE('Summary Dashboard'!G6:G7),"")
A7: Assessment Status:
A10: COMPLETED BY (NETWORK ENGINEERING)
A11: Name:
A12: Title:
A13: Date:
A14: Signature:
A15: Comments:
A17: REVIEWED BY (ISO)
A18: Name:
A19: Title:
A20: Date:
A21: Signature:
... A37: Special Considerations:
