Workbook

Sheet Instructions & Legend
A1: ISMS-IMP-A.8.20-21-22.S4 - Network Segmentation Matrix & Assessment ISO/IEC 27001:2022 - Control A.8.20-21-22: Network Security
A3: Document Information
A4: Document ID | B4: ISMS-IMP-A.8.20-21-22.S4
A5: Workbook Title | B5: Network Segmentation Matrix & Assessment
A6: Control Reference | B6: ISO/IEC 27001:2022 - Control A.8.20-21-22: Network Security
A7: Version | B7: 1.0
A8: Assessment Date
A9: Completed By
A10: Organisation
A12: Instructions
A13: 1. Review and document the network segmentation architecture.
A14: 2. Map zone-to-zone communication paths in the Segmentation Matrix.
A15: 3. Complete the Zone Security Assessment for each network zone.
A16: 4. Document firewall rules and ACLs governing inter-zone traffic.
A17: 5. Assess micro-segmentation capabilities and deployment status.
A18: 6. Review compliance against segmentation policy requirements.
A19: 7. Identify and document gaps with remediation plans.
A20: 8. Maintain the Evidence Register with all supporting documentation.
... A23: Status Legend
A24: Symbol | B24: Status | C24: Description
A25: ✓ | B25: Compliant / Complete | C25: Requirement fully met
A26: ⚠ | B26: Partial / In Progress | C26: Partially met or in progress
A27: ✗ | B27: Non-Compliant / Not Started | C27: Requirement not met
A28: — | B28: Not Applicable | C28: Not applicable to this assessment

Sheet Security Zones Inventory
A1: SECURITY ZONES INVENTORY - GENERATED 07.03.2026
A2: Define all security zones in the network. This is the foundation for the segmentation matrix.
A3: Zone ID | B3: Zone Name | C3: Purpose | D3: Trust Level | E3: Networks/Subnets | F3: VLANs | G3: Segmentation Type | H3: Devices Count | I3: Critical Assets | J3: Internet Access | K3: Owner | L3: Notes
A4: =IF(B4<>"","ZONE-" & TEXT(1,"00"),"")
A5: =IF(B5<>"","ZONE-" & TEXT(2,"00"),"")
A6: =IF(B6<>"","ZONE-" & TEXT(3,"00"),"")
A7: =IF(B7<>"","ZONE-" & TEXT(4,"00"),"")
A8: =IF(B8<>"","ZONE-" & TEXT(5,"00"),"")
A9: =IF(B9<>"","ZONE-" & TEXT(6,"00"),"")
A10: =IF(B10<>"","ZONE-" & TEXT(7,"00"),"")
A11: =IF(B11<>"","ZONE-" & TEXT(8,"00"),"")
A12: =IF(B12<>"","ZONE-" & TEXT(9,"00"),"")
A13: =IF(B13<>"","ZONE-" & TEXT(10,"00"),"")
A14: =IF(B14<>"","ZONE-" & TEXT(11,"00"),"")
A15: =IF(B15<>"","ZONE-" & TEXT(12,"00"),"")
A16: =IF(B16<>"","ZONE-" & TEXT(13,"00"),"")
A17: =IF(B17<>"","ZONE-" & TEXT(14,"00"),"")
A18: =IF(B18<>"","ZONE-" & TEXT(15,"00"),"")
A19: =IF(B19<>"","ZONE-" & TEXT(16,"00"),"")
A20: =IF(B20<>"","ZONE-" & TEXT(17,"00"),"")
A21: =IF(B21<>"","ZONE-" & TEXT(18,"00"),"")
A22: =IF(B22<>"","ZONE-" & TEXT(19,"00"),"")
A23: =IF(B23<>"","ZONE-" & TEXT(20,"00"),"")
A24: =IF(B24<>"","ZONE-" & TEXT(21,"00"),"")
A25: =IF(B25<>"","ZONE-" & TEXT(22,"00"),"")
A26: =IF(B26<>"","ZONE-" & TEXT(23,"00"),"")
A27: =IF(B27<>"","ZONE-" & TEXT(24,"00"),"")
A28: =IF(B28<>"","ZONE-" & TEXT(25,"00"),"")
A29: =IF(B29<>"","ZONE-" & TEXT(26,"00"),"")
A30: =IF(B30<>"","ZONE-" & TEXT(27,"00"),"")
A31: =IF(B31<>"","ZONE-" & TEXT(28,"00"),"")
A32: =IF(B32<>"","ZONE-" & TEXT(29,"00"),"")
A33: =IF(B33<>"","ZONE-" & TEXT(30,"00"),"")
A34: =IF(B34<>"","ZONE-" & TEXT(31,"00"),"")
A35: =IF(B35<>"","ZONE-" & TEXT(32,"00"),"")
A36: =IF(B36<>"","ZONE-" & TEXT(33,"00"),"")
A37: =IF(B37<>"","ZONE-" & TEXT(34,"00"),"")
A38: =IF(B38<>"","ZONE-" & TEXT(35,"00"),"")
A39: =IF(B39<>"","ZONE-" & TEXT(36,"00"),"")
A40: =IF(B40<>"","ZONE-" & TEXT(37,"00"),"")
...

Sheet Segmentation Matrix
A1: NETWORK SEGMENTATION MATRIX - ZONE-TO-ZONE TRAFFIC RULES
A2: Define allowed/denied traffic between security zones. This is the CORE segmentation assessment.
A3: FORMAT: Each row defines traffic flow from Source Zone → Destination Zone. Action: Allow/Deny/Inspect.
A4: Rule ID | B4: Source Zone | C4: Destination Zone | D4: Traffic Action | E4: Protocols/Ports | F4: Justification | G4: Firewall Enforced | H4: ACL Enforced | I4: Monitoring | J4: Last Reviewed | K4: Notes
A5: =IF(B5<>"","SEG-" & TEXT(1,"000"),"")
A6: =IF(B6<>"","SEG-" & TEXT(2,"000"),"")
A7: =IF(B7<>"","SEG-" & TEXT(3,"000"),"")
A8: =IF(B8<>"","SEG-" & TEXT(4,"000"),"")
A9: =IF(B9<>"","SEG-" & TEXT(5,"000"),"")
A10: =IF(B10<>"","SEG-" & TEXT(6,"000"),"")
A11: =IF(B11<>"","SEG-" & TEXT(7,"000"),"")
A12: =IF(B12<>"","SEG-" & TEXT(8,"000"),"")
A13: =IF(B13<>"","SEG-" & TEXT(9,"000"),"")
A14: =IF(B14<>"","SEG-" & TEXT(10,"000"),"")
A15: =IF(B15<>"","SEG-" & TEXT(11,"000"),"")
A16: =IF(B16<>"","SEG-" & TEXT(12,"000"),"")
A17: =IF(B17<>"","SEG-" & TEXT(13,"000"),"")
A18: =IF(B18<>"","SEG-" & TEXT(14,"000"),"")
A19: =IF(B19<>"","SEG-" & TEXT(15,"000"),"")
A20: =IF(B20<>"","SEG-" & TEXT(16,"000"),"")
A21: =IF(B21<>"","SEG-" & TEXT(17,"000"),"")
A22: =IF(B22<>"","SEG-" & TEXT(18,"000"),"")
A23: =IF(B23<>"","SEG-" & TEXT(19,"000"),"")
A24: =IF(B24<>"","SEG-" & TEXT(20,"000"),"")
A25: =IF(B25<>"","SEG-" & TEXT(21,"000"),"")
A26: =IF(B26<>"","SEG-" & TEXT(22,"000"),"")
A27: =IF(B27<>"","SEG-" & TEXT(23,"000"),"")
A28: =IF(B28<>"","SEG-" & TEXT(24,"000"),"")
A29: =IF(B29<>"","SEG-" & TEXT(25,"000"),"")
A30: =IF(B30<>"","SEG-" & TEXT(26,"000"),"")
A31: =IF(B31<>"","SEG-" & TEXT(27,"000"),"")
A32: =IF(B32<>"","SEG-" & TEXT(28,"000"),"")
A33: =IF(B33<>"","SEG-" & TEXT(29,"000"),"")
A34: =IF(B34<>"","SEG-" & TEXT(30,"000"),"")
A35: =IF(B35<>"","SEG-" & TEXT(31,"000"),"")
A36: =IF(B36<>"","SEG-" & TEXT(32,"000"),"")
A37: =IF(B37<>"","SEG-" & TEXT(33,"000"),"")
A38: =IF(B38<>"","SEG-" & TEXT(34,"000"),"")
A39: =IF(B39<>"","SEG-" & TEXT(35,"000"),"")
A40: =IF(B40<>"","SEG-" & TEXT(36,"000"),"")
...

Sheet VLAN Inventory
A1: VLAN INVENTORY & DESIGN ASSESSMENT
A2: Document all VLANs. Verify VLAN numbering, naming standards, and zone assignment.
A3: VLAN ID | B3: VLAN Name | C3: Security Zone | D3: IP Subnet | E3: Purpose | F3: Devices/Ports | G3: Trunk Allowed | H3: Native VLAN | I3: Last Reviewed | J3: Notes
A4: 10 | B4: VLAN-10-USERS-LAN | C4: Internal | D4: 10.10.0.0/24 | E4: End-user workstations | F4: sw-access-01 Gi0/1-24 | G4: No | H4: No
A56: VLAN Design Best Practices (per IMP-S5)
A57: • VLAN NUMBERING: Consistent scheme (e.g., 10-99 for users, 100-199 for servers, 200-299 for management)
A58: • VLAN NAMING: Descriptive names (e.g., VLAN-10-USERS-FLOOR1, VLAN-100-SERVERS-WEB)
A59: • NATIVE VLAN: Change from default VLAN 1, use dedicated unused VLAN
A60: • VLAN PRUNING: Only allow necessary VLANs on trunks
A61: • ONE VLAN PER ZONE: Each security zone maps to dedicated VLANs
A62: • DOCUMENTATION: Maintain VLAN database with assignments and purpose

Sheet Firewall Rules Assessment
A1: FIREWALL RULES ASSESSMENT
A2: Review firewall rules that enforce zone segmentation. Focus on inter-zone traffic controls.
A3: Rule ID | B3: Firewall | C3: Rule Number | D3: Source Zone | E3: Destination Zone | F3: Source IP/Network | G3: Destination IP/Network | H3: Service/Port | I3: Action | J3: Review Status | K3: Last Modified | L3: Reviewed By | M3: Notes
A4: FW-RULE-001 | B4: core-fw-01 | C4: 1 | D4: Internet | E4: DMZ | F4: Any | G4: 10.10.1.0/24 | H4: TCP/80, TCP/443 | I4: Allow | J4: Current | K4: 01.01.2026 | L4: Network Security Team | M4: Permit inbound HTTP/HTTPS to DMZ web servers
A5: =IF(B5<>"","FW-RULE-" & TEXT(2,"000"),"")
A6: =IF(B6<>"","FW-RULE-" & TEXT(3,"000"),"")
A7: =IF(B7<>"","FW-RULE-" & TEXT(4,"000"),"")
A8: =IF(B8<>"","FW-RULE-" & TEXT(5,"000"),"")
A9: =IF(B9<>"","FW-RULE-" & TEXT(6,"000"),"")
A10: =IF(B10<>"","FW-RULE-" & TEXT(7,"000"),"")
A11: =IF(B11<>"","FW-RULE-" & TEXT(8,"000"),"")
A12: =IF(B12<>"","FW-RULE-" & TEXT(9,"000"),"")
A13: =IF(B13<>"","FW-RULE-" & TEXT(10,"000"),"")
A14: =IF(B14<>"","FW-RULE-" & TEXT(11,"000"),"")
A15: =IF(B15<>"","FW-RULE-" & TEXT(12,"000"),"")
A16: =IF(B16<>"","FW-RULE-" & TEXT(13,"000"),"")
A17: =IF(B17<>"","FW-RULE-" & TEXT(14,"000"),"")
A18: =IF(B18<>"","FW-RULE-" & TEXT(15,"000"),"")
A19: =IF(B19<>"","FW-RULE-" & TEXT(16,"000"),"")
A20: =IF(B20<>"","FW-RULE-" & TEXT(17,"000"),"")
A21: =IF(B21<>"","FW-RULE-" & TEXT(18,"000"),"")
A22: =IF(B22<>"","FW-RULE-" & TEXT(19,"000"),"")
A23: =IF(B23<>"","FW-RULE-" & TEXT(20,"000"),"")
A24: =IF(B24<>"","FW-RULE-" & TEXT(21,"000"),"")
A25: =IF(B25<>"","FW-RULE-" & TEXT(22,"000"),"")
A26: =IF(B26<>"","FW-RULE-" & TEXT(23,"000"),"")
A27: =IF(B27<>"","FW-RULE-" & TEXT(24,"000"),"")
A28: =IF(B28<>"","FW-RULE-" & TEXT(25,"000"),"")
A29: =IF(B29<>"","FW-RULE-" & TEXT(26,"000"),"")
A30: =IF(B30<>"","FW-RULE-" & TEXT(27,"000"),"")
A31: =IF(B31<>"","FW-RULE-" & TEXT(28,"000"),"")
A32: =IF(B32<>"","FW-RULE-" & TEXT(29,"000"),"")
A33: =IF(B33<>"","FW-RULE-" & TEXT(30,"000"),"")
A34: =IF(B34<>"","FW-RULE-" & TEXT(31,"000"),"")
A35: =IF(B35<>"","FW-RULE-" & TEXT(32,"000"),"")
A36: =IF(B36<>"","FW-RULE-" & TEXT(33,"000"),"")
A37: =IF(B37<>"","FW-RULE-" & TEXT(34,"000"),"")
A38: =IF(B38<>"","FW-RULE-" & TEXT(35,"000"),"")
A39: =IF(B39<>"","FW-RULE-" & TEXT(36,"000"),"")
A40: =IF(B40<>"","FW-RULE-" & TEXT(37,"000"),"")
...

Sheet ACL Assessment
A1: ACL (ACCESS CONTROL LIST) ASSESSMENT
A2: Review router/switch ACLs that enforce segmentation. Complement firewall rules.
A3: ACL ID | B3: Device | C3: ACL Name/Number | D3: Interface | E3: Direction | F3: Purpose | G3: Zones Protected | H3: Review Status | I3: Effectiveness | J3: Last Modified | K3: Reviewed By | L3: Notes
A4: =IF(B4<>"","ACL-" & TEXT(1,"00"),"")
A5: =IF(B5<>"","ACL-" & TEXT(2,"00"),"")
A6: =IF(B6<>"","ACL-" & TEXT(3,"00"),"")
A7: =IF(B7<>"","ACL-" & TEXT(4,"00"),"")
A8: =IF(B8<>"","ACL-" & TEXT(5,"00"),"")
A9: =IF(B9<>"","ACL-" & TEXT(6,"00"),"")
A10: =IF(B10<>"","ACL-" & TEXT(7,"00"),"")
A11: =IF(B11<>"","ACL-" & TEXT(8,"00"),"")
A12: =IF(B12<>"","ACL-" & TEXT(9,"00"),"")
A13: =IF(B13<>"","ACL-" & TEXT(10,"00"),"")
A14: =IF(B14<>"","ACL-" & TEXT(11,"00"),"")
A15: =IF(B15<>"","ACL-" & TEXT(12,"00"),"")
A16: =IF(B16<>"","ACL-" & TEXT(13,"00"),"")
A17: =IF(B17<>"","ACL-" & TEXT(14,"00"),"")
A18: =IF(B18<>"","ACL-" & TEXT(15,"00"),"")
A19: =IF(B19<>"","ACL-" & TEXT(16,"00"),"")
A20: =IF(B20<>"","ACL-" & TEXT(17,"00"),"")
A21: =IF(B21<>"","ACL-" & TEXT(18,"00"),"")
A22: =IF(B22<>"","ACL-" & TEXT(19,"00"),"")
A23: =IF(B23<>"","ACL-" & TEXT(20,"00"),"")
A24: =IF(B24<>"","ACL-" & TEXT(21,"00"),"")
A25: =IF(B25<>"","ACL-" & TEXT(22,"00"),"")
A26: =IF(B26<>"","ACL-" & TEXT(23,"00"),"")
A27: =IF(B27<>"","ACL-" & TEXT(24,"00"),"")
A28: =IF(B28<>"","ACL-" & TEXT(25,"00"),"")
A29: =IF(B29<>"","ACL-" & TEXT(26,"00"),"")
A30: =IF(B30<>"","ACL-" & TEXT(27,"00"),"")
A31: =IF(B31<>"","ACL-" & TEXT(28,"00"),"")
A32: =IF(B32<>"","ACL-" & TEXT(29,"00"),"")
A33: =IF(B33<>"","ACL-" & TEXT(30,"00"),"")
A34: =IF(B34<>"","ACL-" & TEXT(31,"00"),"")
A35: =IF(B35<>"","ACL-" & TEXT(32,"00"),"")
A36: =IF(B36<>"","ACL-" & TEXT(33,"00"),"")
A37: =IF(B37<>"","ACL-" & TEXT(34,"00"),"")
A38: =IF(B38<>"","ACL-" & TEXT(35,"00"),"")
A39: =IF(B39<>"","ACL-" & TEXT(36,"00"),"")
A40: =IF(B40<>"","ACL-" & TEXT(37,"00"),"")
...

Sheet Segmentation Testing
A1: SEGMENTATION EFFECTIVENESS TESTING
A2: Test segmentation effectiveness. Verify traffic is blocked when expected (no bypass routes).
A3: Test ID | B3: Test Name | C3: Source Zone | D3: Destination Zone | E3: Expected Result | F3: Actual Result | G3: Test Result | H3: Test Method | I3: Test Date | J3: Tested By | K3: Notes
A4: SEG-TEST-01 | B4: Internet DMZ to Corporate LAN | C4: Internet DMZ | D4: Corporate LAN | E4: Deny | F4: Deny | G4: Pass | H4: Port Scan (nmap) | I4: 15.01.2026 | J4: Network Security Team | K4: Firewall confirmed blocking all traffic from DMZ to Corporate LAN
A5: =IF(B5<>"","SEG-TEST-" & TEXT(2,"00"),"")
A6: =IF(B6<>"","SEG-TEST-" & TEXT(3,"00"),"")
A7: =IF(B7<>"","SEG-TEST-" & TEXT(4,"00"),"")
A8: =IF(B8<>"","SEG-TEST-" & TEXT(5,"00"),"")
A9: =IF(B9<>"","SEG-TEST-" & TEXT(6,"00"),"")
A10: =IF(B10<>"","SEG-TEST-" & TEXT(7,"00"),"")
A11: =IF(B11<>"","SEG-TEST-" & TEXT(8,"00"),"")
A12: =IF(B12<>"","SEG-TEST-" & TEXT(9,"00"),"")
A13: =IF(B13<>"","SEG-TEST-" & TEXT(10,"00"),"")
A14: =IF(B14<>"","SEG-TEST-" & TEXT(11,"00"),"")
A15: =IF(B15<>"","SEG-TEST-" & TEXT(12,"00"),"")
A16: =IF(B16<>"","SEG-TEST-" & TEXT(13,"00"),"")
A17: =IF(B17<>"","SEG-TEST-" & TEXT(14,"00"),"")
A18: =IF(B18<>"","SEG-TEST-" & TEXT(15,"00"),"")
A19: =IF(B19<>"","SEG-TEST-" & TEXT(16,"00"),"")
A20: =IF(B20<>"","SEG-TEST-" & TEXT(17,"00"),"")
A21: =IF(B21<>"","SEG-TEST-" & TEXT(18,"00"),"")
A22: =IF(B22<>"","SEG-TEST-" & TEXT(19,"00"),"")
A23: =IF(B23<>"","SEG-TEST-" & TEXT(20,"00"),"")
A24: =IF(B24<>"","SEG-TEST-" & TEXT(21,"00"),"")
A25: =IF(B25<>"","SEG-TEST-" & TEXT(22,"00"),"")
A26: =IF(B26<>"","SEG-TEST-" & TEXT(23,"00"),"")
A27: =IF(B27<>"","SEG-TEST-" & TEXT(24,"00"),"")
A28: =IF(B28<>"","SEG-TEST-" & TEXT(25,"00"),"")
A29: =IF(B29<>"","SEG-TEST-" & TEXT(26,"00"),"")
A30: =IF(B30<>"","SEG-TEST-" & TEXT(27,"00"),"")
A31: =IF(B31<>"","SEG-TEST-" & TEXT(28,"00"),"")
A32: =IF(B32<>"","SEG-TEST-" & TEXT(29,"00"),"")
A33: =IF(B33<>"","SEG-TEST-" & TEXT(30,"00"),"")
A35: Segmentation Testing Methods (per IMP-S5)
A36: Test Method | B36: Description
A37: Ping Test | B37: Simple connectivity test - should fail if segmentation working
A38: Traceroute | B38: Verify traffic path - should stop at firewall/router
A39: Port Scan (nmap) | B39: Verify ports blocked between zones
A40: HTTP/HTTPS Request | B40: Test application layer connectivity
A41: Packet Capture | B41: Capture traffic to verify deny/drop behaviour
...

Sheet Gap Analysis
A1: SEGMENTATION GAPS - REMEDIATION TRACKING
A2: Document segmentation gaps: flat networks, excessive trust, missing controls, bypass routes.
A3: Gap ID | B3: Gap Type | C3: Location/Zone | D3: Description | E3: Risk | F3: Severity | G3: Remediation Plan | H3: Owner | I3: Status | J3: Target Date
A4: SEG-GAP-001 | B4: Flat Network | C4: Server VLAN (10.10.2.0/24) | D4: No segmentation between application and database server tiers | E4: Lateral movement possible from app to database servers | F4: Critical | G4: Create dedicated database VLAN; permit only app→DB on port 1433 via firewall | H4: Network Architecture Team | I4: Open | J4: 28.02.2026
A5: =IF(B5<>"","SEG-GAP-" & TEXT(2,"000"),"")
A6: =IF(B6<>"","SEG-GAP-" & TEXT(3,"000"),"")
A7: =IF(B7<>"","SEG-GAP-" & TEXT(4,"000"),"")
A8: =IF(B8<>"","SEG-GAP-" & TEXT(5,"000"),"")
A9: =IF(B9<>"","SEG-GAP-" & TEXT(6,"000"),"")
A10: =IF(B10<>"","SEG-GAP-" & TEXT(7,"000"),"")
A11: =IF(B11<>"","SEG-GAP-" & TEXT(8,"000"),"")
A12: =IF(B12<>"","SEG-GAP-" & TEXT(9,"000"),"")
A13: =IF(B13<>"","SEG-GAP-" & TEXT(10,"000"),"")
A14: =IF(B14<>"","SEG-GAP-" & TEXT(11,"000"),"")
A15: =IF(B15<>"","SEG-GAP-" & TEXT(12,"000"),"")
A16: =IF(B16<>"","SEG-GAP-" & TEXT(13,"000"),"")
A17: =IF(B17<>"","SEG-GAP-" & TEXT(14,"000"),"")
A18: =IF(B18<>"","SEG-GAP-" & TEXT(15,"000"),"")
A19: =IF(B19<>"","SEG-GAP-" & TEXT(16,"000"),"")
A20: =IF(B20<>"","SEG-GAP-" & TEXT(17,"000"),"")
A21: =IF(B21<>"","SEG-GAP-" & TEXT(18,"000"),"")
A22: =IF(B22<>"","SEG-GAP-" & TEXT(19,"000"),"")
A23: =IF(B23<>"","SEG-GAP-" & TEXT(20,"000"),"")
A24: =IF(B24<>"","SEG-GAP-" & TEXT(21,"000"),"")
A25: =IF(B25<>"","SEG-GAP-" & TEXT(22,"000"),"")
A26: =IF(B26<>"","SEG-GAP-" & TEXT(23,"000"),"")
A27: =IF(B27<>"","SEG-GAP-" & TEXT(24,"000"),"")
A28: =IF(B28<>"","SEG-GAP-" & TEXT(25,"000"),"")
A29: =IF(B29<>"","SEG-GAP-" & TEXT(26,"000"),"")
A30: =IF(B30<>"","SEG-GAP-" & TEXT(27,"000"),"")
A31: =IF(B31<>"","SEG-GAP-" & TEXT(28,"000"),"")
A32: =IF(B32<>"","SEG-GAP-" & TEXT(29,"000"),"")
A33: =IF(B33<>"","SEG-GAP-" & TEXT(30,"000"),"")
A34: =IF(B34<>"","SEG-GAP-" & TEXT(31,"000"),"")
A35: =IF(B35<>"","SEG-GAP-" & TEXT(32,"000"),"")
A36: =IF(B36<>"","SEG-GAP-" & TEXT(33,"000"),"")
A37: =IF(B37<>"","SEG-GAP-" & TEXT(34,"000"),"")
A38: =IF(B38<>"","SEG-GAP-" & TEXT(35,"000"),"")
A39: =IF(B39<>"","SEG-GAP-" & TEXT(36,"000"),"")
A40: =IF(B40<>"","SEG-GAP-" & TEXT(37,"000"),"")
...

Sheet Remediation Roadmap
A1: SEGMENTATION REMEDIATION ROADMAP
A2: Prioritised plan for segmentation improvements. Focus on Critical gaps first.
A3: Priority | B3: Severity | C3: Improvement | D3: Affected Zones | E3: Remediation Action | F3: Owner | G3: Target Date | H3: Status
A4: 1
A5: 2
A6: 3
A7: 4
A8: 5
A9: 6
A10: 7
A11: 8
A12: 9
A13: 10
A14: 11
A15: 12
... A33: 30
A35: Segmentation Remediation Approach
A36: 1. CRITICAL FIRST: Address Critical gaps immediately (flat networks, bypass routes)
A37: 2. QUICK WINS: Implement easy improvements (VLAN assignment, ACL updates)
A38: 3. FIREWALL RULES: Review and tighten firewall rules between zones
A39: 4. TESTING: Re-test after each change to verify effectiveness
A40: 5. DOCUMENTATION: Update network documentation (topology, VLAN database)
A41: 6. MONITORING: Enable logging and alerting for inter-zone traffic

Sheet Evidence Register
A1: EVIDENCE REGISTER
A2: List all evidence files/documents referenced in this assessment (audit traceability).
A4: Evidence ID | B4: Assessment Area | C4: Evidence Type | D4: Description | E4: Location/Path | F4: Date Collected | G4: Collected By | H4: Verification Status
A5: EV-001 | B5: Network Segmentation Assessment | C5: Screenshot | D5: Network segmentation test results and firewall rule review documentation | E5: /evidence/A.8.20-22/ | F5: 15.01.2026 | G5: Assessor Name | H5: ✅ Verified

Sheet Summary Dashboard
A1: NETWORK SEGMENTATION MATRIX & ASSESSMENT — SUMMARY DASHBOARD
A2: ISO/IEC 27001:2022 — Controls A.8.20 · A.8.21 · A.8.22: Network Security, Security of Network Services and Segregation of Networks
A4: TABLE 1: ASSESSMENT AREA COMPLIANCE
A5: Assessment Area | B5: Total | C5: Yes | D5: Partial | E5: No | F5: N-A | G5: Compliance %
A6: Segmentation Testing | B6: =COUNTA('Segmentation Testing'!B5:B33) | C6: =COUNTIF('Segmentation Testing'!G5:G33,"Pass") | D6: =COUNTIF('Segmentation Testing'!G5:G33,"Partial") | E6: =COUNTIF('Segmentation Testing'!G5:G33,"Fail") | F6: =B6-(C6+D6+E6) | G6: =IF((B6-F6)=0,"0%",ROUND(C6/(B6-F6)*100,1)&"%")
A7: Firewall Rules Assessment | B7: =COUNTA('Firewall Rules Assessment'!B5:B103) | C7: =COUNTIF('Firewall Rules Assessment'!J5:J103,"Current") | D7: =COUNTIF('Firewall Rules Assessment'!J5:J103,"Requires Review") | E7: =COUNTIF('Firewall Rules Assessment'!J5:J103,"Outdated")+COUNTIF('Firewall Rules Assessment'!J5:J103,"Unused") | F7: =B7-(C7+D7+E7) | G7: =IF((B7-F7)=0,"0%",ROUND(C7/(B7-F7)*100,1)&"%")
A8: Gap Analysis | B8: =COUNTA('Gap Analysis'!B5:B53) | C8: =COUNTIF('Gap Analysis'!I5:I53,"Resolved") | D8: =COUNTIF('Gap Analysis'!I5:I53,"In Progress") | E8: =COUNTIF('Gap Analysis'!I5:I53,"Open") | F8: =B8-(C8+D8+E8) | G8: =IF((B8-F8)=0,"0%",ROUND(C8/(B8-F8)*100,1)&"%")
A9: TOTAL | B9: =SUM(B6:B8) | C9: =SUM(C6:C8) | D9: =SUM(D6:D8) | E9: =SUM(E6:E8) | F9: =SUM(F6:F8) | G9: =IF((B9-F9)=0,"0%",ROUND(C9/(B9-F9)*100,1)&"%")
A11: TABLE 2: KEY METRICS
A12: Metric | B12: Value | C12: What This Shows
A13: Failed Segmentation Tests | B13: =COUNTIF('Segmentation Testing'!G5:G33,"Fail") | C13: Tests confirming bypass routes or misconfigurations (immediate investigation required)
A14: Untested Segments | B14: =COUNTIF('Segmentation Testing'!G5:G33,"Not Tested") | C14: Test cases not yet executed (unknown segmentation effectiveness)
A15: Partial Test Results | B15: =COUNTIF('Segmentation Testing'!G5:G33,"Partial") | C15: Tests with partial pass (incomplete segmentation enforcement)
A16: Outdated Firewall Rules | B16: =COUNTIF('Firewall Rules Assessment'!J5:J103,"Outdated") | C16: Firewall rules requiring immediate review (may permit unauthorised traffic)
A17: Unused Firewall Rules | B17: =COUNTIF('Firewall Rules Assessment'!J5:J103,"Unused") | C17: Unused rules creating unnecessary attack surface (remove or review)
A18: Rules Requiring Review | B18: =COUNTIF('Firewall Rules Assessment'!J5:J103,"Requires Review") | C18: Rules overdue for periodic review (potential policy violations)
A19: Open Segmentation Gaps | B19: =COUNTIF('Gap Analysis'!I5:I53,"Open") | C19: Outstanding segmentation gaps without active remediation
A20: Overall Compliance Rate | B20: =G9 | C20: Overall network segmentation compliance percentage (TABLE 1 total)
A22: TABLE 3: CRITICAL FINDINGS
A23: Critical Finding Type | B23: Count | C23: Filter Instructions
A24: Failed Segmentation Tests | B24: =COUNTIF('Segmentation Testing'!G5:G33,"Fail") | C24: Filter Segmentation Testing: Test Result = "Fail"
A25: Outdated Firewall Rules | B25: =COUNTIF('Firewall Rules Assessment'!J5:J103,"Outdated") | C25: Filter Firewall Rules Assessment: Review Status = "Outdated"
A26: Open Segmentation Gaps | B26: =COUNTIF('Gap Analysis'!I5:I53,"Open") | C26: Filter Gap Analysis: Status = "Open"
A27: Untested Segments | B27: =COUNTIF('Segmentation Testing'!G5:G33,"Not Tested") | C27: Filter Segmentation Testing: Test Result = "Not Tested"
A28: Critical Severity Gaps | B28: =COUNTIF('Gap Analysis'!F5:F53,"Critical") | C28: Filter Gap Analysis: Severity = "Critical"
A29: TOTAL | B29: =SUM(B24:B28) | C29: Total critical findings requiring immediate remediation

Sheet Approval Sign-Off
A1: ASSESSMENT APPROVAL AND SIGN-OFF
A2: ISO/IEC 27001:2022 - Control A.8.20-21-22: Network Security
A3: ASSESSMENT SUMMARY
A4: Document: | B4: ISMS-IMP-A.8.20-21-22.S4 - Network Segmentation Matrix & Assessment
A5: Assessment Period:
A6: Overall Compliance Rating: | B6: =IFERROR(AVERAGE('Summary Dashboard'!G6:G8),"")
A7: Assessment Status:
A8: Assessed By:
A11: COMPLETED BY (ASSESSOR)
A12: Name:
A13: Title:
A14: Date:
A15: Signature:
A16: Comments:
A18: REVIEWED BY (INFORMATION SECURITY OFFICER)
A19: Name:
A20: Title:
A21: Date:
... A38: Special Considerations:
