Workbook

Sheet Instructions & Legend
A1: ISMS-IMP-A.8.20-22.S5 - Network Security Controls Coverage Matrix ISO/IEC 27001:2022 - Control A.8.20-22: Network Security
A3: Document Information
A4: Document ID | B4: ISMS-IMP-A.8.20-22.S5
A5: Workbook Title | B5: Network Security Controls Coverage Matrix
A6: Control Reference | B6: ISO/IEC 27001:2022 - Control A.8.20-22: Network Security
A7: Version | B7: 1.0
A8: Assessment Date
A9: Completed By
A10: Organisation
A12: Instructions
A13: 1. Review the Controls Coverage Matrix to understand the full scope of the assessment.
A14: 2. Map network device controls to security zones using data from WB1 and WB2.
A15: 3. Map network service controls to security zones using data from WB3.
A16: 4. Assess control effectiveness for each security zone.
A17: 5. Validate defense-in-depth across all critical zones.
A18: 6. Identify coverage gaps and single points of failure.
A19: 7. Verify integration with logging (A.8.15) and monitoring (A.8.16).
A20: 8. Document all evidence in the Evidence Register tab.
... A23: Status Legend
A24: Symbol | B24: Status | C24: Description
A25: ✓ | B25: Compliant / Complete | C25: Requirement fully met
A26: ⚠ | B26: Partial / In Progress | C26: Partially met or in progress
A27: ✗ | B27: Non-Compliant / Not Started | C27: Requirement not met
A28: — | B28: Not Applicable | C28: Not applicable to this assessment

Sheet Controls Coverage Matrix
A1: SECURITY CONTROLS COVERAGE MATRIX - GENERATED 10.03.2026
A2: Matrix: Rows = Security Zones | Columns = Security Controls | Cell = Coverage Status (Covered/Not Covered/Partial)
A3: Zone ID | B3: Zone Name | C3: Perimeter Firewall | D3: Network Device Hardening | E3: Network Monitoring | F3: Network Logging | G3: Wireless Security | H3: Remote Access VPN | I3: Network Access Control (NAC) | J3: DNS Security (DNSSEC) | K3: DHCP Security | L3: NTP Security | M3: Proxy/Web Filtering | N3: Load Balancer Security | O3: AAA Services (RADIUS/TACACS+) | P3: SNMP Security | Q3: Syslog Security | R3: Zone Segmentation | S3: VLAN Segmentation | T3: Firewall Inter-Zone Rules | U3: ACL Enforcement | V3: Segmentation Testing | W3: Microsegmentation | AB3: Coverage %
A4: ZONE-001 | B4: Internet DMZ | C4: Covered | D4: Covered | E4: Covered | F4: Covered | G4: Covered | H4: Covered | I4: Covered | J4: Covered | K4: Covered | L4: Covered | M4: Covered | N4: Covered | O4: Covered | P4: Covered | Q4: Covered | R4: Covered | S4: Covered | T4: Covered | U4: Covered | V4: Covered | W4: Covered | X4: Covered | Y4: Covered | Z4: Covered | AA4: Covered | AB4: =IF(COUNTA(C4:AA4)=0,"",COUNTIF(C4:AA4,"Covered")/COUNTA(C4:AA4)*100)
AB5: =IF(COUNTA(C5:AA5)=0,"",COUNTIF(C5:AA5,"Covered")/COUNTA(C5:AA5)*100)
AB6: =IF(COUNTA(C6:AA6)=0,"",COUNTIF(C6:AA6,"Covered")/COUNTA(C6:AA6)*100)
AB7: =IF(COUNTA(C7:AA7)=0,"",COUNTIF(C7:AA7,"Covered")/COUNTA(C7:AA7)*100)
AB8: =IF(COUNTA(C8:AA8)=0,"",COUNTIF(C8:AA8,"Covered")/COUNTA(C8:AA8)*100)
AB9: =IF(COUNTA(C9:AA9)=0,"",COUNTIF(C9:AA9,"Covered")/COUNTA(C9:AA9)*100)
AB10: =IF(COUNTA(C10:AA10)=0,"",COUNTIF(C10:AA10,"Covered")/COUNTA(C10:AA10)*100)
AB11: =IF(COUNTA(C11:AA11)=0,"",COUNTIF(C11:AA11,"Covered")/COUNTA(C11:AA11)*100)
AB12: =IF(COUNTA(C12:AA12)=0,"",COUNTIF(C12:AA12,"Covered")/COUNTA(C12:AA12)*100)
AB13: =IF(COUNTA(C13:AA13)=0,"",COUNTIF(C13:AA13,"Covered")/COUNTA(C13:AA13)*100)
AB14: =IF(COUNTA(C14:AA14)=0,"",COUNTIF(C14:AA14,"Covered")/COUNTA(C14:AA14)*100)
AB15: =IF(COUNTA(C15:AA15)=0,"",COUNTIF(C15:AA15,"Covered")/COUNTA(C15:AA15)*100)
AB16: =IF(COUNTA(C16:AA16)=0,"",COUNTIF(C16:AA16,"Covered")/COUNTA(C16:AA16)*100)
... AB54: =IF(COUNTA(C54:AA54)=0,"",COUNTIF(C54:AA54,"Covered")/COUNTA(C54:AA54)*100)

Sheet Zone Control Assessment
A1: ZONE CONTROL ASSESSMENT - EFFECTIVENESS BY ZONE
A2: Assess overall control effectiveness for each security zone.
A3: Zone ID | B3: Zone Name | C3: Risk Level | D3: Controls Required | E3: Controls Implemented | F3: Control Coverage % | G3: Effectiveness Rating | H3: Gaps Identified | I3: Last Assessment | J3: Assessed By | K3: Notes
A4: ZONE-001 | B4: Internet DMZ | C4: High | D4: 12 | E4: 10 | F4: 83% | G4: Partially Effective | H4: 2 | I4: 15.01.2026 | J4: Network Security Team
A56: Control Effectiveness Assessment Guidelines
A57: Effective: All required controls implemented, tested, and functioning correctly
A58: Partially Effective: Most controls implemented, some gaps or testing incomplete
A59: Ineffective: Significant control gaps, controls not functioning, or not tested
A60: Not Assessed: Zone has not yet been assessed for control effectiveness

Sheet Device Control Mapping
A1: DEVICE-TO-CONTROL MAPPING (FROM WB1 + WB2)
A2: Map which network devices implement which security controls. Data from WB1 (Inventory) + WB2 (Hardening).
A3: Device ID | B3: Device Type | C3: Hostname | D3: Security Zone | E3: Controls Provided | F3: Control Category | G3: Hardening Score | H3: Effectiveness | I3: Last Assessed | J3: Notes
A4: DEV-001 | B4: Firewall | C4: fw-01.example.com | D4: DMZ | E4: Traffic Filtering, IDS/IPS, VPN Termination | F4: A.8.20, A.8.22 | G4: 92 | H4: Effective | I4: 15.01.2026
A56: Example Device-to-Control Mappings
A57: Device Type | B57: Controls Provided | C57: Control Category
A58: Firewall | B58: Perimeter Firewall, Inter-Zone Rules, Logging | C58: A.8.20, A.8.22
A59: Router | B59: ACL Enforcement, Network Segmentation | C59: A.8.20, A.8.22
A60: Switch | B60: VLAN Segmentation, Port Security, DHCP Snooping | C60: A.8.22
A61: DNS Server | B61: DNS Security (DNSSEC), Query Logging | C61: A.8.21
A62: DHCP Server | B62: DHCP Security, Scope Management | C62: A.8.21
A63: Proxy | B63: Web Filtering, SSL Inspection, Malware Scanning | C63: A.8.21
A64: Load Balancer | B64: Load Balancer Security, SSL Termination | C64: A.8.21
A65: SIEM | B65: Network Monitoring, Logging | C65: A.8.20

Sheet Service Control Mapping
A1: SERVICE-TO-CONTROL MAPPING (FROM WB3)
A2: Map which network services implement which security controls. Data from WB3 (Services Catalog).
A3: Service ID | B3: Service Type | C3: Service Name | D3: Controls Provided | E3: Control Category | F3: Security Score | G3: Zones Served | H3: Last Assessed | I3: Notes
A4: SCM-001 | B4: DNS | C4: Core DNS Server | D4: DNS Security, DNSSEC, Query Filtering | E4: A.8.21 | F4: 92 | G4: DMZ, Management | H4: 15.01.2026
A56: Example Service-to-Control Mappings
A57: Service | B57: Controls Provided
A58: DNS | B58: DNS Security (DNSSEC), Query Logging, Rate Limiting, Split DNS
A59: DHCP | B59: DHCP Security, DHCP Snooping, Rogue Detection
A60: NTP | B60: NTP Security, Time Synchronization, Authentication
A61: Proxy | B61: Web Filtering, SSL Inspection, Malware Scanning, Logging
A62: Load Balancer | B62: Load Balancing Security, SSL Termination, Health Checks
A63: RADIUS/TACACS+ | B63: AAA Services, Strong Authentication, Command Authorisation
A64: SNMP | B64: SNMP Security (SNMPv3), Device Monitoring
A65: Syslog | B65: Centralised Logging, TLS Encryption, Retention

Sheet Control Effectiveness
A1: OVERALL CONTROL EFFECTIVENESS ASSESSMENT
A2: Assess effectiveness of each security control across all zones.
A3: Control Name | B3: Control Category | C3: Zones Covered | D3: Total Zones | E3: Coverage % | F3: Effectiveness Rating | G3: Weaknesses | H3: Improvement Actions
A4: Perimeter Firewall | B4: A.8.20 - Network Security
A5: Network Device Hardening | B5: A.8.20 - Network Security
A6: Network Monitoring | B6: A.8.20 - Network Security
A7: Network Logging | B7: A.8.20 - Network Security
A8: Wireless Security | B8: A.8.20 - Network Security
A9: Remote Access VPN | B9: A.8.20 - Network Security
A10: Network Access Control (NAC) | B10: A.8.20 - Network Security
A11: DNS Security (DNSSEC) | B11: A.8.21 - Network Services
A12: DHCP Security | B12: A.8.21 - Network Services
A13: NTP Security | B13: A.8.21 - Network Services
A14: Proxy/Web Filtering | B14: A.8.21 - Network Services
A15: Load Balancer Security | B15: A.8.21 - Network Services
... A24: Microsegmentation | B24: A.8.22 - Network Segmentation

Sheet Gap Analysis
A1: SECURITY CONTROL COVERAGE GAPS
A2: Zones or assets with insufficient security control coverage.
A3: Gap ID | B3: Zone/Asset | C3: Missing Control | D3: Control Category | E3: Risk | F3: Severity | G3: Remediation Plan | H3: Owner | I3: Target Date | J3: Status
A4: COV-GAP-001 | B4: Internet DMZ | C4: Missing IDS/IPS Coverage | D4: Preventive | E4: No intrusion detection on DMZ — attacks undetected | F4: Critical | G4: Deploy IDS/IPS at DMZ perimeter; configure alerts to SIEM | H4: Security Team | I4: 28.02.2026 | J4: Open
A5: =IF(B5<>"","COV-GAP-" & TEXT(2,"000"),"")
A6: =IF(B6<>"","COV-GAP-" & TEXT(3,"000"),"")
A7: =IF(B7<>"","COV-GAP-" & TEXT(4,"000"),"")
A8: =IF(B8<>"","COV-GAP-" & TEXT(5,"000"),"")
A9: =IF(B9<>"","COV-GAP-" & TEXT(6,"000"),"")
A10: =IF(B10<>"","COV-GAP-" & TEXT(7,"000"),"")
A11: =IF(B11<>"","COV-GAP-" & TEXT(8,"000"),"")
A12: =IF(B12<>"","COV-GAP-" & TEXT(9,"000"),"")
A13: =IF(B13<>"","COV-GAP-" & TEXT(10,"000"),"")
A14: =IF(B14<>"","COV-GAP-" & TEXT(11,"000"),"")
A15: =IF(B15<>"","COV-GAP-" & TEXT(12,"000"),"")
A16: =IF(B16<>"","COV-GAP-" & TEXT(13,"000"),"")
A17: =IF(B17<>"","COV-GAP-" & TEXT(14,"000"),"")
A18: =IF(B18<>"","COV-GAP-" & TEXT(15,"000"),"")
A19: =IF(B19<>"","COV-GAP-" & TEXT(16,"000"),"")
A20: =IF(B20<>"","COV-GAP-" & TEXT(17,"000"),"")
A21: =IF(B21<>"","COV-GAP-" & TEXT(18,"000"),"")
A22: =IF(B22<>"","COV-GAP-" & TEXT(19,"000"),"")
A23: =IF(B23<>"","COV-GAP-" & TEXT(20,"000"),"")
A24: =IF(B24<>"","COV-GAP-" & TEXT(21,"000"),"")
A25: =IF(B25<>"","COV-GAP-" & TEXT(22,"000"),"")
A26: =IF(B26<>"","COV-GAP-" & TEXT(23,"000"),"")
A27: =IF(B27<>"","COV-GAP-" & TEXT(24,"000"),"")
A28: =IF(B28<>"","COV-GAP-" & TEXT(25,"000"),"")
A29: =IF(B29<>"","COV-GAP-" & TEXT(26,"000"),"")
A30: =IF(B30<>"","COV-GAP-" & TEXT(27,"000"),"")
A31: =IF(B31<>"","COV-GAP-" & TEXT(28,"000"),"")
A32: =IF(B32<>"","COV-GAP-" & TEXT(29,"000"),"")
A33: =IF(B33<>"","COV-GAP-" & TEXT(30,"000"),"")
A34: =IF(B34<>"","COV-GAP-" & TEXT(31,"000"),"")
A35: =IF(B35<>"","COV-GAP-" & TEXT(32,"000"),"")
A36: =IF(B36<>"","COV-GAP-" & TEXT(33,"000"),"")
A37: =IF(B37<>"","COV-GAP-" & TEXT(34,"000"),"")
A38: =IF(B38<>"","COV-GAP-" & TEXT(35,"000"),"")
A39: =IF(B39<>"","COV-GAP-" & TEXT(36,"000"),"")
A40: =IF(B40<>"","COV-GAP-" & TEXT(37,"000"),"")
...

Sheet Defense In Depth
A1: DEFENSE-IN-DEPTH VALIDATION
A2: Verify multiple layers of controls protect critical zones (no single point of failure).
A3: Zone/Asset | B3: Risk Level | C3: Layer 1 Control | D3: Layer 2 Control | E3: Layer 3 Control | F3: Additional Layers | G3: Defense-in-Depth OK | H3: Notes
A4: Internet DMZ | B4: Critical | C4: Perimeter Firewall | D4: VLAN Segmentation | E4: ACLs on Routers | F4: IDS/IPS Monitoring | G4: Yes | H4: Firewall + VLAN + ACL + IDS = 4 layers
A56: Defense-in-Depth Principles
A57: • MULTIPLE LAYERS: Critical zones require 3+ independent layers of controls
A58: • NO SINGLE POINT OF FAILURE: If one control fails, others still protect
A59: • DIVERSE CONTROLS: Different types (Firewall + VLAN + ACL + Monitoring)
A60: • COMPENSATING CONTROLS: If primary control unavailable, compensating controls in place
A61: • CRITICAL ASSETS: Datacenter, management networks require strongest defense-in-depth
A63: Example Defense-in-Depth Layers
A64: Layer 1: Perimeter Firewall (blocks external threats)
A65: Layer 2: Network Segmentation (isolates zones via VLANs)
A66: Layer 3: Internal Firewalls (zone-to-zone filtering)
A67: Layer 4: ACLs on Routers/Switches (additional filtering)
A68: Layer 5: Network Monitoring/IDS (detect anomalies)
A69: Layer 6: Host-based Firewalls (endpoint protection)

Sheet Executive Summary
A1: NETWORK SECURITY CONTROLS - EXECUTIVE SUMMARY
A3: Assessment Overview
A4: This workbook (WB5) integrates findings from:
A5: • WB1: Network Infrastructure Inventory
A6: • WB2: Device Security Assessment
A7: • WB3: Network Services Catalog
A8: • WB4: Network Segmentation Matrix
A10: Purpose: Map security controls coverage across all network zones and assets.
A11: Controls Assessed: ISO 27001:2022 A.8.20 (Network Security), A.8.21 (Network Services), A.8.22 (Network Segmentation)
A13: Key Findings
A14: 1. COVERAGE: [Insert average zone coverage %] average control coverage across all zones
A15: 2. GAPS: [Insert count] critical coverage gaps identified (see Gap Analysis sheet)
... A31: 5. Update controls matrix after each major network change

Sheet Evidence Register
A1: EVIDENCE REGISTER
A2: List all evidence files/documents referenced in this assessment (audit traceability).
A4: Evidence ID | B4: Assessment Area | C4: Evidence Type | D4: Description | E4: Location/Path | F4: Date Collected | G4: Collected By | H4: Verification Status
A5: EV-001 | B5: Controls Coverage Assessment | C5: Configuration file | D5: Network control coverage matrix and zone control assessment documentation | E5: /evidence/A.8.20-22/ | F5: 15.01.2026 | G5: Assessor Name | H5: ✅ Verified

Sheet Summary Dashboard
A1: NETWORK SECURITY CONTROLS COVERAGE MATRIX — SUMMARY DASHBOARD
A2: ISO/IEC 27001:2022 — Controls A.8.20 · A.8.21 · A.8.22: Network Security, Security of Network Services and Segregation of Networks
A4: TABLE 1: ASSESSMENT AREA COMPLIANCE
A5: Assessment Area | B5: Total | C5: Yes | D5: Partial | E5: No | F5: N-A | G5: Compliance %
A6: Controls Coverage Matrix | B6: =COUNTA('Controls Coverage Matrix'!C5:AA54) | C6: =COUNTIF('Controls Coverage Matrix'!C5:AA54,"Covered") | D6: =COUNTIF('Controls Coverage Matrix'!C5:AA54,"Partially Covered") | E6: =COUNTIF('Controls Coverage Matrix'!C5:AA54,"Not Covered") | F6: =B6-(C6+D6+E6) | G6: =IF((B6-F6)=0,"0%",ROUND(C6/(B6-F6)*100,1)&"%")
A7: Zone Control Assessment | B7: =COUNTA('Zone Control Assessment'!B5:B54) | C7: =COUNTIF('Zone Control Assessment'!G5:G54,"Effective") | D7: =COUNTIF('Zone Control Assessment'!G5:G54,"Partially Effective") | E7: =COUNTIF('Zone Control Assessment'!G5:G54,"Ineffective") | F7: =B7-(C7+D7+E7) | G7: =IF((B7-F7)=0,"0%",ROUND(C7/(B7-F7)*100,1)&"%")
A8: Device Control Mapping | B8: =COUNTA('Device Control Mapping'!B5:B54) | C8: =COUNTIF('Device Control Mapping'!H5:H54,"Effective") | D8: =COUNTIF('Device Control Mapping'!H5:H54,"Partially Effective") | E8: =COUNTIF('Device Control Mapping'!H5:H54,"Ineffective") | F8: =B8-(C8+D8+E8) | G8: =IF((B8-F8)=0,"0%",ROUND(C8/(B8-F8)*100,1)&"%")
A9: Service Control Mapping | B9: =COUNTA('Service Control Mapping'!B5:B54) | C9: =COUNTIF('Service Control Mapping'!F5:F54,">=80") | D9: =COUNTIFS('Service Control Mapping'!F5:F54,">=50",'Service Control Mapping'!F5:F54,"<80") | E9: =COUNTIFS('Service Control Mapping'!F5:F54,">=0",'Service Control Mapping'!F5:F54,"<50") | F9: =B9-(C9+D9+E9) | G9: =IF((B9-F9)=0,"0%",ROUND(C9/(B9-F9)*100,1)&"%")
A10: Control Effectiveness | B10: =COUNTA('Control Effectiveness'!B5:B24) | C10: =COUNTIF('Control Effectiveness'!F5:F24,"Effective") | D10: =COUNTIF('Control Effectiveness'!F5:F24,"Partially Effective") | E10: =COUNTIF('Control Effectiveness'!F5:F24,"Ineffective") | F10: =B10-(C10+D10+E10) | G10: =IF((B10-F10)=0,"0%",ROUND(C10/(B10-F10)*100,1)&"%")
A11: TOTAL | B11: =SUM(B6:B10) | C11: =SUM(C6:C10) | D11: =SUM(D6:D10) | E11: =SUM(E6:E10) | F11: =SUM(F6:F10) | G11: =IF((B11-F11)=0,"0%",ROUND(C11/(B11-F11)*100,1)&"%")
A13: TABLE 2: KEY METRICS
A14: Metric | B14: Value | C14: What This Shows
A15: Uncovered Control-Zone Combinations | B15: =COUNTIF('Controls Coverage Matrix'!C5:AA54,"Not Covered") | C15: Zones without required security controls (defence-in-depth gaps)
A16: Partially Covered Combinations | B16: =COUNTIF('Controls Coverage Matrix'!C5:AA54,"Partially Covered") | C16: Zones with incomplete security control coverage
A17: Ineffective Controls | B17: =COUNTIF('Control Effectiveness'!F5:F24,"Ineffective") | C17: Controls assessed as ineffective (non-functional or bypassed)
A18: Partially Effective Controls | B18: =COUNTIF('Control Effectiveness'!F5:F24,"Partially Effective") | C18: Controls operating at reduced effectiveness
A19: Not Assessed Controls | B19: =COUNTIF('Control Effectiveness'!F5:F24,"Not Assessed") | C19: Controls without effectiveness rating (assessment required)
A20: Critical Gap Analysis | B20: =COUNTIF('Gap Analysis'!F5:F43,"Critical") | C20: Critical-severity control coverage gaps (immediate deployment required)
A21: High Severity Gap Analysis | B21: =COUNTIF('Gap Analysis'!F5:F43,"High") | C21: High-severity control gaps requiring prioritised remediation
A22: Overall Compliance Rate | B22: =G11 | C22: Overall controls coverage compliance percentage (TABLE 1 total)
A24: TABLE 3: CRITICAL FINDINGS
A25: Critical Finding Type | B25: Count | C25: Filter Instructions
A26: Uncovered Control-Zone Combinations | B26: =COUNTIF('Controls Coverage Matrix'!C5:AA54,"Not Covered") | C26: Filter Controls Coverage Matrix: Any control column = "Not Covered"
A27: Ineffective Controls | B27: =COUNTIF('Control Effectiveness'!F5:F24,"Ineffective") | C27: Filter Control Effectiveness: Effectiveness Rating = "Ineffective"
A28: Critical Gap Analysis | B28: =COUNTIF('Gap Analysis'!F5:F43,"Critical") | C28: Filter Gap Analysis: Severity = "Critical"
A29: High Severity Gap Analysis | B29: =COUNTIF('Gap Analysis'!F5:F43,"High") | C29: Filter Gap Analysis: Severity = "High"
A30: Not Assessed Controls | B30: =COUNTIF('Control Effectiveness'!F5:F24,"Not Assessed") | C30: Filter Control Effectiveness: Effectiveness Rating = "Not Assessed"
A31: TOTAL | B31: =SUM(B26:B30) | C31: Total critical findings requiring immediate investigation

Sheet Approval Sign-Off
A1: ASSESSMENT APPROVAL AND SIGN-OFF
A2: ISO/IEC 27001:2022 - Control A.8.20-22: Network Security
A3: ASSESSMENT SUMMARY
A4: Document: | B4: ISMS-IMP-A.8.20-22.S5 - Network Security Controls Coverage Matrix
A5: Assessment Period:
A6: Overall Compliance Rating: | B6: =IFERROR(AVERAGE('Summary Dashboard'!G6:G10),"")
A7: Assessment Status:
A8: Assessed By:
A11: COMPLETED BY (ASSESSOR)
A12: Name:
A13: Title:
A14: Date:
A15: Signature:
A16: Comments:
A18: REVIEWED BY (INFORMATION SECURITY OFFICER)
A19: Name:
A20: Title:
A21: Date:
... A38: Special Considerations:
