Workbook

Sheet Instructions & Guide
A1: ISMS-IMP-A.8.20-21-22.2 - Network Device Security Assessment ISO/IEC 27001:2022 - Controls A.8.20, A.8.21, A.8.22: Network Security
A3: Document Information
A4: Workbook: | B4: Network Device Security Assessment
A5: Generated: | B5: 31.01.2026
A6: Version: | B6: 1.0
A7: Control: | B7: ISO 27001:2022 A.8.20 (Networks Security)
A8: Purpose: | B8: Assess device hardening compliance against security baselines
A9: Related IMP: | B9: ISMS-IMP-A.8.20-21-22-S3 (Device Hardening Process)
A10: Prerequisite: | B10: Workbook 1 (Device Inventory) should be completed
A12: Assessment Methodology
A13: 1. PREPARATION: Review Device_Inventory from Workbook 1, identify devices to assess
A14: 2. BASELINE REVIEW: Study Hardening_Baseline_Reference sheet (CIS Benchmarks, vendor guides)
A15: 3. DEVICE ASSESSMENT: For each device, evaluate compliance with each hardening requirement
A16: 4. SCORING: Use Yes/No/N/A for each requirement. Compliance score auto-calculates.
A17: 5. GAP IDENTIFICATION: Document non-compliant items in Gap_Summary sheet
A18: 6. REMEDIATION: Prioritize gaps by severity, create remediation plan
A19: 7. VALIDATION: Re-assess after remediation, update compliance scores
A20: 8. EVIDENCE: Maintain configuration backups, scan results as evidence
A22: Assessment Response Criteria
A23: Response | B23: Definition | C23: When to Use
A24: Yes | B24: Requirement is fully implemented and verified | C24: Hardening control is configured correctly and confirmed
A25: No | B25: Requirement is NOT implemented or incorrectly configured | C25: Control is missing, disabled, or misconfigured
A26: N/A | B26: Requirement does not apply to this device | C26: Device type/role does not require this control
A28: Compliance Scoring Formula
A29: Compliance Score (%) = (Count of "Yes") / (Count of "Yes" + Count of "No") × 100
A30: 📌 NOTE: "N/A" responses are excluded from scoring (not applicable controls do not affect compliance)
A32: Hardening Requirements Overview (15 Requirements)
A33: # | B33: Requirement | C33: Applicability
A34: 1 | B34: Default Credentials Disabled | C34: All devices
A35: 2 | B35: Strong Password Policy | C35: All devices
A36: 3 | B36: Multi-Factor Authentication (MFA) | C36: Management devices, critical infrastructure
A37: 4 | B37: Unnecessary Services Disabled | C37: All devices (disable unused services)
A38: 5 | B38: Secure Management (SSH/HTTPS Only) | C38: All devices (SSH for CLI, HTTPS for web)
A39: 6 | B39: Logging Enabled | C39: All devices (syslog, local logs)
A40: 7 | B40: NTP Configured | C40: All devices (time synchronization)
A41: 8 | B41: SNMPv3 Only (v1/v2c Disabled) | C41: All devices (if SNMP used)
A42: 9 | B42: Session Timeouts Configured | C42: All devices (idle timeout)
A43: 10 | B43: Banner Messages Configured | C43: All devices (login banner)
A44: 11 | B44: Configuration Backups | C44: All devices (automated backups)
A45: 12 | B45: Firmware/Software Up-to-Date | C45: All devices (security patches)
...

Sheet Device_Hardening_Assessment
A1: Network Device Hardening Assessment - Generated 31.01.2026
A2: 📋 Assess each device against 15 hardening requirements. Yellow cells are assessment fields (Yes/No/N/A). Compliance score auto-calculates.
A3: Device ID | B3: Device Type | C3: Hostname | D3: Primary IP | E3: Criticality | F3: Default Credentials Disabled | G3: Strong Password Policy | H3: Multi-Factor Authentication (MFA) | I3: Unnecessary Services Disabled | J3: Secure Management (SSH/HTTPS Only) | K3: Logging Enabled | L3: NTP Configured | M3: SNMPv3 Only (v1/v2c Disabled) | N3: Session Timeouts Configured | O3: Banner Messages Configured | P3: Configuration Backups | Q3: Firmware/Software Up-to-Date | R3: Access Control Lists (ACLs) | S3: Encrypted Management Traffic | T3: Least Privilege Access | U3: Compliance Score (%) | V3: Gap Count | W3: Assessment Date | X3: Assessor | Y3: Notes
U4: =IF(COUNTIF(F4:T4,"Yes")+COUNTIF(F4:T4,"No")=0,"",COUNTIF(F4:T4,"Yes")/(COUNTIF(F4:T4,"Yes")+COUNTIF(F4:T4,"No"))*100) | V4: =COUNTIF(F4:T4,"No")
U5: =IF(COUNTIF(F5:T5,"Yes")+COUNTIF(F5:T5,"No")=0,"",COUNTIF(F5:T5,"Yes")/(COUNTIF(F5:T5,"Yes")+COUNTIF(F5:T5,"No"))*100) | V5: =COUNTIF(F5:T5,"No")
U6: =IF(COUNTIF(F6:T6,"Yes")+COUNTIF(F6:T6,"No")=0,"",COUNTIF(F6:T6,"Yes")/(COUNTIF(F6:T6,"Yes")+COUNTIF(F6:T6,"No"))*100) | V6: =COUNTIF(F6:T6,"No")
U7: =IF(COUNTIF(F7:T7,"Yes")+COUNTIF(F7:T7,"No")=0,"",COUNTIF(F7:T7,"Yes")/(COUNTIF(F7:T7,"Yes")+COUNTIF(F7:T7,"No"))*100) | V7: =COUNTIF(F7:T7,"No")
U8: =IF(COUNTIF(F8:T8,"Yes")+COUNTIF(F8:T8,"No")=0,"",COUNTIF(F8:T8,"Yes")/(COUNTIF(F8:T8,"Yes")+COUNTIF(F8:T8,"No"))*100) | V8: =COUNTIF(F8:T8,"No")
U9: =IF(COUNTIF(F9:T9,"Yes")+COUNTIF(F9:T9,"No")=0,"",COUNTIF(F9:T9,"Yes")/(COUNTIF(F9:T9,"Yes")+COUNTIF(F9:T9,"No"))*100) | V9: =COUNTIF(F9:T9,"No")
U10: =IF(COUNTIF(F10:T10,"Yes")+COUNTIF(F10:T10,"No")=0,"",COUNTIF(F10:T10,"Yes")/(COUNTIF(F10:T10,"Yes")+COUNTIF(F10:T10,"No"))*100) | V10: =COUNTIF(F10:T10,"No")
U11: =IF(COUNTIF(F11:T11,"Yes")+COUNTIF(F11:T11,"No")=0,"",COUNTIF(F11:T11,"Yes")/(COUNTIF(F11:T11,"Yes")+COUNTIF(F11:T11,"No"))*100) | V11: =COUNTIF(F11:T11,"No")
U12: =IF(COUNTIF(F12:T12,"Yes")+COUNTIF(F12:T12,"No")=0,"",COUNTIF(F12:T12,"Yes")/(COUNTIF(F12:T12,"Yes")+COUNTIF(F12:T12,"No"))*100) | V12: =COUNTIF(F12:T12,"No")
U13: =IF(COUNTIF(F13:T13,"Yes")+COUNTIF(F13:T13,"No")=0,"",COUNTIF(F13:T13,"Yes")/(COUNTIF(F13:T13,"Yes")+COUNTIF(F13:T13,"No"))*100) | V13: =COUNTIF(F13:T13,"No")
U14: =IF(COUNTIF(F14:T14,"Yes")+COUNTIF(F14:T14,"No")=0,"",COUNTIF(F14:T14,"Yes")/(COUNTIF(F14:T14,"Yes")+COUNTIF(F14:T14,"No"))*100) | V14: =COUNTIF(F14:T14,"No")
U15: =IF(COUNTIF(F15:T15,"Yes")+COUNTIF(F15:T15,"No")=0,"",COUNTIF(F15:T15,"Yes")/(COUNTIF(F15:T15,"Yes")+COUNTIF(F15:T15,"No"))*100) | V15: =COUNTIF(F15:T15,"No")
... U153: =IF(COUNTIF(F153:T153,"Yes")+COUNTIF(F153:T153,"No")=0,"",COUNTIF(F153:T153,"Yes")/(COUNTIF(F153:T153,"Yes")+COUNTIF(F153:T153,"No"))*100) | V153: =COUNTIF(F153:T153,"No")

Sheet Hardening_Baseline_Reference
A1: Device Hardening Baseline Reference
A2: Reference guide for device hardening based on CIS Benchmarks and vendor security guides
A4: CIS Benchmarks & Industry Standards
A5: Device Type | B5: Benchmark/Guide | C5: Version | D5: URL/Reference
A6: Cisco IOS | B6: CIS Cisco IOS Benchmark | C6: v4.1.0 | D6: https://www.cisecurity.org/benchmark/cisco
A7: Juniper JunOS | B7: CIS Juniper Benchmark | C7: v2.1.0 | D7: https://www.cisecurity.org/benchmark/juniper
A8: Palo Alto | B8: CIS Palo Alto Firewall Benchmark | C8: v1.1.0 | D8: https://www.cisecurity.org/benchmark/palo_alto_networks
A9: Fortinet | B9: CIS Fortinet FortiOS Benchmark | C9: v1.1.0 | D9: https://www.cisecurity.org/benchmark/fortinet
A10: Aruba | B10: Aruba Hardening Guide | C10: Latest | D10: https://www.arubanetworks.com/techdocs/
A11: Generic Network | B11: NIST SP 800-41 (Firewall/Router) | C11: Rev 1 | D11: https://csrc.nist.gov/publications/detail/sp/800-41/rev-1/final
A12: Wireless | B12: CIS Wireless Network Security | C12: v1.0 | D12: https://www.cisecurity.org/
A14: Hardening Requirements - Implementation Guidance
A15: Requirement | B15: Implementation Guidance | C15: Verification Method
A16: Default Credentials Disabled | B16: Change default usernames/passwords (admin/admin, cisco/cisco, etc.). Disable or rename default accounts. | C16: Attempt login with default credentials (should fail). Review user list.
A17: Strong Password Policy | B17: Min 12 chars, complexity (upper/lower/number/special), expiration 90 days, history 5 passwords. | C17: Check password policy config. Test weak password (should be rejected).
A18: Multi-Factor Authentication | B18: Enable MFA for admin access (TACACS+, RADIUS with OTP/tokens). Critical for privileged access. | C18: Verify AAA config, test login (should require 2nd factor).
A19: Unnecessary Services Disabled | B19: Disable unused protocols: HTTP (use HTTPS), Telnet (use SSH), FTP, TFTP, finger, echo, CDP (on edge). | C19: Port scan device, check running services list.
A20: Secure Management (SSH/HTTPS) | B20: Use SSH for CLI (disable Telnet), HTTPS for web (disable HTTP). SSH v2 only. | C20: Telnet to device (should fail). Check SSH version.
A21: Logging Enabled | B21: Enable syslog to centralized server. Log severity: informational or higher. Buffer logging. | C21: Check logging config, verify logs reaching syslog server.
A22: NTP Configured | B22: Configure NTP client, point to internal NTP servers. Enable NTP authentication if possible. | C22: Check NTP config, verify time sync (ntpstat, show ntp status).
A23: SNMPv3 Only | B23: Use SNMPv3 with authentication and encryption. Disable SNMPv1/v2c (community strings). | C23: Check SNMP config, test v2c query (should fail).
A24: Session Timeouts | B24: Configure idle timeout (e.g., 10 minutes for console, 15 min for VTY). Auto-logout inactive sessions. | C24: Check timeout config (exec-timeout, idle-timeout).
A25: Banner Messages | B25: Configure login banner warning unauthorized access is prohibited. MOTD and login banners. | C25: Check banner config, verify displayed on login.
A26: Configuration Backups | B26: Automated nightly config backups to secure location. Use RANCID, Oxidized, or scripts. | C26: Verify backup schedule, check recent backup files exist.
... A30: Least Privilege Access | B30: Role-based access control (RBAC). Users have minimum privileges needed. Privilege levels configured. | C30: Review user privilege levels, test restricted user access.
A32: Device-Specific Hardening Notes
A33: Routers | B33: Disable IP source routing, enable uRPF, implement ACLs, secure routing protocols (MD5 auth).
A34: Switches | B34: Enable port security, DHCP snooping, DAI, disable DTP, change native VLAN, disable unused ports.
A35: Firewalls | B35: Default deny policy, rule cleanup, logging all denied traffic, regular rule review.
A36: Wireless APs | B36: WPA3 or WPA2-Enterprise, disable WPS, hide SSID (optional), MAC filtering, rogue AP detection.
A37: Load Balancers | B37: Strong SSL/TLS ciphers, disable SSLv3/TLS1.0, enable HSTS, session persistence security.

Sheet Gap_Summary
A1: Device Hardening Gaps - Summary & Remediation Tracking
A2: 📋 Document all "No" responses from Device_Hardening_Assessment. Track remediation progress and priority.
A3: Gap ID | B3: Device ID | C3: Device Type | D3: Hostname | E3: Hardening Requirement | F3: Current State | G3: Gap Severity | H3: Remediation Plan | I3: Owner | J3: Status | K3: Target Date
A4: =IF(B4<>"","HARD-GAP-" & TEXT(1,"000"),"")
A5: =IF(B5<>"","HARD-GAP-" & TEXT(2,"000"),"")
A6: =IF(B6<>"","HARD-GAP-" & TEXT(3,"000"),"")
A7: =IF(B7<>"","HARD-GAP-" & TEXT(4,"000"),"")
A8: =IF(B8<>"","HARD-GAP-" & TEXT(5,"000"),"")
A9: =IF(B9<>"","HARD-GAP-" & TEXT(6,"000"),"")
A10: =IF(B10<>"","HARD-GAP-" & TEXT(7,"000"),"")
A11: =IF(B11<>"","HARD-GAP-" & TEXT(8,"000"),"")
A12: =IF(B12<>"","HARD-GAP-" & TEXT(9,"000"),"")
A13: =IF(B13<>"","HARD-GAP-" & TEXT(10,"000"),"")
A14: =IF(B14<>"","HARD-GAP-" & TEXT(11,"000"),"")
A15: =IF(B15<>"","HARD-GAP-" & TEXT(12,"000"),"")
A16: =IF(B16<>"","HARD-GAP-" & TEXT(13,"000"),"")
A17: =IF(B17<>"","HARD-GAP-" & TEXT(14,"000"),"")
A18: =IF(B18<>"","HARD-GAP-" & TEXT(15,"000"),"")
A19: =IF(B19<>"","HARD-GAP-" & TEXT(16,"000"),"")
A20: =IF(B20<>"","HARD-GAP-" & TEXT(17,"000"),"")
A21: =IF(B21<>"","HARD-GAP-" & TEXT(18,"000"),"")
A22: =IF(B22<>"","HARD-GAP-" & TEXT(19,"000"),"")
A23: =IF(B23<>"","HARD-GAP-" & TEXT(20,"000"),"")
A24: =IF(B24<>"","HARD-GAP-" & TEXT(21,"000"),"")
A25: =IF(B25<>"","HARD-GAP-" & TEXT(22,"000"),"")
A26: =IF(B26<>"","HARD-GAP-" & TEXT(23,"000"),"")
A27: =IF(B27<>"","HARD-GAP-" & TEXT(24,"000"),"")
A28: =IF(B28<>"","HARD-GAP-" & TEXT(25,"000"),"")
A29: =IF(B29<>"","HARD-GAP-" & TEXT(26,"000"),"")
A30: =IF(B30<>"","HARD-GAP-" & TEXT(27,"000"),"")
A31: =IF(B31<>"","HARD-GAP-" & TEXT(28,"000"),"")
A32: =IF(B32<>"","HARD-GAP-" & TEXT(29,"000"),"")
A33: =IF(B33<>"","HARD-GAP-" & TEXT(30,"000"),"")
A34: =IF(B34<>"","HARD-GAP-" & TEXT(31,"000"),"")
A35: =IF(B35<>"","HARD-GAP-" & TEXT(32,"000"),"")
A36: =IF(B36<>"","HARD-GAP-" & TEXT(33,"000"),"")
A37: =IF(B37<>"","HARD-GAP-" & TEXT(34,"000"),"")
A38: =IF(B38<>"","HARD-GAP-" & TEXT(35,"000"),"")
A39: =IF(B39<>"","HARD-GAP-" & TEXT(36,"000"),"")
A40: =IF(B40<>"","HARD-GAP-" & TEXT(37,"000"),"")
...

Sheet Compliance_Scoring
A1: Overall Hardening Compliance Scoring
A3: Summary Statistics
A4: Metric | B4: Value | C4: Formula
A5: Total Devices Assessed | B5: =COUNTA(Device_Hardening_Assessment!A4:A153) | C5: =COUNTA(Device_Hardening_Assessment!A4:A153)
A6: Devices with Score > 0% | B6: =COUNTIF(Device_Hardening_Assessment!U4:U153,">0") | C6: =COUNTIF(Device_Hardening_Assessment!U4:U153,">0")
A7: Average Compliance Score | B7: =AVERAGE(Device_Hardening_Assessment!U4:U153) | C7: =AVERAGE(Device_Hardening_Assessment!U4:U153)
A8: Compliant Devices (≥95%) | B8: =COUNTIF(Device_Hardening_Assessment!U4:U153,">=95") | C8: =COUNTIF(Device_Hardening_Assessment!U4:U153,">=95")
A9: Partially Compliant (80-94%) | B9: =COUNTIFS(Device_Hardening_Assessment!U4:U153,">=80",Device_Hardening_Assessment!U4:U153,"<95") | C9: =COUNTIFS(Device_Hardening_Assessment!U4:U153,">=80",Device_Hardening_Assessment!U4:U153,"<95")
A10: Non-Compliant (<80%) | B10: =COUNTIF(Device_Hardening_Assessment!U4:U153,"<80") | C10: =COUNTIF(Device_Hardening_Assessment!U4:U153,"<80")
A11: Total Identified Gaps | B11: =SUM(Device_Hardening_Assessment!V4:V153) | C11: =SUM(Device_Hardening_Assessment!V4:V153)
A13: Compliance Status Distribution
A14: Status | B14: Count | C14: Percentage
A15: Compliant (≥95%) | B15: =COUNTIF(Device_Hardening_Assessment!U4:U153,">=95") | C15: =B15/B5*100
A16: Partially Compliant (80-94%) | B16: =COUNTIFS(Device_Hardening_Assessment!U4:U153,">=80",Device_Hardening_Assessment!U4:U153,"<95") | C16: =B16/B5*100
A17: Non-Compliant (<80%) | B17: =COUNTIF(Device_Hardening_Assessment!U4:U153,"<80") | C17: =B17/B5*100
A18: Not Assessed | B18: =COUNTIF(Device_Hardening_Assessment!U4:U153,"") | C18: =B18/B5*100
A20: Compliance Targets & Status
A21: Metric | B21: Target | C21: Current | D21: Status
A22: Average Compliance Score | B22: ≥ 95% | C22: =B5 | D22: =IF(C22>=95,"✔ Met","✗ Not Met")
A23: Compliant Devices % | B23: ≥ 80% | C23: =B8/B5*100 | D23: =IF(C23>=80,"✔ Met","✗ Not Met")
A24: Critical Gaps | B24: =0 | C24: =COUNTIF(Gap_Summary!G4:G103,"Critical") | D24: =IF(C24=0,"✔ Met","✗ Not Met")
A25: High Gaps Remediation | B25: ≥ 80% | C25: =COUNTIFS(Gap_Summary!G4:G103,"High",Gap_Summary!J4:J103,"Completed")/COUNTIF(Gap_Summary!G4:G103,"High")*100 | D25: =IF(C25>=80,"✔ Met","✗ Not Met")

Sheet Device_Type_Compliance
A1: Compliance Analysis by Device Type
A2: Breakdown of hardening compliance scores by device type to identify problem areas
A4: Average Compliance Score by Device Type
A5: Device Type | B5: Device Count | C5: Avg Compliance Score | D5: Min Score | E5: Max Score
A6: Router | B6: =COUNTIF(Device_Hardening_Assessment!B4:B153,"Router") | C6: =AVERAGEIF(Device_Hardening_Assessment!B4:B153,"Router",Device_Hardening_Assessment!U4:U153) | D6: =MINIFS(Device_Hardening_Assessment!U4:U153,Device_Hardening_Assessment!B4:B153,"Router") | E6: =MAXIFS(Device_Hardening_Assessment!U4:U153,Device_Hardening_Assessment!B4:B153,"Router")
A7: Switch | B7: =COUNTIF(Device_Hardening_Assessment!B4:B153,"Switch") | C7: =AVERAGEIF(Device_Hardening_Assessment!B4:B153,"Switch",Device_Hardening_Assessment!U4:U153) | D7: =MINIFS(Device_Hardening_Assessment!U4:U153,Device_Hardening_Assessment!B4:B153,"Switch") | E7: =MAXIFS(Device_Hardening_Assessment!U4:U153,Device_Hardening_Assessment!B4:B153,"Switch")
A8: Firewall | B8: =COUNTIF(Device_Hardening_Assessment!B4:B153,"Firewall") | C8: =AVERAGEIF(Device_Hardening_Assessment!B4:B153,"Firewall",Device_Hardening_Assessment!U4:U153) | D8: =MINIFS(Device_Hardening_Assessment!U4:U153,Device_Hardening_Assessment!B4:B153,"Firewall") | E8: =MAXIFS(Device_Hardening_Assessment!U4:U153,Device_Hardening_Assessment!B4:B153,"Firewall")
A9: Wireless AP | B9: =COUNTIF(Device_Hardening_Assessment!B4:B153,"Wireless AP") | C9: =AVERAGEIF(Device_Hardening_Assessment!B4:B153,"Wireless AP",Device_Hardening_Assessment!U4:U153) | D9: =MINIFS(Device_Hardening_Assessment!U4:U153,Device_Hardening_Assessment!B4:B153,"Wireless AP") | E9: =MAXIFS(Device_Hardening_Assessment!U4:U153,Device_Hardening_Assessment!B4:B153,"Wireless AP")
A10: Load Balancer | B10: =COUNTIF(Device_Hardening_Assessment!B4:B153,"Load Balancer") | C10: =AVERAGEIF(Device_Hardening_Assessment!B4:B153,"Load Balancer",Device_Hardening_Assessment!U4:U153) | D10: =MINIFS(Device_Hardening_Assessment!U4:U153,Device_Hardening_Assessment!B4:B153,"Load Balancer") | E10: =MAXIFS(Device_Hardening_Assessment!U4:U153,Device_Hardening_Assessment!B4:B153,"Load Balancer")
A11: VPN Concentrator | B11: =COUNTIF(Device_Hardening_Assessment!B4:B153,"VPN Concentrator") | C11: =AVERAGEIF(Device_Hardening_Assessment!B4:B153,"VPN Concentrator",Device_Hardening_Assessment!U4:U153) | D11: =MINIFS(Device_Hardening_Assessment!U4:U153,Device_Hardening_Assessment!B4:B153,"VPN Concentrator") | E11: =MAXIFS(Device_Hardening_Assessment!U4:U153,Device_Hardening_Assessment!B4:B153,"VPN Concentrator")
A12: IDS/IPS | B12: =COUNTIF(Device_Hardening_Assessment!B4:B153,"IDS/IPS") | C12: =AVERAGEIF(Device_Hardening_Assessment!B4:B153,"IDS/IPS",Device_Hardening_Assessment!U4:U153) | D12: =MINIFS(Device_Hardening_Assessment!U4:U153,Device_Hardening_Assessment!B4:B153,"IDS/IPS") | E12: =MAXIFS(Device_Hardening_Assessment!U4:U153,Device_Hardening_Assessment!B4:B153,"IDS/IPS")
A13: Network Management | B13: =COUNTIF(Device_Hardening_Assessment!B4:B153,"Network Management") | C13: =AVERAGEIF(Device_Hardening_Assessment!B4:B153,"Network Management",Device_Hardening_Assessment!U4:U153) | D13: =MINIFS(Device_Hardening_Assessment!U4:U153,Device_Hardening_Assessment!B4:B153,"Network Management") | E13: =MAXIFS(Device_Hardening_Assessment!U4:U153,Device_Hardening_Assessment!B4:B153,"Network Management")
A14: Other | B14: =COUNTIF(Device_Hardening_Assessment!B4:B153,"Other") | C14: =AVERAGEIF(Device_Hardening_Assessment!B4:B153,"Other",Device_Hardening_Assessment!U4:U153) | D14: =MINIFS(Device_Hardening_Assessment!U4:U153,Device_Hardening_Assessment!B4:B153,"Other") | E14: =MAXIFS(Device_Hardening_Assessment!U4:U153,Device_Hardening_Assessment!B4:B153,"Other")

Sheet Top_Gaps_Analysis
A1: Top Hardening Gaps - Most Common Failures
A2: Identify most frequently failed hardening requirements across all devices
A4: Hardening Requirements Failure Analysis (15 Requirements)
A5: Requirement | B5: Total 'No' Count | C5: Failure Rate % | D5: Priority
A6: Default Credentials Disabled | B6: =COUNTIF(Device_Hardening_Assessment!F4:F153,"No") | C6: =B6/COUNTA(Device_Hardening_Assessment!F4:F153)*100 | D6: =IF(C6>=75,"CRITICAL",IF(C6>=50,"HIGH",IF(C6>=25,"MEDIUM","LOW")))
A7: Strong Password Policy | B7: =COUNTIF(Device_Hardening_Assessment!G4:G153,"No") | C7: =B7/COUNTA(Device_Hardening_Assessment!G4:G153)*100 | D7: =IF(C7>=75,"CRITICAL",IF(C7>=50,"HIGH",IF(C7>=25,"MEDIUM","LOW")))
A8: Multi-Factor Authentication (MFA) | B8: =COUNTIF(Device_Hardening_Assessment!H4:H153,"No") | C8: =B8/COUNTA(Device_Hardening_Assessment!H4:H153)*100 | D8: =IF(C8>=75,"CRITICAL",IF(C8>=50,"HIGH",IF(C8>=25,"MEDIUM","LOW")))
A9: Unnecessary Services Disabled | B9: =COUNTIF(Device_Hardening_Assessment!I4:I153,"No") | C9: =B9/COUNTA(Device_Hardening_Assessment!I4:I153)*100 | D9: =IF(C9>=75,"CRITICAL",IF(C9>=50,"HIGH",IF(C9>=25,"MEDIUM","LOW")))
A10: Secure Management (SSH/HTTPS Only) | B10: =COUNTIF(Device_Hardening_Assessment!J4:J153,"No") | C10: =B10/COUNTA(Device_Hardening_Assessment!J4:J153)*100 | D10: =IF(C10>=75,"CRITICAL",IF(C10>=50,"HIGH",IF(C10>=25,"MEDIUM","LOW")))
A11: Logging Enabled | B11: =COUNTIF(Device_Hardening_Assessment!K4:K153,"No") | C11: =B11/COUNTA(Device_Hardening_Assessment!K4:K153)*100 | D11: =IF(C11>=75,"CRITICAL",IF(C11>=50,"HIGH",IF(C11>=25,"MEDIUM","LOW")))
A12: NTP Configured | B12: =COUNTIF(Device_Hardening_Assessment!L4:L153,"No") | C12: =B12/COUNTA(Device_Hardening_Assessment!L4:L153)*100 | D12: =IF(C12>=75,"CRITICAL",IF(C12>=50,"HIGH",IF(C12>=25,"MEDIUM","LOW")))
A13: SNMPv3 Only (v1/v2c Disabled) | B13: =COUNTIF(Device_Hardening_Assessment!M4:M153,"No") | C13: =B13/COUNTA(Device_Hardening_Assessment!M4:M153)*100 | D13: =IF(C13>=75,"CRITICAL",IF(C13>=50,"HIGH",IF(C13>=25,"MEDIUM","LOW")))
A14: Session Timeouts Configured | B14: =COUNTIF(Device_Hardening_Assessment!N4:N153,"No") | C14: =B14/COUNTA(Device_Hardening_Assessment!N4:N153)*100 | D14: =IF(C14>=75,"CRITICAL",IF(C14>=50,"HIGH",IF(C14>=25,"MEDIUM","LOW")))
A15: Banner Messages Configured | B15: =COUNTIF(Device_Hardening_Assessment!O4:O153,"No") | C15: =B15/COUNTA(Device_Hardening_Assessment!O4:O153)*100 | D15: =IF(C15>=75,"CRITICAL",IF(C15>=50,"HIGH",IF(C15>=25,"MEDIUM","LOW")))
A16: Configuration Backups | B16: =COUNTIF(Device_Hardening_Assessment!P4:P153,"No") | C16: =B16/COUNTA(Device_Hardening_Assessment!P4:P153)*100 | D16: =IF(C16>=75,"CRITICAL",IF(C16>=50,"HIGH",IF(C16>=25,"MEDIUM","LOW")))
A17: Firmware/Software Up-to-Date | B17: =COUNTIF(Device_Hardening_Assessment!Q4:Q153,"No") | C17: =B17/COUNTA(Device_Hardening_Assessment!Q4:Q153)*100 | D17: =IF(C17>=75,"CRITICAL",IF(C17>=50,"HIGH",IF(C17>=25,"MEDIUM","LOW")))
A18: Access Control Lists (ACLs) | B18: =COUNTIF(Device_Hardening_Assessment!R4:R153,"No") | C18: =B18/COUNTA(Device_Hardening_Assessment!R4:R153)*100 | D18: =IF(C18>=75,"CRITICAL",IF(C18>=50,"HIGH",IF(C18>=25,"MEDIUM","LOW")))
A19: Encrypted Management Traffic | B19: =COUNTIF(Device_Hardening_Assessment!S4:S153,"No") | C19: =B19/COUNTA(Device_Hardening_Assessment!S4:S153)*100 | D19: =IF(C19>=75,"CRITICAL",IF(C19>=50,"HIGH",IF(C19>=25,"MEDIUM","LOW")))
A20: Least Privilege Access | B20: =COUNTIF(Device_Hardening_Assessment!T4:T153,"No") | C20: =B20/COUNTA(Device_Hardening_Assessment!T4:T153)*100 | D20: =IF(C20>=75,"CRITICAL",IF(C20>=50,"HIGH",IF(C20>=25,"MEDIUM","LOW")))

Sheet Remediation_Roadmap
A1: Hardening Remediation Roadmap
A2: 📋 Prioritized remediation plan sorted by severity. Focus on Critical/High gaps first.
A3: Priority | B3: Severity | C3: Gap Description | D3: Affected Devices | E3: Remediation Action | F3: Owner | G3: Target Date | H3: Status
A4: 1
A5: 2
A6: 3
A7: 4
A8: 5
A9: 6
A10: 7
A11: 8
A12: 9
A13: 10
A14: 11
A15: 12
... A53: 50
A55: Remediation Approach Guidelines
A56: 1. PRIORITIZE BY SEVERITY: Address Critical gaps immediately, then High, then Medium/Low
A57: 2. CLUSTER BY REQUIREMENT: Remediate same requirement across multiple devices together (efficiency)
A58: 3. LOW-HANGING FRUIT: Quick wins (e.g., enable logging, configure banners) → build momentum
A59: 4. COMPLEX ITEMS: MFA, major config changes require planning, testing, approval
A60: 5. VALIDATE: Test in lab/dev environment before production deployment
A61: 6. DOCUMENT: Maintain change records, configuration backups, validation evidence
A62: 7. RE-ASSESS: After remediation, re-run assessment to confirm compliance improvement
