Workbook

Sheet Executive Summary
A1: CLD-CHK-A.6 — Use, Retention and Disclosure Limitation Compliance Checklist
A3: DOCUMENT INFORMATION
A4: Document ID | B4: CLD-CHK-A.6
A5: Source Policy | B5: CLD-POL-A.6
A6: ISO Controls | B6: Use, Retention and Disclosure Limitation
A7: Generated | B7: 10.03.2026
A8: Prepared By
A9: Organisation
A10: Review Cycle | B10: Annual
A12: OVERALL COMPLIANCE STATUS
A13: Overall Compliance | B13: ='Dashboard'!G6
A14: Status | B14: =IF(Dashboard!G6="N/A","NOT ASSESSED",IF(ISNUMBER(VALUE(SUBSTITUTE(Dashboard!G6,"%",""))),IF(VALUE(SUBSTITUTE(Dashboard!G6,"%",""))>=90,"GREEN",IF(VALUE(SUBSTITUTE(Dashboard!G6,"%",""))>=70,"AMBER","RED")),"NOT ASSESSED"))
A16: KEY METRICS
A17: Total Requirements | B17: ='Dashboard'!B6
A18: Compliant | B18: ='Dashboard'!C6
A19: Partial | B19: ='Dashboard'!D6
A20: Non-Compliant | B20: ='Dashboard'!E6
A21: Not Applicable | B21: ='Dashboard'!F6
A22: Owner Coverage | B22: =IF(Dashboard!B6=0,"N/A",ROUND((COUNTA('Retention Limitation and Disclosure Notification'!F4:F8)+COUNTA('Recording of PII Disclosures'!F4:F7))/Dashboard!B6*100,0)&"%")
A24: DOMAIN STATUS SUMMARY
A25: Domain | B25: Compliance % | C25: Compliant | D25: Gaps | E25: Status
A26: Retention Limitation and Disclosure Notification | B26: ='Dashboard'!G4 | C26: ='Dashboard'!C4 | D26: ='Dashboard'!E4 | E26: =IF(Dashboard!G4="N/A","--",IF(ISNUMBER(VALUE(SUBSTITUTE(Dashboard!G4,"%",""))),IF(VALUE(SUBSTITUTE(Dashboard!G4,"%",""))>=90,"PASS",IF(VALUE(SUBSTITUTE(Dashboard!G4,"%",""))>=70,"REVIEW","FAIL")),"--"))
A27: Recording of PII Disclosures | B27: ='Dashboard'!G5 | C27: ='Dashboard'!C5 | D27: ='Dashboard'!E5 | E27: =IF(Dashboard!G5="N/A","--",IF(ISNUMBER(VALUE(SUBSTITUTE(Dashboard!G5,"%",""))),IF(VALUE(SUBSTITUTE(Dashboard!G5,"%",""))>=90,"PASS",IF(VALUE(SUBSTITUTE(Dashboard!G5,"%",""))>=70,"REVIEW","FAIL")),"--"))
A29: CRITICAL ISSUES
A30: # | B30: Issue Description | C30: Domain | D30: Owner | E30: Due Date
A31: 1
A32: 2
A33: 3
A34: 4
A35: 5
A37: MANAGEMENT COMMENTARY
A38: [Enter management commentary on use, retention and disclosure limitation posture]
A42: APPROVAL
A43: Assessed By
A44: Name:
A45: Date:
A46: Signature:
A47: Decision:
A49: Reviewed By (DPO)
A50: Name:
...

Sheet Dashboard
A1: Use, Retention and Disclosure Limitation — Compliance Dashboard
A3: Domain | B3: Total Reqs | C3: Compliant | D3: Partial | E3: Non-Compliant | F3: N/A | G3: Compliance %
A4: Retention Limitation and Disclosure Notification | B4: =COUNTA('Retention Limitation and Disclosure Notification'!D4:D8) | C4: =COUNTIF('Retention Limitation and Disclosure Notification'!D4:D8,"Compliant") | D4: =COUNTIF('Retention Limitation and Disclosure Notification'!D4:D8,"Partial") | E4: =COUNTIF('Retention Limitation and Disclosure Notification'!D4:D8,"Non-Compliant") | F4: =COUNTIF('Retention Limitation and Disclosure Notification'!D4:D8,"N/A") | G4: =IF((B4-F4)=0,"N/A",ROUND(C4/(B4-F4)*100,1)&"%")
A5: Recording of PII Disclosures | B5: =COUNTA('Recording of PII Disclosures'!D4:D7) | C5: =COUNTIF('Recording of PII Disclosures'!D4:D7,"Compliant") | D5: =COUNTIF('Recording of PII Disclosures'!D4:D7,"Partial") | E5: =COUNTIF('Recording of PII Disclosures'!D4:D7,"Non-Compliant") | F5: =COUNTIF('Recording of PII Disclosures'!D4:D7,"N/A") | G5: =IF((B5-F5)=0,"N/A",ROUND(C5/(B5-F5)*100,1)&"%")
A6: TOTAL | B6: =SUM(B4:B5) | C6: =SUM(C4:C5) | D6: =SUM(D4:D5) | E6: =SUM(E4:E5) | F6: =SUM(F4:F5) | G6: =IF((B6-F6)=0,"N/A",ROUND(C6/(B6-F6)*100,1)&"%")
A8: COMPLIANCE BY STATUS
A9: Compliant | B9: =C6 | C9: =IF(B6=0,"",ROUND(B9/B6*100,1)&"%")
A10: Partial | B10: =D6 | C10: =IF(B6=0,"",ROUND(B10/B6*100,1)&"%")
A11: Non-Compliant | B11: =E6 | C11: =IF(B6=0,"",ROUND(B11/B6*100,1)&"%")
A12: N/A | B12: =F6 | C12: =IF(B6=0,"",ROUND(B12/B6*100,1)&"%")
A14: TOP GAPS (Manual Entry)
A15: Priority | B15: Domain | C15: Requirement | D15: Owner | E15: Due Date | F15: Status
A27: COMPLIANCE TREND (Manual Entry)
A28: Assessment Date | B28: Overall % | C28: Compliant | D28: Gaps | E28: Assessor | F28: Notes

Sheet Retention Limitation and Disclosure Notification
A1: Retention Limitation and Disclosure Notification — Compliance Checklist
A2: ISO/IEC 27018:2025 — Controls A.6.1-2: Use, Retention and Disclosure Limitation
A3: Req # | B3: Section | C3: Requirement | D3: Status | E3: Evidence | F3: Owner | G3: Due Date | H3: Notes
A4: A.6-01 | B4: Retention Schedule Adherence | C4: The organisation shall retain PII on behalf of controllers only for the duration specified in the service agreement. Where the service agreement does not specify a retention period, the organisation shall request explicit written instructions from the PII controller before implementing any retention configuration.
A5: A.6-02 | B5: Automated Retention Enforcement | C5: The organisation shall implement automated retention enforcement (automated deletion or archival) wherever technically feasible. Reliance on manual deletion is acceptable only where automated enforcement is technically not possible, in which case manual deletion shall be scheduled, logged, and reviewed quarterly.
A6: A.6.1-01 | B6: Prior Notification of Compelled Disclosure | C6: Where the organisation receives a legally binding request from a law enforcement agency, regulatory authority, court, or other governmental body requiring disclosure of PII belonging to a PII controller, the organisation shall notify the relevant PII controller prior to disclosure, including: the identity of the requesting authority (to the extent legally permissible); the categories and scope of PII requested; the legal basis cited; and the requested disclosure deadline. The controller shall be given a reasonable opportunity to seek legal challenge before disclosure where the deadline permits.
A7: A.6.1-02 | B7: Notification Prohibited by Law | C7: Where applicable law prohibits the organisation from notifying the PII controller of a disclosure request, the organisation shall: document the legal prohibition and the date from which notification is restricted; notify the PII controller at the earliest opportunity after the prohibition lapses; and if permanently prohibited, publish a transparency report or warrant canary to the maximum extent legally permissible.
A8: A.6.1-03 | B8: Minimum Disclosure Principle | C8: All legally compelled disclosures shall be limited to the minimum PII required to satisfy the legal obligation. The organisation shall not provide broader access or data sets than specifically required by the legal order. Where the scope of a legal order is ambiguous, legal advice shall be sought before responding.

Sheet Recording of PII Disclosures
A1: Recording of PII Disclosures — Compliance Checklist
A2: ISO/IEC 27018:2025 — Controls A.6.1-2: Use, Retention and Disclosure Limitation
A3: Req # | B3: Section | C3: Requirement | D3: Status | E3: Evidence | F3: Owner | G3: Due Date | H3: Notes
A4: A.6.2-01 | B4: PII Disclosure Register | C4: The organisation shall maintain a PII Disclosure Register recording every disclosure of PII to a third party, including legally compelled disclosures. Each entry shall record: date of disclosure; recipient identity; categories of PII disclosed; approximate number of data subjects affected; legal basis or controller instruction authorising the disclosure; whether the PII controller was notified (and if not, reason and date of subsequent notification); and the authorising officer.
A5: A.6.2-02 | B5: Register Maintenance | C5: The PII Disclosure Register shall be maintained by the DPO, protected against unauthorised modification, and subject to quarterly review. The register shall be retained for minimum 5 years from the date of each recorded disclosure.
A6: A.6.2-03 | B6: Controller Access | C6: The PII Disclosure Register shall be made available to any PII controller upon request, restricted to records pertaining to that controller's PII. The organisation shall respond to controller register access requests within 5 business days.
A7: A.6.2-04 | B7: Transparency Reporting | C7: The organisation shall publish an annual transparency report summarising legally compelled disclosure requests received (where legally permissible), including aggregated counts of requests by type and jurisdiction, and the number of notifications issued to PII controllers. Where a warrant canary is maintained, it shall be updated at minimum every 6 months.
