Workbook

Sheet Executive Summary
A1: ISMS-OP-CHK-A.5.19-23 — Cloud Services and Supplier Security Compliance Checklist
A3: DOCUMENT INFORMATION
A4: Document ID | B4: ISMS-OP-CHK-A.5.19-23
A5: Source Policy | B5: ISMS-OP-POL-A.5.19-23
A6: ISO Controls | B6: Cloud Services and Supplier Security
A7: Generated | B7: 30.09.2026
A8: Prepared By
A9: Organisation
A10: Review Cycle | B10: Annual
A12: OVERALL COMPLIANCE STATUS
A13: Overall Compliance | B13: ='Dashboard'!G13
A14: Status | B14: =IF(Dashboard!H13>0,"INCOMPLETE",IF(Dashboard!G13="N/A","NOT ASSESSED",IF(ISNUMBER(VALUE(SUBSTITUTE(Dashboard!G13,"%",""))),IF(VALUE(SUBSTITUTE(Dashboard!G13,"%",""))>=90,"GREEN",IF(VALUE(SUBSTITUTE(Dashboard!G13,"%",""))>=70,"AMBER","RED")),"NOT ASSESSED")))
A16: KEY METRICS
A17: Total Requirements | B17: ='Dashboard'!B13
A18: Compliant | B18: ='Dashboard'!C13
A19: Partial | B19: ='Dashboard'!D13
A20: Non-Compliant | B20: ='Dashboard'!E13
A21: Not Applicable | B21: ='Dashboard'!F13
A22: Unanswered | B22: ='Dashboard'!H13
A23: Owner Coverage | B23: =IF(Dashboard!B13=0,"N/A",ROUND((COUNTA('Supplier & Cloud Service'!F4:F8)+COUNTA('Info Security Requirements'!F4:F4)+COUNTA('Audit and Review'!F4:F5)+COUNTA('Risk Management'!F4:F6)+COUNTA('Supplier & Cloud Service Select'!F4:F5)+COUNTA('Contracts, Agreements & Data'!F4:F12)+COUNTA('Security Incident Management'!F4:F10)+COUNTA('End of Contract'!F4:F5)+COUNTA('Changes Cloud Service Supplier'!F4:F7))/Dashboard!B13*100,0)&"%")
A25: DOMAIN STATUS SUMMARY
A26: Domain | B26: Compliance % | C26: Compliant | D26: Gaps | E26: Status
A27: Supplier & Cloud Service | B27: ='Dashboard'!G4 | C27: ='Dashboard'!C4 | D27: ='Dashboard'!E4 | E27: =IF(Dashboard!H4>0,"INCOMPLETE",IF(Dashboard!G4="N/A","--",IF(ISNUMBER(VALUE(SUBSTITUTE(Dashboard!G4,"%",""))),IF(VALUE(SUBSTITUTE(Dashboard!G4,"%",""))>=90,"PASS",IF(VALUE(SUBSTITUTE(Dashboard!G4,"%",""))>=70,"REVIEW","FAIL")),"--")))
A28: Info Security Requirements | B28: ='Dashboard'!G5 | C28: ='Dashboard'!C5 | D28: ='Dashboard'!E5 | E28: =IF(Dashboard!H5>0,"INCOMPLETE",IF(Dashboard!G5="N/A","--",IF(ISNUMBER(VALUE(SUBSTITUTE(Dashboard!G5,"%",""))),IF(VALUE(SUBSTITUTE(Dashboard!G5,"%",""))>=90,"PASS",IF(VALUE(SUBSTITUTE(Dashboard!G5,"%",""))>=70,"REVIEW","FAIL")),"--")))
A29: Audit and Review | B29: ='Dashboard'!G6 | C29: ='Dashboard'!C6 | D29: ='Dashboard'!E6 | E29: =IF(Dashboard!H6>0,"INCOMPLETE",IF(Dashboard!G6="N/A","--",IF(ISNUMBER(VALUE(SUBSTITUTE(Dashboard!G6,"%",""))),IF(VALUE(SUBSTITUTE(Dashboard!G6,"%",""))>=90,"PASS",IF(VALUE(SUBSTITUTE(Dashboard!G6,"%",""))>=70,"REVIEW","FAIL")),"--")))
A30: Risk Management | B30: ='Dashboard'!G7 | C30: ='Dashboard'!C7 | D30: ='Dashboard'!E7 | E30: =IF(Dashboard!H7>0,"INCOMPLETE",IF(Dashboard!G7="N/A","--",IF(ISNUMBER(VALUE(SUBSTITUTE(Dashboard!G7,"%",""))),IF(VALUE(SUBSTITUTE(Dashboard!G7,"%",""))>=90,"PASS",IF(VALUE(SUBSTITUTE(Dashboard!G7,"%",""))>=70,"REVIEW","FAIL")),"--")))
A31: Supplier & Cloud Service Select | B31: ='Dashboard'!G8 | C31: ='Dashboard'!C8 | D31: ='Dashboard'!E8 | E31: =IF(Dashboard!H8>0,"INCOMPLETE",IF(Dashboard!G8="N/A","--",IF(ISNUMBER(VALUE(SUBSTITUTE(Dashboard!G8,"%",""))),IF(VALUE(SUBSTITUTE(Dashboard!G8,"%",""))>=90,"PASS",IF(VALUE(SUBSTITUTE(Dashboard!G8,"%",""))>=70,"REVIEW","FAIL")),"--")))
A32: Contracts, Agreements & Data | B32: ='Dashboard'!G9 | C32: ='Dashboard'!C9 | D32: ='Dashboard'!E9 | E32: =IF(Dashboard!H9>0,"INCOMPLETE",IF(Dashboard!G9="N/A","--",IF(ISNUMBER(VALUE(SUBSTITUTE(Dashboard!G9,"%",""))),IF(VALUE(SUBSTITUTE(Dashboard!G9,"%",""))>=90,"PASS",IF(VALUE(SUBSTITUTE(Dashboard!G9,"%",""))>=70,"REVIEW","FAIL")),"--")))
A33: Security Incident Management | B33: ='Dashboard'!G10 | C33: ='Dashboard'!C10 | D33: ='Dashboard'!E10 | E33: =IF(Dashboard!H10>0,"INCOMPLETE",IF(Dashboard!G10="N/A","--",IF(ISNUMBER(VALUE(SUBSTITUTE(Dashboard!G10,"%",""))),IF(VALUE(SUBSTITUTE(Dashboard!G10,"%",""))>=90,"PASS",IF(VALUE(SUBSTITUTE(Dashboard!G10,"%",""))>=70,"REVIEW","FAIL")),"--")))
A34: End of Contract | B34: ='Dashboard'!G11 | C34: ='Dashboard'!C11 | D34: ='Dashboard'!E11 | E34: =IF(Dashboard!H11>0,"INCOMPLETE",IF(Dashboard!G11="N/A","--",IF(ISNUMBER(VALUE(SUBSTITUTE(Dashboard!G11,"%",""))),IF(VALUE(SUBSTITUTE(Dashboard!G11,"%",""))>=90,"PASS",IF(VALUE(SUBSTITUTE(Dashboard!G11,"%",""))>=70,"REVIEW","FAIL")),"--")))
A35: Changes Cloud Service Supplier | B35: ='Dashboard'!G12 | C35: ='Dashboard'!C12 | D35: ='Dashboard'!E12 | E35: =IF(Dashboard!H12>0,"INCOMPLETE",IF(Dashboard!G12="N/A","--",IF(ISNUMBER(VALUE(SUBSTITUTE(Dashboard!G12,"%",""))),IF(VALUE(SUBSTITUTE(Dashboard!G12,"%",""))>=90,"PASS",IF(VALUE(SUBSTITUTE(Dashboard!G12,"%",""))>=70,"REVIEW","FAIL")),"--")))
A37: CRITICAL ISSUES
A38: # | B38: Issue Description | C38: Domain | D38: Owner | E38: Due Date
A39: 1
A40: 2
A41: 3
A42: 4
A43: 5
A45: MANAGEMENT COMMENTARY
A46: [Enter management commentary on cloud services and supplier security posture]
...

Sheet Dashboard
A1: Cloud Services and Supplier Security — Compliance Dashboard
A3: Domain | B3: Total Reqs | C3: Compliant | D3: Partial | E3: Non-Compliant | F3: N/A | G3: Compliance % | H3: Unassessed
A4: Supplier & Cloud Service | B4: =COUNTA('Supplier & Cloud Service'!A4:A8) | C4: =COUNTIF('Supplier & Cloud Service'!D4:D8,"Compliant") | D4: =COUNTIF('Supplier & Cloud Service'!D4:D8,"Partial") | E4: =COUNTIF('Supplier & Cloud Service'!D4:D8,"Non-Compliant") | F4: =COUNTIF('Supplier & Cloud Service'!D4:D8,"N/A") | G4: =IF((B4-F4)=0,"N/A",ROUND(C4/(B4-F4)*100,1)&"%") | H4: =B4-(C4+D4+E4+F4)
A5: Info Security Requirements | B5: =COUNTA('Info Security Requirements'!A4:A4) | C5: =COUNTIF('Info Security Requirements'!D4:D4,"Compliant") | D5: =COUNTIF('Info Security Requirements'!D4:D4,"Partial") | E5: =COUNTIF('Info Security Requirements'!D4:D4,"Non-Compliant") | F5: =COUNTIF('Info Security Requirements'!D4:D4,"N/A") | G5: =IF((B5-F5)=0,"N/A",ROUND(C5/(B5-F5)*100,1)&"%") | H5: =B5-(C5+D5+E5+F5)
A6: Audit and Review | B6: =COUNTA('Audit and Review'!A4:A5) | C6: =COUNTIF('Audit and Review'!D4:D5,"Compliant") | D6: =COUNTIF('Audit and Review'!D4:D5,"Partial") | E6: =COUNTIF('Audit and Review'!D4:D5,"Non-Compliant") | F6: =COUNTIF('Audit and Review'!D4:D5,"N/A") | G6: =IF((B6-F6)=0,"N/A",ROUND(C6/(B6-F6)*100,1)&"%") | H6: =B6-(C6+D6+E6+F6)
A7: Risk Management | B7: =COUNTA('Risk Management'!A4:A6) | C7: =COUNTIF('Risk Management'!D4:D6,"Compliant") | D7: =COUNTIF('Risk Management'!D4:D6,"Partial") | E7: =COUNTIF('Risk Management'!D4:D6,"Non-Compliant") | F7: =COUNTIF('Risk Management'!D4:D6,"N/A") | G7: =IF((B7-F7)=0,"N/A",ROUND(C7/(B7-F7)*100,1)&"%") | H7: =B7-(C7+D7+E7+F7)
A8: Supplier & Cloud Service Select | B8: =COUNTA('Supplier & Cloud Service Select'!A4:A5) | C8: =COUNTIF('Supplier & Cloud Service Select'!D4:D5,"Compliant") | D8: =COUNTIF('Supplier & Cloud Service Select'!D4:D5,"Partial") | E8: =COUNTIF('Supplier & Cloud Service Select'!D4:D5,"Non-Compliant") | F8: =COUNTIF('Supplier & Cloud Service Select'!D4:D5,"N/A") | G8: =IF((B8-F8)=0,"N/A",ROUND(C8/(B8-F8)*100,1)&"%") | H8: =B8-(C8+D8+E8+F8)
A9: Contracts, Agreements & Data | B9: =COUNTA('Contracts, Agreements & Data'!A4:A12) | C9: =COUNTIF('Contracts, Agreements & Data'!D4:D12,"Compliant") | D9: =COUNTIF('Contracts, Agreements & Data'!D4:D12,"Partial") | E9: =COUNTIF('Contracts, Agreements & Data'!D4:D12,"Non-Compliant") | F9: =COUNTIF('Contracts, Agreements & Data'!D4:D12,"N/A") | G9: =IF((B9-F9)=0,"N/A",ROUND(C9/(B9-F9)*100,1)&"%") | H9: =B9-(C9+D9+E9+F9)
A10: Security Incident Management | B10: =COUNTA('Security Incident Management'!A4:A10) | C10: =COUNTIF('Security Incident Management'!D4:D10,"Compliant") | D10: =COUNTIF('Security Incident Management'!D4:D10,"Partial") | E10: =COUNTIF('Security Incident Management'!D4:D10,"Non-Compliant") | F10: =COUNTIF('Security Incident Management'!D4:D10,"N/A") | G10: =IF((B10-F10)=0,"N/A",ROUND(C10/(B10-F10)*100,1)&"%") | H10: =B10-(C10+D10+E10+F10)
A11: End of Contract | B11: =COUNTA('End of Contract'!A4:A5) | C11: =COUNTIF('End of Contract'!D4:D5,"Compliant") | D11: =COUNTIF('End of Contract'!D4:D5,"Partial") | E11: =COUNTIF('End of Contract'!D4:D5,"Non-Compliant") | F11: =COUNTIF('End of Contract'!D4:D5,"N/A") | G11: =IF((B11-F11)=0,"N/A",ROUND(C11/(B11-F11)*100,1)&"%") | H11: =B11-(C11+D11+E11+F11)
A12: Changes Cloud Service Supplier | B12: =COUNTA('Changes Cloud Service Supplier'!A4:A7) | C12: =COUNTIF('Changes Cloud Service Supplier'!D4:D7,"Compliant") | D12: =COUNTIF('Changes Cloud Service Supplier'!D4:D7,"Partial") | E12: =COUNTIF('Changes Cloud Service Supplier'!D4:D7,"Non-Compliant") | F12: =COUNTIF('Changes Cloud Service Supplier'!D4:D7,"N/A") | G12: =IF((B12-F12)=0,"N/A",ROUND(C12/(B12-F12)*100,1)&"%") | H12: =B12-(C12+D12+E12+F12)
A13: TOTAL | B13: =SUM(B4:B12) | C13: =SUM(C4:C12) | D13: =SUM(D4:D12) | E13: =SUM(E4:E12) | F13: =SUM(F4:F12) | G13: =IF((B13-F13)=0,"N/A",ROUND(C13/(B13-F13)*100,1)&"%") | H13: =SUM(H4:H12)
A15: COMPLIANCE BY STATUS
A16: Compliant | B16: =C13 | C16: =IF(B13=0,"",ROUND(B16/B13*100,1)&"%")
A17: Partial | B17: =D13 | C17: =IF(B13=0,"",ROUND(B17/B13*100,1)&"%")
A18: Non-Compliant | B18: =E13 | C18: =IF(B13=0,"",ROUND(B18/B13*100,1)&"%")
A19: N/A | B19: =F13 | C19: =IF(B13=0,"",ROUND(B19/B13*100,1)&"%")
A21: TOP GAPS (Manual Entry)
A22: Priority | B22: Domain | C22: Requirement | D22: Owner | E22: Due Date | F22: Status
A34: COMPLIANCE TREND (Manual Entry)
A35: Assessment Date | B35: Overall % | C35: Compliant | D35: Gaps | E35: Assessor | F35: Notes

Sheet Supplier & Cloud Service
A1: Supplier & Cloud Service — Compliance Checklist
A2: ISO/IEC 27001:2022 — Controls A.5.19-23: Cloud Services and Supplier Security
A3: Req # | B3: Section | C3: Requirement | D3: Status | E3: Evidence | F3: Owner | G3: Due Date | H3: Notes
A4: A.5.19-23-01 | B4: Third-Party Suppliers And Cloud Services | C4: All third-party suppliers and cloud services shall be registered and recorded in the Supplier and Cloud Service Register.
A5: A.5.19-23-02 | B5: Update Frequency: The Register | C5: Update frequency: The register shall be reviewed and updated at least quarterly* or upon any new supplier engagement, contract change, or supplier exit.
A6: A.5.19-23-03 | B6: Suppliers And Cloud Services | C6: Suppliers and cloud services shall be assessed for criticality to the business.
A7: A.5.19-23-04 | B7: Suppliers And Cloud Services | C7: Suppliers and cloud services shall be classified based on the data processed, stored, or transmitted and their criticality to business operations:.
A8: A.5.19-23-05 | B8: In Addition, The Following | C8: In addition, the following shall be captured as a minimum:.

Sheet Info Security Requirements
A1: Info Security Requirements — Compliance Checklist
A2: ISO/IEC 27001:2022 — Controls A.5.19-23: Cloud Services and Supplier Security
A3: Req # | B3: Section | C3: Requirement | D3: Status | E3: Evidence | F3: Owner | G3: Due Date | H3: Notes
A4: A.5.19-23-06 | B4: The Organisation | C4: Where a supplier cannot provide recognised certification, the organisation shall conduct a documented risk assessment and, if the supplier is engaged, implement compensating controls and obtain risk acceptance from the Information Security Manager and risk owner.

Sheet Audit and Review
A1: Audit and Review — Compliance Checklist
A2: ISO/IEC 27001:2022 — Controls A.5.19-23: Cloud Services and Supplier Security
A3: Req # | B3: Section | C3: Requirement | D3: Status | E3: Evidence | F3: Owner | G3: Due Date | H3: Notes
A4: A.5.19-23-07 | B4: Obtain And Review The Most Current | C4: The organisation shall obtain and review the most current independent audit reports (within 12 months) for each Critical cloud service annually.
A5: A.5.19-23-08 | B5: The Service | C5: Where a cloud provider does not provide independent third-party reports, the service shall not be used for Confidential or Restricted data without CISO approval and documented residual risk acceptance.

Sheet Risk Management
A1: Risk Management — Compliance Checklist
A2: ISO/IEC 27001:2022 — Controls A.5.19-23: Cloud Services and Supplier Security
A3: Req # | B3: Section | C3: Requirement | D3: Status | E3: Evidence | F3: Owner | G3: Due Date | H3: Notes
A4: A.5.19-23-09 | B4: Every Supplier Handling Confidential Or | C4: Every supplier handling confidential or personal data shall be entered onto the Risk Register and managed via the organisation's risk management process.
A5: A.5.19-23-10 | B5: Cloud Service Risks | C5: Cloud service risks shall include assessment of:.
A6: A.5.19-23-11 | B6: Concentration Risk (Dependency On A | C6: Concentration risk (dependency on a single provider for critical services) — where a single provider hosts more than 50% of critical services or more than 75% of Confidential data, this shall be flagged in the risk register with a mitigation plan or accepted residual risk. Mitigation options include multi-provider diversification, multi-region deployment within the same provider, and validated exit strategy.

Sheet Supplier & Cloud Service Select
A1: Supplier & Cloud Service Select — Compliance Checklist
A2: ISO/IEC 27001:2022 — Controls A.5.19-23: Cloud Services and Supplier Security
A3: Req # | B3: Section | C3: Requirement | D3: Status | E3: Evidence | F3: Owner | G3: Due Date | H3: Notes
A4: A.5.19-23-12 | B4: Suppliers And Cloud Services | C4: Suppliers and cloud services shall be selected based on their ability to meet the needs of the business.
A5: A.5.19-23-13 | B5: Before Engaging A Supplier Or Cloud | C5: Before engaging a supplier or cloud service provider, data security due diligence shall be carried out that includes:.

Sheet Contracts, Agreements & Data
A1: Contracts, Agreements & Data — Compliance Checklist
A2: ISO/IEC 27001:2022 — Controls A.5.19-23: Cloud Services and Supplier Security
A3: Req # | B3: Section | C3: Requirement | D3: Status | E3: Evidence | F3: Owner | G3: Due Date | H3: Notes
A4: A.5.19-23-14 | B4: An Appropriate Contract, Agreement, | C4: An appropriate contract, agreement, and/or Data Processing Agreement shall be in place and enforceable before engaging any supplier or cloud service provider to process, store, or transmit confidential or personal information.
A5: A.5.19-23-15 | B5: Contracts And Agreements | C5: Contracts and agreements shall address, at a minimum:.
A6: A.5.19-23-16 | B6: The Use By Suppliers Of Sub-Contractors | C6: The use by suppliers of sub-contractors or sub-processors shall be approved by the Information Security Manager. Sub-contractors and sub-processors are subject to the same terms and security requirements as the supplier.
A7: A.5.19-23-17 | B7: Cloud Service Providers | C7: Cloud service providers shall disclose their sub-processor list. The organisation shall be notified of changes to sub-processors at least 30 days in advance and shall retain the right to object where contractually achievable. Where objection rights cannot be obtained (as is common with major cloud providers), this limitation shall be documented in the risk register as residual risk with compensating controls (encryption, access monitoring).
A8: A.5.19-23-18 | B8: Suppliers Processing Personal Data On | C8: All suppliers processing personal data on behalf of the organisation shall have a Data Processing Agreement in place that meets the requirements of Swiss nFADP (revDSG) Art. 9 and, where applicable, GDPR Art. 28.
A9: A.5.19-23-19 | B9: The Data Processing Agreement | C9: The Data Processing Agreement shall address:.
A10: A.5.19-23-20 | B10: The Organisation | C10: Where suppliers or cloud service providers process or store personal data outside Switzerland, the organisation shall verify that adequate data protection exists in the destination country per the Swiss Federal Council's adequacy list (Annex 1 to the Data Protection Ordinance).
A11: A.5.19-23-21 | B11: For Transfers To Countries Not On | C11: For transfers to countries not on the adequacy list, appropriate safeguards shall be in place:.
A12: A.5.19-23-22 | B12: For Transfers To The United States | C12: For transfers to the United States, the organisation shall verify that the receiving organisation is certified under the Swiss-U.S. Data Privacy Framework. Where the provider is US-headquartered and subject to the US CLOUD Act, a jurisdictional risk assessment shall be documented, including encryption and key management arrangements and the provider's legal challenge commitments.

Sheet Security Incident Management
A1: Security Incident Management — Compliance Checklist
A2: ISO/IEC 27001:2022 — Controls A.5.19-23: Cloud Services and Supplier Security
A3: Req # | B3: Section | C3: Requirement | D3: Status | E3: Evidence | F3: Owner | G3: Due Date | H3: Notes
A4: A.5.19-23-23 | B4: Suppliers And Cloud Service Providers | C4: Suppliers and cloud service providers shall have a security incident management process in place.
A5: A.5.19-23-24 | B5: Supplier And Cloud Service Security | C5: Supplier and cloud service security incidents that impact confidential or personal information shall be reported to the organisation within the following timelines:.
A6: A.5.19-23-25 | B6: Be Documented As A Residual Risk | C6: Where a supplier cannot commit to the 12-hour timeline, this shall be documented as a residual risk with compensating controls (more frequent supplier reviews, enhanced monitoring, backup provider).
A7: A.5.19-23-26 | B7: The Notification | C7: The notification shall include, at a minimum:.
A8: A.5.19-23-27 | B8: Supplier And Cloud Service Security | C8: Supplier and cloud service security incidents shall be managed as part of the organisation's incident management process, in accordance with the Incident Management Policy.
A9: A.5.19-23-28 | B9: The Organisation | C9: Where a supplier incident involves a personal data breach, the organisation shall assess notification obligations under nFADP (notification to the FDPIC as soon as possible) and, where applicable, GDPR Art. 33 (notification to the supervisory authority within 72 hours).
A10: A.5.19-23-29 | B10: The Supplier'S Incident Management | C10: Where appropriate, the supplier's incident management process shall be followed in coordination with the organisation's own procedures.

Sheet End of Contract
A1: End of Contract — Compliance Checklist
A2: ISO/IEC 27001:2022 — Controls A.5.19-23: Cloud Services and Supplier Security
A3: Req # | B3: Section | C3: Requirement | D3: Status | E3: Evidence | F3: Owner | G3: Due Date | H3: Notes
A4: A.5.19-23-30 | B4: At The End Of The Contract | C4: At the end of the contract, the supplier or cloud service provider shall confirm in writing that it has met its contractual and legal obligations for the destruction of organisation confidential and personal information.
A5: A.5.19-23-31 | B5: Practicable, And Relevant (Acknowledging | C5: Where appropriate, practicable, and relevant (acknowledging limitations with cloud services), the following shall be completed:.

Sheet Changes Cloud Service Supplier
A1: Changes Cloud Service Supplier — Compliance Checklist
A2: ISO/IEC 27001:2022 — Controls A.5.19-23: Cloud Services and Supplier Security
A3: Req # | B3: Section | C3: Requirement | D3: Status | E3: Evidence | F3: Owner | G3: Due Date | H3: Notes
A4: A.5.19-23-32 | B4: Follow The Change Management Policy And | C4: Changes shall follow the Change Management Policy and change management process.
A5: A.5.19-23-33 | B5: Changes To Cloud Suppliers Are | C5: Changes to cloud suppliers are significant changes and shall not be taken lightly. Such changes shall be treated as a project with appropriate resources, risk management, project management, and stakeholder communication.
A6: A.5.19-23-34 | B6: Maintain An Exit Strategy For Each | C6: The organisation shall maintain an exit strategy for each Critical cloud service to ensure that a transition or exit can be executed in a controlled manner if required.
A7: A.5.19-23-35 | B7: Exit Strategies | C7: Exit strategies shall be reviewed annually or upon contract renewal.
