Workbook

Sheet Instructions_Legend
A1: ISMS-IMP-A.5.1-2-6.1-2.S5 - Governance Compliance Dashboard
A2: Instructions, Navigation Guide, and Legend
A4: PURPOSE
A5: This workbook provides an integrated governance compliance dashboard for the Secure Employment and Roles framework (A.5.1, A.5.2, A.6.1, A.6.2). It aggregates findings from S1-S4 assessment workbooks into a board-facing executive summary with weighted compliance scoring and cross-domain gap identification.
A9: WORKBOOK STRUCTURE
A11: # | B11: Sheet Name | C11: Description
A12: 1 | B12: Instructions_Legend | C12: Navigation guide and legend (this sheet)
A13: 2 | B13: Executive_Summary | C13: Board-facing summary with weighted compliance score
A14: 3 | B14: Maturity_Assessment | C14: 5-level maturity model with trend analysis
A15: 4 | B15: Policy_Summary | C15: S1 (A.5.1) Policy Framework domain metrics
A16: 5 | B16: Roles_Summary | C16: S2 (A.5.2) Roles & Responsibilities domain metrics
A17: 6 | B17: Screening_Summary | C17: S3 (A.6.1) Screening domain metrics + FADP indicator
A18: 7 | B18: Contract_Summary | C18: S4 (A.6.2/A.6.5) Employment terms + NDA focal point
A19: 8 | B19: Gap_Analysis | C19: Consolidated gaps with cross-domain flags
A20: 9 | B20: Evidence_Register | C20: Consolidated evidence index
A21: 10 | B21: Action_Items | C21: Remediation tracker
A22: 11 | B22: Approval_Sign_Off | C22: Three-level governance certification with FADP
A25: COLOR LEGEND
A27: Color | B27: Sample | C27: Meaning
A28: Yellow | C28: User Input - Cells requiring manual entry
A29: Light Blue | C29: Calculated - Auto-populated/formula cells
A30: Gray | C30: Labels - Row/column headers
A31: Green | C31: Compliant - Meets requirements
A32: Amber/Yellow | C32: Partial - Partially meets requirements
A33: Red | C33: Non-Compliant - Does not meet requirements
A34: Purple | C34: FADP Relevant - Swiss data protection applicable
A37: COMPLIANCE WEIGHTING
A39: Domain | B39: Weight | C39: Source
A40: Policy Framework (A.5.1) | B40: 35% | C40: S1 Workbook
A41: Roles & Responsibilities (A.5.2) | B41: 25% | C41: S2 Workbook
A42: Screening & Vetting (A.6.1) | B42: 20% | C42: S3 Workbook
A43: Employment Terms (A.6.2) | B43: 20% | C43: S4 Workbook
A44: TOTAL | B44: 100% | C44: -
A47: KEY INDICATORS
A49: Indicator | B49: Description
A50: FADP Indicator | B50: Swiss Federal Act on Data Protection compliance flag
A51: NDA Rate | B51: Percentage of employees with signed NDAs
A52: Cross-Domain Gap | B52: Gap affecting multiple control domains
A53: Maturity Level | B53: CMM-style 1-5 maturity assessment

Sheet Executive_Summary
A1: ISMS-IMP-A.5.1-2-6.1-2.S5 - Executive Summary
A2: Governance Compliance Dashboard - Board-Level View
A4: Document ID: | B4: ISMS-IMP-A.5.1-2-6.1-2.S5 | E4: OVERALL COMPLIANCE | I4: FADP STATUS
A5: Control Reference: | B5: ISO/IEC 27001:2022 - Control A.5.1-2-6.1-2: Information Security Policies and Organization
A6: Assessment Period: | E6: =ROUND((Policy_Summary!B20*0.35)+(Roles_Summary!B20*0.25)+(Screening_Summary!B20*0.20)+(Contract_Summary!B20*0.20),1) | I6: =IF(Screening_Summary!B22="Yes","COMPLIANT",IF(Screening_Summary!B22="Partial","PARTIAL","REVIEW REQUIRED"))
A7: Assessment Date: | B7: =TODAY()
A8: Prepared By:
A9: Framework Version: | B9: 1.0
A11: DOMAIN COMPLIANCE BREAKDOWN
A13: Domain | B13: Weight | C13: Raw Score | D13: Weighted Score | E13: Status | F13: Source Workbook
A14: Policy Framework (A.5.1) | B14: 35% | C14: =Policy_Summary!B20 | D14: =C14*0.35 | E14: =IF(C14>=0.9,"Compliant",IF(C14>=0.7,"Partial","Non-Compliant")) | F14: S1
A15: Roles & Responsibilities (A.5.2) | B15: 25% | C15: =Roles_Summary!B20 | D15: =C15*0.25 | E15: =IF(C15>=0.9,"Compliant",IF(C15>=0.7,"Partial","Non-Compliant")) | F15: S2
A16: Screening & Vetting (A.6.1) | B16: 20% | C16: =Screening_Summary!B20 | D16: =C16*0.20 | E16: =IF(C16>=0.9,"Compliant",IF(C16>=0.7,"Partial","Non-Compliant")) | F16: S3
A17: Employment Terms (A.6.2) | B17: 20% | C17: =Contract_Summary!B20 | D17: =C17*0.20 | E17: =IF(C17>=0.9,"Compliant",IF(C17>=0.7,"Partial","Non-Compliant")) | F17: S4
A18: WEIGHTED TOTAL | B18: 100% | D18: =SUM(D14:D17)
A20: KEY PERFORMANCE INDICATORS
A22: KPI | B22: Current Value | C22: Target | D22: Status | E22: Owner
A23: NDA Compliance Rate | B23: =Contract_Summary!B24 | C23: >=95% | D23: =IF(B23>=VALUE(SUBSTITUTE(C23,"%","")/100),"On Target","Below Target") | E23: Employment
A24: Policy Acknowledgment Rate | B24: =Policy_Summary!B24 | C24: >=90% | D24: =IF(B24>=VALUE(SUBSTITUTE(C24,"%","")/100),"On Target","Below Target") | E24: Policy
A25: Screening Completion Rate | B25: =Screening_Summary!B24 | C25: 100% | D25: =IF(B25>=VALUE(SUBSTITUTE(C25,"%","")/100),"On Target","Below Target") | E25: HR
A26: FADP Training Completion | B26: =Screening_Summary!B26 | C26: >=95% | D26: =IF(B26>=VALUE(SUBSTITUTE(C26,"%","")/100),"On Target","Below Target") | E26: Training
A27: Critical Gaps Open | B27: =Gap_Analysis!B50 | C27: 0 | D27: =IF(B27>=VALUE(SUBSTITUTE(C27,"%","")/100),"On Target","Below Target") | E27: Risk
A28: Cross-Domain Gaps | B28: =Gap_Analysis!B51 | C28: 0 | D28: =IF(B28>=VALUE(SUBSTITUTE(C28,"%","")/100),"On Target","Below Target") | E28: Risk
A31: ASSESSMENT STATUS
A33: Overall Assessment Status:
A34: Next Board Review:
A35: CISO Recommendation:

Sheet Maturity_Assessment
A1: MATURITY ASSESSMENT
A2: 5-Level Capability Maturity Model for Secure Employment Framework
A4: MATURITY LEVEL DEFINITIONS
A6: Level | B6: Description
A7: Level 1 - Initial | B7: Ad-hoc processes, inconsistent execution, reactive approach
A8: Level 2 - Repeatable | B8: Basic processes documented, some consistency
A9: Level 3 - Defined | B9: Standardized processes, proactive management
A10: Level 4 - Managed | B10: Measured processes, quantitative goals
A11: Level 5 - Optimized | B11: Continuous improvement, best practice leadership
A14: DOMAIN MATURITY ASSESSMENT
A16: Domain | B16: Control | C16: Current Level | D16: Target Level | E16: Gap | F16: Trend | G16: Priority | H16: Notes
A17: Policy Framework | B17: A.5.1 | E17: =IF(AND(C17<>"",D17<>""),D17-C17,"") | G17: =IF(E17="","",IF(E17>=2,"High",IF(E17>=1,"Medium","Low")))
A18: Roles & Responsibilities | B18: A.5.2 | E18: =IF(AND(C18<>"",D18<>""),D18-C18,"") | G18: =IF(E18="","",IF(E18>=2,"High",IF(E18>=1,"Medium","Low")))
A19: Screening & Vetting | B19: A.6.1 | E19: =IF(AND(C19<>"",D19<>""),D19-C19,"") | G19: =IF(E19="","",IF(E19>=2,"High",IF(E19>=1,"Medium","Low")))
A20: Employment Terms | B20: A.6.2 | E20: =IF(AND(C20<>"",D20<>""),D20-C20,"") | G20: =IF(E20="","",IF(E20>=2,"High",IF(E20>=1,"Medium","Low")))
A23: OVERALL MATURITY SUMMARY
A25: Average Current Maturity: | B25: =AVERAGE(C17:C20)
A26: Average Target Maturity: | B26: =AVERAGE(D17:D20)
A27: Overall Gap: | B27: =B26-B25
A30: TREND HISTORY
A32: Assessment Date | B32: Policy (A.5.1) | C32: Roles (A.5.2) | D32: Screening (A.6.1) | E32: Terms (A.6.2) | F32: Average | G32: Notes
F33: =IF(B33<>"",AVERAGE(B33:E33),"")
F34: =IF(B34<>"",AVERAGE(B34:E34),"")
F35: =IF(B35<>"",AVERAGE(B35:E35),"")
F36: =IF(B36<>"",AVERAGE(B36:E36),"")
F37: =IF(B37<>"",AVERAGE(B37:E37),"")

Sheet Policy_Summary
A1: POLICY FRAMEWORK SUMMARY (A.5.1)
A2: S1 Workbook Metrics - Policies for Information Security
A4: Source Workbook: | B4: ISMS-IMP-A.5.1-2-6.1-2.S1_Policy_Framework
A5: Weight in Dashboard: | B5: 35%
A7: KEY METRICS
A9: Total Policies Assessed:
A10: Policies Compliant:
A11: Policies Partial:
A12: Policies Non-Compliant:
A13: Tier-1 Policies:
A14: Tier-2 Policies:
A15: Tier-3 Policies:
A16: Average Policy Age (months):
A17: Overdue Reviews:
A18: Policies with Gaps:
A20: OVERALL COMPLIANCE SCORE
A22: COMPLIANCE BY DOMAIN
A24: Domain | B24: =B20 | C24: Score | D24: Status
A25: Policy Inventory Completeness | B25: 25% | D25: =IF(C25="","",IF(C25>=0.9,"Compliant",IF(C25>=0.7,"Partial","Non-Compliant")))
A26: Policy Lifecycle Compliance | B26: 25% | D26: =IF(C26="","",IF(C26>=0.9,"Compliant",IF(C26>=0.7,"Partial","Non-Compliant")))
A27: Policy Governance | B27: 20% | D27: =IF(C27="","",IF(C27>=0.9,"Compliant",IF(C27>=0.7,"Partial","Non-Compliant")))
A28: Policy Classification | B28: 10% | D28: =IF(C28="","",IF(C28>=0.9,"Compliant",IF(C28>=0.7,"Partial","Non-Compliant")))
A29: Policy Communication | B29: 15% | D29: =IF(C29="","",IF(C29>=0.9,"Compliant",IF(C29>=0.7,"Partial","Non-Compliant")))
A30: Policy Repository | B30: 5% | D30: =IF(C30="","",IF(C30>=0.9,"Compliant",IF(C30>=0.7,"Partial","Non-Compliant")))
A33: Policy Acknowledgment Rate:

Sheet Roles_Summary
A1: ROLES & RESPONSIBILITIES SUMMARY (A.5.2)
A2: S2 Workbook Metrics - Information Security Roles and Responsibilities
A4: Source Workbook: | B4: ISMS-IMP-A.5.1-2-6.1-2.S2_Roles_Responsibilities
A5: Weight in Dashboard: | B5: 25%
A7: KEY METRICS
A9: Total Roles Defined:
A10: Roles with Clear Ownership:
A11: Roles with RACI Matrix:
A12: Roles with Documented Responsibilities:
A13: Key Security Roles Filled:
A14: Roles with Succession Planning:
A15: Segregation of Duties Verified:
A16: Role-Based Access Aligned:
A17: Roles Requiring Update:
A18: Vacant Critical Roles:
A20: OVERALL COMPLIANCE SCORE
A22: COMPLIANCE BY DOMAIN
A24: Domain | B24: Weight | C24: Score | D24: Status
A25: Role Definition Completeness | B25: 30% | D25: =IF(C25="","",IF(C25>=0.9,"Compliant",IF(C25>=0.7,"Partial","Non-Compliant")))
A26: RACI Matrix Coverage | B26: 25% | D26: =IF(C26="","",IF(C26>=0.9,"Compliant",IF(C26>=0.7,"Partial","Non-Compliant")))
A27: Segregation of Duties | B27: 20% | D27: =IF(C27="","",IF(C27>=0.9,"Compliant",IF(C27>=0.7,"Partial","Non-Compliant")))
A28: Succession Planning | B28: 15% | D28: =IF(C28="","",IF(C28>=0.9,"Compliant",IF(C28>=0.7,"Partial","Non-Compliant")))
A29: Role Documentation | B29: 10% | D29: =IF(C29="","",IF(C29>=0.9,"Compliant",IF(C29>=0.7,"Partial","Non-Compliant")))

Sheet Screening_Summary
A1: SCREENING & VETTING SUMMARY (A.6.1)
A2: S3 Workbook Metrics - Personnel Screening and Background Verification
A4: Source Workbook: | B4: ISMS-IMP-A.5.1-2-6.1-2.S3_Screening_Vetting
A5: Weight in Dashboard: | B5: 20%
A7: KEY METRICS
A9: Total Personnel in Scope:
A10: Screening Completed:
A11: Screening Pending:
A12: Screening Overdue:
A13: Reference Checks Completed:
A14: Criminal Record Checks:
A15: Credential Verifications:
A16: Re-Screening Due:
A17: Exceptions Documented:
A18: Risk-Based Screening Applied:
A20: OVERALL COMPLIANCE SCORE
A22: SWISS FADP COMPLIANCE
A24: FADP Compliant Screening Process: | B24: =B10/(B9)*100
A25: Data Minimization Applied:
A26: FADP Training Completed:
A27: Consent Documentation:
A28: Cross-Border Transfer Controls:
A29: Data Retention Compliance:

Sheet Contract_Summary
A1: EMPLOYMENT TERMS SUMMARY (A.6.2)
A2: S4 Workbook Metrics - Terms and Conditions of Employment
A4: Source Workbook: | B4: ISMS-IMP-A.5.1-2-6.1-2.S4_Employment_Terms
A5: Weight in Dashboard: | B5: 20%
A7: KEY METRICS
A9: Total Employees in Scope:
A10: Contracts with Security Terms:
A11: Contracts Reviewed (Annual):
A12: Contracts Requiring Update:
A13: Security Clauses Standard:
A14: Acceptable Use Acknowledged:
A15: Post-Employment Terms Defined:
A16: Contractor Agreements Compliant:
A17: Third-Party Terms Verified:
A18: Contract Templates Updated:
A20: OVERALL COMPLIANCE SCORE
... A33: COMPLIANCE BY DOMAIN
A35: Domain | B35: Weight | C35: Score | D35: Status
A36: Security Clause Coverage | B36: 30% | D36: =IF(C36="","",IF(C36>=0.9,"Compliant",IF(C36>=0.7,"Partial","Non-Compliant")))
A37: NDA Compliance | B37: 25% | D37: =IF(C37="","",IF(C37>=0.9,"Compliant",IF(C37>=0.7,"Partial","Non-Compliant")))
A38: Acceptable Use Acknowledgment | B38: 20% | D38: =IF(C38="","",IF(C38>=0.9,"Compliant",IF(C38>=0.7,"Partial","Non-Compliant")))
A39: Post-Employment Terms | B39: 15% | D39: =IF(C39="","",IF(C39>=0.9,"Compliant",IF(C39>=0.7,"Partial","Non-Compliant")))
A40: Contract Review Currency | B40: 10% | D40: =IF(C40="","",IF(C40>=0.9,"Compliant",IF(C40>=0.7,"Partial","Non-Compliant")))

Sheet Gap_Analysis
A1: CONSOLIDATED GAP ANALYSIS
A2: Cross-Domain Gap Identification and Remediation Tracking
A4: GAP SUMMARY
A6: Total Gaps Identified: | B6: =COUNTA(A11:A110)-1
A7: Critical Gaps: | B7: =COUNTIF(F11:F110,"Critical")
A8: High Gaps: | B8: =COUNTIF(F11:F110,"High")
A9: Medium Gaps: | B9: =COUNTIF(F11:F110,"Medium")
A10: Low Gaps: | B10: =COUNTIF(F11:F110,"Low")
A11: Gap_ID | B11: Source_Workbook | C11: Primary_Control | D11: Gap_Title | E11: Gap_Description | F11: Risk_Level | G11: Affected_Domains | H11: Cross_Domain_Flag | I11: Remediation_Action | J11: Owner | K11: Target_Date | L11: Status | M11: FADP_Relevant | N11: Notes
A12: =IF(D12<>"",TEXT(ROW()-11,"GAP-000"),"") | H12: =IF(G12="","",IF(LEN(G12)-LEN(SUBSTITUTE(G12,",",""))>=1,"Yes","No"))
A13: =IF(D13<>"",TEXT(ROW()-11,"GAP-000"),"") | H13: =IF(G13="","",IF(LEN(G13)-LEN(SUBSTITUTE(G13,",",""))>=1,"Yes","No"))
A14: =IF(D14<>"",TEXT(ROW()-11,"GAP-000"),"") | H14: =IF(G14="","",IF(LEN(G14)-LEN(SUBSTITUTE(G14,",",""))>=1,"Yes","No"))
A15: =IF(D15<>"",TEXT(ROW()-11,"GAP-000"),"") | H15: =IF(G15="","",IF(LEN(G15)-LEN(SUBSTITUTE(G15,",",""))>=1,"Yes","No"))
A16: =IF(D16<>"",TEXT(ROW()-11,"GAP-000"),"") | H16: =IF(G16="","",IF(LEN(G16)-LEN(SUBSTITUTE(G16,",",""))>=1,"Yes","No"))
A17: =IF(D17<>"",TEXT(ROW()-11,"GAP-000"),"") | H17: =IF(G17="","",IF(LEN(G17)-LEN(SUBSTITUTE(G17,",",""))>=1,"Yes","No"))
A18: =IF(D18<>"",TEXT(ROW()-11,"GAP-000"),"") | H18: =IF(G18="","",IF(LEN(G18)-LEN(SUBSTITUTE(G18,",",""))>=1,"Yes","No"))
A19: =IF(D19<>"",TEXT(ROW()-11,"GAP-000"),"") | H19: =IF(G19="","",IF(LEN(G19)-LEN(SUBSTITUTE(G19,",",""))>=1,"Yes","No"))
A20: =IF(D20<>"",TEXT(ROW()-11,"GAP-000"),"") | H20: =IF(G20="","",IF(LEN(G20)-LEN(SUBSTITUTE(G20,",",""))>=1,"Yes","No"))
A21: =IF(D21<>"",TEXT(ROW()-11,"GAP-000"),"") | H21: =IF(G21="","",IF(LEN(G21)-LEN(SUBSTITUTE(G21,",",""))>=1,"Yes","No"))
A22: =IF(D22<>"",TEXT(ROW()-11,"GAP-000"),"") | H22: =IF(G22="","",IF(LEN(G22)-LEN(SUBSTITUTE(G22,",",""))>=1,"Yes","No"))
A23: =IF(D23<>"",TEXT(ROW()-11,"GAP-000"),"") | H23: =IF(G23="","",IF(LEN(G23)-LEN(SUBSTITUTE(G23,",",""))>=1,"Yes","No"))
... A49: =IF(D49<>"",TEXT(ROW()-11,"GAP-000"),"") | H49: =IF(G49="","",IF(LEN(G49)-LEN(SUBSTITUTE(G49,",",""))>=1,"Yes","No"))
A50: =IF(D50<>"",TEXT(ROW()-11,"GAP-000"),"") | B50: =COUNTIF(H11:H110,"Yes") | H50: =IF(G50="","",IF(LEN(G50)-LEN(SUBSTITUTE(G50,",",""))>=1,"Yes","No"))
A51: =IF(D51<>"",TEXT(ROW()-11,"GAP-000"),"") | B51: =B50 | H51: =IF(G51="","",IF(LEN(G51)-LEN(SUBSTITUTE(G51,",",""))>=1,"Yes","No"))
A52: =IF(D52<>"",TEXT(ROW()-11,"GAP-000"),"") | H52: =IF(G52="","",IF(LEN(G52)-LEN(SUBSTITUTE(G52,",",""))>=1,"Yes","No"))
A53: =IF(D53<>"",TEXT(ROW()-11,"GAP-000"),"") | H53: =IF(G53="","",IF(LEN(G53)-LEN(SUBSTITUTE(G53,",",""))>=1,"Yes","No"))
A54: =IF(D54<>"",TEXT(ROW()-11,"GAP-000"),"") | H54: =IF(G54="","",IF(LEN(G54)-LEN(SUBSTITUTE(G54,",",""))>=1,"Yes","No"))
A55: =IF(D55<>"",TEXT(ROW()-11,"GAP-000"),"") | H55: =IF(G55="","",IF(LEN(G55)-LEN(SUBSTITUTE(G55,",",""))>=1,"Yes","No"))
A56: =IF(D56<>"",TEXT(ROW()-11,"GAP-000"),"") | H56: =IF(G56="","",IF(LEN(G56)-LEN(SUBSTITUTE(G56,",",""))>=1,"Yes","No"))
A57: =IF(D57<>"",TEXT(ROW()-11,"GAP-000"),"") | H57: =IF(G57="","",IF(LEN(G57)-LEN(SUBSTITUTE(G57,",",""))>=1,"Yes","No"))
A58: =IF(D58<>"",TEXT(ROW()-11,"GAP-000"),"") | H58: =IF(G58="","",IF(LEN(G58)-LEN(SUBSTITUTE(G58,",",""))>=1,"Yes","No"))
A59: =IF(D59<>"",TEXT(ROW()-11,"GAP-000"),"") | H59: =IF(G59="","",IF(LEN(G59)-LEN(SUBSTITUTE(G59,",",""))>=1,"Yes","No"))
A60: =IF(D60<>"",TEXT(ROW()-11,"GAP-000"),"") | H60: =IF(G60="","",IF(LEN(G60)-LEN(SUBSTITUTE(G60,",",""))>=1,"Yes","No"))
A61: =IF(D61<>"",TEXT(ROW()-11,"GAP-000"),"") | H61: =IF(G61="","",IF(LEN(G61)-LEN(SUBSTITUTE(G61,",",""))>=1,"Yes","No"))
A62: =IF(D62<>"",TEXT(ROW()-11,"GAP-000"),"") | H62: =IF(G62="","",IF(LEN(G62)-LEN(SUBSTITUTE(G62,",",""))>=1,"Yes","No"))
A63: =IF(D63<>"",TEXT(ROW()-11,"GAP-000"),"") | H63: =IF(G63="","",IF(LEN(G63)-LEN(SUBSTITUTE(G63,",",""))>=1,"Yes","No"))
... A110: =IF(D110<>"",TEXT(ROW()-11,"GAP-000"),"") | H110: =IF(G110="","",IF(LEN(G110)-LEN(SUBSTITUTE(G110,",",""))>=1,"Yes","No"))

Sheet Evidence_Register
A1: CONSOLIDATED EVIDENCE REGISTER
A2: Evidence Index for Governance Compliance Dashboard
A4: Evidence_ID | B4: Source_Workbook | C4: Evidence_Type | D4: Description | E4: Related_Control | F4: Related_Gap_ID | G4: File_Location | H4: Date_Collected | I4: Collected_By | J4: Verification_Status | K4: Notes
A5: =IF(D5<>"",TEXT(ROW()-4,"EVD-000"),"")
A6: =IF(D6<>"",TEXT(ROW()-4,"EVD-000"),"")
A7: =IF(D7<>"",TEXT(ROW()-4,"EVD-000"),"")
A8: =IF(D8<>"",TEXT(ROW()-4,"EVD-000"),"")
A9: =IF(D9<>"",TEXT(ROW()-4,"EVD-000"),"")
A10: =IF(D10<>"",TEXT(ROW()-4,"EVD-000"),"")
A11: =IF(D11<>"",TEXT(ROW()-4,"EVD-000"),"")
A12: =IF(D12<>"",TEXT(ROW()-4,"EVD-000"),"")
A13: =IF(D13<>"",TEXT(ROW()-4,"EVD-000"),"")
A14: =IF(D14<>"",TEXT(ROW()-4,"EVD-000"),"")
A15: =IF(D15<>"",TEXT(ROW()-4,"EVD-000"),"")
A16: =IF(D16<>"",TEXT(ROW()-4,"EVD-000"),"")
... A154: =IF(D154<>"",TEXT(ROW()-4,"EVD-000"),"")

Sheet Action_Items
A1: ACTION ITEMS TRACKER
A2: Remediation Tracking for Identified Gaps
A4: ACTION SUMMARY
A6: Total Actions: | B6: =COUNTA(A10:A109)-1
A7: Actions Open: | B7: =COUNTIF(G10:G109,"Open")+COUNTIF(G10:G109,"In-Progress")
A8: Actions Blocked: | B8: =COUNTIF(G10:G109,"Blocked")
A9: Actions Completed: | B9: =COUNTIF(G10:G109,"Completed")
A10: Action_ID | B10: Related_Gap_ID | C10: Action_Description | D10: Priority | E10: Owner | F10: Target_Date | G10: Status | H10: Progress_% | I10: Last_Update | J10: Update_Notes | K10: Blocking_Issues | L10: Escalation_Required | M10: Escalation_To
A11: =IF(B11<>"",SUBSTITUTE(B11,"GAP","ACT"),"")
A12: =IF(B12<>"",SUBSTITUTE(B12,"GAP","ACT"),"")
A13: =IF(B13<>"",SUBSTITUTE(B13,"GAP","ACT"),"")
A14: =IF(B14<>"",SUBSTITUTE(B14,"GAP","ACT"),"")
A15: =IF(B15<>"",SUBSTITUTE(B15,"GAP","ACT"),"")
A16: =IF(B16<>"",SUBSTITUTE(B16,"GAP","ACT"),"")
A17: =IF(B17<>"",SUBSTITUTE(B17,"GAP","ACT"),"")
A18: =IF(B18<>"",SUBSTITUTE(B18,"GAP","ACT"),"")
A19: =IF(B19<>"",SUBSTITUTE(B19,"GAP","ACT"),"")
A20: =IF(B20<>"",SUBSTITUTE(B20,"GAP","ACT"),"")
A21: =IF(B21<>"",SUBSTITUTE(B21,"GAP","ACT"),"")
A22: =IF(B22<>"",SUBSTITUTE(B22,"GAP","ACT"),"")
... A109: =IF(B109<>"",SUBSTITUTE(B109,"GAP","ACT"),"")

Sheet Approval_Sign_Off
A1: GOVERNANCE CERTIFICATION
A2: Three-Level Approval with FADP Acknowledgment
A4: ASSESSMENT SUMMARY
A6: Document ID: | B6: ISMS-IMP-A.5.1-2-6.1-2.S5
A7: Assessment Period: | B7: =Executive_Summary!B6
A8: Overall Compliance Score: | B8: =Executive_Summary!E6
A9: Policy Domain (A.5.1): | B9: =Policy_Summary!B20
A10: Roles Domain (A.5.2): | B10: =Roles_Summary!B20
A11: Screening Domain (A.6.1): | B11: =Screening_Summary!B20
A12: Employment Domain (A.6.2): | B12: =Contract_Summary!B20
A13: Total Gaps Identified: | B13: =Gap_Analysis!B6
A14: Critical/High Gaps: | B14: =Gap_Analysis!B7+Gap_Analysis!B8
A15: Cross-Domain Gaps: | B15: =Gap_Analysis!B51
A16: FADP Compliance Status: | B16: =Executive_Summary!I6
A18: LEVEL 1: PREPARED BY (Assessor)
A20: Name:
A21: Role:
A22: Date:
A23: Signature:
A24: Certification: | B24: I certify this assessment is complete and accurate based on S1-S4 workbook data
A27: LEVEL 2: REVIEWED BY (Security Manager)
A29: Name:
A30: Role:
A31: Date:
A32: Signature:
A34: Review Checklist:
A35: [ ] S1-S4 workbook data verified
A36: [ ] Weighted scores calculated correctly
A37: [ ] All gaps accounted for
A38: [ ] Cross-domain impacts identified
A39: [ ] NDA compliance rate verified
A40: [ ] FADP indicators reviewed
... A51: Signature:
A53: CISO Certification: | B53: I approve this Governance Compliance Dashboard as an accurate representation of the organization's compliance status for controls A.5.1, A.5.2, A.6.1, and A.6.2. I acknowledge the FADP compliance status and accept residual risk for identified gaps.
A57: FADP ACKNOWLEDGMENT
A59: FADP Compliance Verified:
A60: Data Protection Officer Consulted:
A61: FADP Risk Acceptance:
A64: ASSESSMENT STATUS
A66: Final Assessment Status:
...
