Workbook
Name Template_ID_List: Contract_Template_Assessment!$A$5:$A$54
Name Employee_ID_List: Personnel_Contract_Compliance!$A$5:$A$204

Sheet Dashboard
A1: ISMS-IMP-A.5.1-2-6.1-2.S4 - Employment Contract Assessment Dashboard
A2: ISO/IEC 27001:2022 Controls A.6.1/A.6.2 - Screening & Terms and Conditions of Employment
A4: Document ID: | B4: ISMS-IMP-A.5.1-2-6.1-2.S4
A5: Related Policy: | B5: ISMS-POL-A.5.1-2-6.1-2, Section 7
A6: ISO Controls: | B6: A.6.1 (Screening), A.6.2 (Terms & Conditions)
A7: Assessment Period:
A8: Assessment Date: | B8: =TODAY()
A9: Assessor Name:
A10: Assessor Role:
A11: Organization:
A12: Review Cycle: | B12: Annual
A13: Last Updated: | B13: =NOW()
A14: Assessment Status:
A15: Next Review Date:
A17: OVERALL EMPLOYMENT CONTRACT COMPLIANCE
A19: Overall Compliance Score | B19: =AVERAGE(C32,C33,C34,C35,C36) | C19: 90% | D19: =IF(B19>=C19,"On Target",IF(B19>=C19*0.9,"Close","Below Target"))
A20: Contract Templates Assessed | B20: =COUNTA(Contract_Template_Assessment!A:A)-4 | C20: N/A | D20: =IF(B20>=C20,"On Target",IF(B20>=C20*0.9,"Close","Below Target"))
A21: Templates Compliant | B21: =COUNTIF(Contract_Template_Assessment!M:M,"Compliant") | C21: 100% | D21: =IF(B21>=C21,"On Target",IF(B21>=C21*0.9,"Close","Below Target"))
A22: Personnel with Contracts Verified | B22: =COUNTIF(Personnel_Contract_Compliance!N:N,"Compliant") | C22: N/A | D22: =IF(B22>=C22,"On Target",IF(B22>=C22*0.9,"Close","Below Target"))
A23: NDA Coverage Rate | B23: =COUNTIF(Confidentiality_NDA_Tracking!K:K,"Active")/COUNTA(Confidentiality_NDA_Tracking!A:A)*100 | C23: 100% | D23: =IF(B23>=C23,"On Target",IF(B23>=C23*0.9,"Close","Below Target"))
A24: Critical Gaps | B24: =COUNTIF(Gap_Analysis!F:F,"Critical") | C24: 0 | D24: =IF(B24>=C24,"On Target",IF(B24>=C24*0.9,"Close","Below Target"))
A25: High Priority Gaps | B25: =COUNTIF(Gap_Analysis!F:F,"High") | C25: 0 | D25: =IF(B25>=C25,"On Target",IF(B25>=C25*0.9,"Close","Below Target"))
A26: Contractor Agreements Verified | B26: =COUNTIF(Contractor_Agreement_Assessment!L:L,"Compliant") | C26: N/A | D26: =IF(B26>=C26,"On Target",IF(B26>=C26*0.9,"Close","Below Target"))
A28: DOMAIN COMPLIANCE BREAKDOWN
A30: Domain | B30: Weight | C30: Score (%) | D30: Weighted Score | E30: Status
A32: Contract Template Completeness | B32: 20% | C32: =COUNTIF(Contract_Template_Assessment!M:M,"Compliant")/COUNTA(Contract_Template_Assessment!A:A)*100 | D32: =C32*0.20 | E32: =IF(C32>=0.9,"Pass",IF(C32>=0.7,"Partial","Fail"))
A33: Required Clause Coverage | B33: 25% | C33: =COUNTIF(Required_Clause_Registry!H:H,"Covered")/COUNTA(Required_Clause_Registry!A:A)*100 | D33: =C33*0.25 | E33: =IF(C33>=0.9,"Pass",IF(C33>=0.7,"Partial","Fail"))
A34: Personnel Contract Compliance | B34: 25% | C34: =COUNTIF(Personnel_Contract_Compliance!N:N,"Compliant")/COUNTA(Personnel_Contract_Compliance!A:A)*100 | D34: =C34*0.25 | E34: =IF(C34>=0.9,"Pass",IF(C34>=0.7,"Partial","Fail"))
A35: NDA/Confidentiality Coverage | B35: 20% | C35: =COUNTIF(Confidentiality_NDA_Tracking!K:K,"Active")/COUNTA(Confidentiality_NDA_Tracking!A:A)*100 | D35: =C35*0.20 | E35: =IF(C35>=0.9,"Pass",IF(C35>=0.7,"Partial","Fail"))
A36: Contractor Agreement Compliance | B36: 10% | C36: =COUNTIF(Contractor_Agreement_Assessment!L:L,"Compliant")/COUNTA(Contractor_Agreement_Assessment!A:A)*100 | D36: =C36*0.10 | E36: =IF(C36>=0.9,"Pass",IF(C36>=0.7,"Partial","Fail"))
A38: TOTAL WEIGHTED SCORE | B38: 100% | C38: =SUM(D32:D36)

Sheet Contract_Template_Assessment
A1: CONTRACT TEMPLATE ASSESSMENT
A2: Verification of employment contract templates for security clause completeness
A4: Template_ID | B4: Template_Name | C4: Template_Type | D4: Personnel_Category | E4: Current_Version | F4: Version_Date | G4: Last_Review_Date | H4: Next_Review_Date | I4: Security_Clauses_Count | J4: Required_Clauses_Met | K4: Legal_Review_Date | L4: Legal_Approved | M4: Compliance_Status | N4: Notes
M5: =IF(B5="","",IF(AND(J5="Yes",L5="Yes",H5>=TODAY()),"Compliant",IF(OR(J5="No",L5="No"),"Non-Compliant","Partial")))
M6: =IF(B6="","",IF(AND(J6="Yes",L6="Yes",H6>=TODAY()),"Compliant",IF(OR(J6="No",L6="No"),"Non-Compliant","Partial")))
M7: =IF(B7="","",IF(AND(J7="Yes",L7="Yes",H7>=TODAY()),"Compliant",IF(OR(J7="No",L7="No"),"Non-Compliant","Partial")))
M8: =IF(B8="","",IF(AND(J8="Yes",L8="Yes",H8>=TODAY()),"Compliant",IF(OR(J8="No",L8="No"),"Non-Compliant","Partial")))
M9: =IF(B9="","",IF(AND(J9="Yes",L9="Yes",H9>=TODAY()),"Compliant",IF(OR(J9="No",L9="No"),"Non-Compliant","Partial")))
M10: =IF(B10="","",IF(AND(J10="Yes",L10="Yes",H10>=TODAY()),"Compliant",IF(OR(J10="No",L10="No"),"Non-Compliant","Partial")))
M11: =IF(B11="","",IF(AND(J11="Yes",L11="Yes",H11>=TODAY()),"Compliant",IF(OR(J11="No",L11="No"),"Non-Compliant","Partial")))
M12: =IF(B12="","",IF(AND(J12="Yes",L12="Yes",H12>=TODAY()),"Compliant",IF(OR(J12="No",L12="No"),"Non-Compliant","Partial")))
M13: =IF(B13="","",IF(AND(J13="Yes",L13="Yes",H13>=TODAY()),"Compliant",IF(OR(J13="No",L13="No"),"Non-Compliant","Partial")))
M14: =IF(B14="","",IF(AND(J14="Yes",L14="Yes",H14>=TODAY()),"Compliant",IF(OR(J14="No",L14="No"),"Non-Compliant","Partial")))
M15: =IF(B15="","",IF(AND(J15="Yes",L15="Yes",H15>=TODAY()),"Compliant",IF(OR(J15="No",L15="No"),"Non-Compliant","Partial")))
M16: =IF(B16="","",IF(AND(J16="Yes",L16="Yes",H16>=TODAY()),"Compliant",IF(OR(J16="No",L16="No"),"Non-Compliant","Partial")))
... M54: =IF(B54="","",IF(AND(J54="Yes",L54="Yes",H54>=TODAY()),"Compliant",IF(OR(J54="No",L54="No"),"Non-Compliant","Partial")))

Sheet Required_Clause_Registry
A1: REQUIRED CLAUSE REGISTRY
A2: Master list of required security clauses with template coverage verification
A4: Clause_ID | B4: Clause_Category | C4: Clause_Title | D4: Clause_Description | E4: ISO_27001_Reference | F4: Legal_Requirement | G4: Mandatory_For | H4: Coverage_Status | I4: Templates_With_Clause | J4: Gap_If_Missing | K4: Last_Verified | L4: Notes
A5: RC-001 | B5: Confidentiality | C5: Confidentiality and Non-Disclosure | D5: Employee agrees to maintain confidentiality of all company information | E5: A.5.1, A.6.2 | F5: Employment Law
A6: RC-002 | B6: Confidentiality | C6: Non-Disclosure Agreement Reference | D6: Reference to standalone NDA or embedded NDA terms | E6: A.6.2 | F6: Employment Law
A7: RC-003 | B7: IP Rights | C7: Intellectual Property Assignment | D7: All work product IP belongs to the organization | E7: A.5.1 | F7: IP Law
A8: RC-004 | B8: IP Rights | C8: Invention Assignment | D8: Employee assigns rights to inventions created during employment | E8: A.5.1 | F8: Patent Law
A9: RC-005 | B9: Security | C9: Information Security Responsibilities | D9: Employee responsibilities for information security | E9: A.6.2 | F9: ISMS Policy
A10: RC-006 | B10: Security | C10: Acceptable Use Agreement Reference | D10: Reference to or acknowledgment of acceptable use policy | E10: A.5.10 | F10: ISMS Policy
A11: RC-007 | B11: Security | C11: Access Control Acknowledgment | D11: Agreement to comply with access control policies | E11: A.5.15 | F11: ISMS Policy
A12: RC-008 | B12: Security | C12: Password/Authentication Requirements | D12: Agreement to follow authentication policies | E12: A.5.17 | F12: ISMS Policy
A13: RC-009 | B13: Post-Employment | C13: Return of Assets | D13: Obligation to return all company assets upon termination | E13: A.6.5 | F13: Employment Law
A14: RC-010 | B14: Post-Employment | C14: Post-Employment Confidentiality | D14: Confidentiality obligations continue after termination | E14: A.6.5 | F14: Contract Law
A15: RC-011 | B15: Post-Employment | C15: Non-Compete Clause | D15: Restrictions on competing employment if applicable | E15: A.6.5 | F15: Contract Law
A16: RC-012 | B16: Post-Employment | C16: Non-Solicitation Clause | D16: Restrictions on soliciting employees/clients | E16: A.6.5 | F16: Contract Law
... A24: RC-020 | B24: Monitoring | C24: Monitoring Acknowledgment | D24: Acknowledgment of workplace/IT monitoring practices | E24: A.8.15 | F24: Employment Law

Sheet Personnel_Contract_Compliance
A1: PERSONNEL CONTRACT COMPLIANCE
A2: Individual employee contract verification and compliance tracking
A4: Employee_ID | B4: Employee_Name | C4: Department | D4: Role_Title | E4: Employment_Type | F4: Start_Date | G4: Contract_Template_Used | H4: Contract_Signed | I4: Contract_Date | J4: Contract_On_File | K4: All_Clauses_Present | L4: Screening_Complete | M4: Background_Check_Date | N4: Compliance_Status | O4: Notes
N5: =IF(B5="","",IF(AND(H5="Yes",J5="Yes",K5="Yes",L5="Yes"),"Compliant",IF(OR(H5="No",J5="No",L5="No"),"Non-Compliant","Partial")))
N6: =IF(B6="","",IF(AND(H6="Yes",J6="Yes",K6="Yes",L6="Yes"),"Compliant",IF(OR(H6="No",J6="No",L6="No"),"Non-Compliant","Partial")))
N7: =IF(B7="","",IF(AND(H7="Yes",J7="Yes",K7="Yes",L7="Yes"),"Compliant",IF(OR(H7="No",J7="No",L7="No"),"Non-Compliant","Partial")))
N8: =IF(B8="","",IF(AND(H8="Yes",J8="Yes",K8="Yes",L8="Yes"),"Compliant",IF(OR(H8="No",J8="No",L8="No"),"Non-Compliant","Partial")))
N9: =IF(B9="","",IF(AND(H9="Yes",J9="Yes",K9="Yes",L9="Yes"),"Compliant",IF(OR(H9="No",J9="No",L9="No"),"Non-Compliant","Partial")))
N10: =IF(B10="","",IF(AND(H10="Yes",J10="Yes",K10="Yes",L10="Yes"),"Compliant",IF(OR(H10="No",J10="No",L10="No"),"Non-Compliant","Partial")))
N11: =IF(B11="","",IF(AND(H11="Yes",J11="Yes",K11="Yes",L11="Yes"),"Compliant",IF(OR(H11="No",J11="No",L11="No"),"Non-Compliant","Partial")))
N12: =IF(B12="","",IF(AND(H12="Yes",J12="Yes",K12="Yes",L12="Yes"),"Compliant",IF(OR(H12="No",J12="No",L12="No"),"Non-Compliant","Partial")))
N13: =IF(B13="","",IF(AND(H13="Yes",J13="Yes",K13="Yes",L13="Yes"),"Compliant",IF(OR(H13="No",J13="No",L13="No"),"Non-Compliant","Partial")))
N14: =IF(B14="","",IF(AND(H14="Yes",J14="Yes",K14="Yes",L14="Yes"),"Compliant",IF(OR(H14="No",J14="No",L14="No"),"Non-Compliant","Partial")))
N15: =IF(B15="","",IF(AND(H15="Yes",J15="Yes",K15="Yes",L15="Yes"),"Compliant",IF(OR(H15="No",J15="No",L15="No"),"Non-Compliant","Partial")))
N16: =IF(B16="","",IF(AND(H16="Yes",J16="Yes",K16="Yes",L16="Yes"),"Compliant",IF(OR(H16="No",J16="No",L16="No"),"Non-Compliant","Partial")))
... N204: =IF(B204="","",IF(AND(H204="Yes",J204="Yes",K204="Yes",L204="Yes"),"Compliant",IF(OR(H204="No",J204="No",L204="No"),"Non-Compliant","Partial")))

Sheet Confidentiality_NDA_Tracking
A1: CONFIDENTIALITY & NDA TRACKING
A2: AUDIT FOCAL POINT: NDA and confidentiality agreement status per individual
A4: Employee_ID | B4: Employee_Name | C4: Department | D4: NDA_Type | E4: NDA_Version | F4: Date_Signed | G4: Expiration_Date | H4: Covers_IP | I4: Covers_Trade_Secrets | J4: Covers_Post_Employment | K4: NDA_Status | L4: Renewal_Required | M4: Document_Location | N4: Notes
A5: =IF(ROW()-4<=COUNTA(Personnel_Contract_Compliance!$A:$A)-4,INDEX(Personnel_Contract_Compliance!$A:$A,ROW()-3),"") | B5: =IF(A5<>"",VLOOKUP(A5,Personnel_Contract_Compliance!$A:$B,2,FALSE),"") | C5: =IF(A5<>"",VLOOKUP(A5,Personnel_Contract_Compliance!$A:$C,3,FALSE),"") | K5: =IF(B5="","",IF(AND(F5<>"",OR(G5="",G5>=TODAY())),"Active",IF(AND(F5<>"",G5<TODAY()),"Expired",IF(F5="","Missing","Unknown"))))
A6: =IF(ROW()-4<=COUNTA(Personnel_Contract_Compliance!$A:$A)-4,INDEX(Personnel_Contract_Compliance!$A:$A,ROW()-3),"") | B6: =IF(A6<>"",VLOOKUP(A6,Personnel_Contract_Compliance!$A:$B,2,FALSE),"") | C6: =IF(A6<>"",VLOOKUP(A6,Personnel_Contract_Compliance!$A:$C,3,FALSE),"") | K6: =IF(B6="","",IF(AND(F6<>"",OR(G6="",G6>=TODAY())),"Active",IF(AND(F6<>"",G6<TODAY()),"Expired",IF(F6="","Missing","Unknown"))))
A7: =IF(ROW()-4<=COUNTA(Personnel_Contract_Compliance!$A:$A)-4,INDEX(Personnel_Contract_Compliance!$A:$A,ROW()-3),"") | B7: =IF(A7<>"",VLOOKUP(A7,Personnel_Contract_Compliance!$A:$B,2,FALSE),"") | C7: =IF(A7<>"",VLOOKUP(A7,Personnel_Contract_Compliance!$A:$C,3,FALSE),"") | K7: =IF(B7="","",IF(AND(F7<>"",OR(G7="",G7>=TODAY())),"Active",IF(AND(F7<>"",G7<TODAY()),"Expired",IF(F7="","Missing","Unknown"))))
A8: =IF(ROW()-4<=COUNTA(Personnel_Contract_Compliance!$A:$A)-4,INDEX(Personnel_Contract_Compliance!$A:$A,ROW()-3),"") | B8: =IF(A8<>"",VLOOKUP(A8,Personnel_Contract_Compliance!$A:$B,2,FALSE),"") | C8: =IF(A8<>"",VLOOKUP(A8,Personnel_Contract_Compliance!$A:$C,3,FALSE),"") | K8: =IF(B8="","",IF(AND(F8<>"",OR(G8="",G8>=TODAY())),"Active",IF(AND(F8<>"",G8<TODAY()),"Expired",IF(F8="","Missing","Unknown"))))
A9: =IF(ROW()-4<=COUNTA(Personnel_Contract_Compliance!$A:$A)-4,INDEX(Personnel_Contract_Compliance!$A:$A,ROW()-3),"") | B9: =IF(A9<>"",VLOOKUP(A9,Personnel_Contract_Compliance!$A:$B,2,FALSE),"") | C9: =IF(A9<>"",VLOOKUP(A9,Personnel_Contract_Compliance!$A:$C,3,FALSE),"") | K9: =IF(B9="","",IF(AND(F9<>"",OR(G9="",G9>=TODAY())),"Active",IF(AND(F9<>"",G9<TODAY()),"Expired",IF(F9="","Missing","Unknown"))))
A10: =IF(ROW()-4<=COUNTA(Personnel_Contract_Compliance!$A:$A)-4,INDEX(Personnel_Contract_Compliance!$A:$A,ROW()-3),"") | B10: =IF(A10<>"",VLOOKUP(A10,Personnel_Contract_Compliance!$A:$B,2,FALSE),"") | C10: =IF(A10<>"",VLOOKUP(A10,Personnel_Contract_Compliance!$A:$C,3,FALSE),"") | K10: =IF(B10="","",IF(AND(F10<>"",OR(G10="",G10>=TODAY())),"Active",IF(AND(F10<>"",G10<TODAY()),"Expired",IF(F10="","Missing","Unknown"))))
A11: =IF(ROW()-4<=COUNTA(Personnel_Contract_Compliance!$A:$A)-4,INDEX(Personnel_Contract_Compliance!$A:$A,ROW()-3),"") | B11: =IF(A11<>"",VLOOKUP(A11,Personnel_Contract_Compliance!$A:$B,2,FALSE),"") | C11: =IF(A11<>"",VLOOKUP(A11,Personnel_Contract_Compliance!$A:$C,3,FALSE),"") | K11: =IF(B11="","",IF(AND(F11<>"",OR(G11="",G11>=TODAY())),"Active",IF(AND(F11<>"",G11<TODAY()),"Expired",IF(F11="","Missing","Unknown"))))
A12: =IF(ROW()-4<=COUNTA(Personnel_Contract_Compliance!$A:$A)-4,INDEX(Personnel_Contract_Compliance!$A:$A,ROW()-3),"") | B12: =IF(A12<>"",VLOOKUP(A12,Personnel_Contract_Compliance!$A:$B,2,FALSE),"") | C12: =IF(A12<>"",VLOOKUP(A12,Personnel_Contract_Compliance!$A:$C,3,FALSE),"") | K12: =IF(B12="","",IF(AND(F12<>"",OR(G12="",G12>=TODAY())),"Active",IF(AND(F12<>"",G12<TODAY()),"Expired",IF(F12="","Missing","Unknown"))))
A13: =IF(ROW()-4<=COUNTA(Personnel_Contract_Compliance!$A:$A)-4,INDEX(Personnel_Contract_Compliance!$A:$A,ROW()-3),"") | B13: =IF(A13<>"",VLOOKUP(A13,Personnel_Contract_Compliance!$A:$B,2,FALSE),"") | C13: =IF(A13<>"",VLOOKUP(A13,Personnel_Contract_Compliance!$A:$C,3,FALSE),"") | K13: =IF(B13="","",IF(AND(F13<>"",OR(G13="",G13>=TODAY())),"Active",IF(AND(F13<>"",G13<TODAY()),"Expired",IF(F13="","Missing","Unknown"))))
A14: =IF(ROW()-4<=COUNTA(Personnel_Contract_Compliance!$A:$A)-4,INDEX(Personnel_Contract_Compliance!$A:$A,ROW()-3),"") | B14: =IF(A14<>"",VLOOKUP(A14,Personnel_Contract_Compliance!$A:$B,2,FALSE),"") | C14: =IF(A14<>"",VLOOKUP(A14,Personnel_Contract_Compliance!$A:$C,3,FALSE),"") | K14: =IF(B14="","",IF(AND(F14<>"",OR(G14="",G14>=TODAY())),"Active",IF(AND(F14<>"",G14<TODAY()),"Expired",IF(F14="","Missing","Unknown"))))
A15: =IF(ROW()-4<=COUNTA(Personnel_Contract_Compliance!$A:$A)-4,INDEX(Personnel_Contract_Compliance!$A:$A,ROW()-3),"") | B15: =IF(A15<>"",VLOOKUP(A15,Personnel_Contract_Compliance!$A:$B,2,FALSE),"") | C15: =IF(A15<>"",VLOOKUP(A15,Personnel_Contract_Compliance!$A:$C,3,FALSE),"") | K15: =IF(B15="","",IF(AND(F15<>"",OR(G15="",G15>=TODAY())),"Active",IF(AND(F15<>"",G15<TODAY()),"Expired",IF(F15="","Missing","Unknown"))))
A16: =IF(ROW()-4<=COUNTA(Personnel_Contract_Compliance!$A:$A)-4,INDEX(Personnel_Contract_Compliance!$A:$A,ROW()-3),"") | B16: =IF(A16<>"",VLOOKUP(A16,Personnel_Contract_Compliance!$A:$B,2,FALSE),"") | C16: =IF(A16<>"",VLOOKUP(A16,Personnel_Contract_Compliance!$A:$C,3,FALSE),"") | K16: =IF(B16="","",IF(AND(F16<>"",OR(G16="",G16>=TODAY())),"Active",IF(AND(F16<>"",G16<TODAY()),"Expired",IF(F16="","Missing","Unknown"))))
... A204: =IF(ROW()-4<=COUNTA(Personnel_Contract_Compliance!$A:$A)-4,INDEX(Personnel_Contract_Compliance!$A:$A,ROW()-3),"") | B204: =IF(A204<>"",VLOOKUP(A204,Personnel_Contract_Compliance!$A:$B,2,FALSE),"") | C204: =IF(A204<>"",VLOOKUP(A204,Personnel_Contract_Compliance!$A:$C,3,FALSE),"") | K204: =IF(B204="","",IF(AND(F204<>"",OR(G204="",G204>=TODAY())),"Active",IF(AND(F204<>"",G204<TODAY()),"Expired",IF(F204="","Missing","Unknown"))))

Sheet Post_Employment_Obligations
A1: POST-EMPLOYMENT OBLIGATIONS TRACKING
A2: Tracking individuals with ongoing confidentiality and non-compete obligations
A4: Former_Employee_ID | B4: Former_Employee_Name | C4: Former_Department | D4: Former_Role | E4: Termination_Date | F4: Termination_Type | G4: Confidentiality_End_Date | H4: Non_Compete_End_Date | I4: Non_Solicit_End_Date | J4: IP_Assignment_Perpetual | K4: Assets_Returned | L4: Exit_Interview_Complete | M4: Obligation_Status | N4: Monitoring_Required | O4: Notes
M5: =IF(B5="","",IF(AND(K5="Yes",L5="Yes",OR(G5="Perpetual",G5>=TODAY())),"Active-Compliant",IF(OR(K5="No",L5="No"),"Non-Compliant",IF(AND(G5<TODAY(),H5<TODAY(),I5<TODAY()),"Expired","Active-Review"))))
M6: =IF(B6="","",IF(AND(K6="Yes",L6="Yes",OR(G6="Perpetual",G6>=TODAY())),"Active-Compliant",IF(OR(K6="No",L6="No"),"Non-Compliant",IF(AND(G6<TODAY(),H6<TODAY(),I6<TODAY()),"Expired","Active-Review"))))
M7: =IF(B7="","",IF(AND(K7="Yes",L7="Yes",OR(G7="Perpetual",G7>=TODAY())),"Active-Compliant",IF(OR(K7="No",L7="No"),"Non-Compliant",IF(AND(G7<TODAY(),H7<TODAY(),I7<TODAY()),"Expired","Active-Review"))))
M8: =IF(B8="","",IF(AND(K8="Yes",L8="Yes",OR(G8="Perpetual",G8>=TODAY())),"Active-Compliant",IF(OR(K8="No",L8="No"),"Non-Compliant",IF(AND(G8<TODAY(),H8<TODAY(),I8<TODAY()),"Expired","Active-Review"))))
M9: =IF(B9="","",IF(AND(K9="Yes",L9="Yes",OR(G9="Perpetual",G9>=TODAY())),"Active-Compliant",IF(OR(K9="No",L9="No"),"Non-Compliant",IF(AND(G9<TODAY(),H9<TODAY(),I9<TODAY()),"Expired","Active-Review"))))
M10: =IF(B10="","",IF(AND(K10="Yes",L10="Yes",OR(G10="Perpetual",G10>=TODAY())),"Active-Compliant",IF(OR(K10="No",L10="No"),"Non-Compliant",IF(AND(G10<TODAY(),H10<TODAY(),I10<TODAY()),"Expired","Active-Review"))))
M11: =IF(B11="","",IF(AND(K11="Yes",L11="Yes",OR(G11="Perpetual",G11>=TODAY())),"Active-Compliant",IF(OR(K11="No",L11="No"),"Non-Compliant",IF(AND(G11<TODAY(),H11<TODAY(),I11<TODAY()),"Expired","Active-Review"))))
M12: =IF(B12="","",IF(AND(K12="Yes",L12="Yes",OR(G12="Perpetual",G12>=TODAY())),"Active-Compliant",IF(OR(K12="No",L12="No"),"Non-Compliant",IF(AND(G12<TODAY(),H12<TODAY(),I12<TODAY()),"Expired","Active-Review"))))
M13: =IF(B13="","",IF(AND(K13="Yes",L13="Yes",OR(G13="Perpetual",G13>=TODAY())),"Active-Compliant",IF(OR(K13="No",L13="No"),"Non-Compliant",IF(AND(G13<TODAY(),H13<TODAY(),I13<TODAY()),"Expired","Active-Review"))))
M14: =IF(B14="","",IF(AND(K14="Yes",L14="Yes",OR(G14="Perpetual",G14>=TODAY())),"Active-Compliant",IF(OR(K14="No",L14="No"),"Non-Compliant",IF(AND(G14<TODAY(),H14<TODAY(),I14<TODAY()),"Expired","Active-Review"))))
M15: =IF(B15="","",IF(AND(K15="Yes",L15="Yes",OR(G15="Perpetual",G15>=TODAY())),"Active-Compliant",IF(OR(K15="No",L15="No"),"Non-Compliant",IF(AND(G15<TODAY(),H15<TODAY(),I15<TODAY()),"Expired","Active-Review"))))
M16: =IF(B16="","",IF(AND(K16="Yes",L16="Yes",OR(G16="Perpetual",G16>=TODAY())),"Active-Compliant",IF(OR(K16="No",L16="No"),"Non-Compliant",IF(AND(G16<TODAY(),H16<TODAY(),I16<TODAY()),"Expired","Active-Review"))))
... M104: =IF(B104="","",IF(AND(K104="Yes",L104="Yes",OR(G104="Perpetual",G104>=TODAY())),"Active-Compliant",IF(OR(K104="No",L104="No"),"Non-Compliant",IF(AND(G104<TODAY(),H104<TODAY(),I104<TODAY()),"Expired","Active-Review"))))

Sheet Contractor_Agreement_Assessment
A1: CONTRACTOR AGREEMENT ASSESSMENT
A2: Third-party, contractor, and vendor agreement security clause verification
A4: Contractor_ID | B4: Contractor_Name | C4: Company_Name | D4: Contract_Type | E4: Services_Provided | F4: Contract_Start | G4: Contract_End | H4: NDA_In_Place | I4: Security_Clauses_Present | J4: Data_Access_Level | K4: Background_Check | L4: Compliance_Status | M4: Sponsor_Manager | N4: Notes
L5: =IF(B5="","",IF(AND(H5="Yes",I5="Yes",OR(K5="Yes",K5="N/A")),"Compliant",IF(OR(H5="No",I5="No"),"Non-Compliant","Partial")))
L6: =IF(B6="","",IF(AND(H6="Yes",I6="Yes",OR(K6="Yes",K6="N/A")),"Compliant",IF(OR(H6="No",I6="No"),"Non-Compliant","Partial")))
L7: =IF(B7="","",IF(AND(H7="Yes",I7="Yes",OR(K7="Yes",K7="N/A")),"Compliant",IF(OR(H7="No",I7="No"),"Non-Compliant","Partial")))
L8: =IF(B8="","",IF(AND(H8="Yes",I8="Yes",OR(K8="Yes",K8="N/A")),"Compliant",IF(OR(H8="No",I8="No"),"Non-Compliant","Partial")))
L9: =IF(B9="","",IF(AND(H9="Yes",I9="Yes",OR(K9="Yes",K9="N/A")),"Compliant",IF(OR(H9="No",I9="No"),"Non-Compliant","Partial")))
L10: =IF(B10="","",IF(AND(H10="Yes",I10="Yes",OR(K10="Yes",K10="N/A")),"Compliant",IF(OR(H10="No",I10="No"),"Non-Compliant","Partial")))
L11: =IF(B11="","",IF(AND(H11="Yes",I11="Yes",OR(K11="Yes",K11="N/A")),"Compliant",IF(OR(H11="No",I11="No"),"Non-Compliant","Partial")))
L12: =IF(B12="","",IF(AND(H12="Yes",I12="Yes",OR(K12="Yes",K12="N/A")),"Compliant",IF(OR(H12="No",I12="No"),"Non-Compliant","Partial")))
L13: =IF(B13="","",IF(AND(H13="Yes",I13="Yes",OR(K13="Yes",K13="N/A")),"Compliant",IF(OR(H13="No",I13="No"),"Non-Compliant","Partial")))
L14: =IF(B14="","",IF(AND(H14="Yes",I14="Yes",OR(K14="Yes",K14="N/A")),"Compliant",IF(OR(H14="No",I14="No"),"Non-Compliant","Partial")))
L15: =IF(B15="","",IF(AND(H15="Yes",I15="Yes",OR(K15="Yes",K15="N/A")),"Compliant",IF(OR(H15="No",I15="No"),"Non-Compliant","Partial")))
L16: =IF(B16="","",IF(AND(H16="Yes",I16="Yes",OR(K16="Yes",K16="N/A")),"Compliant",IF(OR(H16="No",I16="No"),"Non-Compliant","Partial")))
... L104: =IF(B104="","",IF(AND(H104="Yes",I104="Yes",OR(K104="Yes",K104="N/A")),"Compliant",IF(OR(H104="No",I104="No"),"Non-Compliant","Partial")))

Sheet Gap_Analysis
A1: GAP ANALYSIS
A2: Consolidated gaps from all employment contract assessment domains
A4: Gap_ID | B4: Source_Sheet | C4: Affected_Entity | D4: Gap_Category | E4: Gap_Description | F4: Risk_Level | G4: Impact_Assessment | H4: Affected_Personnel_Count | I4: Remediation_Action | J4: Responsible_Party | K4: Target_Completion_Date | L4: Estimated_Effort | M4: Dependencies | N4: Status | O4: Completion_Evidence | P4: Risk_Acceptance
A5: =IF(B5<>"",TEXT(ROW()-4,"GAP-000"),"")
A6: =IF(B6<>"",TEXT(ROW()-4,"GAP-000"),"")
A7: =IF(B7<>"",TEXT(ROW()-4,"GAP-000"),"")
A8: =IF(B8<>"",TEXT(ROW()-4,"GAP-000"),"")
A9: =IF(B9<>"",TEXT(ROW()-4,"GAP-000"),"")
A10: =IF(B10<>"",TEXT(ROW()-4,"GAP-000"),"")
A11: =IF(B11<>"",TEXT(ROW()-4,"GAP-000"),"")
A12: =IF(B12<>"",TEXT(ROW()-4,"GAP-000"),"")
A13: =IF(B13<>"",TEXT(ROW()-4,"GAP-000"),"")
A14: =IF(B14<>"",TEXT(ROW()-4,"GAP-000"),"")
A15: =IF(B15<>"",TEXT(ROW()-4,"GAP-000"),"")
A16: =IF(B16<>"",TEXT(ROW()-4,"GAP-000"),"")
... A104: =IF(B104<>"",TEXT(ROW()-4,"GAP-000"),"")

Sheet Evidence_Register
A1: EVIDENCE REGISTER
A2: Documentation of all supporting evidence for employment contract assessment
A4: Evidence_ID | B4: Evidence_Type | C4: Description | D4: Related_Entity_ID | E4: Related_Assessment_Sheet | F4: File_Location | G4: Date_Collected | H4: Collected_By | I4: Verification_Status | J4: Notes
A5: =IF(B5<>"",TEXT(ROW()-4,"EVD-000"),"")
A6: =IF(B6<>"",TEXT(ROW()-4,"EVD-000"),"")
A7: =IF(B7<>"",TEXT(ROW()-4,"EVD-000"),"")
A8: =IF(B8<>"",TEXT(ROW()-4,"EVD-000"),"")
A9: =IF(B9<>"",TEXT(ROW()-4,"EVD-000"),"")
A10: =IF(B10<>"",TEXT(ROW()-4,"EVD-000"),"")
A11: =IF(B11<>"",TEXT(ROW()-4,"EVD-000"),"")
A12: =IF(B12<>"",TEXT(ROW()-4,"EVD-000"),"")
A13: =IF(B13<>"",TEXT(ROW()-4,"EVD-000"),"")
A14: =IF(B14<>"",TEXT(ROW()-4,"EVD-000"),"")
A15: =IF(B15<>"",TEXT(ROW()-4,"EVD-000"),"")
A16: =IF(B16<>"",TEXT(ROW()-4,"EVD-000"),"")
... A104: =IF(B104<>"",TEXT(ROW()-4,"EVD-000"),"")

Sheet Approval_Sign_Off
A1: APPROVAL & SIGN-OFF
A3: ASSESSMENT SUMMARY
A5: Document: | B5: ISMS-IMP-A.5.1-2-6.1-2.S4
A6: Assessment Period: | B6: =Dashboard!B7
A7: Overall Compliance Score: | B7: =Dashboard!B19
A8: Contract Templates Assessed: | B8: =Dashboard!B20
A9: Personnel Contracts Verified: | B9: =Dashboard!B22
A10: NDA Coverage Rate: | B10: =Dashboard!B23
A11: Critical Gaps: | B11: =Dashboard!B24
A12: High Priority Gaps: | B12: =Dashboard!B25
A13: Contractor Agreements Verified: | B13: =Dashboard!B26
A16: LEVEL 1: PREPARED BY
A17: Name:
A18: Role:
A19: Date:
A20: Signature:
A21: Certification: | B21: I certify this assessment is complete and accurate
A22: Comments:
A24: LEVEL 2: REVIEWED BY (HR / LEGAL)
A25: Name:
A26: Role:
A27: Date:
A28: Signature:
A30: Review Checklist:
A31: [ ] Contract templates reviewed and current
A32: [ ] All required security clauses verified
A33: [ ] Personnel contract compliance checked
A34: [ ] NDA coverage 100% (audit focal point)
A35: [ ] Post-employment obligations tracked
... A45: Signature:
A46: Final Approval: | B46: I approve this assessment as accurate
A47: Risk Acceptance: | B47: I accept residual risk for: [list]
A48: Comments:
A50: Next Review Date:
A51: Assessment Status:
A53: Audit Readiness Checklist:
A54: [ ] All three approvals complete
A55: [ ] Evidence 100% verified
A56: [ ] NDA coverage verified (audit focal point)
A57: [ ] All critical gaps have remediation plans
...
