Workbook

Sheet Executive Summary
A1: ISMS-OP-CHK-A.5.8 — Information Security in Project Management Compliance Checklist
A3: DOCUMENT INFORMATION
A4: Document ID | B4: ISMS-OP-CHK-A.5.8
A5: Source Policy | B5: ISMS-OP-POL-A.5.8
A6: ISO Controls | B6: Information Security in Project Management
A7: Generated | B7: 30.09.2026
A8: Prepared By
A9: Organisation
A10: Review Cycle | B10: Annual
A12: OVERALL COMPLIANCE STATUS
A13: Overall Compliance | B13: ='Dashboard'!G14
A14: Status | B14: =IF(Dashboard!H14>0,"INCOMPLETE",IF(Dashboard!G14="N/A","NOT ASSESSED",IF(ISNUMBER(VALUE(SUBSTITUTE(Dashboard!G14,"%",""))),IF(VALUE(SUBSTITUTE(Dashboard!G14,"%",""))>=90,"GREEN",IF(VALUE(SUBSTITUTE(Dashboard!G14,"%",""))>=70,"AMBER","RED")),"NOT ASSESSED")))
A16: KEY METRICS
A17: Total Requirements | B17: ='Dashboard'!B14
A18: Compliant | B18: ='Dashboard'!C14
A19: Partial | B19: ='Dashboard'!D14
A20: Non-Compliant | B20: ='Dashboard'!E14
A21: Not Applicable | B21: ='Dashboard'!F14
A22: Unanswered | B22: ='Dashboard'!H14
A23: Owner Coverage | B23: =IF(Dashboard!B14=0,"N/A",ROUND((COUNTA('Project Classification'!F4:F9)+COUNTA('Security Reqs Identification'!F4:F7)+COUNTA('Phase Gate Security Reviews'!F4:F6)+COUNTA('Sec Testing by Classification'!F4:F6)+COUNTA('Sec Handover and Acceptance'!F4:F7)+COUNTA('Project Security Roles'!F4:F4)+COUNTA('DPIA Integration'!F4:F6)+COUNTA('Agile & Iterative Project'!F4:F5)+COUNTA('Procurement Project Security'!F4:F8)+COUNTA('Compliance Measurement'!F4:F7))/Dashboard!B14*100,0)&"%")
A25: DOMAIN STATUS SUMMARY
A26: Domain | B26: Compliance % | C26: Compliant | D26: Gaps | E26: Status
A27: Project Classification | B27: ='Dashboard'!G4 | C27: ='Dashboard'!C4 | D27: ='Dashboard'!E4 | E27: =IF(Dashboard!H4>0,"INCOMPLETE",IF(Dashboard!G4="N/A","--",IF(ISNUMBER(VALUE(SUBSTITUTE(Dashboard!G4,"%",""))),IF(VALUE(SUBSTITUTE(Dashboard!G4,"%",""))>=90,"PASS",IF(VALUE(SUBSTITUTE(Dashboard!G4,"%",""))>=70,"REVIEW","FAIL")),"--")))
A28: Security Reqs Identification | B28: ='Dashboard'!G5 | C28: ='Dashboard'!C5 | D28: ='Dashboard'!E5 | E28: =IF(Dashboard!H5>0,"INCOMPLETE",IF(Dashboard!G5="N/A","--",IF(ISNUMBER(VALUE(SUBSTITUTE(Dashboard!G5,"%",""))),IF(VALUE(SUBSTITUTE(Dashboard!G5,"%",""))>=90,"PASS",IF(VALUE(SUBSTITUTE(Dashboard!G5,"%",""))>=70,"REVIEW","FAIL")),"--")))
A29: Phase Gate Security Reviews | B29: ='Dashboard'!G6 | C29: ='Dashboard'!C6 | D29: ='Dashboard'!E6 | E29: =IF(Dashboard!H6>0,"INCOMPLETE",IF(Dashboard!G6="N/A","--",IF(ISNUMBER(VALUE(SUBSTITUTE(Dashboard!G6,"%",""))),IF(VALUE(SUBSTITUTE(Dashboard!G6,"%",""))>=90,"PASS",IF(VALUE(SUBSTITUTE(Dashboard!G6,"%",""))>=70,"REVIEW","FAIL")),"--")))
A30: Sec Testing by Classification | B30: ='Dashboard'!G7 | C30: ='Dashboard'!C7 | D30: ='Dashboard'!E7 | E30: =IF(Dashboard!H7>0,"INCOMPLETE",IF(Dashboard!G7="N/A","--",IF(ISNUMBER(VALUE(SUBSTITUTE(Dashboard!G7,"%",""))),IF(VALUE(SUBSTITUTE(Dashboard!G7,"%",""))>=90,"PASS",IF(VALUE(SUBSTITUTE(Dashboard!G7,"%",""))>=70,"REVIEW","FAIL")),"--")))
A31: Sec Handover and Acceptance | B31: ='Dashboard'!G8 | C31: ='Dashboard'!C8 | D31: ='Dashboard'!E8 | E31: =IF(Dashboard!H8>0,"INCOMPLETE",IF(Dashboard!G8="N/A","--",IF(ISNUMBER(VALUE(SUBSTITUTE(Dashboard!G8,"%",""))),IF(VALUE(SUBSTITUTE(Dashboard!G8,"%",""))>=90,"PASS",IF(VALUE(SUBSTITUTE(Dashboard!G8,"%",""))>=70,"REVIEW","FAIL")),"--")))
A32: Project Security Roles | B32: ='Dashboard'!G9 | C32: ='Dashboard'!C9 | D32: ='Dashboard'!E9 | E32: =IF(Dashboard!H9>0,"INCOMPLETE",IF(Dashboard!G9="N/A","--",IF(ISNUMBER(VALUE(SUBSTITUTE(Dashboard!G9,"%",""))),IF(VALUE(SUBSTITUTE(Dashboard!G9,"%",""))>=90,"PASS",IF(VALUE(SUBSTITUTE(Dashboard!G9,"%",""))>=70,"REVIEW","FAIL")),"--")))
A33: DPIA Integration | B33: ='Dashboard'!G10 | C33: ='Dashboard'!C10 | D33: ='Dashboard'!E10 | E33: =IF(Dashboard!H10>0,"INCOMPLETE",IF(Dashboard!G10="N/A","--",IF(ISNUMBER(VALUE(SUBSTITUTE(Dashboard!G10,"%",""))),IF(VALUE(SUBSTITUTE(Dashboard!G10,"%",""))>=90,"PASS",IF(VALUE(SUBSTITUTE(Dashboard!G10,"%",""))>=70,"REVIEW","FAIL")),"--")))
A34: Agile & Iterative Project | B34: ='Dashboard'!G11 | C34: ='Dashboard'!C11 | D34: ='Dashboard'!E11 | E34: =IF(Dashboard!H11>0,"INCOMPLETE",IF(Dashboard!G11="N/A","--",IF(ISNUMBER(VALUE(SUBSTITUTE(Dashboard!G11,"%",""))),IF(VALUE(SUBSTITUTE(Dashboard!G11,"%",""))>=90,"PASS",IF(VALUE(SUBSTITUTE(Dashboard!G11,"%",""))>=70,"REVIEW","FAIL")),"--")))
A35: Procurement Project Security | B35: ='Dashboard'!G12 | C35: ='Dashboard'!C12 | D35: ='Dashboard'!E12 | E35: =IF(Dashboard!H12>0,"INCOMPLETE",IF(Dashboard!G12="N/A","--",IF(ISNUMBER(VALUE(SUBSTITUTE(Dashboard!G12,"%",""))),IF(VALUE(SUBSTITUTE(Dashboard!G12,"%",""))>=90,"PASS",IF(VALUE(SUBSTITUTE(Dashboard!G12,"%",""))>=70,"REVIEW","FAIL")),"--")))
A36: Compliance Measurement | B36: ='Dashboard'!G13 | C36: ='Dashboard'!C13 | D36: ='Dashboard'!E13 | E36: =IF(Dashboard!H13>0,"INCOMPLETE",IF(Dashboard!G13="N/A","--",IF(ISNUMBER(VALUE(SUBSTITUTE(Dashboard!G13,"%",""))),IF(VALUE(SUBSTITUTE(Dashboard!G13,"%",""))>=90,"PASS",IF(VALUE(SUBSTITUTE(Dashboard!G13,"%",""))>=70,"REVIEW","FAIL")),"--")))
A38: CRITICAL ISSUES
A39: # | B39: Issue Description | C39: Domain | D39: Owner | E39: Due Date
A40: 1
A41: 2
A42: 3
A43: 4
A44: 5
A46: MANAGEMENT COMMENTARY
...

Sheet Dashboard
A1: Information Security in Project Management — Compliance Dashboard
A3: Domain | B3: Total Reqs | C3: Compliant | D3: Partial | E3: Non-Compliant | F3: N/A | G3: Compliance % | H3: Unassessed
A4: Project Classification | B4: =COUNTA('Project Classification'!A4:A9) | C4: =COUNTIF('Project Classification'!D4:D9,"Compliant") | D4: =COUNTIF('Project Classification'!D4:D9,"Partial") | E4: =COUNTIF('Project Classification'!D4:D9,"Non-Compliant") | F4: =COUNTIF('Project Classification'!D4:D9,"N/A") | G4: =IF((B4-F4)=0,"N/A",ROUND(C4/(B4-F4)*100,1)&"%") | H4: =B4-(C4+D4+E4+F4)
A5: Security Reqs Identification | B5: =COUNTA('Security Reqs Identification'!A4:A7) | C5: =COUNTIF('Security Reqs Identification'!D4:D7,"Compliant") | D5: =COUNTIF('Security Reqs Identification'!D4:D7,"Partial") | E5: =COUNTIF('Security Reqs Identification'!D4:D7,"Non-Compliant") | F5: =COUNTIF('Security Reqs Identification'!D4:D7,"N/A") | G5: =IF((B5-F5)=0,"N/A",ROUND(C5/(B5-F5)*100,1)&"%") | H5: =B5-(C5+D5+E5+F5)
A6: Phase Gate Security Reviews | B6: =COUNTA('Phase Gate Security Reviews'!A4:A6) | C6: =COUNTIF('Phase Gate Security Reviews'!D4:D6,"Compliant") | D6: =COUNTIF('Phase Gate Security Reviews'!D4:D6,"Partial") | E6: =COUNTIF('Phase Gate Security Reviews'!D4:D6,"Non-Compliant") | F6: =COUNTIF('Phase Gate Security Reviews'!D4:D6,"N/A") | G6: =IF((B6-F6)=0,"N/A",ROUND(C6/(B6-F6)*100,1)&"%") | H6: =B6-(C6+D6+E6+F6)
A7: Sec Testing by Classification | B7: =COUNTA('Sec Testing by Classification'!A4:A6) | C7: =COUNTIF('Sec Testing by Classification'!D4:D6,"Compliant") | D7: =COUNTIF('Sec Testing by Classification'!D4:D6,"Partial") | E7: =COUNTIF('Sec Testing by Classification'!D4:D6,"Non-Compliant") | F7: =COUNTIF('Sec Testing by Classification'!D4:D6,"N/A") | G7: =IF((B7-F7)=0,"N/A",ROUND(C7/(B7-F7)*100,1)&"%") | H7: =B7-(C7+D7+E7+F7)
A8: Sec Handover and Acceptance | B8: =COUNTA('Sec Handover and Acceptance'!A4:A7) | C8: =COUNTIF('Sec Handover and Acceptance'!D4:D7,"Compliant") | D8: =COUNTIF('Sec Handover and Acceptance'!D4:D7,"Partial") | E8: =COUNTIF('Sec Handover and Acceptance'!D4:D7,"Non-Compliant") | F8: =COUNTIF('Sec Handover and Acceptance'!D4:D7,"N/A") | G8: =IF((B8-F8)=0,"N/A",ROUND(C8/(B8-F8)*100,1)&"%") | H8: =B8-(C8+D8+E8+F8)
A9: Project Security Roles | B9: =COUNTA('Project Security Roles'!A4:A4) | C9: =COUNTIF('Project Security Roles'!D4:D4,"Compliant") | D9: =COUNTIF('Project Security Roles'!D4:D4,"Partial") | E9: =COUNTIF('Project Security Roles'!D4:D4,"Non-Compliant") | F9: =COUNTIF('Project Security Roles'!D4:D4,"N/A") | G9: =IF((B9-F9)=0,"N/A",ROUND(C9/(B9-F9)*100,1)&"%") | H9: =B9-(C9+D9+E9+F9)
A10: DPIA Integration | B10: =COUNTA('DPIA Integration'!A4:A6) | C10: =COUNTIF('DPIA Integration'!D4:D6,"Compliant") | D10: =COUNTIF('DPIA Integration'!D4:D6,"Partial") | E10: =COUNTIF('DPIA Integration'!D4:D6,"Non-Compliant") | F10: =COUNTIF('DPIA Integration'!D4:D6,"N/A") | G10: =IF((B10-F10)=0,"N/A",ROUND(C10/(B10-F10)*100,1)&"%") | H10: =B10-(C10+D10+E10+F10)
A11: Agile & Iterative Project | B11: =COUNTA('Agile & Iterative Project'!A4:A5) | C11: =COUNTIF('Agile & Iterative Project'!D4:D5,"Compliant") | D11: =COUNTIF('Agile & Iterative Project'!D4:D5,"Partial") | E11: =COUNTIF('Agile & Iterative Project'!D4:D5,"Non-Compliant") | F11: =COUNTIF('Agile & Iterative Project'!D4:D5,"N/A") | G11: =IF((B11-F11)=0,"N/A",ROUND(C11/(B11-F11)*100,1)&"%") | H11: =B11-(C11+D11+E11+F11)
A12: Procurement Project Security | B12: =COUNTA('Procurement Project Security'!A4:A8) | C12: =COUNTIF('Procurement Project Security'!D4:D8,"Compliant") | D12: =COUNTIF('Procurement Project Security'!D4:D8,"Partial") | E12: =COUNTIF('Procurement Project Security'!D4:D8,"Non-Compliant") | F12: =COUNTIF('Procurement Project Security'!D4:D8,"N/A") | G12: =IF((B12-F12)=0,"N/A",ROUND(C12/(B12-F12)*100,1)&"%") | H12: =B12-(C12+D12+E12+F12)
A13: Compliance Measurement | B13: =COUNTA('Compliance Measurement'!A4:A7) | C13: =COUNTIF('Compliance Measurement'!D4:D7,"Compliant") | D13: =COUNTIF('Compliance Measurement'!D4:D7,"Partial") | E13: =COUNTIF('Compliance Measurement'!D4:D7,"Non-Compliant") | F13: =COUNTIF('Compliance Measurement'!D4:D7,"N/A") | G13: =IF((B13-F13)=0,"N/A",ROUND(C13/(B13-F13)*100,1)&"%") | H13: =B13-(C13+D13+E13+F13)
A14: TOTAL | B14: =SUM(B4:B13) | C14: =SUM(C4:C13) | D14: =SUM(D4:D13) | E14: =SUM(E4:E13) | F14: =SUM(F4:F13) | G14: =IF((B14-F14)=0,"N/A",ROUND(C14/(B14-F14)*100,1)&"%") | H14: =SUM(H4:H13)
A16: COMPLIANCE BY STATUS
A17: Compliant | B17: =C14 | C17: =IF(B14=0,"",ROUND(B17/B14*100,1)&"%")
A18: Partial | B18: =D14 | C18: =IF(B14=0,"",ROUND(B18/B14*100,1)&"%")
A19: Non-Compliant | B19: =E14 | C19: =IF(B14=0,"",ROUND(B19/B14*100,1)&"%")
A20: N/A | B20: =F14 | C20: =IF(B14=0,"",ROUND(B20/B14*100,1)&"%")
A22: TOP GAPS (Manual Entry)
A23: Priority | B23: Domain | C23: Requirement | D23: Owner | E23: Due Date | F23: Status
A35: COMPLIANCE TREND (Manual Entry)
A36: Assessment Date | B36: Overall % | C36: Compliant | D36: Gaps | E36: Assessor | F36: Notes

Sheet Project Classification
A1: Project Classification — Compliance Checklist
A2: ISO/IEC 27001:2022 — Control A.5.8: Information Security in Project Management
A3: Req # | B3: Section | C3: Requirement | D3: Status | E3: Evidence | F3: Owner | G3: Due Date | H3: Notes
A4: A.5.8-01 | B4: Be Classified By Information Security | C4: All projects shall be classified by information security risk to determine proportional security requirements. Classification shall occur at project initiation and be documented in the project charter or equivalent initiation document.
A5: A.5.8-02 | B5: Be Classified Based On The Highest | C5: Projects shall be classified based on the highest applicable factor across the following dimensions:.
A6: A.5.8-03 | B6: Classification Rule: If Any Single | C6: Classification rule: If any single factor meets the High Risk criteria, the project shall be classified as High Risk. If any factor meets Medium Risk (and no factor is High Risk), classify as Medium Risk. Only if all factors are Low Risk shall the project be classified as Low Risk*.
A7: A.5.8-04 | B7: Be Reviewed At Each Phase Gate | C7: Classification shall be reviewed at each phase gate. If project scope, data sensitivity, or external exposure changes materially, the classification shall be updated and re-approved.
A8: A.5.8-05 | B8: Project Managers | C8: Project managers shall estimate security costs based on project classification when preparing project budgets:.
A9: A.5.8-06 | B9: Security Budget Estimates | C9: Security budget estimates shall be included in the project initiation documentation and approved as part of the project budget. Where actual security costs are expected to exceed the estimated range, the Project Manager shall notify the Information Security Officer and adjust the project budget accordingly.

Sheet Security Reqs Identification
A1: Security Reqs Identification — Compliance Checklist
A2: ISO/IEC 27001:2022 — Control A.5.8: Information Security in Project Management
A3: Req # | B3: Section | C3: Requirement | D3: Status | E3: Evidence | F3: Owner | G3: Due Date | H3: Notes
A4: A.5.8-07 | B4: Security Requirements For Project | C4: Security requirements for project deliverables shall be identified systematically during the planning phase based on the project's classification and the categories of assets and data involved.
A5: A.5.8-08 | B5: The Project Manager, With Information | C5: The Project Manager, with Information Security Officer support, shall assess each of the following requirement categories against project scope:.
A6: A.5.8-09 | B6: High And Medium Risk Projects: Security | C6: High and Medium Risk projects: Security requirements shall be documented in a Security Requirements Register (or equivalent section in [Project Management Tool]) and tracked through to implementation and testing.
A7: A.5.8-10 | B7: Low Risk Projects: Security Requirements | C7: Low Risk projects: Security requirements shall be documented as risk mitigation items in the project risk register with confirmation of applicable policy compliance.

Sheet Phase Gate Security Reviews
A1: Phase Gate Security Reviews — Compliance Checklist
A2: ISO/IEC 27001:2022 — Control A.5.8: Information Security in Project Management
A3: Req # | B3: Section | C3: Requirement | D3: Status | E3: Evidence | F3: Owner | G3: Due Date | H3: Notes
A4: A.5.8-11 | B4: Security Reviews | C4: Security reviews shall be integrated into project governance at the following phase gates. Projects shall not proceed to the next phase until security criteria for the current phase gate are satisfied or formally accepted by the appropriate authority.
A5: A.5.8-12 | B5: Security Concerns At Phase Gates | C5: Security concerns at phase gates shall be escalated within:.
A6: A.5.8-13 | B6: Not Proceed To The Next Phase | C6: Projects shall not proceed to the next phase without resolving Critical security concerns. High security concerns may proceed with formal risk acceptance from the appropriate authority. Medium and Low concerns may proceed with a documented mitigation plan.

Sheet Sec Testing by Classification
A1: Sec Testing by Classification — Compliance Checklist
A2: ISO/IEC 27001:2022 — Control A.5.8: Information Security in Project Management
A3: Req # | B3: Section | C3: Requirement | D3: Status | E3: Evidence | F3: Owner | G3: Due Date | H3: Notes
A4: A.5.8-14 | B4: Include Security Testing Proportional To | C4: All projects shall include security testing proportional to their classification level. Testing shall be completed before deployment and the results documented.
A5: A.5.8-15 | B5: Residual Risk | C5: If remediation targets cannot be achieved before the deployment deadline, residual risk shall be formally accepted per the Exception Management section of this policy.
A6: A.5.8-16 | B6: Testing Evidence (Scan Reports, | C6: Testing evidence (scan reports, penetration test reports, code review findings) shall be archived per records management requirements.

Sheet Sec Handover and Acceptance
A1: Sec Handover and Acceptance — Compliance Checklist
A2: ISO/IEC 27001:2022 — Control A.5.8: Information Security in Project Management
A3: Req # | B3: Section | C3: Requirement | D3: Status | E3: Evidence | F3: Owner | G3: Due Date | H3: Notes
A4: A.5.8-17 | B4: At Project Closure, Security Handover | C4: At project closure, security handover documentation shall be provided to the operational team and validated as complete before the project is formally closed. Incomplete security handover blocks project closure.
A5: A.5.8-18 | B5: The Security Handover Package | C5: The security handover package shall include:.
A6: A.5.8-19 | B6: The Operational Owner | C6: The operational owner shall confirm handover completeness via a signed Security Handover Checklist before the Project Manager requests project closure authorisation. For High Risk projects, the CISO shall additionally approve the handover.
A7: A.5.8-20 | B7: Upon Handover Acceptance, The Project | C7: Upon handover acceptance, the Project Manager shall ensure:.

Sheet Project Security Roles
A1: Project Security Roles — Compliance Checklist
A2: ISO/IEC 27001:2022 — Control A.5.8: Information Security in Project Management
A3: Req # | B3: Section | C3: Requirement | D3: Status | E3: Evidence | F3: Owner | G3: Due Date | H3: Notes
A4: A.5.8-21 | B4: The Information Security Officer | C4: The Information Security Officer shall coordinate the Security Champion programme, including selection criteria, training content, and ongoing support.

Sheet DPIA Integration
A1: DPIA Integration — Compliance Checklist
A2: ISO/IEC 27001:2022 — Control A.5.8: Information Security in Project Management
A3: Req # | B3: Section | C3: Requirement | D3: Status | E3: Evidence | F3: Owner | G3: Due Date | H3: Notes
A4: A.5.8-22 | B4: A Data Protection Impact Assessment | C4: Where a project involves the processing of personal data, a Data Protection Impact Assessment (DPIA) screening shall be performed at project initiation to determine whether a full DPIA is required.
A5: A.5.8-23 | B5: A Dpia Screening | C5: A DPIA screening shall be completed for every project that processes personal data. The screening shall assess whether the planned processing is likely to result in high risk to individuals' personality or fundamental rights, as required by Swiss nFADP Art. 22.
A6: A.5.8-24 | B6: The Completed Dpia | C6: The completed DPIA shall be reviewed by the Data Protection Officer (or CISO where no DPO is appointed) and approved before the project proceeds to execution. Where the DPIA identifies residual high risks that cannot be mitigated, the organisation shall consult the Federal Data Protection and Information Commissioner (FDPIC) before proceeding, as required by nFADP Art. 23.

Sheet Agile & Iterative Project
A1: Agile & Iterative Project — Compliance Checklist
A2: ISO/IEC 27001:2022 — Control A.5.8: Information Security in Project Management
A3: Req # | B3: Section | C3: Requirement | D3: Status | E3: Evidence | F3: Owner | G3: Due Date | H3: Notes
A4: A.5.8-25 | B4: For Projects Using Agile, Scrum, Or | C4: For projects using Agile, Scrum, or other iterative methodologies, security shall be integrated into the iterative process rather than deferred to the end.
A5: A.5.8-26 | B5: Rather Than Single Phase Gates, | C5: Rather than single phase gates, iterative projects shall implement security checkpoints at the following points:.

Sheet Procurement Project Security
A1: Procurement Project Security — Compliance Checklist
A2: ISO/IEC 27001:2022 — Control A.5.8: Information Security in Project Management
A3: Req # | B3: Section | C3: Requirement | D3: Status | E3: Evidence | F3: Owner | G3: Due Date | H3: Notes
A4: A.5.8-27 | B4: Projects Involving Procurement Of It | C4: Projects involving procurement of IT systems, software, or services shall include information security requirements in the procurement process.
A5: A.5.8-28 | B5: Vendor Security Assessment: Vendors | C5: Vendor security assessment: Vendors shall be assessed against the organisation's supplier security requirements (per the Supplier Relationship Security Policy) before contract award.
A6: A.5.8-29 | B6: Security Requirements In Contracts: | C6: Security requirements in contracts: Contracts shall include information security requirements, including data protection obligations, incident notification requirements, audit rights, and subcontractor controls.
A7: A.5.8-30 | B7: Security Acceptance Criteria: | C7: Security acceptance criteria: Procurement acceptance criteria shall include security validation (e.g., vulnerability scan of delivered system, security configuration review, access control verification).
A8: A.5.8-31 | B8: Data Processing Agreements: Where The | C8: Data processing agreements: Where the vendor processes personal data on behalf of the organisation, a data processing agreement compliant with nFADP Art. 9 (and GDPR Art. 28 where applicable) shall be executed before data processing begins.

Sheet Compliance Measurement
A1: Compliance Measurement — Compliance Checklist
A2: ISO/IEC 27001:2022 — Control A.5.8: Information Security in Project Management
A3: Req # | B3: Section | C3: Requirement | D3: Status | E3: Evidence | F3: Owner | G3: Due Date | H3: Notes
A4: A.5.8-32 | B4: The Following Metrics | C4: The following metrics shall be tracked and reported to the CISO quarterly:.
A5: A.5.8-33 | B5: The Ciso | C5: The CISO shall maintain a project security metrics dashboard providing at-a-glance programme health visibility. The dashboard shall include:.
A6: A.5.8-34 | B6: The Dashboard | C6: The dashboard shall be reviewed at the monthly CISO review and included in the quarterly Executive Management report to provide clear visibility of project security programme effectiveness.
A7: A.5.8-35 | B7: Metrics Breaching Red Thresholds | C7: Metrics breaching red thresholds shall be escalated to the CISO for immediate attention and reported at the next Management Review.
