Workbook

Sheet Executive Summary
A1: ISMS-OP-CHK-A.8.20-22 — Network Security Compliance Checklist
A3: DOCUMENT INFORMATION
A4: Document ID | B4: ISMS-OP-CHK-A.8.20-22
A5: Source Policy | B5: ISMS-OP-POL-A.8.20-22
A6: ISO Controls | B6: Network Security
A7: Generated | B7: 30.09.2026
A8: Prepared By
A9: Organisation
A10: Review Cycle | B10: Annual
A12: OVERALL COMPLIANCE STATUS
A13: Overall Compliance | B13: ='Dashboard'!G13
A14: Status | B14: =IF(Dashboard!H13>0,"INCOMPLETE",IF(Dashboard!G13="N/A","NOT ASSESSED",IF(ISNUMBER(VALUE(SUBSTITUTE(Dashboard!G13,"%",""))),IF(VALUE(SUBSTITUTE(Dashboard!G13,"%",""))>=90,"GREEN",IF(VALUE(SUBSTITUTE(Dashboard!G13,"%",""))>=70,"AMBER","RED")),"NOT ASSESSED")))
A16: KEY METRICS
A17: Total Requirements | B17: ='Dashboard'!B13
A18: Compliant | B18: ='Dashboard'!C13
A19: Partial | B19: ='Dashboard'!D13
A20: Non-Compliant | B20: ='Dashboard'!E13
A21: Not Applicable | B21: ='Dashboard'!F13
A22: Unanswered | B22: ='Dashboard'!H13
A23: Owner Coverage | B23: =IF(Dashboard!B13=0,"N/A",ROUND((COUNTA('Network Controls'!F4:F13)+COUNTA('Security of Network Services'!F4:F6)+COUNTA('Segregation in Networks'!F4:F30)+COUNTA('Access Networks & Network'!F4:F7)+COUNTA('Remote Access'!F4:F8)+COUNTA('Network Locations'!F4:F7)+COUNTA('Physical Network Devices'!F4:F6)+COUNTA('Web Filtering'!F4:F7)+COUNTA('Host Intrusion, Network'!F4:F7))/Dashboard!B13*100,0)&"%")
A25: DOMAIN STATUS SUMMARY
A26: Domain | B26: Compliance % | C26: Compliant | D26: Gaps | E26: Status
A27: Network Controls | B27: ='Dashboard'!G4 | C27: ='Dashboard'!C4 | D27: ='Dashboard'!E4 | E27: =IF(Dashboard!H4>0,"INCOMPLETE",IF(Dashboard!G4="N/A","--",IF(ISNUMBER(VALUE(SUBSTITUTE(Dashboard!G4,"%",""))),IF(VALUE(SUBSTITUTE(Dashboard!G4,"%",""))>=90,"PASS",IF(VALUE(SUBSTITUTE(Dashboard!G4,"%",""))>=70,"REVIEW","FAIL")),"--")))
A28: Security of Network Services | B28: ='Dashboard'!G5 | C28: ='Dashboard'!C5 | D28: ='Dashboard'!E5 | E28: =IF(Dashboard!H5>0,"INCOMPLETE",IF(Dashboard!G5="N/A","--",IF(ISNUMBER(VALUE(SUBSTITUTE(Dashboard!G5,"%",""))),IF(VALUE(SUBSTITUTE(Dashboard!G5,"%",""))>=90,"PASS",IF(VALUE(SUBSTITUTE(Dashboard!G5,"%",""))>=70,"REVIEW","FAIL")),"--")))
A29: Segregation in Networks | B29: ='Dashboard'!G6 | C29: ='Dashboard'!C6 | D29: ='Dashboard'!E6 | E29: =IF(Dashboard!H6>0,"INCOMPLETE",IF(Dashboard!G6="N/A","--",IF(ISNUMBER(VALUE(SUBSTITUTE(Dashboard!G6,"%",""))),IF(VALUE(SUBSTITUTE(Dashboard!G6,"%",""))>=90,"PASS",IF(VALUE(SUBSTITUTE(Dashboard!G6,"%",""))>=70,"REVIEW","FAIL")),"--")))
A30: Access Networks & Network | B30: ='Dashboard'!G7 | C30: ='Dashboard'!C7 | D30: ='Dashboard'!E7 | E30: =IF(Dashboard!H7>0,"INCOMPLETE",IF(Dashboard!G7="N/A","--",IF(ISNUMBER(VALUE(SUBSTITUTE(Dashboard!G7,"%",""))),IF(VALUE(SUBSTITUTE(Dashboard!G7,"%",""))>=90,"PASS",IF(VALUE(SUBSTITUTE(Dashboard!G7,"%",""))>=70,"REVIEW","FAIL")),"--")))
A31: Remote Access | B31: ='Dashboard'!G8 | C31: ='Dashboard'!C8 | D31: ='Dashboard'!E8 | E31: =IF(Dashboard!H8>0,"INCOMPLETE",IF(Dashboard!G8="N/A","--",IF(ISNUMBER(VALUE(SUBSTITUTE(Dashboard!G8,"%",""))),IF(VALUE(SUBSTITUTE(Dashboard!G8,"%",""))>=90,"PASS",IF(VALUE(SUBSTITUTE(Dashboard!G8,"%",""))>=70,"REVIEW","FAIL")),"--")))
A32: Network Locations | B32: ='Dashboard'!G9 | C32: ='Dashboard'!C9 | D32: ='Dashboard'!E9 | E32: =IF(Dashboard!H9>0,"INCOMPLETE",IF(Dashboard!G9="N/A","--",IF(ISNUMBER(VALUE(SUBSTITUTE(Dashboard!G9,"%",""))),IF(VALUE(SUBSTITUTE(Dashboard!G9,"%",""))>=90,"PASS",IF(VALUE(SUBSTITUTE(Dashboard!G9,"%",""))>=70,"REVIEW","FAIL")),"--")))
A33: Physical Network Devices | B33: ='Dashboard'!G10 | C33: ='Dashboard'!C10 | D33: ='Dashboard'!E10 | E33: =IF(Dashboard!H10>0,"INCOMPLETE",IF(Dashboard!G10="N/A","--",IF(ISNUMBER(VALUE(SUBSTITUTE(Dashboard!G10,"%",""))),IF(VALUE(SUBSTITUTE(Dashboard!G10,"%",""))>=90,"PASS",IF(VALUE(SUBSTITUTE(Dashboard!G10,"%",""))>=70,"REVIEW","FAIL")),"--")))
A34: Web Filtering | B34: ='Dashboard'!G11 | C34: ='Dashboard'!C11 | D34: ='Dashboard'!E11 | E34: =IF(Dashboard!H11>0,"INCOMPLETE",IF(Dashboard!G11="N/A","--",IF(ISNUMBER(VALUE(SUBSTITUTE(Dashboard!G11,"%",""))),IF(VALUE(SUBSTITUTE(Dashboard!G11,"%",""))>=90,"PASS",IF(VALUE(SUBSTITUTE(Dashboard!G11,"%",""))>=70,"REVIEW","FAIL")),"--")))
A35: Host Intrusion, Network | B35: ='Dashboard'!G12 | C35: ='Dashboard'!C12 | D35: ='Dashboard'!E12 | E35: =IF(Dashboard!H12>0,"INCOMPLETE",IF(Dashboard!G12="N/A","--",IF(ISNUMBER(VALUE(SUBSTITUTE(Dashboard!G12,"%",""))),IF(VALUE(SUBSTITUTE(Dashboard!G12,"%",""))>=90,"PASS",IF(VALUE(SUBSTITUTE(Dashboard!G12,"%",""))>=70,"REVIEW","FAIL")),"--")))
A37: CRITICAL ISSUES
A38: # | B38: Issue Description | C38: Domain | D38: Owner | E38: Due Date
A39: 1
A40: 2
A41: 3
A42: 4
A43: 5
A45: MANAGEMENT COMMENTARY
A46: [Enter management commentary on network security posture]
...

Sheet Dashboard
A1: Network Security — Compliance Dashboard
A3: Domain | B3: Total Reqs | C3: Compliant | D3: Partial | E3: Non-Compliant | F3: N/A | G3: Compliance % | H3: Unassessed
A4: Network Controls | B4: =COUNTA('Network Controls'!A4:A13) | C4: =COUNTIF('Network Controls'!D4:D13,"Compliant") | D4: =COUNTIF('Network Controls'!D4:D13,"Partial") | E4: =COUNTIF('Network Controls'!D4:D13,"Non-Compliant") | F4: =COUNTIF('Network Controls'!D4:D13,"N/A") | G4: =IF((B4-F4)=0,"N/A",ROUND(C4/(B4-F4)*100,1)&"%") | H4: =B4-(C4+D4+E4+F4)
A5: Security of Network Services | B5: =COUNTA('Security of Network Services'!A4:A6) | C5: =COUNTIF('Security of Network Services'!D4:D6,"Compliant") | D5: =COUNTIF('Security of Network Services'!D4:D6,"Partial") | E5: =COUNTIF('Security of Network Services'!D4:D6,"Non-Compliant") | F5: =COUNTIF('Security of Network Services'!D4:D6,"N/A") | G5: =IF((B5-F5)=0,"N/A",ROUND(C5/(B5-F5)*100,1)&"%") | H5: =B5-(C5+D5+E5+F5)
A6: Segregation in Networks | B6: =COUNTA('Segregation in Networks'!A4:A30) | C6: =COUNTIF('Segregation in Networks'!D4:D30,"Compliant") | D6: =COUNTIF('Segregation in Networks'!D4:D30,"Partial") | E6: =COUNTIF('Segregation in Networks'!D4:D30,"Non-Compliant") | F6: =COUNTIF('Segregation in Networks'!D4:D30,"N/A") | G6: =IF((B6-F6)=0,"N/A",ROUND(C6/(B6-F6)*100,1)&"%") | H6: =B6-(C6+D6+E6+F6)
A7: Access Networks & Network | B7: =COUNTA('Access Networks & Network'!A4:A7) | C7: =COUNTIF('Access Networks & Network'!D4:D7,"Compliant") | D7: =COUNTIF('Access Networks & Network'!D4:D7,"Partial") | E7: =COUNTIF('Access Networks & Network'!D4:D7,"Non-Compliant") | F7: =COUNTIF('Access Networks & Network'!D4:D7,"N/A") | G7: =IF((B7-F7)=0,"N/A",ROUND(C7/(B7-F7)*100,1)&"%") | H7: =B7-(C7+D7+E7+F7)
A8: Remote Access | B8: =COUNTA('Remote Access'!A4:A8) | C8: =COUNTIF('Remote Access'!D4:D8,"Compliant") | D8: =COUNTIF('Remote Access'!D4:D8,"Partial") | E8: =COUNTIF('Remote Access'!D4:D8,"Non-Compliant") | F8: =COUNTIF('Remote Access'!D4:D8,"N/A") | G8: =IF((B8-F8)=0,"N/A",ROUND(C8/(B8-F8)*100,1)&"%") | H8: =B8-(C8+D8+E8+F8)
A9: Network Locations | B9: =COUNTA('Network Locations'!A4:A7) | C9: =COUNTIF('Network Locations'!D4:D7,"Compliant") | D9: =COUNTIF('Network Locations'!D4:D7,"Partial") | E9: =COUNTIF('Network Locations'!D4:D7,"Non-Compliant") | F9: =COUNTIF('Network Locations'!D4:D7,"N/A") | G9: =IF((B9-F9)=0,"N/A",ROUND(C9/(B9-F9)*100,1)&"%") | H9: =B9-(C9+D9+E9+F9)
A10: Physical Network Devices | B10: =COUNTA('Physical Network Devices'!A4:A6) | C10: =COUNTIF('Physical Network Devices'!D4:D6,"Compliant") | D10: =COUNTIF('Physical Network Devices'!D4:D6,"Partial") | E10: =COUNTIF('Physical Network Devices'!D4:D6,"Non-Compliant") | F10: =COUNTIF('Physical Network Devices'!D4:D6,"N/A") | G10: =IF((B10-F10)=0,"N/A",ROUND(C10/(B10-F10)*100,1)&"%") | H10: =B10-(C10+D10+E10+F10)
A11: Web Filtering | B11: =COUNTA('Web Filtering'!A4:A7) | C11: =COUNTIF('Web Filtering'!D4:D7,"Compliant") | D11: =COUNTIF('Web Filtering'!D4:D7,"Partial") | E11: =COUNTIF('Web Filtering'!D4:D7,"Non-Compliant") | F11: =COUNTIF('Web Filtering'!D4:D7,"N/A") | G11: =IF((B11-F11)=0,"N/A",ROUND(C11/(B11-F11)*100,1)&"%") | H11: =B11-(C11+D11+E11+F11)
A12: Host Intrusion, Network | B12: =COUNTA('Host Intrusion, Network'!A4:A7) | C12: =COUNTIF('Host Intrusion, Network'!D4:D7,"Compliant") | D12: =COUNTIF('Host Intrusion, Network'!D4:D7,"Partial") | E12: =COUNTIF('Host Intrusion, Network'!D4:D7,"Non-Compliant") | F12: =COUNTIF('Host Intrusion, Network'!D4:D7,"N/A") | G12: =IF((B12-F12)=0,"N/A",ROUND(C12/(B12-F12)*100,1)&"%") | H12: =B12-(C12+D12+E12+F12)
A13: TOTAL | B13: =SUM(B4:B12) | C13: =SUM(C4:C12) | D13: =SUM(D4:D12) | E13: =SUM(E4:E12) | F13: =SUM(F4:F12) | G13: =IF((B13-F13)=0,"N/A",ROUND(C13/(B13-F13)*100,1)&"%") | H13: =SUM(H4:H12)
A15: COMPLIANCE BY STATUS
A16: Compliant | B16: =C13 | C16: =IF(B13=0,"",ROUND(B16/B13*100,1)&"%")
A17: Partial | B17: =D13 | C17: =IF(B13=0,"",ROUND(B17/B13*100,1)&"%")
A18: Non-Compliant | B18: =E13 | C18: =IF(B13=0,"",ROUND(B18/B13*100,1)&"%")
A19: N/A | B19: =F13 | C19: =IF(B13=0,"",ROUND(B19/B13*100,1)&"%")
A21: TOP GAPS (Manual Entry)
A22: Priority | B22: Domain | C22: Requirement | D22: Owner | E22: Due Date | F22: Status
A34: COMPLIANCE TREND (Manual Entry)
A35: Assessment Date | B35: Overall % | C35: Compliant | D35: Gaps | E35: Assessor | F35: Notes

Sheet Network Controls
A1: Network Controls — Compliance Checklist
A2: ISO/IEC 27001:2022 — Controls A.8.20-22: Network Security
A3: Req # | B3: Section | C3: Requirement | D3: Status | E3: Evidence | F3: Owner | G3: Due Date | H3: Notes
A4: A.8.20-22-01 | B4: Responsibilities And Procedures For The | C4: Responsibilities and procedures for the management of networking equipment shall be established and documented.
A5: A.8.20-22-02 | B5: Operational Responsibility For Networks | C5: Operational responsibility for networks shall be separated from computer operations where appropriate.
A6: A.8.20-22-03 | B6: Special Controls | C6: Special controls shall be established to safeguard the confidentiality and integrity of data passing over public networks or over wireless networks and to protect the connected systems and applications.
A7: A.8.20-22-04 | B7: Appropriate Logging And Monitoring | C7: Appropriate logging and monitoring shall be applied to enable recording and detection of actions that may affect, or are relevant to, information security.
A8: A.8.20-22-05 | B8: Management Activities | C8: Management activities shall be closely coordinated both to optimise the service to the organisation and to ensure that controls are consistently applied across the information processing infrastructure.
A9: A.8.20-22-06 | B9: Systems On The Network | C9: Systems on the network shall be authenticated before being granted access.
A10: A.8.20-22-07 | B10: System Connections To The Network | C10: System connections to the network shall be restricted to authorised and compliant devices.
A11: A.8.20-22-08 | B11: Network Device Default Passwords And | C11: Network device default passwords and accounts shall be changed or disabled before deployment.
A12: A.8.20-22-09 | B12: Administrative Access To Network Devices | C12: Administrative access to network devices shall use encrypted management protocols (SSH, HTTPS). Telnet and unencrypted SNMP (v1/v2c) shall not be used.
A13: A.8.20-22-10 | B13: Network Device Firmware And Software | C13: Network device firmware and software shall be maintained at current, vendor-supported versions. Security patches shall be applied according to the following timelines:.

Sheet Security of Network Services
A1: Security of Network Services — Compliance Checklist
A2: ISO/IEC 27001:2022 — Controls A.8.20-22: Network Security
A3: Req # | B3: Section | C3: Requirement | D3: Status | E3: Evidence | F3: Owner | G3: Due Date | H3: Notes
A4: A.8.20-22-11 | B4: Security Mechanisms, Service Levels, And | C4: Security mechanisms, service levels, and management requirements of all network services shall be identified and included in network services agreements, whether these services are provided in-house or outsourced.
A5: A.8.20-22-12 | B5: The Ability Of The Network Service | C5: The ability of the network service provider to manage agreed services in a secure way shall be determined and regularly monitored, and the right to audit shall be agreed.
A6: A.8.20-22-13 | B6: The Security Arrangements Necessary For | C6: The security arrangements necessary for particular services, such as security features, service levels, and management requirements, shall be identified. The organisation shall ensure that network service providers implement these measures.

Sheet Segregation in Networks
A1: Segregation in Networks — Compliance Checklist
A2: ISO/IEC 27001:2022 — Controls A.8.20-22: Network Security
A3: Req # | B3: Section | C3: Requirement | D3: Status | E3: Evidence | F3: Owner | G3: Due Date | H3: Notes
A4: A.8.20-22-14 | B4: Large Networks | C4: Large networks shall be divided into separate network domains. The domains shall be chosen based on trust levels, data classification, and business function.
A5: A.8.20-22-15 | B5: The Perimeter Of Each Domain | C5: The perimeter of each domain shall be well defined. Access between network domains shall be controlled at the perimeter using a gateway (e.g., firewall, filtering router) with a default-deny posture.
A6: A.8.20-22-16 | B6: The Criteria For Segregation Of Networks | C6: The criteria for segregation of networks into domains, and the access allowed through the gateways, shall be based on an assessment of the security requirements of each domain. The assessment shall be in accordance with the access control policy, access requirements, value and classification of information processed, and shall take account of the relative cost and performance impact of incorporating suitable gateway technology.
A7: A.8.20-22-17 | B7: Firewall Rule Changes | C7: All firewall rule changes shall follow a documented change management process with business justification and approval.
A8: A.8.20-22-18 | B8: Firewall Rule Sets | C8: Firewall rule sets shall be reviewed at least annually to remove obsolete rules and verify continued business justification.
A9: A.8.20-22-19 | B9: Be Documented With Sign-Off From The | C9: Reviews shall be documented with sign-off from the network administrator and CISO.
A10: A.8.20-22-20 | B10: Default-Deny Policy | C10: Default-deny policy shall be verified during each review (all traffic blocked unless explicitly permitted).
A11: A.8.20-22-21 | B11: Minimum Network Segments | C11: Minimum network segments shall include:.
A12: A.8.20-22-22 | B12: Additional Segments (E.G., Dmz For | C12: Additional segments (e.g., DMZ for public-facing services, development/test environments) shall be created based on risk assessment.
A13: A.8.20-22-23 | B13: Guest Networks | C13: Guest networks shall be configured with the following security controls:.
A14: A.8.20-22-24 | B14: Isolation: No Access To Corporate | C14: Isolation: No access to corporate network segments (firewall rules shall enforce separation).
A15: A.8.20-22-25 | B15: Internet-Only Access: Guests | C15: Internet-only access: Guests shall access only the Internet, not internal resources.
... A30: A.8.20-22-40 | B30: Wpa (Original) And Tkip Encryption | C30: WPA (original) and TKIP encryption shall not be used.

Sheet Access Networks & Network
A1: Access Networks & Network — Compliance Checklist
A2: ISO/IEC 27001:2022 — Controls A.8.20-22: Network Security
A3: Req # | B3: Section | C3: Requirement | D3: Status | E3: Evidence | F3: Owner | G3: Due Date | H3: Notes
A4: A.8.20-22-41 | B4: Only Be Provided With Access To | C4: Users shall only be provided with access to the network and network services that they have been specifically authorised to use.
A5: A.8.20-22-42 | B5: Access To Networks And Network Services | C5: Access to networks and network services shall be in line with the Access Control Policy.
A6: A.8.20-22-43 | B6: Before Connecting To The Network, | C6: Before connecting to the network, devices shall have:.
A7: A.8.20-22-44 | B7: Implement Technical Controls To Enforce | C7: The organisation shall implement technical controls to enforce device compliance before granting network access. Enforcement mechanisms include network access control (NAC) solutions, 802.1X certificate or credential-based authentication, VPN gateway posture assessment, or manual registration and approval by IT. Non-compliant devices shall be placed in a quarantine or restricted segment until compliance is achieved.

Sheet Remote Access
A1: Remote Access — Compliance Checklist
A2: ISO/IEC 27001:2022 — Controls A.8.20-22: Network Security
A3: Req # | B3: Section | C3: Requirement | D3: Status | E3: Evidence | F3: Owner | G3: Due Date | H3: Notes
A4: A.8.20-22-45 | B4: Remote Access To The Organisation | C4: Remote access to the organisation network shall be secured using encrypted tunnels (VPN or equivalent) with multi-factor authentication.
A5: A.8.20-22-46 | B5: Vpn Connections | C5: VPN connections shall use current, secure protocols:.
A6: A.8.20-22-47 | B6: Pptp And L2Tp Without Ipsec | C6: PPTP and L2TP without IPsec shall not be used.
A7: A.8.20-22-48 | B7: Remote Connections | C7: Remote connections shall be set to disconnect after a defined period of inactivity.
A8: A.8.20-22-49 | B8: A List Of Users With Remote | C8: A list of users with remote access shall be maintained and reviewed quarterly.

Sheet Network Locations
A1: Network Locations — Compliance Checklist
A2: ISO/IEC 27001:2022 — Controls A.8.20-22: Network Security
A3: Req # | B3: Section | C3: Requirement | D3: Status | E3: Evidence | F3: Owner | G3: Due Date | H3: Notes
A4: A.8.20-22-50 | B4: Network Infrastructure And Data | C4: Network infrastructure and data processing locations shall be selected based on risk assessment, data classification, and applicable data protection requirements.
A5: A.8.20-22-51 | B5: The Following Hierarchy Of Preference | C5: The following hierarchy of preference shall apply for the location of network infrastructure, data centres, and cloud services processing personal or confidential data:.
A6: A.8.20-22-52 | B6: Within Countries Recognised By The Swiss | C6: Within countries recognised by the Swiss Federal Council as providing adequate data protection per Annex 1 of the Data Protection Ordinance (DSV). The current adequacy list is published by the Federal Data Protection and Information Commissioner (FDPIC) and shall be verified before deploying infrastructure or services in a new jurisdiction.
A7: A.8.20-22-53 | B7: Cross-Border Data Transfers | C7: Cross-border data transfers shall comply with the Information Transfer Policy and nFADP requirements. Legal counsel shall verify the adequacy status of any country before deployment.

Sheet Physical Network Devices
A1: Physical Network Devices — Compliance Checklist
A2: ISO/IEC 27001:2022 — Controls A.8.20-22: Network Security
A3: Req # | B3: Section | C3: Requirement | D3: Status | E3: Evidence | F3: Owner | G3: Due Date | H3: Notes
A4: A.8.20-22-54 | B4: Physical Network Devices | C4: Physical network devices shall be managed in line with the Physical and Environmental Security Policy, specifically the sections on cabling security, equipment siting and protection, and access control.
A5: A.8.20-22-55 | B5: Physical Network Devices | C5: Physical network devices shall be destroyed in line with the Information Classification and Handling Policy, specifically the section on the destruction of electronic media and devices.
A6: A.8.20-22-56 | B6: Physical Network Devices | C6: Physical network devices shall be managed in line with the Asset Management Policy and subject to the asset management process.

Sheet Web Filtering
A1: Web Filtering — Compliance Checklist
A2: ISO/IEC 27001:2022 — Controls A.8.20-22: Network Security
A3: Req # | B3: Section | C3: Requirement | D3: Status | E3: Evidence | F3: Owner | G3: Due Date | H3: Notes
A4: A.8.20-22-57 | B4: Access To Websites | C4: Access to websites containing illegal information or known to contain malicious content shall be restricted.
A5: A.8.20-22-58 | B5: Access To The Following Types Of | C5: Access to the following types of websites shall be blocked where practicable:.
A6: A.8.20-22-59 | B6: Web Filtering | C6: Web filtering shall be implemented using DNS-based filtering, web proxy, or equivalent technology. Filter categories and exceptions shall be reviewed quarterly.
A7: A.8.20-22-60 | B7: Internal Dns Zones | C7: Internal DNS zones shall not be exposed to the Internet. Split-horizon DNS is recommended for organisations with internal and external name resolution.

Sheet Host Intrusion, Network
A1: Host Intrusion, Network — Compliance Checklist
A2: ISO/IEC 27001:2022 — Controls A.8.20-22: Network Security
A3: Req # | B3: Section | C3: Requirement | D3: Status | E3: Evidence | F3: Owner | G3: Due Date | H3: Notes
A4: A.8.20-22-61 | B4: Network Services And Devices | C4: Network services and devices shall be managed in line with the Malware and Antivirus Policy.
A5: A.8.20-22-62 | B5: Host Intrusion Detection And Network | C5: Host intrusion detection and network intrusion detection/prevention shall be deployed based on risk, business need, and where practical to do so.
A6: A.8.20-22-63 | B6: Additional Deployment Locations | C6: Additional deployment locations shall be determined by risk assessment. Where dedicated IDS/IPS appliances are not feasible, equivalent detection capabilities (e.g., EDR with network visibility, cloud-native security tools) are acceptable.
A7: A.8.20-22-64 | B7: Network Traffic | C7: Network traffic shall be monitored for anomalous behaviour. Security alerts shall be triaged and escalated per the Incident Management process.
