Workbook

Sheet Instructions & Legend
A1: ISMS-IMP-A.8.24.4 - Key Management Assessment ISO/IEC 27001:2022 - Control A.8.24: Use of Cryptography
A3: Document Information
A4: Document ID | B4: ISMS-IMP-A.8.24.4
A5: Workbook Title | B5: Key Management Assessment
A6: Control Reference | B6: ISO/IEC 27001:2022 - Control A.8.24: Use of Cryptography
A7: Version | B7: 1.0
A8: Assessment Date
A9: Completed By
A10: Organisation
A12: Instructions
A13: 1. Complete each worksheet tab (1–5) for applicable key management areas.
A14: 2. Use dropdown menus for standardised entries (Status, Key Type, Algorithm, Storage Method, etc.).
A15: 3. Fill in yellow-highlighted cells with your information.
A16: 4. If Status = Partial or Non-Compliant, complete the Exception/Deviation section.
A17: 5. Document key lifecycle details for each cryptographic system.
A18: 6. Provide evidence location/path for each implementation entry.
A19: 7. Summary Dashboard auto-calculates compliance statistics per key management area.
A20: 8. Maintain the Evidence Register for audit traceability.
... A23: Status Legend
A24: Symbol | B24: Status | C24: Description
A25: ✓ | B25: Compliant / Complete | C25: Requirement fully met
A26: ⚠ | B26: Partial / In Progress | C26: Partially met or in progress
A27: ✗ | B27: Non-Compliant / Not Started | C27: Requirement not met
A28: — | B28: Not Applicable | C28: Not applicable to this assessment

Sheet 1. Key Generation
A1: 1. KEY GENERATION - CRYPTOGRAPHIC KEY CREATION Policy Requirement: Cryptographic keys MUST be generated using approved algorithms with cryptographically secure random number generators (Policy Section 2.4.1)
A2: ISO/IEC 27001:2022 | Control A.8.24: Use of Cryptography
A3: Does your organisation generate cryptographic keys for encryption, signing, or authentication purposes?
A4: Response:
A6: System/Service | B6: Key Type | C6: Algorithm | D6: Key Length (bits) | E6: Storage Method | F6: Data Classification | G6: Lifecycle Stage | H6: Status | I6: Evidence Location | J6: Gap Description | K6: Remediation Needed | L6: Exception ID | M6: Risk ID | N6: Compensating Controls | O6: Responsible Person | P6: Target Date | Q6: Budget Required | R6: Random Number Generator | S6: Generation Location | T6: Key Ceremony Performed | U6: Entropy Source Verified | V6: Generation Audit Log
A7: Example: Production Database Encryption - FINDB01 | B7: Data Encryption Key | C7: AES-256 | D7: 256 | E7: HSM | F7: Restricted | G7: Active | H7: ✅ Compliant | I7: /evidence/key-mgmt/FINDB01-key-generation-log.pdf | J7: None | K7: No | L7: N/A | M7: N/A | N7: N/A | O7: N/A | P7: N/A | Q7: No | R7: HSM RNG | S7: HSM | T7: Yes | U7: Yes | V7: Yes
A22: 1. KEY GENERATION CHECKLIST
A23: ☐ | B23: Requirement | C23: Status
A24: ☐ | B24: Approved algorithms only (AES-256, RSA ≥3072, Ed25519, ECDSA P-256+)
A25: ☐ | B25: Cryptographically secure random number generator (CSRNG) used
A26: ☐ | B26: FIPS 140-2 Level 2+ validated cryptographic module (production)
A27: ☐ | B27: Key generation performed in secure environment (HSM/KMS/TPM)
A28: ☐ | B28: Weak algorithms prohibited (DES, 3DES, MD5, SHA-1, RSA <2048)
A29: ☐ | B29: Key ceremony documented for master/root keys
A30: ☐ | B30: Dual control/split knowledge for critical key generation
A31: ☐ | B31: Key generation audit logging enabled
A32: ☐ | B32: Generated keys never exposed in plaintext outside secure boundary
A33: ☐ | B33: Entropy source quality verified and tested
A34: ☐ | B34: Key generation procedures documented
A35: ☐ | B35: Key metadata tracked (creation date, purpose, owner, classification)
... A40: ☐ | B40: Cryptographic roles and responsibilities defined — key custodians, security officers, and approvers identified
A41: Checklist Score: | B41: =IFERROR(ROUND(COUNTIF(C24:C40,"✅ Yes")/COUNTA(C24:C40)*100,0)&"%","0%")
A43: APPROVED ALGORITHMS BY USE CASE
A44: Use Case | B44: Minimum Algorithm | C44: Key Length | D44: Notes
A45: Symmetric Encryption (Data at Rest) | B45: AES | C45: 256 bits | D45: AES-256-GCM preferred
A46: Symmetric Encryption (Data in Transit) | B46: AES, ChaCha20 | C46: 256 bits | D46: ChaCha20-Poly1305 for mobile
A47: Asymmetric Encryption | B47: RSA, ECDH | C47: RSA ≥3072, ECDH P-256+ | D47: RSA-4096 for long-term
A48: Digital Signatures | B48: RSA, Ed25519, ECDSA | C48: RSA ≥3072, Ed25519, ECDSA P-256+ | D48: Ed25519 preferred for new systems
A49: Key Exchange | B49: ECDH, RSA | C49: ECDH P-256+, RSA ≥3072 | D49: Use ephemeral keys for PFS
A50: Hashing | B50: SHA-256, SHA-384, SHA-512 | C50: N/A (output size) | D50: SHA-256 minimum
A51: HMAC | B51: HMAC-SHA256 | C51: ≥256 bits | D51: For message authentication
A53: EXCEPTION / DEVIATION DOCUMENTATION (Complete if Status = Partial or Non-Compliant)
A54: Formal exception request submitted:
A55: Exception ID:
A56: Risk acceptance documented:
A57: Risk ID:
A58: Compensating Controls (summary):
A59: ☐ Enhanced monitoring and alerting
A60: ☐ Restricted network access / air-gapped systems
A61: ☐ Additional encryption layer
...

Sheet 2. Key Storage
A1: 2. KEY STORAGE - SECURE KEY PROTECTION Policy Requirement: Cryptographic keys MUST be stored in hardware security modules (HSM), cloud KMS, or TPM for production systems. Software keystores permitted only for non-production with documented risk acceptance (Policy Section 2.4.2)
A2: ISO/IEC 27001:2022 | Control A.8.24: Use of Cryptography
A3: Does your organisation store cryptographic keys that require protection?
A4: Response:
A6: System/Service | B6: Key Type | C6: Algorithm | D6: Key Length (bits) | E6: Storage Method | F6: Data Classification | G6: Lifecycle Stage | H6: Status | I6: Evidence Location | J6: Gap Description | K6: Remediation Needed | L6: Exception ID | M6: Risk ID | N6: Compensating Controls | O6: Responsible Person | P6: Target Date | Q6: Budget Required | R6: HSM/KMS Model | S6: FIPS 140 Level | T6: Access Control Method | U6: Encryption at Rest | V6: Physical Security | W6: Key Backup Exists
A7: Example: Azure Key Vault - App1 Keys | B7: Key Encryption Key | C7: RSA-4096 | D7: 4096 | E7: Cloud KMS | F7: Confidential | G7: Active | H7: ✅ Compliant | I7: /evidence/key-mgmt/app1-kv-config.pdf | J7: None | K7: No | L7: N/A | M7: N/A | N7: N/A | O7: N/A | P7: N/A | Q7: No | R7: Azure Key Vault | S7: Level 2 | T7: MFA Required | U7: Yes | V7: Cloud Provider | W7: Yes
A22: 2. KEY STORAGE CHECKLIST
A23: ☐ | B23: Requirement | C23: Status
A24: ☐ | B24: Production keys stored in HSM, cloud KMS, or TPM
A25: ☐ | B25: FIPS 140-2 Level 2+ (or FIPS 140-3 equivalent) for production
A26: ☐ | B26: Keys encrypted when stored (key encryption keys protected by HSM)
A27: ☐ | B27: Keys never stored in plaintext files or code repositories
A28: ☐ | B28: Keys never stored in application configuration files
A29: ☐ | B29: Keys never stored in environment variables (production)
A30: ☐ | B30: Keys never stored in databases without encryption
A31: ☐ | B31: Access to keys restricted by role-based access control (RBAC)
A32: ☐ | B32: Multi-factor authentication required for key access
A33: ☐ | B33: Dual control/split knowledge for master keys
A34: ☐ | B34: Key access logged and monitored
A35: ☐ | B35: Keys physically secured (locked facilities, tamper-evident HSMs)
... A40: ☐ | B40: Unused/obsolete keys securely destroyed
A41: Checklist Score: | B41: =IFERROR(ROUND(COUNTIF(C24:C40,"✅ Yes")/COUNTA(C24:C40)*100,0)&"%","0%")
A43: APPROVED KEY STORAGE SOLUTIONS
A44: Solution Type | B44: Examples | C44: FIPS 140-2 Level | D44: Use Case
A45: Hardware HSM | B45: Thales Luna, Entrust nShield, Utimaco | C45: Level 3/4 | D45: High-security production
A46: Cloud HSM | B46: AWS CloudHSM, Azure Dedicated HSM | C46: Level 3 | D46: Cloud-native high-security
A47: Cloud KMS | B47: AWS KMS, Azure Key Vault, GCP Cloud KMS | C47: Level 2/3 | D47: General cloud workloads
A48: TPM | B48: TPM 2.0 (various vendors) | C48: Level 2 | D48: Endpoint/device keys
A49: Software Vault | B49: HashiCorp Vault, CyberArk | C49: Varies | D49: Non-production acceptable
A51: EXCEPTION / DEVIATION DOCUMENTATION (Complete if Status = Partial or Non-Compliant)
A52: Formal exception request submitted:
A53: Exception ID:
A54: Risk acceptance documented:
A55: Risk ID:
A56: Compensating Controls (summary):
A57: ☐ Enhanced monitoring and alerting
A58: ☐ Restricted network access / air-gapped systems
A59: ☐ Additional encryption layer
A60: ☐ Manual key management procedures
A61: ☐ Increased audit frequency
...

Sheet 3. Key Rotation
A1: 3. KEY ROTATION - CRYPTOGRAPHIC KEY LIFECYCLE MANAGEMENT Policy Requirement: Cryptographic keys MUST be rotated according to defined schedules: Encryption keys annually, signing keys biennially, session keys hourly/daily (Policy Section 2.4.3)
A2: ISO/IEC 27001:2022 | Control A.8.24: Use of Cryptography
A3: Does your organisation have a key rotation policy and implementation for cryptographic keys?
A4: Response:
A6: System/Service | B6: Key Type | C6: Algorithm | D6: Key Length (bits) | E6: Storage Method | F6: Data Classification | G6: Lifecycle Stage | H6: Status | I6: Evidence Location | J6: Gap Description | K6: Remediation Needed | L6: Exception ID | M6: Risk ID | N6: Compensating Controls | O6: Responsible Person | P6: Target Date | Q6: Budget Required | R6: Rotation Schedule | S6: Last Rotation Date | T6: Next Rotation Due | U6: Automated Rotation | V6: Rotation Tested | W6: Re-encryption Required
A7: Example: API Signing Keys | B7: Signing Key | C7: RSA-3072 | D7: 3072 | E7: Cloud KMS | F7: Confidential | G7: Active | H7: ✅ Compliant | I7: /evidence/key-mgmt/api-key-rotation.pdf | J7: None | K7: No | L7: N/A | M7: N/A | N7: N/A | O7: N/A | P7: N/A | Q7: No | R7: Quarterly | S7: 2024-10-01 | T7: 2025-01-01 | U7: Yes | V7: Yes | W7: No
A22: 3. KEY ROTATION CHECKLIST
A23: ☐ | B23: Requirement | C23: Status
A24: ☐ | B24: Key rotation policy documented and approved
A25: ☐ | B25: Encryption keys (data at rest) rotated annually minimum
A26: ☐ | B26: Signing keys rotated biennially minimum
A27: ☐ | B27: Session keys rotated hourly/daily
A28: ☐ | B28: Master keys rotated every 1-3 years
A29: ☐ | B29: Key rotation automated where possible
A30: ☐ | B30: Key rotation triggers defined (time, usage, compromise)
A31: ☐ | B31: Data re-encryption performed after key rotation
A32: ☐ | B32: Old keys retained for decryption (with restricted access)
A33: ☐ | B33: Key version tracking implemented
A34: ☐ | B34: Rotation procedures tested in non-production
A35: ☐ | B35: Rotation audit logs maintained
... A39: ☐ | B39: Cryptoperiod limits enforced (max key usage duration)
A40: Checklist Score: | B40: =IFERROR(ROUND(COUNTIF(C24:C39,"✅ Yes")/COUNTA(C24:C39)*100,0)&"%","0%")
A42: ROTATION SCHEDULE BY KEY TYPE
A43: Key Type | B43: Minimum Rotation Frequency | C43: Recommended Frequency | D43: Trigger Events
A44: Master Encryption Key | B44: 1 year | C44: 1 year | D44: Compromise, personnel change
A45: Data Encryption Key | B45: 1 year | C45: 90 days | D45: High volume usage, compromise
A46: Key Encryption Key | B46: 1 year | C46: 1 year | D46: Master key rotation, compromise
A47: Signing Key | B47: 2 years | C47: 1 year | D47: Certificate expiry, compromise
A48: Session Key | B48: 24 hours | C48: 1 hour | D48: Session end, compromise
A49: API Key | B49: 90 days | C49: 30-90 days | D49: Personnel change, compromise
A50: TLS/SSL Certificate Private Key | B50: Certificate validity | C50: Annual | D50: Certificate renewal, compromise
A51: SSH Key | B51: 1 year | C51: 90 days | D51: Personnel change, compromise
A52: Database TDE Key | B52: 1 year | C52: 1 year | D52: Compliance requirement, compromise
A54: EXCEPTION / DEVIATION DOCUMENTATION (Complete if Status = Partial or Non-Compliant)
A55: Formal exception request submitted:
A56: Exception ID:
A57: Risk acceptance documented:
A58: Risk ID:
A59: Compensating Controls (summary):
A60: ☐ Enhanced monitoring and alerting
...

Sheet 4. Key Backup & Recovery
A1: 4. KEY BACKUP & RECOVERY - BUSINESS CONTINUITY Policy Requirement: Cryptographic keys MUST have documented backup and recovery procedures. Backup keys stored with equal or greater security than production keys (Policy Section 2.4.4)
A2: ISO/IEC 27001:2022 | Control A.8.24: Use of Cryptography
A3: Does your organisation maintain backup and recovery procedures for cryptographic keys?
A4: Response:
A6: System/Service | B6: Key Type | C6: Algorithm | D6: Key Length (bits) | E6: Storage Method | F6: Data Classification | G6: Lifecycle Stage | H6: Status | I6: Evidence Location | J6: Gap Description | K6: Remediation Needed | L6: Exception ID | M6: Risk ID | N6: Compensating Controls | O6: Responsible Person | P6: Target Date | Q6: Budget Required | R6: Backup Method | S6: Backup Encryption | T6: Backup Location | U6: Recovery Tested | V6: Last Recovery Test | W6: RTO (Recovery Time) | X6: Escrow Agreement
A7: Example: Master Encryption Key Backup | B7: Master Key | C7: AES-256 | D7: 256 | E7: HSM | F7: Restricted | G7: Active | H7: ✅ Compliant | I7: /evidence/key-mgmt/master-key-backup.pdf | J7: None | K7: No | L7: N/A | M7: N/A | N7: N/A | O7: N/A | P7: N/A | Q7: No | R7: HSM Backup | S7: Yes | T7: Offsite Secure Vault | U7: Yes | V7: 2024-06-15 | W7: <1 hour | X7: Yes
A22: 4. KEY BACKUP & RECOVERY CHECKLIST
A23: ☐ | B23: Requirement | C23: Status
A24: ☐ | B24: Key backup and recovery procedures documented
A25: ☐ | B25: All critical keys have backup copies
A26: ☐ | B26: Backup keys encrypted with equal or stronger encryption
A27: ☐ | B27: Backup keys stored separately from production keys
A28: ☐ | B28: Geographic separation of backup keys (offsite/different region)
A29: ☐ | B29: Backup key access restricted (dual control/escrow)
A30: ☐ | B30: Key recovery procedures tested quarterly
A31: ☐ | B31: Recovery time objective (RTO) defined and documented
A32: ☐ | B32: Recovery point objective (RPO) defined and documented
A33: ☐ | B33: Key escrow agreements in place (where required)
A34: ☐ | B34: Split knowledge/dual control for backup key recovery
A35: ☐ | B35: Backup key inventory maintained and audited
... A41: ☐ | B41: HSM backup cards stored in secure facility
A42: Checklist Score: | B42: =IFERROR(ROUND(COUNTIF(C24:C41,"✅ Yes")/COUNTA(C24:C41)*100,0)&"%","0%")
A44: BACKUP STRATEGIES BY KEY TYPE
A45: Key Type | B45: Recommended Backup Method | C45: Storage Location | D45: Recovery Testing Frequency
A46: Master Keys | B46: HSM backup card + escrow | C46: Offsite secure vault | D46: Annually
A47: Encryption Keys | B47: KMS automated backup | C47: Different region/account | D47: Quarterly
A48: Certificate Private Keys | B48: Encrypted file backup | C48: Secure file storage | D48: Semi-annually
A49: SSH Keys | B49: Encrypted backup + key management system | C49: Secrets vault | D49: Annually
A50: API Keys | B50: Secrets management system | C50: Multi-region vault | D50: Quarterly
A51: Database TDE Keys | B51: Native database backup + KMS | C51: Encrypted backup storage | D51: Quarterly
A53: EXCEPTION / DEVIATION DOCUMENTATION (Complete if Status = Partial or Non-Compliant)
A54: Formal exception request submitted:
A55: Exception ID:
A56: Risk acceptance documented:
A57: Risk ID:
A58: Compensating Controls (summary):
A59: ☐ Enhanced monitoring and alerting
A60: ☐ Restricted network access / air-gapped systems
A61: ☐ Additional encryption layer
A62: ☐ Manual key management procedures
...

Sheet 5. Certificate Management
A1: 5. CERTIFICATE MANAGEMENT - DIGITAL CERTIFICATE LIFECYCLE Policy Requirement: Digital certificates MUST be issued from trusted Certificate Authorities. Certificate lifecycle management includes issuance, renewal, revocation, and expiration monitoring (Policy Section 2.4.5)
A2: ISO/IEC 27001:2022 | Control A.8.24: Use of Cryptography
A3: Does your organisation use digital certificates for TLS/SSL, code signing, email signing, or authentication?
A4: Response:
A6: System/Service | B6: Key Type | C6: Algorithm | D6: Key Length (bits) | E6: Storage Method | F6: Data Classification | G6: Lifecycle Stage | H6: Status | I6: Evidence Location | J6: Gap Description | K6: Remediation Needed | L6: Exception ID | M6: Risk ID | N6: Compensating Controls | O6: Responsible Person | P6: Target Date | Q6: Budget Required | R6: Certificate Type | S6: Issuing CA | T6: Certificate Validity | U6: Expiration Date | V6: Auto-Renewal | W6: Revocation Method | X6: Monitoring Enabled
A7: Example: Production Web Server TLS | B7: Certificate | C7: RSA-2048 | D7: 2048 | E7: TPM | F7: Public | G7: Active | H7: ✅ Compliant | I7: /evidence/key-mgmt/web-tls-cert.pdf | J7: None | K7: No | L7: N/A | M7: N/A | N7: N/A | O7: N/A | P7: N/A | Q7: No | R7: TLS/SSL Server | S7: Let's Encrypt | T7: ≤90 days | U7: 2025-03-15 | V7: Yes | W7: OCSP | X7: Yes
A22: 5. CERTIFICATE MANAGEMENT CHECKLIST
A23: ☐ | B23: Requirement | C23: Status
A24: ☐ | B24: Certificates issued from trusted public CA (for external services)
A25: ☐ | B25: Internal CA infrastructure properly secured (for internal services)
A26: ☐ | B26: Certificate validity ≤397 days (public TLS certificates)
A27: ☐ | B27: Certificate validity ≤90 days preferred (automated renewal)
A28: ☐ | B28: Self-signed certificates NOT used in production
A29: ☐ | B29: Certificate inventory maintained and up to date
A30: ☐ | B30: Certificate expiration monitoring implemented
A31: ☐ | B31: Alerts configured for 30/60/90 days before expiration
A32: ☐ | B32: Automated certificate renewal configured
A33: ☐ | B33: Certificate renewal tested in non-production
A34: ☐ | B34: Certificate revocation procedures documented
A35: ☐ | B35: CRL or OCSP configured for revocation checking
... A45: ☐ | B45: Jurisdictional restrictions identified — use of cryptographic products compliant with laws of all countries where data is processed or stored
A46: Checklist Score: | B46: =IFERROR(ROUND(COUNTIF(C24:C45,"✅ Yes")/COUNTA(C24:C45)*100,0)&"%","0%")
A48: CERTIFICATE VALIDITY STANDARDS
A49: Certificate Type | B49: Maximum Validity | C49: Recommended Validity | D49: Renewal Process
A50: Public TLS/SSL | B50: 397 days (13 months) | C50: 90 days | D50: ACME/Let's Encrypt automated
A51: Internal TLS/SSL | B51: 2 years | C51: 1 year | D51: Internal CA automated
A52: Code Signing | B52: 3 years | C52: 1 year | D52: Manual with hardware token
A53: Email (S/MIME) | B53: 2 years | C53: 1 year | D53: PKI automated or manual
A54: Client Authentication | B54: 2 years | C54: 1 year | D54: PKI automated
A55: Root CA | B55: 20 years | C55: 10 years | D55: Manual with ceremony
A56: Intermediate CA | B56: 10 years | C56: 5 years | D56: Manual with ceremony
A58: CERTIFICATE LIFECYCLE STAGES
A59: Stage | B59: Actions | C59: Responsible Role | D59: Documentation Required
A60: Request | B60: Generate CSR, validate domain/identity | C60: System Owner | D60: CSR details, approval
A61: Issuance | B61: CA validation, certificate generation | C61: CA Admin | D61: Issuance record, validation log
A62: Installation | B62: Deploy certificate to service | C62: System Admin | D62: Deployment log, verification
A63: Monitoring | B63: Track expiration, validate configuration | C63: Security Team | D63: Monitoring dashboard
A64: Renewal | B64: Generate new CSR, request renewal | C64: System Owner | D64: Renewal approval, testing
A65: Revocation | B65: Revoke compromised/obsolete certificate | C65: CA Admin | D65: Incident record, revocation log
A66: Archival | B66: Archive expired certificates | C66: Security Team | D66: Archive log, retention period
...

Sheet 6. Key Destruction
A1: 6. KEY DESTRUCTION - CRYPTOGRAPHIC KEY DISPOSAL Policy Requirement: Cryptographic keys that have reached end-of-life MUST be securely destroyed and destruction documented (Policy Section 2.4.6)
A2: ISO/IEC 27001:2022 | Control A.8.24: Use of Cryptography
A3: Does your organisation have documented procedures for secure cryptographic key destruction and disposal?
A4: Response:
A6: Key ID | B6: Key Type | C6: Algorithm | D6: Creation Date | E6: Scheduled Destruction Date | F6: Destruction Method | G6: Actual Destruction Date | H6: Verification Method | I6: Authorised By | J6: Status
A7: KEY-001 | B7: Data Encryption Key | C7: AES-256 | D7: 01.01.2023 | E7: 01.01.2025 | F7: Crypto-erasure | G7: 15.12.2024 | H7: Third-party audit + log | I7: CISO | J7: ✅ Destroyed
A59: KEY DESTRUCTION CHECKLIST
A60: ☐ | B60: Requirement | C60: Status
A61: ☐ | B61: Key destruction policy documented and approved
A62: ☐ | B62: Destruction procedures defined for each key type (HSM, software, cloud)
A63: ☐ | B63: Cryptographic erasure used where physical destruction not possible
A64: ☐ | B64: Destruction authority (authorisation) defined and enforced
A65: ☐ | B65: Dual-person authorisation required for master/critical key destruction
A66: ☐ | B66: Destruction records maintained (what, when, who, how)
A67: ☐ | B67: Third-party verification for high-sensitivity key destruction
A68: ☐ | B68: Hardware-based keys: HSM/token physically destroyed or cryptographically zeroed
A69: ☐ | B69: Cloud KMS keys: provider deletion confirmation obtained
A70: ☐ | B70: Destruction audit trail retained for minimum 7 years
A71: ☐ | B71: All copies of key (backup, escrow) destroyed simultaneously
A72: ☐ | B72: Destruction tested and verified in non-production
... A75: ☐ | B75: Post-destruction verification procedure in place
A76: Checklist Score: | B76: =IFERROR(ROUND(COUNTIF(C61:C75,"✅ Yes")/COUNTA(C61:C75)*100,0)&"%","0%")

Sheet Evidence Register
A1: EVIDENCE REGISTER
A2: List all evidence files/documents referenced in this assessment (audit traceability).
A4: Evidence ID | B4: Assessment Area | C4: Evidence Type | D4: Description | E4: Location/Path | F4: Date Collected | G4: Collected By | H4: Verification Status
A5: EV-001 | B5: 1. Key Generation | C5: Configuration file | D5: TLS/encryption configuration export for audit evidence | E5: /evidence/a824/config-export-2025.txt | F5: 01.01.2025 | G5: Security Team | H5: ✅ Verified

Sheet Summary Dashboard
A1: KEY MANAGEMENT ASSESSMENT — SUMMARY DASHBOARD
A2: ISO/IEC 27001:2022 | Control A.8.24 | Cryptographic Key Management
A4: TABLE 1: ASSESSMENT AREA COMPLIANCE OVERVIEW
A5: Assessment Area | B5: Total Items | C5: Compliant | D5: Partial | E5: Non-Compliant | F5: N/A | G5: Compliance %
A6: 1. Key Generation | B6: =COUNTA('1. Key Generation'!H8:H90) | C6: =COUNTIF('1. Key Generation'!H8:H90,"✅*") | D6: =COUNTIF('1. Key Generation'!H8:H90,"⚠️*") | E6: =COUNTIF('1. Key Generation'!H8:H90,"❌*") | F6: =COUNTIF('1. Key Generation'!H8:H90,"N/A") | G6: =IF((B6-F6)=0,"0%",ROUND(C6/(B6-F6)*100,1)&"%")
A7: 2. Key Storage | B7: =COUNTA('2. Key Storage'!H8:H90) | C7: =COUNTIF('2. Key Storage'!H8:H90,"✅*") | D7: =COUNTIF('2. Key Storage'!H8:H90,"⚠️*") | E7: =COUNTIF('2. Key Storage'!H8:H90,"❌*") | F7: =COUNTIF('2. Key Storage'!H8:H90,"N/A") | G7: =IF((B7-F7)=0,"0%",ROUND(C7/(B7-F7)*100,1)&"%")
A8: 3. Key Rotation | B8: =COUNTA('3. Key Rotation'!H8:H90) | C8: =COUNTIF('3. Key Rotation'!H8:H90,"✅*") | D8: =COUNTIF('3. Key Rotation'!H8:H90,"⚠️*") | E8: =COUNTIF('3. Key Rotation'!H8:H90,"❌*") | F8: =COUNTIF('3. Key Rotation'!H8:H90,"N/A") | G8: =IF((B8-F8)=0,"0%",ROUND(C8/(B8-F8)*100,1)&"%")
A9: 4. Key Backup & Recovery | B9: =COUNTA('4. Key Backup & Recovery'!H8:H90) | C9: =COUNTIF('4. Key Backup & Recovery'!H8:H90,"✅*") | D9: =COUNTIF('4. Key Backup & Recovery'!H8:H90,"⚠️*") | E9: =COUNTIF('4. Key Backup & Recovery'!H8:H90,"❌*") | F9: =COUNTIF('4. Key Backup & Recovery'!H8:H90,"N/A") | G9: =IF((B9-F9)=0,"0%",ROUND(C9/(B9-F9)*100,1)&"%")
A10: 5. Certificate Management | B10: =COUNTA('5. Certificate Management'!H8:H90) | C10: =COUNTIF('5. Certificate Management'!H8:H90,"✅*") | D10: =COUNTIF('5. Certificate Management'!H8:H90,"⚠️*") | E10: =COUNTIF('5. Certificate Management'!H8:H90,"❌*") | F10: =COUNTIF('5. Certificate Management'!H8:H90,"N/A") | G10: =IF((B10-F10)=0,"0%",ROUND(C10/(B10-F10)*100,1)&"%")
A11: 6. Key Destruction | B11: =COUNTA('6. Key Destruction'!H8:H90) | C11: =COUNTIF('6. Key Destruction'!H8:H90,"✅*") | D11: =COUNTIF('6. Key Destruction'!H8:H90,"⚠️*") | E11: =COUNTIF('6. Key Destruction'!H8:H90,"❌*") | F11: =COUNTIF('6. Key Destruction'!H8:H90,"N/A") | G11: =IF((B11-F11)=0,"0%",ROUND(C11/(B11-F11)*100,1)&"%")
A12: TOTAL | B12: =SUM(B6:B11) | C12: =SUM(C6:C11) | D12: =SUM(D6:D11) | E12: =SUM(E6:E11) | F12: =SUM(F6:F11) | G12: =IF((B12-F12)=0,"0%",ROUND(C12/(B12-F12)*100,1)&"%")
A14: TABLE 2: KEY METRICS
A15: KPI | B15: Current Value | C15: Target | D15: Status | E15: Last Updated | F15: Owner | G15: Notes
A16: Metric (Auto-computed) | B16: Value | C16: Notes
A17: Non-Compliant Items (all domains) | B17: =COUNTIF('1. Key Generation'!H8:H90,"❌*")+COUNTIF('2. Key Storage'!H8:H90,"❌*")+COUNTIF('3. Key Rotation'!H8:H90,"❌*")+COUNTIF('4. Key Backup & Recovery'!H8:H90,"❌*")+COUNTIF('5. Certificate Management'!H8:H90,"❌*")+COUNTIF('6. Key Destruction'!H8:H90,"❌*")
A18: Partial Items (all domains) | B18: =COUNTIF('1. Key Generation'!H8:H90,"⚠️*")+COUNTIF('2. Key Storage'!H8:H90,"⚠️*")+COUNTIF('3. Key Rotation'!H8:H90,"⚠️*")+COUNTIF('4. Key Backup & Recovery'!H8:H90,"⚠️*")+COUNTIF('5. Certificate Management'!H8:H90,"⚠️*")+COUNTIF('6. Key Destruction'!H8:H90,"⚠️*")
A19: Compliant Items (all domains) | B19: =COUNTIF('1. Key Generation'!H8:H90,"✅*")+COUNTIF('2. Key Storage'!H8:H90,"✅*")+COUNTIF('3. Key Rotation'!H8:H90,"✅*")+COUNTIF('4. Key Backup & Recovery'!H8:H90,"✅*")+COUNTIF('5. Certificate Management'!H8:H90,"✅*")+COUNTIF('6. Key Destruction'!H8:H90,"✅*")
A20: Total Assessed Items (all domains) | B20: =COUNTA('1. Key Generation'!H8:H90)+COUNTA('2. Key Storage'!H8:H90)+COUNTA('3. Key Rotation'!H8:H90)+COUNTA('4. Key Backup & Recovery'!H8:H90)+COUNTA('5. Certificate Management'!H8:H90)+COUNTA('6. Key Destruction'!H8:H90)
A21: AES-256 Keys (count) | B21: =SUM(COUNTIF('1. Key Generation'!C8:C90,"AES-256"),COUNTIF('2. Key Storage'!C8:C90,"AES-256"),COUNTIF('3. Key Rotation'!C8:C90,"AES-256"),COUNTIF('4. Key Backup & Recovery'!C8:C90,"AES-256"),COUNTIF('5. Certificate Management'!C8:C90,"AES-256"),COUNTIF('6. Key Destruction'!C8:C90,"AES-256"))
A22: RSA-4096 Keys (count) | B22: =SUM(COUNTIF('1. Key Generation'!C8:C90,"RSA-4096"),COUNTIF('2. Key Storage'!C8:C90,"RSA-4096"),COUNTIF('3. Key Rotation'!C8:C90,"RSA-4096"),COUNTIF('4. Key Backup & Recovery'!C8:C90,"RSA-4096"),COUNTIF('5. Certificate Management'!C8:C90,"RSA-4096"),COUNTIF('6. Key Destruction'!C8:C90,"RSA-4096"))
A23: RSA-3072 Keys (count) | B23: =SUM(COUNTIF('1. Key Generation'!C8:C90,"RSA-3072"),COUNTIF('2. Key Storage'!C8:C90,"RSA-3072"),COUNTIF('3. Key Rotation'!C8:C90,"RSA-3072"),COUNTIF('4. Key Backup & Recovery'!C8:C90,"RSA-3072"),COUNTIF('5. Certificate Management'!C8:C90,"RSA-3072"),COUNTIF('6. Key Destruction'!C8:C90,"RSA-3072"))
A24: Non-Approved Algorithms (count) | B24: =SUM(COUNTIF('1. Key Generation'!C8:C90,"Other"),COUNTIF('2. Key Storage'!C8:C90,"Other"),COUNTIF('3. Key Rotation'!C8:C90,"Other"),COUNTIF('4. Key Backup & Recovery'!C8:C90,"Other"),COUNTIF('5. Certificate Management'!C8:C90,"Other"),COUNTIF('6. Key Destruction'!C8:C90,"Other"))
A25: Active Keys (Lifecycle: Active) | B25: =SUM(COUNTIF('1. Key Generation'!G8:G90,"Active"),COUNTIF('2. Key Storage'!G8:G90,"Active"),COUNTIF('3. Key Rotation'!G8:G90,"Active"),COUNTIF('4. Key Backup & Recovery'!G8:G90,"Active"),COUNTIF('5. Certificate Management'!G8:G90,"Active"),COUNTIF('6. Key Destruction'!G8:G90,"Active"))
A26: Archived Keys (Lifecycle: Archived) | B26: =SUM(COUNTIF('1. Key Generation'!G8:G90,"Archived"),COUNTIF('2. Key Storage'!G8:G90,"Archived"),COUNTIF('3. Key Rotation'!G8:G90,"Archived"),COUNTIF('4. Key Backup & Recovery'!G8:G90,"Archived"),COUNTIF('5. Certificate Management'!G8:G90,"Archived"),COUNTIF('6. Key Destruction'!G8:G90,"Archived"))
A27: Destroyed Keys (Lifecycle: Destroyed) | B27: =SUM(COUNTIF('1. Key Generation'!G8:G90,"Destroyed"),COUNTIF('2. Key Storage'!G8:G90,"Destroyed"),COUNTIF('3. Key Rotation'!G8:G90,"Destroyed"),COUNTIF('4. Key Backup & Recovery'!G8:G90,"Destroyed"),COUNTIF('5. Certificate Management'!G8:G90,"Destroyed"),COUNTIF('6. Key Destruction'!G8:G90,"Destroyed"))
A28: Keys Pending Rotation | B28: =SUM(COUNTIF('1. Key Generation'!G8:G90,"Pending Rotation"),COUNTIF('2. Key Storage'!G8:G90,"Pending Rotation"),COUNTIF('3. Key Rotation'!G8:G90,"Pending Rotation"),COUNTIF('4. Key Backup & Recovery'!G8:G90,"Pending Rotation"),COUNTIF('5. Certificate Management'!G8:G90,"Pending Rotation"),COUNTIF('6. Key Destruction'!G8:G90,"Pending Rotation"))
A31: Total Cryptographic Keys Managed (count) | C31: Count
A32: Keys in HSM / TPM / Cloud KMS | C32: ≥90%
A33: Approved Algorithm Compliance – AES-256 / RSA-3072+ | C33: 100%
A34: Automated Key Rotation Coverage | C34: ≥80%
A35: Certificates Expiring < 30 Days (count) | C35: 0
A36: Expired / Non-Compliant Certificates (count) | C36: 0
A37: FIPS 140-2 Level 2+ Validated Modules | C37: 100%
A38: Key Backup & Recovery Tested | C38: 100%
A39: Certificate Auto-Renewal Enabled | C39: ≥90%
A40: Evidence Documentation Rate | C40: 100%
A44: TABLE 3: DOMAIN COMPLIANCE SUMMARY
A45: Key Management Domain | B45: Non-Compliant | C45: Partial | D45: Compliant | E45: N/A | F45: Total Items | G45: Compliance %
A46: 1. Key Generation | B46: =COUNTIF('1. Key Generation'!H8:H90,"❌*") | C46: =COUNTIF('1. Key Generation'!H8:H90,"⚠️*") | D46: =COUNTIF('1. Key Generation'!H8:H90,"✅*") | E46: =COUNTIF('1. Key Generation'!H8:H90,"N/A") | F46: =COUNTA('1. Key Generation'!H8:H90) | G46: =IF((F46-E46)=0,0,D46/(F46-E46))
A47: 2. Key Storage | B47: =COUNTIF('2. Key Storage'!H8:H90,"❌*") | C47: =COUNTIF('2. Key Storage'!H8:H90,"⚠️*") | D47: =COUNTIF('2. Key Storage'!H8:H90,"✅*") | E47: =COUNTIF('2. Key Storage'!H8:H90,"N/A") | F47: =COUNTA('2. Key Storage'!H8:H90) | G47: =IF((F47-E47)=0,0,D47/(F47-E47))
...

Sheet Approval Sign-Off
A1: ASSESSMENT APPROVAL AND SIGN-OFF
A3: ASSESSMENT SUMMARY
A4: Document: | B4: ISMS-IMP-A.8.24.4 - Key Management Assessment
A5: Assessment Period:
A6: Overall Compliance: | B6: ='Summary Dashboard'!G11
A7: Assessment Status:
A10: COMPLETED BY (ASSESSOR)
A11: Name:
A12: Title:
A13: Date:
A14: Signature:
A15: Comments:
A17: REVIEWED BY (INFORMATION SECURITY OFFICER)
A18: Name:
A19: Title:
A20: Date:
A21: Signature:
... A37: Special Considerations:
