Workbook

Sheet Instructions & Legend
A1: ISMS-IMP-A.8.24.2 - Data Storage Cryptography Assessment ISO/IEC 27001:2022 - Control A.8.24: Use of Cryptography
A3: Document Information
A4: Document ID | B4: ISMS-IMP-A.8.24.2
A5: Workbook Title | B5: Data Storage Cryptography Assessment
A6: Control Reference | B6: ISO/IEC 27001:2022 - Control A.8.24: Use of Cryptography
A7: Version | B7: 1.0
A8: Assessment Date
A9: Completed By
A10: Organisation
A12: Instructions
A13: 1. Complete each worksheet tab (1–7) for applicable storage systems.
A14: 2. Use dropdown menus for standardised entries (Status, Encryption Type, Algorithm, etc.).
A15: 3. Fill in yellow-highlighted cells with your information.
A16: 4. If Status = Partial or Non-Compliant, complete the Exception/Deviation section.
A17: 5. Document key management details for each encrypted storage system.
A18: 6. Provide evidence location/path for each implementation entry.
A19: 7. Summary Dashboard auto-calculates compliance statistics per storage type.
A20: 8. Maintain the Evidence Register for audit traceability.
... A23: Status Legend
A24: Symbol | B24: Status | C24: Description
A25: ✓ | B25: Compliant / Complete | C25: Requirement fully met
A26: ⚠ | B26: Partial / In Progress | C26: Partially met or in progress
A27: ✗ | B27: Non-Compliant / Not Started | C27: Requirement not met
A28: — | B28: Not Applicable | C28: Not applicable to this assessment

Sheet 1. Mobile Devices
A1: 1. MOBILE DEVICES - DATA AT REST ENCRYPTION Policy Requirement: Mobile devices storing organisational data MUST use full device encryption (Policy Section 2.3.1)
A2: ISO/IEC 27001:2022 | Control A.8.24: Use of Cryptography
A3: Does your organisation issue or allow mobile devices (smartphones, tablets) that store organisational data?
A4: Response:
A6: Storage System/Device | B6: Data Classification | C6: Encryption Status | D6: Encryption Type | E6: Algorithm & Key Size | F6: Key Management Method | G6: Key Rotation Enabled | H6: Status | I6: Evidence Location | J6: Gap Description | K6: Remediation Needed | L6: Exception ID | M6: Risk ID | N6: Compensating Controls | O6: Responsible Person | P6: Target Date | Q6: Budget Required
A7: Example: Production SQL Server 2019 - FINDB01 | B7: Restricted | C7: Encrypted | D7: Database TDE | E7: AES-256 | F7: HSM | G7: ✅ Yes | H7: ✅ Compliant | I7: /evidence/databases/FINDB01-TDE-config.pdf | J7: None | K7: ❌ No | L7: N/A | M7: N/A | N7: N/A | O7: N/A | P7: N/A | Q7: ❌ No
A22: 1. MOBILE DEVICES ENCRYPTION CHECKLIST
A23: ☐ | B23: Requirement | C23: Status
A24: ☐ | B24: iOS devices: FileVault/built-in encryption enabled
A25: ☐ | B25: Android devices: Full device encryption enabled
A26: ☐ | B26: MDM policy enforces encryption
A27: ☐ | B27: Encryption status verified via MDM reporting
A28: ☐ | B28: PIN/password/biometric required for device unlock
A29: ☐ | B29: Remote wipe capability configured
A30: ☐ | B30: Encryption cannot be disabled by user
A31: ☐ | B31: BYOD devices meet encryption requirements
A32: ☐ | B32: Lost/stolen device procedure includes encryption verification
A33: ☐ | B33: Regular compliance audits performed (quarterly minimum)
A34: Checklist Score: | B34: =IFERROR(ROUND(COUNTIF(C24:C33,"✅ Yes")/COUNTA(C24:C33)*100,0)&"%","0%")
A36: EXCEPTION / DEVIATION DOCUMENTATION (Complete if Status = Partial or Non-Compliant)
A37: Formal exception request submitted:
A38: Exception ID:
A39: Risk acceptance documented:
A40: Risk ID:
A41: Compensating Controls (summary):
A42: ☐ Physical security controls (locked facility, restricted access)
A43: ☐ Network segmentation / air-gapped systems
A44: ☐ Enhanced monitoring / DLP controls
A45: ☐ Restricted user access / privileged access management
A46: ☐ Data minimisation / reduced storage scope
A47: ☐ Other (describe):
A49: ADDITIONAL NOTES / COMMENTS

Sheet 2. Laptops & Workstations
A1: 2. LAPTOPS & WORKSTATIONS - DATA AT REST ENCRYPTION Policy Requirement: Laptops and workstations storing sensitive data MUST use full disk encryption (Policy Section 2.3.2)
A2: ISO/IEC 27001:2022 | Control A.8.24: Use of Cryptography
A3: Does your organisation have laptops or workstations that store organisational data locally?
A4: Response:
A6: Storage System/Device | B6: Data Classification | C6: Encryption Status | D6: Encryption Type | E6: Algorithm & Key Size | F6: Key Management Method | G6: Key Rotation Enabled | H6: Status | I6: Evidence Location | J6: Gap Description | K6: Remediation Needed | L6: Exception ID | M6: Risk ID | N6: Compensating Controls | O6: Responsible Person | P6: Target Date | Q6: Budget Required
A7: Example: Production SQL Server 2019 - FINDB01 | B7: Restricted | C7: Encrypted | D7: Database TDE | E7: AES-256 | F7: HSM | G7: ✅ Yes | H7: ✅ Compliant | I7: /evidence/databases/FINDB01-TDE-config.pdf | J7: None | K7: ❌ No | L7: N/A | M7: N/A | N7: N/A | O7: N/A | P7: N/A | Q7: ❌ No
A22: 2. LAPTOPS & WORKSTATIONS ENCRYPTION CHECKLIST
A23: ☐ | B23: Requirement | C23: Status
A24: ☐ | B24: Windows: BitLocker enabled and configured
A25: ☐ | B25: macOS: FileVault 2 enabled
A26: ☐ | B26: Linux: LUKS/dm-crypt configured
A27: ☐ | B27: TPM 2.0 utilised for key storage (where available)
A28: ☐ | B28: Pre-boot authentication required
A29: ☐ | B29: Recovery keys securely escrowed
A30: ☐ | B30: Encryption status monitored centrally
A31: ☐ | B31: Users cannot disable encryption
A32: ☐ | B32: Encryption applied before device deployment
A33: ☐ | B33: Hibernate/sleep mode protected
A34: ☐ | B34: External storage auto-encryption policy enforced
A35: Checklist Score: | B35: =IFERROR(ROUND(COUNTIF(C24:C34,"✅ Yes")/COUNTA(C24:C34)*100,0)&"%","0%")
A37: EXCEPTION / DEVIATION DOCUMENTATION (Complete if Status = Partial or Non-Compliant)
A38: Formal exception request submitted:
A39: Exception ID:
A40: Risk acceptance documented:
A41: Risk ID:
A42: Compensating Controls (summary):
A43: ☐ Physical security controls (locked facility, restricted access)
A44: ☐ Network segmentation / air-gapped systems
A45: ☐ Enhanced monitoring / DLP controls
A46: ☐ Restricted user access / privileged access management
A47: ☐ Data minimisation / reduced storage scope
A48: ☐ Other (describe):
A50: ADDITIONAL NOTES / COMMENTS

Sheet 3. Servers
A1: 3. SERVERS - DATA AT REST ENCRYPTION Policy Requirement: Servers storing sensitive data MUST implement appropriate encryption at rest (Policy Section 2.3.3)
A2: ISO/IEC 27001:2022 | Control A.8.24: Use of Cryptography
A3: Does your organisation operate servers (physical or virtual) that store sensitive organisational data?
A4: Response:
A6: Storage System/Device | B6: Data Classification | C6: Encryption Status | D6: Encryption Type | E6: Algorithm & Key Size | F6: Key Management Method | G6: Key Rotation Enabled | H6: Status | I6: Evidence Location | J6: Gap Description | K6: Remediation Needed | L6: Exception ID | M6: Risk ID | N6: Compensating Controls | O6: Responsible Person | P6: Target Date | Q6: Budget Required
A7: Example: Production SQL Server 2019 - FINDB01 | B7: Restricted | C7: Encrypted | D7: Database TDE | E7: AES-256 | F7: HSM | G7: ✅ Yes | H7: ✅ Compliant | I7: /evidence/databases/FINDB01-TDE-config.pdf | J7: None | K7: ❌ No | L7: N/A | M7: N/A | N7: N/A | O7: N/A | P7: N/A | Q7: ❌ No
A22: 3. SERVERS ENCRYPTION CHECKLIST
A23: ☐ | B23: Requirement | C23: Status
A24: ☐ | B24: OS-level encryption enabled (LUKS, BitLocker, etc.)
A25: ☐ | B25: Storage volume/LUN encryption configured
A26: ☐ | B26: Virtual machine disk encryption enabled
A27: ☐ | B27: Key management solution integrated
A28: ☐ | B28: Encryption keys stored separately from encrypted data
A29: ☐ | B29: SAN/NAS encryption enabled (if applicable)
A30: ☐ | B30: Self-encrypting drives (SED) utilised where appropriate
A31: ☐ | B31: Boot volumes encrypted
A32: ☐ | B32: Temporary/swap space encrypted
A33: ☐ | B33: Encryption status monitoring automated
A34: ☐ | B34: Key rotation procedures documented and implemented
A35: ☐ | B35: HSM integration for key protection (production systems)
A36: Checklist Score: | B36: =IFERROR(ROUND(COUNTIF(C24:C35,"✅ Yes")/COUNTA(C24:C35)*100,0)&"%","0%")
A38: EXCEPTION / DEVIATION DOCUMENTATION (Complete if Status = Partial or Non-Compliant)
A39: Formal exception request submitted:
A40: Exception ID:
A41: Risk acceptance documented:
A42: Risk ID:
A43: Compensating Controls (summary):
A44: ☐ Physical security controls (locked facility, restricted access)
A45: ☐ Network segmentation / air-gapped systems
A46: ☐ Enhanced monitoring / DLP controls
A47: ☐ Restricted user access / privileged access management
A48: ☐ Data minimisation / reduced storage scope
A49: ☐ Other (describe):
A51: ADDITIONAL NOTES / COMMENTS

Sheet 4. Databases
A1: 4. DATABASES - DATA AT REST ENCRYPTION Policy Requirement: Databases containing sensitive data MUST implement Transparent Data Encryption or equivalent (Policy Section 2.3.4)
A2: ISO/IEC 27001:2022 | Control A.8.24: Use of Cryptography
A3: Does your organisation operate databases that store sensitive or regulated data?
A4: Response:
A6: Storage System/Device | B6: Data Classification | C6: Encryption Status | D6: Encryption Type | E6: Algorithm & Key Size | F6: Key Management Method | G6: Key Rotation Enabled | H6: Status | I6: Evidence Location | J6: Gap Description | K6: Remediation Needed | L6: Exception ID | M6: Risk ID | N6: Compensating Controls | O6: Responsible Person | P6: Target Date | Q6: Budget Required
A7: Example: Production SQL Server 2019 - FINDB01 | B7: Restricted | C7: Encrypted | D7: Database TDE | E7: AES-256 | F7: HSM | G7: ✅ Yes | H7: ✅ Compliant | I7: /evidence/databases/FINDB01-TDE-config.pdf | J7: None | K7: ❌ No | L7: N/A | M7: N/A | N7: N/A | O7: N/A | P7: N/A | Q7: ❌ No
A22: 4. DATABASES ENCRYPTION CHECKLIST
A23: ☐ | B23: Requirement | C23: Status
A24: ☐ | B24: TDE (Transparent Data Encryption) enabled
A25: ☐ | B25: Encryption at column level for sensitive fields (if applicable)
A26: ☐ | B26: Encryption at tablespace level configured
A27: ☐ | B27: Database backup files encrypted
A28: ☐ | B28: Transaction logs encrypted
A29: ☐ | B29: Encryption keys managed via KMS/HSM
A30: ☐ | B30: Master encryption key rotated per policy
A31: ☐ | B31: Encryption does not significantly impact performance
A32: ☐ | B32: Application-layer encryption for PII/PHI (if TDE unavailable)
A33: ☐ | B33: Encryption status verified in database audit logs
A34: ☐ | B34: Development/test databases use encryption for prod data
A35: ☐ | B35: Database snapshots/clones encrypted
A36: Checklist Score: | B36: =IFERROR(ROUND(COUNTIF(C24:C35,"✅ Yes")/COUNTA(C24:C35)*100,0)&"%","0%")
A38: Technology-Specific Notes / Examples
A39: SQL Server: | B39: TDE, Always Encrypted
A40: Oracle: | B40: TDE, DBMS_CRYPTO
A41: PostgreSQL: | B41: pgcrypto, LUKS volume encryption
A42: MySQL: | B42: InnoDB encryption, file-level encryption
A43: MongoDB: | B43: Encrypted Storage Engine
A44: Cassandra: | B44: Transparent data encryption
A46: EXCEPTION / DEVIATION DOCUMENTATION (Complete if Status = Partial or Non-Compliant)
A47: Formal exception request submitted:
A48: Exception ID:
A49: Risk acceptance documented:
A50: Risk ID:
A51: Compensating Controls (summary):
A52: ☐ Physical security controls (locked facility, restricted access)
A53: ☐ Network segmentation / air-gapped systems
A54: ☐ Enhanced monitoring / DLP controls
A55: ☐ Restricted user access / privileged access management
A56: ☐ Data minimisation / reduced storage scope
A57: ☐ Other (describe):
...

Sheet 5. Cloud Storage
A1: 5. CLOUD STORAGE - DATA AT REST ENCRYPTION Policy Requirement: Cloud storage MUST use provider encryption with customer-managed keys where available (Policy Section 2.3.5)
A2: ISO/IEC 27001:2022 | Control A.8.24: Use of Cryptography
A3: Does your organisation store data in cloud storage services (object storage, block storage, file storage)?
A4: Response:
A6: Storage System/Device | B6: Data Classification | C6: Encryption Status | D6: Encryption Type | E6: Algorithm & Key Size | F6: Key Management Method | G6: Key Rotation Enabled | H6: Status | I6: Evidence Location | J6: Gap Description | K6: Remediation Needed | L6: Exception ID | M6: Risk ID | N6: Compensating Controls | O6: Responsible Person | P6: Target Date | Q6: Budget Required
A7: Example: Production SQL Server 2019 - FINDB01 | B7: Restricted | C7: Encrypted | D7: Database TDE | E7: AES-256 | F7: HSM | G7: ✅ Yes | H7: ✅ Compliant | I7: /evidence/databases/FINDB01-TDE-config.pdf | J7: None | K7: ❌ No | L7: N/A | M7: N/A | N7: N/A | O7: N/A | P7: N/A | Q7: ❌ No
A22: 5. CLOUD STORAGE ENCRYPTION CHECKLIST
A23: ☐ | B23: Requirement | C23: Status
A24: ☐ | B24: Server-side encryption (SSE) enabled by default
A25: ☐ | B25: Customer-managed keys (CMK) configured
A26: ☐ | B26: Client-side encryption implemented for highly sensitive data
A27: ☐ | B27: Encryption key location documented (region/jurisdiction)
A28: ☐ | B28: Cloud KMS integrated (AWS KMS, Azure Key Vault, GCP KMS)
A29: ☐ | B29: Automatic key rotation enabled
A30: ☐ | B30: Encryption validated via cloud audit logs
A31: ☐ | B31: Data encrypted before upload (for maximum sensitivity)
A32: ☐ | B32: Bucket/container policies enforce encryption
A33: ☐ | B33: Cross-region replication maintains encryption
A34: ☐ | B34: Cloud backup snapshots encrypted
A35: ☐ | B35: Compliance certifications verified (SOC 2, ISO 27001)
A36: Checklist Score: | B36: =IFERROR(ROUND(COUNTIF(C24:C35,"✅ Yes")/COUNTA(C24:C35)*100,0)&"%","0%")
A38: Technology-Specific Notes / Examples
A39: AWS: | B39: S3 SSE-KMS, EBS encryption, RDS encryption
A40: Azure: | B40: Storage Service Encryption, Azure Disk Encryption
A41: GCP: | B41: Default encryption at rest, CMEK
A42: Others: | B42: Document specific provider controls
A44: EXCEPTION / DEVIATION DOCUMENTATION (Complete if Status = Partial or Non-Compliant)
A45: Formal exception request submitted:
A46: Exception ID:
A47: Risk acceptance documented:
A48: Risk ID:
A49: Compensating Controls (summary):
A50: ☐ Physical security controls (locked facility, restricted access)
A51: ☐ Network segmentation / air-gapped systems
A52: ☐ Enhanced monitoring / DLP controls
A53: ☐ Restricted user access / privileged access management
A54: ☐ Data minimisation / reduced storage scope
A55: ☐ Other (describe):
A57: ADDITIONAL NOTES / COMMENTS

Sheet 6. Backups
A1: 6. BACKUPS - DATA AT REST ENCRYPTION Policy Requirement: Backup media and backup data MUST be encrypted with strong cryptography (Policy Section 2.3.6)
A2: ISO/IEC 27001:2022 | Control A.8.24: Use of Cryptography
A3: Does your organisation perform backups of systems, databases, or files?
A4: Response:
A6: Storage System/Device | B6: Data Classification | C6: Encryption Status | D6: Encryption Type | E6: Algorithm & Key Size | F6: Key Management Method | G6: Key Rotation Enabled | H6: Status | I6: Evidence Location | J6: Gap Description | K6: Remediation Needed | L6: Exception ID | M6: Risk ID | N6: Compensating Controls | O6: Responsible Person | P6: Target Date | Q6: Budget Required
A7: Example: Production SQL Server 2019 - FINDB01 | B7: Restricted | C7: Encrypted | D7: Database TDE | E7: AES-256 | F7: HSM | G7: ✅ Yes | H7: ✅ Compliant | I7: /evidence/databases/FINDB01-TDE-config.pdf | J7: None | K7: ❌ No | L7: N/A | M7: N/A | N7: N/A | O7: N/A | P7: N/A | Q7: ❌ No
A22: 6. BACKUPS ENCRYPTION CHECKLIST
A23: ☐ | B23: Requirement | C23: Status
A24: ☐ | B24: Full backup encryption enabled
A25: ☐ | B25: Incremental/differential backups encrypted
A26: ☐ | B26: Backup encryption configured before first backup
A27: ☐ | B27: Backup encryption keys managed separately from backup data
A28: ☐ | B28: Offsite/cloud backup storage encrypted in transit AND at rest
A29: ☐ | B29: Tape backups encrypted (if applicable)
A30: ☐ | B30: Virtual machine backups encrypted
A31: ☐ | B31: Database backup encryption independent of TDE
A32: ☐ | B32: Backup restoration tested with encryption
A33: ☐ | B33: Backup encryption key recovery procedure documented
A34: ☐ | B34: Long-term archive backups maintain encryption
A35: ☐ | B35: Backup logs do not expose sensitive data in plaintext
A36: Checklist Score: | B36: =IFERROR(ROUND(COUNTIF(C24:C35,"✅ Yes")/COUNTA(C24:C35)*100,0)&"%","0%")
A38: Technology-Specific Notes / Examples
A39: Agent-based: | B39: Veeam, Commvault, Veritas
A40: Cloud-native: | B40: AWS Backup, Azure Backup
A41: Database-native: | B41: RMAN (Oracle), SQL Server Backup
A42: File-level: | B42: rsync + GPG, Duplicati
A43: Container: | B43: Velero with encryption
A45: EXCEPTION / DEVIATION DOCUMENTATION (Complete if Status = Partial or Non-Compliant)
A46: Formal exception request submitted:
A47: Exception ID:
A48: Risk acceptance documented:
A49: Risk ID:
A50: Compensating Controls (summary):
A51: ☐ Physical security controls (locked facility, restricted access)
A52: ☐ Network segmentation / air-gapped systems
A53: ☐ Enhanced monitoring / DLP controls
A54: ☐ Restricted user access / privileged access management
A55: ☐ Data minimisation / reduced storage scope
A56: ☐ Other (describe):
A58: ADDITIONAL NOTES / COMMENTS

Sheet 7. Removable Media
A1: 7. REMOVABLE MEDIA - DATA AT REST ENCRYPTION Policy Requirement: Removable media storing organisational data MUST be encrypted (Policy Section 2.3.7)
A2: ISO/IEC 27001:2022 | Control A.8.24: Use of Cryptography
A3: Does your organisation use removable media (USB drives, external disks, optical media) to store or transport data?
A4: Response:
A6: Storage System/Device | B6: Data Classification | C6: Encryption Status | D6: Encryption Type | E6: Algorithm & Key Size | F6: Key Management Method | G6: Key Rotation Enabled | H6: Status | I6: Evidence Location | J6: Gap Description | K6: Remediation Needed | L6: Exception ID | M6: Risk ID | N6: Compensating Controls | O6: Responsible Person | P6: Target Date | Q6: Budget Required
A7: Example: Production SQL Server 2019 - FINDB01 | B7: Restricted | C7: Encrypted | D7: Database TDE | E7: AES-256 | F7: HSM | G7: ✅ Yes | H7: ✅ Compliant | I7: /evidence/databases/FINDB01-TDE-config.pdf | J7: None | K7: ❌ No | L7: N/A | M7: N/A | N7: N/A | O7: N/A | P7: N/A | Q7: ❌ No
A22: 7. REMOVABLE MEDIA ENCRYPTION CHECKLIST
A23: ☐ | B23: Requirement | C23: Status
A24: ☐ | B24: USB drive encryption mandatory via policy
A25: ☐ | B25: External hard drive encryption enforced
A26: ☐ | B26: BitLocker To Go / FileVault / LUKS configured
A27: ☐ | B27: Hardware-encrypted USB drives procured
A28: ☐ | B28: Unencrypted removable media blocked by endpoint policy
A29: ☐ | B29: Media encryption verified before data transfer
A30: ☐ | B30: Encrypted optical media (DVD/CD) procedures documented
A31: ☐ | B31: Lost removable media incident response includes encryption check
A32: ☐ | B32: Media disposal/destruction procedures enforce encryption verification
A33: ☐ | B33: Approved removable media inventory maintained
A34: ☐ | B34: Encryption exceptions require formal approval
A35: ☐ | B35: Regular compliance audits of removable media usage
A36: Checklist Score: | B36: =IFERROR(ROUND(COUNTIF(C24:C35,"✅ Yes")/COUNTA(C24:C35)*100,0)&"%","0%")
A38: Technology-Specific Notes / Examples
A39: Windows: | B39: BitLocker To Go
A40: macOS: | B40: FileVault encrypted volumes
A41: Linux: | B41: LUKS containers
A42: Cross-platform: | B42: VeraCrypt
A43: Hardware: | B43: IronKey, Kingston Encrypted USB
A44: Enterprise: | B44: Symantec Endpoint Encryption
A46: EXCEPTION / DEVIATION DOCUMENTATION (Complete if Status = Partial or Non-Compliant)
A47: Formal exception request submitted:
A48: Exception ID:
A49: Risk acceptance documented:
A50: Risk ID:
A51: Compensating Controls (summary):
A52: ☐ Physical security controls (locked facility, restricted access)
A53: ☐ Network segmentation / air-gapped systems
A54: ☐ Enhanced monitoring / DLP controls
A55: ☐ Restricted user access / privileged access management
A56: ☐ Data minimisation / reduced storage scope
A57: ☐ Other (describe):
...

Sheet Evidence Register
A1: EVIDENCE REGISTER
A2: List all evidence files/documents referenced in this assessment (audit traceability).
A4: Evidence ID | B4: Assessment Area | C4: Evidence Type | D4: Description | E4: Location/Path | F4: Date Collected | G4: Collected By | H4: Verification Status
A5: EV-001 | B5: 2. Laptops & Workstations | C5: Configuration file | D5: TLS/encryption configuration export for audit evidence | E5: /evidence/a824/config-export-2025.txt | F5: 01.01.2025 | G5: Security Team | H5: ✅ Verified

Sheet Summary Dashboard
A1: DATA STORAGE CRYPTOGRAPHY ASSESSMENT — SUMMARY DASHBOARD
A2: ISO/IEC 27001:2022 | Control A.8.24 | Data Storage Cryptography
A4: TABLE 1: ASSESSMENT AREA COMPLIANCE OVERVIEW
A5: Assessment Area | B5: Total Items | C5: Compliant | D5: Partial | E5: Non-Compliant | F5: N/A | G5: Compliance %
A6: 1. Mobile Devices | B6: =COUNTA('1. Mobile Devices'!H8:H60) | C6: =COUNTIF('1. Mobile Devices'!H8:H60,"*Compliant") | D6: =COUNTIF('1. Mobile Devices'!H8:H60,"*Partial") | E6: =COUNTIF('1. Mobile Devices'!H8:H60,"*Non-Compliant") | F6: =COUNTIF('1. Mobile Devices'!H8:H60,"N/A") | G6: =IF((B6-F6)=0,"0%",ROUND(C6/(B6-F6)*100,1)&"%")
A7: 2. Laptops & Workstations | B7: =COUNTA('2. Laptops & Workstations'!H8:H60) | C7: =COUNTIF('2. Laptops & Workstations'!H8:H60,"*Compliant") | D7: =COUNTIF('2. Laptops & Workstations'!H8:H60,"*Partial") | E7: =COUNTIF('2. Laptops & Workstations'!H8:H60,"*Non-Compliant") | F7: =COUNTIF('2. Laptops & Workstations'!H8:H60,"N/A") | G7: =IF((B7-F7)=0,"0%",ROUND(C7/(B7-F7)*100,1)&"%")
A8: 3. Servers | B8: =COUNTA('3. Servers'!H8:H60) | C8: =COUNTIF('3. Servers'!H8:H60,"*Compliant") | D8: =COUNTIF('3. Servers'!H8:H60,"*Partial") | E8: =COUNTIF('3. Servers'!H8:H60,"*Non-Compliant") | F8: =COUNTIF('3. Servers'!H8:H60,"N/A") | G8: =IF((B8-F8)=0,"0%",ROUND(C8/(B8-F8)*100,1)&"%")
A9: 4. Databases | B9: =COUNTA('4. Databases'!H8:H60) | C9: =COUNTIF('4. Databases'!H8:H60,"*Compliant") | D9: =COUNTIF('4. Databases'!H8:H60,"*Partial") | E9: =COUNTIF('4. Databases'!H8:H60,"*Non-Compliant") | F9: =COUNTIF('4. Databases'!H8:H60,"N/A") | G9: =IF((B9-F9)=0,"0%",ROUND(C9/(B9-F9)*100,1)&"%")
A10: 5. Cloud Storage | B10: =COUNTA('5. Cloud Storage'!H8:H60) | C10: =COUNTIF('5. Cloud Storage'!H8:H60,"*Compliant") | D10: =COUNTIF('5. Cloud Storage'!H8:H60,"*Partial") | E10: =COUNTIF('5. Cloud Storage'!H8:H60,"*Non-Compliant") | F10: =COUNTIF('5. Cloud Storage'!H8:H60,"N/A") | G10: =IF((B10-F10)=0,"0%",ROUND(C10/(B10-F10)*100,1)&"%")
A11: 6. Backups | B11: =COUNTA('6. Backups'!H8:H60) | C11: =COUNTIF('6. Backups'!H8:H60,"*Compliant") | D11: =COUNTIF('6. Backups'!H8:H60,"*Partial") | E11: =COUNTIF('6. Backups'!H8:H60,"*Non-Compliant") | F11: =COUNTIF('6. Backups'!H8:H60,"N/A") | G11: =IF((B11-F11)=0,"0%",ROUND(C11/(B11-F11)*100,1)&"%")
A12: 7. Removable Media | B12: =COUNTA('7. Removable Media'!H8:H60) | C12: =COUNTIF('7. Removable Media'!H8:H60,"*Compliant") | D12: =COUNTIF('7. Removable Media'!H8:H60,"*Partial") | E12: =COUNTIF('7. Removable Media'!H8:H60,"*Non-Compliant") | F12: =COUNTIF('7. Removable Media'!H8:H60,"N/A") | G12: =IF((B12-F12)=0,"0%",ROUND(C12/(B12-F12)*100,1)&"%")
A13: TOTAL | B13: =SUM(B6:B12) | C13: =SUM(C6:C12) | D13: =SUM(D6:D12) | E13: =SUM(E6:E12) | F13: =SUM(F6:F12) | G13: =IF((B13-F13)=0,"0%",ROUND(C13/(B13-F13)*100,1)&"%")
A15: TABLE 2: KEY METRICS
A16: KPI | B16: Current Value | C16: Target | D16: Status | E16: Last Updated | F16: Owner | G16: Notes
A17: Metric (Auto-computed) | B17: Value | C17: Notes
A18: Not Encrypted Count (all domains) | B18: =SUM(COUNTIF('1. Mobile Devices'!C8:C60,"Not Encrypted"),COUNTIF('2. Laptops & Workstations'!C8:C60,"Not Encrypted"),COUNTIF('3. Servers'!C8:C60,"Not Encrypted"),COUNTIF('4. Databases'!C8:C60,"Not Encrypted"),COUNTIF('5. Cloud Storage'!C8:C60,"Not Encrypted"),COUNTIF('6. Backups'!C8:C60,"Not Encrypted"),COUNTIF('7. Removable Media'!C8:C60,"Not Encrypted"))
A19: Partially Encrypted Count (all domains) | B19: =SUM(COUNTIF('1. Mobile Devices'!C8:C60,"Partially Encrypted"),COUNTIF('2. Laptops & Workstations'!C8:C60,"Partially Encrypted"),COUNTIF('3. Servers'!C8:C60,"Partially Encrypted"),COUNTIF('4. Databases'!C8:C60,"Partially Encrypted"),COUNTIF('5. Cloud Storage'!C8:C60,"Partially Encrypted"),COUNTIF('6. Backups'!C8:C60,"Partially Encrypted"),COUNTIF('7. Removable Media'!C8:C60,"Partially Encrypted"))
A20: Key Rotation Disabled (all domains) | B20: =SUM(COUNTIF('1. Mobile Devices'!G8:G60,"❌ No"),COUNTIF('2. Laptops & Workstations'!G8:G60,"❌ No"),COUNTIF('3. Servers'!G8:G60,"❌ No"),COUNTIF('4. Databases'!G8:G60,"❌ No"),COUNTIF('5. Cloud Storage'!G8:G60,"❌ No"),COUNTIF('6. Backups'!G8:G60,"❌ No"),COUNTIF('7. Removable Media'!G8:G60,"❌ No"))
A21: HSM in Use (all domains) | B21: =SUM(COUNTIF('1. Mobile Devices'!F8:F60,"HSM"),COUNTIF('2. Laptops & Workstations'!F8:F60,"HSM"),COUNTIF('3. Servers'!F8:F60,"HSM"),COUNTIF('4. Databases'!F8:F60,"HSM"),COUNTIF('5. Cloud Storage'!F8:F60,"HSM"),COUNTIF('6. Backups'!F8:F60,"HSM"),COUNTIF('7. Removable Media'!F8:F60,"HSM"))
A22: Cloud KMS in Use (all domains) | B22: =SUM(COUNTIF('1. Mobile Devices'!F8:F60,"Cloud KMS"),COUNTIF('2. Laptops & Workstations'!F8:F60,"Cloud KMS"),COUNTIF('3. Servers'!F8:F60,"Cloud KMS"),COUNTIF('4. Databases'!F8:F60,"Cloud KMS"),COUNTIF('5. Cloud Storage'!F8:F60,"Cloud KMS"),COUNTIF('6. Backups'!F8:F60,"Cloud KMS"),COUNTIF('7. Removable Media'!F8:F60,"Cloud KMS"))
A23: Non-Compliant Items (all domains) | B23: =COUNTIF('1. Mobile Devices'!H8:H60,"*Non-Compliant")+COUNTIF('2. Laptops & Workstations'!H8:H60,"*Non-Compliant")+COUNTIF('3. Servers'!H8:H60,"*Non-Compliant")+COUNTIF('4. Databases'!H8:H60,"*Non-Compliant")+COUNTIF('5. Cloud Storage'!H8:H60,"*Non-Compliant")+COUNTIF('6. Backups'!H8:H60,"*Non-Compliant")+COUNTIF('7. Removable Media'!H8:H60,"*Non-Compliant")
A24: Total Assessed Items (all domains) | B24: =COUNTA('1. Mobile Devices'!H8:H60)+COUNTA('2. Laptops & Workstations'!H8:H60)+COUNTA('3. Servers'!H8:H60)+COUNTA('4. Databases'!H8:H60)+COUNTA('5. Cloud Storage'!H8:H60)+COUNTA('6. Backups'!H8:H60)+COUNTA('7. Removable Media'!H8:H60)
A27: Full-Disk Encryption – Laptops / Workstations | C27: 100%
A28: Mobile Device Encryption | C28: 100%
A29: Server Data-at-Rest Encryption | C29: ≥95%
A30: Database Encryption – TDE / Column-Level | C30: 100%
A31: Cloud Storage Encryption | C31: 100%
A32: Backup Encryption | C32: 100%
A33: Removable Media Encryption | C33: 100%
A34: Encryption Algorithm Compliance – AES-256+ | C34: 100%
A35: Key Rotation Compliance | C35: ≥90%
A36: Evidence Documentation Rate | C36: 100%
A40: TABLE 3: DOMAIN COMPLIANCE SUMMARY
A41: Storage Domain | B41: Not Encrypted | C41: Key Rotation Off | D41: HSM in Use | E41: Non-Compliant | F41: Total Items | G41: Compliance %
A42: 1. Mobile Devices | B42: =COUNTIF('1. Mobile Devices'!C8:C60,"Not Encrypted") | C42: =COUNTIF('1. Mobile Devices'!G8:G60,"❌ No") | D42: =COUNTIF('1. Mobile Devices'!F8:F60,"HSM") | E42: =COUNTIF('1. Mobile Devices'!H8:H60,"*Non-Compliant") | F42: =COUNTA('1. Mobile Devices'!H8:H60) | G42: =IF(F42=0,0,(F42-E42)/F42)
A43: 2. Laptops & Workstations | B43: =COUNTIF('2. Laptops & Workstations'!C8:C60,"Not Encrypted") | C43: =COUNTIF('2. Laptops & Workstations'!G8:G60,"❌ No") | D43: =COUNTIF('2. Laptops & Workstations'!F8:F60,"HSM") | E43: =COUNTIF('2. Laptops & Workstations'!H8:H60,"*Non-Compliant") | F43: =COUNTA('2. Laptops & Workstations'!H8:H60) | G43: =IF(F43=0,0,(F43-E43)/F43)
A44: 3. Servers | B44: =COUNTIF('3. Servers'!C8:C60,"Not Encrypted") | C44: =COUNTIF('3. Servers'!G8:G60,"❌ No") | D44: =COUNTIF('3. Servers'!F8:F60,"HSM") | E44: =COUNTIF('3. Servers'!H8:H60,"*Non-Compliant") | F44: =COUNTA('3. Servers'!H8:H60) | G44: =IF(F44=0,0,(F44-E44)/F44)
A45: 4. Databases | B45: =COUNTIF('4. Databases'!C8:C60,"Not Encrypted") | C45: =COUNTIF('4. Databases'!G8:G60,"❌ No") | D45: =COUNTIF('4. Databases'!F8:F60,"HSM") | E45: =COUNTIF('4. Databases'!H8:H60,"*Non-Compliant") | F45: =COUNTA('4. Databases'!H8:H60) | G45: =IF(F45=0,0,(F45-E45)/F45)
A46: 5. Cloud Storage | B46: =COUNTIF('5. Cloud Storage'!C8:C60,"Not Encrypted") | C46: =COUNTIF('5. Cloud Storage'!G8:G60,"❌ No") | D46: =COUNTIF('5. Cloud Storage'!F8:F60,"HSM") | E46: =COUNTIF('5. Cloud Storage'!H8:H60,"*Non-Compliant") | F46: =COUNTA('5. Cloud Storage'!H8:H60) | G46: =IF(F46=0,0,(F46-E46)/F46)
A47: 6. Backups | B47: =COUNTIF('6. Backups'!C8:C60,"Not Encrypted") | C47: =COUNTIF('6. Backups'!G8:G60,"❌ No") | D47: =COUNTIF('6. Backups'!F8:F60,"HSM") | E47: =COUNTIF('6. Backups'!H8:H60,"*Non-Compliant") | F47: =COUNTA('6. Backups'!H8:H60) | G47: =IF(F47=0,0,(F47-E47)/F47)
...

Sheet Approval Sign-Off
A1: ASSESSMENT APPROVAL AND SIGN-OFF
A3: ASSESSMENT SUMMARY
A4: Document: | B4: ISMS-IMP-A.8.24.2 - Data Storage Assessment
A5: Assessment Period:
A6: Overall Compliance: | B6: ='Summary Dashboard'!G13
A7: Assessment Status:
A10: COMPLETED BY (ASSESSOR)
A11: Name:
A12: Title:
A13: Date:
A14: Signature:
A15: Comments:
A17: REVIEWED BY (INFORMATION SECURITY OFFICER)
A18: Name:
A19: Title:
A20: Date:
A21: Signature:
... A37: Special Considerations:
