Workbook

Sheet Instructions & Legend
A1: ISMS-IMP-A.8.24.1 - Data Transmission Cryptography Assessment ISO/IEC 27001:2022 - Control A.8.24: Use of Cryptography
A3: Document Information
A4: Document ID | B4: ISMS-IMP-A.8.24.1
A5: Workbook Title | B5: Data Transmission Cryptography Assessment
A6: Control Reference | B6: ISO/IEC 27001:2022 - Control A.8.24: Use of Cryptography
A7: Version | B7: 1.0
A8: Assessment Date
A9: Completed By
A10: Organisation
A12: Instructions
A13: 1. Complete each worksheet tab for applicable systems/services.
A14: 2. Use dropdown menus for standardised entries (Status, Remediation, etc.).
A15: 3. Fill in yellow-highlighted cells with your information.
A16: 4. If Status = Partial or Non-Compliant, complete the Exception/Deviation section.
A17: 5. Check all applicable items in the Compliance Checklist for each section.
A18: 6. Provide evidence location/path for each implementation entry.
A19: 7. Summary Dashboard auto-calculates compliance statistics.
A20: 8. Maintain the Evidence Register for audit traceability.
... A23: Status Legend
A24: Symbol | B24: Status | C24: Description
A25: ✓ | B25: Compliant / Complete | C25: Requirement fully met
A26: ⚠ | B26: Partial / In Progress | C26: Partially met or in progress
A27: ✗ | B27: Non-Compliant / Not Started | C27: Requirement not met
A28: — | B28: Not Applicable | C28: Not applicable to this assessment

Sheet 1.1 External HTTPS-TLS
A1: 1.1 HTTPS/TLS - EXTERNAL WEB SERVICES Policy Requirement: All externally accessible web services MUST use TLS encryption with valid certificates from trusted CAs (Policy Section 2.2.1)
A2: ISO/IEC 27001:2022 | Control A.8.24: Use of Cryptography
A3: Does your organisation have external-facing web services or websites?
A4: Response:
A6: Service Description | B6: Current TLS Version | C6: Certificate Source (CA) | D6: Certificate Validity | E6: Status | F6: Evidence Location | G6: Gap Description | H6: Remediation Needed
A7: Corporate website (www.example.com) | B7: TLS 1.3 | C7: Let's Encrypt | D7: 90 days | E7: ✅ Compliant | F7: /evidence/a824/1.1-ssllabs-website-20260218.pdf | G7: None | H7: ❌ No
A32: Additional Details
A33: Number of external web services:
A34: Certificate expiration monitoring configured:
A35: Automated certificate renewal (REQUIRED for public CAs by Mar 2026):
A36: Certificate inventory maintained:
A38: COMPLIANCE CHECKLIST
A39: ☐ | B39: Requirement | C39: Status
A40: ☐ | B40: TLS 1.3 preferred OR TLS 1.2 minimum
A41: ☐ | B41: Valid certificates from trusted public CA
A42: ☐ | B42: Certificate validity: ≤398d (until Mar 2026), ≤200d (Mar 2026+), ≤100d (Mar 2027+), ≤47d (Mar 2029+)
A43: ☐ | B43: Self-signed certificates NOT used in production
A44: ☐ | B44: HTTP automatically redirects to HTTPS
A45: ☐ | B45: HSTS header configured
A46: ☐ | B46: Strong cipher suites configured
A47: ☐ | B47: Weak protocols disabled (TLS 1.1, 1.0, SSL)
A48: ☐ | B48: Perfect Forward Secrecy (PFS) enabled
A49: ☐ | B49: Certificate expiration alerts (≥ 30 days)
A50: ☐ | B50: Automation infrastructure ready for 47-day certificate lifecycle (by Mar 2029)
A51: Checklist Score: | B51: =IFERROR(ROUND(COUNTIF(C40:C50,"✅ Yes")/COUNTA(C40:C50)*100,0)&"%","0%")
A53: EXCEPTION / DEVIATION DOCUMENTATION (Complete if Status = Partial or Non-Compliant)
A54: Formal exception request submitted:
A55: Exception ID:
A56: Risk acceptance documented:
A57: Risk ID:
A58: Compensating Controls (summary):
A59: ☐ Network segmentation / firewall restrictions
A60: ☐ Enhanced monitoring / alerting
A61: ☐ IP allowlisting / access restrictions
A62: ☐ Other (describe):
A63: Remediation actions required:
A64: Responsible person:
... A68: ADDITIONAL NOTES / COMMENTS

Sheet 1.2 Internal HTTPS-TLS
A1: 1.2 HTTPS/TLS - INTERNAL WEB SERVICES Policy Requirement: Internal web services containing sensitive data (Confidential or Restricted classification) MUST use TLS (Policy Section 2.2.1)
A2: ISO/IEC 27001:2022 | Control A.8.24: Use of Cryptography
A3: Does your organisation have internal web services (intranet, internal portals, internal APIs)?
A4: Response:
A6: Service Description | B6: Data Classification | C6: Current TLS Version | D6: Certificate Type | E6: Status | F6: Evidence Location | G6: Gap Description | H6: Remediation Needed
A7: HR portal (hr.internal.example.com) | B7: Confidential | C7: TLS 1.2 | D7: Internal CA | E7: ✅ Compliant | F7: /evidence/a824/1.2-internal-tls-config-20260218.txt | G7: None | H7: ❌ No
A32: Additional Details
A33: Number of internal web services:
A34: Data classification(s) handled:
A35: Internal CA in use:
A36: Certificate management process documented:
A38: COMPLIANCE CHECKLIST
A39: ☐ | B39: Requirement | C39: Status
A40: ☐ | B40: TLS 1.2+ for services with Confidential/Restricted data
A41: ☐ | B41: Valid certificates (internal CA acceptable)
A42: ☐ | B42: Services with non-sensitive data: Risk assessed and documented
A43: ☐ | B43: Certificate inventory maintained
A44: ☐ | B44: Certificate expiration monitoring configured
A45: Checklist Score: | B45: =IFERROR(ROUND(COUNTIF(C40:C44,"✅ Yes")/COUNTA(C40:C44)*100,0)&"%","0%")
A47: EXCEPTION / DEVIATION DOCUMENTATION (Complete if Status = Partial or Non-Compliant)
A48: Formal exception request submitted:
A49: Exception ID:
A50: Risk acceptance documented:
A51: Risk ID:
A52: Compensating Controls (summary):
A53: ☐ Network segmentation / firewall restrictions
A54: ☐ Enhanced monitoring / alerting
A55: ☐ IP allowlisting / access restrictions
A56: ☐ Other (describe):
A57: Remediation actions required:
A58: Responsible person:
... A62: ADDITIONAL NOTES / COMMENTS

Sheet 2.1 Email Encryption
A1: 2.1 EMAIL ENCRYPTION Policy Requirement: Emails containing classified information (Confidential or Restricted) MUST be encrypted when sent externally (Policy Section 2.2.2)
A2: ISO/IEC 27001:2022 | Control A.8.24: Use of Cryptography
A3: Does your organisation send emails containing classified information to external parties?
A4: Response:
A6: Email System | B6: Encryption Solution | C6: Encryption Method | D6: User Adoption Rate | E6: Status | F6: Evidence Location | G6: Gap Description | H6: Remediation Needed
A7: Microsoft Exchange Online | B7: S/MIME | C7: End-to-end encryption | D7: 85% | E7: ⚠️ Partial | F7: /evidence/a824/2.1-smime-policy-20260218.pdf | G7: User adoption below 90% target | H7: ✅ Yes
A32: Additional Details
A33: Encryption solution in use:
A34: PKI infrastructure for email:
A35: User training provided:
A36: Encryption enforced via policy/DLP:
A38: COMPLIANCE CHECKLIST
A39: ☐ | B39: Requirement | C39: Status
A40: ☐ | B40: S/MIME or PGP/GPG encryption available
A41: ☐ | B41: Users trained on when/how to encrypt sensitive emails
A42: ☐ | B42: PKI infrastructure in place for S/MIME
A43: ☐ | B43: Opportunistic TLS enabled for mail server connections
A44: ☐ | B44: STARTTLS enabled for SMTP
A45: Checklist Score: | B45: =IFERROR(ROUND(COUNTIF(C40:C44,"✅ Yes")/COUNTA(C40:C44)*100,0)&"%","0%")
A47: EXCEPTION / DEVIATION DOCUMENTATION (Complete if Status = Partial or Non-Compliant)
A48: Formal exception request submitted:
A49: Exception ID:
A50: Risk acceptance documented:
A51: Risk ID:
A52: Compensating Controls (summary):
A53: ☐ Network segmentation / firewall restrictions
A54: ☐ Enhanced monitoring / alerting
A55: ☐ IP allowlisting / access restrictions
A56: ☐ Other (describe):
A57: Remediation actions required:
A58: Responsible person:
... A62: ADDITIONAL NOTES / COMMENTS

Sheet 2.2 Digital Signatures
A1: 2.2 DIGITAL SIGNATURES Policy Requirement: Digital signatures RECOMMENDED for all external emails, REQUIRED for legal/financial/official communications (Policy Section 2.2.2)
A2: ISO/IEC 27001:2022 | Control A.8.24: Use of Cryptography
A3: Does your organisation use digital signatures for email?
A4: Response:
A6: Use Case | B6: Signature Method | C6: Certificate Source | D6: Status | E6: Evidence Location | F6: Gap Description | G6: Remediation Needed
A7: Contract signing | B7: S/MIME | C7: Internal CA | D7: ✅ Compliant | E7: /evidence/a824/2.2-digital-sig-cert-20260218.p12 | F7: None | G7: ❌ No
A32: Additional Details
A33: Digital signatures used for:
A34: Certificate source:
A36: COMPLIANCE CHECKLIST
A37: ☐ | B37: Requirement | C37: Status
A38: ☐ | B38: Digital signatures available for required use cases
A39: ☐ | B39: Email certificates issued from trusted CA or internal PKI
A40: ☐ | B40: Certificate validity ≤ 1 year
A41: ☐ | B41: Users trained on digital signature usage
A42: ☐ | B42: Non-repudiation implemented for legally binding transactions — digital signatures with qualified certificates where required
A43: ☐ | B43: Audit log integrity protected — cryptographic checksums (HMAC, digital signatures) applied to audit logs to detect tampering
A44: ☐ | B44: Time-stamping implemented — qualified electronic timestamps applied to critical evidence and transaction records
A45: Checklist Score: | B45: =IFERROR(ROUND(COUNTIF(C38:C44,"✅ Yes")/COUNTA(C38:C44)*100,0)&"%","0%")
A47: EXCEPTION / DEVIATION DOCUMENTATION (Complete if Status = Partial or Non-Compliant)
A48: Formal exception request submitted:
A49: Exception ID:
A50: Risk acceptance documented:
A51: Risk ID:
A52: Compensating Controls (summary):
A53: ☐ Network segmentation / firewall restrictions
A54: ☐ Enhanced monitoring / alerting
A55: ☐ IP allowlisting / access restrictions
A56: ☐ Other (describe):
A57: Remediation actions required:
A58: Responsible person:
... A62: ADDITIONAL NOTES / COMMENTS

Sheet 3.1 File Transfer Protocols
A1: 3.1 SECURE FILE TRANSFER Policy Requirement: File transfers containing sensitive data MUST use encrypted protocols (SFTP, FTPS, HTTPS). Unencrypted FTP is PROHIBITED (Policy Section 2.2.3)
A2: ISO/IEC 27001:2022 | Control A.8.24: Use of Cryptography
A3: Does your organisation transfer files containing sensitive data to/from external parties or between systems?
A4: Response:
A6: Transfer Method/System | B6: Protocol Used | C6: Authentication Method | D6: Data Classification | E6: Status | F6: Evidence Location | G6: Gap Description | H6: Remediation Needed
A7: SFTP Server (files.example.com) | B7: SFTP | C7: SSH key + MFA | D7: Confidential | E7: ✅ Compliant | F7: /evidence/a824/3.1-sftp-config-20260218.txt | G7: None | H7: ❌ No
A32: Additional Details
A33: Approved protocols in use:
A34: Prohibited protocols detected:
A35: Authentication:
A37: COMPLIANCE CHECKLIST
A38: ☐ | B38: Requirement | C38: Status
A39: ☐ | B39: SFTP, FTPS, or HTTPS used for sensitive file transfers
A40: ☐ | B40: Plain FTP NOT used for sensitive data
A41: ☐ | B41: Strong authentication configured (key-based preferred)
A42: ☐ | B42: MFA required for external file transfer
A43: ☐ | B43: File transfer logging enabled
A44: ☐ | B44: SSH keys rotated annually (if SFTP used)
A45: Checklist Score: | B45: =IFERROR(ROUND(COUNTIF(C39:C44,"✅ Yes")/COUNTA(C39:C44)*100,0)&"%","0%")
A47: EXCEPTION / DEVIATION DOCUMENTATION (Complete if Status = Partial or Non-Compliant)
A48: Formal exception request submitted:
A49: Exception ID:
A50: Risk acceptance documented:
A51: Risk ID:
A52: Compensating Controls (summary):
A53: ☐ Network segmentation / firewall restrictions
A54: ☐ Enhanced monitoring / alerting
A55: ☐ IP allowlisting / access restrictions
A56: ☐ Other (describe):
A57: Remediation actions required:
A58: Responsible person:
... A62: ADDITIONAL NOTES / COMMENTS

Sheet 4.1 VPN
A1: 4.1 VPN (VIRTUAL PRIVATE NETWORK) Policy Requirement: All remote access to organisational networks MUST use encrypted VPN with approved protocols (IPsec, WireGuard, OpenVPN). MFA REQUIRED (Policy Section 2.2.4)
A2: ISO/IEC 27001:2022 | Control A.8.24: Use of Cryptography
A3: Does your organisation provide remote access via VPN?
A4: Response:
A6: VPN Solution | B6: Protocol | C6: Encryption Algorithm | D6: MFA Enabled | E6: Status | F6: Evidence Location | G6: Gap Description | H6: Remediation Needed
A7: Cisco AnyConnect | B7: IKEv2/IPSec | C7: AES-256 | D7: ✅ Yes | E7: ✅ Compliant | F7: /evidence/a824/4.1-vpn-config-20260218.pdf | G7: None | H7: ❌ No
A32: Additional Details
A33: VPN protocol in use:
A34: Encryption algorithm:
A35: Number of VPN users:
A36: MFA solution:
A37: Split-tunneling:
A39: COMPLIANCE CHECKLIST
A40: ☐ | B40: Requirement | C40: Status
A41: ☐ | B41: Approved VPN protocol (IPsec/IKEv2, WireGuard, OpenVPN with TLS 1.2+)
A42: ☐ | B42: AES-256 or ChaCha20 encryption
A43: ☐ | B43: Perfect Forward Secrecy (PFS) enabled
A44: ☐ | B44: MFA required for all VPN connections
A45: ☐ | B45: Certificate-based authentication (preferred) OR strong pre-shared key
A46: ☐ | B46: VPN session timeout configured (≤30 minutes idle)
A47: ☐ | B47: Split-tunneling disabled (or documented exception)
A48: ☐ | B48: VPN access logs retained and reviewed
A49: Checklist Score: | B49: =IFERROR(ROUND(COUNTIF(C41:C48,"✅ Yes")/COUNTA(C41:C48)*100,0)&"%","0%")
A51: EXCEPTION / DEVIATION DOCUMENTATION (Complete if Status = Partial or Non-Compliant)
A52: Formal exception request submitted:
A53: Exception ID:
A54: Risk acceptance documented:
A55: Risk ID:
A56: Compensating Controls (summary):
A57: ☐ Network segmentation / firewall restrictions
A58: ☐ Enhanced monitoring / alerting
A59: ☐ IP allowlisting / access restrictions
A60: ☐ Other (describe):
A61: Remediation actions required:
A62: Responsible person:
... A66: ADDITIONAL NOTES / COMMENTS

Sheet 4.2 SSH
A1: 4.2 SSH (SECURE SHELL) Policy Requirement: SSH REQUIRED for all administrative and remote terminal access. SSH protocol version 2 REQUIRED, password authentication SHOULD be disabled (Policy Section 2.2.4)
A2: ISO/IEC 27001:2022 | Control A.8.24: Use of Cryptography
A3: Does your organisation use SSH for remote system administration?
A4: Response:
A6: System/Service | B6: SSH Version | C6: Authentication Method | D6: Key Algorithm | E6: Status | F6: Evidence Location | G6: Gap Description | H6: Remediation Needed
A7: Linux production servers | B7: SSH 2.0 | C7: Public key (RSA) | D7: RSA-4096 | E7: ✅ Compliant | F7: /evidence/a824/4.2-ssh-key-audit-20260218.txt | G7: None | H7: ❌ No
A32: Additional Details
A33: SSH protocol version:
A34: Authentication method:
A35: SSH key types in use:
A36: Root login via SSH:
A37: SSH key rotation schedule:
A39: COMPLIANCE CHECKLIST
A40: ☐ | B40: Requirement | C40: Status
A41: ☐ | B41: SSH protocol version 2 only (SSHv1 disabled)
A42: ☐ | B42: Key-based authentication (password auth disabled preferred)
A43: ☐ | B43: Minimum key length: RSA 2048-bit or Ed25519
A44: ☐ | B44: Root login disabled
A45: ☐ | B45: SSH keys rotated annually
A46: ☐ | B46: Unused SSH keys removed
A47: ☐ | B47: Strong algorithms configured (per Policy Appendix A)
A48: ☐ | B48: Weak algorithms disabled (DSA, MD5, SHA-1)
A49: Checklist Score: | B49: =IFERROR(ROUND(COUNTIF(C41:C48,"✅ Yes")/COUNTA(C41:C48)*100,0)&"%","0%")
A51: EXCEPTION / DEVIATION DOCUMENTATION (Complete if Status = Partial or Non-Compliant)
A52: Formal exception request submitted:
A53: Exception ID:
A54: Risk acceptance documented:
A55: Risk ID:
A56: Compensating Controls (summary):
A57: ☐ Network segmentation / firewall restrictions
A58: ☐ Enhanced monitoring / alerting
A59: ☐ IP allowlisting / access restrictions
A60: ☐ Other (describe):
A61: Remediation actions required:
A62: Responsible person:
... A66: ADDITIONAL NOTES / COMMENTS

Sheet 4.3 RDP
A1: 4.3 RDP (REMOTE DESKTOP PROTOCOL) Policy Requirement: RDP connections MUST be encrypted using TLS. RDP MUST NOT be directly exposed to the Internet (Policy Section 2.2.4)
A2: ISO/IEC 27001:2022 | Control A.8.24: Use of Cryptography
A3: Does your organisation use RDP for remote access?
A4: Response:
A6: System/Environment | B6: RDP Access Method | C6: TLS Encryption | D6: NLA Enabled | E6: Status | F6: Evidence Location | G6: Gap Description | H6: Remediation Needed
A7: Windows admin servers | B7: VPN + RDP Gateway | C7: TLS 1.2 | D7: ✅ Yes | E7: ✅ Compliant | F7: /evidence/a824/4.3-rdp-config-20260218.png | G7: None | H7: ❌ No
A32: Additional Details
A33: RDP access method:
A34: Network Level Authentication (NLA):
A35: MFA for RDP:
A36: RDP encryption level:
A38: COMPLIANCE CHECKLIST
A39: ☐ | B39: Requirement | C39: Status
A40: ☐ | B40: RDP accessed through VPN or jump host (NOT directly exposed)
A41: ☐ | B41: TLS encryption configured
A42: ☐ | B42: Network Level Authentication (NLA) enabled
A43: ☐ | B43: RDP encryption level set to 'High'
A44: ☐ | B44: MFA required for production system access
A45: ☐ | B45: RDP session recording (recommended for privileged access)
A46: Checklist Score: | B46: =IFERROR(ROUND(COUNTIF(C40:C45,"✅ Yes")/COUNTA(C40:C45)*100,0)&"%","0%")
A48: EXCEPTION / DEVIATION DOCUMENTATION (Complete if Status = Partial or Non-Compliant)
A49: Formal exception request submitted:
A50: Exception ID:
A51: Risk acceptance documented:
A52: Risk ID:
A53: Compensating Controls (summary):
A54: ☐ Network segmentation / firewall restrictions
A55: ☐ Enhanced monitoring / alerting
A56: ☐ IP allowlisting / access restrictions
A57: ☐ Other (describe):
A58: Remediation actions required:
A59: Responsible person:
... A63: ADDITIONAL NOTES / COMMENTS

Sheet 5.1 API Security
A1: 5.1 API SECURITY Policy Requirement: API endpoints MUST use HTTPS with TLS 1.2+. API authentication MUST use OAuth 2.0, API keys (256-bit entropy), or mutual TLS (Policy Section 2.2.5)
A2: ISO/IEC 27001:2022 | Control A.8.24: Use of Cryptography
A3: Does your organisation expose APIs (REST, SOAP, GraphQL, etc.)?
A4: Response:
A6: API Name/Service | B6: Authentication Method | C6: TLS Version | D6: API Key Management | E6: Token Expiry | F6: Status | G6: Evidence Location | H6: Gap Description | I6: Remediation Needed
A7: Customer REST API | B7: OAuth 2.0 / JWT | C7: TLS 1.3 | D7: Vault (HashiCorp) | E7: 1 hour | F7: ✅ Compliant | G7: /evidence/a824/5.1-api-tls-scan-20260218.pdf | H7: None | I7: ❌ No
A32: Additional Details
A33: Number of APIs:
A34: API authentication:
A35: API key entropy:
A36: API key rotation:
A37: API keys stored in:
A39: COMPLIANCE CHECKLIST
A40: ☐ | B40: Requirement | C40: Status
A41: ☐ | B41: All API endpoints use HTTPS (TLS 1.2+)
A42: ☐ | B42: HTTP endpoints disabled or blocked
A43: ☐ | B43: OAuth 2.0 with PKCE (for user-facing APIs)
A44: ☐ | B44: API keys have ≥256-bit entropy
A45: ☐ | B45: API keys rotate every 90 days
A46: ☐ | B46: API keys stored in secrets manager (NOT in code/config)
A47: ☐ | B47: Access tokens expire within 1 hour
A48: ☐ | B48: Refresh tokens expire within 24 hours
A49: ☐ | B49: Rate limiting implemented per API key
A50: ☐ | B50: API keys NOT passed in URL query parameters
A51: Checklist Score: | B51: =IFERROR(ROUND(COUNTIF(C41:C50,"✅ Yes")/COUNTA(C41:C50)*100,0)&"%","0%")
A53: EXCEPTION / DEVIATION DOCUMENTATION (Complete if Status = Partial or Non-Compliant)
A54: Formal exception request submitted:
A55: Exception ID:
A56: Risk acceptance documented:
A57: Risk ID:
A58: Compensating Controls (summary):
A59: ☐ Network segmentation / firewall restrictions
A60: ☐ Enhanced monitoring / alerting
A61: ☐ IP allowlisting / access restrictions
A62: ☐ Other (describe):
A63: Remediation actions required:
A64: Responsible person:
... A68: ADDITIONAL NOTES / COMMENTS

Sheet 6.1 Database Connections
A1: 6.1 DATABASE CONNECTIONS Policy Requirement: Database connections MUST use encrypted protocols (TLS for PostgreSQL/MySQL, encrypted connections for MSSQL) (Policy Section 2.2.6)
A2: ISO/IEC 27001:2022 | Control A.8.24: Use of Cryptography
A3: Does your organisation have applications connecting to databases?
A4: Response:
A6: Database System | B6: Connection Encryption | C6: Certificate Validation | D6: Status | E6: Evidence Location | F6: Gap Description | G6: Remediation Needed
A7: PostgreSQL 15 (FINDB01) | B7: TLS 1.2 (sslmode=verify-full) | C7: Internal CA (verify-full) | D7: ✅ Compliant | E7: /evidence/a824/6.1-db-tls-config-20260218.txt | F7: None | G7: ❌ No
A32: Additional Details
A33: Database systems in use:
A34: Connection encryption enforced:
A36: COMPLIANCE CHECKLIST
A37: ☐ | B37: Requirement | C37: Status
A38: ☐ | B38: Database connections encrypted (TLS/SSL)
A39: ☐ | B39: Certificate validation enabled (not 'trust any certificate')
A40: ☐ | B40: Self-signed certificates only for internal databases (with proper CA)
A41: ☐ | B41: Unencrypted connections disabled or documented exception
A42: Checklist Score: | B42: =IFERROR(ROUND(COUNTIF(C38:C41,"✅ Yes")/COUNTA(C38:C41)*100,0)&"%","0%")
A44: EXCEPTION / DEVIATION DOCUMENTATION (Complete if Status = Partial or Non-Compliant)
A45: Formal exception request submitted:
A46: Exception ID:
A47: Risk acceptance documented:
A48: Risk ID:
A49: Compensating Controls (summary):
A50: ☐ Network segmentation / firewall restrictions
A51: ☐ Enhanced monitoring / alerting
A52: ☐ IP allowlisting / access restrictions
A53: ☐ Other (describe):
A54: Remediation actions required:
A55: Responsible person:
... A59: ADDITIONAL NOTES / COMMENTS

Sheet 6.2 Wireless Networks
A1: 6.2 WIRELESS NETWORKS Policy Requirement: Wireless networks MUST use WPA3-Enterprise or WPA2-Enterprise minimum. WEP and WPA (original) PROHIBITED (Policy Section 2.2.6)
A2: ISO/IEC 27001:2022 | Control A.8.24: Use of Cryptography
A3: Does your organisation have wireless networks?
A4: Response:
A6: Network SSID | B6: Encryption Standard | C6: Authentication Method | D6: Status | E6: Evidence Location | F6: Gap Description | G6: Remediation Needed
A7: CORP-WIFI | B7: WPA3-Enterprise | C7: 802.1X / EAP-TLS | D7: ✅ Compliant | E7: /evidence/a824/6.2-wifi-controller-20260218.png | F7: None | G7: ❌ No
A32: Additional Details
A33: Corporate WiFi encryption:
A34: Guest WiFi:
A35: 802.1X authentication:
A36: WiFi password strength:
A38: COMPLIANCE CHECKLIST
A39: ☐ | B39: Requirement | C39: Status
A40: ☐ | B40: WPA3-Enterprise or WPA2-Enterprise for corporate networks
A41: ☐ | B41: 802.1X with EAP-TLS (certificate-based) preferred
A42: ☐ | B42: WPA2-Personal only with strong passphrase (≥20 characters)
A43: ☐ | B43: WEP and WPA (original) NOT used
A44: ☐ | B44: Guest wireless isolated from corporate network
A45: ☐ | B45: WiFi passwords rotated quarterly (for PSK networks)
A46: Checklist Score: | B46: =IFERROR(ROUND(COUNTIF(C40:C45,"✅ Yes")/COUNTA(C40:C45)*100,0)&"%","0%")
A48: EXCEPTION / DEVIATION DOCUMENTATION (Complete if Status = Partial or Non-Compliant)
A49: Formal exception request submitted:
A50: Exception ID:
A51: Risk acceptance documented:
A52: Risk ID:
A53: Compensating Controls (summary):
A54: ☐ Network segmentation / firewall restrictions
A55: ☐ Enhanced monitoring / alerting
A56: ☐ IP allowlisting / access restrictions
A57: ☐ Other (describe):
A58: Remediation actions required:
A59: Responsible person:
... A63: ADDITIONAL NOTES / COMMENTS

Sheet 7.1 Cloud Transmission
A1: 7.1 CLOUD DATA TRANSMISSION Policy Requirement: Connections to cloud provider APIs MUST use TLS 1.2+. Private connectivity options (PrivateLink, Private Link, Private Service Connect) RECOMMENDED for high-volume or sensitive data (Policy Section 2.2.7)
A2: ISO/IEC 27001:2022 | Control A.8.24: Use of Cryptography
A3: Does your organisation use cloud services (AWS, Azure, GCP, SaaS)?
A4: Response:
A6: Cloud Provider/Service | B6: Connection Method | C6: Encryption | D6: Status | E6: Evidence Location | F6: Gap Description | G6: Remediation Needed
A7: AWS S3 (data backups) | B7: HTTPS/TLS 1.3 | C7: AES-256 (in transit + at rest) | D7: ✅ Compliant | E7: /evidence/a824/7.1-aws-config-20260218.pdf | F7: None | G7: ❌ No
A32: Additional Details
A33: Connection type:
A34: Data classification transmitted:
A35: Cloud providers used:
A37: COMPLIANCE CHECKLIST
A38: ☐ | B38: Requirement | C38: Status
A39: ☐ | B39: TLS 1.2+ for all cloud API connections
A40: ☐ | B40: Private connectivity for Confidential/Restricted data (preferred)
A41: ☐ | B41: Cloud provider native encryption enabled
A42: ☐ | B42: Data encrypted in transit to/from cloud
A43: Checklist Score: | B43: =IFERROR(ROUND(COUNTIF(C39:C42,"✅ Yes")/COUNTA(C39:C42)*100,0)&"%","0%")
A45: EXCEPTION / DEVIATION DOCUMENTATION (Complete if Status = Partial or Non-Compliant)
A46: Formal exception request submitted:
A47: Exception ID:
A48: Risk acceptance documented:
A49: Risk ID:
A50: Compensating Controls (summary):
A51: ☐ Network segmentation / firewall restrictions
A52: ☐ Enhanced monitoring / alerting
A53: ☐ IP allowlisting / access restrictions
A54: ☐ Other (describe):
A55: Remediation actions required:
A56: Responsible person:
... A60: ADDITIONAL NOTES / COMMENTS

Sheet Evidence Register
A1: EVIDENCE REGISTER
A2: List all evidence files/documents referenced in this assessment (audit traceability).
A4: Evidence ID | B4: Assessment Area | C4: Evidence Type | D4: Description | E4: Location/Path | F4: Date Collected | G4: Collected By | H4: Verification Status
A5: EV-001 | B5: 1.1 External HTTPS-TLS | C5: Configuration file | D5: TLS/encryption configuration export for audit evidence | E5: /evidence/a824/config-export-2025.txt | F5: 01.01.2025 | G5: Security Team | H5: ✅ Verified

Sheet Summary Dashboard
A1: DATA TRANSMISSION CRYPTOGRAPHY ASSESSMENT — SUMMARY DASHBOARD
A2: ISO/IEC 27001:2022 | Control A.8.24 | Data Transmission Cryptography
A4: TABLE 1: ASSESSMENT AREA COMPLIANCE OVERVIEW
A5: Assessment Area | B5: Total Items | C5: Compliant | D5: Partial | E5: Non-Compliant | F5: N/A | G5: Compliance %
A6: 1.1 External HTTPS/TLS | B6: =COUNTA('1.1 External HTTPS-TLS'!E8:E69) | C6: =COUNTIF('1.1 External HTTPS-TLS'!E8:E69,"*Compliant") | D6: =COUNTIF('1.1 External HTTPS-TLS'!E8:E69,"*Partial") | E6: =COUNTIF('1.1 External HTTPS-TLS'!E8:E69,"*Non-Compliant") | F6: =COUNTIF('1.1 External HTTPS-TLS'!E8:E69,"N/A") | G6: =IF((B6-F6)=0,"0%",ROUND(C6/(B6-F6)*100,1)&"%")
A7: 1.2 Internal HTTPS/TLS | B7: =COUNTA('1.2 Internal HTTPS-TLS'!E8:E69) | C7: =COUNTIF('1.2 Internal HTTPS-TLS'!E8:E69,"*Compliant") | D7: =COUNTIF('1.2 Internal HTTPS-TLS'!E8:E69,"*Partial") | E7: =COUNTIF('1.2 Internal HTTPS-TLS'!E8:E69,"*Non-Compliant") | F7: =COUNTIF('1.2 Internal HTTPS-TLS'!E8:E69,"N/A") | G7: =IF((B7-F7)=0,"0%",ROUND(C7/(B7-F7)*100,1)&"%")
A8: 2.1 Email Encryption | B8: =COUNTA('2.1 Email Encryption'!E8:E69) | C8: =COUNTIF('2.1 Email Encryption'!E8:E69,"*Compliant") | D8: =COUNTIF('2.1 Email Encryption'!E8:E69,"*Partial") | E8: =COUNTIF('2.1 Email Encryption'!E8:E69,"*Non-Compliant") | F8: =COUNTIF('2.1 Email Encryption'!E8:E69,"N/A") | G8: =IF((B8-F8)=0,"0%",ROUND(C8/(B8-F8)*100,1)&"%")
A9: 2.2 Digital Signatures | B9: =COUNTA('2.2 Digital Signatures'!D8:D69) | C9: =COUNTIF('2.2 Digital Signatures'!D8:D69,"*Compliant") | D9: =COUNTIF('2.2 Digital Signatures'!D8:D69,"*Partial") | E9: =COUNTIF('2.2 Digital Signatures'!D8:D69,"*Non-Compliant") | F9: =COUNTIF('2.2 Digital Signatures'!D8:D69,"N/A") | G9: =IF((B9-F9)=0,"0%",ROUND(C9/(B9-F9)*100,1)&"%")
A10: 3.1 File Transfer | B10: =COUNTA('3.1 File Transfer Protocols'!E8:E69) | C10: =COUNTIF('3.1 File Transfer Protocols'!E8:E69,"*Compliant") | D10: =COUNTIF('3.1 File Transfer Protocols'!E8:E69,"*Partial") | E10: =COUNTIF('3.1 File Transfer Protocols'!E8:E69,"*Non-Compliant") | F10: =COUNTIF('3.1 File Transfer Protocols'!E8:E69,"N/A") | G10: =IF((B10-F10)=0,"0%",ROUND(C10/(B10-F10)*100,1)&"%")
A11: 4.1 VPN | B11: =COUNTA('4.1 VPN'!E8:E69) | C11: =COUNTIF('4.1 VPN'!E8:E69,"*Compliant") | D11: =COUNTIF('4.1 VPN'!E8:E69,"*Partial") | E11: =COUNTIF('4.1 VPN'!E8:E69,"*Non-Compliant") | F11: =COUNTIF('4.1 VPN'!E8:E69,"N/A") | G11: =IF((B11-F11)=0,"0%",ROUND(C11/(B11-F11)*100,1)&"%")
A12: 4.2 SSH | B12: =COUNTA('4.2 SSH'!E8:E69) | C12: =COUNTIF('4.2 SSH'!E8:E69,"*Compliant") | D12: =COUNTIF('4.2 SSH'!E8:E69,"*Partial") | E12: =COUNTIF('4.2 SSH'!E8:E69,"*Non-Compliant") | F12: =COUNTIF('4.2 SSH'!E8:E69,"N/A") | G12: =IF((B12-F12)=0,"0%",ROUND(C12/(B12-F12)*100,1)&"%")
A13: 4.3 RDP | B13: =COUNTA('4.3 RDP'!E8:E69) | C13: =COUNTIF('4.3 RDP'!E8:E69,"*Compliant") | D13: =COUNTIF('4.3 RDP'!E8:E69,"*Partial") | E13: =COUNTIF('4.3 RDP'!E8:E69,"*Non-Compliant") | F13: =COUNTIF('4.3 RDP'!E8:E69,"N/A") | G13: =IF((B13-F13)=0,"0%",ROUND(C13/(B13-F13)*100,1)&"%")
A14: 5.1 API Security | B14: =COUNTA('5.1 API Security'!F8:F69) | C14: =COUNTIF('5.1 API Security'!F8:F69,"*Compliant") | D14: =COUNTIF('5.1 API Security'!F8:F69,"*Partial") | E14: =COUNTIF('5.1 API Security'!F8:F69,"*Non-Compliant") | F14: =COUNTIF('5.1 API Security'!F8:F69,"N/A") | G14: =IF((B14-F14)=0,"0%",ROUND(C14/(B14-F14)*100,1)&"%")
A15: 6.1 Database Connections | B15: =COUNTA('6.1 Database Connections'!D8:D69) | C15: =COUNTIF('6.1 Database Connections'!D8:D69,"*Compliant") | D15: =COUNTIF('6.1 Database Connections'!D8:D69,"*Partial") | E15: =COUNTIF('6.1 Database Connections'!D8:D69,"*Non-Compliant") | F15: =COUNTIF('6.1 Database Connections'!D8:D69,"N/A") | G15: =IF((B15-F15)=0,"0%",ROUND(C15/(B15-F15)*100,1)&"%")
A16: 6.2 Wireless Networks | B16: =COUNTA('6.2 Wireless Networks'!D8:D69) | C16: =COUNTIF('6.2 Wireless Networks'!D8:D69,"*Compliant") | D16: =COUNTIF('6.2 Wireless Networks'!D8:D69,"*Partial") | E16: =COUNTIF('6.2 Wireless Networks'!D8:D69,"*Non-Compliant") | F16: =COUNTIF('6.2 Wireless Networks'!D8:D69,"N/A") | G16: =IF((B16-F16)=0,"0%",ROUND(C16/(B16-F16)*100,1)&"%")
A17: 7.1 Cloud Transmission | B17: =COUNTA('7.1 Cloud Transmission'!D8:D69) | C17: =COUNTIF('7.1 Cloud Transmission'!D8:D69,"*Compliant") | D17: =COUNTIF('7.1 Cloud Transmission'!D8:D69,"*Partial") | E17: =COUNTIF('7.1 Cloud Transmission'!D8:D69,"*Non-Compliant") | F17: =COUNTIF('7.1 Cloud Transmission'!D8:D69,"N/A") | G17: =IF((B17-F17)=0,"0%",ROUND(C17/(B17-F17)*100,1)&"%")
A18: TOTAL | B18: =SUM(B6:B17) | C18: =SUM(C6:C17) | D18: =SUM(D6:D17) | E18: =SUM(E6:E17) | F18: =SUM(F6:F17) | G18: =IF((B18-F18)=0,"0%",ROUND(C18/(B18-F18)*100,1)&"%")
A20: TABLE 2: KEY METRICS
A21: KPI | B21: Current Value | C21: Target | D21: Status | E21: Last Updated | F21: Owner | G21: Notes
A22: TLS 1.2+ Coverage – External | C22: 100%
A23: TLS 1.2+ Coverage – Internal | C23: ≥95%
A24: Email Encryption – Sensitive Data | C24: 100%
A25: VPN Compliance Rate | C25: 100%
A26: SSH Key Rotation Compliance | C26: ≥90%
A27: API mTLS Coverage | C27: ≥95%
A28: Database Encryption in Transit | C28: 100%
A29: Cloud Transmission Encryption | C29: 100%
A30: Certificates Expiring < 30 Days (count) | C30: 0
A31: Evidence Documentation Rate | C31: 100%
A35: TABLE 3: DOMAIN COMPLIANCE SUMMARY
A36: Transmission Domain | B36: Non-Compliant | C36: Partial | D36: Compliant | E36: N/A | F36: Total Items | G36: Compliance %
A37: 1.1 External HTTPS/TLS | B37: =COUNTIF('1.1 External HTTPS-TLS'!E8:E69,"*Non-Compliant") | C37: =COUNTIF('1.1 External HTTPS-TLS'!E8:E69,"*Partial") | D37: =COUNTIF('1.1 External HTTPS-TLS'!E8:E69,"*Compliant") | E37: =COUNTIF('1.1 External HTTPS-TLS'!E8:E69,"N/A") | F37: =COUNTA('1.1 External HTTPS-TLS'!E8:E69) | G37: =IF((F37-E37)=0,0,D37/(F37-E37))
A38: 1.2 Internal HTTPS/TLS | B38: =COUNTIF('1.2 Internal HTTPS-TLS'!E8:E69,"*Non-Compliant") | C38: =COUNTIF('1.2 Internal HTTPS-TLS'!E8:E69,"*Partial") | D38: =COUNTIF('1.2 Internal HTTPS-TLS'!E8:E69,"*Compliant") | E38: =COUNTIF('1.2 Internal HTTPS-TLS'!E8:E69,"N/A") | F38: =COUNTA('1.2 Internal HTTPS-TLS'!E8:E69) | G38: =IF((F38-E38)=0,0,D38/(F38-E38))
A39: 2.1 Email Encryption | B39: =COUNTIF('2.1 Email Encryption'!E8:E69,"*Non-Compliant") | C39: =COUNTIF('2.1 Email Encryption'!E8:E69,"*Partial") | D39: =COUNTIF('2.1 Email Encryption'!E8:E69,"*Compliant") | E39: =COUNTIF('2.1 Email Encryption'!E8:E69,"N/A") | F39: =COUNTA('2.1 Email Encryption'!E8:E69) | G39: =IF((F39-E39)=0,0,D39/(F39-E39))
A40: 2.2 Digital Signatures | B40: =COUNTIF('2.2 Digital Signatures'!D8:D69,"*Non-Compliant") | C40: =COUNTIF('2.2 Digital Signatures'!D8:D69,"*Partial") | D40: =COUNTIF('2.2 Digital Signatures'!D8:D69,"*Compliant") | E40: =COUNTIF('2.2 Digital Signatures'!D8:D69,"N/A") | F40: =COUNTA('2.2 Digital Signatures'!D8:D69) | G40: =IF((F40-E40)=0,0,D40/(F40-E40))
A41: 3.1 File Transfer | B41: =COUNTIF('3.1 File Transfer Protocols'!E8:E69,"*Non-Compliant") | C41: =COUNTIF('3.1 File Transfer Protocols'!E8:E69,"*Partial") | D41: =COUNTIF('3.1 File Transfer Protocols'!E8:E69,"*Compliant") | E41: =COUNTIF('3.1 File Transfer Protocols'!E8:E69,"N/A") | F41: =COUNTA('3.1 File Transfer Protocols'!E8:E69) | G41: =IF((F41-E41)=0,0,D41/(F41-E41))
A42: 4.1 VPN | B42: =COUNTIF('4.1 VPN'!E8:E69,"*Non-Compliant") | C42: =COUNTIF('4.1 VPN'!E8:E69,"*Partial") | D42: =COUNTIF('4.1 VPN'!E8:E69,"*Compliant") | E42: =COUNTIF('4.1 VPN'!E8:E69,"N/A") | F42: =COUNTA('4.1 VPN'!E8:E69) | G42: =IF((F42-E42)=0,0,D42/(F42-E42))
A43: 4.2 SSH | B43: =COUNTIF('4.2 SSH'!E8:E69,"*Non-Compliant") | C43: =COUNTIF('4.2 SSH'!E8:E69,"*Partial") | D43: =COUNTIF('4.2 SSH'!E8:E69,"*Compliant") | E43: =COUNTIF('4.2 SSH'!E8:E69,"N/A") | F43: =COUNTA('4.2 SSH'!E8:E69) | G43: =IF((F43-E43)=0,0,D43/(F43-E43))
A44: 4.3 RDP | B44: =COUNTIF('4.3 RDP'!E8:E69,"*Non-Compliant") | C44: =COUNTIF('4.3 RDP'!E8:E69,"*Partial") | D44: =COUNTIF('4.3 RDP'!E8:E69,"*Compliant") | E44: =COUNTIF('4.3 RDP'!E8:E69,"N/A") | F44: =COUNTA('4.3 RDP'!E8:E69) | G44: =IF((F44-E44)=0,0,D44/(F44-E44))
A45: 5.1 API Security | B45: =COUNTIF('5.1 API Security'!F8:F69,"*Non-Compliant") | C45: =COUNTIF('5.1 API Security'!F8:F69,"*Partial") | D45: =COUNTIF('5.1 API Security'!F8:F69,"*Compliant") | E45: =COUNTIF('5.1 API Security'!F8:F69,"N/A") | F45: =COUNTA('5.1 API Security'!F8:F69) | G45: =IF((F45-E45)=0,0,D45/(F45-E45))
...

Sheet Approval Sign-Off
A1: ASSESSMENT APPROVAL AND SIGN-OFF
A3: ASSESSMENT SUMMARY
A4: Document: | B4: ISMS-IMP-A.8.24.1 - Data Transmission Assessment
A5: Assessment Period:
A6: Overall Compliance: | B6: ='Summary Dashboard'!G18
A7: Assessment Status:
A10: COMPLETED BY (ASSESSOR)
A11: Name:
A12: Title:
A13: Date:
A14: Signature:
A15: Comments:
A17: REVIEWED BY (INFORMATION SECURITY OFFICER)
A18: Name:
A19: Title:
A20: Date:
A21: Signature:
... A37: Special Considerations:
