Workbook

Sheet Executive Summary
A1: PRIV-CHK-A.1.2.2-5 — Lawful Basis and Consent Compliance Checklist
A3: DOCUMENT INFORMATION
A4: Document ID | B4: PRIV-CHK-A.1.2.2-5
A5: Source Policy | B5: PRIV-POL-A.1.2.2-5
A6: ISO Controls | B6: Lawful Basis and Consent
A7: Generated | B7: 10.03.2026
A8: Prepared By
A9: Organisation
A10: Review Cycle | B10: Annual
A12: OVERALL COMPLIANCE STATUS
A13: Overall Compliance | B13: ='Dashboard'!G8
A14: Status | B14: =IF(Dashboard!G8="N/A","NOT ASSESSED",IF(ISNUMBER(VALUE(SUBSTITUTE(Dashboard!G8,"%",""))),IF(VALUE(SUBSTITUTE(Dashboard!G8,"%",""))>=90,"GREEN",IF(VALUE(SUBSTITUTE(Dashboard!G8,"%",""))>=70,"AMBER","RED")),"NOT ASSESSED"))
A16: KEY METRICS
A17: Total Requirements | B17: ='Dashboard'!B8
A18: Compliant | B18: ='Dashboard'!C8
A19: Partial | B19: ='Dashboard'!D8
A20: Non-Compliant | B20: ='Dashboard'!E8
A21: Not Applicable | B21: ='Dashboard'!F8
A22: Owner Coverage | B22: =IF(Dashboard!B8=0,"N/A",ROUND((COUNTA('Purpose Documentation'!F4:F8)+COUNTA('Lawful Basis Determination'!F4:F9)+COUNTA('Consent Process Design'!F4:F8)+COUNTA('Consent Obtaining and Recording'!F4:F9))/Dashboard!B8*100,0)&"%")
A24: DOMAIN STATUS SUMMARY
A25: Domain | B25: Compliance % | C25: Compliant | D25: Gaps | E25: Status
A26: Purpose Documentation | B26: ='Dashboard'!G4 | C26: ='Dashboard'!C4 | D26: ='Dashboard'!E4 | E26: =IF(Dashboard!G4="N/A","--",IF(ISNUMBER(VALUE(SUBSTITUTE(Dashboard!G4,"%",""))),IF(VALUE(SUBSTITUTE(Dashboard!G4,"%",""))>=90,"PASS",IF(VALUE(SUBSTITUTE(Dashboard!G4,"%",""))>=70,"REVIEW","FAIL")),"--"))
A27: Lawful Basis Determination | B27: ='Dashboard'!G5 | C27: ='Dashboard'!C5 | D27: ='Dashboard'!E5 | E27: =IF(Dashboard!G5="N/A","--",IF(ISNUMBER(VALUE(SUBSTITUTE(Dashboard!G5,"%",""))),IF(VALUE(SUBSTITUTE(Dashboard!G5,"%",""))>=90,"PASS",IF(VALUE(SUBSTITUTE(Dashboard!G5,"%",""))>=70,"REVIEW","FAIL")),"--"))
A28: Consent Process Design | B28: ='Dashboard'!G6 | C28: ='Dashboard'!C6 | D28: ='Dashboard'!E6 | E28: =IF(Dashboard!G6="N/A","--",IF(ISNUMBER(VALUE(SUBSTITUTE(Dashboard!G6,"%",""))),IF(VALUE(SUBSTITUTE(Dashboard!G6,"%",""))>=90,"PASS",IF(VALUE(SUBSTITUTE(Dashboard!G6,"%",""))>=70,"REVIEW","FAIL")),"--"))
A29: Consent Obtaining and Recording | B29: ='Dashboard'!G7 | C29: ='Dashboard'!C7 | D29: ='Dashboard'!E7 | E29: =IF(Dashboard!G7="N/A","--",IF(ISNUMBER(VALUE(SUBSTITUTE(Dashboard!G7,"%",""))),IF(VALUE(SUBSTITUTE(Dashboard!G7,"%",""))>=90,"PASS",IF(VALUE(SUBSTITUTE(Dashboard!G7,"%",""))>=70,"REVIEW","FAIL")),"--"))
A31: CRITICAL ISSUES
A32: # | B32: Issue Description | C32: Domain | D32: Owner | E32: Due Date
A33: 1
A34: 2
A35: 3
A36: 4
A37: 5
A39: MANAGEMENT COMMENTARY
A40: [Enter management commentary on lawful basis and consent posture]
A44: APPROVAL
A45: Assessed By
A46: Name:
A47: Date:
A48: Signature:
A49: Decision:
...

Sheet Dashboard
A1: Lawful Basis and Consent — Compliance Dashboard
A3: Domain | B3: Total Reqs | C3: Compliant | D3: Partial | E3: Non-Compliant | F3: N/A | G3: Compliance %
A4: Purpose Documentation | B4: =COUNTA('Purpose Documentation'!D4:D8) | C4: =COUNTIF('Purpose Documentation'!D4:D8,"Compliant") | D4: =COUNTIF('Purpose Documentation'!D4:D8,"Partial") | E4: =COUNTIF('Purpose Documentation'!D4:D8,"Non-Compliant") | F4: =COUNTIF('Purpose Documentation'!D4:D8,"N/A") | G4: =IF((B4-F4)=0,"N/A",ROUND(C4/(B4-F4)*100,1)&"%")
A5: Lawful Basis Determination | B5: =COUNTA('Lawful Basis Determination'!D4:D9) | C5: =COUNTIF('Lawful Basis Determination'!D4:D9,"Compliant") | D5: =COUNTIF('Lawful Basis Determination'!D4:D9,"Partial") | E5: =COUNTIF('Lawful Basis Determination'!D4:D9,"Non-Compliant") | F5: =COUNTIF('Lawful Basis Determination'!D4:D9,"N/A") | G5: =IF((B5-F5)=0,"N/A",ROUND(C5/(B5-F5)*100,1)&"%")
A6: Consent Process Design | B6: =COUNTA('Consent Process Design'!D4:D8) | C6: =COUNTIF('Consent Process Design'!D4:D8,"Compliant") | D6: =COUNTIF('Consent Process Design'!D4:D8,"Partial") | E6: =COUNTIF('Consent Process Design'!D4:D8,"Non-Compliant") | F6: =COUNTIF('Consent Process Design'!D4:D8,"N/A") | G6: =IF((B6-F6)=0,"N/A",ROUND(C6/(B6-F6)*100,1)&"%")
A7: Consent Obtaining and Recording | B7: =COUNTA('Consent Obtaining and Recording'!D4:D9) | C7: =COUNTIF('Consent Obtaining and Recording'!D4:D9,"Compliant") | D7: =COUNTIF('Consent Obtaining and Recording'!D4:D9,"Partial") | E7: =COUNTIF('Consent Obtaining and Recording'!D4:D9,"Non-Compliant") | F7: =COUNTIF('Consent Obtaining and Recording'!D4:D9,"N/A") | G7: =IF((B7-F7)=0,"N/A",ROUND(C7/(B7-F7)*100,1)&"%")
A8: TOTAL | B8: =SUM(B4:B7) | C8: =SUM(C4:C7) | D8: =SUM(D4:D7) | E8: =SUM(E4:E7) | F8: =SUM(F4:F7) | G8: =IF((B8-F8)=0,"N/A",ROUND(C8/(B8-F8)*100,1)&"%")
A10: COMPLIANCE BY STATUS
A11: Compliant | B11: =C8 | C11: =IF(B8=0,"",ROUND(B11/B8*100,1)&"%")
A12: Partial | B12: =D8 | C12: =IF(B8=0,"",ROUND(B12/B8*100,1)&"%")
A13: Non-Compliant | B13: =E8 | C13: =IF(B8=0,"",ROUND(B13/B8*100,1)&"%")
A14: N/A | B14: =F8 | C14: =IF(B8=0,"",ROUND(B14/B8*100,1)&"%")
A16: TOP GAPS (Manual Entry)
A17: Priority | B17: Domain | C17: Requirement | D17: Owner | E17: Due Date | F17: Status
A29: COMPLIANCE TREND (Manual Entry)
A30: Assessment Date | B30: Overall % | C30: Compliant | D30: Gaps | E30: Assessor | F30: Notes

Sheet Purpose Documentation
A1: Purpose Documentation — Compliance Checklist
A2: ISO/IEC 27701:2025 — Controls A.1.2.2-5: Lawful Basis and Consent
A3: Req # | B3: Section | C3: Requirement | D3: Status | E3: Evidence | F3: Owner | G3: Due Date | H3: Notes
A4: A.1.2.2-01 | B4: Purpose Identification | C4: The organisation shall identify and document the specific, explicit, and legitimate purposes for which each category of PII is processed. Vague or generic purposes are not acceptable.
A5: A.1.2.2-02 | B5: RoPA Entry | C5: Each processing purpose shall be documented in the Record of Processing Activities (RoPA) with sufficient specificity to enable data subjects, lawful basis determination, and supervisory authority assessment.
A6: A.1.2.2-03 | B6: Purpose Limitation | C6: PII collected for a documented purpose shall not be processed for a different purpose unless fresh consent is obtained, a compatibility assessment confirms compatibility, or a new legal basis exists.
A7: A.1.2.2-04 | B7: Compatibility Assessment | C7: The DPO shall conduct and document a compatibility assessment before any secondary use of PII. Assessments shall be maintained in the Purpose Register as part of the RoPA.
A8: A.1.2.2-05 | B8: Purpose Review | C8: Documented purposes shall be reviewed at minimum annually as part of RoPA review, when a processing activity changes materially, and upon DPA guidance that affects how a purpose is interpreted.

Sheet Lawful Basis Determination
A1: Lawful Basis Determination — Compliance Checklist
A2: ISO/IEC 27701:2025 — Controls A.1.2.2-5: Lawful Basis and Consent
A3: Req # | B3: Section | C3: Requirement | D3: Status | E3: Evidence | F3: Owner | G3: Due Date | H3: Notes
A4: A.1.2.3-01 | B4: Basis Determination | C4: The organisation shall determine, document, and be able to demonstrate the lawful basis for each processing purpose. No PII processing shall commence without a documented lawful basis.
A5: A.1.2.3-02 | B5: Basis Selection | C5: The lawful basis for each processing activity shall be selected from GDPR Article 6 (ordinary PII) and, where special category PII is involved, an additional condition from GDPR Article 9(2) shall be identified.
A6: A.1.2.3-03 | B6: Legitimate Interests Assessment | C6: Where legitimate interests (Article 6(1)(f)) is the lawful basis, the organisation shall conduct and document a Legitimate Interests Assessment (LIA) prior to commencing processing.
A7: A.1.2.3-04 | B7: RoPA Lawful Basis Record | C7: For each processing activity, the RoPA shall record: the primary lawful basis; for special category PII the Article 9(2) condition; for legitimate interests the LIA reference; for legal obligation the specific legal provision; and for consent the consent record reference.
A8: A.1.2.3-05 | B8: Demonstrability | C8: The organisation shall be able to demonstrate lawful basis compliance at any time. The DPO shall maintain documented evidence of each basis determination, including the reasoning and any supporting assessments.
A9: A.1.2.3-06 | B9: Basis Review | C9: Documented lawful basis determinations shall be reviewed when processing activities change materially, when legislation changes, or at minimum annually as part of RoPA review.

Sheet Consent Process Design
A1: Consent Process Design — Compliance Checklist
A2: ISO/IEC 27701:2025 — Controls A.1.2.2-5: Lawful Basis and Consent
A3: Req # | B3: Section | C3: Requirement | D3: Status | E3: Evidence | F3: Owner | G3: Due Date | H3: Notes
A4: A.1.2.4-01 | B4: Process Documentation | C4: Where consent is the lawful basis, the organisation shall determine and document a process by which it can demonstrate if, when, and how consent for the processing of PII was obtained from PII principals.
A5: A.1.2.4-02 | B5: Consent Validity | C5: Consent shall meet all validity conditions: freely given (no detriment for refusal); specific (separate per distinct purpose); informed (information per PRIV-POL-A.1.3.2-4 provided before consent); and unambiguous (positive opt-in — no pre-ticked boxes, silence, or inactivity).
A6: A.1.2.4-03 | B6: Withdrawal Mechanism | C6: Data subjects shall be informed of their right to withdraw consent at any time, and withdrawal shall be as easy as giving consent. The withdrawal mechanism shall be documented as part of the consent process.
A7: A.1.2.4-04 | B7: Child Consent Process | C7: Where PII of children is processed on a consent basis, the consent process shall require parental or guardian consent, include proportionate age verification measures, and be approved by the DPO before deployment.
A8: A.1.2.4-05 | B8: Consent Process Review | C8: Documented consent processes shall be reviewed when the processing activity changes, when new consent mechanisms are deployed, and at minimum annually by the DPO.

Sheet Consent Obtaining and Recording
A1: Consent Obtaining and Recording — Compliance Checklist
A2: ISO/IEC 27701:2025 — Controls A.1.2.2-5: Lawful Basis and Consent
A3: Req # | B3: Section | C3: Requirement | D3: Status | E3: Evidence | F3: Owner | G3: Due Date | H3: Notes
A4: A.1.2.5-01 | B4: Consent Obtaining | C4: The organisation shall obtain and record consent from PII principals according to the documented consent processes. Consent shall not be assumed or inferred from inaction.
A5: A.1.2.5-02 | B5: Consent Record Content | C5: For each consent-based processing activity, the consent record shall capture: identity of the PII principal; timestamp of consent; version of the consent statement presented; purposes for which consent was given; and channel or mechanism through which consent was obtained.
A6: A.1.2.5-03 | B6: Consent Record Protection | C6: Consent records shall be protected against loss and falsification per PRIV-POL-A.3.13-16, retained for the duration of the processing activity plus 3 years minimum, and accessible to the DPO for subject rights fulfilment and supervisory authority requests.
A7: A.1.2.5-04 | B7: Consent Withdrawal Action | C7: Upon withdrawal of consent, processing based solely on that consent shall cease without undue delay, PII shall be deleted or anonymised unless another lawful basis applies, and third parties shall be notified per PRIV-POL-A.1.3.5-10.
A8: A.1.2.5-05 | B8: Consent Refresh | C8: Where consent has become invalid (e.g. due to purpose change, long period of inactivity, or regulatory change), the organisation shall seek fresh consent or cease the processing activity.
A9: A.1.2.5-06 | B9: Supervisory Authority Demonstrability | C9: The organisation shall be able to demonstrate to the supervisory authority, on request, that consent was validly obtained for each consent-based processing activity by producing the consent record and documenting the process followed.
