Workbook

Sheet Instructions & Legend
A1: ISMS-IMP-A.5.23.S4 - Ongoing Governance & Risk Management v1.0
A2: ISO/IEC 27001:2022 - Control A.5.23: Cloud Services Security
A4: Document ID: | B4: ISMS-IMP-A.5.23.S4
A5: Assessment Area: | B5: Ongoing Cloud Service Governance & Risk Management
A6: Related Policy: | B6: ISMS-POL-A.5.19-23-S5 Section 6
A7: Version: | B7: 2.0 (Regulatory Update)
A8: Assessment Date: | B8: [ENTER DATE]
A9: Completed By: | B9: [ENTER NAME]
A10: Organization: | B10: [ENTER ORGANIZATION]
A11: Review Cycle: | B11: Quarterly
A13: HOW TO USE THIS WORKBOOK
A14: 1. Complete each assessment sheet (2-7) for all cloud services in scope
A15: 2. Use dropdown menus for standardized entries
A16: 3. Fill in yellow-highlighted cells with your information
A17: 4. If Status = Partial or Non-Compliant, document gaps and remediation
A18: 5. Provide evidence location/path for each assessment entry
A19: 6. Complete Jurisdictional Risk sheet (8) for all US-nexus providers (NEW)
A20: 7. Document DORA ICT risk monitoring frequency if in scope
A21: 8. Classify NIS2 incidents according to severity thresholds
A22: 9. Monitor AI systems according to AI Act risk classification
A23: 10. Assign regulatory risk owners for all identified risks
A24: 11. Summary Dashboard auto-calculates compliance statistics
... A28: STATUS LEGEND
A29: Status | B29: Color | C29: Meaning
A30: {CHECK} Compliant | C30: Fully meets requirements
A31: {WARNING} Partial | C31: Partially implemented, gaps exist
A32: {XMARK} Non-Compliant | C32: Not implemented or major gaps
A33: N/A | C33: Not applicable to this service
A36: REGULATORY COMPLIANCE (NEW IN v1.0)
A37: This workbook includes updated requirements for:
A38: • DORA (Digital Operational Resilience Act) - ICT risk management
A39: • NIS2 (Network and Information Security Directive 2) - Incident management
A40: • EU AI Act - AI system risk monitoring
A41: • US CLOUD Act - Jurisdictional risk assessment (NEW Sheet 8)
A43: REGULATORY APPLICABILITY GUIDANCE
A44: If You Are... | B44: Complete These Fields
A45: EU Financial Entity (DORA scope) | B45: All DORA fields (mandatory)
A46: EU Essential/Important Entity (NIS2) | B46: All NIS2 fields (mandatory)
A47: Operating AI Systems from vendors | B47: All AI Act risk monitoring fields
A48: Using US-HQ Providers | B48: Sheet 8 Jurisdictional Risk (all)
...

Sheet 2. Access Review
A1: 2. ACCESS REVIEW & RECERTIFICATION
A2: Policy Reference: Access to cloud services MUST be reviewed quarterly. Orphan accounts MUST be disabled within 24 hours. (Policy Section 6.1)
A4: Microsoft 365 | B4: 2024-12-01 | C4: 2025-03-01 | D4: IT Security | E4: Completed | F4: 2 users removed | G4: ✓ Compliant | H4: Status | I4: Evidence Location | J4: Gap Description | K4: Remediation Needed | L4: Exception ID | M4: Risk ID | N4: Compensating Controls | O4: Responsible Team/Owner | P4: Target Remediation Date | Q4: Last Review Date | R4: Last Review Date | S4: Review Outcome | T4: Total Accounts Reviewed | U4: Orphan Accounts Found | V4: Excessive Privileges Found | W4: Accounts Remediated | X4: Next Review Due
A5: Azure Cloud Platform | B5: 2024-12-01 | C5: 2025-03-01 | D5: IT Security | E5: Completed | F5: 2 users removed | G5: ✓ Compliant | H5: ✅ Compliant | I5: /evidence/access/M365 | K5: No | O5: IT Ops | Q5: 2025-12-15 | R5: 2025-12-15 | S5: Passed | T5: 245 | U5: 3 | V5: 5 | W5: 8 | X5: 2026-03-15
A6: AWS S3 Storage | B6: 2024-12-01 | C6: 2025-03-01 | D6: IT Security | E6: Completed | F6: 2 users removed | G6: ✓ Compliant
A7: Salesforce CRM | B7: 2024-12-01 | C7: 2025-03-01 | D7: IT Security | E7: Completed | F7: 2 users removed | G7: ✓ Compliant
A8: ServiceNow ITSM | B8: 2024-12-01 | C8: 2025-03-01 | D8: IT Security | E8: Completed | F8: 2 users removed | G8: ✓ Compliant
A26: ACCESS REVIEW & RECERTIFICATION - COMPLIANCE CHECKLIST
A27: ☐ | B27: Requirement | C27: Status | D27: Notes/Evidence
A28: ☐ | B28: Quarterly access review schedule documented and communicated
A29: ☐ | B29: Access review covers all user types (employees, contractors, service accounts)
A30: ☐ | B30: Privileged access reviewed separately with enhanced scrutiny
A31: ☐ | B31: Review includes comparison against job role/least privilege
A32: ☐ | B32: Orphan account detection process automated or scheduled
A33: ☐ | B33: Orphan accounts disabled within 24 hours of detection
A34: ☐ | B34: Terminated user access revoked within SLA (24 hours)
A35: ☐ | B35: Service account ownership verified and documented
A36: ☐ | B36: Shared account usage minimized and justified
A37: ☐ | B37: MFA status verified during access review
A38: ☐ | B38: External/guest access reviewed and time-limited
A39: ☐ | B39: Access review findings documented with evidence
... A42: ☐ | B42: Access review process covers all cloud services in inventory
A44: Checklist Compliance Score: | C44: =IF(COUNTA(C28:C42)=0,"N/A",ROUND(COUNTIF(C28:C42,"Yes")/COUNTIF(C28:C42,"<>N/A")*100,1)&"%")

Sheet 3. Change Management
A1: 3. CHANGE MANAGEMENT
A2: Policy Reference: All cloud service changes MUST follow change management process. Emergency changes require post-review within 48 hours. (Policy Section 6.2)
A4: Cloud Service Name | B4: Vendor Name | C4: Service Type | D4: Review Period | E4: Service Criticality | F4: Data Classification | G4: Change Type | H4: Status | I4: Evidence Location | J4: Gap Description | K4: Remediation Needed | L4: Exception ID | M4: Risk ID | N4: Compensating Controls | O4: Responsible Team/Owner | P4: Target Remediation Date | Q4: Last Review Date | R4: Change Count (Period) | S4: Impact Level | T4: Approval Status | U4: Rollback Plan Documented | V4: Rollback Tested | W4: Post-Change Review Done | X4: Security Impact Assessed
A5: Example: Microsoft 365 | B5: Microsoft | C5: SaaS | D5: Q4 | E5: Critical | F5: Confidential | G5: Config Change | H5: ⚠ Partial | I5: /evidence/changes/M365 | J5: Rollback not tested | K5: Yes | M5: RSK-2025-042 | N5: Manual verification | O5: IT Ops | P5: 2026-01-31 | Q5: 2025-12-01 | R5: 12 | S5: Medium | T5: Approved | U5: Yes | V5: No | W5: Yes | X5: Yes
A26: CHANGE MANAGEMENT - COMPLIANCE CHECKLIST
A27: ☐ | B27: Requirement | C27: Status | D27: Notes/Evidence
A28: ☐ | B28: Change management process documented for cloud services
A29: ☐ | B29: Provider change notifications monitored and assessed
A30: ☐ | B30: Configuration changes require security review before approval
A31: ☐ | B31: Integration changes assessed for data flow impact
A32: ☐ | B32: Emergency change process defined with post-review requirement
A33: ☐ | B33: Emergency changes reviewed within 48 hours
A34: ☐ | B34: Rollback procedures documented for critical changes
A35: ☐ | B35: Rollback procedures tested before go-live (critical changes)
A36: ☐ | B36: Change calendar maintained and communicated
A37: ☐ | B37: Change conflicts identified and resolved
A38: ☐ | B38: Security impact assessment required for all changes
A39: ☐ | B39: Change audit trail maintained in ticketing system
... A42: ☐ | B42: Provider maintenance windows tracked and planned for
A44: Checklist Compliance Score: | C44: =IF(COUNTA(C28:C42)=0,"N/A",ROUND(COUNTIF(C28:C42,"Yes")/COUNTIF(C28:C42,"<>N/A")*100,1)&"%")

Sheet 4. Incident Management
A1: 4. INCIDENT & PROBLEM MANAGEMENT
A2: Policy Reference: Cloud service incidents MUST be detected, reported, and resolved per incident management procedures. (Policy Section 6.3)
A4: INC-001 | B4: M365 Phishing Attempt | C4: Medium | D4: Detected | E4: Security Team | F4: DORA Reported | G4: Incident Severity | H4: Status | I4: Evidence Location | J4: Gap Description | K4: Remediation Needed | L4: Exception ID | M4: Risk ID | N4: Compensating Controls | O4: Responsible Team/Owner | P4: Target Remediation Date | Q4: Last Review Date | R4: Incident Count (Period) | S4: MTTR (Hours) | T4: Root Cause Documented | U4: Playbook Updated | V4: Vendor Notified | W4: Customer Impact | X4: Lessons Learned Captured | Y4: DORA_Risk_Monitoring | Z4: NIS2_Incident_Classification | AA4: AI_Risk_Monitoring_Status | AB4: Regulatory_Risk_Owner
A5: INC-002 | B5: AWS S3 Misconfiguration | C5: High | D5: Resolved | E5: Cloud Team | F5: DORA Reported | G5: P3-Medium | H5: ✅ Compliant | I5: /evidence/incidents/M365 | K5: No | O5: Security | Q5: 2025-12-20 | R5: 4 | S5: 2.5 | T5: Yes | U5: Yes | V5: N/A | W5: No | X5: Yes | Y5: Quarterly Reviews | Z5: Minor (No notification required) | AA5: Periodic Review | AB5: CISO
A6: INC-003 | B6: Salesforce Login Anomaly | C6: Low | D6: Closed | E6: SOC | F6: Not Applicable
A26: INCIDENT & PROBLEM MANAGEMENT - COMPLIANCE CHECKLIST
A27: ☐ | B27: Requirement | C27: Status | D27: Notes/Evidence
A28: ☐ | B28: Incident detection mechanisms in place for cloud services
A29: ☐ | B29: Alerting thresholds defined and tuned
A30: ☐ | B30: Incident classification aligned with org severity matrix
A31: ☐ | B31: Escalation paths defined for cloud service incidents
A32: ☐ | B32: Vendor notification procedures documented
A33: ☐ | B33: Vendor incident response SLAs tracked
A34: ☐ | B34: Internal incident response playbooks exist per service
A35: ☐ | B35: Playbooks reviewed/updated after incidents
A36: ☐ | B36: Root cause analysis performed for P1/P2 incidents
A37: ☐ | B37: Lessons learned documented and shared
A38: ☐ | B38: Problem management process identifies recurring issues
A39: ☐ | B39: Known error database maintained for cloud services
... A61: ☐ | B61: AI-INC-06: Human oversight failures documented and remediated
A63: Checklist Compliance Score: | C63: =IF(COUNTA(C28:C61)=0,"N/A",ROUND(COUNTIF(C28:C61,"Yes")/COUNTIF(C28:C61,"<>N/A")*100,1)&"%")

Sheet 5. Business Continuity
A1: 5. BUSINESS CONTINUITY
A2: Policy Reference: BC/DR plans MUST exist for Critical/High services. Failover MUST be tested annually. RTO/RPO MUST be verified. (Policy Section 6.4)
A4: Cloud Service Name | B4: Vendor Name | C4: Service Type | D4: Review Period | E4: Service Criticality | F4: Data Classification | G4: BC Tier | H4: Status | I4: Evidence Location | J4: Gap Description | K4: Remediation Needed | L4: Exception ID | M4: Risk ID | N4: Compensating Controls | O4: Responsible Team/Owner | P4: Target Remediation Date | Q4: Last Review Date | R4: Last Test Date | S4: Test Result | T4: RTO Target (Hours) | U4: RTO Achieved (Hours) | V4: RPO Target (Hours) | W4: RPO Achieved (Hours) | X4: Next Test Due
A5: Example: Microsoft 365 | B5: Microsoft | C5: SaaS | D5: Q4 | E5: Critical | F5: Confidential | G5: Tier 1 (<4hr) | H5: ✅ Compliant | I5: /evidence/bcdr/M365 | K5: No | O5: IT Ops | Q5: 2025-11-15 | R5: 2025-11-15 | S5: Passed | T5: 4 | U5: 3.5 | V5: 1 | W5: 0.5 | X5: 2026-11-15
A26: BUSINESS CONTINUITY - COMPLIANCE CHECKLIST
A27: ☐ | B27: Requirement | C27: Status | D27: Notes/Evidence
A28: ☐ | B28: BC/DR plan documented for Critical/High services
A29: ☐ | B29: Vendor BC/DR capabilities verified and documented
A30: ☐ | B30: RTO requirements defined per service criticality
A31: ☐ | B31: RPO requirements defined per data classification
A32: ☐ | B32: Failover procedures documented and accessible
A33: ☐ | B33: Failover tested annually (minimum)
A34: ☐ | B34: Test results documented with evidence
A35: ☐ | B35: RTO achievement verified during tests
A36: ☐ | B36: RPO achievement verified during tests
A37: ☐ | B37: Data backup restoration tested
A38: ☐ | B38: Multi-region/availability zone strategy documented
A39: ☐ | B39: Single points of failure identified and mitigated
... A42: ☐ | B42: BC plan reviewed after significant changes
A44: Checklist Compliance Score: | C44: =IF(COUNTA(C28:C42)=0,"N/A",ROUND(COUNTIF(C28:C42,"Yes")/COUNTIF(C28:C42,"<>N/A")*100,1)&"%")

Sheet 6. Vendor Risk Monitoring
A1: 6. VENDOR RISK MONITORING
A2: Policy Reference: Cloud vendor risk MUST be monitored continuously. Security posture changes MUST trigger reassessment. (Policy Section 6.5)
A4: Cloud Service Name | B4: Vendor Name | C4: Service Type | D4: Review Period | E4: Service Criticality | F4: Data Classification | G4: Risk Rating | H4: Status | I4: Evidence Location | J4: Gap Description | K4: Remediation Needed | L4: Exception ID | M4: Risk ID | N4: Compensating Controls | O4: Responsible Team/Owner | P4: Target Remediation Date | Q4: Last Review Date | R4: Risk Score Trend | S4: Security Incidents (YTD) | T4: Cert Expiry Tracked | U4: Next Cert Expiry | V4: Financial Health | W4: Last Assessment Date | X4: Reassessment Trigger Met
A5: Example: Microsoft 365 | B5: Microsoft | C5: SaaS | D5: Q4 | E5: Critical | F5: Confidential | G5: Low | H5: ✅ Compliant | I5: /evidence/vendor/MSFT | K5: No | O5: Risk Management | Q5: 2025-10-01 | R5: Stable | S5: 0 | T5: Yes | U5: 2026-08-15 | V5: Strong | W5: 2025-10-01 | X5: No
A26: VENDOR RISK MONITORING - COMPLIANCE CHECKLIST
A27: ☐ | B27: Requirement | C27: Status | D27: Notes/Evidence
A28: ☐ | B28: Vendor risk assessment performed at onboarding
A29: ☐ | B29: Annual vendor risk reassessment scheduled
A30: ☐ | B30: Risk scoring methodology documented and consistent
A31: ☐ | B31: Security certifications tracked (ISO 27001, SOC 2, etc.)
A32: ☐ | B32: Certification expiry dates monitored with alerts
A33: ☐ | B33: Vendor security incidents monitored via news/feeds
A34: ☐ | B34: Vendor breach notification process documented
A35: ☐ | B35: Financial health indicators monitored for critical vendors
A36: ☐ | B36: Vendor concentration risk assessed
A37: ☐ | B37: Sub-processor changes tracked and assessed
A38: ☐ | B38: Geopolitical risk factors considered
A39: ☐ | B39: Vendor security questionnaire refreshed periodically
... A42: ☐ | B42: Vendor risk dashboard available to stakeholders
A44: Checklist Compliance Score: | C44: =IF(COUNTA(C28:C42)=0,"N/A",ROUND(COUNTIF(C28:C42,"Yes")/COUNTIF(C28:C42,"<>N/A")*100,1)&"%")

Sheet 7. Exit Strategy Review
A1: EXIT STRATEGY ANNUAL REVIEW & POC TESTING
A2: POL-S5 Section 8: Annual review required. DORA Art. 28.6: Annual PoC testing for critical ICT providers.
A3: Service Name | B3: Provider | C3: Criticality | D3: Exit Strategy Type (Current) | E3: Last Review Date | F3: Next Review Date | G3: Review Status | H3: PoC Testing Required? | I3: PoC Test Date (Last) | J3: PoC Test Result | K3: PoC Test Next Due | L3: Exit Strategy Changed? | M3: Reviewer Name | N3: Notes
A4: Microsoft 365 | B4: Microsoft | C4: Critical | D4: Cloud-to-Cloud | E4: 2025-08-06 | F4: 2026-08-06 | G4: Current | H4: Yes (Critical) | I4: 2025-12-04 | J4: Pass | K4: 2026-12-04 | L4: No | M4: J. Smith | N4: Annual review completed
A5: Azure Cloud Platform | B5: Microsoft | C5: Critical | D5: Hybrid | E5: 2025-08-06 | F5: 2026-08-06 | G5: Current | H5: Yes (Critical) | I5: 2025-12-04 | J5: Pass | K5: 2026-12-04 | L5: No | M5: J. Smith | N5: Annual review completed
A6: AWS S3 Storage | B6: Amazon | C6: High | D6: Cloud-to-Cloud | E6: 2025-08-06 | F6: 2026-08-06 | G6: Current | H6: No (Not Critical) | J6: Not Applicable | L6: No | M6: J. Smith | N6: Annual review completed
A7: Salesforce CRM | B7: Salesforce | C7: High | D7: Cloud-to-Cloud | E7: 2025-08-06 | F7: 2026-08-06 | G7: Current | H7: No (Not Critical) | J7: Not Applicable | L7: No | M7: J. Smith | N7: Annual review completed
A8: ServiceNow ITSM | B8: ServiceNow | C8: High | D8: Cloud-to-Cloud | E8: 2025-08-06 | F8: 2026-08-06 | G8: Current | H8: No (Not Critical) | J8: Not Applicable | L8: No | M8: J. Smith | N8: Annual review completed
A9: SAP S/4HANA Cloud | B9: SAP | C9: Critical | D9: Hybrid | E9: 2025-08-06 | F9: 2026-08-06 | G9: Current | H9: Yes (Critical) | I9: 2025-12-04 | J9: Pass | K9: 2026-12-04 | L9: No | M9: J. Smith | N9: Annual review completed
A10: Crowdstrike Falcon | B10: Crowdstrike | C10: Critical | D10: Cloud-to-Cloud | E10: 2025-08-06 | F10: 2026-08-06 | G10: Current | H10: Yes (Critical) | I10: 2025-12-04 | J10: Pass | K10: 2026-12-04 | L10: No | M10: J. Smith | N10: Annual review completed
A11: Slack Enterprise | B11: Salesforce | C11: Medium | D11: Cloud-to-Cloud | E11: 2025-08-06 | F11: 2026-08-06 | G11: Current | H11: No (Not Critical) | J11: Not Applicable | L11: No | M11: J. Smith | N11: Annual review completed
A105: EXIT STRATEGY REVIEW COMPLIANCE CHECKLIST
A106: 1. ✅ Exit strategy review completed for all Critical/High services (annual)
A107: 2. ✅ Review dates scheduled for all services
A108: 3. ✅ Review status tracked (Current/Overdue/In Progress)
A109: 4. ✅ PoC testing completed for Critical services (DORA Art. 28.6)
A110: 5. ✅ PoC test results documented (Pass/Fail)
A111: 6. ✅ PoC testing scheduled annually (12-month cycle)
A112: 7. ✅ Exit strategy changes documented with justification
A113: 8. ✅ On-Premises selections validated by CISO (TCO analysis)
A114: 9. ✅ Alternative providers still viable (market check)
A115: 10. ✅ Migration complexity reassessed (technology changes)
A116: 11. ✅ Lock-in risk status verified (new integrations?)
... A165: • ISMS-IMP-A.5.23.S1 Sheet 4 (Exit Strategy Assessment)

Sheet 8. Jurisdictional Risk
A1: JURISDICTIONAL RISK ASSESSMENT
A2: CLOUD Act, Data Sovereignty, and Cross-Border Transfer Analysis
A3: ⚠ US-headquartered providers may be compelled to disclose data under CLOUD Act regardless of data location.
A5: Assessment_ID | B5: Cloud_Service_Name | C5: Provider_Name | D5: Provider_HQ_Country | E5: Provider_HQ_Jurisdiction | F5: US_Parent_Company | G5: CLOUD_Act_Applicability | H5: Data_Processing_Locations | I5: EU_Data_Boundary_Available | J5: Customer_Managed_Keys | K5: Legal_Challenge_Commitment | L5: Adequacy_Decision_Status | M5: Transfer_Mechanism | N5: Risk_Level | O5: Risk_Accepted_By | P5: Risk_Acceptance_Date | Q5: Compensating_Controls | R5: Review_Date | S5: Evidence_Reference | T5: Notes
A6: =CONCATENATE("JRA-",TEXT(ROW()-5,"000"))
A7: =CONCATENATE("JRA-",TEXT(ROW()-5,"000"))
A8: =CONCATENATE("JRA-",TEXT(ROW()-5,"000"))
A9: =CONCATENATE("JRA-",TEXT(ROW()-5,"000"))
A10: =CONCATENATE("JRA-",TEXT(ROW()-5,"000"))
A11: =CONCATENATE("JRA-",TEXT(ROW()-5,"000"))
A12: =CONCATENATE("JRA-",TEXT(ROW()-5,"000"))
A13: =CONCATENATE("JRA-",TEXT(ROW()-5,"000"))
A14: =CONCATENATE("JRA-",TEXT(ROW()-5,"000"))
A15: =CONCATENATE("JRA-",TEXT(ROW()-5,"000"))
A16: =CONCATENATE("JRA-",TEXT(ROW()-5,"000"))
A17: =CONCATENATE("JRA-",TEXT(ROW()-5,"000"))
... A30: =CONCATENATE("JRA-",TEXT(ROW()-5,"000"))
A33: JURISDICTIONAL RISK CHECKLIST
A34: ☐ | B34: Requirement | C34: Evidence
A35: ☐ | B35: Provider HQ jurisdiction identified and documented
A36: ☐ | B36: US parent company status verified
A37: ☐ | B37: CLOUD Act exposure assessed for US-nexus providers
A38: ☐ | B38: Data processing locations documented in DPA
A39: ☐ | B39: EU Data Boundary availability checked
A40: ☐ | B40: Customer-managed encryption keys option evaluated
A41: ☐ | B41: Legal challenge commitment verified
A42: ☐ | B42: Transfer mechanism documented (SCCs, BCRs, etc.)
A43: ☐ | B43: Risk acceptance recorded if residual risk remains
A44: ☐ | B44: Compensating controls documented for high-risk providers

Sheet 9. Summary Dashboard
A1: ONGOING GOVERNANCE & RISK - COMPLIANCE SUMMARY DASHBOARD v1.0
A3: TABLE 1: COMPLIANCE SUMMARY BY ASSESSMENT AREA
A4: Assessment Area | B4: Total Items | C4: Compliant | D4: Partial | E4: Non-Compliant | F4: N/A | G4: Compliance %
A5: 2. Access Review | B5: =COUNTA('2. Access Review'!A6:A24) | C5: =COUNTIF('2. Access Review'!H6:H24,"✅ Compliant") | D5: =COUNTIF('2. Access Review'!H6:H24,"⚠ Partial") | E5: =COUNTIF('2. Access Review'!H6:H24,"❌ Non-Compliant") | F5: =COUNTIF('2. Access Review'!H6:H24,"N/A") | G5: =IF(B5-F5=0,"N/A",ROUND(C5/(B5-F5)*100,1)&"%")
A6: 3. Change Management | B6: =COUNTA('3. Change Management'!A6:A24) | C6: =COUNTIF('3. Change Management'!H6:H24,"✅ Compliant") | D6: =COUNTIF('3. Change Management'!H6:H24,"⚠ Partial") | E6: =COUNTIF('3. Change Management'!H6:H24,"❌ Non-Compliant") | F6: =COUNTIF('3. Change Management'!H6:H24,"N/A") | G6: =IF(B6-F6=0,"N/A",ROUND(C6/(B6-F6)*100,1)&"%")
A7: 4. Incident Management | B7: =COUNTA('4. Incident Management'!A6:A24) | C7: =COUNTIF('4. Incident Management'!H6:H24,"✅ Compliant") | D7: =COUNTIF('4. Incident Management'!H6:H24,"⚠ Partial") | E7: =COUNTIF('4. Incident Management'!H6:H24,"❌ Non-Compliant") | F7: =COUNTIF('4. Incident Management'!H6:H24,"N/A") | G7: =IF(B7-F7=0,"N/A",ROUND(C7/(B7-F7)*100,1)&"%")
A8: 5. Business Continuity | B8: =COUNTA('5. Business Continuity'!A6:A24) | C8: =COUNTIF('5. Business Continuity'!H6:H24,"✅ Compliant") | D8: =COUNTIF('5. Business Continuity'!H6:H24,"⚠ Partial") | E8: =COUNTIF('5. Business Continuity'!H6:H24,"❌ Non-Compliant") | F8: =COUNTIF('5. Business Continuity'!H6:H24,"N/A") | G8: =IF(B8-F8=0,"N/A",ROUND(C8/(B8-F8)*100,1)&"%")
A9: 6. Vendor Risk Monitoring | B9: =COUNTA('6. Vendor Risk Monitoring'!A6:A24) | C9: =COUNTIF('6. Vendor Risk Monitoring'!H6:H24,"✅ Compliant") | D9: =COUNTIF('6. Vendor Risk Monitoring'!H6:H24,"⚠ Partial") | E9: =COUNTIF('6. Vendor Risk Monitoring'!H6:H24,"❌ Non-Compliant") | F9: =COUNTIF('6. Vendor Risk Monitoring'!H6:H24,"N/A") | G9: =IF(B9-F9=0,"N/A",ROUND(C9/(B9-F9)*100,1)&"%")
A10: TOTAL | B10: =SUM(B5:B9) | C10: =SUM(C5:C9) | D10: =SUM(D5:D9) | E10: =SUM(E5:E9) | F10: =SUM(F5:F9) | G10: =IF(B10-F10=0,"N/A",ROUND(C10/(B10-F10)*100,1)&"%")
A13: TABLE 2: JURISDICTIONAL & CLOUD ACT RISK SUMMARY
A14: Metric | B14: Count | C14: Status
A15: US-HQ Providers (CLOUD Act Scope) | B15: =COUNTIF('8. Jurisdictional Risk'!E6:E30,"United States") | C15: =IF(B15>0,"{WARNING} Review","{CHECK} OK")
A16: Providers with US Parent Company | B16: =COUNTIF('8. Jurisdictional Risk'!F6:F30,"Yes") | C16: =IF(B16>0,"{WARNING} Review","{CHECK} OK")
A17: CLOUD Act Potential Exposure (Unmitigated) | B17: =COUNTIF('8. Jurisdictional Risk'!G6:G30,"Potential*") | C17: =IF(B17>0,"{WARNING} Review","{CHECK} OK")
A18: CLOUD Act Mitigated | B18: =COUNTIFS('8. Jurisdictional Risk'!G6:G30,"Mitigated*") | C18: Info
A19: High/Critical Jurisdictional Risk | B19: =COUNTIF('8. Jurisdictional Risk'!N6:N30,"High")+COUNTIF('8. Jurisdictional Risk'!N6:N30,"Critical") | C19: =IF(B19>0,"{XMARK} Action","{CHECK} OK")
A20: Providers Without EU Data Boundary | B20: =COUNTIF('8. Jurisdictional Risk'!I6:I30,"No") | C20: =IF(B20>0,"{WARNING} Review","{CHECK} OK")
A21: Providers Without Customer-Managed Keys | B21: =COUNTIF('8. Jurisdictional Risk'!J6:J30,"No") | C21: =IF(B21>0,"{WARNING} Review","{CHECK} OK")
A24: TABLE 3: REGULATORY RISK MONITORING STATUS
A25: Metric | B25: Count | C25: Status
A26: DORA Risks Not Monitored | B26: =COUNTIF('4. Incident Management'!Y6:Y30,"Not Monitored") | C26: =IF(B26>0,"{XMARK} Action","{CHECK} OK")
A27: NIS2 Significant Incidents (Require ≤24h notification) | B27: =COUNTIF('4. Incident Management'!Z6:Z30,"Significant*") | C27: =IF(B27>0,"{WARNING} Review","{CHECK} OK")
A28: AI Systems Requiring Active Monitoring | B28: =COUNTIF('4. Incident Management'!AA6:AA30,"Active Monitoring") | C28: Info
A29: Regulatory Risks Without Assigned Owner | B29: =COUNTIF('4. Incident Management'!AB6:AB30,"") | C29: =IF(B29>0,"{XMARK} Action","{CHECK} OK")
A33: KEY GOVERNANCE METRICS
A34: Total Cloud Services Assessed: | C34: =B10
A35: Services Requiring Remediation: | C35: =COUNTIF('2. Access Review'!K6:K24,"Yes")+COUNTIF('3. Change Management'!K6:K24,"Yes")+COUNTIF('4. Incident Management'!K6:K24,"Yes")+COUNTIF('5. Business Continuity'!K6:K24,"Yes")+COUNTIF('6. Vendor Risk Monitoring'!K6:K24,"Yes")
A36: Access Reviews Overdue: | C36: =COUNTIF('2. Access Review'!S6:S24,"Overdue")
A37: Open P1/P2 Incidents: | C37: =COUNTIF('4. Incident Management'!G6:G24,"P1-Critical")+COUNTIF('4. Incident Management'!G6:G24,"P2-High")
A38: BC Tests Overdue: | C38: =COUNTIF('5. Business Continuity'!S6:S24,"Not Tested")
A39: High/Critical Risk Vendors: | C39: =COUNTIF('6. Vendor Risk Monitoring'!G6:G24,"Critical")+COUNTIF('6. Vendor Risk Monitoring'!G6:G24,"High")
A42: OVERALL GOVERNANCE HEALTH SCORE
A43: Score: | B43: =G10
A44: Rating: | B44: =IF(G10="N/A","Not Assessed",IF(VALUE(SUBSTITUTE(G10,"%",""))>=90,"Excellent",IF(VALUE(SUBSTITUTE(G10,"%",""))>=75,"Good",IF(VALUE(SUBSTITUTE(G10,"%",""))>=60,"Needs Improvement","Critical"))))

Sheet 10. Evidence Register
A1: EVIDENCE REGISTER - ONGOING GOVERNANCE & RISK v1.0
A2: Audit trail for governance assessments - Evidence ID Format: EV-OGR-###
A4: Evidence ID | B4: Assessment Area | C4: Cloud Service | D4: Evidence Type | E4: Description | F4: Location/Path | G4: Date Collected | H4: Collected By | I4: Verification Status
A5: EV-OGR-001
A6: EV-OGR-002
A7: EV-OGR-003
A8: EV-OGR-004
A9: EV-OGR-005
A10: EV-OGR-006
A11: EV-OGR-007
A12: EV-OGR-008
A13: EV-OGR-009
A14: EV-OGR-010
A15: EV-OGR-011
A16: EV-OGR-012
... A124: EV-OGR-120

Sheet 11. Approval Sign-Of
A1: ASSESSMENT APPROVAL AND SIGN-OFF v1.0
A3: ASSESSMENT SUMMARY
A4: Assessment Document: | B4: ISMS-IMP-A.5.23.S4 - Ongoing Governance & Risk Management v1.0
A5: Assessment Period: | B5: [ENTER PERIOD - e.g., Q4 2025]
A6: Overall Compliance Rate: | B6: ='9. Summary Dashboard'!G10
A7: Jurisdictional Risks Identified: | B7: ='9. Summary Dashboard'!B20
A8: DORA Risks Not Monitored: | B8: ='9. Summary Dashboard'!B28
A9: NIS2 Significant Incidents: | B9: ='9. Summary Dashboard'!B29
A10: AI Monitoring Required: | B10: ='9. Summary Dashboard'!B30
A11: Assessment Status: | B11: [SELECT STATUS]
A14: COMPLETED BY (ASSESSOR)
A15: Name:
A16: Title:
A17: Department:
A18: Date:
A19: Signature:
A20: Comments:
A22: REVIEWED BY (IT OPERATIONS MANAGER)
A23: Name:
A24: Title:
A25: Department:
A26: Date:
... A67: Decision:
