Workbook

Sheet Executive Summary
A1: ISMS-OP-CHK-A.5.3 — Segregation of Duties Compliance Checklist
A3: DOCUMENT INFORMATION
A4: Document ID | B4: ISMS-OP-CHK-A.5.3
A5: Source Policy | B5: ISMS-OP-POL-A.5.3
A6: ISO Controls | B6: Segregation of Duties
A7: Generated | B7: 08.02.2026
A8: Prepared By
A9: Organisation
A10: Review Cycle | B10: Annual
A12: OVERALL COMPLIANCE STATUS
A13: Overall Compliance | B13: ='Dashboard'!G10
A14: Status | B14: =IF(Dashboard!G10="N/A","NOT ASSESSED",IF(ISNUMBER(VALUE(SUBSTITUTE(Dashboard!G10,"%",""))),IF(VALUE(SUBSTITUTE(Dashboard!G10,"%",""))>=90,"GREEN",IF(VALUE(SUBSTITUTE(Dashboard!G10,"%",""))>=70,"AMBER","RED")),"NOT ASSESSED"))
A16: KEY METRICS
A17: Total Requirements | B17: ='Dashboard'!B10
A18: Compliant | B18: ='Dashboard'!C10
A19: Partial | B19: ='Dashboard'!D10
A20: Non-Compliant | B20: ='Dashboard'!E10
A21: Not Applicable | B21: ='Dashboard'!F10
A22: Owner Coverage | B22: =IF(Dashboard!B10=0,"N/A",ROUND((COUNTA('Conflicting Duties Ident'!F4:F10)+COUNTA('Small Team & SME Comp Controls'!F4:F12)+COUNTA('Technical Segregation Controls'!F4:F15)+COUNTA('Exception Management'!F4:F9)+COUNTA('SoD Matrix Maintenance'!F4:F6)+COUNTA('Compliance Measurement'!F4:F5))/Dashboard!B10*100,0)&"%")
A24: DOMAIN STATUS SUMMARY
A25: Domain | B25: Compliance % | C25: Compliant | D25: Gaps | E25: Status
A26: Conflicting Duties Ident | B26: ='Dashboard'!G4 | C26: ='Dashboard'!C4 | D26: ='Dashboard'!E4 | E26: =IF(Dashboard!G4="N/A","--",IF(ISNUMBER(VALUE(SUBSTITUTE(Dashboard!G4,"%",""))),IF(VALUE(SUBSTITUTE(Dashboard!G4,"%",""))>=90,"PASS",IF(VALUE(SUBSTITUTE(Dashboard!G4,"%",""))>=70,"REVIEW","FAIL")),"--"))
A27: Small Team & SME Comp Controls | B27: ='Dashboard'!G5 | C27: ='Dashboard'!C5 | D27: ='Dashboard'!E5 | E27: =IF(Dashboard!G5="N/A","--",IF(ISNUMBER(VALUE(SUBSTITUTE(Dashboard!G5,"%",""))),IF(VALUE(SUBSTITUTE(Dashboard!G5,"%",""))>=90,"PASS",IF(VALUE(SUBSTITUTE(Dashboard!G5,"%",""))>=70,"REVIEW","FAIL")),"--"))
A28: Technical Segregation Controls | B28: ='Dashboard'!G6 | C28: ='Dashboard'!C6 | D28: ='Dashboard'!E6 | E28: =IF(Dashboard!G6="N/A","--",IF(ISNUMBER(VALUE(SUBSTITUTE(Dashboard!G6,"%",""))),IF(VALUE(SUBSTITUTE(Dashboard!G6,"%",""))>=90,"PASS",IF(VALUE(SUBSTITUTE(Dashboard!G6,"%",""))>=70,"REVIEW","FAIL")),"--"))
A29: Exception Management | B29: ='Dashboard'!G7 | C29: ='Dashboard'!C7 | D29: ='Dashboard'!E7 | E29: =IF(Dashboard!G7="N/A","--",IF(ISNUMBER(VALUE(SUBSTITUTE(Dashboard!G7,"%",""))),IF(VALUE(SUBSTITUTE(Dashboard!G7,"%",""))>=90,"PASS",IF(VALUE(SUBSTITUTE(Dashboard!G7,"%",""))>=70,"REVIEW","FAIL")),"--"))
A30: SoD Matrix Maintenance | B30: ='Dashboard'!G8 | C30: ='Dashboard'!C8 | D30: ='Dashboard'!E8 | E30: =IF(Dashboard!G8="N/A","--",IF(ISNUMBER(VALUE(SUBSTITUTE(Dashboard!G8,"%",""))),IF(VALUE(SUBSTITUTE(Dashboard!G8,"%",""))>=90,"PASS",IF(VALUE(SUBSTITUTE(Dashboard!G8,"%",""))>=70,"REVIEW","FAIL")),"--"))
A31: Compliance Measurement | B31: ='Dashboard'!G9 | C31: ='Dashboard'!C9 | D31: ='Dashboard'!E9 | E31: =IF(Dashboard!G9="N/A","--",IF(ISNUMBER(VALUE(SUBSTITUTE(Dashboard!G9,"%",""))),IF(VALUE(SUBSTITUTE(Dashboard!G9,"%",""))>=90,"PASS",IF(VALUE(SUBSTITUTE(Dashboard!G9,"%",""))>=70,"REVIEW","FAIL")),"--"))
A33: CRITICAL ISSUES
A34: # | B34: Issue Description | C34: Domain | D34: Owner | E34: Due Date
A35: 1
A36: 2
A37: 3
A38: 4
A39: 5
A41: MANAGEMENT COMMENTARY
A42: [Enter management commentary on segregation of duties posture]
A46: APPROVAL
A47: Assessed By
A48: Name:
A49: Date:
...

Sheet Dashboard
A1: Segregation of Duties — Compliance Dashboard
A3: Domain | B3: Total Reqs | C3: Compliant | D3: Partial | E3: Non-Compliant | F3: N/A | G3: Compliance %
A4: Conflicting Duties Ident | B4: =COUNTA('Conflicting Duties Ident'!D4:D10) | C4: =COUNTIF('Conflicting Duties Ident'!D4:D10,"Compliant") | D4: =COUNTIF('Conflicting Duties Ident'!D4:D10,"Partial") | E4: =COUNTIF('Conflicting Duties Ident'!D4:D10,"Non-Compliant") | F4: =COUNTIF('Conflicting Duties Ident'!D4:D10,"N/A") | G4: =IF((B4-F4)=0,"N/A",ROUND(C4/(B4-F4)*100,1)&"%")
A5: Small Team & SME Comp Controls | B5: =COUNTA('Small Team & SME Comp Controls'!D4:D12) | C5: =COUNTIF('Small Team & SME Comp Controls'!D4:D12,"Compliant") | D5: =COUNTIF('Small Team & SME Comp Controls'!D4:D12,"Partial") | E5: =COUNTIF('Small Team & SME Comp Controls'!D4:D12,"Non-Compliant") | F5: =COUNTIF('Small Team & SME Comp Controls'!D4:D12,"N/A") | G5: =IF((B5-F5)=0,"N/A",ROUND(C5/(B5-F5)*100,1)&"%")
A6: Technical Segregation Controls | B6: =COUNTA('Technical Segregation Controls'!D4:D15) | C6: =COUNTIF('Technical Segregation Controls'!D4:D15,"Compliant") | D6: =COUNTIF('Technical Segregation Controls'!D4:D15,"Partial") | E6: =COUNTIF('Technical Segregation Controls'!D4:D15,"Non-Compliant") | F6: =COUNTIF('Technical Segregation Controls'!D4:D15,"N/A") | G6: =IF((B6-F6)=0,"N/A",ROUND(C6/(B6-F6)*100,1)&"%")
A7: Exception Management | B7: =COUNTA('Exception Management'!D4:D9) | C7: =COUNTIF('Exception Management'!D4:D9,"Compliant") | D7: =COUNTIF('Exception Management'!D4:D9,"Partial") | E7: =COUNTIF('Exception Management'!D4:D9,"Non-Compliant") | F7: =COUNTIF('Exception Management'!D4:D9,"N/A") | G7: =IF((B7-F7)=0,"N/A",ROUND(C7/(B7-F7)*100,1)&"%")
A8: SoD Matrix Maintenance | B8: =COUNTA('SoD Matrix Maintenance'!D4:D6) | C8: =COUNTIF('SoD Matrix Maintenance'!D4:D6,"Compliant") | D8: =COUNTIF('SoD Matrix Maintenance'!D4:D6,"Partial") | E8: =COUNTIF('SoD Matrix Maintenance'!D4:D6,"Non-Compliant") | F8: =COUNTIF('SoD Matrix Maintenance'!D4:D6,"N/A") | G8: =IF((B8-F8)=0,"N/A",ROUND(C8/(B8-F8)*100,1)&"%")
A9: Compliance Measurement | B9: =COUNTA('Compliance Measurement'!D4:D5) | C9: =COUNTIF('Compliance Measurement'!D4:D5,"Compliant") | D9: =COUNTIF('Compliance Measurement'!D4:D5,"Partial") | E9: =COUNTIF('Compliance Measurement'!D4:D5,"Non-Compliant") | F9: =COUNTIF('Compliance Measurement'!D4:D5,"N/A") | G9: =IF((B9-F9)=0,"N/A",ROUND(C9/(B9-F9)*100,1)&"%")
A10: TOTAL | B10: =SUM(B4:B9) | C10: =SUM(C4:C9) | D10: =SUM(D4:D9) | E10: =SUM(E4:E9) | F10: =SUM(F4:F9) | G10: =IF((B10-F10)=0,"N/A",ROUND(C10/(B10-F10)*100,1)&"%")
A12: COMPLIANCE BY STATUS
A13: Compliant | B13: =C10 | C13: =IF(B10=0,"",ROUND(B13/B10*100,1)&"%")
A14: Partial | B14: =D10 | C14: =IF(B10=0,"",ROUND(B14/B10*100,1)&"%")
A15: Non-Compliant | B15: =E10 | C15: =IF(B10=0,"",ROUND(B15/B10*100,1)&"%")
A16: N/A | B16: =F10 | C16: =IF(B10=0,"",ROUND(B16/B10*100,1)&"%")
A18: TOP GAPS (Manual Entry)
A19: Priority | B19: Domain | C19: Requirement | D19: Owner | E19: Due Date | F19: Status
A31: COMPLIANCE TREND (Manual Entry)
A32: Assessment Date | B32: Overall % | C32: Compliant | D32: Gaps | E32: Assessor | F32: Notes

Sheet Conflicting Duties Ident
A1: Conflicting Duties Ident — Compliance Checklist
A2: ISO/IEC 27001:2022 — Control A.5.3: Segregation of Duties
A3: Req # | B3: Section | C3: Requirement | D3: Status | E3: Evidence | F3: Owner | G3: Due Date | H3: Notes
A4: A.5.3-01 | B4: Maintain A Documented Sod Matrix | C4: The organisation shall maintain a documented SoD matrix identifying duty combinations that require segregation. The following categories provide the baseline:.
A5: A.5.3-02 | B5: The Following Duty Combinations | C5: The following duty combinations shall be segregated:.
A6: A.5.3-03 | B6: The Following Duty Combinations | C6: The following duty combinations shall be segregated:.
A7: A.5.3-04 | B7: The Following Duty Combinations | C7: The following duty combinations shall be segregated:.
A8: A.5.3-05 | B8: The Following Duty Combinations | C8: The following duty combinations shall be segregated:.
A9: A.5.3-06 | B9: Department Heads | C9: Department heads shall review the SoD matrix annually for their area and report any newly identified conflicts to the CISO. The CISO shall maintain the consolidated organisational SoD matrix in [GRC Tool] or equivalent register.
A10: A.5.3-07 | B10: > Where A Dedicated Grc Tool | C10: > Where a dedicated GRC tool is not yet deployed, the organisation shall maintain registers in controlled shared storage with version control, access logging, and quarterly integrity verification by the CISO.

Sheet Small Team & SME Comp Controls
A1: Small Team & SME Comp Controls — Compliance Checklist
A2: ISO/IEC 27001:2022 — Control A.5.3: Segregation of Duties
A3: Req # | B3: Section | C3: Requirement | D3: Status | E3: Evidence | F3: Owner | G3: Due Date | H3: Notes
A4: A.5.3-08 | B4: Where Segregation Cannot Be Fully | C4: Where segregation cannot be fully achieved due to limited personnel — a common situation in small and medium-sized organisations — compensating controls shall be implemented to provide equivalent risk mitigation.
A5: A.5.3-09 | B5: All Five Of The Following Compensating | C5: When full duty segregation is not feasible, all five of the following compensating controls shall be implemented for each identified conflict:.
A6: A.5.3-10 | B6: An Independent Party | C6: An independent party shall review the process quarterly at minimum. The review shall include:.
A7: A.5.3-11 | B7: Review Documentation*: Each Quarterly | C7: Review documentation*: Each quarterly review shall produce a written report documenting scope, findings, issues identified, and recommendations. Reports retained for 3 years.
A8: A.5.3-12 | B8: Issue Escalation*: Issues Identified | C8: Issue escalation*: Issues identified during independent review shall be escalated to the CISO within 5 business days and resolved within 30 calendar days.
A9: A.5.3-13 | B9: Compensating Control Arrangement | C9: Each compensating control arrangement shall be formally documented with:.
A10: A.5.3-14 | B10: Compensating Control Documentation | C10: Compensating control documentation shall be maintained in [GRC Tool] or an equivalent register accessible to the CISO and Internal Audit.
A11: A.5.3-15 | B11: Compensating Control Arrangements | C11: Compensating control arrangements shall be re-evaluated when:.
A12: A.5.3-16 | B12: The Effectiveness Of Compensating | C12: The effectiveness of compensating controls shall be verified through:.

Sheet Technical Segregation Controls
A1: Technical Segregation Controls — Compliance Checklist
A2: ISO/IEC 27001:2022 — Control A.5.3: Segregation of Duties
A3: Req # | B3: Section | C3: Requirement | D3: Status | E3: Evidence | F3: Owner | G3: Due Date | H3: Notes
A4: A.5.3-17 | B4: Information Systems Supporting | C4: Information systems supporting segregated processes shall implement the following technical controls:.
A5: A.5.3-18 | B5: Role-Based Access Control (Rbac): Roles | C5: Role-based access control (RBAC): Roles shall be defined in the identity provider or application to enforce duty separation. Conflicting roles shall be documented as mutually exclusive.
A6: A.5.3-19 | B6: Mutual Exclusion Constraints: The Access | C6: Mutual exclusion constraints: The access control system ([Identity Provider / ERP / HR System]) shall prevent a single user from holding conflicting roles simultaneously. Where the system does not natively support mutual exclusion, a manual review shall be conducted at every access provisioning event.
A7: A.5.3-20 | B7: Workflow Controls: Multi-Step Business | C7: Workflow controls: Multi-step business processes shall require different authorised individuals at each approval stage. Self-approval shall be technically blocked where feasible and prohibited by policy in all cases.
A8: A.5.3-21 | B8: Privileged Access Management: Privileged | C8: Privileged access management: Privileged accounts shall be separate from standard accounts. No individual shall approve their own elevated access requests.
A9: A.5.3-22 | B9: Automated Systems: Mutual Exclusion | C9: Automated systems: Mutual exclusion constraints shall be tested annually by attempting to assign conflicting roles to a test user and verifying the system blocks the assignment. Test results documented.
A10: A.5.3-23 | B10: Manual Review Systems: Access | C10: Manual review systems: Access provisioning checklists shall include SoD conflict check with documented verification before access grant. Provisioner shall reference SoD matrix and confirm no conflicts.
A11: A.5.3-24 | B11: Quarterly Access Review: All User Role | C11: Quarterly access review: All user role assignments shall be compared against SoD matrix to detect any conflicts that bypassed provisioning controls. Findings resolved within 30 calendar days.
A12: A.5.3-25 | B12: Immutable Logging: All Activities In | C12: Immutable logging: All activities in segregated processes shall be logged to a centralised logging platform ([SIEM] or equivalent) that the process participants cannot modify or delete.
A13: A.5.3-26 | B13: Actor Identification: Logs | C13: Actor identification: Logs shall clearly identify the individual performing each action at every stage of the process.
A14: A.5.3-27 | B14: Timestamp And Action Recording: All | C14: Timestamp and action recording: All approvals, modifications, and process completions shall be recorded with accurate timestamps.
A15: A.5.3-28 | B15: Log Protection: Audit Logs | C15: Log protection: Audit logs shall be protected against modification or deletion per the Logging and Monitoring Policy. Acceptable implementations include write-once storage, restricted administrator access with separate log reviewer, retention locks, or centralised log aggregation with integrity verification.

Sheet Exception Management
A1: Exception Management — Compliance Checklist
A2: ISO/IEC 27001:2022 — Control A.5.3: Segregation of Duties
A3: Req # | B3: Section | C3: Requirement | D3: Status | E3: Evidence | F3: Owner | G3: Due Date | H3: Notes
A4: A.5.3-29 | B4: Exceptions To Segregation Requirements | C4: Exceptions to segregation requirements shall be managed through a formal process. Self-approval of segregation exceptions is never permitted.
A5: A.5.3-30 | B5: Full Review Within 24 Hours Of | C5: Full review within 24 hours of exception end — the CISO or delegate shall verify that compensating controls were effective and no irregularities occurred. Review sign-off documented.
A6: A.5.3-31 | B6: Emergency Exception Log*: All Emergency | C6: Emergency exception log*: All emergency exceptions shall be logged in the Exception Register with 'Emergency' flag.
A7: A.5.3-32 | B7: The Following Exceptions | C7: The following exceptions shall not be granted under any circumstances:.
A8: A.5.3-33 | B8: Be Recorded In The Exception Register | C8: All exceptions shall be recorded in the Exception Register maintained in [GRC Tool] or equivalent. Each record shall include:.
A9: A.5.3-34 | B9: The Ciso | C9: The CISO shall review the Exception Register monthly and report active exceptions to Executive Management quarterly.

Sheet SoD Matrix Maintenance
A1: SoD Matrix Maintenance — Compliance Checklist
A2: ISO/IEC 27001:2022 — Control A.5.3: Segregation of Duties
A3: Req # | B3: Section | C3: Requirement | D3: Status | E3: Evidence | F3: Owner | G3: Due Date | H3: Notes
A4: A.5.3-35 | B4: The Organisational Sod Matrix | C4: The organisational SoD matrix shall be reviewed and updated annually. The review shall:.
A5: A.5.3-36 | B5: It Operations | C5: IT Operations shall generate access reports quarterly from the identity provider and application access systems. The CISO shall compare these reports against the SoD matrix to verify:.
A6: A.5.3-37 | B6: Be Documented And Conflicts Resolved | C6: Findings shall be documented and conflicts resolved within 30 calendar days of discovery.

Sheet Compliance Measurement
A1: Compliance Measurement — Compliance Checklist
A2: ISO/IEC 27001:2022 — Control A.5.3: Segregation of Duties
A3: Req # | B3: Section | C3: Requirement | D3: Status | E3: Evidence | F3: Owner | G3: Due Date | H3: Notes
A4: A.5.3-38 | B4: The Following Metrics | C4: The following metrics shall be tracked and reported to the CISO quarterly:.
A5: A.5.3-39 | B5: Metrics Breaching Red Thresholds | C5: Metrics breaching red thresholds shall be escalated to the CISO for immediate attention and reported at the next Management Review.
