Workbook

Sheet Executive Summary
A1: ISMS-OP-CHK-A.8.32 — Change Management Compliance Checklist
A3: DOCUMENT INFORMATION
A4: Document ID | B4: ISMS-OP-CHK-A.8.32
A5: Source Policy | B5: ISMS-OP-POL-A.8.32
A6: ISO Controls | B6: Change Management
A7: Generated | B7: 08.02.2026
A8: Prepared By
A9: Organisation
A10: Review Cycle | B10: Annual
A12: OVERALL COMPLIANCE STATUS
A13: Overall Compliance | B13: ='Dashboard'!G19
A14: Status | B14: =IF(Dashboard!G19="N/A","NOT ASSESSED",IF(ISNUMBER(VALUE(SUBSTITUTE(Dashboard!G19,"%",""))),IF(VALUE(SUBSTITUTE(Dashboard!G19,"%",""))>=90,"GREEN",IF(VALUE(SUBSTITUTE(Dashboard!G19,"%",""))>=70,"AMBER","RED")),"NOT ASSESSED"))
A16: KEY METRICS
A17: Total Requirements | B17: ='Dashboard'!B19
A18: Compliant | B18: ='Dashboard'!C19
A19: Partial | B19: ='Dashboard'!D19
A20: Non-Compliant | B20: ='Dashboard'!E19
A21: Not Applicable | B21: ='Dashboard'!F19
A22: Owner Coverage | B22: =IF(Dashboard!B19=0,"N/A",ROUND((COUNTA('Change Classification'!F4:F5)+COUNTA('Change Request Process'!F4:F8)+COUNTA('Change Advisory Board (CAB)'!F4:F5)+COUNTA('Standard Change Catalogue'!F4:F6)+COUNTA('Testing and Validation'!F4:F14)+COUNTA('Implementation and Rollback'!F4:F9)+COUNTA('Communication'!F4:F4)+COUNTA('Emergency Changes'!F4:F7)+COUNTA('Post-Impl Review (PIR)'!F4:F4)+COUNTA('Change Freeze Periods'!F4:F4)+COUNTA('Record Keeping & Documentation'!F4:F6)+COUNTA('Configuration Mgmt Integration'!F4:F6)+COUNTA('Unauthorised Changes'!F4:F4)+COUNTA('Change-Incident Correlation'!F4:F5)+COUNTA('Change Management Metrics'!F4:F5))/Dashboard!B19*100,0)&"%")
A24: DOMAIN STATUS SUMMARY
A25: Domain | B25: Compliance % | C25: Compliant | D25: Gaps | E25: Status
A26: Change Classification | B26: ='Dashboard'!G4 | C26: ='Dashboard'!C4 | D26: ='Dashboard'!E4 | E26: =IF(Dashboard!G4="N/A","--",IF(ISNUMBER(VALUE(SUBSTITUTE(Dashboard!G4,"%",""))),IF(VALUE(SUBSTITUTE(Dashboard!G4,"%",""))>=90,"PASS",IF(VALUE(SUBSTITUTE(Dashboard!G4,"%",""))>=70,"REVIEW","FAIL")),"--"))
A27: Change Request Process | B27: ='Dashboard'!G5 | C27: ='Dashboard'!C5 | D27: ='Dashboard'!E5 | E27: =IF(Dashboard!G5="N/A","--",IF(ISNUMBER(VALUE(SUBSTITUTE(Dashboard!G5,"%",""))),IF(VALUE(SUBSTITUTE(Dashboard!G5,"%",""))>=90,"PASS",IF(VALUE(SUBSTITUTE(Dashboard!G5,"%",""))>=70,"REVIEW","FAIL")),"--"))
A28: Change Advisory Board (CAB) | B28: ='Dashboard'!G6 | C28: ='Dashboard'!C6 | D28: ='Dashboard'!E6 | E28: =IF(Dashboard!G6="N/A","--",IF(ISNUMBER(VALUE(SUBSTITUTE(Dashboard!G6,"%",""))),IF(VALUE(SUBSTITUTE(Dashboard!G6,"%",""))>=90,"PASS",IF(VALUE(SUBSTITUTE(Dashboard!G6,"%",""))>=70,"REVIEW","FAIL")),"--"))
A29: Standard Change Catalogue | B29: ='Dashboard'!G7 | C29: ='Dashboard'!C7 | D29: ='Dashboard'!E7 | E29: =IF(Dashboard!G7="N/A","--",IF(ISNUMBER(VALUE(SUBSTITUTE(Dashboard!G7,"%",""))),IF(VALUE(SUBSTITUTE(Dashboard!G7,"%",""))>=90,"PASS",IF(VALUE(SUBSTITUTE(Dashboard!G7,"%",""))>=70,"REVIEW","FAIL")),"--"))
A30: Testing and Validation | B30: ='Dashboard'!G8 | C30: ='Dashboard'!C8 | D30: ='Dashboard'!E8 | E30: =IF(Dashboard!G8="N/A","--",IF(ISNUMBER(VALUE(SUBSTITUTE(Dashboard!G8,"%",""))),IF(VALUE(SUBSTITUTE(Dashboard!G8,"%",""))>=90,"PASS",IF(VALUE(SUBSTITUTE(Dashboard!G8,"%",""))>=70,"REVIEW","FAIL")),"--"))
A31: Implementation and Rollback | B31: ='Dashboard'!G9 | C31: ='Dashboard'!C9 | D31: ='Dashboard'!E9 | E31: =IF(Dashboard!G9="N/A","--",IF(ISNUMBER(VALUE(SUBSTITUTE(Dashboard!G9,"%",""))),IF(VALUE(SUBSTITUTE(Dashboard!G9,"%",""))>=90,"PASS",IF(VALUE(SUBSTITUTE(Dashboard!G9,"%",""))>=70,"REVIEW","FAIL")),"--"))
A32: Communication | B32: ='Dashboard'!G10 | C32: ='Dashboard'!C10 | D32: ='Dashboard'!E10 | E32: =IF(Dashboard!G10="N/A","--",IF(ISNUMBER(VALUE(SUBSTITUTE(Dashboard!G10,"%",""))),IF(VALUE(SUBSTITUTE(Dashboard!G10,"%",""))>=90,"PASS",IF(VALUE(SUBSTITUTE(Dashboard!G10,"%",""))>=70,"REVIEW","FAIL")),"--"))
A33: Emergency Changes | B33: ='Dashboard'!G11 | C33: ='Dashboard'!C11 | D33: ='Dashboard'!E11 | E33: =IF(Dashboard!G11="N/A","--",IF(ISNUMBER(VALUE(SUBSTITUTE(Dashboard!G11,"%",""))),IF(VALUE(SUBSTITUTE(Dashboard!G11,"%",""))>=90,"PASS",IF(VALUE(SUBSTITUTE(Dashboard!G11,"%",""))>=70,"REVIEW","FAIL")),"--"))
A34: Post-Impl Review (PIR) | B34: ='Dashboard'!G12 | C34: ='Dashboard'!C12 | D34: ='Dashboard'!E12 | E34: =IF(Dashboard!G12="N/A","--",IF(ISNUMBER(VALUE(SUBSTITUTE(Dashboard!G12,"%",""))),IF(VALUE(SUBSTITUTE(Dashboard!G12,"%",""))>=90,"PASS",IF(VALUE(SUBSTITUTE(Dashboard!G12,"%",""))>=70,"REVIEW","FAIL")),"--"))
A35: Change Freeze Periods | B35: ='Dashboard'!G13 | C35: ='Dashboard'!C13 | D35: ='Dashboard'!E13 | E35: =IF(Dashboard!G13="N/A","--",IF(ISNUMBER(VALUE(SUBSTITUTE(Dashboard!G13,"%",""))),IF(VALUE(SUBSTITUTE(Dashboard!G13,"%",""))>=90,"PASS",IF(VALUE(SUBSTITUTE(Dashboard!G13,"%",""))>=70,"REVIEW","FAIL")),"--"))
A36: Record Keeping & Documentation | B36: ='Dashboard'!G14 | C36: ='Dashboard'!C14 | D36: ='Dashboard'!E14 | E36: =IF(Dashboard!G14="N/A","--",IF(ISNUMBER(VALUE(SUBSTITUTE(Dashboard!G14,"%",""))),IF(VALUE(SUBSTITUTE(Dashboard!G14,"%",""))>=90,"PASS",IF(VALUE(SUBSTITUTE(Dashboard!G14,"%",""))>=70,"REVIEW","FAIL")),"--"))
A37: Configuration Mgmt Integration | B37: ='Dashboard'!G15 | C37: ='Dashboard'!C15 | D37: ='Dashboard'!E15 | E37: =IF(Dashboard!G15="N/A","--",IF(ISNUMBER(VALUE(SUBSTITUTE(Dashboard!G15,"%",""))),IF(VALUE(SUBSTITUTE(Dashboard!G15,"%",""))>=90,"PASS",IF(VALUE(SUBSTITUTE(Dashboard!G15,"%",""))>=70,"REVIEW","FAIL")),"--"))
... A40: Change Management Metrics | B40: ='Dashboard'!G18 | C40: ='Dashboard'!C18 | D40: ='Dashboard'!E18 | E40: =IF(Dashboard!G18="N/A","--",IF(ISNUMBER(VALUE(SUBSTITUTE(Dashboard!G18,"%",""))),IF(VALUE(SUBSTITUTE(Dashboard!G18,"%",""))>=90,"PASS",IF(VALUE(SUBSTITUTE(Dashboard!G18,"%",""))>=70,"REVIEW","FAIL")),"--"))
A42: CRITICAL ISSUES
A43: # | B43: Issue Description | C43: Domain | D43: Owner | E43: Due Date
A44: 1
A45: 2
A46: 3
A47: 4
...

Sheet Dashboard
A1: Change Management — Compliance Dashboard
A3: Domain | B3: Total Reqs | C3: Compliant | D3: Partial | E3: Non-Compliant | F3: N/A | G3: Compliance %
A4: Change Classification | B4: =COUNTA('Change Classification'!D4:D5) | C4: =COUNTIF('Change Classification'!D4:D5,"Compliant") | D4: =COUNTIF('Change Classification'!D4:D5,"Partial") | E4: =COUNTIF('Change Classification'!D4:D5,"Non-Compliant") | F4: =COUNTIF('Change Classification'!D4:D5,"N/A") | G4: =IF((B4-F4)=0,"N/A",ROUND(C4/(B4-F4)*100,1)&"%")
A5: Change Request Process | B5: =COUNTA('Change Request Process'!D4:D8) | C5: =COUNTIF('Change Request Process'!D4:D8,"Compliant") | D5: =COUNTIF('Change Request Process'!D4:D8,"Partial") | E5: =COUNTIF('Change Request Process'!D4:D8,"Non-Compliant") | F5: =COUNTIF('Change Request Process'!D4:D8,"N/A") | G5: =IF((B5-F5)=0,"N/A",ROUND(C5/(B5-F5)*100,1)&"%")
A6: Change Advisory Board (CAB) | B6: =COUNTA('Change Advisory Board (CAB)'!D4:D5) | C6: =COUNTIF('Change Advisory Board (CAB)'!D4:D5,"Compliant") | D6: =COUNTIF('Change Advisory Board (CAB)'!D4:D5,"Partial") | E6: =COUNTIF('Change Advisory Board (CAB)'!D4:D5,"Non-Compliant") | F6: =COUNTIF('Change Advisory Board (CAB)'!D4:D5,"N/A") | G6: =IF((B6-F6)=0,"N/A",ROUND(C6/(B6-F6)*100,1)&"%")
A7: Standard Change Catalogue | B7: =COUNTA('Standard Change Catalogue'!D4:D6) | C7: =COUNTIF('Standard Change Catalogue'!D4:D6,"Compliant") | D7: =COUNTIF('Standard Change Catalogue'!D4:D6,"Partial") | E7: =COUNTIF('Standard Change Catalogue'!D4:D6,"Non-Compliant") | F7: =COUNTIF('Standard Change Catalogue'!D4:D6,"N/A") | G7: =IF((B7-F7)=0,"N/A",ROUND(C7/(B7-F7)*100,1)&"%")
A8: Testing and Validation | B8: =COUNTA('Testing and Validation'!D4:D14) | C8: =COUNTIF('Testing and Validation'!D4:D14,"Compliant") | D8: =COUNTIF('Testing and Validation'!D4:D14,"Partial") | E8: =COUNTIF('Testing and Validation'!D4:D14,"Non-Compliant") | F8: =COUNTIF('Testing and Validation'!D4:D14,"N/A") | G8: =IF((B8-F8)=0,"N/A",ROUND(C8/(B8-F8)*100,1)&"%")
A9: Implementation and Rollback | B9: =COUNTA('Implementation and Rollback'!D4:D9) | C9: =COUNTIF('Implementation and Rollback'!D4:D9,"Compliant") | D9: =COUNTIF('Implementation and Rollback'!D4:D9,"Partial") | E9: =COUNTIF('Implementation and Rollback'!D4:D9,"Non-Compliant") | F9: =COUNTIF('Implementation and Rollback'!D4:D9,"N/A") | G9: =IF((B9-F9)=0,"N/A",ROUND(C9/(B9-F9)*100,1)&"%")
A10: Communication | B10: =COUNTA('Communication'!D4:D4) | C10: =COUNTIF('Communication'!D4:D4,"Compliant") | D10: =COUNTIF('Communication'!D4:D4,"Partial") | E10: =COUNTIF('Communication'!D4:D4,"Non-Compliant") | F10: =COUNTIF('Communication'!D4:D4,"N/A") | G10: =IF((B10-F10)=0,"N/A",ROUND(C10/(B10-F10)*100,1)&"%")
A11: Emergency Changes | B11: =COUNTA('Emergency Changes'!D4:D7) | C11: =COUNTIF('Emergency Changes'!D4:D7,"Compliant") | D11: =COUNTIF('Emergency Changes'!D4:D7,"Partial") | E11: =COUNTIF('Emergency Changes'!D4:D7,"Non-Compliant") | F11: =COUNTIF('Emergency Changes'!D4:D7,"N/A") | G11: =IF((B11-F11)=0,"N/A",ROUND(C11/(B11-F11)*100,1)&"%")
A12: Post-Impl Review (PIR) | B12: =COUNTA('Post-Impl Review (PIR)'!D4:D4) | C12: =COUNTIF('Post-Impl Review (PIR)'!D4:D4,"Compliant") | D12: =COUNTIF('Post-Impl Review (PIR)'!D4:D4,"Partial") | E12: =COUNTIF('Post-Impl Review (PIR)'!D4:D4,"Non-Compliant") | F12: =COUNTIF('Post-Impl Review (PIR)'!D4:D4,"N/A") | G12: =IF((B12-F12)=0,"N/A",ROUND(C12/(B12-F12)*100,1)&"%")
A13: Change Freeze Periods | B13: =COUNTA('Change Freeze Periods'!D4:D4) | C13: =COUNTIF('Change Freeze Periods'!D4:D4,"Compliant") | D13: =COUNTIF('Change Freeze Periods'!D4:D4,"Partial") | E13: =COUNTIF('Change Freeze Periods'!D4:D4,"Non-Compliant") | F13: =COUNTIF('Change Freeze Periods'!D4:D4,"N/A") | G13: =IF((B13-F13)=0,"N/A",ROUND(C13/(B13-F13)*100,1)&"%")
A14: Record Keeping & Documentation | B14: =COUNTA('Record Keeping & Documentation'!D4:D6) | C14: =COUNTIF('Record Keeping & Documentation'!D4:D6,"Compliant") | D14: =COUNTIF('Record Keeping & Documentation'!D4:D6,"Partial") | E14: =COUNTIF('Record Keeping & Documentation'!D4:D6,"Non-Compliant") | F14: =COUNTIF('Record Keeping & Documentation'!D4:D6,"N/A") | G14: =IF((B14-F14)=0,"N/A",ROUND(C14/(B14-F14)*100,1)&"%")
A15: Configuration Mgmt Integration | B15: =COUNTA('Configuration Mgmt Integration'!D4:D6) | C15: =COUNTIF('Configuration Mgmt Integration'!D4:D6,"Compliant") | D15: =COUNTIF('Configuration Mgmt Integration'!D4:D6,"Partial") | E15: =COUNTIF('Configuration Mgmt Integration'!D4:D6,"Non-Compliant") | F15: =COUNTIF('Configuration Mgmt Integration'!D4:D6,"N/A") | G15: =IF((B15-F15)=0,"N/A",ROUND(C15/(B15-F15)*100,1)&"%")
A16: Unauthorised Changes | B16: =COUNTA('Unauthorised Changes'!D4:D4) | C16: =COUNTIF('Unauthorised Changes'!D4:D4,"Compliant") | D16: =COUNTIF('Unauthorised Changes'!D4:D4,"Partial") | E16: =COUNTIF('Unauthorised Changes'!D4:D4,"Non-Compliant") | F16: =COUNTIF('Unauthorised Changes'!D4:D4,"N/A") | G16: =IF((B16-F16)=0,"N/A",ROUND(C16/(B16-F16)*100,1)&"%")
A17: Change-Incident Correlation | B17: =COUNTA('Change-Incident Correlation'!D4:D5) | C17: =COUNTIF('Change-Incident Correlation'!D4:D5,"Compliant") | D17: =COUNTIF('Change-Incident Correlation'!D4:D5,"Partial") | E17: =COUNTIF('Change-Incident Correlation'!D4:D5,"Non-Compliant") | F17: =COUNTIF('Change-Incident Correlation'!D4:D5,"N/A") | G17: =IF((B17-F17)=0,"N/A",ROUND(C17/(B17-F17)*100,1)&"%")
A18: Change Management Metrics | B18: =COUNTA('Change Management Metrics'!D4:D5) | C18: =COUNTIF('Change Management Metrics'!D4:D5,"Compliant") | D18: =COUNTIF('Change Management Metrics'!D4:D5,"Partial") | E18: =COUNTIF('Change Management Metrics'!D4:D5,"Non-Compliant") | F18: =COUNTIF('Change Management Metrics'!D4:D5,"N/A") | G18: =IF((B18-F18)=0,"N/A",ROUND(C18/(B18-F18)*100,1)&"%")
A19: TOTAL | B19: =SUM(B4:B18) | C19: =SUM(C4:C18) | D19: =SUM(D4:D18) | E19: =SUM(E4:E18) | F19: =SUM(F4:F18) | G19: =IF((B19-F19)=0,"N/A",ROUND(C19/(B19-F19)*100,1)&"%")
A21: COMPLIANCE BY STATUS
A22: Compliant | B22: =C19 | C22: =IF(B19=0,"",ROUND(B22/B19*100,1)&"%")
A23: Partial | B23: =D19 | C23: =IF(B19=0,"",ROUND(B23/B19*100,1)&"%")
A24: Non-Compliant | B24: =E19 | C24: =IF(B19=0,"",ROUND(B24/B19*100,1)&"%")
A25: N/A | B25: =F19 | C25: =IF(B19=0,"",ROUND(B25/B19*100,1)&"%")
A27: TOP GAPS (Manual Entry)
A28: Priority | B28: Domain | C28: Requirement | D28: Owner | E28: Due Date | F28: Status
A40: COMPLIANCE TREND (Manual Entry)
A41: Assessment Date | B41: Overall % | C41: Compliant | D41: Gaps | E41: Assessor | F41: Notes

Sheet Change Classification
A1: Change Classification — Compliance Checklist
A2: ISO/IEC 27001:2022 — Control A.8.32: Change Management
A3: Req # | B3: Section | C3: Requirement | D3: Status | E3: Evidence | F3: Owner | G3: Due Date | H3: Notes
A4: A.8.32-01 | B4: Be Classified Into One Of Three | C4: All changes shall be classified into one of three categories:.
A5: A.8.32-02 | B5: Changes That Fall Into Grey Areas | C5: Changes that fall into grey areas shall be escalated to the Change Manager for classification.

Sheet Change Request Process
A1: Change Request Process — Compliance Checklist
A2: ISO/IEC 27001:2022 — Control A.8.32: Change Management
A3: Req # | B3: Section | C3: Requirement | D3: Status | E3: Evidence | F3: Owner | G3: Due Date | H3: Notes
A4: A.8.32-03 | B4: In-Scope Changes | C4: All in-scope changes shall be submitted as formal change requests in the change management system: [Specify: ServiceNow, Jira Service Management, Azure DevOps, or 'In selection; interim: ticketing system/spreadsheet'].
A5: A.8.32-04 | B5: Change Request | C5: Each change request shall include, at minimum:.
A6: A.8.32-05 | B6: Be Assessed For Impact Before | C6: All changes shall be assessed for impact before implementation:.
A7: A.8.32-06 | B7: Security Impact: Confidentiality, | C7: Security impact: Confidentiality, integrity, availability risks. Changes affecting systems that process personal data shall include an assessment of data protection impact.
A8: A.8.32-07 | B8: Approval Authority | C8: Approval authority shall be based on change risk level:.

Sheet Change Advisory Board (CAB)
A1: Change Advisory Board (CAB) — Compliance Checklist
A2: ISO/IEC 27001:2022 — Control A.8.32: Change Management
A3: Req # | B3: Section | C3: Requirement | D3: Status | E3: Evidence | F3: Owner | G3: Due Date | H3: Notes
A4: A.8.32-08 | B4: Establish A Change Advisory Board For | C4: The organisation shall establish a Change Advisory Board for review of normal and emergency changes.
A5: A.8.32-09 | B5: Records: Meeting Minutes | C5: Records: Meeting minutes shall be maintained for all CAB meetings, documenting date, attendees, changes reviewed, decisions, rationale, and action items. Minutes retained for 3 years.

Sheet Standard Change Catalogue
A1: Standard Change Catalogue — Compliance Checklist
A2: ISO/IEC 27001:2022 — Control A.8.32: Change Management
A3: Req # | B3: Section | C3: Requirement | D3: Status | E3: Evidence | F3: Owner | G3: Due Date | H3: Notes
A4: A.8.32-10 | B4: Maintain A Standard Change Catalogue | C4: The organisation shall maintain a Standard Change Catalogue containing pre-approved, low-risk, routine changes.
A5: A.8.32-11 | B5: Catalogue Entry | C5: Each catalogue entry shall include:.
A6: A.8.32-12 | B6: Standard Changes | C6: Standard changes shall still be logged in the change management system for audit trail and incident correlation, even though CAB review is not required.

Sheet Testing and Validation
A1: Testing and Validation — Compliance Checklist
A2: ISO/IEC 27001:2022 — Control A.8.32: Change Management
A3: Req # | B3: Section | C3: Requirement | D3: Status | E3: Evidence | F3: Owner | G3: Due Date | H3: Notes
A4: A.8.32-13 | B4: Be Tested Before Deployment To | C4: Changes shall be tested before deployment to production:.
A5: A.8.32-14 | B5: Be Tested In Non-Production Environments | C5: Changes shall be tested in non-production environments (development, test/QA, staging) before production deployment.
A6: A.8.32-15 | B6: Non-Production Environments | C6: Non-production environments shall be logically or physically separated from production with separate credentials and access controls.
A7: A.8.32-16 | B7: Production Data | C7: Production data shall not be used in test environments without masking or anonymisation per the Information Classification and Handling Policy.
A8: A.8.32-17 | B8: Promotion From Test To Production | C8: Promotion from test to production shall require formal sign-off and verified test results.
A9: A.8.32-18 | B9: Production Changes | C9: Production changes shall be executed only by authorised personnel with the following controls:.
A10: A.8.32-19 | B10: Separation Of Duties: Developers | C10: Separation of duties: Developers shall not deploy their own changes to production without independent review and approval from a designated release manager, operations team member, or CAB.
A11: A.8.32-20 | B11: Multi-Factor Authentication | C11: Multi-factor authentication shall be required for production access.
A12: A.8.32-21 | B12: Privileged Access Management: Production | C12: Privileged access management: Production deployment accounts shall be separate from development accounts.
A13: A.8.32-22 | B13: Production Changes | C13: All production changes shall be audit-logged with user identity, timestamp, and change content.
A14: A.8.32-23 | B14: Exception*: In Organisations With Fewer | C14: Exception*: In organisations with fewer than 5 IT staff where full separation is not feasible, compensating controls shall include enhanced logging, CISO review of all production changes monthly, and peer review post-implementation.

Sheet Implementation and Rollback
A1: Implementation and Rollback — Compliance Checklist
A2: ISO/IEC 27001:2022 — Control A.8.32: Change Management
A3: Req # | B3: Section | C3: Requirement | D3: Status | E3: Evidence | F3: Owner | G3: Due Date | H3: Notes
A4: A.8.32-24 | B4: Be Implemented Following The Approved | C4: Changes shall be implemented following the approved implementation plan with:.
A5: A.8.32-25 | B5: Establish Preferred Change Windows To | C5: The organisation shall establish preferred change windows to minimise business disruption:.
A6: A.8.32-26 | B6: A Rollback Procedure | C6: A rollback procedure shall be agreed upon before implementing changes to production systems. Rollback shall be executed when:.
A7: A.8.32-27 | B7: For High And Critical Risk Changes | C7: For High and Critical risk changes, rollback procedures shall be:.
A8: A.8.32-28 | B8: Rollback Testing | C8: Rollback testing shall verify:.
A9: A.8.32-29 | B9: Destructive Changes), A Forward-Fix Plan | C9: Where rollback testing is not feasible (one-way migrations, destructive changes), a forward-fix plan shall be documented as an alternative to rollback.

Sheet Communication
A1: Communication — Compliance Checklist
A2: ISO/IEC 27001:2022 — Control A.8.32: Change Management
A3: Req # | B3: Section | C3: Requirement | D3: Status | E3: Evidence | F3: Owner | G3: Due Date | H3: Notes
A4: A.8.32-30 | B4: Affected Stakeholders | C4: Affected stakeholders shall be notified of changes, including:.

Sheet Emergency Changes
A1: Emergency Changes — Compliance Checklist
A2: ISO/IEC 27001:2022 — Control A.8.32: Change Management
A3: Req # | B3: Section | C3: Requirement | D3: Status | E3: Evidence | F3: Owner | G3: Due Date | H3: Notes
A4: A.8.32-31 | B4: Be Classified As Emergency Only When | C4: Changes shall be classified as emergency only when:.
A5: A.8.32-32 | B5: Emergency Classification | C5: Emergency classification shall not be used for convenience, poor planning, routine work, or desired features.
A6: A.8.32-33 | B6: Emergency Change Percentage | C6: Emergency change percentage shall be tracked monthly. Target: <5% of all changes.
A7: A.8.32-34 | B7: Emergency Change Abuse*: Using Emergency | C7: Emergency change abuse*: Using emergency classification inappropriately (convenience, poor planning) constitutes policy non-compliance and shall be escalated to the CISO.

Sheet Post-Impl Review (PIR)
A1: Post-Impl Review (PIR) — Compliance Checklist
A2: ISO/IEC 27001:2022 — Control A.8.32: Change Management
A3: Req # | B3: Section | C3: Requirement | D3: Status | E3: Evidence | F3: Owner | G3: Due Date | H3: Notes
A4: A.8.32-35 | B4: Post-Implementation Reviews | C4: Post-implementation reviews shall be conducted for:.

Sheet Change Freeze Periods
A1: Change Freeze Periods — Compliance Checklist
A2: ISO/IEC 27001:2022 — Control A.8.32: Change Management
A3: Req # | B3: Section | C3: Requirement | D3: Status | E3: Evidence | F3: Owner | G3: Due Date | H3: Notes
A4: A.8.32-36 | B4: Change Freeze Periods | C4: Change freeze periods shall be:.

Sheet Record Keeping & Documentation
A1: Record Keeping & Documentation — Compliance Checklist
A2: ISO/IEC 27001:2022 — Control A.8.32: Change Management
A3: Req # | B3: Section | C3: Requirement | D3: Status | E3: Evidence | F3: Owner | G3: Due Date | H3: Notes
A4: A.8.32-37 | B4: Complete Change Records | C4: Complete change records shall be maintained including:.
A5: A.8.32-38 | B5: Change Records | C5: Change records shall be retained for a minimum of 3 years for operational reference and 7 years for audit evidence.
A6: A.8.32-39 | B6: Following System Changes, The Following | C6: Following system changes, the following documentation shall be updated within 5 business days:.

Sheet Configuration Mgmt Integration
A1: Configuration Mgmt Integration — Compliance Checklist
A2: ISO/IEC 27001:2022 — Control A.8.32: Change Management
A3: Req # | B3: Section | C3: Requirement | D3: Status | E3: Evidence | F3: Owner | G3: Due Date | H3: Notes
A4: A.8.32-40 | B4: Configuration Baselines | C4: Configuration baselines shall be updated following approved changes.
A5: A.8.32-41 | B5: Configuration Drift Detection (Actual | C5: Configuration drift detection (actual vs. baseline) shall trigger investigation and a corrective change request.
A6: A.8.32-42 | B6: The Configuration Management Database | C6: The configuration management database (CMDB) or equivalent inventory shall be the authoritative source for impact assessment (what systems are affected).

Sheet Unauthorised Changes
A1: Unauthorised Changes — Compliance Checklist
A2: ISO/IEC 27001:2022 — Control A.8.32: Change Management
A3: Req # | B3: Section | C3: Requirement | D3: Status | E3: Evidence | F3: Owner | G3: Due Date | H3: Notes
A4: A.8.32-43 | B4: Unauthorised Changes — Changes Made | C4: Unauthorised changes — changes made without following the change management process — shall be:.

Sheet Change-Incident Correlation
A1: Change-Incident Correlation — Compliance Checklist
A2: ISO/IEC 27001:2022 — Control A.8.32: Change Management
A3: Req # | B3: Section | C3: Requirement | D3: Status | E3: Evidence | F3: Owner | G3: Due Date | H3: Notes
A4: A.8.32-44 | B4: The Change Manager | C4: When a security incident or service outage occurs, the Change Manager shall:.
A5: A.8.32-45 | B5: The Catalogue Entry | C5: If the change was in the Standard Change Catalogue, the catalogue entry shall be reviewed and potentially reclassified or removed.

Sheet Change Management Metrics
A1: Change Management Metrics — Compliance Checklist
A2: ISO/IEC 27001:2022 — Control A.8.32: Change Management
A3: Req # | B3: Section | C3: Requirement | D3: Status | E3: Evidence | F3: Owner | G3: Due Date | H3: Notes
A4: A.8.32-46 | B4: The Information Security Management Team | C4: The information security management team shall report change management metrics to the CISO at least quarterly:.
A5: A.8.32-47 | B5: Metrics Breaching Red Thresholds | C5: Metrics breaching red thresholds shall be escalated to the CISO for immediate attention and reported at the next Management Review.
