Workbook

Sheet Executive Summary
A1: PRIV-CHK-A.1.5.2-5 — PII Transfer and Disclosure Compliance Checklist
A3: DOCUMENT INFORMATION
A4: Document ID | B4: PRIV-CHK-A.1.5.2-5
A5: Source Policy | B5: PRIV-POL-A.1.5.2-5
A6: ISO Controls | B6: PII Transfer and Disclosure
A7: Generated | B7: 30.09.2026
A8: Prepared By
A9: Organisation
A10: Review Cycle | B10: Annual
A12: OVERALL COMPLIANCE STATUS
A13: Overall Compliance | B13: ='Dashboard'!G8
A14: Status | B14: =IF(Dashboard!H8>0,"INCOMPLETE",IF(Dashboard!G8="N/A","NOT ASSESSED",IF(ISNUMBER(VALUE(SUBSTITUTE(Dashboard!G8,"%",""))),IF(VALUE(SUBSTITUTE(Dashboard!G8,"%",""))>=90,"GREEN",IF(VALUE(SUBSTITUTE(Dashboard!G8,"%",""))>=70,"AMBER","RED")),"NOT ASSESSED")))
A16: KEY METRICS
A17: Total Requirements | B17: ='Dashboard'!B8
A18: Compliant | B18: ='Dashboard'!C8
A19: Partial | B19: ='Dashboard'!D8
A20: Non-Compliant | B20: ='Dashboard'!E8
A21: Not Applicable | B21: ='Dashboard'!F8
A22: Unanswered | B22: ='Dashboard'!H8
A23: Owner Coverage | B23: =IF(Dashboard!B8=0,"N/A",ROUND((COUNTA('Transfer Basis Identification'!F4:F7)+COUNTA('Transfer Destinations'!F4:F6)+COUNTA('Transfer Records'!F4:F7)+COUNTA('Disclosure Records'!F4:F6))/Dashboard!B8*100,0)&"%")
A25: DOMAIN STATUS SUMMARY
A26: Domain | B26: Compliance % | C26: Compliant | D26: Gaps | E26: Status
A27: Transfer Basis Identification | B27: ='Dashboard'!G4 | C27: ='Dashboard'!C4 | D27: ='Dashboard'!E4 | E27: =IF(Dashboard!H4>0,"INCOMPLETE",IF(Dashboard!G4="N/A","--",IF(ISNUMBER(VALUE(SUBSTITUTE(Dashboard!G4,"%",""))),IF(VALUE(SUBSTITUTE(Dashboard!G4,"%",""))>=90,"PASS",IF(VALUE(SUBSTITUTE(Dashboard!G4,"%",""))>=70,"REVIEW","FAIL")),"--")))
A28: Transfer Destinations | B28: ='Dashboard'!G5 | C28: ='Dashboard'!C5 | D28: ='Dashboard'!E5 | E28: =IF(Dashboard!H5>0,"INCOMPLETE",IF(Dashboard!G5="N/A","--",IF(ISNUMBER(VALUE(SUBSTITUTE(Dashboard!G5,"%",""))),IF(VALUE(SUBSTITUTE(Dashboard!G5,"%",""))>=90,"PASS",IF(VALUE(SUBSTITUTE(Dashboard!G5,"%",""))>=70,"REVIEW","FAIL")),"--")))
A29: Transfer Records | B29: ='Dashboard'!G6 | C29: ='Dashboard'!C6 | D29: ='Dashboard'!E6 | E29: =IF(Dashboard!H6>0,"INCOMPLETE",IF(Dashboard!G6="N/A","--",IF(ISNUMBER(VALUE(SUBSTITUTE(Dashboard!G6,"%",""))),IF(VALUE(SUBSTITUTE(Dashboard!G6,"%",""))>=90,"PASS",IF(VALUE(SUBSTITUTE(Dashboard!G6,"%",""))>=70,"REVIEW","FAIL")),"--")))
A30: Disclosure Records | B30: ='Dashboard'!G7 | C30: ='Dashboard'!C7 | D30: ='Dashboard'!E7 | E30: =IF(Dashboard!H7>0,"INCOMPLETE",IF(Dashboard!G7="N/A","--",IF(ISNUMBER(VALUE(SUBSTITUTE(Dashboard!G7,"%",""))),IF(VALUE(SUBSTITUTE(Dashboard!G7,"%",""))>=90,"PASS",IF(VALUE(SUBSTITUTE(Dashboard!G7,"%",""))>=70,"REVIEW","FAIL")),"--")))
A32: CRITICAL ISSUES
A33: # | B33: Issue Description | C33: Domain | D33: Owner | E33: Due Date
A34: 1
A35: 2
A36: 3
A37: 4
A38: 5
A40: MANAGEMENT COMMENTARY
A41: [Enter management commentary on pii transfer and disclosure posture]
A45: APPROVAL
A46: Assessed By
A47: Name:
A48: Date:
A49: Signature:
...

Sheet Dashboard
A1: PII Transfer and Disclosure — Compliance Dashboard
A3: Domain | B3: Total Reqs | C3: Compliant | D3: Partial | E3: Non-Compliant | F3: N/A | G3: Compliance % | H3: Unassessed
A4: Transfer Basis Identification | B4: =COUNTA('Transfer Basis Identification'!A4:A7) | C4: =COUNTIF('Transfer Basis Identification'!D4:D7,"Compliant") | D4: =COUNTIF('Transfer Basis Identification'!D4:D7,"Partial") | E4: =COUNTIF('Transfer Basis Identification'!D4:D7,"Non-Compliant") | F4: =COUNTIF('Transfer Basis Identification'!D4:D7,"N/A") | G4: =IF((B4-F4)=0,"N/A",ROUND(C4/(B4-F4)*100,1)&"%") | H4: =B4-(C4+D4+E4+F4)
A5: Transfer Destinations | B5: =COUNTA('Transfer Destinations'!A4:A6) | C5: =COUNTIF('Transfer Destinations'!D4:D6,"Compliant") | D5: =COUNTIF('Transfer Destinations'!D4:D6,"Partial") | E5: =COUNTIF('Transfer Destinations'!D4:D6,"Non-Compliant") | F5: =COUNTIF('Transfer Destinations'!D4:D6,"N/A") | G5: =IF((B5-F5)=0,"N/A",ROUND(C5/(B5-F5)*100,1)&"%") | H5: =B5-(C5+D5+E5+F5)
A6: Transfer Records | B6: =COUNTA('Transfer Records'!A4:A7) | C6: =COUNTIF('Transfer Records'!D4:D7,"Compliant") | D6: =COUNTIF('Transfer Records'!D4:D7,"Partial") | E6: =COUNTIF('Transfer Records'!D4:D7,"Non-Compliant") | F6: =COUNTIF('Transfer Records'!D4:D7,"N/A") | G6: =IF((B6-F6)=0,"N/A",ROUND(C6/(B6-F6)*100,1)&"%") | H6: =B6-(C6+D6+E6+F6)
A7: Disclosure Records | B7: =COUNTA('Disclosure Records'!A4:A6) | C7: =COUNTIF('Disclosure Records'!D4:D6,"Compliant") | D7: =COUNTIF('Disclosure Records'!D4:D6,"Partial") | E7: =COUNTIF('Disclosure Records'!D4:D6,"Non-Compliant") | F7: =COUNTIF('Disclosure Records'!D4:D6,"N/A") | G7: =IF((B7-F7)=0,"N/A",ROUND(C7/(B7-F7)*100,1)&"%") | H7: =B7-(C7+D7+E7+F7)
A8: TOTAL | B8: =SUM(B4:B7) | C8: =SUM(C4:C7) | D8: =SUM(D4:D7) | E8: =SUM(E4:E7) | F8: =SUM(F4:F7) | G8: =IF((B8-F8)=0,"N/A",ROUND(C8/(B8-F8)*100,1)&"%") | H8: =SUM(H4:H7)
A10: COMPLIANCE BY STATUS
A11: Compliant | B11: =C8 | C11: =IF(B8=0,"",ROUND(B11/B8*100,1)&"%")
A12: Partial | B12: =D8 | C12: =IF(B8=0,"",ROUND(B12/B8*100,1)&"%")
A13: Non-Compliant | B13: =E8 | C13: =IF(B8=0,"",ROUND(B13/B8*100,1)&"%")
A14: N/A | B14: =F8 | C14: =IF(B8=0,"",ROUND(B14/B8*100,1)&"%")
A16: TOP GAPS (Manual Entry)
A17: Priority | B17: Domain | C17: Requirement | D17: Owner | E17: Due Date | F17: Status
A29: COMPLIANCE TREND (Manual Entry)
A30: Assessment Date | B30: Overall % | C30: Compliant | D30: Gaps | E30: Assessor | F30: Notes

Sheet Transfer Basis Identification
A1: Transfer Basis Identification — Compliance Checklist
A2: ISO/IEC 27701:2025 — Controls A.1.5.2-5: PII Transfer and Disclosure
A3: Req # | B3: Section | C3: Requirement | D3: Status | E3: Evidence | F3: Owner | G3: Due Date | H3: Notes
A4: A.1.5.2-01 | B4: Legal Basis Identification | C4: The organisation shall identify and document the legal basis for each transfer of PII to a third country or international organisation. No PII shall be transferred to a third country without a documented legal basis.
A5: A.1.5.2-02 | B5: Transfer Mechanisms | C5: Transfers shall be made under one of the approved mechanisms: adequacy decision (EU Commission or Swiss FDPIC); Standard Contractual Clauses (EU SCCs 2021 or Swiss FDPIC-approved SCCs); Binding Corporate Rules (DPA-approved BCRs for intra-group transfers); or Article 49 derogations for exceptional non-systematic cases.
A6: A.1.5.2-03 | B6: Transfer Impact Assessment | C6: Where SCCs or other contractual mechanisms are used, the DPO shall conduct a Transfer Impact Assessment (TIA) evaluating whether the destination country's legal framework provides essentially equivalent protection. TIA records shall be maintained in the International Transfer Register.
A7: A.1.5.2-04 | B7: Transfer Basis Review | C7: Transfer bases shall be reviewed when adequacy status changes, when SCCs are updated by the regulatory authority, and at minimum annually. Transfers that lose their legal basis shall cease until an alternative mechanism is established.

Sheet Transfer Destinations
A1: Transfer Destinations — Compliance Checklist
A2: ISO/IEC 27701:2025 — Controls A.1.5.2-5: PII Transfer and Disclosure
A3: Req # | B3: Section | C3: Requirement | D3: Status | E3: Evidence | F3: Owner | G3: Due Date | H3: Notes
A4: A.1.5.3-01 | B4: Transfer Country Register | C4: The DPO shall maintain a Transfer Country Register (as part of the RoPA) listing: country or international organisation; transfer mechanism and legal basis; categories of PII that may be transferred; relevant processing activities; and adequacy status or safeguard reference.
A5: A.1.5.3-02 | B5: Register Currency | C5: The Transfer Country Register shall be updated when new transfer destinations are identified, when adequacy status changes, and at minimum annually. Transfers to countries not listed in the register require DPO approval before commencement.
A6: A.1.5.3-03 | B6: RoPA Transfer Section | C6: The RoPA shall include for each processing activity the transfer destinations, transfer mechanisms, and safeguards. This is a mandatory RoPA element per GDPR Article 30(1)(e) and shall be maintained alongside the Transfer Country Register.

Sheet Transfer Records
A1: Transfer Records — Compliance Checklist
A2: ISO/IEC 27701:2025 — Controls A.1.5.2-5: PII Transfer and Disclosure
A3: Req # | B3: Section | C3: Requirement | D3: Status | E3: Evidence | F3: Owner | G3: Due Date | H3: Notes
A4: A.1.5.4-01 | B4: Transfer Record Content | C4: For each transfer of PII to or from a third party, the organisation shall record: date and time; identity of sending and receiving party; categories of PII transferred and approximate volume; legal basis; transfer mechanism (for cross-border transfers); and reference to the governing agreement.
A5: A.1.5.4-02 | B5: Third Party Cooperation Requirement | C5: The organisation shall require in its agreements with third parties that they cooperate with data subject rights requests involving PII that has been transferred, to the extent necessary to fulfil the organisation's obligations as controller.
A6: A.1.5.4-03 | B6: Transfer Record Retention | C6: Transfer records shall be retained for a minimum of 3 years and be accessible to the DPO for data subject rights fulfilment and supervisory authority requests.
A7: A.1.5.4-04 | B7: Rights Support | C7: Transfer records shall enable the organisation to: respond to data subject access requests with information on recipients; notify third parties of erasure or rectification obligations per PRIV-POL-A.1.3.5-10 (A.1.3.8); and demonstrate accountability to supervisory authorities.

Sheet Disclosure Records
A1: Disclosure Records — Compliance Checklist
A2: ISO/IEC 27701:2025 — Controls A.1.5.2-5: PII Transfer and Disclosure
A3: Req # | B3: Section | C3: Requirement | D3: Status | E3: Evidence | F3: Owner | G3: Due Date | H3: Notes
A4: A.1.5.5-01 | B4: Disclosure Register | C4: The organisation shall maintain a Disclosure Register recording all disclosures of PII to third parties — including which PII was disclosed, to whom, and when. The Disclosure Register forms part of the broader RoPA. Records shall be retained for minimum 3 years.
A5: A.1.5.5-02 | B5: Disclosure Scope | C5: Disclosure records shall cover all communications of PII to third parties: routine disclosures under ongoing processor or supplier relationships; one-time disclosures (e.g. to advisors, auditors, regulators); and mandatory disclosures under legal obligation (e.g. to law enforcement, tax authorities).
A6: A.1.5.5-03 | B6: Data Subject Rights Support | C6: Disclosure records shall support data subject access requests, as data subjects have the right to know the recipients or categories of recipients of their PII. The DPO shall be able to retrieve disclosure records for any individual data subject upon request.
