Workbook

Sheet Executive Summary
A1: AI-CHK-A.6.2 — AI System Lifecycle Compliance Checklist
A3: DOCUMENT INFORMATION
A4: Document ID | B4: AI-CHK-A.6.2
A5: Source Policy | B5: AI-POL-A.6.2
A6: ISO Controls | B6: AI System Lifecycle
A7: Generated | B7: 30.09.2026
A8: Prepared By
A9: Organisation
A10: Review Cycle | B10: Annual
A12: OVERALL COMPLIANCE STATUS
A13: Overall Compliance | B13: ='Dashboard'!G9
A14: Status | B14: =IF(Dashboard!H9>0,"INCOMPLETE",IF(Dashboard!G9="N/A","NOT ASSESSED",IF(ISNUMBER(VALUE(SUBSTITUTE(Dashboard!G9,"%",""))),IF(VALUE(SUBSTITUTE(Dashboard!G9,"%",""))>=90,"GREEN",IF(VALUE(SUBSTITUTE(Dashboard!G9,"%",""))>=70,"AMBER","RED")),"NOT ASSESSED")))
A16: KEY METRICS
A17: Total Requirements | B17: ='Dashboard'!B9
A18: Compliant | B18: ='Dashboard'!C9
A19: Partial | B19: ='Dashboard'!D9
A20: Non-Compliant | B20: ='Dashboard'!E9
A21: Not Applicable | B21: ='Dashboard'!F9
A22: Unanswered | B22: ='Dashboard'!H9
A23: Owner Coverage | B23: =IF(Dashboard!B9=0,"N/A",ROUND((COUNTA('AI System Specification'!F4:F8)+COUNTA('Operation'!F4:F8)+COUNTA('Monitoring'!F4:F8)+COUNTA('Change Management'!F4:F7)+COUNTA('Decommissioning'!F4:F7))/Dashboard!B9*100,0)&"%")
A25: DOMAIN STATUS SUMMARY
A26: Domain | B26: Compliance % | C26: Compliant | D26: Gaps | E26: Status
A27: AI System Specification | B27: ='Dashboard'!G4 | C27: ='Dashboard'!C4 | D27: ='Dashboard'!E4 | E27: =IF(Dashboard!H4>0,"INCOMPLETE",IF(Dashboard!G4="N/A","--",IF(ISNUMBER(VALUE(SUBSTITUTE(Dashboard!G4,"%",""))),IF(VALUE(SUBSTITUTE(Dashboard!G4,"%",""))>=90,"PASS",IF(VALUE(SUBSTITUTE(Dashboard!G4,"%",""))>=70,"REVIEW","FAIL")),"--")))
A28: Operation | B28: ='Dashboard'!G5 | C28: ='Dashboard'!C5 | D28: ='Dashboard'!E5 | E28: =IF(Dashboard!H5>0,"INCOMPLETE",IF(Dashboard!G5="N/A","--",IF(ISNUMBER(VALUE(SUBSTITUTE(Dashboard!G5,"%",""))),IF(VALUE(SUBSTITUTE(Dashboard!G5,"%",""))>=90,"PASS",IF(VALUE(SUBSTITUTE(Dashboard!G5,"%",""))>=70,"REVIEW","FAIL")),"--")))
A29: Monitoring | B29: ='Dashboard'!G6 | C29: ='Dashboard'!C6 | D29: ='Dashboard'!E6 | E29: =IF(Dashboard!H6>0,"INCOMPLETE",IF(Dashboard!G6="N/A","--",IF(ISNUMBER(VALUE(SUBSTITUTE(Dashboard!G6,"%",""))),IF(VALUE(SUBSTITUTE(Dashboard!G6,"%",""))>=90,"PASS",IF(VALUE(SUBSTITUTE(Dashboard!G6,"%",""))>=70,"REVIEW","FAIL")),"--")))
A30: Change Management | B30: ='Dashboard'!G7 | C30: ='Dashboard'!C7 | D30: ='Dashboard'!E7 | E30: =IF(Dashboard!H7>0,"INCOMPLETE",IF(Dashboard!G7="N/A","--",IF(ISNUMBER(VALUE(SUBSTITUTE(Dashboard!G7,"%",""))),IF(VALUE(SUBSTITUTE(Dashboard!G7,"%",""))>=90,"PASS",IF(VALUE(SUBSTITUTE(Dashboard!G7,"%",""))>=70,"REVIEW","FAIL")),"--")))
A31: Decommissioning | B31: ='Dashboard'!G8 | C31: ='Dashboard'!C8 | D31: ='Dashboard'!E8 | E31: =IF(Dashboard!H8>0,"INCOMPLETE",IF(Dashboard!G8="N/A","--",IF(ISNUMBER(VALUE(SUBSTITUTE(Dashboard!G8,"%",""))),IF(VALUE(SUBSTITUTE(Dashboard!G8,"%",""))>=90,"PASS",IF(VALUE(SUBSTITUTE(Dashboard!G8,"%",""))>=70,"REVIEW","FAIL")),"--")))
A33: CRITICAL ISSUES
A34: # | B34: Issue Description | C34: Domain | D34: Owner | E34: Due Date
A35: 1
A36: 2
A37: 3
A38: 4
A39: 5
A41: MANAGEMENT COMMENTARY
A42: [Enter management commentary on ai system lifecycle posture]
A46: APPROVAL
A47: Assessed By (AI System Owner)
A48: Name:
A49: Date:
...

Sheet Dashboard
A1: AI System Lifecycle — Compliance Dashboard
A3: Domain | B3: Total Reqs | C3: Compliant | D3: Partial | E3: Non-Compliant | F3: N/A | G3: Compliance % | H3: Unassessed
A4: AI System Specification | B4: =COUNTA('AI System Specification'!A4:A8) | C4: =COUNTIF('AI System Specification'!D4:D8,"Compliant") | D4: =COUNTIF('AI System Specification'!D4:D8,"Partial") | E4: =COUNTIF('AI System Specification'!D4:D8,"Non-Compliant") | F4: =COUNTIF('AI System Specification'!D4:D8,"N/A") | G4: =IF((B4-F4)=0,"N/A",ROUND(C4/(B4-F4)*100,1)&"%") | H4: =B4-(C4+D4+E4+F4)
A5: Operation | B5: =COUNTA('Operation'!A4:A8) | C5: =COUNTIF('Operation'!D4:D8,"Compliant") | D5: =COUNTIF('Operation'!D4:D8,"Partial") | E5: =COUNTIF('Operation'!D4:D8,"Non-Compliant") | F5: =COUNTIF('Operation'!D4:D8,"N/A") | G5: =IF((B5-F5)=0,"N/A",ROUND(C5/(B5-F5)*100,1)&"%") | H5: =B5-(C5+D5+E5+F5)
A6: Monitoring | B6: =COUNTA('Monitoring'!A4:A8) | C6: =COUNTIF('Monitoring'!D4:D8,"Compliant") | D6: =COUNTIF('Monitoring'!D4:D8,"Partial") | E6: =COUNTIF('Monitoring'!D4:D8,"Non-Compliant") | F6: =COUNTIF('Monitoring'!D4:D8,"N/A") | G6: =IF((B6-F6)=0,"N/A",ROUND(C6/(B6-F6)*100,1)&"%") | H6: =B6-(C6+D6+E6+F6)
A7: Change Management | B7: =COUNTA('Change Management'!A4:A7) | C7: =COUNTIF('Change Management'!D4:D7,"Compliant") | D7: =COUNTIF('Change Management'!D4:D7,"Partial") | E7: =COUNTIF('Change Management'!D4:D7,"Non-Compliant") | F7: =COUNTIF('Change Management'!D4:D7,"N/A") | G7: =IF((B7-F7)=0,"N/A",ROUND(C7/(B7-F7)*100,1)&"%") | H7: =B7-(C7+D7+E7+F7)
A8: Decommissioning | B8: =COUNTA('Decommissioning'!A4:A7) | C8: =COUNTIF('Decommissioning'!D4:D7,"Compliant") | D8: =COUNTIF('Decommissioning'!D4:D7,"Partial") | E8: =COUNTIF('Decommissioning'!D4:D7,"Non-Compliant") | F8: =COUNTIF('Decommissioning'!D4:D7,"N/A") | G8: =IF((B8-F8)=0,"N/A",ROUND(C8/(B8-F8)*100,1)&"%") | H8: =B8-(C8+D8+E8+F8)
A9: TOTAL | B9: =SUM(B4:B8) | C9: =SUM(C4:C8) | D9: =SUM(D4:D8) | E9: =SUM(E4:E8) | F9: =SUM(F4:F8) | G9: =IF((B9-F9)=0,"N/A",ROUND(C9/(B9-F9)*100,1)&"%") | H9: =SUM(H4:H8)
A11: COMPLIANCE BY STATUS
A12: Compliant | B12: =C9 | C12: =IF(B9=0,"",ROUND(B12/B9*100,1)&"%")
A13: Partial | B13: =D9 | C13: =IF(B9=0,"",ROUND(B13/B9*100,1)&"%")
A14: Non-Compliant | B14: =E9 | C14: =IF(B9=0,"",ROUND(B14/B9*100,1)&"%")
A15: N/A | B15: =F9 | C15: =IF(B9=0,"",ROUND(B15/B9*100,1)&"%")
A17: TOP GAPS (Manual Entry)
A18: Priority | B18: Domain | C18: Requirement | D18: Owner | E18: Due Date | F18: Status
A30: COMPLIANCE TREND (Manual Entry)
A31: Assessment Date | B31: Overall % | C31: Compliant | D31: Gaps | E31: Assessor | F31: Notes

Sheet AI System Specification
A1: AI System Specification — Compliance Checklist
A2: ISO/IEC 42001:2023 — Controls A.6.2: AI System Lifecycle
A3: Req # | B3: Section | C3: Requirement | D3: Status | E3: Evidence | F3: Owner | G3: Due Date | H3: Notes
A4: A.6.2.1-01 | B4: System Specification Document | C4: Every in-scope AI system shall have a current system specification document covering: system purpose, intended use, use restrictions, input and output definitions, performance requirements, and human oversight mechanism. The specification shall be approved before development commences.
A5: A.6.2.1-02 | B5: Technical Documentation | C5: Technical documentation shall be maintained for every AI system, structured per the requirements in AI-IMP-A.6.2-TG. Technical documentation shall be sufficient to enable evaluation of the system's compliance with applicable requirements.
A6: A.6.2.1-03 | B6: Specification Scope | C6: The system specification shall define: the populations affected, the geographic scope of deployment, the languages supported, and the environmental conditions under which the system is designed to operate.
A7: A.6.2.1-04 | B7: Pre-Operational Checklist | C7: Before a new AI system enters operational use, the AI System Owner shall complete a pre-operational checklist confirming: AISIA approved, V&V complete, user training complete, monitoring in place, and operational procedures documented.
A8: A.6.2.1-05 | B8: Specification Currency | C8: The system specification shall be updated whenever a material change is made to the AI system. Outdated specifications shall not remain as the current version; superseded versions shall be preserved in version control.

Sheet Operation
A1: Operation — Compliance Checklist
A2: ISO/IEC 42001:2023 — Controls A.6.2: AI System Lifecycle
A3: Req # | B3: Section | C3: Requirement | D3: Status | E3: Evidence | F3: Owner | G3: Due Date | H3: Notes
A4: A.6.2.2-01 | B4: Operational Procedures | C4: The organisation shall document operational procedures for each AI system covering: normal operation, escalation of AI outputs for human review, override procedures, and incident first response. Procedures shall be accessible to all operators.
A5: A.6.2.2-02 | B5: Operator Training | C5: All persons operating an AI system shall have completed the required training before the system enters operational use. The AI System Owner shall maintain training completion records and refresh training when the system changes materially.
A6: A.6.2.2-03 | B6: Intended Use Enforcement | C6: The AI System Owner shall implement controls to prevent operational use of the AI system for purposes outside its documented intended use. Where misuse is detected, the AI System Owner shall escalate per the process in AI-POL-A.9.2-4.
A7: A.6.2.2-04 | B7: Output Review for High-Impact Systems | C7: For AI systems classified as High impact, the organisation shall implement a process for human review of AI outputs before those outputs are acted upon in consequential decisions. The review process shall be documented and auditable.
A8: A.6.2.2-05 | B8: Operational Logging | C8: AI systems shall generate operational logs meeting the minimum logging requirements in AI-IMP-A.6.2-TG. Logs shall be retained per the retention schedule proportionate to the system's impact classification.

Sheet Monitoring
A1: Monitoring — Compliance Checklist
A2: ISO/IEC 42001:2023 — Controls A.6.2: AI System Lifecycle
A3: Req # | B3: Section | C3: Requirement | D3: Status | E3: Evidence | F3: Owner | G3: Due Date | H3: Notes
A4: A.6.2.3-01 | B4: Monitoring Plan | C4: The AI System Owner shall maintain a monitoring plan for each AI system, defining: KPIs monitored, monitoring frequency, alert thresholds, and escalation paths. The monitoring plan shall be proportionate to the system's impact classification.
A5: A.6.2.3-02 | B5: Performance Monitoring | C5: The organisation shall monitor AI system performance against defined KPIs in operation. Performance results shall be recorded. Degradation below defined thresholds shall trigger escalation.
A6: A.6.2.3-03 | B6: Distributional Shift Detection | C6: The AI System Owner shall implement monitoring for distributional shift — changes in input data distributions that may degrade model performance or introduce bias. Detected shifts shall be assessed and reported to the AI Governance Officer.
A7: A.6.2.3-04 | B7: Incident Trigger | C7: The monitoring plan shall define the thresholds at which a monitoring alert escalates to a formal AI incident under AI-POL-A.6.2. Escalation criteria shall be documented and communicated to all operators.
A8: A.6.2.3-05 | B8: Monitoring Review | C8: Monitoring results shall be reviewed by the AI System Owner at minimum quarterly for High-impact systems, semi-annually for Medium-impact, and annually for Low-impact. Review findings shall feed into the periodic AISIA review.

Sheet Change Management
A1: Change Management — Compliance Checklist
A2: ISO/IEC 42001:2023 — Controls A.6.2: AI System Lifecycle
A3: Req # | B3: Section | C3: Requirement | D3: Status | E3: Evidence | F3: Owner | G3: Due Date | H3: Notes
A4: A.6.2.4-01 | B4: Change Classification | C4: The AI System Owner shall classify all proposed changes to an AI system as material or minor per the criteria in AI-POL-A.6.2. Material changes shall require a new or updated AISIA and re-validation before deployment.
A5: A.6.2.4-02 | B5: Change Approval | C5: Material changes shall be approved by the AI Governance Officer before implementation. Minor changes shall be approved by the AI System Owner. All changes shall be logged with classification, approval record, and effective date.
A6: A.6.2.4-03 | B6: Emergency Change Procedure | C6: The organisation shall define an emergency change procedure for urgent fixes to AI systems in production. Emergency changes shall still require post-deployment review and retrospective AISIA update where the change has impact implications.
A7: A.6.2.4-04 | B7: Version Management | C7: All AI system versions deployed to production shall be recorded in the model registry with: version identifier, deployment date, key change summary, V&V Record reference, and AISIA version applicable at time of deployment.

Sheet Decommissioning
A1: Decommissioning — Compliance Checklist
A2: ISO/IEC 42001:2023 — Controls A.6.2: AI System Lifecycle
A3: Req # | B3: Section | C3: Requirement | D3: Status | E3: Evidence | F3: Owner | G3: Due Date | H3: Notes
A4: A.6.2.5-01 | B4: Decommissioning Plan | C4: Before decommissioning an AI system, the AI System Owner shall prepare a decommissioning plan covering: user notification, data deletion or transfer, downstream system impacts, handover to replacement system if applicable, and record retention.
A5: A.6.2.5-02 | B5: User Notification | C5: Users and affected parties shall be notified of AI system decommissioning with adequate notice proportionate to the system's impact classification. Notification content and distribution shall be documented.
A6: A.6.2.5-03 | B6: Data Deletion | C6: Upon decommissioning, the organisation shall implement data deletion per the AI system's data retention schedule. Deletion of personal data shall comply with GDPR Article 17 requirements. Deletion shall be confirmed and documented.
A7: A.6.2.5-04 | B7: Record Retention | C7: Following decommissioning, AISIA records, V&V Records, incident records, and audit logs for the AI system shall be retained for a minimum of 5 years. The AI Governance Officer shall confirm record retention is in place before system shutdown.
