Workbook

Sheet Executive Summary
A1: ISMS-OP-CHK-A.6.6 — Confidentiality and Non-Disclosure Agreements Compliance Checklist
A3: DOCUMENT INFORMATION
A4: Document ID | B4: ISMS-OP-CHK-A.6.6
A5: Source Policy | B5: ISMS-OP-POL-A.6.6
A6: ISO Controls | B6: Confidentiality and Non-Disclosure Agreements
A7: Generated | B7: 08.02.2026
A8: Prepared By
A9: Organisation
A10: Review Cycle | B10: Annual
A12: OVERALL COMPLIANCE STATUS
A13: Overall Compliance | B13: ='Dashboard'!G11
A14: Status | B14: =IF(Dashboard!G11="N/A","NOT ASSESSED",IF(ISNUMBER(VALUE(SUBSTITUTE(Dashboard!G11,"%",""))),IF(VALUE(SUBSTITUTE(Dashboard!G11,"%",""))>=90,"GREEN",IF(VALUE(SUBSTITUTE(Dashboard!G11,"%",""))>=70,"AMBER","RED")),"NOT ASSESSED"))
A16: KEY METRICS
A17: Total Requirements | B17: ='Dashboard'!B11
A18: Compliant | B18: ='Dashboard'!C11
A19: Partial | B19: ='Dashboard'!D11
A20: Non-Compliant | B20: ='Dashboard'!E11
A21: Not Applicable | B21: ='Dashboard'!F11
A22: Owner Coverage | B22: =IF(Dashboard!B11=0,"N/A",ROUND((COUNTA('NDA Requirements'!F4:F7)+COUNTA('Template Requirements'!F4:F7)+COUNTA('Stakeholder-Specific Reqs'!F4:F11)+COUNTA('Execution and Storage'!F4:F7)+COUNTA('Periodic Review & Gap'!F4:F7)+COUNTA('Post-Employment Obligations'!F4:F7)+COUNTA('Compliance Measurement'!F4:F4))/Dashboard!B11*100,0)&"%")
A24: DOMAIN STATUS SUMMARY
A25: Domain | B25: Compliance % | C25: Compliant | D25: Gaps | E25: Status
A26: NDA Requirements | B26: ='Dashboard'!G4 | C26: ='Dashboard'!C4 | D26: ='Dashboard'!E4 | E26: =IF(Dashboard!G4="N/A","--",IF(ISNUMBER(VALUE(SUBSTITUTE(Dashboard!G4,"%",""))),IF(VALUE(SUBSTITUTE(Dashboard!G4,"%",""))>=90,"PASS",IF(VALUE(SUBSTITUTE(Dashboard!G4,"%",""))>=70,"REVIEW","FAIL")),"--"))
A27: Template Requirements | B27: ='Dashboard'!G5 | C27: ='Dashboard'!C5 | D27: ='Dashboard'!E5 | E27: =IF(Dashboard!G5="N/A","--",IF(ISNUMBER(VALUE(SUBSTITUTE(Dashboard!G5,"%",""))),IF(VALUE(SUBSTITUTE(Dashboard!G5,"%",""))>=90,"PASS",IF(VALUE(SUBSTITUTE(Dashboard!G5,"%",""))>=70,"REVIEW","FAIL")),"--"))
A28: Stakeholder-Specific Reqs | B28: ='Dashboard'!G6 | C28: ='Dashboard'!C6 | D28: ='Dashboard'!E6 | E28: =IF(Dashboard!G6="N/A","--",IF(ISNUMBER(VALUE(SUBSTITUTE(Dashboard!G6,"%",""))),IF(VALUE(SUBSTITUTE(Dashboard!G6,"%",""))>=90,"PASS",IF(VALUE(SUBSTITUTE(Dashboard!G6,"%",""))>=70,"REVIEW","FAIL")),"--"))
A29: Execution and Storage | B29: ='Dashboard'!G7 | C29: ='Dashboard'!C7 | D29: ='Dashboard'!E7 | E29: =IF(Dashboard!G7="N/A","--",IF(ISNUMBER(VALUE(SUBSTITUTE(Dashboard!G7,"%",""))),IF(VALUE(SUBSTITUTE(Dashboard!G7,"%",""))>=90,"PASS",IF(VALUE(SUBSTITUTE(Dashboard!G7,"%",""))>=70,"REVIEW","FAIL")),"--"))
A30: Periodic Review & Gap | B30: ='Dashboard'!G8 | C30: ='Dashboard'!C8 | D30: ='Dashboard'!E8 | E30: =IF(Dashboard!G8="N/A","--",IF(ISNUMBER(VALUE(SUBSTITUTE(Dashboard!G8,"%",""))),IF(VALUE(SUBSTITUTE(Dashboard!G8,"%",""))>=90,"PASS",IF(VALUE(SUBSTITUTE(Dashboard!G8,"%",""))>=70,"REVIEW","FAIL")),"--"))
A31: Post-Employment Obligations | B31: ='Dashboard'!G9 | C31: ='Dashboard'!C9 | D31: ='Dashboard'!E9 | E31: =IF(Dashboard!G9="N/A","--",IF(ISNUMBER(VALUE(SUBSTITUTE(Dashboard!G9,"%",""))),IF(VALUE(SUBSTITUTE(Dashboard!G9,"%",""))>=90,"PASS",IF(VALUE(SUBSTITUTE(Dashboard!G9,"%",""))>=70,"REVIEW","FAIL")),"--"))
A32: Compliance Measurement | B32: ='Dashboard'!G10 | C32: ='Dashboard'!C10 | D32: ='Dashboard'!E10 | E32: =IF(Dashboard!G10="N/A","--",IF(ISNUMBER(VALUE(SUBSTITUTE(Dashboard!G10,"%",""))),IF(VALUE(SUBSTITUTE(Dashboard!G10,"%",""))>=90,"PASS",IF(VALUE(SUBSTITUTE(Dashboard!G10,"%",""))>=70,"REVIEW","FAIL")),"--"))
A34: CRITICAL ISSUES
A35: # | B35: Issue Description | C35: Domain | D35: Owner | E35: Due Date
A36: 1
A37: 2
A38: 3
A39: 4
A40: 5
A42: MANAGEMENT COMMENTARY
A43: [Enter management commentary on confidentiality and non-disclosure agreements posture]
A47: APPROVAL
A48: Assessed By
A49: Name:
...

Sheet Dashboard
A1: Confidentiality and Non-Disclosure Agreements — Compliance Dashboard
A3: Domain | B3: Total Reqs | C3: Compliant | D3: Partial | E3: Non-Compliant | F3: N/A | G3: Compliance %
A4: NDA Requirements | B4: =COUNTA('NDA Requirements'!D4:D7) | C4: =COUNTIF('NDA Requirements'!D4:D7,"Compliant") | D4: =COUNTIF('NDA Requirements'!D4:D7,"Partial") | E4: =COUNTIF('NDA Requirements'!D4:D7,"Non-Compliant") | F4: =COUNTIF('NDA Requirements'!D4:D7,"N/A") | G4: =IF((B4-F4)=0,"N/A",ROUND(C4/(B4-F4)*100,1)&"%")
A5: Template Requirements | B5: =COUNTA('Template Requirements'!D4:D7) | C5: =COUNTIF('Template Requirements'!D4:D7,"Compliant") | D5: =COUNTIF('Template Requirements'!D4:D7,"Partial") | E5: =COUNTIF('Template Requirements'!D4:D7,"Non-Compliant") | F5: =COUNTIF('Template Requirements'!D4:D7,"N/A") | G5: =IF((B5-F5)=0,"N/A",ROUND(C5/(B5-F5)*100,1)&"%")
A6: Stakeholder-Specific Reqs | B6: =COUNTA('Stakeholder-Specific Reqs'!D4:D11) | C6: =COUNTIF('Stakeholder-Specific Reqs'!D4:D11,"Compliant") | D6: =COUNTIF('Stakeholder-Specific Reqs'!D4:D11,"Partial") | E6: =COUNTIF('Stakeholder-Specific Reqs'!D4:D11,"Non-Compliant") | F6: =COUNTIF('Stakeholder-Specific Reqs'!D4:D11,"N/A") | G6: =IF((B6-F6)=0,"N/A",ROUND(C6/(B6-F6)*100,1)&"%")
A7: Execution and Storage | B7: =COUNTA('Execution and Storage'!D4:D7) | C7: =COUNTIF('Execution and Storage'!D4:D7,"Compliant") | D7: =COUNTIF('Execution and Storage'!D4:D7,"Partial") | E7: =COUNTIF('Execution and Storage'!D4:D7,"Non-Compliant") | F7: =COUNTIF('Execution and Storage'!D4:D7,"N/A") | G7: =IF((B7-F7)=0,"N/A",ROUND(C7/(B7-F7)*100,1)&"%")
A8: Periodic Review & Gap | B8: =COUNTA('Periodic Review & Gap'!D4:D7) | C8: =COUNTIF('Periodic Review & Gap'!D4:D7,"Compliant") | D8: =COUNTIF('Periodic Review & Gap'!D4:D7,"Partial") | E8: =COUNTIF('Periodic Review & Gap'!D4:D7,"Non-Compliant") | F8: =COUNTIF('Periodic Review & Gap'!D4:D7,"N/A") | G8: =IF((B8-F8)=0,"N/A",ROUND(C8/(B8-F8)*100,1)&"%")
A9: Post-Employment Obligations | B9: =COUNTA('Post-Employment Obligations'!D4:D7) | C9: =COUNTIF('Post-Employment Obligations'!D4:D7,"Compliant") | D9: =COUNTIF('Post-Employment Obligations'!D4:D7,"Partial") | E9: =COUNTIF('Post-Employment Obligations'!D4:D7,"Non-Compliant") | F9: =COUNTIF('Post-Employment Obligations'!D4:D7,"N/A") | G9: =IF((B9-F9)=0,"N/A",ROUND(C9/(B9-F9)*100,1)&"%")
A10: Compliance Measurement | B10: =COUNTA('Compliance Measurement'!D4:D4) | C10: =COUNTIF('Compliance Measurement'!D4:D4,"Compliant") | D10: =COUNTIF('Compliance Measurement'!D4:D4,"Partial") | E10: =COUNTIF('Compliance Measurement'!D4:D4,"Non-Compliant") | F10: =COUNTIF('Compliance Measurement'!D4:D4,"N/A") | G10: =IF((B10-F10)=0,"N/A",ROUND(C10/(B10-F10)*100,1)&"%")
A11: TOTAL | B11: =SUM(B4:B10) | C11: =SUM(C4:C10) | D11: =SUM(D4:D10) | E11: =SUM(E4:E10) | F11: =SUM(F4:F10) | G11: =IF((B11-F11)=0,"N/A",ROUND(C11/(B11-F11)*100,1)&"%")
A13: COMPLIANCE BY STATUS
A14: Compliant | B14: =C11 | C14: =IF(B11=0,"",ROUND(B14/B11*100,1)&"%")
A15: Partial | B15: =D11 | C15: =IF(B11=0,"",ROUND(B15/B11*100,1)&"%")
A16: Non-Compliant | B16: =E11 | C16: =IF(B11=0,"",ROUND(B16/B11*100,1)&"%")
A17: N/A | B17: =F11 | C17: =IF(B11=0,"",ROUND(B17/B11*100,1)&"%")
A19: TOP GAPS (Manual Entry)
A20: Priority | B20: Domain | C20: Requirement | D20: Owner | E20: Due Date | F20: Status
A32: COMPLIANCE TREND (Manual Entry)
A33: Assessment Date | B33: Overall % | C33: Compliant | D33: Gaps | E33: Assessor | F33: Notes

Sheet NDA Requirements
A1: NDA Requirements — Compliance Checklist
A2: ISO/IEC 27001:2022 — Control A.6.6: Confidentiality and Non-Disclosure Agreements
A3: Req # | B3: Section | C3: Requirement | D3: Status | E3: Evidence | F3: Owner | G3: Due Date | H3: Notes
A4: A.6.6-01 | B4: No Person | C4: No person shall be granted access to the organisation's confidential information, systems, or facilities without a valid, signed confidentiality or non-disclosure agreement in place. NDAs shall be executed before access is granted — not retrospectively.
A5: A.6.6-02 | B5: Coverage Targets*: The Organisation | C5: Coverage targets*: The organisation shall achieve and maintain the following NDA coverage rates:.
A6: A.6.6-03 | B6: Be Executed According To The Following | C6: NDAs shall be executed according to the following timelines:.
A7: A.6.6-04 | B7: Be Legally Enforceable In The | C7: All NDAs shall be legally enforceable in the organisation's operating jurisdictions. Legal Counsel shall review and approve all NDA templates. NDAs shall reference:.

Sheet Template Requirements
A1: Template Requirements — Compliance Checklist
A2: ISO/IEC 27001:2022 — Control A.6.6: Confidentiality and Non-Disclosure Agreements
A3: Req # | B3: Section | C3: Requirement | D3: Status | E3: Evidence | F3: Owner | G3: Due Date | H3: Notes
A4: A.6.6-05 | B4: Maintain Six Standardised Nda Templates, | C4: The organisation shall maintain six standardised NDA templates, one for each stakeholder category:.
A5: A.6.6-06 | B5: Nda Templates | C5: All NDA templates shall include the following elements:.
A6: A.6.6-07 | B6: Nda Templates | C6: NDA templates shall be reviewed:.
A7: A.6.6-08 | B7: Upon A Trigger Event, Legal Counsel | C7: Upon a trigger event, Legal Counsel shall initiate review within 5 business days and record the review requirement in the NDA Template Register maintained in [Contract Management System].

Sheet Stakeholder-Specific Reqs
A1: Stakeholder-Specific Reqs — Compliance Checklist
A2: ISO/IEC 27001:2022 — Control A.6.6: Confidentiality and Non-Disclosure Agreements
A3: Req # | B3: Section | C3: Requirement | D3: Status | E3: Evidence | F3: Owner | G3: Due Date | H3: Notes
A4: A.6.6-09 | B4: Employment Ndas | C4: Employment NDAs shall:.
A5: A.6.6-10 | B5: Contractor Ndas | C5: Contractor NDAs shall:.
A6: A.6.6-11 | B6: Vendor Ndas | C6: Vendor NDAs shall:.
A7: A.6.6-12 | B7: Data Processing Agreement (Dpa) | C7: Data Processing Agreement (DPA) requirements*: When a vendor will process personal data on behalf of the organisation, the Vendor NDA template shall include or reference a DPA covering the following elements (per nFADP Art. 9, GDPR Art. 28):.
A8: A.6.6-13 | B8: Mutual Ndas For Partners | C8: Mutual NDAs for partners shall:.
A9: A.6.6-14 | B9: Director/Advisor Ndas | C9: Director/Advisor NDAs shall:.
A10: A.6.6-15 | B10: Conflict Assessment | C10: Conflict assessment shall be performed at Director onboarding and annually thereafter (Chair + Legal Counsel).
A11: A.6.6-16 | B11: Visitor Ndas | C11: Visitor NDAs shall:.

Sheet Execution and Storage
A1: Execution and Storage — Compliance Checklist
A2: ISO/IEC 27001:2022 — Control A.6.6: Confidentiality and Non-Disclosure Agreements
A3: Req # | B3: Section | C3: Requirement | D3: Status | E3: Evidence | F3: Owner | G3: Due Date | H3: Notes
A4: A.6.6-17 | B4: Be | C4: NDAs shall be:.
A5: A.6.6-18 | B5: Executed Ndas | C5: Executed NDAs shall be:.
A6: A.6.6-19 | B6: Maintain A Register Of All Active | C6: The organisation shall maintain a register of all active NDAs. The register shall include:.
A7: A.6.6-20 | B7: The Nda Register | C7: The NDA Register shall be maintained in [Contract Management System] and reconciled quarterly against the personnel directory and active vendor/partner lists.

Sheet Periodic Review & Gap
A1: Periodic Review & Gap — Compliance Checklist
A2: ISO/IEC 27001:2022 — Control A.6.6: Confidentiality and Non-Disclosure Agreements
A3: Req # | B3: Section | C3: Requirement | D3: Status | E3: Evidence | F3: Owner | G3: Due Date | H3: Notes
A4: A.6.6-21 | B4: Periodic Reviews | C4: Periodic reviews shall assess:.
A5: A.6.6-22 | B5: Annual Review By Legal Counsel | C5: Annual review by Legal Counsel shall assess each template against the following criteria:.
A6: A.6.6-23 | B6: The Following Escalation | C6: When remediation timelines cannot be met, the following escalation shall apply:.
A7: A.6.6-24 | B7: Compensating Controls: If Access Cannot | C7: Compensating controls: If access cannot be immediately suspended pending NDA execution, documented compensating controls shall be implemented within 2 business days* of the deadline and reviewed weekly until the NDA is executed.

Sheet Post-Employment Obligations
A1: Post-Employment Obligations — Compliance Checklist
A2: ISO/IEC 27001:2022 — Control A.6.6: Confidentiality and Non-Disclosure Agreements
A3: Req # | B3: Section | C3: Requirement | D3: Status | E3: Evidence | F3: Owner | G3: Due Date | H3: Notes
A4: A.6.6-25 | B4: Confidentiality Obligations | C4: Confidentiality obligations shall survive the termination of employment, contract, or business relationship. Post-termination obligations shall be communicated to the departing individual in writing before or on the last working day, as part of the exit process (per A.6.4–5).
A5: A.6.6-26 | B5: Maintain A Post-Termination Obligation | C5: The organisation shall maintain a Post-Termination Obligation Register for all departed personnel and ended third-party relationships. The register shall include:.
A6: A.6.6-27 | B6: The Register | C6: The register shall be:.
A7: A.6.6-28 | B7: Upon Obligation Expiration, The Record | C7: Upon obligation expiration, the record shall be archived in historical compliance records, retained per document retention policy (minimum 7 years from expiration), and removed from active monitoring.

Sheet Compliance Measurement
A1: Compliance Measurement — Compliance Checklist
A2: ISO/IEC 27001:2022 — Control A.6.6: Confidentiality and Non-Disclosure Agreements
A3: Req # | B3: Section | C3: Requirement | D3: Status | E3: Evidence | F3: Owner | G3: Due Date | H3: Notes
A4: A.6.6-29 | B4: Be Reported To The Ciso Monthly | C4: Metrics shall be reported to the CISO monthly and to the Management Review Team quarterly.
