Workbook

Sheet Instructions & Legend
A1: ISMS-IMP-A.5.23.S3 — Secure Configuration & Deployment v1.0
A2: ISO/IEC 27001:2022 - Control A.5.23: Information security for use of cloud services
A4: DOCUMENT INFORMATION
A5: Document ID: | B5: ISMS-IMP-A.5.23.S3
A6: Assessment Area: | B6: Secure Configuration & Deployment
A7: Related Policy: | B7: ISMS-POL-A.5.19-23-S5
A8: Version: | B8: 2.0 (Regulatory Update)
A9: Assessment Date:
A10: Completed By:
A11: Organization:
A12: Review Cycle: | B12: Quarterly
A15: HOW TO USE THIS WORKBOOK
A16: 1. Reference ISMS-IMP-A.5.23.S1 (Inventory) for authoritative cloud service list
A17: 2. Complete each worksheet tab (2–7) for all cloud services requiring config assessment
A18: 3. Use dropdown menus for standardized entries (Environment, Status, etc.)
A19: 4. Fill in yellow-highlighted cells with your configuration-specific information
A20: 5. Complete Jurisdictional Risk sheet (7) for all US-nexus providers (NEW)
A21: 6. Document DORA configuration requirements if in scope
A22: 7. Validate NIS2 secure deployment procedures if applicable
A23: 8. Complete AI Act deployment controls for AI-enabled services
A24: 9. Provide evidence: screenshots, config exports, security scan results
A25: 10. Summary Dashboard auto-calculates compliance by config area and environment
A26: 11. Obtain final approval from IT Operations, Security, DPO, and CISO
A29: STATUS LEGEND
A30: {CHECK} Compliant | B30: Configuration meets security requirements
A31: {WARNING} Partial | B31: Some settings correct, gaps exist
A32: {XMARK} Non-Compliant | B32: Configuration does not meet requirements
A33: N/A | B33: Control does not apply to this service
A36: REGULATORY COMPLIANCE (NEW IN v1.0)
A37: This workbook includes updated requirements for:
A38: • DORA (Digital Operational Resilience Act) - Configuration documentation
A39: • NIS2 (Network and Information Security Directive 2) - Secure deployment
A40: • EU AI Act - AI system deployment controls
A41: • US CLOUD Act - Jurisdictional risk assessment (NEW Sheet 7)
A43: REGULATORY APPLICABILITY GUIDANCE
A44: If You Are... | B44: Complete These Fields
A45: EU Financial Entity (DORA scope) | B45: All DORA fields (mandatory)
A46: EU Essential/Important Entity (NIS2) | B46: All NIS2 fields (mandatory)
A47: Deploying AI Systems from vendors | B47: All AI Act deployment controls
A48: Using US-HQ Providers | B48: Sheet 7 Jurisdictional Risk (all)
...

Sheet 2. Configuration Baseline
A1: CONFIGURATION BASELINE Policy Requirement: Configuration baseline documented, change-controlled, drift-monitored, CIS-validated (Policy S5 Section 9.1)
A2: Assessment Question: Are configuration baselines properly documented, version-controlled, and validated for your cloud services?
A4: Assessment_ID | B4: Cloud_Service_Name | C4: Vendor_Name | D4: Service_Type | E4: Environment | F4: Service_Criticality | G4: Data_Classification | H4: Configuration_Item | I4: Status | J4: Evidence_Location | K4: Gap_Description | L4: Remediation_Needed | M4: Exception_ID | N4: Risk_ID | O4: Compensating_Controls | P4: Responsible_Team | Q4: Target_Remediation_Date | R4: Baseline_Version | S4: Change_Mgmt_ID | T4: Drift_Monitoring | U4: CIS_Benchmark | V4: Last_Validated | W4: Config_Backup | X4: Privileged_Access_Log | Y4: Security_By_Default | Z4: DORA_Config_Documentation | AA4: NIS2_Secure_Deployment | AB4: AI_System_Deployment_Controls
A5: =CONCATENATE("CON-",TEXT(ROW()-4,"000"))
A6: =CONCATENATE("CON-",TEXT(ROW()-4,"000"))
A7: =CONCATENATE("CON-",TEXT(ROW()-4,"000"))
A8: =CONCATENATE("CON-",TEXT(ROW()-4,"000"))
A9: =CONCATENATE("CON-",TEXT(ROW()-4,"000"))
A10: =CONCATENATE("CON-",TEXT(ROW()-4,"000"))
A11: =CONCATENATE("CON-",TEXT(ROW()-4,"000"))
A12: =CONCATENATE("CON-",TEXT(ROW()-4,"000"))
A13: =CONCATENATE("CON-",TEXT(ROW()-4,"000"))
A14: =CONCATENATE("CON-",TEXT(ROW()-4,"000"))
A15: =CONCATENATE("CON-",TEXT(ROW()-4,"000"))
A16: =CONCATENATE("CON-",TEXT(ROW()-4,"000"))
... A30: =CONCATENATE("CON-",TEXT(ROW()-4,"000"))
A33: COMPLIANCE CHECKLIST
A34: ☐ | B34: Requirement | C34: Evidence
A35: ☐ | B35: Configuration baseline documented and version-controlled | C35: Baseline doc + version history
A36: ☐ | B36: Change management process for cloud configurations | C36: Change log/ITSM tickets
A37: ☐ | B37: Configuration drift monitoring enabled | C37: Drift detection config
A38: ☐ | B38: Security configuration validated against CIS benchmarks | C38: CIS scan report
A39: ☐ | B39: Configuration backup and recovery tested | C39: Backup test results
A40: ☐ | B40: Privileged access to configurations logged and monitored | C40: Access log screenshot
A41: ☐ | B41: Security-by-default configurations applied | C41: Default settings review
A42: ☐ | B42: CFG-DORA-01: Configuration baseline documented and version-controlled | C42: DORA: Version control
A43: ☐ | B43: CFG-DORA-02: Change management process for cloud configurations | C43: DORA: Change records
A44: ☐ | B44: CFG-DORA-03: Configuration drift monitoring enabled | C44: DORA: Monitoring config
A45: ☐ | B45: CFG-DORA-04: Security configuration validated against CIS benchmarks | C45: DORA: CIS compliance
... A56: ☐ | B56: CFG-AI-05: Human oversight mechanisms configured | C56: AI Act: Oversight config

Sheet 3. Access Control Setup
A1: ACCESS CONTROL SETUP Policy Requirement: SSO integration, MFA enforced, RBAC implemented, privileged access controlled (Policy S5 Section 9.1)
A2: Assessment Question: Are identity and access controls properly configured for your cloud services?
A4: Assessment_ID | B4: Cloud_Service_Name | C4: Vendor_Name | D4: Service_Type | E4: Environment | F4: Service_Criticality | G4: Data_Classification | H4: Configuration_Item | I4: Status | J4: Evidence_Location | K4: Gap_Description | L4: Remediation_Needed | M4: Exception_ID | N4: Risk_ID | O4: Compensating_Controls | P4: Responsible_Team | Q4: Target_Remediation_Date | R4: SSO_Integrated | S4: MFA_Enforced | T4: RBAC_Implemented | U4: Privileged_Access_JIT | V4: Service_Accounts_Inventoried | W4: Last_Access_Review | X4: Admin_Account_Count
A5: =CONCATENATE("ACC-",TEXT(ROW()-4,"000"))
A6: =CONCATENATE("ACC-",TEXT(ROW()-4,"000"))
A7: =CONCATENATE("ACC-",TEXT(ROW()-4,"000"))
A8: =CONCATENATE("ACC-",TEXT(ROW()-4,"000"))
A9: =CONCATENATE("ACC-",TEXT(ROW()-4,"000"))
A10: =CONCATENATE("ACC-",TEXT(ROW()-4,"000"))
A11: =CONCATENATE("ACC-",TEXT(ROW()-4,"000"))
A12: =CONCATENATE("ACC-",TEXT(ROW()-4,"000"))
A13: =CONCATENATE("ACC-",TEXT(ROW()-4,"000"))
A14: =CONCATENATE("ACC-",TEXT(ROW()-4,"000"))
A15: =CONCATENATE("ACC-",TEXT(ROW()-4,"000"))
A16: =CONCATENATE("ACC-",TEXT(ROW()-4,"000"))
... A30: =CONCATENATE("ACC-",TEXT(ROW()-4,"000"))
A33: COMPLIANCE CHECKLIST
A34: ☐ | B34: Requirement | C34: Evidence
A35: ☐ | B35: SSO configured via organizational IdP (Entra ID, Okta, etc.) | C35: SSO config screenshot
A36: ☐ | B36: MFA enforced for all users | C36: MFA policy screenshot
A37: ☐ | B37: MFA mandatory for privileged accounts | C37: Admin MFA verification
A38: ☐ | B38: RBAC roles documented and implemented | C38: Role matrix document
A39: ☐ | B39: Least privilege principle applied | C39: Permission audit
A40: ☐ | B40: Service accounts inventoried with owners | C40: Service account register
A41: ☐ | B41: Privileged access is time-limited (JIT) | C41: PAM configuration
A42: ☐ | B42: Access reviews performed quarterly | C42: Access review report
A43: ☐ | B43: Default accounts disabled or renamed | C43: Security baseline check
A44: ☐ | B44: Failed login alerting configured | C44: Alert rule screenshot

Sheet 4. Network Security
A1: NETWORK SECURITY CONFIGURATION Policy Requirement: Access restrictions, secure connectivity, network segmentation (Policy S5 Section 5.2)
A2: Assessment Question: Are network security controls properly configured for your cloud services?
A4: Assessment_ID | B4: Cloud_Service_Name | C4: Vendor_Name | D4: Service_Type | E4: Environment | F4: Service_Criticality | G4: Data_Classification | H4: Configuration_Item | I4: Status | J4: Evidence_Location | K4: Gap_Description | L4: Remediation_Needed | M4: Exception_ID | N4: Risk_ID | O4: Compensating_Controls | P4: Responsible_Team | Q4: Target_Remediation_Date | R4: IP_Restrictions | S4: Private_Connectivity | T4: Network_Segmentation | U4: WAF_Enabled | V4: DDoS_Protection | W4: Firewall_Rules_Documented | X4: Public_Endpoints_Count
A5: =CONCATENATE("NET-",TEXT(ROW()-4,"000"))
A6: =CONCATENATE("NET-",TEXT(ROW()-4,"000"))
A7: =CONCATENATE("NET-",TEXT(ROW()-4,"000"))
A8: =CONCATENATE("NET-",TEXT(ROW()-4,"000"))
A9: =CONCATENATE("NET-",TEXT(ROW()-4,"000"))
A10: =CONCATENATE("NET-",TEXT(ROW()-4,"000"))
A11: =CONCATENATE("NET-",TEXT(ROW()-4,"000"))
A12: =CONCATENATE("NET-",TEXT(ROW()-4,"000"))
A13: =CONCATENATE("NET-",TEXT(ROW()-4,"000"))
A14: =CONCATENATE("NET-",TEXT(ROW()-4,"000"))
A15: =CONCATENATE("NET-",TEXT(ROW()-4,"000"))
A16: =CONCATENATE("NET-",TEXT(ROW()-4,"000"))
... A30: =CONCATENATE("NET-",TEXT(ROW()-4,"000"))
A33: COMPLIANCE CHECKLIST
A34: ☐ | B34: Requirement | C34: Evidence
A35: ☐ | B35: IP allowlisting configured for admin access | C35: Firewall rules
A36: ☐ | B36: Private endpoints used where available | C36: Network architecture
A37: ☐ | B37: VPN/ExpressRoute for sensitive workloads | C37: Connectivity config
A38: ☐ | B38: Network segmentation between environments | C38: Network diagram
A39: ☐ | B39: WAF configured for web applications | C39: WAF rules export
A40: ☐ | B40: DDoS protection enabled | C40: DDoS settings
A41: ☐ | B41: Firewall rules documented and reviewed | C41: Rule documentation
A42: ☐ | B42: Public endpoints minimized and justified | C42: Endpoint inventory

Sheet 5. Encryption Configuration
A1: ENCRYPTION CONFIGURATION Policy Requirement: Encryption at rest and in transit, key management, secure key storage (Policy S5 Section 9.2)
A2: Assessment Question: Are encryption controls properly configured for your cloud services?
A4: Assessment_ID | B4: Cloud_Service_Name | C4: Vendor_Name | D4: Service_Type | E4: Environment | F4: Service_Criticality | G4: Data_Classification | H4: Configuration_Item | I4: Status | J4: Evidence_Location | K4: Gap_Description | L4: Remediation_Needed | M4: Exception_ID | N4: Risk_ID | O4: Compensating_Controls | P4: Responsible_Team | Q4: Target_Remediation_Date | R4: Encryption_At_Rest | S4: Encryption_In_Transit | T4: Encryption_Algorithm | U4: Key_Management | V4: Key_Rotation_Period | W4: HSM_Used | X4: Last_Key_Rotation
A5: =CONCATENATE("ENC-",TEXT(ROW()-4,"000"))
A6: =CONCATENATE("ENC-",TEXT(ROW()-4,"000"))
A7: =CONCATENATE("ENC-",TEXT(ROW()-4,"000"))
A8: =CONCATENATE("ENC-",TEXT(ROW()-4,"000"))
A9: =CONCATENATE("ENC-",TEXT(ROW()-4,"000"))
A10: =CONCATENATE("ENC-",TEXT(ROW()-4,"000"))
A11: =CONCATENATE("ENC-",TEXT(ROW()-4,"000"))
A12: =CONCATENATE("ENC-",TEXT(ROW()-4,"000"))
A13: =CONCATENATE("ENC-",TEXT(ROW()-4,"000"))
A14: =CONCATENATE("ENC-",TEXT(ROW()-4,"000"))
A15: =CONCATENATE("ENC-",TEXT(ROW()-4,"000"))
A16: =CONCATENATE("ENC-",TEXT(ROW()-4,"000"))
... A30: =CONCATENATE("ENC-",TEXT(ROW()-4,"000"))
A33: COMPLIANCE CHECKLIST
A34: ☐ | B34: Requirement | C34: Evidence
A35: ☐ | B35: TLS 1.2+ enforced for all connections | C35: TLS config, SSL scan
A36: ☐ | B36: AES-256 encryption at rest enabled | C36: Encryption settings
A37: ☐ | B37: Encryption keys stored securely (HSM/KMS) | C37: Key management config
A38: ☐ | B38: Key rotation policy implemented | C38: Rotation schedule
A39: ☐ | B39: Customer-managed keys (CMK) used for sensitive data | C39: CMK configuration
A40: ☐ | B40: Key access logged and monitored | C40: Key access logs
A41: ☐ | B41: Encryption validated for backups | C41: Backup encryption check
A42: ☐ | B42: Secure deletion process documented | C42: Deletion procedures

Sheet 6. Deployment Checklist
A1: DEPLOYMENT CHECKLIST Policy Requirement: Pre-deployment validation, security approval, backup testing, monitoring (Policy S5 Section 5.2)
A2: Assessment Question: Have all deployment security requirements been met for your cloud services?
A4: Assessment_ID | B4: Cloud_Service_Name | C4: Vendor_Name | D4: Service_Type | E4: Environment | F4: Service_Criticality | G4: Data_Classification | H4: Configuration_Item | I4: Status | J4: Evidence_Location | K4: Gap_Description | L4: Remediation_Needed | M4: Exception_ID | N4: Risk_ID | O4: Compensating_Controls | P4: Responsible_Team | Q4: Target_Remediation_Date | R4: Pre_Deploy_Scan | S4: Security_Approved | T4: Backup_Tested | U4: Monitoring_Enabled | V4: Runbook_Available | W4: Rollback_Plan | X4: Deployment_Date
A5: =CONCATENATE("DEP-",TEXT(ROW()-4,"000"))
A6: =CONCATENATE("DEP-",TEXT(ROW()-4,"000"))
A7: =CONCATENATE("DEP-",TEXT(ROW()-4,"000"))
A8: =CONCATENATE("DEP-",TEXT(ROW()-4,"000"))
A9: =CONCATENATE("DEP-",TEXT(ROW()-4,"000"))
A10: =CONCATENATE("DEP-",TEXT(ROW()-4,"000"))
A11: =CONCATENATE("DEP-",TEXT(ROW()-4,"000"))
A12: =CONCATENATE("DEP-",TEXT(ROW()-4,"000"))
A13: =CONCATENATE("DEP-",TEXT(ROW()-4,"000"))
A14: =CONCATENATE("DEP-",TEXT(ROW()-4,"000"))
A15: =CONCATENATE("DEP-",TEXT(ROW()-4,"000"))
A16: =CONCATENATE("DEP-",TEXT(ROW()-4,"000"))
... A30: =CONCATENATE("DEP-",TEXT(ROW()-4,"000"))
A33: COMPLIANCE CHECKLIST
A34: ☐ | B34: Requirement | C34: Evidence
A35: ☐ | B35: Pre-deployment security scan completed | C35: Scan report
A36: ☐ | B36: Security team approval obtained | C36: Approval ticket
A37: ☐ | B37: Backup and recovery tested | C37: Test results
A38: ☐ | B38: Monitoring and alerting configured | C38: Monitoring config
A39: ☐ | B39: Deployment runbook available | C39: Runbook document
A40: ☐ | B40: Rollback plan documented and tested | C40: Rollback procedure
A41: ☐ | B41: Production deployment authorized | C41: Change approval
A42: ☐ | B42: Post-deployment validation completed | C42: Validation report

Sheet 7. Jurisdictional Risk
A1: JURISDICTIONAL RISK ASSESSMENT
A2: CLOUD Act, Data Sovereignty, and Cross-Border Transfer Analysis
A3: ⚠ US-headquartered providers may be compelled to disclose data under CLOUD Act regardless of data location.
A5: Assessment_ID | B5: Cloud_Service_Name | C5: Provider_Name | D5: Provider_HQ_Country | E5: Provider_HQ_Jurisdiction | F5: US_Parent_Company | G5: CLOUD_Act_Applicability | H5: Data_Processing_Locations | I5: EU_Data_Boundary_Available | J5: Customer_Managed_Keys | K5: Legal_Challenge_Commitment | L5: Adequacy_Decision_Status | M5: Transfer_Mechanism | N5: Risk_Level | O5: Risk_Accepted_By | P5: Risk_Acceptance_Date | Q5: Compensating_Controls | R5: Review_Date | S5: Evidence_Reference | T5: Notes
A6: =CONCATENATE("JRA-",TEXT(ROW()-5,"000"))
A7: =CONCATENATE("JRA-",TEXT(ROW()-5,"000"))
A8: =CONCATENATE("JRA-",TEXT(ROW()-5,"000"))
A9: =CONCATENATE("JRA-",TEXT(ROW()-5,"000"))
A10: =CONCATENATE("JRA-",TEXT(ROW()-5,"000"))
A11: =CONCATENATE("JRA-",TEXT(ROW()-5,"000"))
A12: =CONCATENATE("JRA-",TEXT(ROW()-5,"000"))
A13: =CONCATENATE("JRA-",TEXT(ROW()-5,"000"))
A14: =CONCATENATE("JRA-",TEXT(ROW()-5,"000"))
A15: =CONCATENATE("JRA-",TEXT(ROW()-5,"000"))
A16: =CONCATENATE("JRA-",TEXT(ROW()-5,"000"))
A17: =CONCATENATE("JRA-",TEXT(ROW()-5,"000"))
... A30: =CONCATENATE("JRA-",TEXT(ROW()-5,"000"))
A33: JURISDICTIONAL RISK CHECKLIST
A34: ☐ | B34: Requirement | C34: Evidence
A35: ☐ | B35: Provider HQ jurisdiction identified and documented | C35: Vendor documentation
A36: ☐ | B36: US parent company status verified | C36: Corporate structure review
A37: ☐ | B37: CLOUD Act exposure assessed for US-nexus providers | C37: Legal review
A38: ☐ | B38: Data processing locations documented in DPA | C38: DPA review
A39: ☐ | B39: EU Data Boundary availability checked | C39: Vendor announcement/docs
A40: ☐ | B40: Customer-managed encryption keys option evaluated | C40: Technical documentation
A41: ☐ | B41: Legal challenge commitment verified | C41: Contract/Public statement
A42: ☐ | B42: Transfer mechanism documented (SCCs, BCRs, etc.) | C42: DPA
A43: ☐ | B43: Risk acceptance recorded if residual risk remains | C43: Risk register
A44: ☐ | B44: Compensating controls documented for high-risk providers | C44: Control documentation

Sheet 8. Summary Dashboard
A1: SECURE CONFIGURATION - COMPLIANCE SUMMARY DASHBOARD v1.0
A3: TABLE 1: COMPLIANCE BY CONFIGURATION AREA
A4: Configuration Area | B4: Total Items | C4: ✅ Compliant | D4: ⚠ Partial | E4: ❌ Non-Compliant | F4: N/A | G4: Compliance %
A5: Configuration Baseline | B5: =COUNTA('2. Configuration Baseline'!B5:B30)-COUNTBLANK('2. Configuration Baseline'!B5:B30) | C5: =COUNTIF('2. Configuration Baseline'!I5:I30,"✅*") | D5: =COUNTIF('2. Configuration Baseline'!I5:I30,"⚠*") | E5: =COUNTIF('2. Configuration Baseline'!I5:I30,"❌*") | F5: =COUNTIF('2. Configuration Baseline'!I5:I30,"N/A") | G5: =IF(B5-F5>0,ROUND(C5/(B5-F5)*100,1)&"%","N/A")
A6: Access Control Setup | B6: =COUNTA('3. Access Control Setup'!B5:B30)-COUNTBLANK('3. Access Control Setup'!B5:B30) | C6: =COUNTIF('3. Access Control Setup'!I5:I30,"✅*") | D6: =COUNTIF('3. Access Control Setup'!I5:I30,"⚠*") | E6: =COUNTIF('3. Access Control Setup'!I5:I30,"❌*") | F6: =COUNTIF('3. Access Control Setup'!I5:I30,"N/A") | G6: =IF(B6-F6>0,ROUND(C6/(B6-F6)*100,1)&"%","N/A")
A7: Network Security | B7: =COUNTA('4. Network Security'!B5:B30)-COUNTBLANK('4. Network Security'!B5:B30) | C7: =COUNTIF('4. Network Security'!I5:I30,"✅*") | D7: =COUNTIF('4. Network Security'!I5:I30,"⚠*") | E7: =COUNTIF('4. Network Security'!I5:I30,"❌*") | F7: =COUNTIF('4. Network Security'!I5:I30,"N/A") | G7: =IF(B7-F7>0,ROUND(C7/(B7-F7)*100,1)&"%","N/A")
A8: Encryption Configuration | B8: =COUNTA('5. Encryption Configuration'!B5:B30)-COUNTBLANK('5. Encryption Configuration'!B5:B30) | C8: =COUNTIF('5. Encryption Configuration'!I5:I30,"✅*") | D8: =COUNTIF('5. Encryption Configuration'!I5:I30,"⚠*") | E8: =COUNTIF('5. Encryption Configuration'!I5:I30,"❌*") | F8: =COUNTIF('5. Encryption Configuration'!I5:I30,"N/A") | G8: =IF(B8-F8>0,ROUND(C8/(B8-F8)*100,1)&"%","N/A")
A9: Deployment Checklist | B9: =COUNTA('6. Deployment Checklist'!B5:B30)-COUNTBLANK('6. Deployment Checklist'!B5:B30) | C9: =COUNTIF('6. Deployment Checklist'!I5:I30,"✅*") | D9: =COUNTIF('6. Deployment Checklist'!I5:I30,"⚠*") | E9: =COUNTIF('6. Deployment Checklist'!I5:I30,"❌*") | F9: =COUNTIF('6. Deployment Checklist'!I5:I30,"N/A") | G9: =IF(B9-F9>0,ROUND(C9/(B9-F9)*100,1)&"%","N/A")
A10: TOTAL | B10: =SUM(B5:B9) | C10: =SUM(C5:C9) | D10: =SUM(D5:D9) | E10: =SUM(E5:E9) | F10: =SUM(F5:F9) | G10: =IF(B10-F10>0,ROUND(C10/(B10-F10)*100,1)&"%","N/A")
A13: TABLE 2: JURISDICTIONAL & CLOUD ACT RISK SUMMARY
A14: Metric | B14: Count | C14: Status
A15: US-HQ Providers (CLOUD Act Scope) | B15: =COUNTIF('7. Jurisdictional Risk'!E6:E30,"United States") | C15: =IF(B15>0,"{WARNING} Review","{CHECK} OK")
A16: Providers with US Parent Company | B16: =COUNTIF('7. Jurisdictional Risk'!F6:F30,"Yes") | C16: =IF(B16>0,"{WARNING} Review","{CHECK} OK")
A17: CLOUD Act Potential Exposure (Unmitigated) | B17: =COUNTIF('7. Jurisdictional Risk'!G6:G30,"Potential*") | C17: =IF(B17>0,"{WARNING} Review","{CHECK} OK")
A18: CLOUD Act Mitigated | B18: =COUNTIFS('7. Jurisdictional Risk'!G6:G30,"Mitigated*") | C18: Info
A19: High/Critical Jurisdictional Risk | B19: =COUNTIF('7. Jurisdictional Risk'!N6:N30,"High")+COUNTIF('7. Jurisdictional Risk'!N6:N30,"Critical") | C19: =IF(B19>0,"{XMARK} Action","{CHECK} OK")
A20: Providers Without EU Data Boundary | B20: =COUNTIF('7. Jurisdictional Risk'!I6:I30,"No") | C20: =IF(B20>0,"{WARNING} Review","{CHECK} OK")
A21: Providers Without Customer-Managed Keys | B21: =COUNTIF('7. Jurisdictional Risk'!J6:J30,"No") | C21: =IF(B21>0,"{WARNING} Review","{CHECK} OK")
A24: TABLE 3: REGULATORY DEPLOYMENT COMPLIANCE
A25: Metric | B25: Count | C25: Status
A26: DORA Non-Compliant Configurations | B26: =COUNTIF('2. Configuration Baseline'!Y5:Y30,"Non-Compliant") | C26: =IF(B26>0,"{XMARK} Action","{CHECK} OK")
A27: NIS2 Non-Compliant Deployments | B27: =COUNTIF('2. Configuration Baseline'!Z5:Z30,"Non-Compliant") | C27: =IF(B27>0,"{XMARK} Action","{CHECK} OK")
A28: High-Risk AI Systems Pending Assessment | B28: =COUNTIF('2. Configuration Baseline'!AA5:AA30,"*Pending*") | C28: =IF(B28>0,"{WARNING} Review","{CHECK} OK")
A32: TABLE 4: CRITICAL GAPS BY ENVIRONMENT
A33: Gap Type | B33: Count | C33: Priority
A34: Production + Non-Compliant | B34: [Manual Count] | C34: Critical
A35: Critical Service + Non-Compliant | B35: [Manual Count] | C35: Critical
A36: MFA Not Enforced (Production) | B36: [Manual Count] | C36: High
A37: No Encryption at Rest | B37: [Manual Count] | C37: High
A38: Logging Not Enabled | B38: [Manual Count] | C38: High
A39: No Backup for Critical Services | B39: [Manual Count] | C39: High

Sheet 9. Evidence Register
A1: EVIDENCE REGISTER - SECURE CONFIGURATION & DEPLOYMENT v1.0
A3: Evidence ID | B3: Cloud Service Name | C3: Configuration Area | D3: Evidence Type | E3: Description | F3: File Location | G3: Capture Date | H3: Captured By | I3: Status
A4: =CONCATENATE("EV-SCD-",TEXT(ROW()-3,"000"))
A5: =CONCATENATE("EV-SCD-",TEXT(ROW()-3,"000"))
A6: =CONCATENATE("EV-SCD-",TEXT(ROW()-3,"000"))
A7: =CONCATENATE("EV-SCD-",TEXT(ROW()-3,"000"))
A8: =CONCATENATE("EV-SCD-",TEXT(ROW()-3,"000"))
A9: =CONCATENATE("EV-SCD-",TEXT(ROW()-3,"000"))
A10: =CONCATENATE("EV-SCD-",TEXT(ROW()-3,"000"))
A11: =CONCATENATE("EV-SCD-",TEXT(ROW()-3,"000"))
A12: =CONCATENATE("EV-SCD-",TEXT(ROW()-3,"000"))
A13: =CONCATENATE("EV-SCD-",TEXT(ROW()-3,"000"))
A14: =CONCATENATE("EV-SCD-",TEXT(ROW()-3,"000"))
A15: =CONCATENATE("EV-SCD-",TEXT(ROW()-3,"000"))
... A40: =CONCATENATE("EV-SCD-",TEXT(ROW()-3,"000"))

Sheet 10. Approval Sign-Of
A1: APPROVAL SIGN-OFF - SECURE CONFIGURATION ASSESSMENT v1.0
A3: ASSESSMENT SUMMARY
A4: Assessment Completed By:
A5: Completion Date:
A6: Total Configurations Assessed: | B6: ='8. Summary Dashboard'!B9
A7: Overall Compliance %: | B7: ='8. Summary Dashboard'!G9
A8: Jurisdictional Risks Identified: | B8: ='8. Summary Dashboard'!B20
A9: DORA Config Non-Compliance: | B9: ='8. Summary Dashboard'!B27
A10: NIS2 Deployment Non-Compliance: | B10: ='8. Summary Dashboard'!B28
A11: Critical Gaps Identified:
A12: Remediation Plan Attached:
A15: IT OPERATIONS REVIEW
A16: Reviewed By (IT Ops):
A17: Review Date:
A18: Technical Accuracy Status:
A19: IT Ops Comments:
A22: SECURITY TEAM REVIEW
A23: Reviewed By (Security):
A24: Review Date:
A25: Security Compliance Status:
A26: Security Comments:
... A47: Special Considerations:
