Workbook

Sheet Executive Summary
A1: PRIV-CHK-A.1.3.5-10 — Data Subject Rights Compliance Checklist
A3: DOCUMENT INFORMATION
A4: Document ID | B4: PRIV-CHK-A.1.3.5-10
A5: Source Policy | B5: PRIV-POL-A.1.3.5-10
A6: ISO Controls | B6: Data Subject Rights
A7: Generated | B7: 10.03.2026
A8: Prepared By
A9: Organisation
A10: Review Cycle | B10: Annual
A12: OVERALL COMPLIANCE STATUS
A13: Overall Compliance | B13: ='Dashboard'!G10
A14: Status | B14: =IF(Dashboard!G10="N/A","NOT ASSESSED",IF(ISNUMBER(VALUE(SUBSTITUTE(Dashboard!G10,"%",""))),IF(VALUE(SUBSTITUTE(Dashboard!G10,"%",""))>=90,"GREEN",IF(VALUE(SUBSTITUTE(Dashboard!G10,"%",""))>=70,"AMBER","RED")),"NOT ASSESSED"))
A16: KEY METRICS
A17: Total Requirements | B17: ='Dashboard'!B10
A18: Compliant | B18: ='Dashboard'!C10
A19: Partial | B19: ='Dashboard'!D10
A20: Non-Compliant | B20: ='Dashboard'!E10
A21: Not Applicable | B21: ='Dashboard'!F10
A22: Owner Coverage | B22: =IF(Dashboard!B10=0,"N/A",ROUND((COUNTA('Consent Withdrawal Mechanism'!F4:F7)+COUNTA('Right to Object'!F4:F7)+COUNTA('Access, Correction and Erasure'!F4:F8)+COUNTA('Informing Third Parties'!F4:F6)+COUNTA('Copy of PII'!F4:F5)+COUNTA('Handling Requests'!F4:F8))/Dashboard!B10*100,0)&"%")
A24: DOMAIN STATUS SUMMARY
A25: Domain | B25: Compliance % | C25: Compliant | D25: Gaps | E25: Status
A26: Consent Withdrawal Mechanism | B26: ='Dashboard'!G4 | C26: ='Dashboard'!C4 | D26: ='Dashboard'!E4 | E26: =IF(Dashboard!G4="N/A","--",IF(ISNUMBER(VALUE(SUBSTITUTE(Dashboard!G4,"%",""))),IF(VALUE(SUBSTITUTE(Dashboard!G4,"%",""))>=90,"PASS",IF(VALUE(SUBSTITUTE(Dashboard!G4,"%",""))>=70,"REVIEW","FAIL")),"--"))
A27: Right to Object | B27: ='Dashboard'!G5 | C27: ='Dashboard'!C5 | D27: ='Dashboard'!E5 | E27: =IF(Dashboard!G5="N/A","--",IF(ISNUMBER(VALUE(SUBSTITUTE(Dashboard!G5,"%",""))),IF(VALUE(SUBSTITUTE(Dashboard!G5,"%",""))>=90,"PASS",IF(VALUE(SUBSTITUTE(Dashboard!G5,"%",""))>=70,"REVIEW","FAIL")),"--"))
A28: Access, Correction and Erasure | B28: ='Dashboard'!G6 | C28: ='Dashboard'!C6 | D28: ='Dashboard'!E6 | E28: =IF(Dashboard!G6="N/A","--",IF(ISNUMBER(VALUE(SUBSTITUTE(Dashboard!G6,"%",""))),IF(VALUE(SUBSTITUTE(Dashboard!G6,"%",""))>=90,"PASS",IF(VALUE(SUBSTITUTE(Dashboard!G6,"%",""))>=70,"REVIEW","FAIL")),"--"))
A29: Informing Third Parties | B29: ='Dashboard'!G7 | C29: ='Dashboard'!C7 | D29: ='Dashboard'!E7 | E29: =IF(Dashboard!G7="N/A","--",IF(ISNUMBER(VALUE(SUBSTITUTE(Dashboard!G7,"%",""))),IF(VALUE(SUBSTITUTE(Dashboard!G7,"%",""))>=90,"PASS",IF(VALUE(SUBSTITUTE(Dashboard!G7,"%",""))>=70,"REVIEW","FAIL")),"--"))
A30: Copy of PII | B30: ='Dashboard'!G8 | C30: ='Dashboard'!C8 | D30: ='Dashboard'!E8 | E30: =IF(Dashboard!G8="N/A","--",IF(ISNUMBER(VALUE(SUBSTITUTE(Dashboard!G8,"%",""))),IF(VALUE(SUBSTITUTE(Dashboard!G8,"%",""))>=90,"PASS",IF(VALUE(SUBSTITUTE(Dashboard!G8,"%",""))>=70,"REVIEW","FAIL")),"--"))
A31: Handling Requests | B31: ='Dashboard'!G9 | C31: ='Dashboard'!C9 | D31: ='Dashboard'!E9 | E31: =IF(Dashboard!G9="N/A","--",IF(ISNUMBER(VALUE(SUBSTITUTE(Dashboard!G9,"%",""))),IF(VALUE(SUBSTITUTE(Dashboard!G9,"%",""))>=90,"PASS",IF(VALUE(SUBSTITUTE(Dashboard!G9,"%",""))>=70,"REVIEW","FAIL")),"--"))
A33: CRITICAL ISSUES
A34: # | B34: Issue Description | C34: Domain | D34: Owner | E34: Due Date
A35: 1
A36: 2
A37: 3
A38: 4
A39: 5
A41: MANAGEMENT COMMENTARY
A42: [Enter management commentary on data subject rights posture]
A46: APPROVAL
A47: Assessed By
A48: Name:
A49: Date:
...

Sheet Dashboard
A1: Data Subject Rights — Compliance Dashboard
A3: Domain | B3: Total Reqs | C3: Compliant | D3: Partial | E3: Non-Compliant | F3: N/A | G3: Compliance %
A4: Consent Withdrawal Mechanism | B4: =COUNTA('Consent Withdrawal Mechanism'!D4:D7) | C4: =COUNTIF('Consent Withdrawal Mechanism'!D4:D7,"Compliant") | D4: =COUNTIF('Consent Withdrawal Mechanism'!D4:D7,"Partial") | E4: =COUNTIF('Consent Withdrawal Mechanism'!D4:D7,"Non-Compliant") | F4: =COUNTIF('Consent Withdrawal Mechanism'!D4:D7,"N/A") | G4: =IF((B4-F4)=0,"N/A",ROUND(C4/(B4-F4)*100,1)&"%")
A5: Right to Object | B5: =COUNTA('Right to Object'!D4:D7) | C5: =COUNTIF('Right to Object'!D4:D7,"Compliant") | D5: =COUNTIF('Right to Object'!D4:D7,"Partial") | E5: =COUNTIF('Right to Object'!D4:D7,"Non-Compliant") | F5: =COUNTIF('Right to Object'!D4:D7,"N/A") | G5: =IF((B5-F5)=0,"N/A",ROUND(C5/(B5-F5)*100,1)&"%")
A6: Access, Correction and Erasure | B6: =COUNTA('Access, Correction and Erasure'!D4:D8) | C6: =COUNTIF('Access, Correction and Erasure'!D4:D8,"Compliant") | D6: =COUNTIF('Access, Correction and Erasure'!D4:D8,"Partial") | E6: =COUNTIF('Access, Correction and Erasure'!D4:D8,"Non-Compliant") | F6: =COUNTIF('Access, Correction and Erasure'!D4:D8,"N/A") | G6: =IF((B6-F6)=0,"N/A",ROUND(C6/(B6-F6)*100,1)&"%")
A7: Informing Third Parties | B7: =COUNTA('Informing Third Parties'!D4:D6) | C7: =COUNTIF('Informing Third Parties'!D4:D6,"Compliant") | D7: =COUNTIF('Informing Third Parties'!D4:D6,"Partial") | E7: =COUNTIF('Informing Third Parties'!D4:D6,"Non-Compliant") | F7: =COUNTIF('Informing Third Parties'!D4:D6,"N/A") | G7: =IF((B7-F7)=0,"N/A",ROUND(C7/(B7-F7)*100,1)&"%")
A8: Copy of PII | B8: =COUNTA('Copy of PII'!D4:D5) | C8: =COUNTIF('Copy of PII'!D4:D5,"Compliant") | D8: =COUNTIF('Copy of PII'!D4:D5,"Partial") | E8: =COUNTIF('Copy of PII'!D4:D5,"Non-Compliant") | F8: =COUNTIF('Copy of PII'!D4:D5,"N/A") | G8: =IF((B8-F8)=0,"N/A",ROUND(C8/(B8-F8)*100,1)&"%")
A9: Handling Requests | B9: =COUNTA('Handling Requests'!D4:D8) | C9: =COUNTIF('Handling Requests'!D4:D8,"Compliant") | D9: =COUNTIF('Handling Requests'!D4:D8,"Partial") | E9: =COUNTIF('Handling Requests'!D4:D8,"Non-Compliant") | F9: =COUNTIF('Handling Requests'!D4:D8,"N/A") | G9: =IF((B9-F9)=0,"N/A",ROUND(C9/(B9-F9)*100,1)&"%")
A10: TOTAL | B10: =SUM(B4:B9) | C10: =SUM(C4:C9) | D10: =SUM(D4:D9) | E10: =SUM(E4:E9) | F10: =SUM(F4:F9) | G10: =IF((B10-F10)=0,"N/A",ROUND(C10/(B10-F10)*100,1)&"%")
A12: COMPLIANCE BY STATUS
A13: Compliant | B13: =C10 | C13: =IF(B10=0,"",ROUND(B13/B10*100,1)&"%")
A14: Partial | B14: =D10 | C14: =IF(B10=0,"",ROUND(B14/B10*100,1)&"%")
A15: Non-Compliant | B15: =E10 | C15: =IF(B10=0,"",ROUND(B15/B10*100,1)&"%")
A16: N/A | B16: =F10 | C16: =IF(B10=0,"",ROUND(B16/B10*100,1)&"%")
A18: TOP GAPS (Manual Entry)
A19: Priority | B19: Domain | C19: Requirement | D19: Owner | E19: Due Date | F19: Status
A31: COMPLIANCE TREND (Manual Entry)
A32: Assessment Date | B32: Overall % | C32: Compliant | D32: Gaps | E32: Assessor | F32: Notes

Sheet Consent Withdrawal Mechanism
A1: Consent Withdrawal Mechanism — Compliance Checklist
A2: ISO/IEC 27701:2025 — Controls A.1.3.5-10: Data Subject Rights
A3: Req # | B3: Section | C3: Requirement | D3: Status | E3: Evidence | F3: Owner | G3: Due Date | H3: Notes
A4: A.1.3.5-01 | B4: Withdrawal Mechanism | C4: The organisation shall provide PII principals with a mechanism to modify or withdraw their consent at any time. The mechanism shall be as easy to use as giving consent, clearly communicated in the privacy notice and at the point of consent, and effective without penalty or detriment.
A5: A.1.3.5-02 | B5: Processing Cessation | C5: Upon withdrawal of consent, processing based solely on that consent shall cease without undue delay. Where another lawful basis independently supports continued processing, the DPO shall assess applicability and document the basis continuation.
A6: A.1.3.5-03 | B6: PII Handling After Withdrawal | C6: After consent withdrawal, PII shall be deleted or anonymised unless a lawful basis for continued retention exists. The decision and basis shall be documented.
A7: A.1.3.5-04 | B7: Third Party Notification | C7: Third parties who received PII under the consent-based processing shall be notified of the consent withdrawal per the obligations in A.1.3.8 below.

Sheet Right to Object
A1: Right to Object — Compliance Checklist
A2: ISO/IEC 27701:2025 — Controls A.1.3.5-10: Data Subject Rights
A3: Req # | B3: Section | C3: Requirement | D3: Status | E3: Evidence | F3: Owner | G3: Due Date | H3: Notes
A4: A.1.3.6-01 | B4: Objection Mechanism | C4: The organisation shall provide PII principals with an accessible mechanism to object to the processing of their PII. The mechanism shall be clearly communicated in the privacy notice and at the latest at the first communication with the data subject.
A5: A.1.3.6-02 | B5: Legitimate Interests Objection | C5: Where processing is based on legitimate interests or public task, a data subject's objection shall result in cessation of processing unless the organisation can demonstrate compelling legitimate grounds that override the data subject's interests, rights, and freedoms. A DPO assessment of compelling grounds shall be documented.
A6: A.1.3.6-03 | B6: Direct Marketing Objection | C6: Where PII is processed for direct marketing purposes, a data subject's objection shall result in immediate cessation of direct marketing processing. No compelling grounds assessment is required; the right is absolute.
A7: A.1.3.6-04 | B7: Objection Outcome Documentation | C7: The outcome of all objection assessments (cessation decision or compelling grounds determination) shall be documented in the Data Subject Rights Register and communicated to the data subject.

Sheet Access, Correction and Erasure
A1: Access, Correction and Erasure — Compliance Checklist
A2: ISO/IEC 27701:2025 — Controls A.1.3.5-10: Data Subject Rights
A3: Req # | B3: Section | C3: Requirement | D3: Status | E3: Evidence | F3: Owner | G3: Due Date | H3: Notes
A4: A.1.3.7-01 | B4: Right of Access | C4: Upon a valid access request, the organisation shall provide: confirmation of whether PII is being processed; a copy of the PII; and supplementary information per GDPR Article 15(1) including purposes, categories, recipients, transfers, retention periods, rights, source, and automated decision-making information.
A5: A.1.3.7-02 | B5: Right to Rectification | C5: Upon a valid rectification request, the organisation shall correct inaccurate PII without undue delay. Where accuracy is disputed, the data subject may request restriction of processing pending resolution. Corrections shall be documented.
A6: A.1.3.7-03 | B6: Right to Erasure | C6: Upon a valid erasure request, the organisation shall erase PII where: it is no longer necessary for the purpose; consent is withdrawn and no other lawful basis applies; the data subject objects and there are no overriding grounds; processing was unlawful; or erasure is required by law.
A7: A.1.3.7-04 | B7: Erasure Refusal | C7: Erasure requests that cannot be fulfilled due to a countervailing legal obligation or other exemption shall receive a documented refusal with explanation and information about the right to complain to the supervisory authority.
A8: A.1.3.7-05 | B8: Right to Restriction | C8: Upon a valid restriction request (where accuracy is contested, processing is unlawful but deletion not wanted, retention needed for legal claims, or objection pending), the organisation shall restrict processing to storage only until the restriction condition resolves.

Sheet Informing Third Parties
A1: Informing Third Parties — Compliance Checklist
A2: ISO/IEC 27701:2025 — Controls A.1.3.5-10: Data Subject Rights
A3: Req # | B3: Section | C3: Requirement | D3: Status | E3: Evidence | F3: Owner | G3: Due Date | H3: Notes
A4: A.1.3.8-01 | B4: Third Party Notification Obligation | C4: Where PII has been disclosed to third parties and a data subject subsequently withdraws consent, objects, requests rectification, or requests erasure, the organisation shall inform each third party to whom the PII was disclosed of the relevant change or request.
A5: A.1.3.8-02 | B5: Disproportionate Effort Exception | C5: Where informing third parties proves impossible or involves disproportionate effort, the reason shall be documented. The data subject shall be informed of which third parties have been notified upon request.
A6: A.1.3.8-03 | B6: Third Party Notification Records | C6: Records of third party notifications shall be maintained for 3 years, including the identity of the third parties notified, the date of notification, and the content communicated.

Sheet Copy of PII
A1: Copy of PII — Compliance Checklist
A2: ISO/IEC 27701:2025 — Controls A.1.3.5-10: Data Subject Rights
A3: Req # | B3: Section | C3: Requirement | D3: Status | E3: Evidence | F3: Owner | G3: Due Date | H3: Notes
A4: A.1.3.9-01 | B4: Copy Provision | C4: Upon request, the organisation shall provide the data subject with a copy of their PII in a commonly used, machine-readable format (for portability requests under GDPR Article 20 where applicable) or in a generally accessible format.
A5: A.1.3.9-02 | B5: Fees | C5: The first copy of PII shall be provided free of charge. A reasonable administrative fee may be charged for subsequent copies, provided the data subject is informed of the fee before it is applied.

Sheet Handling Requests
A1: Handling Requests — Compliance Checklist
A2: ISO/IEC 27701:2025 — Controls A.1.3.5-10: Data Subject Rights
A3: Req # | B3: Section | C3: Requirement | D3: Status | E3: Evidence | F3: Owner | G3: Due Date | H3: Notes
A4: A.1.3.10-01 | B4: Request Procedures | C4: The organisation shall define and document policies and procedures for receiving, validating, and responding to all categories of data subject rights requests. These procedures shall be known to all personnel.
A5: A.1.3.10-02 | B5: Response Timeframes | C5: All data subject rights requests shall be acknowledged and responded to within one month of receipt. Where requests are complex or numerous, the period may be extended by a further two months — with notification to the data subject within the first month, including the reason for extension.
A6: A.1.3.10-03 | B6: Identity Verification | C6: Before fulfilling a rights request involving disclosure of PII, the organisation shall verify the identity of the requester with reasonable measures proportionate to the sensitivity of the PII. Identity verification shall not be unnecessarily burdensome.
A7: A.1.3.10-04 | B7: Manifestly Unfounded Requests | C7: Requests that are manifestly unfounded or excessive (including repetitive requests) may be refused. Refusals shall be documented with reasoning, and the data subject shall be informed of their right to complain to the supervisory authority.
A8: A.1.3.10-05 | B8: Data Subject Rights Register | C8: All rights requests shall be logged in the Data Subject Rights Register, recording: request type, receipt date, identity verification date, response date, outcome, and any extensions or refusals. The register shall be retained for 5 years.
