Workbook

Sheet Instructions & Legend
A1: ISMS-IMP-A.8.1-7-18-19.1 ISO/IEC 27001:2022 - Controls A.8.1, A.8.7, A.8.18, A.8.19: Endpoint Security
A2: ISO/IEC 27001:2022 - Controls A.8.1, A.8.7, A.8.18, A.8.19
A4: Document ID: | B4: ISMS-IMP-A.8.1-7-18-19.S1
A5: Workbook: | B5: Endpoint Inventory Assessment
A6: Version: | B6: 1.0
A7: Generated: | B7: 08.02.2026 11:49
A8: Assessment Period: | B8: [To be completed by assessor]
A9: Assessor: | B9: [Name]
A11: 📋 PURPOSE
A12: This workbook provides a comprehensive assessment of endpoint devices (laptops, desktops, mobile devices) for compliance with ISO/IEC 27001:2022 Controls A.8.1 (User Endpoint Devices), A.8.7 (Protection Against Malware), A.8.18 (Use of Privileged Utility Programs), and A.8.19 (Installation of Software on Operational Systems). The assessment evaluates: • Complete endpoint inventory and classification • Security baseline compliance (OS hardening, firewall, encryption) • Encryption coverage and key management • MDM/endpoint management enrollment and capabilities • Evidence collection and gap identification
A19: 📊 WORKBOOK STRUCTURE
A20: Sheet Name | B20: Description
A21: Inventory | B21: Complete endpoint device inventory (Device ID, Hostname, Type, OS, User, Location, Status)
A22: Classification | B22: Device type distribution analysis and ownership model breakdown
A23: Baseline_Compliance | B23: Per-endpoint baseline compliance assessment (OS hardening, firewall, antivirus)
A24: Encryption_Status | B24: Encryption technology, status, key management per endpoint
A25: Management_Enrollment | B25: MDM/endpoint management platform, enrollment status, capabilities
A26: Capability_Requirements | B26: Policy requirements mapped to implementation (A.8.1 control mapping)
A27: Evidence_Register | B27: Comprehensive evidence documentation (100 evidence entries)
A28: Gap_Analysis | B28: Gap identification, severity classification, remediation tracking
A29: Approval_Sign_Off | B29: Multi-level approval workflow (Assessor → IT Ops Manager → CISO)
A31: 🎨 STATUS LEGEND
A32: Status/Severity | B32: Meaning | C32: Color
A33: {CHECK} Compliant / Active / Enrolled | B33: Device meets all requirements, fully compliant | C33: █████
A34: {WARNING} Partial Compliance | B34: Device partially compliant, some requirements not met | C34: █████
A35: {XMARK} Non-Compliant / Not Installed | B35: Device does not meet requirements, critical gap | C35: █████
A36: ❓ Unknown | B36: Status cannot be determined, requires investigation | C36: █████
A37: 🔴 Critical Severity | B37: Critical gap requiring immediate remediation (7 days) | C37: █████
A38: 🟠 High Severity | B38: High-priority gap requiring remediation (30 days) | C38: █████
A39: 🟡 Medium Severity | B39: Medium-priority gap requiring remediation (60 days) | C39: █████
A40: 🟢 Low Severity | B40: Low-priority gap, scheduled remediation (90 days) | C40: █████
A42: 📖 USAGE INSTRUCTIONS
A43: Step | B43: Instructions
A44: 1. Inventory Sheet | B44: Complete endpoint inventory from MDM/SCCM/Jamf exports. Populate Device ID, Hostname, Type, OS, User, Location, Status for ALL endpoints.
A45: 2. Classification Sheet | B45: Auto-calculates device type distribution. Review for accuracy.
A46: 3. Baseline_Compliance | B46: Assess each endpoint against security baseline (OS hardening, firewall, encryption, antivirus). Use compliance status dropdowns.
A47: 4. Encryption_Status | B47: Document encryption technology per endpoint (BitLocker, FileVault, LUKS, built-in). Verify encryption active.
A48: 5. Management_Enrollment | B48: Document MDM platform enrollment status. Identify unmanaged devices.
A49: 6. Capability_Requirements | B49: Map policy requirements to implementation. Verify all 30 requirements addressed.
A50: 7. Evidence_Register | B50: Document ALL evidence (config exports, screenshots, reports, certificates). Minimum 20 evidence entries.
...

Sheet Inventory
A1: ENDPOINT DEVICE INVENTORY
A2: Complete inventory of all endpoint devices (laptops, desktops, mobile devices, tablets)
A4: Device ID | B4: Hostname | C4: Device Type | D4: Operating System | E4: OS Version | F4: Primary User | G4: Department | H4: Ownership Model | I4: Location | J4: Serial Number | K4: Asset Tag | L4: Purchase Date | M4: Last Seen | N4: Device Status | O4: Criticality | P4: Notes
A5: EP-1001
A6: EP-1002
A7: EP-1003
A8: EP-1004
A9: EP-1005
A10: EP-1006
A11: EP-1007
A12: EP-1008
A13: EP-1009
A14: EP-1010
A15: EP-1011
A16: EP-1012
... A57: 📊 INVENTORY SUMMARY
A58: Total Endpoints: | B58: =COUNTA(B5:B54)
A59: Active Devices: | B59: =COUNTIF(N5:N54,"✅ Active")
A60: Inactive/Retired: | B60: =COUNTIF(N5:N54,"⏸️ Inactive")+COUNTIF(N5:N54,"🔒 Retired")

Sheet Classification
A1: ENDPOINT CLASSIFICATION & DISTRIBUTION
A2: Device type distribution, ownership model breakdown, and criticality analysis
A4: 💻 DEVICE TYPE DISTRIBUTION
A5: Device Type | B5: Count | C5: Percentage
A6: 💻 Laptop | B6: =COUNTIF(Inventory!C:C,"💻 Laptop") | C6: =IF(B12>0,B6/B12*100,0)&"%"
A7: 🖥️ Desktop | B7: =COUNTIF(Inventory!C:C,"🖥️ Desktop") | C7: =IF(B13>0,B7/B13*100,0)&"%"
A8: 📱 Mobile (iOS) | B8: =COUNTIF(Inventory!C:C,"📱 Mobile (iOS)") | C8: =IF(B14>0,B8/B14*100,0)&"%"
A9: 📱 Mobile (Android) | B9: =COUNTIF(Inventory!C:C,"📱 Mobile (Android)") | C9: =IF(B15>0,B9/B15*100,0)&"%"
A10: ⌚ Tablet | B10: =COUNTIF(Inventory!C:C,"⌚ Tablet") | C10: =IF(B16>0,B10/B16*100,0)&"%"
A11: 🔧 Workstation | B11: =COUNTIF(Inventory!C:C,"🔧 Workstation") | C11: =IF(B17>0,B11/B17*100,0)&"%"
A12: Other | B12: =COUNTIF(Inventory!C:C,"Other") | C12: =IF(B18>0,B12/B18*100,0)&"%"
A13: TOTAL | B13: =SUM(B6:B12)
A15: 🏢 OWNERSHIP MODEL DISTRIBUTION
A16: Ownership Model | B16: Count | C16: Percentage
A17: 🏢 Corporate-Owned | B17: =COUNTIF(Inventory!H:H,"🏢 Corporate-Owned") | C17: =IF(B21>0,B17/B21*100,0)&"%"
A18: 👤 BYOD | B18: =COUNTIF(Inventory!H:H,"👤 BYOD") | C18: =IF(B22>0,B18/B22*100,0)&"%"
A19: 🤝 Contractor | B19: =COUNTIF(Inventory!H:H,"🤝 Contractor") | C19: =IF(B23>0,B19/B23*100,0)&"%"
A20: 👥 Shared Device | B20: =COUNTIF(Inventory!H:H,"👥 Shared Device") | C20: =IF(B24>0,B20/B24*100,0)&"%"
A21: Other | B21: =COUNTIF(Inventory!H:H,"Other") | C21: =IF(B25>0,B21/B25*100,0)&"%"
A22: TOTAL | B22: =SUM(B17:B21)
A24: 🎯 CRITICALITY DISTRIBUTION
A25: Criticality Level | B25: Count | C25: Percentage
A26: 🔴 Critical | B26: =COUNTIF(Inventory!O:O,"🔴 Critical") | C26: =IF(B29>0,B26/B29*100,0)&"%"
A27: 🟠 High | B27: =COUNTIF(Inventory!O:O,"🟠 High") | C27: =IF(B30>0,B27/B30*100,0)&"%"
A28: 🟡 Medium | B28: =COUNTIF(Inventory!O:O,"🟡 Medium") | C28: =IF(B31>0,B28/B31*100,0)&"%"
A29: 🟢 Low | B29: =COUNTIF(Inventory!O:O,"🟢 Low") | C29: =IF(B32>0,B29/B32*100,0)&"%"
A30: TOTAL | B30: =SUM(B26:B29)

Sheet Baseline_Compliance
A1: ENDPOINT BASELINE COMPLIANCE ASSESSMENT
A2: Per-endpoint security baseline compliance (OS hardening, firewall, antivirus, configuration)
A4: Device ID | B4: Hostname | C4: Device Type | D4: OS Hardening | E4: Firewall Status | F4: Antivirus Status | G4: Screen Lock | H4: Auto-Lock Time | I4: Password Policy | J4: Baseline Profile | K4: Compliance Status | L4: Notes
A5: =Inventory!A5 | B5: =Inventory!B5 | C5: =Inventory!C5 | K5: =IF(AND(D5="✅ Compliant",E5="✅ Enabled",F5="✅ Active",G5="Yes",I5="✅ Compliant"),"✅ Compliant",IF(OR(D5="❌ Non-Compliant",E5="❌ Disabled",F5="❌ Not Installed"),"❌ Non-Compliant","⚠ Partial"))
A6: =Inventory!A6 | B6: =Inventory!B6 | C6: =Inventory!C6 | K6: =IF(AND(D6="✅ Compliant",E6="✅ Enabled",F6="✅ Active",G6="Yes",I6="✅ Compliant"),"✅ Compliant",IF(OR(D6="❌ Non-Compliant",E6="❌ Disabled",F6="❌ Not Installed"),"❌ Non-Compliant","⚠ Partial"))
A7: =Inventory!A7 | B7: =Inventory!B7 | C7: =Inventory!C7 | K7: =IF(AND(D7="✅ Compliant",E7="✅ Enabled",F7="✅ Active",G7="Yes",I7="✅ Compliant"),"✅ Compliant",IF(OR(D7="❌ Non-Compliant",E7="❌ Disabled",F7="❌ Not Installed"),"❌ Non-Compliant","⚠ Partial"))
A8: =Inventory!A8 | B8: =Inventory!B8 | C8: =Inventory!C8 | K8: =IF(AND(D8="✅ Compliant",E8="✅ Enabled",F8="✅ Active",G8="Yes",I8="✅ Compliant"),"✅ Compliant",IF(OR(D8="❌ Non-Compliant",E8="❌ Disabled",F8="❌ Not Installed"),"❌ Non-Compliant","⚠ Partial"))
A9: =Inventory!A9 | B9: =Inventory!B9 | C9: =Inventory!C9 | K9: =IF(AND(D9="✅ Compliant",E9="✅ Enabled",F9="✅ Active",G9="Yes",I9="✅ Compliant"),"✅ Compliant",IF(OR(D9="❌ Non-Compliant",E9="❌ Disabled",F9="❌ Not Installed"),"❌ Non-Compliant","⚠ Partial"))
A10: =Inventory!A10 | B10: =Inventory!B10 | C10: =Inventory!C10 | K10: =IF(AND(D10="✅ Compliant",E10="✅ Enabled",F10="✅ Active",G10="Yes",I10="✅ Compliant"),"✅ Compliant",IF(OR(D10="❌ Non-Compliant",E10="❌ Disabled",F10="❌ Not Installed"),"❌ Non-Compliant","⚠ Partial"))
A11: =Inventory!A11 | B11: =Inventory!B11 | C11: =Inventory!C11 | K11: =IF(AND(D11="✅ Compliant",E11="✅ Enabled",F11="✅ Active",G11="Yes",I11="✅ Compliant"),"✅ Compliant",IF(OR(D11="❌ Non-Compliant",E11="❌ Disabled",F11="❌ Not Installed"),"❌ Non-Compliant","⚠ Partial"))
A12: =Inventory!A12 | B12: =Inventory!B12 | C12: =Inventory!C12 | K12: =IF(AND(D12="✅ Compliant",E12="✅ Enabled",F12="✅ Active",G12="Yes",I12="✅ Compliant"),"✅ Compliant",IF(OR(D12="❌ Non-Compliant",E12="❌ Disabled",F12="❌ Not Installed"),"❌ Non-Compliant","⚠ Partial"))
A13: =Inventory!A13 | B13: =Inventory!B13 | C13: =Inventory!C13 | K13: =IF(AND(D13="✅ Compliant",E13="✅ Enabled",F13="✅ Active",G13="Yes",I13="✅ Compliant"),"✅ Compliant",IF(OR(D13="❌ Non-Compliant",E13="❌ Disabled",F13="❌ Not Installed"),"❌ Non-Compliant","⚠ Partial"))
A14: =Inventory!A14 | B14: =Inventory!B14 | C14: =Inventory!C14 | K14: =IF(AND(D14="✅ Compliant",E14="✅ Enabled",F14="✅ Active",G14="Yes",I14="✅ Compliant"),"✅ Compliant",IF(OR(D14="❌ Non-Compliant",E14="❌ Disabled",F14="❌ Not Installed"),"❌ Non-Compliant","⚠ Partial"))
A15: =Inventory!A15 | B15: =Inventory!B15 | C15: =Inventory!C15 | K15: =IF(AND(D15="✅ Compliant",E15="✅ Enabled",F15="✅ Active",G15="Yes",I15="✅ Compliant"),"✅ Compliant",IF(OR(D15="❌ Non-Compliant",E15="❌ Disabled",F15="❌ Not Installed"),"❌ Non-Compliant","⚠ Partial"))
A16: =Inventory!A16 | B16: =Inventory!B16 | C16: =Inventory!C16 | K16: =IF(AND(D16="✅ Compliant",E16="✅ Enabled",F16="✅ Active",G16="Yes",I16="✅ Compliant"),"✅ Compliant",IF(OR(D16="❌ Non-Compliant",E16="❌ Disabled",F16="❌ Not Installed"),"❌ Non-Compliant","⚠ Partial"))
... A54: =Inventory!A54 | B54: =Inventory!B54 | C54: =Inventory!C54 | K54: =IF(AND(D54="✅ Compliant",E54="✅ Enabled",F54="✅ Active",G54="Yes",I54="✅ Compliant"),"✅ Compliant",IF(OR(D54="❌ Non-Compliant",E54="❌ Disabled",F54="❌ Not Installed"),"❌ Non-Compliant","⚠ Partial"))
A57: 📊 BASELINE COMPLIANCE SUMMARY
A58: ✅ Fully Compliant: | B58: =COUNTIF(K5:K54,"✅ Compliant")
A59: ⚠ Partially Compliant: | B59: =COUNTIF(K5:K54,"⚠ Partial")
A60: ❌ Non-Compliant: | B60: =COUNTIF(K5:K54,"❌ Non-Compliant")
A61: Compliance Rate: | B61: =IF(COUNTA(K5:K54)>0,COUNTIF(K5:K54,"✅ Compliant")/COUNTA(K5:K54)*100,0)&"%"

Sheet Encryption_Status
A1: ENDPOINT ENCRYPTION STATUS
A2: Encryption technology, status, key management, and recovery procedures per endpoint
A4: Device ID | B4: Hostname | C4: Device Type | D4: Encryption Technology | E4: Encryption Status | F4: Full Disk Encryption | G4: Key Escrow/Recovery | H4: Recovery Key Location | I4: Last Verified Date | J4: Notes
A5: =Inventory!A5 | B5: =Inventory!B5 | C5: =Inventory!C5
A6: =Inventory!A6 | B6: =Inventory!B6 | C6: =Inventory!C6
A7: =Inventory!A7 | B7: =Inventory!B7 | C7: =Inventory!C7
A8: =Inventory!A8 | B8: =Inventory!B8 | C8: =Inventory!C8
A9: =Inventory!A9 | B9: =Inventory!B9 | C9: =Inventory!C9
A10: =Inventory!A10 | B10: =Inventory!B10 | C10: =Inventory!C10
A11: =Inventory!A11 | B11: =Inventory!B11 | C11: =Inventory!C11
A12: =Inventory!A12 | B12: =Inventory!B12 | C12: =Inventory!C12
A13: =Inventory!A13 | B13: =Inventory!B13 | C13: =Inventory!C13
A14: =Inventory!A14 | B14: =Inventory!B14 | C14: =Inventory!C14
A15: =Inventory!A15 | B15: =Inventory!B15 | C15: =Inventory!C15
A16: =Inventory!A16 | B16: =Inventory!B16 | C16: =Inventory!C16
... A54: =Inventory!A54 | B54: =Inventory!B54 | C54: =Inventory!C54
A57: 📊 ENCRYPTION COVERAGE SUMMARY
A58: ✅ Encrypted: | B58: =COUNTIF(E5:E54,"✅ Encrypted")
A59: ❌ Not Encrypted: | B59: =COUNTIF(E5:E54,"❌ Not Encrypted")
A60: Encryption Coverage Rate: | B60: =IF(COUNTA(E5:E54)>0,COUNTIF(E5:E54,"✅ Encrypted")/COUNTA(E5:E54)*100,0)&"%"
A62: BitLocker (Windows): | B62: =COUNTIF(D5:D54,"BitLocker")
A63: FileVault (macOS): | B63: =COUNTIF(D5:D54,"FileVault")
A64: Built-in (iOS/Android): | B64: =COUNTIF(D5:D54,"Built-in (iOS/Android)")
A65: LUKS (Linux): | B65: =COUNTIF(D5:D54,"LUKS")

Sheet Management_Enrollment
A1: ENDPOINT MANAGEMENT ENROLLMENT
A2: MDM platform enrollment status, capabilities, and management coverage
A4: Device ID | B4: Hostname | C4: Device Type | D4: MDM Platform | E4: Enrollment Status | F4: Management Agent Version | G4: Last Check-In | H4: Remote Wipe Capable | I4: Policy Enforcement | J4: Compliance Policy Applied | K4: Notes
A5: =Inventory!A5 | B5: =Inventory!B5 | C5: =Inventory!C5
A6: =Inventory!A6 | B6: =Inventory!B6 | C6: =Inventory!C6
A7: =Inventory!A7 | B7: =Inventory!B7 | C7: =Inventory!C7
A8: =Inventory!A8 | B8: =Inventory!B8 | C8: =Inventory!C8
A9: =Inventory!A9 | B9: =Inventory!B9 | C9: =Inventory!C9
A10: =Inventory!A10 | B10: =Inventory!B10 | C10: =Inventory!C10
A11: =Inventory!A11 | B11: =Inventory!B11 | C11: =Inventory!C11
A12: =Inventory!A12 | B12: =Inventory!B12 | C12: =Inventory!C12
A13: =Inventory!A13 | B13: =Inventory!B13 | C13: =Inventory!C13
A14: =Inventory!A14 | B14: =Inventory!B14 | C14: =Inventory!C14
A15: =Inventory!A15 | B15: =Inventory!B15 | C15: =Inventory!C15
A16: =Inventory!A16 | B16: =Inventory!B16 | C16: =Inventory!C16
... A54: =Inventory!A54 | B54: =Inventory!B54 | C54: =Inventory!C54
A57: 📊 MANAGEMENT ENROLLMENT SUMMARY
A58: ✅ Enrolled: | B58: =COUNTIF(E5:E54,"✅ Enrolled")
A59: ❌ Not Enrolled: | B59: =COUNTIF(E5:E54,"❌ Not Enrolled")
A60: Enrollment Rate: | B60: =IF(COUNTA(E5:E54)>0,COUNTIF(E5:E54,"✅ Enrolled")/COUNTA(E5:E54)*100,0)&"%"
A62: By MDM Platform:
A63: Microsoft Intune: | B63: =COUNTIF(D5:D54,"Microsoft Intune")
A64: Jamf Pro: | B64: =COUNTIF(D5:D54,"Jamf Pro")
A65: SCCM: | B65: =COUNTIF(D5:D54,"SCCM")
A66: None: | B66: =COUNTIF(D5:D54,"None")

Sheet Capability_Requirements
A1: CAPABILITY REQUIREMENTS MAPPING
A2: A.8.1 Policy Requirements → Implementation Verification (30 requirements)
A4: Req ID | B4: Policy Requirement | C4: Implemented | D4: Evidence Reference | E4: Notes | F4: Status
A5: REQ-A81-001 | B5: Complete endpoint inventory maintained | F5: =IF(C5="Yes","✅ Compliant",IF(C5="N/A","N/A","❌ Gap"))
A6: REQ-A81-002 | B6: Endpoints classified by type, ownership, criticality | F6: =IF(C6="Yes","✅ Compliant",IF(C6="N/A","N/A","❌ Gap"))
A7: REQ-A81-003 | B7: Security baselines defined per endpoint type | F7: =IF(C7="Yes","✅ Compliant",IF(C7="N/A","N/A","❌ Gap"))
A8: REQ-A81-004 | B8: Baseline compliance ≥95% for corporate endpoints | F8: =IF(C8="Yes","✅ Compliant",IF(C8="N/A","N/A","❌ Gap"))
A9: REQ-A81-005 | B9: Full disk encryption for laptops (≥95%) | F9: =IF(C9="Yes","✅ Compliant",IF(C9="N/A","N/A","❌ Gap"))
A10: REQ-A81-006 | B10: Full disk encryption for desktops (≥90%) | F10: =IF(C10="Yes","✅ Compliant",IF(C10="N/A","N/A","❌ Gap"))
A11: REQ-A81-007 | B11: Mobile devices encrypted (≥95%) | F11: =IF(C11="Yes","✅ Compliant",IF(C11="N/A","N/A","❌ Gap"))
A12: REQ-A81-008 | B12: Encryption key escrow/recovery implemented | F12: =IF(C12="Yes","✅ Compliant",IF(C12="N/A","N/A","❌ Gap"))
A13: REQ-A81-009 | B13: MDM enrollment ≥95% corporate endpoints | F13: =IF(C13="Yes","✅ Compliant",IF(C13="N/A","N/A","❌ Gap"))
A14: REQ-A81-010 | B14: MDM enrollment ≥80% BYOD (if BYOD allowed) | F14: =IF(C14="Yes","✅ Compliant",IF(C14="N/A","N/A","❌ Gap"))
A15: REQ-A81-011 | B15: Remote wipe capability for all corporate mobile devices | F15: =IF(C15="Yes","✅ Compliant",IF(C15="N/A","N/A","❌ Gap"))
A16: REQ-A81-012 | B16: Screen lock enforced (max 15 minutes) | F16: =IF(C16="Yes","✅ Compliant",IF(C16="N/A","N/A","❌ Gap"))
... A34: REQ-A81-030 | B34: Annual endpoint security assessment | F34: =IF(C34="Yes","✅ Compliant",IF(C34="N/A","N/A","❌ Gap"))
A37: 📊 REQUIREMENTS COMPLIANCE SUMMARY
A38: Total Requirements: | B38: 30
A39: Implemented: | B39: =COUNTIF(C5:C34,"Yes")
A40: Not Implemented: | B40: =COUNTIF(C5:C34,"No")
A41: Compliance Rate: | B41: =IF(COUNT(B39:B40)>0,B39/B38*100,0)&"%"

Sheet Evidence_Register
A1: EVIDENCE REGISTER
A2: Comprehensive evidence documentation for endpoint inventory assessment (100 evidence entries)
A4: Evidence ID | B4: Evidence Type | C4: Description | D4: Related Requirement | E4: Related Worksheet/Device | F4: File Location | G4: Collection Date | H4: Collected By | I4: Verification Status | J4: Notes
A5: EVD-001
A6: EVD-002
A7: EVD-003
A8: EVD-004
A9: EVD-005
A10: EVD-006
A11: EVD-007
A12: EVD-008
A13: EVD-009
A14: EVD-010
A15: EVD-011
A16: EVD-012
... A107: 📊 EVIDENCE SUMMARY
A108: Total Evidence Entries: | B108: =COUNTA(C5:C104)
A109: ✅ Verified: | B109: =COUNTIF(I5:I104,"✅ Verified")
A110: ⏳ Pending: | B110: =COUNTIF(I5:I104,"⏳ Pending")
A111: Verification Rate: | B111: =IF(B108>0,B109/B108*100,0)&"%"

Sheet Gap_Analysis
A1: GAP ANALYSIS & REMEDIATION TRACKING
A2: Gap identification, severity classification, remediation planning and tracking (40 gap entries)
A4: Gap ID | B4: Gap Description | C4: Affected Devices/Count | D4: Related Requirement | E4: Severity | F4: Risk | G4: Root Cause | H4: Remediation Plan | I4: Owner | J4: Due Date | K4: Status | L4: Budget Required | M4: Notes
A5: GAP-001
A6: GAP-002
A7: GAP-003
A8: GAP-004
A9: GAP-005
A10: GAP-006
A11: GAP-007
A12: GAP-008
A13: GAP-009
A14: GAP-010
A15: GAP-011
A16: GAP-012
... A47: 📊 GAP SUMMARY BY SEVERITY
A48: 🔴 Critical: | B48: =COUNTIF(E5:E44,"🔴 Critical")
A49: 🟠 High: | B49: =COUNTIF(E5:E44,"🟠 High")
A50: 🟡 Medium: | B50: =COUNTIF(E5:E44,"🟡 Medium")
A51: 🟢 Low: | B51: =COUNTIF(E5:E44,"🟢 Low")
A53: 📊 GAP SUMMARY BY STATUS
A54: 🔴 Open: | B54: =COUNTIF(K5:K44,"🔴 Open")
A55: 🟡 In Progress: | B55: =COUNTIF(K5:K44,"🟡 In Progress")
A56: ✅ Closed: | B56: =COUNTIF(K5:K44,"✅ Closed")

Sheet Approval_Sign_Off
A1: APPROVAL & SIGN-OFF WORKFLOW
A2: Three-level approval: Assessor → IT Operations Manager → CISO
A4: 📋 ASSESSMENT SUMMARY
A5: Assessment Period: | B5: [Start Date] to [End Date]
A6: Total Endpoints Assessed: | B6: =COUNTA(Inventory!A5:A54)
A7: Baseline Compliance Rate: | B7: =Baseline_Compliance!B58
A8: Encryption Coverage Rate: | B8: =Encryption_Status!B58
A9: MDM Enrollment Rate: | B9: =Management_Enrollment!B58
A10: Requirements Implemented: | B10: =Capability_Requirements!B37
A11: Critical Gaps: | B11: =Gap_Analysis!B48
A12: High Gaps: | B12: =Gap_Analysis!B49
A13: Evidence Entries: | B13: =Evidence_Register!B107
A15: ✍️ APPROVAL WORKFLOW
A16: LEVEL 1: ASSESSOR SIGN-OFF
A17: Assessor Name:
A18: Assessor Title:
A19: Assessment Complete Date:
A20: Assessor Signature:
A21: Assessor Comments:
A23: LEVEL 2: IT OPERATIONS MANAGER REVIEW
A24: Reviewer Name:
A25: Review Date:
A26: Decision:
A27: IT Ops Manager Signature:
... A39: Next Assessment Due:
