Workbook

Sheet Executive Summary
A1: ISMS-OP-CHK-A.5.31 — Legal, Statutory, Regulatory and Contractual Requirements Compliance Checklist
A3: DOCUMENT INFORMATION
A4: Document ID | B4: ISMS-OP-CHK-A.5.31
A5: Source Policy | B5: ISMS-OP-POL-A.5.31
A6: ISO Controls | B6: Legal, Statutory, Regulatory and Contractual Requirements
A7: Generated | B7: 08.02.2026
A8: Prepared By
A9: Organisation
A10: Review Cycle | B10: Annual
A12: OVERALL COMPLIANCE STATUS
A13: Overall Compliance | B13: ='Dashboard'!G10
A14: Status | B14: =IF(Dashboard!G10="N/A","NOT ASSESSED",IF(ISNUMBER(VALUE(SUBSTITUTE(Dashboard!G10,"%",""))),IF(VALUE(SUBSTITUTE(Dashboard!G10,"%",""))>=90,"GREEN",IF(VALUE(SUBSTITUTE(Dashboard!G10,"%",""))>=70,"AMBER","RED")),"NOT ASSESSED"))
A16: KEY METRICS
A17: Total Requirements | B17: ='Dashboard'!B10
A18: Compliant | B18: ='Dashboard'!C10
A19: Partial | B19: ='Dashboard'!D10
A20: Non-Compliant | B20: ='Dashboard'!E10
A21: Not Applicable | B21: ='Dashboard'!F10
A22: Owner Coverage | B22: =IF(Dashboard!B10=0,"N/A",ROUND((COUNTA('Reg Ident and Applicability'!F4:F12)+COUNTA('Swiss Regulatory Requirements'!F4:F36)+COUNTA('Contractual Requirements'!F4:F14)+COUNTA('Compliance Mon and Review'!F4:F10)+COUNTA('Compliance Measurement'!F4:F4)+COUNTA('Reg Change Comms (SOC 2 CC2.3)'!F4:F4))/Dashboard!B10*100,0)&"%")
A24: DOMAIN STATUS SUMMARY
A25: Domain | B25: Compliance % | C25: Compliant | D25: Gaps | E25: Status
A26: Reg Ident and Applicability | B26: ='Dashboard'!G4 | C26: ='Dashboard'!C4 | D26: ='Dashboard'!E4 | E26: =IF(Dashboard!G4="N/A","--",IF(ISNUMBER(VALUE(SUBSTITUTE(Dashboard!G4,"%",""))),IF(VALUE(SUBSTITUTE(Dashboard!G4,"%",""))>=90,"PASS",IF(VALUE(SUBSTITUTE(Dashboard!G4,"%",""))>=70,"REVIEW","FAIL")),"--"))
A27: Swiss Regulatory Requirements | B27: ='Dashboard'!G5 | C27: ='Dashboard'!C5 | D27: ='Dashboard'!E5 | E27: =IF(Dashboard!G5="N/A","--",IF(ISNUMBER(VALUE(SUBSTITUTE(Dashboard!G5,"%",""))),IF(VALUE(SUBSTITUTE(Dashboard!G5,"%",""))>=90,"PASS",IF(VALUE(SUBSTITUTE(Dashboard!G5,"%",""))>=70,"REVIEW","FAIL")),"--"))
A28: Contractual Requirements | B28: ='Dashboard'!G6 | C28: ='Dashboard'!C6 | D28: ='Dashboard'!E6 | E28: =IF(Dashboard!G6="N/A","--",IF(ISNUMBER(VALUE(SUBSTITUTE(Dashboard!G6,"%",""))),IF(VALUE(SUBSTITUTE(Dashboard!G6,"%",""))>=90,"PASS",IF(VALUE(SUBSTITUTE(Dashboard!G6,"%",""))>=70,"REVIEW","FAIL")),"--"))
A29: Compliance Mon and Review | B29: ='Dashboard'!G7 | C29: ='Dashboard'!C7 | D29: ='Dashboard'!E7 | E29: =IF(Dashboard!G7="N/A","--",IF(ISNUMBER(VALUE(SUBSTITUTE(Dashboard!G7,"%",""))),IF(VALUE(SUBSTITUTE(Dashboard!G7,"%",""))>=90,"PASS",IF(VALUE(SUBSTITUTE(Dashboard!G7,"%",""))>=70,"REVIEW","FAIL")),"--"))
A30: Compliance Measurement | B30: ='Dashboard'!G8 | C30: ='Dashboard'!C8 | D30: ='Dashboard'!E8 | E30: =IF(Dashboard!G8="N/A","--",IF(ISNUMBER(VALUE(SUBSTITUTE(Dashboard!G8,"%",""))),IF(VALUE(SUBSTITUTE(Dashboard!G8,"%",""))>=90,"PASS",IF(VALUE(SUBSTITUTE(Dashboard!G8,"%",""))>=70,"REVIEW","FAIL")),"--"))
A31: Reg Change Comms (SOC 2 CC2.3) | B31: ='Dashboard'!G9 | C31: ='Dashboard'!C9 | D31: ='Dashboard'!E9 | E31: =IF(Dashboard!G9="N/A","--",IF(ISNUMBER(VALUE(SUBSTITUTE(Dashboard!G9,"%",""))),IF(VALUE(SUBSTITUTE(Dashboard!G9,"%",""))>=90,"PASS",IF(VALUE(SUBSTITUTE(Dashboard!G9,"%",""))>=70,"REVIEW","FAIL")),"--"))
A33: CRITICAL ISSUES
A34: # | B34: Issue Description | C34: Domain | D34: Owner | E34: Due Date
A35: 1
A36: 2
A37: 3
A38: 4
A39: 5
A41: MANAGEMENT COMMENTARY
A42: [Enter management commentary on legal, statutory, regulatory and contractual requirements posture]
A46: APPROVAL
A47: Assessed By
A48: Name:
A49: Date:
...

Sheet Dashboard
A1: Legal, Statutory, Regulatory and Contractual Requirements — Compliance Dashboard
A3: Domain | B3: Total Reqs | C3: Compliant | D3: Partial | E3: Non-Compliant | F3: N/A | G3: Compliance %
A4: Reg Ident and Applicability | B4: =COUNTA('Reg Ident and Applicability'!D4:D12) | C4: =COUNTIF('Reg Ident and Applicability'!D4:D12,"Compliant") | D4: =COUNTIF('Reg Ident and Applicability'!D4:D12,"Partial") | E4: =COUNTIF('Reg Ident and Applicability'!D4:D12,"Non-Compliant") | F4: =COUNTIF('Reg Ident and Applicability'!D4:D12,"N/A") | G4: =IF((B4-F4)=0,"N/A",ROUND(C4/(B4-F4)*100,1)&"%")
A5: Swiss Regulatory Requirements | B5: =COUNTA('Swiss Regulatory Requirements'!D4:D36) | C5: =COUNTIF('Swiss Regulatory Requirements'!D4:D36,"Compliant") | D5: =COUNTIF('Swiss Regulatory Requirements'!D4:D36,"Partial") | E5: =COUNTIF('Swiss Regulatory Requirements'!D4:D36,"Non-Compliant") | F5: =COUNTIF('Swiss Regulatory Requirements'!D4:D36,"N/A") | G5: =IF((B5-F5)=0,"N/A",ROUND(C5/(B5-F5)*100,1)&"%")
A6: Contractual Requirements | B6: =COUNTA('Contractual Requirements'!D4:D14) | C6: =COUNTIF('Contractual Requirements'!D4:D14,"Compliant") | D6: =COUNTIF('Contractual Requirements'!D4:D14,"Partial") | E6: =COUNTIF('Contractual Requirements'!D4:D14,"Non-Compliant") | F6: =COUNTIF('Contractual Requirements'!D4:D14,"N/A") | G6: =IF((B6-F6)=0,"N/A",ROUND(C6/(B6-F6)*100,1)&"%")
A7: Compliance Mon and Review | B7: =COUNTA('Compliance Mon and Review'!D4:D10) | C7: =COUNTIF('Compliance Mon and Review'!D4:D10,"Compliant") | D7: =COUNTIF('Compliance Mon and Review'!D4:D10,"Partial") | E7: =COUNTIF('Compliance Mon and Review'!D4:D10,"Non-Compliant") | F7: =COUNTIF('Compliance Mon and Review'!D4:D10,"N/A") | G7: =IF((B7-F7)=0,"N/A",ROUND(C7/(B7-F7)*100,1)&"%")
A8: Compliance Measurement | B8: =COUNTA('Compliance Measurement'!D4:D4) | C8: =COUNTIF('Compliance Measurement'!D4:D4,"Compliant") | D8: =COUNTIF('Compliance Measurement'!D4:D4,"Partial") | E8: =COUNTIF('Compliance Measurement'!D4:D4,"Non-Compliant") | F8: =COUNTIF('Compliance Measurement'!D4:D4,"N/A") | G8: =IF((B8-F8)=0,"N/A",ROUND(C8/(B8-F8)*100,1)&"%")
A9: Reg Change Comms (SOC 2 CC2.3) | B9: =COUNTA('Reg Change Comms (SOC 2 CC2.3)'!D4:D4) | C9: =COUNTIF('Reg Change Comms (SOC 2 CC2.3)'!D4:D4,"Compliant") | D9: =COUNTIF('Reg Change Comms (SOC 2 CC2.3)'!D4:D4,"Partial") | E9: =COUNTIF('Reg Change Comms (SOC 2 CC2.3)'!D4:D4,"Non-Compliant") | F9: =COUNTIF('Reg Change Comms (SOC 2 CC2.3)'!D4:D4,"N/A") | G9: =IF((B9-F9)=0,"N/A",ROUND(C9/(B9-F9)*100,1)&"%")
A10: TOTAL | B10: =SUM(B4:B9) | C10: =SUM(C4:C9) | D10: =SUM(D4:D9) | E10: =SUM(E4:E9) | F10: =SUM(F4:F9) | G10: =IF((B10-F10)=0,"N/A",ROUND(C10/(B10-F10)*100,1)&"%")
A12: COMPLIANCE BY STATUS
A13: Compliant | B13: =C10 | C13: =IF(B10=0,"",ROUND(B13/B10*100,1)&"%")
A14: Partial | B14: =D10 | C14: =IF(B10=0,"",ROUND(B14/B10*100,1)&"%")
A15: Non-Compliant | B15: =E10 | C15: =IF(B10=0,"",ROUND(B15/B10*100,1)&"%")
A16: N/A | B16: =F10 | C16: =IF(B10=0,"",ROUND(B16/B10*100,1)&"%")
A18: TOP GAPS (Manual Entry)
A19: Priority | B19: Domain | C19: Requirement | D19: Owner | E19: Due Date | F19: Status
A31: COMPLIANCE TREND (Manual Entry)
A32: Assessment Date | B32: Overall % | C32: Compliant | D32: Gaps | E32: Assessor | F32: Notes

Sheet Reg Ident and Applicability
A1: Reg Ident and Applicability — Compliance Checklist
A2: ISO/IEC 27001:2022 — Control A.5.31: Legal, Statutory, Regulatory and Contractual Requirements
A3: Req # | B3: Section | C3: Requirement | D3: Status | E3: Evidence | F3: Owner | G3: Due Date | H3: Notes
A4: A.5.31-01 | B4: Maintain A Systematic Process For | C4: The organisation shall maintain a systematic process for identifying legal, statutory, regulatory, and contractual requirements relevant to information security. This process shall be initiated:.
A5: A.5.31-02 | B5: Annual Comprehensive Review — Full Scan | C5: Annual comprehensive review — full scan of the regulatory landscape and validation of all entries in the Regulatory Register. Performed in Q4 (October–November) to align with the annual Management Review cycle and allow remediation planning for the following year. The review completion date shall be documented in the Regulatory Register.
A6: A.5.31-03 | B6: Utilise The Following Sources To | C6: The organisation shall utilise the following sources to identify potentially applicable regulations, listed in order of authority:.
A7: A.5.31-04 | B7: Higher-Authority Sources Take | C7: Where sources conflict, higher-authority sources take precedence. Conflicts between equal-level sources (e.g., nFADP vs. GDPR) shall be resolved by legal counsel.
A8: A.5.31-05 | B8: For Each Potentially Applicable | C8: For each potentially applicable regulation, the organisation shall assess applicability across three dimensions:.
A9: A.5.31-06 | B9: Or If Applicability Is Uncertain, It | C9: If a regulation is clearly relevant across any dimension, or if applicability is uncertain, it shall be added to the Regulatory Register with an appropriate tier classification.
A10: A.5.31-07 | B10: Applicable Regulation | C10: Each applicable regulation shall be classified into one of three tiers:.
A11: A.5.31-08 | B11: Default Position:* Where Applicability | C11: Default position:* Where applicability is uncertain after assessment, the organisation shall default to a higher tier (Tier 1 over Tier 2, Tier 2 over Tier 3) to reduce the risk of non-compliance.
A12: A.5.31-09 | B12: Maintain A Regulatory Register | C12: The organisation shall maintain a Regulatory Register documenting all applicable requirements. This register is the authoritative source for regulatory compliance obligations.

Sheet Swiss Regulatory Requirements
A1: Swiss Regulatory Requirements — Compliance Checklist
A2: ISO/IEC 27001:2022 — Control A.5.31: Legal, Statutory, Regulatory and Contractual Requirements
A3: Req # | B3: Section | C3: Requirement | D3: Status | E3: Evidence | F3: Owner | G3: Due Date | H3: Notes
A4: A.5.31-10 | B4: The Swiss Nfadp, Effective 1 September | C4: The Swiss nFADP, effective 1 September 2023, is the primary data protection legislation governing the organisation's processing of personal data. The organisation shall comply with the following key requirements:.
A5: A.5.31-11 | B5: Personal Data | C5: Personal data shall be:.
A6: A.5.31-12 | B6: Processed Lawfully And In Good Faith | C6: Processed lawfully and in good faith — Processing shall be conducted transparently, with a clear and documented purpose.
A7: A.5.31-13 | B7: Collected For Specified Purposes — Data | C7: Collected for specified purposes — Data shall be collected for specific, stated purposes and shall not be further processed in a manner incompatible with those purposes.
A8: A.5.31-14 | B8: Proportionate — Only Data That Is | C8: Proportionate — Only data that is adequate, relevant, and limited to what is necessary for the stated purpose shall be collected and processed.
A9: A.5.31-15 | B9: Accurate — Personal Data | C9: Accurate — Personal data shall be accurate, and every reasonable step shall be taken to ensure that inaccurate data is rectified or erased without delay.
A10: A.5.31-16 | B10: Not Retained Longer Than Necessary — | C10: Not retained longer than necessary — Data shall be retained only for as long as necessary for the processing purpose, or as required by law. It shall then be destroyed or anonymised.
A11: A.5.31-17 | B11: Processed Securely — Appropriate | C11: Processed securely — Appropriate technical and organisational measures shall be implemented to protect personal data against unauthorised processing, accidental loss, or destruction (Art. 8 nFADP).
A12: A.5.31-18 | B12: A Valid Legal Basis Under Gdpr | C12: Where the organisation also processes data of EU/EEA individuals, a valid legal basis under GDPR Article 6 shall be identified and documented for each processing activity.
A13: A.5.31-19 | B13: Inform Data Subjects At The Time | C13: The organisation shall inform data subjects at the time of data collection. Privacy notices shall include: the identity and contact details of the controller, purposes of processing, categories of data processed, recipients or categories of recipients, whether data is transferred abroad and applicable safeguards, the retention period, and the rights of data subjects.
A14: A.5.31-20 | B14: Maintain A Data Subject Rights Request | C14: The organisation shall maintain a Data Subject Rights Request Register documenting all requests, responses, and timelines. SLA tracking shall include:.
A15: A.5.31-21 | B15: Data Security Breaches | C15: Data security breaches shall be reported to the Federal Data Protection and Information Commissioner (FDPIC) as soon as possible where the breach is likely to result in a high risk to the personality or fundamental rights of data subjects. Data subjects shall also be informed where necessary for their protection or where the FDPIC requires it.
... A36: A.5.31-42 | B36: Be Aware Of The Enforcement Mechanisms | C36: The organisation shall be aware of the enforcement mechanisms and potential penalties under applicable regulations:.

Sheet Contractual Requirements
A1: Contractual Requirements — Compliance Checklist
A2: ISO/IEC 27001:2022 — Control A.5.31: Legal, Statutory, Regulatory and Contractual Requirements
A3: Req # | B3: Section | C3: Requirement | D3: Status | E3: Evidence | F3: Owner | G3: Due Date | H3: Notes
A4: A.5.31-43 | B4: Systematically Review All Customer | C4: The organisation shall systematically review all customer contracts for compliance requirements related to information security. This includes:.
A5: A.5.31-44 | B5: Contractual Compliance Requirements | C5: Contractual compliance requirements shall be assessed and added to the Regulatory Register with the appropriate tier classification. Where a customer contract explicitly requires compliance with a specific regulation and includes enforcement mechanisms (penalties, termination rights), the requirement shall be classified as Tier 1.
A6: A.5.31-45 | B6: Pre-Signature Review — Business | C6: Pre-signature review — Business Development shall flag all compliance clauses to the Compliance Officer before contract execution.
A7: A.5.31-46 | B7: Gap Notification — Where Gaps Exist | C7: Gap notification — Where gaps exist, Business Development shall be informed of the remediation timeline before contract execution. Contracts shall not be signed where Tier 1 compliance gaps cannot be remediated within the contract start date.
A8: A.5.31-47 | B8: Renewal Review — Compliance Clauses | C8: Renewal review — Compliance clauses shall be reviewed at each contract renewal for changes or new requirements.
A9: A.5.31-48 | B9: Review Supplier And Subprocessor | C9: The organisation shall review supplier and subprocessor agreements for obligations that flow through to the organisation. This includes:.
A10: A.5.31-49 | B10: Pass-Through Obligations | C10: Pass-through obligations shall be documented in the Regulatory Register alongside directly applicable regulations.
A11: A.5.31-50 | B11: The Compliance Requirements Associated | C11: Where the organisation holds or pursues certifications, the compliance requirements associated with those certifications shall be treated as Tier 1 obligations:.
A12: A.5.31-51 | B12: Certification Requirements | C12: Certification requirements shall be reviewed upon any of the following triggers:.
A13: A.5.31-52 | B13: Comply With Applicable Laws And | C13: The organisation shall comply with applicable laws and regulations regarding the use of cryptography, including:.
A14: A.5.31-53 | B14: These Requirements | C14: These requirements shall be documented in the Regulatory Register and reflected in the Use of Cryptography Policy (ISMS-OP-POL-A.8.24).

Sheet Compliance Mon and Review
A1: Compliance Mon and Review — Compliance Checklist
A2: ISO/IEC 27001:2022 — Control A.5.31: Legal, Statutory, Regulatory and Contractual Requirements
A3: Req # | B3: Section | C3: Requirement | D3: Status | E3: Evidence | F3: Owner | G3: Due Date | H3: Notes
A4: A.5.31-54 | B4: Conduct A Comprehensive Annual Review Of | C4: The organisation shall conduct a comprehensive annual review of all entries in the Regulatory Register:.
A5: A.5.31-55 | B5: The Annual Review | C5: The annual review shall be performed by the Compliance Officer (or equivalent), with ISMS Manager approval of the review summary.
A6: A.5.31-56 | B6: In Addition To The Annual Review | C6: In addition to the annual review, the Regulatory Register shall be revisited when triggered by:.
A7: A.5.31-57 | B7: Reassessments Triggered By Events | C7: Reassessments triggered by events shall be completed within 30 days of the trigger event (within 60 days for mergers and acquisitions due to complexity).
A8: A.5.31-58 | B8: Track To Closure — Monitor Progress | C8: Track to closure — Monitor progress. Gaps overdue by more than 30 days shall be escalated to the ISMS Manager; gaps overdue by more than 60 days shall be escalated to executive management.
A9: A.5.31-59 | B9: The Organisation | C9: Where full remediation is not feasible within the required timeframe, the organisation shall implement compensating controls and document a formal risk acceptance signed by executive management.
A10: A.5.31-60 | B10: External Dependency Gaps:* Where | C10: External dependency gaps:* Where remediation depends on a third party (e.g., vendor software update, supplier contract amendment, cloud provider feature), the gap owner shall:.

Sheet Compliance Measurement
A1: Compliance Measurement — Compliance Checklist
A2: ISO/IEC 27001:2022 — Control A.5.31: Legal, Statutory, Regulatory and Contractual Requirements
A3: Req # | B3: Section | C3: Requirement | D3: Status | E3: Evidence | F3: Owner | G3: Due Date | H3: Notes
A4: A.5.31-61 | B4: The Information Security Management Team | C4: The information security management team shall verify compliance with this policy through various methods, including but not limited to: Regulatory Register audits, compliance gap analysis, internal and external audits, regulatory review records, and feedback to the policy owner.

Sheet Reg Change Comms (SOC 2 CC2.3)
A1: Reg Change Comms (SOC 2 CC2.3) — Compliance Checklist
A2: ISO/IEC 27001:2022 — Control A.5.31: Legal, Statutory, Regulatory and Contractual Requirements
A3: Req # | B3: Section | C3: Requirement | D3: Status | E3: Evidence | F3: Owner | G3: Due Date | H3: Notes
A4: A.5.31-62 | B4: Acknowledgement — Team Leads | C4: Acknowledgement — Team leads shall acknowledge receipt and confirm understanding within 5 business days.
