Workbook

Sheet Instructions & Legend
A1: ISMS-IMP-A.8.9.4 - Security Hardening Assessment ISO/IEC 27001:2022 - Control A.8.9: Configuration Management
A3: Document Information
A4: Document ID | B4: ISMS-IMP-A.8.9.4
A5: Workbook Title | B5: Security Hardening Assessment
A6: Control Reference | B6: ISO/IEC 27001:2022 - Control A.8.9: Configuration Management
A7: Version | B7: 1.0
A8: Assessment Date
A9: Completed By
A10: Organisation
A12: Instructions
A13: 1. Complete each worksheet tab for applicable systems/services.
A14: 2. Use dropdown menus for standardised entries (Status, Remediation, etc.).
A15: 3. Fill in yellow-highlighted cells with your information.
A16: 4. If Status = Partial or Non-Compliant, complete the Exception/Deviation section.
A17: 5. Check all applicable items in the Compliance Checklist for each section.
A18: 6. Provide evidence location/path for each implementation entry.
A19: 7. Summary Dashboard auto-calculates compliance statistics.
A20: 8. Maintain the Evidence Register for audit traceability.
... A23: Status Legend
A24: Symbol | B24: Status | C24: Description
A25: ✓ | B25: Compliant / Complete | C25: Requirement fully met
A26: ⚠ | B26: Partial / In Progress | C26: Partially met or in progress
A27: ✗ | B27: Non-Compliant / Not Started | C27: Requirement not met
A28: — | B28: Not Applicable | C28: Not applicable to this assessment

Sheet Hardening Standard Register
A1: HARDENING STANDARD REGISTER
A2: Standard ID | B2: Standard Name | C2: Standard Category | D2: Standard Version | E2: Issuing Authority | F2: Applicability Scope | G2: Compliance Level | H2: Mandatory Optional | I2: Regulatory Driver | J2: Control Count | K2: Implementation Target | L2: Review Frequency | M2: Last Review Date | N2: Next Review Date | O2: Standard Owner | P2: Documentation Location | Q2: Notes | R2: Status
A3: =IF(B3<>"", "HS-"&TEXT(ROW()-2,"000"), "") | H3: Mandatory | K3: 0.95 | L3: Quarterly | R3: Active
A4: =IF(B4<>"", "HS-"&TEXT(ROW()-2,"000"), "") | H4: Mandatory | K4: 0.95 | L4: Quarterly | R4: Active
A5: =IF(B5<>"", "HS-"&TEXT(ROW()-2,"000"), "") | H5: Mandatory | K5: 0.95 | L5: Quarterly | R5: Active
A6: =IF(B6<>"", "HS-"&TEXT(ROW()-2,"000"), "") | H6: Mandatory | K6: 0.95 | L6: Quarterly | R6: Active
A7: =IF(B7<>"", "HS-"&TEXT(ROW()-2,"000"), "") | H7: Mandatory | K7: 0.95 | L7: Quarterly | R7: Active
A8: =IF(B8<>"", "HS-"&TEXT(ROW()-2,"000"), "") | H8: Mandatory | K8: 0.95 | L8: Quarterly | R8: Active
A9: =IF(B9<>"", "HS-"&TEXT(ROW()-2,"000"), "") | H9: Mandatory | K9: 0.95 | L9: Quarterly | R9: Active
A10: =IF(B10<>"", "HS-"&TEXT(ROW()-2,"000"), "") | H10: Mandatory | K10: 0.95 | L10: Quarterly | R10: Active
A11: =IF(B11<>"", "HS-"&TEXT(ROW()-2,"000"), "") | H11: Mandatory | K11: 0.95 | L11: Quarterly | R11: Active
A12: =IF(B12<>"", "HS-"&TEXT(ROW()-2,"000"), "") | H12: Mandatory | K12: 0.95 | L12: Quarterly | R12: Active
A13: =IF(B13<>"", "HS-"&TEXT(ROW()-2,"000"), "") | H13: Mandatory | K13: 0.95 | L13: Quarterly | R13: Active
A14: =IF(B14<>"", "HS-"&TEXT(ROW()-2,"000"), "") | H14: Mandatory | K14: 0.95 | L14: Quarterly | R14: Active
... A32: =IF(B32<>"", "HS-"&TEXT(ROW()-2,"000"), "") | H32: Mandatory | K32: 0.95 | L32: Quarterly | R32: Active

Sheet Asset Type Hardening Matrix
A1: ASSET TYPE HARDENING MATRIX
A2: ASSET TYPE | B2: =IF('Hardening Standard Register'!A3<>"", 'Hardening Standard Register'!A3&": "&LEFT('Hardening Standard Register'!B3,20), "") | C2: =IF('Hardening Standard Register'!A4<>"", 'Hardening Standard Register'!A4&": "&LEFT('Hardening Standard Register'!B4,20), "") | D2: =IF('Hardening Standard Register'!A5<>"", 'Hardening Standard Register'!A5&": "&LEFT('Hardening Standard Register'!B5,20), "") | E2: =IF('Hardening Standard Register'!A6<>"", 'Hardening Standard Register'!A6&": "&LEFT('Hardening Standard Register'!B6,20), "") | F2: =IF('Hardening Standard Register'!A7<>"", 'Hardening Standard Register'!A7&": "&LEFT('Hardening Standard Register'!B7,20), "") | G2: =IF('Hardening Standard Register'!A8<>"", 'Hardening Standard Register'!A8&": "&LEFT('Hardening Standard Register'!B8,20), "") | H2: =IF('Hardening Standard Register'!A9<>"", 'Hardening Standard Register'!A9&": "&LEFT('Hardening Standard Register'!B9,20), "") | I2: =IF('Hardening Standard Register'!A10<>"", 'Hardening Standard Register'!A10&": "&LEFT('Hardening Standard Register'!B10,20), "") | J2: =IF('Hardening Standard Register'!A11<>"", 'Hardening Standard Register'!A11&": "&LEFT('Hardening Standard Register'!B11,20), "") | K2: =IF('Hardening Standard Register'!A12<>"", 'Hardening Standard Register'!A12&": "&LEFT('Hardening Standard Register'!B12,20), "") | L2: =IF('Hardening Standard Register'!A13<>"", 'Hardening Standard Register'!A13&": "&LEFT('Hardening Standard Register'!B13,20), "") | M2: =IF('Hardening Standard Register'!A14<>"", 'Hardening Standard Register'!A14&": "&LEFT('Hardening Standard Register'!B14,20), "") | N2: =IF('Hardening Standard Register'!A15<>"", 'Hardening Standard Register'!A15&": "&LEFT('Hardening Standard Register'!B15,20), "") | O2: =IF('Hardening Standard Register'!A16<>"", 'Hardening Standard Register'!A16&": "&LEFT('Hardening Standard Register'!B16,20), "") | P2: =IF('Hardening Standard Register'!A17<>"", 'Hardening Standard Register'!A17&": "&LEFT('Hardening Standard Register'!B17,20), "") | Q2: =IF('Hardening Standard Register'!A18<>"", 'Hardening Standard Register'!A18&": "&LEFT('Hardening Standard Register'!B18,20), "") | R2: =IF('Hardening Standard Register'!A19<>"", 'Hardening Standard Register'!A19&": "&LEFT('Hardening Standard Register'!B19,20), "") | S2: =IF('Hardening Standard Register'!A20<>"", 'Hardening Standard Register'!A20&": "&LEFT('Hardening Standard Register'!B20,20), "") | T2: =IF('Hardening Standard Register'!A21<>"", 'Hardening Standard Register'!A21&": "&LEFT('Hardening Standard Register'!B21,20), "") | U2: =IF('Hardening Standard Register'!A22<>"", 'Hardening Standard Register'!A22&": "&LEFT('Hardening Standard Register'!B22,20), "") | V2: =IF('Hardening Standard Register'!A23<>"", 'Hardening Standard Register'!A23&": "&LEFT('Hardening Standard Register'!B23,20), "") | W2: =IF('Hardening Standard Register'!A24<>"", 'Hardening Standard Register'!A24&": "&LEFT('Hardening Standard Register'!B24,20), "") | X2: =IF('Hardening Standard Register'!A25<>"", 'Hardening Standard Register'!A25&": "&LEFT('Hardening Standard Register'!B25,20), "") | Y2: =IF('Hardening Standard Register'!A26<>"", 'Hardening Standard Register'!A26&": "&LEFT('Hardening Standard Register'!B26,20), "") | Z2: =IF('Hardening Standard Register'!A27<>"", 'Hardening Standard Register'!A27&": "&LEFT('Hardening Standard Register'!B27,20), "") | AA2: =IF('Hardening Standard Register'!A28<>"", 'Hardening Standard Register'!A28&": "&LEFT('Hardening Standard Register'!B28,20), "") | AB2: =IF('Hardening Standard Register'!A29<>"", 'Hardening Standard Register'!A29&": "&LEFT('Hardening Standard Register'!B29,20), "") | AC2: =IF('Hardening Standard Register'!A30<>"", 'Hardening Standard Register'!A30&": "&LEFT('Hardening Standard Register'!B30,20), "") | AD2: =IF('Hardening Standard Register'!A31<>"", 'Hardening Standard Register'!A31&": "&LEFT('Hardening Standard Register'!B31,20), "") | AE2: =IF('Hardening Standard Register'!A32<>"", 'Hardening Standard Register'!A32&": "&LEFT('Hardening Standard Register'!B32,20), "") | AF2: Required Standards Count | AG2: Recommended Standards Count | AH2: Total Applicable Standards | AI2: High Hardening Burden
A3: --- INFRASTRUCTURE ---
A4: Physical Server | AF4: =COUNTIF(B4:AE4,"Required") | AG4: =COUNTIF(B4:AE4,"Recommended") | AH4: =AF4+AG4 | AI4: =IF(AF4>5,"Yes","")
A5: Virtual Server (VM) | AF5: =COUNTIF(B5:AE5,"Required") | AG5: =COUNTIF(B5:AE5,"Recommended") | AH5: =AF5+AG5 | AI5: =IF(AF5>5,"Yes","")
A6: Hypervisor/VM Host | AF6: =COUNTIF(B6:AE6,"Required") | AG6: =COUNTIF(B6:AE6,"Recommended") | AH6: =AF6+AG6 | AI6: =IF(AF6>5,"Yes","")
A7: Container Host | AF7: =COUNTIF(B7:AE7,"Required") | AG7: =COUNTIF(B7:AE7,"Recommended") | AH7: =AF7+AG7 | AI7: =IF(AF7>5,"Yes","")
A8: Storage Array | AF8: =COUNTIF(B8:AE8,"Required") | AG8: =COUNTIF(B8:AE8,"Recommended") | AH8: =AF8+AG8 | AI8: =IF(AF8>5,"Yes","")
A9: Backup Appliance | AF9: =COUNTIF(B9:AE9,"Required") | AG9: =COUNTIF(B9:AE9,"Recommended") | AH9: =AF9+AG9 | AI9: =IF(AF9>5,"Yes","")
A10: Database Server | AF10: =COUNTIF(B10:AE10,"Required") | AG10: =COUNTIF(B10:AE10,"Recommended") | AH10: =AF10+AG10 | AI10: =IF(AF10>5,"Yes","")
A11: Application Server | AF11: =COUNTIF(B11:AE11,"Required") | AG11: =COUNTIF(B11:AE11,"Recommended") | AH11: =AF11+AG11 | AI11: =IF(AF11>5,"Yes","")
A12: Legacy System | AF12: =COUNTIF(B12:AE12,"Required") | AG12: =COUNTIF(B12:AE12,"Recommended") | AH12: =AF12+AG12 | AI12: =IF(AF12>5,"Yes","")
A13: --- ENDPOINT ---
A14: Corporate Workstation | AF14: =COUNTIF(B14:AE14,"Required") | AG14: =COUNTIF(B14:AE14,"Recommended") | AH14: =AF14+AG14 | AI14: =IF(AF14>5,"Yes","")
A15: Corporate Laptop | AF15: =COUNTIF(B15:AE15,"Required") | AG15: =COUNTIF(B15:AE15,"Recommended") | AH15: =AF15+AG15 | AI15: =IF(AF15>5,"Yes","")
A16: Executive Device | AF16: =COUNTIF(B16:AE16,"Required") | AG16: =COUNTIF(B16:AE16,"Recommended") | AH16: =AF16+AG16 | AI16: =IF(AF16>5,"Yes","")
A17: Mobile Device (Corporate) | AF17: =COUNTIF(B17:AE17,"Required") | AG17: =COUNTIF(B17:AE17,"Recommended") | AH17: =AF17+AG17 | AI17: =IF(AF17>5,"Yes","")
A18: Mobile Device (BYOD) | AF18: =COUNTIF(B18:AE18,"Required") | AG18: =COUNTIF(B18:AE18,"Recommended") | AH18: =AF18+AG18 | AI18: =IF(AF18>5,"Yes","")
A19: Thin Client | AF19: =COUNTIF(B19:AE19,"Required") | AG19: =COUNTIF(B19:AE19,"Recommended") | AH19: =AF19+AG19 | AI19: =IF(AF19>5,"Yes","")
A20: Kiosk/Shared Terminal | AF20: =COUNTIF(B20:AE20,"Required") | AG20: =COUNTIF(B20:AE20,"Recommended") | AH20: =AF20+AG20 | AI20: =IF(AF20>5,"Yes","")
A21: --- NETWORK SERVICES ---
A22: Core Router | AF22: =COUNTIF(B22:AE22,"Required") | AG22: =COUNTIF(B22:AE22,"Recommended") | AH22: =AF22+AG22 | AI22: =IF(AF22>5,"Yes","")
A23: Edge Router | AF23: =COUNTIF(B23:AE23,"Required") | AG23: =COUNTIF(B23:AE23,"Recommended") | AH23: =AF23+AG23 | AI23: =IF(AF23>5,"Yes","")
A24: L2/L3 Switch | AF24: =COUNTIF(B24:AE24,"Required") | AG24: =COUNTIF(B24:AE24,"Recommended") | AH24: =AF24+AG24 | AI24: =IF(AF24>5,"Yes","")
A25: Wireless Access Point | AF25: =COUNTIF(B25:AE25,"Required") | AG25: =COUNTIF(B25:AE25,"Recommended") | AH25: =AF25+AG25 | AI25: =IF(AF25>5,"Yes","")
A26: Firewall | AF26: =COUNTIF(B26:AE26,"Required") | AG26: =COUNTIF(B26:AE26,"Recommended") | AH26: =AF26+AG26 | AI26: =IF(AF26>5,"Yes","")
A27: IDS/IPS Appliance | AF27: =COUNTIF(B27:AE27,"Required") | AG27: =COUNTIF(B27:AE27,"Recommended") | AH27: =AF27+AG27 | AI27: =IF(AF27>5,"Yes","")
A28: Load Balancer | AF28: =COUNTIF(B28:AE28,"Required") | AG28: =COUNTIF(B28:AE28,"Recommended") | AH28: =AF28+AG28 | AI28: =IF(AF28>5,"Yes","")
A29: VPN Concentrator | AF29: =COUNTIF(B29:AE29,"Required") | AG29: =COUNTIF(B29:AE29,"Recommended") | AH29: =AF29+AG29 | AI29: =IF(AF29>5,"Yes","")
A30: --- APPLICATIONS ---
A31: Web Application | AF31: =COUNTIF(B31:AE31,"Required") | AG31: =COUNTIF(B31:AE31,"Recommended") | AH31: =AF31+AG31 | AI31: =IF(AF31>5,"Yes","")
A32: API Service | AF32: =COUNTIF(B32:AE32,"Required") | AG32: =COUNTIF(B32:AE32,"Recommended") | AH32: =AF32+AG32 | AI32: =IF(AF32>5,"Yes","")
A33: Database Management System | AF33: =COUNTIF(B33:AE33,"Required") | AG33: =COUNTIF(B33:AE33,"Recommended") | AH33: =AF33+AG33 | AI33: =IF(AF33>5,"Yes","")
A34: File Server/NAS | AF34: =COUNTIF(B34:AE34,"Required") | AG34: =COUNTIF(B34:AE34,"Recommended") | AH34: =AF34+AG34 | AI34: =IF(AF34>5,"Yes","")
A35: Email System | AF35: =COUNTIF(B35:AE35,"Required") | AG35: =COUNTIF(B35:AE35,"Recommended") | AH35: =AF35+AG35 | AI35: =IF(AF35>5,"Yes","")
A36: Authentication Service (IAM) | AF36: =COUNTIF(B36:AE36,"Required") | AG36: =COUNTIF(B36:AE36,"Recommended") | AH36: =AF36+AG36 | AI36: =IF(AF36>5,"Yes","")
A37: Monitoring/Logging System | AF37: =COUNTIF(B37:AE37,"Required") | AG37: =COUNTIF(B37:AE37,"Recommended") | AH37: =AF37+AG37 | AI37: =IF(AF37>5,"Yes","")
A38: --- CLOUD & VIRTUAL ---
A39: IaaS Instance | AF39: =COUNTIF(B39:AE39,"Required") | AG39: =COUNTIF(B39:AE39,"Recommended") | AH39: =AF39+AG39 | AI39: =IF(AF39>5,"Yes","")
A40: PaaS Application | AF40: =COUNTIF(B40:AE40,"Required") | AG40: =COUNTIF(B40:AE40,"Recommended") | AH40: =AF40+AG40 | AI40: =IF(AF40>5,"Yes","")
...

Sheet Asset Hardening Assessment
A1: Asset ID | B1: Asset Name | C1: Asset Type | D1: Asset Tier | E1: Asset Owner | F1: Location | G1: Operating System | H1: Applicable Standards | I1: Standards Count | J1: Total Controls | K1: Implemented Controls | L1: Partial Controls | M1: Not Implemented Controls | N1: Not Applicable Controls | O1: Compliance Percentage | P1: High Risk Gaps | Q1: Medium Risk Gaps | R1: Low Risk Gaps | S1: Active Exceptions | T1: Compensating Controls | U1: Compliance Status | V1: Last Assessment Date | W1: Next Assessment Date | X1: Assessor | Y1: Evidence Reference | Z1: Remediation Status | AA1: Target Compliance Date | AB1: Notes
O2: =IF(AND(J2>0,(J2-N2)>0), (K2+(L2*0.5))/(J2-N2), "") | U2: =IF(O2="","", IF(AND(O2=1, P2=0), "Fully Compliant", IF(AND(O2>=0.95, P2=0), "Compliant", IF(O2>=0.9, "Substantially Compliant", IF(O2>=0.8, "Partially Compliant", "Non-Compliant"))))) | W2: =IF(V2<>"", V2+90, "") | X2: [Security Analyst] | Z2: Not Started
O3: =IF(AND(J3>0,(J3-N3)>0), (K3+(L3*0.5))/(J3-N3), "") | U3: =IF(O3="","", IF(AND(O3=1, P3=0), "Fully Compliant", IF(AND(O3>=0.95, P3=0), "Compliant", IF(O3>=0.9, "Substantially Compliant", IF(O3>=0.8, "Partially Compliant", "Non-Compliant"))))) | W3: =IF(V3<>"", V3+90, "") | X3: [Security Analyst] | Z3: Not Started
O4: =IF(AND(J4>0,(J4-N4)>0), (K4+(L4*0.5))/(J4-N4), "") | U4: =IF(O4="","", IF(AND(O4=1, P4=0), "Fully Compliant", IF(AND(O4>=0.95, P4=0), "Compliant", IF(O4>=0.9, "Substantially Compliant", IF(O4>=0.8, "Partially Compliant", "Non-Compliant"))))) | W4: =IF(V4<>"", V4+90, "") | X4: [Security Analyst] | Z4: Not Started
O5: =IF(AND(J5>0,(J5-N5)>0), (K5+(L5*0.5))/(J5-N5), "") | U5: =IF(O5="","", IF(AND(O5=1, P5=0), "Fully Compliant", IF(AND(O5>=0.95, P5=0), "Compliant", IF(O5>=0.9, "Substantially Compliant", IF(O5>=0.8, "Partially Compliant", "Non-Compliant"))))) | W5: =IF(V5<>"", V5+90, "") | X5: [Security Analyst] | Z5: Not Started
O6: =IF(AND(J6>0,(J6-N6)>0), (K6+(L6*0.5))/(J6-N6), "") | U6: =IF(O6="","", IF(AND(O6=1, P6=0), "Fully Compliant", IF(AND(O6>=0.95, P6=0), "Compliant", IF(O6>=0.9, "Substantially Compliant", IF(O6>=0.8, "Partially Compliant", "Non-Compliant"))))) | W6: =IF(V6<>"", V6+90, "") | X6: [Security Analyst] | Z6: Not Started
O7: =IF(AND(J7>0,(J7-N7)>0), (K7+(L7*0.5))/(J7-N7), "") | U7: =IF(O7="","", IF(AND(O7=1, P7=0), "Fully Compliant", IF(AND(O7>=0.95, P7=0), "Compliant", IF(O7>=0.9, "Substantially Compliant", IF(O7>=0.8, "Partially Compliant", "Non-Compliant"))))) | W7: =IF(V7<>"", V7+90, "") | X7: [Security Analyst] | Z7: Not Started
O8: =IF(AND(J8>0,(J8-N8)>0), (K8+(L8*0.5))/(J8-N8), "") | U8: =IF(O8="","", IF(AND(O8=1, P8=0), "Fully Compliant", IF(AND(O8>=0.95, P8=0), "Compliant", IF(O8>=0.9, "Substantially Compliant", IF(O8>=0.8, "Partially Compliant", "Non-Compliant"))))) | W8: =IF(V8<>"", V8+90, "") | X8: [Security Analyst] | Z8: Not Started
O9: =IF(AND(J9>0,(J9-N9)>0), (K9+(L9*0.5))/(J9-N9), "") | U9: =IF(O9="","", IF(AND(O9=1, P9=0), "Fully Compliant", IF(AND(O9>=0.95, P9=0), "Compliant", IF(O9>=0.9, "Substantially Compliant", IF(O9>=0.8, "Partially Compliant", "Non-Compliant"))))) | W9: =IF(V9<>"", V9+90, "") | X9: [Security Analyst] | Z9: Not Started
O10: =IF(AND(J10>0,(J10-N10)>0), (K10+(L10*0.5))/(J10-N10), "") | U10: =IF(O10="","", IF(AND(O10=1, P10=0), "Fully Compliant", IF(AND(O10>=0.95, P10=0), "Compliant", IF(O10>=0.9, "Substantially Compliant", IF(O10>=0.8, "Partially Compliant", "Non-Compliant"))))) | W10: =IF(V10<>"", V10+90, "") | X10: [Security Analyst] | Z10: Not Started
O11: =IF(AND(J11>0,(J11-N11)>0), (K11+(L11*0.5))/(J11-N11), "") | U11: =IF(O11="","", IF(AND(O11=1, P11=0), "Fully Compliant", IF(AND(O11>=0.95, P11=0), "Compliant", IF(O11>=0.9, "Substantially Compliant", IF(O11>=0.8, "Partially Compliant", "Non-Compliant"))))) | W11: =IF(V11<>"", V11+90, "") | X11: [Security Analyst] | Z11: Not Started
O12: =IF(AND(J12>0,(J12-N12)>0), (K12+(L12*0.5))/(J12-N12), "") | U12: =IF(O12="","", IF(AND(O12=1, P12=0), "Fully Compliant", IF(AND(O12>=0.95, P12=0), "Compliant", IF(O12>=0.9, "Substantially Compliant", IF(O12>=0.8, "Partially Compliant", "Non-Compliant"))))) | W12: =IF(V12<>"", V12+90, "") | X12: [Security Analyst] | Z12: Not Started
O13: =IF(AND(J13>0,(J13-N13)>0), (K13+(L13*0.5))/(J13-N13), "") | U13: =IF(O13="","", IF(AND(O13=1, P13=0), "Fully Compliant", IF(AND(O13>=0.95, P13=0), "Compliant", IF(O13>=0.9, "Substantially Compliant", IF(O13>=0.8, "Partially Compliant", "Non-Compliant"))))) | W13: =IF(V13<>"", V13+90, "") | X13: [Security Analyst] | Z13: Not Started
... O101: =IF(AND(J101>0,(J101-N101)>0), (K101+(L101*0.5))/(J101-N101), "") | U101: =IF(O101="","", IF(AND(O101=1, P101=0), "Fully Compliant", IF(AND(O101>=0.95, P101=0), "Compliant", IF(O101>=0.9, "Substantially Compliant", IF(O101>=0.8, "Partially Compliant", "Non-Compliant"))))) | W101: =IF(V101<>"", V101+90, "") | X101: [Security Analyst] | Z101: Not Started

Sheet Control Compliance Detail
A1: Control ID | B1: Asset ID | C1: Asset Name | D1: Standard ID | E1: Standard Name | F1: Control Number | G1: Control Title | H1: Control Description | I1: Control Category | J1: Control Severity | K1: Implementation Status | L1: Implementation Method | M1: Implementation Evidence | N1: Configuration Setting | O1: Expected Value | P1: Actual Value | Q1: Compliance Status | R1: Gap Description | S1: Gap Risk Rating | T1: Remediation Required | U1: Remediation Plan | V1: Remediation Owner | W1: Target Remediation Date | X1: Exception Status | Y1: Exception ID | Z1: Compensating Control | AA1: Last Verified Date | AB1: Verified By | AC1: Evidence Reference | AD1: Verification Method | AE1: Next Verification Date | AF1: Notes
A2: =IF(B2<>"", "HC-"&TEXT(ROW()-1,"00000"), "") | Q2: =IF(K2="", "", IF(ISNUMBER(SEARCH("Implemented",K2)), "Pass", IF(ISNUMBER(SEARCH("Partial",K2)), "Partial", IF(ISNUMBER(SEARCH("Not Applicable",K2)), "N/A", "Fail")))) | T2: =IF(Q2="", "", IF(OR(Q2="Fail", Q2="Partial"), "Yes", "No")) | X2: No | AB2: [Security Analyst] | AE2: =IF(AA2<>"", AA2+90, "")
A3: =IF(B3<>"", "HC-"&TEXT(ROW()-1,"00000"), "") | Q3: =IF(K3="", "", IF(ISNUMBER(SEARCH("Implemented",K3)), "Pass", IF(ISNUMBER(SEARCH("Partial",K3)), "Partial", IF(ISNUMBER(SEARCH("Not Applicable",K3)), "N/A", "Fail")))) | T3: =IF(Q3="", "", IF(OR(Q3="Fail", Q3="Partial"), "Yes", "No")) | X3: No | AB3: [Security Analyst] | AE3: =IF(AA3<>"", AA3+90, "")
A4: =IF(B4<>"", "HC-"&TEXT(ROW()-1,"00000"), "") | Q4: =IF(K4="", "", IF(ISNUMBER(SEARCH("Implemented",K4)), "Pass", IF(ISNUMBER(SEARCH("Partial",K4)), "Partial", IF(ISNUMBER(SEARCH("Not Applicable",K4)), "N/A", "Fail")))) | T4: =IF(Q4="", "", IF(OR(Q4="Fail", Q4="Partial"), "Yes", "No")) | X4: No | AB4: [Security Analyst] | AE4: =IF(AA4<>"", AA4+90, "")
A5: =IF(B5<>"", "HC-"&TEXT(ROW()-1,"00000"), "") | Q5: =IF(K5="", "", IF(ISNUMBER(SEARCH("Implemented",K5)), "Pass", IF(ISNUMBER(SEARCH("Partial",K5)), "Partial", IF(ISNUMBER(SEARCH("Not Applicable",K5)), "N/A", "Fail")))) | T5: =IF(Q5="", "", IF(OR(Q5="Fail", Q5="Partial"), "Yes", "No")) | X5: No | AB5: [Security Analyst] | AE5: =IF(AA5<>"", AA5+90, "")
A6: =IF(B6<>"", "HC-"&TEXT(ROW()-1,"00000"), "") | Q6: =IF(K6="", "", IF(ISNUMBER(SEARCH("Implemented",K6)), "Pass", IF(ISNUMBER(SEARCH("Partial",K6)), "Partial", IF(ISNUMBER(SEARCH("Not Applicable",K6)), "N/A", "Fail")))) | T6: =IF(Q6="", "", IF(OR(Q6="Fail", Q6="Partial"), "Yes", "No")) | X6: No | AB6: [Security Analyst] | AE6: =IF(AA6<>"", AA6+90, "")
A7: =IF(B7<>"", "HC-"&TEXT(ROW()-1,"00000"), "") | Q7: =IF(K7="", "", IF(ISNUMBER(SEARCH("Implemented",K7)), "Pass", IF(ISNUMBER(SEARCH("Partial",K7)), "Partial", IF(ISNUMBER(SEARCH("Not Applicable",K7)), "N/A", "Fail")))) | T7: =IF(Q7="", "", IF(OR(Q7="Fail", Q7="Partial"), "Yes", "No")) | X7: No | AB7: [Security Analyst] | AE7: =IF(AA7<>"", AA7+90, "")
A8: =IF(B8<>"", "HC-"&TEXT(ROW()-1,"00000"), "") | Q8: =IF(K8="", "", IF(ISNUMBER(SEARCH("Implemented",K8)), "Pass", IF(ISNUMBER(SEARCH("Partial",K8)), "Partial", IF(ISNUMBER(SEARCH("Not Applicable",K8)), "N/A", "Fail")))) | T8: =IF(Q8="", "", IF(OR(Q8="Fail", Q8="Partial"), "Yes", "No")) | X8: No | AB8: [Security Analyst] | AE8: =IF(AA8<>"", AA8+90, "")
A9: =IF(B9<>"", "HC-"&TEXT(ROW()-1,"00000"), "") | Q9: =IF(K9="", "", IF(ISNUMBER(SEARCH("Implemented",K9)), "Pass", IF(ISNUMBER(SEARCH("Partial",K9)), "Partial", IF(ISNUMBER(SEARCH("Not Applicable",K9)), "N/A", "Fail")))) | T9: =IF(Q9="", "", IF(OR(Q9="Fail", Q9="Partial"), "Yes", "No")) | X9: No | AB9: [Security Analyst] | AE9: =IF(AA9<>"", AA9+90, "")
A10: =IF(B10<>"", "HC-"&TEXT(ROW()-1,"00000"), "") | Q10: =IF(K10="", "", IF(ISNUMBER(SEARCH("Implemented",K10)), "Pass", IF(ISNUMBER(SEARCH("Partial",K10)), "Partial", IF(ISNUMBER(SEARCH("Not Applicable",K10)), "N/A", "Fail")))) | T10: =IF(Q10="", "", IF(OR(Q10="Fail", Q10="Partial"), "Yes", "No")) | X10: No | AB10: [Security Analyst] | AE10: =IF(AA10<>"", AA10+90, "")
A11: =IF(B11<>"", "HC-"&TEXT(ROW()-1,"00000"), "") | Q11: =IF(K11="", "", IF(ISNUMBER(SEARCH("Implemented",K11)), "Pass", IF(ISNUMBER(SEARCH("Partial",K11)), "Partial", IF(ISNUMBER(SEARCH("Not Applicable",K11)), "N/A", "Fail")))) | T11: =IF(Q11="", "", IF(OR(Q11="Fail", Q11="Partial"), "Yes", "No")) | X11: No | AB11: [Security Analyst] | AE11: =IF(AA11<>"", AA11+90, "")
A12: =IF(B12<>"", "HC-"&TEXT(ROW()-1,"00000"), "") | Q12: =IF(K12="", "", IF(ISNUMBER(SEARCH("Implemented",K12)), "Pass", IF(ISNUMBER(SEARCH("Partial",K12)), "Partial", IF(ISNUMBER(SEARCH("Not Applicable",K12)), "N/A", "Fail")))) | T12: =IF(Q12="", "", IF(OR(Q12="Fail", Q12="Partial"), "Yes", "No")) | X12: No | AB12: [Security Analyst] | AE12: =IF(AA12<>"", AA12+90, "")
A13: =IF(B13<>"", "HC-"&TEXT(ROW()-1,"00000"), "") | Q13: =IF(K13="", "", IF(ISNUMBER(SEARCH("Implemented",K13)), "Pass", IF(ISNUMBER(SEARCH("Partial",K13)), "Partial", IF(ISNUMBER(SEARCH("Not Applicable",K13)), "N/A", "Fail")))) | T13: =IF(Q13="", "", IF(OR(Q13="Fail", Q13="Partial"), "Yes", "No")) | X13: No | AB13: [Security Analyst] | AE13: =IF(AA13<>"", AA13+90, "")
... A501: =IF(B501<>"", "HC-"&TEXT(ROW()-1,"00000"), "") | Q501: =IF(K501="", "", IF(ISNUMBER(SEARCH("Implemented",K501)), "Pass", IF(ISNUMBER(SEARCH("Partial",K501)), "Partial", IF(ISNUMBER(SEARCH("Not Applicable",K501)), "N/A", "Fail")))) | T501: =IF(Q501="", "", IF(OR(Q501="Fail", Q501="Partial"), "Yes", "No")) | X501: No | AB501: [Security Analyst] | AE501: =IF(AA501<>"", AA501+90, "")

Sheet Exception Management
A1: EXCEPTION MANAGEMENT
A2: Exception ID | B2: Control ID | C2: Asset ID | D2: Asset Name | E2: Standard ID | F2: Control Number | G2: Control Title | H2: Control Severity | I2: Exception Type | J2: Exception Reason | K2: Business Justification | L2: Risk Assessment | M2: Residual Risk Rating | N2: Compensating Control Required | O2: Compensating Control Description | P2: Compensating Control Effectiveness | Q2: Requested By | R2: Request Date | S2: Reviewed By | T2: Review Date | U2: Approved By | V2: Approval Date | W2: Exception Status | X2: Exception Duration | Y2: Valid From Date | Z2: Valid Until Date | AA2: Days Until Expiry | AB2: Review Required | AC2: Last Review Date | AD2: Next Review Date | AE2: Audit Trail | AF2: Monitoring Required | AG2: Monitoring Description | AH2: Re Assessment Trigger | AI2: Exception Closure Plan | AJ2: Documentation Reference | AK2: Notes
A3: =IF(B3<>"", "EXC-"&TEXT(ROW()-2,"000"), "") | N3: Yes | W3: Pending Review | Z3: =IF(AND(Y3<>"", X3<>""), IF(X3="3 Months", Y3+90, IF(X3="6 Months", Y3+180, IF(X3="12 Months", Y3+365, IF(X3="24 Months", Y3+730, Y3+365)))), "") | AD3: =IF(AND(Y3<>"", Z3<>""), Y3+((Z3-Y3)/2), "") | AF3: Yes
A4: =IF(B4<>"", "EXC-"&TEXT(ROW()-2,"000"), "") | N4: Yes | W4: Pending Review | Z4: =IF(AND(Y4<>"", X4<>""), IF(X4="3 Months", Y4+90, IF(X4="6 Months", Y4+180, IF(X4="12 Months", Y4+365, IF(X4="24 Months", Y4+730, Y4+365)))), "") | AD4: =IF(AND(Y4<>"", Z4<>""), Y4+((Z4-Y4)/2), "") | AF4: Yes
A5: =IF(B5<>"", "EXC-"&TEXT(ROW()-2,"000"), "") | N5: Yes | W5: Pending Review | Z5: =IF(AND(Y5<>"", X5<>""), IF(X5="3 Months", Y5+90, IF(X5="6 Months", Y5+180, IF(X5="12 Months", Y5+365, IF(X5="24 Months", Y5+730, Y5+365)))), "") | AD5: =IF(AND(Y5<>"", Z5<>""), Y5+((Z5-Y5)/2), "") | AF5: Yes
A6: =IF(B6<>"", "EXC-"&TEXT(ROW()-2,"000"), "") | N6: Yes | W6: Pending Review | Z6: =IF(AND(Y6<>"", X6<>""), IF(X6="3 Months", Y6+90, IF(X6="6 Months", Y6+180, IF(X6="12 Months", Y6+365, IF(X6="24 Months", Y6+730, Y6+365)))), "") | AD6: =IF(AND(Y6<>"", Z6<>""), Y6+((Z6-Y6)/2), "") | AF6: Yes
A7: =IF(B7<>"", "EXC-"&TEXT(ROW()-2,"000"), "") | N7: Yes | W7: Pending Review | Z7: =IF(AND(Y7<>"", X7<>""), IF(X7="3 Months", Y7+90, IF(X7="6 Months", Y7+180, IF(X7="12 Months", Y7+365, IF(X7="24 Months", Y7+730, Y7+365)))), "") | AD7: =IF(AND(Y7<>"", Z7<>""), Y7+((Z7-Y7)/2), "") | AF7: Yes
A8: =IF(B8<>"", "EXC-"&TEXT(ROW()-2,"000"), "") | N8: Yes | W8: Pending Review | Z8: =IF(AND(Y8<>"", X8<>""), IF(X8="3 Months", Y8+90, IF(X8="6 Months", Y8+180, IF(X8="12 Months", Y8+365, IF(X8="24 Months", Y8+730, Y8+365)))), "") | AD8: =IF(AND(Y8<>"", Z8<>""), Y8+((Z8-Y8)/2), "") | AF8: Yes
A9: =IF(B9<>"", "EXC-"&TEXT(ROW()-2,"000"), "") | N9: Yes | W9: Pending Review | Z9: =IF(AND(Y9<>"", X9<>""), IF(X9="3 Months", Y9+90, IF(X9="6 Months", Y9+180, IF(X9="12 Months", Y9+365, IF(X9="24 Months", Y9+730, Y9+365)))), "") | AD9: =IF(AND(Y9<>"", Z9<>""), Y9+((Z9-Y9)/2), "") | AF9: Yes
A10: =IF(B10<>"", "EXC-"&TEXT(ROW()-2,"000"), "") | N10: Yes | W10: Pending Review | Z10: =IF(AND(Y10<>"", X10<>""), IF(X10="3 Months", Y10+90, IF(X10="6 Months", Y10+180, IF(X10="12 Months", Y10+365, IF(X10="24 Months", Y10+730, Y10+365)))), "") | AD10: =IF(AND(Y10<>"", Z10<>""), Y10+((Z10-Y10)/2), "") | AF10: Yes
A11: =IF(B11<>"", "EXC-"&TEXT(ROW()-2,"000"), "") | N11: Yes | W11: Pending Review | Z11: =IF(AND(Y11<>"", X11<>""), IF(X11="3 Months", Y11+90, IF(X11="6 Months", Y11+180, IF(X11="12 Months", Y11+365, IF(X11="24 Months", Y11+730, Y11+365)))), "") | AD11: =IF(AND(Y11<>"", Z11<>""), Y11+((Z11-Y11)/2), "") | AF11: Yes
A12: =IF(B12<>"", "EXC-"&TEXT(ROW()-2,"000"), "") | N12: Yes | W12: Pending Review | Z12: =IF(AND(Y12<>"", X12<>""), IF(X12="3 Months", Y12+90, IF(X12="6 Months", Y12+180, IF(X12="12 Months", Y12+365, IF(X12="24 Months", Y12+730, Y12+365)))), "") | AD12: =IF(AND(Y12<>"", Z12<>""), Y12+((Z12-Y12)/2), "") | AF12: Yes
A13: =IF(B13<>"", "EXC-"&TEXT(ROW()-2,"000"), "") | N13: Yes | W13: Pending Review | Z13: =IF(AND(Y13<>"", X13<>""), IF(X13="3 Months", Y13+90, IF(X13="6 Months", Y13+180, IF(X13="12 Months", Y13+365, IF(X13="24 Months", Y13+730, Y13+365)))), "") | AD13: =IF(AND(Y13<>"", Z13<>""), Y13+((Z13-Y13)/2), "") | AF13: Yes
A14: =IF(B14<>"", "EXC-"&TEXT(ROW()-2,"000"), "") | N14: Yes | W14: Pending Review | Z14: =IF(AND(Y14<>"", X14<>""), IF(X14="3 Months", Y14+90, IF(X14="6 Months", Y14+180, IF(X14="12 Months", Y14+365, IF(X14="24 Months", Y14+730, Y14+365)))), "") | AD14: =IF(AND(Y14<>"", Z14<>""), Y14+((Z14-Y14)/2), "") | AF14: Yes
... A52: =IF(B52<>"", "EXC-"&TEXT(ROW()-2,"000"), "") | N52: Yes | W52: Pending Review | Z52: =IF(AND(Y52<>"", X52<>""), IF(X52="3 Months", Y52+90, IF(X52="6 Months", Y52+180, IF(X52="12 Months", Y52+365, IF(X52="24 Months", Y52+730, Y52+365)))), "") | AD52: =IF(AND(Y52<>"", Z52<>""), Y52+((Z52-Y52)/2), "") | AF52: Yes

Sheet Remediation Tracking
A1: REMEDIATION TRACKING
A2: Remediation ID | B2: Gap Type | C2: Control ID | D2: Asset ID | E2: Asset Name | F2: Asset Tier | G2: Standard ID | H2: Control Number | I2: Control Title | J2: Control Severity | K2: Gap Description | L2: Gap Risk Rating | M2: Impact Assessment | N2: Discovery Date | O2: Discovery Method | P2: Remediation Required | Q2: Remediation Strategy | R2: Remediation Description | S2: Remediation Owner | T2: Remediation Team | U2: Estimated Effort | V2: Estimated Cost | W2: Dependencies | X2: Remediation Priority | Y2: Target Start Date | Z2: Target Completion Date | AA2: Actual Start Date | AB2: Actual Completion Date | AC2: Days To Remediate | AD2: Days Overdue | AE2: Status | AF2: Status Notes | AG2: Completion Percentage | AH2: Blocker Description | AI2: Verification Required | AJ2: Verification Method | AK2: Verified By | AL2: Verification Date | AM2: Verification Result | AN2: Re Test Required | AO2: Change Request ID | AP2: Risk Acceptance ID | AQ2: Evidence Reference | AR2: Lessons Learned | AS2: Preventive Action | AT2: Closure Date | AU2: Approved By | AV2: Notes
A3: =IF(B3<>"", "REM-"&TEXT(ROW()-2,"000"), "") | P3: Yes | X3: =IF(L3="", "", IF(ISNUMBER(SEARCH("Critical",L3)), "Critical", IF(AND(ISNUMBER(SEARCH("High",L3)), ISNUMBER(SEARCH("Critical",F3))), "Critical", IF(ISNUMBER(SEARCH("High",L3)), "High", IF(ISNUMBER(SEARCH("Medium",L3)), "Medium", "Low"))))) | Z3: =IF(AND(N3<>"", X3<>""), IF(X3="Critical", N3+3, IF(X3="High", N3+7, IF(X3="Medium", N3+30, N3+90))), "") | AC3: =IF(AND(AA3<>"", AB3<>""), AB3-AA3, "") | AE3: Identified | AG3: 0 | AI3: Yes | AN3: No
A4: =IF(B4<>"", "REM-"&TEXT(ROW()-2,"000"), "") | P4: Yes | X4: =IF(L4="", "", IF(ISNUMBER(SEARCH("Critical",L4)), "Critical", IF(AND(ISNUMBER(SEARCH("High",L4)), ISNUMBER(SEARCH("Critical",F4))), "Critical", IF(ISNUMBER(SEARCH("High",L4)), "High", IF(ISNUMBER(SEARCH("Medium",L4)), "Medium", "Low"))))) | Z4: =IF(AND(N4<>"", X4<>""), IF(X4="Critical", N4+3, IF(X4="High", N4+7, IF(X4="Medium", N4+30, N4+90))), "") | AC4: =IF(AND(AA4<>"", AB4<>""), AB4-AA4, "") | AE4: Identified | AG4: 0 | AI4: Yes | AN4: No
A5: =IF(B5<>"", "REM-"&TEXT(ROW()-2,"000"), "") | P5: Yes | X5: =IF(L5="", "", IF(ISNUMBER(SEARCH("Critical",L5)), "Critical", IF(AND(ISNUMBER(SEARCH("High",L5)), ISNUMBER(SEARCH("Critical",F5))), "Critical", IF(ISNUMBER(SEARCH("High",L5)), "High", IF(ISNUMBER(SEARCH("Medium",L5)), "Medium", "Low"))))) | Z5: =IF(AND(N5<>"", X5<>""), IF(X5="Critical", N5+3, IF(X5="High", N5+7, IF(X5="Medium", N5+30, N5+90))), "") | AC5: =IF(AND(AA5<>"", AB5<>""), AB5-AA5, "") | AE5: Identified | AG5: 0 | AI5: Yes | AN5: No
A6: =IF(B6<>"", "REM-"&TEXT(ROW()-2,"000"), "") | P6: Yes | X6: =IF(L6="", "", IF(ISNUMBER(SEARCH("Critical",L6)), "Critical", IF(AND(ISNUMBER(SEARCH("High",L6)), ISNUMBER(SEARCH("Critical",F6))), "Critical", IF(ISNUMBER(SEARCH("High",L6)), "High", IF(ISNUMBER(SEARCH("Medium",L6)), "Medium", "Low"))))) | Z6: =IF(AND(N6<>"", X6<>""), IF(X6="Critical", N6+3, IF(X6="High", N6+7, IF(X6="Medium", N6+30, N6+90))), "") | AC6: =IF(AND(AA6<>"", AB6<>""), AB6-AA6, "") | AE6: Identified | AG6: 0 | AI6: Yes | AN6: No
A7: =IF(B7<>"", "REM-"&TEXT(ROW()-2,"000"), "") | P7: Yes | X7: =IF(L7="", "", IF(ISNUMBER(SEARCH("Critical",L7)), "Critical", IF(AND(ISNUMBER(SEARCH("High",L7)), ISNUMBER(SEARCH("Critical",F7))), "Critical", IF(ISNUMBER(SEARCH("High",L7)), "High", IF(ISNUMBER(SEARCH("Medium",L7)), "Medium", "Low"))))) | Z7: =IF(AND(N7<>"", X7<>""), IF(X7="Critical", N7+3, IF(X7="High", N7+7, IF(X7="Medium", N7+30, N7+90))), "") | AC7: =IF(AND(AA7<>"", AB7<>""), AB7-AA7, "") | AE7: Identified | AG7: 0 | AI7: Yes | AN7: No
A8: =IF(B8<>"", "REM-"&TEXT(ROW()-2,"000"), "") | P8: Yes | X8: =IF(L8="", "", IF(ISNUMBER(SEARCH("Critical",L8)), "Critical", IF(AND(ISNUMBER(SEARCH("High",L8)), ISNUMBER(SEARCH("Critical",F8))), "Critical", IF(ISNUMBER(SEARCH("High",L8)), "High", IF(ISNUMBER(SEARCH("Medium",L8)), "Medium", "Low"))))) | Z8: =IF(AND(N8<>"", X8<>""), IF(X8="Critical", N8+3, IF(X8="High", N8+7, IF(X8="Medium", N8+30, N8+90))), "") | AC8: =IF(AND(AA8<>"", AB8<>""), AB8-AA8, "") | AE8: Identified | AG8: 0 | AI8: Yes | AN8: No
A9: =IF(B9<>"", "REM-"&TEXT(ROW()-2,"000"), "") | P9: Yes | X9: =IF(L9="", "", IF(ISNUMBER(SEARCH("Critical",L9)), "Critical", IF(AND(ISNUMBER(SEARCH("High",L9)), ISNUMBER(SEARCH("Critical",F9))), "Critical", IF(ISNUMBER(SEARCH("High",L9)), "High", IF(ISNUMBER(SEARCH("Medium",L9)), "Medium", "Low"))))) | Z9: =IF(AND(N9<>"", X9<>""), IF(X9="Critical", N9+3, IF(X9="High", N9+7, IF(X9="Medium", N9+30, N9+90))), "") | AC9: =IF(AND(AA9<>"", AB9<>""), AB9-AA9, "") | AE9: Identified | AG9: 0 | AI9: Yes | AN9: No
A10: =IF(B10<>"", "REM-"&TEXT(ROW()-2,"000"), "") | P10: Yes | X10: =IF(L10="", "", IF(ISNUMBER(SEARCH("Critical",L10)), "Critical", IF(AND(ISNUMBER(SEARCH("High",L10)), ISNUMBER(SEARCH("Critical",F10))), "Critical", IF(ISNUMBER(SEARCH("High",L10)), "High", IF(ISNUMBER(SEARCH("Medium",L10)), "Medium", "Low"))))) | Z10: =IF(AND(N10<>"", X10<>""), IF(X10="Critical", N10+3, IF(X10="High", N10+7, IF(X10="Medium", N10+30, N10+90))), "") | AC10: =IF(AND(AA10<>"", AB10<>""), AB10-AA10, "") | AE10: Identified | AG10: 0 | AI10: Yes | AN10: No
A11: =IF(B11<>"", "REM-"&TEXT(ROW()-2,"000"), "") | P11: Yes | X11: =IF(L11="", "", IF(ISNUMBER(SEARCH("Critical",L11)), "Critical", IF(AND(ISNUMBER(SEARCH("High",L11)), ISNUMBER(SEARCH("Critical",F11))), "Critical", IF(ISNUMBER(SEARCH("High",L11)), "High", IF(ISNUMBER(SEARCH("Medium",L11)), "Medium", "Low"))))) | Z11: =IF(AND(N11<>"", X11<>""), IF(X11="Critical", N11+3, IF(X11="High", N11+7, IF(X11="Medium", N11+30, N11+90))), "") | AC11: =IF(AND(AA11<>"", AB11<>""), AB11-AA11, "") | AE11: Identified | AG11: 0 | AI11: Yes | AN11: No
A12: =IF(B12<>"", "REM-"&TEXT(ROW()-2,"000"), "") | P12: Yes | X12: =IF(L12="", "", IF(ISNUMBER(SEARCH("Critical",L12)), "Critical", IF(AND(ISNUMBER(SEARCH("High",L12)), ISNUMBER(SEARCH("Critical",F12))), "Critical", IF(ISNUMBER(SEARCH("High",L12)), "High", IF(ISNUMBER(SEARCH("Medium",L12)), "Medium", "Low"))))) | Z12: =IF(AND(N12<>"", X12<>""), IF(X12="Critical", N12+3, IF(X12="High", N12+7, IF(X12="Medium", N12+30, N12+90))), "") | AC12: =IF(AND(AA12<>"", AB12<>""), AB12-AA12, "") | AE12: Identified | AG12: 0 | AI12: Yes | AN12: No
A13: =IF(B13<>"", "REM-"&TEXT(ROW()-2,"000"), "") | P13: Yes | X13: =IF(L13="", "", IF(ISNUMBER(SEARCH("Critical",L13)), "Critical", IF(AND(ISNUMBER(SEARCH("High",L13)), ISNUMBER(SEARCH("Critical",F13))), "Critical", IF(ISNUMBER(SEARCH("High",L13)), "High", IF(ISNUMBER(SEARCH("Medium",L13)), "Medium", "Low"))))) | Z13: =IF(AND(N13<>"", X13<>""), IF(X13="Critical", N13+3, IF(X13="High", N13+7, IF(X13="Medium", N13+30, N13+90))), "") | AC13: =IF(AND(AA13<>"", AB13<>""), AB13-AA13, "") | AE13: Identified | AG13: 0 | AI13: Yes | AN13: No
A14: =IF(B14<>"", "REM-"&TEXT(ROW()-2,"000"), "") | P14: Yes | X14: =IF(L14="", "", IF(ISNUMBER(SEARCH("Critical",L14)), "Critical", IF(AND(ISNUMBER(SEARCH("High",L14)), ISNUMBER(SEARCH("Critical",F14))), "Critical", IF(ISNUMBER(SEARCH("High",L14)), "High", IF(ISNUMBER(SEARCH("Medium",L14)), "Medium", "Low"))))) | Z14: =IF(AND(N14<>"", X14<>""), IF(X14="Critical", N14+3, IF(X14="High", N14+7, IF(X14="Medium", N14+30, N14+90))), "") | AC14: =IF(AND(AA14<>"", AB14<>""), AB14-AA14, "") | AE14: Identified | AG14: 0 | AI14: Yes | AN14: No
... A102: =IF(B102<>"", "REM-"&TEXT(ROW()-2,"000"), "") | P102: Yes | X102: =IF(L102="", "", IF(ISNUMBER(SEARCH("Critical",L102)), "Critical", IF(AND(ISNUMBER(SEARCH("High",L102)), ISNUMBER(SEARCH("Critical",F102))), "Critical", IF(ISNUMBER(SEARCH("High",L102)), "High", IF(ISNUMBER(SEARCH("Medium",L102)), "Medium", "Low"))))) | Z102: =IF(AND(N102<>"", X102<>""), IF(X102="Critical", N102+3, IF(X102="High", N102+7, IF(X102="Medium", N102+30, N102+90))), "") | AC102: =IF(AND(AA102<>"", AB102<>""), AB102-AA102, "") | AE102: Identified | AG102: 0 | AI102: Yes | AN102: No

Sheet Gap Prioritization
A1: GAP PRIORITIZATION
A2: Priority Rank | B2: Remediation ID | C2: Asset ID | D2: Asset Name | E2: Asset Tier | F2: Control ID | G2: Control Number | H2: Control Title | I2: Standard ID | J2: Control Severity | K2: Gap Risk Rating | L2: Gap Description | M2: Exploitation Likelihood | N2: Impact Assessment | O2: Risk Score | P2: Priority Category | Q2: Remediation Owner | R2: Estimated Effort | S2: Target Completion Date | T2: Days Until Target | U2: Status | V2: Dependencies | W2: Quick Win | X2: Related Gaps | Y2: Batch Opportunity
A3: =IF(B3<>"", ROW()-2, "") | B3: ='Remediation Tracking'!A3 | C3: ='Remediation Tracking'!D3 | D3: ='Remediation Tracking'!E3 | E3: ='Remediation Tracking'!F3 | F3: ='Remediation Tracking'!C3 | G3: ='Remediation Tracking'!H3 | H3: ='Remediation Tracking'!I3 | I3: ='Remediation Tracking'!G3 | J3: ='Remediation Tracking'!J3 | K3: ='Remediation Tracking'!L3 | L3: ='Remediation Tracking'!K3 | M3: Medium | N3: ='Remediation Tracking'!M3 | O3: =IF(E3="", "", (IF(ISNUMBER(SEARCH("Critical",E3)),5,IF(ISNUMBER(SEARCH("High",E3)),4,IF(ISNUMBER(SEARCH("Medium",E3)),3,2)))*10) + (IF(ISNUMBER(SEARCH("Critical",J3)),5,IF(ISNUMBER(SEARCH("High",J3)),4,IF(ISNUMBER(SEARCH("Medium",J3)),3,2)))*8) + (IF(ISNUMBER(SEARCH("Very High",M3)),5,IF(ISNUMBER(SEARCH("Very Low",M3)),1,IF(ISNUMBER(SEARCH("High",M3)),4,IF(ISNUMBER(SEARCH("Medium",M3)),3,IF(ISNUMBER(SEARCH("Low",M3)),2,1)))))*6) + (IF(T3<0, ABS(T3)/7*2, 0))) | P3: =IF(O3="", "", IF(AND(ISNUMBER(SEARCH("Critical",E3)), OR(ISNUMBER(SEARCH("Critical",K3)),ISNUMBER(SEARCH("High",K3))), T3<0), "P0 - Critical & Urgent", IF(AND(ISNUMBER(SEARCH("Critical",E3)), OR(ISNUMBER(SEARCH("Critical",K3)),ISNUMBER(SEARCH("High",K3)))), "P1 - Critical", IF(OR(AND(ISNUMBER(SEARCH("High",E3)),ISNUMBER(SEARCH("High",K3))),AND(ISNUMBER(SEARCH("Critical",E3)),ISNUMBER(SEARCH("Medium",K3)))), "P2 - High Priority", IF(OR(AND(ISNUMBER(SEARCH("Medium",E3)),ISNUMBER(SEARCH("High",K3))),AND(ISNUMBER(SEARCH("High",E3)),ISNUMBER(SEARCH("Medium",K3)))), "P3 - Medium Priority", "P4 - Low Priority"))))) | Q3: ='Remediation Tracking'!S3 | R3: ='Remediation Tracking'!U3 | S3: ='Remediation Tracking'!Z3 | U3: ='Remediation Tracking'!AE3 | V3: ='Remediation Tracking'!W3 | W3: =IF(AND(OR(R3="<1 hour",R3="1-4 hours",R3="1 day"), OR(K3="Medium",K3="High",K3="Critical")), "Yes - Quick Win", "No")
A4: =IF(B4<>"", ROW()-2, "") | B4: ='Remediation Tracking'!A4 | C4: ='Remediation Tracking'!D4 | D4: ='Remediation Tracking'!E4 | E4: ='Remediation Tracking'!F4 | F4: ='Remediation Tracking'!C4 | G4: ='Remediation Tracking'!H4 | H4: ='Remediation Tracking'!I4 | I4: ='Remediation Tracking'!G4 | J4: ='Remediation Tracking'!J4 | K4: ='Remediation Tracking'!L4 | L4: ='Remediation Tracking'!K4 | M4: Medium | N4: ='Remediation Tracking'!M4 | O4: =IF(E4="", "", (IF(ISNUMBER(SEARCH("Critical",E4)),5,IF(ISNUMBER(SEARCH("High",E4)),4,IF(ISNUMBER(SEARCH("Medium",E4)),3,2)))*10) + (IF(ISNUMBER(SEARCH("Critical",J4)),5,IF(ISNUMBER(SEARCH("High",J4)),4,IF(ISNUMBER(SEARCH("Medium",J4)),3,2)))*8) + (IF(ISNUMBER(SEARCH("Very High",M4)),5,IF(ISNUMBER(SEARCH("Very Low",M4)),1,IF(ISNUMBER(SEARCH("High",M4)),4,IF(ISNUMBER(SEARCH("Medium",M4)),3,IF(ISNUMBER(SEARCH("Low",M4)),2,1)))))*6) + (IF(T4<0, ABS(T4)/7*2, 0))) | P4: =IF(O4="", "", IF(AND(ISNUMBER(SEARCH("Critical",E4)), OR(ISNUMBER(SEARCH("Critical",K4)),ISNUMBER(SEARCH("High",K4))), T4<0), "P0 - Critical & Urgent", IF(AND(ISNUMBER(SEARCH("Critical",E4)), OR(ISNUMBER(SEARCH("Critical",K4)),ISNUMBER(SEARCH("High",K4)))), "P1 - Critical", IF(OR(AND(ISNUMBER(SEARCH("High",E4)),ISNUMBER(SEARCH("High",K4))),AND(ISNUMBER(SEARCH("Critical",E4)),ISNUMBER(SEARCH("Medium",K4)))), "P2 - High Priority", IF(OR(AND(ISNUMBER(SEARCH("Medium",E4)),ISNUMBER(SEARCH("High",K4))),AND(ISNUMBER(SEARCH("High",E4)),ISNUMBER(SEARCH("Medium",K4)))), "P3 - Medium Priority", "P4 - Low Priority"))))) | Q4: ='Remediation Tracking'!S4 | R4: ='Remediation Tracking'!U4 | S4: ='Remediation Tracking'!Z4 | U4: ='Remediation Tracking'!AE4 | V4: ='Remediation Tracking'!W4 | W4: =IF(AND(OR(R4="<1 hour",R4="1-4 hours",R4="1 day"), OR(K4="Medium",K4="High",K4="Critical")), "Yes - Quick Win", "No")
A5: =IF(B5<>"", ROW()-2, "") | B5: ='Remediation Tracking'!A5 | C5: ='Remediation Tracking'!D5 | D5: ='Remediation Tracking'!E5 | E5: ='Remediation Tracking'!F5 | F5: ='Remediation Tracking'!C5 | G5: ='Remediation Tracking'!H5 | H5: ='Remediation Tracking'!I5 | I5: ='Remediation Tracking'!G5 | J5: ='Remediation Tracking'!J5 | K5: ='Remediation Tracking'!L5 | L5: ='Remediation Tracking'!K5 | M5: Medium | N5: ='Remediation Tracking'!M5 | O5: =IF(E5="", "", (IF(ISNUMBER(SEARCH("Critical",E5)),5,IF(ISNUMBER(SEARCH("High",E5)),4,IF(ISNUMBER(SEARCH("Medium",E5)),3,2)))*10) + (IF(ISNUMBER(SEARCH("Critical",J5)),5,IF(ISNUMBER(SEARCH("High",J5)),4,IF(ISNUMBER(SEARCH("Medium",J5)),3,2)))*8) + (IF(ISNUMBER(SEARCH("Very High",M5)),5,IF(ISNUMBER(SEARCH("Very Low",M5)),1,IF(ISNUMBER(SEARCH("High",M5)),4,IF(ISNUMBER(SEARCH("Medium",M5)),3,IF(ISNUMBER(SEARCH("Low",M5)),2,1)))))*6) + (IF(T5<0, ABS(T5)/7*2, 0))) | P5: =IF(O5="", "", IF(AND(ISNUMBER(SEARCH("Critical",E5)), OR(ISNUMBER(SEARCH("Critical",K5)),ISNUMBER(SEARCH("High",K5))), T5<0), "P0 - Critical & Urgent", IF(AND(ISNUMBER(SEARCH("Critical",E5)), OR(ISNUMBER(SEARCH("Critical",K5)),ISNUMBER(SEARCH("High",K5)))), "P1 - Critical", IF(OR(AND(ISNUMBER(SEARCH("High",E5)),ISNUMBER(SEARCH("High",K5))),AND(ISNUMBER(SEARCH("Critical",E5)),ISNUMBER(SEARCH("Medium",K5)))), "P2 - High Priority", IF(OR(AND(ISNUMBER(SEARCH("Medium",E5)),ISNUMBER(SEARCH("High",K5))),AND(ISNUMBER(SEARCH("High",E5)),ISNUMBER(SEARCH("Medium",K5)))), "P3 - Medium Priority", "P4 - Low Priority"))))) | Q5: ='Remediation Tracking'!S5 | R5: ='Remediation Tracking'!U5 | S5: ='Remediation Tracking'!Z5 | U5: ='Remediation Tracking'!AE5 | V5: ='Remediation Tracking'!W5 | W5: =IF(AND(OR(R5="<1 hour",R5="1-4 hours",R5="1 day"), OR(K5="Medium",K5="High",K5="Critical")), "Yes - Quick Win", "No")
A6: =IF(B6<>"", ROW()-2, "") | B6: ='Remediation Tracking'!A6 | C6: ='Remediation Tracking'!D6 | D6: ='Remediation Tracking'!E6 | E6: ='Remediation Tracking'!F6 | F6: ='Remediation Tracking'!C6 | G6: ='Remediation Tracking'!H6 | H6: ='Remediation Tracking'!I6 | I6: ='Remediation Tracking'!G6 | J6: ='Remediation Tracking'!J6 | K6: ='Remediation Tracking'!L6 | L6: ='Remediation Tracking'!K6 | M6: Medium | N6: ='Remediation Tracking'!M6 | O6: =IF(E6="", "", (IF(ISNUMBER(SEARCH("Critical",E6)),5,IF(ISNUMBER(SEARCH("High",E6)),4,IF(ISNUMBER(SEARCH("Medium",E6)),3,2)))*10) + (IF(ISNUMBER(SEARCH("Critical",J6)),5,IF(ISNUMBER(SEARCH("High",J6)),4,IF(ISNUMBER(SEARCH("Medium",J6)),3,2)))*8) + (IF(ISNUMBER(SEARCH("Very High",M6)),5,IF(ISNUMBER(SEARCH("Very Low",M6)),1,IF(ISNUMBER(SEARCH("High",M6)),4,IF(ISNUMBER(SEARCH("Medium",M6)),3,IF(ISNUMBER(SEARCH("Low",M6)),2,1)))))*6) + (IF(T6<0, ABS(T6)/7*2, 0))) | P6: =IF(O6="", "", IF(AND(ISNUMBER(SEARCH("Critical",E6)), OR(ISNUMBER(SEARCH("Critical",K6)),ISNUMBER(SEARCH("High",K6))), T6<0), "P0 - Critical & Urgent", IF(AND(ISNUMBER(SEARCH("Critical",E6)), OR(ISNUMBER(SEARCH("Critical",K6)),ISNUMBER(SEARCH("High",K6)))), "P1 - Critical", IF(OR(AND(ISNUMBER(SEARCH("High",E6)),ISNUMBER(SEARCH("High",K6))),AND(ISNUMBER(SEARCH("Critical",E6)),ISNUMBER(SEARCH("Medium",K6)))), "P2 - High Priority", IF(OR(AND(ISNUMBER(SEARCH("Medium",E6)),ISNUMBER(SEARCH("High",K6))),AND(ISNUMBER(SEARCH("High",E6)),ISNUMBER(SEARCH("Medium",K6)))), "P3 - Medium Priority", "P4 - Low Priority"))))) | Q6: ='Remediation Tracking'!S6 | R6: ='Remediation Tracking'!U6 | S6: ='Remediation Tracking'!Z6 | U6: ='Remediation Tracking'!AE6 | V6: ='Remediation Tracking'!W6 | W6: =IF(AND(OR(R6="<1 hour",R6="1-4 hours",R6="1 day"), OR(K6="Medium",K6="High",K6="Critical")), "Yes - Quick Win", "No")
A7: =IF(B7<>"", ROW()-2, "") | B7: ='Remediation Tracking'!A7 | C7: ='Remediation Tracking'!D7 | D7: ='Remediation Tracking'!E7 | E7: ='Remediation Tracking'!F7 | F7: ='Remediation Tracking'!C7 | G7: ='Remediation Tracking'!H7 | H7: ='Remediation Tracking'!I7 | I7: ='Remediation Tracking'!G7 | J7: ='Remediation Tracking'!J7 | K7: ='Remediation Tracking'!L7 | L7: ='Remediation Tracking'!K7 | M7: Medium | N7: ='Remediation Tracking'!M7 | O7: =IF(E7="", "", (IF(ISNUMBER(SEARCH("Critical",E7)),5,IF(ISNUMBER(SEARCH("High",E7)),4,IF(ISNUMBER(SEARCH("Medium",E7)),3,2)))*10) + (IF(ISNUMBER(SEARCH("Critical",J7)),5,IF(ISNUMBER(SEARCH("High",J7)),4,IF(ISNUMBER(SEARCH("Medium",J7)),3,2)))*8) + (IF(ISNUMBER(SEARCH("Very High",M7)),5,IF(ISNUMBER(SEARCH("Very Low",M7)),1,IF(ISNUMBER(SEARCH("High",M7)),4,IF(ISNUMBER(SEARCH("Medium",M7)),3,IF(ISNUMBER(SEARCH("Low",M7)),2,1)))))*6) + (IF(T7<0, ABS(T7)/7*2, 0))) | P7: =IF(O7="", "", IF(AND(ISNUMBER(SEARCH("Critical",E7)), OR(ISNUMBER(SEARCH("Critical",K7)),ISNUMBER(SEARCH("High",K7))), T7<0), "P0 - Critical & Urgent", IF(AND(ISNUMBER(SEARCH("Critical",E7)), OR(ISNUMBER(SEARCH("Critical",K7)),ISNUMBER(SEARCH("High",K7)))), "P1 - Critical", IF(OR(AND(ISNUMBER(SEARCH("High",E7)),ISNUMBER(SEARCH("High",K7))),AND(ISNUMBER(SEARCH("Critical",E7)),ISNUMBER(SEARCH("Medium",K7)))), "P2 - High Priority", IF(OR(AND(ISNUMBER(SEARCH("Medium",E7)),ISNUMBER(SEARCH("High",K7))),AND(ISNUMBER(SEARCH("High",E7)),ISNUMBER(SEARCH("Medium",K7)))), "P3 - Medium Priority", "P4 - Low Priority"))))) | Q7: ='Remediation Tracking'!S7 | R7: ='Remediation Tracking'!U7 | S7: ='Remediation Tracking'!Z7 | U7: ='Remediation Tracking'!AE7 | V7: ='Remediation Tracking'!W7 | W7: =IF(AND(OR(R7="<1 hour",R7="1-4 hours",R7="1 day"), OR(K7="Medium",K7="High",K7="Critical")), "Yes - Quick Win", "No")
A8: =IF(B8<>"", ROW()-2, "") | B8: ='Remediation Tracking'!A8 | C8: ='Remediation Tracking'!D8 | D8: ='Remediation Tracking'!E8 | E8: ='Remediation Tracking'!F8 | F8: ='Remediation Tracking'!C8 | G8: ='Remediation Tracking'!H8 | H8: ='Remediation Tracking'!I8 | I8: ='Remediation Tracking'!G8 | J8: ='Remediation Tracking'!J8 | K8: ='Remediation Tracking'!L8 | L8: ='Remediation Tracking'!K8 | M8: Medium | N8: ='Remediation Tracking'!M8 | O8: =IF(E8="", "", (IF(ISNUMBER(SEARCH("Critical",E8)),5,IF(ISNUMBER(SEARCH("High",E8)),4,IF(ISNUMBER(SEARCH("Medium",E8)),3,2)))*10) + (IF(ISNUMBER(SEARCH("Critical",J8)),5,IF(ISNUMBER(SEARCH("High",J8)),4,IF(ISNUMBER(SEARCH("Medium",J8)),3,2)))*8) + (IF(ISNUMBER(SEARCH("Very High",M8)),5,IF(ISNUMBER(SEARCH("Very Low",M8)),1,IF(ISNUMBER(SEARCH("High",M8)),4,IF(ISNUMBER(SEARCH("Medium",M8)),3,IF(ISNUMBER(SEARCH("Low",M8)),2,1)))))*6) + (IF(T8<0, ABS(T8)/7*2, 0))) | P8: =IF(O8="", "", IF(AND(ISNUMBER(SEARCH("Critical",E8)), OR(ISNUMBER(SEARCH("Critical",K8)),ISNUMBER(SEARCH("High",K8))), T8<0), "P0 - Critical & Urgent", IF(AND(ISNUMBER(SEARCH("Critical",E8)), OR(ISNUMBER(SEARCH("Critical",K8)),ISNUMBER(SEARCH("High",K8)))), "P1 - Critical", IF(OR(AND(ISNUMBER(SEARCH("High",E8)),ISNUMBER(SEARCH("High",K8))),AND(ISNUMBER(SEARCH("Critical",E8)),ISNUMBER(SEARCH("Medium",K8)))), "P2 - High Priority", IF(OR(AND(ISNUMBER(SEARCH("Medium",E8)),ISNUMBER(SEARCH("High",K8))),AND(ISNUMBER(SEARCH("High",E8)),ISNUMBER(SEARCH("Medium",K8)))), "P3 - Medium Priority", "P4 - Low Priority"))))) | Q8: ='Remediation Tracking'!S8 | R8: ='Remediation Tracking'!U8 | S8: ='Remediation Tracking'!Z8 | U8: ='Remediation Tracking'!AE8 | V8: ='Remediation Tracking'!W8 | W8: =IF(AND(OR(R8="<1 hour",R8="1-4 hours",R8="1 day"), OR(K8="Medium",K8="High",K8="Critical")), "Yes - Quick Win", "No")
A9: =IF(B9<>"", ROW()-2, "") | B9: ='Remediation Tracking'!A9 | C9: ='Remediation Tracking'!D9 | D9: ='Remediation Tracking'!E9 | E9: ='Remediation Tracking'!F9 | F9: ='Remediation Tracking'!C9 | G9: ='Remediation Tracking'!H9 | H9: ='Remediation Tracking'!I9 | I9: ='Remediation Tracking'!G9 | J9: ='Remediation Tracking'!J9 | K9: ='Remediation Tracking'!L9 | L9: ='Remediation Tracking'!K9 | M9: Medium | N9: ='Remediation Tracking'!M9 | O9: =IF(E9="", "", (IF(ISNUMBER(SEARCH("Critical",E9)),5,IF(ISNUMBER(SEARCH("High",E9)),4,IF(ISNUMBER(SEARCH("Medium",E9)),3,2)))*10) + (IF(ISNUMBER(SEARCH("Critical",J9)),5,IF(ISNUMBER(SEARCH("High",J9)),4,IF(ISNUMBER(SEARCH("Medium",J9)),3,2)))*8) + (IF(ISNUMBER(SEARCH("Very High",M9)),5,IF(ISNUMBER(SEARCH("Very Low",M9)),1,IF(ISNUMBER(SEARCH("High",M9)),4,IF(ISNUMBER(SEARCH("Medium",M9)),3,IF(ISNUMBER(SEARCH("Low",M9)),2,1)))))*6) + (IF(T9<0, ABS(T9)/7*2, 0))) | P9: =IF(O9="", "", IF(AND(ISNUMBER(SEARCH("Critical",E9)), OR(ISNUMBER(SEARCH("Critical",K9)),ISNUMBER(SEARCH("High",K9))), T9<0), "P0 - Critical & Urgent", IF(AND(ISNUMBER(SEARCH("Critical",E9)), OR(ISNUMBER(SEARCH("Critical",K9)),ISNUMBER(SEARCH("High",K9)))), "P1 - Critical", IF(OR(AND(ISNUMBER(SEARCH("High",E9)),ISNUMBER(SEARCH("High",K9))),AND(ISNUMBER(SEARCH("Critical",E9)),ISNUMBER(SEARCH("Medium",K9)))), "P2 - High Priority", IF(OR(AND(ISNUMBER(SEARCH("Medium",E9)),ISNUMBER(SEARCH("High",K9))),AND(ISNUMBER(SEARCH("High",E9)),ISNUMBER(SEARCH("Medium",K9)))), "P3 - Medium Priority", "P4 - Low Priority"))))) | Q9: ='Remediation Tracking'!S9 | R9: ='Remediation Tracking'!U9 | S9: ='Remediation Tracking'!Z9 | U9: ='Remediation Tracking'!AE9 | V9: ='Remediation Tracking'!W9 | W9: =IF(AND(OR(R9="<1 hour",R9="1-4 hours",R9="1 day"), OR(K9="Medium",K9="High",K9="Critical")), "Yes - Quick Win", "No")
A10: =IF(B10<>"", ROW()-2, "") | B10: ='Remediation Tracking'!A10 | C10: ='Remediation Tracking'!D10 | D10: ='Remediation Tracking'!E10 | E10: ='Remediation Tracking'!F10 | F10: ='Remediation Tracking'!C10 | G10: ='Remediation Tracking'!H10 | H10: ='Remediation Tracking'!I10 | I10: ='Remediation Tracking'!G10 | J10: ='Remediation Tracking'!J10 | K10: ='Remediation Tracking'!L10 | L10: ='Remediation Tracking'!K10 | M10: Medium | N10: ='Remediation Tracking'!M10 | O10: =IF(E10="", "", (IF(ISNUMBER(SEARCH("Critical",E10)),5,IF(ISNUMBER(SEARCH("High",E10)),4,IF(ISNUMBER(SEARCH("Medium",E10)),3,2)))*10) + (IF(ISNUMBER(SEARCH("Critical",J10)),5,IF(ISNUMBER(SEARCH("High",J10)),4,IF(ISNUMBER(SEARCH("Medium",J10)),3,2)))*8) + (IF(ISNUMBER(SEARCH("Very High",M10)),5,IF(ISNUMBER(SEARCH("Very Low",M10)),1,IF(ISNUMBER(SEARCH("High",M10)),4,IF(ISNUMBER(SEARCH("Medium",M10)),3,IF(ISNUMBER(SEARCH("Low",M10)),2,1)))))*6) + (IF(T10<0, ABS(T10)/7*2, 0))) | P10: =IF(O10="", "", IF(AND(ISNUMBER(SEARCH("Critical",E10)), OR(ISNUMBER(SEARCH("Critical",K10)),ISNUMBER(SEARCH("High",K10))), T10<0), "P0 - Critical & Urgent", IF(AND(ISNUMBER(SEARCH("Critical",E10)), OR(ISNUMBER(SEARCH("Critical",K10)),ISNUMBER(SEARCH("High",K10)))), "P1 - Critical", IF(OR(AND(ISNUMBER(SEARCH("High",E10)),ISNUMBER(SEARCH("High",K10))),AND(ISNUMBER(SEARCH("Critical",E10)),ISNUMBER(SEARCH("Medium",K10)))), "P2 - High Priority", IF(OR(AND(ISNUMBER(SEARCH("Medium",E10)),ISNUMBER(SEARCH("High",K10))),AND(ISNUMBER(SEARCH("High",E10)),ISNUMBER(SEARCH("Medium",K10)))), "P3 - Medium Priority", "P4 - Low Priority"))))) | Q10: ='Remediation Tracking'!S10 | R10: ='Remediation Tracking'!U10 | S10: ='Remediation Tracking'!Z10 | U10: ='Remediation Tracking'!AE10 | V10: ='Remediation Tracking'!W10 | W10: =IF(AND(OR(R10="<1 hour",R10="1-4 hours",R10="1 day"), OR(K10="Medium",K10="High",K10="Critical")), "Yes - Quick Win", "No")
A11: =IF(B11<>"", ROW()-2, "") | B11: ='Remediation Tracking'!A11 | C11: ='Remediation Tracking'!D11 | D11: ='Remediation Tracking'!E11 | E11: ='Remediation Tracking'!F11 | F11: ='Remediation Tracking'!C11 | G11: ='Remediation Tracking'!H11 | H11: ='Remediation Tracking'!I11 | I11: ='Remediation Tracking'!G11 | J11: ='Remediation Tracking'!J11 | K11: ='Remediation Tracking'!L11 | L11: ='Remediation Tracking'!K11 | M11: Medium | N11: ='Remediation Tracking'!M11 | O11: =IF(E11="", "", (IF(ISNUMBER(SEARCH("Critical",E11)),5,IF(ISNUMBER(SEARCH("High",E11)),4,IF(ISNUMBER(SEARCH("Medium",E11)),3,2)))*10) + (IF(ISNUMBER(SEARCH("Critical",J11)),5,IF(ISNUMBER(SEARCH("High",J11)),4,IF(ISNUMBER(SEARCH("Medium",J11)),3,2)))*8) + (IF(ISNUMBER(SEARCH("Very High",M11)),5,IF(ISNUMBER(SEARCH("Very Low",M11)),1,IF(ISNUMBER(SEARCH("High",M11)),4,IF(ISNUMBER(SEARCH("Medium",M11)),3,IF(ISNUMBER(SEARCH("Low",M11)),2,1)))))*6) + (IF(T11<0, ABS(T11)/7*2, 0))) | P11: =IF(O11="", "", IF(AND(ISNUMBER(SEARCH("Critical",E11)), OR(ISNUMBER(SEARCH("Critical",K11)),ISNUMBER(SEARCH("High",K11))), T11<0), "P0 - Critical & Urgent", IF(AND(ISNUMBER(SEARCH("Critical",E11)), OR(ISNUMBER(SEARCH("Critical",K11)),ISNUMBER(SEARCH("High",K11)))), "P1 - Critical", IF(OR(AND(ISNUMBER(SEARCH("High",E11)),ISNUMBER(SEARCH("High",K11))),AND(ISNUMBER(SEARCH("Critical",E11)),ISNUMBER(SEARCH("Medium",K11)))), "P2 - High Priority", IF(OR(AND(ISNUMBER(SEARCH("Medium",E11)),ISNUMBER(SEARCH("High",K11))),AND(ISNUMBER(SEARCH("High",E11)),ISNUMBER(SEARCH("Medium",K11)))), "P3 - Medium Priority", "P4 - Low Priority"))))) | Q11: ='Remediation Tracking'!S11 | R11: ='Remediation Tracking'!U11 | S11: ='Remediation Tracking'!Z11 | U11: ='Remediation Tracking'!AE11 | V11: ='Remediation Tracking'!W11 | W11: =IF(AND(OR(R11="<1 hour",R11="1-4 hours",R11="1 day"), OR(K11="Medium",K11="High",K11="Critical")), "Yes - Quick Win", "No")
A12: =IF(B12<>"", ROW()-2, "") | B12: ='Remediation Tracking'!A12 | C12: ='Remediation Tracking'!D12 | D12: ='Remediation Tracking'!E12 | E12: ='Remediation Tracking'!F12 | F12: ='Remediation Tracking'!C12 | G12: ='Remediation Tracking'!H12 | H12: ='Remediation Tracking'!I12 | I12: ='Remediation Tracking'!G12 | J12: ='Remediation Tracking'!J12 | K12: ='Remediation Tracking'!L12 | L12: ='Remediation Tracking'!K12 | M12: Medium | N12: ='Remediation Tracking'!M12 | O12: =IF(E12="", "", (IF(ISNUMBER(SEARCH("Critical",E12)),5,IF(ISNUMBER(SEARCH("High",E12)),4,IF(ISNUMBER(SEARCH("Medium",E12)),3,2)))*10) + (IF(ISNUMBER(SEARCH("Critical",J12)),5,IF(ISNUMBER(SEARCH("High",J12)),4,IF(ISNUMBER(SEARCH("Medium",J12)),3,2)))*8) + (IF(ISNUMBER(SEARCH("Very High",M12)),5,IF(ISNUMBER(SEARCH("Very Low",M12)),1,IF(ISNUMBER(SEARCH("High",M12)),4,IF(ISNUMBER(SEARCH("Medium",M12)),3,IF(ISNUMBER(SEARCH("Low",M12)),2,1)))))*6) + (IF(T12<0, ABS(T12)/7*2, 0))) | P12: =IF(O12="", "", IF(AND(ISNUMBER(SEARCH("Critical",E12)), OR(ISNUMBER(SEARCH("Critical",K12)),ISNUMBER(SEARCH("High",K12))), T12<0), "P0 - Critical & Urgent", IF(AND(ISNUMBER(SEARCH("Critical",E12)), OR(ISNUMBER(SEARCH("Critical",K12)),ISNUMBER(SEARCH("High",K12)))), "P1 - Critical", IF(OR(AND(ISNUMBER(SEARCH("High",E12)),ISNUMBER(SEARCH("High",K12))),AND(ISNUMBER(SEARCH("Critical",E12)),ISNUMBER(SEARCH("Medium",K12)))), "P2 - High Priority", IF(OR(AND(ISNUMBER(SEARCH("Medium",E12)),ISNUMBER(SEARCH("High",K12))),AND(ISNUMBER(SEARCH("High",E12)),ISNUMBER(SEARCH("Medium",K12)))), "P3 - Medium Priority", "P4 - Low Priority"))))) | Q12: ='Remediation Tracking'!S12 | R12: ='Remediation Tracking'!U12 | S12: ='Remediation Tracking'!Z12 | U12: ='Remediation Tracking'!AE12 | V12: ='Remediation Tracking'!W12 | W12: =IF(AND(OR(R12="<1 hour",R12="1-4 hours",R12="1 day"), OR(K12="Medium",K12="High",K12="Critical")), "Yes - Quick Win", "No")
A13: =IF(B13<>"", ROW()-2, "") | B13: ='Remediation Tracking'!A13 | C13: ='Remediation Tracking'!D13 | D13: ='Remediation Tracking'!E13 | E13: ='Remediation Tracking'!F13 | F13: ='Remediation Tracking'!C13 | G13: ='Remediation Tracking'!H13 | H13: ='Remediation Tracking'!I13 | I13: ='Remediation Tracking'!G13 | J13: ='Remediation Tracking'!J13 | K13: ='Remediation Tracking'!L13 | L13: ='Remediation Tracking'!K13 | M13: Medium | N13: ='Remediation Tracking'!M13 | O13: =IF(E13="", "", (IF(ISNUMBER(SEARCH("Critical",E13)),5,IF(ISNUMBER(SEARCH("High",E13)),4,IF(ISNUMBER(SEARCH("Medium",E13)),3,2)))*10) + (IF(ISNUMBER(SEARCH("Critical",J13)),5,IF(ISNUMBER(SEARCH("High",J13)),4,IF(ISNUMBER(SEARCH("Medium",J13)),3,2)))*8) + (IF(ISNUMBER(SEARCH("Very High",M13)),5,IF(ISNUMBER(SEARCH("Very Low",M13)),1,IF(ISNUMBER(SEARCH("High",M13)),4,IF(ISNUMBER(SEARCH("Medium",M13)),3,IF(ISNUMBER(SEARCH("Low",M13)),2,1)))))*6) + (IF(T13<0, ABS(T13)/7*2, 0))) | P13: =IF(O13="", "", IF(AND(ISNUMBER(SEARCH("Critical",E13)), OR(ISNUMBER(SEARCH("Critical",K13)),ISNUMBER(SEARCH("High",K13))), T13<0), "P0 - Critical & Urgent", IF(AND(ISNUMBER(SEARCH("Critical",E13)), OR(ISNUMBER(SEARCH("Critical",K13)),ISNUMBER(SEARCH("High",K13)))), "P1 - Critical", IF(OR(AND(ISNUMBER(SEARCH("High",E13)),ISNUMBER(SEARCH("High",K13))),AND(ISNUMBER(SEARCH("Critical",E13)),ISNUMBER(SEARCH("Medium",K13)))), "P2 - High Priority", IF(OR(AND(ISNUMBER(SEARCH("Medium",E13)),ISNUMBER(SEARCH("High",K13))),AND(ISNUMBER(SEARCH("High",E13)),ISNUMBER(SEARCH("Medium",K13)))), "P3 - Medium Priority", "P4 - Low Priority"))))) | Q13: ='Remediation Tracking'!S13 | R13: ='Remediation Tracking'!U13 | S13: ='Remediation Tracking'!Z13 | U13: ='Remediation Tracking'!AE13 | V13: ='Remediation Tracking'!W13 | W13: =IF(AND(OR(R13="<1 hour",R13="1-4 hours",R13="1 day"), OR(K13="Medium",K13="High",K13="Critical")), "Yes - Quick Win", "No")
A14: =IF(B14<>"", ROW()-2, "") | B14: ='Remediation Tracking'!A14 | C14: ='Remediation Tracking'!D14 | D14: ='Remediation Tracking'!E14 | E14: ='Remediation Tracking'!F14 | F14: ='Remediation Tracking'!C14 | G14: ='Remediation Tracking'!H14 | H14: ='Remediation Tracking'!I14 | I14: ='Remediation Tracking'!G14 | J14: ='Remediation Tracking'!J14 | K14: ='Remediation Tracking'!L14 | L14: ='Remediation Tracking'!K14 | M14: Medium | N14: ='Remediation Tracking'!M14 | O14: =IF(E14="", "", (IF(ISNUMBER(SEARCH("Critical",E14)),5,IF(ISNUMBER(SEARCH("High",E14)),4,IF(ISNUMBER(SEARCH("Medium",E14)),3,2)))*10) + (IF(ISNUMBER(SEARCH("Critical",J14)),5,IF(ISNUMBER(SEARCH("High",J14)),4,IF(ISNUMBER(SEARCH("Medium",J14)),3,2)))*8) + (IF(ISNUMBER(SEARCH("Very High",M14)),5,IF(ISNUMBER(SEARCH("Very Low",M14)),1,IF(ISNUMBER(SEARCH("High",M14)),4,IF(ISNUMBER(SEARCH("Medium",M14)),3,IF(ISNUMBER(SEARCH("Low",M14)),2,1)))))*6) + (IF(T14<0, ABS(T14)/7*2, 0))) | P14: =IF(O14="", "", IF(AND(ISNUMBER(SEARCH("Critical",E14)), OR(ISNUMBER(SEARCH("Critical",K14)),ISNUMBER(SEARCH("High",K14))), T14<0), "P0 - Critical & Urgent", IF(AND(ISNUMBER(SEARCH("Critical",E14)), OR(ISNUMBER(SEARCH("Critical",K14)),ISNUMBER(SEARCH("High",K14)))), "P1 - Critical", IF(OR(AND(ISNUMBER(SEARCH("High",E14)),ISNUMBER(SEARCH("High",K14))),AND(ISNUMBER(SEARCH("Critical",E14)),ISNUMBER(SEARCH("Medium",K14)))), "P2 - High Priority", IF(OR(AND(ISNUMBER(SEARCH("Medium",E14)),ISNUMBER(SEARCH("High",K14))),AND(ISNUMBER(SEARCH("High",E14)),ISNUMBER(SEARCH("Medium",K14)))), "P3 - Medium Priority", "P4 - Low Priority"))))) | Q14: ='Remediation Tracking'!S14 | R14: ='Remediation Tracking'!U14 | S14: ='Remediation Tracking'!Z14 | U14: ='Remediation Tracking'!AE14 | V14: ='Remediation Tracking'!W14 | W14: =IF(AND(OR(R14="<1 hour",R14="1-4 hours",R14="1 day"), OR(K14="Medium",K14="High",K14="Critical")), "Yes - Quick Win", "No")
