Workbook

Sheet Executive Summary
A1: ISMS-OP-CHK-A.8.33-34 — Test Information and Audit Testing Protection Compliance Checklist
A3: DOCUMENT INFORMATION
A4: Document ID | B4: ISMS-OP-CHK-A.8.33-34
A5: Source Policy | B5: ISMS-OP-POL-A.8.33-34
A6: ISO Controls | B6: Test Information and Audit Testing Protection
A7: Generated | B7: 30.09.2026
A8: Prepared By
A9: Organisation
A10: Review Cycle | B10: Annual
A12: OVERALL COMPLIANCE STATUS
A13: Overall Compliance | B13: ='Dashboard'!G13
A14: Status | B14: =IF(Dashboard!H13>0,"INCOMPLETE",IF(Dashboard!G13="N/A","NOT ASSESSED",IF(ISNUMBER(VALUE(SUBSTITUTE(Dashboard!G13,"%",""))),IF(VALUE(SUBSTITUTE(Dashboard!G13,"%",""))>=90,"GREEN",IF(VALUE(SUBSTITUTE(Dashboard!G13,"%",""))>=70,"AMBER","RED")),"NOT ASSESSED")))
A16: KEY METRICS
A17: Total Requirements | B17: ='Dashboard'!B13
A18: Compliant | B18: ='Dashboard'!C13
A19: Partial | B19: ='Dashboard'!D13
A20: Non-Compliant | B20: ='Dashboard'!E13
A21: Not Applicable | B21: ='Dashboard'!F13
A22: Unanswered | B22: ='Dashboard'!H13
A23: Owner Coverage | B23: =IF(Dashboard!B13=0,"N/A",ROUND((COUNTA('Test Data Selection'!F4:F7)+COUNTA('Test Data Protection'!F4:F13)+COUNTA('Test Data Lifecycle'!F4:F15)+COUNTA('Audit Planning and Governance'!F4:F10)+COUNTA('Auditor Access Control'!F4:F7)+COUNTA('Penetration Testing Controls'!F4:F15)+COUNTA('Audit Tool Management'!F4:F6)+COUNTA('Audit Log Protection'!F4:F9)+COUNTA('Incident Handling During Audit'!F4:F10))/Dashboard!B13*100,0)&"%")
A25: DOMAIN STATUS SUMMARY
A26: Domain | B26: Compliance % | C26: Compliant | D26: Gaps | E26: Status
A27: Test Data Selection | B27: ='Dashboard'!G4 | C27: ='Dashboard'!C4 | D27: ='Dashboard'!E4 | E27: =IF(Dashboard!H4>0,"INCOMPLETE",IF(Dashboard!G4="N/A","--",IF(ISNUMBER(VALUE(SUBSTITUTE(Dashboard!G4,"%",""))),IF(VALUE(SUBSTITUTE(Dashboard!G4,"%",""))>=90,"PASS",IF(VALUE(SUBSTITUTE(Dashboard!G4,"%",""))>=70,"REVIEW","FAIL")),"--")))
A28: Test Data Protection | B28: ='Dashboard'!G5 | C28: ='Dashboard'!C5 | D28: ='Dashboard'!E5 | E28: =IF(Dashboard!H5>0,"INCOMPLETE",IF(Dashboard!G5="N/A","--",IF(ISNUMBER(VALUE(SUBSTITUTE(Dashboard!G5,"%",""))),IF(VALUE(SUBSTITUTE(Dashboard!G5,"%",""))>=90,"PASS",IF(VALUE(SUBSTITUTE(Dashboard!G5,"%",""))>=70,"REVIEW","FAIL")),"--")))
A29: Test Data Lifecycle | B29: ='Dashboard'!G6 | C29: ='Dashboard'!C6 | D29: ='Dashboard'!E6 | E29: =IF(Dashboard!H6>0,"INCOMPLETE",IF(Dashboard!G6="N/A","--",IF(ISNUMBER(VALUE(SUBSTITUTE(Dashboard!G6,"%",""))),IF(VALUE(SUBSTITUTE(Dashboard!G6,"%",""))>=90,"PASS",IF(VALUE(SUBSTITUTE(Dashboard!G6,"%",""))>=70,"REVIEW","FAIL")),"--")))
A30: Audit Planning and Governance | B30: ='Dashboard'!G7 | C30: ='Dashboard'!C7 | D30: ='Dashboard'!E7 | E30: =IF(Dashboard!H7>0,"INCOMPLETE",IF(Dashboard!G7="N/A","--",IF(ISNUMBER(VALUE(SUBSTITUTE(Dashboard!G7,"%",""))),IF(VALUE(SUBSTITUTE(Dashboard!G7,"%",""))>=90,"PASS",IF(VALUE(SUBSTITUTE(Dashboard!G7,"%",""))>=70,"REVIEW","FAIL")),"--")))
A31: Auditor Access Control | B31: ='Dashboard'!G8 | C31: ='Dashboard'!C8 | D31: ='Dashboard'!E8 | E31: =IF(Dashboard!H8>0,"INCOMPLETE",IF(Dashboard!G8="N/A","--",IF(ISNUMBER(VALUE(SUBSTITUTE(Dashboard!G8,"%",""))),IF(VALUE(SUBSTITUTE(Dashboard!G8,"%",""))>=90,"PASS",IF(VALUE(SUBSTITUTE(Dashboard!G8,"%",""))>=70,"REVIEW","FAIL")),"--")))
A32: Penetration Testing Controls | B32: ='Dashboard'!G9 | C32: ='Dashboard'!C9 | D32: ='Dashboard'!E9 | E32: =IF(Dashboard!H9>0,"INCOMPLETE",IF(Dashboard!G9="N/A","--",IF(ISNUMBER(VALUE(SUBSTITUTE(Dashboard!G9,"%",""))),IF(VALUE(SUBSTITUTE(Dashboard!G9,"%",""))>=90,"PASS",IF(VALUE(SUBSTITUTE(Dashboard!G9,"%",""))>=70,"REVIEW","FAIL")),"--")))
A33: Audit Tool Management | B33: ='Dashboard'!G10 | C33: ='Dashboard'!C10 | D33: ='Dashboard'!E10 | E33: =IF(Dashboard!H10>0,"INCOMPLETE",IF(Dashboard!G10="N/A","--",IF(ISNUMBER(VALUE(SUBSTITUTE(Dashboard!G10,"%",""))),IF(VALUE(SUBSTITUTE(Dashboard!G10,"%",""))>=90,"PASS",IF(VALUE(SUBSTITUTE(Dashboard!G10,"%",""))>=70,"REVIEW","FAIL")),"--")))
A34: Audit Log Protection | B34: ='Dashboard'!G11 | C34: ='Dashboard'!C11 | D34: ='Dashboard'!E11 | E34: =IF(Dashboard!H11>0,"INCOMPLETE",IF(Dashboard!G11="N/A","--",IF(ISNUMBER(VALUE(SUBSTITUTE(Dashboard!G11,"%",""))),IF(VALUE(SUBSTITUTE(Dashboard!G11,"%",""))>=90,"PASS",IF(VALUE(SUBSTITUTE(Dashboard!G11,"%",""))>=70,"REVIEW","FAIL")),"--")))
A35: Incident Handling During Audit | B35: ='Dashboard'!G12 | C35: ='Dashboard'!C12 | D35: ='Dashboard'!E12 | E35: =IF(Dashboard!H12>0,"INCOMPLETE",IF(Dashboard!G12="N/A","--",IF(ISNUMBER(VALUE(SUBSTITUTE(Dashboard!G12,"%",""))),IF(VALUE(SUBSTITUTE(Dashboard!G12,"%",""))>=90,"PASS",IF(VALUE(SUBSTITUTE(Dashboard!G12,"%",""))>=70,"REVIEW","FAIL")),"--")))
A37: CRITICAL ISSUES
A38: # | B38: Issue Description | C38: Domain | D38: Owner | E38: Due Date
A39: 1
A40: 2
A41: 3
A42: 4
A43: 5
A45: MANAGEMENT COMMENTARY
A46: [Enter management commentary on test information and audit testing protection posture]
...

Sheet Dashboard
A1: Test Information and Audit Testing Protection — Compliance Dashboard
A3: Domain | B3: Total Reqs | C3: Compliant | D3: Partial | E3: Non-Compliant | F3: N/A | G3: Compliance % | H3: Unassessed
A4: Test Data Selection | B4: =COUNTA('Test Data Selection'!A4:A7) | C4: =COUNTIF('Test Data Selection'!D4:D7,"Compliant") | D4: =COUNTIF('Test Data Selection'!D4:D7,"Partial") | E4: =COUNTIF('Test Data Selection'!D4:D7,"Non-Compliant") | F4: =COUNTIF('Test Data Selection'!D4:D7,"N/A") | G4: =IF((B4-F4)=0,"N/A",ROUND(C4/(B4-F4)*100,1)&"%") | H4: =B4-(C4+D4+E4+F4)
A5: Test Data Protection | B5: =COUNTA('Test Data Protection'!A4:A13) | C5: =COUNTIF('Test Data Protection'!D4:D13,"Compliant") | D5: =COUNTIF('Test Data Protection'!D4:D13,"Partial") | E5: =COUNTIF('Test Data Protection'!D4:D13,"Non-Compliant") | F5: =COUNTIF('Test Data Protection'!D4:D13,"N/A") | G5: =IF((B5-F5)=0,"N/A",ROUND(C5/(B5-F5)*100,1)&"%") | H5: =B5-(C5+D5+E5+F5)
A6: Test Data Lifecycle | B6: =COUNTA('Test Data Lifecycle'!A4:A15) | C6: =COUNTIF('Test Data Lifecycle'!D4:D15,"Compliant") | D6: =COUNTIF('Test Data Lifecycle'!D4:D15,"Partial") | E6: =COUNTIF('Test Data Lifecycle'!D4:D15,"Non-Compliant") | F6: =COUNTIF('Test Data Lifecycle'!D4:D15,"N/A") | G6: =IF((B6-F6)=0,"N/A",ROUND(C6/(B6-F6)*100,1)&"%") | H6: =B6-(C6+D6+E6+F6)
A7: Audit Planning and Governance | B7: =COUNTA('Audit Planning and Governance'!A4:A10) | C7: =COUNTIF('Audit Planning and Governance'!D4:D10,"Compliant") | D7: =COUNTIF('Audit Planning and Governance'!D4:D10,"Partial") | E7: =COUNTIF('Audit Planning and Governance'!D4:D10,"Non-Compliant") | F7: =COUNTIF('Audit Planning and Governance'!D4:D10,"N/A") | G7: =IF((B7-F7)=0,"N/A",ROUND(C7/(B7-F7)*100,1)&"%") | H7: =B7-(C7+D7+E7+F7)
A8: Auditor Access Control | B8: =COUNTA('Auditor Access Control'!A4:A7) | C8: =COUNTIF('Auditor Access Control'!D4:D7,"Compliant") | D8: =COUNTIF('Auditor Access Control'!D4:D7,"Partial") | E8: =COUNTIF('Auditor Access Control'!D4:D7,"Non-Compliant") | F8: =COUNTIF('Auditor Access Control'!D4:D7,"N/A") | G8: =IF((B8-F8)=0,"N/A",ROUND(C8/(B8-F8)*100,1)&"%") | H8: =B8-(C8+D8+E8+F8)
A9: Penetration Testing Controls | B9: =COUNTA('Penetration Testing Controls'!A4:A15) | C9: =COUNTIF('Penetration Testing Controls'!D4:D15,"Compliant") | D9: =COUNTIF('Penetration Testing Controls'!D4:D15,"Partial") | E9: =COUNTIF('Penetration Testing Controls'!D4:D15,"Non-Compliant") | F9: =COUNTIF('Penetration Testing Controls'!D4:D15,"N/A") | G9: =IF((B9-F9)=0,"N/A",ROUND(C9/(B9-F9)*100,1)&"%") | H9: =B9-(C9+D9+E9+F9)
A10: Audit Tool Management | B10: =COUNTA('Audit Tool Management'!A4:A6) | C10: =COUNTIF('Audit Tool Management'!D4:D6,"Compliant") | D10: =COUNTIF('Audit Tool Management'!D4:D6,"Partial") | E10: =COUNTIF('Audit Tool Management'!D4:D6,"Non-Compliant") | F10: =COUNTIF('Audit Tool Management'!D4:D6,"N/A") | G10: =IF((B10-F10)=0,"N/A",ROUND(C10/(B10-F10)*100,1)&"%") | H10: =B10-(C10+D10+E10+F10)
A11: Audit Log Protection | B11: =COUNTA('Audit Log Protection'!A4:A9) | C11: =COUNTIF('Audit Log Protection'!D4:D9,"Compliant") | D11: =COUNTIF('Audit Log Protection'!D4:D9,"Partial") | E11: =COUNTIF('Audit Log Protection'!D4:D9,"Non-Compliant") | F11: =COUNTIF('Audit Log Protection'!D4:D9,"N/A") | G11: =IF((B11-F11)=0,"N/A",ROUND(C11/(B11-F11)*100,1)&"%") | H11: =B11-(C11+D11+E11+F11)
A12: Incident Handling During Audit | B12: =COUNTA('Incident Handling During Audit'!A4:A10) | C12: =COUNTIF('Incident Handling During Audit'!D4:D10,"Compliant") | D12: =COUNTIF('Incident Handling During Audit'!D4:D10,"Partial") | E12: =COUNTIF('Incident Handling During Audit'!D4:D10,"Non-Compliant") | F12: =COUNTIF('Incident Handling During Audit'!D4:D10,"N/A") | G12: =IF((B12-F12)=0,"N/A",ROUND(C12/(B12-F12)*100,1)&"%") | H12: =B12-(C12+D12+E12+F12)
A13: TOTAL | B13: =SUM(B4:B12) | C13: =SUM(C4:C12) | D13: =SUM(D4:D12) | E13: =SUM(E4:E12) | F13: =SUM(F4:F12) | G13: =IF((B13-F13)=0,"N/A",ROUND(C13/(B13-F13)*100,1)&"%") | H13: =SUM(H4:H12)
A15: COMPLIANCE BY STATUS
A16: Compliant | B16: =C13 | C16: =IF(B13=0,"",ROUND(B16/B13*100,1)&"%")
A17: Partial | B17: =D13 | C17: =IF(B13=0,"",ROUND(B17/B13*100,1)&"%")
A18: Non-Compliant | B18: =E13 | C18: =IF(B13=0,"",ROUND(B18/B13*100,1)&"%")
A19: N/A | B19: =F13 | C19: =IF(B13=0,"",ROUND(B19/B13*100,1)&"%")
A21: TOP GAPS (Manual Entry)
A22: Priority | B22: Domain | C22: Requirement | D22: Owner | E22: Due Date | F22: Status
A34: COMPLIANCE TREND (Manual Entry)
A35: Assessment Date | B35: Overall % | C35: Compliant | D35: Gaps | E35: Assessor | F35: Notes

Sheet Test Data Selection
A1: Test Data Selection — Compliance Checklist
A2: ISO/IEC 27001:2022 — Controls A.8.33-34: Test Information and Audit Testing Protection
A3: Req # | B3: Section | C3: Requirement | D3: Status | E3: Evidence | F3: Owner | G3: Due Date | H3: Notes
A4: A.8.33-34-01 | B4: Establish A Clear Hierarchy Of | C4: The organisation shall establish a clear hierarchy of preference for test data sources.
A5: A.8.33-34-02 | B5: Direct Production Copies | C5: Direct production copies shall only be permitted where all other options are demonstrably inadequate, with documented justification, time-limited approval (maximum 30 days), enhanced access controls, and mandatory deletion upon completion.
A6: A.8.33-34-03 | B6: The Data Owner And Information Security | C6: Where a decision results in Priority 3 or higher, the Data Owner and Information Security Manager shall be consulted before proceeding.
A7: A.8.33-34-04 | B7: Test Data Classification*: Test Data | C7: Test Data Classification*: Test data shall be classified according to the organisation's information classification scheme. Production-derived test data inherits the classification of the source data until masking or anonymisation is validated. Synthetic data shall be classified based on business context (typically Internal). Classification determines the protection controls required.

Sheet Test Data Protection
A1: Test Data Protection — Compliance Checklist
A2: ISO/IEC 27001:2022 — Controls A.8.33-34: Test Information and Audit Testing Protection
A3: Req # | B3: Section | C3: Requirement | D3: Status | E3: Evidence | F3: Owner | G3: Due Date | H3: Notes
A4: A.8.33-34-05 | B4: The Organisation | C4: When production data is required for testing, the organisation shall apply data protection techniques before the data is accessible in any test environment.
A5: A.8.33-34-06 | B5: Render Re-Identification Not Reasonably | C5: Anonymisation shall render re-identification not reasonably possible, considering available means of re-identification, cost of re-identification, and intended purpose.
A6: A.8.33-34-07 | B6: Anonymisation Techniques | C6: Anonymisation techniques shall be validated before use and reviewed annually for continued effectiveness, accounting for advances in re-identification techniques including AI-assisted methods.
A7: A.8.33-34-08 | B7: Pseudonymised Data Remains Personal Data | C7: Pseudonymised data remains personal data and shall be protected accordingly.
A8: A.8.33-34-09 | B8: The Mapping Key (Pseudonym-To-Identity) | C8: The mapping key (pseudonym-to-identity) shall be stored separately from the pseudonymised dataset, with access restricted to authorised personnel.
A9: A.8.33-34-10 | B9: Pseudonymised Test Data | C9: Pseudonymised test data shall be subject to the same access controls as the original data classification.
A10: A.8.33-34-11 | B10: Data Masking | C10: Data masking shall be applied using [Data Masking Tool] (e.g., Informatica, Delphix, IBM InfoSphere Optim, or equivalent) or approved scripted methods.
A11: A.8.33-34-12 | B11: Masking Validation*: Masked Data | C11: Masking Validation*: Masked data shall be validated before release to test environments to confirm that original sensitive values are not recoverable, data format is preserved for application compatibility, referential integrity is maintained across related datasets, and no plaintext personal data exists in the masked output. Validation results shall be documented and approved by the Information Security Manager.
A12: A.8.33-34-13 | B12: Be Generated To Preserve The Statistical | C12: Where synthetic data is used, it shall be generated to preserve the statistical properties, data distributions, and referential integrity required for effective testing without containing any real personal or business data.
A13: A.8.33-34-14 | B13: Synthetic Data Generators | C13: Synthetic data generators shall be documented, version-controlled, and reviewed periodically to ensure generated data remains fit for purpose. The organisation shall maintain records of synthetic data generation parameters and validation results.

Sheet Test Data Lifecycle
A1: Test Data Lifecycle — Compliance Checklist
A2: ISO/IEC 27001:2022 — Controls A.8.33-34: Test Information and Audit Testing Protection
A3: Req # | B3: Section | C3: Requirement | D3: Status | E3: Evidence | F3: Owner | G3: Due Date | H3: Notes
A4: A.8.33-34-15 | B4: Test Data Creation Or Refresh | C4: Test data creation or refresh shall be requested through a documented process.
A5: A.8.33-34-16 | B5: Masking Or Anonymisation | C5: Masking or anonymisation shall be applied before data is accessible in the test environment (not after).
A6: A.8.33-34-17 | B6: Data Provisioning Activities | C6: All data provisioning activities shall be logged for audit purposes.
A7: A.8.33-34-18 | B7: Test Data | C7: Test data containing masked or pseudonymised production data shall be retained only for the duration of the testing requirement. Upon project completion, test data shall be deleted within 30 days.
A8: A.8.33-34-19 | B8: Test Data | C8: Test data shall be reviewed quarterly for continued need.
A9: A.8.33-34-20 | B9: Data Older Than 90 Days Without | C9: Data older than 90 days without documented active usage shall be flagged for deletion.
A10: A.8.33-34-21 | B10: Automated Retention Monitoring | C10: Automated retention monitoring shall alert when data exceeds thresholds.
A11: A.8.33-34-22 | B11: Disposal*: Test Data Disposal | C11: Disposal*: Test data disposal shall follow the same secure deletion procedures as production data of equivalent classification. Disposal shall be verified and documented.
A12: A.8.33-34-23 | B12: Fresh Masking | C12: Fresh masking shall be applied to each refresh cycle (prior masking does not carry over).
A13: A.8.33-34-24 | B13: Refresh Procedures | C13: Refresh procedures shall be documented and approved by the Data Owner.
A14: A.8.33-34-25 | B14: Refresh Activities | C14: Refresh activities shall be logged, including source system, volume, masking method, and operator.
A15: A.8.33-34-26 | B15: Previous Test Data | C15: Previous test data shall be securely deleted before or immediately after refresh completion.

Sheet Audit Planning and Governance
A1: Audit Planning and Governance — Compliance Checklist
A2: ISO/IEC 27001:2022 — Controls A.8.33-34: Test Information and Audit Testing Protection
A3: Req # | B3: Section | C3: Requirement | D3: Status | E3: Evidence | F3: Owner | G3: Due Date | H3: Notes
A4: A.8.33-34-27 | B4: Before Any Audit Testing Commences, The | C4: Before any audit testing commences, the organisation shall establish formal agreement between the tester and appropriate management covering:.
A5: A.8.33-34-28 | B5: Pre-Audit Agreements | C5: Pre-audit agreements shall be documented, signed by both parties, and retained as evidence.
A6: A.8.33-34-29 | B6: Audit Testing Activities | C6: Audit testing activities shall be scheduled to minimise operational impact:.
A7: A.8.33-34-30 | B7: Critical Business Periods (E.G., | C7: Critical business periods (e.g., month-end close, peak trading, system maintenance windows) shall be avoided unless specifically testing resilience during those periods.
A8: A.8.33-34-31 | B8: Testing Windows | C8: Testing windows shall be coordinated with IT Operations and relevant system owners.
A9: A.8.33-34-32 | B9: Affected Stakeholders | C9: Affected stakeholders shall be notified of planned testing activities, including timing, scope, and potential impact.
A10: A.8.33-34-33 | B10: Emergency Or Unscheduled Testing | C10: Emergency or unscheduled testing shall follow an expedited approval process with post-facto review within 48 hours.

Sheet Auditor Access Control
A1: Auditor Access Control — Compliance Checklist
A2: ISO/IEC 27001:2022 — Controls A.8.33-34: Test Information and Audit Testing Protection
A3: Req # | B3: Section | C3: Requirement | D3: Status | E3: Evidence | F3: Owner | G3: Due Date | H3: Notes
A4: A.8.33-34-34 | B4: Access Granted To Auditors, Assessors, | C4: Access granted to auditors, assessors, and penetration testers shall follow the principle of least privilege.
A5: A.8.33-34-35 | B5: An Administrator With The Necessary | C5: Where read-only access is not feasible, an administrator with the necessary access rights shall perform system or data access on behalf of the auditor, with the auditor observing and directing.
A6: A.8.33-34-36 | B6: Device Security*: Before Granting | C6: Device Security*: Before granting access, the organisation shall verify that auditor devices meet minimum security requirements, including current operating system patches, active endpoint protection, full disk encryption, and no known malware. Auditors using non-compliant devices shall be provided with organisation-managed devices or virtual desktop access.
A7: A.8.33-34-37 | B7: Access Deprovisioning*: Auditor Access | C7: Access Deprovisioning*: Auditor access shall be revoked within 24 hours of audit completion or the agreed access expiration date, whichever is earlier. Deprovisioning shall be verified and documented.

Sheet Penetration Testing Controls
A1: Penetration Testing Controls — Compliance Checklist
A2: ISO/IEC 27001:2022 — Controls A.8.33-34: Test Information and Audit Testing Protection
A3: Req # | B3: Section | C3: Requirement | D3: Status | E3: Evidence | F3: Owner | G3: Due Date | H3: Notes
A4: A.8.33-34-38 | B4: Penetration Testing And Active Security | C4: Penetration testing and active security testing shall be authorised in writing by the CISO (or delegate) and relevant system owners before testing begins.
A5: A.8.33-34-39 | B5: Rules Of Engagement* | C5: Rules of Engagement* shall document:.
A6: A.8.33-34-40 | B6: It Operations | C6: IT Operations shall be on standby with the ability to intervene if operational systems are affected.
A7: A.8.33-34-41 | B7: Be Conducted In Isolated Or | C7: Testing shall be conducted in isolated or non-production environments where possible.
A8: A.8.33-34-42 | B8: Rollback And Recovery Procedures | C8: Where production testing is required, rollback and recovery procedures shall be prepared in advance.
A9: A.8.33-34-43 | B9: Be Suspended Immediately If Unintended | C9: Testing shall be suspended immediately if unintended operational impact occurs, and shall not resume without explicit approval from the IT Operations Manager and CISO.
A10: A.8.33-34-44 | B10: Critical Vulnerabilities Discovered | C10: Critical vulnerabilities discovered during testing shall be reported to the Security Team immediately (not deferred to the final report).
A11: A.8.33-34-45 | B11: Be Handled Per The Organisation'S | C11: Vulnerabilities shall be handled per the organisation's vulnerability management process (A.8.8).
A12: A.8.33-34-46 | B12: Not Exploit Vulnerabilities Beyond The | C12: Testers shall not exploit vulnerabilities beyond the scope necessary for verification and risk assessment.
A13: A.8.33-34-47 | B13: Penetration Testing Reports | C13: Penetration testing reports shall be classified as Confidential and distributed only to authorised recipients.
A14: A.8.33-34-48 | B14: During Active Penetration Testing Or | C14: During active penetration testing or extended audit engagements, the tester shall provide daily status updates to the designated organisational contact. Status updates shall include:.
A15: A.8.33-34-49 | B15: Critical Findings | C15: Critical findings shall be reported immediately by phone to the CISO, in addition to any daily status update. The format and frequency of status reporting shall be agreed in the pre-audit agreement.

Sheet Audit Tool Management
A1: Audit Tool Management — Compliance Checklist
A2: ISO/IEC 27001:2022 — Controls A.8.33-34: Test Information and Audit Testing Protection
A3: Req # | B3: Section | C3: Requirement | D3: Status | E3: Evidence | F3: Owner | G3: Due Date | H3: Notes
A4: A.8.33-34-50 | B4: Audit And Testing Tools Used To | C4: Audit and testing tools used to assess the organisation's systems shall be:.
A5: A.8.33-34-51 | B5: Audit Tools | C5: Audit tools shall not be installed on production systems without explicit CISO approval. Where possible, audit tools shall be run from dedicated audit workstations or isolated virtual environments.
A6: A.8.33-34-52 | B6: Audit Tools, Scripts, And Configuration | C6: Audit tools, scripts, and configuration files shall be protected from unauthorised access both during and after the engagement. Tools capable of exploiting vulnerabilities or bypassing security controls shall be removed from organisational systems upon audit completion.

Sheet Audit Log Protection
A1: Audit Log Protection — Compliance Checklist
A2: ISO/IEC 27001:2022 — Controls A.8.33-34: Test Information and Audit Testing Protection
A3: Req # | B3: Section | C3: Requirement | D3: Status | E3: Evidence | F3: Owner | G3: Due Date | H3: Notes
A4: A.8.33-34-53 | B4: Logs Generated During Audit And Testing | C4: Logs generated during audit and testing activities shall be protected from unauthorised modification or deletion to maintain the integrity of the audit trail.
A5: A.8.33-34-54 | B5: Audit Logs | C5: Audit logs shall be written to tamper-evident storage (e.g., write-once media, SIEM with integrity controls, or equivalent).
A6: A.8.33-34-55 | B6: Capture: Timestamp (Utc), User Identity, | C6: Logs shall capture: timestamp (UTC), user identity, source IP, action performed, system affected, and outcome (success/failure).
A7: A.8.33-34-56 | B7: Logs Generated During Audit Testing | C7: Logs generated during audit testing shall be retained per the organisation's log retention policy (minimum 1 year for access events, 3 years for security events).
A8: A.8.33-34-57 | B8: Be Available For Review If Audit | C8: Logs shall be available for review if audit findings are disputed or require clarification.
A9: A.8.33-34-58 | B9: During Active Penetration Testing, | C9: During active penetration testing, enhanced monitoring shall be enabled to distinguish authorised testing activity from genuine security events.

Sheet Incident Handling During Audit
A1: Incident Handling During Audit — Compliance Checklist
A2: ISO/IEC 27001:2022 — Controls A.8.33-34: Test Information and Audit Testing Protection
A3: Req # | B3: Section | C3: Requirement | D3: Status | E3: Evidence | F3: Owner | G3: Due Date | H3: Notes
A4: A.8.33-34-59 | B4: Immediate Suspension: Testing | C4: Immediate suspension: Testing shall cease immediately upon detection of unintended impact.
A5: A.8.33-34-60 | B5: Notification: It Operations | C5: Notification: IT Operations shall be notified for containment and recovery.
A6: A.8.33-34-61 | B6: Root Cause Analysis: The Cause Of | C6: Root cause analysis: The cause of the unintended impact shall be documented.
A7: A.8.33-34-62 | B7: Remediation: Affected Systems | C7: Remediation: Affected systems shall be restored to normal operation.
A8: A.8.33-34-63 | B8: Resumption Approval: Testing | C8: Resumption approval: Testing shall not resume without explicit approval from the IT Operations Manager.
A9: A.8.33-34-64 | B9: Lessons Learned: Incident | C9: Lessons learned: Incident shall be documented and incorporated into future pre-audit planning.
A10: A.8.33-34-65 | B10: Genuine Security Incidents Discovered | C10: Genuine security incidents discovered during audit testing (e.g., evidence of prior compromise, active threats) shall be escalated immediately per the organisation's incident management process (A.5.24-28).
