Workbook

Sheet Instructions & Legend
A1: ISMS-IMP-A.8.17.2 - Time Synchronisation Status Assessment ISO/IEC 27001:2022 - Control A.8.17: Clock Synchronisation
A3: Document Information
A4: Document ID | B4: ISMS-IMP-A.8.17.2
A5: Workbook Title | B5: Time Synchronisation Status Assessment
A6: Control Reference | B6: ISO/IEC 27001:2022 - Control A.8.17: Clock Synchronisation
A7: Version | B7: 1.0
A8: Assessment Date
A9: Completed By
A10: Organisation
A12: Instructions
A13: 1. Complete the System Inventory sheet with all time-dependent systems.
A14: 2. Record drift measurements in the Drift Analysis sheet.
A15: 3. Log synchronisation gaps and failures in the Gap Analysis sheet.
A16: 4. Review overall compliance in the Summary Dashboard sheet.
A17: 5. Record all evidence in the Evidence Register sheet.
A18: 6. Complete the Approval Sign-Off sheet when assessment is finished.
A19: 7. Use dropdown lists where provided for consistent data entry.
A20: 8. Add rows as needed — formulas auto-extend for new data.
... A23: Status Legend
A24: Symbol | B24: Status | C24: Description
A25: ✓ | B25: Compliant / Complete | C25: Requirement fully met
A26: ⚠ | B26: Partial / In Progress | C26: Partially met or in progress
A27: ✗ | B27: Non-Compliant / Not Started | C27: Requirement not met
A28: — | B28: Not Applicable | C28: Not applicable to this assessment

Sheet System Inventory
A1: SYSTEM INVENTORY
A2: Record all systems and verify NTP synchronisation status and drift compliance
A3: System Name [*] | B3: Asset ID | C3: Type [*] | D3: OS/Platform | E3: Criticality | F3: NTP Server(s) Configured [*] | G3: Sync Status [*] | H3: Stratum | I3: Current Drift (ms) [*] | J3: Last Sync Time | K3: Last Verified [*] | L3: Compliance | M3: Notes
A4: web-server-01.org.local | B4: SRV-001 | C4: Server-Physical | D4: Ubuntu 22.04 | E4: High | F4: ntp1.organisation.local, ntp2.organisation.local | G4: ✅ Synced | H4: 3 | I4: 0.5 | J4: 07.03.2026 12:28:13 | K4: 07.03.2026 | L4: =IF(G8="✅ Synced",IF(E8="Critical",IF(ABS(I8)<=100,"✅ PASS","❌ FAIL"),IF(ABS(I8)<=1000,"✅ PASS","❌ FAIL")),"❌ FAIL") | M4: Verified via chronyc tracking
A5: db-server-01.org.local | B5: SRV-002 | C5: Server-Virtual | D5: Windows Server 2022 | E5: Critical | F5: ntp1.organisation.local, ntp2.organisation.local | G5: ✅ Synced | H5: 3 | I5: 25.3 | J5: 07.03.2026 12:28:13 | K5: 07.03.2026 | L5: =IF(G8="✅ Synced",IF(E8="Critical",IF(ABS(I8)<=100,"✅ PASS","❌ FAIL"),IF(ABS(I8)<=1000,"✅ PASS","❌ FAIL")),"❌ FAIL") | M5: Verified via w32tm
A6: firewall-01.org.local | B6: NET-001 | C6: Network Device | D6: Cisco ASA | E6: Critical | F6: 10.0.1.10, 10.0.1.11 | G6: ✅ Synced | H6: 3 | I6: 15.7 | J6: 07.03.2026 12:28:13 | K6: 07.03.2026 | L6: =IF(G8="✅ Synced",IF(E8="Critical",IF(ABS(I8)<=100,"✅ PASS","❌ FAIL"),IF(ABS(I8)<=1000,"✅ PASS","❌ FAIL")),"❌ FAIL") | M6: Verified via show ntp status
A7: siem-01.org.local | B7: SEC-001 | C7: Security Appliance | D7: Splunk Enterprise | E7: Critical | F7: ntp1.organisation.local, ntp2.organisation.local | G7: ❌ Not Synced | H7: 16 | I7: 1500.0 | J7: N/A | K7: 07.03.2026 | L7: =IF(G8="✅ Synced",IF(E8="Critical",IF(ABS(I8)<=100,"✅ PASS","❌ FAIL"),IF(ABS(I8)<=1000,"✅ PASS","❌ FAIL")),"❌ FAIL") | M7: NTP service not configured - REQUIRES REMEDIATION
A8: app-server-03.org.local | B8: SRV-005 | C8: Server-Cloud | D8: Amazon Linux 2 | E8: Medium | F8: 169.254.169.123 (AWS Time Sync) | G8: ✅ Synced | H8: 3 | I8: 2.1 | J8: 07.03.2026 12:28:13 | K8: 07.03.2026 | L8: =IF(G8="✅ Synced",IF(E8="Critical",IF(ABS(I8)<=100,"✅ PASS","❌ FAIL"),IF(ABS(I8)<=1000,"✅ PASS","❌ FAIL")),"❌ FAIL") | M8: Using AWS Time Sync Service
L9: =IF(G9="✅ Synced",IF(E9="Critical",IF(ABS(I9)<=100,"✅ PASS","❌ FAIL"),IF(ABS(I9)<=1000,"✅ PASS","❌ FAIL")),"❌ FAIL")
L10: =IF(G10="✅ Synced",IF(E10="Critical",IF(ABS(I10)<=100,"✅ PASS","❌ FAIL"),IF(ABS(I10)<=1000,"✅ PASS","❌ FAIL")),"❌ FAIL")
L11: =IF(G11="✅ Synced",IF(E11="Critical",IF(ABS(I11)<=100,"✅ PASS","❌ FAIL"),IF(ABS(I11)<=1000,"✅ PASS","❌ FAIL")),"❌ FAIL")
L12: =IF(G12="✅ Synced",IF(E12="Critical",IF(ABS(I12)<=100,"✅ PASS","❌ FAIL"),IF(ABS(I12)<=1000,"✅ PASS","❌ FAIL")),"❌ FAIL")
L13: =IF(G13="✅ Synced",IF(E13="Critical",IF(ABS(I13)<=100,"✅ PASS","❌ FAIL"),IF(ABS(I13)<=1000,"✅ PASS","❌ FAIL")),"❌ FAIL")
L14: =IF(G14="✅ Synced",IF(E14="Critical",IF(ABS(I14)<=100,"✅ PASS","❌ FAIL"),IF(ABS(I14)<=1000,"✅ PASS","❌ FAIL")),"❌ FAIL")
L15: =IF(G15="✅ Synced",IF(E15="Critical",IF(ABS(I15)<=100,"✅ PASS","❌ FAIL"),IF(ABS(I15)<=1000,"✅ PASS","❌ FAIL")),"❌ FAIL")
L16: =IF(G16="✅ Synced",IF(E16="Critical",IF(ABS(I16)<=100,"✅ PASS","❌ FAIL"),IF(ABS(I16)<=1000,"✅ PASS","❌ FAIL")),"❌ FAIL")
L17: =IF(G17="✅ Synced",IF(E17="Critical",IF(ABS(I17)<=100,"✅ PASS","❌ FAIL"),IF(ABS(I17)<=1000,"✅ PASS","❌ FAIL")),"❌ FAIL")
L18: =IF(G18="✅ Synced",IF(E18="Critical",IF(ABS(I18)<=100,"✅ PASS","❌ FAIL"),IF(ABS(I18)<=1000,"✅ PASS","❌ FAIL")),"❌ FAIL")
L19: =IF(G19="✅ Synced",IF(E19="Critical",IF(ABS(I19)<=100,"✅ PASS","❌ FAIL"),IF(ABS(I19)<=1000,"✅ PASS","❌ FAIL")),"❌ FAIL")
L20: =IF(G20="✅ Synced",IF(E20="Critical",IF(ABS(I20)<=100,"✅ PASS","❌ FAIL"),IF(ABS(I20)<=1000,"✅ PASS","❌ FAIL")),"❌ FAIL")
... L54: =IF(G54="✅ Synced",IF(E54="Critical",IF(ABS(I54)<=100,"✅ PASS","❌ FAIL"),IF(ABS(I54)<=1000,"✅ PASS","❌ FAIL")),"❌ FAIL")

Sheet Drift Analysis
A1: TIME DRIFT STATISTICAL ANALYSIS
A2: Analysis of time drift across all synchronized systems
A4: Overall Drift Statistics
A5: Metric | B5: Value | C5: Unit | D5: Notes
A6: Total Systems Assessed | B6: =COUNTA('System Inventory'!A5:A54) | C6: systems | D6: All systems in inventory
A7: Systems Synchronized | B7: =COUNTIF('System Inventory'!G5:G54,"✅ Synced") | C7: systems | D7: Stratum ≠ 16
A8: Systems Not Synchronized | B8: =COUNTIF('System Inventory'!G5:G54,"❌ Not Synced")+COUNTIF('System Inventory'!G5:G54,"⚠ Sync Failed") | C8: systems | D8: Requires remediation
A9: Average Drift (Synced Systems) | B9: =AVERAGEIF('System Inventory'!G5:G54,"✅ Synced",'System Inventory'!I5:I54) | C9: ms | D9: Mean time offset
A10: Maximum Drift (Synced Systems) | B10: =MAXIFS('System Inventory'!I5:I54,'System Inventory'!G5:G54,"✅ Synced") | C10: ms | D10: Highest offset observed
A11: Minimum Drift (Synced Systems) | B11: =MINIFS('System Inventory'!I5:I54,'System Inventory'!G5:G54,"✅ Synced") | C11: ms | D11: Lowest offset observed
A12: Standard Deviation | B12: =STDEV('System Inventory'!I5:I54) | C12: ms | D12: Variation in drift
A15: Drift Distribution by Threshold
A16: Threshold | B16: Count | C16: Percentage | D16: Status
A17: ≤ 10ms (High-Precision) | B17: =COUNTIFS('System Inventory'!I5:I54,"<=10",'System Inventory'!I5:I54,">=-10",'System Inventory'!G5:G54,"✅ Synced") | C17: =B17/B6*100 | D17: Excellent
A18: ≤ 100ms (Critical Systems) | B18: =COUNTIFS('System Inventory'!I5:I54,"<=100",'System Inventory'!I5:I54,">=-100",'System Inventory'!G5:G54,"✅ Synced") | C18: =B18/B6*100 | D18: Good for critical
A19: ≤ 1000ms (General Systems) | B19: =COUNTIFS('System Inventory'!I5:I54,"<=1000",'System Inventory'!I5:I54,">=-1000",'System Inventory'!G5:G54,"✅ Synced") | C19: =B19/B6*100 | D19: Acceptable
A20: > 1000ms (Exceeds Threshold) | B20: =COUNTIFS('System Inventory'!I5:I54,">1000",'System Inventory'!G5:G54,"✅ Synced")+COUNTIFS('System Inventory'!I5:I54,"<-1000",'System Inventory'!G5:G54,"✅ Synced") | C20: =B20/B6*100 | D20: FAIL - Requires action
A23: Drift Analysis by System Type
A24: System Type | B24: Avg Drift (ms) | C24: Max Drift (ms) | D24: Count
A25: Server-Physical | B25: =AVERAGEIF('System Inventory'!C5:C54,"Server-Physical",'System Inventory'!I5:I54) | C25: =MAXIFS('System Inventory'!I5:I54,'System Inventory'!C5:C54,"Server-Physical") | D25: =COUNTIF('System Inventory'!C5:C54,"Server-Physical")
A26: Server-Virtual | B26: =AVERAGEIF('System Inventory'!C5:C54,"Server-Virtual",'System Inventory'!I5:I54) | C26: =MAXIFS('System Inventory'!I5:I54,'System Inventory'!C5:C54,"Server-Virtual") | D26: =COUNTIF('System Inventory'!C5:C54,"Server-Virtual")
A27: Server-Cloud | B27: =AVERAGEIF('System Inventory'!C5:C54,"Server-Cloud",'System Inventory'!I5:I54) | C27: =MAXIFS('System Inventory'!I5:I54,'System Inventory'!C5:C54,"Server-Cloud") | D27: =COUNTIF('System Inventory'!C5:C54,"Server-Cloud")
A28: Network Device | B28: =AVERAGEIF('System Inventory'!C5:C54,"Network Device",'System Inventory'!I5:I54) | C28: =MAXIFS('System Inventory'!I5:I54,'System Inventory'!C5:C54,"Network Device") | D28: =COUNTIF('System Inventory'!C5:C54,"Network Device")
A29: Security Appliance | B29: =AVERAGEIF('System Inventory'!C5:C54,"Security Appliance",'System Inventory'!I5:I54) | C29: =MAXIFS('System Inventory'!I5:I54,'System Inventory'!C5:C54,"Security Appliance") | D29: =COUNTIF('System Inventory'!C5:C54,"Security Appliance")
A32: Drift Analysis by Criticality
A33: Criticality | B33: Avg Drift (ms) | C33: Max Drift (ms) | D33: Count
A34: Critical | B34: =AVERAGEIF('System Inventory'!E5:E54,"Critical",'System Inventory'!I5:I54) | C34: =MAXIFS('System Inventory'!I5:I54,'System Inventory'!E5:E54,"Critical") | D34: =COUNTIF('System Inventory'!E5:E54,"Critical")
A35: High | B35: =AVERAGEIF('System Inventory'!E5:E54,"High",'System Inventory'!I5:I54) | C35: =MAXIFS('System Inventory'!I5:I54,'System Inventory'!E5:E54,"High") | D35: =COUNTIF('System Inventory'!E5:E54,"High")
A36: Medium | B36: =AVERAGEIF('System Inventory'!E5:E54,"Medium",'System Inventory'!I5:I54) | C36: =MAXIFS('System Inventory'!I5:I54,'System Inventory'!E5:E54,"Medium") | D36: =COUNTIF('System Inventory'!E5:E54,"Medium")
A37: Low | B37: =AVERAGEIF('System Inventory'!E5:E54,"Low",'System Inventory'!I5:I54) | C37: =MAXIFS('System Inventory'!I5:I54,'System Inventory'!E5:E54,"Low") | D37: =COUNTIF('System Inventory'!E5:E54,"Low")

Sheet Gap Analysis
A1: GAP ANALYSIS — NON-COMPLIANT SYSTEMS
A2: Systems not synchronised or exceeding drift threshold — requires immediate remediation
A3: System Name [*] | B3: Type [*] | C3: Criticality [*] | D3: Sync Status [*] | E3: Drift (ms) [*] | F3: Issue Category [*] | G3: Remediation Action [*] | H3: Target Date
A4: siem-01.org.local | B4: Security Appliance | C4: Critical | D4: ✅ Synced | E4: 150.0 | F4: Excessive Drift (Critical) | G4: Investigate time source quality, restart NTP | H4: 10.03.2026

Sheet Evidence Register
A1: EVIDENCE REGISTER
A2: Evidence tracking for Time Synchronisation Status Assessment
A4: Evidence ID | B4: Assessment Area | C4: Evidence Type | D4: Description | E4: Location/Path | F4: Date Collected | G4: Collected By | H4: Verification Status
A5: EV-001 | B5: Time Drift Report Q1 2025 | C5: Log Extract | D5: Automated time drift monitoring report showing <50ms drift on all servers | E5: /evidence/ntp/drift-report-q1-2025.csv | F5: 01.04.2025 | G5: SOC Team | H5: Verified

Sheet Summary Dashboard
A1: TIME SYNCHRONISATION STATUS ASSESSMENT — SUMMARY DASHBOARD
A2: System Synchronisation Status — A.8.17 Clock Synchronisation
A4: TABLE 1: COMPLIANCE BY CRITICALITY
A5: Assessment Area | B5: Total Items | C5: Compliant | D5: Partial | E5: Non-Compliant | F5: N/A | G5: Compliance %
A6: Critical Systems | B6: =COUNTIF('System Inventory'!E5:E54,"Critical") | C6: =COUNTIFS('System Inventory'!E5:E54,"Critical",'System Inventory'!L5:L54,"✅ PASS") | D6: 0 | E6: =B9-C9-F9 | F6: =COUNTIFS('System Inventory'!E5:E54,"Critical",'System Inventory'!G5:G54,"Excluded") | G6: =IF((B10-F10)=0,0,C10/(B10-F10))
A7: High Systems | B7: =COUNTIF('System Inventory'!E5:E54,"High") | C7: =COUNTIFS('System Inventory'!E5:E54,"High",'System Inventory'!L5:L54,"✅ PASS") | D7: 0 | E7: =B9-C9-F9 | F7: =COUNTIFS('System Inventory'!E5:E54,"High",'System Inventory'!G5:G54,"Excluded") | G7: =IF((B10-F10)=0,0,C10/(B10-F10))
A8: Medium Systems | B8: =COUNTIF('System Inventory'!E5:E54,"Medium") | C8: =COUNTIFS('System Inventory'!E5:E54,"Medium",'System Inventory'!L5:L54,"✅ PASS") | D8: 0 | E8: =B9-C9-F9 | F8: =COUNTIFS('System Inventory'!E5:E54,"Medium",'System Inventory'!G5:G54,"Excluded") | G8: =IF((B10-F10)=0,0,C10/(B10-F10))
A9: Low Systems | B9: =COUNTIF('System Inventory'!E5:E54,"Low") | C9: =COUNTIFS('System Inventory'!E5:E54,"Low",'System Inventory'!L5:L54,"✅ PASS") | D9: 0 | E9: =B9-C9-F9 | F9: =COUNTIFS('System Inventory'!E5:E54,"Low",'System Inventory'!G5:G54,"Excluded") | G9: =IF((B10-F10)=0,0,C10/(B10-F10))
A10: TOTAL | B10: =B6+B7+B8+B9 | C10: =C6+C7+C8+C9 | D10: 0 | E10: =E6+E7+E8+E9 | F10: =F6+F7+F8+F9 | G10: =IF((B10-F10)=0,0,C10/(B10-F10))
A12: TABLE 2: KEY PERFORMANCE METRICS
A13: Metric | B13: Value | C13: Category
A14: Total Systems Assessed | B14: =COUNTA('System Inventory'!A5:A54) | C14: Overall
A15: Systems Synchronized (✅ Synced) | B15: =COUNTIF('System Inventory'!G5:G54,"✅ Synced") | C15: Sync Status
A16: Systems Not Synchronized (❌ Not Synced) | B16: =COUNTIF('System Inventory'!G5:G54,"❌ Not Synced") | C16: Sync Status
A17: Sync Failures (⚠ Sync Failed) | B17: =COUNTIF('System Inventory'!G5:G54,"⚠ Sync Failed") | C17: Sync Status
A18: Unknown Sync Status | B18: =COUNTIF('System Inventory'!G5:G54,"Unknown") | C18: Sync Status
A19: Systems Excluded from Assessment | B19: =COUNTIF('System Inventory'!G5:G54,"Excluded") | C19: Sync Status
A20: Compliant Systems (✅ PASS) | B20: =COUNTIF('System Inventory'!L5:L54,"✅ PASS") | C20: Compliance
A21: Non-Compliant Systems (❌ FAIL) | B21: =COUNTA('System Inventory'!A5:A54)-COUNTIF('System Inventory'!L5:L54,"✅ PASS")-COUNTIF('System Inventory'!G5:G54,"Excluded") | C21: Compliance
A22: Synchronisation Rate % | B22: =IF(COUNTA('System Inventory'!A5:A54)=0,0,COUNTIF('System Inventory'!G5:G54,"✅ Synced")/COUNTA('System Inventory'!A5:A54)) | C22: Compliance
A23: Compliance Rate % | B23: =IF(COUNTA('System Inventory'!A5:A54)-COUNTIF('System Inventory'!G5:G54,"Excluded")=0,0,COUNTIF('System Inventory'!L5:L54,"✅ PASS")/(COUNTA('System Inventory'!A5:A54)-COUNTIF('System Inventory'!G5:G54,"Excluded"))) | C23: Compliance
A24: Critical Systems Total | B24: =COUNTIF('System Inventory'!E5:E54,"Critical") | C24: By Criticality
A25: Critical Systems Compliant | B25: =COUNTIFS('System Inventory'!E5:E54,"Critical",'System Inventory'!L5:L54,"✅ PASS") | C25: By Criticality
A26: High Systems Total | B26: =COUNTIF('System Inventory'!E5:E54,"High") | C26: By Criticality
A27: High Systems Compliant | B27: =COUNTIFS('System Inventory'!E5:E54,"High",'System Inventory'!L5:L54,"✅ PASS") | C27: By Criticality
A28: Medium Systems Total | B28: =COUNTIF('System Inventory'!E5:E54,"Medium") | C28: By Criticality
A29: Medium Systems Compliant | B29: =COUNTIFS('System Inventory'!E5:E54,"Medium",'System Inventory'!L5:L54,"✅ PASS") | C29: By Criticality
A30: Server-Physical Count | B30: =COUNTIF('System Inventory'!C5:C54,"Server-Physical") | C30: By Type
A31: Server-Virtual Count | B31: =COUNTIF('System Inventory'!C5:C54,"Server-Virtual") | C31: By Type
A32: Server-Cloud Count | B32: =COUNTIF('System Inventory'!C5:C54,"Server-Cloud") | C32: By Type
A33: Network Device Count | B33: =COUNTIF('System Inventory'!C5:C54,"Network Device") | C33: By Type
A34: Security Appliance Count | B34: =COUNTIF('System Inventory'!C5:C54,"Security Appliance") | C34: By Type
A36: TABLE 3: CRITICAL FINDINGS — NON-COMPLIANT CRITICAL & HIGH SYSTEMS
A37: Assessment Area | B37: System Name | C37: Criticality | D37: Sync Status | E37: Drift (ms) | F37: Compliance | G37: Notes
A38: System Inventory — Critical | B38: =IFERROR(INDEX('System Inventory'!A$5:A$54,SMALL(IF(('System Inventory'!E$5:E$54="Critical")*('System Inventory'!L$5:L$54="❌ FAIL"),ROW('System Inventory'!A$5:A$54)-ROW('System Inventory'!A$5)+1),1)),"") | C38: =IFERROR(INDEX('System Inventory'!E$5:E$54,SMALL(IF(('System Inventory'!E$5:E$54="Critical")*('System Inventory'!L$5:L$54="❌ FAIL"),ROW('System Inventory'!A$5:A$54)-ROW('System Inventory'!A$5)+1),1)),"") | D38: =IFERROR(INDEX('System Inventory'!G$5:G$54,SMALL(IF(('System Inventory'!E$5:E$54="Critical")*('System Inventory'!L$5:L$54="❌ FAIL"),ROW('System Inventory'!A$5:A$54)-ROW('System Inventory'!A$5)+1),1)),"") | E38: =IFERROR(INDEX('System Inventory'!I$5:I$54,SMALL(IF(('System Inventory'!E$5:E$54="Critical")*('System Inventory'!L$5:L$54="❌ FAIL"),ROW('System Inventory'!A$5:A$54)-ROW('System Inventory'!A$5)+1),1)),"") | F38: =IFERROR(INDEX('System Inventory'!L$5:L$54,SMALL(IF(('System Inventory'!E$5:E$54="Critical")*('System Inventory'!L$5:L$54="❌ FAIL"),ROW('System Inventory'!A$5:A$54)-ROW('System Inventory'!A$5)+1),1)),"") | G38: =IFERROR(INDEX('System Inventory'!M$5:M$54,SMALL(IF(('System Inventory'!E$5:E$54="Critical")*('System Inventory'!L$5:L$54="❌ FAIL"),ROW('System Inventory'!A$5:A$54)-ROW('System Inventory'!A$5)+1),1)),"")
A39: System Inventory — Critical | B39: =IFERROR(INDEX('System Inventory'!A$5:A$54,SMALL(IF(('System Inventory'!E$5:E$54="Critical")*('System Inventory'!L$5:L$54="❌ FAIL"),ROW('System Inventory'!A$5:A$54)-ROW('System Inventory'!A$5)+1),2)),"") | C39: =IFERROR(INDEX('System Inventory'!E$5:E$54,SMALL(IF(('System Inventory'!E$5:E$54="Critical")*('System Inventory'!L$5:L$54="❌ FAIL"),ROW('System Inventory'!A$5:A$54)-ROW('System Inventory'!A$5)+1),2)),"") | D39: =IFERROR(INDEX('System Inventory'!G$5:G$54,SMALL(IF(('System Inventory'!E$5:E$54="Critical")*('System Inventory'!L$5:L$54="❌ FAIL"),ROW('System Inventory'!A$5:A$54)-ROW('System Inventory'!A$5)+1),2)),"") | E39: =IFERROR(INDEX('System Inventory'!I$5:I$54,SMALL(IF(('System Inventory'!E$5:E$54="Critical")*('System Inventory'!L$5:L$54="❌ FAIL"),ROW('System Inventory'!A$5:A$54)-ROW('System Inventory'!A$5)+1),2)),"") | F39: =IFERROR(INDEX('System Inventory'!L$5:L$54,SMALL(IF(('System Inventory'!E$5:E$54="Critical")*('System Inventory'!L$5:L$54="❌ FAIL"),ROW('System Inventory'!A$5:A$54)-ROW('System Inventory'!A$5)+1),2)),"") | G39: =IFERROR(INDEX('System Inventory'!M$5:M$54,SMALL(IF(('System Inventory'!E$5:E$54="Critical")*('System Inventory'!L$5:L$54="❌ FAIL"),ROW('System Inventory'!A$5:A$54)-ROW('System Inventory'!A$5)+1),2)),"")
A40: System Inventory — Critical | B40: =IFERROR(INDEX('System Inventory'!A$5:A$54,SMALL(IF(('System Inventory'!E$5:E$54="Critical")*('System Inventory'!L$5:L$54="❌ FAIL"),ROW('System Inventory'!A$5:A$54)-ROW('System Inventory'!A$5)+1),3)),"") | C40: =IFERROR(INDEX('System Inventory'!E$5:E$54,SMALL(IF(('System Inventory'!E$5:E$54="Critical")*('System Inventory'!L$5:L$54="❌ FAIL"),ROW('System Inventory'!A$5:A$54)-ROW('System Inventory'!A$5)+1),3)),"") | D40: =IFERROR(INDEX('System Inventory'!G$5:G$54,SMALL(IF(('System Inventory'!E$5:E$54="Critical")*('System Inventory'!L$5:L$54="❌ FAIL"),ROW('System Inventory'!A$5:A$54)-ROW('System Inventory'!A$5)+1),3)),"") | E40: =IFERROR(INDEX('System Inventory'!I$5:I$54,SMALL(IF(('System Inventory'!E$5:E$54="Critical")*('System Inventory'!L$5:L$54="❌ FAIL"),ROW('System Inventory'!A$5:A$54)-ROW('System Inventory'!A$5)+1),3)),"") | F40: =IFERROR(INDEX('System Inventory'!L$5:L$54,SMALL(IF(('System Inventory'!E$5:E$54="Critical")*('System Inventory'!L$5:L$54="❌ FAIL"),ROW('System Inventory'!A$5:A$54)-ROW('System Inventory'!A$5)+1),3)),"") | G40: =IFERROR(INDEX('System Inventory'!M$5:M$54,SMALL(IF(('System Inventory'!E$5:E$54="Critical")*('System Inventory'!L$5:L$54="❌ FAIL"),ROW('System Inventory'!A$5:A$54)-ROW('System Inventory'!A$5)+1),3)),"")
A41: System Inventory — Critical | B41: =IFERROR(INDEX('System Inventory'!A$5:A$54,SMALL(IF(('System Inventory'!E$5:E$54="Critical")*('System Inventory'!L$5:L$54="❌ FAIL"),ROW('System Inventory'!A$5:A$54)-ROW('System Inventory'!A$5)+1),4)),"") | C41: =IFERROR(INDEX('System Inventory'!E$5:E$54,SMALL(IF(('System Inventory'!E$5:E$54="Critical")*('System Inventory'!L$5:L$54="❌ FAIL"),ROW('System Inventory'!A$5:A$54)-ROW('System Inventory'!A$5)+1),4)),"") | D41: =IFERROR(INDEX('System Inventory'!G$5:G$54,SMALL(IF(('System Inventory'!E$5:E$54="Critical")*('System Inventory'!L$5:L$54="❌ FAIL"),ROW('System Inventory'!A$5:A$54)-ROW('System Inventory'!A$5)+1),4)),"") | E41: =IFERROR(INDEX('System Inventory'!I$5:I$54,SMALL(IF(('System Inventory'!E$5:E$54="Critical")*('System Inventory'!L$5:L$54="❌ FAIL"),ROW('System Inventory'!A$5:A$54)-ROW('System Inventory'!A$5)+1),4)),"") | F41: =IFERROR(INDEX('System Inventory'!L$5:L$54,SMALL(IF(('System Inventory'!E$5:E$54="Critical")*('System Inventory'!L$5:L$54="❌ FAIL"),ROW('System Inventory'!A$5:A$54)-ROW('System Inventory'!A$5)+1),4)),"") | G41: =IFERROR(INDEX('System Inventory'!M$5:M$54,SMALL(IF(('System Inventory'!E$5:E$54="Critical")*('System Inventory'!L$5:L$54="❌ FAIL"),ROW('System Inventory'!A$5:A$54)-ROW('System Inventory'!A$5)+1),4)),"")
A42: System Inventory — Critical | B42: =IFERROR(INDEX('System Inventory'!A$5:A$54,SMALL(IF(('System Inventory'!E$5:E$54="Critical")*('System Inventory'!L$5:L$54="❌ FAIL"),ROW('System Inventory'!A$5:A$54)-ROW('System Inventory'!A$5)+1),5)),"") | C42: =IFERROR(INDEX('System Inventory'!E$5:E$54,SMALL(IF(('System Inventory'!E$5:E$54="Critical")*('System Inventory'!L$5:L$54="❌ FAIL"),ROW('System Inventory'!A$5:A$54)-ROW('System Inventory'!A$5)+1),5)),"") | D42: =IFERROR(INDEX('System Inventory'!G$5:G$54,SMALL(IF(('System Inventory'!E$5:E$54="Critical")*('System Inventory'!L$5:L$54="❌ FAIL"),ROW('System Inventory'!A$5:A$54)-ROW('System Inventory'!A$5)+1),5)),"") | E42: =IFERROR(INDEX('System Inventory'!I$5:I$54,SMALL(IF(('System Inventory'!E$5:E$54="Critical")*('System Inventory'!L$5:L$54="❌ FAIL"),ROW('System Inventory'!A$5:A$54)-ROW('System Inventory'!A$5)+1),5)),"") | F42: =IFERROR(INDEX('System Inventory'!L$5:L$54,SMALL(IF(('System Inventory'!E$5:E$54="Critical")*('System Inventory'!L$5:L$54="❌ FAIL"),ROW('System Inventory'!A$5:A$54)-ROW('System Inventory'!A$5)+1),5)),"") | G42: =IFERROR(INDEX('System Inventory'!M$5:M$54,SMALL(IF(('System Inventory'!E$5:E$54="Critical")*('System Inventory'!L$5:L$54="❌ FAIL"),ROW('System Inventory'!A$5:A$54)-ROW('System Inventory'!A$5)+1),5)),"")
A43: System Inventory — High | B43: =IFERROR(INDEX('System Inventory'!A$5:A$54,SMALL(IF(('System Inventory'!E$5:E$54="High")*('System Inventory'!L$5:L$54="❌ FAIL"),ROW('System Inventory'!A$5:A$54)-ROW('System Inventory'!A$5)+1),1)),"") | C43: =IFERROR(INDEX('System Inventory'!E$5:E$54,SMALL(IF(('System Inventory'!E$5:E$54="High")*('System Inventory'!L$5:L$54="❌ FAIL"),ROW('System Inventory'!A$5:A$54)-ROW('System Inventory'!A$5)+1),1)),"") | D43: =IFERROR(INDEX('System Inventory'!G$5:G$54,SMALL(IF(('System Inventory'!E$5:E$54="High")*('System Inventory'!L$5:L$54="❌ FAIL"),ROW('System Inventory'!A$5:A$54)-ROW('System Inventory'!A$5)+1),1)),"") | E43: =IFERROR(INDEX('System Inventory'!I$5:I$54,SMALL(IF(('System Inventory'!E$5:E$54="High")*('System Inventory'!L$5:L$54="❌ FAIL"),ROW('System Inventory'!A$5:A$54)-ROW('System Inventory'!A$5)+1),1)),"") | F43: =IFERROR(INDEX('System Inventory'!L$5:L$54,SMALL(IF(('System Inventory'!E$5:E$54="High")*('System Inventory'!L$5:L$54="❌ FAIL"),ROW('System Inventory'!A$5:A$54)-ROW('System Inventory'!A$5)+1),1)),"") | G43: =IFERROR(INDEX('System Inventory'!M$5:M$54,SMALL(IF(('System Inventory'!E$5:E$54="High")*('System Inventory'!L$5:L$54="❌ FAIL"),ROW('System Inventory'!A$5:A$54)-ROW('System Inventory'!A$5)+1),1)),"")
...

Sheet Approval Sign-Off
A1: ASSESSMENT APPROVAL AND SIGN-OFF
A3: ASSESSMENT SUMMARY
A4: Document: | B4: ISMS-IMP-A.8.17.2 - Time Synchronisation Status Assessment
A5: Assessment Period:
A6: Overall Compliance: | B6: =IFERROR(AVERAGE('Summary Dashboard'!G6:G8),"")
A7: Assessment Status:
A10: COMPLETED BY (ASSESSOR)
A11: Name:
A12: Title:
A13: Date:
A14: Signature:
A15: Comments:
A17: REVIEWED BY (INFORMATION SECURITY OFFICER)
A18: Name:
A19: Title:
A20: Date:
A21: Signature:
... A37: Special Considerations:
