Workbook

Sheet Instructions & Legend
A1: ISMS-IMP-A.8.15.1 - Log Source Inventory Assessment ISO/IEC 27001:2022 - Control A.8.15: Logging
A4: Document ID: | B4: ISMS-IMP-A.8.15.1
A5: Assessment Area: | B5: Log Source Inventory and Completeness
A6: Related Policy: | B6: ISMS-POL-A.8.15-S2.1 (Event Logging Requirements)
A7: Version: | B7: 1.0
A8: Assessment Date: | B8: [USER INPUT - DD.MM.YYYY]
A9: Completed By: | B9: [USER INPUT]
A10: Organization: | B10: [USER INPUT]
A11: Review Cycle: | B11: Annual (full assessment), Quarterly (updates)
A14: HOW TO USE THIS WORKBOOK
A15: 1. Complete the 'System Inventory' sheet for all in-scope systems
A16: 2. For each system, document log sources and event types logged
A17: 3. Use dropdowns to ensure consistent data entry
A18: 4. Yellow cells require user input, gray cells are auto-calculated
A19: 5. Complete compliance checklist for each log source type
A20: 6. Review Summary Dashboard for overall compliance status
A21: 7. Document gaps in Gap Analysis sheet
A22: 8. Develop remediation plan for identified gaps
A23: 9. Obtain approvals in Approval & Sign-Off sheet
A26: LEGEND - CELL COLOR CODING
A27: Yellow (FFFFCC) | B27: User input required
A28: Green (C6EFCE) | B28: Compliant / Complete
A29: Red (FFC7CE) | B29: Non-compliant / Missing
A30: Gray (E7E6E6) | B30: Auto-calculated / Reference data
A31: Blue (4472C4) | B31: Instructions / Headers
A34: KEY DEFINITIONS
A35: Log Source | B35: Any system, application, or device generating event logs
A36: Event Type | B36: Category of logged activity (authentication, authorization, etc.)
A37: SIEM | B37: Security Information and Event Management system
A38: Hot Storage | B38: Real-time searchable log storage (0-90 days typical)
A39: Warm Storage | B39: Compressed, slower-access storage (91-365 days typical)
A40: Cold Storage | B40: Archive storage (>1 year)
A41: WORM | B41: Write-Once-Read-Many (immutable storage)
A42: Syslog | B42: Standard logging protocol (RFC 5424)
A43: CEF | B43: Common Event Format
A44: EVTX | B44: Windows Event Log format

Sheet System Inventory
A1: SYSTEM INVENTORY - Log Source Catalog
A2: Document all systems in scope for logging. Include servers, network devices, applications, cloud services, and security tools.
A7: System ID | B7: System Name | C7: System Type | D7: Operating System / Platform | E7: Environment | F7: Data Classification | G7: Business Criticality | H7: Regulatory Scope | I7: Logging Priority | J7: System Owner | K7: Owner Email | L7: Hostname / FQDN | M7: Primary IP | N7: Location | O7: Logging Enabled | P7: Forwarding to SIEM | Q7: Compliance Status
A8: SYS-001 | B8: web-prod-01 | C8: Server | D8: Linux | E8: Production | F8: Confidential | G8: Critical (T1) | H8: PCI DSS, GDPR | I8: P1-Critical | J8: John Doe | K8: jdoe@example.com | L8: web-prod-01.example.com | M8: 10.0.1.50 | N8: DC1 | O8: Yes | P8: Yes | Q8: Compliant
A9: =IF(B9<>"","SYS-"&TEXT(ROW()-8,"000"),"") | Q9: =IF(B9="","",IF(AND(O9="Yes",P9="Yes"),"Compliant",IF(OR(O9="Partial",P9="Planned"),"Partial","Non-Compliant")))
A10: =IF(B10<>"","SYS-"&TEXT(ROW()-8,"000"),"") | Q10: =IF(B10="","",IF(AND(O10="Yes",P10="Yes"),"Compliant",IF(OR(O10="Partial",P10="Planned"),"Partial","Non-Compliant")))
A11: =IF(B11<>"","SYS-"&TEXT(ROW()-8,"000"),"") | Q11: =IF(B11="","",IF(AND(O11="Yes",P11="Yes"),"Compliant",IF(OR(O11="Partial",P11="Planned"),"Partial","Non-Compliant")))
A12: =IF(B12<>"","SYS-"&TEXT(ROW()-8,"000"),"") | Q12: =IF(B12="","",IF(AND(O12="Yes",P12="Yes"),"Compliant",IF(OR(O12="Partial",P12="Planned"),"Partial","Non-Compliant")))
A13: =IF(B13<>"","SYS-"&TEXT(ROW()-8,"000"),"") | Q13: =IF(B13="","",IF(AND(O13="Yes",P13="Yes"),"Compliant",IF(OR(O13="Partial",P13="Planned"),"Partial","Non-Compliant")))
A14: =IF(B14<>"","SYS-"&TEXT(ROW()-8,"000"),"") | Q14: =IF(B14="","",IF(AND(O14="Yes",P14="Yes"),"Compliant",IF(OR(O14="Partial",P14="Planned"),"Partial","Non-Compliant")))
A15: =IF(B15<>"","SYS-"&TEXT(ROW()-8,"000"),"") | Q15: =IF(B15="","",IF(AND(O15="Yes",P15="Yes"),"Compliant",IF(OR(O15="Partial",P15="Planned"),"Partial","Non-Compliant")))
A16: =IF(B16<>"","SYS-"&TEXT(ROW()-8,"000"),"") | Q16: =IF(B16="","",IF(AND(O16="Yes",P16="Yes"),"Compliant",IF(OR(O16="Partial",P16="Planned"),"Partial","Non-Compliant")))
A17: =IF(B17<>"","SYS-"&TEXT(ROW()-8,"000"),"") | Q17: =IF(B17="","",IF(AND(O17="Yes",P17="Yes"),"Compliant",IF(OR(O17="Partial",P17="Planned"),"Partial","Non-Compliant")))
A18: =IF(B18<>"","SYS-"&TEXT(ROW()-8,"000"),"") | Q18: =IF(B18="","",IF(AND(O18="Yes",P18="Yes"),"Compliant",IF(OR(O18="Partial",P18="Planned"),"Partial","Non-Compliant")))
A19: =IF(B19<>"","SYS-"&TEXT(ROW()-8,"000"),"") | Q19: =IF(B19="","",IF(AND(O19="Yes",P19="Yes"),"Compliant",IF(OR(O19="Partial",P19="Planned"),"Partial","Non-Compliant")))
A20: =IF(B20<>"","SYS-"&TEXT(ROW()-8,"000"),"") | Q20: =IF(B20="","",IF(AND(O20="Yes",P20="Yes"),"Compliant",IF(OR(O20="Partial",P20="Planned"),"Partial","Non-Compliant")))
... A100: =IF(B100<>"","SYS-"&TEXT(ROW()-8,"000"),"") | Q100: =IF(B100="","",IF(AND(O100="Yes",P100="Yes"),"Compliant",IF(OR(O100="Partial",P100="Planned"),"Partial","Non-Compliant")))

Sheet Log Event Types by System
A1: LOG EVENT TYPES BY SYSTEM
A2: For each system, document which event types are logged. This assesses logging completeness per ISMS-POL-A.8.15-S2.1
A7: System ID | B7: System Name | C7: Authentication Events | D7: Authorization Events | E7: Administrative Actions | F7: Security Events | G7: Application Events | H7: System Events | I7: Network Events | J7: Database Events | K7: Log Format | L7: Timestamp Format | M7: Timezone | N7: Est. Daily Volume (MB) | O7: Retention Period (months) | P7: Storage Tier | Q7: Protection Mechanisms | R7: Event Types Completeness | S7: Notes
A8: SYS-001 | B8: web-prod-01 | C8: Yes | D8: Yes | E8: Yes | F8: Yes | G8: Yes | H8: Partial | I8: Partial | J8: N/A | K8: Syslog | L8: ISO 8601 | M8: UTC | N8: 150 | O8: 12 | P8: Hot | Q8: Access Controls, Encryption | R8: 87.5% | S8: Web server logs include app events
B9: =IF(A9="","",IFERROR(VLOOKUP(A9,'System Inventory'!A:B,2,FALSE),"Not Found")) | R9: =IF(A9="","",COUNTIF(C9:J9,"*Yes*")/COUNTA(C9:J9))
B10: =IF(A10="","",IFERROR(VLOOKUP(A10,'System Inventory'!A:B,2,FALSE),"Not Found")) | R10: =IF(A10="","",COUNTIF(C10:J10,"*Yes*")/COUNTA(C10:J10))
B11: =IF(A11="","",IFERROR(VLOOKUP(A11,'System Inventory'!A:B,2,FALSE),"Not Found")) | R11: =IF(A11="","",COUNTIF(C11:J11,"*Yes*")/COUNTA(C11:J11))
B12: =IF(A12="","",IFERROR(VLOOKUP(A12,'System Inventory'!A:B,2,FALSE),"Not Found")) | R12: =IF(A12="","",COUNTIF(C12:J12,"*Yes*")/COUNTA(C12:J12))
B13: =IF(A13="","",IFERROR(VLOOKUP(A13,'System Inventory'!A:B,2,FALSE),"Not Found")) | R13: =IF(A13="","",COUNTIF(C13:J13,"*Yes*")/COUNTA(C13:J13))
B14: =IF(A14="","",IFERROR(VLOOKUP(A14,'System Inventory'!A:B,2,FALSE),"Not Found")) | R14: =IF(A14="","",COUNTIF(C14:J14,"*Yes*")/COUNTA(C14:J14))
B15: =IF(A15="","",IFERROR(VLOOKUP(A15,'System Inventory'!A:B,2,FALSE),"Not Found")) | R15: =IF(A15="","",COUNTIF(C15:J15,"*Yes*")/COUNTA(C15:J15))
B16: =IF(A16="","",IFERROR(VLOOKUP(A16,'System Inventory'!A:B,2,FALSE),"Not Found")) | R16: =IF(A16="","",COUNTIF(C16:J16,"*Yes*")/COUNTA(C16:J16))
B17: =IF(A17="","",IFERROR(VLOOKUP(A17,'System Inventory'!A:B,2,FALSE),"Not Found")) | R17: =IF(A17="","",COUNTIF(C17:J17,"*Yes*")/COUNTA(C17:J17))
B18: =IF(A18="","",IFERROR(VLOOKUP(A18,'System Inventory'!A:B,2,FALSE),"Not Found")) | R18: =IF(A18="","",COUNTIF(C18:J18,"*Yes*")/COUNTA(C18:J18))
B19: =IF(A19="","",IFERROR(VLOOKUP(A19,'System Inventory'!A:B,2,FALSE),"Not Found")) | R19: =IF(A19="","",COUNTIF(C19:J19,"*Yes*")/COUNTA(C19:J19))
B20: =IF(A20="","",IFERROR(VLOOKUP(A20,'System Inventory'!A:B,2,FALSE),"Not Found")) | R20: =IF(A20="","",COUNTIF(C20:J20,"*Yes*")/COUNTA(C20:J20))
... B100: =IF(A100="","",IFERROR(VLOOKUP(A100,'System Inventory'!A:B,2,FALSE),"Not Found")) | R100: =IF(A100="","",COUNTIF(C100:J100,"*Yes*")/COUNTA(C100:J100))

Sheet Authentication Logging
A1: AUTHENTICATION LOGGING ASSESSMENT
A2: Assess authentication event logging completeness per ISMS-POL-A.8.15-S2.1.2
A4: Policy Requirement: ISMS-POL-A.8.15-S2.1.2 (Authentication Events)
A7: System ID | B7: System Name | C7: Logs Successful Logins | D7: Logs Failed Logins | E7: Logs Account Lockouts | F7: Logs Password Changes | G7: Logs Session Start/End | H7: Includes User ID | I7: Includes Timestamp | J7: Includes Source IP | K7: Includes Auth Method | L7: MFA Events Logged | M7: SSO Events Logged | N7: Service Account Auth | O7: Privileged Auth Logged | P7: Compliance Score | Q7: Gap Description | R7: Remediation Plan
A8: SYS-001 | B8: web-prod-01 | C8: Yes | D8: Yes | E8: Yes | F8: Yes | G8: Yes | H8: Yes | I8: Yes | J8: Yes | K8: Yes | L8: Yes | M8: Yes | N8: N/A | O8: Yes | P8: 100.0%
B9: =IF(A9="","",IFERROR(VLOOKUP(A9,'System Inventory'!A:B,2,FALSE),"Not Found")) | P9: =IF(A9="","",(COUNTIF(C9:M9,"*Yes*")/COUNTIF(C9:M9,"<>N/A"))*100)
B10: =IF(A10="","",IFERROR(VLOOKUP(A10,'System Inventory'!A:B,2,FALSE),"Not Found")) | P10: =IF(A10="","",(COUNTIF(C10:M10,"*Yes*")/COUNTIF(C10:M10,"<>N/A"))*100)
B11: =IF(A11="","",IFERROR(VLOOKUP(A11,'System Inventory'!A:B,2,FALSE),"Not Found")) | P11: =IF(A11="","",(COUNTIF(C11:M11,"*Yes*")/COUNTIF(C11:M11,"<>N/A"))*100)
B12: =IF(A12="","",IFERROR(VLOOKUP(A12,'System Inventory'!A:B,2,FALSE),"Not Found")) | P12: =IF(A12="","",(COUNTIF(C12:M12,"*Yes*")/COUNTIF(C12:M12,"<>N/A"))*100)
B13: =IF(A13="","",IFERROR(VLOOKUP(A13,'System Inventory'!A:B,2,FALSE),"Not Found")) | P13: =IF(A13="","",(COUNTIF(C13:M13,"*Yes*")/COUNTIF(C13:M13,"<>N/A"))*100)
B14: =IF(A14="","",IFERROR(VLOOKUP(A14,'System Inventory'!A:B,2,FALSE),"Not Found")) | P14: =IF(A14="","",(COUNTIF(C14:M14,"*Yes*")/COUNTIF(C14:M14,"<>N/A"))*100)
B15: =IF(A15="","",IFERROR(VLOOKUP(A15,'System Inventory'!A:B,2,FALSE),"Not Found")) | P15: =IF(A15="","",(COUNTIF(C15:M15,"*Yes*")/COUNTIF(C15:M15,"<>N/A"))*100)
B16: =IF(A16="","",IFERROR(VLOOKUP(A16,'System Inventory'!A:B,2,FALSE),"Not Found")) | P16: =IF(A16="","",(COUNTIF(C16:M16,"*Yes*")/COUNTIF(C16:M16,"<>N/A"))*100)
B17: =IF(A17="","",IFERROR(VLOOKUP(A17,'System Inventory'!A:B,2,FALSE),"Not Found")) | P17: =IF(A17="","",(COUNTIF(C17:M17,"*Yes*")/COUNTIF(C17:M17,"<>N/A"))*100)
B18: =IF(A18="","",IFERROR(VLOOKUP(A18,'System Inventory'!A:B,2,FALSE),"Not Found")) | P18: =IF(A18="","",(COUNTIF(C18:M18,"*Yes*")/COUNTIF(C18:M18,"<>N/A"))*100)
B19: =IF(A19="","",IFERROR(VLOOKUP(A19,'System Inventory'!A:B,2,FALSE),"Not Found")) | P19: =IF(A19="","",(COUNTIF(C19:M19,"*Yes*")/COUNTIF(C19:M19,"<>N/A"))*100)
B20: =IF(A20="","",IFERROR(VLOOKUP(A20,'System Inventory'!A:B,2,FALSE),"Not Found")) | P20: =IF(A20="","",(COUNTIF(C20:M20,"*Yes*")/COUNTIF(C20:M20,"<>N/A"))*100)
... B100: =IF(A100="","",IFERROR(VLOOKUP(A100,'System Inventory'!A:B,2,FALSE),"Not Found")) | P100: =IF(A100="","",(COUNTIF(C100:M100,"*Yes*")/COUNTIF(C100:M100,"<>N/A"))*100)

Sheet Authorization & Access
A1: AUTHORIZATION & ACCESS LOGGING ASSESSMENT
A2: Assess access control event logging per ISMS-POL-A.8.15-S2.1.3
A4: Policy Requirement: ISMS-POL-A.8.15-S2.1.3 (Authorization Events)
A7: System ID | B7: System Name | C7: Logs Access Grants | D7: Logs Access Denials | E7: Logs Permission Changes | F7: Logs Privilege Escalation | G7: Logs Data Access (Sensitive) | H7: Includes User ID | I7: Includes Resource Accessed | J7: Includes Action Type | K7: Includes Outcome | L7: Includes Reason (denied) | M7: Includes Before/After State | N7: Logs Group Membership | O7: Logs Role Assignment | P7: Compliance Score | Q7: Gap Description | R7: Remediation Plan
A8: SYS-001 | B8: web-prod-01 | C8: Yes | D8: Yes | E8: Yes | F8: Yes | G8: Yes | H8: Yes | I8: Yes | J8: Yes | K8: Yes | L8: Partial | M8: Partial | N8: Yes | O8: Yes | P8: 92.3% | Q8: Before/After state partially logged | R8: Enhance logging
B9: =IF(A9="","",IFERROR(VLOOKUP(A9,'System Inventory'!A:B,2,FALSE),"Not Found")) | P9: =IF(A9="","",(COUNTIF(C9:M9,"*Yes*")/COUNTIF(C9:M9,"<>N/A"))*100)
B10: =IF(A10="","",IFERROR(VLOOKUP(A10,'System Inventory'!A:B,2,FALSE),"Not Found")) | P10: =IF(A10="","",(COUNTIF(C10:M10,"*Yes*")/COUNTIF(C10:M10,"<>N/A"))*100)
B11: =IF(A11="","",IFERROR(VLOOKUP(A11,'System Inventory'!A:B,2,FALSE),"Not Found")) | P11: =IF(A11="","",(COUNTIF(C11:M11,"*Yes*")/COUNTIF(C11:M11,"<>N/A"))*100)
B12: =IF(A12="","",IFERROR(VLOOKUP(A12,'System Inventory'!A:B,2,FALSE),"Not Found")) | P12: =IF(A12="","",(COUNTIF(C12:M12,"*Yes*")/COUNTIF(C12:M12,"<>N/A"))*100)
B13: =IF(A13="","",IFERROR(VLOOKUP(A13,'System Inventory'!A:B,2,FALSE),"Not Found")) | P13: =IF(A13="","",(COUNTIF(C13:M13,"*Yes*")/COUNTIF(C13:M13,"<>N/A"))*100)
B14: =IF(A14="","",IFERROR(VLOOKUP(A14,'System Inventory'!A:B,2,FALSE),"Not Found")) | P14: =IF(A14="","",(COUNTIF(C14:M14,"*Yes*")/COUNTIF(C14:M14,"<>N/A"))*100)
B15: =IF(A15="","",IFERROR(VLOOKUP(A15,'System Inventory'!A:B,2,FALSE),"Not Found")) | P15: =IF(A15="","",(COUNTIF(C15:M15,"*Yes*")/COUNTIF(C15:M15,"<>N/A"))*100)
B16: =IF(A16="","",IFERROR(VLOOKUP(A16,'System Inventory'!A:B,2,FALSE),"Not Found")) | P16: =IF(A16="","",(COUNTIF(C16:M16,"*Yes*")/COUNTIF(C16:M16,"<>N/A"))*100)
B17: =IF(A17="","",IFERROR(VLOOKUP(A17,'System Inventory'!A:B,2,FALSE),"Not Found")) | P17: =IF(A17="","",(COUNTIF(C17:M17,"*Yes*")/COUNTIF(C17:M17,"<>N/A"))*100)
B18: =IF(A18="","",IFERROR(VLOOKUP(A18,'System Inventory'!A:B,2,FALSE),"Not Found")) | P18: =IF(A18="","",(COUNTIF(C18:M18,"*Yes*")/COUNTIF(C18:M18,"<>N/A"))*100)
B19: =IF(A19="","",IFERROR(VLOOKUP(A19,'System Inventory'!A:B,2,FALSE),"Not Found")) | P19: =IF(A19="","",(COUNTIF(C19:M19,"*Yes*")/COUNTIF(C19:M19,"<>N/A"))*100)
B20: =IF(A20="","",IFERROR(VLOOKUP(A20,'System Inventory'!A:B,2,FALSE),"Not Found")) | P20: =IF(A20="","",(COUNTIF(C20:M20,"*Yes*")/COUNTIF(C20:M20,"<>N/A"))*100)
... B100: =IF(A100="","",IFERROR(VLOOKUP(A100,'System Inventory'!A:B,2,FALSE),"Not Found")) | P100: =IF(A100="","",(COUNTIF(C100:M100,"*Yes*")/COUNTIF(C100:M100,"<>N/A"))*100)

Sheet Administrative Activity
A1: ADMINISTRATIVE ACTIVITY LOGGING ASSESSMENT
A2: Assess administrative action logging per ISMS-POL-A.8.15-S2.1.4
A4: Policy Requirement: ISMS-POL-A.8.15-S2.1.4 (Administrative Actions)
A7: System ID | B7: System Name | C7: User Account Management | D7: Group/Role Management | E7: Configuration Changes | F7: Security Policy Changes | G7: Software Install/Uninstall | H7: Service Start/Stop | I7: Patch Application | J7: Bulk Data Operations | K7: Privileged Session Logging | L7: Includes Administrator ID | M7: Includes Before/After Values | N7: Includes Timestamp | O7: Includes Change Reason | P7: Compliance Score | Q7: Gap Description | R7: Remediation Plan
A8: SYS-001 | B8: web-prod-01 | C8: Yes | D8: Yes | E8: Yes | F8: Yes | G8: Partial | H8: Yes | I8: Partial | J8: No | K8: Yes | L8: Yes | M8: Partial | N8: Yes | O8: No | P8: 76.9% | Q8: Change reason not logged, bulk ops not logged | R8: Implement change logging
B9: =IF(A9="","",IFERROR(VLOOKUP(A9,'System Inventory'!A:B,2,FALSE),"Not Found")) | P9: =IF(A9="","",(COUNTIF(C9:M9,"*Yes*")/COUNTIF(C9:M9,"<>N/A"))*100)
B10: =IF(A10="","",IFERROR(VLOOKUP(A10,'System Inventory'!A:B,2,FALSE),"Not Found")) | P10: =IF(A10="","",(COUNTIF(C10:M10,"*Yes*")/COUNTIF(C10:M10,"<>N/A"))*100)
B11: =IF(A11="","",IFERROR(VLOOKUP(A11,'System Inventory'!A:B,2,FALSE),"Not Found")) | P11: =IF(A11="","",(COUNTIF(C11:M11,"*Yes*")/COUNTIF(C11:M11,"<>N/A"))*100)
B12: =IF(A12="","",IFERROR(VLOOKUP(A12,'System Inventory'!A:B,2,FALSE),"Not Found")) | P12: =IF(A12="","",(COUNTIF(C12:M12,"*Yes*")/COUNTIF(C12:M12,"<>N/A"))*100)
B13: =IF(A13="","",IFERROR(VLOOKUP(A13,'System Inventory'!A:B,2,FALSE),"Not Found")) | P13: =IF(A13="","",(COUNTIF(C13:M13,"*Yes*")/COUNTIF(C13:M13,"<>N/A"))*100)
B14: =IF(A14="","",IFERROR(VLOOKUP(A14,'System Inventory'!A:B,2,FALSE),"Not Found")) | P14: =IF(A14="","",(COUNTIF(C14:M14,"*Yes*")/COUNTIF(C14:M14,"<>N/A"))*100)
B15: =IF(A15="","",IFERROR(VLOOKUP(A15,'System Inventory'!A:B,2,FALSE),"Not Found")) | P15: =IF(A15="","",(COUNTIF(C15:M15,"*Yes*")/COUNTIF(C15:M15,"<>N/A"))*100)
B16: =IF(A16="","",IFERROR(VLOOKUP(A16,'System Inventory'!A:B,2,FALSE),"Not Found")) | P16: =IF(A16="","",(COUNTIF(C16:M16,"*Yes*")/COUNTIF(C16:M16,"<>N/A"))*100)
B17: =IF(A17="","",IFERROR(VLOOKUP(A17,'System Inventory'!A:B,2,FALSE),"Not Found")) | P17: =IF(A17="","",(COUNTIF(C17:M17,"*Yes*")/COUNTIF(C17:M17,"<>N/A"))*100)
B18: =IF(A18="","",IFERROR(VLOOKUP(A18,'System Inventory'!A:B,2,FALSE),"Not Found")) | P18: =IF(A18="","",(COUNTIF(C18:M18,"*Yes*")/COUNTIF(C18:M18,"<>N/A"))*100)
B19: =IF(A19="","",IFERROR(VLOOKUP(A19,'System Inventory'!A:B,2,FALSE),"Not Found")) | P19: =IF(A19="","",(COUNTIF(C19:M19,"*Yes*")/COUNTIF(C19:M19,"<>N/A"))*100)
B20: =IF(A20="","",IFERROR(VLOOKUP(A20,'System Inventory'!A:B,2,FALSE),"Not Found")) | P20: =IF(A20="","",(COUNTIF(C20:M20,"*Yes*")/COUNTIF(C20:M20,"<>N/A"))*100)
... B100: =IF(A100="","",IFERROR(VLOOKUP(A100,'System Inventory'!A:B,2,FALSE),"Not Found")) | P100: =IF(A100="","",(COUNTIF(C100:M100,"*Yes*")/COUNTIF(C100:M100,"<>N/A"))*100)

Sheet Security Event Logging
A1: SECURITY EVENT LOGGING ASSESSMENT
A2: Assess security tool and event logging per ISMS-POL-A.8.15-S2.1.5
A4: Policy Requirement: ISMS-POL-A.8.15-S2.1.5 (Security Events)
A7: System ID | B7: System Name | C7: Firewall Events | D7: IDS/IPS Alerts | E7: Anti-malware Events | F7: DLP Events | G7: Web Filtering Events | H7: Email Gateway Events | I7: EDR Events | J7: Vulnerability Scan Results | K7: Security Incident Events | L7: Includes Severity Level | M7: Includes Threat Indicators | N7: Includes Response Actions | O7: Automated Response Logged | P7: Compliance Score | Q7: Gap Description | R7: Remediation Plan
A8: FW-001 | B8: perimeter-fw-01 | C8: Yes | D8: Yes | E8: N/A | F8: N/A | G8: N/A | H8: N/A | I8: N/A | J8: N/A | K8: Yes | L8: Yes | M8: Yes | N8: Partial | O8: No | P8: 100.0% | Q8: Automated response not logged | R8: Enable response logging
B9: =IF(A9="","",IFERROR(VLOOKUP(A9,'System Inventory'!A:B,2,FALSE),"Not Found")) | P9: =IF(A9="","",(COUNTIF(C9:M9,"*Yes*")/COUNTIF(C9:M9,"<>N/A"))*100)
B10: =IF(A10="","",IFERROR(VLOOKUP(A10,'System Inventory'!A:B,2,FALSE),"Not Found")) | P10: =IF(A10="","",(COUNTIF(C10:M10,"*Yes*")/COUNTIF(C10:M10,"<>N/A"))*100)
B11: =IF(A11="","",IFERROR(VLOOKUP(A11,'System Inventory'!A:B,2,FALSE),"Not Found")) | P11: =IF(A11="","",(COUNTIF(C11:M11,"*Yes*")/COUNTIF(C11:M11,"<>N/A"))*100)
B12: =IF(A12="","",IFERROR(VLOOKUP(A12,'System Inventory'!A:B,2,FALSE),"Not Found")) | P12: =IF(A12="","",(COUNTIF(C12:M12,"*Yes*")/COUNTIF(C12:M12,"<>N/A"))*100)
B13: =IF(A13="","",IFERROR(VLOOKUP(A13,'System Inventory'!A:B,2,FALSE),"Not Found")) | P13: =IF(A13="","",(COUNTIF(C13:M13,"*Yes*")/COUNTIF(C13:M13,"<>N/A"))*100)
B14: =IF(A14="","",IFERROR(VLOOKUP(A14,'System Inventory'!A:B,2,FALSE),"Not Found")) | P14: =IF(A14="","",(COUNTIF(C14:M14,"*Yes*")/COUNTIF(C14:M14,"<>N/A"))*100)
B15: =IF(A15="","",IFERROR(VLOOKUP(A15,'System Inventory'!A:B,2,FALSE),"Not Found")) | P15: =IF(A15="","",(COUNTIF(C15:M15,"*Yes*")/COUNTIF(C15:M15,"<>N/A"))*100)
B16: =IF(A16="","",IFERROR(VLOOKUP(A16,'System Inventory'!A:B,2,FALSE),"Not Found")) | P16: =IF(A16="","",(COUNTIF(C16:M16,"*Yes*")/COUNTIF(C16:M16,"<>N/A"))*100)
B17: =IF(A17="","",IFERROR(VLOOKUP(A17,'System Inventory'!A:B,2,FALSE),"Not Found")) | P17: =IF(A17="","",(COUNTIF(C17:M17,"*Yes*")/COUNTIF(C17:M17,"<>N/A"))*100)
B18: =IF(A18="","",IFERROR(VLOOKUP(A18,'System Inventory'!A:B,2,FALSE),"Not Found")) | P18: =IF(A18="","",(COUNTIF(C18:M18,"*Yes*")/COUNTIF(C18:M18,"<>N/A"))*100)
B19: =IF(A19="","",IFERROR(VLOOKUP(A19,'System Inventory'!A:B,2,FALSE),"Not Found")) | P19: =IF(A19="","",(COUNTIF(C19:M19,"*Yes*")/COUNTIF(C19:M19,"<>N/A"))*100)
B20: =IF(A20="","",IFERROR(VLOOKUP(A20,'System Inventory'!A:B,2,FALSE),"Not Found")) | P20: =IF(A20="","",(COUNTIF(C20:M20,"*Yes*")/COUNTIF(C20:M20,"<>N/A"))*100)
... B100: =IF(A100="","",IFERROR(VLOOKUP(A100,'System Inventory'!A:B,2,FALSE),"Not Found")) | P100: =IF(A100="","",(COUNTIF(C100:M100,"*Yes*")/COUNTIF(C100:M100,"<>N/A"))*100)

Sheet Application & Database
A1: APPLICATION & DATABASE LOGGING ASSESSMENT
A2: Assess application and database logging per ISMS-POL-A.8.15-S2.1.7
A4: Policy Requirement: ISMS-POL-A.8.15-S2.1.7 (Application & Database Events)
A7: System ID | B7: System Name | C7: Web App Access Logging | D7: API Call Logging | E7: Transaction Logging | F7: Application Errors | G7: Database Connections | H7: Database Queries (Sensitive) | I7: Schema Changes (DDL) | J7: Permission Grants | K7: Backup/Restore Operations | L7: Includes User/App Identity | M7: Includes Data Modified | N7: Includes Query Text | O7: Includes Row Count | P7: Compliance Score | Q7: Gap Description | R7: Remediation Plan
A8: DB-001 | B8: prod-db-01 | C8: N/A | D8: Yes | E8: Yes | F8: Yes | G8: Yes | H8: Yes | I8: Yes | J8: Yes | K8: Yes | L8: Yes | M8: Partial | N8: Partial | O8: Yes | P8: 91.7% | Q8: Query text truncated, data modified partially logged | R8: Enable full query logging
B9: =IF(A9="","",IFERROR(VLOOKUP(A9,'System Inventory'!A:B,2,FALSE),"Not Found")) | P9: =IF(A9="","",(COUNTIF(C9:M9,"*Yes*")/COUNTIF(C9:M9,"<>N/A"))*100)
B10: =IF(A10="","",IFERROR(VLOOKUP(A10,'System Inventory'!A:B,2,FALSE),"Not Found")) | P10: =IF(A10="","",(COUNTIF(C10:M10,"*Yes*")/COUNTIF(C10:M10,"<>N/A"))*100)
B11: =IF(A11="","",IFERROR(VLOOKUP(A11,'System Inventory'!A:B,2,FALSE),"Not Found")) | P11: =IF(A11="","",(COUNTIF(C11:M11,"*Yes*")/COUNTIF(C11:M11,"<>N/A"))*100)
B12: =IF(A12="","",IFERROR(VLOOKUP(A12,'System Inventory'!A:B,2,FALSE),"Not Found")) | P12: =IF(A12="","",(COUNTIF(C12:M12,"*Yes*")/COUNTIF(C12:M12,"<>N/A"))*100)
B13: =IF(A13="","",IFERROR(VLOOKUP(A13,'System Inventory'!A:B,2,FALSE),"Not Found")) | P13: =IF(A13="","",(COUNTIF(C13:M13,"*Yes*")/COUNTIF(C13:M13,"<>N/A"))*100)
B14: =IF(A14="","",IFERROR(VLOOKUP(A14,'System Inventory'!A:B,2,FALSE),"Not Found")) | P14: =IF(A14="","",(COUNTIF(C14:M14,"*Yes*")/COUNTIF(C14:M14,"<>N/A"))*100)
B15: =IF(A15="","",IFERROR(VLOOKUP(A15,'System Inventory'!A:B,2,FALSE),"Not Found")) | P15: =IF(A15="","",(COUNTIF(C15:M15,"*Yes*")/COUNTIF(C15:M15,"<>N/A"))*100)
B16: =IF(A16="","",IFERROR(VLOOKUP(A16,'System Inventory'!A:B,2,FALSE),"Not Found")) | P16: =IF(A16="","",(COUNTIF(C16:M16,"*Yes*")/COUNTIF(C16:M16,"<>N/A"))*100)
B17: =IF(A17="","",IFERROR(VLOOKUP(A17,'System Inventory'!A:B,2,FALSE),"Not Found")) | P17: =IF(A17="","",(COUNTIF(C17:M17,"*Yes*")/COUNTIF(C17:M17,"<>N/A"))*100)
B18: =IF(A18="","",IFERROR(VLOOKUP(A18,'System Inventory'!A:B,2,FALSE),"Not Found")) | P18: =IF(A18="","",(COUNTIF(C18:M18,"*Yes*")/COUNTIF(C18:M18,"<>N/A"))*100)
B19: =IF(A19="","",IFERROR(VLOOKUP(A19,'System Inventory'!A:B,2,FALSE),"Not Found")) | P19: =IF(A19="","",(COUNTIF(C19:M19,"*Yes*")/COUNTIF(C19:M19,"<>N/A"))*100)
B20: =IF(A20="","",IFERROR(VLOOKUP(A20,'System Inventory'!A:B,2,FALSE),"Not Found")) | P20: =IF(A20="","",(COUNTIF(C20:M20,"*Yes*")/COUNTIF(C20:M20,"<>N/A"))*100)
... B100: =IF(A100="","",IFERROR(VLOOKUP(A100,'System Inventory'!A:B,2,FALSE),"Not Found")) | P100: =IF(A100="","",(COUNTIF(C100:M100,"*Yes*")/COUNTIF(C100:M100,"<>N/A"))*100)

Sheet Network Device Logging
A1: NETWORK DEVICE LOGGING ASSESSMENT
A2: Assess network infrastructure logging per ISMS-POL-A.8.15-S2.1.8
A4: Policy Requirement: ISMS-POL-A.8.15-S2.1.8 (Network Events)
A7: Device ID | B7: Device Name | C7: Connection Logging | D7: Rule Match Logging | E7: Configuration Changes | F7: Interface Up/Down Events | G7: Routing Changes | H7: VPN Session Logging | I7: DHCP/DNS Events | J7: Wireless Events | K7: NAT Translations | L7: Includes Source/Dest IP | M7: Includes Ports/Protocols | N7: Includes Action (allow/deny) | O7: Includes Bytes Transferred | P7: Compliance Score | Q7: Gap Description | R7: Remediation Plan
A8: NET-001 | B8: core-switch-01 | C8: Yes | D8: Yes | E8: Yes | F8: Yes | G8: Yes | H8: N/A | I8: Yes | J8: N/A | K8: N/A | L8: Yes | M8: Yes | N8: Yes | O8: No | P8: 100.0% | Q8: Bytes transferred not logged | R8: Enable traffic volume logging
B9: =IF(A9="","",IFERROR(VLOOKUP(A9,'System Inventory'!A:B,2,FALSE),"Not Found")) | P9: =IF(A9="","",(COUNTIF(C9:M9,"*Yes*")/COUNTIF(C9:M9,"<>N/A"))*100)
B10: =IF(A10="","",IFERROR(VLOOKUP(A10,'System Inventory'!A:B,2,FALSE),"Not Found")) | P10: =IF(A10="","",(COUNTIF(C10:M10,"*Yes*")/COUNTIF(C10:M10,"<>N/A"))*100)
B11: =IF(A11="","",IFERROR(VLOOKUP(A11,'System Inventory'!A:B,2,FALSE),"Not Found")) | P11: =IF(A11="","",(COUNTIF(C11:M11,"*Yes*")/COUNTIF(C11:M11,"<>N/A"))*100)
B12: =IF(A12="","",IFERROR(VLOOKUP(A12,'System Inventory'!A:B,2,FALSE),"Not Found")) | P12: =IF(A12="","",(COUNTIF(C12:M12,"*Yes*")/COUNTIF(C12:M12,"<>N/A"))*100)
B13: =IF(A13="","",IFERROR(VLOOKUP(A13,'System Inventory'!A:B,2,FALSE),"Not Found")) | P13: =IF(A13="","",(COUNTIF(C13:M13,"*Yes*")/COUNTIF(C13:M13,"<>N/A"))*100)
B14: =IF(A14="","",IFERROR(VLOOKUP(A14,'System Inventory'!A:B,2,FALSE),"Not Found")) | P14: =IF(A14="","",(COUNTIF(C14:M14,"*Yes*")/COUNTIF(C14:M14,"<>N/A"))*100)
B15: =IF(A15="","",IFERROR(VLOOKUP(A15,'System Inventory'!A:B,2,FALSE),"Not Found")) | P15: =IF(A15="","",(COUNTIF(C15:M15,"*Yes*")/COUNTIF(C15:M15,"<>N/A"))*100)
B16: =IF(A16="","",IFERROR(VLOOKUP(A16,'System Inventory'!A:B,2,FALSE),"Not Found")) | P16: =IF(A16="","",(COUNTIF(C16:M16,"*Yes*")/COUNTIF(C16:M16,"<>N/A"))*100)
B17: =IF(A17="","",IFERROR(VLOOKUP(A17,'System Inventory'!A:B,2,FALSE),"Not Found")) | P17: =IF(A17="","",(COUNTIF(C17:M17,"*Yes*")/COUNTIF(C17:M17,"<>N/A"))*100)
B18: =IF(A18="","",IFERROR(VLOOKUP(A18,'System Inventory'!A:B,2,FALSE),"Not Found")) | P18: =IF(A18="","",(COUNTIF(C18:M18,"*Yes*")/COUNTIF(C18:M18,"<>N/A"))*100)
B19: =IF(A19="","",IFERROR(VLOOKUP(A19,'System Inventory'!A:B,2,FALSE),"Not Found")) | P19: =IF(A19="","",(COUNTIF(C19:M19,"*Yes*")/COUNTIF(C19:M19,"<>N/A"))*100)
B20: =IF(A20="","",IFERROR(VLOOKUP(A20,'System Inventory'!A:B,2,FALSE),"Not Found")) | P20: =IF(A20="","",(COUNTIF(C20:M20,"*Yes*")/COUNTIF(C20:M20,"<>N/A"))*100)
... B100: =IF(A100="","",IFERROR(VLOOKUP(A100,'System Inventory'!A:B,2,FALSE),"Not Found")) | P100: =IF(A100="","",(COUNTIF(C100:M100,"*Yes*")/COUNTIF(C100:M100,"<>N/A"))*100)

Sheet Gap Analysis
A1: GAP ANALYSIS - CONSOLIDATED FINDINGS
A2: Document all identified gaps from assessment sheets. Prioritize by risk and establish remediation plans with clear ownership and target dates.
A7: Gap ID | B7: System ID | C7: System Name | D7: Gap Category | E7: Gap Description | F7: Policy Requirement | G7: Impact / Risk | H7: Remediation Action | I7: Responsible Party | J7: Target Date | K7: Status | L7: Notes
A8: GAP-001 | B8: SYS-042 | C8: mail-server-01 | D8: Event Type Not Logged | E8: Failed authentication attempts not logged | F8: ISMS-POL-A.8.15-S2.1.2 | G8: High | H8: Configure mail server to log authentication failures | I8: System Admin Team | J8: 31.03.2026 | K8: Open | L8: Vendor support required for config change
A9: =IF(B9<>"","GAP-"&TEXT(ROW()-8,"000"),"") | C9: =IF(B9="","",IFERROR(VLOOKUP(B9,'System Inventory'!A:B,2,FALSE),"Not Found"))
A10: =IF(B10<>"","GAP-"&TEXT(ROW()-8,"000"),"") | C10: =IF(B10="","",IFERROR(VLOOKUP(B10,'System Inventory'!A:B,2,FALSE),"Not Found"))
A11: =IF(B11<>"","GAP-"&TEXT(ROW()-8,"000"),"") | C11: =IF(B11="","",IFERROR(VLOOKUP(B11,'System Inventory'!A:B,2,FALSE),"Not Found"))
A12: =IF(B12<>"","GAP-"&TEXT(ROW()-8,"000"),"") | C12: =IF(B12="","",IFERROR(VLOOKUP(B12,'System Inventory'!A:B,2,FALSE),"Not Found"))
A13: =IF(B13<>"","GAP-"&TEXT(ROW()-8,"000"),"") | C13: =IF(B13="","",IFERROR(VLOOKUP(B13,'System Inventory'!A:B,2,FALSE),"Not Found"))
A14: =IF(B14<>"","GAP-"&TEXT(ROW()-8,"000"),"") | C14: =IF(B14="","",IFERROR(VLOOKUP(B14,'System Inventory'!A:B,2,FALSE),"Not Found"))
A15: =IF(B15<>"","GAP-"&TEXT(ROW()-8,"000"),"") | C15: =IF(B15="","",IFERROR(VLOOKUP(B15,'System Inventory'!A:B,2,FALSE),"Not Found"))
A16: =IF(B16<>"","GAP-"&TEXT(ROW()-8,"000"),"") | C16: =IF(B16="","",IFERROR(VLOOKUP(B16,'System Inventory'!A:B,2,FALSE),"Not Found"))
A17: =IF(B17<>"","GAP-"&TEXT(ROW()-8,"000"),"") | C17: =IF(B17="","",IFERROR(VLOOKUP(B17,'System Inventory'!A:B,2,FALSE),"Not Found"))
A18: =IF(B18<>"","GAP-"&TEXT(ROW()-8,"000"),"") | C18: =IF(B18="","",IFERROR(VLOOKUP(B18,'System Inventory'!A:B,2,FALSE),"Not Found"))
A19: =IF(B19<>"","GAP-"&TEXT(ROW()-8,"000"),"") | C19: =IF(B19="","",IFERROR(VLOOKUP(B19,'System Inventory'!A:B,2,FALSE),"Not Found"))
A20: =IF(B20<>"","GAP-"&TEXT(ROW()-8,"000"),"") | C20: =IF(B20="","",IFERROR(VLOOKUP(B20,'System Inventory'!A:B,2,FALSE),"Not Found"))
... A100: =IF(B100<>"","GAP-"&TEXT(ROW()-8,"000"),"") | C100: =IF(B100="","",IFERROR(VLOOKUP(B100,'System Inventory'!A:B,2,FALSE),"Not Found"))
A105: GAP SUMMARY STATISTICS
A107: Total Gaps Identified: | B107: =COUNTA(A9:A100)
A108: Open Gaps: | B108: =COUNTIF(K9:K100,"*Open*")
A109: In Progress: | B109: =COUNTIF(K9:K100,"*In Progress*")
A110: Resolved: | B110: =COUNTIF(K9:K100,"*Resolved*")
A111: Critical Priority: | B111: =COUNTIF(G9:G100,"*Critical*")
A112: High Priority: | B112: =COUNTIF(G9:G100,"*High*")
A113: Overdue (Past Target Date): | B113: =SUMPRODUCT((K9:K100<>"Resolved")*(J9:J100<TODAY())*(J9:J100<>""))

Sheet Evidence Register
A1: EVIDENCE REGISTER
A2: Register all evidence artifacts collected during assessment. Include log samples, screenshots, configurations, and documentation.
A7: Evidence ID | B7: Evidence Type | C7: Description | D7: Related System(s) | E7: Related Policy Req | F7: File Name / Location | G7: Collected By | H7: Collection Date | I7: Retention Period | J7: Notes
A8: EVD-001 | B8: Log Sample | C8: Authentication log sample from web server | D8: SYS-001 (web-prod-01) | E8: S2.1.2 | F8: auth_logs_sample_20260106.txt | G8: SOC Analyst | H8: 06.01.2026 | I8: 3 years | J8: Sample covers 24h period
A9: =IF(B9<>"","EVD-"&TEXT(ROW()-8,"000"),"")
A10: =IF(B10<>"","EVD-"&TEXT(ROW()-8,"000"),"")
A11: =IF(B11<>"","EVD-"&TEXT(ROW()-8,"000"),"")
A12: =IF(B12<>"","EVD-"&TEXT(ROW()-8,"000"),"")
A13: =IF(B13<>"","EVD-"&TEXT(ROW()-8,"000"),"")
A14: =IF(B14<>"","EVD-"&TEXT(ROW()-8,"000"),"")
A15: =IF(B15<>"","EVD-"&TEXT(ROW()-8,"000"),"")
A16: =IF(B16<>"","EVD-"&TEXT(ROW()-8,"000"),"")
A17: =IF(B17<>"","EVD-"&TEXT(ROW()-8,"000"),"")
A18: =IF(B18<>"","EVD-"&TEXT(ROW()-8,"000"),"")
A19: =IF(B19<>"","EVD-"&TEXT(ROW()-8,"000"),"")
A20: =IF(B20<>"","EVD-"&TEXT(ROW()-8,"000"),"")
... A108: =IF(B108<>"","EVD-"&TEXT(ROW()-8,"000"),"")

Sheet Summary Dashboard
A1: LOGGING COMPLIANCE DASHBOARD
A2: Executive Summary - ISO/IEC 27001:2022 Control A.8.15
A4: 1. OVERALL COMPLIANCE SUMMARY
A6: Metric | B6: Value | C6: Target | D6: Status
A7: Total Systems Assessed | B7: =COUNTA('System Inventory'!B9:B100) | C7: N/A | D7: =IF(B7>0,"✓","✗")
A8: Systems with Logging Enabled | B8: =COUNTIF('System Inventory'!O:O,"Yes") | C8: 100% | D8: =IF(B8>0,"✓","✗")
A9: Systems Forwarding to SIEM | B9: =COUNTIF('System Inventory'!P:P,"Yes") | C9: 100% | D9: =IF(B9>0,"✓","✗")
A10: Overall Compliance Rate | B10: =AVERAGE('Authentication Logging'!P9:P100,'Authorization & Access'!P9:P100,'Administrative Activity'!P9:P100,'Security Event Logging'!P9:P100,'Application & Database'!P9:P100,'Network Device Logging'!P9:P100) | C10: >95% | D10: =IF(B10>=95%,"✓ Met","✗ Not Met")
A11: Critical Systems Compliant (P1) | B11: =COUNTIFS('System Inventory'!I:I,"P1-Critical",'System Inventory'!Q:Q,"Compliant")/COUNTIF('System Inventory'!I:I,"P1-Critical") | C11: 100% | D11: =IF(B11>=00%,"✓ Met","✗ Not Met")
A12: High Systems Compliant (P2) | B12: =COUNTIFS('System Inventory'!I:I,"P2-High",'System Inventory'!Q:Q,"Compliant")/COUNTIF('System Inventory'!I:I,"P2-High") | C12: >95% | D12: =IF(B12>=95%,"✓ Met","✗ Not Met")
A13: Medium Systems Compliant (P3) | B13: =COUNTIFS('System Inventory'!I:I,"P3-Medium",'System Inventory'!Q:Q,"Compliant")/COUNTIF('System Inventory'!I:I,"P3-Medium") | C13: >90% | D13: =IF(B13>=90%,"✓ Met","✗ Not Met")
A16: 2. EVENT TYPE COVERAGE
A18: Event Type | B18: Systems Logging | C18: % Coverage | D18: Target | E18: Status
A19: Authentication | B19: =COUNTIF('Log Event Types by System'!C:C,"Yes") | C19: =B19/COUNTA('System Inventory'!B9:B100) | D19: >95% | E19: =IF(C19>=95%,"✓ Met","✗ Not Met")
A20: Authorization | B20: =COUNTIF('Log Event Types by System'!D:D,"Yes") | C20: =B20/COUNTA('System Inventory'!B9:B100) | D20: >95% | E20: =IF(C20>=95%,"✓ Met","✗ Not Met")
A21: Administrative | B21: =COUNTIF('Log Event Types by System'!E:E,"Yes") | C21: =B21/COUNTA('System Inventory'!B9:B100) | D21: >95% | E21: =IF(C21>=95%,"✓ Met","✗ Not Met")
A22: Security Events | B22: =COUNTIF('Log Event Types by System'!F:F,"Yes") | C22: =B22/COUNTA('System Inventory'!B9:B100) | D22: 100% | E22: =IF(C22>=00%,"✓ Met","✗ Not Met")
A23: Application | B23: =COUNTIF('Log Event Types by System'!G:G,"Yes") | C23: =B23/COUNTA('System Inventory'!B9:B100) | D23: >90% | E23: =IF(C23>=90%,"✓ Met","✗ Not Met")
A24: System | B24: =COUNTIF('Log Event Types by System'!H:H,"Yes") | C24: =B24/COUNTA('System Inventory'!B9:B100) | D24: >85% | E24: =IF(C24>=85%,"✓ Met","✗ Not Met")
A25: Network | B25: =COUNTIF('Log Event Types by System'!I:I,"Yes") | C25: =B25/COUNTA('System Inventory'!B9:B100) | D25: >85% | E25: =IF(C25>=85%,"✓ Met","✗ Not Met")
A26: Database | B26: =COUNTIF('Log Event Types by System'!J:J,"Yes") | C26: =B26/COUNTA('System Inventory'!B9:B100) | D26: >90% | E26: =IF(C26>=90%,"✓ Met","✗ Not Met")
A30: 3. GAP SUMMARY BY PRIORITY
A32: Priority | B32: Open Gaps | C32: In Progress | D32: Resolved | E32: Overdue | F32: % Complete
A33: Critical | B33: =COUNTIFS('Gap Analysis'!G:G,"*Critical*",'Gap Analysis'!K:K,"*Open*") | C33: =COUNTIFS('Gap Analysis'!G:G,"*Critical*",'Gap Analysis'!K:K,"*In Progress*") | D33: =COUNTIFS('Gap Analysis'!G:G,"*Critical*",'Gap Analysis'!K:K,"*Resolved*") | E33: =SUMPRODUCT((ISNUMBER(SEARCH("*Critical*",'Gap Analysis'!G:G)))*((ISNUMBER(SEARCH("*Open*",'Gap Analysis'!K:K)))+(ISNUMBER(SEARCH("*In Progress*",'Gap Analysis'!K:K))))*('Gap Analysis'!J:J<TODAY())*('Gap Analysis'!J:J<>"")) | F33: =IF((B33+C33+D33)=0,0,D33/(B33+C33+D33))
A34: High | B34: =COUNTIFS('Gap Analysis'!G:G,"*High*",'Gap Analysis'!K:K,"*Open*") | C34: =COUNTIFS('Gap Analysis'!G:G,"*High*",'Gap Analysis'!K:K,"*In Progress*") | D34: =COUNTIFS('Gap Analysis'!G:G,"*High*",'Gap Analysis'!K:K,"*Resolved*") | E34: =SUMPRODUCT((ISNUMBER(SEARCH("*High*",'Gap Analysis'!G:G)))*((ISNUMBER(SEARCH("*Open*",'Gap Analysis'!K:K)))+(ISNUMBER(SEARCH("*In Progress*",'Gap Analysis'!K:K))))*('Gap Analysis'!J:J<TODAY())*('Gap Analysis'!J:J<>"")) | F34: =IF((B34+C34+D34)=0,0,D34/(B34+C34+D34))
A35: Medium | B35: =COUNTIFS('Gap Analysis'!G:G,"*Medium*",'Gap Analysis'!K:K,"*Open*") | C35: =COUNTIFS('Gap Analysis'!G:G,"*Medium*",'Gap Analysis'!K:K,"*In Progress*") | D35: =COUNTIFS('Gap Analysis'!G:G,"*Medium*",'Gap Analysis'!K:K,"*Resolved*") | E35: =SUMPRODUCT((ISNUMBER(SEARCH("*Medium*",'Gap Analysis'!G:G)))*((ISNUMBER(SEARCH("*Open*",'Gap Analysis'!K:K)))+(ISNUMBER(SEARCH("*In Progress*",'Gap Analysis'!K:K))))*('Gap Analysis'!J:J<TODAY())*('Gap Analysis'!J:J<>"")) | F35: =IF((B35+C35+D35)=0,0,D35/(B35+C35+D35))
A36: Low | B36: =COUNTIFS('Gap Analysis'!G:G,"*Low*",'Gap Analysis'!K:K,"*Open*") | C36: =COUNTIFS('Gap Analysis'!G:G,"*Low*",'Gap Analysis'!K:K,"*In Progress*") | D36: =COUNTIFS('Gap Analysis'!G:G,"*Low*",'Gap Analysis'!K:K,"*Resolved*") | E36: =SUMPRODUCT((ISNUMBER(SEARCH("*Low*",'Gap Analysis'!G:G)))*((ISNUMBER(SEARCH("*Open*",'Gap Analysis'!K:K)))+(ISNUMBER(SEARCH("*In Progress*",'Gap Analysis'!K:K))))*('Gap Analysis'!J:J<TODAY())*('Gap Analysis'!J:J<>"")) | F36: =IF((B36+C36+D36)=0,0,D36/(B36+C36+D36))
A37: TOTAL | B37: =SUM(B33:B36) | C37: =SUM(C33:C36) | D37: =SUM(D33:D36) | E37: =SUM(E33:E36) | F37: =IF((B37+C37+D37)=0,0,D37/(B37+C37+D37))
A40: 4. TOP GAPS REQUIRING ATTENTION
A41: Top 10 gaps sorted by priority (Critical first) and target date (most overdue first)
A42: Gap ID | B42: System | C42: Description | D42: Priority | E42: Target Date | F42: Status
A43: Note: Manually copy top 10 gaps from Gap Analysis sheet after sorting by Priority (desc) and Target Date (asc)
A55: 5. RECOMMENDATIONS
A57: 1. IMMEDIATE ACTIONS (Critical Gaps):
A58: • Address all Critical priority gaps within 30 days
A59: • Implement logging on all P1-Critical systems showing non-compliant status
A60: • Enable SIEM forwarding for security event sources
A62: 2. SHORT-TERM IMPROVEMENTS (30-90 days):
A63: • Standardize log formats across similar system types
A64: • Implement centralized authentication logging for all applications
...

Sheet Approval & Sign-Off
A1: APPROVAL & SIGN-OFF
A2: Multi-level approval workflow for Log Source Inventory Assessment
A4: APPROVAL WORKFLOW
A6: Role | B6: Name | C6: Date | D6: Signature | E6: Status
A7: System Owners (collective) | B7: [List names] | D7: _____ | E7: ☐ Reviewed
A8: Log Administrator | B8: [Name] | D8: _____ | E8: ☐ Reviewed
A9: SOC Lead | B9: [Name] | D9: _____ | E9: ☐ Reviewed
A10: Information Security Manager | B10: [Name] | D10: _____ | E10: ☐ Approved
A11: CISO | B11: [Name] | D11: _____ | E11: ☐ Approved
A14: ACKNOWLEDGMENTS CHECKLIST
A16: ☐ Assessment completed per ISMS-POL-A.8.15-S2.1
A17: ☐ All in-scope systems documented in System Inventory
A18: ☐ Event type logging assessed for all systems
A19: ☐ Gaps identified and prioritized
A20: ☐ Remediation plan established with target dates
A21: ☐ Resources committed for gap remediation
A22: ☐ Evidence artifacts collected and registered
A23: ☐ Next assessment date scheduled
A24: ☐ Stakeholders informed of findings
A25: ☐ Dashboard reviewed with management
A28: APPROVAL COMMENTS / CONDITIONS
