Workbook

Sheet Executive Summary
A1: ISMS-OP-CHK-A.5.37 — Documented Operating Procedures Compliance Checklist
A3: DOCUMENT INFORMATION
A4: Document ID | B4: ISMS-OP-CHK-A.5.37
A5: Source Policy | B5: ISMS-OP-POL-A.5.37
A6: ISO Controls | B6: Documented Operating Procedures
A7: Generated | B7: 08.02.2026
A8: Prepared By
A9: Organisation
A10: Review Cycle | B10: Annual
A12: OVERALL COMPLIANCE STATUS
A13: Overall Compliance | B13: ='Dashboard'!G12
A14: Status | B14: =IF(Dashboard!G12="N/A","NOT ASSESSED",IF(ISNUMBER(VALUE(SUBSTITUTE(Dashboard!G12,"%",""))),IF(VALUE(SUBSTITUTE(Dashboard!G12,"%",""))>=90,"GREEN",IF(VALUE(SUBSTITUTE(Dashboard!G12,"%",""))>=70,"AMBER","RED")),"NOT ASSESSED"))
A16: KEY METRICS
A17: Total Requirements | B17: ='Dashboard'!B12
A18: Compliant | B18: ='Dashboard'!C12
A19: Partial | B19: ='Dashboard'!D12
A20: Non-Compliant | B20: ='Dashboard'!E12
A21: Not Applicable | B21: ='Dashboard'!F12
A22: Owner Coverage | B22: =IF(Dashboard!B12=0,"N/A",ROUND((COUNTA('Mandatory Documented Procedures'!F4:F4)+COUNTA('Creating and Updating Procs'!F4:F5)+COUNTA('Document Storage and Avail'!F4:F7)+COUNTA('Version Control and Approval'!F4:F6)+COUNTA('Procedure Review and Maint'!F4:F6)+COUNTA('Procedure Documentation Metrics'!F4:F5)+COUNTA('Records Management'!F4:F9)+COUNTA('Training and Competence'!F4:F8))/Dashboard!B12*100,0)&"%")
A24: DOMAIN STATUS SUMMARY
A25: Domain | B25: Compliance % | C25: Compliant | D25: Gaps | E25: Status
A26: Mandatory Documented Procedures | B26: ='Dashboard'!G4 | C26: ='Dashboard'!C4 | D26: ='Dashboard'!E4 | E26: =IF(Dashboard!G4="N/A","--",IF(ISNUMBER(VALUE(SUBSTITUTE(Dashboard!G4,"%",""))),IF(VALUE(SUBSTITUTE(Dashboard!G4,"%",""))>=90,"PASS",IF(VALUE(SUBSTITUTE(Dashboard!G4,"%",""))>=70,"REVIEW","FAIL")),"--"))
A27: Creating and Updating Procs | B27: ='Dashboard'!G5 | C27: ='Dashboard'!C5 | D27: ='Dashboard'!E5 | E27: =IF(Dashboard!G5="N/A","--",IF(ISNUMBER(VALUE(SUBSTITUTE(Dashboard!G5,"%",""))),IF(VALUE(SUBSTITUTE(Dashboard!G5,"%",""))>=90,"PASS",IF(VALUE(SUBSTITUTE(Dashboard!G5,"%",""))>=70,"REVIEW","FAIL")),"--"))
A28: Document Storage and Avail | B28: ='Dashboard'!G6 | C28: ='Dashboard'!C6 | D28: ='Dashboard'!E6 | E28: =IF(Dashboard!G6="N/A","--",IF(ISNUMBER(VALUE(SUBSTITUTE(Dashboard!G6,"%",""))),IF(VALUE(SUBSTITUTE(Dashboard!G6,"%",""))>=90,"PASS",IF(VALUE(SUBSTITUTE(Dashboard!G6,"%",""))>=70,"REVIEW","FAIL")),"--"))
A29: Version Control and Approval | B29: ='Dashboard'!G7 | C29: ='Dashboard'!C7 | D29: ='Dashboard'!E7 | E29: =IF(Dashboard!G7="N/A","--",IF(ISNUMBER(VALUE(SUBSTITUTE(Dashboard!G7,"%",""))),IF(VALUE(SUBSTITUTE(Dashboard!G7,"%",""))>=90,"PASS",IF(VALUE(SUBSTITUTE(Dashboard!G7,"%",""))>=70,"REVIEW","FAIL")),"--"))
A30: Procedure Review and Maint | B30: ='Dashboard'!G8 | C30: ='Dashboard'!C8 | D30: ='Dashboard'!E8 | E30: =IF(Dashboard!G8="N/A","--",IF(ISNUMBER(VALUE(SUBSTITUTE(Dashboard!G8,"%",""))),IF(VALUE(SUBSTITUTE(Dashboard!G8,"%",""))>=90,"PASS",IF(VALUE(SUBSTITUTE(Dashboard!G8,"%",""))>=70,"REVIEW","FAIL")),"--"))
A31: Procedure Documentation Metrics | B31: ='Dashboard'!G9 | C31: ='Dashboard'!C9 | D31: ='Dashboard'!E9 | E31: =IF(Dashboard!G9="N/A","--",IF(ISNUMBER(VALUE(SUBSTITUTE(Dashboard!G9,"%",""))),IF(VALUE(SUBSTITUTE(Dashboard!G9,"%",""))>=90,"PASS",IF(VALUE(SUBSTITUTE(Dashboard!G9,"%",""))>=70,"REVIEW","FAIL")),"--"))
A32: Records Management | B32: ='Dashboard'!G10 | C32: ='Dashboard'!C10 | D32: ='Dashboard'!E10 | E32: =IF(Dashboard!G10="N/A","--",IF(ISNUMBER(VALUE(SUBSTITUTE(Dashboard!G10,"%",""))),IF(VALUE(SUBSTITUTE(Dashboard!G10,"%",""))>=90,"PASS",IF(VALUE(SUBSTITUTE(Dashboard!G10,"%",""))>=70,"REVIEW","FAIL")),"--"))
A33: Training and Competence | B33: ='Dashboard'!G11 | C33: ='Dashboard'!C11 | D33: ='Dashboard'!E11 | E33: =IF(Dashboard!G11="N/A","--",IF(ISNUMBER(VALUE(SUBSTITUTE(Dashboard!G11,"%",""))),IF(VALUE(SUBSTITUTE(Dashboard!G11,"%",""))>=90,"PASS",IF(VALUE(SUBSTITUTE(Dashboard!G11,"%",""))>=70,"REVIEW","FAIL")),"--"))
A35: CRITICAL ISSUES
A36: # | B36: Issue Description | C36: Domain | D36: Owner | E36: Due Date
A37: 1
A38: 2
A39: 3
A40: 4
A41: 5
A43: MANAGEMENT COMMENTARY
A44: [Enter management commentary on documented operating procedures posture]
A48: APPROVAL
A49: Assessed By
...

Sheet Dashboard
A1: Documented Operating Procedures — Compliance Dashboard
A3: Domain | B3: Total Reqs | C3: Compliant | D3: Partial | E3: Non-Compliant | F3: N/A | G3: Compliance %
A4: Mandatory Documented Procedures | B4: =COUNTA('Mandatory Documented Procedures'!D4:D4) | C4: =COUNTIF('Mandatory Documented Procedures'!D4:D4,"Compliant") | D4: =COUNTIF('Mandatory Documented Procedures'!D4:D4,"Partial") | E4: =COUNTIF('Mandatory Documented Procedures'!D4:D4,"Non-Compliant") | F4: =COUNTIF('Mandatory Documented Procedures'!D4:D4,"N/A") | G4: =IF((B4-F4)=0,"N/A",ROUND(C4/(B4-F4)*100,1)&"%")
A5: Creating and Updating Procs | B5: =COUNTA('Creating and Updating Procs'!D4:D5) | C5: =COUNTIF('Creating and Updating Procs'!D4:D5,"Compliant") | D5: =COUNTIF('Creating and Updating Procs'!D4:D5,"Partial") | E5: =COUNTIF('Creating and Updating Procs'!D4:D5,"Non-Compliant") | F5: =COUNTIF('Creating and Updating Procs'!D4:D5,"N/A") | G5: =IF((B5-F5)=0,"N/A",ROUND(C5/(B5-F5)*100,1)&"%")
A6: Document Storage and Avail | B6: =COUNTA('Document Storage and Avail'!D4:D7) | C6: =COUNTIF('Document Storage and Avail'!D4:D7,"Compliant") | D6: =COUNTIF('Document Storage and Avail'!D4:D7,"Partial") | E6: =COUNTIF('Document Storage and Avail'!D4:D7,"Non-Compliant") | F6: =COUNTIF('Document Storage and Avail'!D4:D7,"N/A") | G6: =IF((B6-F6)=0,"N/A",ROUND(C6/(B6-F6)*100,1)&"%")
A7: Version Control and Approval | B7: =COUNTA('Version Control and Approval'!D4:D6) | C7: =COUNTIF('Version Control and Approval'!D4:D6,"Compliant") | D7: =COUNTIF('Version Control and Approval'!D4:D6,"Partial") | E7: =COUNTIF('Version Control and Approval'!D4:D6,"Non-Compliant") | F7: =COUNTIF('Version Control and Approval'!D4:D6,"N/A") | G7: =IF((B7-F7)=0,"N/A",ROUND(C7/(B7-F7)*100,1)&"%")
A8: Procedure Review and Maint | B8: =COUNTA('Procedure Review and Maint'!D4:D6) | C8: =COUNTIF('Procedure Review and Maint'!D4:D6,"Compliant") | D8: =COUNTIF('Procedure Review and Maint'!D4:D6,"Partial") | E8: =COUNTIF('Procedure Review and Maint'!D4:D6,"Non-Compliant") | F8: =COUNTIF('Procedure Review and Maint'!D4:D6,"N/A") | G8: =IF((B8-F8)=0,"N/A",ROUND(C8/(B8-F8)*100,1)&"%")
A9: Procedure Documentation Metrics | B9: =COUNTA('Procedure Documentation Metrics'!D4:D5) | C9: =COUNTIF('Procedure Documentation Metrics'!D4:D5,"Compliant") | D9: =COUNTIF('Procedure Documentation Metrics'!D4:D5,"Partial") | E9: =COUNTIF('Procedure Documentation Metrics'!D4:D5,"Non-Compliant") | F9: =COUNTIF('Procedure Documentation Metrics'!D4:D5,"N/A") | G9: =IF((B9-F9)=0,"N/A",ROUND(C9/(B9-F9)*100,1)&"%")
A10: Records Management | B10: =COUNTA('Records Management'!D4:D9) | C10: =COUNTIF('Records Management'!D4:D9,"Compliant") | D10: =COUNTIF('Records Management'!D4:D9,"Partial") | E10: =COUNTIF('Records Management'!D4:D9,"Non-Compliant") | F10: =COUNTIF('Records Management'!D4:D9,"N/A") | G10: =IF((B10-F10)=0,"N/A",ROUND(C10/(B10-F10)*100,1)&"%")
A11: Training and Competence | B11: =COUNTA('Training and Competence'!D4:D8) | C11: =COUNTIF('Training and Competence'!D4:D8,"Compliant") | D11: =COUNTIF('Training and Competence'!D4:D8,"Partial") | E11: =COUNTIF('Training and Competence'!D4:D8,"Non-Compliant") | F11: =COUNTIF('Training and Competence'!D4:D8,"N/A") | G11: =IF((B11-F11)=0,"N/A",ROUND(C11/(B11-F11)*100,1)&"%")
A12: TOTAL | B12: =SUM(B4:B11) | C12: =SUM(C4:C11) | D12: =SUM(D4:D11) | E12: =SUM(E4:E11) | F12: =SUM(F4:F11) | G12: =IF((B12-F12)=0,"N/A",ROUND(C12/(B12-F12)*100,1)&"%")
A14: COMPLIANCE BY STATUS
A15: Compliant | B15: =C12 | C15: =IF(B12=0,"",ROUND(B15/B12*100,1)&"%")
A16: Partial | B16: =D12 | C16: =IF(B12=0,"",ROUND(B16/B12*100,1)&"%")
A17: Non-Compliant | B17: =E12 | C17: =IF(B12=0,"",ROUND(B17/B12*100,1)&"%")
A18: N/A | B18: =F12 | C18: =IF(B12=0,"",ROUND(B18/B12*100,1)&"%")
A20: TOP GAPS (Manual Entry)
A21: Priority | B21: Domain | C21: Requirement | D21: Owner | E21: Due Date | F21: Status
A33: COMPLIANCE TREND (Manual Entry)
A34: Assessment Date | B34: Overall % | C34: Compliant | D34: Gaps | E34: Assessor | F34: Notes

Sheet Mandatory Documented Procedures
A1: Mandatory Documented Procedures — Compliance Checklist
A2: ISO/IEC 27001:2022 — Control A.5.37: Documented Operating Procedures
A3: Req # | B3: Section | C3: Requirement | D3: Status | E3: Evidence | F3: Owner | G3: Due Date | H3: Notes
A4: A.5.37-01 | B4: Document Operating Procedures For The | C4: The organisation shall document operating procedures for the following categories:.

Sheet Creating and Updating Procs
A1: Creating and Updating Procs — Compliance Checklist
A2: ISO/IEC 27001:2022 — Control A.5.37: Documented Operating Procedures
A3: Req # | B3: Section | C3: Requirement | D3: Status | E3: Evidence | F3: Owner | G3: Due Date | H3: Notes
A4: A.5.37-02 | B4: Operating Procedures | C4: All operating procedures shall include the following mandatory elements:.
A5: A.5.37-03 | B5: Be Created In Electronic Format Using | C5: Procedures shall be created in electronic format using standard, supported office applications or native operational systems. The organisation shall ensure appropriate identification and description (title, date, author, reference number), consistent format (language, software version, graphics), and review and approval for suitability and adequacy.

Sheet Document Storage and Avail
A1: Document Storage and Avail — Compliance Checklist
A2: ISO/IEC 27001:2022 — Control A.5.37: Documented Operating Procedures
A3: Req # | B3: Section | C3: Requirement | D3: Status | E3: Evidence | F3: Owner | G3: Due Date | H3: Notes
A4: A.5.37-04 | B4: Be Stored In The Organisation'S Document | C4: Procedures shall be stored in the organisation's document management system: [Specify: SharePoint, Confluence, Notion, or equivalent].
A5: A.5.37-05 | B5: For Critical Services, The Organisation | C5: For critical services, the organisation shall maintain an offline pack containing, at minimum:.
A6: A.5.37-06 | B6: Be Verified Quarterly With A Recorded | C6: Currency shall be verified quarterly with a recorded checklist confirming version alignment with the authoritative repository.
A7: A.5.37-07 | B7: Annual Audit*: During Annual Internal | C7: Annual audit*: During annual internal audit, the offline pack shall be opened and verified against the authoritative repository (100% version match required).

Sheet Version Control and Approval
A1: Version Control and Approval — Compliance Checklist
A2: ISO/IEC 27001:2022 — Control A.5.37: Documented Operating Procedures
A3: Req # | B3: Section | C3: Requirement | D3: Status | E3: Evidence | F3: Owner | G3: Due Date | H3: Notes
A4: A.5.37-08 | B4: Only The Latest Approved Version | C4: Only the latest approved version shall be presented to users.
A5: A.5.37-09 | B5: Previous Versions | C5: Previous versions shall be archived (not deleted) for audit trail.
A6: A.5.37-10 | B6: Be Notified To Affected Personnel | C6: Updates shall be notified to affected personnel.

Sheet Procedure Review and Maint
A1: Procedure Review and Maint — Compliance Checklist
A2: ISO/IEC 27001:2022 — Control A.5.37: Documented Operating Procedures
A3: Req # | B3: Section | C3: Requirement | D3: Status | E3: Evidence | F3: Owner | G3: Due Date | H3: Notes
A4: A.5.37-11 | B4: Personnel Using Procedures | C4: Personnel using procedures shall report:.
A5: A.5.37-12 | B5: Critical Procedures | C5: Critical procedures shall be tested at defined intervals:.
A6: A.5.37-13 | B6: Be Documented | C6: Testing shall be documented, including: test date and participants, test scenario, results (success/partial/failure), issues identified, and remediation actions.

Sheet Procedure Documentation Metrics
A1: Procedure Documentation Metrics — Compliance Checklist
A2: ISO/IEC 27001:2022 — Control A.5.37: Documented Operating Procedures
A3: Req # | B3: Section | C3: Requirement | D3: Status | E3: Evidence | F3: Owner | G3: Due Date | H3: Notes
A4: A.5.37-14 | B4: Track The Following Procedure | C4: The organisation shall track the following procedure documentation metrics:.
A5: A.5.37-15 | B5: Metrics Breaching Targets | C5: Metrics breaching targets shall be escalated to the CISO and reported at the next Management Review.

Sheet Records Management
A1: Records Management — Compliance Checklist
A2: ISO/IEC 27001:2022 — Control A.5.37: Documented Operating Procedures
A3: Req # | B3: Section | C3: Requirement | D3: Status | E3: Evidence | F3: Owner | G3: Due Date | H3: Notes
A4: A.5.37-16 | B4: Obsolete Documents And Records | C4: Obsolete documents and records shall be archived in line with data retention requirements:.
A5: A.5.37-17 | B5: Obsolete Documents And Records That Are | C5: Obsolete documents and records that are not required for audit and/or legal and regulatory purposes shall be securely deleted per the Information Classification and Handling Policy within 90 days of obsolescence determination.
A6: A.5.37-18 | B6: Documented Information Of External | C6: Documented information of external origin determined by the organisation to be necessary for the planning and operation of the Information Security Management System shall be identified and controlled (e.g., ISO standards, vendor documentation, regulatory guidance).
A7: A.5.37-19 | B7: No Editing: External Documents | C7: No editing: External documents shall not be modified; annotations or summaries created as separate internal documents.
A8: A.5.37-20 | B8: Be Classified In Line With The | C8: Documents shall be classified in line with the Information Classification and Handling Policy.
A9: A.5.37-21 | B9: Classified Procedures | C9: Classified procedures shall be handled, stored, and transmitted according to their classification level. Confidential procedures shall have restricted access (role-based, need-to-know).

Sheet Training and Competence
A1: Training and Competence — Compliance Checklist
A2: ISO/IEC 27001:2022 — Control A.5.37: Documented Operating Procedures
A3: Req # | B3: Section | C3: Requirement | D3: Status | E3: Evidence | F3: Owner | G3: Due Date | H3: Notes
A4: A.5.37-22 | B4: Be Trained On Relevant Procedures Before | C4: Personnel shall be trained on relevant procedures before performing them independently.
A5: A.5.37-23 | B5: Training Records | C5: Training records shall be maintained.
A6: A.5.37-24 | B6: Be Verified Through Observation, | C6: Competence shall be verified through observation, assessment, or supervisor sign-off.
A7: A.5.37-25 | B7: Refresher Training | C7: Refresher training shall be provided when procedures are significantly updated.
A8: A.5.37-26 | B8: Cross-Training | C8: Cross-training shall be implemented for critical procedures to avoid single points of failure.
