Workbook

Sheet Executive Summary
A1: PRIV-CHK-A.1.4.2-5 — Data Minimisation Compliance Checklist
A3: DOCUMENT INFORMATION
A4: Document ID | B4: PRIV-CHK-A.1.4.2-5
A5: Source Policy | B5: PRIV-POL-A.1.4.2-5
A6: ISO Controls | B6: Data Minimisation
A7: Generated | B7: 10.03.2026
A8: Prepared By
A9: Organisation
A10: Review Cycle | B10: Annual
A12: OVERALL COMPLIANCE STATUS
A13: Overall Compliance | B13: ='Dashboard'!G8
A14: Status | B14: =IF(Dashboard!G8="N/A","NOT ASSESSED",IF(ISNUMBER(VALUE(SUBSTITUTE(Dashboard!G8,"%",""))),IF(VALUE(SUBSTITUTE(Dashboard!G8,"%",""))>=90,"GREEN",IF(VALUE(SUBSTITUTE(Dashboard!G8,"%",""))>=70,"AMBER","RED")),"NOT ASSESSED"))
A16: KEY METRICS
A17: Total Requirements | B17: ='Dashboard'!B8
A18: Compliant | B18: ='Dashboard'!C8
A19: Partial | B19: ='Dashboard'!D8
A20: Non-Compliant | B20: ='Dashboard'!E8
A21: Not Applicable | B21: ='Dashboard'!F8
A22: Owner Coverage | B22: =IF(Dashboard!B8=0,"N/A",ROUND((COUNTA('Limit Collection'!F4:F7)+COUNTA('Limit Processing'!F4:F7)+COUNTA('Accuracy and Quality'!F4:F8)+COUNTA('Minimisation Objectives'!F4:F7))/Dashboard!B8*100,0)&"%")
A24: DOMAIN STATUS SUMMARY
A25: Domain | B25: Compliance % | C25: Compliant | D25: Gaps | E25: Status
A26: Limit Collection | B26: ='Dashboard'!G4 | C26: ='Dashboard'!C4 | D26: ='Dashboard'!E4 | E26: =IF(Dashboard!G4="N/A","--",IF(ISNUMBER(VALUE(SUBSTITUTE(Dashboard!G4,"%",""))),IF(VALUE(SUBSTITUTE(Dashboard!G4,"%",""))>=90,"PASS",IF(VALUE(SUBSTITUTE(Dashboard!G4,"%",""))>=70,"REVIEW","FAIL")),"--"))
A27: Limit Processing | B27: ='Dashboard'!G5 | C27: ='Dashboard'!C5 | D27: ='Dashboard'!E5 | E27: =IF(Dashboard!G5="N/A","--",IF(ISNUMBER(VALUE(SUBSTITUTE(Dashboard!G5,"%",""))),IF(VALUE(SUBSTITUTE(Dashboard!G5,"%",""))>=90,"PASS",IF(VALUE(SUBSTITUTE(Dashboard!G5,"%",""))>=70,"REVIEW","FAIL")),"--"))
A28: Accuracy and Quality | B28: ='Dashboard'!G6 | C28: ='Dashboard'!C6 | D28: ='Dashboard'!E6 | E28: =IF(Dashboard!G6="N/A","--",IF(ISNUMBER(VALUE(SUBSTITUTE(Dashboard!G6,"%",""))),IF(VALUE(SUBSTITUTE(Dashboard!G6,"%",""))>=90,"PASS",IF(VALUE(SUBSTITUTE(Dashboard!G6,"%",""))>=70,"REVIEW","FAIL")),"--"))
A29: Minimisation Objectives | B29: ='Dashboard'!G7 | C29: ='Dashboard'!C7 | D29: ='Dashboard'!E7 | E29: =IF(Dashboard!G7="N/A","--",IF(ISNUMBER(VALUE(SUBSTITUTE(Dashboard!G7,"%",""))),IF(VALUE(SUBSTITUTE(Dashboard!G7,"%",""))>=90,"PASS",IF(VALUE(SUBSTITUTE(Dashboard!G7,"%",""))>=70,"REVIEW","FAIL")),"--"))
A31: CRITICAL ISSUES
A32: # | B32: Issue Description | C32: Domain | D32: Owner | E32: Due Date
A33: 1
A34: 2
A35: 3
A36: 4
A37: 5
A39: MANAGEMENT COMMENTARY
A40: [Enter management commentary on data minimisation posture]
A44: APPROVAL
A45: Assessed By
A46: Name:
A47: Date:
A48: Signature:
A49: Decision:
...

Sheet Dashboard
A1: Data Minimisation — Compliance Dashboard
A3: Domain | B3: Total Reqs | C3: Compliant | D3: Partial | E3: Non-Compliant | F3: N/A | G3: Compliance %
A4: Limit Collection | B4: =COUNTA('Limit Collection'!D4:D7) | C4: =COUNTIF('Limit Collection'!D4:D7,"Compliant") | D4: =COUNTIF('Limit Collection'!D4:D7,"Partial") | E4: =COUNTIF('Limit Collection'!D4:D7,"Non-Compliant") | F4: =COUNTIF('Limit Collection'!D4:D7,"N/A") | G4: =IF((B4-F4)=0,"N/A",ROUND(C4/(B4-F4)*100,1)&"%")
A5: Limit Processing | B5: =COUNTA('Limit Processing'!D4:D7) | C5: =COUNTIF('Limit Processing'!D4:D7,"Compliant") | D5: =COUNTIF('Limit Processing'!D4:D7,"Partial") | E5: =COUNTIF('Limit Processing'!D4:D7,"Non-Compliant") | F5: =COUNTIF('Limit Processing'!D4:D7,"N/A") | G5: =IF((B5-F5)=0,"N/A",ROUND(C5/(B5-F5)*100,1)&"%")
A6: Accuracy and Quality | B6: =COUNTA('Accuracy and Quality'!D4:D8) | C6: =COUNTIF('Accuracy and Quality'!D4:D8,"Compliant") | D6: =COUNTIF('Accuracy and Quality'!D4:D8,"Partial") | E6: =COUNTIF('Accuracy and Quality'!D4:D8,"Non-Compliant") | F6: =COUNTIF('Accuracy and Quality'!D4:D8,"N/A") | G6: =IF((B6-F6)=0,"N/A",ROUND(C6/(B6-F6)*100,1)&"%")
A7: Minimisation Objectives | B7: =COUNTA('Minimisation Objectives'!D4:D7) | C7: =COUNTIF('Minimisation Objectives'!D4:D7,"Compliant") | D7: =COUNTIF('Minimisation Objectives'!D4:D7,"Partial") | E7: =COUNTIF('Minimisation Objectives'!D4:D7,"Non-Compliant") | F7: =COUNTIF('Minimisation Objectives'!D4:D7,"N/A") | G7: =IF((B7-F7)=0,"N/A",ROUND(C7/(B7-F7)*100,1)&"%")
A8: TOTAL | B8: =SUM(B4:B7) | C8: =SUM(C4:C7) | D8: =SUM(D4:D7) | E8: =SUM(E4:E7) | F8: =SUM(F4:F7) | G8: =IF((B8-F8)=0,"N/A",ROUND(C8/(B8-F8)*100,1)&"%")
A10: COMPLIANCE BY STATUS
A11: Compliant | B11: =C8 | C11: =IF(B8=0,"",ROUND(B11/B8*100,1)&"%")
A12: Partial | B12: =D8 | C12: =IF(B8=0,"",ROUND(B12/B8*100,1)&"%")
A13: Non-Compliant | B13: =E8 | C13: =IF(B8=0,"",ROUND(B13/B8*100,1)&"%")
A14: N/A | B14: =F8 | C14: =IF(B8=0,"",ROUND(B14/B8*100,1)&"%")
A16: TOP GAPS (Manual Entry)
A17: Priority | B17: Domain | C17: Requirement | D17: Owner | E17: Due Date | F17: Status
A29: COMPLIANCE TREND (Manual Entry)
A30: Assessment Date | B30: Overall % | C30: Compliant | D30: Gaps | E30: Assessor | F30: Notes

Sheet Limit Collection
A1: Limit Collection — Compliance Checklist
A2: ISO/IEC 27701:2025 — Controls A.1.4.2-5: Data Minimisation
A3: Req # | B3: Section | C3: Requirement | D3: Status | E3: Evidence | F3: Owner | G3: Due Date | H3: Notes
A4: A.1.4.2-01 | B4: Collection Minimisation | C4: The organisation shall limit the collection of PII to the minimum that is relevant, proportional, and necessary for the identified purposes. 'Nice to have' data collection is not a valid justification.
A5: A.1.4.2-02 | B5: Field Justification | C5: Each data field collected shall be traceable to a specific documented purpose in the RoPA. Fields without a documented purpose shall not be collected.
A6: A.1.4.2-03 | B6: DPO Review of New Collection | C6: New data collection points (forms, APIs, integrations) require DPO review of the fields to be collected before deployment. Privacy by design (data minimisation as the default at design stage) shall be applied per GDPR Article 25.
A7: A.1.4.2-04 | B7: Collection Review | C7: Existing data collection points shall be reviewed at minimum annually to confirm that all fields collected remain necessary for documented purposes. Fields no longer necessary shall be removed.

Sheet Limit Processing
A1: Limit Processing — Compliance Checklist
A2: ISO/IEC 27701:2025 — Controls A.1.4.2-5: Data Minimisation
A3: Req # | B3: Section | C3: Requirement | D3: Status | E3: Evidence | F3: Owner | G3: Due Date | H3: Notes
A4: A.1.4.3-01 | B4: Processing Access Restriction | C4: Access to PII for processing shall be restricted to personnel and systems with a documented processing purpose (minimum necessary principle). Role-based access controls shall enforce this restriction.
A5: A.1.4.3-02 | B5: Secondary Processing Assessment | C5: Secondary processing of PII for a purpose not identified at collection requires a purpose compatibility assessment (per PRIV-POL-A.1.2.2-5) and a new lawful basis where required. No secondary processing shall commence without DPO assessment.
A6: A.1.4.3-03 | B6: Analytics and Profiling | C6: Aggregation, profiling, or analytics that go beyond the documented purpose require DPO assessment before commencement. The assessment outcome shall be documented.
A7: A.1.4.3-04 | B7: Pseudonymisation Preference | C7: Where the processing purpose can be fulfilled with pseudonymised or anonymised data, the pseudonymised or anonymised version shall be used in preference to identifiable PII, particularly for testing, analytics, and research.

Sheet Accuracy and Quality
A1: Accuracy and Quality — Compliance Checklist
A2: ISO/IEC 27701:2025 — Controls A.1.4.2-5: Data Minimisation
A3: Req # | B3: Section | C3: Requirement | D3: Status | E3: Evidence | F3: Owner | G3: Due Date | H3: Notes
A4: A.1.4.4-01 | B4: Accuracy Requirement | C4: The organisation shall ensure that PII held and processed is as accurate, complete, and up to date as necessary for the processing purposes, throughout the lifecycle of the PII.
A5: A.1.4.4-02 | B5: Collection Validation | C5: Collection processes shall include reasonable validation measures to prevent the entry of obviously inaccurate data (e.g. date format validation, email format validation, range checks for numeric fields).
A6: A.1.4.4-03 | B6: Update Mechanisms | C6: PII that is known to change over time shall have a defined review or update mechanism. Data subjects shall be given the means to update their own PII where technically feasible.
A7: A.1.4.4-04 | B7: Inaccuracy Correction | C7: Where inaccurate PII is identified — whether by the organisation or through a data subject rectification request — it shall be corrected without undue delay. The correction shall be documented.
A8: A.1.4.4-05 | B8: Enhanced Accuracy Controls | C8: PII used for significant decisions (financial, health, legal) shall have enhanced accuracy controls. The organisation shall not retain PII that has become inaccurate for purposes where accuracy is necessary, when the inaccuracy cannot be corrected.

Sheet Minimisation Objectives
A1: Minimisation Objectives — Compliance Checklist
A2: ISO/IEC 27701:2025 — Controls A.1.4.2-5: Data Minimisation
A3: Req # | B3: Section | C3: Requirement | D3: Status | E3: Evidence | F3: Owner | G3: Due Date | H3: Notes
A4: A.1.4.5-01 | B4: Documented Objectives | C4: The organisation shall define and document PII minimisation objectives covering: collection minimisation; processing minimisation; retention minimisation; de-identification for secondary use; and aggregation minimisation.
A5: A.1.4.5-02 | B5: De-identification Mechanisms | C5: The organisation shall document the de-identification mechanisms used to meet minimisation objectives, including pseudonymisation (reversible, still PII under GDPR) and anonymisation (irreversible, not PII where re-identification is not reasonably possible — confirmed by DPO).
A6: A.1.4.5-03 | B6: Objectives Review | C6: PII minimisation objectives and mechanisms shall be reviewed at minimum annually, when new processing activities commence, and when regulatory guidance on minimisation changes.
A7: A.1.4.5-04 | B7: Objectives Demonstrability | C7: The organisation shall be able to demonstrate that minimisation objectives are being met in practice, through evidence of DPO reviews, RoPA field justifications, de-identification records, and collection point documentation.
