Workbook

Sheet Executive Summary
A1: AI-CHK-A.2.2-4 — AI Policy Framework Compliance Checklist
A3: DOCUMENT INFORMATION
A4: Document ID | B4: AI-CHK-A.2.2-4
A5: Source Policy | B5: AI-POL-A.2.2-4
A6: ISO Controls | B6: AI Policy Framework
A7: Generated | B7: 15.04.2026
A8: Prepared By
A9: Organisation
A10: Review Cycle | B10: Annual
A12: OVERALL COMPLIANCE STATUS
A13: Overall Compliance | B13: ='Dashboard'!G7
A14: Status | B14: =IF(Dashboard!G7="N/A","NOT ASSESSED",IF(ISNUMBER(VALUE(SUBSTITUTE(Dashboard!G7,"%",""))),IF(VALUE(SUBSTITUTE(Dashboard!G7,"%",""))>=90,"GREEN",IF(VALUE(SUBSTITUTE(Dashboard!G7,"%",""))>=70,"AMBER","RED")),"NOT ASSESSED"))
A16: KEY METRICS
A17: Total Requirements | B17: ='Dashboard'!B7
A18: Compliant | B18: ='Dashboard'!C7
A19: Partial | B19: ='Dashboard'!D7
A20: Non-Compliant | B20: ='Dashboard'!E7
A21: Not Applicable | B21: ='Dashboard'!F7
A22: Owner Coverage | B22: =IF(Dashboard!B7=0,"N/A",ROUND((COUNTA('Responsible AI Policy'!F4:F9)+COUNTA('Responsible AI Principles'!F4:F9)+COUNTA('AI Policy Processes'!F4:F8))/Dashboard!B7*100,0)&"%")
A24: DOMAIN STATUS SUMMARY
A25: Domain | B25: Compliance % | C25: Compliant | D25: Gaps | E25: Status
A26: Responsible AI Policy | B26: ='Dashboard'!G4 | C26: ='Dashboard'!C4 | D26: ='Dashboard'!E4 | E26: =IF(Dashboard!G4="N/A","--",IF(ISNUMBER(VALUE(SUBSTITUTE(Dashboard!G4,"%",""))),IF(VALUE(SUBSTITUTE(Dashboard!G4,"%",""))>=90,"PASS",IF(VALUE(SUBSTITUTE(Dashboard!G4,"%",""))>=70,"REVIEW","FAIL")),"--"))
A27: Responsible AI Principles | B27: ='Dashboard'!G5 | C27: ='Dashboard'!C5 | D27: ='Dashboard'!E5 | E27: =IF(Dashboard!G5="N/A","--",IF(ISNUMBER(VALUE(SUBSTITUTE(Dashboard!G5,"%",""))),IF(VALUE(SUBSTITUTE(Dashboard!G5,"%",""))>=90,"PASS",IF(VALUE(SUBSTITUTE(Dashboard!G5,"%",""))>=70,"REVIEW","FAIL")),"--"))
A28: AI Policy Processes | B28: ='Dashboard'!G6 | C28: ='Dashboard'!C6 | D28: ='Dashboard'!E6 | E28: =IF(Dashboard!G6="N/A","--",IF(ISNUMBER(VALUE(SUBSTITUTE(Dashboard!G6,"%",""))),IF(VALUE(SUBSTITUTE(Dashboard!G6,"%",""))>=90,"PASS",IF(VALUE(SUBSTITUTE(Dashboard!G6,"%",""))>=70,"REVIEW","FAIL")),"--"))
A30: CRITICAL ISSUES
A31: # | B31: Issue Description | C31: Domain | D31: Owner | E31: Due Date
A32: 1
A33: 2
A34: 3
A35: 4
A36: 5
A38: MANAGEMENT COMMENTARY
A39: [Enter management commentary on ai policy framework posture]
A43: APPROVAL
A44: Assessed By (AI System Owner)
A45: Name:
A46: Date:
A47: Signature:
A48: Decision:
A50: Reviewed By (AI Governance Officer)
...

Sheet Dashboard
A1: AI Policy Framework — Compliance Dashboard
A3: Domain | B3: Total Reqs | C3: Compliant | D3: Partial | E3: Non-Compliant | F3: N/A | G3: Compliance %
A4: Responsible AI Policy | B4: =COUNTA('Responsible AI Policy'!D4:D9) | C4: =COUNTIF('Responsible AI Policy'!D4:D9,"Compliant") | D4: =COUNTIF('Responsible AI Policy'!D4:D9,"Partial") | E4: =COUNTIF('Responsible AI Policy'!D4:D9,"Non-Compliant") | F4: =COUNTIF('Responsible AI Policy'!D4:D9,"N/A") | G4: =IF((B4-F4)=0,"N/A",ROUND(C4/(B4-F4)*100,1)&"%")
A5: Responsible AI Principles | B5: =COUNTA('Responsible AI Principles'!D4:D9) | C5: =COUNTIF('Responsible AI Principles'!D4:D9,"Compliant") | D5: =COUNTIF('Responsible AI Principles'!D4:D9,"Partial") | E5: =COUNTIF('Responsible AI Principles'!D4:D9,"Non-Compliant") | F5: =COUNTIF('Responsible AI Principles'!D4:D9,"N/A") | G5: =IF((B5-F5)=0,"N/A",ROUND(C5/(B5-F5)*100,1)&"%")
A6: AI Policy Processes | B6: =COUNTA('AI Policy Processes'!D4:D8) | C6: =COUNTIF('AI Policy Processes'!D4:D8,"Compliant") | D6: =COUNTIF('AI Policy Processes'!D4:D8,"Partial") | E6: =COUNTIF('AI Policy Processes'!D4:D8,"Non-Compliant") | F6: =COUNTIF('AI Policy Processes'!D4:D8,"N/A") | G6: =IF((B6-F6)=0,"N/A",ROUND(C6/(B6-F6)*100,1)&"%")
A7: TOTAL | B7: =SUM(B4:B6) | C7: =SUM(C4:C6) | D7: =SUM(D4:D6) | E7: =SUM(E4:E6) | F7: =SUM(F4:F6) | G7: =IF((B7-F7)=0,"N/A",ROUND(C7/(B7-F7)*100,1)&"%")
A9: COMPLIANCE BY STATUS
A10: Compliant | B10: =C7 | C10: =IF(B7=0,"",ROUND(B10/B7*100,1)&"%")
A11: Partial | B11: =D7 | C11: =IF(B7=0,"",ROUND(B11/B7*100,1)&"%")
A12: Non-Compliant | B12: =E7 | C12: =IF(B7=0,"",ROUND(B12/B7*100,1)&"%")
A13: N/A | B13: =F7 | C13: =IF(B7=0,"",ROUND(B13/B7*100,1)&"%")
A15: TOP GAPS (Manual Entry)
A16: Priority | B16: Domain | C16: Requirement | D16: Owner | E16: Due Date | F16: Status
A28: COMPLIANCE TREND (Manual Entry)
A29: Assessment Date | B29: Overall % | C29: Compliant | D29: Gaps | E29: Assessor | F29: Notes

Sheet Responsible AI Policy
A1: Responsible AI Policy — Compliance Checklist
A2: ISO/IEC 42001:2023 — Controls A.2.2-4: AI Policy Framework
A3: Req # | B3: Section | C3: Requirement | D3: Status | E3: Evidence | F3: Owner | G3: Due Date | H3: Notes
A4: A.2.2-01 | B4: Policy Establishment | C4: The organisation shall establish a policy for the responsible development and/or use of AI systems. The policy shall be approved by Executive Management and documented.
A5: A.2.2-02 | B5: Policy Scope | C5: The AI policy shall define the scope of AI systems covered and identify the organisational activities related to AI systems to which the policy applies.
A6: A.2.2-03 | B6: Policy Communication | C6: The AI policy shall be communicated to all persons within the organisation whose roles are relevant to AI systems, and made available to interested parties as appropriate.
A7: A.2.2-04 | B7: Policy Review | C7: The AI policy shall be reviewed at planned intervals and when significant changes occur to ensure its continuing suitability, adequacy, and effectiveness.
A8: A.2.2-05 | B8: Policy Alignment | C8: The AI policy shall be consistent with applicable laws and regulations and aligned with [Organisation]'s overall information security and data protection policies.
A9: A.2.2-06 | B9: Policy Authority | C9: The AI policy shall establish clear authority and accountability for AI governance, naming the AI Governance Officer role as responsible for the AIMS.

Sheet Responsible AI Principles
A1: Responsible AI Principles — Compliance Checklist
A2: ISO/IEC 42001:2023 — Controls A.2.2-4: AI Policy Framework
A3: Req # | B3: Section | C3: Requirement | D3: Status | E3: Evidence | F3: Owner | G3: Due Date | H3: Notes
A4: A.2.3-01 | B4: Principles Establishment | C4: The organisation shall establish and document principles for the responsible development and use of AI systems. Principles shall be approved by Executive Management.
A5: A.2.3-02 | B5: Human Agency and Oversight | C5: The responsible AI principles shall include a commitment to human agency and oversight — AI systems shall be designed to support human decision-making with meaningful human review for consequential outputs.
A6: A.2.3-03 | B6: Fairness and Non-Discrimination | C6: The responsible AI principles shall include a commitment to fairness — AI systems shall be assessed for potential bias and discriminatory impact before deployment and in operation.
A7: A.2.3-04 | B7: Privacy by Design | C7: The responsible AI principles shall include a commitment to privacy — personal data in AI systems shall be governed by documented legal bases and minimisation requirements.
A8: A.2.3-05 | B8: Robustness and Safety | C8: The responsible AI principles shall include a commitment to robustness, security, and safety — AI systems shall undergo validation before deployment and be monitored in operation.
A9: A.2.3-06 | B9: Accountability and Transparency | C9: The responsible AI principles shall include a commitment to accountability and transparency — every AI system shall have a named owner accountable for its compliance, and transparency shall be provided to users and affected individuals.

Sheet AI Policy Processes
A1: AI Policy Processes — Compliance Checklist
A2: ISO/IEC 42001:2023 — Controls A.2.2-4: AI Policy Framework
A3: Req # | B3: Section | C3: Requirement | D3: Status | E3: Evidence | F3: Owner | G3: Due Date | H3: Notes
A4: A.2.4-01 | B4: Policy Integration | C4: The organisation shall implement processes to ensure that AI policy requirements are integrated into the AI system lifecycle — from specification through deployment and operation.
A5: A.2.4-02 | B5: Compliance Monitoring | C5: The organisation shall implement a process to monitor compliance with the AI policy. Non-compliance shall be escalated and addressed per defined escalation paths.
A6: A.2.4-03 | B6: Policy Hierarchy | C6: The organisation shall maintain a documented AI policy hierarchy (foundation policies → control-specific policies → implementation guides) ensuring that lower-tier documents do not contradict higher-tier requirements.
A7: A.2.4-04 | B7: Awareness and Training | C7: The organisation shall ensure that persons with AI-related roles receive training on the AI policy and relevant responsible AI requirements appropriate to their role.
A8: A.2.4-05 | B8: Effectiveness Measurement | C8: The organisation shall define and measure indicators of AI policy effectiveness, reporting results to Executive Management at least annually via the AIMS management review.
