Workbook

Sheet Executive Summary
A1: ISMS-OP-CHK-A.8.10 — Information Deletion Compliance Checklist
A3: DOCUMENT INFORMATION
A4: Document ID | B4: ISMS-OP-CHK-A.8.10
A5: Source Policy | B5: ISMS-OP-POL-A.8.10
A6: ISO Controls | B6: Information Deletion
A7: Generated | B7: 30.09.2026
A8: Prepared By
A9: Organisation
A10: Review Cycle | B10: Annual
A12: OVERALL COMPLIANCE STATUS
A13: Overall Compliance | B13: ='Dashboard'!G11
A14: Status | B14: =IF(Dashboard!H11>0,"INCOMPLETE",IF(Dashboard!G11="N/A","NOT ASSESSED",IF(ISNUMBER(VALUE(SUBSTITUTE(Dashboard!G11,"%",""))),IF(VALUE(SUBSTITUTE(Dashboard!G11,"%",""))>=90,"GREEN",IF(VALUE(SUBSTITUTE(Dashboard!G11,"%",""))>=70,"AMBER","RED")),"NOT ASSESSED")))
A16: KEY METRICS
A17: Total Requirements | B17: ='Dashboard'!B11
A18: Compliant | B18: ='Dashboard'!C11
A19: Partial | B19: ='Dashboard'!D11
A20: Non-Compliant | B20: ='Dashboard'!E11
A21: Not Applicable | B21: ='Dashboard'!F11
A22: Unanswered | B22: ='Dashboard'!H11
A23: Owner Coverage | B23: =IF(Dashboard!B11=0,"N/A",ROUND((COUNTA('Retention Schedules & Deletion'!F4:F8)+COUNTA('Deletion Methods'!F4:F12)+COUNTA('Third-Party and Cloud Deletion'!F4:F6)+COUNTA('Data Subject Erasure Requests'!F4:F5)+COUNTA('Legal Hold Management'!F4:F10)+COUNTA('Exception Management'!F4:F6)+COUNTA('Compliance Measurement'!F4:F4))/Dashboard!B11*100,0)&"%")
A25: DOMAIN STATUS SUMMARY
A26: Domain | B26: Compliance % | C26: Compliant | D26: Gaps | E26: Status
A27: Retention Schedules & Deletion | B27: ='Dashboard'!G4 | C27: ='Dashboard'!C4 | D27: ='Dashboard'!E4 | E27: =IF(Dashboard!H4>0,"INCOMPLETE",IF(Dashboard!G4="N/A","--",IF(ISNUMBER(VALUE(SUBSTITUTE(Dashboard!G4,"%",""))),IF(VALUE(SUBSTITUTE(Dashboard!G4,"%",""))>=90,"PASS",IF(VALUE(SUBSTITUTE(Dashboard!G4,"%",""))>=70,"REVIEW","FAIL")),"--")))
A28: Deletion Methods | B28: ='Dashboard'!G5 | C28: ='Dashboard'!C5 | D28: ='Dashboard'!E5 | E28: =IF(Dashboard!H5>0,"INCOMPLETE",IF(Dashboard!G5="N/A","--",IF(ISNUMBER(VALUE(SUBSTITUTE(Dashboard!G5,"%",""))),IF(VALUE(SUBSTITUTE(Dashboard!G5,"%",""))>=90,"PASS",IF(VALUE(SUBSTITUTE(Dashboard!G5,"%",""))>=70,"REVIEW","FAIL")),"--")))
A29: Third-Party and Cloud Deletion | B29: ='Dashboard'!G6 | C29: ='Dashboard'!C6 | D29: ='Dashboard'!E6 | E29: =IF(Dashboard!H6>0,"INCOMPLETE",IF(Dashboard!G6="N/A","--",IF(ISNUMBER(VALUE(SUBSTITUTE(Dashboard!G6,"%",""))),IF(VALUE(SUBSTITUTE(Dashboard!G6,"%",""))>=90,"PASS",IF(VALUE(SUBSTITUTE(Dashboard!G6,"%",""))>=70,"REVIEW","FAIL")),"--")))
A30: Data Subject Erasure Requests | B30: ='Dashboard'!G7 | C30: ='Dashboard'!C7 | D30: ='Dashboard'!E7 | E30: =IF(Dashboard!H7>0,"INCOMPLETE",IF(Dashboard!G7="N/A","--",IF(ISNUMBER(VALUE(SUBSTITUTE(Dashboard!G7,"%",""))),IF(VALUE(SUBSTITUTE(Dashboard!G7,"%",""))>=90,"PASS",IF(VALUE(SUBSTITUTE(Dashboard!G7,"%",""))>=70,"REVIEW","FAIL")),"--")))
A31: Legal Hold Management | B31: ='Dashboard'!G8 | C31: ='Dashboard'!C8 | D31: ='Dashboard'!E8 | E31: =IF(Dashboard!H8>0,"INCOMPLETE",IF(Dashboard!G8="N/A","--",IF(ISNUMBER(VALUE(SUBSTITUTE(Dashboard!G8,"%",""))),IF(VALUE(SUBSTITUTE(Dashboard!G8,"%",""))>=90,"PASS",IF(VALUE(SUBSTITUTE(Dashboard!G8,"%",""))>=70,"REVIEW","FAIL")),"--")))
A32: Exception Management | B32: ='Dashboard'!G9 | C32: ='Dashboard'!C9 | D32: ='Dashboard'!E9 | E32: =IF(Dashboard!H9>0,"INCOMPLETE",IF(Dashboard!G9="N/A","--",IF(ISNUMBER(VALUE(SUBSTITUTE(Dashboard!G9,"%",""))),IF(VALUE(SUBSTITUTE(Dashboard!G9,"%",""))>=90,"PASS",IF(VALUE(SUBSTITUTE(Dashboard!G9,"%",""))>=70,"REVIEW","FAIL")),"--")))
A33: Compliance Measurement | B33: ='Dashboard'!G10 | C33: ='Dashboard'!C10 | D33: ='Dashboard'!E10 | E33: =IF(Dashboard!H10>0,"INCOMPLETE",IF(Dashboard!G10="N/A","--",IF(ISNUMBER(VALUE(SUBSTITUTE(Dashboard!G10,"%",""))),IF(VALUE(SUBSTITUTE(Dashboard!G10,"%",""))>=90,"PASS",IF(VALUE(SUBSTITUTE(Dashboard!G10,"%",""))>=70,"REVIEW","FAIL")),"--")))
A35: CRITICAL ISSUES
A36: # | B36: Issue Description | C36: Domain | D36: Owner | E36: Due Date
A37: 1
A38: 2
A39: 3
A40: 4
A41: 5
A43: MANAGEMENT COMMENTARY
A44: [Enter management commentary on information deletion posture]
A48: APPROVAL
A49: Assessed By
...

Sheet Dashboard
A1: Information Deletion — Compliance Dashboard
A3: Domain | B3: Total Reqs | C3: Compliant | D3: Partial | E3: Non-Compliant | F3: N/A | G3: Compliance % | H3: Unassessed
A4: Retention Schedules & Deletion | B4: =COUNTA('Retention Schedules & Deletion'!A4:A8) | C4: =COUNTIF('Retention Schedules & Deletion'!D4:D8,"Compliant") | D4: =COUNTIF('Retention Schedules & Deletion'!D4:D8,"Partial") | E4: =COUNTIF('Retention Schedules & Deletion'!D4:D8,"Non-Compliant") | F4: =COUNTIF('Retention Schedules & Deletion'!D4:D8,"N/A") | G4: =IF((B4-F4)=0,"N/A",ROUND(C4/(B4-F4)*100,1)&"%") | H4: =B4-(C4+D4+E4+F4)
A5: Deletion Methods | B5: =COUNTA('Deletion Methods'!A4:A12) | C5: =COUNTIF('Deletion Methods'!D4:D12,"Compliant") | D5: =COUNTIF('Deletion Methods'!D4:D12,"Partial") | E5: =COUNTIF('Deletion Methods'!D4:D12,"Non-Compliant") | F5: =COUNTIF('Deletion Methods'!D4:D12,"N/A") | G5: =IF((B5-F5)=0,"N/A",ROUND(C5/(B5-F5)*100,1)&"%") | H5: =B5-(C5+D5+E5+F5)
A6: Third-Party and Cloud Deletion | B6: =COUNTA('Third-Party and Cloud Deletion'!A4:A6) | C6: =COUNTIF('Third-Party and Cloud Deletion'!D4:D6,"Compliant") | D6: =COUNTIF('Third-Party and Cloud Deletion'!D4:D6,"Partial") | E6: =COUNTIF('Third-Party and Cloud Deletion'!D4:D6,"Non-Compliant") | F6: =COUNTIF('Third-Party and Cloud Deletion'!D4:D6,"N/A") | G6: =IF((B6-F6)=0,"N/A",ROUND(C6/(B6-F6)*100,1)&"%") | H6: =B6-(C6+D6+E6+F6)
A7: Data Subject Erasure Requests | B7: =COUNTA('Data Subject Erasure Requests'!A4:A5) | C7: =COUNTIF('Data Subject Erasure Requests'!D4:D5,"Compliant") | D7: =COUNTIF('Data Subject Erasure Requests'!D4:D5,"Partial") | E7: =COUNTIF('Data Subject Erasure Requests'!D4:D5,"Non-Compliant") | F7: =COUNTIF('Data Subject Erasure Requests'!D4:D5,"N/A") | G7: =IF((B7-F7)=0,"N/A",ROUND(C7/(B7-F7)*100,1)&"%") | H7: =B7-(C7+D7+E7+F7)
A8: Legal Hold Management | B8: =COUNTA('Legal Hold Management'!A4:A10) | C8: =COUNTIF('Legal Hold Management'!D4:D10,"Compliant") | D8: =COUNTIF('Legal Hold Management'!D4:D10,"Partial") | E8: =COUNTIF('Legal Hold Management'!D4:D10,"Non-Compliant") | F8: =COUNTIF('Legal Hold Management'!D4:D10,"N/A") | G8: =IF((B8-F8)=0,"N/A",ROUND(C8/(B8-F8)*100,1)&"%") | H8: =B8-(C8+D8+E8+F8)
A9: Exception Management | B9: =COUNTA('Exception Management'!A4:A6) | C9: =COUNTIF('Exception Management'!D4:D6,"Compliant") | D9: =COUNTIF('Exception Management'!D4:D6,"Partial") | E9: =COUNTIF('Exception Management'!D4:D6,"Non-Compliant") | F9: =COUNTIF('Exception Management'!D4:D6,"N/A") | G9: =IF((B9-F9)=0,"N/A",ROUND(C9/(B9-F9)*100,1)&"%") | H9: =B9-(C9+D9+E9+F9)
A10: Compliance Measurement | B10: =COUNTA('Compliance Measurement'!A4:A4) | C10: =COUNTIF('Compliance Measurement'!D4:D4,"Compliant") | D10: =COUNTIF('Compliance Measurement'!D4:D4,"Partial") | E10: =COUNTIF('Compliance Measurement'!D4:D4,"Non-Compliant") | F10: =COUNTIF('Compliance Measurement'!D4:D4,"N/A") | G10: =IF((B10-F10)=0,"N/A",ROUND(C10/(B10-F10)*100,1)&"%") | H10: =B10-(C10+D10+E10+F10)
A11: TOTAL | B11: =SUM(B4:B10) | C11: =SUM(C4:C10) | D11: =SUM(D4:D10) | E11: =SUM(E4:E10) | F11: =SUM(F4:F10) | G11: =IF((B11-F11)=0,"N/A",ROUND(C11/(B11-F11)*100,1)&"%") | H11: =SUM(H4:H10)
A13: COMPLIANCE BY STATUS
A14: Compliant | B14: =C11 | C14: =IF(B11=0,"",ROUND(B14/B11*100,1)&"%")
A15: Partial | B15: =D11 | C15: =IF(B11=0,"",ROUND(B15/B11*100,1)&"%")
A16: Non-Compliant | B16: =E11 | C16: =IF(B11=0,"",ROUND(B16/B11*100,1)&"%")
A17: N/A | B17: =F11 | C17: =IF(B11=0,"",ROUND(B17/B11*100,1)&"%")
A19: TOP GAPS (Manual Entry)
A20: Priority | B20: Domain | C20: Requirement | D20: Owner | E20: Due Date | F20: Status
A32: COMPLIANCE TREND (Manual Entry)
A33: Assessment Date | B33: Overall % | C33: Compliant | D33: Gaps | E33: Assessor | F33: Notes

Sheet Retention Schedules & Deletion
A1: Retention Schedules & Deletion — Compliance Checklist
A2: ISO/IEC 27001:2022 — Control A.8.10: Information Deletion
A3: Req # | B3: Section | C3: Requirement | D3: Status | E3: Evidence | F3: Owner | G3: Due Date | H3: Notes
A4: A.8.10-01 | B4: Maintain A Retention Schedule Defining | C4: The organisation shall maintain a retention schedule defining retention periods for all data categories. Retention periods shall be based on the longest applicable requirement from:.
A5: A.8.10-02 | B5: The Longest Applicable Retention Period | C5: Where multiple requirements apply to the same data, the longest applicable retention period shall govern unless Legal Counsel determines otherwise.
A6: A.8.10-03 | B6: This Table Provides Minimum Reference | C6: This table provides minimum reference periods. The Records Manager shall maintain the authoritative retention schedule, which shall be reviewed annually by Legal Counsel and approved by Executive Management.
A7: A.8.10-04 | B7: Be Initiated When Any Of The | C7: Deletion shall be initiated when any of the following events occurs:.
A8: A.8.10-05 | B8: It Should Be Implemented With Safeguards | C8: Where automated deletion is technically feasible, it should be implemented with safeguards against premature deletion (legal hold checks, business owner notification). Where automation is not feasible, manual deletion procedures shall be documented with defined verification checkpoints.

Sheet Deletion Methods
A1: Deletion Methods — Compliance Checklist
A2: ISO/IEC 27001:2022 — Control A.8.10: Information Deletion
A3: Req # | B3: Section | C3: Requirement | D3: Status | E3: Evidence | F3: Owner | G3: Due Date | H3: Notes
A4: A.8.10-06 | B4: Deletion Methods | C4: Deletion methods shall align with NIST SP 800-88 Rev. 2 (Guidelines for Media Sanitization, September 2025), which defines three sanitisation levels, and IEEE 2883 for media-specific sanitisation techniques.
A5: A.8.10-07 | B5: Target Data | C5: All target data shall have been encrypted before storage (encryption applied retroactively does not qualify).
A6: A.8.10-08 | B6: The Encryption Algorithm | C6: The encryption algorithm shall meet approved minimum standards (AES-256 or equivalent).
A7: A.8.10-09 | B7: A Documented Data-To-Key Mapping | C7: A documented data-to-key mapping shall exist, enabling identification of which encryption keys protect which data.
A8: A.8.10-10 | B8: Key Destruction | C8: Key destruction shall be performed through a verified process (HSM key zeroisation, KMS key deletion with audit log, or equivalent).
A9: A.8.10-11 | B9: Key Destruction Evidence | C9: Key destruction evidence shall be retained (audit logs, HSM certificates) for a minimum of 3 years.
A10: A.8.10-12 | B10: Backup Copies Of The Encryption Key | C10: Backup copies of the encryption key shall also be destroyed — if key backup, escrow, or external storage exists and cannot be verified as destroyed, cryptographic erasure shall not be accepted as the sole deletion method.
A11: A.8.10-13 | B11: Deletion In Production Systems | C11: Deletion in production systems shall extend to all backup copies containing the deleted data, including:.
A12: A.8.10-14 | B12: Immutable Backup Tapes, Retention-Locked | C12: Where immediate deletion from backups is not technically feasible (e.g., immutable backup tapes, retention-locked cloud backups), the organisation shall:.

Sheet Third-Party and Cloud Deletion
A1: Third-Party and Cloud Deletion — Compliance Checklist
A2: ISO/IEC 27001:2022 — Control A.8.10: Information Deletion
A3: Req # | B3: Section | C3: Requirement | D3: Status | E3: Evidence | F3: Owner | G3: Due Date | H3: Notes
A4: A.8.10-15 | B4: Contracts With Third Parties That | C4: All contracts with third parties that process organisational data shall include deletion obligations specifying:.
A5: A.8.10-16 | B5: Before Engaging A Cloud Service Provider | C5: Before engaging a cloud service provider, the organisation shall assess deletion capabilities including:.
A6: A.8.10-17 | B6: Obtain Verification Of Deletion From | C6: The organisation shall obtain verification of deletion from third parties through one or more of the following methods:.

Sheet Data Subject Erasure Requests
A1: Data Subject Erasure Requests — Compliance Checklist
A2: ISO/IEC 27001:2022 — Control A.8.10: Information Deletion
A3: Req # | B3: Section | C3: Requirement | D3: Status | E3: Evidence | F3: Owner | G3: Due Date | H3: Notes
A4: A.8.10-18 | B4: Accept And Process Data Subject Erasure | C4: The organisation shall accept and process data subject erasure requests in compliance with Swiss nFADP Art. 6(4) and, where applicable, GDPR Art. 17 (right to erasure / right to be forgotten).
A5: A.8.10-19 | B5: The Organisation | C5: Where personal data subject to an erasure request was disclosed to third parties, the organisation shall notify those third parties of the erasure request per GDPR Art. 19 and nFADP obligations, unless doing so proves impossible or involves disproportionate effort.

Sheet Legal Hold Management
A1: Legal Hold Management — Compliance Checklist
A2: ISO/IEC 27001:2022 — Control A.8.10: Information Deletion
A3: Req # | B3: Section | C3: Requirement | D3: Status | E3: Evidence | F3: Owner | G3: Due Date | H3: Notes
A4: A.8.10-20 | B4: Be Suspended When Data Is Subject | C4: Deletion shall be suspended when data is subject to a legal hold for any of the following reasons:.
A5: A.8.10-21 | B5: Affected Custodians Are Notified Within | C5: Affected custodians are notified within 24 hours and shall acknowledge receipt within 2 business days.
A6: A.8.10-22 | B6: Legal Holds | C6: Legal holds shall be reviewed at least quarterly by Legal Counsel. Each review shall produce a documented assessment including:.
A7: A.8.10-23 | B7: Data Held Beyond Normal Retention Solely | C7: Data held beyond normal retention solely due to the legal hold shall be deleted within 90 days of hold release, unless an approved business justification exists.
A8: A.8.10-24 | B8: Restriction Of Processing | C8: Restriction of processing shall be applied (data preserved but not actively used).
A9: A.8.10-25 | B9: Execute Within 30 Days Of Hold | C9: Deletion shall execute within 30 days of hold release.
A10: A.8.10-26 | B10: The Data Subject | C10: The data subject shall be informed that the request has been noted but cannot currently be fulfilled, citing the applicable legal exception, without disclosing details that could prejudice legal proceedings.

Sheet Exception Management
A1: Exception Management — Compliance Checklist
A2: ISO/IEC 27001:2022 — Control A.8.10: Information Deletion
A3: Req # | B3: Section | C3: Requirement | D3: Status | E3: Evidence | F3: Owner | G3: Due Date | H3: Notes
A4: A.8.10-27 | B4: Proposed Expiry Date (Exceptions | C4: Proposed expiry date (exceptions shall not be indefinite).
A5: A.8.10-28 | B5: The Following Exceptions | C5: The following exceptions shall not be granted:.
A6: A.8.10-29 | B6: Approved Exceptions | C6: All approved exceptions shall be recorded in the exception register with owner, approval date, expiry date, compensating controls, and review schedule. Exceptions shall be reviewed quarterly and auto-expire unless renewed through the approval process.

Sheet Compliance Measurement
A1: Compliance Measurement — Compliance Checklist
A2: ISO/IEC 27001:2022 — Control A.8.10: Information Deletion
A3: Req # | B3: Section | C3: Requirement | D3: Status | E3: Evidence | F3: Owner | G3: Due Date | H3: Notes
A4: A.8.10-30 | B4: Metrics Breaching Targets | C4: Metrics breaching targets shall be escalated to the CISO for immediate attention and reported at the next Management Review.
