Workbook

Sheet Executive Summary
A1: ISMS-OP-CHK-A.8.1-7-18-19 — Endpoint Security Compliance Checklist
A3: DOCUMENT INFORMATION
A4: Document ID | B4: ISMS-OP-CHK-A.8.1-7-18-19
A5: Source Policy | B5: ISMS-OP-POL-A.8.1-7-18-19
A6: ISO Controls | B6: Endpoint Security
A7: Generated | B7: 30.09.2026
A8: Prepared By
A9: Organisation
A10: Review Cycle | B10: Annual
A12: OVERALL COMPLIANCE STATUS
A13: Overall Compliance | B13: ='Dashboard'!G9
A14: Status | B14: =IF(Dashboard!H9>0,"INCOMPLETE",IF(Dashboard!G9="N/A","NOT ASSESSED",IF(ISNUMBER(VALUE(SUBSTITUTE(Dashboard!G9,"%",""))),IF(VALUE(SUBSTITUTE(Dashboard!G9,"%",""))>=90,"GREEN",IF(VALUE(SUBSTITUTE(Dashboard!G9,"%",""))>=70,"AMBER","RED")),"NOT ASSESSED")))
A16: KEY METRICS
A17: Total Requirements | B17: ='Dashboard'!B9
A18: Compliant | B18: ='Dashboard'!C9
A19: Partial | B19: ='Dashboard'!D9
A20: Non-Compliant | B20: ='Dashboard'!E9
A21: Not Applicable | B21: ='Dashboard'!F9
A22: Unanswered | B22: ='Dashboard'!H9
A23: Owner Coverage | B23: =IF(Dashboard!B9=0,"N/A",ROUND((COUNTA('User Endpoint Devices'!F4:F29)+COUNTA('Malware and Antivirus Prot'!F4:F15)+COUNTA('Education'!F4:F4)+COUNTA('Privileged Utility Programs'!F4:F9)+COUNTA('Installation Software Op'!F4:F14))/Dashboard!B9*100,0)&"%")
A25: DOMAIN STATUS SUMMARY
A26: Domain | B26: Compliance % | C26: Compliant | D26: Gaps | E26: Status
A27: User Endpoint Devices | B27: ='Dashboard'!G4 | C27: ='Dashboard'!C4 | D27: ='Dashboard'!E4 | E27: =IF(Dashboard!H4>0,"INCOMPLETE",IF(Dashboard!G4="N/A","--",IF(ISNUMBER(VALUE(SUBSTITUTE(Dashboard!G4,"%",""))),IF(VALUE(SUBSTITUTE(Dashboard!G4,"%",""))>=90,"PASS",IF(VALUE(SUBSTITUTE(Dashboard!G4,"%",""))>=70,"REVIEW","FAIL")),"--")))
A28: Malware and Antivirus Prot | B28: ='Dashboard'!G5 | C28: ='Dashboard'!C5 | D28: ='Dashboard'!E5 | E28: =IF(Dashboard!H5>0,"INCOMPLETE",IF(Dashboard!G5="N/A","--",IF(ISNUMBER(VALUE(SUBSTITUTE(Dashboard!G5,"%",""))),IF(VALUE(SUBSTITUTE(Dashboard!G5,"%",""))>=90,"PASS",IF(VALUE(SUBSTITUTE(Dashboard!G5,"%",""))>=70,"REVIEW","FAIL")),"--")))
A29: Education | B29: ='Dashboard'!G6 | C29: ='Dashboard'!C6 | D29: ='Dashboard'!E6 | E29: =IF(Dashboard!H6>0,"INCOMPLETE",IF(Dashboard!G6="N/A","--",IF(ISNUMBER(VALUE(SUBSTITUTE(Dashboard!G6,"%",""))),IF(VALUE(SUBSTITUTE(Dashboard!G6,"%",""))>=90,"PASS",IF(VALUE(SUBSTITUTE(Dashboard!G6,"%",""))>=70,"REVIEW","FAIL")),"--")))
A30: Privileged Utility Programs | B30: ='Dashboard'!G7 | C30: ='Dashboard'!C7 | D30: ='Dashboard'!E7 | E30: =IF(Dashboard!H7>0,"INCOMPLETE",IF(Dashboard!G7="N/A","--",IF(ISNUMBER(VALUE(SUBSTITUTE(Dashboard!G7,"%",""))),IF(VALUE(SUBSTITUTE(Dashboard!G7,"%",""))>=90,"PASS",IF(VALUE(SUBSTITUTE(Dashboard!G7,"%",""))>=70,"REVIEW","FAIL")),"--")))
A31: Installation Software Op | B31: ='Dashboard'!G8 | C31: ='Dashboard'!C8 | D31: ='Dashboard'!E8 | E31: =IF(Dashboard!H8>0,"INCOMPLETE",IF(Dashboard!G8="N/A","--",IF(ISNUMBER(VALUE(SUBSTITUTE(Dashboard!G8,"%",""))),IF(VALUE(SUBSTITUTE(Dashboard!G8,"%",""))>=90,"PASS",IF(VALUE(SUBSTITUTE(Dashboard!G8,"%",""))>=70,"REVIEW","FAIL")),"--")))
A33: CRITICAL ISSUES
A34: # | B34: Issue Description | C34: Domain | D34: Owner | E34: Due Date
A35: 1
A36: 2
A37: 3
A38: 4
A39: 5
A41: MANAGEMENT COMMENTARY
A42: [Enter management commentary on endpoint security posture]
A46: APPROVAL
A47: Assessed By
A48: Name:
A49: Date:
...

Sheet Dashboard
A1: Endpoint Security — Compliance Dashboard
A3: Domain | B3: Total Reqs | C3: Compliant | D3: Partial | E3: Non-Compliant | F3: N/A | G3: Compliance % | H3: Unassessed
A4: User Endpoint Devices | B4: =COUNTA('User Endpoint Devices'!A4:A29) | C4: =COUNTIF('User Endpoint Devices'!D4:D29,"Compliant") | D4: =COUNTIF('User Endpoint Devices'!D4:D29,"Partial") | E4: =COUNTIF('User Endpoint Devices'!D4:D29,"Non-Compliant") | F4: =COUNTIF('User Endpoint Devices'!D4:D29,"N/A") | G4: =IF((B4-F4)=0,"N/A",ROUND(C4/(B4-F4)*100,1)&"%") | H4: =B4-(C4+D4+E4+F4)
A5: Malware and Antivirus Prot | B5: =COUNTA('Malware and Antivirus Prot'!A4:A15) | C5: =COUNTIF('Malware and Antivirus Prot'!D4:D15,"Compliant") | D5: =COUNTIF('Malware and Antivirus Prot'!D4:D15,"Partial") | E5: =COUNTIF('Malware and Antivirus Prot'!D4:D15,"Non-Compliant") | F5: =COUNTIF('Malware and Antivirus Prot'!D4:D15,"N/A") | G5: =IF((B5-F5)=0,"N/A",ROUND(C5/(B5-F5)*100,1)&"%") | H5: =B5-(C5+D5+E5+F5)
A6: Education | B6: =COUNTA('Education'!A4:A4) | C6: =COUNTIF('Education'!D4:D4,"Compliant") | D6: =COUNTIF('Education'!D4:D4,"Partial") | E6: =COUNTIF('Education'!D4:D4,"Non-Compliant") | F6: =COUNTIF('Education'!D4:D4,"N/A") | G6: =IF((B6-F6)=0,"N/A",ROUND(C6/(B6-F6)*100,1)&"%") | H6: =B6-(C6+D6+E6+F6)
A7: Privileged Utility Programs | B7: =COUNTA('Privileged Utility Programs'!A4:A9) | C7: =COUNTIF('Privileged Utility Programs'!D4:D9,"Compliant") | D7: =COUNTIF('Privileged Utility Programs'!D4:D9,"Partial") | E7: =COUNTIF('Privileged Utility Programs'!D4:D9,"Non-Compliant") | F7: =COUNTIF('Privileged Utility Programs'!D4:D9,"N/A") | G7: =IF((B7-F7)=0,"N/A",ROUND(C7/(B7-F7)*100,1)&"%") | H7: =B7-(C7+D7+E7+F7)
A8: Installation Software Op | B8: =COUNTA('Installation Software Op'!A4:A14) | C8: =COUNTIF('Installation Software Op'!D4:D14,"Compliant") | D8: =COUNTIF('Installation Software Op'!D4:D14,"Partial") | E8: =COUNTIF('Installation Software Op'!D4:D14,"Non-Compliant") | F8: =COUNTIF('Installation Software Op'!D4:D14,"N/A") | G8: =IF((B8-F8)=0,"N/A",ROUND(C8/(B8-F8)*100,1)&"%") | H8: =B8-(C8+D8+E8+F8)
A9: TOTAL | B9: =SUM(B4:B8) | C9: =SUM(C4:C8) | D9: =SUM(D4:D8) | E9: =SUM(E4:E8) | F9: =SUM(F4:F8) | G9: =IF((B9-F9)=0,"N/A",ROUND(C9/(B9-F9)*100,1)&"%") | H9: =SUM(H4:H8)
A11: COMPLIANCE BY STATUS
A12: Compliant | B12: =C9 | C12: =IF(B9=0,"",ROUND(B12/B9*100,1)&"%")
A13: Partial | B13: =D9 | C13: =IF(B9=0,"",ROUND(B13/B9*100,1)&"%")
A14: Non-Compliant | B14: =E9 | C14: =IF(B9=0,"",ROUND(B14/B9*100,1)&"%")
A15: N/A | B15: =F9 | C15: =IF(B9=0,"",ROUND(B15/B9*100,1)&"%")
A17: TOP GAPS (Manual Entry)
A18: Priority | B18: Domain | C18: Requirement | D18: Owner | E18: Due Date | F18: Status
A30: COMPLIANCE TREND (Manual Entry)
A31: Assessment Date | B31: Overall % | C31: Compliant | D31: Gaps | E31: Assessor | F31: Notes

Sheet User Endpoint Devices
A1: User Endpoint Devices — Compliance Checklist
A2: ISO/IEC 27001:2022 — Controls A.8.1-7-18-19: Endpoint Security
A3: Req # | B3: Section | C3: Requirement | D3: Status | E3: Evidence | F3: Owner | G3: Due Date | H3: Notes
A4: A.8.1-7-18-19-01 | B4: Endpoint Devices | C4: All endpoint devices shall be registered in the asset register before being issued to users. The register shall record the device type, serial number, assigned user, operating system, encryption status, and issue date.
A5: A.8.1-7-18-19-02 | B5: Devices That Are Lost, Stolen, | C5: Devices that are lost, stolen, decommissioned, or reassigned shall be updated in the asset register promptly.
A6: A.8.1-7-18-19-03 | B6: Endpoint Devices | C6: All endpoint devices shall be configured to a documented security baseline before deployment. The baseline shall include:.
A7: A.8.1-7-18-19-04 | B7: The Configuration Baseline | C7: The configuration baseline shall be documented and version-controlled. Baseline standards shall reference vendor hardening guides and CIS Benchmarks. The baseline shall be reviewed at least annually or when significant changes occur to the operating system or threat landscape.
A8: A.8.1-7-18-19-05 | B8: The Following Categories Of Management | C8: The following categories of management tools shall be deployed to support endpoint security:.
A9: A.8.1-7-18-19-06 | B9: Endpoint Devices (Laptops, Desktops, | C9: All endpoint devices (laptops, desktops, mobile devices) shall have full-disk encryption enabled:.
A10: A.8.1-7-18-19-07 | B10: Device Encryption | C10: Device encryption shall not be disabled by the end user.
A11: A.8.1-7-18-19-08 | B11: Recovery Keys | C11: Recovery keys shall be escrowed centrally via MDM (e.g., Jamf Pro, Intune, or equivalent) or equivalent key escrow solution managed by IT. Recovery key access shall be logged and restricted to authorised IT personnel.
A12: A.8.1-7-18-19-09 | B12: Encryption Status | C12: Encryption status shall be verified before the device is approved for use with confidential data.
A13: A.8.1-7-18-19-10 | B13: Lock Automatically After 15 Minutes Of | C13: Devices shall lock automatically after 15 minutes of inactivity. Devices with access to confidential or sensitive personal data shall lock after 5 minutes of inactivity.
A14: A.8.1-7-18-19-11 | B14: Lock Their Devices Manually When Leaving | C14: Users shall lock their devices manually when leaving them unattended (Windows+L, Ctrl+Command+Q, or equivalent).
A15: A.8.1-7-18-19-12 | B15: Authentication (Password, Pin, Or | C15: Authentication (password, PIN, or biometric) shall be required to unlock.
... A29: A.8.1-7-18-19-26 | B29: Be Stated And Enforced Through Technical | C29: If BYOD is not permitted, this shall be stated and enforced through technical controls.

Sheet Malware and Antivirus Prot
A1: Malware and Antivirus Prot — Compliance Checklist
A2: ISO/IEC 27001:2022 — Controls A.8.1-7-18-19: Endpoint Security
A3: Req # | B3: Section | C3: Requirement | D3: Status | E3: Evidence | F3: Owner | G3: Due Date | H3: Notes
A4: A.8.1-7-18-19-27 | B4: Only Organisation-Approved And Licensed | C4: Only organisation-approved and licensed software shall be installed on organisation equipment.
A5: A.8.1-7-18-19-28 | B5: Unauthorised Software, Downloaded | C5: Unauthorised software, downloaded software, freeware, or unapproved utilities shall not be installed.
A6: A.8.1-7-18-19-29 | B6: Malware Protection Software (Endpoint | C6: Malware protection software (endpoint detection and response — EDR, or next-generation antivirus — NGAV, as appropriate to the organisation's risk profile) shall be installed on every device that can run it.
A7: A.8.1-7-18-19-30 | B7: Malware Protection Software | C7: Malware protection software shall:.
A8: A.8.1-7-18-19-31 | B8: Suspected Infections | C8: Suspected infections shall be managed via the Incident Management process. The following events shall trigger an incident report:.
A9: A.8.1-7-18-19-32 | B9: Email Servers And Gateways | C9: Email servers and gateways shall have malware scanning that inspects all inbound and outbound email, including attachments.
A10: A.8.1-7-18-19-33 | B10: Internet Proxies Or Secure Web Gateways | C10: Internet proxies or secure web gateways shall be configured to:.
A11: A.8.1-7-18-19-34 | B11: Allow-Listing And Deny-Listing | C11: Allow-listing and deny-listing shall be deployed to control access to approved and prohibited web resources.
A12: A.8.1-7-18-19-35 | B12: File Integrity Monitoring | C12: File integrity monitoring shall be implemented for system-critical files and files that contain or provide access to personal or confidential data, based on risk and business need.
A13: A.8.1-7-18-19-36 | B13: Autorun And Autoplay | C13: Autorun and autoplay shall be disabled for all removable media.
A14: A.8.1-7-18-19-37 | B14: Removable Media | C14: Removable media shall be automatically scanned for malware when connected.
A15: A.8.1-7-18-19-38 | B15: Only Organisation-Owned, Encrypted | C15: Only organisation-owned, encrypted removable media shall be approved for use with confidential data, in line with the Information Transfer Policy.

Sheet Education
A1: Education — Compliance Checklist
A2: ISO/IEC 27001:2022 — Controls A.8.1-7-18-19: Endpoint Security
A3: Req # | B3: Section | C3: Requirement | D3: Status | E3: Evidence | F3: Owner | G3: Due Date | H3: Notes
A4: A.8.1-7-18-19-39 | B4: Be Educated Periodically As Part Of | C4: Users shall be educated periodically as part of the security awareness programme on:.

Sheet Privileged Utility Programs
A1: Privileged Utility Programs — Compliance Checklist
A2: ISO/IEC 27001:2022 — Controls A.8.1-7-18-19: Endpoint Security
A3: Req # | B3: Section | C3: Requirement | D3: Status | E3: Evidence | F3: Owner | G3: Due Date | H3: Notes
A4: A.8.1-7-18-19-40 | B4: Access To Privileged Utility Programs | C4: Access to privileged utility programs shall be restricted to authorised personnel only, based on the principle of least privilege.
A5: A.8.1-7-18-19-41 | B5: Multi-Factor Authentication | C5: Multi-factor authentication shall be required for accessing privileged utility programs on critical systems.
A6: A.8.1-7-18-19-42 | B6: Execution Of Privileged Utility Programs | C6: All execution of privileged utility programs shall be logged, including the user, timestamp, utility name, and target system.
A7: A.8.1-7-18-19-43 | B7: Privileged Utility Programs That Are Not | C7: Privileged utility programs that are not required for operational purposes shall be removed or disabled.
A8: A.8.1-7-18-19-44 | B8: The Use Of Privileged Utility Programs | C8: The use of privileged utility programs shall be subject to periodic review (at least quarterly) to verify continued business justification.
A9: A.8.1-7-18-19-45 | B9: Maintain A Documented List Of Approved | C9: The organisation shall maintain a documented list of approved privileged utility programs by role.

Sheet Installation Software Op
A1: Installation Software Op — Compliance Checklist
A2: ISO/IEC 27001:2022 — Controls A.8.1-7-18-19: Endpoint Security
A3: Req # | B3: Section | C3: Requirement | D3: Status | E3: Evidence | F3: Owner | G3: Due Date | H3: Notes
A4: A.8.1-7-18-19-46 | B4: Software Installation On Operational | C4: Software installation on operational systems shall be performed only by authorised personnel (IT administrators or designated support staff).
A5: A.8.1-7-18-19-47 | B5: Standard Users | C5: Standard users shall not have local administrator rights. Where elevation is required, a managed privilege escalation mechanism shall be used:.
A6: A.8.1-7-18-19-48 | B6: Privilege Escalations | C6: All privilege escalations shall be logged (user, timestamp, justification, duration, approver).
A7: A.8.1-7-18-19-49 | B7: Software Installations | C7: All software installations shall follow the organisation's change management process, including testing, approval, and documentation.
A8: A.8.1-7-18-19-50 | B8: Only Approved Software From The | C8: Only approved software from the organisation's software catalogue shall be installed. New software requests shall be submitted through a formal approval process.
A9: A.8.1-7-18-19-51 | B9: Operating Systems, Applications, And | C9: Operating systems, applications, and browser software on endpoint devices shall be kept up to date. Security patches shall be applied according to the following timelines:.
A10: A.8.1-7-18-19-52 | B10: Be Tested Before Deployment Using The | C10: Patches shall be tested before deployment using the following approach:.
A11: A.8.1-7-18-19-53 | B11: Patch Failure Handling: If A Patch | C11: Patch failure handling: If a patch causes operational issues in the pilot group, deployment shall be halted, the issue documented, and the vendor contacted. A workaround or compensating control shall be applied until a stable patch is available.
A12: A.8.1-7-18-19-54 | B12: Automatic Updates | C12: Automatic updates shall be enabled for operating systems and supported applications. Devices that have not applied critical patches within the defined timeframe shall be flagged for remediation or restricted from network access.
A13: A.8.1-7-18-19-55 | B13: A Rollback Strategy | C13: A rollback strategy shall be agreed upon before applying updates or installations to operational systems to ensure business continuity if a patch causes issues.
A14: A.8.1-7-18-19-56 | B14: A Record Of All Software Changes | C14: A record of all software changes on operational systems shall be maintained, including the software name, version, date of installation, and the individual who performed the change.
