Workbook

Sheet Instructions & Legend
A1: ISMS-IMP-A.5.32-33.S1 - IP Rights Inventory ISO/IEC 27001:2022 - Control A.5.32: Intellectual Property Rights
A3: Document Information
A4: Document ID | B4: ISMS-IMP-A.5.32-33.S1
A5: Workbook Title | B5: IP Rights Inventory
A6: Control Reference | B6: ISO/IEC 27001:2022 - Control A.5.32: Intellectual Property Rights
A7: Version | B7: 1.0
A8: Assessment Date
A9: Completed By
A10: Organisation
A12: Instructions
A13: 1. Complete IP Asset Inventory — list all intellectual property assets (software, content, data).
A14: 2. Complete IP Protection Assessment — evaluate controls protecting each IP asset.
A15: 3. Complete Third-Party IP Register — document third-party IP in use and licence obligations.
A16: 4. Complete Software License Compliance — verify all software licences are current and compliant.
A17: 5. Complete Gap Analysis — identify IP assets with inadequate protection controls.
A18: 6. Maintain the Evidence Register with licence agreements and protection control evidence.
A19: 7. Obtain final approval and sign-off in the Approval Sign-Off sheet.
A21: Status Legend
A22: Symbol | B22: Status | C22: Description
A23: ✓ | B23: Compliant / Complete | C23: Requirement fully met
A24: ⚠ | B24: Partial / In Progress | C24: Partially met or in progress
A25: ✗ | B25: Non-Compliant / Not Started | C25: Requirement not met
A26: — | B26: Not Applicable | C26: Not applicable to this assessment

Sheet IP Asset Inventory
A1: IP ASSET INVENTORY
A2: Comprehensive register of all organisational intellectual property
A4: IP Asset ID | B4: IP Asset Name | C4: IP Category | D4: Description | E4: IP Owner | F4: Custodian | G4: Legal Protection Status | H4: Business Value | I4: Classification | J4: Creation Date | K4: Last Review | L4: Notes
A5: IP-001 | B5: Customer Analytics Algorithm | C5: Trade Secret | D5: Proprietary algorithm for customer churn prediction | E5: Chief Data Officer | F5: Analytics Team Lead | G5: Registered | H5: High | I5: Restricted | J5: 2023-01-15 | K5: 2025-01-15 | L5: Annual review completed

Sheet IP Protection Assessment
A1: IP PROTECTION ASSESSMENT
A2: Protection controls assessment for each IP asset
A4: IP Asset ID | B4: IP Asset Name | C4: Access Control | D4: Technical Controls | E4: Administrative Controls | F4: Physical Controls | G4: Legal Protection | H4: Control Effectiveness | I4: Gap Description | J4: Remediation Needed | K4: Status
A5: IP-001 | B5: Customer Analytics Algorithm | C5: Role-based access, need-to-know basis | D5: Encryption at rest, code obfuscation | E5: NDA for all staff with access | F5: Secure server room, access cards | G5: Trade secret protection registered | H5: Effective | K5: Complete

Sheet Third-Party IP Register
A1: THIRD-PARTY IP REGISTER
A2: Licensed software, content, and third-party intellectual property
A4: Third-Party IP ID | B4: Software/Content Name | C4: Vendor | D4: License Type | E4: License Quantity | F4: Deployed Quantity | G4: Compliance Status | H4: Contract Reference | I4: Renewal Date | J4: Open Source License | K4: Notes
A5: TP-001 | B5: Microsoft 365 | C5: Microsoft | D5: Subscription | E5: 500 | F5: 487 | G5: Compliant | H5: MSA-2024-001 | I5: 2026-12-31 | J5: N/A | K5: Enterprise agreement, includes Teams

Sheet Software License Compliance
A1: SOFTWARE LICENSE COMPLIANCE
A2: License entitlement vs deployment reconciliation
A4: Software Name | B4: Vendor | C4: License Model | D4: Entitled | E4: Deployed | F4: Variance | G4: Compliance Risk | H4: Remediation Action | I4: Due Date | J4: Status
A5: Microsoft Windows Server | B5: Microsoft | C5: Per Core | D5: 48 | E5: 48 | F5: 0 | G5: None | H5: No action required — fully licensed | I5: N/A | J5: Complete
F6: =IF(AND(D6<>"",E6<>""),E6-D6,"")
F7: =IF(AND(D7<>"",E7<>""),E7-D7,"")
F8: =IF(AND(D8<>"",E8<>""),E8-D8,"")
F9: =IF(AND(D9<>"",E9<>""),E9-D9,"")
F10: =IF(AND(D10<>"",E10<>""),E10-D10,"")
F11: =IF(AND(D11<>"",E11<>""),E11-D11,"")
F12: =IF(AND(D12<>"",E12<>""),E12-D12,"")
F13: =IF(AND(D13<>"",E13<>""),E13-D13,"")
F14: =IF(AND(D14<>"",E14<>""),E14-D14,"")
F15: =IF(AND(D15<>"",E15<>""),E15-D15,"")
F16: =IF(AND(D16<>"",E16<>""),E16-D16,"")
F17: =IF(AND(D17<>"",E17<>""),E17-D17,"")
... F55: =IF(AND(D55<>"",E55<>""),E55-D55,"")

Sheet Gap Analysis
A1: GAP ANALYSIS
A2: Identified protection and compliance gaps with remediation tracking
A4: Gap ID | B4: Gap Category | C4: Description | D4: Related IP | E4: Risk Rating | F4: Remediation Action | G4: Owner | H4: Due Date | I4: Status | J4: Notes
A5: GAP-001 | B5: Compliance | C5: Two software titles deployed without valid licence | D5: TP-002 Adobe Creative Cloud | E5: High | F5: Purchase 2 additional licences immediately | G5: Procurement Manager | H5: 2026-03-15 | I5: Open | J5: Urgent — licence audit finding

Sheet Evidence Register
A1: EVIDENCE REGISTER
A2: Audit evidence supporting IP protection assessment
A4: Evidence ID | B4: Description | C4: Evidence Type | D4: Related Item | E4: Storage Location | F4: Collected Date | G4: Collected By | H4: Verification Status
A5: EV-001 | B5: IP asset inventory register review | C5: Document | D5: IP Asset Inventory | E5: /evidence/ip-rights/asset-register-2026.xlsx | F5: 2026-02-01 | G5: Legal Counsel | H5: Verified

Sheet Summary Dashboard
A1: IP RIGHTS INVENTORY — SUMMARY DASHBOARD
A2: ISO/IEC 27001:2022 — Control A.5.32: Intellectual Property Rights
A4: TABLE 1: ASSESSMENT AREA COMPLIANCE OVERVIEW
A5: Assessment Area | B5: Total Items | C5: Compliant | D5: Partial | E5: Non-Compliant | F5: N/A | G5: Compliance %
A6: IP Asset Inventory | B6: =COUNTA('IP Asset Inventory'!B6:B55) | C6: =COUNTIF('IP Asset Inventory'!G6:G55,"Registered") | D6: =COUNTIF('IP Asset Inventory'!G6:G55,"Pending") | E6: =COUNTIF('IP Asset Inventory'!G6:G55,"Unregistered") | F6: =COUNTIF('IP Asset Inventory'!G6:G55,"N/A") | G6: =IFERROR(IF((B6-F6)=0,0,C6/(B6-F6)),"")
A7: IP Protection Assessment | B7: =COUNTA('IP Protection Assessment'!B6:B55) | C7: =COUNTIF('IP Protection Assessment'!H6:H55,"Effective") | D7: =COUNTIF('IP Protection Assessment'!H6:H55,"Partial") | E7: =COUNTIF('IP Protection Assessment'!H6:H55,"Ineffective") | F7: 0 | G7: =IFERROR(IF((B7-F7)=0,0,C7/(B7-F7)),"")
A8: Third-Party IP Register | B8: =COUNTA('Third-Party IP Register'!B6:B55) | C8: =COUNTIF('Third-Party IP Register'!G6:G55,"Compliant") | D8: =COUNTIF('Third-Party IP Register'!G6:G55,"Under-utilised") | E8: =COUNTIF('Third-Party IP Register'!G6:G55,"Over-deployed") | F8: 0 | G8: =IFERROR(IF((B8-F8)=0,0,C8/(B8-F8)),"")
A9: Software License Compliance | B9: =COUNTA('Software License Compliance'!A6:A55) | C9: =COUNTIF('Software License Compliance'!J6:J55,"Complete") | D9: =COUNTIF('Software License Compliance'!J6:J55,"In Progress") | E9: =COUNTIF('Software License Compliance'!J6:J55,"Open") | F9: =COUNTIF('Software License Compliance'!J6:J55,"N/A") | G9: =IFERROR(IF((B9-F9)=0,0,C9/(B9-F9)),"")
A10: TOTAL | B10: =SUM(B6:B9) | C10: =SUM(C6:C9) | D10: =SUM(D6:D9) | E10: =SUM(E6:E9) | F10: =SUM(F6:F9) | G10: =IFERROR(IF((B10-F10)=0,0,C10/(B10-F10)),"")
A12: TABLE 2: KEY METRICS
A13: Metric | B13: Value
A14: IP Asset Inventory Metrics
A15: Total IP Assets Documented | B15: =COUNTA('IP Asset Inventory'!B6:B55)
A16: High Business Value Assets | B16: =COUNTIF('IP Asset Inventory'!H6:H55,"High")
A17: Registered (Protected) IP Assets | B17: =COUNTIF('IP Asset Inventory'!G6:G55,"Registered")
A18: Pending Registration | B18: =COUNTIF('IP Asset Inventory'!G6:G55,"Pending")
A19: Unregistered (At Risk) Assets | B19: =COUNTIF('IP Asset Inventory'!G6:G55,"Unregistered")
A20: Trade Secrets Documented | B20: =COUNTIF('IP Asset Inventory'!C6:C55,"Trade Secret")
A21: Restricted Classification Assets | B21: =COUNTIF('IP Asset Inventory'!I6:I55,"Restricted")
A22: IP Protection Assessment Metrics
A23: Total Assessments | B23: =COUNTA('IP Protection Assessment'!B6:B55)
A24: Controls Rated Effective | B24: =COUNTIF('IP Protection Assessment'!H6:H55,"Effective")
A25: Controls Partially Effective | B25: =COUNTIF('IP Protection Assessment'!H6:H55,"Partial")
A26: Remediation Completed | B26: =COUNTIF('IP Protection Assessment'!K6:K55,"Complete")
A27: Remediation In Progress | B27: =COUNTIF('IP Protection Assessment'!K6:K55,"In Progress")
A28: Third-Party IP Metrics
A29: Total Third-Party IP Items | B29: =COUNTA('Third-Party IP Register'!B6:B55)
A30: License Compliant Items | B30: =COUNTIF('Third-Party IP Register'!G6:G55,"Compliant")
A31: Over-Deployed Licenses | B31: =COUNTIF('Third-Party IP Register'!G6:G55,"Over-deployed")
A32: Open Source Components | B32: =COUNTIF('Third-Party IP Register'!D6:D55,"Open Source")
A33: Subscription Licenses | B33: =COUNTIF('Third-Party IP Register'!D6:D55,"Subscription")
A34: Software License Metrics
A35: Total Software Items Tracked | B35: =COUNTA('Software License Compliance'!A6:A55)
A36: High Compliance Risk Items | B36: =COUNTIF('Software License Compliance'!G6:G55,"High")
A37: Remediations Open | B37: =COUNTIF('Software License Compliance'!J6:J55,"Open")
A41: TABLE 3: CRITICAL FINDINGS REQUIRING IMMEDIATE ATTENTION
A42: Category | B42: Finding | C42: Count | D42: Severity | E42: Action Required
A43: IP Asset Inventory | B43: Unregistered high-value IP assets | C43: =COUNTIFS('IP Asset Inventory'!G6:G55,"Unregistered",'IP Asset Inventory'!H6:H55,"High") | D43: Critical | E43: Immediate
A44: IP Asset Inventory | B44: Restricted assets without registration | C44: =COUNTIFS('IP Asset Inventory'!I6:I55,"Restricted",'IP Asset Inventory'!G6:G55,"Unregistered") | D44: Critical | E44: Immediate
A45: IP Protection Assessment | B45: Ineffective protection controls | C45: =COUNTIF('IP Protection Assessment'!H6:H55,"Ineffective") | D45: Critical | E45: Immediate
...

Sheet Approval Sign-Off
A1: ASSESSMENT APPROVAL AND SIGN-OFF
A2: ISO/IEC 27001:2022 - Control A.5.32: Intellectual Property Rights
A3: ASSESSMENT SUMMARY
A4: Document: | B4: ISMS-IMP-A.5.32-33.S1 - IP Rights Inventory
A5: Assessment Period:
A6: Overall Compliance Rating: | B6: =IFERROR(AVERAGE('Summary Dashboard'!G6:G9),"")
A7: Assessment Status:
A8: Assessed By:
A11: COMPLETED BY (ASSESSOR)
A12: Name:
A13: Title:
A14: Date:
A15: Signature:
A16: Comments:
A18: REVIEWED BY (INFORMATION SECURITY OFFICER)
A19: Name:
A20: Title:
A21: Date:
... A38: Special Considerations:
