Workbook

Sheet Instructions & Legend
A1: ISMS-IMP-A.5.32-33.S3 - Retention Disposal Schedule ISO/IEC 27001:2022 - Control A.5.33: Protection of Records
A3: Document Information
A4: Document ID | B4: ISMS-IMP-A.5.32-33.S3
A5: Workbook Title | B5: Retention Disposal Schedule
A6: Control Reference | B6: ISO/IEC 27001:2022 - Control A.5.33: Protection of Records
A7: Version | B7: 1.0
A8: Assessment Date
A9: Completed By
A10: Organisation
A12: Instructions
A13: 1. Complete Retention Schedule — document retention periods for all records categories.
A14: 2. Complete Regulatory Mapping — align retention periods to legal and regulatory requirements.
A15: 3. Review Disposal Queue — identify records past their retention period requiring disposal.
A16: 4. Complete Disposal Method Matrix — map record types to approved disposal methods.
A17: 5. Complete Destruction Verification — document disposal with certificates of destruction.
A18: 6. Complete Exception Register — record any records retained beyond standard periods with justification.
A19: 7. Complete Gap Analysis — identify retention or disposal process gaps.
A20: 8. Maintain the Evidence Register with retention schedules and disposal records.
... A23: Status Legend
A24: Symbol | B24: Status | C24: Description
A25: ✓ | B25: Compliant / Complete | C25: Requirement fully met
A26: ⚠ | B26: Partial / In Progress | C26: Partially met or in progress
A27: ✗ | B27: Non-Compliant / Not Started | C27: Requirement not met
A28: — | B28: Not Applicable | C28: Not applicable to this assessment

Sheet Retention Schedule
A1: RETENTION SCHEDULE
A2: Retention periods for all record categories
A4: Record Category ID | B4: Category Name | C4: Retention Period | D4: Retention Basis | E4: Basis Detail | F4: Retention Trigger | G4: Grace Period | H4: Review Cycle | I4: Last Review | J4: Next Review | K4: Notes
A5: REC-001 | B5: Financial Ledgers | C5: 10 years | D5: Regulatory | E5: Swiss CO Art. 958f | F5: Year-End | G5: 90 days | H5: Annual | I5: 2025-12-31 | J5: 2026-12-31 | K5: Mandatory regulatory retention

Sheet Regulatory Mapping
A1: REGULATORY MAPPING
A2: Regulations driving record retention requirements
A4: Regulation ID | B4: Regulation Name | C4: Section/Article | D4: Record Types Affected | E4: Required Retention | F4: Retention Trigger | G4: Penalty for Non-Compliance | H4: Last Review | I4: Reviewer | J4: Notes
A5: REG-001 | B5: Swiss Code of Obligations | C5: Art. 958f | D5: Bookkeeping, financial records | E5: 10 years | F5: Fiscal year end | G5: Administrative fines, audit findings | H5: 2026-01-01 | I5: Legal Counsel | J5: Core financial records retention

Sheet Disposal Queue
A1: DISPOSAL QUEUE
A2: Records due or approaching disposal date
A4: Queue ID | B4: Record Category | C4: Retention End Date | D4: Volume - Physical | E4: Volume - Electronic | F4: Legal Hold Status | G4: Disposal Priority | H4: Target Disposal Date | I4: Assigned To | J4: Status | K4: Notes
A5: DQ-001 | B5: Financial Ledgers 2015 | C5: 2025-12-31 | D5: 3 archive boxes | E5: 2.4 GB | F5: No | G5: High | H5: 2026-03-31 | I5: Records Manager | J5: Pending | K5: 10-year retention period expired

Sheet Disposal Method Matrix
A1: DISPOSAL METHOD MATRIX
A2: Appropriate disposal methods by classification level
A4: Classification | B4: Physical - Paper | C4: Physical - Media | D4: Electronic - On-Prem | E4: Electronic - Cloud | F4: Verification Required | G4: Approved Vendors | H4: Special Handling
A5: Restricted | B5: Cross-cut P-5, witnessed incineration | C5: Degaussing + physical destruction | D5: NIST 800-88 Rev. 2 Purge, cryptographic erasure | E5: Provider purge + verification certificate | F5: Certificate of destruction, witness signature | G5: [List approved vendors] | H5: Witnessed destruction required
A6: Confidential | B6: Cross-cut shredding P-4 | C6: Degaussing or physical destruction | D6: NIST 800-88 Rev. 2 Clear, secure deletion | E6: Provider deletion + confirmation | F6: Certificate of destruction | G6: [List approved vendors] | H6: Batch processing acceptable
A7: Internal | B7: Standard shredding P-3 | C7: Standard deletion or physical destruction | D7: Secure deletion with verification | E7: Standard deletion | F7: Disposal log entry | G7: Internal IT or approved vendor | H7: Standard process
A8: Public | B8: Recycling acceptable | C8: Standard disposal or recycling | D8: Standard deletion | E8: Standard deletion | F8: Disposal log entry | G8: Any certified recycler | H8: No special requirements

Sheet Destruction Verification
A1: DESTRUCTION VERIFICATION
A2: Evidence of secure record destruction
A4: Destruction ID | B4: Record Category | C4: Volume | D4: Destruction Date | E4: Method Used | F4: Performed By | G4: Witness | H4: Certificate Reference | I4: Storage Location | J4: Verification Status
A5: DEST-001 | B5: Financial Ledgers 2014 | C5: 3 archive boxes | D5: 2026-01-15 | E5: Cross-cut shredding P-4, witnessed | F5: Secure Shredding GmbH | G5: Records Manager | H5: CERT-2026-001 | I5: /evidence/destruction/cert-2026-001.pdf | J5: Verified

Sheet Exception Register
A1: EXCEPTION REGISTER
A2: Retention extensions and early disposals
A4: Exception ID | B4: Exception Type | C4: Record Category | D4: Original Retention | E4: New Retention | F4: Reason | G4: Requested By | H4: Approved By | I4: Approval Date | J4: Expiration | K4: Status
A5: EXC-001 | B5: Extension | C5: Personnel Files — Former Employees | D5: Employment + 10 years | E5: Employment + 15 years | F5: Ongoing litigation requires extended retention | G5: Legal Counsel | H5: CISO | I5: 2025-09-01 | J5: 2030-12-31 | K5: Active

Sheet Gap Analysis
A1: GAP ANALYSIS
A2: Identified retention and disposal issues
A4: Gap ID | B4: Gap Category | C4: Description | D4: Related Item | E4: Risk Rating | F4: Remediation Action | G4: Owner | H4: Due Date | I4: Status
A5: GAP-001 | B5: Disposal | C5: 12 record categories have no documented disposal method | D5: Disposal Method Matrix | E5: High | F5: Define disposal methods for all record categories in matrix | G5: Records Manager | H5: 2026-04-15 | I5: Open

Sheet Evidence Register
A1: EVIDENCE REGISTER
A2: Audit evidence supporting retention and disposal
A4: Evidence ID | B4: Description | C4: Evidence Type | D4: Related Item | E4: Storage Location | F4: Collected Date | G4: Collected By | H4: Verification Status
A5: EV-001 | B5: Certificate of destruction — Financial Ledgers 2014 | C5: Certificate | D5: Destruction Verification DEST-001 | E5: /evidence/destruction/cert-2026-001.pdf | F5: 2026-01-15 | G5: Records Manager | H5: Verified

Sheet Summary Dashboard
A1: RETENTION DISPOSAL SCHEDULE — SUMMARY DASHBOARD
A2: ISO/IEC 27001:2022 — Control A.5.33: Protection of Records — Retention & Disposal
A4: TABLE 1: ASSESSMENT AREA COMPLIANCE OVERVIEW
A5: Assessment Area | B5: Total Items | C5: Compliant | D5: Partial | E5: Non-Compliant | F5: N/A | G5: Compliance %
A6: Retention Schedule | B6: =COUNTA('Retention Schedule'!B6:B55) | C6: =COUNTIF('Retention Schedule'!H6:H55,"Annual") | D6: =COUNTIF('Retention Schedule'!H6:H55,"Biennial") | E6: =COUNTIF('Retention Schedule'!H6:H55,"Triennial") | F6: 0 | G6: =IFERROR(IF((B6-F6)=0,0,C6/(B6-F6)),"")
A7: Disposal Queue | B7: =COUNTA('Disposal Queue'!B6:B55) | C7: =COUNTIF('Disposal Queue'!J6:J55,"Complete") | D7: =COUNTIF('Disposal Queue'!J6:J55,"In Progress") | E7: =COUNTIF('Disposal Queue'!J6:J55,"Pending") | F7: =COUNTIF('Disposal Queue'!J6:J55,"On Hold") | G7: =IFERROR(IF((B7-F7)=0,0,C7/(B7-F7)),"")
A8: Destruction Verification | B8: =COUNTA('Destruction Verification'!B6:B55) | C8: =COUNTIF('Destruction Verification'!J6:J55,"Verified") | D8: =COUNTIF('Destruction Verification'!J6:J55,"Pending") | E8: =COUNTIF('Destruction Verification'!J6:J55,"Not Verified") | F8: 0 | G8: =IFERROR(IF((B8-F8)=0,0,C8/(B8-F8)),"")
A9: Exception Register | B9: =COUNTA('Exception Register'!B6:B55) | C9: =COUNTIF('Exception Register'!K6:K55,"Expired")+COUNTIF('Exception Register'!K6:K55,"Cancelled") | D9: 0 | E9: =COUNTIF('Exception Register'!K6:K55,"Active") | F9: 0 | G9: =IFERROR(IF((B9-F9)=0,0,C9/(B9-F9)),"")
A10: TOTAL | B10: =SUM(B6:B9) | C10: =SUM(C6:C9) | D10: =SUM(D6:D9) | E10: =SUM(E6:E9) | F10: =SUM(F6:F9) | G10: =IFERROR(IF((B10-F10)=0,0,C10/(B10-F10)),"")
A12: TABLE 2: KEY METRICS
A13: Metric | B13: Value
A14: Retention Schedule Metrics
A15: Total Record Categories Scheduled | B15: =COUNTA('Retention Schedule'!B6:B55)
A16: Regulatory-Driven Retention | B16: =COUNTIF('Retention Schedule'!D6:D55,"Regulatory")
A17: Contractual Retention | B17: =COUNTIF('Retention Schedule'!D6:D55,"Contractual")
A18: Annual Review Cycle | B18: =COUNTIF('Retention Schedule'!H6:H55,"Annual")
A19: Biennial or Longer Review Cycle | B19: =COUNTIF('Retention Schedule'!H6:H55,"Biennial")+COUNTIF('Retention Schedule'!H6:H55,"Triennial")
A20: Disposal Queue Metrics
A21: Total Items in Disposal Queue | B21: =COUNTA('Disposal Queue'!B6:B55)
A22: Disposals Complete | B22: =COUNTIF('Disposal Queue'!J6:J55,"Complete")
A23: Disposals Pending | B23: =COUNTIF('Disposal Queue'!J6:J55,"Pending")
A24: Items on Legal Hold | B24: =COUNTIF('Disposal Queue'!F6:F55,"Yes")
A25: High Priority Disposals | B25: =COUNTIF('Disposal Queue'!G6:G55,"High")
A26: Destruction Verification Metrics
A27: Total Destruction Records | B27: =COUNTA('Destruction Verification'!B6:B55)
A28: Verified Destructions | B28: =COUNTIF('Destruction Verification'!J6:J55,"Verified")
A29: Pending Verifications | B29: =COUNTIF('Destruction Verification'!J6:J55,"Pending")
A30: Not Verified | B30: =COUNTIF('Destruction Verification'!J6:J55,"Not Verified")
A31: Exception Register Metrics
A32: Active Exceptions | B32: =COUNTIF('Exception Register'!K6:K55,"Active")
A33: Retention Extensions | B33: =COUNTIF('Exception Register'!B6:B55,"Extension")
A34: Early Disposals | B34: =COUNTIF('Exception Register'!B6:B55,"Early Disposal")
A38: TABLE 3: CRITICAL FINDINGS REQUIRING IMMEDIATE ATTENTION
A39: Category | B39: Finding | C39: Count | D39: Severity | E39: Action Required
A40: Disposal Queue | B40: Overdue (pending) disposals | C40: =COUNTIF('Disposal Queue'!J6:J55,"Pending") | D40: Critical | E40: Immediate
A41: Disposal Queue | B41: High priority outstanding disposals | C41: =COUNTIFS('Disposal Queue'!G6:G55,"High",'Disposal Queue'!J6:J55,"Pending") | D41: Critical | E41: Immediate
A42: Destruction Verification | B42: Destructions not verified | C42: =COUNTIF('Destruction Verification'!J6:J55,"Not Verified") | D42: Critical | E42: Immediate
A43: Destruction Verification | B43: Verifications pending | C43: =COUNTIF('Destruction Verification'!J6:J55,"Pending") | D43: High | E43: Urgent
A44: Exception Register | B44: Active exceptions requiring review | C44: =COUNTIF('Exception Register'!K6:K55,"Active") | D44: High | E44: Urgent
A45: Disposal Queue | B45: Items with legal hold — disposal blocked | C45: =COUNTIF('Disposal Queue'!F6:F55,"Yes") | D45: High | E45: Monitor
...

Sheet Approval Sign-Off
A1: ASSESSMENT APPROVAL AND SIGN-OFF
A2: ISO/IEC 27001:2022 - Control A.5.33: Protection of Records
A3: ASSESSMENT SUMMARY
A4: Document: | B4: ISMS-IMP-A.5.32-33.S3 - Retention Disposal Schedule
A5: Assessment Period:
A6: Overall Compliance Rating: | B6: =IFERROR(AVERAGE('Summary Dashboard'!G6:G9),"")
A7: Assessment Status:
A8: Assessed By:
A11: COMPLETED BY (ASSESSOR)
A12: Name:
A13: Title:
A14: Date:
A15: Signature:
A16: Comments:
A18: REVIEWED BY (INFORMATION SECURITY OFFICER)
A19: Name:
A20: Title:
A21: Date:
... A38: Special Considerations:
