Workbook

Sheet Instructions & Legend
A1: ISMS-IMP-A.5.32-33.S2 - Records Protection Assessment ISO/IEC 27001:2022 - Control A.5.33: Protection of Records
A3: Document Information
A4: Document ID | B4: ISMS-IMP-A.5.32-33.S2
A5: Workbook Title | B5: Records Protection Assessment
A6: Control Reference | B6: ISO/IEC 27001:2022 - Control A.5.33: Protection of Records
A7: Version | B7: 1.0
A8: Assessment Date
A9: Completed By
A10: Organisation
A12: Instructions
A13: 1. Complete Records Category Inventory — classify all records by type and retention requirement.
A14: 2. Complete Protection Controls — assess controls protecting records (access, encryption, backup).
A15: 3. Complete Integrity Verification — verify records integrity controls (checksums, audit trails).
A16: 4. Complete Access Control Review — confirm only authorised personnel can access sensitive records.
A17: 5. Complete Legal Hold Register — track records under legal hold with hold dates and reasons.
A18: 6. Complete Backup Verification — confirm records are included in backup and restoration is tested.
A19: 7. Complete Gap Analysis — identify categories with insufficient protection.
A20: 8. Maintain the Evidence Register with protection assessments and test results.
... A23: Status Legend
A24: Symbol | B24: Status | C24: Description
A25: ✓ | B25: Compliant / Complete | C25: Requirement fully met
A26: ⚠ | B26: Partial / In Progress | C26: Partially met or in progress
A27: ✗ | B27: Non-Compliant / Not Started | C27: Requirement not met
A28: — | B28: Not Applicable | C28: Not applicable to this assessment

Sheet Records Category Inventory
A1: RECORDS CATEGORY INVENTORY
A2: Comprehensive register of all record categories requiring protection
A4: Record Category ID | B4: Category Name | C4: Record Type | D4: Description | E4: Custodian Department | F4: Storage Location | G4: Format | H4: Retention Requirement | I4: Confidentiality | J4: Integrity Requirement | K4: Availability Requirement | L4: Notes
A5: REC-001 | B5: Financial Ledgers | C5: Financial | D5: General ledger, sub-ledgers, journal entries | E5: Finance | F5: SAP ERP, Archive Server | G5: Electronic | H5: Swiss CO Art. 958f - 10 years | I5: Confidential | J5: Critical | K5: Business Critical | L5: Integrity critical for audit

Sheet Protection Controls
A1: PROTECTION CONTROLS ASSESSMENT
A2: Confidentiality, integrity, and availability controls per record category
A4: Record Category ID | B4: Category Name | C4: Confidentiality Controls | D4: Integrity Controls | E4: Availability Controls | F4: Physical Controls | G4: Control Effectiveness | H4: Gap Description | I4: Remediation Needed | J4: Status
A5: REC-001 | B5: Financial Ledgers | C5: AES-256 encryption, role-based access, MFA required | D5: Digital signatures, WORM storage, daily integrity checks | E5: 99.9% SLA, geo-redundant backup, 4-hour RTO | F5: Server room physical controls, CCTV | G5: Effective | J5: Complete

Sheet Integrity Verification
A1: INTEGRITY VERIFICATION
A2: Testing and verification of record integrity mechanisms
A4: Test ID | B4: Record Category | C4: Integrity Mechanism | D4: Test Date | E4: Test Performed | F4: Expected Result | G4: Actual Result | H4: Status | I4: Issues | J4: Remediation
A5: INT-001 | B5: Financial Ledgers | C5: Digital Signature | D5: 2026-01-15 | E5: SHA-256 hash verification of all ledger entries | F5: All hashes match baseline | G5: All hashes match baseline | H5: Pass

Sheet Access Control Review
A1: ACCESS CONTROL REVIEW
A2: Assessment of access controls for record storage systems
A4: System Name | B4: Record Categories | C4: Access Control Type | D4: User Count | E4: Privileged Users | F4: Last Access Review | G4: Access Logging | H4: Log Retention | I4: Issues | J4: Remediation | K4: Status
A5: SAP ERP | B5: Financial Ledgers, Personnel Records | C5: RBAC | D5: 245 | E5: 8 | F5: 2026-01-01 | G5: Yes | H5: 7 years | K5: Compliant

Sheet Legal Hold Register
A1: LEGAL HOLD REGISTER
A2: Litigation and investigation holds affecting record retention
A4: Hold ID | B4: Matter Name | C4: Legal Counsel | D4: Effective Date | E4: Record Categories | F4: Custodians Notified | G4: Notification Date | H4: Release Date | I4: Status | J4: Notes
A5: LH-001 | B5: Supplier Contract Dispute 2025 | C5: Dr. Anna Fischer | D5: 2025-06-01 | E5: Financial Ledgers, Contract Records | F5: Finance Director, Legal Team | G5: 2025-06-02 | I5: Active | J5: All custodians acknowledged hold notice

Sheet Backup Verification
A1: BACKUP VERIFICATION
A2: Backup and recovery verification for records availability
A4: Record Category | B4: Backup System | C4: Backup Frequency | D4: Backup Location | E4: Last Backup Date | F4: Last Verification | G4: Last Recovery Test | H4: RTO Target | I4: RTO Achieved | J4: RPO Target | K4: RPO Achieved | L4: Status | M4: Issues
A5: Financial Ledgers | B5: Veeam Backup & Replication | C5: Daily | D5: Secondary DC (Geneva) + Azure Blob | E5: 2026-02-22 | F5: 2026-02-22 | G5: 2026-01-15 | H5: 4 hours | I5: 2.5 hours | J5: 1 hour | K5: 45 minutes | L5: Compliant

Sheet Gap Analysis
A1: GAP ANALYSIS
A2: Identified protection gaps with remediation tracking
A4: Gap ID | B4: Gap Category | C4: Description | D4: Related Record Category | E4: Risk Rating | F4: Remediation Action | G4: Owner | H4: Due Date | I4: Status | J4: Notes
A5: GAP-001 | B5: Integrity | C5: Backup server logs not protected against tampering | D5: Security Audit Logs | E5: High | F5: Implement WORM storage for backup log repository | G5: IT Operations Manager | H5: 2026-04-01 | I5: Open | J5: Log integrity critical for audit trail

Sheet Evidence Register
A1: EVIDENCE REGISTER
A2: Audit evidence supporting records protection assessment
A4: Evidence ID | B4: Description | C4: Evidence Type | D4: Related Item | E4: Storage Location | F4: Collected Date | G4: Collected By | H4: Verification Status
A5: EV-001 | B5: Records protection controls review | C5: Document | D5: Protection Controls | E5: /evidence/records/protection-controls-review-2026.pdf | F5: 2026-02-01 | G5: Records Manager | H5: Verified

Sheet Summary Dashboard
A1: RECORDS PROTECTION ASSESSMENT — SUMMARY DASHBOARD
A2: ISO/IEC 27001:2022 — Control A.5.33: Protection of Records
A4: TABLE 1: ASSESSMENT AREA COMPLIANCE OVERVIEW
A5: Assessment Area | B5: Total Items | C5: Compliant | D5: Partial | E5: Non-Compliant | F5: N/A | G5: Compliance %
A6: Records Category Inventory | B6: =COUNTA('Records Category Inventory'!B6:B55) | C6: =COUNTIF('Records Category Inventory'!I6:I55,"Restricted")+COUNTIF('Records Category Inventory'!I6:I55,"Confidential") | D6: =COUNTIF('Records Category Inventory'!I6:I55,"Internal") | E6: =COUNTIF('Records Category Inventory'!I6:I55,"Public") | F6: 0 | G6: =IFERROR(IF((B6-F6)=0,0,C6/(B6-F6)),"")
A7: Protection Controls | B7: =COUNTA('Protection Controls'!B6:B55) | C7: =COUNTIF('Protection Controls'!G6:G55,"Effective") | D7: =COUNTIF('Protection Controls'!G6:G55,"Partial") | E7: =COUNTIF('Protection Controls'!G6:G55,"Ineffective") | F7: 0 | G7: =IFERROR(IF((B7-F7)=0,0,C7/(B7-F7)),"")
A8: Integrity Verification | B8: =COUNTA('Integrity Verification'!B6:B55) | C8: =COUNTIF('Integrity Verification'!H6:H55,"Pass") | D8: =COUNTIF('Integrity Verification'!H6:H55,"Partial") | E8: =COUNTIF('Integrity Verification'!H6:H55,"Fail") | F8: =COUNTIF('Integrity Verification'!H6:H55,"Not Tested") | G8: =IFERROR(IF((B8-F8)=0,0,C8/(B8-F8)),"")
A9: Access Control Review | B9: =COUNTA('Access Control Review'!A6:A55) | C9: =COUNTIF('Access Control Review'!K6:K55,"Compliant") | D9: =COUNTIF('Access Control Review'!K6:K55,"Partial") | E9: =COUNTIF('Access Control Review'!K6:K55,"Non-Compliant") | F9: 0 | G9: =IFERROR(IF((B9-F9)=0,0,C9/(B9-F9)),"")
A10: Backup Verification | B10: =COUNTA('Backup Verification'!A6:A55) | C10: =COUNTIF('Backup Verification'!L6:L55,"Compliant") | D10: 0 | E10: =COUNTIF('Backup Verification'!L6:L55,"Non-Compliant") | F10: 0 | G10: =IFERROR(IF((B10-F10)=0,0,C10/(B10-F10)),"")
A11: TOTAL | B11: =SUM(B6:B10) | C11: =SUM(C6:C10) | D11: =SUM(D6:D10) | E11: =SUM(E6:E10) | F11: =SUM(F6:F10) | G11: =IFERROR(IF((B11-F11)=0,0,C11/(B11-F11)),"")
A13: TABLE 2: KEY METRICS
A14: Metric | B14: Value
A15: Records Inventory Metrics
A16: Total Record Categories | B16: =COUNTA('Records Category Inventory'!B6:B55)
A17: Financial Records | B17: =COUNTIF('Records Category Inventory'!C6:C55,"Financial")
A18: Personnel Records | B18: =COUNTIF('Records Category Inventory'!C6:C55,"Personnel")
A19: Critical Integrity Requirement | B19: =COUNTIF('Records Category Inventory'!J6:J55,"Critical")
A20: Mission Critical Availability | B20: =COUNTIF('Records Category Inventory'!K6:K55,"Mission Critical")
A21: Electronic Records | B21: =COUNTIF('Records Category Inventory'!G6:G55,"Electronic")
A22: Protection Control Metrics
A23: Total Controls Assessed | B23: =COUNTA('Protection Controls'!B6:B55)
A24: Effective Controls | B24: =COUNTIF('Protection Controls'!G6:G55,"Effective")
A25: Ineffective Controls | B25: =COUNTIF('Protection Controls'!G6:G55,"Ineffective")
A26: Integrity and Access Metrics
A27: Integrity Tests Passed | B27: =COUNTIF('Integrity Verification'!H6:H55,"Pass")
A28: Integrity Tests Failed | B28: =COUNTIF('Integrity Verification'!H6:H55,"Fail")
A29: Systems with Access Logging | B29: =COUNTIF('Access Control Review'!G6:G55,"Yes")
A30: Non-Compliant Access Controls | B30: =COUNTIF('Access Control Review'!K6:K55,"Non-Compliant")
A31: Legal Hold and Backup Metrics
A32: Active Legal Holds | B32: =COUNTIF('Legal Hold Register'!I6:I55,"Active")
A33: Released Legal Holds | B33: =COUNTIF('Legal Hold Register'!I6:I55,"Released")
A34: Daily Backup Frequency Systems | B34: =COUNTIF('Backup Verification'!C6:C55,"Daily")
A35: Backup Non-Compliant | B35: =COUNTIF('Backup Verification'!L6:L55,"Non-Compliant")
A39: TABLE 3: CRITICAL FINDINGS REQUIRING IMMEDIATE ATTENTION
A40: Category | B40: Finding | C40: Count | D40: Severity | E40: Action Required
A41: Protection Controls | B41: Ineffective CIA controls | C41: =COUNTIF('Protection Controls'!G6:G55,"Ineffective") | D41: Critical | E41: Immediate
A42: Integrity Verification | B42: Integrity tests failed | C42: =COUNTIF('Integrity Verification'!H6:H55,"Fail") | D42: Critical | E42: Immediate
A43: Access Control Review | B43: Non-compliant access controls | C43: =COUNTIF('Access Control Review'!K6:K55,"Non-Compliant") | D43: Critical | E43: Immediate
A44: Backup Verification | B44: Backup non-compliant | C44: =COUNTIF('Backup Verification'!L6:L55,"Non-Compliant") | D44: Critical | E44: Immediate
A45: Access Control Review | B45: Systems without access logging | C45: =COUNTIF('Access Control Review'!G6:G55,"No") | D45: High | E45: Urgent
...

Sheet Approval Sign-Off
A1: ASSESSMENT APPROVAL AND SIGN-OFF
A2: ISO/IEC 27001:2022 - Control A.5.33: Protection of Records
A3: ASSESSMENT SUMMARY
A4: Document: | B4: ISMS-IMP-A.5.32-33.S2 - Records Protection Assessment
A5: Assessment Period:
A6: Overall Compliance Rating: | B6: =IFERROR(AVERAGE('Summary Dashboard'!G6:G10),"")
A7: Assessment Status:
A8: Assessed By:
A11: COMPLETED BY (ASSESSOR)
A12: Name:
A13: Title:
A14: Date:
A15: Signature:
A16: Comments:
A18: REVIEWED BY (INFORMATION SECURITY OFFICER)
A19: Name:
A20: Title:
A21: Date:
... A38: Special Considerations:
