Workbook

Sheet Executive Summary
A1: ISMS-OP-CHK-A.8.16 — Monitoring Activities Compliance Checklist
A3: DOCUMENT INFORMATION
A4: Document ID | B4: ISMS-OP-CHK-A.8.16
A5: Source Policy | B5: ISMS-OP-POL-A.8.16
A6: ISO Controls | B6: Monitoring Activities
A7: Generated | B7: 08.02.2026
A8: Prepared By
A9: Organisation
A10: Review Cycle | B10: Annual
A12: OVERALL COMPLIANCE STATUS
A13: Overall Compliance | B13: ='Dashboard'!G10
A14: Status | B14: =IF(Dashboard!G10="N/A","NOT ASSESSED",IF(ISNUMBER(VALUE(SUBSTITUTE(Dashboard!G10,"%",""))),IF(VALUE(SUBSTITUTE(Dashboard!G10,"%",""))>=90,"GREEN",IF(VALUE(SUBSTITUTE(Dashboard!G10,"%",""))>=70,"AMBER","RED")),"NOT ASSESSED"))
A16: KEY METRICS
A17: Total Requirements | B17: ='Dashboard'!B10
A18: Compliant | B18: ='Dashboard'!C10
A19: Partial | B19: ='Dashboard'!D10
A20: Non-Compliant | B20: ='Dashboard'!E10
A21: Not Applicable | B21: ='Dashboard'!F10
A22: Owner Coverage | B22: =IF(Dashboard!B10=0,"N/A",ROUND((COUNTA('What to Monitor'!F4:F5)+COUNTA('Behavioural Baselines'!F4:F8)+COUNTA('Monitoring Architecture'!F4:F11)+COUNTA('Alert Management'!F4:F12)+COUNTA('Key Performance Indicators'!F4:F4)+COUNTA('Employee Privacy and Monitoring'!F4:F12))/Dashboard!B10*100,0)&"%")
A24: DOMAIN STATUS SUMMARY
A25: Domain | B25: Compliance % | C25: Compliant | D25: Gaps | E25: Status
A26: What to Monitor | B26: ='Dashboard'!G4 | C26: ='Dashboard'!C4 | D26: ='Dashboard'!E4 | E26: =IF(Dashboard!G4="N/A","--",IF(ISNUMBER(VALUE(SUBSTITUTE(Dashboard!G4,"%",""))),IF(VALUE(SUBSTITUTE(Dashboard!G4,"%",""))>=90,"PASS",IF(VALUE(SUBSTITUTE(Dashboard!G4,"%",""))>=70,"REVIEW","FAIL")),"--"))
A27: Behavioural Baselines | B27: ='Dashboard'!G5 | C27: ='Dashboard'!C5 | D27: ='Dashboard'!E5 | E27: =IF(Dashboard!G5="N/A","--",IF(ISNUMBER(VALUE(SUBSTITUTE(Dashboard!G5,"%",""))),IF(VALUE(SUBSTITUTE(Dashboard!G5,"%",""))>=90,"PASS",IF(VALUE(SUBSTITUTE(Dashboard!G5,"%",""))>=70,"REVIEW","FAIL")),"--"))
A28: Monitoring Architecture | B28: ='Dashboard'!G6 | C28: ='Dashboard'!C6 | D28: ='Dashboard'!E6 | E28: =IF(Dashboard!G6="N/A","--",IF(ISNUMBER(VALUE(SUBSTITUTE(Dashboard!G6,"%",""))),IF(VALUE(SUBSTITUTE(Dashboard!G6,"%",""))>=90,"PASS",IF(VALUE(SUBSTITUTE(Dashboard!G6,"%",""))>=70,"REVIEW","FAIL")),"--"))
A29: Alert Management | B29: ='Dashboard'!G7 | C29: ='Dashboard'!C7 | D29: ='Dashboard'!E7 | E29: =IF(Dashboard!G7="N/A","--",IF(ISNUMBER(VALUE(SUBSTITUTE(Dashboard!G7,"%",""))),IF(VALUE(SUBSTITUTE(Dashboard!G7,"%",""))>=90,"PASS",IF(VALUE(SUBSTITUTE(Dashboard!G7,"%",""))>=70,"REVIEW","FAIL")),"--"))
A30: Key Performance Indicators | B30: ='Dashboard'!G8 | C30: ='Dashboard'!C8 | D30: ='Dashboard'!E8 | E30: =IF(Dashboard!G8="N/A","--",IF(ISNUMBER(VALUE(SUBSTITUTE(Dashboard!G8,"%",""))),IF(VALUE(SUBSTITUTE(Dashboard!G8,"%",""))>=90,"PASS",IF(VALUE(SUBSTITUTE(Dashboard!G8,"%",""))>=70,"REVIEW","FAIL")),"--"))
A31: Employee Privacy and Monitoring | B31: ='Dashboard'!G9 | C31: ='Dashboard'!C9 | D31: ='Dashboard'!E9 | E31: =IF(Dashboard!G9="N/A","--",IF(ISNUMBER(VALUE(SUBSTITUTE(Dashboard!G9,"%",""))),IF(VALUE(SUBSTITUTE(Dashboard!G9,"%",""))>=90,"PASS",IF(VALUE(SUBSTITUTE(Dashboard!G9,"%",""))>=70,"REVIEW","FAIL")),"--"))
A33: CRITICAL ISSUES
A34: # | B34: Issue Description | C34: Domain | D34: Owner | E34: Due Date
A35: 1
A36: 2
A37: 3
A38: 4
A39: 5
A41: MANAGEMENT COMMENTARY
A42: [Enter management commentary on monitoring activities posture]
A46: APPROVAL
A47: Assessed By
A48: Name:
A49: Date:
...

Sheet Dashboard
A1: Monitoring Activities — Compliance Dashboard
A3: Domain | B3: Total Reqs | C3: Compliant | D3: Partial | E3: Non-Compliant | F3: N/A | G3: Compliance %
A4: What to Monitor | B4: =COUNTA('What to Monitor'!D4:D5) | C4: =COUNTIF('What to Monitor'!D4:D5,"Compliant") | D4: =COUNTIF('What to Monitor'!D4:D5,"Partial") | E4: =COUNTIF('What to Monitor'!D4:D5,"Non-Compliant") | F4: =COUNTIF('What to Monitor'!D4:D5,"N/A") | G4: =IF((B4-F4)=0,"N/A",ROUND(C4/(B4-F4)*100,1)&"%")
A5: Behavioural Baselines | B5: =COUNTA('Behavioural Baselines'!D4:D8) | C5: =COUNTIF('Behavioural Baselines'!D4:D8,"Compliant") | D5: =COUNTIF('Behavioural Baselines'!D4:D8,"Partial") | E5: =COUNTIF('Behavioural Baselines'!D4:D8,"Non-Compliant") | F5: =COUNTIF('Behavioural Baselines'!D4:D8,"N/A") | G5: =IF((B5-F5)=0,"N/A",ROUND(C5/(B5-F5)*100,1)&"%")
A6: Monitoring Architecture | B6: =COUNTA('Monitoring Architecture'!D4:D11) | C6: =COUNTIF('Monitoring Architecture'!D4:D11,"Compliant") | D6: =COUNTIF('Monitoring Architecture'!D4:D11,"Partial") | E6: =COUNTIF('Monitoring Architecture'!D4:D11,"Non-Compliant") | F6: =COUNTIF('Monitoring Architecture'!D4:D11,"N/A") | G6: =IF((B6-F6)=0,"N/A",ROUND(C6/(B6-F6)*100,1)&"%")
A7: Alert Management | B7: =COUNTA('Alert Management'!D4:D12) | C7: =COUNTIF('Alert Management'!D4:D12,"Compliant") | D7: =COUNTIF('Alert Management'!D4:D12,"Partial") | E7: =COUNTIF('Alert Management'!D4:D12,"Non-Compliant") | F7: =COUNTIF('Alert Management'!D4:D12,"N/A") | G7: =IF((B7-F7)=0,"N/A",ROUND(C7/(B7-F7)*100,1)&"%")
A8: Key Performance Indicators | B8: =COUNTA('Key Performance Indicators'!D4:D4) | C8: =COUNTIF('Key Performance Indicators'!D4:D4,"Compliant") | D8: =COUNTIF('Key Performance Indicators'!D4:D4,"Partial") | E8: =COUNTIF('Key Performance Indicators'!D4:D4,"Non-Compliant") | F8: =COUNTIF('Key Performance Indicators'!D4:D4,"N/A") | G8: =IF((B8-F8)=0,"N/A",ROUND(C8/(B8-F8)*100,1)&"%")
A9: Employee Privacy and Monitoring | B9: =COUNTA('Employee Privacy and Monitoring'!D4:D12) | C9: =COUNTIF('Employee Privacy and Monitoring'!D4:D12,"Compliant") | D9: =COUNTIF('Employee Privacy and Monitoring'!D4:D12,"Partial") | E9: =COUNTIF('Employee Privacy and Monitoring'!D4:D12,"Non-Compliant") | F9: =COUNTIF('Employee Privacy and Monitoring'!D4:D12,"N/A") | G9: =IF((B9-F9)=0,"N/A",ROUND(C9/(B9-F9)*100,1)&"%")
A10: TOTAL | B10: =SUM(B4:B9) | C10: =SUM(C4:C9) | D10: =SUM(D4:D9) | E10: =SUM(E4:E9) | F10: =SUM(F4:F9) | G10: =IF((B10-F10)=0,"N/A",ROUND(C10/(B10-F10)*100,1)&"%")
A12: COMPLIANCE BY STATUS
A13: Compliant | B13: =C10 | C13: =IF(B10=0,"",ROUND(B13/B10*100,1)&"%")
A14: Partial | B14: =D10 | C14: =IF(B10=0,"",ROUND(B14/B10*100,1)&"%")
A15: Non-Compliant | B15: =E10 | C15: =IF(B10=0,"",ROUND(B15/B10*100,1)&"%")
A16: N/A | B16: =F10 | C16: =IF(B10=0,"",ROUND(B16/B10*100,1)&"%")
A18: TOP GAPS (Manual Entry)
A19: Priority | B19: Domain | C19: Requirement | D19: Owner | E19: Due Date | F19: Status
A31: COMPLIANCE TREND (Manual Entry)
A32: Assessment Date | B32: Overall % | C32: Compliant | D32: Gaps | E32: Assessor | F32: Notes

Sheet What to Monitor
A1: What to Monitor — Compliance Checklist
A2: ISO/IEC 27001:2022 — Control A.8.16: Monitoring Activities
A3: Req # | B3: Section | C3: Requirement | D3: Status | E3: Evidence | F3: Owner | G3: Due Date | H3: Notes
A4: A.8.16-01 | B4: The Following | C4: The following shall be monitored for anomalous behaviour and security events:.
A5: A.8.16-02 | B5: Be Prioritised For Monitoring Based On | C5: Systems shall be prioritised for monitoring based on risk:.

Sheet Behavioural Baselines
A1: Behavioural Baselines — Compliance Checklist
A2: ISO/IEC 27001:2022 — Control A.8.16: Monitoring Activities
A3: Req # | B3: Section | C3: Requirement | D3: Status | E3: Evidence | F3: Owner | G3: Due Date | H3: Notes
A4: A.8.16-03 | B4: Before Anomaly Detection Is Effective, | C4: Before anomaly detection is effective, the organisation shall establish baselines of normal behaviour. Initial baselines shall be established within 30 days of monitoring deployment for each system or system group. During the baseline establishment period, monitoring shall operate in 'learning mode' — alerts shall be generated but reviewed with increased tolerance for false positives until baselines are validated.
A5: A.8.16-04 | B5: Document | C5: Baselines shall document:.
A6: A.8.16-05 | B6: Be Reviewed And Updated | C6: Baselines shall be reviewed and updated:.
A7: A.8.16-06 | B7: Monitoring Systems | C7: Monitoring systems shall be configured to detect deviations from established baselines, including:.
A8: A.8.16-07 | B8: User Behaviour Anomalies: Access Outside | C8: User behaviour anomalies: access outside normal working hours, access to resources not previously accessed, impossible travel between geographic locations. Impossible travel is defined as authentication events from two geographic locations within a timeframe that makes physical travel between them implausible (e.g., logins from Zurich and Tokyo within 2 hours). The organisation shall define impossible travel parameters based on: maximum plausible travel speed, VPN/proxy exclusions for known corporate exit points, and tolerance for mobile device location inaccuracy.

Sheet Monitoring Architecture
A1: Monitoring Architecture — Compliance Checklist
A2: ISO/IEC 27001:2022 — Control A.8.16: Monitoring Activities
A3: Req # | B3: Section | C3: Requirement | D3: Status | E3: Evidence | F3: Owner | G3: Due Date | H3: Notes
A4: A.8.16-08 | B4: Deploy A Centralised Monitoring Platform | C4: The organisation shall deploy a centralised monitoring platform capable of:.
A5: A.8.16-09 | B5: A Layered Monitoring Approach | C5: A layered monitoring approach shall be implemented:.
A6: A.8.16-10 | B6: Cloud Audit Logs (Aws Cloudtrail, Azure | C6: Cloud audit logs (AWS CloudTrail, Azure Activity Log, GCP Cloud Audit Logs) shall be forwarded to the centralised monitoring platform.
A7: A.8.16-11 | B7: Cloud Security Posture Changes (E.G., | C7: Cloud security posture changes (e.g., public S3 bucket creation, security group modification, IAM policy changes) shall generate immediate alerts.
A8: A.8.16-12 | B8: Saas Administrative Actions (M365 Admin | C8: SaaS administrative actions (M365 admin portal, Google Workspace admin, Salesforce setup changes) shall be monitored for unauthorised configuration changes.
A9: A.8.16-13 | B9: Cloud Api Activity | C9: Cloud API activity shall be monitored for unusual volumes, access from unexpected locations, and use of deprecated or high-risk API endpoints.
A10: A.8.16-14 | B10: The Monitoring Infrastructure Itself | C10: The monitoring infrastructure itself shall be monitored to ensure continuous availability:.
A11: A.8.16-15 | B11: Monthly Health Report: It Operations | C11: Monthly health report: IT Operations shall produce a monthly monitoring platform health report covering uptime, ingestion rates, agent coverage, and capacity projections.

Sheet Alert Management
A1: Alert Management — Compliance Checklist
A2: ISO/IEC 27001:2022 — Control A.8.16: Monitoring Activities
A3: Req # | B3: Section | C3: Requirement | D3: Status | E3: Evidence | F3: Owner | G3: Due Date | H3: Notes
A4: A.8.16-16 | B4: Be Classified By Severity To Drive | C4: Alerts shall be classified by severity to drive response timelines:.
A5: A.8.16-17 | B5: Alert Response Staffing Model*: The | C5: Alert response staffing model*: The organisation shall define its alert response staffing approach:.
A6: A.8.16-18 | B6: The Chosen Model | C6: The chosen model shall be documented and approved by the CISO. After-hours response capability shall be tested quarterly.
A7: A.8.16-19 | B7: Detection Rules | C7: Detection rules shall be reviewed and tuned monthly to reduce false positive rates.
A8: A.8.16-20 | B8: Suppression Rules | C8: Suppression rules shall be documented with justification and reviewed quarterly.
A9: A.8.16-21 | B9: New Detection Rules | C9: New detection rules shall be added when: threat intelligence identifies new attack patterns, incidents reveal detection gaps, or new systems/applications are deployed.
A10: A.8.16-22 | B10: Detection Rule Change Control: All | C10: Detection rule change control: All changes to detection rules (new rules, modifications, suppressions, deletions) shall follow a documented process: change request with justification, peer review by a second analyst, testing in a non-production/staging environment where feasible, approval by the Information Security lead, and deployment with rollback capability. Emergency rule changes (e.g., in response to an active threat) may bypass peer review but shall be retrospectively reviewed within 48 hours.
A11: A.8.16-23 | B11: Alert Volumes And False Positive Rates | C11: Alert volumes and false positive rates shall be tracked as key performance indicators.
A12: A.8.16-24 | B12: False Positive Management Process: When | C12: False positive management process: When a false positive is identified, the analyst shall: (a) document the root cause (misconfigured rule, legitimate business process, environmental noise), (b) determine the appropriate action (tune rule, add exception, suppress with expiry, accept), (c) implement the change through the detection rule change control process, and (d) verify the tuning does not suppress true positives. Persistent false positive sources (>10 occurrences per week from the same rule) shall be prioritised for tuning within 5 business days.

Sheet Key Performance Indicators
A1: Key Performance Indicators — Compliance Checklist
A2: ISO/IEC 27001:2022 — Control A.8.16: Monitoring Activities
A3: Req # | B3: Section | C3: Requirement | D3: Status | E3: Evidence | F3: Owner | G3: Due Date | H3: Notes
A4: A.8.16-25 | B4: The Following Metrics | C4: The following metrics shall be tracked to measure monitoring effectiveness:.

Sheet Employee Privacy and Monitoring
A1: Employee Privacy and Monitoring — Compliance Checklist
A2: ISO/IEC 27001:2022 — Control A.8.16: Monitoring Activities
A3: Req # | B3: Section | C3: Requirement | D3: Status | E3: Evidence | F3: Owner | G3: Due Date | H3: Notes
A4: A.8.16-26 | B4: Monitoring Activities | C4: Monitoring activities shall comply with Swiss employment law:.
A5: A.8.16-27 | B5: The Following Safeguards | C5: The following safeguards shall be applied:.
A6: A.8.16-28 | B6: Serve Legitimate Security Purposes | C6: Monitoring shall serve legitimate security purposes (threat detection, incident investigation, compliance verification) — not behavioural surveillance or performance management.
A7: A.8.16-29 | B7: Be Informed In Advance That Monitoring | C7: Employees shall be informed in advance that monitoring takes place, what is monitored, and why, through the acceptable use policy and employment documentation.
A8: A.8.16-30 | B8: Only The Minimum Necessary Data | C8: Only the minimum necessary data shall be collected and retained (data minimisation).
A9: A.8.16-31 | B9: Monitoring Data | C9: Monitoring data shall not be used for HR performance evaluation, disciplinary action for non-security matters, or general behavioural profiling.
A10: A.8.16-32 | B10: Personalised Analysis (Identifying | C10: Personalised analysis (identifying individual users) shall only occur when: (a) an alert indicates a potential security incident or policy violation, and (b) the investigation is documented with justification.
A11: A.8.16-33 | B11: Mdr Providers, Forensic Investigators), | C11: Where monitoring data is shared with external parties (e.g., MDR providers, forensic investigators), personal identifiers shall be minimised or anonymised where feasible.
A12: A.8.16-34 | B12: A Data Protection Impact Assessment | C12: A Data Protection Impact Assessment (DPIA) under nFADP Art. 22 shall be conducted before deployment of monitoring that meets any of the following criteria:.
