Workbook

Sheet Instructions & Legend
A1: ISMS-IMP-A.8.11.4 - Testing & Validation Framework ISO/IEC 27001:2022 - Control A.8.11: Data Masking
A3: Document Information
A4: Document ID | B4: ISMS-IMP-A.8.11.4
A5: Assessment Area | B5: Masking Testing & Validation
A6: Related Policy | B6: ISMS-POL-A.8.11
A7: Version | B7: 1.0
A8: Assessment Date
A9: Completed By
A10: Organisation
A11: Review Cycle | B11: Quarterly
A13: Instructions
A14: 1. Define your test strategy and scope in the Testing Procedures sheet.
A15: 2. Execute pre-deployment validation tests and record results.
A16: 3. Conduct post-deployment verification within 24 hours of deployment.
A17: 4. Validate masking completeness across all sensitive fields.
A18: 5. Test format preservation and referential integrity.
A19: 6. Assess re-identification risk and data utility.
A20: 7. Measure performance impact and document findings.
A21: 8. Configure ongoing monitoring and continuous validation.
A22: 9. Document all test results in the Evidence Register for audit traceability.
A23: 10. Obtain final approval and sign-off from IT Security, ISO, and CISO.
A25: Status Legend
A26: Symbol | B26: Status | C26: Description
A27: ✅ | B27: Compliant | C27: Requirement fully met with evidence
A28: ⚠ | B28: Partial | C28: Partially implemented, gaps identified
A29: ❌ | B29: Non-Compliant | C29: Requirement not met, remediation needed
A30: — | B30: Not Applicable | C30: Not applicable to this organisation
A32: TESTING DIMENSIONS
A33: Dimension | B33: Key Question | C33: Success Criteria | D33: Target
A34: Effectiveness | B34: Is data actually masked? | C34: Original data not visible | D34: 100% fields masked
A35: Completeness | B35: Are ALL sensitive fields masked? | C35: Coverage = 100% | D35: 100%
A36: Re-identification Risk | B36: Can original data be inferred? | C36: Re-ID attempts fail | D36: 0% re-ID rate
A37: Data Utility | B37: Does masked data still work? | C37: Apps function correctly | D37: ≥95% utility
A38: Performance | B38: Does masking slow things down? | C38: Acceptable impact | D38: <10% degradation
A40: ACCEPTABLE EVIDENCE (examples)
A41: ✓ Pre-deployment test reports and pass/fail summaries
A42: ✓ Post-deployment validation screenshots and logs
A43: ✓ Masking coverage analysis reports
A44: ✓ Re-identification risk assessment results
A45: ✓ Data utility validation test suite results
...

Sheet Testing Procedures
A1: TESTING PROCEDURES DOCUMENTATION
A2: Testing procedures must be documented and followed consistently (ISMS-POL-A.8.11-S2.4 Section 3)
A3: Are formal testing procedures documented for validating masking effectiveness?
A6: Procedure ID | B6: Procedure Name | C6: Test Type | D6: When Performed | E6: Responsible Role | F6: Test Method | G6: Tools Used | H6: Pass Criteria | I6: Frequency | J6: Documentation Required | K6: Procedure Status | L6: Last Updated | M6: Notes
A7: PROC-001 | B7: Visual Inspection of Masked Data | C7: Pre-Deployment | D7: Before each data refresh to non-prod | E7: Data Engineer | F7: Manual Review | G7: Database client (DBeaver, pgAdmin) | H7: No plaintext PII visible in sample of 100 records | I7: Per Refresh | J7: Screenshot evidence + sign-off email | K7: ✅ Active | L7: 15.01.2026 | M7: Standard procedure for all environments

Sheet PreDeployment Tests
A1: PRE-DEPLOYMENT TESTING
A2: Policy Reference: Before deploying masked data, verify effectiveness through visual inspection, automated validation, and comparison testing (ISMS-POL-A.8.11-S2.4 Section 4.1)
A3: Are pre-deployment tests performed BEFORE masked data is deployed to target environments?
A6: Test ID | B6: Test Name/Description | C6: Environment Tested | D6: Data Category Tested | E6: Test Type | F6: Test Date | G6: Tester Name | H6: Test Method | I6: Test Result | J6: Pass Criteria | K6: Actual Outcome | L6: Issues Found | M6: Remediation Required? | N6: Remediation Status | O6: Retest Date | P6: Notes/Comments | Q6: Evidence ID | R6: Visual Inspection Done? | S6: Automated Validation Done? | T6: Comparison Test Done? | U6: Sample Size Tested | V6: Approval to Deploy?
A7: TEST-001 | B7: Customer CRM | C7: Production | D7: CAT-PII-D | E7: Format Preservation | F7: 15.01.2026 | G7: Data Engineer | H7: Manual inspection | I7: Pass | J7: Email fields maintain @domain format after masking | K7: Test Plan v1.0 | L7: EV-001 | M7: No | N7: N/A | O7: 15.01.2026 | P7: Validated and approved
A60: PRE-DEPLOYMENT CHECKLIST
A61: ☐ | B61: Visual inspection performed on sample masked records
A62: ☐ | B62: No plaintext PII visible in masked data
A63: ☐ | B63: Automated validation scripts executed
A64: ☐ | B64: 100% of identified sensitive fields masked
A65: ☐ | B65: No NULL values where masking expected
A66: ☐ | B66: Format validation passed (emails, phones, dates, etc.)
A67: ☐ | B67: Comparison test: NO matching values with production
A68: ☐ | B68: Referential integrity preserved (if required)
A69: ☐ | B69: Test results documented
A70: ☐ | B70: Failed tests remediated before deployment
A71: ☐ | B71: Approval obtained to deploy masked data
A72: ☐ | B72: Deployment blocked if ANY test fails

Sheet PostDeployment Validation
A1: POST-DEPLOYMENT VALIDATION
A2: Policy Reference: After deploying masked data, immediate validation (within 24 hours) and periodic validation (monthly/quarterly) required (ISMS-POL-A.8.11-S2.4 Section 4.2)
A3: Is post-deployment validation performed to verify masking effectiveness in the target environment?
A6: Test ID | B6: Test Name/Description | C6: Environment Tested | D6: Data Category Tested | E6: Test Type | F6: Test Date | G6: Tester Name | H6: Test Method | I6: Test Result | J6: Pass Criteria | K6: Actual Outcome | L6: Issues Found | M6: Remediation Required? | N6: Remediation Status | O6: Retest Date | P6: Notes/Comments | Q6: Evidence ID | R6: Validation Timing | S6: Schema Change Impact? | T6: User Feedback Reviewed? | U6: Issues Reported by Users? | V6: Next Validation Date
A7: TEST-001 | B7: Customer CRM | C7: Production | D7: CAT-PII-D | E7: Format Preservation | F7: 15.01.2026 | G7: Data Engineer | H7: Manual inspection | I7: Pass | J7: Email fields maintain @domain format after masking | K7: Test Plan v1.0 | L7: EV-001 | M7: No | N7: N/A | O7: 15.01.2026 | P7: Validated and approved
A60: POST-DEPLOYMENT CHECKLIST
A61: ☐ | B61: Immediate validation performed within 24 hours of deployment
A62: ☐ | B62: Masking verified in target environment
A63: ☐ | B63: Application functionality tested (if applicable)
A64: ☐ | B64: User feedback reviewed for masking issues
A65: ☐ | B65: No reports of visible PII from users
A66: ☐ | B66: Periodic validation scheduled (monthly/quarterly)
A67: ☐ | B67: Schema change impact assessed after every schema update
A68: ☐ | B68: Monitoring logs reviewed for masking failures
A69: ☐ | B69: Failed validations escalated to ISO
A70: ☐ | B70: Re-testing performed after remediation

Sheet Completeness Testing
A1: COMPLETENESS TESTING & COVERAGE VALIDATION
A2: Policy Reference: 100% of identified sensitive fields must be masked. Schema drift detection required. (ISMS-POL-A.8.11-S2.4 Section 5)
A3: Is masking completeness tested to ensure 100% of sensitive fields are masked?
A6: Test ID | B6: Test Name/Description | C6: Environment Tested | D6: Data Category Tested | E6: Test Type | F6: Test Date | G6: Tester Name | H6: Test Method | I6: Test Result | J6: Pass Criteria | K6: Actual Outcome | L6: Issues Found | M6: Remediation Required? | N6: Remediation Status | O6: Retest Date | P6: Notes/Comments | Q6: Evidence ID | R6: Total Sensitive Fields | S6: Masked Fields Count | T6: Coverage % | U6: Unmasked Fields Found | V6: Schema Drift Detected? | W6: New Columns Added? | X6: Masking Rules Updated?
A7: TEST-001 | B7: Customer CRM | C7: Production | D7: CAT-PII-D | E7: Format Preservation | F7: 15.01.2026 | G7: Data Engineer | H7: Manual inspection | I7: Pass | J7: Email fields maintain @domain format after masking | K7: Test Plan v1.0 | L7: EV-001 | M7: No | N7: N/A | O7: 15.01.2026 | P7: Validated and approved
A60: COMPLETENESS CHECKLIST
A61: ☐ | B61: Sensitive fields inventory maintained
A62: ☐ | B62: Coverage calculated: (Masked Fields / Total Sensitive Fields) × 100
A63: ☐ | B63: Coverage target: 100% (with documented exceptions only)
A64: ☐ | B64: Schema comparison performed before every data refresh
A65: ☐ | B65: New columns detected and assessed for sensitivity
A66: ☐ | B66: Masking rules updated within 5 days for new sensitive columns
A67: ☐ | B67: Re-testing performed after masking rule updates
A68: ☐ | B68: Unmasked sensitive fields flagged for remediation
A69: ☐ | B69: Coverage gaps escalated to Data Owner and ISO
A70: ☐ | B70: Coverage metrics tracked over time
A71: ☐ | B71: Automated schema drift detection in place
A72: ☐ | B72: Coverage audit performed quarterly

Sheet Format Preservation
A1: FORMAT & TYPE PRESERVATION VALIDATION
A2: Policy Reference: Masked data must maintain correct format (email, phone, date, etc.) per validation requirements (ISMS-POL-A.8.11-S2.4 Section 7.3)
A3: Is format preservation validated to ensure masked data matches expected data types/formats?
A6: Test ID | B6: Test Name/Description | C6: Environment Tested | D6: Data Category Tested | E6: Test Type | F6: Test Date | G6: Tester Name | H6: Test Method | I6: Test Result | J6: Pass Criteria | K6: Actual Outcome | L6: Issues Found | M6: Remediation Required? | N6: Remediation Status | O6: Retest Date | P6: Notes/Comments | Q6: Evidence ID | R6: Field Data Type | S6: Format Validation Method | T6: Expected Format | U6: Format Pass Rate % | V6: Format Failures Count
A7: TEST-001 | B7: Customer CRM | C7: Production | D7: CAT-PII-D | E7: Format Preservation | F7: 15.01.2026 | G7: Data Engineer | H7: Manual inspection | I7: Pass | J7: Email fields maintain @domain format after masking | K7: Test Plan v1.0 | L7: EV-001 | M7: No | N7: N/A | O7: 15.01.2026 | P7: Validated and approved
A60: FORMAT CHECKLIST
A61: ☐ | B61: Email format validation: Masked emails match email regex
A62: ☐ | B62: Phone format validation: Masked phones match phone format
A63: ☐ | B63: Credit card format validation: Masked cards pass Luhn (if required)
A64: ☐ | B64: Date format validation: Masked dates are valid dates
A65: ☐ | B65: ZIP code format validation: Masked ZIPs are valid format
A66: ☐ | B66: SSN format validation: Masked SSNs match SSN format
A67: ☐ | B67: Custom format validation performed (domain-specific)
A68: ☐ | B68: Format failures logged and remediated
A69: ☐ | B69: Format pass rate target: ≥99%
A70: ☐ | B70: Automated format validation scripts in place

Sheet Referential Integrity
A1: REFERENTIAL INTEGRITY TESTING
A2: Policy Reference: Foreign key constraints and data consistency must be preserved across related tables (ISMS-POL-A.8.11-S2.4 Section 7.2)
A3: Is referential integrity validated to ensure relationships preserved after masking?
A6: Test ID | B6: Test Name/Description | C6: Environment Tested | D6: Data Category Tested | E6: Test Type | F6: Test Date | G6: Tester Name | H6: Test Method | I6: Test Result | J6: Pass Criteria | K6: Actual Outcome | L6: Issues Found | M6: Remediation Required? | N6: Remediation Status | O6: Retest Date | P6: Notes/Comments | Q6: Evidence ID | R6: Parent Table | S6: Child Table | T6: Foreign Key Field | U6: FK Violations Found | V6: Consistency Maintained?
A7: TEST-001 | B7: Customer CRM | C7: Production | D7: CAT-PII-D | E7: Format Preservation | F7: 15.01.2026 | G7: Data Engineer | H7: Manual inspection | I7: Pass | J7: Email fields maintain @domain format after masking | K7: Test Plan v1.0 | L7: EV-001 | M7: No | N7: N/A | O7: 15.01.2026 | P7: Validated and approved
A60: REFERENTIAL CHECKLIST
A61: ☐ | B61: Foreign key constraints validated after masking
A62: ☐ | B62: Related records can be joined correctly
A63: ☐ | B63: Consistent masking across related tables (same ID → same masked value)
A64: ☐ | B64: Database integrity checks executed
A65: ☐ | B65: Zero foreign key violations
A66: ☐ | B66: Orphaned records identified and remediated
A67: ☐ | B67: Automated integrity validation scripts in place
A68: ☐ | B68: Integrity failures block data deployment

Sheet ReIdentification Risk
A1: RE-IDENTIFICATION RISK ASSESSMENT
A2: Policy Reference: Re-identification testing must be performed to verify masked data cannot be re-identified. Target: 0% re-ID rate. (ISMS-POL-A.8.11-S2.4 Section 6)
A3: Is re-identification risk testing performed to verify masked data cannot be re-identified?
A6: Test ID | B6: Test Name/Description | C6: Environment Tested | D6: Data Category Tested | E6: Test Type | F6: Test Date | G6: Tester Name | H6: Test Method | I6: Test Result | J6: Pass Criteria | K6: Actual Outcome | L6: Issues Found | M6: Remediation Required? | N6: Remediation Status | O6: Retest Date | P6: Notes/Comments | Q6: Evidence ID | R6: Re-ID Technique Used | S6: Re-ID Attempts | T6: Successful Re-IDs | U6: Re-ID Success Rate % | V6: Risk Level | W6: K-Anonymity Value | X6: Mitigation Required?
A7: TEST-001 | B7: Customer CRM | C7: Production | D7: CAT-PII-D | E7: Format Preservation | F7: 15.01.2026 | G7: Data Engineer | H7: Manual inspection | I7: Pass | J7: Email fields maintain @domain format after masking | K7: Test Plan v1.0 | L7: EV-001 | M7: No | N7: N/A | O7: 15.01.2026 | P7: Validated and approved
A60: RE-IDENTIFICATION CHECKLIST
A61: ☐ | B61: Direct matching test: No matches between masked and production
A62: ☐ | B62: Quasi-identifier combination test performed
A63: ☐ | B63: Statistical inference test performed
A64: ☐ | B64: External data correlation test performed
A65: ☐ | B65: Re-identification success rate calculated
A66: ☐ | B66: Re-ID rate target: 0% (zero successful re-identifications)
A67: ☐ | B67: If 1-5% re-ID rate: Mitigation applied (additional masking/aggregation)
A68: ☐ | B68: If >5% re-ID rate: Immediate remediation (re-design masking)
A69: ☐ | B69: K-anonymity assessment performed (optional but recommended)
A70: ☐ | B70: K-anonymity value: k ≥ 5 (if applicable)
A71: ☐ | B71: Quasi-identifiers documented
A72: ☐ | B72: Re-ID test scenarios documented
... A75: ☐ | B75: Re-ID testing performed quarterly

Sheet Data Utility Validation
A1: DATA UTILITY VALIDATION
A2: Policy Reference: Masked data must support intended use cases. Target: ≥95% utility. (ISMS-POL-A.8.11-S2.4 Section 7)
A3: Is data utility validated to ensure applications/analytics work correctly with masked data?
A6: Test ID | B6: Test Name/Description | C6: Environment Tested | D6: Data Category Tested | E6: Test Type | F6: Test Date | G6: Tester Name | H6: Test Method | I6: Test Result | J6: Pass Criteria | K6: Actual Outcome | L6: Issues Found | M6: Remediation Required? | N6: Remediation Status | O6: Retest Date | P6: Notes/Comments | Q6: Evidence ID | R6: Use Case Type | S6: Test Suite Executed? | T6: Tests Passed Count | U6: Tests Failed Count | V6: Utility Score % | W6: Expected Failures? | X6: Acceptable?
A7: TEST-001 | B7: Customer CRM | C7: Production | D7: CAT-PII-D | E7: Format Preservation | F7: 15.01.2026 | G7: Data Engineer | H7: Manual inspection | I7: Pass | J7: Email fields maintain @domain format after masking | K7: Test Plan v1.0 | L7: EV-001 | M7: No | N7: N/A | O7: 15.01.2026 | P7: Validated and approved
A60: DATA CHECKLIST
A61: ☐ | B61: Application test suite executed with masked data
A62: ☐ | B62: All critical tests pass (or expected failures documented)
A63: ☐ | B63: Performance testing with masked data acceptable
A64: ☐ | B64: UAT completed successfully with masked data
A65: ☐ | B65: Training exercises work with masked data
A66: ☐ | B66: Statistical analysis results comparable (±acceptable margin)
A67: ☐ | B67: ML model accuracy acceptable when trained on masked data
A68: ☐ | B68: Reports render correctly with masked data
A69: ☐ | B69: Aggregations produce valid results
A70: ☐ | B70: Utility score calculated: % of use cases that work correctly
A71: ☐ | B71: Utility score target: ≥95%
A72: ☐ | B72: Utility failures documented and remediated

Sheet Performance Testing
A1: PERFORMANCE IMPACT TESTING
A2: Policy Reference: Masking performance impact must be measured. Target: <10% degradation. (ISMS-POL-A.8.11-S2.4 Section 8)
A3: Is performance impact tested to ensure masking overhead is acceptable?
A6: Test ID | B6: Test Name/Description | C6: Environment Tested | D6: Data Category Tested | E6: Test Type | F6: Test Date | G6: Tester Name | H6: Test Method | I6: Test Result | J6: Pass Criteria | K6: Actual Outcome | L6: Issues Found | M6: Remediation Required? | N6: Remediation Status | O6: Retest Date | P6: Notes/Comments | Q6: Evidence ID | R6: Metric Type | S6: Baseline (Unmasked) | T6: With Masking | U6: Performance Impact % | V6: Acceptable? | W6: Optimization Needed? | X6: Optimization Applied?
A7: TEST-001 | B7: Customer CRM | C7: Production | D7: CAT-PII-D | E7: Format Preservation | F7: 15.01.2026 | G7: Data Engineer | H7: Manual inspection | I7: Pass | J7: Email fields maintain @domain format after masking | K7: Test Plan v1.0 | L7: EV-001 | M7: No | N7: N/A | O7: 15.01.2026 | P7: Validated and approved
A60: PERFORMANCE CHECKLIST
A61: ☐ | B61: Baseline performance measured (without masking)
A62: ☐ | B62: Performance measured with masking enabled
A63: ☐ | B63: Performance impact calculated: ((Masked - Baseline) / Baseline) × 100
A64: ☐ | B64: Performance impact target: <10% degradation
A65: ☐ | B65: Query performance tested
A66: ☐ | B66: Data load/refresh performance tested
A67: ☐ | B67: Report generation performance tested
A68: ☐ | B68: If impact ≥10%: Optimization strategies implemented
A69: ☐ | B69: Performance re-tested after optimization
A70: ☐ | B70: Performance metrics tracked over time

Sheet Ongoing Monitoring
A1: ONGOING MONITORING & CONTINUOUS VALIDATION
A2: Policy Reference: Continuous monitoring and periodic re-testing required to detect masking degradation (ISMS-POL-A.8.11-S2.4 Section 9)
A3: Is ongoing monitoring in place to continuously validate masking effectiveness?
A6: Test ID | B6: Test Name/Description | C6: Environment Tested | D6: Data Category Tested | E6: Test Type | F6: Test Date | G6: Tester Name | H6: Test Method | I6: Test Result | J6: Pass Criteria | K6: Actual Outcome | L6: Issues Found | M6: Remediation Required? | N6: Remediation Status | O6: Retest Date | P6: Notes/Comments | Q6: Evidence ID | R6: Monitoring Type | S6: Monitoring Frequency | T6: Alert Configured? | U6: Incidents Detected | V6: Incident Response Time
A7: TEST-001 | B7: Customer CRM | C7: Production | D7: CAT-PII-D | E7: Format Preservation | F7: 15.01.2026 | G7: Data Engineer | H7: Manual inspection | I7: Pass | J7: Email fields maintain @domain format after masking | K7: Test Plan v1.0 | L7: EV-001 | M7: No | N7: N/A | O7: 15.01.2026 | P7: Validated and approved
A60: ONGOING CHECKLIST
A61: ☐ | B61: Automated monitoring enabled for masking failures
A62: ☐ | B62: Alerts configured for masking rule violations
A63: ☐ | B63: Monitoring logs reviewed regularly (daily/weekly)
A64: ☐ | B64: Schema change alerts configured
A65: ☐ | B65: Periodic re-testing scheduled (monthly/quarterly)
A66: ☐ | B66: Re-testing performed after every data refresh
A67: ☐ | B67: Re-testing performed after every schema change
A68: ☐ | B68: Incident response time tracked (target: <24 hours)
A69: ☐ | B69: Masking failures escalated to ISO
A70: ☐ | B70: Root cause analysis performed for failures
A71: ☐ | B71: Monitoring metrics tracked over time
A72: ☐ | B72: Annual comprehensive masking audit performed

Sheet Gap Analysis
A1: TESTING GAP ANALYSIS & REMEDIATION PLAN
A2: Identify gaps in testing validation processes (51 rows: 1 sample + 50 empty)
A3: Gap ID | B3: Test Type | C3: Gap Description | D3: Current State | E3: Target State | F3: Risk Level | G3: Impact | H3: Remediation Action | I3: Owner | J3: Target Date | K3: Status | L3: Evidence ID
A4: GAP-001 | B4: Format Preservation | C4: Email masking does not preserve format (@ symbol position varies) | D4: Email masked as random string | E4: Email format preserved (user@domain structure maintained) | F4: Medium | G4: Validation tests fail; masked data breaks application logic | H4: Implement format-preserving masking function for email fields | I4: Data Engineering | J4: 31.03.2026 | K4: In Progress | L4: EV-001

Sheet Evidence Register
A1: EVIDENCE REGISTER
A2: List all evidence files/documents referenced in this assessment (audit traceability).
A4: Evidence ID | B4: Category | C4: Description | D4: Source/Location | E4: Date Collected | F4: Collected By | G4: Status | H4: Notes
A5: EV-001 | B5: Test report | C5: Data masking validation test results for production migration | D5: /evidence/masking-validation-prod-migration.pdf | E5: 15.01.2026 | F5: QA Team | G5: Verified | H5: Pre-deployment validation completed successfully

Sheet Summary Dashboard
A1: Testing & Validation Framework — SUMMARY DASHBOARD
A2: Summary Dashboard | Testing & Validation Framework | Generated: 01.03.2026
A4: TABLE 1 – COMPLIANCE ASSESSMENT SUMMARY
A5: Assessment Area | B5: Total Items | C5: Compliant | D5: Partial | E5: Non-Compliant | F5: N/A | G5: Compliance %
A6: Pre-Deployment Tests | B6: =C6+D6+E6+F6 | C6: =COUNTIF('PreDeployment Tests'!I8:I100,"✅ Pass") | D6: =COUNTIF('PreDeployment Tests'!I8:I100,"⚠️ Partial") | E6: =COUNTIF('PreDeployment Tests'!I8:I100,"❌ Fail")+COUNTIF('PreDeployment Tests'!I8:I100,"Blocked") | F6: =COUNTIF('PreDeployment Tests'!I8:I100,"N/A") | G6: =IF((B6-F6)=0,0,C6/(B6-F6))
A7: Post-Deployment Validation | B7: =C7+D7+E7+F7 | C7: =COUNTIF('PostDeployment Validation'!I8:I100,"✅ Pass") | D7: =COUNTIF('PostDeployment Validation'!I8:I100,"⚠️ Partial") | E7: =COUNTIF('PostDeployment Validation'!I8:I100,"❌ Fail")+COUNTIF('PostDeployment Validation'!I8:I100,"Blocked") | F7: =COUNTIF('PostDeployment Validation'!I8:I100,"N/A") | G7: =IF((B7-F7)=0,0,C7/(B7-F7))
A8: Completeness Testing | B8: =C8+D8+E8+F8 | C8: =COUNTIF('Completeness Testing'!I8:I100,"✅ Pass") | D8: =COUNTIF('Completeness Testing'!I8:I100,"⚠️ Partial") | E8: =COUNTIF('Completeness Testing'!I8:I100,"❌ Fail")+COUNTIF('Completeness Testing'!I8:I100,"Blocked") | F8: =COUNTIF('Completeness Testing'!I8:I100,"N/A") | G8: =IF((B8-F8)=0,0,C8/(B8-F8))
A9: Format Preservation | B9: =C9+D9+E9+F9 | C9: =COUNTIF('Format Preservation'!I8:I100,"✅ Pass") | D9: =COUNTIF('Format Preservation'!I8:I100,"⚠️ Partial") | E9: =COUNTIF('Format Preservation'!I8:I100,"❌ Fail")+COUNTIF('Format Preservation'!I8:I100,"Blocked") | F9: =COUNTIF('Format Preservation'!I8:I100,"N/A") | G9: =IF((B9-F9)=0,0,C9/(B9-F9))
A10: Referential Integrity | B10: =C10+D10+E10+F10 | C10: =COUNTIF('Referential Integrity'!I8:I100,"✅ Pass") | D10: =COUNTIF('Referential Integrity'!I8:I100,"⚠️ Partial") | E10: =COUNTIF('Referential Integrity'!I8:I100,"❌ Fail")+COUNTIF('Referential Integrity'!I8:I100,"Blocked") | F10: =COUNTIF('Referential Integrity'!I8:I100,"N/A") | G10: =IF((B10-F10)=0,0,C10/(B10-F10))
A11: Re-Identification Risk | B11: =C11+D11+E11+F11 | C11: =COUNTIF('ReIdentification Risk'!I8:I100,"✅ Pass") | D11: =COUNTIF('ReIdentification Risk'!I8:I100,"⚠️ Partial") | E11: =COUNTIF('ReIdentification Risk'!I8:I100,"❌ Fail")+COUNTIF('ReIdentification Risk'!I8:I100,"Blocked") | F11: =COUNTIF('ReIdentification Risk'!I8:I100,"N/A") | G11: =IF((B11-F11)=0,0,C11/(B11-F11))
A12: Data Utility Validation | B12: =C12+D12+E12+F12 | C12: =COUNTIF('Data Utility Validation'!I8:I100,"✅ Pass") | D12: =COUNTIF('Data Utility Validation'!I8:I100,"⚠️ Partial") | E12: =COUNTIF('Data Utility Validation'!I8:I100,"❌ Fail")+COUNTIF('Data Utility Validation'!I8:I100,"Blocked") | F12: =COUNTIF('Data Utility Validation'!I8:I100,"N/A") | G12: =IF((B12-F12)=0,0,C12/(B12-F12))
A13: Performance Testing | B13: =C13+D13+E13+F13 | C13: =COUNTIF('Performance Testing'!I8:I100,"✅ Pass") | D13: =COUNTIF('Performance Testing'!I8:I100,"⚠️ Partial") | E13: =COUNTIF('Performance Testing'!I8:I100,"❌ Fail")+COUNTIF('Performance Testing'!I8:I100,"Blocked") | F13: =COUNTIF('Performance Testing'!I8:I100,"N/A") | G13: =IF((B13-F13)=0,0,C13/(B13-F13))
A14: Ongoing Monitoring | B14: =C14+D14+E14+F14 | C14: =COUNTIF('Ongoing Monitoring'!I8:I100,"✅ Pass") | D14: =COUNTIF('Ongoing Monitoring'!I8:I100,"⚠️ Partial") | E14: =COUNTIF('Ongoing Monitoring'!I8:I100,"❌ Fail")+COUNTIF('Ongoing Monitoring'!I8:I100,"Blocked") | F14: =COUNTIF('Ongoing Monitoring'!I8:I100,"N/A") | G14: =IF((B14-F14)=0,0,C14/(B14-F14))
A15: TOTAL | B15: =SUM(B6:B14) | C15: =SUM(C6:C14) | D15: =SUM(D6:D14) | E15: =SUM(E6:E14) | F15: =SUM(F6:F14) | G15: =IF((B15-F15)=0,0,C15/(B15-F15))
A17: TABLE 2 – KEY METRICS
A18: Metric | B18: Value | C18: Target
A19: Pre-Deployment Test Pass Rate (%) | B19: =IF(COUNTA('PreDeployment Tests'!I8:I100)=0,"N/A",TEXT(COUNTIF('PreDeployment Tests'!I8:I100,"✅ Pass")/COUNTA('PreDeployment Tests'!I8:I100),"0.0%")) | C19: 100%
A20: Post-Deployment Validation Pass Rate (%) | B20: =IF(COUNTA('PostDeployment Validation'!I8:I100)=0,"N/A",TEXT(COUNTIF('PostDeployment Validation'!I8:I100,"✅ Pass")/COUNTA('PostDeployment Validation'!I8:I100),"0.0%")) | C20: 100%
A21: Re-Identification Risk Test Pass Rate (%) | B21: =IF(COUNTA('ReIdentification Risk'!I8:I100)=0,"N/A",TEXT(COUNTIF('ReIdentification Risk'!I8:I100,"✅ Pass")/COUNTA('ReIdentification Risk'!I8:I100),"0.0%")) | C21: 100%
A22: Data Utility Validation Pass Rate (%) | B22: =IF(COUNTA('Data Utility Validation'!I8:I100)=0,"N/A",TEXT(COUNTIF('Data Utility Validation'!I8:I100,"✅ Pass")/COUNTA('Data Utility Validation'!I8:I100),"0.0%")) | C22: >=95%
A23: Performance Impact Tests Within Threshold (%) | B23: =IF(COUNTA('Performance Testing'!I8:I100)=0,"N/A",TEXT(COUNTIF('Performance Testing'!I8:I100,"✅ Pass")/COUNTA('Performance Testing'!I8:I100),"0.0%")) | C23: >=90%
A24: Overall Test Pass Rate (%) | B24: =IF(B15-F15=0,"N/A",TEXT(C15/(B15-F15),"0.0%")) | C24: 100%
A26: TABLE 3 – KEY FINDINGS & RECOMMENDATIONS
A27: # | B27: Finding | C27: Impact | D27: Recommendation | E27: Priority | F27: Status | G27: Notes
A28: 1 | B28: Pre-deployment validation tests not consistently documented or signed off | C28: High — unvalidated masking deployments risk real data reaching non-production | D28: Define mandatory pre-deployment checklist; block data refresh without sign-off evidence | E28: P1 | F28: Open
A29: 2 | B29: Re-identification risk testing not performed for all data categories | C29: High — masked data may still be re-identifiable via quasi-identifier combinations | D29: Conduct re-ID risk assessment for all data categories; document k-anonymity values | E29: P1 | F29: Open
A30: 3 | B30: Format preservation failures for email and phone masking detected | C30: Medium — application logic fails when masked data breaks expected format constraints | D30: Implement format-preserving masking functions; add automated regex validation to test pipeline | E30: P2 | F30: In Progress
A31: 4 | B31: Ongoing monitoring alerts not configured for all masking rules | C31: Medium — masking failures may go undetected between periodic test cycles | D31: Configure automated alerts for masking rule violations; integrate with SIEM; define SLA for response | E31: P2 | F31: Open

Sheet Approval Sign-Off
A1: ASSESSMENT APPROVAL AND SIGN-OFF
A3: ASSESSMENT SUMMARY
A4: Document: | B4: ISMS-IMP-A.8.11.4 - Testing & Validation Framework
A5: Assessment Period:
A6: Overall Compliance: | B6: =IFERROR(AVERAGE('Summary Dashboard'!G6:G14),"")
A7: Assessment Status:
A10: PREPARED BY (IT SECURITY)
A11: Name:
A12: Title:
A13: Date:
A14: Signature:
A15: Comments:
A17: REVIEWED BY (ISO)
A18: Name:
A19: Title:
A20: Date:
A21: Signature:
... A37: Special Considerations:
