Workbook

Sheet Instructions & Legend
A1: ISMS-IMP-A.8.11.1 - Data Inventory & Classification Assessment ISO/IEC 27001:2022 - Control A.8.11: Data Masking
A3: Document Information
A4: Document ID | B4: ISMS-IMP-A.8.11.1
A5: Control Reference | B5: ISO/IEC 27001:2022 - Control A.8.11: Data Masking
A6: Framework Version | B6: 1.0
A7: Generated Date | B7: 07.03.2026
A8: Classification | B8: CONFIDENTIAL
A9: Owner
A10: Status | B10: DRAFT
A12: Instructions
A13: 1. Start with System Inventory — list ALL systems/databases that process data.
A14: 2. Use Data Category Reference to understand sensitivity taxonomy.
A15: 3. Complete Sensitive Data Inventory for each system (table/field level).
A16: 4. Apply classification using the Classification Matrix sheet.
A17: 5. Map data to regulatory requirements in Regulatory Mapping.
A18: 6. Assign data owners in Data Owner Assignment.
A19: 7. Prioritise masking efforts in Masking Priority Matrix.
A20: 8. Document gaps in Gap Analysis.
A21: 9. Maintain evidence in Evidence Register.
A22: 10. Review summary metrics in Summary Dashboard.
A23: 11. Obtain required approvals in Approval Sign-Off.
A25: DATA CATEGORY TAXONOMY
A26: Category ID | B26: Category Name | C26: Examples
A27: CAT-PII-D | B27: Direct PII | C27: Name, SSN/AHV, Passport, Email, Phone
A28: CAT-PII-I | B28: Indirect PII | C28: DOB+ZIP, Job Title+Department
A29: CAT-FIN | B29: Financial Data | C29: Credit Card (PAN), IBAN, Account Balance
A30: CAT-HLT | B30: Health Data | C30: Diagnoses, Prescriptions, Medical Records
A31: CAT-CRD | B31: Credentials | C31: Passwords, API Keys, Tokens
A32: CAT-PRP | B32: Proprietary | C32: Trade Secrets, Pricing, IP
A33: CAT-LOC | B33: Location Data | C33: GPS, IP Address, Travel History
A34: CAT-BIO | B34: Biometric | C34: Fingerprints, Facial Geometry
A35: CAT-GEN | B35: Genetic Data | C35: DNA, Genetic Test Results
A36: CAT-CHD | B36: Child Data | C36: Data of minors (<16 GDPR / <18)
A38: SENSITIVITY CLASSIFICATION LEVELS
A39: Level | B39: Definition | C39: Masking Requirement
A40: Critical | B40: Severe harm if exposed, regulatory breach | C40: SHALL mask in ALL non-production
A41: High | B41: Substantial harm, privacy violation | C41: SHALL mask in non-production
A42: Medium | B42: Moderate harm, business impact | C42: SHOULD mask in non-production
A43: Low | B43: Minimal harm | C43: MAY mask based on risk
A44: Public | B44: No confidentiality requirement | C44: N/A
...

Sheet System Inventory
A1: SYSTEM & DATABASE INVENTORY
A2: List ALL systems that process, store, or transmit data (50 row template)
A3: Does your organisation maintain a comprehensive inventory of all systems containing sensitive data?
A4: Response:
A6: System ID | B6: System Name | C6: System Type | D6: Environment | E6: Contains Sensitive Data? | F6: Data Categories Present | G6: Hosting Location | H6: Primary Data Owner | I6: System Owner/Admin | J6: Inventory Status | K6: Last Inventory Date | L6: Next Review Date | M6: Record Count (Approx) | N6: Retention Period | O6: Regulatory Scope | P6: Decommission Date | Q6: Notes/Comments
A7: SYS-001 | B7: Customer CRM System | C7: Application | D7: Production | E7: Yes | F7: CAT-PII-D, CAT-FIN | G7: AWS | H7: VP Sales | I7: IT Manager | J7: ✅ Complete | K7: 2024-12-15 | L7: 2025-03-15 | M7: 500000 | N7: 7 years | O7: GDPR, FADP | Q7: Primary customer database
A59: SYSTEM INVENTORY CHECKLIST
A60: # | B60: Checklist Item | C60: Status | D60: Evidence | E60: Notes
A61: 1 | B61: Is a system inventory maintained?
A62: 2 | B62: Are all production systems documented?
A63: 3 | B63: Are non-production environments included?
A64: 4 | B64: Are SaaS/cloud systems included?
A65: 5 | B65: Are backup/archive systems included?
A66: 6 | B66: Are data warehouses/analytics systems included?
A67: 7 | B67: Is system type classified for each entry?
A68: 8 | B68: Is hosting location documented?
A69: 9 | B69: Are system owners assigned?
A70: 10 | B70: Are data owners assigned?
A71: 11 | B71: Is inventory reviewed quarterly?
A72: 12 | B72: Are decommissioned systems tracked?
... A75: 15 | B75: Are regulatory requirements mapped?
A76: SYSTEM TYPE DEFINITIONS
A77: System Type | B77: Description | C77: Examples
A78: Database | B78: Relational or NoSQL databases | C78: Oracle, PostgreSQL, MongoDB, SQL Server
A79: Application | B79: Business applications | C79: CRM, ERP, HR systems, custom apps
A80: SaaS | B80: Cloud-based software services | C80: Salesforce, Workday, ServiceNow
A81: File Share | B81: File storage systems | C81: SharePoint, NAS, file servers
A82: API | B82: API gateways and services | C82: REST APIs, integration platforms
A83: Data Warehouse | B83: Analytics and BI systems | C83: Snowflake, Redshift, BigQuery
A84: Backup System | B84: Backup and recovery systems | C84: Veeam, backup appliances
A85: Archive | B85: Long-term storage | C85: Tape systems, cold storage
A86: Other | B86: Other system types | C86: (Document in notes)

Sheet Data Category Reference
A1: SENSITIVE DATA CATEGORY REFERENCE
A2: Reference taxonomy from ISMS-POL-A.8.11-S2.1
A4: Category ID | B4: Category Name | C4: Description | D4: Examples | E4: Sensitivity Level | F4: Masking Priority | G4: Regulatory Driver
A5: CAT-PII-D | B5: Direct PII | C5: Data that directly identifies an individual | D5: Full Name, SSN/AHV, Passport, Driver's License, Email, Phone, Address, Photo | E5: High/Critical | F5: Required | G5: FADP, GDPR
A6: CAT-PII-I | B6: Indirect PII | C6: Data that can identify when combined | D6: DOB+ZIP, Job Title+Department, Employee ID | E6: Medium/High | F6: Required when combined | G6: FADP, GDPR
A7: CAT-FIN | B7: Financial Data | C7: Payment and financial account data | D7: PAN (Credit Card), CVV, IBAN, Account Balance, Salary, Tax ID | E7: Critical | F7: Required | G7: PCI-DSS, FADP, GDPR
A8: CAT-HLT | B8: Health Data | C8: Medical and health information | D8: Medical Record Number, Diagnoses, Medications, Lab Results, Insurance ID, Mental Health Records | E8: Critical | F8: Required | G8: FADP, GDPR Article 9
A9: CAT-CRD | B9: Credentials | C9: Authentication and access data | D9: Passwords, Password Hashes, API Keys, OAuth Tokens, Private Keys, DB Connection Strings | E9: Critical | F9: Required (Never display) | G9: Best Practice
A10: CAT-PRP | B10: Proprietary | C10: Business-sensitive information | D10: Trade Secrets, Pricing Models, Strategic Plans, Source Code | E10: High | F10: Recommended | G10: Business Confidentiality
A11: CAT-LOC | B11: Location Data | C11: Geographic and tracking data | D11: GPS Coordinates, IP Addresses, Travel History | E11: Medium/High | F11: Recommended | G11: GDPR (personal location)
A12: CAT-BIO | B12: Biometric Data | C12: Physical/behavioural identifiers | D12: Fingerprints, Facial Geometry, Voice Prints, Retina Scans | E12: Critical | F12: Required | G12: GDPR Article 9
A13: CAT-GEN | B13: Genetic Data | C13: DNA and genetic information | D13: DNA Sequences, Genetic Test Results, Hereditary Information | E13: Critical | F13: Required | G13: GDPR Article 9
A14: CAT-CHD | B14: Child Data | C14: Data relating to minors | D14: Any PII of persons under 16 (GDPR) / 18 (local) | E14: Critical | F14: Required | G14: GDPR Article 8, COPPA

Sheet Sensitive Data Inventory
A1: SENSITIVE DATA ELEMENT INVENTORY
A2: Document sensitive data at the table/field level (51 row template: 1 sample + 50 empty)
A3: Has your organisation identified all sensitive data fields across systems?
A4: Response:
A6: Data Element ID | B6: System Name | C6: Database/Schema | D6: Table/Collection Name | E6: Field/Column Name | F6: Data Type | G6: Data Category | H6: Specific PII Type | I6: Sensitivity Level | J6: Contains PII? | K6: Regulatory Scope | L6: Masking Required? | M6: Current Masking Status | N6: Record Count (Approx) | O6: Data Owner | P6: Discovery Method | Q6: Discovery Date | R6: Notes/Comments
A7: DE-001 | B7: Customer CRM System | C7: CRM_PROD | D7: Customers | E7: email_address | F7: String | G7: CAT-PII-D | H7: Email | I7: High | J7: Yes | K7: GDPR, FADP | L7: Yes | M7: Not Masked | N7: 500000 | O7: VP Sales | P7: Schema Review | Q7: 2024-11-15 | R7: Primary customer contact email
A59: SENSITIVE DATA INVENTORY CHECKLIST
A60: # | B60: Checklist Item | C60: Status | D60: Evidence | E60: Notes
A61: 1 | B61: Is sensitive data identified at field level?
A62: 2 | B62: Are all production databases inventoried?
A63: 3 | B63: Are non-production environments inventoried?
A64: 4 | B64: Is PII specifically flagged?
A65: 5 | B65: Are special category data (GDPR Art.9) identified?
A66: 6 | B66: Is financial data (PCI scope) identified?
A67: 7 | B67: Are credentials/secrets identified?
A68: 8 | B68: Is data category assigned per field?
A69: 9 | B69: Is sensitivity level assigned?
A70: 10 | B70: Is masking requirement determined?
A71: 11 | B71: Is current masking status documented?
A72: 12 | B72: Are record counts estimated?
... A78: 18 | B78: Are discovery results validated manually?

Sheet Classification Matrix
A1: DATA CLASSIFICATION MATRIX
A2: Map data sensitivity to organisational classification scheme
A3: Does your organisation classify sensitive data according to an established taxonomy?
A4: Response:
A6: CLASSIFICATION SUMMARY
A7: Organisational Class | B7: Typical Sensitivity | C7: Data Categories | D7: Masking Requirement | E7: Count of Fields
A8: Restricted | B8: Critical | C8: CAT-HLT, CAT-BIO, CAT-GEN, CAT-FIN (PAN) | D8: Mandatory in ALL non-prod | E8: =COUNTIF('Classification Matrix'!F:F,"Restricted")
A9: Confidential | B9: High | C9: CAT-PII-D, CAT-FIN, CAT-CRD | D9: Mandatory in non-prod | E9: =COUNTIF('Classification Matrix'!F:F,"Confidential")
A10: Internal | B10: Medium | C10: CAT-PII-I, CAT-PRP, CAT-LOC | D10: Risk-based masking | E10: =COUNTIF('Classification Matrix'!F:F,"Internal")
A11: Public | B11: Low/None | C11: Non-sensitive data | D11: No masking required | E11: =COUNTIF('Classification Matrix'!F:F,"Public")
A14: CLASSIFICATION ASSIGNMENT (51 rows: 1 sample + 50 empty)
A15: Data Element ID | B15: System Name | C15: Field Name | D15: Data Category | E15: Sensitivity Level | F15: Organisational Classification | G15: Masking Requirement | H15: Classification Rationale | I15: Classified By | J15: Classification Date | K15: Last Review Date | L15: Next Review Date
A16: DE-001 | B16: Customer CRM System | C16: email_address | D16: CAT-PII-D | E16: High | F16: Confidential | G16: Mandatory in non-prod | H16: Email field contains direct PII under GDPR/FADP | I16: Data Protection Officer | J16: 15.01.2026 | K16: 15.01.2026 | L16: 15.01.2027
A68: CLASSIFICATION CHECKLIST
A69: # | B69: Checklist Item | C69: Status | D69: Evidence | E69: Notes
A70: 1 | B70: Is organisational classification scheme defined?
A71: 2 | B71: Are all sensitive fields classified?
A72: 3 | B72: Is classification aligned with data categories?
A73: 4 | B73: Are masking requirements derived from classification?
A74: 5 | B74: Is classification rationale documented?
A75: 6 | B75: Are classifiers identified per field?
A76: 7 | B76: Is classification reviewed annually?
A77: 8 | B77: Are regulatory overrides documented?
A78: 9 | B78: Is reclassification process defined?
A79: 10 | B79: Are classification changes tracked?

Sheet Regulatory Mapping
A1: REGULATORY REQUIREMENT MAPPING
A2: Map data to applicable privacy and security regulations
A3: Has your organisation identified which data is subject to specific regulatory requirements?
A4: Response:
A6: REGULATORY SUMMARY
A7: Regulation | B7: Applicability | C7: Data Categories in Scope | D7: Field Count | E7: Masking Mandated?
A8: GDPR (EU) | C8: Art. 32 Security | D8: =COUNTIF('Regulatory Mapping'!E:E,"Yes") | E8: Yes (Art. 32)
A9: FADP (Switzerland) | C9: Data Protection | D9: =COUNTIF('Regulatory Mapping'!E:E,"Yes") | E9: Yes
A10: HIPAA (US - if applicable) | C10: Protected Health Info | D10: =COUNTIF('Regulatory Mapping'!E:E,"Yes") | E10: Yes
A11: PCI-DSS (if processing cards) | C11: Cardholder Data | D11: =COUNTIF('Regulatory Mapping'!E:E,"Yes") | E11: Yes (Req 3.4)
A12: CCPA/CPRA (California) | C12: Consumer Privacy | D12: =COUNTIF('Regulatory Mapping'!E:E,"Yes") | E12: Recommended
A13: Other (specify) | D13: =COUNTIF('Regulatory Mapping'!E:E,"Yes")
A15: DETAILED REGULATORY MAPPING (51 rows: 1 sample + 50 empty)
A16: Data Element ID | B16: System Name | C16: Field Name | D16: Data Category | E16: GDPR Applicable? | F16: GDPR Article | G16: FADP Applicable? | H16: HIPAA Applicable? | I16: PCI-DSS Applicable? | J16: Other Regulations | K16: Masking Mandated by Reg? | L16: Regulatory Reference | M16: Compliance Deadline | N16: Notes
A17: DE-001 | B17: Customer CRM System | C17: email_address | D17: CAT-PII-D | E17: Yes | F17: Art. 4(1), Art. 32 | G17: Yes | H17: No | I17: No | K17: Yes | L17: GDPR Art. 32 (security); FADP Art. 7 | N17: Email is direct PII under both GDPR and FADP
A69: REGULATORY COMPLIANCE CHECKLIST
A70: # | B70: Checklist Item | C70: Status | D70: Evidence | E70: Notes
A71: 1 | B71: Are applicable regulations identified?
A72: 2 | B72: Is GDPR applicability determined?
A73: 3 | B73: Is FADP applicability determined?
A74: 4 | B74: Is HIPAA applicability determined (if US)?
A75: 5 | B75: Is PCI-DSS applicability determined?
A76: 6 | B76: Are GDPR special categories (Art.9) identified?
A77: 7 | B77: Is PCI-DSS PAN data identified?
A78: 8 | B78: Are masking requirements per regulation documented?
A79: 9 | B79: Are regulatory references cited?
A80: 10 | B80: Are compliance deadlines tracked?
A81: 11 | B81: Is DPO consulted for GDPR scope?
A82: 12 | B82: Are cross-border data transfers considered?

Sheet Data Owner Assignment
A1: DATA OWNERSHIP ASSIGNMENT
A2: Assign data owners per system and data category (ISMS-POL-A.8.11-S3)
A3: Has your organisation assigned data owners for all sensitive data categories?
A4: Response:
A6: OWNERSHIP SUMMARY BY DATA CATEGORY
A7: Data Category | B7: Data Owner (Role) | C7: Data Owner (Name) | D7: Backup Owner | E7: Assignment Date | F7: Last Review
A8: CAT-PII-D (Direct PII)
A9: CAT-PII-I (Indirect PII)
A10: CAT-FIN (Financial)
A11: CAT-HLT (Health)
A12: CAT-CRD (Credentials)
A13: CAT-PRP (Proprietary)
A14: CAT-LOC (Location)
A15: CAT-BIO (Biometric)
A16: CAT-GEN (Genetic)
A17: CAT-CHD (Child Data)
A19: OWNERSHIP BY SYSTEM (51 rows: 1 sample + 50 empty)
A20: System Name | B20: System Owner | C20: Primary Data Owner | D20: Data Steward | E20: Business Owner | F20: Data Categories in System | G20: Ownership Documented? | H20: RACI Matrix Reference | I20: Assignment Date | J20: Last Review Date | K20: Next Review Date | L20: Approval Status | M20: Approver | N20: Notes
A21: Customer CRM System | B21: CTO | C21: VP Sales | D21: CRM Data Analyst | E21: VP Sales | F21: CAT-PII-D, CAT-FIN | G21: Yes | H21: /docs/raci-matrix-crm.xlsx | I21: 15.01.2026 | J21: 15.01.2026 | K21: 15.01.2027 | L21: Approved | M21: CISO | N21: Annual ownership review completed Q1 2026
A73: DATA OWNER RESPONSIBILITIES (Reference)
A74: Responsibility | B74: Requirement Level | C74: Policy Reference
A75: Approve data classification | B75: SHALL | C75: REQ-CLS-031
A76: Approve masking techniques for their data | B76: SHALL | C76: REQ-CLS-031
A77: Review classification annually | B77: SHALL | C77: REQ-CLS-032
A78: Approve access to unmasked data | B78: SHALL | C78: REQ-ENV-041
A79: Review masking effectiveness | B79: SHOULD | C79: REQ-TST-020
A80: Participate in risk assessments | B80: SHOULD | C80: REQ-GOV-010
A82: OWNERSHIP CHECKLIST
A83: # | B83: Checklist Item | C83: Status | D83: Evidence | E83: Notes
A84: 1 | B84: Are data owners assigned per category?
A85: 2 | B85: Are data owners assigned per system?
A86: 3 | B86: Are data stewards identified?
A87: 4 | B87: Are backup owners assigned?
A88: 5 | B88: Is ownership documented in RACI matrix?
A89: 6 | B89: Have data owners acknowledged responsibilities?
A90: 7 | B90: Are ownership changes tracked?
A91: 8 | B91: Is ownership reviewed annually?
A92: 9 | B92: Are data owners trained on masking requirements?
A93: 10 | B93: Do data owners approve masking techniques?

Sheet Masking Priority Matrix
A1: MASKING PRIORITY & RISK ASSESSMENT
A2: Prioritise masking efforts based on risk, compliance, and business impact
A3: Has your organisation prioritised masking implementation based on risk assessment?
A4: Response:
A6: PRIORITY SCORE FORMULA: (Sensitivity × 3) + (Exposure Risk × 2) + (Regulatory Weight × 2) + (Volume Factor × 1)
A8: Priority Tiers:
A9: P1 (Critical): Score ≥ 35 — Immediate action required
A10: P2 (High): Score 25-34 — Implement within 3 months
A11: P3 (Medium): Score 15-24 — Implement within 6 months
A12: P4 (Low): Score < 15 — Risk-based timeline
A13: PRIORITY ASSESSMENT (51 rows: 1 sample + 50 empty)
A14: Data Element ID | B14: System Name | C14: Field Name | D14: Data Category | E14: Sensitivity Score (1-5) | F14: Exposure Risk (1-5) | G14: Regulatory Score (1-5) | H14: Volume Score (1-5) | I14: Total Priority Score | J14: Priority Tier | K14: Current Masking Status | L14: Target Implementation Date | M14: Assigned To | N14: Implementation Status | O14: Blocking Issues | P14: Notes
A15: DE-001 | B15: Customer CRM System | C15: email_address | D15: CAT-PII-D | E15: 5 | F15: 5 | G15: 5 | H15: 5 | I15: 40 | J15: P1 | K15: Not Masked | L15: 31.01.2026 | M15: Data Engineering | N15: In Progress | P15: Critical P1 - production unmasked data
A67: PRIORITY TIER SUMMARY
A68: Priority Tier | B68: Count | C68: % of Total | D68: Avg Score | E68: Complete | F68: In Progress | G68: Not Started
A69: P1 (Critical)
A70: P2 (High)
A71: P3 (Medium)
A72: P4 (Low)
A73: TOTAL
A75: PRIORITY CHECKLIST
A76: # | B76: Checklist Item | C76: Status | D76: Evidence | E76: Notes
A77: 1 | B77: Is risk-based prioritization performed?
A78: 2 | B78: Are sensitivity levels factored into priority?
A79: 3 | B79: Is exposure risk assessed per field?
A80: 4 | B80: Are regulatory mandates weighted?
A81: 5 | B81: Is data volume considered?
A82: 6 | B82: Are P1 items addressed immediately?
A83: 7 | B83: Are target dates assigned per priority?
A84: 8 | B84: Are responsible parties assigned?
A85: 9 | B85: Is implementation status tracked?
A86: 10 | B86: Are blocking issues documented?

Sheet Gap Analysis
A1: DATA INVENTORY & CLASSIFICATION GAP ANALYSIS
A2: Identify missing inventory, classification, ownership, or masking
A4: GAP SUMMARY
A5: Gap Category | B5: Count | C5: % of Total | D5: Risk Level | E5: Remediation Owner | F5: Target Date
A6: Systems not inventoried
A7: Systems with unknown sensitive data
A8: Fields not classified
A9: Fields without data owner
A10: Regulatory mapping incomplete
A11: Masking required but not implemented
A12: Masking status unknown
A14: DETAILED GAP REGISTER (51 rows: 1 sample + 50 empty)
A15: Gap ID | B15: Gap Category | C15: System Name | D15: Field/Data Element | E15: Gap Description | F15: Risk Level | G15: Impact if Not Remediated | H15: Root Cause | I15: Remediation Action | J15: Remediation Owner | K15: Target Completion Date | L15: Status | M15: Actual Completion Date | N15: Verification Method | O15: Notes
A16: GAP-001 | B16: Masking Missing | C16: HR Payroll System | D16: employee_bank_account | E16: Bank account numbers not masked in test environment - real employee data visible | F16: High | G16: Potential data breach if test environment compromised; GDPR/FADP violation | H16: Masking not configured during initial deployment in 2024 | I16: Implement static data masking for bank_account field using format-preserving encryption | J16: Data Engineering Team | K16: 31.03.2026 | L16: In Progress | N16: Manual testing post-implementation | O16: Approved by DPO 15.01.2026; high priority P1
A68: GAP ANALYSIS CHECKLIST
A69: # | B69: Checklist Item | C69: Status | D69: Evidence | E69: Notes
A70: 1 | B70: Is gap analysis performed quarterly?
A71: 2 | B71: Are missing inventories identified?
A72: 3 | B72: Are unclassified systems identified?
A73: 4 | B73: Are fields without owners identified?
A74: 5 | B74: Are regulatory gaps documented?
A75: 6 | B75: Are masking gaps prioritised?
A76: 7 | B76: Are root causes analysed?
A77: 8 | B77: Are remediation actions defined?
A78: 9 | B78: Are remediation owners assigned?
A79: 10 | B79: Are target dates realistic?
A80: 11 | B80: Is gap closure tracked?
A81: 12 | B81: Are accepted risks documented?

Sheet Evidence Register
A1: EVIDENCE REGISTER
A2: List all evidence files/documents referenced in this assessment (ISMS-IMP-A.8.11.1).
A4: Evidence ID | B4: Category | C4: Description | D4: Source/Location | E4: Date Collected | F4: Collected By | G4: Status | H4: Notes
A5: EV-001 | B5: Data Discovery Report | C5: Sensitive data inventory scan results for Q1 2026 | D5: /evidence/data-discovery-q1-2026.xlsx | E5: 15.01.2026 | F5: Data Protection Team | G5: Verified | H5: Quarterly scan covering all production databases

Sheet Summary Dashboard
A1: Data Inventory & Classification Assessment — SUMMARY DASHBOARD
A2: Summary Dashboard | Data Inventory & Classification Assessment | Generated: 07.03.2026
A4: TABLE 1 – COMPLIANCE ASSESSMENT SUMMARY
A5: Assessment Area | B5: Total Items | C5: Compliant | D5: Partial | E5: Non-Compliant | F5: N/A | G5: Compliance %
A6: Sensitive Data Inventory | B6: =COUNTA('Sensitive Data Inventory'!B8:B100) | C6: =COUNTIF('Sensitive Data Inventory'!M8:M100,"Masked")+COUNTIF('Sensitive Data Inventory'!M8:M100,"Encrypted") | D6: =COUNTIF('Sensitive Data Inventory'!M8:M100,"Partially Masked") | E6: =COUNTIF('Sensitive Data Inventory'!M8:M100,"Not Masked") | F6: =COUNTIF('Sensitive Data Inventory'!M8:M100,"Planned") | G6: =IF((B6-F6)=0,0,C6/(B6-F6))
A7: System Inventory | B7: =COUNTA('System Inventory'!B8:B100) | C7: =COUNTIF('System Inventory'!J8:J100,"✅ Complete") | D7: =COUNTIF('System Inventory'!J8:J100,"⚠️ Partial") | E7: =COUNTIF('System Inventory'!J8:J100,"❌ Missing") | F7: =COUNTIF('System Inventory'!J8:J100,"N/A") | G7: =IF((B7-F7)=0,0,C7/(B7-F7))
A8: Classification Matrix | B8: =COUNTA('Classification Matrix'!B17:B100) | C8: =COUNTA('Classification Matrix'!F17:F100) | D8: =0 | E8: =0 | F8: =0 | G8: =IF((B8-F8)=0,0,C8/(B8-F8))
A9: Masking Priority Matrix | B9: =COUNTA('Masking Priority Matrix'!B16:B100) | C9: =COUNTIF('Masking Priority Matrix'!N16:N100,"Complete") | D9: =COUNTIF('Masking Priority Matrix'!N16:N100,"In Progress") | E9: =COUNTIF('Masking Priority Matrix'!N16:N100,"Not Started")+COUNTIF('Masking Priority Matrix'!N16:N100,"Blocked") | F9: =0 | G9: =IF((B9-F9)=0,0,C9/(B9-F9))
A10: Gap Analysis | B10: =COUNTA('Gap Analysis'!B17:B100) | C10: =COUNTIF('Gap Analysis'!L17:L100,"Complete")+COUNTIF('Gap Analysis'!L17:L100,"Accepted Risk") | D10: =COUNTIF('Gap Analysis'!L17:L100,"In Progress") | E10: =COUNTIF('Gap Analysis'!L17:L100,"Open") | F10: =0 | G10: =IF((B10-F10)=0,0,C10/(B10-F10))
A11: TOTAL | B11: =SUM(B6:B10) | C11: =SUM(C6:C10) | D11: =SUM(D6:D10) | E11: =SUM(E6:E10) | F11: =SUM(F6:F10) | G11: =IF((B11-F11)=0,0,C11/(B11-F11))
A13: TABLE 2 – KEY METRICS
A14: Metric | B14: Value | C14: Target
A15: Sensitive Data Fields Masked (%) | B15: =IF(COUNTA('Sensitive Data Inventory'!M8:M100)=0,"N/A",TEXT((COUNTIF('Sensitive Data Inventory'!M8:M100,"Masked")+COUNTIF('Sensitive Data Inventory'!M8:M100,"Encrypted"))/COUNTA('Sensitive Data Inventory'!M8:M100),"0.0%")) | C15: 100%
A16: Systems Fully Inventoried (%) | B16: =IF(COUNTA('System Inventory'!J8:J100)=0,"N/A",TEXT(COUNTIF('System Inventory'!J8:J100,"✅ Complete")/COUNTA('System Inventory'!J8:J100),"0.0%")) | C16: 100%
A17: Data Fields Classified (%) | B17: =IF(COUNTA('Classification Matrix'!A17:A100)=0,"N/A",TEXT(COUNTA('Classification Matrix'!F17:F100)/COUNTA('Classification Matrix'!A17:A100),"0.0%")) | C17: 100%
A18: P1 Gaps Remediated (%) | B18: =IF(COUNTA('Gap Analysis'!A17:A100)=0,"N/A",TEXT((COUNTIF('Gap Analysis'!L17:L100,"Complete")+COUNTIF('Gap Analysis'!L17:L100,"Accepted Risk"))/COUNTA('Gap Analysis'!A17:A100),"0.0%")) | C18: 100%
A19: Open Critical Gaps (Count) | B19: =COUNTIF('Gap Analysis'!L17:L100,"Open") | C19: 0
A20: Masking Implementation Complete (%) | B20: =IF(COUNTA('Masking Priority Matrix'!N16:N100)=0,"N/A",TEXT(COUNTIF('Masking Priority Matrix'!N16:N100,"Complete")/COUNTA('Masking Priority Matrix'!N16:N100),"0.0%")) | C20: 100%
A22: TABLE 3 – KEY FINDINGS & RECOMMENDATIONS
A23: # | B23: Finding | C23: Impact | D23: Recommendation | E23: Priority | F23: Status | G23: Notes
A24: 1 | B24: Sensitive data fields not yet masked in non-production environments | C24: High — GDPR/FADP non-compliance risk | D24: Implement Static Data Masking (SDM) in all non-production data refresh pipelines | E24: P1 | F24: Open
A25: 2 | B25: Data classification incomplete for some systems | C25: Medium — masking priorities cannot be set without classification | D25: Complete classification matrix for all inventoried systems; assign data owners | E25: P2 | F25: In Progress
A26: 3 | B26: Data owner assignments missing for several systems | C26: Medium — accountability gap; masking decisions require owner approval | D26: Conduct data ownership workshops; RACI matrix to be approved by CISO | E26: P2 | F26: Open
A27: 4 | B27: Gap analysis items not all remediated | C27: Medium — open gaps indicate unprotected sensitive data | D27: Prioritise P1 gaps; establish 30/60/90 day remediation milestones | E27: P2 | F27: In Progress

Sheet Approval Sign-Off
A1: ASSESSMENT APPROVAL AND SIGN-OFF
A3: ASSESSMENT SUMMARY
A4: Document: | B4: ISMS-IMP-A.8.11.1 - Data Inventory & Classification Assessment
A5: Assessment Period:
A6: Overall Compliance: | B6: =IFERROR(AVERAGE('Summary Dashboard'!G6:G10),"")
A7: Assessment Status:
A10: PREPARED BY (DATA GOVERNANCE)
A11: Name:
A12: Title:
A13: Date:
A14: Signature:
A15: Comments:
A17: REVIEWED BY (DPO / ISO)
A18: Name:
A19: Title:
A20: Date:
A21: Signature:
... A39: Notes:
