Workbook

Sheet Instructions_Legend
A1: ISMS Control A.8.11.5 - Master Compliance Dashboard
A2: ISO/IEC 27001:2022 - Data Masking Policy Compliance Overview - Systems Engineering Approach
A4: DOCUMENT INFORMATION
A5: Document ID: | B5: ISMS-IMP-A.8.11.5
A6: Document Type: | B6: Master Compliance Dashboard
A7: Assessment Area: | B7: Data Masking - Consolidated View
A8: Related Policies: | B8: All ISMS-POL-A.8.11-S2.x
A9: Version: | B9: 1.0
A10: Dashboard Date: | B10: [USER INPUT]
A11: Prepared By: | B11: [USER INPUT]
A12: Organization: | B12: [USER INPUT]
A13: Review Cycle: | B13: Quarterly
A14: Last Updated: | B14: =TODAY()
A17: SYSTEMS ENGINEERING WORKFLOW
A18: This dashboard follows a Systems Engineering approach with automated data integration:
A20: Step 1: Complete Assessments | B20: Generate all 4 domain workbooks (with dated filenames)
B21: • ISMS-IMP-A.8.11.1 - Data Inventory & Classification
B22: • ISMS-IMP-A.8.11.2 - Masking Technique Selection
B23: • ISMS-IMP-A.8.11.3 - Environment Coverage Assessment
B24: • ISMS-IMP-A.8.11.4 - Testing & Validation Framework
A26: Step 2: Normalize Files | B26: Run normalization script to create standardized filenames:
B27: $ python3 normalize_assessment_files_a811.py
B28: Creates: Dashboard_Sources/ folder
B29: Output files:
B30: → ISMS-IMP-A.8.11.1.xlsx (Data Inventory)
B31: → ISMS-IMP-A.8.11.2.xlsx (Masking Techniques)
B32: → ISMS-IMP-A.8.11.3.xlsx (Environment Coverage)
B33: → ISMS-IMP-A.8.11.4.xlsx (Testing & Validation)
B34: → normalization_manifest_a811.txt (audit trail)
A36: Step 3: Generate Dashboard | B36: Run this script to create the master dashboard:
B37: $ python3 generate_a811_5_compliance_dashboard.py
A39: Step 4: Deploy Dashboard | B39: Place generated dashboard in Dashboard_Sources/ folder:
B40: $ mv ISMS-IMP-A.8.11.5_Compliance_Dashboard_*.xlsx Dashboard_Sources/
A42: Step 5: Update Links | B42: Open dashboard in Excel/LibreOffice:
B43: 1. Open Dashboard_Sources/ISMS-IMP-A.8.11.5_Compliance_Dashboard_*.xlsx
B44: 2. When prompted 'Update Links?' → Click 'Yes' or 'Update'
B45: 3. Dashboard auto-populates with data from normalized files
B46: 4. Verify no #REF! errors (indicates source files are present)
A49: EXTERNAL WORKBOOK ARCHITECTURE
A50: This dashboard uses EXTERNAL FORMULAS to link to normalized source files:
...

Sheet Executive_Summary
A1: EXECUTIVE SUMMARY - DATA MASKING COMPLIANCE
A2: One-Page Overview for CISO, DPO, and Board - Consolidated View of All Domains
A4: OVERALL COMPLIANCE SCORECARD
A5: Metric | B5: Value | C5: Target | D5: Status | E5: Trend
A6: Overall Compliance Score | B6: =AVERAGE(B7:B12) | C6: ≥90%
A7: Data Inventory Coverage | B7: =[ISMS-IMP-A.8.11.1.xlsx]Summary_Dashboard!$B$7 | C7: 100%
A8: Sensitive Fields Classified | B8: =[ISMS-IMP-A.8.11.1.xlsx]Summary_Dashboard!$B$6 | C8: 100%
A9: Masking Technique Deployment | B9: =[ISMS-IMP-A.8.11.2.xlsx]Summary_Dashboard!$B$6 | C9: ≥90%
A10: Non-Production Masking Coverage | B10: =[ISMS-IMP-A.8.11.3.xlsx]Summary_Dashboard!$B$7 | C10: 100%
A11: Production DDM Coverage | B11: =[ISMS-IMP-A.8.11.3.xlsx]Summary_Dashboard!$B$10 | C11: ≥90%
A12: Testing Pass Rate | B12: =[ISMS-IMP-A.8.11.4.xlsx]Summary_Dashboard!$B$8 | C12: ≥95%
A13: Re-Identification Risk | B13: =[ISMS-IMP-A.8.11.4.xlsx]Summary_Dashboard!$B$12 | C13: 0%
A14: Data Utility Score | B14: =[ISMS-IMP-A.8.11.4.xlsx]Summary_Dashboard!$B$13 | C14: ≥95%
A15: Performance Impact | B15: =[ISMS-IMP-A.8.11.4.xlsx]Summary_Dashboard!$B$14 | C15: <10%
A17: DOMAIN QUICK STATS
A18: Domain | B18: Total Items | C18: Compliant | D18: Partial | E18: Non-Compliant | F18: Coverage %
A19: 1. Data Inventory | B19: =[ISMS-IMP-A.8.11.1.xlsx]Summary_Dashboard!$B$5 | C19: =[ISMS-IMP-A.8.11.1.xlsx]Summary_Dashboard!$C$10 | D19: =[ISMS-IMP-A.8.11.1.xlsx]Summary_Dashboard!$D$10 | E19: =[ISMS-IMP-A.8.11.1.xlsx]Summary_Dashboard!$E$10 | F19: =C19/B19
A20: 2. Masking Techniques | B20: =[ISMS-IMP-A.8.11.2.xlsx]Summary_Dashboard!$B$5 | C20: =[ISMS-IMP-A.8.11.2.xlsx]Summary_Dashboard!$C$10 | D20: =[ISMS-IMP-A.8.11.2.xlsx]Summary_Dashboard!$D$10 | E20: =[ISMS-IMP-A.8.11.2.xlsx]Summary_Dashboard!$E$10 | F20: =C20/B20
A21: 3. Environment Coverage | B21: =[ISMS-IMP-A.8.11.3.xlsx]Summary_Dashboard!$B$5 | C21: =[ISMS-IMP-A.8.11.3.xlsx]Summary_Dashboard!$C$10 | D21: =[ISMS-IMP-A.8.11.3.xlsx]Summary_Dashboard!$D$10 | E21: =[ISMS-IMP-A.8.11.3.xlsx]Summary_Dashboard!$E$10 | F21: =C21/B21
A22: 4. Testing & Validation | B22: =[ISMS-IMP-A.8.11.4.xlsx]Summary_Dashboard!$B$5 | C22: =[ISMS-IMP-A.8.11.4.xlsx]Summary_Dashboard!$C$10 | D22: =[ISMS-IMP-A.8.11.4.xlsx]Summary_Dashboard!$D$10 | E22: =[ISMS-IMP-A.8.11.4.xlsx]Summary_Dashboard!$E$10 | F22: =C22/B22
A23: TOTAL | B23: =SUM(B19:B22) | C23: =SUM(C19:C22) | D23: =SUM(D19:D22) | E23: =SUM(E19:E22) | F23: =AVERAGE(F19:F22)
A25: CRITICAL GAPS (TOP 10) - IMMEDIATE ATTENTION REQUIRED
A26: Priority | B26: Gap Description | C26: Domain | D26: Risk Level | E26: Owner | F26: Target Date | G26: Status
A27: P0-Critical | B27: Unmasked PII in UAT environment | C27: Domain 3 | D27: Critical | E27: [ASSIGN] | F27: [DATE] | G27: Open
A28: P0-Critical | B28: Production data copied to dev without masking | C28: Domain 3 | D28: Critical | E28: [ASSIGN] | F28: [DATE] | G28: Open
A29: P1-High | B29: Credit card numbers not masked in test DB | C29: Domain 1 | D29: High | E29: [ASSIGN] | F29: [DATE] | G29: Open
A30: P1-High | B30: Re-identification possible via join attacks | C30: Domain 4 | D30: High | E30: [ASSIGN] | F30: [DATE] | G30: Open
A31: P1-High | B31: Backup tapes contain unmasked sensitive data | C31: Domain 3 | D31: High | E31: [ASSIGN] | F31: [DATE] | G31: Open
A32: P2-Medium | B32: Incomplete data inventory for cloud systems | C32: Domain 1 | D32: Medium | E32: [ASSIGN] | F32: [DATE] | G32: In Progress
A33: P2-Medium | B33: DDM not implemented in production API | C33: Domain 2 | D33: Medium | E33: [ASSIGN] | F33: [DATE] | G33: Planned
A34: P2-Medium | B34: Testing coverage <95% for masking functions | C34: Domain 4 | D34: Medium | E34: [ASSIGN] | F34: [DATE] | G34: In Progress
A35: P3-Low | B35: Data owner assignment incomplete (15% missing) | C35: Domain 1 | D35: Low | E35: [ASSIGN] | F35: [DATE] | G35: Planned
A36: P3-Low | B36: Evidence documentation gaps for 3 systems | C36: Domain 1 | D36: Low | E36: [ASSIGN] | F36: [DATE] | G36: Planned
A38: RISK SUMMARY BY CATEGORY
A39: Risk Category | B39: Critical | C39: High | D39: Medium | E39: Low | F39: Total | G39: Mitigation Status
A40: Unmasked Environments | B40: =COUNTIFS(Risk_Register!$B:$B,"Data Leakage",Risk_Register!$G:$G,"Critical")
A41: Re-Identification Risk | B41: =COUNTIFS(Risk_Register!$B:$B,"Re-identification",Risk_Register!$G:$G,"Critical")
A42: Schema Drift (Unmasked Fields) | B42: =COUNTIFS(Risk_Register!$B:$B,"Incomplete Coverage",Risk_Register!$G:$G,"High")
A43: Performance Impact | B43: =COUNTIFS(Risk_Register!$B:$B,"Performance Impact",Risk_Register!$G:$G,"Medium")
A44: Compliance Violations | B44: =COUNTIFS(Risk_Register!$B:$B,"Compliance Violation",Risk_Register!$G:$G,"Critical")
...

Sheet Domain_1_Summary
A1: DOMAIN 1 SUMMARY - DATA INVENTORY & CLASSIFICATION
A2: Data Source: [ISMS-IMP-A.8.11.1.xlsx]Summary_Dashboard (Normalized File)
A4: SUMMARY METRICS FROM SOURCE WORKBOOK
A5: Metric | B5: Value | C5: Formula Reference | D5: Target | E5: Status
A6: Metric 1 | B6: =[ISMS-IMP-A.8.11.1.xlsx]Summary_Dashboard!$B$5 | C6: Summary_Dashboard!B5
A7: Metric 2 | B7: =[ISMS-IMP-A.8.11.1.xlsx]Summary_Dashboard!$B$6 | C7: Summary_Dashboard!B6
A8: Metric 3 | B8: =[ISMS-IMP-A.8.11.1.xlsx]Summary_Dashboard!$B$7 | C8: Summary_Dashboard!B7
A9: Metric 4 | B9: =[ISMS-IMP-A.8.11.1.xlsx]Summary_Dashboard!$B$8 | C9: Summary_Dashboard!B8
A10: Metric 5 | B10: =[ISMS-IMP-A.8.11.1.xlsx]Summary_Dashboard!$B$9 | C10: Summary_Dashboard!B9
A11: Metric 6 | B11: =[ISMS-IMP-A.8.11.1.xlsx]Summary_Dashboard!$B$10 | C11: Summary_Dashboard!B10
A12: Metric 7 | B12: =[ISMS-IMP-A.8.11.1.xlsx]Summary_Dashboard!$B$11 | C12: Summary_Dashboard!B11
A13: Metric 8 | B13: =[ISMS-IMP-A.8.11.1.xlsx]Summary_Dashboard!$B$12 | C13: Summary_Dashboard!B12
A14: Metric 9 | B14: =[ISMS-IMP-A.8.11.1.xlsx]Summary_Dashboard!$B$13 | C14: Summary_Dashboard!B13
A15: Metric 10 | B15: =[ISMS-IMP-A.8.11.1.xlsx]Summary_Dashboard!$B$14 | C15: Summary_Dashboard!B14
A16: Metric 11 | B16: =[ISMS-IMP-A.8.11.1.xlsx]Summary_Dashboard!$B$15 | C16: Summary_Dashboard!B15
A17: Metric 12 | B17: =[ISMS-IMP-A.8.11.1.xlsx]Summary_Dashboard!$B$16 | C17: Summary_Dashboard!B16
A18: Metric 13 | B18: =[ISMS-IMP-A.8.11.1.xlsx]Summary_Dashboard!$B$17 | C18: Summary_Dashboard!B17
A19: Metric 14 | B19: =[ISMS-IMP-A.8.11.1.xlsx]Summary_Dashboard!$B$18 | C19: Summary_Dashboard!B18
A20: Metric 15 | B20: =[ISMS-IMP-A.8.11.1.xlsx]Summary_Dashboard!$B$19 | C20: Summary_Dashboard!B19
A22: COMPLIANCE STATUS BREAKDOWN
A23: Status Category | B23: Count | C23: Percentage | D23: Trend | E23: Notes
A24: Compliant (Green) | B24: =[ISMS-IMP-A.8.11.1.xlsx]Summary_Dashboard!$C$10 | C24: =B24/B28
A25: Partial (Yellow) | B25: =[ISMS-IMP-A.8.11.1.xlsx]Summary_Dashboard!$D$10 | C25: =B24/B27
A26: Non-Compliant (Red) | B26: =[ISMS-IMP-A.8.11.1.xlsx]Summary_Dashboard!$E$10 | C26: =B24/B26
A27: Planned (Blue) | B27: =[ISMS-IMP-A.8.11.1.xlsx]Summary_Dashboard!$F$10 | C27: =B24/B25
A28: TOTAL | B28: =SUM(B24:B27) | C28: 100%
A30: KEY FINDINGS (MANUAL ENTRY)
A31: Finding 1:
A32: Finding 2:
A33: Finding 3:
A34: Finding 4:
A35: Finding 5:
A37: GAPS & RISKS IDENTIFIED IN DOMAIN 1
A38: Severity | B38: Count | C38: % of Total | D38: Action Required
A39: Critical | B39: =COUNTIFS(Consolidated_Gap_Analysis!$B:$B,"Domain 1",Consolidated_Gap_Analysis!$G:$G,"Critical")
A40: High | B40: =COUNTIFS(Consolidated_Gap_Analysis!$B:$B,"Domain 1",Consolidated_Gap_Analysis!$G:$G,"High")
A41: Medium | B41: =COUNTIFS(Consolidated_Gap_Analysis!$B:$B,"Domain 1",Consolidated_Gap_Analysis!$G:$G,"Medium")
A42: Low | B42: =COUNTIFS(Consolidated_Gap_Analysis!$B:$B,"Domain 1",Consolidated_Gap_Analysis!$G:$G,"Low")

Sheet Domain_2_Summary
A1: DOMAIN 2 SUMMARY - MASKING TECHNIQUE SELECTION
A2: Data Source: [ISMS-IMP-A.8.11.2.xlsx]Summary_Dashboard (Normalized File)
A4: SUMMARY METRICS FROM SOURCE WORKBOOK
A5: Metric | B5: Value | C5: Formula Reference | D5: Target | E5: Status
A6: Metric 1 | B6: =[ISMS-IMP-A.8.11.2.xlsx]Summary_Dashboard!$B$5 | C6: Summary_Dashboard!B5
A7: Metric 2 | B7: =[ISMS-IMP-A.8.11.2.xlsx]Summary_Dashboard!$B$6 | C7: Summary_Dashboard!B6
A8: Metric 3 | B8: =[ISMS-IMP-A.8.11.2.xlsx]Summary_Dashboard!$B$7 | C8: Summary_Dashboard!B7
A9: Metric 4 | B9: =[ISMS-IMP-A.8.11.2.xlsx]Summary_Dashboard!$B$8 | C9: Summary_Dashboard!B8
A10: Metric 5 | B10: =[ISMS-IMP-A.8.11.2.xlsx]Summary_Dashboard!$B$9 | C10: Summary_Dashboard!B9
A11: Metric 6 | B11: =[ISMS-IMP-A.8.11.2.xlsx]Summary_Dashboard!$B$10 | C11: Summary_Dashboard!B10
A12: Metric 7 | B12: =[ISMS-IMP-A.8.11.2.xlsx]Summary_Dashboard!$B$11 | C12: Summary_Dashboard!B11
A13: Metric 8 | B13: =[ISMS-IMP-A.8.11.2.xlsx]Summary_Dashboard!$B$12 | C13: Summary_Dashboard!B12
A14: Metric 9 | B14: =[ISMS-IMP-A.8.11.2.xlsx]Summary_Dashboard!$B$13 | C14: Summary_Dashboard!B13
A15: Metric 10 | B15: =[ISMS-IMP-A.8.11.2.xlsx]Summary_Dashboard!$B$14 | C15: Summary_Dashboard!B14
A16: Metric 11 | B16: =[ISMS-IMP-A.8.11.2.xlsx]Summary_Dashboard!$B$15 | C16: Summary_Dashboard!B15
A17: Metric 12 | B17: =[ISMS-IMP-A.8.11.2.xlsx]Summary_Dashboard!$B$16 | C17: Summary_Dashboard!B16
A18: Metric 13 | B18: =[ISMS-IMP-A.8.11.2.xlsx]Summary_Dashboard!$B$17 | C18: Summary_Dashboard!B17
A19: Metric 14 | B19: =[ISMS-IMP-A.8.11.2.xlsx]Summary_Dashboard!$B$18 | C19: Summary_Dashboard!B18
A20: Metric 15 | B20: =[ISMS-IMP-A.8.11.2.xlsx]Summary_Dashboard!$B$19 | C20: Summary_Dashboard!B19
A22: COMPLIANCE STATUS BREAKDOWN
A23: Status Category | B23: Count | C23: Percentage | D23: Trend | E23: Notes
A24: Compliant (Green) | B24: =[ISMS-IMP-A.8.11.2.xlsx]Summary_Dashboard!$C$10 | C24: =B24/B28
A25: Partial (Yellow) | B25: =[ISMS-IMP-A.8.11.2.xlsx]Summary_Dashboard!$D$10 | C25: =B24/B27
A26: Non-Compliant (Red) | B26: =[ISMS-IMP-A.8.11.2.xlsx]Summary_Dashboard!$E$10 | C26: =B24/B26
A27: Planned (Blue) | B27: =[ISMS-IMP-A.8.11.2.xlsx]Summary_Dashboard!$F$10 | C27: =B24/B25
A28: TOTAL | B28: =SUM(B24:B27) | C28: 100%
A30: KEY FINDINGS (MANUAL ENTRY)
A31: Finding 1:
A32: Finding 2:
A33: Finding 3:
A34: Finding 4:
A35: Finding 5:
A37: GAPS & RISKS IDENTIFIED IN DOMAIN 2
A38: Severity | B38: Count | C38: % of Total | D38: Action Required
A39: Critical | B39: =COUNTIFS(Consolidated_Gap_Analysis!$B:$B,"Domain 2",Consolidated_Gap_Analysis!$G:$G,"Critical")
A40: High | B40: =COUNTIFS(Consolidated_Gap_Analysis!$B:$B,"Domain 2",Consolidated_Gap_Analysis!$G:$G,"High")
A41: Medium | B41: =COUNTIFS(Consolidated_Gap_Analysis!$B:$B,"Domain 2",Consolidated_Gap_Analysis!$G:$G,"Medium")
A42: Low | B42: =COUNTIFS(Consolidated_Gap_Analysis!$B:$B,"Domain 2",Consolidated_Gap_Analysis!$G:$G,"Low")

Sheet Domain_3_Summary
A1: DOMAIN 3 SUMMARY - ENVIRONMENT COVERAGE
A2: Data Source: [ISMS-IMP-A.8.11.3.xlsx]Summary_Dashboard (Normalized File)
A4: SUMMARY METRICS FROM SOURCE WORKBOOK
A5: Metric | B5: Value | C5: Formula Reference | D5: Target | E5: Status
A6: Metric 1 | B6: =[ISMS-IMP-A.8.11.3.xlsx]Summary_Dashboard!$B$5 | C6: Summary_Dashboard!B5
A7: Metric 2 | B7: =[ISMS-IMP-A.8.11.3.xlsx]Summary_Dashboard!$B$6 | C7: Summary_Dashboard!B6
A8: Metric 3 | B8: =[ISMS-IMP-A.8.11.3.xlsx]Summary_Dashboard!$B$7 | C8: Summary_Dashboard!B7
A9: Metric 4 | B9: =[ISMS-IMP-A.8.11.3.xlsx]Summary_Dashboard!$B$8 | C9: Summary_Dashboard!B8
A10: Metric 5 | B10: =[ISMS-IMP-A.8.11.3.xlsx]Summary_Dashboard!$B$9 | C10: Summary_Dashboard!B9
A11: Metric 6 | B11: =[ISMS-IMP-A.8.11.3.xlsx]Summary_Dashboard!$B$10 | C11: Summary_Dashboard!B10
A12: Metric 7 | B12: =[ISMS-IMP-A.8.11.3.xlsx]Summary_Dashboard!$B$11 | C12: Summary_Dashboard!B11
A13: Metric 8 | B13: =[ISMS-IMP-A.8.11.3.xlsx]Summary_Dashboard!$B$12 | C13: Summary_Dashboard!B12
A14: Metric 9 | B14: =[ISMS-IMP-A.8.11.3.xlsx]Summary_Dashboard!$B$13 | C14: Summary_Dashboard!B13
A15: Metric 10 | B15: =[ISMS-IMP-A.8.11.3.xlsx]Summary_Dashboard!$B$14 | C15: Summary_Dashboard!B14
A16: Metric 11 | B16: =[ISMS-IMP-A.8.11.3.xlsx]Summary_Dashboard!$B$15 | C16: Summary_Dashboard!B15
A17: Metric 12 | B17: =[ISMS-IMP-A.8.11.3.xlsx]Summary_Dashboard!$B$16 | C17: Summary_Dashboard!B16
A18: Metric 13 | B18: =[ISMS-IMP-A.8.11.3.xlsx]Summary_Dashboard!$B$17 | C18: Summary_Dashboard!B17
A19: Metric 14 | B19: =[ISMS-IMP-A.8.11.3.xlsx]Summary_Dashboard!$B$18 | C19: Summary_Dashboard!B18
A20: Metric 15 | B20: =[ISMS-IMP-A.8.11.3.xlsx]Summary_Dashboard!$B$19 | C20: Summary_Dashboard!B19
A22: COMPLIANCE STATUS BREAKDOWN
A23: Status Category | B23: Count | C23: Percentage | D23: Trend | E23: Notes
A24: Compliant (Green) | B24: =[ISMS-IMP-A.8.11.3.xlsx]Summary_Dashboard!$C$10 | C24: =B24/B28
A25: Partial (Yellow) | B25: =[ISMS-IMP-A.8.11.3.xlsx]Summary_Dashboard!$D$10 | C25: =B24/B27
A26: Non-Compliant (Red) | B26: =[ISMS-IMP-A.8.11.3.xlsx]Summary_Dashboard!$E$10 | C26: =B24/B26
A27: Planned (Blue) | B27: =[ISMS-IMP-A.8.11.3.xlsx]Summary_Dashboard!$F$10 | C27: =B24/B25
A28: TOTAL | B28: =SUM(B24:B27) | C28: 100%
A30: KEY FINDINGS (MANUAL ENTRY)
A31: Finding 1:
A32: Finding 2:
A33: Finding 3:
A34: Finding 4:
A35: Finding 5:
A37: GAPS & RISKS IDENTIFIED IN DOMAIN 3
A38: Severity | B38: Count | C38: % of Total | D38: Action Required
A39: Critical | B39: =COUNTIFS(Consolidated_Gap_Analysis!$B:$B,"Domain 3",Consolidated_Gap_Analysis!$G:$G,"Critical")
A40: High | B40: =COUNTIFS(Consolidated_Gap_Analysis!$B:$B,"Domain 3",Consolidated_Gap_Analysis!$G:$G,"High")
A41: Medium | B41: =COUNTIFS(Consolidated_Gap_Analysis!$B:$B,"Domain 3",Consolidated_Gap_Analysis!$G:$G,"Medium")
A42: Low | B42: =COUNTIFS(Consolidated_Gap_Analysis!$B:$B,"Domain 3",Consolidated_Gap_Analysis!$G:$G,"Low")

Sheet Domain_4_Summary
A1: DOMAIN 4 SUMMARY - TESTING & VALIDATION
A2: Data Source: [ISMS-IMP-A.8.11.4.xlsx]Summary_Dashboard (Normalized File)
A4: SUMMARY METRICS FROM SOURCE WORKBOOK
A5: Metric | B5: Value | C5: Formula Reference | D5: Target | E5: Status
A6: Metric 1 | B6: =[ISMS-IMP-A.8.11.4.xlsx]Summary_Dashboard!$B$5 | C6: Summary_Dashboard!B5
A7: Metric 2 | B7: =[ISMS-IMP-A.8.11.4.xlsx]Summary_Dashboard!$B$6 | C7: Summary_Dashboard!B6
A8: Metric 3 | B8: =[ISMS-IMP-A.8.11.4.xlsx]Summary_Dashboard!$B$7 | C8: Summary_Dashboard!B7
A9: Metric 4 | B9: =[ISMS-IMP-A.8.11.4.xlsx]Summary_Dashboard!$B$8 | C9: Summary_Dashboard!B8
A10: Metric 5 | B10: =[ISMS-IMP-A.8.11.4.xlsx]Summary_Dashboard!$B$9 | C10: Summary_Dashboard!B9
A11: Metric 6 | B11: =[ISMS-IMP-A.8.11.4.xlsx]Summary_Dashboard!$B$10 | C11: Summary_Dashboard!B10
A12: Metric 7 | B12: =[ISMS-IMP-A.8.11.4.xlsx]Summary_Dashboard!$B$11 | C12: Summary_Dashboard!B11
A13: Metric 8 | B13: =[ISMS-IMP-A.8.11.4.xlsx]Summary_Dashboard!$B$12 | C13: Summary_Dashboard!B12
A14: Metric 9 | B14: =[ISMS-IMP-A.8.11.4.xlsx]Summary_Dashboard!$B$13 | C14: Summary_Dashboard!B13
A15: Metric 10 | B15: =[ISMS-IMP-A.8.11.4.xlsx]Summary_Dashboard!$B$14 | C15: Summary_Dashboard!B14
A16: Metric 11 | B16: =[ISMS-IMP-A.8.11.4.xlsx]Summary_Dashboard!$B$15 | C16: Summary_Dashboard!B15
A17: Metric 12 | B17: =[ISMS-IMP-A.8.11.4.xlsx]Summary_Dashboard!$B$16 | C17: Summary_Dashboard!B16
A18: Metric 13 | B18: =[ISMS-IMP-A.8.11.4.xlsx]Summary_Dashboard!$B$17 | C18: Summary_Dashboard!B17
A19: Metric 14 | B19: =[ISMS-IMP-A.8.11.4.xlsx]Summary_Dashboard!$B$18 | C19: Summary_Dashboard!B18
A20: Metric 15 | B20: =[ISMS-IMP-A.8.11.4.xlsx]Summary_Dashboard!$B$19 | C20: Summary_Dashboard!B19
A22: COMPLIANCE STATUS BREAKDOWN
A23: Status Category | B23: Count | C23: Percentage | D23: Trend | E23: Notes
A24: Compliant (Green) | B24: =[ISMS-IMP-A.8.11.4.xlsx]Summary_Dashboard!$C$10 | C24: =B24/B28
A25: Partial (Yellow) | B25: =[ISMS-IMP-A.8.11.4.xlsx]Summary_Dashboard!$D$10 | C25: =B24/B27
A26: Non-Compliant (Red) | B26: =[ISMS-IMP-A.8.11.4.xlsx]Summary_Dashboard!$E$10 | C26: =B24/B26
A27: Planned (Blue) | B27: =[ISMS-IMP-A.8.11.4.xlsx]Summary_Dashboard!$F$10 | C27: =B24/B25
A28: TOTAL | B28: =SUM(B24:B27) | C28: 100%
A30: KEY FINDINGS (MANUAL ENTRY)
A31: Finding 1:
A32: Finding 2:
A33: Finding 3:
A34: Finding 4:
A35: Finding 5:
A37: GAPS & RISKS IDENTIFIED IN DOMAIN 4
A38: Severity | B38: Count | C38: % of Total | D38: Action Required
A39: Critical | B39: =COUNTIFS(Consolidated_Gap_Analysis!$B:$B,"Domain 4",Consolidated_Gap_Analysis!$G:$G,"Critical")
A40: High | B40: =COUNTIFS(Consolidated_Gap_Analysis!$B:$B,"Domain 4",Consolidated_Gap_Analysis!$G:$G,"High")
A41: Medium | B41: =COUNTIFS(Consolidated_Gap_Analysis!$B:$B,"Domain 4",Consolidated_Gap_Analysis!$G:$G,"Medium")
A42: Low | B42: =COUNTIFS(Consolidated_Gap_Analysis!$B:$B,"Domain 4",Consolidated_Gap_Analysis!$G:$G,"Low")

Sheet Consolidated_Gap_Analysis
A1: CONSOLIDATED GAP ANALYSIS - ALL DOMAINS
A2: Aggregate gaps from all four domain assessments (50 entries)
A3: Gap ID | B3: Domain | C3: Gap Category | D3: Gap Description | E3: Current State | F3: Target State | G3: Risk Level | H3: Business Impact | I3: Remediation Action | J3: Owner | K3: Target Date | L3: Status | M3: Dependencies | N3: Evidence ID
A5: G-811-001 | B5: Domain 1 | C5: Data Inventory | D5: Cloud system inventory incomplete - AWS RDS instances not catalogued | E5: Manual tracking | F5: Automated discovery | G5: High
A6: G-811-002 | B6: Domain 1 | C6: Classification | D6: Credit card fields missing classification tags in 3 databases | E6: Unclassified | F6: CAT-FIN tagged | G6: Critical
A7: G-811-003 | B7: Domain 1 | C7: Data Ownership | D7: 15% of sensitive fields lack assigned data owners | E7: No owner | F7: Owner assigned | G7: Medium
A8: G-811-004 | B8: Domain 2 | C8: Technique Selection | D8: Tokenization not implemented for payment card data | E8: Clear text | F8: Tokenized | G8: Critical
A9: G-811-005 | B9: Domain 2 | C9: Algorithm Strength | D9: MD5 hashing used instead of SHA-256 in legacy system | E9: Weak hashing | F9: SHA-256+ | G9: High
A10: G-811-006 | B10: Domain 3 | C10: Non-Prod Masking | D10: UAT environment contains unmasked production PII | E10: Production copy | F10: Fully masked | G10: Critical
A11: G-811-007 | B11: Domain 3 | C11: Development Env | D11: Dev database refreshed weekly with unmasked data | E11: Production copy | F11: Masked refresh | G11: Critical
A12: G-811-008 | B12: Domain 3 | C12: DDM Implementation | D12: Production API endpoints expose unmasked SSN | E12: Clear text API | F12: DDM enabled | G12: Critical
A13: G-811-009 | B13: Domain 3 | C13: Backup Encryption | D13: Weekly backups not encrypted at rest | E13: Unencrypted | F13: AES-256 encrypted | G13: High
A14: G-811-010 | B14: Domain 4 | C14: Testing Coverage | D14: Only 70% of masking functions have automated tests | E14: 70% coverage | F14: ≥95% coverage | G14: Medium
A15: G-811-011 | B15: Domain 4 | C15: Re-ID Testing | D15: Re-identification risk not tested via join attacks | E15: Not tested | F15: Tested quarterly | G15: High
A16: G-811-012 | B16: Domain 4 | C16: Performance Testing | D16: Masking impact on query performance not measured | E16: Unknown impact | F16: Measured <10% | G16: Medium
... A24: G-811-020 | B24: Domain 4 | C24: Evidence Documentation | D24: Test results not retained per 2-year policy | E24: Ad-hoc retention | F24: Policy compliant | G24: Medium

Sheet Risk_Register
A1: MASKING RISK REGISTER - COMPREHENSIVE
A2: Data masking risks with likelihood, impact, risk scores, and mitigation strategies (40 entries)
A3: Risk ID | B3: Risk Category | C3: Risk Description | D3: Affected Domain | E3: Likelihood (1-5) | F3: Impact (1-5) | G3: Risk Score | H3: Risk Level | I3: Mitigation Strategy | J3: Owner | K3: Target Date | L3: Status | M3: Residual Risk | N3: Residual Score | O3: Notes
A5: R-811-001 | B5: Data Leakage | C5: Unmasked sensitive data exposed in non-production environments (UAT, QA, Dev) | D5: Domain 3 | E5: 4 | F5: 5 | G5: =E5*F5 | H5: =IF(G5>=15,"Critical",IF(G5>=10,"High",IF(G5>=5,"Medium","Low"))) | I5: Implement comprehensive environment-level masking with automated validation
A6: R-811-002 | B6: Re-identification | C6: Ability to reverse-engineer masked data to original values via join attacks or inference | D6: Domain 4 | E6: 3 | F6: 5 | G6: =E6*F6 | H6: =IF(G6>=15,"Critical",IF(G6>=10,"High",IF(G6>=5,"Medium","Low"))) | I6: Implement k-anonymity testing, suppress quasi-identifiers, validate via penetration testing
A7: R-811-003 | B7: Data Utility Loss | C7: Over-masking reduces data usefulness for testing, analytics, and business operations | D7: Domain 2 | E7: 3 | F7: 4 | G7: =E7*F7 | H7: =IF(G7>=15,"Critical",IF(G7>=10,"High",IF(G7>=5,"Medium","Low"))) | I7: Balance masking strength with utility requirements, implement format-preserving techniques
A8: R-811-004 | B8: Compliance Violation | C8: Failure to mask data violates GDPR Art. 32, FADP Art. 8, or contractual obligations | D8: All Domains | E8: 3 | F8: 5 | G8: =E8*F8 | H8: =IF(G8>=15,"Critical",IF(G8>=10,"High",IF(G8>=5,"Medium","Low"))) | I8: Map regulatory requirements to masking controls, document compliance evidence
A9: R-811-005 | B9: Performance Impact | C9: Masking operations degrade system performance beyond acceptable thresholds (>10%) | D9: Domain 4 | E9: 2 | F9: 3 | G9: =E9*F9 | H9: =IF(G9>=15,"Critical",IF(G9>=10,"High",IF(G9>=5,"Medium","Low"))) | I9: Benchmark performance, optimize algorithms, implement caching where appropriate
A10: R-811-006 | B10: Key Management | C10: Loss, compromise, or unauthorized access to masking keys or algorithms | D10: Domain 2 | E10: 2 | F10: 5 | G10: =E10*F10 | H10: =IF(G10>=15,"Critical",IF(G10>=10,"High",IF(G10>=5,"Medium","Low"))) | I10: Implement HSM/KMS for key storage, rotate keys regularly, enforce access controls
A11: R-811-007 | B11: Process Bypass | C11: Data extraction methods circumvent masking controls (direct DB access, exports) | D11: Domain 3 | E11: 3 | F11: 4 | G11: =E11*F11 | H11: =IF(G11>=15,"Critical",IF(G11>=10,"High",IF(G11>=5,"Medium","Low"))) | I11: Enforce access controls at all layers, monitor data extraction, implement audit logging
A12: R-811-008 | B12: Incomplete Coverage | C12: Sensitive data exists in unmapped/unmasked locations (shadow IT, cloud, archives) | D12: Domain 1 | E12: 4 | F12: 4 | G12: =E12*F12 | H12: =IF(G12>=15,"Critical",IF(G12>=10,"High",IF(G12>=5,"Medium","Low"))) | I12: Conduct comprehensive data discovery, implement automated detection, quarterly audits
A13: R-811-009 | B13: Third-Party Access | C13: Vendors, partners, or contractors receive unmasked sensitive data | D13: Domain 3 | E13: 3 | F13: 4 | G13: =E13*F13 | H13: =IF(G13>=15,"Critical",IF(G13>=10,"High",IF(G13>=5,"Medium","Low"))) | I13: Implement masked views for external access, contractual data protection clauses
A14: R-811-010 | B14: Audit Failure | C14: Insufficient evidence for regulatory audits (testing, validation, gap remediation) | D14: Domain 4 | E14: 2 | F14: 3 | G14: =E14*F14 | H14: =IF(G14>=15,"Critical",IF(G14>=10,"High",IF(G14>=5,"Medium","Low"))) | I14: Maintain comprehensive evidence register, document all testing, quarterly reviews
A15: R-811-011 | B15: Schema Drift | C15: New sensitive fields added to production without corresponding masking rules | D15: Domain 1 | E15: 4 | F15: 4 | G15: =E15*F15 | H15: =IF(G15>=15,"Critical",IF(G15>=10,"High",IF(G15>=5,"Medium","Low"))) | I15: Implement automated schema change detection, mandatory security review for DB changes
A16: R-811-012 | B16: Backup Exposure | C16: Unencrypted or unmasked backups/archives expose sensitive data | D16: Domain 3 | E16: 3 | F16: 5 | G16: =E16*F16 | H16: =IF(G16>=15,"Critical",IF(G16>=10,"High",IF(G16>=5,"Medium","Low"))) | I16: Encrypt all backups at rest, apply masking to long-term archives, test recovery procedures
... A24: R-811-020 | B24: Test Data Aging | C24: Test datasets become stale, teams revert to using production data | D24: Domain 3 | E24: 3 | F24: 3 | G24: =E24*F24 | H24: =IF(G24>=15,"Critical",IF(G24>=10,"High",IF(G24>=5,"Medium","Low"))) | I24: Automated test data refresh procedures, synthetic data generation, policy enforcement
G25: =IF(AND(E25<>"",F25<>""),E25*F25,"") | H25: =IF(G25="","",IF(G25>=15,"Critical",IF(G25>=10,"High",IF(G25>=5,"Medium","Low"))))
G26: =IF(AND(E26<>"",F26<>""),E26*F26,"") | H26: =IF(G26="","",IF(G26>=15,"Critical",IF(G26>=10,"High",IF(G26>=5,"Medium","Low"))))
G27: =IF(AND(E27<>"",F27<>""),E27*F27,"") | H27: =IF(G27="","",IF(G27>=15,"Critical",IF(G27>=10,"High",IF(G27>=5,"Medium","Low"))))
G28: =IF(AND(E28<>"",F28<>""),E28*F28,"") | H28: =IF(G28="","",IF(G28>=15,"Critical",IF(G28>=10,"High",IF(G28>=5,"Medium","Low"))))
G29: =IF(AND(E29<>"",F29<>""),E29*F29,"") | H29: =IF(G29="","",IF(G29>=15,"Critical",IF(G29>=10,"High",IF(G29>=5,"Medium","Low"))))
G30: =IF(AND(E30<>"",F30<>""),E30*F30,"") | H30: =IF(G30="","",IF(G30>=15,"Critical",IF(G30>=10,"High",IF(G30>=5,"Medium","Low"))))
G31: =IF(AND(E31<>"",F31<>""),E31*F31,"") | H31: =IF(G31="","",IF(G31>=15,"Critical",IF(G31>=10,"High",IF(G31>=5,"Medium","Low"))))
G32: =IF(AND(E32<>"",F32<>""),E32*F32,"") | H32: =IF(G32="","",IF(G32>=15,"Critical",IF(G32>=10,"High",IF(G32>=5,"Medium","Low"))))
G33: =IF(AND(E33<>"",F33<>""),E33*F33,"") | H33: =IF(G33="","",IF(G33>=15,"Critical",IF(G33>=10,"High",IF(G33>=5,"Medium","Low"))))
G34: =IF(AND(E34<>"",F34<>""),E34*F34,"") | H34: =IF(G34="","",IF(G34>=15,"Critical",IF(G34>=10,"High",IF(G34>=5,"Medium","Low"))))
G35: =IF(AND(E35<>"",F35<>""),E35*F35,"") | H35: =IF(G35="","",IF(G35>=15,"Critical",IF(G35>=10,"High",IF(G35>=5,"Medium","Low"))))
G36: =IF(AND(E36<>"",F36<>""),E36*F36,"") | H36: =IF(G36="","",IF(G36>=15,"Critical",IF(G36>=10,"High",IF(G36>=5,"Medium","Low"))))
... G44: =IF(AND(E44<>"",F44<>""),E44*F44,"") | H44: =IF(G44="","",IF(G44>=15,"Critical",IF(G44>=10,"High",IF(G44>=5,"Medium","Low"))))

Sheet Remediation_Roadmap
A1: REMEDIATION ROADMAP - PRIORITIZED ACTION PLAN
A2: Prioritized action plan for closing gaps and mitigating risks (50 action items)
A3: Action ID | B3: Priority | C3: Action Description | D3: Related Gap/Risk | E3: Domain | F3: Owner | G3: Start Date | H3: Target Date | I3: Status | J3: % Complete | K3: Effort (Days) | L3: Dependencies | M3: Success Criteria | N3: Notes
A5: A-811-001 | B5: P0-Critical | C5: Implement static masking for all UAT environments | D5: G-811-006 | E5: Domain 3 | K5: 30
A6: A-811-002 | B6: P0-Critical | C6: Deploy DDM for production API endpoints exposing PII | D6: G-811-008 | E6: Domain 3 | K6: 45
A7: A-811-003 | B7: P0-Critical | C7: Migrate masking keys from config files to HSM/KMS | D7: G-811-014 | E7: Domain 2 | K7: 20
A8: A-811-004 | B8: P1-High | C8: Complete cloud system inventory (AWS, Azure, GCP) | D8: G-811-001 | E8: Domain 1 | K8: 15
A9: A-811-005 | B9: P1-High | C9: Implement tokenization for payment card data | D9: G-811-004 | E9: Domain 2 | K9: 60
A10: A-811-006 | B10: P1-High | C10: Encrypt all backup tapes and archives at rest | D10: G-811-009 | E10: Domain 3 | K10: 30
A11: A-811-007 | B11: P1-High | C11: Implement automated schema drift detection | D11: G-811-013 | E11: Domain 1 | K11: 45
A12: A-811-008 | B12: P1-High | C12: Mask vendor access views to customer PII | D12: G-811-016 | E12: Domain 3 | K12: 30
A13: A-811-009 | B13: P2-Medium | C13: Classify credit card fields in 3 remaining databases | D13: G-811-002 | E13: Domain 1 | K13: 10
A14: A-811-010 | B14: P2-Medium | C14: Assign data owners for 15% unassigned sensitive fields | D14: G-811-003 | E14: Domain 1 | K14: 20
A15: A-811-011 | B15: P2-Medium | C15: Upgrade MD5 hashing to SHA-256 in legacy system | D15: G-811-005 | E15: Domain 2 | K15: 40
A16: A-811-012 | B16: P2-Medium | C16: Implement masked data refresh for development DB | D16: G-811-007 | E16: Domain 3 | K16: 25
... A29: A-811-025 | B29: P2-Medium | C29: Create disaster recovery procedures for token vault | D29: R-811-016 | E29: Domain 2 | K29: 20

Sheet Evidence_Master_Index
A1: EVIDENCE MASTER INDEX - ALL DOMAINS
A2: Centralized audit trail for all compliance evidence across all domains (100 entries)
A3: Evidence ID | B3: Domain | C3: Evidence Type | D3: Description | E3: Related Assessment | F3: Document Name/Link | G3: Date Created | H3: Owner | I3: Retention Period | J3: Location

Sheet KPI_Dashboard
A1: KEY PERFORMANCE INDICATORS - DATA MASKING COMPLIANCE
A2: Strategic metrics for executive oversight - 23 KPIs with targets and trends
A4: STRATEGIC KPIs (11 Metrics)
A5: KPI | B5: Current Value | C5: Target | D5: Status | E5: Trend | F5: Notes
A6: Overall Compliance Score | B6: =Executive_Summary!B6 | C6: ≥90%
A7: Data Inventory Coverage | B7: =[ISMS-IMP-A.8.11.1.xlsx]Summary_Dashboard!$B$7 | C7: 100%
A8: Sensitive Fields Classified | B8: =[ISMS-IMP-A.8.11.1.xlsx]Summary_Dashboard!$B$6 | C8: 100%
A9: Masking Technique Deployment | B9: =[ISMS-IMP-A.8.11.2.xlsx]Summary_Dashboard!$B$6 | C9: ≥90%
A10: Non-Production Masking Coverage | B10: =[ISMS-IMP-A.8.11.3.xlsx]Summary_Dashboard!$B$7 | C10: 100%
A11: Production DDM Coverage | B11: =[ISMS-IMP-A.8.11.3.xlsx]Summary_Dashboard!$B$10 | C11: ≥90%
A12: Environment Coverage | B12: =[ISMS-IMP-A.8.11.3.xlsx]Summary_Dashboard!$B$6 | C12: 100%
A13: Testing Pass Rate | B13: =[ISMS-IMP-A.8.11.4.xlsx]Summary_Dashboard!$B$8 | C13: ≥95%
A14: Re-Identification Risk | B14: =[ISMS-IMP-A.8.11.4.xlsx]Summary_Dashboard!$B$12 | C14: 0%
A15: Data Utility Score | B15: =[ISMS-IMP-A.8.11.4.xlsx]Summary_Dashboard!$B$13 | C15: ≥95%
A16: Performance Impact | B16: =[ISMS-IMP-A.8.11.4.xlsx]Summary_Dashboard!$B$14 | C16: <10%
A18: OPERATIONAL KPIs (12 Metrics)
A19: KPI | B19: Current Value | C19: Target | D19: Status | E19: Notes
A20: Exception Count (Total) | B20: =COUNTIFS(Domain_3_Summary!$L:$L,"Approved Exception") | C20: ≤5% of envs
A21: High-Risk Gaps | B21: =COUNTIF(Consolidated_Gap_Analysis!$G:$G,"High") | C21: 0
A22: Critical-Risk Gaps | B22: =COUNTIF(Consolidated_Gap_Analysis!$G:$G,"Critical") | C22: 0
A23: Gaps Remediated % | B23: =COUNTIF(Consolidated_Gap_Analysis!$L:$L,"Closed")/COUNTA(Consolidated_Gap_Analysis!$A:$A)*100 | C23: 100%
A24: Average Remediation Time (days) | B24: [Manual calculation] | C24: ≤90
A25: Schema Drift Detection Rate | B25: =[ISMS-IMP-A.8.11.4.xlsx]Summary_Dashboard!$B$15 | C25: 100%
A26: Failed Tests Remediated | B26: =COUNTIF(Domain_4_Summary!$L:$L,"Remediated")/COUNTA(Domain_4_Summary!$L:$L)*100 | C26: 100%
A27: Evidence Documentation Rate | B27: =COUNTA(Evidence_Master_Index!$A:$A)/100*100 | C27: 100%
A28: External Sharing Masked | B28: =[ISMS-IMP-A.8.11.3.xlsx]Summary_Dashboard!$B$20 | C28: 100%
A29: Cloud Environment Compliance | B29: =[ISMS-IMP-A.8.11.3.xlsx]Summary_Dashboard!$B$25 | C29: 100%
A30: Backup Encryption Rate | B30: =[ISMS-IMP-A.8.11.3.xlsx]Summary_Dashboard!$B$30 | C30: 100%
A31: Data Owner Assignment | B31: =[ISMS-IMP-A.8.11.1.xlsx]Summary_Dashboard!$B$10 | C31: 100%
A33: WEIGHTED COMPLIANCE SCORE CALCULATION
A34: Component | B34: Weight | C34: Score | D34: Weighted Score | E34: Notes
A35: Data Inventory & Classification | B35: 20% | C35: =[ISMS-IMP-A.8.11.1.xlsx]Summary_Dashboard!$B$40 | D35: =C35*0.20
A36: Masking Technique Deployment | B36: 20% | C36: =[ISMS-IMP-A.8.11.2.xlsx]Summary_Dashboard!$B$40 | D36: =C36*0.20
A37: Environment Coverage | B37: 25% | C37: =[ISMS-IMP-A.8.11.3.xlsx]Summary_Dashboard!$B$40 | D37: =C37*0.25
A38: Testing & Validation | B38: 25% | C38: =[ISMS-IMP-A.8.11.4.xlsx]Summary_Dashboard!$B$40 | D38: =C38*0.25
A39: Evidence & Documentation | B39: 10% | C39: =COUNTA(Evidence_Master_Index!$A:$A)/100*100 | D39: =C39*0.10
A40: TOTAL COMPLIANCE SCORE | B40: 100% | D40: =SUM(D35:D39)
A42: Score Interpretation:
A43: 90-100% = Excellent (Green) - Certification ready
A44: 70-89% = Acceptable with gaps (Yellow) - Remediation required
...

Sheet CISO_DPO_Approval
A1: EXECUTIVE APPROVAL SIGN-OFF
A2: Multi-level approval workflow for compliance certification (ISO, CISO, DPO, CIO, Board)
A4: 1. INFORMATION SECURITY OFFICER (ISO)
A5: Name:
A6: Title: | B6: Information Security Officer
A7: Review Date:
A8: Recommendation: | B8: ☐ Approve ☐ Approve with Conditions ☐ Reject
A9: Conditions/Comments:
A10: Signature: | B10: _________________________________
A12: 2. CHIEF INFORMATION SECURITY OFFICER (CISO)
A13: Name:
A14: Title: | B14: Chief Information Security Officer
A15: Review Date:
A16: Decision: | B16: ☐ Approved ☐ Approved with Conditions ☐ Rejected
A17: Executive Comments:
A18: Budget Approval: | B18: ☐ Approved ☐ Pending ☐ Denied
A19: Signature: | B19: _________________________________
A21: 3. DATA PROTECTION OFFICER (DPO)
A22: Name:
A23: Title: | B23: Data Protection Officer
A24: Review Date:
A25: Privacy Assessment: | B25: ☐ GDPR Compliant ☐ FADP Compliant ☐ Issues Identified
A26: Data Protection Impact: | B26: ☐ Low ☐ Medium ☐ High
A27: Privacy Comments:
A28: Signature: | B28: _________________________________
A30: 4. CHIEF INFORMATION OFFICER (CIO)
A31: Name:
A32: Title: | B32: Chief Information Officer
A33: Review Date:
A34: Decision: | B34: ☐ Approved ☐ Approved with Conditions ☐ Rejected
A35: Operational Impact:
A36: Comments:
A37: Signature: | B37: _________________________________
A39: 5. EXECUTIVE MANAGEMENT / BOARD (If Required)
A40: Name:
A41: Title:
A42: Review Date:
A43: Decision: | B43: ☐ Approved ☐ Approved with Conditions ☐ Rejected
A44: Strategic Alignment:
A45: Budget Approval: | B45: ☐ Approved ☐ Pending ☐ Denied
...
