Workbook

Sheet Executive Summary
A1: ISMS-OP-CHK-A.8.8 — Management of Technical Vulnerabilities Compliance Checklist
A3: DOCUMENT INFORMATION
A4: Document ID | B4: ISMS-OP-CHK-A.8.8
A5: Source Policy | B5: ISMS-OP-POL-A.8.8
A6: ISO Controls | B6: Management of Technical Vulnerabilities
A7: Generated | B7: 30.09.2026
A8: Prepared By
A9: Organisation
A10: Review Cycle | B10: Annual
A12: OVERALL COMPLIANCE STATUS
A13: Overall Compliance | B13: ='Dashboard'!G11
A14: Status | B14: =IF(Dashboard!H11>0,"INCOMPLETE",IF(Dashboard!G11="N/A","NOT ASSESSED",IF(ISNUMBER(VALUE(SUBSTITUTE(Dashboard!G11,"%",""))),IF(VALUE(SUBSTITUTE(Dashboard!G11,"%",""))>=90,"GREEN",IF(VALUE(SUBSTITUTE(Dashboard!G11,"%",""))>=70,"AMBER","RED")),"NOT ASSESSED")))
A16: KEY METRICS
A17: Total Requirements | B17: ='Dashboard'!B11
A18: Compliant | B18: ='Dashboard'!C11
A19: Partial | B19: ='Dashboard'!D11
A20: Non-Compliant | B20: ='Dashboard'!E11
A21: Not Applicable | B21: ='Dashboard'!F11
A22: Unanswered | B22: ='Dashboard'!H11
A23: Owner Coverage | B23: =IF(Dashboard!B11=0,"N/A",ROUND((COUNTA('Vulnerability Identification'!F4:F11)+COUNTA('Vulnerability Assessment'!F4:F9)+COUNTA('Remediation'!F4:F19)+COUNTA('Exception Management'!F4:F11)+COUNTA('Unsupported Software & Firmware'!F4:F9)+COUNTA('Reporting and Metrics'!F4:F5)+COUNTA('Change Management Integration'!F4:F5))/Dashboard!B11*100,0)&"%")
A25: DOMAIN STATUS SUMMARY
A26: Domain | B26: Compliance % | C26: Compliant | D26: Gaps | E26: Status
A27: Vulnerability Identification | B27: ='Dashboard'!G4 | C27: ='Dashboard'!C4 | D27: ='Dashboard'!E4 | E27: =IF(Dashboard!H4>0,"INCOMPLETE",IF(Dashboard!G4="N/A","--",IF(ISNUMBER(VALUE(SUBSTITUTE(Dashboard!G4,"%",""))),IF(VALUE(SUBSTITUTE(Dashboard!G4,"%",""))>=90,"PASS",IF(VALUE(SUBSTITUTE(Dashboard!G4,"%",""))>=70,"REVIEW","FAIL")),"--")))
A28: Vulnerability Assessment | B28: ='Dashboard'!G5 | C28: ='Dashboard'!C5 | D28: ='Dashboard'!E5 | E28: =IF(Dashboard!H5>0,"INCOMPLETE",IF(Dashboard!G5="N/A","--",IF(ISNUMBER(VALUE(SUBSTITUTE(Dashboard!G5,"%",""))),IF(VALUE(SUBSTITUTE(Dashboard!G5,"%",""))>=90,"PASS",IF(VALUE(SUBSTITUTE(Dashboard!G5,"%",""))>=70,"REVIEW","FAIL")),"--")))
A29: Remediation | B29: ='Dashboard'!G6 | C29: ='Dashboard'!C6 | D29: ='Dashboard'!E6 | E29: =IF(Dashboard!H6>0,"INCOMPLETE",IF(Dashboard!G6="N/A","--",IF(ISNUMBER(VALUE(SUBSTITUTE(Dashboard!G6,"%",""))),IF(VALUE(SUBSTITUTE(Dashboard!G6,"%",""))>=90,"PASS",IF(VALUE(SUBSTITUTE(Dashboard!G6,"%",""))>=70,"REVIEW","FAIL")),"--")))
A30: Exception Management | B30: ='Dashboard'!G7 | C30: ='Dashboard'!C7 | D30: ='Dashboard'!E7 | E30: =IF(Dashboard!H7>0,"INCOMPLETE",IF(Dashboard!G7="N/A","--",IF(ISNUMBER(VALUE(SUBSTITUTE(Dashboard!G7,"%",""))),IF(VALUE(SUBSTITUTE(Dashboard!G7,"%",""))>=90,"PASS",IF(VALUE(SUBSTITUTE(Dashboard!G7,"%",""))>=70,"REVIEW","FAIL")),"--")))
A31: Unsupported Software & Firmware | B31: ='Dashboard'!G8 | C31: ='Dashboard'!C8 | D31: ='Dashboard'!E8 | E31: =IF(Dashboard!H8>0,"INCOMPLETE",IF(Dashboard!G8="N/A","--",IF(ISNUMBER(VALUE(SUBSTITUTE(Dashboard!G8,"%",""))),IF(VALUE(SUBSTITUTE(Dashboard!G8,"%",""))>=90,"PASS",IF(VALUE(SUBSTITUTE(Dashboard!G8,"%",""))>=70,"REVIEW","FAIL")),"--")))
A32: Reporting and Metrics | B32: ='Dashboard'!G9 | C32: ='Dashboard'!C9 | D32: ='Dashboard'!E9 | E32: =IF(Dashboard!H9>0,"INCOMPLETE",IF(Dashboard!G9="N/A","--",IF(ISNUMBER(VALUE(SUBSTITUTE(Dashboard!G9,"%",""))),IF(VALUE(SUBSTITUTE(Dashboard!G9,"%",""))>=90,"PASS",IF(VALUE(SUBSTITUTE(Dashboard!G9,"%",""))>=70,"REVIEW","FAIL")),"--")))
A33: Change Management Integration | B33: ='Dashboard'!G10 | C33: ='Dashboard'!C10 | D33: ='Dashboard'!E10 | E33: =IF(Dashboard!H10>0,"INCOMPLETE",IF(Dashboard!G10="N/A","--",IF(ISNUMBER(VALUE(SUBSTITUTE(Dashboard!G10,"%",""))),IF(VALUE(SUBSTITUTE(Dashboard!G10,"%",""))>=90,"PASS",IF(VALUE(SUBSTITUTE(Dashboard!G10,"%",""))>=70,"REVIEW","FAIL")),"--")))
A35: CRITICAL ISSUES
A36: # | B36: Issue Description | C36: Domain | D36: Owner | E36: Due Date
A37: 1
A38: 2
A39: 3
A40: 4
A41: 5
A43: MANAGEMENT COMMENTARY
A44: [Enter management commentary on management of technical vulnerabilities posture]
A48: APPROVAL
A49: Assessed By
...

Sheet Dashboard
A1: Management of Technical Vulnerabilities — Compliance Dashboard
A3: Domain | B3: Total Reqs | C3: Compliant | D3: Partial | E3: Non-Compliant | F3: N/A | G3: Compliance % | H3: Unassessed
A4: Vulnerability Identification | B4: =COUNTA('Vulnerability Identification'!A4:A11) | C4: =COUNTIF('Vulnerability Identification'!D4:D11,"Compliant") | D4: =COUNTIF('Vulnerability Identification'!D4:D11,"Partial") | E4: =COUNTIF('Vulnerability Identification'!D4:D11,"Non-Compliant") | F4: =COUNTIF('Vulnerability Identification'!D4:D11,"N/A") | G4: =IF((B4-F4)=0,"N/A",ROUND(C4/(B4-F4)*100,1)&"%") | H4: =B4-(C4+D4+E4+F4)
A5: Vulnerability Assessment | B5: =COUNTA('Vulnerability Assessment'!A4:A9) | C5: =COUNTIF('Vulnerability Assessment'!D4:D9,"Compliant") | D5: =COUNTIF('Vulnerability Assessment'!D4:D9,"Partial") | E5: =COUNTIF('Vulnerability Assessment'!D4:D9,"Non-Compliant") | F5: =COUNTIF('Vulnerability Assessment'!D4:D9,"N/A") | G5: =IF((B5-F5)=0,"N/A",ROUND(C5/(B5-F5)*100,1)&"%") | H5: =B5-(C5+D5+E5+F5)
A6: Remediation | B6: =COUNTA('Remediation'!A4:A19) | C6: =COUNTIF('Remediation'!D4:D19,"Compliant") | D6: =COUNTIF('Remediation'!D4:D19,"Partial") | E6: =COUNTIF('Remediation'!D4:D19,"Non-Compliant") | F6: =COUNTIF('Remediation'!D4:D19,"N/A") | G6: =IF((B6-F6)=0,"N/A",ROUND(C6/(B6-F6)*100,1)&"%") | H6: =B6-(C6+D6+E6+F6)
A7: Exception Management | B7: =COUNTA('Exception Management'!A4:A11) | C7: =COUNTIF('Exception Management'!D4:D11,"Compliant") | D7: =COUNTIF('Exception Management'!D4:D11,"Partial") | E7: =COUNTIF('Exception Management'!D4:D11,"Non-Compliant") | F7: =COUNTIF('Exception Management'!D4:D11,"N/A") | G7: =IF((B7-F7)=0,"N/A",ROUND(C7/(B7-F7)*100,1)&"%") | H7: =B7-(C7+D7+E7+F7)
A8: Unsupported Software & Firmware | B8: =COUNTA('Unsupported Software & Firmware'!A4:A9) | C8: =COUNTIF('Unsupported Software & Firmware'!D4:D9,"Compliant") | D8: =COUNTIF('Unsupported Software & Firmware'!D4:D9,"Partial") | E8: =COUNTIF('Unsupported Software & Firmware'!D4:D9,"Non-Compliant") | F8: =COUNTIF('Unsupported Software & Firmware'!D4:D9,"N/A") | G8: =IF((B8-F8)=0,"N/A",ROUND(C8/(B8-F8)*100,1)&"%") | H8: =B8-(C8+D8+E8+F8)
A9: Reporting and Metrics | B9: =COUNTA('Reporting and Metrics'!A4:A5) | C9: =COUNTIF('Reporting and Metrics'!D4:D5,"Compliant") | D9: =COUNTIF('Reporting and Metrics'!D4:D5,"Partial") | E9: =COUNTIF('Reporting and Metrics'!D4:D5,"Non-Compliant") | F9: =COUNTIF('Reporting and Metrics'!D4:D5,"N/A") | G9: =IF((B9-F9)=0,"N/A",ROUND(C9/(B9-F9)*100,1)&"%") | H9: =B9-(C9+D9+E9+F9)
A10: Change Management Integration | B10: =COUNTA('Change Management Integration'!A4:A5) | C10: =COUNTIF('Change Management Integration'!D4:D5,"Compliant") | D10: =COUNTIF('Change Management Integration'!D4:D5,"Partial") | E10: =COUNTIF('Change Management Integration'!D4:D5,"Non-Compliant") | F10: =COUNTIF('Change Management Integration'!D4:D5,"N/A") | G10: =IF((B10-F10)=0,"N/A",ROUND(C10/(B10-F10)*100,1)&"%") | H10: =B10-(C10+D10+E10+F10)
A11: TOTAL | B11: =SUM(B4:B10) | C11: =SUM(C4:C10) | D11: =SUM(D4:D10) | E11: =SUM(E4:E10) | F11: =SUM(F4:F10) | G11: =IF((B11-F11)=0,"N/A",ROUND(C11/(B11-F11)*100,1)&"%") | H11: =SUM(H4:H10)
A13: COMPLIANCE BY STATUS
A14: Compliant | B14: =C11 | C14: =IF(B11=0,"",ROUND(B14/B11*100,1)&"%")
A15: Partial | B15: =D11 | C15: =IF(B11=0,"",ROUND(B15/B11*100,1)&"%")
A16: Non-Compliant | B16: =E11 | C16: =IF(B11=0,"",ROUND(B16/B11*100,1)&"%")
A17: N/A | B17: =F11 | C17: =IF(B11=0,"",ROUND(B17/B11*100,1)&"%")
A19: TOP GAPS (Manual Entry)
A20: Priority | B20: Domain | C20: Requirement | D20: Owner | E20: Due Date | F20: Status
A32: COMPLIANCE TREND (Manual Entry)
A33: Assessment Date | B33: Overall % | C33: Compliant | D33: Gaps | E33: Assessor | F33: Notes

Sheet Vulnerability Identification
A1: Vulnerability Identification — Compliance Checklist
A2: ISO/IEC 27001:2022 — Control A.8.8: Management of Technical Vulnerabilities
A3: Req # | B3: Section | C3: Requirement | D3: Status | E3: Evidence | F3: Owner | G3: Due Date | H3: Notes
A4: A.8.8-01 | B4: Vulnerability Scanning | C4: Vulnerability scanning shall be performed on all in-scope assets to identify known security weaknesses.
A5: A.8.8-02 | B5: Legacy Systems, Ot Devices), Manual | C5: Where automated scanning is not feasible (e.g., legacy systems, OT devices), manual assessment shall be conducted at least quarterly with documented justification for the alternative approach.
A6: A.8.8-03 | B6: Scanning Tools | C6: Scanning tools shall be kept current with the latest vulnerability definitions. Scanning results shall be retained for a minimum of 12 months.
A7: A.8.8-04 | B7: The Following Categories Of Tools | C7: The following categories of tools shall be deployed to support the vulnerability management programme:.
A8: A.8.8-05 | B8: The Information Security Management Team | C8: The information security management team shall monitor vendor security advisories for all deployed products. This includes:.
A9: A.8.8-06 | B9: Be Performed At Least Weekly Through | C9: Monitoring shall be performed at least weekly through vendor mailing lists, security bulletin pages, or automated advisory feeds. A designated member of the information security management team shall be assigned as the vendor advisory owner, responsible for triaging advisories, assessing applicability, and initiating remediation within 2 business days of advisory publication for critical/high severity.
A10: A.8.8-07 | B10: The Following Public Threat Intelligence | C10: The following public threat intelligence sources shall be monitored for vulnerabilities under active exploitation:.
A11: A.8.8-08 | B11: Vulnerabilities Confirmed As Actively | C11: Vulnerabilities confirmed as actively exploited shall receive emergency priority (see Prioritisation section below).

Sheet Vulnerability Assessment
A1: Vulnerability Assessment — Compliance Checklist
A2: ISO/IEC 27001:2022 — Control A.8.8: Management of Technical Vulnerabilities
A3: Req # | B3: Section | C3: Requirement | D3: Status | E3: Evidence | F3: Owner | G3: Due Date | H3: Notes
A4: A.8.8-09 | B4: Vulnerability Severity | C4: Vulnerability severity shall be assessed using the Common Vulnerability Scoring System (CVSS):.
A5: A.8.8-10 | B5: Cvss V3.1 | C5: CVSS v3.1 shall be used as the primary scoring standard.
A6: A.8.8-11 | B6: Cvss V4.0 | C6: CVSS v4.0 shall be used when vendor advisories provide v4.0 scores and the vulnerability management platform supports v4.0 scoring.
A7: A.8.8-12 | B7: This Policy | C7: This policy shall be reviewed when CVSS v4.0 achieves majority adoption across major vendors and scanning platforms.
A8: A.8.8-13 | B8: Remediation Priority | C8: Remediation priority shall be determined by combining CVSS severity with asset criticality (as documented in the asset inventory):.
A9: A.8.8-14 | B9: Override: Vulnerabilities Listed In The | C9: Override: Vulnerabilities listed in the CISA KEV Catalog or confirmed as actively exploited shall receive P0 Emergency* priority regardless of CVSS score or asset criticality.

Sheet Remediation
A1: Remediation — Compliance Checklist
A2: ISO/IEC 27001:2022 — Control A.8.8: Management of Technical Vulnerabilities
A3: Req # | B3: Section | C3: Requirement | D3: Status | E3: Evidence | F3: Owner | G3: Due Date | H3: Notes
A4: A.8.8-15 | B4: Security Patches And Vulnerability Fixes | C4: Security patches and vulnerability fixes shall be applied according to the following timeframes:.
A5: A.8.8-16 | B5: Be Remediated Using The Following | C5: Vulnerabilities shall be remediated using the following methods, in order of preference:.
A6: A.8.8-17 | B6: Workarounds And Compensating Controls | C6: Workarounds and compensating controls are temporary measures. They shall be reviewed monthly and replaced with permanent remediation as soon as available.
A7: A.8.8-18 | B7: Be Tested Before Deployment To | C7: Patches shall be tested before deployment to production systems according to the following requirements:.
A8: A.8.8-19 | B8: P0 Emergency Patches May Be Deployed | C8: P0 emergency patches may be deployed without non-production testing when active exploitation is confirmed and delayed patching poses greater risk than potential operational impact. Testing bypass shall require CISO approval and include enhanced monitoring for 48 hours post-deployment and a documented rollback plan.
A9: A.8.8-20 | B9: Patch Deployment | C9: Patch deployment shall follow the organisation's change management process. Emergency patches may follow an expedited change process with retrospective documentation within 2 business days.
A10: A.8.8-21 | B10: A Rollback Plan | C10: A rollback plan shall be agreed upon before applying patches to production systems.
A11: A.8.8-22 | B11: Automatic Patching | C11: Automatic patching shall be enabled for endpoint devices where available and appropriate. The patching status of endpoint devices shall be checked at least monthly.
A12: A.8.8-23 | B12: Remedial Action | C12: Where a device is found to be non-compliant with patching requirements, remedial action shall be taken. Devices with critical unpatched vulnerabilities beyond the defined timeframe may be restricted from network access until remediated.
A13: A.8.8-24 | B13: Patching Of Production Servers, | C13: Patching of production servers, databases, and infrastructure systems shall follow the standard change management process.
A14: A.8.8-25 | B14: The Patching Status Of Production | C14: The patching status of production systems shall be checked at least monthly. Where a system is found to be non-compliant, remedial action shall be taken and the risk documented.
A15: A.8.8-26 | B15: Be Verified Through Re-Scanning Or | C15: All remediation shall be verified through re-scanning or manual confirmation within 5 business days of patch application to confirm the vulnerability has been resolved and that the patch has not introduced new issues.
... A19: A.8.8-30 | B19: An Exception | C19: If re-remediation fails, an exception shall be raised with compensating controls, and the vulnerability shall be escalated to the CISO.

Sheet Exception Management
A1: Exception Management — Compliance Checklist
A2: ISO/IEC 27001:2022 — Control A.8.8: Management of Technical Vulnerabilities
A3: Req # | B3: Section | C3: Requirement | D3: Status | E3: Evidence | F3: Owner | G3: Due Date | H3: Notes
A4: A.8.8-31 | B4: An Exception | C4: Where a patch or fix cannot be applied within the defined timeframe, an exception shall be raised.
A5: A.8.8-32 | B5: The System Owner | C5: The system owner shall submit an exception request documenting the business justification, the affected systems, and the proposed compensating controls.
A6: A.8.8-33 | B6: The Information Security Management Team | C6: The information security management team shall assess the risk.
A7: A.8.8-34 | B7: The Ciso | C7: The CISO shall approve or deny the exception.
A8: A.8.8-35 | B8: Approved Exceptions | C8: Approved exceptions shall be documented with:.
A9: A.8.8-36 | B9: Be Reviewed Monthly And Tracked In | C9: Exceptions shall be reviewed monthly and tracked in the risk register.
A10: A.8.8-37 | B10: P0 Emergency Vulnerabilities | C10: P0 emergency vulnerabilities shall not receive exceptions.* If a P0 patch cannot be applied, the affected system shall be isolated from the network until remediation is completed.
A11: A.8.8-38 | B11: An Exception Register | C11: An exception register shall be maintained, managed, and reported via the Management Review Team. The register shall record, at minimum:.

Sheet Unsupported Software & Firmware
A1: Unsupported Software & Firmware — Compliance Checklist
A2: ISO/IEC 27001:2022 — Control A.8.8: Management of Technical Vulnerabilities
A3: Req # | B3: Section | C3: Requirement | D3: Status | E3: Evidence | F3: Owner | G3: Due Date | H3: Notes
A4: A.8.8-39 | B4: Software Or Firmware That Has Reached | C4: Software or firmware that has reached end of life (EOL) or end of support (EOS) shall be identified and flagged in the asset inventory.
A5: A.8.8-40 | B5: Unsupported Software Or Firmware | C5: Unsupported software or firmware shall be prioritised for upgrade or replacement. Where immediate replacement is not feasible:.
A6: A.8.8-41 | B6: The Risk | C6: The risk shall be documented in the risk register.
A7: A.8.8-42 | B7: Compensating Controls | C7: Compensating controls shall be implemented (e.g., network isolation, enhanced monitoring, restricted access).
A8: A.8.8-43 | B8: A Remediation Plan With A Target | C8: A remediation plan with a target date shall be documented and approved by the CISO. Target dates for EOL/EOS remediation shall not exceed:.
A9: A.8.8-44 | B9: The Exception | C9: The exception shall be reviewed quarterly.

Sheet Reporting and Metrics
A1: Reporting and Metrics — Compliance Checklist
A2: ISO/IEC 27001:2022 — Control A.8.8: Management of Technical Vulnerabilities
A3: Req # | B3: Section | C3: Requirement | D3: Status | E3: Evidence | F3: Owner | G3: Due Date | H3: Notes
A4: A.8.8-45 | B4: The Information Security Management Team | C4: The information security management team shall report vulnerability management metrics to the CISO at least quarterly:.
A5: A.8.8-46 | B5: Metrics Breaching Red Thresholds | C5: Metrics breaching red thresholds shall be escalated to the CISO for immediate attention and reported at the next Management Review.

Sheet Change Management Integration
A1: Change Management Integration — Compliance Checklist
A2: ISO/IEC 27001:2022 — Control A.8.8: Management of Technical Vulnerabilities
A3: Req # | B3: Section | C3: Requirement | D3: Status | E3: Evidence | F3: Owner | G3: Due Date | H3: Notes
A4: A.8.8-47 | B4: Patch Deployment | C4: Patch deployment shall follow the organisation's change management process:.
A5: A.8.8-48 | B5: Patch Deployments | C5: All patch deployments shall be recorded as change records, linking the vulnerability ID (CVE), affected assets, deployment date, and verification result.
