Workbook

Sheet Executive Summary
A1: ISMS-OP-CHK-A.5.10-11 — Acceptable Use and Return of Assets Compliance Checklist
A3: DOCUMENT INFORMATION
A4: Document ID | B4: ISMS-OP-CHK-A.5.10-11
A5: Source Policy | B5: ISMS-OP-POL-A.5.10-11
A6: ISO Controls | B6: Acceptable Use and Return of Assets
A7: Generated | B7: 08.02.2026
A8: Prepared By
A9: Organisation
A10: Review Cycle | B10: Annual
A12: OVERALL COMPLIANCE STATUS
A13: Overall Compliance | B13: ='Dashboard'!G14
A14: Status | B14: =IF(Dashboard!G14="N/A","NOT ASSESSED",IF(ISNUMBER(VALUE(SUBSTITUTE(Dashboard!G14,"%",""))),IF(VALUE(SUBSTITUTE(Dashboard!G14,"%",""))>=90,"GREEN",IF(VALUE(SUBSTITUTE(Dashboard!G14,"%",""))>=70,"AMBER","RED")),"NOT ASSESSED"))
A16: KEY METRICS
A17: Total Requirements | B17: ='Dashboard'!B14
A18: Compliant | B18: ='Dashboard'!C14
A19: Partial | B19: ='Dashboard'!D14
A20: Non-Compliant | B20: ='Dashboard'!E14
A21: Not Applicable | B21: ='Dashboard'!F14
A22: Owner Coverage | B22: =IF(Dashboard!B14=0,"N/A",ROUND((COUNTA('Individual Responsibility'!F4:F5)+COUNTA('Internet and Email Usage'!F4:F4)+COUNTA('Cloud and SaaS Services'!F4:F7)+COUNTA('Artificial Intelligence Tools'!F4:F10)+COUNTA('Social Media'!F4:F7)+COUNTA('Working Off-Site'!F4:F11)+COUNTA('Removable Storage Devices'!F4:F5)+COUNTA('Monitoring and Filtering'!F4:F10)+COUNTA('Reporting'!F4:F4)+COUNTA('Return of Assets'!F4:F20))/Dashboard!B14*100,0)&"%")
A24: DOMAIN STATUS SUMMARY
A25: Domain | B25: Compliance % | C25: Compliant | D25: Gaps | E25: Status
A26: Individual Responsibility | B26: ='Dashboard'!G4 | C26: ='Dashboard'!C4 | D26: ='Dashboard'!E4 | E26: =IF(Dashboard!G4="N/A","--",IF(ISNUMBER(VALUE(SUBSTITUTE(Dashboard!G4,"%",""))),IF(VALUE(SUBSTITUTE(Dashboard!G4,"%",""))>=90,"PASS",IF(VALUE(SUBSTITUTE(Dashboard!G4,"%",""))>=70,"REVIEW","FAIL")),"--"))
A27: Internet and Email Usage | B27: ='Dashboard'!G5 | C27: ='Dashboard'!C5 | D27: ='Dashboard'!E5 | E27: =IF(Dashboard!G5="N/A","--",IF(ISNUMBER(VALUE(SUBSTITUTE(Dashboard!G5,"%",""))),IF(VALUE(SUBSTITUTE(Dashboard!G5,"%",""))>=90,"PASS",IF(VALUE(SUBSTITUTE(Dashboard!G5,"%",""))>=70,"REVIEW","FAIL")),"--"))
A28: Cloud and SaaS Services | B28: ='Dashboard'!G6 | C28: ='Dashboard'!C6 | D28: ='Dashboard'!E6 | E28: =IF(Dashboard!G6="N/A","--",IF(ISNUMBER(VALUE(SUBSTITUTE(Dashboard!G6,"%",""))),IF(VALUE(SUBSTITUTE(Dashboard!G6,"%",""))>=90,"PASS",IF(VALUE(SUBSTITUTE(Dashboard!G6,"%",""))>=70,"REVIEW","FAIL")),"--"))
A29: Artificial Intelligence Tools | B29: ='Dashboard'!G7 | C29: ='Dashboard'!C7 | D29: ='Dashboard'!E7 | E29: =IF(Dashboard!G7="N/A","--",IF(ISNUMBER(VALUE(SUBSTITUTE(Dashboard!G7,"%",""))),IF(VALUE(SUBSTITUTE(Dashboard!G7,"%",""))>=90,"PASS",IF(VALUE(SUBSTITUTE(Dashboard!G7,"%",""))>=70,"REVIEW","FAIL")),"--"))
A30: Social Media | B30: ='Dashboard'!G8 | C30: ='Dashboard'!C8 | D30: ='Dashboard'!E8 | E30: =IF(Dashboard!G8="N/A","--",IF(ISNUMBER(VALUE(SUBSTITUTE(Dashboard!G8,"%",""))),IF(VALUE(SUBSTITUTE(Dashboard!G8,"%",""))>=90,"PASS",IF(VALUE(SUBSTITUTE(Dashboard!G8,"%",""))>=70,"REVIEW","FAIL")),"--"))
A31: Working Off-Site | B31: ='Dashboard'!G9 | C31: ='Dashboard'!C9 | D31: ='Dashboard'!E9 | E31: =IF(Dashboard!G9="N/A","--",IF(ISNUMBER(VALUE(SUBSTITUTE(Dashboard!G9,"%",""))),IF(VALUE(SUBSTITUTE(Dashboard!G9,"%",""))>=90,"PASS",IF(VALUE(SUBSTITUTE(Dashboard!G9,"%",""))>=70,"REVIEW","FAIL")),"--"))
A32: Removable Storage Devices | B32: ='Dashboard'!G10 | C32: ='Dashboard'!C10 | D32: ='Dashboard'!E10 | E32: =IF(Dashboard!G10="N/A","--",IF(ISNUMBER(VALUE(SUBSTITUTE(Dashboard!G10,"%",""))),IF(VALUE(SUBSTITUTE(Dashboard!G10,"%",""))>=90,"PASS",IF(VALUE(SUBSTITUTE(Dashboard!G10,"%",""))>=70,"REVIEW","FAIL")),"--"))
A33: Monitoring and Filtering | B33: ='Dashboard'!G11 | C33: ='Dashboard'!C11 | D33: ='Dashboard'!E11 | E33: =IF(Dashboard!G11="N/A","--",IF(ISNUMBER(VALUE(SUBSTITUTE(Dashboard!G11,"%",""))),IF(VALUE(SUBSTITUTE(Dashboard!G11,"%",""))>=90,"PASS",IF(VALUE(SUBSTITUTE(Dashboard!G11,"%",""))>=70,"REVIEW","FAIL")),"--"))
A34: Reporting | B34: ='Dashboard'!G12 | C34: ='Dashboard'!C12 | D34: ='Dashboard'!E12 | E34: =IF(Dashboard!G12="N/A","--",IF(ISNUMBER(VALUE(SUBSTITUTE(Dashboard!G12,"%",""))),IF(VALUE(SUBSTITUTE(Dashboard!G12,"%",""))>=90,"PASS",IF(VALUE(SUBSTITUTE(Dashboard!G12,"%",""))>=70,"REVIEW","FAIL")),"--"))
A35: Return of Assets | B35: ='Dashboard'!G13 | C35: ='Dashboard'!C13 | D35: ='Dashboard'!E13 | E35: =IF(Dashboard!G13="N/A","--",IF(ISNUMBER(VALUE(SUBSTITUTE(Dashboard!G13,"%",""))),IF(VALUE(SUBSTITUTE(Dashboard!G13,"%",""))>=90,"PASS",IF(VALUE(SUBSTITUTE(Dashboard!G13,"%",""))>=70,"REVIEW","FAIL")),"--"))
A37: CRITICAL ISSUES
A38: # | B38: Issue Description | C38: Domain | D38: Owner | E38: Due Date
A39: 1
A40: 2
A41: 3
A42: 4
A43: 5
A45: MANAGEMENT COMMENTARY
A46: [Enter management commentary on acceptable use and return of assets posture]
...

Sheet Dashboard
A1: Acceptable Use and Return of Assets — Compliance Dashboard
A3: Domain | B3: Total Reqs | C3: Compliant | D3: Partial | E3: Non-Compliant | F3: N/A | G3: Compliance %
A4: Individual Responsibility | B4: =COUNTA('Individual Responsibility'!D4:D5) | C4: =COUNTIF('Individual Responsibility'!D4:D5,"Compliant") | D4: =COUNTIF('Individual Responsibility'!D4:D5,"Partial") | E4: =COUNTIF('Individual Responsibility'!D4:D5,"Non-Compliant") | F4: =COUNTIF('Individual Responsibility'!D4:D5,"N/A") | G4: =IF((B4-F4)=0,"N/A",ROUND(C4/(B4-F4)*100,1)&"%")
A5: Internet and Email Usage | B5: =COUNTA('Internet and Email Usage'!D4:D4) | C5: =COUNTIF('Internet and Email Usage'!D4:D4,"Compliant") | D5: =COUNTIF('Internet and Email Usage'!D4:D4,"Partial") | E5: =COUNTIF('Internet and Email Usage'!D4:D4,"Non-Compliant") | F5: =COUNTIF('Internet and Email Usage'!D4:D4,"N/A") | G5: =IF((B5-F5)=0,"N/A",ROUND(C5/(B5-F5)*100,1)&"%")
A6: Cloud and SaaS Services | B6: =COUNTA('Cloud and SaaS Services'!D4:D7) | C6: =COUNTIF('Cloud and SaaS Services'!D4:D7,"Compliant") | D6: =COUNTIF('Cloud and SaaS Services'!D4:D7,"Partial") | E6: =COUNTIF('Cloud and SaaS Services'!D4:D7,"Non-Compliant") | F6: =COUNTIF('Cloud and SaaS Services'!D4:D7,"N/A") | G6: =IF((B6-F6)=0,"N/A",ROUND(C6/(B6-F6)*100,1)&"%")
A7: Artificial Intelligence Tools | B7: =COUNTA('Artificial Intelligence Tools'!D4:D10) | C7: =COUNTIF('Artificial Intelligence Tools'!D4:D10,"Compliant") | D7: =COUNTIF('Artificial Intelligence Tools'!D4:D10,"Partial") | E7: =COUNTIF('Artificial Intelligence Tools'!D4:D10,"Non-Compliant") | F7: =COUNTIF('Artificial Intelligence Tools'!D4:D10,"N/A") | G7: =IF((B7-F7)=0,"N/A",ROUND(C7/(B7-F7)*100,1)&"%")
A8: Social Media | B8: =COUNTA('Social Media'!D4:D7) | C8: =COUNTIF('Social Media'!D4:D7,"Compliant") | D8: =COUNTIF('Social Media'!D4:D7,"Partial") | E8: =COUNTIF('Social Media'!D4:D7,"Non-Compliant") | F8: =COUNTIF('Social Media'!D4:D7,"N/A") | G8: =IF((B8-F8)=0,"N/A",ROUND(C8/(B8-F8)*100,1)&"%")
A9: Working Off-Site | B9: =COUNTA('Working Off-Site'!D4:D11) | C9: =COUNTIF('Working Off-Site'!D4:D11,"Compliant") | D9: =COUNTIF('Working Off-Site'!D4:D11,"Partial") | E9: =COUNTIF('Working Off-Site'!D4:D11,"Non-Compliant") | F9: =COUNTIF('Working Off-Site'!D4:D11,"N/A") | G9: =IF((B9-F9)=0,"N/A",ROUND(C9/(B9-F9)*100,1)&"%")
A10: Removable Storage Devices | B10: =COUNTA('Removable Storage Devices'!D4:D5) | C10: =COUNTIF('Removable Storage Devices'!D4:D5,"Compliant") | D10: =COUNTIF('Removable Storage Devices'!D4:D5,"Partial") | E10: =COUNTIF('Removable Storage Devices'!D4:D5,"Non-Compliant") | F10: =COUNTIF('Removable Storage Devices'!D4:D5,"N/A") | G10: =IF((B10-F10)=0,"N/A",ROUND(C10/(B10-F10)*100,1)&"%")
A11: Monitoring and Filtering | B11: =COUNTA('Monitoring and Filtering'!D4:D10) | C11: =COUNTIF('Monitoring and Filtering'!D4:D10,"Compliant") | D11: =COUNTIF('Monitoring and Filtering'!D4:D10,"Partial") | E11: =COUNTIF('Monitoring and Filtering'!D4:D10,"Non-Compliant") | F11: =COUNTIF('Monitoring and Filtering'!D4:D10,"N/A") | G11: =IF((B11-F11)=0,"N/A",ROUND(C11/(B11-F11)*100,1)&"%")
A12: Reporting | B12: =COUNTA('Reporting'!D4:D4) | C12: =COUNTIF('Reporting'!D4:D4,"Compliant") | D12: =COUNTIF('Reporting'!D4:D4,"Partial") | E12: =COUNTIF('Reporting'!D4:D4,"Non-Compliant") | F12: =COUNTIF('Reporting'!D4:D4,"N/A") | G12: =IF((B12-F12)=0,"N/A",ROUND(C12/(B12-F12)*100,1)&"%")
A13: Return of Assets | B13: =COUNTA('Return of Assets'!D4:D20) | C13: =COUNTIF('Return of Assets'!D4:D20,"Compliant") | D13: =COUNTIF('Return of Assets'!D4:D20,"Partial") | E13: =COUNTIF('Return of Assets'!D4:D20,"Non-Compliant") | F13: =COUNTIF('Return of Assets'!D4:D20,"N/A") | G13: =IF((B13-F13)=0,"N/A",ROUND(C13/(B13-F13)*100,1)&"%")
A14: TOTAL | B14: =SUM(B4:B13) | C14: =SUM(C4:C13) | D14: =SUM(D4:D13) | E14: =SUM(E4:E13) | F14: =SUM(F4:F13) | G14: =IF((B14-F14)=0,"N/A",ROUND(C14/(B14-F14)*100,1)&"%")
A16: COMPLIANCE BY STATUS
A17: Compliant | B17: =C14 | C17: =IF(B14=0,"",ROUND(B17/B14*100,1)&"%")
A18: Partial | B18: =D14 | C18: =IF(B14=0,"",ROUND(B18/B14*100,1)&"%")
A19: Non-Compliant | B19: =E14 | C19: =IF(B14=0,"",ROUND(B19/B14*100,1)&"%")
A20: N/A | B20: =F14 | C20: =IF(B14=0,"",ROUND(B20/B14*100,1)&"%")
A22: TOP GAPS (Manual Entry)
A23: Priority | B23: Domain | C23: Requirement | D23: Owner | E23: Due Date | F23: Status
A35: COMPLIANCE TREND (Manual Entry)
A36: Assessment Date | B36: Overall % | C36: Compliant | D36: Gaps | E36: Assessor | F36: Notes

Sheet Individual Responsibility
A1: Individual Responsibility — Compliance Checklist
A2: ISO/IEC 27001:2022 — Controls A.5.10-11: Acceptable Use and Return of Assets
A3: Req # | B3: Section | C3: Requirement | D3: Status | E3: Evidence | F3: Owner | G3: Due Date | H3: Notes
A4: A.5.10-11-01 | B4: Not | C4: Individuals shall not:.
A5: A.5.10-11-02 | B5: Line Managers | C5: Line managers shall ensure that individuals are given clear direction on the extent and limits of their authority regarding IT systems and data.

Sheet Internet and Email Usage
A1: Internet and Email Usage — Compliance Checklist
A2: ISO/IEC 27001:2022 — Controls A.5.10-11: Acceptable Use and Return of Assets
A3: Req # | B3: Section | C3: Requirement | D3: Status | E3: Evidence | F3: Owner | G3: Due Date | H3: Notes
A4: A.5.10-11-03 | B4: Not | C4: Individuals shall not:.

Sheet Cloud and SaaS Services
A1: Cloud and SaaS Services — Compliance Checklist
A2: ISO/IEC 27001:2022 — Controls A.5.10-11: Acceptable Use and Return of Assets
A3: Req # | B3: Section | C3: Requirement | D3: Status | E3: Evidence | F3: Owner | G3: Due Date | H3: Notes
A4: A.5.10-11-04 | B4: Organisation Data | C4: Organisation data shall only be processed in sanctioned cloud and SaaS services that have been assessed and approved by the information security management team. The sanctioned services register is maintained in the organisation's GRC platform, document management system, or intranet and shall be accessible to all employees. Employees shall verify a service is on the sanctioned list before storing organisation data.
A5: A.5.10-11-05 | B5: Not | C5: Individuals shall not:.
A6: A.5.10-11-06 | B6: Individuals | C6: When using sanctioned cloud services, individuals shall:.
A7: A.5.10-11-07 | B7: Unsanctioned Cloud Services (Shadow It) | C7: Unsanctioned cloud services (shadow IT) discovered in use shall be reported to the information security management team for assessment. Where an unsanctioned service is found to process personal or confidential data, it shall be treated as a security event.

Sheet Artificial Intelligence Tools
A1: Artificial Intelligence Tools — Compliance Checklist
A2: ISO/IEC 27001:2022 — Controls A.5.10-11: Acceptable Use and Return of Assets
A3: Req # | B3: Section | C3: Requirement | D3: Status | E3: Evidence | F3: Owner | G3: Due Date | H3: Notes
A4: A.5.10-11-08 | B4: The Use Of Generative Ai Tools | C4: The use of generative AI tools (e.g., ChatGPT, Copilot, Claude, Gemini, or equivalent) shall be governed by the following rules.
A5: A.5.10-11-09 | B5: Maintain A List Of Approved Ai | C5: The organisation shall maintain a list of approved AI tools for business use. Only approved tools with appropriate data protection agreements shall be used for processing organisation information.
A6: A.5.10-11-10 | B6: Request Process: Users Requiring New Ai | C6: Request process: Users requiring new AI tools shall submit a request to the information security management team with business justification and tool details. Assessment shall be completed within 14 business days*.
A7: A.5.10-11-11 | B7: Public Or Free-Tier Ai Tools Without | C7: Public or free-tier AI tools without enterprise data protection agreements shall not be used for organisation data.
A8: A.5.10-11-12 | B8: The Following Information | C8: The following information shall never be entered into any AI tool (including approved tools) unless the tool has been specifically assessed and approved for that data category:.
A9: A.5.10-11-13 | B9: Users Remain Accountable For All | C9: Users remain accountable for all AI-generated content. AI-generated outputs shall be reviewed for accuracy, bias, and appropriateness before use in business decisions, external communications, or official documents.
A10: A.5.10-11-14 | B10: Ai-Generated Content | C10: AI-generated content shall not be presented as human-authored work in contexts where this distinction matters (e.g., regulatory submissions, legal documents, audit evidence).

Sheet Social Media
A1: Social Media — Compliance Checklist
A2: ISO/IEC 27001:2022 — Controls A.5.10-11: Acceptable Use and Return of Assets
A3: Req # | B3: Section | C3: Requirement | D3: Status | E3: Evidence | F3: Owner | G3: Due Date | H3: Notes
A4: A.5.10-11-15 | B4: Exercise Professional Judgement When | C4: Individuals shall exercise professional judgement when using social media in any context that could be associated with the organisation.
A5: A.5.10-11-16 | B5: Not | C5: Individuals shall not:.
A6: A.5.10-11-17 | B6: Official Organisation Social Media | C6: Official organisation social media accounts shall be managed only by authorised personnel. Content published on behalf of the organisation shall follow approved communication guidelines.
A7: A.5.10-11-18 | B7: Defamation) | C7: If an employee makes a post that creates reputational risk*: the employee shall immediately inform their manager and the communications team. The organisation reserves the right to request removal of the post or public clarification. Disciplinary action may result for serious violations (breach of confidentiality, defamation).

Sheet Working Off-Site
A1: Working Off-Site — Compliance Checklist
A2: ISO/IEC 27001:2022 — Controls A.5.10-11: Acceptable Use and Return of Assets
A3: Req # | B3: Section | C3: Requirement | D3: Status | E3: Evidence | F3: Owner | G3: Due Date | H3: Notes
A4: A.5.10-11-19 | B4: Laptops And Mobile Devices May Be | C4: Laptops and mobile devices may be taken off-site for business purposes. The following controls shall apply:.
A5: A.5.10-11-20 | B5: Working Away From The Office | C5: Working away from the office shall be in line with the Remote Working Policy.
A6: A.5.10-11-21 | B6: Laptop And Mobile Device Encryption | C6: Laptop and mobile device encryption shall be enabled.
A7: A.5.10-11-22 | B7: Laptops And Mobile Devices | C7: Laptops and mobile devices shall be protected by a password, PIN, or biometric lock.
A8: A.5.10-11-23 | B8: Equipment And Media Taken Off-Site | C8: Equipment and media taken off-site shall not be left unattended in public places, including on public transport, and shall not be left visible in a vehicle.
A9: A.5.10-11-24 | B9: Laptops And Mobile Devices | C9: Laptops and mobile devices shall be carried as hand luggage when travelling.
A10: A.5.10-11-25 | B10: Be Protected Against Loss Or Compromise | C10: Information shall be protected against loss or compromise when working remotely (for example, at home or in public places).
A11: A.5.10-11-26 | B11: Public Or Unsecured Wi-Fi Networks | C11: Public or unsecured Wi-Fi networks shall not be used for accessing organisation systems without VPN or equivalent encrypted connection.

Sheet Removable Storage Devices
A1: Removable Storage Devices — Compliance Checklist
A2: ISO/IEC 27001:2022 — Controls A.5.10-11: Acceptable Use and Return of Assets
A3: Req # | B3: Section | C3: Requirement | D3: Status | E3: Evidence | F3: Owner | G3: Due Date | H3: Notes
A4: A.5.10-11-27 | B4: Removable Storage Devices Such As Usb | C4: Removable storage devices such as USB drives, external hard drives, and optical media shall not be used unless authorised by the information security management team.
A5: A.5.10-11-28 | B5: Only Organisation-Owned, Managed, And | C5: Only organisation-owned, managed, and encrypted removable storage devices shall be used when transferring internal or confidential data. Personal removable storage devices are prohibited for organisation data.

Sheet Monitoring and Filtering
A1: Monitoring and Filtering — Compliance Checklist
A2: ISO/IEC 27001:2022 — Controls A.5.10-11: Acceptable Use and Return of Assets
A3: Req # | B3: Section | C3: Requirement | D3: Status | E3: Evidence | F3: Owner | G3: Due Date | H3: Notes
A4: A.5.10-11-29 | B4: Comply With Swiss Employment Law And | C4: Monitoring shall comply with Swiss employment law and data protection requirements:.
A5: A.5.10-11-30 | B5: Purpose Limitation: Monitoring | C5: Purpose limitation: Monitoring shall serve legitimate security purposes (detecting threats, investigating incidents, verifying compliance) — not monitoring employee behaviour (Art. 26 ArGV 3).
A6: A.5.10-11-31 | B6: Proportionality: The Least Intrusive | C6: Proportionality: The least intrusive monitoring method shall be used. Anonymous or pseudonymous analysis shall be preferred; nominal analysis shall only occur when anomalies are detected (nFADP Art. 6).
A7: A.5.10-11-32 | B7: Transparency: Employees | C7: Transparency: Employees shall be informed in advance that monitoring takes place, what is monitored, and why — through this policy and the information security awareness programme.
A8: A.5.10-11-33 | B8: Private Communications: The Organisation | C8: Private communications: The organisation shall not access private communications on organisation systems, even where limited personal use is permitted (Art. 328b CO).
A9: A.5.10-11-34 | B9: It System Logging | C9: IT system logging shall take place in accordance with the Logging and Monitoring Policy. Investigations shall be commenced where reasonable suspicion exists of a breach of this or any other policy.
A10: A.5.10-11-35 | B10: Be Conducted By The Information Security | C10: Investigations shall be conducted by the information security management team or designated personnel with appropriate authorisation. Employee rights: Employees investigated shall be informed unless doing so would compromise the investigation or violate legal obligations.

Sheet Reporting
A1: Reporting — Compliance Checklist
A2: ISO/IEC 27001:2022 — Controls A.5.10-11: Acceptable Use and Return of Assets
A3: Req # | B3: Section | C3: Requirement | D3: Status | E3: Evidence | F3: Owner | G3: Due Date | H3: Notes
A4: A.5.10-11-36 | B4: Breaches Of Information Security | C4: All breaches of information security policies shall be investigated. Where investigations reveal misconduct, disciplinary action may follow in line with organisation disciplinary procedures.

Sheet Return of Assets
A1: Return of Assets — Compliance Checklist
A2: ISO/IEC 27001:2022 — Controls A.5.10-11: Acceptable Use and Return of Assets
A3: Req # | B3: Section | C3: Requirement | D3: Status | E3: Evidence | F3: Owner | G3: Due Date | H3: Notes
A4: A.5.10-11-37 | B4: Employees And Third-Party Users | C4: All employees and third-party users shall return all organisation assets in their possession upon termination of their employment, contract, or agreement.
A5: A.5.10-11-38 | B5: A Signed Byod Agreement | C5: Where an employee or third-party user uses their own personal equipment (BYOD) to access organisation data, a signed BYOD agreement shall be in place before access is granted. The agreement shall include consent for remote wipe of organisation data upon termination or device loss, and acknowledgement that organisation data will be managed via MDM.
A6: A.5.10-11-39 | B6: Organisation Data | C6: All organisation data shall be transferred to the organisation and securely erased from the personal device.
A7: A.5.10-11-40 | B7: Mdm Profiles | C7: MDM profiles shall be removed and remote wipe of organisation data confirmed.
A8: A.5.10-11-41 | B8: Full Device Wipe Consent | C8: Where selective wipe (organisation data only) is not technically feasible, full device wipe consent shall be documented in the BYOD agreement.
A9: A.5.10-11-42 | B9: The Byod Record In The Asset | C9: The BYOD record in the asset register shall be updated.
A10: A.5.10-11-43 | B10: The Return Of Assets | C10: The return of assets shall be coordinated between HR and IT as part of the offboarding process.
A11: A.5.10-11-44 | B11: Line Managers | C11: Line managers shall verify that all assets assigned to the departing individual have been returned or accounted for.
A12: A.5.10-11-45 | B12: The Asset Register | C12: The asset register shall be updated to reflect all returned, reassigned, or disposed assets within 5 business days of departure.
A13: A.5.10-11-46 | B13: During Notice Periods, The Organisation | C13: During notice periods, the organisation shall take reasonable measures to prevent unauthorised copying of organisation information.
A14: A.5.10-11-47 | B14: Follow Up Within 5 Business Days | C14: HR shall follow up within 5 business days of the scheduled return date.
A15: A.5.10-11-48 | B15: Access To Organisation Systems From The | C15: Access to organisation systems from the device shall be blocked immediately.
... A20: A.5.10-11-53 | B20: Assets That Are No Longer Required | C20: When an employee changes role within the organisation, assets that are no longer required for the new role shall be returned and reassigned. Access rights shall be reviewed and adjusted to reflect the new role (per the Access Control Policy).
