Workbook

Sheet Executive Summary
A1: ISMS-OP-CHK-A.5.9 — Asset Management Compliance Checklist
A3: DOCUMENT INFORMATION
A4: Document ID | B4: ISMS-OP-CHK-A.5.9
A5: Source Policy | B5: ISMS-OP-POL-A.5.9
A6: ISO Controls | B6: Asset Management
A7: Generated | B7: 30.09.2026
A8: Prepared By
A9: Organisation
A10: Review Cycle | B10: Annual
A12: OVERALL COMPLIANCE STATUS
A13: Overall Compliance | B13: ='Dashboard'!G14
A14: Status | B14: =IF(Dashboard!H14>0,"INCOMPLETE",IF(Dashboard!G14="N/A","NOT ASSESSED",IF(ISNUMBER(VALUE(SUBSTITUTE(Dashboard!G14,"%",""))),IF(VALUE(SUBSTITUTE(Dashboard!G14,"%",""))>=90,"GREEN",IF(VALUE(SUBSTITUTE(Dashboard!G14,"%",""))>=70,"AMBER","RED")),"NOT ASSESSED")))
A16: KEY METRICS
A17: Total Requirements | B17: ='Dashboard'!B14
A18: Compliant | B18: ='Dashboard'!C14
A19: Partial | B19: ='Dashboard'!D14
A20: Non-Compliant | B20: ='Dashboard'!E14
A21: Not Applicable | B21: ='Dashboard'!F14
A22: Unanswered | B22: ='Dashboard'!H14
A23: Owner Coverage | B23: =IF(Dashboard!B14=0,"N/A",ROUND((COUNTA('Asset Categories'!F4:F5)+COUNTA('Inventory Hardware & IT Infra'!F4:F4)+COUNTA('Inventory Software & Licence'!F4:F6)+COUNTA('Inventory Cloud & SaaS Services'!F4:F7)+COUNTA('Inventory of Data & Info Assets'!F4:F4)+COUNTA('Ownership of Assets'!F4:F11)+COUNTA('Asset Lifecycle'!F4:F11)+COUNTA('Acceptable Use of Assets'!F4:F5)+COUNTA('Return of Assets'!F4:F7)+COUNTA('Asset Review'!F4:F5))/Dashboard!B14*100,0)&"%")
A25: DOMAIN STATUS SUMMARY
A26: Domain | B26: Compliance % | C26: Compliant | D26: Gaps | E26: Status
A27: Asset Categories | B27: ='Dashboard'!G4 | C27: ='Dashboard'!C4 | D27: ='Dashboard'!E4 | E27: =IF(Dashboard!H4>0,"INCOMPLETE",IF(Dashboard!G4="N/A","--",IF(ISNUMBER(VALUE(SUBSTITUTE(Dashboard!G4,"%",""))),IF(VALUE(SUBSTITUTE(Dashboard!G4,"%",""))>=90,"PASS",IF(VALUE(SUBSTITUTE(Dashboard!G4,"%",""))>=70,"REVIEW","FAIL")),"--")))
A28: Inventory Hardware & IT Infra | B28: ='Dashboard'!G5 | C28: ='Dashboard'!C5 | D28: ='Dashboard'!E5 | E28: =IF(Dashboard!H5>0,"INCOMPLETE",IF(Dashboard!G5="N/A","--",IF(ISNUMBER(VALUE(SUBSTITUTE(Dashboard!G5,"%",""))),IF(VALUE(SUBSTITUTE(Dashboard!G5,"%",""))>=90,"PASS",IF(VALUE(SUBSTITUTE(Dashboard!G5,"%",""))>=70,"REVIEW","FAIL")),"--")))
A29: Inventory Software & Licence | B29: ='Dashboard'!G6 | C29: ='Dashboard'!C6 | D29: ='Dashboard'!E6 | E29: =IF(Dashboard!H6>0,"INCOMPLETE",IF(Dashboard!G6="N/A","--",IF(ISNUMBER(VALUE(SUBSTITUTE(Dashboard!G6,"%",""))),IF(VALUE(SUBSTITUTE(Dashboard!G6,"%",""))>=90,"PASS",IF(VALUE(SUBSTITUTE(Dashboard!G6,"%",""))>=70,"REVIEW","FAIL")),"--")))
A30: Inventory Cloud & SaaS Services | B30: ='Dashboard'!G7 | C30: ='Dashboard'!C7 | D30: ='Dashboard'!E7 | E30: =IF(Dashboard!H7>0,"INCOMPLETE",IF(Dashboard!G7="N/A","--",IF(ISNUMBER(VALUE(SUBSTITUTE(Dashboard!G7,"%",""))),IF(VALUE(SUBSTITUTE(Dashboard!G7,"%",""))>=90,"PASS",IF(VALUE(SUBSTITUTE(Dashboard!G7,"%",""))>=70,"REVIEW","FAIL")),"--")))
A31: Inventory of Data & Info Assets | B31: ='Dashboard'!G8 | C31: ='Dashboard'!C8 | D31: ='Dashboard'!E8 | E31: =IF(Dashboard!H8>0,"INCOMPLETE",IF(Dashboard!G8="N/A","--",IF(ISNUMBER(VALUE(SUBSTITUTE(Dashboard!G8,"%",""))),IF(VALUE(SUBSTITUTE(Dashboard!G8,"%",""))>=90,"PASS",IF(VALUE(SUBSTITUTE(Dashboard!G8,"%",""))>=70,"REVIEW","FAIL")),"--")))
A32: Ownership of Assets | B32: ='Dashboard'!G9 | C32: ='Dashboard'!C9 | D32: ='Dashboard'!E9 | E32: =IF(Dashboard!H9>0,"INCOMPLETE",IF(Dashboard!G9="N/A","--",IF(ISNUMBER(VALUE(SUBSTITUTE(Dashboard!G9,"%",""))),IF(VALUE(SUBSTITUTE(Dashboard!G9,"%",""))>=90,"PASS",IF(VALUE(SUBSTITUTE(Dashboard!G9,"%",""))>=70,"REVIEW","FAIL")),"--")))
A33: Asset Lifecycle | B33: ='Dashboard'!G10 | C33: ='Dashboard'!C10 | D33: ='Dashboard'!E10 | E33: =IF(Dashboard!H10>0,"INCOMPLETE",IF(Dashboard!G10="N/A","--",IF(ISNUMBER(VALUE(SUBSTITUTE(Dashboard!G10,"%",""))),IF(VALUE(SUBSTITUTE(Dashboard!G10,"%",""))>=90,"PASS",IF(VALUE(SUBSTITUTE(Dashboard!G10,"%",""))>=70,"REVIEW","FAIL")),"--")))
A34: Acceptable Use of Assets | B34: ='Dashboard'!G11 | C34: ='Dashboard'!C11 | D34: ='Dashboard'!E11 | E34: =IF(Dashboard!H11>0,"INCOMPLETE",IF(Dashboard!G11="N/A","--",IF(ISNUMBER(VALUE(SUBSTITUTE(Dashboard!G11,"%",""))),IF(VALUE(SUBSTITUTE(Dashboard!G11,"%",""))>=90,"PASS",IF(VALUE(SUBSTITUTE(Dashboard!G11,"%",""))>=70,"REVIEW","FAIL")),"--")))
A35: Return of Assets | B35: ='Dashboard'!G12 | C35: ='Dashboard'!C12 | D35: ='Dashboard'!E12 | E35: =IF(Dashboard!H12>0,"INCOMPLETE",IF(Dashboard!G12="N/A","--",IF(ISNUMBER(VALUE(SUBSTITUTE(Dashboard!G12,"%",""))),IF(VALUE(SUBSTITUTE(Dashboard!G12,"%",""))>=90,"PASS",IF(VALUE(SUBSTITUTE(Dashboard!G12,"%",""))>=70,"REVIEW","FAIL")),"--")))
A36: Asset Review | B36: ='Dashboard'!G13 | C36: ='Dashboard'!C13 | D36: ='Dashboard'!E13 | E36: =IF(Dashboard!H13>0,"INCOMPLETE",IF(Dashboard!G13="N/A","--",IF(ISNUMBER(VALUE(SUBSTITUTE(Dashboard!G13,"%",""))),IF(VALUE(SUBSTITUTE(Dashboard!G13,"%",""))>=90,"PASS",IF(VALUE(SUBSTITUTE(Dashboard!G13,"%",""))>=70,"REVIEW","FAIL")),"--")))
A38: CRITICAL ISSUES
A39: # | B39: Issue Description | C39: Domain | D39: Owner | E39: Due Date
A40: 1
A41: 2
A42: 3
A43: 4
A44: 5
A46: MANAGEMENT COMMENTARY
...

Sheet Dashboard
A1: Asset Management — Compliance Dashboard
A3: Domain | B3: Total Reqs | C3: Compliant | D3: Partial | E3: Non-Compliant | F3: N/A | G3: Compliance % | H3: Unassessed
A4: Asset Categories | B4: =COUNTA('Asset Categories'!A4:A5) | C4: =COUNTIF('Asset Categories'!D4:D5,"Compliant") | D4: =COUNTIF('Asset Categories'!D4:D5,"Partial") | E4: =COUNTIF('Asset Categories'!D4:D5,"Non-Compliant") | F4: =COUNTIF('Asset Categories'!D4:D5,"N/A") | G4: =IF((B4-F4)=0,"N/A",ROUND(C4/(B4-F4)*100,1)&"%") | H4: =B4-(C4+D4+E4+F4)
A5: Inventory Hardware & IT Infra | B5: =COUNTA('Inventory Hardware & IT Infra'!A4:A4) | C5: =COUNTIF('Inventory Hardware & IT Infra'!D4:D4,"Compliant") | D5: =COUNTIF('Inventory Hardware & IT Infra'!D4:D4,"Partial") | E5: =COUNTIF('Inventory Hardware & IT Infra'!D4:D4,"Non-Compliant") | F5: =COUNTIF('Inventory Hardware & IT Infra'!D4:D4,"N/A") | G5: =IF((B5-F5)=0,"N/A",ROUND(C5/(B5-F5)*100,1)&"%") | H5: =B5-(C5+D5+E5+F5)
A6: Inventory Software & Licence | B6: =COUNTA('Inventory Software & Licence'!A4:A6) | C6: =COUNTIF('Inventory Software & Licence'!D4:D6,"Compliant") | D6: =COUNTIF('Inventory Software & Licence'!D4:D6,"Partial") | E6: =COUNTIF('Inventory Software & Licence'!D4:D6,"Non-Compliant") | F6: =COUNTIF('Inventory Software & Licence'!D4:D6,"N/A") | G6: =IF((B6-F6)=0,"N/A",ROUND(C6/(B6-F6)*100,1)&"%") | H6: =B6-(C6+D6+E6+F6)
A7: Inventory Cloud & SaaS Services | B7: =COUNTA('Inventory Cloud & SaaS Services'!A4:A7) | C7: =COUNTIF('Inventory Cloud & SaaS Services'!D4:D7,"Compliant") | D7: =COUNTIF('Inventory Cloud & SaaS Services'!D4:D7,"Partial") | E7: =COUNTIF('Inventory Cloud & SaaS Services'!D4:D7,"Non-Compliant") | F7: =COUNTIF('Inventory Cloud & SaaS Services'!D4:D7,"N/A") | G7: =IF((B7-F7)=0,"N/A",ROUND(C7/(B7-F7)*100,1)&"%") | H7: =B7-(C7+D7+E7+F7)
A8: Inventory of Data & Info Assets | B8: =COUNTA('Inventory of Data & Info Assets'!A4:A4) | C8: =COUNTIF('Inventory of Data & Info Assets'!D4:D4,"Compliant") | D8: =COUNTIF('Inventory of Data & Info Assets'!D4:D4,"Partial") | E8: =COUNTIF('Inventory of Data & Info Assets'!D4:D4,"Non-Compliant") | F8: =COUNTIF('Inventory of Data & Info Assets'!D4:D4,"N/A") | G8: =IF((B8-F8)=0,"N/A",ROUND(C8/(B8-F8)*100,1)&"%") | H8: =B8-(C8+D8+E8+F8)
A9: Ownership of Assets | B9: =COUNTA('Ownership of Assets'!A4:A11) | C9: =COUNTIF('Ownership of Assets'!D4:D11,"Compliant") | D9: =COUNTIF('Ownership of Assets'!D4:D11,"Partial") | E9: =COUNTIF('Ownership of Assets'!D4:D11,"Non-Compliant") | F9: =COUNTIF('Ownership of Assets'!D4:D11,"N/A") | G9: =IF((B9-F9)=0,"N/A",ROUND(C9/(B9-F9)*100,1)&"%") | H9: =B9-(C9+D9+E9+F9)
A10: Asset Lifecycle | B10: =COUNTA('Asset Lifecycle'!A4:A11) | C10: =COUNTIF('Asset Lifecycle'!D4:D11,"Compliant") | D10: =COUNTIF('Asset Lifecycle'!D4:D11,"Partial") | E10: =COUNTIF('Asset Lifecycle'!D4:D11,"Non-Compliant") | F10: =COUNTIF('Asset Lifecycle'!D4:D11,"N/A") | G10: =IF((B10-F10)=0,"N/A",ROUND(C10/(B10-F10)*100,1)&"%") | H10: =B10-(C10+D10+E10+F10)
A11: Acceptable Use of Assets | B11: =COUNTA('Acceptable Use of Assets'!A4:A5) | C11: =COUNTIF('Acceptable Use of Assets'!D4:D5,"Compliant") | D11: =COUNTIF('Acceptable Use of Assets'!D4:D5,"Partial") | E11: =COUNTIF('Acceptable Use of Assets'!D4:D5,"Non-Compliant") | F11: =COUNTIF('Acceptable Use of Assets'!D4:D5,"N/A") | G11: =IF((B11-F11)=0,"N/A",ROUND(C11/(B11-F11)*100,1)&"%") | H11: =B11-(C11+D11+E11+F11)
A12: Return of Assets | B12: =COUNTA('Return of Assets'!A4:A7) | C12: =COUNTIF('Return of Assets'!D4:D7,"Compliant") | D12: =COUNTIF('Return of Assets'!D4:D7,"Partial") | E12: =COUNTIF('Return of Assets'!D4:D7,"Non-Compliant") | F12: =COUNTIF('Return of Assets'!D4:D7,"N/A") | G12: =IF((B12-F12)=0,"N/A",ROUND(C12/(B12-F12)*100,1)&"%") | H12: =B12-(C12+D12+E12+F12)
A13: Asset Review | B13: =COUNTA('Asset Review'!A4:A5) | C13: =COUNTIF('Asset Review'!D4:D5,"Compliant") | D13: =COUNTIF('Asset Review'!D4:D5,"Partial") | E13: =COUNTIF('Asset Review'!D4:D5,"Non-Compliant") | F13: =COUNTIF('Asset Review'!D4:D5,"N/A") | G13: =IF((B13-F13)=0,"N/A",ROUND(C13/(B13-F13)*100,1)&"%") | H13: =B13-(C13+D13+E13+F13)
A14: TOTAL | B14: =SUM(B4:B13) | C14: =SUM(C4:C13) | D14: =SUM(D4:D13) | E14: =SUM(E4:E13) | F14: =SUM(F4:F13) | G14: =IF((B14-F14)=0,"N/A",ROUND(C14/(B14-F14)*100,1)&"%") | H14: =SUM(H4:H13)
A16: COMPLIANCE BY STATUS
A17: Compliant | B17: =C14 | C17: =IF(B14=0,"",ROUND(B17/B14*100,1)&"%")
A18: Partial | B18: =D14 | C18: =IF(B14=0,"",ROUND(B18/B14*100,1)&"%")
A19: Non-Compliant | B19: =E14 | C19: =IF(B14=0,"",ROUND(B19/B14*100,1)&"%")
A20: N/A | B20: =F14 | C20: =IF(B14=0,"",ROUND(B20/B14*100,1)&"%")
A22: TOP GAPS (Manual Entry)
A23: Priority | B23: Domain | C23: Requirement | D23: Owner | E23: Due Date | F23: Status
A35: COMPLIANCE TREND (Manual Entry)
A36: Assessment Date | B36: Overall % | C36: Compliant | D36: Gaps | E36: Assessor | F36: Notes

Sheet Asset Categories
A1: Asset Categories — Compliance Checklist
A2: ISO/IEC 27001:2022 — Control A.5.9: Asset Management
A3: Req # | B3: Section | C3: Requirement | D3: Status | E3: Evidence | F3: Owner | G3: Due Date | H3: Notes
A4: A.5.9-01 | B4: The Following Categories Of Assets | C4: The following categories of assets shall be inventoried:.
A5: A.5.9-02 | B5: Personnel Competencies: The Register | C5: Personnel competencies: The register documents roles and competencies*, not individual person records. Example: 'Database Administrator competency (2 qualified staff)' — not individual names. Where a critical function is dependent on a single individual (single point of failure), this shall be flagged and a succession or knowledge transfer plan documented to mitigate the risk.

Sheet Inventory Hardware & IT Infra
A1: Inventory Hardware & IT Infra — Compliance Checklist
A2: ISO/IEC 27001:2022 — Control A.5.9: Asset Management
A3: Req # | B3: Section | C3: Requirement | D3: Status | E3: Evidence | F3: Owner | G3: Due Date | H3: Notes
A4: A.5.9-03 | B4: Hardware And It Infrastructure Assets | C4: All hardware and IT infrastructure assets shall be registered in the asset inventory. For each asset, the following attributes shall be recorded:.

Sheet Inventory Software & Licence
A1: Inventory Software & Licence — Compliance Checklist
A2: ISO/IEC 27001:2022 — Control A.5.9: Asset Management
A3: Req # | B3: Section | C3: Requirement | D3: Status | E3: Evidence | F3: Owner | G3: Due Date | H3: Notes
A4: A.5.9-04 | B4: Software And Software Licences | C4: Software and software licences shall be registered in the asset inventory. For each software asset, the following attributes shall be recorded:.
A5: A.5.9-05 | B5: Only Organisation-Approved And Licensed | C5: Only organisation-approved and licensed software shall be deployed. Unauthorised software discovered during inventory reviews shall be reported to the information security management team for assessment and removal.
A6: A.5.9-06 | B6: Software That Has Reached End Of | C6: Software that has reached end of life or end of support shall be flagged and prioritised for upgrade or replacement. Where unsupported software cannot be immediately replaced, the risk shall be documented in the risk register with compensating controls.

Sheet Inventory Cloud & SaaS Services
A1: Inventory Cloud & SaaS Services — Compliance Checklist
A2: ISO/IEC 27001:2022 — Control A.5.9: Asset Management
A3: Req # | B3: Section | C3: Requirement | D3: Status | E3: Evidence | F3: Owner | G3: Due Date | H3: Notes
A4: A.5.9-07 | B4: Cloud Services (Iaas, Paas, Saas) | C4: Cloud services (IaaS, PaaS, SaaS) shall be registered in the asset inventory alongside traditional software. For each cloud service, the following additional attributes shall be recorded:.
A5: A.5.9-08 | B5: Cloud Services | C5: Cloud services shall be classified as:.
A6: A.5.9-09 | B6: New Cloud Services | C6: New cloud services shall be registered in the asset inventory before organisation data is processed in the service (or within 5 business days for emergency deployments with CISO approval).
A7: A.5.9-10 | B7: Unsanctioned Cloud Services (Shadow It) | C7: Unsanctioned cloud services (shadow IT) shall be identified through periodic reviews of expense reports, SSO logs, and network traffic. Newly discovered services shall be assessed for security and data protection compliance before being sanctioned.

Sheet Inventory of Data & Info Assets
A1: Inventory of Data & Info Assets — Compliance Checklist
A2: ISO/IEC 27001:2022 — Control A.5.9: Asset Management
A3: Req # | B3: Section | C3: Requirement | D3: Status | E3: Evidence | F3: Owner | G3: Due Date | H3: Notes
A4: A.5.9-11 | B4: Data And Information Assets | C4: Data and information assets shall be identified, and an inventory drawn up and maintained. For each data asset, the following attributes shall be recorded:.

Sheet Ownership of Assets
A1: Ownership of Assets — Compliance Checklist
A2: ISO/IEC 27001:2022 — Control A.5.9: Asset Management
A3: Req # | B3: Section | C3: Requirement | D3: Status | E3: Evidence | F3: Owner | G3: Due Date | H3: Notes
A4: A.5.9-12 | B4: An Owner | C4: An owner shall be assigned to every inventoried asset. Ownership shall not be left blank.
A5: A.5.9-13 | B5: Asset Owners | C5: Asset owners shall:.
A6: A.5.9-14 | B6: New Assets | C6: New assets shall have an owner assigned at the time of registration.
A7: A.5.9-15 | B7: The Information Security Management Team | C7: Where ownership is unclear, the information security management team shall escalate to the appropriate manager for determination within 30 calendar days.
A8: A.5.9-16 | B8: Assets Without An Assigned Owner Beyond | C8: Assets without an assigned owner beyond 30 days shall be escalated to the CISO with documented justification.
A9: A.5.9-17 | B9: Ownership Changes (E.G., Employee | C9: Ownership changes (e.g., employee departure, role change) shall be updated in the register within 5 business days.
A10: A.5.9-18 | B10: Discovered Unregistered Assets: Assets | C10: Discovered unregistered assets: Assets found in use but not in the inventory shall be immediately registered with a temporary owner (the discoverer's manager or IT), investigated within 14 business days* to determine the business owner and purpose, and either formally assigned to a permanent owner or decommissioned.
A11: A.5.9-19 | B11: Owner Departure: When An Asset Owner | C11: Owner departure: When an asset owner leaves the organisation, ownership shall be reassigned to the departing employee's manager or designated successor within 10 business days* of departure. Assets without reassigned ownership after 30 days shall be escalated to the CISO.

Sheet Asset Lifecycle
A1: Asset Lifecycle — Compliance Checklist
A2: ISO/IEC 27001:2022 — Control A.5.9: Asset Management
A3: Req # | B3: Section | C3: Requirement | D3: Status | E3: Evidence | F3: Owner | G3: Due Date | H3: Notes
A4: A.5.9-20 | B4: Be Registered In The Asset Inventory | C4: All assets shall be registered in the asset inventory within 5 business days of acquisition or deployment. Assets shall not be connected to the network or used to process organisation data until registered.
A5: A.5.9-21 | B5: Any Change To An Asset'S Owner | C5: Any change to an asset's owner, location, classification, or status shall be reflected in the register within 5 business days of the change.
A6: A.5.9-22 | B6: Be Securely Erased Or Destroyed In | C6: Data shall be securely erased or destroyed in line with the Information Classification and Handling Policy, using methods compliant with NIST SP 800-88 (Guidelines for Media Sanitization): Clear (logical overwrite) for INTERNAL data, Purge (cryptographic erasure or degauss) for CONFIDENTIAL data, or Destroy (physical destruction) where required.
A7: A.5.9-23 | B7: Software Licences | C7: Software licences shall be reclaimed or deactivated.
A8: A.5.9-24 | B8: The Asset Register | C8: The asset register shall be updated to reflect the disposal, including the date and method of disposal.
A9: A.5.9-25 | B9: For Assets That Stored Confidential Or | C9: For assets that stored confidential or personal data, evidence of data sanitisation shall be retained (e.g., certificate of destruction, wipe confirmation log).
A10: A.5.9-26 | B10: Personally-Owned Devices Used To Access | C10: Where BYOD is permitted, personally-owned devices used to access organisation data shall be registered in the asset inventory with a flag indicating personal ownership. Minimum BYOD registration attributes:.
A11: A.5.9-27 | B11: Upon Termination Or Contract End, | C11: Upon termination or contract end, organisation data shall be wiped from the personal device, and the BYOD record shall be updated.

Sheet Acceptable Use of Assets
A1: Acceptable Use of Assets — Compliance Checklist
A2: ISO/IEC 27001:2022 — Control A.5.9: Asset Management
A3: Req # | B3: Section | C3: Requirement | D3: Status | E3: Evidence | F3: Owner | G3: Due Date | H3: Notes
A4: A.5.9-28 | B4: Acceptable Use Of Assets | C4: Acceptable use of assets shall be in line with the Acceptable Use Policy.
A5: A.5.9-29 | B5: Not Install Unauthorised Software, | C5: Users shall not install unauthorised software, connect unapproved devices to the network, or use organisation assets for purposes outside the scope of their role.

Sheet Return of Assets
A1: Return of Assets — Compliance Checklist
A2: ISO/IEC 27001:2022 — Control A.5.9: Asset Management
A3: Req # | B3: Section | C3: Requirement | D3: Status | E3: Evidence | F3: Owner | G3: Due Date | H3: Notes
A4: A.5.9-30 | B4: Employees And Third-Party Users | C4: All employees and third-party users shall return all organisation assets in their possession upon termination of their employment, contract, or agreement.
A5: A.5.9-31 | B5: Ensure That All Organisation Information | C5: Where an employee or third-party user has used their own personal equipment (BYOD), procedures shall ensure that all organisation information is transferred to the organisation and securely erased from the personal device.
A6: A.5.9-32 | B6: During Notice Periods, The Organisation | C6: During notice periods, the organisation shall take reasonable measures to prevent unauthorised copying of organisation information by departing employees or third-party users.
A7: A.5.9-33 | B7: The Asset Register | C7: The asset register shall be updated to reflect all returned, reassigned, or disposed assets.

Sheet Asset Review
A1: Asset Review — Compliance Checklist
A2: ISO/IEC 27001:2022 — Control A.5.9: Asset Management
A3: Req # | B3: Section | C3: Requirement | D3: Status | E3: Evidence | F3: Owner | G3: Due Date | H3: Notes
A4: A.5.9-34 | B4: The Asset Inventory | C4: The asset inventory shall be reviewed at the following intervals:.
A5: A.5.9-35 | B5: Department Heads | C5: Department heads shall confirm their asset lists are current during the annual review. Discrepancies shall be investigated and resolved within 30 days.
