Workbook

Sheet Executive Summary
A1: PRIV-CHK-A.2.4.2-4 — Processor Lifecycle Controls Compliance Checklist
A3: DOCUMENT INFORMATION
A4: Document ID | B4: PRIV-CHK-A.2.4.2-4
A5: Source Policy | B5: PRIV-POL-A.2.4.2-4
A6: ISO Controls | B6: Processor Lifecycle Controls
A7: Generated | B7: 10.03.2026
A8: Prepared By
A9: Organisation
A10: Review Cycle | B10: Annual
A12: OVERALL COMPLIANCE STATUS
A13: Overall Compliance | B13: ='Dashboard'!G7
A14: Status | B14: =IF(Dashboard!G7="N/A","NOT ASSESSED",IF(ISNUMBER(VALUE(SUBSTITUTE(Dashboard!G7,"%",""))),IF(VALUE(SUBSTITUTE(Dashboard!G7,"%",""))>=90,"GREEN",IF(VALUE(SUBSTITUTE(Dashboard!G7,"%",""))>=70,"AMBER","RED")),"NOT ASSESSED"))
A16: KEY METRICS
A17: Total Requirements | B17: ='Dashboard'!B7
A18: Compliant | B18: ='Dashboard'!C7
A19: Partial | B19: ='Dashboard'!D7
A20: Non-Compliant | B20: ='Dashboard'!E7
A21: Not Applicable | B21: ='Dashboard'!F7
A22: Owner Coverage | B22: =IF(Dashboard!B7=0,"N/A",ROUND((COUNTA('Temporary Files — Processor'!F4:F7)+COUNTA('Return, Transfer or Disposal'!F4:F8)+COUNTA('Transmission Controls — Processor'!F4:F7))/Dashboard!B7*100,0)&"%")
A24: DOMAIN STATUS SUMMARY
A25: Domain | B25: Compliance % | C25: Compliant | D25: Gaps | E25: Status
A26: Temporary Files — Processor | B26: ='Dashboard'!G4 | C26: ='Dashboard'!C4 | D26: ='Dashboard'!E4 | E26: =IF(Dashboard!G4="N/A","--",IF(ISNUMBER(VALUE(SUBSTITUTE(Dashboard!G4,"%",""))),IF(VALUE(SUBSTITUTE(Dashboard!G4,"%",""))>=90,"PASS",IF(VALUE(SUBSTITUTE(Dashboard!G4,"%",""))>=70,"REVIEW","FAIL")),"--"))
A27: Return, Transfer or Disposal | B27: ='Dashboard'!G5 | C27: ='Dashboard'!C5 | D27: ='Dashboard'!E5 | E27: =IF(Dashboard!G5="N/A","--",IF(ISNUMBER(VALUE(SUBSTITUTE(Dashboard!G5,"%",""))),IF(VALUE(SUBSTITUTE(Dashboard!G5,"%",""))>=90,"PASS",IF(VALUE(SUBSTITUTE(Dashboard!G5,"%",""))>=70,"REVIEW","FAIL")),"--"))
A28: Transmission Controls — Processor | B28: ='Dashboard'!G6 | C28: ='Dashboard'!C6 | D28: ='Dashboard'!E6 | E28: =IF(Dashboard!G6="N/A","--",IF(ISNUMBER(VALUE(SUBSTITUTE(Dashboard!G6,"%",""))),IF(VALUE(SUBSTITUTE(Dashboard!G6,"%",""))>=90,"PASS",IF(VALUE(SUBSTITUTE(Dashboard!G6,"%",""))>=70,"REVIEW","FAIL")),"--"))
A30: CRITICAL ISSUES
A31: # | B31: Issue Description | C31: Domain | D31: Owner | E31: Due Date
A32: 1
A33: 2
A34: 3
A35: 4
A36: 5
A38: MANAGEMENT COMMENTARY
A39: [Enter management commentary on processor lifecycle controls posture]
A43: APPROVAL
A44: Assessed By
A45: Name:
A46: Date:
A47: Signature:
A48: Decision:
A50: Reviewed By (DPO)
...

Sheet Dashboard
A1: Processor Lifecycle Controls — Compliance Dashboard
A3: Domain | B3: Total Reqs | C3: Compliant | D3: Partial | E3: Non-Compliant | F3: N/A | G3: Compliance %
A4: Temporary Files — Processor | B4: =COUNTA('Temporary Files — Processor'!D4:D7) | C4: =COUNTIF('Temporary Files — Processor'!D4:D7,"Compliant") | D4: =COUNTIF('Temporary Files — Processor'!D4:D7,"Partial") | E4: =COUNTIF('Temporary Files — Processor'!D4:D7,"Non-Compliant") | F4: =COUNTIF('Temporary Files — Processor'!D4:D7,"N/A") | G4: =IF((B4-F4)=0,"N/A",ROUND(C4/(B4-F4)*100,1)&"%")
A5: Return, Transfer or Disposal | B5: =COUNTA('Return, Transfer or Disposal'!D4:D8) | C5: =COUNTIF('Return, Transfer or Disposal'!D4:D8,"Compliant") | D5: =COUNTIF('Return, Transfer or Disposal'!D4:D8,"Partial") | E5: =COUNTIF('Return, Transfer or Disposal'!D4:D8,"Non-Compliant") | F5: =COUNTIF('Return, Transfer or Disposal'!D4:D8,"N/A") | G5: =IF((B5-F5)=0,"N/A",ROUND(C5/(B5-F5)*100,1)&"%")
A6: Transmission Controls — Processor | B6: =COUNTA('Transmission Controls — Processor'!D4:D7) | C6: =COUNTIF('Transmission Controls — Processor'!D4:D7,"Compliant") | D6: =COUNTIF('Transmission Controls — Processor'!D4:D7,"Partial") | E6: =COUNTIF('Transmission Controls — Processor'!D4:D7,"Non-Compliant") | F6: =COUNTIF('Transmission Controls — Processor'!D4:D7,"N/A") | G6: =IF((B6-F6)=0,"N/A",ROUND(C6/(B6-F6)*100,1)&"%")
A7: TOTAL | B7: =SUM(B4:B6) | C7: =SUM(C4:C6) | D7: =SUM(D4:D6) | E7: =SUM(E4:E6) | F7: =SUM(F4:F6) | G7: =IF((B7-F7)=0,"N/A",ROUND(C7/(B7-F7)*100,1)&"%")
A9: COMPLIANCE BY STATUS
A10: Compliant | B10: =C7 | C10: =IF(B7=0,"",ROUND(B10/B7*100,1)&"%")
A11: Partial | B11: =D7 | C11: =IF(B7=0,"",ROUND(B11/B7*100,1)&"%")
A12: Non-Compliant | B12: =E7 | C12: =IF(B7=0,"",ROUND(B12/B7*100,1)&"%")
A13: N/A | B13: =F7 | C13: =IF(B7=0,"",ROUND(B13/B7*100,1)&"%")
A15: TOP GAPS (Manual Entry)
A16: Priority | B16: Domain | C16: Requirement | D16: Owner | E16: Due Date | F16: Status
A28: COMPLIANCE TREND (Manual Entry)
A29: Assessment Date | B29: Overall % | C29: Compliant | D29: Gaps | E29: Assessor | F29: Notes

Sheet Temporary Files — Processor
A1: Temporary Files — Processor — Compliance Checklist
A2: ISO/IEC 27701:2025 — Controls A.2.4.2-4: Processor Lifecycle Controls
A3: Req # | B3: Section | C3: Requirement | D3: Status | E3: Evidence | F3: Owner | G3: Due Date | H3: Notes
A4: A.2.4.2-01 | B4: Documented Disposal Periods | C4: Temporary files created as a result of processing customer PII shall be disposed of within documented, specified periods. A schedule of temporary file types and maximum retention periods shall be maintained and made available to customers.
A5: A.2.4.2-02 | B5: Disposal Periods | C5: Processing cache and staging files shall be disposed within 48 hours of processing completion. Error/exception logs containing customer PII shall be disposed within 30 days (automated rotation). Export files generated for customer delivery shall be disposed within 72 hours after confirmed delivery.
A6: A.2.4.2-03 | B6: Automated Purge | C6: Automated purge mechanisms are preferred over manual deletion for customer PII temporary files. Where automated purge is not technically feasible, manual deletion shall be scheduled, logged, and confirmed.
A7: A.2.4.2-04 | B7: Purge Confirmation | C7: Purge confirmation records (automated or manual) for customer PII temporary files shall be maintained for 3 years, sufficient to demonstrate compliance to customers and supervisory authorities.

Sheet Return, Transfer or Disposal
A1: Return, Transfer or Disposal — Compliance Checklist
A2: ISO/IEC 27701:2025 — Controls A.2.4.2-4: Processor Lifecycle Controls
A3: Req # | B3: Section | C3: Requirement | D3: Status | E3: Evidence | F3: Owner | G3: Due Date | H3: Notes
A4: A.2.4.3-01 | B4: End-of-Service Capability | C4: When a customer contract ends or a customer requests return or deletion of their PII, the organisation shall be able to return the PII in an agreed format, transfer it to another processor designated by the customer, or dispose of it securely using approved erasure methods — at the customer's instruction.
A5: A.2.4.3-02 | B5: Customer Instruction | C5: The organisation shall follow the customer's documented instruction for end-of-service PII handling. In the absence of a specific customer instruction, the organisation shall request instructions and follow the default specified in the processor agreement.
A6: A.2.4.3-03 | B6: Disposal Standards | C6: Disposal of customer PII at contract end shall use approved methods: database records via SQL DELETE or cryptographic erasure; file system via cryptographic erasure or approved overwrite; backup media aligned to backup retention schedule with confirmed deletion. Methods are consistent with PRIV-POL-A.1.4.6-10 (A.1.4.9).
A7: A.2.4.3-04 | B7: Disposal Confirmation | C7: Disposal shall be confirmed in writing to the customer within the timeframe specified in the processor agreement (typically within 30 days of service end). Written disposal confirmation records shall be retained for 5 years.
A8: A.2.4.3-05 | B8: Policy Availability | C8: The organisation's return, transfer, and disposal policy shall be made available to customers on request and, where contractually required, as part of the processor agreement documentation.

Sheet Transmission Controls — Processor
A1: Transmission Controls — Processor — Compliance Checklist
A2: ISO/IEC 27701:2025 — Controls A.2.4.2-4: Processor Lifecycle Controls
A3: Req # | B3: Section | C3: Requirement | D3: Status | E3: Evidence | F3: Owner | G3: Due Date | H3: Notes
A4: A.2.4.4-01 | B4: Encryption in Transit | C4: All customer PII transmitted over networks shall be encrypted in transit using current TLS standards (minimum TLS 1.2; TLS 1.3 preferred). Unencrypted transmission of CONFIDENTIAL or RESTRICTED customer PII over public networks is prohibited.
A5: A.2.4.4-02 | B5: Approved Transfer Methods | C5: CONFIDENTIAL and RESTRICTED customer PII transmissions shall use approved secure transfer methods consistent with PRIV-POL-A.3.5-7. The organisation shall ensure that data reaches its intended destination and is not interceptable or diverted.
A6: A.2.4.4-03 | B6: Delivery Confirmation | C6: Delivery confirmation or receipt acknowledgment shall be obtained for RESTRICTED PII transmissions to third parties (including sub-processors and customers). Confirmation records shall be maintained.
A7: A.2.4.4-04 | B7: Transmission Logging | C7: Transmission logs for customer PII carried over networks shall be maintained per PRIV-POL-A.3.23-31 logging requirements, sufficient to identify what was transmitted, to whom, and when.
