Workbook

Sheet Executive Summary
A1: ISMS-OP-CHK-A.7.8-9 — Equipment Siting and Protection Compliance Checklist
A3: DOCUMENT INFORMATION
A4: Document ID | B4: ISMS-OP-CHK-A.7.8-9
A5: Source Policy | B5: ISMS-OP-POL-A.7.8-9
A6: ISO Controls | B6: Equipment Siting and Protection
A7: Generated | B7: 08.02.2026
A8: Prepared By
A9: Organisation
A10: Review Cycle | B10: Annual
A12: OVERALL COMPLIANCE STATUS
A13: Overall Compliance | B13: ='Dashboard'!G9
A14: Status | B14: =IF(Dashboard!G9="N/A","NOT ASSESSED",IF(ISNUMBER(VALUE(SUBSTITUTE(Dashboard!G9,"%",""))),IF(VALUE(SUBSTITUTE(Dashboard!G9,"%",""))>=90,"GREEN",IF(VALUE(SUBSTITUTE(Dashboard!G9,"%",""))>=70,"AMBER","RED")),"NOT ASSESSED"))
A16: KEY METRICS
A17: Total Requirements | B17: ='Dashboard'!B9
A18: Compliant | B18: ='Dashboard'!C9
A19: Partial | B19: ='Dashboard'!D9
A20: Non-Compliant | B20: ='Dashboard'!E9
A21: Not Applicable | B21: ='Dashboard'!F9
A22: Owner Coverage | B22: =IF(Dashboard!B9=0,"N/A",ROUND((COUNTA('Equipment Class for Prot'!F4:F5)+COUNTA('Equipment Siting Requirements'!F4:F39)+COUNTA('Security of Assets Off-Premises'!F4:F46)+COUNTA('Incident Classification'!F4:F5)+COUNTA('Compliance Measurement'!F4:F4))/Dashboard!B9*100,0)&"%")
A24: DOMAIN STATUS SUMMARY
A25: Domain | B25: Compliance % | C25: Compliant | D25: Gaps | E25: Status
A26: Equipment Class for Prot | B26: ='Dashboard'!G4 | C26: ='Dashboard'!C4 | D26: ='Dashboard'!E4 | E26: =IF(Dashboard!G4="N/A","--",IF(ISNUMBER(VALUE(SUBSTITUTE(Dashboard!G4,"%",""))),IF(VALUE(SUBSTITUTE(Dashboard!G4,"%",""))>=90,"PASS",IF(VALUE(SUBSTITUTE(Dashboard!G4,"%",""))>=70,"REVIEW","FAIL")),"--"))
A27: Equipment Siting Requirements | B27: ='Dashboard'!G5 | C27: ='Dashboard'!C5 | D27: ='Dashboard'!E5 | E27: =IF(Dashboard!G5="N/A","--",IF(ISNUMBER(VALUE(SUBSTITUTE(Dashboard!G5,"%",""))),IF(VALUE(SUBSTITUTE(Dashboard!G5,"%",""))>=90,"PASS",IF(VALUE(SUBSTITUTE(Dashboard!G5,"%",""))>=70,"REVIEW","FAIL")),"--"))
A28: Security of Assets Off-Premises | B28: ='Dashboard'!G6 | C28: ='Dashboard'!C6 | D28: ='Dashboard'!E6 | E28: =IF(Dashboard!G6="N/A","--",IF(ISNUMBER(VALUE(SUBSTITUTE(Dashboard!G6,"%",""))),IF(VALUE(SUBSTITUTE(Dashboard!G6,"%",""))>=90,"PASS",IF(VALUE(SUBSTITUTE(Dashboard!G6,"%",""))>=70,"REVIEW","FAIL")),"--"))
A29: Incident Classification | B29: ='Dashboard'!G7 | C29: ='Dashboard'!C7 | D29: ='Dashboard'!E7 | E29: =IF(Dashboard!G7="N/A","--",IF(ISNUMBER(VALUE(SUBSTITUTE(Dashboard!G7,"%",""))),IF(VALUE(SUBSTITUTE(Dashboard!G7,"%",""))>=90,"PASS",IF(VALUE(SUBSTITUTE(Dashboard!G7,"%",""))>=70,"REVIEW","FAIL")),"--"))
A30: Compliance Measurement | B30: ='Dashboard'!G8 | C30: ='Dashboard'!C8 | D30: ='Dashboard'!E8 | E30: =IF(Dashboard!G8="N/A","--",IF(ISNUMBER(VALUE(SUBSTITUTE(Dashboard!G8,"%",""))),IF(VALUE(SUBSTITUTE(Dashboard!G8,"%",""))>=90,"PASS",IF(VALUE(SUBSTITUTE(Dashboard!G8,"%",""))>=70,"REVIEW","FAIL")),"--"))
A32: CRITICAL ISSUES
A33: # | B33: Issue Description | C33: Domain | D33: Owner | E33: Due Date
A34: 1
A35: 2
A36: 3
A37: 4
A38: 5
A40: MANAGEMENT COMMENTARY
A41: [Enter management commentary on equipment siting and protection posture]
A45: APPROVAL
A46: Assessed By
A47: Name:
A48: Date:
A49: Signature:
...

Sheet Dashboard
A1: Equipment Siting and Protection — Compliance Dashboard
A3: Domain | B3: Total Reqs | C3: Compliant | D3: Partial | E3: Non-Compliant | F3: N/A | G3: Compliance %
A4: Equipment Class for Prot | B4: =COUNTA('Equipment Class for Prot'!D4:D5) | C4: =COUNTIF('Equipment Class for Prot'!D4:D5,"Compliant") | D4: =COUNTIF('Equipment Class for Prot'!D4:D5,"Partial") | E4: =COUNTIF('Equipment Class for Prot'!D4:D5,"Non-Compliant") | F4: =COUNTIF('Equipment Class for Prot'!D4:D5,"N/A") | G4: =IF((B4-F4)=0,"N/A",ROUND(C4/(B4-F4)*100,1)&"%")
A5: Equipment Siting Requirements | B5: =COUNTA('Equipment Siting Requirements'!D4:D39) | C5: =COUNTIF('Equipment Siting Requirements'!D4:D39,"Compliant") | D5: =COUNTIF('Equipment Siting Requirements'!D4:D39,"Partial") | E5: =COUNTIF('Equipment Siting Requirements'!D4:D39,"Non-Compliant") | F5: =COUNTIF('Equipment Siting Requirements'!D4:D39,"N/A") | G5: =IF((B5-F5)=0,"N/A",ROUND(C5/(B5-F5)*100,1)&"%")
A6: Security of Assets Off-Premises | B6: =COUNTA('Security of Assets Off-Premises'!D4:D46) | C6: =COUNTIF('Security of Assets Off-Premises'!D4:D46,"Compliant") | D6: =COUNTIF('Security of Assets Off-Premises'!D4:D46,"Partial") | E6: =COUNTIF('Security of Assets Off-Premises'!D4:D46,"Non-Compliant") | F6: =COUNTIF('Security of Assets Off-Premises'!D4:D46,"N/A") | G6: =IF((B6-F6)=0,"N/A",ROUND(C6/(B6-F6)*100,1)&"%")
A7: Incident Classification | B7: =COUNTA('Incident Classification'!D4:D5) | C7: =COUNTIF('Incident Classification'!D4:D5,"Compliant") | D7: =COUNTIF('Incident Classification'!D4:D5,"Partial") | E7: =COUNTIF('Incident Classification'!D4:D5,"Non-Compliant") | F7: =COUNTIF('Incident Classification'!D4:D5,"N/A") | G7: =IF((B7-F7)=0,"N/A",ROUND(C7/(B7-F7)*100,1)&"%")
A8: Compliance Measurement | B8: =COUNTA('Compliance Measurement'!D4:D4) | C8: =COUNTIF('Compliance Measurement'!D4:D4,"Compliant") | D8: =COUNTIF('Compliance Measurement'!D4:D4,"Partial") | E8: =COUNTIF('Compliance Measurement'!D4:D4,"Non-Compliant") | F8: =COUNTIF('Compliance Measurement'!D4:D4,"N/A") | G8: =IF((B8-F8)=0,"N/A",ROUND(C8/(B8-F8)*100,1)&"%")
A9: TOTAL | B9: =SUM(B4:B8) | C9: =SUM(C4:C8) | D9: =SUM(D4:D8) | E9: =SUM(E4:E8) | F9: =SUM(F4:F8) | G9: =IF((B9-F9)=0,"N/A",ROUND(C9/(B9-F9)*100,1)&"%")
A11: COMPLIANCE BY STATUS
A12: Compliant | B12: =C9 | C12: =IF(B9=0,"",ROUND(B12/B9*100,1)&"%")
A13: Partial | B13: =D9 | C13: =IF(B9=0,"",ROUND(B13/B9*100,1)&"%")
A14: Non-Compliant | B14: =E9 | C14: =IF(B9=0,"",ROUND(B14/B9*100,1)&"%")
A15: N/A | B15: =F9 | C15: =IF(B9=0,"",ROUND(B15/B9*100,1)&"%")
A17: TOP GAPS (Manual Entry)
A18: Priority | B18: Domain | C18: Requirement | D18: Owner | E18: Due Date | F18: Status
A30: COMPLIANCE TREND (Manual Entry)
A31: Assessment Date | B31: Overall % | C31: Compliant | D31: Gaps | E31: Assessor | F31: Notes

Sheet Equipment Class for Prot
A1: Equipment Class for Prot — Compliance Checklist
A2: ISO/IEC 27001:2022 — Controls A.7.8-9: Equipment Siting and Protection
A3: Req # | B3: Section | C3: Requirement | D3: Status | E3: Evidence | F3: Owner | G3: Due Date | H3: Notes
A4: A.7.8-9-01 | B4: Be Classified Into Protection Categories | C4: Equipment shall be classified into protection categories to determine appropriate siting requirements and off-premises protection levels:.
A5: A.7.8-9-02 | B5: Category Assignment | C5: Category assignment shall be recorded in [Asset Management System] or [CMDB] as part of asset registration.

Sheet Equipment Siting Requirements
A1: Equipment Siting Requirements — Compliance Checklist
A2: ISO/IEC 27001:2022 — Controls A.7.8-9: Equipment Siting and Protection
A3: Req # | B3: Section | C3: Requirement | D3: Status | E3: Evidence | F3: Owner | G3: Due Date | H3: Notes
A4: A.7.8-9-03 | B4: Equipment Processing Or Storing | C4: Equipment processing or storing information shall be sited to reduce risks from physical and environmental threats, unauthorised access, and damage.
A5: A.7.8-9-04 | B5: Be Placed In Areas With Controlled | C5: Equipment shall be placed in areas with controlled physical access, appropriate to the classification of information it processes.
A6: A.7.8-9-05 | B6: Critical Equipment (Servers, Network | C6: Critical equipment (servers, network infrastructure, storage systems) shall be located in dedicated, access-controlled rooms — not in general office areas, reception zones, or publicly accessible spaces.
A7: A.7.8-9-06 | B7: Be Positioned To Minimise Risk Of | C7: Equipment shall be positioned to minimise risk of overlooking (shoulder surfing). Screens displaying sensitive or confidential information shall be positioned away from windows, corridors, and high-traffic areas.
A8: A.7.8-9-07 | B8: Information Processing Facilities | C8: Information processing facilities handling classified data should be positioned carefully so that unauthorised persons cannot view information displayed on screens during use. Where repositioning is not feasible, privacy screens shall be used.
A9: A.7.8-9-08 | B9: Organisation-Managed Equipment | C9: Organisation-managed equipment shall be clearly segregated from equipment not under organisational control (e.g., personal devices, visitor equipment, shared-tenancy infrastructure).
A10: A.7.8-9-09 | B10: Storage Facilities (Server Racks, | C10: Storage facilities (server racks, storage cabinets, safe rooms) shall be secured to prevent unauthorised access.
A11: A.7.8-9-10 | B11: Be Protected From Temperature Extremes, | C11: Equipment shall be protected from temperature extremes, humidity, dust, vibration, and corrosive atmospheres. Acceptable environmental conditions for equipment operation shall be defined based on manufacturer specifications.
A12: A.7.8-9-11 | B12: Adequate Ventilation And Cooling | C12: Adequate ventilation and cooling shall be provided for equipment rooms. Server rooms and datacentres shall maintain temperature within 18-27 degrees C and humidity within 20-80% relative humidity, consistent with ASHRAE thermal guidelines.
A13: A.7.8-9-12 | B13: Be Elevated Or Protected Where Flood | C13: Equipment shall be elevated or protected where flood risk exists (e.g., raised floors, ground-level barriers, avoidance of basement locations in flood-prone areas).
A14: A.7.8-9-13 | B14: Smoking, Eating, And Drinking | C14: Smoking, eating, and drinking shall be prohibited in server rooms, datacentres, and equipment closets. Guidelines for eating and drinking near workstations shall be communicated to all personnel.
A15: A.7.8-9-14 | B15: Environmental Conditions That May | C15: Environmental conditions that may disrupt operations (temperature, humidity, airborne particulates) shall be continuously monitored in rooms housing Category A (critical infrastructure) equipment, with automated alerting within 15 minutes when thresholds are exceeded. For rooms housing Category B equipment, continuous monitoring should be implemented where technically feasible.
... A39: A.7.8-9-38 | B39: Equipment Processing Classified | C39: Equipment processing classified information in exposed locations shall be protected against information leakage due to electromagnetic emanation, where risk assessment warrants it.

Sheet Security of Assets Off-Premises
A1: Security of Assets Off-Premises — Compliance Checklist
A2: ISO/IEC 27001:2022 — Controls A.7.8-9: Equipment Siting and Protection
A3: Req # | B3: Section | C3: Requirement | D3: Status | E3: Evidence | F3: Owner | G3: Due Date | H3: Notes
A4: A.7.8-9-39 | B4: Off-Site Assets | C4: Off-site assets shall be protected to prevent loss, damage, theft, or compromise of devices and to prevent interruption to the organisation's information processing activities.
A5: A.7.8-9-40 | B5: Removal Of Equipment From Organisational | C5: Removal of equipment from organisational premises shall be authorised by the appropriate line manager prior to removal.
A6: A.7.8-9-41 | B6: Authorisation Records | C6: Authorisation records shall document: equipment details (asset tag, serial number, type), purpose of removal, responsible person, expected return date, and any special handling requirements.
A7: A.7.8-9-42 | B7: High-Value Equipment (Value Exceeding | C7: High-value equipment (value exceeding [CHF threshold]) or equipment containing classified data shall require additional approval from [IT Operations Manager] or equivalent.
A8: A.7.8-9-43 | B8: Bulk Equipment Moves (E.G., Office | C8: Bulk equipment moves (e.g., office relocation, project deployment) shall be authorised through a formal equipment movement request.
A9: A.7.8-9-44 | B9: Equipment Removed From Premises | C9: Equipment removed from premises shall be logged in [Asset Management System] or [CMDB] with current location, custodian, and expected return date.
A10: A.7.8-9-45 | B10: Chain Of Custody | C10: Chain of custody shall be maintained when equipment transfers between individuals. Transfer records shall include both the releasing and receiving party, date, and equipment condition.
A11: A.7.8-9-46 | B11: Return Of Equipment | C11: Return of equipment shall be verified and recorded. Equipment shall be inspected upon return for damage, tampering, or missing components.
A12: A.7.8-9-47 | B12: Equipment Not Returned By The Expected | C12: Equipment not returned by the expected date shall trigger follow-up by the asset owner. Equipment overdue by more than 30 days shall be escalated to the line manager and IT Operations.
A13: A.7.8-9-48 | B13: Not Be Left Unattended In Public | C13: Equipment shall not be left unattended in public places (airports, cafes, conference venues, public transport, vehicles).
A14: A.7.8-9-49 | B14: Be Carried In Unmarked, Nondescript Bags | C14: Equipment shall be carried in unmarked, nondescript bags during transport — not in manufacturer-branded bags or cases that advertise high-value contents.
A15: A.7.8-9-50 | B15: Be Secured In Hotel Safes (Noting | C15: When not in active use, equipment shall be secured in hotel safes (noting size limitations — laptops may not fit standard hotel safes), locked storage, or other secured areas. Where hotel safe capacity is insufficient, equipment shall be kept in locked luggage or the employee shall take equipment with them. Equipment shall not be left visible in hotel rooms.
... A46: A.7.8-9-81 | B46: Lost Or Stolen Equipment During Travel | C46: Lost or stolen equipment during travel shall be reported immediately to IT Operations (for remote wipe initiation) and to the local police. The employee shall document the circumstances and report through the incident management process upon return.

Sheet Incident Classification
A1: Incident Classification — Compliance Checklist
A2: ISO/IEC 27001:2022 — Controls A.7.8-9: Equipment Siting and Protection
A3: Req # | B3: Section | C3: Requirement | D3: Status | E3: Evidence | F3: Owner | G3: Due Date | H3: Notes
A4: A.7.8-9-82 | B4: Equipment-Related Security Events | C4: Equipment-related security events shall be classified and responded to based on severity:.
A5: A.7.8-9-83 | B5: Equipment Security Incidents | C5: Equipment security incidents shall be reported and managed through the organisation's incident management process (A.5.24-28).

Sheet Compliance Measurement
A1: Compliance Measurement — Compliance Checklist
A2: ISO/IEC 27001:2022 — Controls A.7.8-9: Equipment Siting and Protection
A3: Req # | B3: Section | C3: Requirement | D3: Status | E3: Evidence | F3: Owner | G3: Due Date | H3: Notes
A4: A.7.8-9-84 | B4: Be Assessed Using The Following Metrics | C4: Compliance shall be assessed using the following metrics:.
