Workbook

Sheet Instructions & Legend
A1: ISMS-IMP-A.5.35-36.S2 - Compliance Assessment ISO/IEC 27001:2022 - Control A.5.36: Compliance with Policies, Rules and Standards
A3: Document Information
A4: Document ID | B4: ISMS-IMP-A.5.35-36.S2
A5: Workbook Title | B5: Compliance Assessment
A6: Control Reference | B6: ISO/IEC 27001:2022 - Control A.5.36: Compliance with Policies, Rules and Standards
A7: Version | B7: 1.0
A8: Assessment Date
A9: Completed By
A10: Organisation
A12: Instructions
A13: 1. Complete Policy Compliance — assess compliance with all information security policies.
A14: 2. Complete Control Compliance — evaluate implementation status of all applicable controls.
A15: 3. Complete Department Assessment — assess compliance across all organisational units.
A16: 4. Complete NonCompliance Register — document all non-compliance findings with root causes.
A17: 5. Review the Summary Dashboard for overall compliance posture.
A18: 6. Maintain Evidence Records with assessment results and supporting documentation.
A19: 7. Obtain final approval and sign-off in the Approval Sign-Off sheet.
A21: Status Legend
A22: Symbol | B22: Status | C22: Description
A23: ✓ | B23: Compliant / Complete | C23: Requirement fully met
A24: ⚠ | B24: Partial / In Progress | C24: Partially met or in progress
A25: ✗ | B25: Non-Compliant / Not Started | C25: Requirement not met
A26: — | B26: Not Applicable | C26: Not applicable to this assessment

Sheet Policy Compliance
A1: POLICY COMPLIANCE ASSESSMENT
A2: Assess each information security policy for compliance — record version, compliance status, assessor, evidence references, and any remediation required.
A3: Policy ID | B3: Policy Name | C3: Policy Version | D3: Compliance Status | E3: Last Reviewed | F3: Assessed By | G3: Assessment Date | H3: Evidence Ref | I3: NonCompliance Issues | J3: Remediation Status | K3: Notes
A4: ISMS-POL-A.5.1-4 | B4: Information Security Governance Policy | C4: v2.1 | D4: Compliant | E4: 01.01.2026 | F4: CISO | G4: 15.02.2026 | H4: EV-001 | J4: N/A | K4: Policy reviewed and approved for 2026

Sheet Control Compliance
A1: CONTROL COMPLIANCE STATUS
A2: Record implementation status for each ISO 27001:2022 Annex A control — track compliance status, implementation percentage, and identified gaps.
A3: Control ID | B3: Control Name | C3: Control Category | D3: Compliance Status | E3: Implementation % | F3: Last Assessed | G3: Assessed By | H3: Evidence Ref | I3: Gaps Identified | J3: Notes
A4: A.5.1 | B4: Policies for information security | C4: Organisational | D4: Fully Implemented | E4: 100% | F4: 15.02.2026 | G4: CISO | H4: EV-010 | I4: None | J4: Policy suite reviewed and approved

Sheet Department Assessment
A1: DEPARTMENT SELF-ASSESSMENT
A2: Department managers self-assess compliance with IS requirements — rate each area and provide an overall Green/Amber/Red compliance rating.
A3: Department | B3: Manager | C3: Assessment Period | D3: AUP Compliance | E3: Access Control Compliance | F3: Incident Reporting Compliance | G3: Training Compliance | H3: Asset Management Compliance | I3: Overall Rating | J3: Issues Identified | K3: Improvement Actions | L3: Sign Off Date
A4: IT Operations | B4: A. Johnson | C4: Q1 2026 | D4: Compliant | E4: Compliant | F4: Compliant | G4: Partial | H4: Compliant | I4: Green | J4: Training programme 60% complete — target Q2 2026 | K4: Complete security awareness training by 30.06.2026 | L4: 28.02.2026

Sheet NonCompliance Register
A1: NON-COMPLIANCE REGISTER
A2: Register all non-compliance findings — assign severity, remediation actions, owners, and target dates; track status through to closure.
A3: NC ID | B3: Identified Date | C3: Policy Control Ref | D3: Department | E3: NC Description | F3: Root Cause | G3: Severity | H3: Remediation Action | I3: Owner | J3: Target Date | K3: Status | L3: Closure Date
A4: NC-001 | B4: 10.02.2026 | C4: ISMS-POL-A.5.15-18 | D4: IT Operations | E4: MFA not enforced for all privileged accounts | F4: Policy not updated following cloud migration | G4: High | H4: Enable MFA for all admin accounts in Azure AD | I4: IT Operations Manager | J4: 31.03.2026 | K4: In Progress

Sheet Evidence Register
A1: EVIDENCE REGISTER
A2: Record all evidence collected during compliance assessments — link each item to an assessment, specify type, storage location, and validity period.
A4: Evidence ID | B4: Evidence Type | C4: Description | D4: Related Assessment | E4: Collection Date | F4: Location | G4: Collected By | H4: Valid Until
A5: EV-001 | B5: Policy Document | C5: Information Security Governance Policy v2.1 | D5: Policy Compliance | E5: 15.02.2026 | F5: //sharepoint/isms/policies/is-governance-policy-v2.1.pdf | G5: CISO | H5: 31.12.2028

Sheet Summary Dashboard
A1: COMPLIANCE ASSESSMENT — SUMMARY DASHBOARD
A2: ISO/IEC 27001:2022 | Control A.5.36: Compliance with Policies, Rules and Standards
A4: TABLE 1: ASSESSMENT AREA COMPLIANCE OVERVIEW
A5: Assessment Area | B5: Total Items | C5: Compliant | D5: Partial | E5: Non-Compliant | F5: N/A | G5: Compliance %
A6: Policy Compliance | B6: =COUNTA('Policy Compliance'!B5:B54) | C6: =COUNTIF('Policy Compliance'!D5:D54,"Compliant") | D6: =COUNTIF('Policy Compliance'!D5:D54,"Partial") | E6: =COUNTIF('Policy Compliance'!D5:D54,"Non-Compliant") | F6: =COUNTIF('Policy Compliance'!D5:D54,"Not Applicable")+COUNTIF('Policy Compliance'!D5:D54,"Not Assessed") | G6: =IFERROR(IF((B6-F6)=0,0,C6/(B6-F6)),"")
A7: Control Implementation | B7: =COUNTA('Control Compliance'!B5:B54) | C7: =COUNTIF('Control Compliance'!D5:D54,"Fully Implemented") | D7: =COUNTIF('Control Compliance'!D5:D54,"Partially Implemented") | E7: =COUNTIF('Control Compliance'!D5:D54,"Not Implemented") | F7: =COUNTIF('Control Compliance'!D5:D54,"Not Applicable") | G7: =IFERROR(IF((B7-F7)=0,0,C7/(B7-F7)),"")
A8: Departmental Compliance | B8: =COUNTA('Department Assessment'!A5:A54) | C8: =COUNTIF('Department Assessment'!I5:I54,"Green") | D8: =COUNTIF('Department Assessment'!I5:I54,"Amber") | E8: =COUNTIF('Department Assessment'!I5:I54,"Red") | F8: =0 | G8: =IFERROR(IF((B8-F8)=0,0,C8/(B8-F8)),"")
A9: Non-Compliance Management | B9: =COUNTA('NonCompliance Register'!B5:B104) | C9: =COUNTIF('NonCompliance Register'!K5:K104,"Closed") | D9: =COUNTIF('NonCompliance Register'!K5:K104,"In Progress")+COUNTIF('NonCompliance Register'!K5:K104,"Pending Verification") | E9: =COUNTIF('NonCompliance Register'!K5:K104,"Open") | F9: =COUNTIF('NonCompliance Register'!K5:K104,"Risk Accepted") | G9: =IFERROR(IF((B9-F9)=0,0,C9/(B9-F9)),"")
A10: TOTAL | B10: =SUM(B6:B9) | C10: =SUM(C6:C9) | D10: =SUM(D6:D9) | E10: =SUM(E6:E9) | F10: =SUM(F6:F9) | G10: =IFERROR(IF((B10-F10)=0,0,C10/(B10-F10)),"")
A12: TABLE 2: KEY METRICS
A13: Metric | B13: Value
A14: Total Policies Assessed | B14: =COUNTA('Policy Compliance'!B5:B54)
A15: Policies Compliant | B15: =COUNTIF('Policy Compliance'!D5:D54,"Compliant")
A16: Policies Partially Compliant | B16: =COUNTIF('Policy Compliance'!D5:D54,"Partial")
A17: Policies Non-Compliant | B17: =COUNTIF('Policy Compliance'!D5:D54,"Non-Compliant")
A18: Policies Not Yet Assessed | B18: =COUNTIF('Policy Compliance'!D5:D54,"Not Assessed")
A19: Controls Fully Implemented | B19: =COUNTIF('Control Compliance'!D5:D54,"Fully Implemented")
A20: Controls Partially Implemented | B20: =COUNTIF('Control Compliance'!D5:D54,"Partially Implemented")
A21: Controls Not Implemented | B21: =COUNTIF('Control Compliance'!D5:D54,"Not Implemented")
A22: Total Departments Assessed | B22: =COUNTA('Department Assessment'!A5:A54)
A23: Departments Rated Green (Compliant) | B23: =COUNTIF('Department Assessment'!I5:I54,"Green")
A24: Departments Rated Amber (Partial) | B24: =COUNTIF('Department Assessment'!I5:I54,"Amber")
A25: Departments Rated Red (Non-Compliant) | B25: =COUNTIF('Department Assessment'!I5:I54,"Red")
A26: Total Non-Conformances | B26: =COUNTA('NonCompliance Register'!B5:B104)
A27: Critical Non-Conformances Open | B27: =COUNTIFS('NonCompliance Register'!G5:G104,"Critical",'NonCompliance Register'!K5:K104,"Open")
A28: High Severity NCs Open | B28: =COUNTIFS('NonCompliance Register'!G5:G104,"High",'NonCompliance Register'!K5:K104,"Open")
A29: NCs Closed (Remediated) | B29: =COUNTIF('NonCompliance Register'!K5:K104,"Closed")
A30: AUP Compliance — Compliant Departments | B30: =COUNTIF('Department Assessment'!D5:D54,"Compliant")
A31: Access Control Compliance — Compliant Depts | B31: =COUNTIF('Department Assessment'!E5:E54,"Compliant")
A32: Training Compliance — Compliant Departments | B32: =COUNTIF('Department Assessment'!G5:G54,"Compliant")
A33: Incident Reporting Compliance — Compliant Depts | B33: =COUNTIF('Department Assessment'!F5:F54,"Compliant")
A37: TABLE 3: CRITICAL FINDINGS REQUIRING IMMEDIATE ATTENTION
A38: Category | B38: Finding | C38: Count | D38: Severity | E38: Action Required
A39: Policy Compliance | B39: Non-compliant policies | C39: =COUNTIF('Policy Compliance'!D5:D54,"Non-Compliant") | D39: Critical | E39: Immediate policy review
A40: Policy Compliance | B40: Policies not yet assessed | C40: =COUNTIF('Policy Compliance'!D5:D54,"Not Assessed") | D40: High | E40: Schedule assessment
A41: Control Implementation | B41: Controls not implemented | C41: =COUNTIF('Control Compliance'!D5:D54,"Not Implemented") | D41: Critical | E41: Risk acceptance or implement
A42: Departmental Compliance | B42: Departments rated Red | C42: =COUNTIF('Department Assessment'!I5:I54,"Red") | D42: Critical | E42: Management intervention
A43: Non-Compliance | B43: Critical NCs open | C43: =COUNTIFS('NonCompliance Register'!G5:G104,"Critical",'NonCompliance Register'!K5:K104,"Open") | D43: Critical | E43: Immediate corrective action
A44: Non-Compliance | B44: High severity NCs open | C44: =COUNTIFS('NonCompliance Register'!G5:G104,"High",'NonCompliance Register'!K5:K104,"Open") | D44: High | E44: Assign owner and date
A45: Access Control | B45: AUP non-compliance by departments | C45: =COUNTIF('Department Assessment'!D5:D54,"Non-Compliant") | D45: High | E45: Enforce AUP compliance
...

Sheet Approval Sign-Off
A1: ASSESSMENT APPROVAL AND SIGN-OFF
A2: ISO/IEC 27001:2022 - Control A.5.36: Compliance with Policies, Rules and Standards
A3: ASSESSMENT SUMMARY
A4: Document: | B4: ISMS-IMP-A.5.35-36.S2 - Compliance Assessment
A5: Assessment Period:
A6: Overall Compliance Rating: | B6: =IFERROR(AVERAGE('Summary Dashboard'!G6:G9),"")
A7: Assessment Status:
A8: Assessed By:
A11: COMPLETED BY (ASSESSOR)
A12: Name:
A13: Title:
A14: Date:
A15: Signature:
A16: Comments:
A18: REVIEWED BY (INFORMATION SECURITY OFFICER)
A19: Name:
A20: Title:
A21: Date:
... A38: Special Considerations:
