Workbook

Sheet Instructions & Legend
A1: ISMS-IMP-A.5.35-36.S3 - Findings and Remediation Management ISO/IEC 27001:2022 - Control A.5.35-36: Compliance & Review
A3: Document Information
A4: Document ID | B4: ISMS-IMP-A.5.35-36.S3
A5: Workbook Title | B5: Findings and Remediation Management
A6: Control Reference | B6: ISO/IEC 27001:2022 - Control A.5.35-36: Compliance & Review
A7: Version | B7: 1.0
A8: Assessment Date
A9: Completed By
A10: Organisation
A12: Instructions
A13: 1. Complete Findings Register — log all compliance findings with severity, source, and date.
A14: 2. Complete Remediation Actions — assign owners, resources, and target dates to each finding.
A15: 3. Complete Root Cause Analysis — identify systemic causes to prevent recurrence.
A16: 4. Complete Verification Log — record evidence that each remediation action is completed.
A17: 5. Review Trend Analysis — identify recurring finding types requiring systemic improvement.
A18: 6. Maintain Evidence Records with finding reports and remediation evidence.
A19: 7. Obtain final approval and sign-off in the Approval Sign-Off sheet.
A21: Status Legend
A22: Symbol | B22: Status | C22: Description
A23: ✓ | B23: Compliant / Complete | C23: Requirement fully met
A24: ⚠ | B24: Partial / In Progress | C24: Partially met or in progress
A25: ✗ | B25: Non-Compliant / Not Started | C25: Requirement not met
A26: — | B26: Not Applicable | C26: Not applicable to this assessment

Sheet Findings Register
A1: CONSOLIDATED FINDINGS REGISTER
A2: Consolidated register of all findings from independent reviews and compliance assessments — track severity, owner, and status through to closure.
A3: Finding ID | B3: Source | C3: Source Ref | D3: Finding Date | E3: Finding Type | F3: Severity | G3: Control Reference | H3: Finding Description | I3: Root Cause | J3: Recommendation | K3: Owner | L3: Target Date | M3: Status | N3: Days Open
A4: FND-001 | B4: Independent Review | C4: REV-2026-001 | D4: 15.03.2026 | E4: Non-Conformity | F4: Major | G4: A.5.15, A.8.5 | H4: MFA not enforced for privileged accounts in cloud environment | I4: Policy gap — MFA policy not updated following cloud migration | J4: Enforce MFA for all admin accounts in Azure AD within 30 days | K4: IT Operations Manager | L4: 14.04.2026 | M4: In Progress
N5: =IF(AND(D5<>"",M5<>"Closed"),TODAY()-D5,"")
N6: =IF(AND(D6<>"",M6<>"Closed"),TODAY()-D6,"")
N7: =IF(AND(D7<>"",M7<>"Closed"),TODAY()-D7,"")
N8: =IF(AND(D8<>"",M8<>"Closed"),TODAY()-D8,"")
N9: =IF(AND(D9<>"",M9<>"Closed"),TODAY()-D9,"")
N10: =IF(AND(D10<>"",M10<>"Closed"),TODAY()-D10,"")
N11: =IF(AND(D11<>"",M11<>"Closed"),TODAY()-D11,"")
N12: =IF(AND(D12<>"",M12<>"Closed"),TODAY()-D12,"")
N13: =IF(AND(D13<>"",M13<>"Closed"),TODAY()-D13,"")
N14: =IF(AND(D14<>"",M14<>"Closed"),TODAY()-D14,"")
N15: =IF(AND(D15<>"",M15<>"Closed"),TODAY()-D15,"")
N16: =IF(AND(D16<>"",M16<>"Closed"),TODAY()-D16,"")
... N54: =IF(AND(D54<>"",M54<>"Closed"),TODAY()-D54,"")

Sheet Remediation Actions
A1: REMEDIATION ACTION TRACKER
A2: Track corrective and preventive actions arising from findings — assign action type, owner, target dates, and track completion through verification.
A3: Action ID | B3: Finding Ref | C3: Action Description | D3: Action Type | E3: Owner | F3: Start Date | G3: Target Date | H3: Actual Date | I3: Status | J3: % Complete | K3: Verification Method | L3: Notes
A4: ACT-001 | B4: FND-001 | C4: Enable MFA for all privileged accounts in Azure AD | D4: Corrective Action | E4: IT Operations Manager | F4: 16.03.2026 | G4: 14.04.2026 | I4: In Progress | J4: 40% | K4: System check — Azure AD MFA report | L4: Phase 1 complete: admin accounts done; user accounts in progress

Sheet Root Cause Analysis
A1: ROOT CAUSE ANALYSIS
A2: Document root cause analysis for significant findings — identify whether issues are systemic and define preventive actions to avoid recurrence.
A3: RCA ID | B3: Finding Ref | C3: Problem Statement | D3: Analysis Method | E3: Root Cause Category | F3: Root Cause Description | G3: Contributing Factors | H3: Systemic Issue | I3: Preventive Actions | J3: Analyst | K3: Analysis Date
A4: RCA-001 | B4: FND-001 | C4: MFA not enforced for privileged accounts following cloud migration | D4: 5 Whys | E4: Process | F4: MFA policy was not updated when infrastructure migrated to Azure — process gap in change management | G4: Lack of IS review gate in cloud migration project | H4: Yes | I4: Add IS review gate to all infrastructure change projects | J4: CISO | K4: 18.03.2026

Sheet Verification Log
A1: VERIFICATION LOG
A2: Verify that remediation actions are effective — document verification method, evidence reviewed, outcome, and closure recommendation for each finding.
A3: Verification ID | B3: Finding Ref | C3: Action Ref | D3: Verification Date | E3: Verifier | F3: Verification Method | G3: Evidence Reviewed | H3: Verification Result | I3: Closure Recommendation | J3: Follow Up Required | K3: Notes
A4: VER-001 | B4: FND-001 | C4: ACT-001 | D4: 20.04.2026 | E4: CISO | F4: System Check | G4: Azure AD MFA enforcement report — all admins | H4: Effective | I4: Close | J4: No | K4: MFA confirmed active for all 45 privileged accounts — finding closed

Sheet Trend Analysis
A1: FINDINGS TREND ANALYSIS
A2: Track findings volume and closure rates across review periods — monitor trends to identify systemic issues and measure improvement over time.
A3: Period | B3: Major NCs | C3: Minor NCs | D3: Observations | E3: Total Findings | F3: Closed This Period | G3: Open at Period End | H3: Avg Days to Close | I3: Repeat Findings | J3: Notes
A4: Q1 2026 | B4: 2 | C4: 5 | D4: 8 | E4: =SUM(B4:D4) | F4: 10 | G4: 12 | H4: 18 | I4: 1 | J4: Post-certification audit period
A5: Q2 2026 | E5: =SUM(B5:D5)
A6: Q3 2026 | E6: =SUM(B6:D6)
A7: Q4 2026 | E7: =SUM(B7:D7)
A8: Q1 2027 | E8: =SUM(B8:D8)
A9: Q2 2027 | E9: =SUM(B9:D9)
A10: Q3 2027 | E10: =SUM(B10:D10)
A11: Q4 2027 | E11: =SUM(B11:D11)
A12: Q1 2028 | E12: =SUM(B12:D12)

Sheet Evidence Register
A1: EVIDENCE REGISTER
A2: Store references to all audit evidence collected during independent reviews and compliance assessments — maintain location, custodian, and retention details.
A4: Evidence ID | B4: Evidence Type | C4: Description | D4: Related Finding | E4: Collection Date | F4: Location | G4: Collected By | H4: Retention Until
A5: EV-001 | B5: Finding Report | C5: Independent review report — MFA non-conformity (FND-001) | D5: FND-001 | E5: 15.03.2026 | F5: /SharePoint/ISMS/Reviews/2026/Q1/FND-001-Report.pdf | G5: CISO | H5: 15.03.2029

Sheet Summary Dashboard
A1: FINDINGS AND REMEDIATION MANAGEMENT — SUMMARY DASHBOARD
A2: ISO/IEC 27001:2022 | Controls A.5.35-36: Independent Review and Compliance
A4: TABLE 1: COMPLIANCE STATUS OVERVIEW
A5: Assessment Area | B5: Total Items | C5: Compliant | D5: Partial | E5: Non-Compliant | F5: N/A | G5: Compliance %
A6: Findings Management | B6: =COUNTA('Findings Register'!B5:B54) | C6: =COUNTIF('Findings Register'!M5:M54,"Closed") | D6: =COUNTIF('Findings Register'!M5:M54,"In Progress")+COUNTIF('Findings Register'!M5:M54,"Pending Verification") | E6: =COUNTIF('Findings Register'!M5:M54,"Open") | F6: =COUNTIF('Findings Register'!M5:M54,"Risk Accepted") | G6: =IFERROR(IF((B6-F6)=0,0,C6/(B6-F6)),"")
A7: Remediation Actions | B7: =COUNTA('Remediation Actions'!B5:B54) | C7: =COUNTIF('Remediation Actions'!I5:I54,"Completed") | D7: =COUNTIF('Remediation Actions'!I5:I54,"In Progress") | E7: =COUNTIF('Remediation Actions'!I5:I54,"Not Started")+COUNTIF('Remediation Actions'!I5:I54,"On Hold") | F7: =COUNTIF('Remediation Actions'!I5:I54,"Cancelled") | G7: =IFERROR(IF((B7-F7)=0,0,C7/(B7-F7)),"")
A8: Root Cause Analysis | B8: =COUNTA('Root Cause Analysis'!B5:B54) | C8: =COUNTIF('Root Cause Analysis'!H5:H54,"No") | D8: 0 | E8: =COUNTIF('Root Cause Analysis'!H5:H54,"Yes") | F8: 0 | G8: =IFERROR(IF((B8-F8)=0,0,C8/(B8-F8)),"")
A9: Effectiveness Verification | B9: =COUNTA('Verification Log'!B5:B54) | C9: =COUNTIF('Verification Log'!H5:H54,"Effective") | D9: =COUNTIF('Verification Log'!H5:H54,"Partially Effective") | E9: =COUNTIF('Verification Log'!H5:H54,"Not Effective") | F9: 0 | G9: =IFERROR(IF((B9-F9)=0,0,C9/(B9-F9)),"")
A10: TOTAL | B10: =SUM(B6:B9) | C10: =SUM(C6:C9) | D10: =SUM(D6:D9) | E10: =SUM(E6:E9) | F10: =SUM(F6:F9) | G10: =IFERROR(IF((B10-F10)=0,0,C10/(B10-F10)),"")
A12: TABLE 2: KEY METRICS
A13: Metric | B13: Value
A14: Total Findings Registered | B14: =COUNTA('Findings Register'!B5:B54)
A15: Major Non-Conformities | B15: =COUNTIF('Findings Register'!F5:F54,"Major")
A16: Minor Non-Conformities | B16: =COUNTIF('Findings Register'!F5:F54,"Minor")
A17: Observations | B17: =COUNTIF('Findings Register'!E5:E54,"Observation")
A18: Open Findings | B18: =COUNTIF('Findings Register'!M5:M54,"Open")
A19: Findings from Independent Reviews | B19: =COUNTIF('Findings Register'!B5:B54,"Independent Review")
A20: Findings from Compliance Assessment | B20: =COUNTIF('Findings Register'!B5:B54,"Compliance Assessment")
A21: Total Remediation Actions | B21: =COUNTA('Remediation Actions'!B5:B54)
A22: Actions Completed | B22: =COUNTIF('Remediation Actions'!I5:I54,"Completed")
A23: Actions In Progress | B23: =COUNTIF('Remediation Actions'!I5:I54,"In Progress")
A24: Actions Not Started | B24: =COUNTIF('Remediation Actions'!I5:I54,"Not Started")
A25: Corrective Actions | B25: =COUNTIF('Remediation Actions'!D5:D54,"Corrective Action")
A26: Systemic Issues Identified (RCA) | B26: =COUNTIF('Root Cause Analysis'!H5:H54,"Yes")
A27: Process-Related Root Causes | B27: =COUNTIF('Root Cause Analysis'!E5:E54,"Process")
A28: People-Related Root Causes | B28: =COUNTIF('Root Cause Analysis'!E5:E54,"People")
A29: Technology-Related Root Causes | B29: =COUNTIF('Root Cause Analysis'!E5:E54,"Technology")
A30: Total Verifications | B30: =COUNTA('Verification Log'!B5:B54)
A31: Effective Verifications | B31: =COUNTIF('Verification Log'!H5:H54,"Effective")
A32: Not Effective Verifications | B32: =COUNTIF('Verification Log'!H5:H54,"Not Effective")
A33: Re-Work Required | B33: =COUNTIF('Verification Log'!I5:I54,"Re-work Required")
A37: TABLE 3: CRITICAL FINDINGS REQUIRING IMMEDIATE ATTENTION
A38: Category | B38: Finding | C38: Count | D38: Severity | E38: Action Required
A39: Findings Management | B39: Major NCs open | C39: =COUNTIFS('Findings Register'!F5:F54,"Major",'Findings Register'!M5:M54,"Open") | D39: Critical | E39: Immediate escalation
A40: Findings Management | B40: All open findings | C40: =COUNTIF('Findings Register'!M5:M54,"Open") | D40: High | E40: Assign remediation owner
A41: Findings Management | B41: Findings pending verification >30 days | C41: =COUNTIF('Findings Register'!M5:M54,"Pending Verification") | D41: High | E41: Complete verification
A42: Remediation | B42: Actions not started | C42: =COUNTIF('Remediation Actions'!I5:I54,"Not Started") | D42: High | E42: Start immediately
A43: Remediation | B43: Actions on hold | C43: =COUNTIF('Remediation Actions'!I5:I54,"On Hold") | D43: Medium | E43: Review blockers
A44: Root Cause Analysis | B44: Systemic issues identified | C44: =COUNTIF('Root Cause Analysis'!H5:H54,"Yes") | D44: High | E44: Review prevention programme
A45: Effectiveness | B45: Verifications failed (Not Effective) | C45: =COUNTIF('Verification Log'!H5:H54,"Not Effective") | D45: Critical | E45: Re-work remediation
...

Sheet Approval Sign-Off
A1: ASSESSMENT APPROVAL AND SIGN-OFF
A2: ISO/IEC 27001:2022 - Control A.5.35-36: Compliance & Review
A3: ASSESSMENT SUMMARY
A4: Document: | B4: ISMS-IMP-A.5.35-36.S3 - Findings and Remediation Management
A5: Assessment Period:
A6: Overall Compliance Rating: | B6: =IFERROR(AVERAGE('Summary Dashboard'!G6:G9),"")
A7: Assessment Status:
A8: Assessed By:
A11: COMPLETED BY (ASSESSOR)
A12: Name:
A13: Title:
A14: Date:
A15: Signature:
A16: Comments:
A18: REVIEWED BY (INFORMATION SECURITY OFFICER)
A19: Name:
A20: Title:
A21: Date:
... A38: Special Considerations:
