Workbook

Sheet Executive Summary
A1: AI-CHK-A.6.1 — AI Development Governance Compliance Checklist
A3: DOCUMENT INFORMATION
A4: Document ID | B4: AI-CHK-A.6.1
A5: Source Policy | B5: AI-POL-A.6.1
A6: ISO Controls | B6: AI Development Governance
A7: Generated | B7: 15.04.2026
A8: Prepared By
A9: Organisation
A10: Review Cycle | B10: Annual
A12: OVERALL COMPLIANCE STATUS
A13: Overall Compliance | B13: ='Dashboard'!G9
A14: Status | B14: =IF(Dashboard!G9="N/A","NOT ASSESSED",IF(ISNUMBER(VALUE(SUBSTITUTE(Dashboard!G9,"%",""))),IF(VALUE(SUBSTITUTE(Dashboard!G9,"%",""))>=90,"GREEN",IF(VALUE(SUBSTITUTE(Dashboard!G9,"%",""))>=70,"AMBER","RED")),"NOT ASSESSED"))
A16: KEY METRICS
A17: Total Requirements | B17: ='Dashboard'!B9
A18: Compliant | B18: ='Dashboard'!C9
A19: Partial | B19: ='Dashboard'!D9
A20: Non-Compliant | B20: ='Dashboard'!E9
A21: Not Applicable | B21: ='Dashboard'!F9
A22: Owner Coverage | B22: =IF(Dashboard!B9=0,"N/A",ROUND((COUNTA('Responsible Design'!F4:F8)+COUNTA('Data Engineering for AI'!F4:F8)+COUNTA('Bias Assessment'!F4:F8)+COUNTA('Validation and Verification'!F4:F8)+COUNTA('Human Oversight in Development'!F4:F7))/Dashboard!B9*100,0)&"%")
A24: DOMAIN STATUS SUMMARY
A25: Domain | B25: Compliance % | C25: Compliant | D25: Gaps | E25: Status
A26: Responsible Design | B26: ='Dashboard'!G4 | C26: ='Dashboard'!C4 | D26: ='Dashboard'!E4 | E26: =IF(Dashboard!G4="N/A","--",IF(ISNUMBER(VALUE(SUBSTITUTE(Dashboard!G4,"%",""))),IF(VALUE(SUBSTITUTE(Dashboard!G4,"%",""))>=90,"PASS",IF(VALUE(SUBSTITUTE(Dashboard!G4,"%",""))>=70,"REVIEW","FAIL")),"--"))
A27: Data Engineering for AI | B27: ='Dashboard'!G5 | C27: ='Dashboard'!C5 | D27: ='Dashboard'!E5 | E27: =IF(Dashboard!G5="N/A","--",IF(ISNUMBER(VALUE(SUBSTITUTE(Dashboard!G5,"%",""))),IF(VALUE(SUBSTITUTE(Dashboard!G5,"%",""))>=90,"PASS",IF(VALUE(SUBSTITUTE(Dashboard!G5,"%",""))>=70,"REVIEW","FAIL")),"--"))
A28: Bias Assessment | B28: ='Dashboard'!G6 | C28: ='Dashboard'!C6 | D28: ='Dashboard'!E6 | E28: =IF(Dashboard!G6="N/A","--",IF(ISNUMBER(VALUE(SUBSTITUTE(Dashboard!G6,"%",""))),IF(VALUE(SUBSTITUTE(Dashboard!G6,"%",""))>=90,"PASS",IF(VALUE(SUBSTITUTE(Dashboard!G6,"%",""))>=70,"REVIEW","FAIL")),"--"))
A29: Validation and Verification | B29: ='Dashboard'!G7 | C29: ='Dashboard'!C7 | D29: ='Dashboard'!E7 | E29: =IF(Dashboard!G7="N/A","--",IF(ISNUMBER(VALUE(SUBSTITUTE(Dashboard!G7,"%",""))),IF(VALUE(SUBSTITUTE(Dashboard!G7,"%",""))>=90,"PASS",IF(VALUE(SUBSTITUTE(Dashboard!G7,"%",""))>=70,"REVIEW","FAIL")),"--"))
A30: Human Oversight in Development | B30: ='Dashboard'!G8 | C30: ='Dashboard'!C8 | D30: ='Dashboard'!E8 | E30: =IF(Dashboard!G8="N/A","--",IF(ISNUMBER(VALUE(SUBSTITUTE(Dashboard!G8,"%",""))),IF(VALUE(SUBSTITUTE(Dashboard!G8,"%",""))>=90,"PASS",IF(VALUE(SUBSTITUTE(Dashboard!G8,"%",""))>=70,"REVIEW","FAIL")),"--"))
A32: CRITICAL ISSUES
A33: # | B33: Issue Description | C33: Domain | D33: Owner | E33: Due Date
A34: 1
A35: 2
A36: 3
A37: 4
A38: 5
A40: MANAGEMENT COMMENTARY
A41: [Enter management commentary on ai development governance posture]
A45: APPROVAL
A46: Assessed By (AI System Owner)
A47: Name:
A48: Date:
A49: Signature:
...

Sheet Dashboard
A1: AI Development Governance — Compliance Dashboard
A3: Domain | B3: Total Reqs | C3: Compliant | D3: Partial | E3: Non-Compliant | F3: N/A | G3: Compliance %
A4: Responsible Design | B4: =COUNTA('Responsible Design'!D4:D8) | C4: =COUNTIF('Responsible Design'!D4:D8,"Compliant") | D4: =COUNTIF('Responsible Design'!D4:D8,"Partial") | E4: =COUNTIF('Responsible Design'!D4:D8,"Non-Compliant") | F4: =COUNTIF('Responsible Design'!D4:D8,"N/A") | G4: =IF((B4-F4)=0,"N/A",ROUND(C4/(B4-F4)*100,1)&"%")
A5: Data Engineering for AI | B5: =COUNTA('Data Engineering for AI'!D4:D8) | C5: =COUNTIF('Data Engineering for AI'!D4:D8,"Compliant") | D5: =COUNTIF('Data Engineering for AI'!D4:D8,"Partial") | E5: =COUNTIF('Data Engineering for AI'!D4:D8,"Non-Compliant") | F5: =COUNTIF('Data Engineering for AI'!D4:D8,"N/A") | G5: =IF((B5-F5)=0,"N/A",ROUND(C5/(B5-F5)*100,1)&"%")
A6: Bias Assessment | B6: =COUNTA('Bias Assessment'!D4:D8) | C6: =COUNTIF('Bias Assessment'!D4:D8,"Compliant") | D6: =COUNTIF('Bias Assessment'!D4:D8,"Partial") | E6: =COUNTIF('Bias Assessment'!D4:D8,"Non-Compliant") | F6: =COUNTIF('Bias Assessment'!D4:D8,"N/A") | G6: =IF((B6-F6)=0,"N/A",ROUND(C6/(B6-F6)*100,1)&"%")
A7: Validation and Verification | B7: =COUNTA('Validation and Verification'!D4:D8) | C7: =COUNTIF('Validation and Verification'!D4:D8,"Compliant") | D7: =COUNTIF('Validation and Verification'!D4:D8,"Partial") | E7: =COUNTIF('Validation and Verification'!D4:D8,"Non-Compliant") | F7: =COUNTIF('Validation and Verification'!D4:D8,"N/A") | G7: =IF((B7-F7)=0,"N/A",ROUND(C7/(B7-F7)*100,1)&"%")
A8: Human Oversight in Development | B8: =COUNTA('Human Oversight in Development'!D4:D7) | C8: =COUNTIF('Human Oversight in Development'!D4:D7,"Compliant") | D8: =COUNTIF('Human Oversight in Development'!D4:D7,"Partial") | E8: =COUNTIF('Human Oversight in Development'!D4:D7,"Non-Compliant") | F8: =COUNTIF('Human Oversight in Development'!D4:D7,"N/A") | G8: =IF((B8-F8)=0,"N/A",ROUND(C8/(B8-F8)*100,1)&"%")
A9: TOTAL | B9: =SUM(B4:B8) | C9: =SUM(C4:C8) | D9: =SUM(D4:D8) | E9: =SUM(E4:E8) | F9: =SUM(F4:F8) | G9: =IF((B9-F9)=0,"N/A",ROUND(C9/(B9-F9)*100,1)&"%")
A11: COMPLIANCE BY STATUS
A12: Compliant | B12: =C9 | C12: =IF(B9=0,"",ROUND(B12/B9*100,1)&"%")
A13: Partial | B13: =D9 | C13: =IF(B9=0,"",ROUND(B13/B9*100,1)&"%")
A14: Non-Compliant | B14: =E9 | C14: =IF(B9=0,"",ROUND(B14/B9*100,1)&"%")
A15: N/A | B15: =F9 | C15: =IF(B9=0,"",ROUND(B15/B9*100,1)&"%")
A17: TOP GAPS (Manual Entry)
A18: Priority | B18: Domain | C18: Requirement | D18: Owner | E18: Due Date | F18: Status
A30: COMPLIANCE TREND (Manual Entry)
A31: Assessment Date | B31: Overall % | C31: Compliant | D31: Gaps | E31: Assessor | F31: Notes

Sheet Responsible Design
A1: Responsible Design — Compliance Checklist
A2: ISO/IEC 42001:2023 — Controls A.6.1: AI Development Governance
A3: Req # | B3: Section | C3: Requirement | D3: Status | E3: Evidence | F3: Owner | G3: Due Date | H3: Notes
A4: A.6.1.1-01 | B4: AISIA as Design Input | C4: The AI System Impact Assessment (AISIA) shall be completed or initiated before or during the design phase and shall serve as a formal input to design decisions. Designers shall document how AISIA findings have influenced system design.
A5: A.6.1.1-02 | B5: Responsible Design Review | C5: Before design is finalised, the AI System Owner shall conduct a responsible design review addressing: intended use scope, use-case restrictions, human oversight mechanism design, transparency to end users, and explainability requirements proportionate to impact classification.
A6: A.6.1.1-03 | B6: Explainability by Design | C6: For AI systems classified as Medium or High impact, the design shall incorporate an explainability mechanism enabling human reviewers to understand the basis for individual AI outputs. The mechanism shall be documented in the system architecture.
A7: A.6.1.1-04 | B7: Prohibited Design Patterns | C7: The organisation shall document and enforce a list of prohibited design patterns — including systems designed to be deceptive to users, systems that exploit cognitive biases, and systems implementing subliminal manipulation.
A8: A.6.1.1-05 | B8: Design Documentation | C8: The design phase shall produce a system specification document covering intended use, use restrictions, input and output definitions, human oversight design, and references to the AISIA and applicable fairness requirements.

Sheet Data Engineering for AI
A1: Data Engineering for AI — Compliance Checklist
A2: ISO/IEC 42001:2023 — Controls A.6.1: AI Development Governance
A3: Req # | B3: Section | C3: Requirement | D3: Status | E3: Evidence | F3: Owner | G3: Due Date | H3: Notes
A4: A.6.1.2-01 | B4: Data Governance Gate | C4: No AI system shall enter the model development phase until all training datasets have passed the data quality gate defined in AI-POL-A.7.2-6 and have documented Data Quality Records on file.
A5: A.6.1.2-02 | B5: Personal Data Controls | C5: Where training data contains personal data, the development team shall confirm a documented legal basis before use, apply data minimisation techniques, and ensure that the Data Acquisition Record references the legal basis and data governance controls applied.
A6: A.6.1.2-03 | B6: Prohibited Data Enforcement | C6: The development team shall verify that no prohibited data sources (as defined in AI-POL-A.7.2-6) are used in training or fine-tuning without explicit written approval from the AI Governance Officer.
A7: A.6.1.2-04 | B7: Data Preparation Documentation | C7: All data preparation steps — including cleaning, transformation, augmentation, feature engineering, and train/test splits — shall be documented in a Data Preparation Documentation record per the template in AI-IMP-A.7.2-6-TG.
A8: A.6.1.2-05 | B8: Reproducibility | C8: Training data pipelines shall be version-controlled and reproducible. The exact dataset version, preprocessing steps, and random seeds used for each model training run shall be recorded in the model registry entry for that run.

Sheet Bias Assessment
A1: Bias Assessment — Compliance Checklist
A2: ISO/IEC 42001:2023 — Controls A.6.1: AI Development Governance
A3: Req # | B3: Section | C3: Requirement | D3: Status | E3: Evidence | F3: Owner | G3: Due Date | H3: Notes
A4: A.6.1.3-01 | B4: Mandatory Bias Assessment | C4: Every AI system that produces outputs affecting individuals shall undergo a bias assessment before deployment. The assessment shall be documented and linked from the AISIA and V&V Record.
A5: A.6.1.3-02 | B5: Protected Characteristics | C5: The bias assessment shall evaluate system performance across all applicable protected characteristics under relevant law — including but not limited to: age, sex, race/ethnicity, disability, and religion. The characteristics assessed shall be documented.
A6: A.6.1.3-03 | B6: Fairness Metrics | C6: The bias assessment shall apply quantitative fairness metrics appropriate to the system's output type. The selected metrics, their definitions, computed values, and pass/fail thresholds shall be documented in the V&V Record.
A7: A.6.1.3-04 | B7: Bias Remediation | C7: Where bias assessment identifies unacceptable disparate impact, the development team shall implement remediation measures — including resampling, re-weighting, adversarial debiasing, or post-processing calibration — and re-run the assessment to confirm remediation effectiveness.
A8: A.6.1.3-05 | B8: Ongoing Bias Monitoring | C8: For deployed AI systems, the AI System Owner shall implement ongoing monitoring for distributional shift that could introduce or amplify bias. Monitoring results shall feed into the periodic AISIA review.

Sheet Validation and Verification
A1: Validation and Verification — Compliance Checklist
A2: ISO/IEC 42001:2023 — Controls A.6.1: AI Development Governance
A3: Req # | B3: Section | C3: Requirement | D3: Status | E3: Evidence | F3: Owner | G3: Due Date | H3: Notes
A4: A.6.1.4-01 | B4: V&V Requirement | C4: Every AI system shall undergo formal Validation and Verification (V&V) before deployment. V&V shall produce a documented V&V Record per the template in AI-IMP-A.6.1-TG. Systems without a signed V&V Record shall not be deployed.
A5: A.6.1.4-02 | B5: V&V Scope | C5: The V&V process shall cover: functional correctness against specification, performance against defined thresholds, bias assessment results, security testing (adversarial inputs, prompt injection where applicable), and human oversight mechanism effectiveness.
A6: A.6.1.4-03 | B6: V&V Independence | C6: For AI systems classified as High impact, V&V shall include independent review by a person other than the primary developer. The independent reviewer's sign-off shall be recorded in the V&V Record.
A7: A.6.1.4-04 | B7: Deployment Gate Criteria | C7: The V&V Record shall document whether the system meets the deployment gate: AISIA approved, all V&V tests passed or waivers documented, legal review complete where required, AI System Owner sign-off obtained. No deployment shall proceed without a closed deployment gate.
A8: A.6.1.4-05 | B8: Re-Validation on Material Change | C8: Any material change to a deployed AI system shall trigger re-validation covering the affected components. The scope of re-validation shall be proportionate to the nature of the change and shall be approved by the AI Governance Officer.

Sheet Human Oversight in Development
A1: Human Oversight in Development — Compliance Checklist
A2: ISO/IEC 42001:2023 — Controls A.6.1: AI Development Governance
A3: Req # | B3: Section | C3: Requirement | D3: Status | E3: Evidence | F3: Owner | G3: Due Date | H3: Notes
A4: A.6.1.5-01 | B4: Oversight Mechanism Design | C4: Every AI system shall have a defined human oversight mechanism that enables a human to review, override, or halt AI outputs. The mechanism shall be specified in the system design and tested as part of V&V.
A5: A.6.1.5-02 | B5: Override Capability | C5: AI systems whose outputs are acted upon automatically shall provide an effective mechanism for authorised personnel to override or suspend AI-driven actions. The override mechanism shall be documented and accessible without specialist knowledge.
A6: A.6.1.5-03 | B6: Human Review Enablement | C6: For AI systems classified as Medium or High impact, the system design shall provide human reviewers with the information needed to exercise independent judgement — including the AI's output, the confidence level or uncertainty, and the key inputs that drove the output.
A7: A.6.1.5-04 | B7: Automation Bias Mitigation | C7: Where human reviewers are present, the design shall include measures to mitigate automation bias — the tendency for humans to defer to AI outputs without exercising independent judgement. Measures shall be documented in the User Documentation.
