Workbook

Sheet Instructions
A1: ISMS-IMP-A.5.7.5 - Threat Intelligence Standalone Dashboard
A2: Instructions & Monthly Workflow Guide
A4: 1. OVERVIEW
A6: Purpose: | B6: Executive TI program dashboard for Board presentations and C-suite reporting
A7: Audience: | B7: C-suite, Board members, External stakeholders
A8: Update Time: | B8: 10 minutes monthly + 30 minutes quarterly
A9: Dependencies: | B9: NONE - Completely standalone (no external workbook links)
A11: Key Difference: This Dashboard (5.7.5) vs Comprehensive Dashboard (5.7.4)
A12: Feature | B12: 5.7.4 Comprehensive | D12: 5.7.5 Standalone (This)
A13: Data Source | B13: External references (auto) | D13: Manual entry
A14: Update Time | B14: Seconds (refresh links) | D14: 10 minutes
A15: Audience | B15: Security team, Auditors | D15: Board, C-suite
A16: Detail Level | B16: Operational | D16: Strategic
A17: Use Case | B17: Internal operations | D17: Executive briefings
A19: 2. MONTHLY WORKFLOW (10 Minutes) - Do on 1st Business Day
A20: Step | B20: Action | D20: Details
A21: 1 | B21: Open Sheet 2 | D21: Monthly_Data_Entry sheet
A22: 2 | B22: Enter Period | D22: Format: January 2025
A23: 3 | B23: Fill Metrics | D23: 20 fields across 6 sections (see Section 3 below)
A24: 4 | B24: Set Status | D24: Change dropdown to 'Final'
A25: 5 | B25: Check Dashboard | D25: Review Sheet 3 (auto-updates)
A26: 6 | B26: Update Actions | D26: Sheet 5 if needed
A27: 7 | B27: Update Risks | D27: Sheet 7 if needed
A28: 8 | B28: Save File | D28: Use dated filename for archive
A29: 9 | B29: Export PDF | D29: Sheet 3 → File → Save As → PDF
A31: 3. WHERE TO FIND DATA (20 Metrics)
A32: Metric | C32: Data Source
A33: Active TI Sources | C33: ISMS-IMP-A.5.7.1 Sheet 2 or TI platform
A34: Average Source Quality | C34: Quality scores from evaluations (1-5 scale)
A35: Products Published | C35: Document repository count this month
A36: Stakeholder Satisfaction | C36: Monthly survey average (1-5 scale)
A37: IOCs Deployed | C37: SIEM dashboard count
A38: IOC Hit Rate % | C38: SIEM analytics: (Hits / Total) × 100
A39: CVSS 4.0 Adoption % | C39: Vuln mgmt: (v4.0 / Total) × 100
A40: High CVSS Open | C40: Count CVSS≥7.0 + active exploit (MUST=0)
A41: Incidents Prevented | C41: ISMS-IMP-A.5.7.3 Sheet 7
A42: Cost Avoidance CHF | C42: Sum of prevented incident costs
A44: See Sheet 2 for all 20 metrics with examples
A46: 4. QUARTERLY TASKS (Additional 30 Min) - Do Last Week of Quarter
A47: Task | B47: Action
...

Sheet Monthly_Data_Entry
A1: Monthly Data Entry - Threat Intelligence Program
A2: Complete all fields on 1st business day of new month (10 minutes)
A4: A. DOCUMENT CONTROL
A5: Field | B5: Value | C5: Instructions | D5: Example
A6: Reporting_Period | C6: Format: Month YYYY | D6: January 2025
A7: Entry_Date | B7: =TODAY() | C7: Auto-filled | D7: 2025-02-03
A8: Entered_By | C8: Your email | D8: jane.ciso@example.com
A9: Status | B9: Draft | C9: Set to 'Final' when complete | D9: Draft / Final
A11: B. SOURCE PORTFOLIO METRICS
A12: Field | B12: Value | C12: Instructions | D12: Example
A13: Active_TI_Sources | C13: Count of active sources | D13: 18
A14: Average_Source_Quality | C14: 1.0-5.0 scale | D14: 4.2
A15: Coverage_Gaps_Count | C15: Number of identified gaps | D15: 2
A16: Annual_Source_Cost_CHF | C16: Total subscription costs | D16: 450000
A18: C. INTELLIGENCE PRODUCTION METRICS
A19: Field | B19: Value | C19: Instructions | D19: Example
A20: Intelligence_Products_Published | C20: Count this month | D20: 23
A21: Average_Time_To_Produce_Hours | C21: Hours from collection to publication | D21: 6.5
A22: Stakeholder_Satisfaction_Rating | C22: 1.0-5.0 scale | D22: 4.3
A23: Intelligence_Consumption_Rate | C23: Percentage (0-100) | D23: 82
A25: D. INTEGRATION & EFFECTIVENESS METRICS
A26: Field | B26: Value | C26: Instructions | D26: Example
A27: Security_Tools_Integrated | C27: Count of tools with TI feeds | D27: 9
A28: IOCs_Deployed | C28: IOCs deployed this month | D28: 1247
A29: IOC_Hit_Rate | C29: Percentage (0-100) | D29: 12.3
A30: IOC_False_Positive_Rate | C30: Percentage (0-100) | D30: 3.8
A32: E. CVSS & VULNERABILITY METRICS
A33: Field | B33: Value | C33: Instructions | D33: Example
A34: CVSS_4_0_Adoption_Rate | C34: Percentage (0-100) | D34: 68
A35: CVSS_Source_Accuracy_Rate | C35: Percentage (0-100) | D35: 91
A36: High_CVSS_Active_Exploitation_Open | C36: Count (MUST be 0) | D36: 0
A37: VTL_Records_Created | C37: Vulnerability-Threat Links | D37: 47
A39: F. PREVENTION & IMPACT METRICS
A40: Field | B40: Value | C40: Instructions | D40: Example
A41: Incidents_Prevented | C41: Count this month | D41: 4
A42: Cost_Avoidance_CHF | C42: Estimated savings | D42: 275000
A43: Risk_Assessments_Updated | C43: Count this month | D43: 3
A44: P1_P2_Incidents_With_TI_Context | C44: Percentage (0-100) | D44: 85
A47: NOTES / COMMENTS

Sheet Executive_Dashboard
A1: [Organization Logo] | E1: THREAT INTELLIGENCE PROGRAM
A2: Executive Summary Dashboard
A3: Reporting Period: | B3: =Monthly_Data_Entry!B5 | H3: Report Date: | I3: =TODAY()
A4: Program Health Score
A5: =AVERAGE(B10,B11,B12,B13)
A8: KEY PERFORMANCE INDICATORS
A9: SOURCE PORTFOLIO | D9: PRODUCTION QUALITY | G9: INTEGRATION | I9: CVSS & PREVENTION
A10: Active Sources | B10: =Monthly_Data_Entry!B10 | D10: Products | E10: =Monthly_Data_Entry!B17 | G10: Tools Integrated | H10: =Monthly_Data_Entry!B25 | I10: CVSS 4.0 Adoption % | J10: =Monthly_Data_Entry!B32
A11: Avg Quality | B11: =Monthly_Data_Entry!B11 | D11: Satisfaction | E11: =Monthly_Data_Entry!B19 | G11: IOC Hit Rate % | H11: =Monthly_Data_Entry!B27 | I11: Incidents Prevented | J11: =Monthly_Data_Entry!B40
A12: Coverage Gaps | B12: =Monthly_Data_Entry!B12 | D12: Consumption % | E12: =Monthly_Data_Entry!B20 | G12: False Positive % | H12: =Monthly_Data_Entry!B28 | I12: High CVSS Open | J12: =Monthly_Data_Entry!B34
A14: CRITICAL METRICS - THIS MONTH VS TARGET
A15: Metric | B15: Target | C15: Last Month | D15: This Month | E15: Status | F15: Trend
A16: Stakeholder Satisfaction | B16: >=4.0 | C16: =OFFSET(Trend_History!F:F,-1,0) | D16: =Monthly_Data_Entry!B19
A17: IOC Hit Rate % | B17: >=10 | D17: =Monthly_Data_Entry!B27
A18: Incidents Prevented | B18: >=3 | D18: =Monthly_Data_Entry!B40
A19: CVSS Accuracy % | B19: >=90 | D19: =Monthly_Data_Entry!B33
A20: False Positive % | B20: <=5 | D20: =Monthly_Data_Entry!B28
A22: TOP 3 ACHIEVEMENTS | D22: TOP 3 RISKS | H22: TOP 3 ACTIONS REQUIRED
A23: • [From Critical_Actions, Type=Achievement] | D23: • [From Risk_Summary, Priority=Critical] | H23: • [From Critical_Actions, Priority=High]
A28: Data Source: Self-reported metrics | Next Update: 1st business day of next month

Sheet Trend_History
A1: Trend History - 12 Month Rolling Data
A2: Data automatically appended from Monthly_Data_Entry when Status = 'Final'
A4: Period | B4: Entry_Date | C4: Active_Sources | D4: Avg_Quality | E4: Coverage_Gaps | F4: Products_Published | G4: Satisfaction | H4: IOCs_Deployed | I4: Hit_Rate_% | J4: False_Positive_% | K4: CVSS_4.0_% | L4: CVSS_Accuracy_% | M4: High_CVSS_Open | N4: Prevented | O4: Cost_Avoid_CHF | P4: Program_Health | Q4: Notes
A5: 2025-01 | B5: 2025-02-01 | C5: 18 | D5: 4.2 | E5: 2 | F5: 23 | G5: 4.3 | H5: 1247 | I5: 12.3 | J5: 3.8 | K5: 68 | L5: 91 | M5: 0 | N5: 4 | O5: 275000 | P5: 4.1 | Q5: Q1 data
A7: INSTRUCTIONS:
A8: • This sheet stores last 24 months of data for trending
A9: • New row appended automatically when Monthly_Data_Entry Status = 'Final'
A10: • Used for sparklines and charts in Executive_Dashboard
A11: • Keep last 24 months, delete older rows

Sheet Critical_Actions
A1: Critical Actions - Executive Attention Required
A2: Track 5-10 actions requiring executive decisions or awareness
A4: Action_ID | B4: Action_Type | C4: Description | D4: Owner | E4: Priority | F4: Due_Date | G4: Status | H4: Resolution | I4: Created_Date | J4: Completed_Date
A5: ACT-2025-01 | B5: Budget | C5: CrowdStrike renewal requires board approval | D5: CISO | E5: High | F5: 31.03.2025 | G5: Open | I5: 10.01.2025
A6: ACT-2025-02 | B6: Achievement | C6: Prevented 4 major incidents using threat intelligence | D6: TI Lead | E6: Medium | F6: 31.01.2025 | G6: Completed | H6: Documented in monthly report | I6: 05.01.2025 | J6: 31.01.2025
A9: SUMMARY METRICS
A10: Total Actions: | B10: =COUNTA(A5:A100)
A11: Critical Priority: | B11: =COUNTIF(E5:E100,"Critical")
A12: Overdue: | B12: =COUNTIFS(F5:F100,"<"&TODAY(),G5:G100,"<>Completed")
A13: Completed This Quarter: | B13: =COUNTIFS(J5:J100,">="&DATE(YEAR(TODAY()),QUARTER(TODAY())*3-2,1),G5:G100,"Completed")

Sheet Quarterly_Summary
A1: Quarterly Summary - Board Reporting
A2: Quarter-over-quarter comparison and strategic highlights
A4: A. QUARTERLY METRICS
A5: Metric | B5: Q-4 | C5: Q-3 | D5: Q-2 | E5: Q-1 (Current) | F5: QoQ Change | G5: YoY Change
A6: SOURCE PORTFOLIO
A7: Active Sources
A8: Avg Quality (1-5)
A9: Coverage Gaps
A10: PRODUCTION
A11: Products (Quarterly)
A12: Satisfaction (1-5)
A13: INTEGRATION
A14: IOCs Deployed (Q)
A15: Hit Rate (%)
A16: CVSS & PREVENTION
A17: CVSS 4.0 Adoption (%)
... A22: B. QUARTERLY HIGHLIGHTS
A23: Quarter | B23: Top 3 Achievements | E23: Top 3 Challenges
A24: Q-1 (Current)
A27: Q-2
A30: Q-3
A34: C. CISO COMMENTARY - STRATEGIC OBSERVATIONS
A35: [CISO Commentary: Quarterly strategic priorities, budget implications, resource needs - max 500 characters]

Sheet Risk_Summary
A1: Risk Summary - Program Risks Requiring Executive Attention
A2: Top 5-10 risks to threat intelligence program effectiveness
A4: Risk_ID | B4: Risk_Category | C4: Risk_Description | D4: Likelihood | E4: Impact | F4: Risk_Score | G4: Mitigation_Status | H4: Mitigation_Plan | I4: Owner | J4: Review_Date | K4: Status
A5: RISK-2025-01 | B5: Staffing | C5: Lead threat analyst departure without trained backup | D5: High | E5: High | F5: =IF(D5="High",IF(E5="Critical",12,IF(E5="High",9,IF(E5="Medium",6,3))),IF(D5="Medium",IF(E5="Critical",8,IF(E5="High",6,IF(E5="Medium",4,2))),IF(E5="Critical",4,IF(E5="High",3,IF(E5="Medium",2,1))))) | G5: Planned | H5: Cross-training analyst 2 | I5: CISO | J5: 15.01.2025 | K5: Active
A6: RISK-2025-02 | B6: Source_Portfolio | C6: Over-reliance on single commercial vendor | D6: Medium | E6: High | F6: =IF(D6="High",IF(E6="Critical",12,IF(E6="High",9,IF(E6="Medium",6,3))),IF(D6="Medium",IF(E6="Critical",8,IF(E6="High",6,IF(E6="Medium",4,2))),IF(E6="Critical",4,IF(E6="High",3,IF(E6="Medium",2,1))))) | G6: In_Progress | H6: Diversifying to 3 vendors | I6: TI Lead | J6: 20.01.2025 | K6: Active
A9: RISK SCORE MATRIX
A10: Likelihood \ Impact | B10: Low | C10: Medium | D10: High | E10: Critical
A11: High | B11: 3 | C11: 6 | D11: 9 | E11: 12
A12: Medium | B12: 2 | C12: 4 | D12: 6 | E12: 8
A13: Low | B13: 1 | C13: 2 | D13: 3 | E13: 4
A15: SUMMARY METRICS
A16: Total Active Risks: | B16: =COUNTIF(K5:K100,"Active")
A17: Critical Risks (Score ≥9): | B17: =COUNTIFS(F5:F100,">=9",K5:K100,"Active")
A18: High Risks (Score 6-8): | B18: =COUNTIFS(F5:F100,">=6",F5:F100,"<9",K5:K100,"Active")
A19: Risks Needing Mitigation: | B19: =COUNTIFS(G5:G100,"None",K5:K100,"Active")

Sheet ROI_Summary
A1: ROI Summary - Threat Intelligence Program Value
A2: Cost-benefit analysis and program value justification
A4: A. ANNUAL PROGRAM COSTS
A5: Cost Category | B5: This Year (CHF) | C5: Last Year (CHF) | D5: Change (CHF) | E5: Change (%) | F5: Notes
A6: Commercial TI Sources | B6: 450000 | C6: 420000 | D6: =B6-C6 | E6: =(B6-C6)/C6*100
A7: Staffing (FTE cost) | B7: 600000 | C7: 580000 | D7: =B7-C7 | E7: =(B7-C7)/C7*100
A8: Tools & Infrastructure | B8: 150000 | C8: 140000 | D8: =B8-C8 | E8: =(B8-C8)/C8*100
A9: Training & Certifications | B9: 25000 | C9: 20000 | D9: =B9-C9 | E9: =(B9-C9)/C9*100
A10: Travel & Conferences | B10: 15000 | C10: 12000 | D10: =B10-C10 | E10: =(B10-C10)/C10*100
A11: TOTAL PROGRAM COST | B11: =SUM(B6:B10) | C11: =SUM(C6:C10) | D11: =B11-C11 | E11: =(B11-C11)/C11*100
A13: B. VALUE DELIVERED
A14: Value Category | B14: This Year (CHF) | C14: Last Year (CHF) | D14: Change (CHF) | E14: Change (%) | F14: Calculation Method
A15: Incidents Prevented (Cost Avoidance) | B15: 3300000 | C15: 2800000 | D15: =B15-C15 | E15: =(B15-C15)/C15*100 | F15: From Trend_History
A16: Faster Incident Response (Time Savings) | B16: 450000 | C16: 380000 | D16: =B16-C16 | E16: =(B16-C16)/C16*100 | F16: 120 hrs × 3750/hr
A17: Risk Assessment Improvements | B17: 180000 | C17: 150000 | D17: =B17-C17 | E17: =(B17-C17)/C17*100 | F17: 12 updates × 15K
A18: Compliance & Audit Efficiency | B18: 90000 | C18: 75000 | D18: =B18-C18 | E18: =(B18-C18)/C18*100 | F18: 60 hrs × 1500/hr
A19: TOTAL VALUE DELIVERED | B19: =SUM(B15:B18) | C19: =SUM(C15:C18) | D19: =B19-C19 | E19: =(B19-C19)/C19*100
A21: C. ROI CALCULATION
A22: Metric | B22: This Year | C22: Last Year | D22: 3-Year Avg | E22: Interpretation
A23: Total Value Delivered (CHF) | B23: =B19 | C23: =C19
A24: Total Program Cost (CHF) | B24: =B11 | C24: =C11
A25: Net Value (CHF) | B25: =B21-B22 | C25: =C21-C22
A26: ROI Ratio | B26: =B20/B21 | C26: =C20/C21 | E26: >=3.0 Excellent
A27: ROI Percentage | B27: =(B20/B21-1)*100 | C27: =(C20/C21-1)*100 | E27: >=200% Excellent
A30: D. CVSS-BASED PREVENTION VALUE (Annual)
A31: CVSS Severity | B31: Incidents Prevented | C31: Avg Cost/Incident | D31: Total Value (CHF) | E31: % of Total
A32: Critical (9.0-10.0) | B32: 8 | C32: 150000 | D32: =B32*C32 | E32: =D32/D$36*100
A33: High (7.0-8.9) | B33: 18 | C33: 75000 | D33: =B33*C33 | E33: =D33/D$36*100
A34: Medium (4.0-6.9) | B34: 14 | C34: 25000 | D34: =B34*C34 | E34: =D34/D$36*100
A35: Low (0.1-3.9) | B35: 4 | C35: 5000 | D35: =B35*C35 | E35: =D35/D$36*100
A36: TOTAL | B36: =SUM(B32:B35) | C36: =AVERAGE(C32:C35) | D36: =SUM(D32:D35)

Sheet Metadata
A1: Workbook Metadata - Document Control
A3: Workbook_Version | B3: 1.0
A4: Workbook_Type | B4: Standalone Dashboard (Manual Entry)
A5: Total_Sheets | B5: 9
A6: Generation_Date | B6: 08.02.2026
A7: Generator_Script | B7: generate_a57_5_standalone.py
A8: Script_Version | B8: 1.0.0
A9: Python_Version | B9: 3.x
A10: openpyxl_Version | B10: 3.x
A11: Last_Modified_Date | B11: =TODAY()
A12: Last_Modified_By | B12: =USER()
A13: Reporting_Period_Current | B13: =Monthly_Data_Entry!B5
A14: Data_Entry_Status | B14: =Monthly_Data_Entry!B8
A15: Related_Policy | B15: ISMS-POL-A.5.7
A16: Related_IMP_Spec | B16: ISMS-IMP-A.5.7.5 v1.0
A17: Complementary_Dashboard | B17: ISMS-IMP-A.5.7.4 (Comprehensive)
A18: ISO_27001_Control | B18: A.5.7 (Threat Intelligence)
A19: Audience | B19: C-suite, Board, External Stakeholders
A20: Update_Frequency | B20: Monthly (1st business day)
A21: Quarterly_Review | B21: Last week of quarter
A24: CHANGELOG
A25: v1.0 (10.01.2025): - Initial release with 9 sheets - Monthly manual data entry workflow (10 minutes) - Executive one-page dashboard (auto-generated) - 12-month trend tracking - Quarterly Board reporting - Top risks and critical actions tracking - ROI calculation and cost-benefit analysis - CVSS-based prevention value tracking - ISO 27001 compliance status - Completely standalone (no external workbook dependencies)
A37: SHEET INVENTORY
A38: Sheet 1 | B38: Instructions | C38: User guide and workflow
A39: Sheet 2 | B39: Monthly_Data_Entry | C39: Manual entry form (15-20 metrics)
A40: Sheet 3 | B40: Executive_Dashboard | C40: One-page visual summary (print-ready)
A41: Sheet 4 | B41: Trend_History | C41: 12-month historical data
A42: Sheet 5 | B42: Critical_Actions | C42: Top 5-10 executive actions
A43: Sheet 6 | B43: Quarterly_Summary | C43: QoQ comparison for Board
A44: Sheet 7 | B44: Risk_Summary | C44: Top program risks
A45: Sheet 8 | B45: ROI_Summary | C45: Cost-benefit analysis
A46: Sheet 9 | B46: Metadata | C46: This sheet - document control
