Workbook

Sheet Executive Summary
A1: PRIV-CHK-A.1.2.6-9 — Privacy Governance and Records Compliance Checklist
A3: DOCUMENT INFORMATION
A4: Document ID | B4: PRIV-CHK-A.1.2.6-9
A5: Source Policy | B5: PRIV-POL-A.1.2.6-9
A6: ISO Controls | B6: Privacy Governance and Records
A7: Generated | B7: 10.03.2026
A8: Prepared By
A9: Organisation
A10: Review Cycle | B10: Annual
A12: OVERALL COMPLIANCE STATUS
A13: Overall Compliance | B13: ='Dashboard'!G8
A14: Status | B14: =IF(Dashboard!G8="N/A","NOT ASSESSED",IF(ISNUMBER(VALUE(SUBSTITUTE(Dashboard!G8,"%",""))),IF(VALUE(SUBSTITUTE(Dashboard!G8,"%",""))>=90,"GREEN",IF(VALUE(SUBSTITUTE(Dashboard!G8,"%",""))>=70,"AMBER","RED")),"NOT ASSESSED"))
A16: KEY METRICS
A17: Total Requirements | B17: ='Dashboard'!B8
A18: Compliant | B18: ='Dashboard'!C8
A19: Partial | B19: ='Dashboard'!D8
A20: Non-Compliant | B20: ='Dashboard'!E8
A21: Not Applicable | B21: ='Dashboard'!F8
A22: Owner Coverage | B22: =IF(Dashboard!B8=0,"N/A",ROUND((COUNTA('Privacy Impact Assessment'!F4:F8)+COUNTA('Processor Contracts'!F4:F9)+COUNTA('Joint Controller Arrangements'!F4:F7)+COUNTA('Records of Processing Activities'!F4:F8))/Dashboard!B8*100,0)&"%")
A24: DOMAIN STATUS SUMMARY
A25: Domain | B25: Compliance % | C25: Compliant | D25: Gaps | E25: Status
A26: Privacy Impact Assessment | B26: ='Dashboard'!G4 | C26: ='Dashboard'!C4 | D26: ='Dashboard'!E4 | E26: =IF(Dashboard!G4="N/A","--",IF(ISNUMBER(VALUE(SUBSTITUTE(Dashboard!G4,"%",""))),IF(VALUE(SUBSTITUTE(Dashboard!G4,"%",""))>=90,"PASS",IF(VALUE(SUBSTITUTE(Dashboard!G4,"%",""))>=70,"REVIEW","FAIL")),"--"))
A27: Processor Contracts | B27: ='Dashboard'!G5 | C27: ='Dashboard'!C5 | D27: ='Dashboard'!E5 | E27: =IF(Dashboard!G5="N/A","--",IF(ISNUMBER(VALUE(SUBSTITUTE(Dashboard!G5,"%",""))),IF(VALUE(SUBSTITUTE(Dashboard!G5,"%",""))>=90,"PASS",IF(VALUE(SUBSTITUTE(Dashboard!G5,"%",""))>=70,"REVIEW","FAIL")),"--"))
A28: Joint Controller Arrangements | B28: ='Dashboard'!G6 | C28: ='Dashboard'!C6 | D28: ='Dashboard'!E6 | E28: =IF(Dashboard!G6="N/A","--",IF(ISNUMBER(VALUE(SUBSTITUTE(Dashboard!G6,"%",""))),IF(VALUE(SUBSTITUTE(Dashboard!G6,"%",""))>=90,"PASS",IF(VALUE(SUBSTITUTE(Dashboard!G6,"%",""))>=70,"REVIEW","FAIL")),"--"))
A29: Records of Processing Activities | B29: ='Dashboard'!G7 | C29: ='Dashboard'!C7 | D29: ='Dashboard'!E7 | E29: =IF(Dashboard!G7="N/A","--",IF(ISNUMBER(VALUE(SUBSTITUTE(Dashboard!G7,"%",""))),IF(VALUE(SUBSTITUTE(Dashboard!G7,"%",""))>=90,"PASS",IF(VALUE(SUBSTITUTE(Dashboard!G7,"%",""))>=70,"REVIEW","FAIL")),"--"))
A31: CRITICAL ISSUES
A32: # | B32: Issue Description | C32: Domain | D32: Owner | E32: Due Date
A33: 1
A34: 2
A35: 3
A36: 4
A37: 5
A39: MANAGEMENT COMMENTARY
A40: [Enter management commentary on privacy governance and records posture]
A44: APPROVAL
A45: Assessed By
A46: Name:
A47: Date:
A48: Signature:
A49: Decision:
...

Sheet Dashboard
A1: Privacy Governance and Records — Compliance Dashboard
A3: Domain | B3: Total Reqs | C3: Compliant | D3: Partial | E3: Non-Compliant | F3: N/A | G3: Compliance %
A4: Privacy Impact Assessment | B4: =COUNTA('Privacy Impact Assessment'!D4:D8) | C4: =COUNTIF('Privacy Impact Assessment'!D4:D8,"Compliant") | D4: =COUNTIF('Privacy Impact Assessment'!D4:D8,"Partial") | E4: =COUNTIF('Privacy Impact Assessment'!D4:D8,"Non-Compliant") | F4: =COUNTIF('Privacy Impact Assessment'!D4:D8,"N/A") | G4: =IF((B4-F4)=0,"N/A",ROUND(C4/(B4-F4)*100,1)&"%")
A5: Processor Contracts | B5: =COUNTA('Processor Contracts'!D4:D9) | C5: =COUNTIF('Processor Contracts'!D4:D9,"Compliant") | D5: =COUNTIF('Processor Contracts'!D4:D9,"Partial") | E5: =COUNTIF('Processor Contracts'!D4:D9,"Non-Compliant") | F5: =COUNTIF('Processor Contracts'!D4:D9,"N/A") | G5: =IF((B5-F5)=0,"N/A",ROUND(C5/(B5-F5)*100,1)&"%")
A6: Joint Controller Arrangements | B6: =COUNTA('Joint Controller Arrangements'!D4:D7) | C6: =COUNTIF('Joint Controller Arrangements'!D4:D7,"Compliant") | D6: =COUNTIF('Joint Controller Arrangements'!D4:D7,"Partial") | E6: =COUNTIF('Joint Controller Arrangements'!D4:D7,"Non-Compliant") | F6: =COUNTIF('Joint Controller Arrangements'!D4:D7,"N/A") | G6: =IF((B6-F6)=0,"N/A",ROUND(C6/(B6-F6)*100,1)&"%")
A7: Records of Processing Activities | B7: =COUNTA('Records of Processing Activities'!D4:D8) | C7: =COUNTIF('Records of Processing Activities'!D4:D8,"Compliant") | D7: =COUNTIF('Records of Processing Activities'!D4:D8,"Partial") | E7: =COUNTIF('Records of Processing Activities'!D4:D8,"Non-Compliant") | F7: =COUNTIF('Records of Processing Activities'!D4:D8,"N/A") | G7: =IF((B7-F7)=0,"N/A",ROUND(C7/(B7-F7)*100,1)&"%")
A8: TOTAL | B8: =SUM(B4:B7) | C8: =SUM(C4:C7) | D8: =SUM(D4:D7) | E8: =SUM(E4:E7) | F8: =SUM(F4:F7) | G8: =IF((B8-F8)=0,"N/A",ROUND(C8/(B8-F8)*100,1)&"%")
A10: COMPLIANCE BY STATUS
A11: Compliant | B11: =C8 | C11: =IF(B8=0,"",ROUND(B11/B8*100,1)&"%")
A12: Partial | B12: =D8 | C12: =IF(B8=0,"",ROUND(B12/B8*100,1)&"%")
A13: Non-Compliant | B13: =E8 | C13: =IF(B8=0,"",ROUND(B13/B8*100,1)&"%")
A14: N/A | B14: =F8 | C14: =IF(B8=0,"",ROUND(B14/B8*100,1)&"%")
A16: TOP GAPS (Manual Entry)
A17: Priority | B17: Domain | C17: Requirement | D17: Owner | E17: Due Date | F17: Status
A29: COMPLIANCE TREND (Manual Entry)
A30: Assessment Date | B30: Overall % | C30: Compliant | D30: Gaps | E30: Assessor | F30: Notes

Sheet Privacy Impact Assessment
A1: Privacy Impact Assessment — Compliance Checklist
A2: ISO/IEC 27701:2025 — Controls A.1.2.6-9: Privacy Governance and Records
A3: Req # | B3: Section | C3: Requirement | D3: Status | E3: Evidence | F3: Owner | G3: Due Date | H3: Notes
A4: A.1.2.6-01 | B4: DPIA Screening | C4: All new processing activities and material changes to existing activities shall undergo a DPIA screening by the DPO to determine whether a full DPIA is required. Screening decisions shall be documented.
A5: A.1.2.6-02 | B5: High-Risk Triggers | C5: A full DPIA is mandatory where processing is likely to result in high risk, including: systematic profiling with legal effects; large-scale special category processing; systematic monitoring of public areas; use of new technologies with large PII volumes; and any type on the supervisory authority's DPIA required list.
A6: A.1.2.6-03 | B6: DPIA Execution | C6: Full DPIAs shall be conducted in accordance with GDPR Article 35, describing processing operations, necessity and proportionality, risks to data subjects, and measures to address those risks.
A7: A.1.2.6-04 | B7: Residual High Risk | C7: A DPIA that identifies residual high risk after implementing risk-reduction measures requires prior consultation with the competent supervisory authority (GDPR Article 36), Executive Management approval, and documented risk acceptance or processing halt decision.
A8: A.1.2.6-05 | B8: DPIA Register | C8: DPIA results shall be documented and maintained in the DPIA Register. DPIAs shall be reviewed when processing changes materially or after a significant privacy incident involving the processing activity.

Sheet Processor Contracts
A1: Processor Contracts — Compliance Checklist
A2: ISO/IEC 27701:2025 — Controls A.1.2.6-9: Privacy Governance and Records
A3: Req # | B3: Section | C3: Requirement | D3: Status | E3: Evidence | F3: Owner | G3: Due Date | H3: Notes
A4: A.1.2.7-01 | B4: Contract Requirement | C4: The organisation shall have a written contract with every PII processor it uses. No PII shall be transferred to an external processor without a current, signed processor agreement.
A5: A.1.2.7-02 | B5: Mandatory Contract Content | C5: Processor agreements shall address at minimum the obligations required by GDPR Article 28(3): processing only on documented instructions; personnel confidentiality; appropriate security measures; sub-processor restrictions; data subject rights assistance; security and breach notification assistance; return or deletion of PII at end of service; and cooperation with audits.
A6: A.1.2.7-03 | B6: ISO 27701 Table A.2 Reference | C6: Processor agreements shall also reference the appropriate controls from ISO/IEC 27701:2025 Table A.2, requiring the processor to implement controls equivalent to those in PRIV-POL-A.2.x.
A7: A.1.2.7-04 | B7: Sub-processor Controls | C7: The processor agreement shall require that sub-processors are engaged only with the organisation's prior written consent, and that the same data protection obligations as in the primary agreement are imposed on sub-processors.
A8: A.1.2.7-05 | B8: Processor Agreement Register | C8: The DPO shall maintain a Processor Agreement Register listing all active processor agreements with status, review date, and processor contact. No PII processor engagement commences without a register entry.
A9: A.1.2.7-06 | B9: Processor Due Diligence | C9: Prior to engaging a PII processor, the organisation shall conduct and document due diligence on the processor's technical and organisational security measures, confirming they are sufficient to meet GDPR Article 28(1) requirements.

Sheet Joint Controller Arrangements
A1: Joint Controller Arrangements — Compliance Checklist
A2: ISO/IEC 27701:2025 — Controls A.1.2.6-9: Privacy Governance and Records
A3: Req # | B3: Section | C3: Requirement | D3: Status | E3: Evidence | F3: Owner | G3: Due Date | H3: Notes
A4: A.1.2.8-01 | B4: Arrangement Requirement | C4: Where the organisation jointly determines the purposes and means of PII processing with another controller, the organisation shall determine respective roles and responsibilities with that joint controller in a transparent arrangement before processing commences.
A5: A.1.2.8-02 | B5: Arrangement Content | C5: Joint controller arrangements shall determine: respective responsibilities for GDPR obligations (Article 26(1)); which controller provides privacy notices to data subjects; which controller is primary point of contact for data subject rights; data security responsibilities; and breach notification responsibilities.
A6: A.1.2.8-03 | B6: Data Subject Information | C6: The essence of the joint controller arrangement (i.e. which controller data subjects should contact and for what) shall be made available to data subjects, directly or by reference in the privacy notice.
A7: A.1.2.8-04 | B7: Review and Approval | C7: Joint controller arrangements require DPO and Legal/Compliance review before execution. Executed arrangements shall be maintained in the Joint Controller Arrangement Register.

Sheet Records of Processing Activities
A1: Records of Processing Activities — Compliance Checklist
A2: ISO/IEC 27701:2025 — Controls A.1.2.6-9: Privacy Governance and Records
A3: Req # | B3: Section | C3: Requirement | D3: Status | E3: Evidence | F3: Owner | G3: Due Date | H3: Notes
A4: A.1.2.9-01 | B4: RoPA Requirement | C4: The organisation shall determine and securely maintain a Record of Processing Activities (RoPA) in support of its obligations as PII Controller for all processing of PII. The RoPA shall be available to supervisory authorities on request.
A5: A.1.2.9-02 | B5: RoPA Content | C5: The RoPA shall contain for each processing activity: name and contact details of the controller and DPO; purposes of the processing; categories of data subjects and PII; categories of recipients; third-country transfers and safeguards; retention periods; and description of technical and organisational security measures.
A6: A.1.2.9-03 | B6: Additional Records | C6: In addition to the RoPA, the organisation shall maintain: DPIA Register; Processor Agreement Register; Joint Controller Arrangement Register; consent records (per PRIV-POL-A.1.2.2-5); and LIA records (per PRIV-POL-A.1.2.2-5).
A7: A.1.2.9-04 | B7: RoPA Maintenance | C7: The DPO shall own and maintain the RoPA. It shall be updated whenever a new processing activity commences, an existing activity changes materially, or a processing activity ceases.
A8: A.1.2.9-05 | B8: Records Protection | C8: All privacy records (RoPA, DPIA Register, Processor Agreement Register, consent records) shall be protected against loss, unauthorised access, and falsification in accordance with PRIV-POL-A.3.13-16.
