Workbook

Sheet Executive Summary
A1: PRIV-CHK-A.2.5.7-9 — Sub-processor Management Compliance Checklist
A3: DOCUMENT INFORMATION
A4: Document ID | B4: PRIV-CHK-A.2.5.7-9
A5: Source Policy | B5: PRIV-POL-A.2.5.7-9
A6: ISO Controls | B6: Sub-processor Management
A7: Generated | B7: 30.09.2026
A8: Prepared By
A9: Organisation
A10: Review Cycle | B10: Annual
A12: OVERALL COMPLIANCE STATUS
A13: Overall Compliance | B13: ='Dashboard'!G7
A14: Status | B14: =IF(Dashboard!H7>0,"INCOMPLETE",IF(Dashboard!G7="N/A","NOT ASSESSED",IF(ISNUMBER(VALUE(SUBSTITUTE(Dashboard!G7,"%",""))),IF(VALUE(SUBSTITUTE(Dashboard!G7,"%",""))>=90,"GREEN",IF(VALUE(SUBSTITUTE(Dashboard!G7,"%",""))>=70,"AMBER","RED")),"NOT ASSESSED")))
A16: KEY METRICS
A17: Total Requirements | B17: ='Dashboard'!B7
A18: Compliant | B18: ='Dashboard'!C7
A19: Partial | B19: ='Dashboard'!D7
A20: Non-Compliant | B20: ='Dashboard'!E7
A21: Not Applicable | B21: ='Dashboard'!F7
A22: Unanswered | B22: ='Dashboard'!H7
A23: Owner Coverage | B23: =IF(Dashboard!B7=0,"N/A",ROUND((COUNTA('Sub-processor Disclosure'!F4:F7)+COUNTA('Sub-processor Engagement'!F4:F8)+COUNTA('Sub-processor Changes'!F4:F7))/Dashboard!B7*100,0)&"%")
A25: DOMAIN STATUS SUMMARY
A26: Domain | B26: Compliance % | C26: Compliant | D26: Gaps | E26: Status
A27: Sub-processor Disclosure | B27: ='Dashboard'!G4 | C27: ='Dashboard'!C4 | D27: ='Dashboard'!E4 | E27: =IF(Dashboard!H4>0,"INCOMPLETE",IF(Dashboard!G4="N/A","--",IF(ISNUMBER(VALUE(SUBSTITUTE(Dashboard!G4,"%",""))),IF(VALUE(SUBSTITUTE(Dashboard!G4,"%",""))>=90,"PASS",IF(VALUE(SUBSTITUTE(Dashboard!G4,"%",""))>=70,"REVIEW","FAIL")),"--")))
A28: Sub-processor Engagement | B28: ='Dashboard'!G5 | C28: ='Dashboard'!C5 | D28: ='Dashboard'!E5 | E28: =IF(Dashboard!H5>0,"INCOMPLETE",IF(Dashboard!G5="N/A","--",IF(ISNUMBER(VALUE(SUBSTITUTE(Dashboard!G5,"%",""))),IF(VALUE(SUBSTITUTE(Dashboard!G5,"%",""))>=90,"PASS",IF(VALUE(SUBSTITUTE(Dashboard!G5,"%",""))>=70,"REVIEW","FAIL")),"--")))
A29: Sub-processor Changes | B29: ='Dashboard'!G6 | C29: ='Dashboard'!C6 | D29: ='Dashboard'!E6 | E29: =IF(Dashboard!H6>0,"INCOMPLETE",IF(Dashboard!G6="N/A","--",IF(ISNUMBER(VALUE(SUBSTITUTE(Dashboard!G6,"%",""))),IF(VALUE(SUBSTITUTE(Dashboard!G6,"%",""))>=90,"PASS",IF(VALUE(SUBSTITUTE(Dashboard!G6,"%",""))>=70,"REVIEW","FAIL")),"--")))
A31: CRITICAL ISSUES
A32: # | B32: Issue Description | C32: Domain | D32: Owner | E32: Due Date
A33: 1
A34: 2
A35: 3
A36: 4
A37: 5
A39: MANAGEMENT COMMENTARY
A40: [Enter management commentary on sub-processor management posture]
A44: APPROVAL
A45: Assessed By
A46: Name:
A47: Date:
A48: Signature:
A49: Decision:
...

Sheet Dashboard
A1: Sub-processor Management — Compliance Dashboard
A3: Domain | B3: Total Reqs | C3: Compliant | D3: Partial | E3: Non-Compliant | F3: N/A | G3: Compliance % | H3: Unassessed
A4: Sub-processor Disclosure | B4: =COUNTA('Sub-processor Disclosure'!A4:A7) | C4: =COUNTIF('Sub-processor Disclosure'!D4:D7,"Compliant") | D4: =COUNTIF('Sub-processor Disclosure'!D4:D7,"Partial") | E4: =COUNTIF('Sub-processor Disclosure'!D4:D7,"Non-Compliant") | F4: =COUNTIF('Sub-processor Disclosure'!D4:D7,"N/A") | G4: =IF((B4-F4)=0,"N/A",ROUND(C4/(B4-F4)*100,1)&"%") | H4: =B4-(C4+D4+E4+F4)
A5: Sub-processor Engagement | B5: =COUNTA('Sub-processor Engagement'!A4:A8) | C5: =COUNTIF('Sub-processor Engagement'!D4:D8,"Compliant") | D5: =COUNTIF('Sub-processor Engagement'!D4:D8,"Partial") | E5: =COUNTIF('Sub-processor Engagement'!D4:D8,"Non-Compliant") | F5: =COUNTIF('Sub-processor Engagement'!D4:D8,"N/A") | G5: =IF((B5-F5)=0,"N/A",ROUND(C5/(B5-F5)*100,1)&"%") | H5: =B5-(C5+D5+E5+F5)
A6: Sub-processor Changes | B6: =COUNTA('Sub-processor Changes'!A4:A7) | C6: =COUNTIF('Sub-processor Changes'!D4:D7,"Compliant") | D6: =COUNTIF('Sub-processor Changes'!D4:D7,"Partial") | E6: =COUNTIF('Sub-processor Changes'!D4:D7,"Non-Compliant") | F6: =COUNTIF('Sub-processor Changes'!D4:D7,"N/A") | G6: =IF((B6-F6)=0,"N/A",ROUND(C6/(B6-F6)*100,1)&"%") | H6: =B6-(C6+D6+E6+F6)
A7: TOTAL | B7: =SUM(B4:B6) | C7: =SUM(C4:C6) | D7: =SUM(D4:D6) | E7: =SUM(E4:E6) | F7: =SUM(F4:F6) | G7: =IF((B7-F7)=0,"N/A",ROUND(C7/(B7-F7)*100,1)&"%") | H7: =SUM(H4:H6)
A9: COMPLIANCE BY STATUS
A10: Compliant | B10: =C7 | C10: =IF(B7=0,"",ROUND(B10/B7*100,1)&"%")
A11: Partial | B11: =D7 | C11: =IF(B7=0,"",ROUND(B11/B7*100,1)&"%")
A12: Non-Compliant | B12: =E7 | C12: =IF(B7=0,"",ROUND(B12/B7*100,1)&"%")
A13: N/A | B13: =F7 | C13: =IF(B7=0,"",ROUND(B13/B7*100,1)&"%")
A15: TOP GAPS (Manual Entry)
A16: Priority | B16: Domain | C16: Requirement | D16: Owner | E16: Due Date | F16: Status
A28: COMPLIANCE TREND (Manual Entry)
A29: Assessment Date | B29: Overall % | C29: Compliant | D29: Gaps | E29: Assessor | F29: Notes

Sheet Sub-processor Disclosure
A1: Sub-processor Disclosure — Compliance Checklist
A2: ISO/IEC 27701:2025 — Controls A.2.5.7-9: Sub-processor Management
A3: Req # | B3: Section | C3: Requirement | D3: Status | E3: Evidence | F3: Owner | G3: Due Date | H3: Notes
A4: A.2.5.7-01 | B4: Pre-Engagement Disclosure | C4: Before commencing processing on behalf of a customer, the organisation shall disclose to the customer whether any sub-processors are used to process that customer's PII. No customer processing shall begin without this disclosure.
A5: A.2.5.7-02 | B5: Sub-processor Register | C5: The DPO shall maintain a Sub-processor Register listing all sub-processors engaged in PII processing on behalf of customers, including: name and contact details; location (country/jurisdiction); nature of processing; categories of PII processed; and applicable customers or services.
A6: A.2.5.7-03 | B6: Register Availability | C6: The Sub-processor Register shall be made available to customers as part of the processor agreement or as a publicly accessible list. Customers shall be notified of updates per A.2.5.9.
A7: A.2.5.7-04 | B7: Disclosure Documentation | C7: Disclosure of sub-processor use to customers shall be documented, including the date of disclosure, the sub-processors disclosed, and customer acknowledgment where applicable.

Sheet Sub-processor Engagement
A1: Sub-processor Engagement — Compliance Checklist
A2: ISO/IEC 27701:2025 — Controls A.2.5.7-9: Sub-processor Management
A3: Req # | B3: Section | C3: Requirement | D3: Status | E3: Evidence | F3: Owner | G3: Due Date | H3: Notes
A4: A.2.5.8-01 | B4: Customer Authorisation | C4: The organisation shall only engage a sub-processor to process customer PII in accordance with the customer contract — i.e., with the customer's specific or general written authorisation. No sub-processor shall be engaged without documented customer authorisation.
A5: A.2.5.8-02 | B5: Sub-processor Agreement Requirements | C5: Before engaging any sub-processor with access to customer PII, a sub-processor agreement shall be executed imposing the same data protection obligations as those in the organisation's processor agreement with the customer, including: processing only on instruction; appropriate security measures; confidentiality; breach notification; return or deletion of PII; and cooperation with audits.
A6: A.2.5.8-03 | B6: Due Diligence | C6: A security due diligence assessment of the sub-processor shall be conducted before engagement and periodically thereafter. Due diligence records shall be maintained for the duration of the engagement plus 3 years.
A7: A.2.5.8-04 | B7: Sub-sub-processor Restrictions | C7: Sub-processor agreements shall restrict the sub-processor from engaging further sub-sub-processors without the organisation's prior written consent, which in turn requires customer authorisation.
A8: A.2.5.8-05 | B8: Processor Liability | C8: The organisation remains fully liable to customers for the performance of sub-processors' obligations. Sub-processor non-compliance is treated as the organisation's non-compliance for the purposes of the customer contract.

Sheet Sub-processor Changes
A1: Sub-processor Changes — Compliance Checklist
A2: ISO/IEC 27701:2025 — Controls A.2.5.7-9: Sub-processor Management
A3: Req # | B3: Section | C3: Requirement | D3: Status | E3: Evidence | F3: Owner | G3: Due Date | H3: Notes
A4: A.2.5.9-01 | B4: Change Notification Obligation | C4: Where the customer contract includes a general written authorisation for sub-processor engagement, the organisation shall notify customers of any intended addition or replacement of sub-processors in advance of the effective date, giving customers the opportunity to object.
A5: A.2.5.9-02 | B5: Notification Period | C5: The advance notification period for sub-processor changes shall be as specified in the processor agreement (typically minimum 30 days). The notification shall include the identity of the new or replacement sub-processor and the nature of processing to be performed.
A6: A.2.5.9-03 | B6: Objection Handling | C6: The organisation shall have a documented process for handling customer objections to sub-processor changes, which may include implementing alternative technical measures or allowing the customer to terminate the service without penalty. Objections and their outcomes shall be documented.
A7: A.2.5.9-04 | B7: Change Records | C7: All sub-processor changes and associated customer notifications, customer responses (objection or no-objection), and outcomes shall be maintained in the Sub-processor Change Register for 3 years.
