Workbook

Sheet Executive Summary
A1: PRIV-CHK-A.1.3.11 — Automated Decision Making Compliance Checklist
A3: DOCUMENT INFORMATION
A4: Document ID | B4: PRIV-CHK-A.1.3.11
A5: Source Policy | B5: PRIV-POL-A.1.3.11
A6: ISO Controls | B6: Automated Decision Making
A7: Generated | B7: 10.03.2026
A8: Prepared By
A9: Organisation
A10: Review Cycle | B10: Annual
A12: OVERALL COMPLIANCE STATUS
A13: Overall Compliance | B13: ='Dashboard'!G7
A14: Status | B14: =IF(Dashboard!G7="N/A","NOT ASSESSED",IF(ISNUMBER(VALUE(SUBSTITUTE(Dashboard!G7,"%",""))),IF(VALUE(SUBSTITUTE(Dashboard!G7,"%",""))>=90,"GREEN",IF(VALUE(SUBSTITUTE(Dashboard!G7,"%",""))>=70,"AMBER","RED")),"NOT ASSESSED"))
A16: KEY METRICS
A17: Total Requirements | B17: ='Dashboard'!B7
A18: Compliant | B18: ='Dashboard'!C7
A19: Partial | B19: ='Dashboard'!D7
A20: Non-Compliant | B20: ='Dashboard'!E7
A21: Not Applicable | B21: ='Dashboard'!F7
A22: Owner Coverage | B22: =IF(Dashboard!B7=0,"N/A",ROUND((COUNTA('ADM Identification'!F4:F7)+COUNTA('Obligations and Safeguards'!F4:F8)+COUNTA('Transparency and Demonstrability'!F4:F7))/Dashboard!B7*100,0)&"%")
A24: DOMAIN STATUS SUMMARY
A25: Domain | B25: Compliance % | C25: Compliant | D25: Gaps | E25: Status
A26: ADM Identification | B26: ='Dashboard'!G4 | C26: ='Dashboard'!C4 | D26: ='Dashboard'!E4 | E26: =IF(Dashboard!G4="N/A","--",IF(ISNUMBER(VALUE(SUBSTITUTE(Dashboard!G4,"%",""))),IF(VALUE(SUBSTITUTE(Dashboard!G4,"%",""))>=90,"PASS",IF(VALUE(SUBSTITUTE(Dashboard!G4,"%",""))>=70,"REVIEW","FAIL")),"--"))
A27: Obligations and Safeguards | B27: ='Dashboard'!G5 | C27: ='Dashboard'!C5 | D27: ='Dashboard'!E5 | E27: =IF(Dashboard!G5="N/A","--",IF(ISNUMBER(VALUE(SUBSTITUTE(Dashboard!G5,"%",""))),IF(VALUE(SUBSTITUTE(Dashboard!G5,"%",""))>=90,"PASS",IF(VALUE(SUBSTITUTE(Dashboard!G5,"%",""))>=70,"REVIEW","FAIL")),"--"))
A28: Transparency and Demonstrability | B28: ='Dashboard'!G6 | C28: ='Dashboard'!C6 | D28: ='Dashboard'!E6 | E28: =IF(Dashboard!G6="N/A","--",IF(ISNUMBER(VALUE(SUBSTITUTE(Dashboard!G6,"%",""))),IF(VALUE(SUBSTITUTE(Dashboard!G6,"%",""))>=90,"PASS",IF(VALUE(SUBSTITUTE(Dashboard!G6,"%",""))>=70,"REVIEW","FAIL")),"--"))
A30: CRITICAL ISSUES
A31: # | B31: Issue Description | C31: Domain | D31: Owner | E31: Due Date
A32: 1
A33: 2
A34: 3
A35: 4
A36: 5
A38: MANAGEMENT COMMENTARY
A39: [Enter management commentary on automated decision making posture]
A43: APPROVAL
A44: Assessed By
A45: Name:
A46: Date:
A47: Signature:
A48: Decision:
A50: Reviewed By (DPO)
...

Sheet Dashboard
A1: Automated Decision Making — Compliance Dashboard
A3: Domain | B3: Total Reqs | C3: Compliant | D3: Partial | E3: Non-Compliant | F3: N/A | G3: Compliance %
A4: ADM Identification | B4: =COUNTA('ADM Identification'!D4:D7) | C4: =COUNTIF('ADM Identification'!D4:D7,"Compliant") | D4: =COUNTIF('ADM Identification'!D4:D7,"Partial") | E4: =COUNTIF('ADM Identification'!D4:D7,"Non-Compliant") | F4: =COUNTIF('ADM Identification'!D4:D7,"N/A") | G4: =IF((B4-F4)=0,"N/A",ROUND(C4/(B4-F4)*100,1)&"%")
A5: Obligations and Safeguards | B5: =COUNTA('Obligations and Safeguards'!D4:D8) | C5: =COUNTIF('Obligations and Safeguards'!D4:D8,"Compliant") | D5: =COUNTIF('Obligations and Safeguards'!D4:D8,"Partial") | E5: =COUNTIF('Obligations and Safeguards'!D4:D8,"Non-Compliant") | F5: =COUNTIF('Obligations and Safeguards'!D4:D8,"N/A") | G5: =IF((B5-F5)=0,"N/A",ROUND(C5/(B5-F5)*100,1)&"%")
A6: Transparency and Demonstrability | B6: =COUNTA('Transparency and Demonstrability'!D4:D7) | C6: =COUNTIF('Transparency and Demonstrability'!D4:D7,"Compliant") | D6: =COUNTIF('Transparency and Demonstrability'!D4:D7,"Partial") | E6: =COUNTIF('Transparency and Demonstrability'!D4:D7,"Non-Compliant") | F6: =COUNTIF('Transparency and Demonstrability'!D4:D7,"N/A") | G6: =IF((B6-F6)=0,"N/A",ROUND(C6/(B6-F6)*100,1)&"%")
A7: TOTAL | B7: =SUM(B4:B6) | C7: =SUM(C4:C6) | D7: =SUM(D4:D6) | E7: =SUM(E4:E6) | F7: =SUM(F4:F6) | G7: =IF((B7-F7)=0,"N/A",ROUND(C7/(B7-F7)*100,1)&"%")
A9: COMPLIANCE BY STATUS
A10: Compliant | B10: =C7 | C10: =IF(B7=0,"",ROUND(B10/B7*100,1)&"%")
A11: Partial | B11: =D7 | C11: =IF(B7=0,"",ROUND(B11/B7*100,1)&"%")
A12: Non-Compliant | B12: =E7 | C12: =IF(B7=0,"",ROUND(B12/B7*100,1)&"%")
A13: N/A | B13: =F7 | C13: =IF(B7=0,"",ROUND(B13/B7*100,1)&"%")
A15: TOP GAPS (Manual Entry)
A16: Priority | B16: Domain | C16: Requirement | D16: Owner | E16: Due Date | F16: Status
A28: COMPLIANCE TREND (Manual Entry)
A29: Assessment Date | B29: Overall % | C29: Compliant | D29: Gaps | E29: Assessor | F29: Notes

Sheet ADM Identification
A1: ADM Identification — Compliance Checklist
A2: ISO/IEC 27701:2025 — Controls A.1.3.11: Automated Decision Making
A3: Req # | B3: Section | C3: Requirement | D3: Status | E3: Evidence | F3: Owner | G3: Due Date | H3: Notes
A4: A.1.3.11-01 | B4: ADM Scope Identification | C4: The organisation shall identify and document all processing activities where decisions are made based solely on automated processing of PII (without meaningful human involvement) AND those decisions produce legal effects or similarly significant effects on data subjects.
A5: A.1.3.11-02 | B5: ADM Register | C5: The DPO shall maintain an ADM Register listing all in-scope automated decision-making activities. The register shall be updated whenever new ADM activities are deployed or existing ones are materially changed.
A6: A.1.3.11-03 | B6: DPO Approval for New ADM | C6: New ADM activities shall be notified to and approved by the DPO before deployment. Development and product teams shall flag ADM activities during product design, not after deployment.
A7: A.1.3.11-04 | B7: Special Category PII in ADM | C7: ADM activities that process special category PII require an Article 9(2) condition in addition to an Article 22 exception, explicit DPO approval, and in most cases a DPIA (per PRIV-POL-A.1.2.6-9).

Sheet Obligations and Safeguards
A1: Obligations and Safeguards — Compliance Checklist
A2: ISO/IEC 27701:2025 — Controls A.1.3.11: Automated Decision Making
A3: Req # | B3: Section | C3: Requirement | D3: Status | E3: Evidence | F3: Owner | G3: Due Date | H3: Notes
A4: A.1.3.11-05 | B4: Obligations Identification | C4: For each ADM activity, the organisation shall identify and document: the right not to be subject to the decision (Article 22(1)); the applicable Article 22 exception (contract, law, or explicit consent); and safeguards required where an exception is invoked.
A5: A.1.3.11-06 | B5: Article 22 Exception Documentation | C5: Where an exception to Article 22 is invoked, the specific exception (necessary for contract, authorised by law, or explicit consent) shall be documented in the ADM Register with supporting evidence of the applicable exception.
A6: A.1.3.11-07 | B6: Human Review Right | C6: Where ADM produces significant effects and an Article 22 exception is invoked, a mechanism for data subjects to request human intervention shall be implemented — meaning a named person reviews the automated output before the decision is finalised or reconsidered.
A7: A.1.3.11-08 | B7: Point of View and Contestation | C7: Where ADM produces significant effects and an Article 22 exception is invoked, mechanisms for data subjects to express their point of view about the decision and to contest the automated decision shall be implemented and communicated to data subjects.
A8: A.1.3.11-09 | B8: Safeguards Communication | C8: Safeguards (human review, point of view, contestation) shall be communicated to data subjects in the privacy notice and upon the automated decision being communicated to them.

Sheet Transparency and Demonstrability
A1: Transparency and Demonstrability — Compliance Checklist
A2: ISO/IEC 27701:2025 — Controls A.1.3.11: Automated Decision Making
A3: Req # | B3: Section | C3: Requirement | D3: Status | E3: Evidence | F3: Owner | G3: Due Date | H3: Notes
A4: A.1.3.11-10 | B4: Transparency Information | C4: For each ADM activity in scope, the transparency information provided to data subjects shall include: the existence of automated decision-making; meaningful information about the logic involved (at a level data subjects can understand); and the significance and envisaged consequences of such processing.
A5: A.1.3.11-11 | B5: Privacy Notice Coverage | C5: The organisation's privacy notice shall include ADM transparency information covering all in-scope ADM activities. The information shall be updated whenever the ADM activities or their logic changes materially.
A6: A.1.3.11-12 | B6: Demonstrability | C6: The organisation shall be able to demonstrate how it addresses its obligations for each ADM activity at any time, to supervisory authorities, data subjects, and certification auditors. The ADM Register and associated documentation (including DPIAs where conducted) are the primary demonstrability evidence.
A7: A.1.3.11-13 | B7: ADM Review | C7: ADM activities and their associated obligations documentation shall be reviewed at minimum annually, when the underlying processing or algorithm changes materially, and following any supervisory authority guidance on automated decision-making.
