Workbook

Sheet Executive Summary
A1: ISMS-OP-CHK-A.7.10 — Storage Media Compliance Checklist
A3: DOCUMENT INFORMATION
A4: Document ID | B4: ISMS-OP-CHK-A.7.10
A5: Source Policy | B5: ISMS-OP-POL-A.7.10
A6: ISO Controls | B6: Storage Media
A7: Generated | B7: 30.09.2026
A8: Prepared By
A9: Organisation
A10: Review Cycle | B10: Annual
A12: OVERALL COMPLIANCE STATUS
A13: Overall Compliance | B13: ='Dashboard'!G11
A14: Status | B14: =IF(Dashboard!H11>0,"INCOMPLETE",IF(Dashboard!G11="N/A","NOT ASSESSED",IF(ISNUMBER(VALUE(SUBSTITUTE(Dashboard!G11,"%",""))),IF(VALUE(SUBSTITUTE(Dashboard!G11,"%",""))>=90,"GREEN",IF(VALUE(SUBSTITUTE(Dashboard!G11,"%",""))>=70,"AMBER","RED")),"NOT ASSESSED")))
A16: KEY METRICS
A17: Total Requirements | B17: ='Dashboard'!B11
A18: Compliant | B18: ='Dashboard'!C11
A19: Partial | B19: ='Dashboard'!D11
A20: Non-Compliant | B20: ='Dashboard'!E11
A21: Not Applicable | B21: ='Dashboard'!F11
A22: Unanswered | B22: ='Dashboard'!H11
A23: Owner Coverage | B23: =IF(Dashboard!B11=0,"N/A",ROUND((COUNTA('Removable Media Management'!F4:F17)+COUNTA('Media Use Requirements'!F4:F13)+COUNTA('Transportation of Storage Media'!F4:F13)+COUNTA('Storage Requirements'!F4:F11)+COUNTA('Disposal of Storage Media'!F4:F21)+COUNTA('Paper Documents & Physical'!F4:F13)+COUNTA('Optional Payment Card Data'!F4:F8))/Dashboard!B11*100,0)&"%")
A25: DOMAIN STATUS SUMMARY
A26: Domain | B26: Compliance % | C26: Compliant | D26: Gaps | E26: Status
A27: Removable Media Management | B27: ='Dashboard'!G4 | C27: ='Dashboard'!C4 | D27: ='Dashboard'!E4 | E27: =IF(Dashboard!H4>0,"INCOMPLETE",IF(Dashboard!G4="N/A","--",IF(ISNUMBER(VALUE(SUBSTITUTE(Dashboard!G4,"%",""))),IF(VALUE(SUBSTITUTE(Dashboard!G4,"%",""))>=90,"PASS",IF(VALUE(SUBSTITUTE(Dashboard!G4,"%",""))>=70,"REVIEW","FAIL")),"--")))
A28: Media Use Requirements | B28: ='Dashboard'!G5 | C28: ='Dashboard'!C5 | D28: ='Dashboard'!E5 | E28: =IF(Dashboard!H5>0,"INCOMPLETE",IF(Dashboard!G5="N/A","--",IF(ISNUMBER(VALUE(SUBSTITUTE(Dashboard!G5,"%",""))),IF(VALUE(SUBSTITUTE(Dashboard!G5,"%",""))>=90,"PASS",IF(VALUE(SUBSTITUTE(Dashboard!G5,"%",""))>=70,"REVIEW","FAIL")),"--")))
A29: Transportation of Storage Media | B29: ='Dashboard'!G6 | C29: ='Dashboard'!C6 | D29: ='Dashboard'!E6 | E29: =IF(Dashboard!H6>0,"INCOMPLETE",IF(Dashboard!G6="N/A","--",IF(ISNUMBER(VALUE(SUBSTITUTE(Dashboard!G6,"%",""))),IF(VALUE(SUBSTITUTE(Dashboard!G6,"%",""))>=90,"PASS",IF(VALUE(SUBSTITUTE(Dashboard!G6,"%",""))>=70,"REVIEW","FAIL")),"--")))
A30: Storage Requirements | B30: ='Dashboard'!G7 | C30: ='Dashboard'!C7 | D30: ='Dashboard'!E7 | E30: =IF(Dashboard!H7>0,"INCOMPLETE",IF(Dashboard!G7="N/A","--",IF(ISNUMBER(VALUE(SUBSTITUTE(Dashboard!G7,"%",""))),IF(VALUE(SUBSTITUTE(Dashboard!G7,"%",""))>=90,"PASS",IF(VALUE(SUBSTITUTE(Dashboard!G7,"%",""))>=70,"REVIEW","FAIL")),"--")))
A31: Disposal of Storage Media | B31: ='Dashboard'!G8 | C31: ='Dashboard'!C8 | D31: ='Dashboard'!E8 | E31: =IF(Dashboard!H8>0,"INCOMPLETE",IF(Dashboard!G8="N/A","--",IF(ISNUMBER(VALUE(SUBSTITUTE(Dashboard!G8,"%",""))),IF(VALUE(SUBSTITUTE(Dashboard!G8,"%",""))>=90,"PASS",IF(VALUE(SUBSTITUTE(Dashboard!G8,"%",""))>=70,"REVIEW","FAIL")),"--")))
A32: Paper Documents & Physical | B32: ='Dashboard'!G9 | C32: ='Dashboard'!C9 | D32: ='Dashboard'!E9 | E32: =IF(Dashboard!H9>0,"INCOMPLETE",IF(Dashboard!G9="N/A","--",IF(ISNUMBER(VALUE(SUBSTITUTE(Dashboard!G9,"%",""))),IF(VALUE(SUBSTITUTE(Dashboard!G9,"%",""))>=90,"PASS",IF(VALUE(SUBSTITUTE(Dashboard!G9,"%",""))>=70,"REVIEW","FAIL")),"--")))
A33: Optional Payment Card Data | B33: ='Dashboard'!G10 | C33: ='Dashboard'!C10 | D33: ='Dashboard'!E10 | E33: =IF(Dashboard!H10>0,"INCOMPLETE",IF(Dashboard!G10="N/A","--",IF(ISNUMBER(VALUE(SUBSTITUTE(Dashboard!G10,"%",""))),IF(VALUE(SUBSTITUTE(Dashboard!G10,"%",""))>=90,"PASS",IF(VALUE(SUBSTITUTE(Dashboard!G10,"%",""))>=70,"REVIEW","FAIL")),"--")))
A35: CRITICAL ISSUES
A36: # | B36: Issue Description | C36: Domain | D36: Owner | E36: Due Date
A37: 1
A38: 2
A39: 3
A40: 4
A41: 5
A43: MANAGEMENT COMMENTARY
A44: [Enter management commentary on storage media posture]
A48: APPROVAL
A49: Assessed By
...

Sheet Dashboard
A1: Storage Media — Compliance Dashboard
A3: Domain | B3: Total Reqs | C3: Compliant | D3: Partial | E3: Non-Compliant | F3: N/A | G3: Compliance % | H3: Unassessed
A4: Removable Media Management | B4: =COUNTA('Removable Media Management'!A4:A17) | C4: =COUNTIF('Removable Media Management'!D4:D17,"Compliant") | D4: =COUNTIF('Removable Media Management'!D4:D17,"Partial") | E4: =COUNTIF('Removable Media Management'!D4:D17,"Non-Compliant") | F4: =COUNTIF('Removable Media Management'!D4:D17,"N/A") | G4: =IF((B4-F4)=0,"N/A",ROUND(C4/(B4-F4)*100,1)&"%") | H4: =B4-(C4+D4+E4+F4)
A5: Media Use Requirements | B5: =COUNTA('Media Use Requirements'!A4:A13) | C5: =COUNTIF('Media Use Requirements'!D4:D13,"Compliant") | D5: =COUNTIF('Media Use Requirements'!D4:D13,"Partial") | E5: =COUNTIF('Media Use Requirements'!D4:D13,"Non-Compliant") | F5: =COUNTIF('Media Use Requirements'!D4:D13,"N/A") | G5: =IF((B5-F5)=0,"N/A",ROUND(C5/(B5-F5)*100,1)&"%") | H5: =B5-(C5+D5+E5+F5)
A6: Transportation of Storage Media | B6: =COUNTA('Transportation of Storage Media'!A4:A13) | C6: =COUNTIF('Transportation of Storage Media'!D4:D13,"Compliant") | D6: =COUNTIF('Transportation of Storage Media'!D4:D13,"Partial") | E6: =COUNTIF('Transportation of Storage Media'!D4:D13,"Non-Compliant") | F6: =COUNTIF('Transportation of Storage Media'!D4:D13,"N/A") | G6: =IF((B6-F6)=0,"N/A",ROUND(C6/(B6-F6)*100,1)&"%") | H6: =B6-(C6+D6+E6+F6)
A7: Storage Requirements | B7: =COUNTA('Storage Requirements'!A4:A11) | C7: =COUNTIF('Storage Requirements'!D4:D11,"Compliant") | D7: =COUNTIF('Storage Requirements'!D4:D11,"Partial") | E7: =COUNTIF('Storage Requirements'!D4:D11,"Non-Compliant") | F7: =COUNTIF('Storage Requirements'!D4:D11,"N/A") | G7: =IF((B7-F7)=0,"N/A",ROUND(C7/(B7-F7)*100,1)&"%") | H7: =B7-(C7+D7+E7+F7)
A8: Disposal of Storage Media | B8: =COUNTA('Disposal of Storage Media'!A4:A21) | C8: =COUNTIF('Disposal of Storage Media'!D4:D21,"Compliant") | D8: =COUNTIF('Disposal of Storage Media'!D4:D21,"Partial") | E8: =COUNTIF('Disposal of Storage Media'!D4:D21,"Non-Compliant") | F8: =COUNTIF('Disposal of Storage Media'!D4:D21,"N/A") | G8: =IF((B8-F8)=0,"N/A",ROUND(C8/(B8-F8)*100,1)&"%") | H8: =B8-(C8+D8+E8+F8)
A9: Paper Documents & Physical | B9: =COUNTA('Paper Documents & Physical'!A4:A13) | C9: =COUNTIF('Paper Documents & Physical'!D4:D13,"Compliant") | D9: =COUNTIF('Paper Documents & Physical'!D4:D13,"Partial") | E9: =COUNTIF('Paper Documents & Physical'!D4:D13,"Non-Compliant") | F9: =COUNTIF('Paper Documents & Physical'!D4:D13,"N/A") | G9: =IF((B9-F9)=0,"N/A",ROUND(C9/(B9-F9)*100,1)&"%") | H9: =B9-(C9+D9+E9+F9)
A10: Optional Payment Card Data | B10: =COUNTA('Optional Payment Card Data'!A4:A8) | C10: =COUNTIF('Optional Payment Card Data'!D4:D8,"Compliant") | D10: =COUNTIF('Optional Payment Card Data'!D4:D8,"Partial") | E10: =COUNTIF('Optional Payment Card Data'!D4:D8,"Non-Compliant") | F10: =COUNTIF('Optional Payment Card Data'!D4:D8,"N/A") | G10: =IF((B10-F10)=0,"N/A",ROUND(C10/(B10-F10)*100,1)&"%") | H10: =B10-(C10+D10+E10+F10)
A11: TOTAL | B11: =SUM(B4:B10) | C11: =SUM(C4:C10) | D11: =SUM(D4:D10) | E11: =SUM(E4:E10) | F11: =SUM(F4:F10) | G11: =IF((B11-F11)=0,"N/A",ROUND(C11/(B11-F11)*100,1)&"%") | H11: =SUM(H4:H10)
A13: COMPLIANCE BY STATUS
A14: Compliant | B14: =C11 | C14: =IF(B11=0,"",ROUND(B14/B11*100,1)&"%")
A15: Partial | B15: =D11 | C15: =IF(B11=0,"",ROUND(B15/B11*100,1)&"%")
A16: Non-Compliant | B16: =E11 | C16: =IF(B11=0,"",ROUND(B16/B11*100,1)&"%")
A17: N/A | B17: =F11 | C17: =IF(B11=0,"",ROUND(B17/B11*100,1)&"%")
A19: TOP GAPS (Manual Entry)
A20: Priority | B20: Domain | C20: Requirement | D20: Owner | E20: Due Date | F20: Status
A32: COMPLIANCE TREND (Manual Entry)
A33: Assessment Date | B33: Overall % | C33: Compliant | D33: Gaps | E33: Assessor | F33: Notes

Sheet Removable Media Management
A1: Removable Media Management — Compliance Checklist
A2: ISO/IEC 27001:2022 — Control A.7.10: Storage Media
A3: Req # | B3: Section | C3: Requirement | D3: Status | E3: Evidence | F3: Owner | G3: Due Date | H3: Notes
A4: A.7.10-01 | B4: Use Of Removable Storage Media | C4: Use of removable storage media shall be authorised before deployment:.
A5: A.7.10-02 | B5: Obtain Authorisation From Their Line | C5: Employees shall obtain authorisation from their line manager before using any removable storage media for organisation data. Authorisation shall specify the permitted use case, data classification, and duration (default 12 months, maximum 24 months).
A6: A.7.10-03 | B6: Removable Media | C6: All removable media shall be registered in [Asset Management System] with the following details: media type, capacity, serial number or asset tag, assigned user, purpose, maximum classification level of data to be stored, and authorisation expiration date.
A7: A.7.10-04 | B7: Only Organisation-Issued Or | C7: Only organisation-issued or organisation-approved removable media shall be used for organisation data. Personal USB drives, external hard drives, or other personal storage devices shall not be used for CONFIDENTIAL or INTERNAL data under any circumstances.
A8: A.7.10-05 | B8: Organisation-Issued Removable Media | C8: Organisation-issued removable media shall be procured through approved suppliers from the organisation's procurement process. Unapproved or unknown-origin media shall not be connected to organisation systems.
A9: A.7.10-06 | B9: Maintain A List Of Approved Removable | C9: The organisation shall maintain a list of approved removable media types. As a minimum:.
A10: A.7.10-07 | B10: Be Encrypted Before First Use (Not | C10: Media shall be encrypted before first use (not encrypted after data is already written — residual unencrypted data risk).
A11: A.7.10-08 | B11: Migration To Hardware Encryption: | C11: Migration to hardware encryption: Software-encrypted exceptions shall be phased out as hardware-encrypted media becomes available (target: all INTERNAL data on hardware encryption within 12 months).
A12: A.7.10-09 | B12: Sd/Microsd Cards: Permitted Only For | C12: SD/microSD cards: Permitted only for specific approved purposes (e.g., cameras, embedded systems). Shall be encrypted where the device supports it.
A13: A.7.10-10 | B13: Unencrypted Removable Media | C13: Unencrypted removable media shall not be used for CONFIDENTIAL data. Exceptions require documented CISO approval with compensating controls and a time limit not exceeding 6 months.
A14: A.7.10-11 | B14: The Approved Media List | C14: The approved media list shall be reviewed and maintained on a regular cycle:.
A15: A.7.10-12 | B15: Approval Process: It Operations Proposes | C15: Approval process: IT Operations proposes additions or removals with technical assessment; CISO approves changes; Procurement updates preferred supplier list; approved media list published on intranet and communicated to all staff. List shall include version date and next review date.
... A17: A.7.10-14 | B17: Audit Results | C17: Audit results shall be documented and retained for 12 months.

Sheet Media Use Requirements
A1: Media Use Requirements — Compliance Checklist
A2: ISO/IEC 27001:2022 — Control A.7.10: Storage Media
A3: Req # | B3: Section | C3: Requirement | D3: Status | E3: Evidence | F3: Owner | G3: Due Date | H3: Notes
A4: A.7.10-15 | B4: Transfer Of Confidential Data To | C4: Transfer of CONFIDENTIAL data to removable media requires documented management approval prior to transfer. The approval record shall state the business justification, recipient, and expected return date.
A5: A.7.10-16 | B5: Data Transferred To Removable Media | C5: All data transferred to removable media shall be encrypted. For CONFIDENTIAL data, AES-256 encryption (hardware or software) is mandatory. For INTERNAL data, AES-128 or stronger is required.
A6: A.7.10-17 | B6: Transfer Logs | C6: Transfer logs shall be maintained for CONFIDENTIAL data, recording: date, user, media identifier, data description, and recipient.
A7: A.7.10-18 | B7: Be Removed From Removable Media As | C7: Data shall be removed from removable media as soon as it is no longer needed for the approved purpose.
A8: A.7.10-19 | B8: Media | C8: Media containing CONFIDENTIAL data shall be password-protected or encrypted with strong authentication (PIN, passphrase, or biometric unlock on the device).
A9: A.7.10-20 | B9: Not Be Left Unattended At Any | C9: Media shall not be left unattended at any time. When not in active use, media shall be secured in locked storage appropriate to the classification level.
A10: A.7.10-21 | B10: Removable Media | C10: Removable media shall not be connected to untrusted or public systems.
A11: A.7.10-22 | B11: Media Contents | C11: Media contents shall be scanned for malware by [Endpoint Protection Tool] before data is opened or transferred to organisation systems. Auto-run and auto-play shall be disabled on all endpoints via [Endpoint Management Tool] policy.
A12: A.7.10-23 | B12: Usb Ports And Removable Media Access | C12: USB ports and removable media access shall be managed centrally via [Endpoint Management Tool] (e.g., Group Policy, MDM, or endpoint protection platform).
A13: A.7.10-24 | B13: Usb Connection Events | C13: All USB connection events shall be logged by the endpoint protection platform. Logs shall be retained for a minimum of 12 months.

Sheet Transportation of Storage Media
A1: Transportation of Storage Media — Compliance Checklist
A2: ISO/IEC 27001:2022 — Control A.7.10: Storage Media
A3: Req # | B3: Section | C3: Requirement | D3: Status | E3: Evidence | F3: Owner | G3: Due Date | H3: Notes
A4: A.7.10-25 | B4: Confidential Media | C4: CONFIDENTIAL media shall be transported only by approved secure courier services with tracking and signature on delivery. Standard postal services shall not be used for CONFIDENTIAL data.
A5: A.7.10-26 | B5: Tamper-Evident Packaging | C5: Tamper-evident packaging shall be used for all media containing CONFIDENTIAL data. The recipient shall inspect packaging for evidence of tampering and report any anomalies immediately.
A6: A.7.10-27 | B6: Chain Of Custody Documentation | C6: Chain of custody documentation shall accompany all shipments of CONFIDENTIAL media (see Chain of Custody section below).
A7: A.7.10-28 | B7: Be Carried In Hand Luggage During | C7: Media shall be carried in hand luggage during travel (never in checked baggage).
A8: A.7.10-29 | B8: Be Encrypted And | C8: Media shall be encrypted and shall not be left unattended at any time during transport.
A9: A.7.10-30 | B9: Transport Through High-Risk Areas | C9: Transport through high-risk areas (public transport hubs, conferences, foreign jurisdictions without adequate data protection) should be avoided where alternatives exist. Where unavoidable, additional encryption and access controls shall be applied.
A10: A.7.10-31 | B10: Courier Instructions For Confidential | C10: Courier instructions for CONFIDENTIAL media: Provide handling instructions to courier; require signature on delivery (no 'leave at door'); track shipment in real time; investigate if delivery delayed >24 hours. Recipient shall inspect packaging for damage upon receipt and report any physical damage immediately.
A11: A.7.10-32 | B11: Transfers Of Media | C11: All transfers of media containing CONFIDENTIAL data between individuals, locations, or organisations shall be documented with:.
A12: A.7.10-33 | B12: Chain Of Custody Records | C12: Chain of custody records shall be retained for 7 years.
A13: A.7.10-34 | B13: Logical Data Transfer Chain Of Custody* | C13: Logical data transfer chain of custody*: Where data is transferred electronically rather than via physical media, chain of custody shall also be documented:.

Sheet Storage Requirements
A1: Storage Requirements — Compliance Checklist
A2: ISO/IEC 27001:2022 — Control A.7.10: Storage Media
A3: Req # | B3: Section | C3: Requirement | D3: Status | E3: Evidence | F3: Owner | G3: Due Date | H3: Notes
A4: A.7.10-35 | B4: Storage Media | C4: Storage media shall be stored in conditions appropriate to both the sensitivity of the information and the physical integrity of the medium:.
A5: A.7.10-36 | B5: Backup Tapes And Cartridges | C5: Backup tapes and cartridges shall be stored in a separate physical location from the systems they back up (off-site or in a separate fire zone).
A6: A.7.10-37 | B6: Backup Media | C6: Backup media shall be encrypted using strong vendor encryption or an organisation-approved encryption tool.
A7: A.7.10-38 | B7: Backup Media | C7: Backup media shall be included in the media inventory and subject to the same quarterly audit as removable media.
A8: A.7.10-39 | B8: Be Retained In Accordance With The | C8: Media shall be retained in accordance with the organisation's data retention schedule. Retention periods are defined by data type, regulatory requirement, and business need.
A9: A.7.10-40 | B9: The Medium | C9: When the retention period for data on a medium expires, the medium shall be sanitised or destroyed per the Disposal section of this policy.
A10: A.7.10-41 | B10: Backup Tapes And Cloud Snapshots | C10: Backup tapes and cloud snapshots shall have documented disposal or deletion triggers aligned with the retention schedule. 'Indefinite' retention is not permitted without documented CISO approval and annual review.
A11: A.7.10-42 | B11: Legal Hold Exception*: If Data Subject | C11: Legal hold exception*: If data subject to legal hold (litigation, investigation, audit), backup deletion shall be suspended for affected data. Legal hold documented in [Asset Management System] with hold reason, start date, and review date. Resumption of deletion requires Legal/Compliance approval.

Sheet Disposal of Storage Media
A1: Disposal of Storage Media — Compliance Checklist
A2: ISO/IEC 27001:2022 — Control A.7.10: Storage Media
A3: Req # | B3: Section | C3: Requirement | D3: Status | E3: Evidence | F3: Owner | G3: Due Date | H3: Notes
A4: A.7.10-43 | B4: Disposal And Sanitisation | C4: Disposal and sanitisation shall ensure that information cannot be recovered, using organisation-approved methods appropriate to the media type and the highest classification of data ever stored on the medium.
A5: A.7.10-44 | B5: Hdd Overwrite — Nist Sp 800-88 | C5: HDD overwrite — NIST SP 800-88 Rev. 2 guidance*: NIST SP 800-88 Rev. 2 (September 2025) confirms that a single-pass overwrite is sufficient for modern HDDs (post-2001 manufacturing). Multi-pass overwrite (e.g., legacy DoD 5220.22-M 3-pass or 7-pass methods) is no longer required and provides no additional security benefit on modern drives. Approved Purge methods for HDDs: manufacturer secure erase command (ATA Secure Erase, NVMe Sanitize), or single-pass overwrite with verification using an approved tool (e.g., DBAN, nwipe, shred, or dd). Verification shall include tool completion report with serial number, timestamp, and pass/fail status.
A6: A.7.10-45 | B6: Degaussing Requirements For Magnetic | C6: Degaussing requirements for magnetic media*: Degaussing effectiveness depends on the magnetic field strength of the degausser relative to the coercivity of the media. The degausser shall be rated for the media type being sanitised:.
A7: A.7.10-46 | B7: Degausser Validation: Degaussing | C7: Degausser validation: Degaussing equipment shall be tested annually (or per manufacturer recommendations) to verify field strength remains within specification. Testing records shall be retained. SSDs and flash media cannot be degaussed — degaussing has no effect on solid-state storage.
A8: A.7.10-47 | B8: Cloud And Virtual Storage Disposal*: | C8: Cloud and virtual storage disposal*: Major cloud providers (AWS, Azure, GCP) do not provide individual destruction certificates for virtual storage. For cloud disposal, the organisation shall:.
A9: A.7.10-48 | B9: Executive Management | C9: Executive Management shall acknowledge reliance on provider-certified deletion processes annually in the Management Review.
A10: A.7.10-49 | B10: Be Securely Erased Using An Approved | C10: All data shall be securely erased using an approved method appropriate to the previous data classification.
A11: A.7.10-50 | B11: Be Verified Using [Secure Wipe Tool] | C11: Erasure shall be verified using [Secure Wipe Tool] and the verification log retained.
A12: A.7.10-51 | B12: Be Inspected For Physical Integrity. | C12: Media shall be inspected for physical integrity. Damaged media shall not be re-used but destroyed.
A13: A.7.10-52 | B13: [Asset Management System] Records | C13: [Asset Management System] records shall be updated with the new assignment, date, and sanitisation evidence.
A14: A.7.10-53 | B14: Licensed Software | C14: Licensed software shall be transferred or removed per licensing terms.
A15: A.7.10-54 | B15: Media Being Disposed Of Externally | C15: Media being disposed of externally shall:.
... A21: A.7.10-60 | B21: Be Filed With The Disposal Record | C21: Certificates shall be filed with the disposal record and retained for 7 years.

Sheet Paper Documents & Physical
A1: Paper Documents & Physical — Compliance Checklist
A2: ISO/IEC 27001:2022 — Control A.7.10: Storage Media
A3: Req # | B3: Section | C3: Requirement | D3: Status | E3: Evidence | F3: Owner | G3: Due Date | H3: Notes
A4: A.7.10-61 | B4: Paper Documents | C4: Paper documents shall be classified and handled per the Information Classification and Handling Policy.
A5: A.7.10-62 | B5: Confidential Documents | C5: CONFIDENTIAL documents shall be stored in locked cabinets or safes when not in immediate active use:.
A6: A.7.10-63 | B6: Be Collected Immediately From Printers, | C6: Documents shall be collected immediately from printers, copiers, and fax machines. Secure print release (pull printing) should be implemented where available.
A7: A.7.10-64 | B7: Clean Desk Policy | C7: Clean desk policy shall be followed at all times (see Secure Areas and Media Handling Policy, A.7.6–7–14).
A8: A.7.10-65 | B8: Paper Destruction | C8: Paper destruction shall comply with DIN 66399 standards. DIN 66399 defines security levels using a letter prefix for the media category (P = paper) and a number for the security level (1–7, higher = smaller particles):.
A9: A.7.10-66 | B9: Be Performed On-Site Using | C9: Shredding shall be performed on-site using organisation-owned shredders where possible. For bulk destruction, approved external providers may be used with collection in locked confidential waste bins and certificates of destruction.
A10: A.7.10-67 | B10: Confidential Waste Bins | C10: Confidential waste bins shall be provided at accessible locations throughout the office. Bins shall be locked and emptied on a scheduled basis by authorised personnel or [Destruction Vendor].
A11: A.7.10-68 | B11: Mass Destruction Events (Office Moves, | C11: Mass destruction events (office moves, archive purges) shall be witnessed or certified.
A12: A.7.10-69 | B12: Follow Din 66399 Media Category F | C12: Destruction shall follow DIN 66399 media category F (film) at security levels corresponding to the classification of the information.
A13: A.7.10-70 | B13: An Approved External Vendor | C13: Where on-site shredding of film media is not possible, an approved external vendor shall be used.

Sheet Optional Payment Card Data
A1: Optional Payment Card Data — Compliance Checklist
A2: ISO/IEC 27001:2022 — Control A.7.10: Storage Media
A3: Req # | B3: Section | C3: Requirement | D3: Status | E3: Evidence | F3: Owner | G3: Due Date | H3: Notes
A4: A.7.10-71 | B4: The Following Additional Requirements | C4: If PCI DSS scope applies, the following additional requirements shall be met:.
A5: A.7.10-72 | B5: Media | C5: Media containing cardholder data shall be physically destroyed when no longer needed for business or legal reasons (PCI DSS Requirement 9.4).
A6: A.7.10-73 | B6: An Inventory Of Media | C6: An inventory of media containing cardholder data shall be maintained and reconciled at least annually (PCI DSS Requirement 9.4.1).
A7: A.7.10-74 | B7: Secure Disposal Of Cardholder Data Media | C7: Secure disposal of cardholder data media shall be documented with destruction certificates (PCI DSS Requirement 9.4.7).
A8: A.7.10-75 | B8: Internal And External Transport Of Media | C8: Internal and external transport of media containing cardholder data shall use secure courier and be logged (PCI DSS Requirement 9.4.3–9.4.4).
