Workbook

Sheet Executive Summary
A1: CLD-SEC-CHK-A.8.35 — Segregation in Virtual Computing Environments Compliance Checklist
A3: DOCUMENT INFORMATION
A4: Document ID | B4: CLD-SEC-CHK-A.8.35
A5: Source Policy | B5: CLD-SEC-POL-A.8.35
A6: ISO Controls | B6: Segregation in Virtual Computing Environments
A7: Generated | B7: 01.08.2026
A8: Prepared By
A9: Organisation
A10: Review Cycle | B10: Annual
A12: OVERALL COMPLIANCE STATUS
A13: Overall Compliance | B13: ='Dashboard'!G6
A14: Status | B14: =IF(Dashboard!G6="N/A","NOT ASSESSED",IF(ISNUMBER(VALUE(SUBSTITUTE(Dashboard!G6,"%",""))),IF(VALUE(SUBSTITUTE(Dashboard!G6,"%",""))>=90,"GREEN",IF(VALUE(SUBSTITUTE(Dashboard!G6,"%",""))>=70,"AMBER","RED")),"NOT ASSESSED"))
A16: KEY METRICS
A17: Total Requirements | B17: ='Dashboard'!B6
A18: Compliant | B18: ='Dashboard'!C6
A19: Partial | B19: ='Dashboard'!D6
A20: Non-Compliant | B20: ='Dashboard'!E6
A21: Not Applicable | B21: ='Dashboard'!F6
A22: Owner Coverage | B22: =IF(Dashboard!B6=0,"N/A",ROUND((COUNTA('CSC Obligations'!F4:F7)+COUNTA('CSP Obligations'!F4:F7))/Dashboard!B6*100,0)&"%")
A24: DOMAIN STATUS SUMMARY
A25: Domain | B25: Compliance % | C25: Compliant | D25: Gaps | E25: Status
A26: CSC Obligations | B26: ='Dashboard'!G4 | C26: ='Dashboard'!C4 | D26: ='Dashboard'!E4 | E26: =IF(Dashboard!G4="N/A","--",IF(ISNUMBER(VALUE(SUBSTITUTE(Dashboard!G4,"%",""))),IF(VALUE(SUBSTITUTE(Dashboard!G4,"%",""))>=90,"PASS",IF(VALUE(SUBSTITUTE(Dashboard!G4,"%",""))>=70,"REVIEW","FAIL")),"--"))
A27: CSP Obligations | B27: ='Dashboard'!G5 | C27: ='Dashboard'!C5 | D27: ='Dashboard'!E5 | E27: =IF(Dashboard!G5="N/A","--",IF(ISNUMBER(VALUE(SUBSTITUTE(Dashboard!G5,"%",""))),IF(VALUE(SUBSTITUTE(Dashboard!G5,"%",""))>=90,"PASS",IF(VALUE(SUBSTITUTE(Dashboard!G5,"%",""))>=70,"REVIEW","FAIL")),"--"))
A29: CRITICAL ISSUES
A30: # | B30: Issue Description | C30: Domain | D30: Owner | E30: Due Date
A31: 1
A32: 2
A33: 3
A34: 4
A35: 5
A37: MANAGEMENT COMMENTARY
A38: [Enter management commentary on segregation in virtual computing environments posture]
A42: APPROVAL
A43: Assessed By
A44: Name:
A45: Date:
A46: Signature:
A47: Decision:
A49: Reviewed By (DPO)
A50: Name:
...

Sheet Dashboard
A1: Segregation in Virtual Computing Environments — Compliance Dashboard
A3: Domain | B3: Total Reqs | C3: Compliant | D3: Partial | E3: Non-Compliant | F3: N/A | G3: Compliance %
A4: CSC Obligations | B4: =COUNTA('CSC Obligations'!D4:D7) | C4: =COUNTIF('CSC Obligations'!D4:D7,"Compliant") | D4: =COUNTIF('CSC Obligations'!D4:D7,"Partial") | E4: =COUNTIF('CSC Obligations'!D4:D7,"Non-Compliant") | F4: =COUNTIF('CSC Obligations'!D4:D7,"N/A") | G4: =IF((B4-F4)=0,"N/A",ROUND(C4/(B4-F4)*100,1)&"%")
A5: CSP Obligations | B5: =COUNTA('CSP Obligations'!D4:D7) | C5: =COUNTIF('CSP Obligations'!D4:D7,"Compliant") | D5: =COUNTIF('CSP Obligations'!D4:D7,"Partial") | E5: =COUNTIF('CSP Obligations'!D4:D7,"Non-Compliant") | F5: =COUNTIF('CSP Obligations'!D4:D7,"N/A") | G5: =IF((B5-F5)=0,"N/A",ROUND(C5/(B5-F5)*100,1)&"%")
A6: TOTAL | B6: =SUM(B4:B5) | C6: =SUM(C4:C5) | D6: =SUM(D4:D5) | E6: =SUM(E4:E5) | F6: =SUM(F4:F5) | G6: =IF((B6-F6)=0,"N/A",ROUND(C6/(B6-F6)*100,1)&"%")
A8: COMPLIANCE BY STATUS
A9: Compliant | B9: =C6 | C9: =IF(B6=0,"",ROUND(B9/B6*100,1)&"%")
A10: Partial | B10: =D6 | C10: =IF(B6=0,"",ROUND(B10/B6*100,1)&"%")
A11: Non-Compliant | B11: =E6 | C11: =IF(B6=0,"",ROUND(B11/B6*100,1)&"%")
A12: N/A | B12: =F6 | C12: =IF(B6=0,"",ROUND(B12/B6*100,1)&"%")
A14: TOP GAPS (Manual Entry)
A15: Priority | B15: Domain | C15: Requirement | D15: Owner | E15: Due Date | F15: Status
A27: COMPLIANCE TREND (Manual Entry)
A28: Assessment Date | B28: Overall % | C28: Compliant | D28: Gaps | E28: Assessor | F28: Notes

Sheet CSC Obligations
A1: CSC Obligations — Compliance Checklist
A2: ISO/IEC 27017:2026 — Controls 8.35: Segregation in Virtual Computing Environments
A3: Req # | B3: Section | C3: Requirement | D3: Status | E3: Evidence | F3: Owner | G3: Due Date | H3: Notes
A4: 8.35-01 | B4: Define Segregation Requirements | C4: The organisation shall define its requirements for segregating its environment to achieve tenant isolation within the shared virtual environment of any cloud service it uses.
A5: 8.35-02 | B5: Verify CSP Meets Requirements | C5: The organisation shall verify, before and periodically during use of the service, that the CSP meets the organisation's stated segregation requirements.
A6: 8.35-03 | B6: Periodic Re-verification | C6: The organisation shall repeat segregation verification at least annually, and whenever the CSP announces a material change to its virtualization or multi-tenancy architecture.
A7: 8.35-04 | B7: Regulatory Segregation Requirements | C7: Where applicable laws or regulations require the segregation of networks or the isolation of network traffic, the organisation shall ensure its virtual computing segregation controls satisfy those requirements in addition to this policy's baseline.

Sheet CSP Obligations
A1: CSP Obligations — Compliance Checklist
A2: ISO/IEC 27017:2026 — Controls 8.35: Segregation in Virtual Computing Environments
A3: Req # | B3: Section | C3: Requirement | D3: Status | E3: Evidence | F3: Owner | G3: Due Date | H3: Notes
A4: 8.35-05 | B4: Enforce Logical Segregation by Layer | C4: The organisation shall enforce logical segregation of CSC data, virtualized applications, operating systems, storage, and network resources, to ensure isolation of resources used by different tenants.
A5: 8.35-06 | B5: Risk Assessment of CSC-Supplied Software | C5: The organisation shall assess the risks associated with running CSC-supplied software within its cloud services before permitting such software to run in shared infrastructure.
A6: 8.35-07 | B6: Separate Internal Administration | C6: The organisation shall enforce separation of its own internal administration functions from the resources used by CSCs.
A7: 8.35-08 | B7: Technology-Dependent Segregation Implementation | C7: Where network and storage configurations are virtualized through a software virtualization function, the organisation shall implement segregation using the segregation functions native to that software, in addition to underlying physical or network-level controls.
