Workbook

Sheet Executive Summary
A1: PRIV-CHK-A.3.13-16 — Compliance, Audit and Review Compliance Checklist
A3: DOCUMENT INFORMATION
A4: Document ID | B4: PRIV-CHK-A.3.13-16
A5: Source Policy | B5: PRIV-POL-A.3.13-16
A6: ISO Controls | B6: Compliance, Audit and Review
A7: Generated | B7: 10.03.2026
A8: Prepared By
A9: Organisation
A10: Review Cycle | B10: Annual
A12: OVERALL COMPLIANCE STATUS
A13: Overall Compliance | B13: ='Dashboard'!G7
A14: Status | B14: =IF(Dashboard!G7="N/A","NOT ASSESSED",IF(ISNUMBER(VALUE(SUBSTITUTE(Dashboard!G7,"%",""))),IF(VALUE(SUBSTITUTE(Dashboard!G7,"%",""))>=90,"GREEN",IF(VALUE(SUBSTITUTE(Dashboard!G7,"%",""))>=70,"AMBER","RED")),"NOT ASSESSED"))
A16: KEY METRICS
A17: Total Requirements | B17: ='Dashboard'!B7
A18: Compliant | B18: ='Dashboard'!C7
A19: Partial | B19: ='Dashboard'!D7
A20: Non-Compliant | B20: ='Dashboard'!E7
A21: Not Applicable | B21: ='Dashboard'!F7
A22: Owner Coverage | B22: =IF(Dashboard!B7=0,"N/A",ROUND((COUNTA('Legal Requirements and Records'!F4:F9)+COUNTA('Independent Review of PIMS'!F4:F8)+COUNTA('Ongoing Compliance Review'!F4:F7))/Dashboard!B7*100,0)&"%")
A24: DOMAIN STATUS SUMMARY
A25: Domain | B25: Compliance % | C25: Compliant | D25: Gaps | E25: Status
A26: Legal Requirements and Records | B26: ='Dashboard'!G4 | C26: ='Dashboard'!C4 | D26: ='Dashboard'!E4 | E26: =IF(Dashboard!G4="N/A","--",IF(ISNUMBER(VALUE(SUBSTITUTE(Dashboard!G4,"%",""))),IF(VALUE(SUBSTITUTE(Dashboard!G4,"%",""))>=90,"PASS",IF(VALUE(SUBSTITUTE(Dashboard!G4,"%",""))>=70,"REVIEW","FAIL")),"--"))
A27: Independent Review of PIMS | B27: ='Dashboard'!G5 | C27: ='Dashboard'!C5 | D27: ='Dashboard'!E5 | E27: =IF(Dashboard!G5="N/A","--",IF(ISNUMBER(VALUE(SUBSTITUTE(Dashboard!G5,"%",""))),IF(VALUE(SUBSTITUTE(Dashboard!G5,"%",""))>=90,"PASS",IF(VALUE(SUBSTITUTE(Dashboard!G5,"%",""))>=70,"REVIEW","FAIL")),"--"))
A28: Ongoing Compliance Review | B28: ='Dashboard'!G6 | C28: ='Dashboard'!C6 | D28: ='Dashboard'!E6 | E28: =IF(Dashboard!G6="N/A","--",IF(ISNUMBER(VALUE(SUBSTITUTE(Dashboard!G6,"%",""))),IF(VALUE(SUBSTITUTE(Dashboard!G6,"%",""))>=90,"PASS",IF(VALUE(SUBSTITUTE(Dashboard!G6,"%",""))>=70,"REVIEW","FAIL")),"--"))
A30: CRITICAL ISSUES
A31: # | B31: Issue Description | C31: Domain | D31: Owner | E31: Due Date
A32: 1
A33: 2
A34: 3
A35: 4
A36: 5
A38: MANAGEMENT COMMENTARY
A39: [Enter management commentary on compliance, audit and review posture]
A43: APPROVAL
A44: Assessed By
A45: Name:
A46: Date:
A47: Signature:
A48: Decision:
A50: Reviewed By (DPO)
...

Sheet Dashboard
A1: Compliance, Audit and Review — Compliance Dashboard
A3: Domain | B3: Total Reqs | C3: Compliant | D3: Partial | E3: Non-Compliant | F3: N/A | G3: Compliance %
A4: Legal Requirements and Records | B4: =COUNTA('Legal Requirements and Records'!D4:D9) | C4: =COUNTIF('Legal Requirements and Records'!D4:D9,"Compliant") | D4: =COUNTIF('Legal Requirements and Records'!D4:D9,"Partial") | E4: =COUNTIF('Legal Requirements and Records'!D4:D9,"Non-Compliant") | F4: =COUNTIF('Legal Requirements and Records'!D4:D9,"N/A") | G4: =IF((B4-F4)=0,"N/A",ROUND(C4/(B4-F4)*100,1)&"%")
A5: Independent Review of PIMS | B5: =COUNTA('Independent Review of PIMS'!D4:D8) | C5: =COUNTIF('Independent Review of PIMS'!D4:D8,"Compliant") | D5: =COUNTIF('Independent Review of PIMS'!D4:D8,"Partial") | E5: =COUNTIF('Independent Review of PIMS'!D4:D8,"Non-Compliant") | F5: =COUNTIF('Independent Review of PIMS'!D4:D8,"N/A") | G5: =IF((B5-F5)=0,"N/A",ROUND(C5/(B5-F5)*100,1)&"%")
A6: Ongoing Compliance Review | B6: =COUNTA('Ongoing Compliance Review'!D4:D7) | C6: =COUNTIF('Ongoing Compliance Review'!D4:D7,"Compliant") | D6: =COUNTIF('Ongoing Compliance Review'!D4:D7,"Partial") | E6: =COUNTIF('Ongoing Compliance Review'!D4:D7,"Non-Compliant") | F6: =COUNTIF('Ongoing Compliance Review'!D4:D7,"N/A") | G6: =IF((B6-F6)=0,"N/A",ROUND(C6/(B6-F6)*100,1)&"%")
A7: TOTAL | B7: =SUM(B4:B6) | C7: =SUM(C4:C6) | D7: =SUM(D4:D6) | E7: =SUM(E4:E6) | F7: =SUM(F4:F6) | G7: =IF((B7-F7)=0,"N/A",ROUND(C7/(B7-F7)*100,1)&"%")
A9: COMPLIANCE BY STATUS
A10: Compliant | B10: =C7 | C10: =IF(B7=0,"",ROUND(B10/B7*100,1)&"%")
A11: Partial | B11: =D7 | C11: =IF(B7=0,"",ROUND(B11/B7*100,1)&"%")
A12: Non-Compliant | B12: =E7 | C12: =IF(B7=0,"",ROUND(B12/B7*100,1)&"%")
A13: N/A | B13: =F7 | C13: =IF(B7=0,"",ROUND(B13/B7*100,1)&"%")
A15: TOP GAPS (Manual Entry)
A16: Priority | B16: Domain | C16: Requirement | D16: Owner | E16: Due Date | F16: Status
A28: COMPLIANCE TREND (Manual Entry)
A29: Assessment Date | B29: Overall % | C29: Compliant | D29: Gaps | E29: Assessor | F29: Notes

Sheet Legal Requirements and Records
A1: Legal Requirements and Records — Compliance Checklist
A2: ISO/IEC 27701:2025 — Controls A.3.13-16: Compliance, Audit and Review
A3: Req # | B3: Section | C3: Requirement | D3: Status | E3: Evidence | F3: Owner | G3: Due Date | H3: Notes
A4: A.3.13-01 | B4: Privacy Legal Requirements Register | C4: The organisation shall maintain a Privacy Legal Requirements Register (PLRR) documenting all legal, statutory, regulatory, and contractual requirements applicable to PII processing, the organisation's approach to meeting each requirement, current compliance status, and review dates. The PLRR is maintained by the DPO and classified CONFIDENTIAL.
A5: A.3.13-02 | B5: PLRR Currency | C5: The PLRR shall be reviewed at minimum annually and updated upon: enactment or amendment of applicable privacy legislation; new or material contract obligations involving PII; new processing activities that bring new regulatory obligations into scope; and DPA guidance or enforcement decisions that materially clarify obligations. Stale entries (unreviewd for more than 12 months) shall be treated as a compliance gap.
A6: A.3.14-01 | B6: Mandatory PII Processing Records | C6: The organisation shall create and maintain the following mandatory PII processing records: Record of Processing Activities (RoPA); consent records; DPIA documentation; DPO appointment records; supervisory authority notifications; data subject rights response records; processor agreements; International Transfer Register; Privacy Breach Register; training and acknowledgment records; PIMS internal audit reports; and PIMS management review records.
A7: A.3.14-02 | B7: Records Protection | C7: PII processing records shall be protected against loss or destruction (backups, defined retention periods); falsification (audit trails with identity and timestamp, prior version retention, DPO authorisation required for deletion); unauthorised access (classification controls per PRIV-POL-A.3.5-7); and unauthorised release (confidentiality controls). Records with regulatory significance shall be stored in systems that log all modifications.
A8: A.3.14-03 | B8: Record Retention Periods | C8: Mandatory retention periods shall be observed for all PII processing records. Minimum periods: RoPA, consent records, DPIA, transfer register — duration of processing plus 3 years; breach register, supervisory authority notifications — 5 years; DPO appointment record — duration of appointment plus 3 years; audit and management review records — 3 years.
A9: A.3.14-04 | B9: Supervisory Authority Access | C9: PII processing records shall be maintained in a secure manner and made available to supervisory authorities on request within the timeframe required by applicable law (GDPR Article 58; CH FADP Article 49). A process for responding to supervisory authority records requests shall be documented in the PIRP.

Sheet Independent Review of PIMS
A1: Independent Review of PIMS — Compliance Checklist
A2: ISO/IEC 27701:2025 — Controls A.3.13-16: Compliance, Audit and Review
A3: Req # | B3: Section | C3: Requirement | D3: Status | E3: Evidence | F3: Owner | G3: Due Date | H3: Notes
A4: A.3.15-01 | B4: Independent Review Requirement | C4: The organisation shall conduct independent reviews of its PIMS — covering people, processes, and technologies related to PII processing — at planned intervals and when significant changes occur. The DPO may not conduct the independent review for PIMS functions they directly manage.
A5: A.3.15-02 | B5: Review Frequency | C5: Independent PIMS reviews shall occur at minimum annually (planned interval) and upon: major new processing activity; material change to organisational structure or processing infrastructure; significant regulatory change; or material privacy incident.
A6: A.3.15-03 | B6: Independence Requirement | C6: Independent reviews shall be conducted by reviewers who are independent of the operational functions responsible for PIMS implementation, have no conflict of interest in the review outcome, and have sufficient competence to assess PIMS controls and regulatory requirements. Acceptable approaches include: internal PIMS audit by the designated PIMS Internal Auditor; external audit by a third-party privacy auditor; or ISO/IEC 27701:2025 certification body audit.
A7: A.3.15-04 | B7: Review Scope | C7: Each independent review shall cover at minimum: policy and documentation completeness and currency; role assignments and competence evidence; evidence of PIMS operation (records per A.3.14); technical controls for PII processing; regulatory compliance status against the PLRR; and status of findings from previous reviews.
A8: A.3.15-05 | B8: Review Outputs | C8: Independent review outputs shall include a review report with findings, non-conformities, observations, and recommendations; formal presentation of findings to Executive Management; DPO response with remediation plan and timelines; and tracking of remediation to closure. Review reports are classified CONFIDENTIAL and retained for minimum 3 years.

Sheet Ongoing Compliance Review
A1: Ongoing Compliance Review — Compliance Checklist
A2: ISO/IEC 27701:2025 — Controls A.3.13-16: Compliance, Audit and Review
A3: Req # | B3: Section | C3: Requirement | D3: Status | E3: Evidence | F3: Owner | G3: Due Date | H3: Notes
A4: A.3.16-01 | B4: Compliance Review Programme | C4: The DPO shall maintain an ongoing compliance review programme covering: all 21 PIMS control group policies; the RoPA (currency and accuracy); processor agreement compliance; technical security control compliance for PII processing environments; and training and awareness completion rates.
A5: A.3.16-02 | B5: Review Frequency by Subject | C5: Minimum compliance review frequencies: RoPA accuracy — quarterly; processor agreement inventory — annually; technical controls compliance for PII systems — annually or upon significant system change; training and acknowledgment records — annually; PIMS policy compliance self-assessment per control group — annually.
A6: A.3.16-03 | B6: Compliance Review Outputs | C6: Compliance reviews shall produce: a written compliance assessment per review subject; a list of identified non-conformities or gaps; remediation actions with owner and target date; escalation to DPO for material compliance gaps; and reporting to Executive Management for systemic compliance issues. Compliance review records are retained for minimum 3 years.
A7: A.3.16-04 | B7: Non-Conformity Management | C7: Non-conformities identified through compliance review shall be documented, assigned an owner, and tracked to closure. Material non-conformities (those presenting significant regulatory risk or risk of harm to data subjects) shall be escalated to Executive Management and, where required, to the relevant supervisory authority as part of the organisation's accountability obligations.
