Workbook

Sheet Executive Dashboard
A1: ISMS-IMP-A.8.23.5 – Web Filtering Compliance Summary Dashboard ISO/IEC 27001:2022 - Control A.8.23: Web Filtering - Executive Overview
A3: Document Information
A4: Document ID | B4: ISMS-IMP-A.8.23.5
A5: Report Type | B5: Compliance Summary Dashboard
A6: Related Policy | B6: ISMS-POL-A.8.23 (Web Filtering)
A7: Version | B7: 1.0
A8: Report Date
A9: Reporting Period
A10: Prepared By
A11: Organization
A12: Review Cycle | B12: Quarterly
A13: Last Updated | B13: =TODAY()
A16: OVERALL WEB FILTERING COMPLIANCE STATUS
A17: Metric | B17: Score | C17: Target | D17: Status
A18: Overall Compliance Rate | B18: =AVERAGE(C25:C28) | C18: ≥95%
A19: Critical Gaps | B19: =COUNTIFS('Gap Analysis'!I8:I207,"Critical",'Gap Analysis'!R8:R207,"<>Closed") | C19: 0
A20: High-Risk Items | B20: =COUNTIFS('Risk Register'!N21:N119,">=15",'Risk Register'!Q21:Q119,"<>Closed") | C20: ≤5
A21: Remediation Progress | B21: =COUNTIF('Remediation Roadmap'!H37:H236,"Completed")/COUNTA('Remediation Roadmap'!H37:H236)*100&"%" | C21: ≥80%
A24: DOMAIN COMPLIANCE SCORES (from Source Workbooks)
A25: # | B25: Assessment Domain | C25: Compliance Score | D25: Status | E25: Critical Gaps | F25: Evidence Count | G25: Last Updated | H25: Assessor
A26: 1 | B26: Filtering Infrastructure | C26: ='[ISMS-IMP-A.8.23.1.xlsx]Gap_Analysis'!B5 | D26: ='[ISMS-IMP-A.8.23.1.xlsx]Gap_Analysis'!C5 | E26: =COUNTIF('[ISMS-IMP-A.8.23.1.xlsx]Gap_Analysis'!F10:F109,"Critical") | F26: =COUNTA('[ISMS-IMP-A.8.23.1.xlsx]Evidence_Register'!A10:A209) | G26: ='[ISMS-IMP-A.8.23.1.xlsx]Instructions & Legend'!B9 | H26: ='[ISMS-IMP-A.8.23.1.xlsx]Instructions & Legend'!B10
A27: 2 | B27: Network Coverage | C27: ='[ISMS-IMP-A.8.23.2.xlsx]Gap_Identification'!B5 | D27: ='[ISMS-IMP-A.8.23.2.xlsx]Gap_Identification'!C5 | E27: =COUNTIF('[ISMS-IMP-A.8.23.2.xlsx]Gap_Identification'!F10:F109,"Critical") | F27: =COUNTA('[ISMS-IMP-A.8.23.2.xlsx]Evidence_Register'!A10:A209) | G27: ='[ISMS-IMP-A.8.23.2.xlsx]Instructions & Legend'!B9 | H27: ='[ISMS-IMP-A.8.23.2.xlsx]Instructions & Legend'!B10
A28: 3 | B28: Policy Configuration | C28: ='[ISMS-IMP-A.8.23.3.xlsx]Gap_Analysis'!B5 | D28: ='[ISMS-IMP-A.8.23.3.xlsx]Gap_Analysis'!C5 | E28: =COUNTIF('[ISMS-IMP-A.8.23.3.xlsx]Gap_Analysis'!F10:F109,"Critical") | F28: =COUNTA('[ISMS-IMP-A.8.23.3.xlsx]Evidence_Register'!A10:A209) | G28: ='[ISMS-IMP-A.8.23.3.xlsx]Instructions & Legend'!B9 | H28: ='[ISMS-IMP-A.8.23.3.xlsx]Instructions & Legend'!B10
A29: 4 | B29: Monitoring & Response | C29: ='[ISMS-IMP-A.8.23.4.xlsx]Gap_Analysis'!B5 | D29: ='[ISMS-IMP-A.8.23.4.xlsx]Gap_Analysis'!C5 | E29: =COUNTIF('[ISMS-IMP-A.8.23.4.xlsx]Gap_Analysis'!F10:F109,"Critical") | F29: =COUNTA('[ISMS-IMP-A.8.23.4.xlsx]Evidence_Register'!A10:A209) | G29: ='[ISMS-IMP-A.8.23.4.xlsx]Instructions_Legend'!B9 | H29: ='[ISMS-IMP-A.8.23.4.xlsx]Instructions_Legend'!B10
A32: KEY PERFORMANCE INDICATORS (Consolidated)
A33: Category | B33: Metric | C33: Current Value | D33: Target | E33: Status | F33: Trend | G33: Notes
A34: Infrastructure | B34: Filtering Solutions Deployed | C34: =COUNTA('[ISMS-IMP-A.8.23.1.xlsx]Solution_Details_Template'!B8:B27) | D34: ≥1 | G34: From A.8.23.1
A35: Infrastructure | B35: Solutions Fully Implemented | C35: =COUNTIF('[ISMS-IMP-A.8.23.1.xlsx]Solution_Details_Template'!I8:I27,"Deployed")/COUNTA('[ISMS-IMP-A.8.23.1.xlsx]Solution_Details_Template'!B8:B27) | D35: 100%
A36: Coverage | B36: Network Segments Covered | C36: =COUNTIF('[ISMS-IMP-A.8.23.2.xlsx]Coverage_Matrix'!D10:D109,"✅ Covered")/COUNTA('[ISMS-IMP-A.8.23.2.xlsx]Network_Segment_Inventory'!A10:A59) | D36: 100% | G36: From A.8.23.2
A37: Coverage | B37: Critical Bypass Risks | C37: =COUNTIF('[ISMS-IMP-A.8.23.2.xlsx]Gap_Identification'!F10:F109,"Critical") | D37: 0
A38: Policy | B38: Threat Categories Blocked | C38: =COUNTIF('[ISMS-IMP-A.8.23.3.xlsx]Threat_Protection'!E10:E59,"Blocked")/COUNTA('[ISMS-IMP-A.8.23.3.xlsx]Threat_Protection'!A10:A59) | D38: ≥95% | G38: From A.8.23.3
A39: Policy | B39: Active Exceptions | C39: =COUNTIF('[ISMS-IMP-A.8.23.3.xlsx]Policy_Exceptions'!G10:G109,"Active") | D39: <10
A40: Monitoring | B40: Alert Rules Configured | C40: =COUNTA('[ISMS-IMP-A.8.23.4.xlsx]Alert_Configuration'!A10:A109) | D40: ≥20 | G40: From A.8.23.4
A41: Monitoring | B41: SLA Compliance Rate | C41: =COUNTIF('[ISMS-IMP-A.8.23.4.xlsx]Incident_Response'!K10:K109,"Met")/COUNTA('[ISMS-IMP-A.8.23.4.xlsx]Incident_Response'!K10:K109) | D41: ≥95%
A42: Response | B42: Open Critical Incidents | C42: =COUNTIFS('[ISMS-IMP-A.8.23.4.xlsx]Incident_Response'!D10:D109,"Critical",'[ISMS-IMP-A.8.23.4.xlsx]Incident_Response'!I10:I109,"Open") | D42: 0
A43: Response | B43: False Positive Rate | C43: =COUNTIF('[ISMS-IMP-A.8.23.4.xlsx]False_Positive_Mgmt'!H10:H109,"Confirmed_FP")/COUNTA('[ISMS-IMP-A.8.23.4.xlsx]Blocked_Events_Analysis'!A10:A109) | D43: <1%
A46: 📊 DASHBOARD NOTES
A47: • This dashboard consolidates data from 4 assessment workbooks via external links
A48: • Blue italic formulas pull live data from normalized source files
A49: • Click 'Update Links' when opening to refresh all data
...

Sheet Gap Analysis
A1: CONSOLIDATED GAP ANALYSIS - A.8.23 WEB FILTERING
A2: Aggregated gaps from all 4 assessment workbooks
A4: Gap ID | B4: Source Assessment | C4: Gap Category | D4: Gap Description | E4: Current State | F4: Target State | G4: Impact | H4: Likelihood | I4: Risk Score | J4: Priority | K4: Remediation Action | L4: Owner | M4: Target Date | N4: Status | O4: Progress % | P4: Cost Estimate | Q4: Dependencies | R4: Verification Method | S4: Status Notes
A5: INSTRUCTIONS: Consolidate gaps from all 4 source workbooks. Each gap should reference its source assessment. Use this sheet for executive-level gap tracking across all web filtering domains.
A6: A.8.23.1-GAP-001 | B6: Filtering Infrastructure | C6: Technology | G6: High | H6: Medium | I6: =G7*H7 | J6: High
A7: A.8.23.2-GAP-001 | B7: Network Coverage | C7: Coverage | G7: Critical | H7: High | I7: =G8*H8 | J7: Critical
A8: A.8.23.3-GAP-001 | B8: Policy Configuration | C8: Policy | G8: Medium | H8: Low | I8: =G9*H9 | J8: Medium
A9: A.8.23.4-GAP-001 | B9: Monitoring & Response | C9: Monitoring | G9: High | H9: Medium | I9: =G10*H10 | J9: High

Sheet Risk Register
A1: RISK REGISTER - A.8.23 WEB FILTERING
A3: RISK SCORING MATRIX
A4: Impact / Likelihood | B4: Low (1) | C4: Medium (2) | D4: High (3) | E4: Critical (4)
A5: Critical (4) | B5: 4 | C5: 8 | D5: 12 | E5: 16
A6: High (3) | B6: 3 | C6: 6 | D6: 9 | E6: 12
A7: Medium (2) | B7: 2 | C7: 4 | D7: 6 | E7: 8
A8: Low (1) | B8: 1 | C8: 2 | D8: 3 | E8: 4
A11: IDENTIFIED RISKS
A12: Risk ID | B12: Source | C12: Risk Category | D12: Risk Description | E12: Threat Source | F12: Vulnerability | G12: Impact | H12: Likelihood | I12: Inherent Risk | J12: Controls | K12: Control Effectiveness | L12: Residual Impact | M12: Residual Likelihood | N12: Residual Risk | O12: Treatment | P12: Owner | Q12: Status
I13: =G13*H13 | N13: =L13*M13
I14: =G14*H14 | N14: =L14*M14
I15: =G15*H15 | N15: =L15*M15
I16: =G16*H16 | N16: =L16*M16
I17: =G17*H17 | N17: =L17*M17
I18: =G18*H18 | N18: =L18*M18
I19: =G19*H19 | N19: =L19*M19
I20: =G20*H20 | N20: =L20*M20
I21: =G21*H21 | N21: =L21*M21
I22: =G22*H22 | N22: =L22*M22
I23: =G23*H23 | N23: =L23*M23
I24: =G24*H24 | N24: =L24*M24
... I112: =G112*H112 | N112: =L112*M112

Sheet Remediation Roadmap
A1: REMEDIATION ROADMAP - A.8.23 WEB FILTERING
A2: Action plan for closing identified gaps and reducing risks
A4: REMEDIATION SUMMARY
A5: Total Action Items | B5: =COUNTA(A37:A236)
A6: Completed | B6: =COUNTIF(H37:H236,"Completed")
A7: In Progress | B7: =COUNTIF(H37:H236,"In Progress")
A8: Not Started | B8: =COUNTIF(H37:H236,"Not Started")
A9: Overdue | B9: =COUNTIFS(H37:H236,"<>Completed",E37:E236,"<"&TODAY())
A10: Overall Progress | B10: =COUNTIF(H37:H236,"Completed")/COUNTA(A37:A236)
A13: IMPLEMENTATION PHASES
A14: Phase 1: Critical (0-30 days) | B14: Immediate action required | C14: Critical gaps, security risks
A15: Phase 2: High (30-90 days) | B15: Quick wins, high impact | C15: Infrastructure, coverage gaps
A16: Phase 3: Medium (90-180 days) | B16: Process improvements | C16: Policy, monitoring enhancements
A17: Phase 4: Low (180-365 days) | B17: Optimization | C17: Fine-tuning, documentation
A20: ACTION ITEMS
A21: Action ID | B21: Phase | C21: Related Gap/Risk | D21: Action Description | E21: Target Date | F21: Assigned Owner | G21: Department | H21: Status | I21: Progress % | J21: Actual Completion | K21: Budget | L21: Dependencies | M21: Success Criteria | N21: Verification | O21: Notes | P21: Last Updated

Sheet KPIs & Metrics
A1: KPIs & METRICS - A.8.23 WEB FILTERING
A3: INFRASTRUCTURE METRICS
A4: KPI Name | B4: Unit | C4: Current Value | D4: Target | E4: Status | F4: Trend | G4: Last Month | H4: YTD Average | I4: Data Source | J4: Update Frequency | K4: Owner | L4: Collection Method | M4: Notes
A5: Total Filtering Solutions | B5: Count | D5: ≥1
A6: Deployment Coverage | B6: % | D6: 100%
A7: Solution Availability | B7: % | D7: ≥99%
A8: Performance - Latency | B8: ms | D8: ≤100ms
A9: Licensing Compliance | B9: % | D9: 100%
A11: COVERAGE METRICS
A12: KPI Name | B12: Unit | C12: Current Value | D12: Target | E12: Status | F12: Trend | G12: Last Month | H12: YTD Average | I12: Data Source | J12: Update Frequency | K12: Owner | L12: Collection Method | M12: Notes
A13: Network Segments Covered | B13: % | D13: 100%
A14: Users Protected | B14: Count | D14: All
A15: Devices Protected | B15: Count | D15: All
A16: Bypass Vulnerabilities | B16: Count | D16: 0
A17: Coverage Verification Rate | B17: % | D17: 100%
A19: POLICY METRICS
A20: KPI Name | B20: Unit | C20: Current Value | D20: Target | E20: Status | F20: Trend | G20: Last Month | H20: YTD Average | I20: Data Source | J20: Update Frequency | K20: Owner | L20: Collection Method | M20: Notes
A21: Threat Categories Blocked | B21: % | D21: ≥95%
A22: Content Categories Configured | B22: Count | D22: ≥30
A23: Active Policy Exceptions | B23: Count | D23: ≤10
A24: Exception Review Compliance | B24: % | D24: 100%
A25: Policy Update Frequency | B25: Days | D25: ≤90
A27: MONITORING METRICS
A28: KPI Name | B28: Unit | C28: Current Value | D28: Target | E28: Status | F28: Trend | G28: Last Month | H28: YTD Average | I28: Data Source | J28: Update Frequency | K28: Owner | L28: Collection Method | M28: Notes
A29: Log Collection Rate | B29: % | D29: 100%
A30: Alert Rules Active | B30: Count | D30: ≥20
A31: Alert Response Time | B31: Minutes | D31: ≤30
A32: Dashboard Availability | B32: % | D32: ≥99%
A33: SIEM Integration Health | B33: % | D33: 100%
A35: INCIDENT METRICS
A36: KPI Name | B36: Unit | C36: Current Value | D36: Target | E36: Status | F36: Trend | G36: Last Month | H36: YTD Average | I36: Data Source | J36: Update Frequency | K36: Owner | L36: Collection Method | M36: Notes
A37: Open Critical Incidents | B37: Count | D37: 0
A38: Mean Time to Detect (MTTD) | B38: Minutes | D38: ≤15
A39: Mean Time to Respond (MTTR) | B39: Hours | D39: ≤4
A40: SLA Compliance Rate | B40: % | D40: ≥95%
A41: False Positive Rate | B41: % | D41: ≤1%
A43: COMPLIANCE METRICS
A44: KPI Name | B44: Unit | C44: Current Value | D44: Target | E44: Status | F44: Trend | G44: Last Month | H44: YTD Average | I44: Data Source | J44: Update Frequency | K44: Owner | L44: Collection Method | M44: Notes
A45: Overall Compliance Score | B45: % | D45: ≥95%
A46: Critical Gaps Open | B46: Count | D46: 0
...

Sheet Evidence Register
A1: EVIDENCE REGISTER - A.8.23 WEB FILTERING
A2: Centralized evidence tracking for audit and compliance verification
A4: EVIDENCE SUMMARY
A5: Total Evidence Items | B5: =COUNTA(A20:A519)
A6: Verified | B6: =COUNTIF(L21:L519,"Verified")
A7: Pending Verification | B7: =COUNTIF(L21:L519,"Pending")
A8: Expired/Missing | B8: =COUNTIF(L21:L519,"Expired")
A9: Verification Rate | B9: =COUNTIF(L21:L519,"Verified")/COUNTA(A20:A519)
A12: EVIDENCE BY CATEGORY
A13: Category | B13: Count | C13: Verified | D13: Verification %
A14: Infrastructure | B14: =COUNTIF(D21:D519,"Infrastructure") | C14: =COUNTIFS(D21:D519,"Infrastructure",L21:L519,"Verified") | D14: =C14/B14
A15: Coverage | B15: =COUNTIF(D21:D519,"Coverage") | C15: =COUNTIFS(D21:D519,"Coverage",L21:L519,"Verified") | D15: =C15/B15
A16: Policy | B16: =COUNTIF(D21:D519,"Policy") | C16: =COUNTIFS(D21:D519,"Policy",L21:L519,"Verified") | D16: =C16/B16
A17: Monitoring | B17: =COUNTIF(D21:D519,"Monitoring") | C17: =COUNTIFS(D21:D519,"Monitoring",L21:L519,"Verified") | D17: =C17/B17
A18: Incident Response | B18: =COUNTIF(D21:D519,"Incident Response") | C18: =COUNTIFS(D21:D519,"Incident Response",L21:L519,"Verified") | D18: =C18/B18
A19: Compliance | B19: =COUNTIF(D21:D519,"Compliance") | C19: =COUNTIFS(D21:D519,"Compliance",L21:L519,"Verified") | D19: =C19/B19
A20: Audit | B20: =COUNTIF(D21:D519,"Audit") | C20: =COUNTIFS(D21:D519,"Audit",L21:L519,"Verified") | D20: =C20/B20
A22: EVIDENCE ITEMS
A23: Evidence ID | B23: Source Assessment | C23: Related Requirement | D23: Category | E23: Evidence Type | F23: Description | G23: File Location | H23: Collection Date | I23: Collected By | J23: Retention Period | K23: Expiry Date | L23: Verification Status | M23: Verified By | N23: Verification Date | O23: Notes
K24: =H24+J24
K25: =H25+J25
K26: =H26+J26
K27: =H27+J27
K28: =H28+J28
K29: =H29+J29
K30: =H30+J30
K31: =H31+J31
K32: =H32+J32
K33: =H33+J33
K34: =H34+J34
K35: =H35+J35
... K523: =H523+J523

Sheet Action Items & Follow-up
A1: ACTION ITEMS & FOLLOW-UP - A.8.23 WEB FILTERING
A3: ACTION SUMMARY
A4: Total Actions | B4: =COUNTA(A20:A219)
A5: Overdue | B5: =COUNTIFS(F20:F219,"<"&TODAY(),G20:G219,"<>Completed")
A6: Due This Week | B6: =COUNTIFS(F20:F219,">="&TODAY(),F20:F219,"<="&TODAY()+7,G20:G219,"<>Completed")
A7: Completed This Month | B7: =COUNTIFS(G20:G219,"Completed",H20:H219,">="&EOMONTH(TODAY(),-1)+1)
A8: Completion Rate | B8: =COUNTIF(G20:G219,"Completed")/COUNTA(A20:A219)
A11: ACTIONS BY PRIORITY
A12: Priority | B12: Total | C12: Open | D12: Overdue | E12: Completed
A13: Critical | B13: =COUNTIF(E20:E219,"Critical") | C13: =COUNTIFS(E20:E219,"Critical",G20:G219,"<>Completed") | D13: =COUNTIFS(E20:E219,"Critical",F20:F219,"<"&TODAY(),G20:G219,"<>Completed") | E13: =COUNTIFS(E20:E219,"Critical",G20:G219,"Completed")
A14: High | B14: =COUNTIF(E20:E219,"High") | C14: =COUNTIFS(E20:E219,"High",G20:G219,"<>Completed") | D14: =COUNTIFS(E20:E219,"High",F20:F219,"<"&TODAY(),G20:G219,"<>Completed") | E14: =COUNTIFS(E20:E219,"High",G20:G219,"Completed")
A15: Medium | B15: =COUNTIF(E20:E219,"Medium") | C15: =COUNTIFS(E20:E219,"Medium",G20:G219,"<>Completed") | D15: =COUNTIFS(E20:E219,"Medium",F20:F219,"<"&TODAY(),G20:G219,"<>Completed") | E15: =COUNTIFS(E20:E219,"Medium",G20:G219,"Completed")
A16: Low | B16: =COUNTIF(E20:E219,"Low") | C16: =COUNTIFS(E20:E219,"Low",G20:G219,"<>Completed") | D16: =COUNTIFS(E20:E219,"Low",F20:F219,"<"&TODAY(),G20:G219,"<>Completed") | E16: =COUNTIFS(E20:E219,"Low",G20:G219,"Completed")
A18: ACTION ITEMS
A19: Action ID | B19: Source | C19: Related Gap/Risk | D19: Action Description | E19: Priority | F19: Due Date | G19: Status | H19: Completion Date | I19: Assigned To | J19: Department | K19: Progress Notes | L19: Blocker | M19: Next Steps | N19: Last Updated

Sheet Audit & Compliance Log
A1: AUDIT & COMPLIANCE LOG - A.8.23 WEB FILTERING
A2: Tracking audit activities, findings, and compliance verification
A4: AUDIT SUMMARY
A5: Last Internal Audit
A6: Last External Audit
A7: Next Scheduled Audit
A8: Total Findings (All Time) | B8: =COUNTA(A20:A119)
A9: Open Findings | B9: =COUNTIF(I21:I119,"Open")
A10: Closed Findings | B10: =COUNTIF(I21:I119,"Closed")
A11: Average Resolution Time (Days) | B11: =AVERAGE(J20:J119)
A14: FINDINGS BY SEVERITY
A15: Severity | B15: Total | C15: Open | D15: Closed | E15: Closure Rate
A16: Critical | B16: =COUNTIF(G21:G119,"Critical") | C16: =COUNTIFS(G21:G119,"Critical",I21:I119,"Open") | D16: =COUNTIFS(G21:G119,"Critical",I21:I119,"Closed") | E16: =D16/B16
A17: High | B17: =COUNTIF(G21:G119,"High") | C17: =COUNTIFS(G21:G119,"High",I21:I119,"Open") | D17: =COUNTIFS(G21:G119,"High",I21:I119,"Closed") | E17: =D17/B17
A18: Medium | B18: =COUNTIF(G21:G119,"Medium") | C18: =COUNTIFS(G21:G119,"Medium",I21:I119,"Open") | D18: =COUNTIFS(G21:G119,"Medium",I21:I119,"Closed") | E18: =D18/B18
A19: Low | B19: =COUNTIF(G21:G119,"Low") | C19: =COUNTIFS(G21:G119,"Low",I21:I119,"Open") | D19: =COUNTIFS(G21:G119,"Low",I21:I119,"Closed") | E19: =D19/B19
A20: Observation | B20: =COUNTIF(G21:G119,"Observation") | C20: =COUNTIFS(G21:G119,"Observation",I21:I119,"Open") | D20: =COUNTIFS(G21:G119,"Observation",I21:I119,"Closed") | E20: =D20/B20
A22: AUDIT FINDINGS & COMPLIANCE RECORDS
A23: Finding ID | B23: Audit Date | C23: Audit Type | D23: Auditor/Source | E23: Finding Category | F23: Finding Description | G23: Severity | H23: Affected Area | I23: Status | J23: Resolution Days | K23: Resolution Date | L23: Remediation Action | M23: Notes
J24: =IF(K24="","",K24-B24)
J25: =IF(K25="","",K25-B25)
J26: =IF(K26="","",K26-B26)
J27: =IF(K27="","",K27-B27)
J28: =IF(K28="","",K28-B28)
J29: =IF(K29="","",K29-B29)
J30: =IF(K30="","",K30-B30)
J31: =IF(K31="","",K31-B31)
J32: =IF(K32="","",K32-B32)
J33: =IF(K33="","",K33-B33)
J34: =IF(K34="","",K34-B34)
J35: =IF(K35="","",K35-B35)
... J123: =IF(K123="","",K123-B123)

Sheet Approval Sign-Off
A1: APPROVAL SIGN-OFF - A.8.23 WEB FILTERING
A2: Multi-level approval workflow for compliance dashboard
A4: ASSESSMENT SUMMARY FOR APPROVAL
A5: Overall Compliance Score | B5: ='Executive Dashboard'!B17
A6: Total Critical Gaps | B6: ='Executive Dashboard'!B18
A7: Total High-Risk Items | B7: ='Executive Dashboard'!B19
A8: Evidence Items Collected | B8: ='Evidence Register'!B5
A9: Open Action Items | B9: ='Action Items & Follow-up'!B6
A10: Audit Readiness Status | C10: Ready/Conditional/Not Ready
A13: ASSESSMENT STATUS
A14: Assessment Status:
A16: ASSESSMENT COMPLETED BY
A17: Name:
A18: Role/Title:
A19: Department:
A20: Email:
A21: Date:
A24: REVIEWED BY (INFORMATION SECURITY OFFICER)
A25: Name:
A26: Date:
A27: Review Notes:
... A47: This is Systems Engineering. This is Evidence > Theater.
