Workbook

Sheet Instructions_Legend
A1: ISMS-IMP-A.8.23.4 – Monitoring & Response Assessment
A2: ISO/IEC 27001:2022 - Control A.8.23: Web Filtering
A4: DOCUMENT INFORMATION
A5: Document ID: | B5: ISMS-IMP-A.8.23.4
A6: Assessment Area: | B6: Monitoring, Logging & Incident Response
A7: Related Policy: | B7: ISMS-POL-A.8.23-S2.3, S5.C
A8: Version: | B8: 1.0
A9: Assessment Date:
A10: Completed By:
A11: Organization:
A12: Review Cycle: | B12: Quarterly
A14: HOW TO USE THIS WORKBOOK
A15: 1. Navigate through each worksheet tab to assess monitoring & response capabilities
A16: 2. Use dropdown menus for standardized entries (Status, Severity, Priority, etc.)
A17: 3. Fill in yellow-highlighted cells with your organization-specific information
A18: 4. Document all log sources, alert rules, dashboards, and incident procedures
A19: 5. Track false positives and analyze blocked event trends
A20: 6. Identify gaps in Sheet 9 (Gap_Analysis) with remediation plans
A21: 7. Link evidence in the Evidence_Register for audit traceability
A22: 8. Obtain required approvals in Sheet 11 (Approval_Sign_Off)
A23: 9. Review quarterly or after significant changes to monitoring infrastructure
A25: STATUS LEGEND
A26: Status | B26: Color | C26: Meaning
A27: Implemented | C27: Fully operational and documented
A28: Partial | C28: Partially implemented, gaps exist
A29: Planned | C29: Scheduled for implementation
A30: Not_Implemented | C30: Not in place
A31: N/A | C31: Not applicable to this environment
A33: PRIORITY LEGEND (for Gaps/Actions)
A34: Critical | B34: Must address within 30 days
A35: High | B35: Address within 90 days
A36: Medium | B36: Address within 180 days
A37: Low | B37: Address within 12 months
A39: WORKBOOK CONTENTS
A40: Sheet 2: Log_Collection | B40: Document log sources, storage, and retention
A41: Sheet 3: Alert_Configuration | B41: Alert rules, thresholds, and notifications
A42: Sheet 4: Monitoring_Dashboard | B42: Dashboards, KPIs, and review frequency
A43: Sheet 5: Incident_Response | B43: Incident handling procedures and SLAs
A44: Sheet 6: Blocked_Events_Analysis | B44: Trend analysis of blocked events
A45: Sheet 7: False_Positive_Mgmt | B45: False positive tracking and tuning
...

Sheet Log_Collection
A1: LOG COLLECTION ASSESSMENT
A2: Document all web filtering log sources, collection methods, storage, and retention compliance
A4: SECTION A: LOG SOURCE INVENTORY
A5: Log_Source_ID | B5: Log_Source_Name | C5: Log_Type | D5: Source_System | E5: Collection_Method | F5: Destination | G5: Format | H5: Retention_Days | I5: Retention_Compliant | J5: Volume_Daily | K5: Status | L5: Evidence_Ref | M5: Notes
A6: LOG-001
A7: LOG-002
A8: LOG-003
A9: LOG-004
A10: LOG-005
A11: LOG-006
A12: LOG-007
A13: LOG-008
A14: LOG-009
A15: LOG-010
A16: LOG-011
A17: LOG-012
... A38: SECTION B: RETENTION REQUIREMENTS
A39: Requirement_ID | B39: Requirement_Source | C39: Log_Type_Affected | D39: Min_Retention_Days | E39: Current_Retention | F39: Compliant | G39: Notes
A40: RET-001
A41: RET-002
A42: RET-003
A43: RET-004
A44: RET-005
A45: RET-006
A46: RET-007
A47: RET-008
A48: RET-009
A49: RET-010
A52: SECTION C: SUMMARY METRICS
A53: Total log sources configured: | B53: =COUNTA(B6:B35)
A54: Blocked request log sources: | B54: =COUNTIF(C6:C35,"Blocked_Requests")
A55: Sources meeting retention: | B55: =COUNTIF(I6:I35,"Yes")
A56: Retention compliance rate: | B56: =IF(COUNTA(I6:I35)>0,COUNTIF(I6:I35,"Yes")/COUNTA(I6:I35),0)
A57: Implemented sources: | B57: =COUNTIF(K6:K35,"Implemented")
A58: Sources needing attention: | B58: =COUNTIF(K6:K35,"Partial")+COUNTIF(K6:K35,"Not_Implemented")

Sheet Alert_Configuration
A1: ALERT CONFIGURATION ASSESSMENT
A2: Document alerting rules, thresholds, notification methods, and escalation paths
A4: SECTION A: ALERT RULES INVENTORY
A5: Alert_ID | B5: Alert_Name | C5: Alert_Category | D5: Trigger_Condition | E5: Threshold_Value | F5: Severity | G5: Notification_Method | H5: Recipients | I5: Response_SLA_Min | J5: Escalation_Path | K5: Auto_Response | L5: Status | M5: Last_Triggered | N5: Evidence_Ref
A6: ALR-001
A7: ALR-002
A8: ALR-003
A9: ALR-004
A10: ALR-005
A11: ALR-006
A12: ALR-007
A13: ALR-008
A14: ALR-009
A15: ALR-010
A16: ALR-011
A17: ALR-012
... A48: SECTION B: ALERT CATEGORIES SUMMARY
A49: Category | B49: Count | C49: Active | D49: Critical_Count | E49: Notes
A50: Threat_Detection | B50: =COUNTIF(C6:C45,"Threat_Detection") | C50: =COUNTIFS(C6:C45,"Threat_Detection",L6:L45,"Implemented") | D50: =COUNTIFS(C6:C45,"Threat_Detection",F6:F45,"Critical")
A51: Policy_Violation | B51: =COUNTIF(C6:C45,"Policy_Violation") | C51: =COUNTIFS(C6:C45,"Policy_Violation",L6:L45,"Implemented") | D51: =COUNTIFS(C6:C45,"Policy_Violation",F6:F45,"Critical")
A52: System_Health | B52: =COUNTIF(C6:C45,"System_Health") | C52: =COUNTIFS(C6:C45,"System_Health",L6:L45,"Implemented") | D52: =COUNTIFS(C6:C45,"System_Health",F6:F45,"Critical")
A53: Threshold_Breach | B53: =COUNTIF(C6:C45,"Threshold_Breach") | C53: =COUNTIFS(C6:C45,"Threshold_Breach",L6:L45,"Implemented") | D53: =COUNTIFS(C6:C45,"Threshold_Breach",F6:F45,"Critical")
A54: Anomaly | B54: =COUNTIF(C6:C45,"Anomaly") | C54: =COUNTIFS(C6:C45,"Anomaly",L6:L45,"Implemented") | D54: =COUNTIFS(C6:C45,"Anomaly",F6:F45,"Critical")
A55: Compliance | B55: =COUNTIF(C6:C45,"Compliance") | C55: =COUNTIFS(C6:C45,"Compliance",L6:L45,"Implemented") | D55: =COUNTIFS(C6:C45,"Compliance",F6:F45,"Critical")
A58: SECTION C: SUMMARY METRICS
A59: Total alert rules configured: | B59: =COUNTA(B6:B45)
A60: Implemented alerts: | B60: =COUNTIF(L6:L45,"Implemented")
A61: Critical severity alerts: | B61: =COUNTIF(F6:F45,"Critical")
A62: High severity alerts: | B62: =COUNTIF(F6:F45,"High")
A63: Alerts with auto-response: | B63: =COUNTIF(K6:K45,"Yes")
A64: Alert coverage score: | B64: =IF(COUNTA(B6:B45)>0,COUNTIF(L6:L45,"Implemented")/COUNTA(B6:B45),0)

Sheet Monitoring_Dashboard
A1: MONITORING DASHBOARD ASSESSMENT
A2: Document monitoring dashboards, KPIs tracked, and review frequency
A4: SECTION A: DASHBOARD INVENTORY
A5: Dashboard_ID | B5: Dashboard_Name | C5: Platform | D5: Primary_Audience | E5: Update_Frequency | F5: Review_Frequency | G5: Key_Metrics_Displayed | H5: Alerting_Integrated | I5: Status | J5: Evidence_Ref
A6: DSH-001
A7: DSH-002
A8: DSH-003
A9: DSH-004
A10: DSH-005
A11: DSH-006
A12: DSH-007
A13: DSH-008
A14: DSH-009
A15: DSH-010
A16: DSH-011
A17: DSH-012
... A28: SECTION B: KEY PERFORMANCE INDICATORS (KPIs)
A29: KPI_ID | B29: KPI_Name | C29: Category | D29: Measurement_Unit | E29: Target_Value | F29: Current_Value | G29: Trend | H29: Review_Freq | I29: Owner_Role | J29: Status
A30: KPI-001 | B30: Total blocked requests (daily) | C30: Volume | D30: Count
A31: KPI-002 | B31: Block rate percentage | C31: Security | D31: Percentage
A32: KPI-003 | B32: Malware blocks (daily) | C32: Security | D32: Count
A33: KPI-004 | B33: Phishing blocks (daily) | C33: Security | D33: Count
A34: KPI-005 | B34: Policy violation blocks | C34: Compliance | D34: Count
A35: KPI-006 | B35: Bypass attempts detected | C35: Security | D35: Count
A36: KPI-007 | B36: False positive rate | C36: Operational | D36: Percentage
A37: KPI-008 | B37: False positive resolution time | C37: Operational | D37: Hours
A38: KPI-009 | B38: Alert response time (avg) | C38: Performance | D38: Minutes
A39: KPI-010 | B39: Critical incident response time | C39: Performance | D39: Minutes
A40: KPI-011 | B40: User complaints (weekly) | C40: Operational | D40: Count
A41: KPI-012 | B41: Exception requests (monthly) | C41: Compliance | D41: Count
... A49: KPI-020 | B49: Configuration change count | C49: Operational | D49: Count
A52: SECTION C: SUMMARY METRICS
A53: Total dashboards configured: | B53: =COUNTA(B6:B25)
A54: Dashboards with alerting: | B54: =COUNTIF(H6:H25,"Yes")
A55: Real-time dashboards: | B55: =COUNTIF(E6:E25,"Real-Time")
A56: KPIs defined: | B56: =COUNTA(B30:B49)
A57: KPIs meeting target: | B57: =COUNTIF(J30:J49,"Met")
A58: KPIs at risk: | B58: =COUNTIF(J30:J49,"At_Risk")+COUNTIF(J30:J49,"Not_Met")

Sheet Incident_Response
A1: INCIDENT RESPONSE ASSESSMENT
A2: Document incident categories, SLAs, response procedures, and performance metrics
A4: SECTION A: INCIDENT CATEGORIES & SLAs
A5: Category_ID | B5: Incident_Category | C5: Default_Severity | D5: Response_SLA_Min | E5: Resolution_SLA_Hrs | F5: Escalation_Threshold | G5: Response_Procedure | H5: Owner_Role | I5: Status
A6: CAT-001 | B6: Malware delivery attempt | C6: Critical | D6: 15 | E6: 4
A7: CAT-002 | B7: Phishing site access | C7: Critical | D7: 15 | E7: 4
A8: CAT-003 | B8: Command & Control communication | C8: Critical | D8: 15 | E8: 2
A9: CAT-004 | B9: Data exfiltration attempt | C9: Critical | D9: 15 | E9: 4
A10: CAT-005 | B10: Exploit kit encounter | C10: High | D10: 30 | E10: 8
A11: CAT-006 | B11: Policy violation - gambling | C11: Medium | D11: 60 | E11: 24
A12: CAT-007 | B12: Policy violation - adult content | C12: Medium | D12: 60 | E12: 24
A13: CAT-008 | B13: Unauthorized bypass attempt | C13: High | D13: 30 | E13: 8
A14: CAT-009 | B14: Web filter system failure | C14: Critical | D14: 15 | E14: 4
A15: CAT-010 | B15: Log collection failure | C15: High | D15: 30 | E15: 8
A16: CAT-011 | B16: False positive - business impact | C16: Medium | D16: 60 | E16: 24
A17: CAT-012 | B17: User access exception request | C17: Low | D17: 240 | E17: 72
... A20: CAT-015 | B20: Performance degradation | C20: Medium | D20: 60 | E20: 24
A24: SECTION B: SLA PERFORMANCE (Last 90 Days)
A25: Metric | B25: Target | C25: Actual | D25: Status | E25: Notes
A26: Critical incident response time | B26: <15 min
A27: High incident response time | B27: <30 min
A28: Medium incident response time | B28: <60 min
A29: Low incident response time | B29: <4 hours
A30: Critical resolution time | B30: <4 hours
A31: High resolution time | B31: <8 hours
A32: Medium resolution time | B32: <24 hours
A33: Overall SLA compliance rate | B33: >95%
A34: Mean time to detect (MTTD) | B34: <5 min
A35: Mean time to respond (MTTR) | B35: <30 min
A38: SECTION C: RECENT INCIDENT SUMMARY (Last 20 Incidents)
A39: Incident_ID | B39: Date_Detected | C39: Category | D39: Severity | E39: Response_Time_Min | F39: Resolution_Time_Hrs | G39: SLA_Met | H39: Root_Cause | I39: Lessons_Learned | J39: Evidence_Ref
A40: INC-001
A41: INC-002
A42: INC-003
A43: INC-004
A44: INC-005
A45: INC-006
A46: INC-007
A47: INC-008
A48: INC-009
...

Sheet Blocked_Events_Analysis
A1: BLOCKED EVENTS ANALYSIS
A2: Analyze patterns, trends, and categories of blocked web filtering events
A4: SECTION A: BLOCKED EVENT CATEGORIES
A5: Category_ID | B5: Block_Category | C5: Events_30_Days | D5: Events_90_Days | E5: Trend | F5: Top_Source | G5: Risk_Level | H5: Action_Required | I5: Notes
A6: BLK-001 | B6: Malware
A7: BLK-002 | B7: Phishing
A8: BLK-003 | B8: Command & Control
A9: BLK-004 | B9: Exploit Kits
A10: BLK-005 | B10: Ransomware
A11: BLK-006 | B11: Cryptomining
A12: BLK-007 | B12: Spam URLs
A13: BLK-008 | B13: Adult Content
A14: BLK-009 | B14: Gambling
A15: BLK-010 | B15: Social Media (if blocked)
A16: BLK-011 | B16: Streaming Media (if blocked)
A17: BLK-012 | B17: File Sharing
... A25: BLK-020 | B25: Other
A28: SECTION B: TOP 10 BLOCKED THREATS (Last 30 Days)
A29: Rank | B29: Threat_Type/URL | C29: Count_30_Days | D29: Percentage | E29: Mitigation_Status | F29: Notes
A30: 1
A31: 2
A32: 3
A33: 4
A34: 5
A35: 6
A36: 7
A37: 8
A38: 9
A39: 10
A42: SECTION C: 6-MONTH TREND ANALYSIS
A43: Month | B43: Total_Blocked | C43: Malware | D43: Phishing | E43: Policy_Violation | F43: Other | G43: Notes
A44: Month-6
A45: Month-5
A46: Month-4
A47: Month-3
A48: Month-2
A49: Current
A52: SECTION D: SUMMARY METRICS
A53: Categories tracked: | B53: =COUNTA(B6:B25)
A54: Categories requiring action: | B54: =COUNTIF(H6:H25,"Yes")
...

Sheet False_Positive_Mgmt
A1: FALSE POSITIVE MANAGEMENT
A2: Track false positives, tuning actions, and resolution effectiveness
A4: SECTION A: FALSE POSITIVE LOG
A5: FP_ID | B5: Date_Reported | C5: Reported_By | D5: Blocked_URL_Category | E5: Business_Justification | F5: Investigation_Result | G5: Resolution_Action | H5: Resolution_Date | I5: Resolution_Time_Hrs | J5: Recurrence | K5: Status | L5: Evidence_Ref
A6: FP-001
A7: FP-002
A8: FP-003
A9: FP-004
A10: FP-005
A11: FP-006
A12: FP-007
A13: FP-008
A14: FP-009
A15: FP-010
A16: FP-011
A17: FP-012
... A58: SECTION B: FALSE POSITIVE METRICS
A59: Metric | B59: Value | C59: Target | D59: Status | E59: Notes
A60: Total FPs reported (last 90 days) | B60: =COUNTA(B6:B55) | C60: <50
A61: Average resolution time (hours) | B61: =IFERROR(AVERAGE(I6:I55),"N/A") | C61: <24
A62: Open FPs | B62: =COUNTIF(K6:K55,"Open") | C62: <10
A63: Confirmed FP rate | B63: =IFERROR(COUNTIF(F6:F55,"Confirmed_FP")/COUNTA(F6:F55),"N/A") | C63: >80%
A64: Recurring FP percentage | B64: =IFERROR((COUNTIF(J6:J55,"Recurring")+COUNTIF(J6:J55,"Chronic"))/COUNTA(J6:J55),"N/A") | C64: <10%
A65: FPs escalated | B65: =COUNTIF(K6:K55,"Escalated") | C65: <5
A66: FPs resolved via whitelist | B66: =COUNTIF(G6:G55,"Whitelist") | C66: Monitor
A67: FPs resolved via tuning | B67: =COUNTIF(G6:G55,"Policy_Tuning") | C67: Monitor

Sheet Reporting_Schedule
A1: REPORTING SCHEDULE
A2: Document regular reports generated for web filtering operations
A4: SECTION A: REPORT INVENTORY
A5: Report_ID | B5: Report_Name | C5: Report_Type | D5: Frequency | E5: Generation_Method | F5: Distribution_List | G5: Delivery_Method | H5: Content_Summary | I5: Last_Generated | J5: Status | K5: Evidence_Ref
A6: RPT-001 | B6: Daily Threat Summary | C6: Operational | D6: Daily
A7: RPT-002 | B7: Weekly Block Statistics | C7: Operational | D7: Weekly
A8: RPT-003 | B8: Monthly Executive Dashboard | C8: Executive | D8: Monthly
A9: RPT-004 | B9: Quarterly Compliance Report | C9: Compliance | D9: Quarterly
A10: RPT-005 | B10: Annual Security Review | C10: Audit | D10: Annual
A11: RPT-006 | B11: Incident Summary Report | C11: Incident | D11: Weekly
A12: RPT-007 | B12: False Positive Analysis | C12: Operational | D12: Monthly
A13: RPT-008 | B13: User Activity Report | C13: Compliance | D13: Monthly
A14: RPT-009 | B14: Policy Exception Report | C14: Compliance | D14: Monthly
A15: RPT-010 | B15: Top Blocked Sites Report | C15: Trend | D15: Weekly
A16: RPT-011 | B16: Bandwidth Usage Report | C16: Operational | D16: Weekly
A17: RPT-012 | B17: SLA Performance Report | C17: Operational | D17: Monthly
... A25: RPT-020 | B25: Custom Ad-hoc Report | C25: Ad-hoc | D25: Ad-hoc
A28: SECTION B: STAKEHOLDER REPORTING COVERAGE
A29: Stakeholder | B29: Required_Reports | C29: Reports_Received | D29: Coverage_% | E29: Notes
A30: CISO | D30: =IFERROR(C30/B30,0)
A31: IT Management | D31: =IFERROR(C31/B31,0)
A32: Compliance Team | D32: =IFERROR(C32/B32,0)
A33: SOC | D33: =IFERROR(C33/B33,0)
A34: Internal Audit | D34: =IFERROR(C34/B34,0)
A35: External Auditors | D35: =IFERROR(C35/B35,0)
A36: HR | D36: =IFERROR(C36/B36,0)
A37: Legal | D37: =IFERROR(C37/B37,0)
A40: SECTION C: SUMMARY METRICS
A41: Total reports configured: | B41: =COUNTA(B6:B25)
A42: Automated reports: | B42: =COUNTIF(E6:E25,"Automated")
A43: Reports implemented: | B43: =COUNTIF(J6:J25,"Implemented")
A44: Daily reports: | B44: =COUNTIF(D6:D25,"Daily")
A45: Stakeholders with full coverage: | B45: =COUNTIF(D30:D37,">=100%")

Sheet Gap_Analysis
A1: GAP ANALYSIS - MONITORING & RESPONSE
A2: Identify and prioritize monitoring and incident response gaps for remediation
A4: GAP REGISTER
A5: Gap_ID | B5: Gap_Category | C5: Gap_Description | D5: Current_State | E5: Target_State | F5: Risk_Impact | G5: Affected_Systems | H5: Remediation_Action | I5: Owner | J5: Target_Date | K5: Status | L5: Priority | M5: Evidence_Ref
A6: GAP4-001
A7: GAP4-002
A8: GAP4-003
A9: GAP4-004
A10: GAP4-005
A11: GAP4-006
A12: GAP4-007
A13: GAP4-008
A14: GAP4-009
A15: GAP4-010
A16: GAP4-011
A17: GAP4-012
... A38: SUMMARY METRICS
A39: Total gaps identified: | B39: =COUNTA(C6:C35)
A40: Critical gaps: | B40: =COUNTIF(F6:F35,"Critical")
A41: High gaps: | B41: =COUNTIF(F6:F35,"High")
A42: Open gaps: | B42: =COUNTIF(K6:K35,"Open")
A43: In Progress gaps: | B43: =COUNTIF(K6:K35,"In_Progress")
A44: Resolved gaps: | B44: =COUNTIF(K6:K35,"Resolved")
A45: Gaps past target date: | B45: =COUNTIFS(K6:K35,"<>Resolved",J6:J35,"<"&TODAY())
A48: GAP CATEGORIES BREAKDOWN
A49: Category | B49: Count | C49: Open | D49: Critical/High
A50: Logging | B50: =COUNTIF(B6:B35,"Logging") | C50: =COUNTIFS(B6:B35,"Logging",K6:K35,"Open") | D50: =COUNTIFS(B6:B35,"Logging",F6:F35,"Critical")+COUNTIFS(B6:B35,"Logging",F6:F35,"High")
A51: Alerting | B51: =COUNTIF(B6:B35,"Alerting") | C51: =COUNTIFS(B6:B35,"Alerting",K6:K35,"Open") | D51: =COUNTIFS(B6:B35,"Alerting",F6:F35,"Critical")+COUNTIFS(B6:B35,"Alerting",F6:F35,"High")
A52: Monitoring | B52: =COUNTIF(B6:B35,"Monitoring") | C52: =COUNTIFS(B6:B35,"Monitoring",K6:K35,"Open") | D52: =COUNTIFS(B6:B35,"Monitoring",F6:F35,"Critical")+COUNTIFS(B6:B35,"Monitoring",F6:F35,"High")
A53: Incident_Response | B53: =COUNTIF(B6:B35,"Incident_Response") | C53: =COUNTIFS(B6:B35,"Incident_Response",K6:K35,"Open") | D53: =COUNTIFS(B6:B35,"Incident_Response",F6:F35,"Critical")+COUNTIFS(B6:B35,"Incident_Response",F6:F35,"High")
A54: Reporting | B54: =COUNTIF(B6:B35,"Reporting") | C54: =COUNTIFS(B6:B35,"Reporting",K6:K35,"Open") | D54: =COUNTIFS(B6:B35,"Reporting",F6:F35,"Critical")+COUNTIFS(B6:B35,"Reporting",F6:F35,"High")
A55: Integration | B55: =COUNTIF(B6:B35,"Integration") | C55: =COUNTIFS(B6:B35,"Integration",K6:K35,"Open") | D55: =COUNTIFS(B6:B35,"Integration",F6:F35,"Critical")+COUNTIFS(B6:B35,"Integration",F6:F35,"High")
A56: Retention | B56: =COUNTIF(B6:B35,"Retention") | C56: =COUNTIFS(B6:B35,"Retention",K6:K35,"Open") | D56: =COUNTIFS(B6:B35,"Retention",F6:F35,"Critical")+COUNTIFS(B6:B35,"Retention",F6:F35,"High")
A57: Process | B57: =COUNTIF(B6:B35,"Process") | C57: =COUNTIFS(B6:B35,"Process",K6:K35,"Open") | D57: =COUNTIFS(B6:B35,"Process",F6:F35,"Critical")+COUNTIFS(B6:B35,"Process",F6:F35,"High")

Sheet Evidence_Register
A1: EVIDENCE REGISTER - MONITORING & RESPONSE
A2: Catalog all evidence supporting monitoring and incident response assessment claims
A4: EVIDENCE CATALOG
A5: Evidence_ID | B5: Evidence_Title | C5: Evidence_Type | D5: Related_Sheet | E5: Related_Item_ID | F5: Date_Collected | G5: Collected_By | H5: Storage_Location | I5: Retention_Until | J5: Verification_Status | K5: Notes
A6: EV4-001
A7: EV4-002
A8: EV4-003
A9: EV4-004
A10: EV4-005
A11: EV4-006
A12: EV4-007
A13: EV4-008
A14: EV4-009
A15: EV4-010
A16: EV4-011
A17: EV4-012
... A108: EVIDENCE SUMMARY
A109: Total evidence items: | B109: =COUNTA(B6:B105)
A110: Verified evidence: | B110: =COUNTIF(J6:J105,"Verified")
A111: Pending verification: | B111: =COUNTIF(J6:J105,"Pending")
A112: Evidence by Log_Collection: | B112: =COUNTIF(D6:D105,"Log_Collection")
A113: Evidence by Alert_Configuration: | B113: =COUNTIF(D6:D105,"Alert_Configuration")
A114: Evidence by Incident_Response: | B114: =COUNTIF(D6:D105,"Incident_Response")

Sheet Approval_Sign_Off
A1: ASSESSMENT APPROVAL - MONITORING & RESPONSE
A2: ISMS-IMP-A.8.23.4 - ISO/IEC 27001:2022 Control A.8.23
A4: ASSESSMENT SUMMARY
A5: Assessment Date: | B5: =Instructions_Legend!B9
A6: Completed By: | B6: =Instructions_Legend!B10
A7: Organization: | B7: =Instructions_Legend!B11
A8: Total Log Sources: | B8: =Log_Collection!B53
A9: Total Alert Rules: | B9: =Alert_Configuration!B64
A10: Total KPIs Tracked: | B10: =Monitoring_Dashboard!B73
A11: Open Incidents: | B11: =COUNTIF(Incident_Response!G40:G59,"No")
A12: Open False Positives: | B12: ='False_Positive_Mgmt'!B63
A13: Open Gaps: | B13: =Gap_Analysis!B40
A14: Evidence Items: | B14: =Evidence_Register!B109
A16: APPROVAL WORKFLOW
A17: Role | B17: Name | C17: Date | D17: Signature | E17: Comments
A18: Completed By (Assessor)
A19: Reviewed By (Security Manager)
A20: Approved By (CISO)
A22: CERTIFICATION STATEMENT
A23: This assessment accurately reflects the current state of web filtering monitoring, logging, alerting, and incident response capabilities. All findings have been verified against actual system configurations and operational evidence. Identified gaps have been documented with remediation plans and assigned to responsible owners.
A25: NEXT REVIEW
A26: Scheduled Review Date:
A27: Review Frequency: | B27: Quarterly
A30: 💡 Assessment Philosophy:
A31: "Theater says 'we monitor.' Engineering says 'we detected 47,392 blocked threats last quarter with 0.3% false positive rate and 15-minute average response time.'"
