Workbook

Sheet Executive Summary
A1: ISMS-OP-CHK-A.8.15 — Logging Compliance Checklist
A3: DOCUMENT INFORMATION
A4: Document ID | B4: ISMS-OP-CHK-A.8.15
A5: Source Policy | B5: ISMS-OP-POL-A.8.15
A6: ISO Controls | B6: Logging
A7: Generated | B7: 08.02.2026
A8: Prepared By
A9: Organisation
A10: Review Cycle | B10: Annual
A12: OVERALL COMPLIANCE STATUS
A13: Overall Compliance | B13: ='Dashboard'!G13
A14: Status | B14: =IF(Dashboard!G13="N/A","NOT ASSESSED",IF(ISNUMBER(VALUE(SUBSTITUTE(Dashboard!G13,"%",""))),IF(VALUE(SUBSTITUTE(Dashboard!G13,"%",""))>=90,"GREEN",IF(VALUE(SUBSTITUTE(Dashboard!G13,"%",""))>=70,"AMBER","RED")),"NOT ASSESSED"))
A16: KEY METRICS
A17: Total Requirements | B17: ='Dashboard'!B13
A18: Compliant | B18: ='Dashboard'!C13
A19: Partial | B19: ='Dashboard'!D13
A20: Non-Compliant | B20: ='Dashboard'!E13
A21: Not Applicable | B21: ='Dashboard'!F13
A22: Owner Coverage | B22: =IF(Dashboard!B13=0,"N/A",ROUND((COUNTA('Event Logging'!F4:F5)+COUNTA('Event Logging Access Control'!F4:F6)+COUNTA('Protection of Event Log Info'!F4:F7)+COUNTA('Centralised Logging'!F4:F7)+COUNTA('Administrator and Operator Logs'!F4:F7)+COUNTA('Event Log Review'!F4:F6)+COUNTA('Event Log Retention'!F4:F6)+COUNTA('Swiss nFADP — DSV Article 4'!F4:F5)+COUNTA('Personal Privacy'!F4:F10))/Dashboard!B13*100,0)&"%")
A24: DOMAIN STATUS SUMMARY
A25: Domain | B25: Compliance % | C25: Compliant | D25: Gaps | E25: Status
A26: Event Logging | B26: ='Dashboard'!G4 | C26: ='Dashboard'!C4 | D26: ='Dashboard'!E4 | E26: =IF(Dashboard!G4="N/A","--",IF(ISNUMBER(VALUE(SUBSTITUTE(Dashboard!G4,"%",""))),IF(VALUE(SUBSTITUTE(Dashboard!G4,"%",""))>=90,"PASS",IF(VALUE(SUBSTITUTE(Dashboard!G4,"%",""))>=70,"REVIEW","FAIL")),"--"))
A27: Event Logging Access Control | B27: ='Dashboard'!G5 | C27: ='Dashboard'!C5 | D27: ='Dashboard'!E5 | E27: =IF(Dashboard!G5="N/A","--",IF(ISNUMBER(VALUE(SUBSTITUTE(Dashboard!G5,"%",""))),IF(VALUE(SUBSTITUTE(Dashboard!G5,"%",""))>=90,"PASS",IF(VALUE(SUBSTITUTE(Dashboard!G5,"%",""))>=70,"REVIEW","FAIL")),"--"))
A28: Protection of Event Log Info | B28: ='Dashboard'!G6 | C28: ='Dashboard'!C6 | D28: ='Dashboard'!E6 | E28: =IF(Dashboard!G6="N/A","--",IF(ISNUMBER(VALUE(SUBSTITUTE(Dashboard!G6,"%",""))),IF(VALUE(SUBSTITUTE(Dashboard!G6,"%",""))>=90,"PASS",IF(VALUE(SUBSTITUTE(Dashboard!G6,"%",""))>=70,"REVIEW","FAIL")),"--"))
A29: Centralised Logging | B29: ='Dashboard'!G7 | C29: ='Dashboard'!C7 | D29: ='Dashboard'!E7 | E29: =IF(Dashboard!G7="N/A","--",IF(ISNUMBER(VALUE(SUBSTITUTE(Dashboard!G7,"%",""))),IF(VALUE(SUBSTITUTE(Dashboard!G7,"%",""))>=90,"PASS",IF(VALUE(SUBSTITUTE(Dashboard!G7,"%",""))>=70,"REVIEW","FAIL")),"--"))
A30: Administrator and Operator Logs | B30: ='Dashboard'!G8 | C30: ='Dashboard'!C8 | D30: ='Dashboard'!E8 | E30: =IF(Dashboard!G8="N/A","--",IF(ISNUMBER(VALUE(SUBSTITUTE(Dashboard!G8,"%",""))),IF(VALUE(SUBSTITUTE(Dashboard!G8,"%",""))>=90,"PASS",IF(VALUE(SUBSTITUTE(Dashboard!G8,"%",""))>=70,"REVIEW","FAIL")),"--"))
A31: Event Log Review | B31: ='Dashboard'!G9 | C31: ='Dashboard'!C9 | D31: ='Dashboard'!E9 | E31: =IF(Dashboard!G9="N/A","--",IF(ISNUMBER(VALUE(SUBSTITUTE(Dashboard!G9,"%",""))),IF(VALUE(SUBSTITUTE(Dashboard!G9,"%",""))>=90,"PASS",IF(VALUE(SUBSTITUTE(Dashboard!G9,"%",""))>=70,"REVIEW","FAIL")),"--"))
A32: Event Log Retention | B32: ='Dashboard'!G10 | C32: ='Dashboard'!C10 | D32: ='Dashboard'!E10 | E32: =IF(Dashboard!G10="N/A","--",IF(ISNUMBER(VALUE(SUBSTITUTE(Dashboard!G10,"%",""))),IF(VALUE(SUBSTITUTE(Dashboard!G10,"%",""))>=90,"PASS",IF(VALUE(SUBSTITUTE(Dashboard!G10,"%",""))>=70,"REVIEW","FAIL")),"--"))
A33: Swiss nFADP — DSV Article 4 | B33: ='Dashboard'!G11 | C33: ='Dashboard'!C11 | D33: ='Dashboard'!E11 | E33: =IF(Dashboard!G11="N/A","--",IF(ISNUMBER(VALUE(SUBSTITUTE(Dashboard!G11,"%",""))),IF(VALUE(SUBSTITUTE(Dashboard!G11,"%",""))>=90,"PASS",IF(VALUE(SUBSTITUTE(Dashboard!G11,"%",""))>=70,"REVIEW","FAIL")),"--"))
A34: Personal Privacy | B34: ='Dashboard'!G12 | C34: ='Dashboard'!C12 | D34: ='Dashboard'!E12 | E34: =IF(Dashboard!G12="N/A","--",IF(ISNUMBER(VALUE(SUBSTITUTE(Dashboard!G12,"%",""))),IF(VALUE(SUBSTITUTE(Dashboard!G12,"%",""))>=90,"PASS",IF(VALUE(SUBSTITUTE(Dashboard!G12,"%",""))>=70,"REVIEW","FAIL")),"--"))
A36: CRITICAL ISSUES
A37: # | B37: Issue Description | C37: Domain | D37: Owner | E37: Due Date
A38: 1
A39: 2
A40: 3
A41: 4
A42: 5
A44: MANAGEMENT COMMENTARY
A45: [Enter management commentary on logging posture]
A49: APPROVAL
...

Sheet Dashboard
A1: Logging — Compliance Dashboard
A3: Domain | B3: Total Reqs | C3: Compliant | D3: Partial | E3: Non-Compliant | F3: N/A | G3: Compliance %
A4: Event Logging | B4: =COUNTA('Event Logging'!D4:D5) | C4: =COUNTIF('Event Logging'!D4:D5,"Compliant") | D4: =COUNTIF('Event Logging'!D4:D5,"Partial") | E4: =COUNTIF('Event Logging'!D4:D5,"Non-Compliant") | F4: =COUNTIF('Event Logging'!D4:D5,"N/A") | G4: =IF((B4-F4)=0,"N/A",ROUND(C4/(B4-F4)*100,1)&"%")
A5: Event Logging Access Control | B5: =COUNTA('Event Logging Access Control'!D4:D6) | C5: =COUNTIF('Event Logging Access Control'!D4:D6,"Compliant") | D5: =COUNTIF('Event Logging Access Control'!D4:D6,"Partial") | E5: =COUNTIF('Event Logging Access Control'!D4:D6,"Non-Compliant") | F5: =COUNTIF('Event Logging Access Control'!D4:D6,"N/A") | G5: =IF((B5-F5)=0,"N/A",ROUND(C5/(B5-F5)*100,1)&"%")
A6: Protection of Event Log Info | B6: =COUNTA('Protection of Event Log Info'!D4:D7) | C6: =COUNTIF('Protection of Event Log Info'!D4:D7,"Compliant") | D6: =COUNTIF('Protection of Event Log Info'!D4:D7,"Partial") | E6: =COUNTIF('Protection of Event Log Info'!D4:D7,"Non-Compliant") | F6: =COUNTIF('Protection of Event Log Info'!D4:D7,"N/A") | G6: =IF((B6-F6)=0,"N/A",ROUND(C6/(B6-F6)*100,1)&"%")
A7: Centralised Logging | B7: =COUNTA('Centralised Logging'!D4:D7) | C7: =COUNTIF('Centralised Logging'!D4:D7,"Compliant") | D7: =COUNTIF('Centralised Logging'!D4:D7,"Partial") | E7: =COUNTIF('Centralised Logging'!D4:D7,"Non-Compliant") | F7: =COUNTIF('Centralised Logging'!D4:D7,"N/A") | G7: =IF((B7-F7)=0,"N/A",ROUND(C7/(B7-F7)*100,1)&"%")
A8: Administrator and Operator Logs | B8: =COUNTA('Administrator and Operator Logs'!D4:D7) | C8: =COUNTIF('Administrator and Operator Logs'!D4:D7,"Compliant") | D8: =COUNTIF('Administrator and Operator Logs'!D4:D7,"Partial") | E8: =COUNTIF('Administrator and Operator Logs'!D4:D7,"Non-Compliant") | F8: =COUNTIF('Administrator and Operator Logs'!D4:D7,"N/A") | G8: =IF((B8-F8)=0,"N/A",ROUND(C8/(B8-F8)*100,1)&"%")
A9: Event Log Review | B9: =COUNTA('Event Log Review'!D4:D6) | C9: =COUNTIF('Event Log Review'!D4:D6,"Compliant") | D9: =COUNTIF('Event Log Review'!D4:D6,"Partial") | E9: =COUNTIF('Event Log Review'!D4:D6,"Non-Compliant") | F9: =COUNTIF('Event Log Review'!D4:D6,"N/A") | G9: =IF((B9-F9)=0,"N/A",ROUND(C9/(B9-F9)*100,1)&"%")
A10: Event Log Retention | B10: =COUNTA('Event Log Retention'!D4:D6) | C10: =COUNTIF('Event Log Retention'!D4:D6,"Compliant") | D10: =COUNTIF('Event Log Retention'!D4:D6,"Partial") | E10: =COUNTIF('Event Log Retention'!D4:D6,"Non-Compliant") | F10: =COUNTIF('Event Log Retention'!D4:D6,"N/A") | G10: =IF((B10-F10)=0,"N/A",ROUND(C10/(B10-F10)*100,1)&"%")
A11: Swiss nFADP — DSV Article 4 | B11: =COUNTA('Swiss nFADP — DSV Article 4'!D4:D5) | C11: =COUNTIF('Swiss nFADP — DSV Article 4'!D4:D5,"Compliant") | D11: =COUNTIF('Swiss nFADP — DSV Article 4'!D4:D5,"Partial") | E11: =COUNTIF('Swiss nFADP — DSV Article 4'!D4:D5,"Non-Compliant") | F11: =COUNTIF('Swiss nFADP — DSV Article 4'!D4:D5,"N/A") | G11: =IF((B11-F11)=0,"N/A",ROUND(C11/(B11-F11)*100,1)&"%")
A12: Personal Privacy | B12: =COUNTA('Personal Privacy'!D4:D10) | C12: =COUNTIF('Personal Privacy'!D4:D10,"Compliant") | D12: =COUNTIF('Personal Privacy'!D4:D10,"Partial") | E12: =COUNTIF('Personal Privacy'!D4:D10,"Non-Compliant") | F12: =COUNTIF('Personal Privacy'!D4:D10,"N/A") | G12: =IF((B12-F12)=0,"N/A",ROUND(C12/(B12-F12)*100,1)&"%")
A13: TOTAL | B13: =SUM(B4:B12) | C13: =SUM(C4:C12) | D13: =SUM(D4:D12) | E13: =SUM(E4:E12) | F13: =SUM(F4:F12) | G13: =IF((B13-F13)=0,"N/A",ROUND(C13/(B13-F13)*100,1)&"%")
A15: COMPLIANCE BY STATUS
A16: Compliant | B16: =C13 | C16: =IF(B13=0,"",ROUND(B16/B13*100,1)&"%")
A17: Partial | B17: =D13 | C17: =IF(B13=0,"",ROUND(B17/B13*100,1)&"%")
A18: Non-Compliant | B18: =E13 | C18: =IF(B13=0,"",ROUND(B18/B13*100,1)&"%")
A19: N/A | B19: =F13 | C19: =IF(B13=0,"",ROUND(B19/B13*100,1)&"%")
A21: TOP GAPS (Manual Entry)
A22: Priority | B22: Domain | C22: Requirement | D22: Owner | E22: Due Date | F22: Status
A34: COMPLIANCE TREND (Manual Entry)
A35: Assessment Date | B35: Overall % | C35: Compliant | D35: Gaps | E35: Assessor | F35: Notes

Sheet Event Logging
A1: Event Logging — Compliance Checklist
A2: ISO/IEC 27001:2022 — Control A.8.15: Logging
A3: Req # | B3: Section | C3: Requirement | D3: Status | E3: Evidence | F3: Owner | G3: Due Date | H3: Notes
A4: A.8.15-01 | B4: Event Logs Recording User Activities, | C4: Event logs recording user activities, exceptions, faults, and information security events shall be produced, kept, and regularly reviewed. The following events shall be logged:.
A5: A.8.15-02 | B5: Log Entry | C5: Each log entry shall include, at minimum:.

Sheet Event Logging Access Control
A1: Event Logging Access Control — Compliance Checklist
A2: ISO/IEC 27001:2022 — Control A.8.15: Logging
A3: Req # | B3: Section | C3: Requirement | D3: Status | E3: Evidence | F3: Owner | G3: Due Date | H3: Notes
A4: A.8.15-03 | B4: Event Logging Access | C4: Event logging shall be performed by authorised personnel only.
A5: A.8.15-04 | B5: Event Log Protection | C5: Event logs shall be protected and access restricted in line with the Access Control Policy. Access to raw logs shall be limited to the information security management team and authorised IT personnel.
A6: A.8.15-05 | B6: System Administrators | C6: System administrators shall not have permission to erase or deactivate logs of their own activities. Where this is not technically enforceable, compensating controls shall be implemented (e.g., forwarding logs to a central system outside the administrator's control, periodic review of administrator activity by a separate role).

Sheet Protection of Event Log Info
A1: Protection of Event Log Info — Compliance Checklist
A2: ISO/IEC 27001:2022 — Control A.8.15: Logging
A3: Req # | B3: Section | C3: Requirement | D3: Status | E3: Evidence | F3: Owner | G3: Due Date | H3: Notes
A4: A.8.15-06 | B4: Logging Facilities And Log Information | C4: Logging facilities and log information shall be protected against tampering and unauthorised access.
A5: A.8.15-07 | B5: Protect Against | C5: Controls shall protect against:.
A6: A.8.15-08 | B6: Storage Exhaustion Causing Loss Of Log | C6: Storage exhaustion causing loss of log data (logs shall fail open — alert when storage reaches 80% capacity rather than silently overwriting). Log storage capacity shall be monitored continuously, with automated alerts at 80% and 90% thresholds. When 90% capacity is reached, archived logs shall be offloaded to long-term storage and the platform team shall assess whether additional capacity is required.
A7: A.8.15-09 | B7: Log Protection | C7: Log protection shall be achieved through:.

Sheet Centralised Logging
A1: Centralised Logging — Compliance Checklist
A2: ISO/IEC 27001:2022 — Control A.8.15: Logging
A3: Req # | B3: Section | C3: Requirement | D3: Status | E3: Evidence | F3: Owner | G3: Due Date | H3: Notes
A4: A.8.15-10 | B4: The Centralised Logging Platform | C4: The centralised logging platform shall meet the following requirements:.
A5: A.8.15-11 | B5: Logs From All Critical Systems | C5: Logs from all critical systems shall be forwarded to the centralised logging platform. The platform shall be:.
A6: A.8.15-12 | B6: Separate From The Systems Generating The | C6: Separate from the systems generating the logs (source system administrators shall not have administrative access to the central log store).
A7: A.8.15-13 | B7: Manual Log Collection And Review | C7: Where automated centralised logging is not feasible for a specific system, manual log collection and review shall be performed at a defined frequency with documented justification.

Sheet Administrator and Operator Logs
A1: Administrator and Operator Logs — Compliance Checklist
A2: ISO/IEC 27001:2022 — Control A.8.15: Logging
A3: Req # | B3: Section | C3: Requirement | D3: Status | E3: Evidence | F3: Owner | G3: Due Date | H3: Notes
A4: A.8.15-14 | B4: System Administrator And System Operator | C4: System administrator and system operator activities shall be logged, and the logs protected and regularly reviewed.
A5: A.8.15-15 | B5: Administrator Actions | C5: Administrator actions shall be forwarded to the centralised logging system in real-time or near-real-time.
A6: A.8.15-16 | B6: A Periodic Review Of Privileged User | C6: A periodic review of privileged user activity shall be conducted (at least quarterly).
A7: A.8.15-17 | B7: Anomalous Privileged Activity (E.G., | C7: Anomalous privileged activity (e.g., after-hours access, bulk data operations, security configuration changes) shall generate alerts.

Sheet Event Log Review
A1: Event Log Review — Compliance Checklist
A2: ISO/IEC 27001:2022 — Control A.8.15: Logging
A3: Req # | B3: Section | C3: Requirement | D3: Status | E3: Evidence | F3: Owner | G3: Due Date | H3: Notes
A4: A.8.15-18 | B4: Responsibilities For Log Analysis | C4: Responsibilities shall be assigned for the analysis of security events recorded in logs.
A5: A.8.15-19 | B5: Automated Alerts For High-Risk Events | C5: The following events shall trigger immediate automated alerts and be escalated to the incident management process:.
A6: A.8.15-20 | B6: Escalation Process For High-Risk Events | C6: When a high-risk event is detected, the following escalation process shall be followed:.

Sheet Event Log Retention
A1: Event Log Retention — Compliance Checklist
A2: ISO/IEC 27001:2022 — Control A.8.15: Logging
A3: Req # | B3: Section | C3: Requirement | D3: Status | E3: Evidence | F3: Owner | G3: Due Date | H3: Notes
A4: A.8.15-21 | B4: Archived Logs | C4: Archived logs shall be encrypted, stored in a secure location, and retrievable within the following timeframes:.
A5: A.8.15-22 | B5: Retrieval Procedures | C5: Retrieval procedures shall be tested at least annually to verify that archived logs are accessible and intact.
A6: A.8.15-23 | B6: Not Be Retained Longer Than Necessary | C6: Logs shall not be retained longer than necessary. When retention periods expire, logs shall be securely deleted in line with the Information Classification and Handling Policy.

Sheet Swiss nFADP — DSV Article 4
A1: Swiss nFADP — DSV Article 4 — Compliance Checklist
A2: ISO/IEC 27001:2022 — Control A.8.15: Logging
A3: Req # | B3: Section | C3: Requirement | D3: Status | E3: Evidence | F3: Owner | G3: Due Date | H3: Notes
A4: A.8.15-24 | B4: Log Storage: Logs Of Sensitive Personal | C4: Log storage: Logs of sensitive personal data processing shall be stored separately from the processing system, retained for a minimum of 1 year, and access restricted to verifying data security compliance and ensuring confidentiality, integrity, availability, and traceability.
A5: A.8.15-25 | B5: Determine Whether DSV Art. 4 Applies | C5: The organisation shall determine whether DSV Art. 4 applies by assessing the following criteria:.

Sheet Personal Privacy
A1: Personal Privacy — Compliance Checklist
A2: ISO/IEC 27001:2022 — Control A.8.15: Logging
A3: Req # | B3: Section | C3: Requirement | D3: Status | E3: Evidence | F3: Owner | G3: Due Date | H3: Notes
A4: A.8.15-26 | B4: The Privacy Of Employees And Customers | C4: The privacy of employees and customers shall be respected in line with Swiss nFADP and applicable legal requirements when implementing logging.
A5: A.8.15-27 | B5: Logging Systems | C5: Logging systems shall serve legitimate security purposes (detecting threats, investigating incidents, verifying compliance) — not primarily for monitoring employee behaviour.
A6: A.8.15-28 | B6: Be Informed In Advance That Logging | C6: Employees shall be informed in advance that logging takes place, what is logged, and why, through the information security awareness programme and employment documentation.
A7: A.8.15-29 | B7: Only The Minimum Necessary Data | C7: Only the minimum necessary data shall be collected and retained (data minimisation).
A8: A.8.15-30 | B8: Access To Logs | C8: Access to logs containing employee data shall be restricted to authorised security and compliance personnel only — not line managers for general browsing.
A9: A.8.15-31 | B9: Keystroke Logging And Continuous | C9: Keystroke logging and continuous individual activity surveillance are disproportionate and shall not be implemented.
A10: A.8.15-32 | B10: Vendors For Troubleshooting | C10: Where logs containing personal data are shared with external parties (e.g., vendors for troubleshooting), personal identifiers shall be masked or anonymised.
