Workbook

Sheet Executive Summary
A1: PRIV-CHK-A.1.4.6-10 — PII Lifecycle, Retention and Disposal Compliance Checklist
A3: DOCUMENT INFORMATION
A4: Document ID | B4: PRIV-CHK-A.1.4.6-10
A5: Source Policy | B5: PRIV-POL-A.1.4.6-10
A6: ISO Controls | B6: PII Lifecycle, Retention and Disposal
A7: Generated | B7: 30.09.2026
A8: Prepared By
A9: Organisation
A10: Review Cycle | B10: Annual
A12: OVERALL COMPLIANCE STATUS
A13: Overall Compliance | B13: ='Dashboard'!G9
A14: Status | B14: =IF(Dashboard!H9>0,"INCOMPLETE",IF(Dashboard!G9="N/A","NOT ASSESSED",IF(ISNUMBER(VALUE(SUBSTITUTE(Dashboard!G9,"%",""))),IF(VALUE(SUBSTITUTE(Dashboard!G9,"%",""))>=90,"GREEN",IF(VALUE(SUBSTITUTE(Dashboard!G9,"%",""))>=70,"AMBER","RED")),"NOT ASSESSED")))
A16: KEY METRICS
A17: Total Requirements | B17: ='Dashboard'!B9
A18: Compliant | B18: ='Dashboard'!C9
A19: Partial | B19: ='Dashboard'!D9
A20: Non-Compliant | B20: ='Dashboard'!E9
A21: Not Applicable | B21: ='Dashboard'!F9
A22: Unanswered | B22: ='Dashboard'!H9
A23: Owner Coverage | B23: =IF(Dashboard!B9=0,"N/A",ROUND((COUNTA('De-identification and Deletion'!F4:F7)+COUNTA('Temporary Files'!F4:F6)+COUNTA('Retention Management'!F4:F8)+COUNTA('Disposal Procedures'!F4:F7)+COUNTA('Transmission Controls'!F4:F7))/Dashboard!B9*100,0)&"%")
A25: DOMAIN STATUS SUMMARY
A26: Domain | B26: Compliance % | C26: Compliant | D26: Gaps | E26: Status
A27: De-identification and Deletion | B27: ='Dashboard'!G4 | C27: ='Dashboard'!C4 | D27: ='Dashboard'!E4 | E27: =IF(Dashboard!H4>0,"INCOMPLETE",IF(Dashboard!G4="N/A","--",IF(ISNUMBER(VALUE(SUBSTITUTE(Dashboard!G4,"%",""))),IF(VALUE(SUBSTITUTE(Dashboard!G4,"%",""))>=90,"PASS",IF(VALUE(SUBSTITUTE(Dashboard!G4,"%",""))>=70,"REVIEW","FAIL")),"--")))
A28: Temporary Files | B28: ='Dashboard'!G5 | C28: ='Dashboard'!C5 | D28: ='Dashboard'!E5 | E28: =IF(Dashboard!H5>0,"INCOMPLETE",IF(Dashboard!G5="N/A","--",IF(ISNUMBER(VALUE(SUBSTITUTE(Dashboard!G5,"%",""))),IF(VALUE(SUBSTITUTE(Dashboard!G5,"%",""))>=90,"PASS",IF(VALUE(SUBSTITUTE(Dashboard!G5,"%",""))>=70,"REVIEW","FAIL")),"--")))
A29: Retention Management | B29: ='Dashboard'!G6 | C29: ='Dashboard'!C6 | D29: ='Dashboard'!E6 | E29: =IF(Dashboard!H6>0,"INCOMPLETE",IF(Dashboard!G6="N/A","--",IF(ISNUMBER(VALUE(SUBSTITUTE(Dashboard!G6,"%",""))),IF(VALUE(SUBSTITUTE(Dashboard!G6,"%",""))>=90,"PASS",IF(VALUE(SUBSTITUTE(Dashboard!G6,"%",""))>=70,"REVIEW","FAIL")),"--")))
A30: Disposal Procedures | B30: ='Dashboard'!G7 | C30: ='Dashboard'!C7 | D30: ='Dashboard'!E7 | E30: =IF(Dashboard!H7>0,"INCOMPLETE",IF(Dashboard!G7="N/A","--",IF(ISNUMBER(VALUE(SUBSTITUTE(Dashboard!G7,"%",""))),IF(VALUE(SUBSTITUTE(Dashboard!G7,"%",""))>=90,"PASS",IF(VALUE(SUBSTITUTE(Dashboard!G7,"%",""))>=70,"REVIEW","FAIL")),"--")))
A31: Transmission Controls | B31: ='Dashboard'!G8 | C31: ='Dashboard'!C8 | D31: ='Dashboard'!E8 | E31: =IF(Dashboard!H8>0,"INCOMPLETE",IF(Dashboard!G8="N/A","--",IF(ISNUMBER(VALUE(SUBSTITUTE(Dashboard!G8,"%",""))),IF(VALUE(SUBSTITUTE(Dashboard!G8,"%",""))>=90,"PASS",IF(VALUE(SUBSTITUTE(Dashboard!G8,"%",""))>=70,"REVIEW","FAIL")),"--")))
A33: CRITICAL ISSUES
A34: # | B34: Issue Description | C34: Domain | D34: Owner | E34: Due Date
A35: 1
A36: 2
A37: 3
A38: 4
A39: 5
A41: MANAGEMENT COMMENTARY
A42: [Enter management commentary on pii lifecycle, retention and disposal posture]
A46: APPROVAL
A47: Assessed By
A48: Name:
A49: Date:
...

Sheet Dashboard
A1: PII Lifecycle, Retention and Disposal — Compliance Dashboard
A3: Domain | B3: Total Reqs | C3: Compliant | D3: Partial | E3: Non-Compliant | F3: N/A | G3: Compliance % | H3: Unassessed
A4: De-identification and Deletion | B4: =COUNTA('De-identification and Deletion'!A4:A7) | C4: =COUNTIF('De-identification and Deletion'!D4:D7,"Compliant") | D4: =COUNTIF('De-identification and Deletion'!D4:D7,"Partial") | E4: =COUNTIF('De-identification and Deletion'!D4:D7,"Non-Compliant") | F4: =COUNTIF('De-identification and Deletion'!D4:D7,"N/A") | G4: =IF((B4-F4)=0,"N/A",ROUND(C4/(B4-F4)*100,1)&"%") | H4: =B4-(C4+D4+E4+F4)
A5: Temporary Files | B5: =COUNTA('Temporary Files'!A4:A6) | C5: =COUNTIF('Temporary Files'!D4:D6,"Compliant") | D5: =COUNTIF('Temporary Files'!D4:D6,"Partial") | E5: =COUNTIF('Temporary Files'!D4:D6,"Non-Compliant") | F5: =COUNTIF('Temporary Files'!D4:D6,"N/A") | G5: =IF((B5-F5)=0,"N/A",ROUND(C5/(B5-F5)*100,1)&"%") | H5: =B5-(C5+D5+E5+F5)
A6: Retention Management | B6: =COUNTA('Retention Management'!A4:A8) | C6: =COUNTIF('Retention Management'!D4:D8,"Compliant") | D6: =COUNTIF('Retention Management'!D4:D8,"Partial") | E6: =COUNTIF('Retention Management'!D4:D8,"Non-Compliant") | F6: =COUNTIF('Retention Management'!D4:D8,"N/A") | G6: =IF((B6-F6)=0,"N/A",ROUND(C6/(B6-F6)*100,1)&"%") | H6: =B6-(C6+D6+E6+F6)
A7: Disposal Procedures | B7: =COUNTA('Disposal Procedures'!A4:A7) | C7: =COUNTIF('Disposal Procedures'!D4:D7,"Compliant") | D7: =COUNTIF('Disposal Procedures'!D4:D7,"Partial") | E7: =COUNTIF('Disposal Procedures'!D4:D7,"Non-Compliant") | F7: =COUNTIF('Disposal Procedures'!D4:D7,"N/A") | G7: =IF((B7-F7)=0,"N/A",ROUND(C7/(B7-F7)*100,1)&"%") | H7: =B7-(C7+D7+E7+F7)
A8: Transmission Controls | B8: =COUNTA('Transmission Controls'!A4:A7) | C8: =COUNTIF('Transmission Controls'!D4:D7,"Compliant") | D8: =COUNTIF('Transmission Controls'!D4:D7,"Partial") | E8: =COUNTIF('Transmission Controls'!D4:D7,"Non-Compliant") | F8: =COUNTIF('Transmission Controls'!D4:D7,"N/A") | G8: =IF((B8-F8)=0,"N/A",ROUND(C8/(B8-F8)*100,1)&"%") | H8: =B8-(C8+D8+E8+F8)
A9: TOTAL | B9: =SUM(B4:B8) | C9: =SUM(C4:C8) | D9: =SUM(D4:D8) | E9: =SUM(E4:E8) | F9: =SUM(F4:F8) | G9: =IF((B9-F9)=0,"N/A",ROUND(C9/(B9-F9)*100,1)&"%") | H9: =SUM(H4:H8)
A11: COMPLIANCE BY STATUS
A12: Compliant | B12: =C9 | C12: =IF(B9=0,"",ROUND(B12/B9*100,1)&"%")
A13: Partial | B13: =D9 | C13: =IF(B9=0,"",ROUND(B13/B9*100,1)&"%")
A14: Non-Compliant | B14: =E9 | C14: =IF(B9=0,"",ROUND(B14/B9*100,1)&"%")
A15: N/A | B15: =F9 | C15: =IF(B9=0,"",ROUND(B15/B9*100,1)&"%")
A17: TOP GAPS (Manual Entry)
A18: Priority | B18: Domain | C18: Requirement | D18: Owner | E18: Due Date | F18: Status
A30: COMPLIANCE TREND (Manual Entry)
A31: Assessment Date | B31: Overall % | C31: Compliant | D31: Gaps | E31: Assessor | F31: Notes

Sheet De-identification and Deletion
A1: De-identification and Deletion — Compliance Checklist
A2: ISO/IEC 27701:2025 — Controls A.1.4.6-10: PII Lifecycle, Retention and Disposal
A3: Req # | B3: Section | C3: Requirement | D3: Status | E3: Evidence | F3: Owner | G3: Due Date | H3: Notes
A4: A.1.4.6-01 | B4: End-of-Purpose Obligation | C4: When PII is no longer necessary for the identified processing purpose(s), the organisation shall either delete the PII (irreversible destruction) or de-identify it to a form that does not permit identification or re-identification of PII principals. This obligation applies as soon as the purpose is no longer served.
A5: A.1.4.6-02 | B5: All Copies | C5: The deletion or de-identification obligation applies to all copies of PII: primary databases, backups, archives, processing logs, and temporary copies. A single primary deletion is not sufficient if copies persist in secondary locations.
A6: A.1.4.6-03 | B6: Legal Hold Retention | C6: Where a legal obligation requires retention beyond the processing purpose (e.g. tax records, employment records, legal hold), retention shall be limited to the legally required period, restricted to the minimum scope, and clearly recorded in the Retention Schedule with the legal provision reference.
A7: A.1.4.6-04 | B7: Anonymisation Confirmation | C7: Where de-identification is used in lieu of deletion, the DPO shall confirm in writing that the de-identification method constitutes true anonymisation such that re-identification is not reasonably possible. Pseudonymised data (re-identifiable with a key) does not satisfy this requirement.

Sheet Temporary Files
A1: Temporary Files — Compliance Checklist
A2: ISO/IEC 27701:2025 — Controls A.1.4.6-10: PII Lifecycle, Retention and Disposal
A3: Req # | B3: Section | C3: Requirement | D3: Status | E3: Evidence | F3: Owner | G3: Due Date | H3: Notes
A4: A.1.4.7-01 | B4: Temporary File Procedures | C4: The organisation shall ensure that temporary files created as a result of PII processing are disposed of following documented procedures within a specified, documented period. A schedule of temporary file types and maximum retention periods shall be maintained.
A5: A.1.4.7-02 | B5: Automated Purge | C5: Automated purge mechanisms are preferred over manual deletion for temporary PII files. Where automated purge is not technically feasible, manual deletion shall be scheduled and logged. Processing cache files shall be purged within 24 hours; export files within 72 hours of transmission.
A6: A.1.4.7-03 | B6: Development Copies | C6: Temporary development copies containing real PII shall be subject to immediate deletion after use. DPO approval is required for any development use of real PII, and deletion confirmation shall be documented.

Sheet Retention Management
A1: Retention Management — Compliance Checklist
A2: ISO/IEC 27701:2025 — Controls A.1.4.6-10: PII Lifecycle, Retention and Disposal
A3: Req # | B3: Section | C3: Requirement | D3: Status | E3: Evidence | F3: Owner | G3: Due Date | H3: Notes
A4: A.1.4.8-01 | B4: Retention Schedule | C4: The DPO shall maintain a PII Retention Schedule specifying: PII category or processing activity; retention period with trigger date; legal or regulatory basis where applicable; and disposal method upon expiry. The schedule forms part of the RoPA.
A5: A.1.4.8-02 | B5: No Unnecessary Retention | C5: The organisation shall not retain PII for longer than is necessary for the purposes for which it is processed. Retention periods shall be based on documented need — not on the principle of 'keeping just in case'.
A6: A.1.4.8-03 | B6: Conflicting Retention Obligations | C6: Where multiple regulatory obligations create different retention requirements for the same data, the longest mandatory period applies for the legally required scope; data not required by the longer obligation shall be deleted at the earliest applicable period.
A7: A.1.4.8-04 | B7: Backup Retention Alignment | C7: Backups containing PII shall be subject to the same retention limits as primary data. Backup retention schedules shall align with PII retention periods or have a documented exception with compensating controls.
A8: A.1.4.8-05 | B8: Retention Schedule Review | C8: The PII Retention Schedule shall be reviewed at minimum annually, upon changes to regulatory requirements, and when processing activities change materially. Review evidence shall be documented.

Sheet Disposal Procedures
A1: Disposal Procedures — Compliance Checklist
A2: ISO/IEC 27701:2025 — Controls A.1.4.6-10: PII Lifecycle, Retention and Disposal
A3: Req # | B3: Section | C3: Requirement | D3: Status | E3: Evidence | F3: Owner | G3: Due Date | H3: Notes
A4: A.1.4.9-01 | B4: Disposal Requirements | C4: PII disposal shall be irreversible (not recoverable by routine technical means), documented (disposal action logged with date, scope, method), verified where technically feasible, and compliant with the classification level per PRIV-POL-A.3.20-22.
A5: A.1.4.9-02 | B5: Disposal Methods | C5: Disposal methods shall be appropriate to the data location: database records — SQL DELETE or approved in-place anonymisation; electronic files — cryptographic erasure or approved overwrite; physical documents — cross-cut shredding (CONFIDENTIAL) or cross-cut plus witness (RESTRICTED); cloud storage — deletion via approved API with provider confirmation.
A6: A.1.4.9-03 | B6: Disposal Triggers | C6: PII disposal shall be triggered by: expiry of the retention period; cessation of the processing purpose; data subject erasure request; consent withdrawal for consent-based processing where no other basis applies; and end of contract or employment for applicable PII categories.
A7: A.1.4.9-04 | B7: Disposal Logs | C7: Disposal logs shall record each disposal action with: date; PII category and scope disposed; disposal method; identity of person who performed or confirmed disposal. Disposal logs shall be retained for 5 years.

Sheet Transmission Controls
A1: Transmission Controls — Compliance Checklist
A2: ISO/IEC 27701:2025 — Controls A.1.4.6-10: PII Lifecycle, Retention and Disposal
A3: Req # | B3: Section | C3: Requirement | D3: Status | E3: Evidence | F3: Owner | G3: Due Date | H3: Notes
A4: A.1.4.10-01 | B4: Encryption in Transit | C4: All PII transmitted over networks shall be encrypted in transit using current TLS standards (minimum TLS 1.2; TLS 1.3 preferred). Unencrypted transmission of CONFIDENTIAL or RESTRICTED PII over public networks is prohibited.
A5: A.1.4.10-02 | B5: Approved Transfer Methods | C5: PII transmitted to external parties shall use approved secure transfer methods per PRIV-POL-A.3.5-7. Transfer mechanisms shall ensure that PII reaches its intended destination and not be interceptable or diverted.
A6: A.1.4.10-03 | B6: Restricted PII Delivery Confirmation | C6: Delivery confirmation or receipt acknowledgment shall be obtained for transfers of RESTRICTED PII (special category). Confirmation records shall be maintained and cross-referenced with the Disclosure Register.
A7: A.1.4.10-04 | B7: Transmission Logging | C7: Transmission logs shall be maintained for CONFIDENTIAL and RESTRICTED PII transfers per PRIV-POL-A.3.23-31 logging requirements. Logs shall be sufficient to identify what was transmitted, to whom, and when.
