Workbook

Sheet Executive Summary
A1: ISMS-OP-CHK-A.5.35-36 — Independent Review and Compliance Compliance Checklist
A3: DOCUMENT INFORMATION
A4: Document ID | B4: ISMS-OP-CHK-A.5.35-36
A5: Source Policy | B5: ISMS-OP-POL-A.5.35-36
A6: ISO Controls | B6: Independent Review and Compliance
A7: Generated | B7: 30.09.2026
A8: Prepared By
A9: Organisation
A10: Review Cycle | B10: Annual
A12: OVERALL COMPLIANCE STATUS
A13: Overall Compliance | B13: ='Dashboard'!G13
A14: Status | B14: =IF(Dashboard!H13>0,"INCOMPLETE",IF(Dashboard!G13="N/A","NOT ASSESSED",IF(ISNUMBER(VALUE(SUBSTITUTE(Dashboard!G13,"%",""))),IF(VALUE(SUBSTITUTE(Dashboard!G13,"%",""))>=90,"GREEN",IF(VALUE(SUBSTITUTE(Dashboard!G13,"%",""))>=70,"AMBER","RED")),"NOT ASSESSED")))
A16: KEY METRICS
A17: Total Requirements | B17: ='Dashboard'!B13
A18: Compliant | B18: ='Dashboard'!C13
A19: Partial | B19: ='Dashboard'!D13
A20: Non-Compliant | B20: ='Dashboard'!E13
A21: Not Applicable | B21: ='Dashboard'!F13
A22: Unanswered | B22: ='Dashboard'!H13
A23: Owner Coverage | B23: =IF(Dashboard!B13=0,"N/A",ROUND((COUNTA('Audit Programme'!F4:F14)+COUNTA('Independent Review of Info Sec'!F4:F23)+COUNTA('Finding Severity Classification'!F4:F4)+COUNTA('Corrective Action & Remediation'!F4:F7)+COUNTA('Compliance Verification'!F4:F8)+COUNTA('Non-Conformity Management'!F4:F9)+COUNTA('Risk Acceptance'!F4:F6)+COUNTA('Compl Metrics and Reporting'!F4:F6)+COUNTA('Improvement Inputs'!F4:F6))/Dashboard!B13*100,0)&"%")
A25: DOMAIN STATUS SUMMARY
A26: Domain | B26: Compliance % | C26: Compliant | D26: Gaps | E26: Status
A27: Audit Programme | B27: ='Dashboard'!G4 | C27: ='Dashboard'!C4 | D27: ='Dashboard'!E4 | E27: =IF(Dashboard!H4>0,"INCOMPLETE",IF(Dashboard!G4="N/A","--",IF(ISNUMBER(VALUE(SUBSTITUTE(Dashboard!G4,"%",""))),IF(VALUE(SUBSTITUTE(Dashboard!G4,"%",""))>=90,"PASS",IF(VALUE(SUBSTITUTE(Dashboard!G4,"%",""))>=70,"REVIEW","FAIL")),"--")))
A28: Independent Review of Info Sec | B28: ='Dashboard'!G5 | C28: ='Dashboard'!C5 | D28: ='Dashboard'!E5 | E28: =IF(Dashboard!H5>0,"INCOMPLETE",IF(Dashboard!G5="N/A","--",IF(ISNUMBER(VALUE(SUBSTITUTE(Dashboard!G5,"%",""))),IF(VALUE(SUBSTITUTE(Dashboard!G5,"%",""))>=90,"PASS",IF(VALUE(SUBSTITUTE(Dashboard!G5,"%",""))>=70,"REVIEW","FAIL")),"--")))
A29: Finding Severity Classification | B29: ='Dashboard'!G6 | C29: ='Dashboard'!C6 | D29: ='Dashboard'!E6 | E29: =IF(Dashboard!H6>0,"INCOMPLETE",IF(Dashboard!G6="N/A","--",IF(ISNUMBER(VALUE(SUBSTITUTE(Dashboard!G6,"%",""))),IF(VALUE(SUBSTITUTE(Dashboard!G6,"%",""))>=90,"PASS",IF(VALUE(SUBSTITUTE(Dashboard!G6,"%",""))>=70,"REVIEW","FAIL")),"--")))
A30: Corrective Action & Remediation | B30: ='Dashboard'!G7 | C30: ='Dashboard'!C7 | D30: ='Dashboard'!E7 | E30: =IF(Dashboard!H7>0,"INCOMPLETE",IF(Dashboard!G7="N/A","--",IF(ISNUMBER(VALUE(SUBSTITUTE(Dashboard!G7,"%",""))),IF(VALUE(SUBSTITUTE(Dashboard!G7,"%",""))>=90,"PASS",IF(VALUE(SUBSTITUTE(Dashboard!G7,"%",""))>=70,"REVIEW","FAIL")),"--")))
A31: Compliance Verification | B31: ='Dashboard'!G8 | C31: ='Dashboard'!C8 | D31: ='Dashboard'!E8 | E31: =IF(Dashboard!H8>0,"INCOMPLETE",IF(Dashboard!G8="N/A","--",IF(ISNUMBER(VALUE(SUBSTITUTE(Dashboard!G8,"%",""))),IF(VALUE(SUBSTITUTE(Dashboard!G8,"%",""))>=90,"PASS",IF(VALUE(SUBSTITUTE(Dashboard!G8,"%",""))>=70,"REVIEW","FAIL")),"--")))
A32: Non-Conformity Management | B32: ='Dashboard'!G9 | C32: ='Dashboard'!C9 | D32: ='Dashboard'!E9 | E32: =IF(Dashboard!H9>0,"INCOMPLETE",IF(Dashboard!G9="N/A","--",IF(ISNUMBER(VALUE(SUBSTITUTE(Dashboard!G9,"%",""))),IF(VALUE(SUBSTITUTE(Dashboard!G9,"%",""))>=90,"PASS",IF(VALUE(SUBSTITUTE(Dashboard!G9,"%",""))>=70,"REVIEW","FAIL")),"--")))
A33: Risk Acceptance | B33: ='Dashboard'!G10 | C33: ='Dashboard'!C10 | D33: ='Dashboard'!E10 | E33: =IF(Dashboard!H10>0,"INCOMPLETE",IF(Dashboard!G10="N/A","--",IF(ISNUMBER(VALUE(SUBSTITUTE(Dashboard!G10,"%",""))),IF(VALUE(SUBSTITUTE(Dashboard!G10,"%",""))>=90,"PASS",IF(VALUE(SUBSTITUTE(Dashboard!G10,"%",""))>=70,"REVIEW","FAIL")),"--")))
A34: Compl Metrics and Reporting | B34: ='Dashboard'!G11 | C34: ='Dashboard'!C11 | D34: ='Dashboard'!E11 | E34: =IF(Dashboard!H11>0,"INCOMPLETE",IF(Dashboard!G11="N/A","--",IF(ISNUMBER(VALUE(SUBSTITUTE(Dashboard!G11,"%",""))),IF(VALUE(SUBSTITUTE(Dashboard!G11,"%",""))>=90,"PASS",IF(VALUE(SUBSTITUTE(Dashboard!G11,"%",""))>=70,"REVIEW","FAIL")),"--")))
A35: Improvement Inputs | B35: ='Dashboard'!G12 | C35: ='Dashboard'!C12 | D35: ='Dashboard'!E12 | E35: =IF(Dashboard!H12>0,"INCOMPLETE",IF(Dashboard!G12="N/A","--",IF(ISNUMBER(VALUE(SUBSTITUTE(Dashboard!G12,"%",""))),IF(VALUE(SUBSTITUTE(Dashboard!G12,"%",""))>=90,"PASS",IF(VALUE(SUBSTITUTE(Dashboard!G12,"%",""))>=70,"REVIEW","FAIL")),"--")))
A37: CRITICAL ISSUES
A38: # | B38: Issue Description | C38: Domain | D38: Owner | E38: Due Date
A39: 1
A40: 2
A41: 3
A42: 4
A43: 5
A45: MANAGEMENT COMMENTARY
A46: [Enter management commentary on independent review and compliance posture]
...

Sheet Dashboard
A1: Independent Review and Compliance — Compliance Dashboard
A3: Domain | B3: Total Reqs | C3: Compliant | D3: Partial | E3: Non-Compliant | F3: N/A | G3: Compliance % | H3: Unassessed
A4: Audit Programme | B4: =COUNTA('Audit Programme'!A4:A14) | C4: =COUNTIF('Audit Programme'!D4:D14,"Compliant") | D4: =COUNTIF('Audit Programme'!D4:D14,"Partial") | E4: =COUNTIF('Audit Programme'!D4:D14,"Non-Compliant") | F4: =COUNTIF('Audit Programme'!D4:D14,"N/A") | G4: =IF((B4-F4)=0,"N/A",ROUND(C4/(B4-F4)*100,1)&"%") | H4: =B4-(C4+D4+E4+F4)
A5: Independent Review of Info Sec | B5: =COUNTA('Independent Review of Info Sec'!A4:A23) | C5: =COUNTIF('Independent Review of Info Sec'!D4:D23,"Compliant") | D5: =COUNTIF('Independent Review of Info Sec'!D4:D23,"Partial") | E5: =COUNTIF('Independent Review of Info Sec'!D4:D23,"Non-Compliant") | F5: =COUNTIF('Independent Review of Info Sec'!D4:D23,"N/A") | G5: =IF((B5-F5)=0,"N/A",ROUND(C5/(B5-F5)*100,1)&"%") | H5: =B5-(C5+D5+E5+F5)
A6: Finding Severity Classification | B6: =COUNTA('Finding Severity Classification'!A4:A4) | C6: =COUNTIF('Finding Severity Classification'!D4:D4,"Compliant") | D6: =COUNTIF('Finding Severity Classification'!D4:D4,"Partial") | E6: =COUNTIF('Finding Severity Classification'!D4:D4,"Non-Compliant") | F6: =COUNTIF('Finding Severity Classification'!D4:D4,"N/A") | G6: =IF((B6-F6)=0,"N/A",ROUND(C6/(B6-F6)*100,1)&"%") | H6: =B6-(C6+D6+E6+F6)
A7: Corrective Action & Remediation | B7: =COUNTA('Corrective Action & Remediation'!A4:A7) | C7: =COUNTIF('Corrective Action & Remediation'!D4:D7,"Compliant") | D7: =COUNTIF('Corrective Action & Remediation'!D4:D7,"Partial") | E7: =COUNTIF('Corrective Action & Remediation'!D4:D7,"Non-Compliant") | F7: =COUNTIF('Corrective Action & Remediation'!D4:D7,"N/A") | G7: =IF((B7-F7)=0,"N/A",ROUND(C7/(B7-F7)*100,1)&"%") | H7: =B7-(C7+D7+E7+F7)
A8: Compliance Verification | B8: =COUNTA('Compliance Verification'!A4:A8) | C8: =COUNTIF('Compliance Verification'!D4:D8,"Compliant") | D8: =COUNTIF('Compliance Verification'!D4:D8,"Partial") | E8: =COUNTIF('Compliance Verification'!D4:D8,"Non-Compliant") | F8: =COUNTIF('Compliance Verification'!D4:D8,"N/A") | G8: =IF((B8-F8)=0,"N/A",ROUND(C8/(B8-F8)*100,1)&"%") | H8: =B8-(C8+D8+E8+F8)
A9: Non-Conformity Management | B9: =COUNTA('Non-Conformity Management'!A4:A9) | C9: =COUNTIF('Non-Conformity Management'!D4:D9,"Compliant") | D9: =COUNTIF('Non-Conformity Management'!D4:D9,"Partial") | E9: =COUNTIF('Non-Conformity Management'!D4:D9,"Non-Compliant") | F9: =COUNTIF('Non-Conformity Management'!D4:D9,"N/A") | G9: =IF((B9-F9)=0,"N/A",ROUND(C9/(B9-F9)*100,1)&"%") | H9: =B9-(C9+D9+E9+F9)
A10: Risk Acceptance | B10: =COUNTA('Risk Acceptance'!A4:A6) | C10: =COUNTIF('Risk Acceptance'!D4:D6,"Compliant") | D10: =COUNTIF('Risk Acceptance'!D4:D6,"Partial") | E10: =COUNTIF('Risk Acceptance'!D4:D6,"Non-Compliant") | F10: =COUNTIF('Risk Acceptance'!D4:D6,"N/A") | G10: =IF((B10-F10)=0,"N/A",ROUND(C10/(B10-F10)*100,1)&"%") | H10: =B10-(C10+D10+E10+F10)
A11: Compl Metrics and Reporting | B11: =COUNTA('Compl Metrics and Reporting'!A4:A6) | C11: =COUNTIF('Compl Metrics and Reporting'!D4:D6,"Compliant") | D11: =COUNTIF('Compl Metrics and Reporting'!D4:D6,"Partial") | E11: =COUNTIF('Compl Metrics and Reporting'!D4:D6,"Non-Compliant") | F11: =COUNTIF('Compl Metrics and Reporting'!D4:D6,"N/A") | G11: =IF((B11-F11)=0,"N/A",ROUND(C11/(B11-F11)*100,1)&"%") | H11: =B11-(C11+D11+E11+F11)
A12: Improvement Inputs | B12: =COUNTA('Improvement Inputs'!A4:A6) | C12: =COUNTIF('Improvement Inputs'!D4:D6,"Compliant") | D12: =COUNTIF('Improvement Inputs'!D4:D6,"Partial") | E12: =COUNTIF('Improvement Inputs'!D4:D6,"Non-Compliant") | F12: =COUNTIF('Improvement Inputs'!D4:D6,"N/A") | G12: =IF((B12-F12)=0,"N/A",ROUND(C12/(B12-F12)*100,1)&"%") | H12: =B12-(C12+D12+E12+F12)
A13: TOTAL | B13: =SUM(B4:B12) | C13: =SUM(C4:C12) | D13: =SUM(D4:D12) | E13: =SUM(E4:E12) | F13: =SUM(F4:F12) | G13: =IF((B13-F13)=0,"N/A",ROUND(C13/(B13-F13)*100,1)&"%") | H13: =SUM(H4:H12)
A15: COMPLIANCE BY STATUS
A16: Compliant | B16: =C13 | C16: =IF(B13=0,"",ROUND(B16/B13*100,1)&"%")
A17: Partial | B17: =D13 | C17: =IF(B13=0,"",ROUND(B17/B13*100,1)&"%")
A18: Non-Compliant | B18: =E13 | C18: =IF(B13=0,"",ROUND(B18/B13*100,1)&"%")
A19: N/A | B19: =F13 | C19: =IF(B13=0,"",ROUND(B19/B13*100,1)&"%")
A21: TOP GAPS (Manual Entry)
A22: Priority | B22: Domain | C22: Requirement | D22: Owner | E22: Due Date | F22: Status
A34: COMPLIANCE TREND (Manual Entry)
A35: Assessment Date | B35: Overall % | C35: Compliant | D35: Gaps | E35: Assessor | F35: Notes

Sheet Audit Programme
A1: Audit Programme — Compliance Checklist
A2: ISO/IEC 27001:2022 — Controls A.5.35-36: Independent Review and Compliance
A3: Req # | B3: Section | C3: Requirement | D3: Status | E3: Evidence | F3: Owner | G3: Due Date | H3: Notes
A4: A.5.35-36-01 | B4: Internal Audits | C4: Internal audits shall be conducted to assess the effectiveness of the information security management system and the controls documented in the Statement of Applicability.
A5: A.5.35-36-02 | B5: Internal Audits | C5: Internal audits shall be planned annually, based on risk and business need, ensuring all ISMS areas are covered over the [specify: 1-year / 3-year] audit cycle.
A6: A.5.35-36-03 | B6: Annual Audit Programme | C6: Annual audit programme shall prioritise:.
A7: A.5.35-36-04 | B7: The Annual Audit Plan | C7: The annual audit plan shall be approved by the Management Review Team by [month, e.g., December] for the following year.
A8: A.5.35-36-05 | B8: Internal Audits | C8: Internal audits shall be conducted by individuals independent of the area being audited (i.e., auditors shall not audit their own work).
A9: A.5.35-36-06 | B9: Internal Audit Results | C9: Internal audit results shall be reported to and overseen by the Management Review Team.
A10: A.5.35-36-07 | B10: External Certification Audits | C10: External certification audits shall be conducted to assess the effectiveness of the information security management system and the controls documented in the Statement of Applicability.
A11: A.5.35-36-08 | B11: External Certification Audits | C11: External certification audits shall be conducted per the certification body's requirements and schedule.
A12: A.5.35-36-09 | B12: External Audit Results | C12: External audit results shall be reported to and overseen by the Management Review Team.
A13: A.5.35-36-10 | B13: Client And Third-Party Audits | C13: Client and third-party audits shall be conducted subject to a contract and/or non-disclosure agreement being in place.
A14: A.5.35-36-11 | B14: Be Reported To And Overseen By | C14: Results shall be reported to and overseen by the Management Review Team.

Sheet Independent Review of Info Sec
A1: Independent Review of Info Sec — Compliance Checklist
A2: ISO/IEC 27001:2022 — Controls A.5.35-36: Independent Review and Compliance
A3: Req # | B3: Section | C3: Requirement | D3: Status | E3: Evidence | F3: Owner | G3: Due Date | H3: Notes
A4: A.5.35-36-12 | B4: Independent Reviews Of The | C4: Independent reviews of the organisation's approach to managing information security shall be conducted:.
A5: A.5.35-36-13 | B5: Be Conducted By Persons Independent Of | C5: Reviews shall be conducted by persons independent of the area being reviewed to prevent 'marking your own homework.' Independence may be achieved through:.
A6: A.5.35-36-14 | B6: Possess Appropriate Competence To | C6: Reviewers shall possess appropriate competence to conduct information security reviews, demonstrated through:.
A7: A.5.35-36-15 | B7: Reviewer Qualifications | C7: Reviewer qualifications shall be verified and documented before assignment to review activities.
A8: A.5.35-36-16 | B8: Independent Reviews | C8: Independent reviews shall assess whether the organisation's information security approach:.
A9: A.5.35-36-17 | B9: Review'S Scope | C9: Each review's scope shall be documented in advance, including: controls and areas to be reviewed, time period covered, review methodology, documentation and evidence requirements, and planned interviews and assessments.
A10: A.5.35-36-18 | B10: Independent Reviews | C10: Independent reviews shall follow a documented plan covering objectives, criteria, sampling methodology, timeline, resource requirements, and reporting requirements.
A11: A.5.35-36-19 | B11: Be Evidence-Based. Evidence Collected | C11: Reviews shall be evidence-based. Evidence collected during reviews shall be retained in the ISMS Evidence Library: [Specify: SharePoint site URL, Confluence space, GRC platform, or equivalent].
A12: A.5.35-36-20 | B12: Evidence Retained | C12: Evidence retained shall include: documentation reviewed, interview notes, observation records, technical assessment results, and sampling records.
A13: A.5.35-36-21 | B13: Review Findings | C13: Review findings shall be documented in a formal review report and communicated to appropriate management levels.
A14: A.5.35-36-22 | B14: Audit And Review Activities | C14: Audit and review activities shall not compromise the security, availability, or integrity of production systems or data (ISO 27001:2022 Control A.8.34).
A15: A.5.35-36-23 | B15: Approved Tools Only: Auditors | C15: Approved tools only: Auditors shall use pre-approved security assessment tools and scanning software. Approval list maintained by CISO.
... A23: A.5.35-36-31 | B23: Audit Evidence | C23: Audit evidence shall be securely disposed of after the retention period per this policy.

Sheet Finding Severity Classification
A1: Finding Severity Classification — Compliance Checklist
A2: ISO/IEC 27001:2022 — Controls A.5.35-36: Independent Review and Compliance
A3: Req # | B3: Section | C3: Requirement | D3: Status | E3: Evidence | F3: Owner | G3: Due Date | H3: Notes
A4: A.5.35-36-32 | B4: Findings From Independent Reviews, | C4: All findings from independent reviews, compliance assessments, and audits shall be classified by severity:.

Sheet Corrective Action & Remediation
A1: Corrective Action & Remediation — Compliance Checklist
A2: ISO/IEC 27001:2022 — Controls A.5.35-36: Independent Review and Compliance
A3: Req # | B3: Section | C3: Requirement | D3: Status | E3: Evidence | F3: Owner | G3: Due Date | H3: Notes
A4: A.5.35-36-33 | B4: Corrective Actions | C4: When findings are identified, corrective actions shall be planned and implemented within the following timeframes:.
A5: A.5.35-36-34 | B5: Corrective Actions | C5: All corrective actions shall be tracked in the corrective action register (incident and corrective action log) with:.
A6: A.5.35-36-35 | B6: Be Tracked And Reported | C6: Progress shall be tracked and reported:.
A7: A.5.35-36-36 | B7: Corrective Actions | C7: Corrective actions shall not be marked as complete until:.

Sheet Compliance Verification
A1: Compliance Verification — Compliance Checklist
A2: ISO/IEC 27001:2022 — Controls A.5.35-36: Independent Review and Compliance
A3: Req # | B3: Section | C3: Requirement | D3: Status | E3: Evidence | F3: Owner | G3: Due Date | H3: Notes
A4: A.5.35-36-37 | B4: Compliance With The Organisation'S | C4: Compliance with the organisation's information security policy, topic-specific policies, rules, and standards shall be reviewed through a three-tier approach:.
A5: A.5.35-36-38 | B5: Be Verified Through Appropriate Methods | C5: Compliance shall be verified through appropriate methods, including:.
A6: A.5.35-36-39 | B6: Compliance Claims | C6: Compliance claims shall be supported by evidence, including:.
A7: A.5.35-36-40 | B7: Compliance Evidence | C7: Compliance evidence shall be stored in the ISMS Evidence Library (SharePoint, Confluence, or equivalent) and retained in accordance with the organisation's records retention schedule.
A8: A.5.35-36-41 | B8: Non-Completion Of Scheduled Assessments | C8: Non-completion of scheduled assessments shall be escalated: 30 days overdue to Department Head, 60 days overdue to CISO, reported at next Management Review.

Sheet Non-Conformity Management
A1: Non-Conformity Management — Compliance Checklist
A2: ISO/IEC 27001:2022 — Controls A.5.35-36: Independent Review and Compliance
A3: Req # | B3: Section | C3: Requirement | D3: Status | E3: Evidence | F3: Owner | G3: Due Date | H3: Notes
A4: A.5.35-36-42 | B4: Non-Conformities Not Resolved Within | C4: Non-conformities not resolved within target timeframes shall be escalated:.
A5: A.5.35-36-43 | B5: Root Cause Analysis (Rca) | C5: Root cause analysis (RCA) shall be conducted for:.
A6: A.5.35-36-44 | B6: Rca Methodology*: The Organisation | C6: RCA methodology*: The organisation shall use a structured RCA approach such as:.
A7: A.5.35-36-45 | B7: Rca Documentation* | C7: RCA documentation* shall include: finding description, analysis method used, identified root cause(s), contributing factors, corrective actions, and preventive actions.
A8: A.5.35-36-46 | B8: The Organisation | C8: When a non-conformity occurs, the organisation shall:.
A9: A.5.35-36-47 | B9: Non-Conformities | C9: Non-conformities shall be recorded, documented, and tracked in the incident and corrective action log. The effectiveness of corrective and preventive actions shall be reviewed.

Sheet Risk Acceptance
A1: Risk Acceptance — Compliance Checklist
A2: ISO/IEC 27001:2022 — Controls A.5.35-36: Independent Review and Compliance
A3: Req # | B3: Section | C3: Requirement | D3: Status | E3: Evidence | F3: Owner | G3: Due Date | H3: Notes
A4: A.5.35-36-48 | B4: Risk Acceptance Requests | C4: Risk acceptance requests shall include:.
A5: A.5.35-36-49 | B5: Risk Acceptances | C5: Risk acceptances shall be reviewed:.
A6: A.5.35-36-50 | B6: The Risk Owner | C6: When a trigger condition occurs, the risk owner shall notify the CISO within 14 days for reassessment.

Sheet Compl Metrics and Reporting
A1: Compl Metrics and Reporting — Compliance Checklist
A2: ISO/IEC 27001:2022 — Controls A.5.35-36: Independent Review and Compliance
A3: Req # | B3: Section | C3: Requirement | D3: Status | E3: Evidence | F3: Owner | G3: Due Date | H3: Notes
A4: A.5.35-36-51 | B4: The Following Kpis | C4: The following KPIs shall be tracked to measure the effectiveness of the compliance and review programme:.
A5: A.5.35-36-52 | B5: Compliance And Review Metrics | C5: Compliance and review metrics shall be tracked over time to identify improvement or degradation trends (quarter-over-quarter, year-over-year), recurring finding patterns, areas requiring focused attention, and the effectiveness of remediation efforts.
A6: A.5.35-36-53 | B6: Trend Data | C6: Trend data shall be retained for a minimum of 3 years to support long-term analysis and certification audit preparation.

Sheet Improvement Inputs
A1: Improvement Inputs — Compliance Checklist
A2: ISO/IEC 27001:2022 — Controls A.5.35-36: Independent Review and Compliance
A3: Req # | B3: Section | C3: Requirement | D3: Status | E3: Evidence | F3: Owner | G3: Due Date | H3: Notes
A4: A.5.35-36-54 | B4: The Following Sources | C4: The following sources shall be considered as inputs for continual improvement of the ISMS:.
A5: A.5.35-36-55 | B5: Management Review Team — The Management | C5: Management Review Team — The Management Review Team shall consider opportunities for improvement as a standing agenda item.
A6: A.5.35-36-56 | B6: Changes To The Information Security | C6: Changes to the information security management system resulting from improvement activities shall be planned, managed, and recorded in the incident and corrective action log or change log, as appropriate.
