Workbook

Sheet Instructions & Legend
A1: ISMS-IMP-A.8.32.3 - Environment Separation Assessment ISO/IEC 27001:2022 - Control A.8.32: Change Management
A3: Document Information
A4: Document ID | B4: ISMS-IMP-A.8.32.3
A5: Workbook Title | B5: Environment Separation Assessment
A6: Control Reference | B6: ISO/IEC 27001:2022 - Control A.8.32: Change Management
A7: Version | B7: 1.0
A8: Assessment Date
A9: Completed By
A10: Organisation
A12: Instructions
A13: 1. Document YOUR development environment configuration and controls.
A14: 2. Document YOUR test/QA environment configuration and controls.
A15: 3. Document YOUR production environment configuration and controls.
A16: 4. Define YOUR environment promotion procedures.
A17: 5. Assess YOUR production data usage in non-production environments (Control 8.33).
A18: 6. Review the Summary Dashboard for compliance metrics.
A19: 7. Maintain the Evidence Register for audit traceability.
A20: 8. Obtain final approval via Approval Sign-Off sheet.
A22: Status Legend
A23: Symbol | B23: Status | C23: Description
A24: ✓ | B24: Compliant / Complete | C24: Requirement fully met
A25: ⚠ | B25: Partial / In Progress | C25: Partially met or in progress
A26: ✗ | B26: Non-Compliant / Not Started | C26: Requirement not met
A27: — | B27: Not Applicable | C27: Not applicable to this assessment

Sheet Environment Inventory
A1: DEVELOPMENT ENVIRONMENT ASSESSMENT
A2: Document development environment configuration and controls
A4: ENVIRONMENT IDENTIFICATION
A5: Attribute | B5: Value | C5: Compliance | D5: Evidence | E5: Notes
A6: Environment Name
A7: Environment Type
A8: Hosting Model
A9: Location/Region
A10: Network Isolation Level
A11: VLAN/Subnet ID
A12: Primary Purpose
A13: Number of Systems
A14: Number of Users with Access
A15: Access Method
A16: Change Frequency
A17: Deployment Tools Used
... A21: ACCESS CONTROL ASSESSMENT
A22: Attribute | B22: Value | C22: Compliance | D22: Evidence | E22: Notes
A23: Developer access granted by default?
A24: Role-Based Access Control (RBAC) implemented?
A25: Access approval process defined?
A26: Access request tracked in ticket system?
A27: Multi-Factor Authentication (MFA) required?
A28: Access review performed?
A29: Privileged access tracked separately?
A30: Shared accounts prohibited?
A31: SSH key management implemented?
A32: Service accounts documented?
A33: Emergency access procedure defined?
A35: DATA CONTROLS (CONTROL 8.33 CRITICAL)
A36: Attribute | B36: Value | C36: Compliance | D36: Evidence | E36: Notes
A37: Production data prohibited in development?
A38: If prod data present, is it anonymized?
A39: Anonymization method documented?
A40: Synthetic data generation capability?
A41: Data subset strategy implemented?
A42: Encryption at rest implemented?
A43: Encryption in transit enforced?
A44: DPO approval obtained (if prod data)?
A46: CHANGE MANAGEMENT INTEGRATION
...

Sheet Access Controls
A1: TEST/QA ENVIRONMENT ASSESSMENT
A2: Document test/QA environment configuration and controls
A4: ENVIRONMENT IDENTIFICATION
A5: Attribute | B5: Value | C5: Compliance | D5: Evidence | E5: Notes
A6: Environment Name
A7: Environment Type
A8: Hosting Model
A9: Location/Region
A10: Network Isolation Level
A11: VLAN/Subnet ID
A12: Primary Purpose
A13: Number of Systems
A14: Number of Users with Access
A15: Access Method
A16: Change Frequency
A17: Test Automation Tools
... A21: ACCESS CONTROL ASSESSMENT
A22: Attribute | B22: Value | C22: Compliance | D22: Evidence | E22: Notes
A23: QA/Tester access controlled?
A24: Developer access restricted vs development?
A25: Role-Based Access Control (RBAC) implemented?
A26: Access approval process defined?
A27: Access request tracked in ticket system?
A28: Multi-Factor Authentication (MFA) required?
A29: Access review performed?
A30: Privileged access tracked separately?
A31: Shared accounts prohibited?
A32: Test data access logged?
A33: UAT user access documented?
A35: DATA CONTROLS (CONTROL 8.33 CRITICAL)
A36: Attribute | B36: Value | C36: Compliance | D36: Evidence | E36: Notes
A37: Production data usage policy enforced?
A38: If prod data present, is it anonymized?
A39: Anonymization method documented?
A40: Anonymization effectiveness tested?
A41: Synthetic data generation capability?
A42: Data subset strategy implemented?
A43: Re-identification risk assessed?
A44: Encryption at rest implemented?
A45: Encryption in transit enforced?
...

Sheet Promotion Workflows
A1: ENVIRONMENT PROMOTION PROCESS
A2: Document promotion workflows between environments (Dev → Test → Prod)
A4: PROMOTION PATH DEFINITION
A5: From Environment | B5: To Environment | C5: Method | D5: Approval Required? | E5: Frequency | F5: Notes
A6: Development | B6: Test
A7: Test | B7: QA
A8: QA | B8: UAT
A9: UAT | B9: Production
A10: Hotfix | B10: Production (Emergency)
A12: PROMOTION CONTROLS & GATES
A13: Control | B13: Dev→Test | C13: Test→QA | D13: QA→Prod | E13: Compliance | F13: Evidence
A14: Code review completed?
A15: Unit tests passed?
A16: Integration tests passed?
A17: Security scan passed?
A18: Performance test passed?
A19: UAT sign-off obtained?
A20: Documentation updated?
A21: Change ticket approved?
A22: Rollback plan documented?
A23: Stakeholders notified?
A24: Change window scheduled?
A25: Backup completed?
... A31: CI/CD PIPELINE ASSESSMENT
A32: Pipeline Stage | B32: Implemented? | C32: Tool/Method | D32: Automated? | E32: Compliance | F32: Notes
A33: Source control integration
A34: Build automation
A35: Unit testing
A36: Code quality analysis
A37: Security scanning (SAST)
A38: Dependency vulnerability scanning
A39: Integration testing
A40: Container scanning (if applicable)
A41: Artifact versioning
A42: Environment-specific config management
A43: Automated deployment to test/QA
A44: Production deployment approval gate

Sheet Data Protection
A1: PRODUCTION DATA IN NON-PRODUCTION ENVIRONMENTS
A2: Control 8.33: Test Information - Production data protection assessment
A4: POLICY & GOVERNANCE
A5: Requirement | B5: Implemented? | C5: Details | D5: Compliance | E5: Evidence | F5: Notes
A6: Production data usage policy documented?
A7: Prohibition of prod data in non-prod enforced?
A8: Exceptions process defined and documented?
A9: DPO review required for exceptions?
A10: Data classification system implemented?
A11: Anonymization procedures documented?
A12: Annual policy review performed?
A14: DATA ANONYMIZATION CONTROLS
A15: Requirement | B15: Implemented? | C15: Details | D15: Compliance | E15: Evidence | F15: Notes
A16: Data masking implemented?
A17: Tokenization used for sensitive fields?
A18: Anonymization testing performed?
A19: Re-identification risk assessed?
A20: Anonymization effectiveness >95%?
A21: PII/PHI identification automated?
A22: Direct identifiers removed?
A23: Indirect identifiers assessed?
A24: Data linkage risk evaluated?
A25: Anonymization audit trail maintained?
A26: Failed anonymization procedures defined?
A27: Anonymization tools validated?
... A34: CURRENT PRODUCTION DATA USAGE IN NON-PRODUCTION
A35: System/Application | B35: Contains Prod Data? | C35: Data Type | D35: Anonymized? | E35: Approval Date | F35: Approved By | G35: Review Date | H35: Compliant? | I35: Evidence
A36: CRM Test Environment | B36: No | C36: Synthetic customer data | D36: N/A | E36: 15.01.2026 | F36: Test Manager | G36: 15.07.2026 | H36: Compliant | I36: EV-DATA-001
A88: SYNTHETIC DATA GENERATION CAPABILITY
A89: Capability | B89: Available? | C89: Tool/Method | D89: Data Types Supported | E89: Usage | F89: Compliance | G89: Evidence
A90: Synthetic data generator
A91: Maintains referential integrity
A92: Realistic data distributions
A93: Supports edge cases
A94: Automated generation

Sheet Environment Config
A1: PRODUCTION ENVIRONMENT ASSESSMENT
A2: Document production environment configuration and controls (HIGHEST SECURITY)
A4: ENVIRONMENT IDENTIFICATION
A5: Attribute | B5: Value | C5: Compliance | D5: Evidence | E5: Notes
A6: Environment Name
A7: Environment Type
A8: Hosting Model
A9: Location/Region
A10: Network Isolation Level
A11: VLAN/Subnet ID
A12: Primary Purpose
A13: Number of Systems
A14: Number of Users Served
A15: Business Criticality
A16: Access Method
A17: Change Window Schedule
... A25: PRODUCTION ACCESS RESTRICTIONS (CRITICAL)
A26: Attribute | B26: Value | C26: Compliance | D26: Evidence | E26: Notes
A27: Developer direct access prohibited?
A28: All access logged and monitored?
A29: Multi-Factor Authentication (MFA) MANDATORY?
A30: Role-Based Access Control (RBAC) enforced?
A31: Principle of Least Privilege applied?
A32: Privileged access requires approval?
A33: Emergency access break-glass procedure?
A34: Access review frequency
A35: Just-In-Time (JIT) access implemented?
A36: Shared accounts prohibited?
A37: Service accounts managed separately?
A38: SSH keys rotated regularly?
... A42: DATA PROTECTION CONTROLS (CONTROL 8.33 CRITICAL)
A43: Attribute | B43: Value | C43: Compliance | D43: Evidence | E43: Notes
A44: Production data NEVER copied to non-prod?
A45: Production data exfiltration monitoring?
A46: Data Loss Prevention (DLP) implemented?
A47: Encryption at rest enforced?
A48: Encryption in transit enforced?
A49: Database access logging comprehensive?
A50: Backup encryption implemented?
A51: Backup tested regularly?
...

Sheet Separation Controls
A1: ENVIRONMENT SEPARATION CONTROLS
A2: Document technical controls enforcing environment separation
A4: TECHNICAL SEPARATION CONTROLS
A5: Control Type | B5: Description | C5: Environments Covered | D5: Implementation Status | E5: Effectiveness | F5: Last Tested | G5: Owner | H5: Evidence
A6: Network Segmentation | B6: VLAN/subnet separation between environments
A7: Firewall Rules | B7: Inter-environment traffic restrictions
A8: IAM Policies | B8: Role-based access per environment
A9: CI/CD Pipeline Controls | B9: Automated promotion with approvals
A10: Database Isolation | B10: Separate database instances/schemas
A11: Secret Management | B11: Environment-specific credentials
A12: Monitoring Separation | B12: Distinct logging/monitoring per env
A13: Container Isolation | B13: Namespace/cluster separation
A16: CONTROL EFFECTIVENESS ASSESSMENT
A17: Assessment Area | B17: Target | C17: Current Score | D17: Gap | E17: Remediation Required | F17: Target Date
A18: Network Separation | B18: 100%
A19: Access Control Separation | B19: 100%
A20: Data Separation | B20: 100%
A21: Code Promotion Controls | B21: 100%

Sheet Evidence Register
A1: EVIDENCE REGISTER
A2: Document all evidence collected during this assessment
A4: Evidence ID | B4: Assessment Area | C4: Evidence Type | D4: Description | E4: Location / Path | F4: Date Collected | G4: Collected By | H4: Verification Status
A5: EV-001 | B5: Environment Separation | C5: Configuration Export | D5: Network segmentation configuration from firewall | E5: \\fileserver\evidence\firewall_rules_export_20260115.csv | F5: 15.01.2026 | G5: Network Administrator | H5: ✅ Verified

Sheet Summary Dashboard
A1: ENVIRONMENT SEPARATION ASSESSMENT — SUMMARY DASHBOARD
A2: ISO/IEC 27001:2022 — Control A.8.32: Change Management
A4: TABLE 1: ASSESSMENT AREA COMPLIANCE OVERVIEW
A5: Assessment Area | B5: Total Items | C5: Compliant | D5: Partial | E5: Non-Compliant | F5: N/A | G5: Compliance %
A6: Environment Inventory | B6: =COUNTA('Environment Inventory'!A6:A55) | C6: =COUNTIF('Environment Inventory'!C6:C55,"✅ Compliant") | D6: =COUNTIF('Environment Inventory'!C6:C55,"⚠ Partial") | E6: =COUNTIF('Environment Inventory'!C6:C55,"❌ Non-Compliant")+COUNTIF('Environment Inventory'!C6:C55,"Pending") | F6: 0 | G6: =IF((B6-F6)=0,0,C6/(B6-F6))
A7: Access Controls | B7: =COUNTA('Access Controls'!A6:A58) | C7: =COUNTIF('Access Controls'!C6:C58,"✅ Compliant") | D7: =COUNTIF('Access Controls'!C6:C58,"⚠ Partial") | E7: =COUNTIF('Access Controls'!C6:C58,"❌ Non-Compliant")+COUNTIF('Access Controls'!C6:C58,"Pending") | F7: 0 | G7: =IF((B7-F7)=0,0,C7/(B7-F7))
A8: Promotion Workflows - Controls & Gates | B8: =COUNTA('Promotion Workflows'!A14:A44) | C8: =COUNTIF('Promotion Workflows'!E14:E44,"✅ Compliant") | D8: =COUNTIF('Promotion Workflows'!E14:E44,"⚠ Partial") | E8: =COUNTIF('Promotion Workflows'!E14:E44,"❌ Non-Compliant")+COUNTIF('Promotion Workflows'!E14:E44,"Pending") | F8: 0 | G8: =IF((B8-F8)=0,0,C8/(B8-F8))
A9: Promotion Workflows - CI/CD Pipeline | B9: =COUNTA('Promotion Workflows'!A33:A44) | C9: =COUNTIF('Promotion Workflows'!E33:E44,"✅ Compliant") | D9: =COUNTIF('Promotion Workflows'!E33:E44,"⚠ Partial") | E9: =COUNTIF('Promotion Workflows'!E33:E44,"❌ Non-Compliant")+COUNTIF('Promotion Workflows'!E33:E44,"Pending") | F9: 0 | G9: =IF((B9-F9)=0,0,C9/(B9-F9))
A10: Data Protection | B10: =COUNTA('Data Protection'!A6:A95) | C10: =COUNTIF('Data Protection'!D6:D95,"✅ Yes") | D10: =COUNTIF('Data Protection'!D6:D95,"⚠ Partial") | E10: =COUNTIF('Data Protection'!D6:D95,"❌ No") | F10: 0 | G10: =IF((B10-F10)=0,0,C10/(B10-F10))
A11: Environment Config | B11: =COUNTA('Environment Config'!A6:A65) | C11: =COUNTIF('Environment Config'!C6:C65,"✅ Compliant") | D11: =COUNTIF('Environment Config'!C6:C65,"⚠ Partial") | E11: =COUNTIF('Environment Config'!C6:C65,"❌ Non-Compliant")+COUNTIF('Environment Config'!C6:C65,"Pending") | F11: 0 | G11: =IF((B11-F11)=0,0,C11/(B11-F11))
A12: Separation Controls | B12: =COUNTA('Separation Controls'!A6:A21) | C12: =COUNTIF('Separation Controls'!D6:D21,"✅ Compliant") | D12: =COUNTIF('Separation Controls'!D6:D21,"⚠ Partial") | E12: =COUNTIF('Separation Controls'!D6:D21,"❌ Non-Compliant")+COUNTIF('Separation Controls'!D6:D21,"Pending") | F12: 0 | G12: =IF((B12-F12)=0,0,C12/(B12-F12))
A13: TOTAL | B13: =SUM(B6:B12) | C13: =SUM(C6:C12) | D13: =SUM(D6:D12) | E13: =SUM(E6:E12) | F13: =SUM(F6:F12) | G13: =IF((B13-F13)=0,0,C13/(B13-F13))
A15: TABLE 2: KEY METRICS
A16: Metric | B16: Value
A17: Network Isolation Coverage | B17: ='Separation Controls'!D6
A18: MFA Enforcement (Production) | B18: ='Access Controls'!C30
A19: Developer Direct Production Access | B19: ='Access Controls'!C35
A20: Change Promotion Success Rate | B20: ='Promotion Workflows'!E14
A24: TABLE 3: CRITICAL FINDINGS
A25: Category | B25: Finding | C25: Count | D25: Severity | E25: Action Required
A26: Environment Separation | B26: Production changes without separate test | C26: =COUNTIF('Environment Inventory'!F6:F55,"❌ Not Implemented") | D26: Critical | E26: Immediate
A27: Environment Separation | B27: Missing environment isolation controls | C27: =COUNTIF('Environment Inventory'!J6:J55,"❌ Not Implemented") | D27: Critical | E27: Immediate
A28: Promotion Process | B28: Production promotions without testing | C28: =COUNTIF('Promotion Workflows'!E14:E44,"❌ Non-Compliant") | D28: Critical | E28: Immediate
A29: Production Access | B29: Unauthorised production access | C29: =COUNTIF('Access Controls'!I6:I58,"❌ Not Implemented") | D29: Critical | E29: Immediate
A30: Data Sync | B30: Production data in lower environments | C30: =COUNTIF('Data Protection'!K6:K94,"❌ Not Implemented") | D30: Critical | E30: Immediate
A31: Environment Separation | B31: Partial environment separation | C31: =COUNTIF('Environment Inventory'!F6:F55,"⚠ Partial") | D31: High | E31: Urgent
A32: Promotion Process | B32: Incomplete promotion controls | C32: =COUNTIF('Promotion Workflows'!E33:E44,"❌ Non-Compliant") | D32: High | E32: Urgent
A33: Production Access | B33: Production access control gaps | C33: =COUNTIF('Access Controls'!I6:I58,"⚠ Partial") | D33: High | E33: Urgent
A34: Data Sync | B34: Data synchronization gaps | C34: =COUNTIF('Data Protection'!K6:K94,"⚠ Partial") | D34: Medium | E34: Plan
A35: Environment Separation | B35: Environment monitoring gaps | C35: =COUNTIF('Environment Inventory'!N6:N55,"Gap") | D35: Medium | E35: Plan

Sheet Approval Sign-Off
A1: ASSESSMENT APPROVAL AND SIGN-OFF
A2: ISO/IEC 27001:2022 - Control A.8.32: Change Management
A3: ASSESSMENT SUMMARY
A4: Document: | B4: ISMS-IMP-A.8.32.3 — Environment Separation Assessment
A5: Assessment Period:
A6: Overall Compliance Rating: | B6: ='Summary Dashboard'!G13
A7: Assessed By:
A8: Assessment Status:
A10: COMPLETED BY (ASSESSOR)
A11: Name:
A12: Title:
A13: Date:
A14: Signature:
A15: Comments:
A17: REVIEWED BY (INFORMATION SECURITY OFFICER)
A18: Name:
A19: Title:
A20: Date:
... A36: Special Considerations:
