Workbook

Sheet Instructions & Legend
A1: ISMS-IMP-A.8.32.1 - Change Process Assessment ISO/IEC 27001:2022 - Control A.8.32: Change Management
A3: Document Information
A4: Document ID | B4: ISMS-IMP-A.8.32.1
A5: Workbook Title | B5: Change Process Assessment
A6: Control Reference | B6: ISO/IEC 27001:2022 - Control A.8.32: Change Management
A7: Version | B7: 1.0
A8: Assessment Date
A9: Completed By
A10: Organisation
A12: Instructions
A13: 1. Document YOUR organisation’s change management process in the Change Process Workflow sheet.
A14: 2. Complete the Approval Authority Matrix with YOUR specific roles and thresholds.
A15: 3. Fill in YOUR communication procedures and stakeholder notification methods.
A16: 4. Document YOUR documentation requirements and record-keeping practices.
A17: 5. Inventory YOUR change management tools (whatever platforms/systems you use).
A18: 6. Review the Summary Dashboard for compliance metrics.
A19: 7. Maintain the Evidence Register for audit traceability.
A20: 8. Obtain final approval and sign-off.
A22: Status Legend
A23: Symbol | B23: Status | C23: Description
A24: ✓ | B24: Compliant / Complete | C24: Requirement fully met
A25: ⚠ | B25: Partial / In Progress | C25: Partially met or in progress
A26: ✗ | B26: Non-Compliant / Not Started | C26: Requirement not met
A27: — | B27: Not Applicable | C27: Not applicable to this assessment

Sheet Change Process Workflow
A1: CHANGE MANAGEMENT PROCESS WORKFLOW
A2: Document the complete change lifecycle in your organisation
A4: PROCESS STAGE MAPPING
A5: Stage | B5: Stage Name | C5: Description | D5: Process Owner | E5: Standard Duration | F5: Tool/System Used | G5: Status | H5: Evidence
A6: 1 | B6: Change Request Initiation | C6: How changes are requested
A7: 2 | B7: Initial Assessment & Screening | C7: Validation and categorization
A8: 3 | B8: Risk & Impact Assessment | C8: Evaluate change risks
A9: 4 | B9: Change Categorization | C9: Standard/Normal/Emergency
A10: 5 | B10: CAB Scheduling (if required) | C10: Schedule review meeting
A11: 6 | B11: CAB Review & Discussion | C11: Formal review process
A12: 7 | B12: Change Authorisation | C12: Approval decision
A13: 8 | B13: Implementation Planning | C13: Schedule and resource allocation
A14: 9 | B14: Stakeholder Communication | C14: Notification procedures
A15: 10 | B15: Pre-Implementation Testing | C15: Testing in non-production
A16: 11 | B16: Change Implementation | C16: Actual execution
A17: 12 | B17: Implementation Verification | C17: Verify success
... A20: 15 | B20: Change Record Closure | C20: Documentation completion
A23: PROCESS DOCUMENTATION REQUIREMENTS
A24: Requirement | B24: Implemented | C24: Documentation Type | D24: Template Available | E24: Location | F24: Responsible Role
A25: Change request form/template
A26: Risk assessment template
A27: Impact assessment template
A28: CAB agenda template
A29: Implementation plan template
A30: Rollback plan template
A31: PIR template
A32: Communication templates
A33: Change closure checklist
A36: WORKFLOW AUTOMATION ASSESSMENT
A37: Capability | B37: Automated | C37: Semi-Automated | D37: Manual | E37: Tool/System | F37: Notes
A38: Change request submission
A39: Request routing/assignment
A40: Approval workflow
A41: Notification distribution
A42: Change calendar updates
A43: Status tracking
A44: Reporting/dashboards
A45: PIR reminders

Sheet Approval Authority Matrix
A1: CHANGE APPROVAL AUTHORITY MATRIX
A2: Define approval authorities by change type and risk level
A4: STANDARD CHANGES APPROVAL
A5: Standard Change Type | B5: Pre-Approved | C5: Self-Service Allowed | D5: Approver (if required) | E5: Approval SLA | F5: Implemented | G5: Evidence
A6: Restart Web Server | B6: Yes | C6: Yes | D6: Web Admin Team Lead | E6: 1 hour | F6: Implemented | G6: EV-STD-001
A59: NORMAL CHANGES APPROVAL MATRIX
A60: Risk Level | B60: Impact Level | C60: Required Approvers | D60: CAB Review Required | E60: Approval Threshold | F60: Typical SLA | G60: Implemented
A61: Low | B61: Low
A62: Low | B62: Medium
A63: Low | B63: High
A64: Medium | B64: Low
A65: Medium | B65: Medium
A66: Medium | B66: High
A67: High | B67: Low
A68: High | B68: Medium
A69: High | B69: High
A70: Critical | B70: Any
A73: EMERGENCY CHANGES APPROVAL
A74: Emergency Criteria | B74: E-CAB Members | C74: Minimum Approvers | D74: Approval Method | E74: Documented | F74: Evidence
A75: System outage affecting critical services
A76: Security incident response
A77: Regulatory compliance deadline
A78: Data loss prevention
A79: [Other - specify]
A82: APPROVAL PROCESS METRICS
A83: Metric | B83: Target | C83: Current | D83: Status
A84: Average approval time (Standard)
A85: Average approval time (Normal - Low Risk)
A86: Average approval time (Normal - High Risk)
A87: Average approval time (Emergency)
A88: Approval backlog (pending >SLA)
A89: Approval rejection rate

Sheet CAB Operations
A1: CHANGE ADVISORY BOARD (CAB) OPERATIONS
A2: Document CAB composition, meeting schedules, and operational procedures
A4: CAB COMPOSITION & MEMBERSHIP
A5: Role | B5: Name | C5: Department | D5: Authority Level | E5: Mandatory/Optional | F5: Delegate | G5: Contact | H5: Status
A6: CAB Chair | D6: Final Decision | E6: Mandatory
A7: IT Security Representative | D7: Veto for Security | E7: Mandatory
A8: Infrastructure Lead | D8: Advisory | E8: Mandatory
A9: Application Lead | D9: Advisory | E9: Mandatory
A10: Business Representative | D10: Advisory | E10: As Needed
A11: Change Manager | D11: Facilitator | E11: Mandatory
A14: CAB MEETING SCHEDULE & PROCEDURES
A15: Meeting Type | B15: Frequency | C15: Day/Time | D15: Duration | E15: Quorum Required | F15: Minutes Owner | G15: Agenda Deadline | H15: Status
A16: Regular CAB | B16: Weekly | D16: 1 hour | E16: Chair + 3 | G16: 24 hours prior
A17: Emergency CAB (eCAB) | B17: As Needed | D17: 30 mins | E17: Chair + 2 | G17: Immediate
A18: CAB Review (Post-Implementation) | B18: Monthly | D18: 2 hours | E18: Chair + 3 | G18: 48 hours prior
A21: CAB RESPONSIBILITIES & DECISION CRITERIA
A22: Responsibility | B22: Description | C22: Owner | D22: Documented? | E22: Evidence Reference
A23: Change Review | B23: Review all Normal and Major changes before implementation
A24: Risk Assessment | B24: Evaluate risk level and approve risk mitigation
A25: Schedule Coordination | B25: Ensure changes don't conflict with other activities
A26: Resource Approval | B26: Verify adequate resources for change implementation
A27: Post-Implementation Review | B27: Review PIR results and lessons learned
A28: Escalation Decisions | B28: Escalate changes requiring executive approval

Sheet Communication
A1: CHANGE COMMUNICATION PROCEDURES
A2: Document stakeholder notification and communication methods
A4: STAKEHOLDER IDENTIFICATION
A5: Stakeholder Group | B5: Role/Description | C5: Notification Trigger | D5: Communication Method | E5: Responsible Party | F5: Template Available | G5: Status
A6: End Users
A7: Service Owners
A8: IT Operations Team
A9: Security Team
A10: Management
A11: CAB Members
A12: External Vendors
A13: [Other - specify]
A14: [Other - specify]
A15: [Other - specify]
A18: COMMUNICATION TEMPLATES
A19: Template Type | B19: Purpose | C19: Content Includes | D19: Approval Required | E19: Format | F19: Location | G19: Maintained
A20: Change Request Acknowledgment | B20: Confirm receipt | C20: Change ID, requestor, next steps
A21: Change Scheduled Notification | B21: Inform of approval & schedule | C21: Change details, date/time, impact
A22: Change Reminder (24h) | B22: Pre-implementation reminder | C22: Time, expected duration, contacts
A23: Change In Progress | B23: During implementation | C23: Status, progress, issues
A24: Change Completed Successfully | B24: Successful completion | C24: Completion time, verification
A25: Change Failed/Rolled Back | B25: Failure notification | C25: Issue, rollback status, next steps
A26: Change Postponed | B26: Schedule change | C26: Reason, new date, next steps
A27: Emergency Change Notice | B27: Urgent notification | C27: Reason, approval, impact
A30: COMMUNICATION CHANNELS ASSESSMENT
A31: Channel | B31: Available | C31: Primary Use | D31: Audience Reach | E31: Reliability | F31: Documented
A32: Email
A33: Internal Portal/Intranet
A34: Change Management System
A35: Instant Messaging (Teams/Slack/etc)
A36: SMS/Text Messages
A37: Status Dashboard
A38: Scheduled Announcements

Sheet Documentation Records
A1: CHANGE DOCUMENTATION REQUIREMENTS
A2: Define record-keeping requirements by change type
A4: STANDARD CHANGE DOCUMENTATION
A5: Documentation Item | B5: Required | C5: Format | D5: Retention Period | E5: Storage Location | F5: Responsible Role | G5: Compliant
A6: Change request (basic)
A7: Requestor identification
A8: Change description
A9: Service/system affected
A10: Implementation date/time
A11: Implementation result
A14: NORMAL CHANGE DOCUMENTATION
A15: Documentation Item | B15: Required | C15: Format | D15: Retention Period | E15: Storage Location | F15: Responsible Role | G15: Compliant
A16: Complete change request
A17: Risk assessment
A18: Impact assessment
A19: Business justification
A20: Technical implementation plan
A21: Test plan/results
A22: Rollback plan
A23: CAB review record
A24: Approval record (all approvers)
A25: Communication records
A26: Implementation log/notes
A27: Verification evidence
... A33: EMERGENCY CHANGE DOCUMENTATION
A34: Documentation Item | B34: Required | C34: Special Requirements | D34: Retention Period | E34: Storage Location | F34: Responsible Role | G34: Compliant
A35: Emergency change justification
A36: E-CAB approval record
A37: Emergency criteria met
A38: Incident ticket reference
A39: Risk accepted by
A40: Implementation record
A41: Mandatory PIR
A42: Retrospective CAB review
A45: RECORD RETENTION & DISPOSAL
A46: Record Type | B46: Retention Period | C46: Disposal Method | D46: Regulatory Requirement | E46: Implemented | F46: Evidence
A47: Standard changes
A48: Normal changes (successful)
A49: Failed changes
A50: Emergency changes
...

Sheet Tool Capabilities
A1: CHANGE MANAGEMENT TOOLS & SYSTEMS INVENTORY
A2: Document all platforms and tools supporting change management
A4: PRIMARY CHANGE MANAGEMENT SYSTEM
A5: Attribute | B5: Value | C5: Evidence Location
A6: SYSTEM IDENTIFICATION
A7: Tool/Platform Name
A8: Vendor/Provider
A9: Version/Release
A10: Deployment Type
A11: Primary Use
A13: CAPABILITIES
A14: Change request submission
A15: Workflow automation
A16: Approval routing
A17: Risk/Impact assessment forms
A18: Change calendar
... A35: SUPPORTING TOOLS & SYSTEMS
A36: Tool/System | B36: Purpose | C36: Integration with Primary | D36: Status | E36: User Count | F36: Evidence
A57: INTEGRATION ARCHITECTURE
A58: Integration Point | B58: Source System | C58: Target System | D58: Integration Type | E58: Automated | F58: Data Exchanged | G58: Status
A73: TOOL ACCESS & SECURITY
A74: Security Control | B74: Implemented | C74: Details | D74: Evidence
A75: Multi-factor authentication
A76: Role-based access control
A77: Audit logging enabled
A78: Data encryption (at rest)
A79: Data encryption (in transit)
A80: Backup/recovery tested
A81: Disaster recovery plan

Sheet Metrics KPIs
A1: CHANGE MANAGEMENT METRICS AND KPIS
A2: Document tracked metrics, targets, and reporting frequency
A4: KEY CHANGE MANAGEMENT METRICS
A5: Metric Name | B5: Description | C5: Target | D5: Current Value | E5: Frequency | F5: Data Source | G5: Owner | H5: Status
A6: Change Success Rate | B6: % of changes implemented without incident | C6: >95% | E6: Monthly
A7: Emergency Change Rate | B7: % of changes classified as emergency | C7: <10% | E7: Monthly
A8: Change Backlog | B8: Number of approved changes awaiting implementation | C8: <20 | E8: Weekly
A9: Mean Time to Implement | B9: Average time from approval to implementation | C9: <5 days | E9: Monthly
A10: Failed Change Rate | B10: % of changes requiring rollback | C10: <5% | E10: Monthly
A11: CAB Approval Time | B11: Average time to CAB decision | C11: <48 hours | E11: Monthly
A12: Post-Implementation Review Rate | B12: % of changes with completed PIR | C12: >90% | E12: Monthly
A13: Change-Related Incidents | B13: Incidents caused by changes | C13: <5/month | E13: Monthly
A16: METRICS REPORTING SCHEDULE
A17: Report Name | B17: Audience | C17: Frequency | D17: Format | E17: Delivery Method | F17: Owner | G17: Status
A18: Weekly Change Summary | B18: IT Management | C18: Weekly | D18: Dashboard
A19: Monthly Change Report | B19: CISO/Executive | C19: Monthly | D19: PDF Report
A20: Quarterly Trend Analysis | B20: Board/Audit | C20: Quarterly | D20: Presentation
A21: Annual Change Review | B21: Executive/Audit | C21: Annual | D21: Full Report

Sheet Evidence Register
A1: EVIDENCE REGISTER
A2: Document all evidence collected during this assessment
A4: Evidence ID | B4: Assessment Area | C4: Evidence Type | D4: Description | E4: Location / Path | F4: Date Collected | G4: Collected By | H4: Verification Status
A5: EV-001 | B5: Change Process Assessment | C5: Policy Document | D5: Change Management Policy v1.0 | E5: \\fileserver\policies\change_mgmt_v1.0.pdf | F5: 15.01.2026 | G5: Change Manager | H5: ✅ Verified

Sheet Summary Dashboard
A1: CHANGE PROCESS ASSESSMENT — SUMMARY DASHBOARD
A2: ISO/IEC 27001:2022 — Control A.8.32: Change Management
A4: TABLE 1: ASSESSMENT AREA COMPLIANCE OVERVIEW
A5: Assessment Area | B5: Total Items | C5: Compliant | D5: Partial | E5: Non-Compliant | F5: N/A | G5: Compliance %
A6: Change Process Workflow | B6: =COUNTA('Change Process Workflow'!G7:G56) | C6: =COUNTIF('Change Process Workflow'!G7:G56,"✅ Implemented") | D6: =COUNTIF('Change Process Workflow'!G7:G56,"⚠ Partial") | E6: =COUNTIF('Change Process Workflow'!G7:G56,"❌ Not Implemented")+COUNTIF('Change Process Workflow'!G7:G56,"Planned") | F6: =COUNTIF('Change Process Workflow'!G7:G56,"N/A") | G6: =IF((B6-F6)=0,0,C6/(B6-F6))
A7: Approval Authority Matrix - Standard Changes | B7: =COUNTA('Approval Authority Matrix'!F7:F89) | C7: =COUNTIF('Approval Authority Matrix'!F7:F89,"✅ Implemented") | D7: =COUNTIF('Approval Authority Matrix'!F7:F89,"⚠ Partial") | E7: =COUNTIF('Approval Authority Matrix'!F7:F89,"❌ Not Implemented")+COUNTIF('Approval Authority Matrix'!F7:F89,"Planned") | F7: =COUNTIF('Approval Authority Matrix'!F7:F89,"N/A") | G7: =IF((B7-F7)=0,0,C7/(B7-F7))
A8: Approval Authority Matrix - Normal Changes | B8: =COUNTA('Approval Authority Matrix'!G61:G89) | C8: =COUNTIF('Approval Authority Matrix'!G61:G89,"✅ Implemented") | D8: =COUNTIF('Approval Authority Matrix'!G61:G89,"⚠ Partial") | E8: =COUNTIF('Approval Authority Matrix'!G61:G89,"❌ Not Implemented")+COUNTIF('Approval Authority Matrix'!G61:G89,"Planned") | F8: =COUNTIF('Approval Authority Matrix'!G61:G89,"N/A") | G8: =IF((B8-F8)=0,0,C8/(B8-F8))
A9: Approval Authority Matrix - Emergency Changes | B9: =COUNTA('Approval Authority Matrix'!E75:E89) | C9: =COUNTIF('Approval Authority Matrix'!E75:E89,"✅ Implemented") | D9: =COUNTIF('Approval Authority Matrix'!E75:E89,"⚠ Partial") | E9: =COUNTIF('Approval Authority Matrix'!E75:E89,"❌ Not Implemented")+COUNTIF('Approval Authority Matrix'!E75:E89,"Planned") | F9: =COUNTIF('Approval Authority Matrix'!E75:E89,"N/A") | G9: =IF((B9-F9)=0,0,C9/(B9-F9))
A10: Communication | B10: =COUNTA('Communication'!G6:G55) | C10: =COUNTIF('Communication'!G6:G55,"✅ Implemented") | D10: =COUNTIF('Communication'!G6:G55,"⚠ Partial") | E10: =COUNTIF('Communication'!G6:G55,"❌ Not Implemented")+COUNTIF('Communication'!G6:G55,"Planned") | F10: =COUNTIF('Communication'!G6:G55,"N/A") | G10: =IF((B10-F10)=0,0,C10/(B10-F10))
A11: Documentation Records | B11: =COUNTA('Documentation Records'!G6:G55) | C11: =COUNTIF('Documentation Records'!G6:G55,"✅ Implemented") | D11: =COUNTIF('Documentation Records'!G6:G55,"⚠ Partial") | E11: =COUNTIF('Documentation Records'!G6:G55,"❌ Not Implemented")+COUNTIF('Documentation Records'!G6:G55,"Planned") | F11: =COUNTIF('Documentation Records'!G6:G55,"N/A") | G11: =IF((B11-F11)=0,0,C11/(B11-F11))
A12: Change Management Tools - Supporting Tools | B12: =COUNTA('Tool Capabilities'!D36:D81) | C12: =COUNTIF('Tool Capabilities'!D36:D81,"✅ Implemented") | D12: =COUNTIF('Tool Capabilities'!D36:D81,"⚠ Partial") | E12: =COUNTIF('Tool Capabilities'!D36:D81,"❌ Not Implemented")+COUNTIF('Tool Capabilities'!D36:D81,"Planned") | F12: =COUNTIF('Tool Capabilities'!D36:D81,"N/A") | G12: =IF((B12-F12)=0,0,C12/(B12-F12))
A13: Change Management Tools - Integration Architecture | B13: =COUNTA('Tool Capabilities'!G57:G81) | C13: =COUNTIF('Tool Capabilities'!G57:G81,"✅ Implemented") | D13: =COUNTIF('Tool Capabilities'!G57:G81,"⚠ Partial") | E13: =COUNTIF('Tool Capabilities'!G57:G81,"❌ Not Implemented")+COUNTIF('Tool Capabilities'!G57:G81,"Planned") | F13: =COUNTIF('Tool Capabilities'!G57:G81,"N/A") | G13: =IF((B13-F13)=0,0,C13/(B13-F13))
A14: TOTAL | B14: =SUM(B6:B13) | C14: =SUM(C6:C13) | D14: =SUM(D6:D13) | E14: =SUM(E6:E13) | F14: =SUM(F6:F13) | G14: =IF((B14-F14)=0,0,C14/(B14-F14))
A16: TABLE 2: KEY METRICS
A17: Metric | B17: Value
A18: Change Success Rate | B18: ='Metrics KPIs'!D6
A19: Emergency Change Rate | B19: ='Metrics KPIs'!D7
A20: Average Change Lead Time | B20: [enter days]
A21: Failed Change Rate | B21: ='Metrics KPIs'!D10
A25: TABLE 3: CRITICAL FINDINGS
A26: Category | B26: Finding | C26: Count | D26: Severity | E26: Action Required
A27: Change Process | B27: Changes without approval | C27: =COUNTIF('Change Process Workflow'!G7:G56,"❌ Not Implemented") | D27: Critical | E27: Immediate
A28: Approval Authority | B28: Emergency changes without approval | C28: =COUNTIF('Approval Authority Matrix'!E75:E89,"❌ Not Implemented") | D28: Critical | E28: Immediate
A29: Communication | B29: Changes without stakeholder notification | C29: =COUNTIF('Communication'!G6:G55,"❌ Not Implemented") | D29: Critical | E29: Immediate
A30: Documentation | B30: Changes without documentation | C30: =COUNTIF('Documentation Records'!G6:G55,"❌ Not Implemented") | D30: Critical | E30: Immediate
A31: Tool Capabilities | B31: Critical tool capability gaps | C31: =COUNTIF('Tool Capabilities'!D36:D81,"❌ Not Implemented") | D31: Critical | E31: Immediate
A32: Change Process | B32: High-risk changes with partial implementation | C32: =COUNTIF('Change Process Workflow'!G7:G56,"⚠ Partial") | D32: High | E32: Urgent
A33: Approval Authority | B33: Standard changes with approval gaps | C33: =COUNTIF('Approval Authority Matrix'!F7:F89,"⚠ Partial") | D33: High | E33: Urgent
A34: Approval Authority | B34: Normal changes with approval gaps | C34: =COUNTIF('Approval Authority Matrix'!G61:G89,"⚠ Partial") | D34: High | E34: Urgent
A35: Communication | B35: Partial communication implementation | C35: =COUNTIF('Communication'!G6:G55,"⚠ Partial") | D35: Medium | E35: Plan
A36: Tool Capabilities | B36: Tool workflow gaps | C36: =COUNTIF('Tool Capabilities'!G57:G81,"⚠ Partial") | D36: Medium | E36: Plan

Sheet Approval Sign-Off
A1: ASSESSMENT APPROVAL AND SIGN-OFF
A2: ISO/IEC 27001:2022 - Control A.8.32: Change Management
A4: ASSESSMENT SUMMARY
A5: Document: | B5: ISMS-IMP-A.8.32.1 — Change Process Assessment
A6: Overall Compliance Rating: | B6: ='Summary Dashboard'!G14
A7: Assessment Period:
A8: Assessed By:
A9: Assessment Status:
A11: COMPLETED BY (ASSESSOR)
A12: Name:
A13: Title:
A14: Date:
A15: Signature:
A16: Comments:
A18: REVIEWED BY (INFORMATION SECURITY OFFICER)
A19: Name:
A20: Title:
... A37: Special Considerations:
