Workbook

Sheet Executive Summary
A1: ISMS-OP-CHK-A.5.32-33 — Information Protection and Records Management Compliance Checklist
A3: DOCUMENT INFORMATION
A4: Document ID | B4: ISMS-OP-CHK-A.5.32-33
A5: Source Policy | B5: ISMS-OP-POL-A.5.32-33
A6: ISO Controls | B6: Information Protection and Records Management
A7: Generated | B7: 08.02.2026
A8: Prepared By
A9: Organisation
A10: Review Cycle | B10: Annual
A12: OVERALL COMPLIANCE STATUS
A13: Overall Compliance | B13: ='Dashboard'!G8
A14: Status | B14: =IF(Dashboard!G8="N/A","NOT ASSESSED",IF(ISNUMBER(VALUE(SUBSTITUTE(Dashboard!G8,"%",""))),IF(VALUE(SUBSTITUTE(Dashboard!G8,"%",""))>=90,"GREEN",IF(VALUE(SUBSTITUTE(Dashboard!G8,"%",""))>=70,"AMBER","RED")),"NOT ASSESSED"))
A16: KEY METRICS
A17: Total Requirements | B17: ='Dashboard'!B8
A18: Compliant | B18: ='Dashboard'!C8
A19: Partial | B19: ='Dashboard'!D8
A20: Non-Compliant | B20: ='Dashboard'!E8
A21: Not Applicable | B21: ='Dashboard'!F8
A22: Owner Coverage | B22: =IF(Dashboard!B8=0,"N/A",ROUND((COUNTA('IP and Records Mgmt Systems'!F4:F4)+COUNTA('Intellectual Property Prot'!F4:F22)+COUNTA('Records Protection'!F4:F19)+COUNTA('Privacy Prots Records'!F4:F5))/Dashboard!B8*100,0)&"%")
A24: DOMAIN STATUS SUMMARY
A25: Domain | B25: Compliance % | C25: Compliant | D25: Gaps | E25: Status
A26: IP and Records Mgmt Systems | B26: ='Dashboard'!G4 | C26: ='Dashboard'!C4 | D26: ='Dashboard'!E4 | E26: =IF(Dashboard!G4="N/A","--",IF(ISNUMBER(VALUE(SUBSTITUTE(Dashboard!G4,"%",""))),IF(VALUE(SUBSTITUTE(Dashboard!G4,"%",""))>=90,"PASS",IF(VALUE(SUBSTITUTE(Dashboard!G4,"%",""))>=70,"REVIEW","FAIL")),"--"))
A27: Intellectual Property Prot | B27: ='Dashboard'!G5 | C27: ='Dashboard'!C5 | D27: ='Dashboard'!E5 | E27: =IF(Dashboard!G5="N/A","--",IF(ISNUMBER(VALUE(SUBSTITUTE(Dashboard!G5,"%",""))),IF(VALUE(SUBSTITUTE(Dashboard!G5,"%",""))>=90,"PASS",IF(VALUE(SUBSTITUTE(Dashboard!G5,"%",""))>=70,"REVIEW","FAIL")),"--"))
A28: Records Protection | B28: ='Dashboard'!G6 | C28: ='Dashboard'!C6 | D28: ='Dashboard'!E6 | E28: =IF(Dashboard!G6="N/A","--",IF(ISNUMBER(VALUE(SUBSTITUTE(Dashboard!G6,"%",""))),IF(VALUE(SUBSTITUTE(Dashboard!G6,"%",""))>=90,"PASS",IF(VALUE(SUBSTITUTE(Dashboard!G6,"%",""))>=70,"REVIEW","FAIL")),"--"))
A29: Privacy Prots Records | B29: ='Dashboard'!G7 | C29: ='Dashboard'!C7 | D29: ='Dashboard'!E7 | E29: =IF(Dashboard!G7="N/A","--",IF(ISNUMBER(VALUE(SUBSTITUTE(Dashboard!G7,"%",""))),IF(VALUE(SUBSTITUTE(Dashboard!G7,"%",""))>=90,"PASS",IF(VALUE(SUBSTITUTE(Dashboard!G7,"%",""))>=70,"REVIEW","FAIL")),"--"))
A31: CRITICAL ISSUES
A32: # | B32: Issue Description | C32: Domain | D32: Owner | E32: Due Date
A33: 1
A34: 2
A35: 3
A36: 4
A37: 5
A39: MANAGEMENT COMMENTARY
A40: [Enter management commentary on information protection and records management posture]
A44: APPROVAL
A45: Assessed By
A46: Name:
A47: Date:
A48: Signature:
A49: Decision:
...

Sheet Dashboard
A1: Information Protection and Records Management — Compliance Dashboard
A3: Domain | B3: Total Reqs | C3: Compliant | D3: Partial | E3: Non-Compliant | F3: N/A | G3: Compliance %
A4: IP and Records Mgmt Systems | B4: =COUNTA('IP and Records Mgmt Systems'!D4:D4) | C4: =COUNTIF('IP and Records Mgmt Systems'!D4:D4,"Compliant") | D4: =COUNTIF('IP and Records Mgmt Systems'!D4:D4,"Partial") | E4: =COUNTIF('IP and Records Mgmt Systems'!D4:D4,"Non-Compliant") | F4: =COUNTIF('IP and Records Mgmt Systems'!D4:D4,"N/A") | G4: =IF((B4-F4)=0,"N/A",ROUND(C4/(B4-F4)*100,1)&"%")
A5: Intellectual Property Prot | B5: =COUNTA('Intellectual Property Prot'!D4:D22) | C5: =COUNTIF('Intellectual Property Prot'!D4:D22,"Compliant") | D5: =COUNTIF('Intellectual Property Prot'!D4:D22,"Partial") | E5: =COUNTIF('Intellectual Property Prot'!D4:D22,"Non-Compliant") | F5: =COUNTIF('Intellectual Property Prot'!D4:D22,"N/A") | G5: =IF((B5-F5)=0,"N/A",ROUND(C5/(B5-F5)*100,1)&"%")
A6: Records Protection | B6: =COUNTA('Records Protection'!D4:D19) | C6: =COUNTIF('Records Protection'!D4:D19,"Compliant") | D6: =COUNTIF('Records Protection'!D4:D19,"Partial") | E6: =COUNTIF('Records Protection'!D4:D19,"Non-Compliant") | F6: =COUNTIF('Records Protection'!D4:D19,"N/A") | G6: =IF((B6-F6)=0,"N/A",ROUND(C6/(B6-F6)*100,1)&"%")
A7: Privacy Prots Records | B7: =COUNTA('Privacy Prots Records'!D4:D5) | C7: =COUNTIF('Privacy Prots Records'!D4:D5,"Compliant") | D7: =COUNTIF('Privacy Prots Records'!D4:D5,"Partial") | E7: =COUNTIF('Privacy Prots Records'!D4:D5,"Non-Compliant") | F7: =COUNTIF('Privacy Prots Records'!D4:D5,"N/A") | G7: =IF((B7-F7)=0,"N/A",ROUND(C7/(B7-F7)*100,1)&"%")
A8: TOTAL | B8: =SUM(B4:B7) | C8: =SUM(C4:C7) | D8: =SUM(D4:D7) | E8: =SUM(E4:E7) | F8: =SUM(F4:F7) | G8: =IF((B8-F8)=0,"N/A",ROUND(C8/(B8-F8)*100,1)&"%")
A10: COMPLIANCE BY STATUS
A11: Compliant | B11: =C8 | C11: =IF(B8=0,"",ROUND(B11/B8*100,1)&"%")
A12: Partial | B12: =D8 | C12: =IF(B8=0,"",ROUND(B12/B8*100,1)&"%")
A13: Non-Compliant | B13: =E8 | C13: =IF(B8=0,"",ROUND(B13/B8*100,1)&"%")
A14: N/A | B14: =F8 | C14: =IF(B8=0,"",ROUND(B14/B8*100,1)&"%")
A16: TOP GAPS (Manual Entry)
A17: Priority | B17: Domain | C17: Requirement | D17: Owner | E17: Due Date | F17: Status
A29: COMPLIANCE TREND (Manual Entry)
A30: Assessment Date | B30: Overall % | C30: Compliant | D30: Gaps | E30: Assessor | F30: Notes

Sheet IP and Records Mgmt Systems
A1: IP and Records Mgmt Systems — Compliance Checklist
A2: ISO/IEC 27001:2022 — Controls A.5.32-33: Information Protection and Records Management
A3: Req # | B3: Section | C3: Requirement | D3: Status | E3: Evidence | F3: Owner | G3: Due Date | H3: Notes
A4: A.5.32-33-01 | B4: Use The Following Systems To Manage | C4: The organisation shall use the following systems to manage intellectual property and records:.

Sheet Intellectual Property Prot
A1: Intellectual Property Prot — Compliance Checklist
A2: ISO/IEC 27001:2022 — Controls A.5.32-33: Information Protection and Records Management
A3: Req # | B3: Section | C3: Requirement | D3: Status | E3: Evidence | F3: Owner | G3: Due Date | H3: Notes
A4: A.5.32-33-02 | B4: Identify And Classify All Intellectual | C4: The organisation shall identify and classify all intellectual property assets:.
A5: A.5.32-33-03 | B5: An Ip Register | C5: An IP register shall be maintained recording all significant intellectual property assets. The register shall include, at minimum:.
A6: A.5.32-33-04 | B6: The Ip Register | C6: The IP register shall be reviewed annually by Legal Counsel (or equivalent role) and the CISO.
A7: A.5.32-33-05 | B7: Protection Controls | C7: Protection controls shall be implemented based on IP type and classification:.
A8: A.5.32-33-06 | B8: Third Parties (Vendors, Consultants, | C8: All third parties (vendors, consultants, contractors, partners) accessing organisation IP or confidential records shall sign a Non-Disclosure Agreement (NDA) before access is granted.
A9: A.5.32-33-07 | B9: Renewal: For Ongoing Relationships, Ndas | C9: Renewal: For ongoing relationships, NDAs shall be reviewed and renewed before expiration.
A10: A.5.32-33-08 | B10: Require Third Party To Return Or | C10: NDA shall require third party to return or certify deletion of all organisation IP upon contract termination.
A11: A.5.32-33-09 | B11: Business Owner | C11: Business owner shall verify return/deletion and document verification in agreement register.
A12: A.5.32-33-10 | B12: Nda Register Review: Legal Counsel | C12: NDA Register Review: Legal Counsel shall review NDA register quarterly* to identify expiring NDAs requiring renewal and terminated relationships requiring IP return verification. Target: 100% of active third parties with valid NDAs.
A13: A.5.32-33-11 | B13: Software Used By The Organisation | C13: All software used by the organisation shall be properly licensed and compliant:.
A14: A.5.32-33-12 | B14: Be Acquired Through Official Channels | C14: Software shall be acquired through official channels only. Evidence of valid licences shall be retained.
A15: A.5.32-33-13 | B15: Be Used In Accordance With Licence | C15: Software shall be used in accordance with licence terms.
... A22: A.5.32-33-20 | B22: Oss Register Review: Development Manager | C22: OSS Register Review: Development Manager shall review OSS register quarterly* to verify all components are properly licensed and documented. Target: 100% OSS components with valid licence approval.

Sheet Records Protection
A1: Records Protection — Compliance Checklist
A2: ISO/IEC 27001:2022 — Controls A.5.32-33: Information Protection and Records Management
A3: Req # | B3: Section | C3: Requirement | D3: Status | E3: Evidence | F3: Owner | G3: Due Date | H3: Notes
A4: A.5.32-33-21 | B4: Classify Records Based On Retention | C4: The organisation shall classify records based on retention requirements and protection needs:.
A5: A.5.32-33-22 | B5: A Documented Retention Schedule | C5: A documented retention schedule shall be maintained:.
A6: A.5.32-33-23 | B6: Conflict Resolution: Where Multiple | C6: Conflict resolution: Where multiple regulations apply, the most stringent retention requirement shall prevail. Where a deletion or erasure request conflicts with legal retention obligations, retention takes precedence — the records shall be access-restricted, the decision documented with Legal Counsel approval, and DPO involvement obtained for personal data.
A7: A.5.32-33-24 | B7: Grace Period*: Records May Be Retained | C7: Grace Period*: Records may be retained up to 12 months beyond the minimum retention period to allow for orderly disposal processes. Records shall not be retained indefinitely without documented justification.
A8: A.5.32-33-25 | B8: Annual Review*: Legal Counsel | C8: Annual Review*: Legal Counsel shall review the retention schedule annually and update for regulatory changes, new record types, or business needs.
A9: A.5.32-33-26 | B9: Be Protected Throughout Their Lifecycle | C9: Records shall be protected throughout their lifecycle:.
A10: A.5.32-33-27 | B10: Backup Restoration Testing | C10: Backup restoration testing shall be performed quarterly for critical records (select 3 sample records from each category, perform test restoration, verify integrity and completeness). Target: 100% successful restoration.
A11: A.5.32-33-28 | B11: Critical Records | C11: Critical records shall have backups stored in a geographically separate location (minimum 100 km from primary site).
A12: A.5.32-33-29 | B12: Backups | C12: Backups containing confidential records shall be encrypted (AES-256 or equivalent).
A13: A.5.32-33-30 | B13: Be Disposed Of Securely When The | C13: Records shall be disposed of securely when the retention period expires (and no legal hold applies):.
A14: A.5.32-33-31 | B14: Disposal Records | C14: Disposal records shall be maintained for the audit trail (minimum 3 years).
A15: A.5.32-33-32 | B15: Certificates Of Destruction | C15: Certificates of destruction shall be obtained for confidential and above records.
... A19: A.5.32-33-36 | B19: Compliance Verification*: Internal Audit | C19: Compliance Verification*: Internal Audit shall verify legal hold compliance annually (sample custodian acknowledgements, verify IT suspension was implemented).

Sheet Privacy Prots Records
A1: Privacy Prots Records — Compliance Checklist
A2: ISO/IEC 27001:2022 — Controls A.5.32-33: Information Protection and Records Management
A3: Req # | B3: Section | C3: Requirement | D3: Status | E3: Evidence | F3: Owner | G3: Due Date | H3: Notes
A4: A.5.32-33-37 | B4: Security Logs | C4: Security logs containing user activity: access restricted to IT Security Team and Internal Audit; logs shall not be browsed by line managers for employee monitoring.
A5: A.5.32-33-38 | B5: Retention Minimisation*: Personal Data | C5: Retention Minimisation*: Personal data in records shall not be retained longer than necessary. Annual review: Records Manager and DPO shall review retention schedule to verify personal data retention periods remain justified and comply with nFADP Art. 6 (proportionality).
