Workbook

Sheet Executive Summary
A1: ISMS-OP-CHK-A.8.6 — Capacity Management Compliance Checklist
A3: DOCUMENT INFORMATION
A4: Document ID | B4: ISMS-OP-CHK-A.8.6
A5: Source Policy | B5: ISMS-OP-POL-A.8.6
A6: ISO Controls | B6: Capacity Management
A7: Generated | B7: 08.02.2026
A8: Prepared By
A9: Organisation
A10: Review Cycle | B10: Annual
A12: OVERALL COMPLIANCE STATUS
A13: Overall Compliance | B13: ='Dashboard'!G16
A14: Status | B14: =IF(Dashboard!G16="N/A","NOT ASSESSED",IF(ISNUMBER(VALUE(SUBSTITUTE(Dashboard!G16,"%",""))),IF(VALUE(SUBSTITUTE(Dashboard!G16,"%",""))>=90,"GREEN",IF(VALUE(SUBSTITUTE(Dashboard!G16,"%",""))>=70,"AMBER","RED")),"NOT ASSESSED"))
A16: KEY METRICS
A17: Total Requirements | B17: ='Dashboard'!B16
A18: Compliant | B18: ='Dashboard'!C16
A19: Partial | B19: ='Dashboard'!D16
A20: Non-Compliant | B20: ='Dashboard'!E16
A21: Not Applicable | B21: ='Dashboard'!F16
A22: Owner Coverage | B22: =IF(Dashboard!B16=0,"N/A",ROUND((COUNTA('Resource Monitoring'!F4:F7)+COUNTA('Threshold Framework & Alerting'!F4:F8)+COUNTA('Capacity Forecasting'!F4:F7)+COUNTA('Auto-Scaling Policies'!F4:F10)+COUNTA('Capacity and Cost Optimisation'!F4:F6)+COUNTA('Capacity & Service Level'!F4:F5)+COUNTA('Capacity Reporting'!F4:F5)+COUNTA('Storage Capacity Management'!F4:F12)+COUNTA('Licence Capacity Management'!F4:F5)+COUNTA('Capacity Incident Response'!F4:F6)+COUNTA('Denial-of-Service Resilience'!F4:F5)+COUNTA('Capacity Planning Committee'!F4:F6))/Dashboard!B16*100,0)&"%")
A24: DOMAIN STATUS SUMMARY
A25: Domain | B25: Compliance % | C25: Compliant | D25: Gaps | E25: Status
A26: Resource Monitoring | B26: ='Dashboard'!G4 | C26: ='Dashboard'!C4 | D26: ='Dashboard'!E4 | E26: =IF(Dashboard!G4="N/A","--",IF(ISNUMBER(VALUE(SUBSTITUTE(Dashboard!G4,"%",""))),IF(VALUE(SUBSTITUTE(Dashboard!G4,"%",""))>=90,"PASS",IF(VALUE(SUBSTITUTE(Dashboard!G4,"%",""))>=70,"REVIEW","FAIL")),"--"))
A27: Threshold Framework & Alerting | B27: ='Dashboard'!G5 | C27: ='Dashboard'!C5 | D27: ='Dashboard'!E5 | E27: =IF(Dashboard!G5="N/A","--",IF(ISNUMBER(VALUE(SUBSTITUTE(Dashboard!G5,"%",""))),IF(VALUE(SUBSTITUTE(Dashboard!G5,"%",""))>=90,"PASS",IF(VALUE(SUBSTITUTE(Dashboard!G5,"%",""))>=70,"REVIEW","FAIL")),"--"))
A28: Capacity Forecasting | B28: ='Dashboard'!G6 | C28: ='Dashboard'!C6 | D28: ='Dashboard'!E6 | E28: =IF(Dashboard!G6="N/A","--",IF(ISNUMBER(VALUE(SUBSTITUTE(Dashboard!G6,"%",""))),IF(VALUE(SUBSTITUTE(Dashboard!G6,"%",""))>=90,"PASS",IF(VALUE(SUBSTITUTE(Dashboard!G6,"%",""))>=70,"REVIEW","FAIL")),"--"))
A29: Auto-Scaling Policies | B29: ='Dashboard'!G7 | C29: ='Dashboard'!C7 | D29: ='Dashboard'!E7 | E29: =IF(Dashboard!G7="N/A","--",IF(ISNUMBER(VALUE(SUBSTITUTE(Dashboard!G7,"%",""))),IF(VALUE(SUBSTITUTE(Dashboard!G7,"%",""))>=90,"PASS",IF(VALUE(SUBSTITUTE(Dashboard!G7,"%",""))>=70,"REVIEW","FAIL")),"--"))
A30: Capacity and Cost Optimisation | B30: ='Dashboard'!G8 | C30: ='Dashboard'!C8 | D30: ='Dashboard'!E8 | E30: =IF(Dashboard!G8="N/A","--",IF(ISNUMBER(VALUE(SUBSTITUTE(Dashboard!G8,"%",""))),IF(VALUE(SUBSTITUTE(Dashboard!G8,"%",""))>=90,"PASS",IF(VALUE(SUBSTITUTE(Dashboard!G8,"%",""))>=70,"REVIEW","FAIL")),"--"))
A31: Capacity & Service Level | B31: ='Dashboard'!G9 | C31: ='Dashboard'!C9 | D31: ='Dashboard'!E9 | E31: =IF(Dashboard!G9="N/A","--",IF(ISNUMBER(VALUE(SUBSTITUTE(Dashboard!G9,"%",""))),IF(VALUE(SUBSTITUTE(Dashboard!G9,"%",""))>=90,"PASS",IF(VALUE(SUBSTITUTE(Dashboard!G9,"%",""))>=70,"REVIEW","FAIL")),"--"))
A32: Capacity Reporting | B32: ='Dashboard'!G10 | C32: ='Dashboard'!C10 | D32: ='Dashboard'!E10 | E32: =IF(Dashboard!G10="N/A","--",IF(ISNUMBER(VALUE(SUBSTITUTE(Dashboard!G10,"%",""))),IF(VALUE(SUBSTITUTE(Dashboard!G10,"%",""))>=90,"PASS",IF(VALUE(SUBSTITUTE(Dashboard!G10,"%",""))>=70,"REVIEW","FAIL")),"--"))
A33: Storage Capacity Management | B33: ='Dashboard'!G11 | C33: ='Dashboard'!C11 | D33: ='Dashboard'!E11 | E33: =IF(Dashboard!G11="N/A","--",IF(ISNUMBER(VALUE(SUBSTITUTE(Dashboard!G11,"%",""))),IF(VALUE(SUBSTITUTE(Dashboard!G11,"%",""))>=90,"PASS",IF(VALUE(SUBSTITUTE(Dashboard!G11,"%",""))>=70,"REVIEW","FAIL")),"--"))
A34: Licence Capacity Management | B34: ='Dashboard'!G12 | C34: ='Dashboard'!C12 | D34: ='Dashboard'!E12 | E34: =IF(Dashboard!G12="N/A","--",IF(ISNUMBER(VALUE(SUBSTITUTE(Dashboard!G12,"%",""))),IF(VALUE(SUBSTITUTE(Dashboard!G12,"%",""))>=90,"PASS",IF(VALUE(SUBSTITUTE(Dashboard!G12,"%",""))>=70,"REVIEW","FAIL")),"--"))
A35: Capacity Incident Response | B35: ='Dashboard'!G13 | C35: ='Dashboard'!C13 | D35: ='Dashboard'!E13 | E35: =IF(Dashboard!G13="N/A","--",IF(ISNUMBER(VALUE(SUBSTITUTE(Dashboard!G13,"%",""))),IF(VALUE(SUBSTITUTE(Dashboard!G13,"%",""))>=90,"PASS",IF(VALUE(SUBSTITUTE(Dashboard!G13,"%",""))>=70,"REVIEW","FAIL")),"--"))
A36: Denial-of-Service Resilience | B36: ='Dashboard'!G14 | C36: ='Dashboard'!C14 | D36: ='Dashboard'!E14 | E36: =IF(Dashboard!G14="N/A","--",IF(ISNUMBER(VALUE(SUBSTITUTE(Dashboard!G14,"%",""))),IF(VALUE(SUBSTITUTE(Dashboard!G14,"%",""))>=90,"PASS",IF(VALUE(SUBSTITUTE(Dashboard!G14,"%",""))>=70,"REVIEW","FAIL")),"--"))
A37: Capacity Planning Committee | B37: ='Dashboard'!G15 | C37: ='Dashboard'!C15 | D37: ='Dashboard'!E15 | E37: =IF(Dashboard!G15="N/A","--",IF(ISNUMBER(VALUE(SUBSTITUTE(Dashboard!G15,"%",""))),IF(VALUE(SUBSTITUTE(Dashboard!G15,"%",""))>=90,"PASS",IF(VALUE(SUBSTITUTE(Dashboard!G15,"%",""))>=70,"REVIEW","FAIL")),"--"))
A39: CRITICAL ISSUES
A40: # | B40: Issue Description | C40: Domain | D40: Owner | E40: Due Date
A41: 1
A42: 2
A43: 3
A44: 4
A45: 5
...

Sheet Dashboard
A1: Capacity Management — Compliance Dashboard
A3: Domain | B3: Total Reqs | C3: Compliant | D3: Partial | E3: Non-Compliant | F3: N/A | G3: Compliance %
A4: Resource Monitoring | B4: =COUNTA('Resource Monitoring'!D4:D7) | C4: =COUNTIF('Resource Monitoring'!D4:D7,"Compliant") | D4: =COUNTIF('Resource Monitoring'!D4:D7,"Partial") | E4: =COUNTIF('Resource Monitoring'!D4:D7,"Non-Compliant") | F4: =COUNTIF('Resource Monitoring'!D4:D7,"N/A") | G4: =IF((B4-F4)=0,"N/A",ROUND(C4/(B4-F4)*100,1)&"%")
A5: Threshold Framework & Alerting | B5: =COUNTA('Threshold Framework & Alerting'!D4:D8) | C5: =COUNTIF('Threshold Framework & Alerting'!D4:D8,"Compliant") | D5: =COUNTIF('Threshold Framework & Alerting'!D4:D8,"Partial") | E5: =COUNTIF('Threshold Framework & Alerting'!D4:D8,"Non-Compliant") | F5: =COUNTIF('Threshold Framework & Alerting'!D4:D8,"N/A") | G5: =IF((B5-F5)=0,"N/A",ROUND(C5/(B5-F5)*100,1)&"%")
A6: Capacity Forecasting | B6: =COUNTA('Capacity Forecasting'!D4:D7) | C6: =COUNTIF('Capacity Forecasting'!D4:D7,"Compliant") | D6: =COUNTIF('Capacity Forecasting'!D4:D7,"Partial") | E6: =COUNTIF('Capacity Forecasting'!D4:D7,"Non-Compliant") | F6: =COUNTIF('Capacity Forecasting'!D4:D7,"N/A") | G6: =IF((B6-F6)=0,"N/A",ROUND(C6/(B6-F6)*100,1)&"%")
A7: Auto-Scaling Policies | B7: =COUNTA('Auto-Scaling Policies'!D4:D10) | C7: =COUNTIF('Auto-Scaling Policies'!D4:D10,"Compliant") | D7: =COUNTIF('Auto-Scaling Policies'!D4:D10,"Partial") | E7: =COUNTIF('Auto-Scaling Policies'!D4:D10,"Non-Compliant") | F7: =COUNTIF('Auto-Scaling Policies'!D4:D10,"N/A") | G7: =IF((B7-F7)=0,"N/A",ROUND(C7/(B7-F7)*100,1)&"%")
A8: Capacity and Cost Optimisation | B8: =COUNTA('Capacity and Cost Optimisation'!D4:D6) | C8: =COUNTIF('Capacity and Cost Optimisation'!D4:D6,"Compliant") | D8: =COUNTIF('Capacity and Cost Optimisation'!D4:D6,"Partial") | E8: =COUNTIF('Capacity and Cost Optimisation'!D4:D6,"Non-Compliant") | F8: =COUNTIF('Capacity and Cost Optimisation'!D4:D6,"N/A") | G8: =IF((B8-F8)=0,"N/A",ROUND(C8/(B8-F8)*100,1)&"%")
A9: Capacity & Service Level | B9: =COUNTA('Capacity & Service Level'!D4:D5) | C9: =COUNTIF('Capacity & Service Level'!D4:D5,"Compliant") | D9: =COUNTIF('Capacity & Service Level'!D4:D5,"Partial") | E9: =COUNTIF('Capacity & Service Level'!D4:D5,"Non-Compliant") | F9: =COUNTIF('Capacity & Service Level'!D4:D5,"N/A") | G9: =IF((B9-F9)=0,"N/A",ROUND(C9/(B9-F9)*100,1)&"%")
A10: Capacity Reporting | B10: =COUNTA('Capacity Reporting'!D4:D5) | C10: =COUNTIF('Capacity Reporting'!D4:D5,"Compliant") | D10: =COUNTIF('Capacity Reporting'!D4:D5,"Partial") | E10: =COUNTIF('Capacity Reporting'!D4:D5,"Non-Compliant") | F10: =COUNTIF('Capacity Reporting'!D4:D5,"N/A") | G10: =IF((B10-F10)=0,"N/A",ROUND(C10/(B10-F10)*100,1)&"%")
A11: Storage Capacity Management | B11: =COUNTA('Storage Capacity Management'!D4:D12) | C11: =COUNTIF('Storage Capacity Management'!D4:D12,"Compliant") | D11: =COUNTIF('Storage Capacity Management'!D4:D12,"Partial") | E11: =COUNTIF('Storage Capacity Management'!D4:D12,"Non-Compliant") | F11: =COUNTIF('Storage Capacity Management'!D4:D12,"N/A") | G11: =IF((B11-F11)=0,"N/A",ROUND(C11/(B11-F11)*100,1)&"%")
A12: Licence Capacity Management | B12: =COUNTA('Licence Capacity Management'!D4:D5) | C12: =COUNTIF('Licence Capacity Management'!D4:D5,"Compliant") | D12: =COUNTIF('Licence Capacity Management'!D4:D5,"Partial") | E12: =COUNTIF('Licence Capacity Management'!D4:D5,"Non-Compliant") | F12: =COUNTIF('Licence Capacity Management'!D4:D5,"N/A") | G12: =IF((B12-F12)=0,"N/A",ROUND(C12/(B12-F12)*100,1)&"%")
A13: Capacity Incident Response | B13: =COUNTA('Capacity Incident Response'!D4:D6) | C13: =COUNTIF('Capacity Incident Response'!D4:D6,"Compliant") | D13: =COUNTIF('Capacity Incident Response'!D4:D6,"Partial") | E13: =COUNTIF('Capacity Incident Response'!D4:D6,"Non-Compliant") | F13: =COUNTIF('Capacity Incident Response'!D4:D6,"N/A") | G13: =IF((B13-F13)=0,"N/A",ROUND(C13/(B13-F13)*100,1)&"%")
A14: Denial-of-Service Resilience | B14: =COUNTA('Denial-of-Service Resilience'!D4:D5) | C14: =COUNTIF('Denial-of-Service Resilience'!D4:D5,"Compliant") | D14: =COUNTIF('Denial-of-Service Resilience'!D4:D5,"Partial") | E14: =COUNTIF('Denial-of-Service Resilience'!D4:D5,"Non-Compliant") | F14: =COUNTIF('Denial-of-Service Resilience'!D4:D5,"N/A") | G14: =IF((B14-F14)=0,"N/A",ROUND(C14/(B14-F14)*100,1)&"%")
A15: Capacity Planning Committee | B15: =COUNTA('Capacity Planning Committee'!D4:D6) | C15: =COUNTIF('Capacity Planning Committee'!D4:D6,"Compliant") | D15: =COUNTIF('Capacity Planning Committee'!D4:D6,"Partial") | E15: =COUNTIF('Capacity Planning Committee'!D4:D6,"Non-Compliant") | F15: =COUNTIF('Capacity Planning Committee'!D4:D6,"N/A") | G15: =IF((B15-F15)=0,"N/A",ROUND(C15/(B15-F15)*100,1)&"%")
A16: TOTAL | B16: =SUM(B4:B15) | C16: =SUM(C4:C15) | D16: =SUM(D4:D15) | E16: =SUM(E4:E15) | F16: =SUM(F4:F15) | G16: =IF((B16-F16)=0,"N/A",ROUND(C16/(B16-F16)*100,1)&"%")
A18: COMPLIANCE BY STATUS
A19: Compliant | B19: =C16 | C19: =IF(B16=0,"",ROUND(B19/B16*100,1)&"%")
A20: Partial | B20: =D16 | C20: =IF(B16=0,"",ROUND(B20/B16*100,1)&"%")
A21: Non-Compliant | B21: =E16 | C21: =IF(B16=0,"",ROUND(B21/B16*100,1)&"%")
A22: N/A | B22: =F16 | C22: =IF(B16=0,"",ROUND(B22/B16*100,1)&"%")
A24: TOP GAPS (Manual Entry)
A25: Priority | B25: Domain | C25: Requirement | D25: Owner | E25: Due Date | F25: Status
A37: COMPLIANCE TREND (Manual Entry)
A38: Assessment Date | B38: Overall % | C38: Compliant | D38: Gaps | E38: Assessor | F38: Notes

Sheet Resource Monitoring
A1: Resource Monitoring — Compliance Checklist
A2: ISO/IEC 27001:2022 — Control A.8.6: Capacity Management
A3: Req # | B3: Section | C3: Requirement | D3: Status | E3: Evidence | F3: Owner | G3: Due Date | H3: Notes
A4: A.8.6-01 | B4: Production Systems And Services | C4: All production systems and services shall have capacity monitoring enabled. Monitoring shall cover, at minimum, the resource categories listed in the Scope section above.
A5: A.8.6-02 | B5: Be Implemented Using [Monitoring | C5: Monitoring shall be implemented using [Monitoring Platform] (e.g., Prometheus, Zabbix, Datadog, Azure Monitor, CloudWatch, or equivalent). The platform shall be documented in the asset inventory with its hosting model, data residency, and administrative access controls.
A6: A.8.6-03 | B6: The Following Metrics | C6: The following metrics shall be collected for each applicable resource type:.
A7: A.8.6-04 | B7: Metric Data | C7: Metric data shall be protected from unauthorised modification or deletion. Where metrics feed security monitoring (A.8.16), log integrity requirements from the Logging Policy (A.8.15) also apply.

Sheet Threshold Framework & Alerting
A1: Threshold Framework & Alerting — Compliance Checklist
A2: ISO/IEC 27001:2022 — Control A.8.6: Capacity Management
A3: Req # | B3: Section | C3: Requirement | D3: Status | E3: Evidence | F3: Owner | G3: Due Date | H3: Notes
A4: A.8.6-05 | B4: Monitored Resources | C4: All monitored resources shall have defined capacity thresholds at three levels:.
A5: A.8.6-06 | B5: Exact Threshold Values | C5: Exact threshold values shall be defined per resource type and system classification, documented in the monitoring platform, and reviewed quarterly. Thresholds shall be tuned based on false positive rates, workload patterns, and near-miss incidents.
A6: A.8.6-07 | B6: Storage-Specific Thresholds* | C6: Storage-specific thresholds* shall also account for growth rate: if storage is projected to reach 95% within 30 days at the current consumption rate, a warning alert shall be generated regardless of current percentage.
A7: A.8.6-08 | B7: Capacity Threshold Alerts | C7: Capacity threshold alerts shall be configured with:.
A8: A.8.6-09 | B8: Integration: Critical And Maximum Alerts | C8: Integration: Critical and maximum alerts shall create incidents automatically in [ITSM Tool] (e.g., ServiceNow, Jira Service Management, or equivalent).

Sheet Capacity Forecasting
A1: Capacity Forecasting — Compliance Checklist
A2: ISO/IEC 27001:2022 — Control A.8.6: Capacity Management
A3: Req # | B3: Section | C3: Requirement | D3: Status | E3: Evidence | F3: Owner | G3: Due Date | H3: Notes
A4: A.8.6-10 | B4: Develop And Maintain Capacity Forecasts | C4: The organisation shall develop and maintain capacity forecasts at three horizons:.
A5: A.8.6-11 | B5: Be Based On | C5: Forecasts shall be based on:.
A6: A.8.6-12 | B6: Conservative Estimates | C6: Where historical data is insufficient (new systems or services), conservative estimates shall be used with more frequent review during the first 6 months of operation.
A7: A.8.6-13 | B7: Target Accuracy: Forecasts | C7: Target accuracy: Forecasts shall be within +/-15% of actual utilisation (measured quarterly).

Sheet Auto-Scaling Policies
A1: Auto-Scaling Policies — Compliance Checklist
A2: ISO/IEC 27001:2022 — Control A.8.6: Capacity Management
A3: Req # | B3: Section | C3: Requirement | D3: Status | E3: Evidence | F3: Owner | G3: Due Date | H3: Notes
A4: A.8.6-14 | B4: Auto-Scaling | C4: Where the organisation operates cloud infrastructure, auto-scaling shall be configured for workloads with variable demand patterns.
A5: A.8.6-15 | B5: Auto-Scaling Configurations | C5: Auto-scaling configurations shall be documented and version-controlled.
A6: A.8.6-16 | B6: Changes To Auto-Scaling Policies For | C6: Changes to auto-scaling policies for production workloads shall follow the change management process (A.8.32).
A7: A.8.6-17 | B7: Maximum Instance Limits | C7: Maximum instance limits shall be reviewed quarterly and aligned with approved budgets.
A8: A.8.6-18 | B8: Auto-Scaling Events | C8: Auto-scaling events shall be logged and reviewed monthly for optimisation opportunities.
A9: A.8.6-19 | B9: Cost Guardrails: Maximum Monthly Spend | C9: Cost guardrails: Maximum monthly spend limits shall be configured at the cloud account or subscription level. Auto-scaling that would breach the spend limit shall trigger an alert to the Infrastructure Manager and CFO delegate.
A10: A.8.6-20 | B10: Fixed-Capacity Services), Manual | C10: Where auto-scaling is not available or not appropriate (on-premises infrastructure, fixed-capacity services), manual capacity expansion procedures shall be documented with defined procurement and deployment lead times.

Sheet Capacity and Cost Optimisation
A1: Capacity and Cost Optimisation — Compliance Checklist
A2: ISO/IEC 27001:2022 — Control A.8.6: Capacity Management
A3: Req # | B3: Section | C3: Requirement | D3: Status | E3: Evidence | F3: Owner | G3: Due Date | H3: Notes
A4: A.8.6-21 | B4: Capacity Management | C4: Capacity management shall balance availability, performance, and cost. Over-provisioning wastes budget; under-provisioning creates risk. The organisation shall actively optimise resource allocation based on measured utilisation data.
A5: A.8.6-22 | B5: The Infrastructure Manager | C5: The Infrastructure Manager shall conduct a quarterly cost review that includes:.
A6: A.8.6-23 | B6: Cost Optimisation Findings | C6: Cost optimisation findings shall be included in the quarterly capacity review report presented to the CIO, CISO, and CFO delegate.

Sheet Capacity & Service Level
A1: Capacity & Service Level — Compliance Checklist
A2: ISO/IEC 27001:2022 — Control A.8.6: Capacity Management
A3: Req # | B3: Section | C3: Requirement | D3: Status | E3: Evidence | F3: Owner | G3: Due Date | H3: Notes
A4: A.8.6-24 | B4: Capacity Thresholds | C4: Capacity thresholds shall be aligned with service level objectives (SLOs) to ensure that capacity constraints do not degrade service quality below agreed levels. The connection between resource utilisation and service performance shall be documented for each critical service.
A5: A.8.6-25 | B5: Capacity Thresholds | C5: Where measured resource utilisation approaches levels that would degrade SLO performance, capacity thresholds shall be adjusted downward to trigger earlier intervention. SLO alignment shall be reviewed quarterly as part of the capacity review process.

Sheet Capacity Reporting
A1: Capacity Reporting — Compliance Checklist
A2: ISO/IEC 27001:2022 — Control A.8.6: Capacity Management
A3: Req # | B3: Section | C3: Requirement | D3: Status | E3: Evidence | F3: Owner | G3: Due Date | H3: Notes
A4: A.8.6-26 | B4: Monthly And Quarterly Reports | C4: Monthly and quarterly reports shall include:.
A5: A.8.6-27 | B5: Be Generated From [Monitoring Platform] | C5: Reports shall be generated from [Monitoring Platform] data. The annual capacity plan shall be approved by the CIO and included in the management review per ISO 27001 Clause 9.3.

Sheet Storage Capacity Management
A1: Storage Capacity Management — Compliance Checklist
A2: ISO/IEC 27001:2022 — Control A.8.6: Capacity Management
A3: Req # | B3: Section | C3: Requirement | D3: Status | E3: Evidence | F3: Owner | G3: Due Date | H3: Notes
A4: A.8.6-28 | B4: Log Storage Capacity | C4: Log storage capacity shall be planned in coordination with the Logging Policy (A.8.15) to ensure retention requirements can be met without storage exhaustion.
A5: A.8.6-29 | B5: Log Storage | C5: Log storage shall have a dedicated warning threshold at 70% and critical threshold at 85%.
A6: A.8.6-30 | B6: Automated Log Rotation Or Archival | C6: If log storage reaches critical threshold, automated log rotation or archival shall be triggered before data loss occurs.
A7: A.8.6-31 | B7: Log Storage Growth Rate | C7: Log storage growth rate shall be tracked and projected monthly.
A8: A.8.6-32 | B8: Database Storage Growth | C8: Database storage growth shall be monitored and forecast separately from file storage.
A9: A.8.6-33 | B9: Database Maintenance Activities | C9: Database maintenance activities (vacuuming, index rebuilds, archival) shall be factored into capacity planning.
A10: A.8.6-34 | B10: Database Storage Thresholds | C10: Database storage thresholds shall account for operational overhead (temporary tables, transaction logs, replication lag).
A11: A.8.6-35 | B11: Backup Storage Capacity | C11: Backup storage capacity shall be planned to accommodate full backup sets for the required retention period per the backup policy (A.5.30–8.13–14).
A12: A.8.6-36 | B12: Growth In Backup Storage | C12: Growth in backup storage shall be forecast based on production data growth and retention policy changes.

Sheet Licence Capacity Management
A1: Licence Capacity Management — Compliance Checklist
A2: ISO/IEC 27001:2022 — Control A.8.6: Capacity Management
A3: Req # | B3: Section | C3: Requirement | D3: Status | E3: Evidence | F3: Owner | G3: Due Date | H3: Notes
A4: A.8.6-37 | B4: Software Licence Capacity | C4: Software licence capacity shall be monitored to prevent compliance violations and service interruptions caused by licence exhaustion.
A5: A.8.6-38 | B5: Licence Renewals | C5: Licence renewals shall be tracked with a minimum 90-day lead time before expiry. Licence capacity requirements shall be included in the medium-term (6–12 month) capacity forecast and aligned with budget planning cycles.

Sheet Capacity Incident Response
A1: Capacity Incident Response — Compliance Checklist
A2: ISO/IEC 27001:2022 — Control A.8.6: Capacity Management
A3: Req # | B3: Section | C3: Requirement | D3: Status | E3: Evidence | F3: Owner | G3: Due Date | H3: Notes
A4: A.8.6-39 | B4: The Organisation'S Incident Management | C4: When capacity exhaustion causes or threatens to cause service impact, the organisation's incident management process (A.5.24–28) shall be invoked.
A5: A.8.6-40 | B5: Capacity-Related Incidents Classified | C5: All capacity-related incidents classified Priority 1 or Priority 2 shall undergo post-incident review within 5 business days. The review shall determine:.
A6: A.8.6-41 | B6: Be Tracked In The Capacity Improvement | C6: Findings shall be tracked in the capacity improvement register until remediation is complete.

Sheet Denial-of-Service Resilience
A1: Denial-of-Service Resilience — Compliance Checklist
A2: ISO/IEC 27001:2022 — Control A.8.6: Capacity Management
A3: Req # | B3: Section | C3: Requirement | D3: Status | E3: Evidence | F3: Owner | G3: Due Date | H3: Notes
A4: A.8.6-42 | B4: Capacity Planning | C4: Capacity planning shall incorporate resilience against denial-of-service (DoS/DDoS) conditions. Capacity should not be planned solely for average or expected peak loads — headroom shall be maintained to absorb unexpected demand spikes, including those caused by malicious activity.
A5: A.8.6-43 | B5: Additional Mitigation Measures (Cdn, | C5: Where external-facing services are exposed to DDoS risk, additional mitigation measures (CDN, DDoS protection services, rate limiting) shall be implemented in coordination with the Network Security Policy (A.8.20–22).

Sheet Capacity Planning Committee
A1: Capacity Planning Committee — Compliance Checklist
A2: ISO/IEC 27001:2022 — Control A.8.6: Capacity Management
A3: Req # | B3: Section | C3: Requirement | D3: Status | E3: Evidence | F3: Owner | G3: Due Date | H3: Notes
A4: A.8.6-44 | B4: The Capacity Planning Committee | C4: The Capacity Planning Committee shall meet quarterly. The agenda shall include:.
A5: A.8.6-45 | B5: Meeting Minutes | C5: Meeting minutes shall be retained as evidence of governance (Evidence #10).
A6: A.8.6-46 | B6: The Quarterly Capacity Review Meeting | C6: Where the organisation is too small to justify a formal committee, the quarterly capacity review meeting between the Infrastructure Manager and CIO shall fulfil this governance function.
