Workbook

Sheet Executive Summary
A1: ISMS-OP-CHK-A.8.12 — Data Leakage Prevention Compliance Checklist
A3: DOCUMENT INFORMATION
A4: Document ID | B4: ISMS-OP-CHK-A.8.12
A5: Source Policy | B5: ISMS-OP-POL-A.8.12
A6: ISO Controls | B6: Data Leakage Prevention
A7: Generated | B7: 08.02.2026
A8: Prepared By
A9: Organisation
A10: Review Cycle | B10: Annual
A12: OVERALL COMPLIANCE STATUS
A13: Overall Compliance | B13: ='Dashboard'!G17
A14: Status | B14: =IF(Dashboard!G17="N/A","NOT ASSESSED",IF(ISNUMBER(VALUE(SUBSTITUTE(Dashboard!G17,"%",""))),IF(VALUE(SUBSTITUTE(Dashboard!G17,"%",""))>=90,"GREEN",IF(VALUE(SUBSTITUTE(Dashboard!G17,"%",""))>=70,"AMBER","RED")),"NOT ASSESSED"))
A16: KEY METRICS
A17: Total Requirements | B17: ='Dashboard'!B17
A18: Compliant | B18: ='Dashboard'!C17
A19: Partial | B19: ='Dashboard'!D17
A20: Non-Compliant | B20: ='Dashboard'!E17
A21: Not Applicable | B21: ='Dashboard'!F17
A22: Owner Coverage | B22: =IF(Dashboard!B17=0,"N/A",ROUND((COUNTA('Service Commitments & Customer'!F4:F5)+COUNTA('Data Classification Integration'!F4:F6)+COUNTA('Channel Protection'!F4:F16)+COUNTA('Third-Party DLP Service'!F4:F7)+COUNTA('Monitoring and Detection'!F4:F6)+COUNTA('DLP Incident Response'!F4:F7)+COUNTA('Employee Monitoring Legal Reqs'!F4:F13)+COUNTA('User Awareness & Acceptable Use'!F4:F5)+COUNTA('DLP Performance and Tuning'!F4:F5)+COUNTA('DLP System Avail & Perf Impact'!F4:F11)+COUNTA('DLP Effectiveness Testing'!F4:F4)+COUNTA('Mgmt Reporting and Oversight'!F4:F6)+COUNTA('Exception Management'!F4:F5))/Dashboard!B17*100,0)&"%")
A24: DOMAIN STATUS SUMMARY
A25: Domain | B25: Compliance % | C25: Compliant | D25: Gaps | E25: Status
A26: Service Commitments & Customer | B26: ='Dashboard'!G4 | C26: ='Dashboard'!C4 | D26: ='Dashboard'!E4 | E26: =IF(Dashboard!G4="N/A","--",IF(ISNUMBER(VALUE(SUBSTITUTE(Dashboard!G4,"%",""))),IF(VALUE(SUBSTITUTE(Dashboard!G4,"%",""))>=90,"PASS",IF(VALUE(SUBSTITUTE(Dashboard!G4,"%",""))>=70,"REVIEW","FAIL")),"--"))
A27: Data Classification Integration | B27: ='Dashboard'!G5 | C27: ='Dashboard'!C5 | D27: ='Dashboard'!E5 | E27: =IF(Dashboard!G5="N/A","--",IF(ISNUMBER(VALUE(SUBSTITUTE(Dashboard!G5,"%",""))),IF(VALUE(SUBSTITUTE(Dashboard!G5,"%",""))>=90,"PASS",IF(VALUE(SUBSTITUTE(Dashboard!G5,"%",""))>=70,"REVIEW","FAIL")),"--"))
A28: Channel Protection | B28: ='Dashboard'!G6 | C28: ='Dashboard'!C6 | D28: ='Dashboard'!E6 | E28: =IF(Dashboard!G6="N/A","--",IF(ISNUMBER(VALUE(SUBSTITUTE(Dashboard!G6,"%",""))),IF(VALUE(SUBSTITUTE(Dashboard!G6,"%",""))>=90,"PASS",IF(VALUE(SUBSTITUTE(Dashboard!G6,"%",""))>=70,"REVIEW","FAIL")),"--"))
A29: Third-Party DLP Service | B29: ='Dashboard'!G7 | C29: ='Dashboard'!C7 | D29: ='Dashboard'!E7 | E29: =IF(Dashboard!G7="N/A","--",IF(ISNUMBER(VALUE(SUBSTITUTE(Dashboard!G7,"%",""))),IF(VALUE(SUBSTITUTE(Dashboard!G7,"%",""))>=90,"PASS",IF(VALUE(SUBSTITUTE(Dashboard!G7,"%",""))>=70,"REVIEW","FAIL")),"--"))
A30: Monitoring and Detection | B30: ='Dashboard'!G8 | C30: ='Dashboard'!C8 | D30: ='Dashboard'!E8 | E30: =IF(Dashboard!G8="N/A","--",IF(ISNUMBER(VALUE(SUBSTITUTE(Dashboard!G8,"%",""))),IF(VALUE(SUBSTITUTE(Dashboard!G8,"%",""))>=90,"PASS",IF(VALUE(SUBSTITUTE(Dashboard!G8,"%",""))>=70,"REVIEW","FAIL")),"--"))
A31: DLP Incident Response | B31: ='Dashboard'!G9 | C31: ='Dashboard'!C9 | D31: ='Dashboard'!E9 | E31: =IF(Dashboard!G9="N/A","--",IF(ISNUMBER(VALUE(SUBSTITUTE(Dashboard!G9,"%",""))),IF(VALUE(SUBSTITUTE(Dashboard!G9,"%",""))>=90,"PASS",IF(VALUE(SUBSTITUTE(Dashboard!G9,"%",""))>=70,"REVIEW","FAIL")),"--"))
A32: Employee Monitoring Legal Reqs | B32: ='Dashboard'!G10 | C32: ='Dashboard'!C10 | D32: ='Dashboard'!E10 | E32: =IF(Dashboard!G10="N/A","--",IF(ISNUMBER(VALUE(SUBSTITUTE(Dashboard!G10,"%",""))),IF(VALUE(SUBSTITUTE(Dashboard!G10,"%",""))>=90,"PASS",IF(VALUE(SUBSTITUTE(Dashboard!G10,"%",""))>=70,"REVIEW","FAIL")),"--"))
A33: User Awareness & Acceptable Use | B33: ='Dashboard'!G11 | C33: ='Dashboard'!C11 | D33: ='Dashboard'!E11 | E33: =IF(Dashboard!G11="N/A","--",IF(ISNUMBER(VALUE(SUBSTITUTE(Dashboard!G11,"%",""))),IF(VALUE(SUBSTITUTE(Dashboard!G11,"%",""))>=90,"PASS",IF(VALUE(SUBSTITUTE(Dashboard!G11,"%",""))>=70,"REVIEW","FAIL")),"--"))
A34: DLP Performance and Tuning | B34: ='Dashboard'!G12 | C34: ='Dashboard'!C12 | D34: ='Dashboard'!E12 | E34: =IF(Dashboard!G12="N/A","--",IF(ISNUMBER(VALUE(SUBSTITUTE(Dashboard!G12,"%",""))),IF(VALUE(SUBSTITUTE(Dashboard!G12,"%",""))>=90,"PASS",IF(VALUE(SUBSTITUTE(Dashboard!G12,"%",""))>=70,"REVIEW","FAIL")),"--"))
A35: DLP System Avail & Perf Impact | B35: ='Dashboard'!G13 | C35: ='Dashboard'!C13 | D35: ='Dashboard'!E13 | E35: =IF(Dashboard!G13="N/A","--",IF(ISNUMBER(VALUE(SUBSTITUTE(Dashboard!G13,"%",""))),IF(VALUE(SUBSTITUTE(Dashboard!G13,"%",""))>=90,"PASS",IF(VALUE(SUBSTITUTE(Dashboard!G13,"%",""))>=70,"REVIEW","FAIL")),"--"))
A36: DLP Effectiveness Testing | B36: ='Dashboard'!G14 | C36: ='Dashboard'!C14 | D36: ='Dashboard'!E14 | E36: =IF(Dashboard!G14="N/A","--",IF(ISNUMBER(VALUE(SUBSTITUTE(Dashboard!G14,"%",""))),IF(VALUE(SUBSTITUTE(Dashboard!G14,"%",""))>=90,"PASS",IF(VALUE(SUBSTITUTE(Dashboard!G14,"%",""))>=70,"REVIEW","FAIL")),"--"))
A37: Mgmt Reporting and Oversight | B37: ='Dashboard'!G15 | C37: ='Dashboard'!C15 | D37: ='Dashboard'!E15 | E37: =IF(Dashboard!G15="N/A","--",IF(ISNUMBER(VALUE(SUBSTITUTE(Dashboard!G15,"%",""))),IF(VALUE(SUBSTITUTE(Dashboard!G15,"%",""))>=90,"PASS",IF(VALUE(SUBSTITUTE(Dashboard!G15,"%",""))>=70,"REVIEW","FAIL")),"--"))
A38: Exception Management | B38: ='Dashboard'!G16 | C38: ='Dashboard'!C16 | D38: ='Dashboard'!E16 | E38: =IF(Dashboard!G16="N/A","--",IF(ISNUMBER(VALUE(SUBSTITUTE(Dashboard!G16,"%",""))),IF(VALUE(SUBSTITUTE(Dashboard!G16,"%",""))>=90,"PASS",IF(VALUE(SUBSTITUTE(Dashboard!G16,"%",""))>=70,"REVIEW","FAIL")),"--"))
A40: CRITICAL ISSUES
A41: # | B41: Issue Description | C41: Domain | D41: Owner | E41: Due Date
A42: 1
A43: 2
A44: 3
A45: 4
...

Sheet Dashboard
A1: Data Leakage Prevention — Compliance Dashboard
A3: Domain | B3: Total Reqs | C3: Compliant | D3: Partial | E3: Non-Compliant | F3: N/A | G3: Compliance %
A4: Service Commitments & Customer | B4: =COUNTA('Service Commitments & Customer'!D4:D5) | C4: =COUNTIF('Service Commitments & Customer'!D4:D5,"Compliant") | D4: =COUNTIF('Service Commitments & Customer'!D4:D5,"Partial") | E4: =COUNTIF('Service Commitments & Customer'!D4:D5,"Non-Compliant") | F4: =COUNTIF('Service Commitments & Customer'!D4:D5,"N/A") | G4: =IF((B4-F4)=0,"N/A",ROUND(C4/(B4-F4)*100,1)&"%")
A5: Data Classification Integration | B5: =COUNTA('Data Classification Integration'!D4:D6) | C5: =COUNTIF('Data Classification Integration'!D4:D6,"Compliant") | D5: =COUNTIF('Data Classification Integration'!D4:D6,"Partial") | E5: =COUNTIF('Data Classification Integration'!D4:D6,"Non-Compliant") | F5: =COUNTIF('Data Classification Integration'!D4:D6,"N/A") | G5: =IF((B5-F5)=0,"N/A",ROUND(C5/(B5-F5)*100,1)&"%")
A6: Channel Protection | B6: =COUNTA('Channel Protection'!D4:D16) | C6: =COUNTIF('Channel Protection'!D4:D16,"Compliant") | D6: =COUNTIF('Channel Protection'!D4:D16,"Partial") | E6: =COUNTIF('Channel Protection'!D4:D16,"Non-Compliant") | F6: =COUNTIF('Channel Protection'!D4:D16,"N/A") | G6: =IF((B6-F6)=0,"N/A",ROUND(C6/(B6-F6)*100,1)&"%")
A7: Third-Party DLP Service | B7: =COUNTA('Third-Party DLP Service'!D4:D7) | C7: =COUNTIF('Third-Party DLP Service'!D4:D7,"Compliant") | D7: =COUNTIF('Third-Party DLP Service'!D4:D7,"Partial") | E7: =COUNTIF('Third-Party DLP Service'!D4:D7,"Non-Compliant") | F7: =COUNTIF('Third-Party DLP Service'!D4:D7,"N/A") | G7: =IF((B7-F7)=0,"N/A",ROUND(C7/(B7-F7)*100,1)&"%")
A8: Monitoring and Detection | B8: =COUNTA('Monitoring and Detection'!D4:D6) | C8: =COUNTIF('Monitoring and Detection'!D4:D6,"Compliant") | D8: =COUNTIF('Monitoring and Detection'!D4:D6,"Partial") | E8: =COUNTIF('Monitoring and Detection'!D4:D6,"Non-Compliant") | F8: =COUNTIF('Monitoring and Detection'!D4:D6,"N/A") | G8: =IF((B8-F8)=0,"N/A",ROUND(C8/(B8-F8)*100,1)&"%")
A9: DLP Incident Response | B9: =COUNTA('DLP Incident Response'!D4:D7) | C9: =COUNTIF('DLP Incident Response'!D4:D7,"Compliant") | D9: =COUNTIF('DLP Incident Response'!D4:D7,"Partial") | E9: =COUNTIF('DLP Incident Response'!D4:D7,"Non-Compliant") | F9: =COUNTIF('DLP Incident Response'!D4:D7,"N/A") | G9: =IF((B9-F9)=0,"N/A",ROUND(C9/(B9-F9)*100,1)&"%")
A10: Employee Monitoring Legal Reqs | B10: =COUNTA('Employee Monitoring Legal Reqs'!D4:D13) | C10: =COUNTIF('Employee Monitoring Legal Reqs'!D4:D13,"Compliant") | D10: =COUNTIF('Employee Monitoring Legal Reqs'!D4:D13,"Partial") | E10: =COUNTIF('Employee Monitoring Legal Reqs'!D4:D13,"Non-Compliant") | F10: =COUNTIF('Employee Monitoring Legal Reqs'!D4:D13,"N/A") | G10: =IF((B10-F10)=0,"N/A",ROUND(C10/(B10-F10)*100,1)&"%")
A11: User Awareness & Acceptable Use | B11: =COUNTA('User Awareness & Acceptable Use'!D4:D5) | C11: =COUNTIF('User Awareness & Acceptable Use'!D4:D5,"Compliant") | D11: =COUNTIF('User Awareness & Acceptable Use'!D4:D5,"Partial") | E11: =COUNTIF('User Awareness & Acceptable Use'!D4:D5,"Non-Compliant") | F11: =COUNTIF('User Awareness & Acceptable Use'!D4:D5,"N/A") | G11: =IF((B11-F11)=0,"N/A",ROUND(C11/(B11-F11)*100,1)&"%")
A12: DLP Performance and Tuning | B12: =COUNTA('DLP Performance and Tuning'!D4:D5) | C12: =COUNTIF('DLP Performance and Tuning'!D4:D5,"Compliant") | D12: =COUNTIF('DLP Performance and Tuning'!D4:D5,"Partial") | E12: =COUNTIF('DLP Performance and Tuning'!D4:D5,"Non-Compliant") | F12: =COUNTIF('DLP Performance and Tuning'!D4:D5,"N/A") | G12: =IF((B12-F12)=0,"N/A",ROUND(C12/(B12-F12)*100,1)&"%")
A13: DLP System Avail & Perf Impact | B13: =COUNTA('DLP System Avail & Perf Impact'!D4:D11) | C13: =COUNTIF('DLP System Avail & Perf Impact'!D4:D11,"Compliant") | D13: =COUNTIF('DLP System Avail & Perf Impact'!D4:D11,"Partial") | E13: =COUNTIF('DLP System Avail & Perf Impact'!D4:D11,"Non-Compliant") | F13: =COUNTIF('DLP System Avail & Perf Impact'!D4:D11,"N/A") | G13: =IF((B13-F13)=0,"N/A",ROUND(C13/(B13-F13)*100,1)&"%")
A14: DLP Effectiveness Testing | B14: =COUNTA('DLP Effectiveness Testing'!D4:D4) | C14: =COUNTIF('DLP Effectiveness Testing'!D4:D4,"Compliant") | D14: =COUNTIF('DLP Effectiveness Testing'!D4:D4,"Partial") | E14: =COUNTIF('DLP Effectiveness Testing'!D4:D4,"Non-Compliant") | F14: =COUNTIF('DLP Effectiveness Testing'!D4:D4,"N/A") | G14: =IF((B14-F14)=0,"N/A",ROUND(C14/(B14-F14)*100,1)&"%")
A15: Mgmt Reporting and Oversight | B15: =COUNTA('Mgmt Reporting and Oversight'!D4:D6) | C15: =COUNTIF('Mgmt Reporting and Oversight'!D4:D6,"Compliant") | D15: =COUNTIF('Mgmt Reporting and Oversight'!D4:D6,"Partial") | E15: =COUNTIF('Mgmt Reporting and Oversight'!D4:D6,"Non-Compliant") | F15: =COUNTIF('Mgmt Reporting and Oversight'!D4:D6,"N/A") | G15: =IF((B15-F15)=0,"N/A",ROUND(C15/(B15-F15)*100,1)&"%")
A16: Exception Management | B16: =COUNTA('Exception Management'!D4:D5) | C16: =COUNTIF('Exception Management'!D4:D5,"Compliant") | D16: =COUNTIF('Exception Management'!D4:D5,"Partial") | E16: =COUNTIF('Exception Management'!D4:D5,"Non-Compliant") | F16: =COUNTIF('Exception Management'!D4:D5,"N/A") | G16: =IF((B16-F16)=0,"N/A",ROUND(C16/(B16-F16)*100,1)&"%")
A17: TOTAL | B17: =SUM(B4:B16) | C17: =SUM(C4:C16) | D17: =SUM(D4:D16) | E17: =SUM(E4:E16) | F17: =SUM(F4:F16) | G17: =IF((B17-F17)=0,"N/A",ROUND(C17/(B17-F17)*100,1)&"%")
A19: COMPLIANCE BY STATUS
A20: Compliant | B20: =C17 | C20: =IF(B17=0,"",ROUND(B20/B17*100,1)&"%")
A21: Partial | B21: =D17 | C21: =IF(B17=0,"",ROUND(B21/B17*100,1)&"%")
A22: Non-Compliant | B22: =E17 | C22: =IF(B17=0,"",ROUND(B22/B17*100,1)&"%")
A23: N/A | B23: =F17 | C23: =IF(B17=0,"",ROUND(B23/B17*100,1)&"%")
A25: TOP GAPS (Manual Entry)
A26: Priority | B26: Domain | C26: Requirement | D26: Owner | E26: Due Date | F26: Status
A38: COMPLIANCE TREND (Manual Entry)
A39: Assessment Date | B39: Overall % | C39: Compliant | D39: Gaps | E39: Assessor | F39: Notes

Sheet Service Commitments & Customer
A1: Service Commitments & Customer — Compliance Checklist
A2: ISO/IEC 27001:2022 — Control A.8.12: Data Leakage Prevention
A3: Req # | B3: Section | C3: Requirement | D3: Status | E3: Evidence | F3: Owner | G3: Due Date | H3: Notes
A4: A.8.12-01 | B4: Customer Data Processed By The | C4: Customer data processed by the organisation shall receive DLP protection commensurate with contractual commitments:.
A5: A.8.12-02 | B5: Customer-Specific Requirements*: Where | C5: Customer-specific requirements*: Where customers have negotiated custom notification timelines, incident severity thresholds, or reporting requirements, these shall be documented in the customer contract register and integrated into DLP alert routing and incident response workflows.

Sheet Data Classification Integration
A1: Data Classification Integration — Compliance Checklist
A2: ISO/IEC 27001:2022 — Control A.8.12: Data Leakage Prevention
A3: Req # | B3: Section | C3: Requirement | D3: Status | E3: Evidence | F3: Owner | G3: Due Date | H3: Notes
A4: A.8.12-03 | B4: Dlp Controls | C4: DLP controls shall be applied based on the organisation's data classification scheme. Classification determines the enforcement mode, channel coverage, and response priority for each data category.
A5: A.8.12-04 | B5: Implement Multiple Identification | C5: The organisation shall implement multiple identification methods to detect sensitive information in transit:.
A6: A.8.12-05 | B6: Maintain An Inventory Of Sensitive Data | C6: The organisation shall maintain an inventory of sensitive data requiring DLP protection, reconciled quarterly against the asset inventory (A.5.9). Specific detection patterns, regex rules, and classification labels shall be documented and maintained by the Security Team.

Sheet Channel Protection
A1: Channel Protection — Compliance Checklist
A2: ISO/IEC 27001:2022 — Control A.8.12: Data Leakage Prevention
A3: Req # | B3: Section | C3: Requirement | D3: Status | E3: Evidence | F3: Owner | G3: Due Date | H3: Notes
A4: A.8.12-06 | B4: Implement Dlp Controls Across All Data | C4: The organisation shall implement DLP controls across all data egress channels to prevent unauthorised information disclosure. Channel coverage shall be verified through technical testing at least quarterly.
A5: A.8.12-07 | B5: Outbound Email (Smtp And Webmail) | C5: All outbound email (SMTP and webmail) shall be subject to DLP content inspection:.
A6: A.8.12-08 | B6: Web-Based Data Egress Channels | C6: Web-based data egress channels shall be monitored and controlled:.
A7: A.8.12-09 | B7: Web Uploads: Monitor And Control File | C7: Web uploads: Monitor and control file uploads to cloud storage services (e.g., Dropbox, Google Drive, personal OneDrive accounts). Approved corporate cloud storage [Cloud Storage Platform] shall be distinguished from personal or unapproved services.
A8: A.8.12-10 | B8: Tls Inspection: Where Legally | C8: TLS inspection: Where legally permissible and technically feasible, inspect encrypted web traffic at the internet gateway to detect sensitive content in HTTPS uploads. TLS inspection shall comply with privacy requirements and be documented in the organisation's privacy notice.
A9: A.8.12-11 | B9: Endpoint Dlp Controls | C9: Endpoint DLP controls shall be deployed on all managed devices:.
A10: A.8.12-12 | B10: Removable Media: Monitor And Control | C10: Removable media: Monitor and control file transfers to USB drives, external hard drives, SD cards, and other removable storage. Block unauthorised removable media usage for Restricted and Confidential data. Approved removable media (e.g., encrypted corporate USB devices) shall be documented.
A11: A.8.12-13 | B11: Printing: Monitor Print Jobs For | C11: Printing: Monitor print jobs for Restricted data. Print-to-PDF and virtual printer activity shall be included in monitoring scope.
A12: A.8.12-14 | B12: Screenshots And Clipboard (Risk-Based): | C12: Screenshots and clipboard (risk-based): Where the risk assessment justifies it, monitor screen capture tools and clipboard operations for Restricted data. This control shall be applied only to specific high-risk roles or data sets, not organisation-wide.
A13: A.8.12-15 | B13: Offline Enforcement: Endpoint Dlp Agents | C13: Offline enforcement: Endpoint DLP agents shall enforce policies when the device is disconnected from the corporate network.
A14: A.8.12-16 | B14: Network-Level Dlp Controls | C14: Network-level DLP controls shall monitor data flows at egress points:.
A15: A.8.12-17 | B15: Corporate Data On Mobile Devices | C15: Corporate data on mobile devices shall be protected:.
A16: A.8.12-18 | B16: Verify Dlp Channel Coverage Through | C16: The organisation shall verify DLP channel coverage through technical testing at least quarterly. Coverage gaps shall be documented with:.

Sheet Third-Party DLP Service
A1: Third-Party DLP Service — Compliance Checklist
A2: ISO/IEC 27001:2022 — Control A.8.12: Data Leakage Prevention
A3: Req # | B3: Section | C3: Requirement | D3: Status | E3: Evidence | F3: Owner | G3: Due Date | H3: Notes
A4: A.8.12-19 | B4: Dlp Service Providers | C4: DLP service providers shall be evaluated against:.
A5: A.8.12-20 | B5: Cloud Dlp Vendor Contracts | C5: Cloud DLP vendor contracts shall include:.
A6: A.8.12-21 | B6: Cloud Dlp Vendors | C6: Cloud DLP vendors shall receive an annual review covering:.
A7: A.8.12-22 | B7: Immediate Notification: Vendor | C7: Immediate notification: Vendor shall notify organisation within 24 hours (per contract).

Sheet Monitoring and Detection
A1: Monitoring and Detection — Compliance Checklist
A2: ISO/IEC 27001:2022 — Control A.8.12: Data Leakage Prevention
A3: Req # | B3: Section | C3: Requirement | D3: Status | E3: Evidence | F3: Owner | G3: Due Date | H3: Notes
A4: A.8.12-23 | B4: Implement Continuous Monitoring To | C4: The organisation shall implement continuous monitoring to detect data leakage attempts and policy violations.
A5: A.8.12-24 | B5: Dlp Events | C5: All DLP events shall be logged with the following information:.
A6: A.8.12-25 | B6: Behavioural Analytics* (Recommended): | C6: Behavioural Analytics* (recommended): Where the organisation deploys user and entity behaviour analytics (UEBA), DLP data shall be correlated with baseline user activity to detect anomalous transfer patterns (e.g., unusual volume, unusual destination, unusual time). Behavioural analytics shall comply with the employee monitoring legal requirements defined in this policy.

Sheet DLP Incident Response
A1: DLP Incident Response — Compliance Checklist
A2: ISO/IEC 27001:2022 — Control A.8.12: Data Leakage Prevention
A3: Req # | B3: Section | C3: Requirement | D3: Status | E3: Evidence | F3: Owner | G3: Due Date | H3: Notes
A4: A.8.12-26 | B4: Dlp Security Incidents | C4: DLP security incidents shall follow the organisation's incident management process (A.5.24-28) with the following DLP-specific requirements.
A5: A.8.12-27 | B5: The Organisation | C5: Where DLP incidents constitute personal data breaches, the organisation shall follow notification requirements:.
A6: A.8.12-28 | B6: The Data Protection Officer (Dpo) Or | C6: The Data Protection Officer (DPO) or designated privacy lead shall be consulted for all DLP incidents involving personal data to determine breach notification obligations.
A7: A.8.12-29 | B7: Dlp-To-Incident-Management Integration*: | C7: DLP-to-Incident-Management Integration*: Critical and High severity DLP events shall automatically create incident tickets in [ITSM Platform] (e.g., ServiceNow, Jira Service Management, or equivalent). Tickets not acknowledged within the response SLA shall auto-escalate per incident management procedures.

Sheet Employee Monitoring Legal Reqs
A1: Employee Monitoring Legal Reqs — Compliance Checklist
A2: ISO/IEC 27001:2022 — Control A.8.12: Data Leakage Prevention
A3: Req # | B3: Section | C3: Requirement | D3: Status | E3: Evidence | F3: Owner | G3: Due Date | H3: Notes
A4: A.8.12-30 | B4: Dlp Monitoring Constitutes A Form Of | C4: DLP monitoring constitutes a form of employee monitoring under Swiss law. The organisation shall comply with the following legal requirements before deploying and operating DLP controls.
A5: A.8.12-31 | B5: Art. 26 Argv 3 (Ordinance 3 | C5: Art. 26 ArGV 3 (Ordinance 3 to the Employment Act)*: Monitoring and surveillance systems shall not be used if their sole or primary purpose is to monitor employee behaviour. DLP systems are permissible because their primary purpose is protecting organisational data from unauthorised disclosure — not monitoring individual employee conduct. However, DLP implementation must demonstrably serve a data protection objective, and any incidental monitoring of employee behaviour must be proportionate.
A6: A.8.12-32 | B6: Art. 328B Co (Swiss Code Of | C6: Art. 328b CO (Swiss Code of Obligations)*: The employer may process data concerning employees only insofar as it relates to the employee's suitability for the employment relationship or is necessary for the performance of the employment contract. DLP monitoring data shall be processed only for information security purposes. DLP data shall not be used for:.
A7: A.8.12-33 | B7: Proportionality: Monitoring Scope | C7: Proportionality: Monitoring scope shall be limited to what is necessary for data protection. The organisation shall not monitor more broadly than required.
A8: A.8.12-34 | B8: Purpose Limitation: Data Collected | C8: Purpose limitation: Data collected through DLP shall be used only for security purposes, not repurposed for other objectives.
A9: A.8.12-35 | B9: Transparency: Employees | C9: Transparency: Employees shall be informed about DLP monitoring before it is activated.
A10: A.8.12-36 | B10: Conduct A Proportionality Assessment | C10: The organisation shall conduct a proportionality assessment before deploying DLP controls. The assessment shall verify that:.
A11: A.8.12-37 | B11: Inform All Employees About Dlp | C11: The organisation shall inform all employees about DLP monitoring through:.
A12: A.8.12-38 | B12: Works Council Consultation (Where | C12: Works council consultation (where applicable): In jurisdictions requiring co-determination, the works council shall be consulted before deploying DLP monitoring.
A13: A.8.12-39 | B13: Critical*: Failure To Provide | C13: Critical*: Failure to provide transparency may render DLP monitoring unlawful. DLP monitoring shall not be activated until employee notification has been completed and documented. The organisation shall retain evidence of employee notification (signed acknowledgments, training completion records, privacy notice distribution records).

Sheet User Awareness & Acceptable Use
A1: User Awareness & Acceptable Use — Compliance Checklist
A2: ISO/IEC 27001:2022 — Control A.8.12: Data Leakage Prevention
A3: Req # | B3: Section | C3: Requirement | D3: Status | E3: Evidence | F3: Owner | G3: Due Date | H3: Notes
A4: A.8.12-40 | B4: Be Informed Of Dlp Controls And | C4: All personnel shall be informed of DLP controls and their responsibilities.
A5: A.8.12-41 | B5: Violations Of Dlp Policy | C5: Violations of DLP policy shall be subject to disciplinary action in accordance with HR policy. Deliberate or repeated attempts to circumvent DLP controls may result in termination of employment.

Sheet DLP Performance and Tuning
A1: DLP Performance and Tuning — Compliance Checklist
A2: ISO/IEC 27001:2022 — Control A.8.12: Data Leakage Prevention
A3: Req # | B3: Section | C3: Requirement | D3: Status | E3: Evidence | F3: Owner | G3: Due Date | H3: Notes
A4: A.8.12-42 | B4: Track Dlp Effectiveness Through Key | C4: The organisation shall track DLP effectiveness through key performance indicators and continuously tune DLP rules to reduce false positives while maintaining detection coverage.
A5: A.8.12-43 | B5: Below-Target Response*: If Metrics Fall | C5: Below-Target Response*: If metrics fall below the acceptable range for two consecutive measurement periods, the CISO shall conduct a root cause analysis within 30 days, implement a corrective action plan, and report remediation status to Executive Management.

Sheet DLP System Avail & Perf Impact
A1: DLP System Avail & Perf Impact — Compliance Checklist
A2: ISO/IEC 27001:2022 — Control A.8.12: Data Leakage Prevention
A3: Req # | B3: Section | C3: Requirement | D3: Status | E3: Evidence | F3: Owner | G3: Due Date | H3: Notes
A4: A.8.12-44 | B4: Dlp Systems | C4: DLP systems shall be configured with explicit fail-safe behaviour to prevent service disruption:.
A5: A.8.12-45 | B5: Dlp System Performance | C5: DLP system performance shall be monitored to prevent service degradation:.
A6: A.8.12-46 | B6: Dlp Systems | C6: DLP systems shall be sized to handle peak traffic with 30% headroom.
A7: A.8.12-47 | B7: Annual Capacity Review | C7: Annual capacity review shall project growth and identify scaling needs.
A8: A.8.12-48 | B8: Customer Notification*: If Dlp | C8: Customer notification*: If DLP containment actions impact customer-facing services, customers shall be notified per the incident communication procedures (typically within 1 hour for customer-impacting incidents).
A9: A.8.12-49 | B9: Dlp Controls | C9: DLP controls shall support the organisation's business continuity and disaster recovery objectives:.
A10: A.8.12-50 | B10: Dlp Systems | C10: DLP systems shall be included in disaster recovery planning with defined recovery priorities:.
A11: A.8.12-51 | B11: Dlp Systems | C11: DLP systems shall be included in annual disaster recovery testing:.

Sheet DLP Effectiveness Testing
A1: DLP Effectiveness Testing — Compliance Checklist
A2: ISO/IEC 27001:2022 — Control A.8.12: Data Leakage Prevention
A3: Req # | B3: Section | C3: Requirement | D3: Status | E3: Evidence | F3: Owner | G3: Due Date | H3: Notes
A4: A.8.12-52 | B4: Conduct Structured Testing To Validate | C4: The organisation shall conduct structured testing to validate that DLP controls detect and prevent unauthorised data disclosure as designed.

Sheet Mgmt Reporting and Oversight
A1: Mgmt Reporting and Oversight — Compliance Checklist
A2: ISO/IEC 27001:2022 — Control A.8.12: Data Leakage Prevention
A3: Req # | B3: Section | C3: Requirement | D3: Status | E3: Evidence | F3: Owner | G3: Due Date | H3: Notes
A4: A.8.12-53 | B4: Dlp Programme Effectiveness And | C4: DLP programme effectiveness and compliance shall be reported to executive management to demonstrate governance and oversight.
A5: A.8.12-54 | B5: The Ciso | C5: The CISO shall provide a quarterly DLP programme summary to executive management covering:.
A6: A.8.12-55 | B6: As Part Of The Iso 27001 | C6: As part of the ISO 27001 Management Review (Clause 9.3), the CISO shall present an annual DLP programme review covering:.

Sheet Exception Management
A1: Exception Management — Compliance Checklist
A2: ISO/IEC 27001:2022 — Control A.8.12: Data Leakage Prevention
A3: Req # | B3: Section | C3: Requirement | D3: Status | E3: Evidence | F3: Owner | G3: Due Date | H3: Notes
A4: A.8.12-56 | B4: Exceptions To Dlp Policy Requirements | C4: Exceptions to DLP policy requirements shall be requested in writing and shall include:.
A5: A.8.12-57 | B5: Active Exceptions | C5: All active exceptions shall be recorded in the DLP Exception Register (format: DLP-EX-YYYY-NNN), reviewed at least quarterly, and revoked when the business justification no longer applies or the risk profile changes.
