Workbook

Sheet Instructions & Legend
A1: ISMS-IMP-A.8.16.1 - Monitoring Infrastructure Assessment ISO/IEC 27001:2022 - Control A.8.16: Monitoring Activities
A3: Document Information
A4: Document ID | B4: ISMS-IMP-A.8.16.1
A5: Workbook Title | B5: Monitoring Infrastructure Assessment
A6: Control Reference | B6: ISO/IEC 27001:2022 - Control A.8.16: Monitoring Activities
A7: Version | B7: 1.0
A8: Assessment Date
A9: Completed By
A10: Organisation
A12: Instructions
A13: 1. Complete each worksheet tab in sequence (1–5).
A14: 2. Use dropdown menus where provided — do not type directly.
A15: 3. Fill all yellow-highlighted cells with your organisation’s information.
A16: 4. Refer to reference tables on each sheet for guidance.
A17: 5. Complete compliance checklists on each assessment sheet.
A18: 6. Document exceptions in the Exception/Deviation blocks.
A19: 7. Gather evidence and list in Evidence Register.
A20: 8. Review Summary Dashboard for compliance gaps.
... A23: Status Legend
A24: Symbol | B24: Status | C24: Description
A25: ✓ | B25: Compliant / Complete | C25: Requirement fully met
A26: ⚠ | B26: Partial / In Progress | C26: Partially met or in progress
A27: ✗ | B27: Non-Compliant / Not Started | C27: Requirement not met
A28: — | B28: Not Applicable | C28: Not applicable to this assessment

Sheet 1. Monitoring Platform
A1: 1. MONITORING PLATFORM CAPABILITIES ASSESSMENT
A2: Policy Reference: ISMS-POL-A.8.16-S2.1.4 - Assess SIEM/monitoring platform capabilities
A3: Does your organisation have monitoring platforms (SIEM, IDS/IPS, EDR, NDR) with adequate capabilities?
A4: Overall Status:
A6: Platform/Tool Name | B6: Platform Type | C6: Vendor/Solution | D6: Deployment Model | E6: Log Collection Methods | F6: Parsing Capabilities | G6: Storage & Indexing | H6: Search Performance | I6: Real-Time Alerting | J6: Correlation Engine | K6: Threat Intel Integration | L6: SOAR Integration | M6: Visualization/Dashboards | N6: High Availability | O6: Disaster Recovery | P6: Current EPS Capacity | Q6: Implementation Status | R6: Last Upgrade Date | S6: Compliance Status | T6: Gaps/Issues | U6: Remediation Priority
A7: Splunk Enterprise | B7: SIEM | C7: Splunk Inc. | D7: Cloud | E7: Agents, Syslog, API | F7: Excellent | G7: Hot/Warm/Cold Tiers | H7: <10 sec | I7: Yes | J7: Advanced | K7: Yes | L7: Yes | M7: Excellent | N7: Yes | O7: Documented | P7: 50'000 EPS | Q7: ✅ Deployed | R7: 15.03.2024 | S7: ✅ Compliant | T7: None | U7: None
A22: MONITORING PLATFORM CAPABILITIES CHECKLIST
A23: # | B23: Requirement
A24: 1 | B24: Primary monitoring platform (SIEM) deployed
A25: 2 | B25: Log collection supports multiple methods (agents, syslog, API)
A26: 3 | B26: Parsing capabilities for common log formats (Windows, Linux, network devices)
A27: 4 | B27: Storage includes hot/warm/cold tiers for cost optimization
A28: 5 | B28: Search performance meets requirements (<10 sec for typical queries)
A29: 6 | B29: Real-time alerting capability enabled
A30: 7 | B30: Correlation engine supports multi-event detection
A31: 8 | B31: Threat intelligence integration implemented
A32: 9 | B32: SOAR or ticketing integration functional
A33: 10 | B33: Dashboards configured for SOC operations
A34: 11 | B34: High availability architecture implemented
A35: 12 | B35: Disaster recovery plan documented and tested
... A38: 15 | B38: Platform security hardened (RBAC, MFA, encryption)
A39: SCORE: | B39: =COUNTIF(U:U,"✅ Compliant")&" / 15"
A40: REFERENCE TABLES
A42: Table 1: Monitoring Platform Types
A43: Platform Type | H43: Primary Purpose | O43: Example Capabilities
A44: SIEM | H44: Centralised log aggregation & correlation | O44: Search, alert, correlate, dashboards
A45: IDS/IPS | H45: Network intrusion detection | O45: Signature matching, anomaly detection
A46: EDR | H46: Endpoint threat detection | O46: Process monitoring, behavioural analysis
A47: NDR | H47: Network traffic analysis | O47: Flow analysis, encrypted traffic analysis
A48: UEBA | H48: User behaviour analytics | O48: Baseline deviation, risk scoring
A51: Table 2: Critical SIEM Capabilities (Per S2.1.4.1)
A52: Capability | H52: Requirement Level | O52: Validation Method
A53: Multi-format log parsing | H53: MUST HAVE | O53: Test with sample logs
A54: Indexed storage | H54: MUST HAVE | O54: Verify search performance
A55: Real-time alerting | H55: MUST HAVE | O55: Test alert generation
A56: Multi-event correlation | H56: MUST HAVE | O56: Create test correlation rule
A57: Threat intel integration | H57: MUST HAVE | O57: Verify IOC matching
A58: Search < 10 sec | H58: SHOULD HAVE | O58: Benchmark queries
A70: EXCEPTION/DEVIATION MANAGEMENT
A71: Exception ID | B71: Risk ID | C71: Business Justification | D71: Compensating Controls | E71: Approval Status | F71: Review Date

Sheet 2. Log Source Coverage
A1: 2. LOG SOURCE COVERAGE ASSESSMENT
A2: Policy Reference: ISMS-POL-A.8.16-S2.1.2 - Assess log source coverage
A3: Does your organisation collect logs from all critical systems and adequate coverage of standard systems?
A4: Overall Coverage Status:
A6: System/Asset Name | B6: System Type | C6: Criticality | D6: Location | E6: System Owner | F6: OS/Platform | G6: Log Types Collected | H6: Collection Method | I6: Collection Protocol | J6: Log Volume (GB/day) | K6: Retention Period (days) | L6: Parsing Status | M6: Integration with SIEM | N6: Collection Status | O6: Last Verified | P6: Reliability | Q6: Compliance Status | R6: Gaps/Issues | S6: Remediation Plan | T6: Priority
A7: DC01-WinServer | B7: Server | C7: Critical | D7: Primary DC | E7: IT Operations | F7: Windows Server 2022 | G7: Security, System, Application | H7: Agent | I7: HTTPS | J7: 2.5 | K7: 365 | L7: Parsed | M7: Yes | N7: ✅ Collecting | O7: 15.12.2024 | P7: High | Q7: ✅ Compliant | R7: None | S7: N/A | T7: None
A43: LOG SOURCE COVERAGE STATISTICS
A44: Metric | F44: Count/Value | K44: Target | P44: Status
A45: Total Systems Inventoried | F45: =COUNTA(A8:A40) | K45: N/A
A46: Critical Systems with Logs | F46: =COUNTIFS(C8:C40,"Critical",N8:N40,"✅ Collecting") | K46: 100%
A47: High Priority Systems with Logs | F47: =COUNTIFS(C8:C40,"High",N8:N40,"✅ Collecting") | K47: >90%
A48: Total Log Volume (GB/day) | F48: =SUM(J8:J40) | K48: Monitor
A49: Systems with Compliance Gaps | F49: =COUNTIFS(Q8:Q40,"❌ Non-Compliant")+COUNTIFS(Q8:Q40,"⚠️ Partial") | K49: 0
A50: Collection Reliability High | F50: =COUNTIF(P8:P40,"High") | K50: Target
A51: Collection Reliability Low | F51: =COUNTIF(P8:P40,"Low") | K51: 0
A53: LOG SOURCE COVERAGE CHECKLIST
A54: # | B54: Requirement
A55: 1 | B55: All critical systems (servers, databases) generating logs
A56: 2 | B56: All network devices (firewalls, routers, switches) generating logs
A57: 3 | B57: All security appliances (IDS/IPS, proxies) generating logs
A58: 4 | B58: Authentication systems (AD, LDAP, SSO) generating logs
A59: 5 | B59: Cloud services generating logs (AWS, Azure, O365)
A60: 6 | B60: Critical applications generating logs
A61: 7 | B61: Endpoints (workstations, laptops) generating logs where required
A62: 8 | B62: Log collection methods reliable (agents, syslog, API)
A63: 9 | B63: Log volume monitored and within capacity
A64: 10 | B64: Log retention periods meet policy requirements (min 90 days for critical)
A65: 11 | B65: Parsing configured for all critical log sources
A66: 12 | B66: SIEM integration functional for all critical sources
... A69: 15 | B69: Coverage assessed quarterly
A70: SCORE: | B70: =COUNTIF(T55:T69,"✅ Compliant")&" / 15"
A75: REFERENCE: CRITICAL SYSTEM TYPES REQUIRING LOG COLLECTION
A76: System Type | H76: Required Log Types | O76: Minimum Retention
A77: Domain Controllers | H77: Security, System, Directory Service | O77: 365 days
A78: Database Servers | H78: Audit, Error, Query logs | O78: 365 days
A79: Web Servers | H79: Access, Error, Security | O79: 180 days
A80: Firewalls | H80: Traffic, Deny, Alert | O80: 365 days
A81: VPN Gateways | H81: Authentication, Connection, Error | O81: 180 days
A82: Email Servers | H82: Message tracking, Security | O82: 180 days
A83: Cloud Services (AWS/Azure/O365) | H83: Activity, Security, Configuration | O83: 365 days

Sheet 3. Data Collection Arch
A1: 3. DATA COLLECTION ARCHITECTURE ASSESSMENT
A2: Policy Reference: ISMS-POL-A.8.16-S2.1.3 - Assess data collection architecture
A3: Is your log collection architecture reliable, secure, and scalable?
A6: Collection Component | B6: Component Type | C6: Purpose/Function | D6: Protocol Used | E6: Encryption Status | F6: Authentication Method | G6: Throughput Capacity | H6: Current Utilization % | I6: Buffer/Queue Size | J6: Failover Configured | K6: Load Balancing | L6: Monitoring Enabled | M6: Health Check Interval | N6: Last Maintenance | O6: Implementation Status | P6: Compliance Status | Q6: Issues/Gaps | R6: Priority
A7: Syslog Forwarder Cluster | B7: Log Forwarder | C7: Central syslog collection | D7: Syslog TLS | E7: TLS 1.3 | F7: Certificate-based | G7: 100K EPS | H7: 65% | I7: 10GB | J7: Yes | K7: Yes | L7: Yes | M7: 60 seconds | N7: 10.12.2024 | O7: ✅ Deployed | P7: ✅ Compliant | Q7: None | R7: None
A59: DATA COLLECTION ARCHITECTURE CHECKLIST
A60: # | B60: Requirement
A61: 1 | B61: Log collection uses encrypted protocols (TLS/HTTPS)
A62: 2 | B62: Authentication required for log submission
A63: 3 | B63: Collection components have adequate throughput capacity
A64: 4 | B64: Buffering/queuing configured to prevent log loss
A65: 5 | B65: Failover mechanisms implemented for critical components
A66: 6 | B66: Load balancing configured where applicable
A67: 7 | B67: Collection infrastructure monitored (health, performance)
A68: 8 | B68: Alerts configured for collection failures
A69: 9 | B69: Collection reliability >99% for critical systems
A70: 10 | B70: Time synchronization (NTP) configured across infrastructure
A71: 11 | B71: Log integrity mechanisms in place (checksums, signatures)
A72: 12 | B72: Collection infrastructure documented (architecture diagrams)
... A75: 15 | B75: Access to collection infrastructure restricted (RBAC)
A76: SCORE: | B76: =COUNTIF(R61:R75,"✅ Compliant")&" / 15"
A77: REFERENCE: COLLECTION PROTOCOL SECURITY LEVELS
A78: Protocol | F78: Security Level | J78: Use Case | O78: Recommendations
A79: Syslog TLS (TCP 6514) | F79: High | J79: Secure syslog | O79: Recommended for all external collection
A80: HTTPS/API | F80: High | J80: Cloud services, REST APIs | O80: Use for cloud and API integrations
A81: Agent-based (HTTPS) | F81: High | J81: Endpoint/server collection | O81: Preferred for servers and endpoints
A82: Syslog TCP (TCP 514) | F82: Medium | J82: Legacy devices | O82: Use only when TLS unavailable
A83: Syslog UDP (UDP 514) | F83: Low | J83: Legacy, low-priority | O83: Avoid for critical systems
A84: SNMP v3 | F84: Medium | J84: Network device monitoring | O84: Acceptable for network devices
A85: NetFlow | F85: Medium | J85: Network traffic metadata | O85: Supplementary to syslog

Sheet 4. Integration Enrichment
A1: 4. INTEGRATION & ENRICHMENT ASSESSMENT
A2: Policy Reference: ISMS-POL-A.8.16-S2.1.5 - Assess integration and data enrichment
A3: Are monitoring systems properly integrated with threat intelligence, asset inventory, and other context sources?
A6: Integration/Enrichment Name | B6: Integration Type | C6: Data Source | D6: Enrichment Type | E6: Integration Method | F6: Update Frequency | G6: Data Quality | H6: Coverage % | I6: Latency | J6: Reliability | K6: Last Updated | L6: Implementation Status | M6: Compliance Status | N6: Value/Impact | O6: Issues/Gaps | P6: Priority
A7: MISP Threat Feed | B7: Real-time | C7: MISP Community | D7: Threat Intel | E7: API | F7: Hourly | G7: Excellent | H7: 95% | I7: <1 min | J7: High | K7: 07.01.2025 | L7: ✅ Deployed | M7: ✅ Compliant | N7: IOC matching for alerts | O7: None | P7: High
A59: INTEGRATION & ENRICHMENT CHECKLIST
A60: # | B60: Requirement
A61: 1 | B61: Threat intelligence feed(s) integrated into SIEM
A62: 2 | B62: Threat intelligence updated at least daily
A63: 3 | B63: GeoIP enrichment configured for IP addresses
A64: 4 | B64: Asset inventory integrated (hostname, owner, criticality)
A65: 5 | B65: User context enrichment (AD/LDAP integration)
A66: 6 | B66: DNS enrichment for domain resolution
A67: 7 | B67: CMDB integration for asset context
A68: 8 | B68: Vulnerability data integrated (scanner results)
A69: 9 | B69: Ticketing system integration (ServiceNow, JIRA)
A70: 10 | B70: SOAR platform integration for automated response
A71: 11 | B71: Cloud provider APIs integrated (AWS, Azure, GCP)
A72: 12 | B72: Enrichment latency acceptable (<5 minutes)
... A75: 15 | B75: Integration documentation maintained
A76: SCORE: | B76: =COUNTIF(P61:P75,"✅ Compliant")&" / 15"
A77: REFERENCE: COMMON ENRICHMENT SOURCES
A78: Enrichment Type | F78: Example Sources | L78: Benefit to Monitoring
A79: Threat Intelligence | F79: MISP, AlienVault OTX, VirusTotal, Abuse.ch | L79: IOC detection, malicious IP/domain identification
A80: GeoIP | F80: MaxMind, IP2Location | L80: Geo-based anomaly detection, compliance
A81: Asset Context | F81: CMDB, ServiceNow, Lansweeper | L81: Criticality assessment, owner identification
A82: User Context | F82: Active Directory, Okta, Microsoft Entra ID (formerly Azure AD) | L82: User behaviour analysis, privilege context
A83: Vulnerability Data | F83: Qualys, Tenable, Rapid7 | L83: Risk scoring, exploit correlation
A84: DNS | F84: Internal DNS, passive DNS | L84: Domain reputation, DGA detection

Sheet 5. Performance Scale
A1: 5. PERFORMANCE & SCALABILITY ASSESSMENT
A2: Policy Reference: ISMS-POL-A.8.16-S2.1.6 - Assess monitoring performance and scalability
A3: Is the monitoring infrastructure performing adequately and scalable for future growth?
A5: CURRENT PERFORMANCE METRICS
A6: Metric | B6: Current Value | C6: Unit | D6: Target/Threshold | E6: Status | F6: Trend | G6: Last Measured | H6: Notes
A7: SIEM Ingestion Rate (Current) | C7: EPS | D7: N/A
A8: SIEM Ingestion Rate (Peak) | C8: EPS | D8: N/A
A9: SIEM Licensed Capacity | C9: EPS | D9: N/A
A10: Capacity Utilization | C10: % | D10: <80%
A11: Average Search Response Time | C11: seconds | D11: <10 sec
A12: Indexing Lag | C12: minutes | D12: <5 min
A13: Storage Utilization | C13: % | D13: <80%
A14: Hot Tier Storage Available | C14: TB | D14: >20%
A15: Daily Log Volume | C15: GB/day | D15: N/A
A16: Data Retention Compliance | C16: days | D16: >=90
A17: SIEM Availability (Last 30d) | C17: % | D17: >99.5%
A18: Alert Generation Latency | C18: seconds | D18: <60 sec
... A21: API Response Time | C21: milliseconds | D21: <500 ms
A24: SCALABILITY ASSESSMENT
A25: Scalability Factor | G25: Current/Projected | M25: Target
A26: Current log sources (count) | M26: N/A
A27: Projected log sources (12 months) | M27: N/A
A28: Current daily log volume (GB) | M28: N/A
A29: Projected daily log volume (12 months, GB) | M29: N/A
A30: Growth rate (%) | M30: <30% increase
A31: Available capacity for growth (%) | M31: >50%
A32: Time to add new log source | M32: <1 hour
A33: Horizontal scaling capability | M33: Yes
A34: Vertical scaling capability | M34: Yes
A35: Capacity planning performed | M35: Quarterly
A37: PERFORMANCE & SCALABILITY CHECKLIST
A38: # | B38: Requirement
A39: 1 | B39: SIEM capacity utilization <80%
A40: 2 | B40: Search performance meets <10 second target
A41: 3 | B41: Indexing lag <5 minutes
A42: 4 | B42: Storage utilization <80%
A43: 5 | B43: SIEM availability >99.5%
A44: 6 | B44: Alert latency <60 seconds
A45: 7 | B45: Capacity planning performed quarterly
A46: 8 | B46: Growth projections documented
...

Sheet Evidence Register
A1: EVIDENCE REGISTER
A2: List all evidence files/documents referenced in this assessment (audit traceability).
A4: Evidence ID | B4: Assessment Area | C4: Evidence Type | D4: Description | E4: Location/Path | F4: Date Collected | G4: Collected By | H4: Verification Status
A5: EV-001 | B5: Monitoring Infrastructure | C5: Configuration file | D5: SIEM platform configuration export — Splunk Enterprise production instance | E5: \\fileserver\isms\evidence\monitoring\splunk-config-export.json | F5: 2024-03-01 | G5: John Davies | H5: Verified

Sheet Summary Dashboard
A1: MONITORING INFRASTRUCTURE ASSESSMENT — SUMMARY DASHBOARD
A2: Summary Dashboard — Monitoring Activities | 01.03.2026
A4: TABLE 1: COMPLIANCE OVERVIEW
A5: Assessment Area | B5: Total Items | C5: Compliant | D5: Partial | E5: Non-Compliant | F5: N/A | G5: Compliance %
A6: 1. Monitoring Platform | B6: =SUM(C6:F6) | C6: =COUNTIF('1. Monitoring Platform'!U24:U200,"✅ Compliant") | D6: =COUNTIF('1. Monitoring Platform'!U24:U200,"⚠️ Partial") | E6: =COUNTIF('1. Monitoring Platform'!U24:U200,"❌ Non-Compliant") | F6: =COUNTIF('1. Monitoring Platform'!U24:U200,"N/A") | G6: =IF((B6-F6)=0,0,C6/(B6-F6))
A7: 2. Log Source Coverage | B7: =SUM(C7:F7) | C7: =COUNTIF('2. Log Source Coverage'!T55:T69,"✅ Compliant") | D7: =COUNTIF('2. Log Source Coverage'!T55:T69,"⚠️ Partial") | E7: =COUNTIF('2. Log Source Coverage'!T55:T69,"❌ Non-Compliant") | F7: =COUNTIF('2. Log Source Coverage'!T55:T69,"N/A") | G7: =IF((B7-F7)=0,0,C7/(B7-F7))
A8: 3. Data Collection Arch | B8: =SUM(C8:F8) | C8: =COUNTIF('3. Data Collection Arch'!R61:R75,"✅ Compliant") | D8: =COUNTIF('3. Data Collection Arch'!R61:R75,"⚠️ Partial") | E8: =COUNTIF('3. Data Collection Arch'!R61:R75,"❌ Non-Compliant") | F8: =COUNTIF('3. Data Collection Arch'!R61:R75,"N/A") | G8: =IF((B8-F8)=0,0,C8/(B8-F8))
A9: 4. Integration Enrichment | B9: =SUM(C9:F9) | C9: =COUNTIF('4. Integration Enrichment'!P61:P75,"✅ Compliant") | D9: =COUNTIF('4. Integration Enrichment'!P61:P75,"⚠️ Partial") | E9: =COUNTIF('4. Integration Enrichment'!P61:P75,"❌ Non-Compliant") | F9: =COUNTIF('4. Integration Enrichment'!P61:P75,"N/A") | G9: =IF((B9-F9)=0,0,C9/(B9-F9))
A10: 5. Performance Scale | B10: =SUM(C10:F10) | C10: =COUNTIF('5. Performance Scale'!Q39:Q53,"✅ Compliant") | D10: =COUNTIF('5. Performance Scale'!Q39:Q53,"⚠️ Partial") | E10: =COUNTIF('5. Performance Scale'!Q39:Q53,"❌ Non-Compliant") | F10: =COUNTIF('5. Performance Scale'!Q39:Q53,"N/A") | G10: =IF((B10-F10)=0,0,C10/(B10-F10))
A11: TOTAL | B11: =SUM(B6:B10) | C11: =SUM(C6:C10) | D11: =SUM(D6:D10) | E11: =SUM(E6:E10) | F11: =SUM(F6:F10) | G11: =IF((B11-F11)=0,0,C11/(B11-F11))
A13: TABLE 2: KEY METRICS
A14: Metric | F14: Value
A15: Monitoring Platforms — Deployed | F15: =COUNTIF('1. Monitoring Platform'!Q8:Q200,"✅ Deployed")
A16: Monitoring Platforms — Compliance Gaps | F16: =COUNTIF('1. Monitoring Platform'!S8:S200,"❌ Non-Compliant")+COUNTIF('1. Monitoring Platform'!S8:S200,"⚠️ Partial")
A17: Log Sources — Actively Collecting | F17: =COUNTIF('2. Log Source Coverage'!N8:N200,"✅ Collecting")
A18: Log Sources — Not Collecting | F18: =COUNTIF('2. Log Source Coverage'!N8:N200,"❌ Not Collecting")
A19: Critical Log Sources Missing | F19: =COUNTIFS('2. Log Source Coverage'!C8:C200,"Critical",'2. Log Source Coverage'!N8:N200,"❌ Not Collecting")
A20: Collection Components — Deployed | F20: =COUNTIF('3. Data Collection Arch'!O8:O200,"✅ Deployed")
A21: Integrations / Enrichment — Deployed | F21: =COUNTIF('4. Integration Enrichment'!L8:L200,"✅ Deployed")
A22: High-Priority Items Across All Sheets | F22: =COUNTIF('2. Log Source Coverage'!C8:C200,"Critical")+COUNTIF('3. Data Collection Arch'!C8:C200,"Critical")+COUNTIF('4. Integration Enrichment'!C8:C200,"Critical")
A24: TABLE 3: CRITICAL FINDINGS
A25: Category / Finding | F25: Count | G25: Action
A26: Log Sources — Not Collecting | F26: =COUNTIF('2. Log Source Coverage'!N8:N200,"❌ Not Collecting")
A27: Critical Log Sources Missing | F27: =COUNTIFS('2. Log Source Coverage'!C8:C200,"Critical",'2. Log Source Coverage'!N8:N200,"❌ Not Collecting")
A28: Platforms — Non-Compliant | F28: =COUNTIF('1. Monitoring Platform'!S8:S200,"❌ Non-Compliant")
A29: Components — Not Deployed | F29: =COUNTIF('3. Data Collection Arch'!O8:O200,"❌ Not Deployed")
A30: Integrations — Not Deployed | F30: =COUNTIF('4. Integration Enrichment'!L8:L200,"❌ Not Deployed")
A31: Filter source sheets using AutoFilter — see column headers above

Sheet Approval Sign-Off
A1: ASSESSMENT APPROVAL AND SIGN-OFF
A2: Monitoring Infrastructure Assessment Approval Workflow
A4: COMPLETED BY
A5: Name:
A6: Title:
A7: Date:
A8: Signature:
A11: REVIEWED BY
A12: Name:
A13: Title:
A14: Date:
A15: Signature:
... A26: Title:
A27: Approval Decision: | B27: [Dropdown: Approved, Approved with Conditions, Rejected]
A28: Date:
A29: Signature:
A31: Conditions/Comments:
A39: FINAL DECISION
A40: Decision:
A42: NEXT REVIEW
A43: Scheduled Review:
