Workbook

Sheet Instructions & Legend
A1: ISMS-IMP-A.8.16.3 - Coverage Assessment ISO/IEC 27001:2022 - Control A.8.16: Monitoring Activities
A3: Document Information
A4: Document ID | B4: ISMS-IMP-A.8.16.3
A5: Workbook Title | B5: Coverage Assessment
A6: Control Reference | B6: ISO/IEC 27001:2022 - Control A.8.16: Monitoring Activities
A7: Version | B7: 1.0
A8: Assessment Date
A9: Completed By
A10: Organisation
A12: Instructions
A13: 1. Complete comprehensive asset inventory (Sheet 1).
A14: 2. Document all network segments and coverage (Sheet 2).
A15: 3. Assess user and identity system monitoring (Sheet 3).
A16: 4. Inventory application monitoring coverage (Sheet 4).
A17: 5. Identify and document all coverage gaps (Sheet 5).
A18: 6. Review Summary Dashboard for overall coverage status.
A19: 7. Prioritise gaps by criticality and regulatory requirements.
A20: 8. Document evidence in Evidence Register.
... A23: Status Legend
A24: Symbol | B24: Status | C24: Description
A25: ✓ | B25: Compliant / Complete | C25: Requirement fully met
A26: ⚠ | B26: Partial / In Progress | C26: Partially met or in progress
A27: ✗ | B27: Non-Compliant / Not Started | C27: Requirement not met
A28: — | B28: Not Applicable | C28: Not applicable to this assessment

Sheet 1. Asset Coverage
A1: 1. ASSET INVENTORY & MONITORING COVERAGE
A2: Policy Reference: ISMS-POL-A.8.16-S2.1.1 - Assess asset coverage
A3: Are all organisational assets inventoried and appropriate assets monitored?
A6: Asset ID | B6: Asset Name | C6: Asset Type | D6: Operating System | E6: Location | F6: Business Unit | G6: Asset Owner | H6: Data Classification | I6: Criticality | J6: Regulatory Scope | K6: Monitoring Required | L6: Currently Monitored | M6: Log Types Collected | N6: Monitoring Platform | O6: Baseline Established | P6: Detection Rules Active | Q6: Last Log Verified | R6: Coverage Status | S6: Gap Reason | T6: Exception Approved | U6: Target Coverage Date | V6: Responsible Party | W6: Notes
A7: SRV-001 | B7: DC01-Primary | C7: Server | D7: Windows Server 2022 | E7: DataCenter-1 | F7: IT Operations | G7: J. Smith | H7: Confidential | I7: Critical | J7: Multiple | K7: Mandatory | L7: Yes | M7: Security, System, Application | N7: Splunk | O7: Yes | P7: 15 | Q7: 05.01.2025 | R7: ✅ Full Coverage | S7: None | T7: N/A | U7: N/A | V7: SOC Team | W7: Production DC
A59: ASSET COVERAGE COMPLIANCE CHECKLIST
A60: # | B60: Requirement
A61: 1 | B61: Complete asset inventory maintained
A62: 2 | B62: Asset inventory updated at least quarterly
A63: 3 | B63: All assets classified by criticality
A64: 4 | B64: All Critical assets monitored (100%)
A65: 5 | B65: >80% of High priority assets monitored
A66: 6 | B66: >60% of Medium priority assets monitored
A67: 7 | B67: All PCI-DSS scope systems monitored
A68: 8 | B68: All HIPAA scope systems monitored
A69: 9 | B69: All systems handling confidential data monitored
A70: 10 | B70: Monitoring coverage gaps documented
A71: 11 | B71: Exceptions formally approved
A72: 12 | B72: Gap remediation plans exist
... A75: 15 | B75: New assets onboarded to monitoring within 30 days
A76: SCORE: | B76: =COUNTIF(W61:W75,"✅ Compliant")&" / 15"

Sheet 2. Network Coverage
A1: 2. NETWORK SEGMENT COVERAGE ASSESSMENT
A2: Policy Reference: ISMS-POL-A.8.16-S2.1.1 - Assess network coverage
A6: Network Segment/Zone | B6: Segment Type | C6: IP Range/CIDR | D6: VLAN ID | E6: Number of Assets | F6: Criticality | G6: Data Classification | H6: Perimeter Monitoring | I6: Flow Monitoring | J6: DNS Monitoring | K6: Endpoint Monitoring | L6: Log Collection Active | M6: Network Tap/SPAN | N6: Isolation Status | O6: Coverage Status | P6: Gaps Identified | Q6: Exception Approved | R6: Target Date | S6: Responsible Party | T6: Notes
A7: Production LAN | B7: Internal LAN | C7: 10.0.1.0/24 | D7: VLAN-10 | E7: 45 | F7: Critical | G7: Confidential | H7: Yes | I7: Yes | J7: Yes | K7: Yes (EDR) | L7: Yes | M7: Yes | N7: Active | O7: ✅ Full | P7: None | Q7: N/A | R7: N/A | S7: SOC Team | T7: Core production segment
A59: NETWORK COVERAGE CHECKLIST
A60: # | B60: Requirement
A61: 1 | B61: All network segments inventoried
A62: 2 | B62: All production segments monitored
A63: 3 | B63: All DMZ segments monitored
A64: 4 | B64: Critical segments have redundant monitoring
A65: 5 | B65: Perimeter traffic monitored (firewall + IDS/IPS)
A66: 6 | B66: Internal traffic monitored (flow data)
A67: 7 | B67: DNS queries monitored
A68: 8 | B68: Endpoints monitored (EDR/AV integration)
A69: 9 | B69: East-west traffic visibility (lateral movement detection)
A70: 10 | B70: Cloud network segments included
A71: SCORE: | B71: =COUNTIF(T61:T70,"✅ Compliant")&" / 10"

Sheet 3. User Identity Coverage
A1: 3. USER & IDENTITY MONITORING COVERAGE
A2: Policy Reference: ISMS-POL-A.8.16-S2.1.2 - Assess user monitoring
A6: Identity System | B6: System Type | C6: User Count | D6: Privileged Account Count | E6: Service Account Count | F6: Authentication Logs Collected | G6: Authorisation Logs Collected | H6: Password Change Logs | I6: Privilege Escalation Logs | J6: MFA Events Logged | K6: SSO Events Logged | L6: Failed Login Monitoring | M6: After-Hours Access Monitoring | N6: Geographic Anomaly Detection | O6: User Behaviour Analytics | P6: Privileged Access Monitoring | Q6: Coverage Status | R6: Gaps/Issues | S6: Priority
A7: Microsoft Entra ID | B7: Cloud IdP | C7: 2500 | D7: 45 | E7: 120 | F7: Yes | G7: Yes | H7: Yes | I7: Yes | J7: Yes | K7: Yes | L7: Yes | M7: Yes | N7: Yes | O7: Yes (UEBA) | P7: Yes (PAM integrated) | Q7: ✅ Compliant | R7: None | S7: High
A59: USER & IDENTITY COVERAGE CHECKLIST
A60: # | B60: Requirement
A61: 1 | B61: Primary identity system (AD/Microsoft Entra ID (formerly Azure AD)) monitored
A62: 2 | B62: All authentication events logged
A63: 3 | B63: Failed login attempts monitored and alerted
A64: 4 | B64: Privileged account usage monitored
A65: 5 | B65: Service account usage monitored
A66: 6 | B66: Password changes logged
A67: 7 | B67: Privilege escalation logged
A68: 8 | B68: MFA events logged (if MFA deployed)
A69: 9 | B69: SSO events logged (if SSO deployed)
A70: 10 | B70: After-hours access monitored
A71: 11 | B71: Geographic anomalies detected
A72: 12 | B72: User behaviour baselines established
... A75: 15 | B75: Identity correlation across systems
A76: SCORE: | B76: =COUNTIF(S61:S75,"✅ Compliant")&" / 15"

Sheet 4. Application Coverage
A1: 4. APPLICATION & SERVICE MONITORING COVERAGE
A2: Policy Reference: ISMS-POL-A.8.16-S2.1.2 - Assess application coverage
A6: Application/Service Name | B6: Application Type | C6: Business Unit | D6: Application Owner | E6: Data Classification | F6: Criticality | G6: User Base | H6: Application Logs Collected | I6: API Logs Collected | J6: Database Logs Collected | K6: Error/Exception Logging | L6: Transaction Logging | M6: Access Control Logs | N6: Data Export Monitoring | O6: Performance Monitoring | P6: WAF Integration | Q6: APM Integration | R6: Coverage Status | S6: Gaps | T6: Target Date | U6: Priority
A7: Customer Portal | B7: Web Application | C7: Sales | D7: M. Johnson | E7: Confidential | F7: High | G7: 5000 users | H7: Yes | I7: Yes | J7: Yes | K7: Yes | L7: Yes | M7: Yes | N7: Yes | O7: Yes | P7: Yes | Q7: Yes | R7: ✅ Compliant | S7: None | T7: N/A | U7: High
A60: APPLICATION COVERAGE CHECKLIST
A61: # | B61: Requirement
A62: 1 | B62: All critical applications monitored
A63: 2 | B63: >80% of high-priority applications monitored
A64: 3 | B64: Application error/exception logs collected
A65: 4 | B65: API calls logged (if API-based)
A66: 5 | B66: Database queries logged (if database-backed)
A67: 6 | B67: User access logged
A68: 7 | B68: Data exports/downloads monitored
A69: 8 | B69: File uploads monitored
A70: 9 | B70: Configuration changes logged
A71: 10 | B71: WAF deployed for internet-facing apps
A72: 11 | B72: APM integrated for performance visibility
A73: 12 | B73: Cloud application logs collected (SaaS)
... A76: 15 | B76: Application security events forwarded to SIEM
A77: SCORE: | B77: =COUNTIF(U62:U76,"✅ Compliant")&" / 15"

Sheet 5. Gap Analysis
A1: 5. COVERAGE GAP ANALYSIS
A2: Policy Reference: ISMS-POL-A.8.16-S2.1 - Document and remediate coverage gaps
A3: Are all monitoring coverage gaps identified, documented, and tracked to remediation?
A6: Gap ID | B6: Gap Category | C6: Affected Asset/System | D6: Gap Description | E6: Business Impact | F6: Risk Level | G6: Root Cause | H6: Exception Approved | I6: Exception ID | J6: Compensating Controls | K6: Remediation Plan | L6: Remediation Owner | M6: Target Date | N6: Budget Required | O6: Status | P6: Status Date | Q6: Verification Method | R6: Notes
A7: GAP-001 | B7: Asset Not Monitored | C7: Legacy File Server | D7: No log collection configured | E7: Medium - non-critical legacy system | F7: Medium | G7: End-of-life system, no agent support | H7: Yes | I7: EXC-2024-015 | J7: Network-level monitoring via firewall | K7: Migrate to new storage platform | L7: Infrastructure Team | M7: 31.03.2025 | N7: Yes | O7: In Progress | P7: 15.12.2024 | Q7: Post-migration verification | R7: Budget approved Q1
A8: ="GAP-"&TEXT(ROW()-7,"000")
A9: ="GAP-"&TEXT(ROW()-7,"000")
A10: ="GAP-"&TEXT(ROW()-7,"000")
A11: ="GAP-"&TEXT(ROW()-7,"000")
A12: ="GAP-"&TEXT(ROW()-7,"000")
A13: ="GAP-"&TEXT(ROW()-7,"000")
A14: ="GAP-"&TEXT(ROW()-7,"000")
A15: ="GAP-"&TEXT(ROW()-7,"000")
A16: ="GAP-"&TEXT(ROW()-7,"000")
A17: ="GAP-"&TEXT(ROW()-7,"000")
A18: ="GAP-"&TEXT(ROW()-7,"000")
A19: ="GAP-"&TEXT(ROW()-7,"000")
... A47: ="GAP-"&TEXT(ROW()-7,"000")
A50: GAP SUMMARY STATISTICS
A51: Metric | F51: Count/Value | J51: Target | M51: Status
A52: Total Gaps Identified | F52: =COUNTA(B8:B47) | J52: N/A
A53: Critical Gaps | F53: =COUNTIF(F8:F47,"Critical") | J53: 0
A54: High Gaps | F54: =COUNTIF(F8:F47,"High") | J54: <5
A55: Open Gaps | F55: =COUNTIF(O8:O47,"Open") | J55: Minimize
A56: In Progress | F56: =COUNTIF(O8:O47,"In Progress") | J56: N/A
A57: Resolved Gaps | F57: =COUNTIF(O8:O47,"Resolved") | J57: Maximize
A58: Accepted Risks | F58: =COUNTIF(O8:O47,"Accepted") | J58: Document
A59: Overdue (Past Target Date) | F59: =SUMPRODUCT((O8:O47<>"Resolved")*(O8:O47<>"Accepted")*(M8:M47<TODAY())*(M8:M47<>"")) | J59: 0
A62: GAP MANAGEMENT CHECKLIST
A63: # | B63: Requirement
A64: 1 | B64: All coverage gaps identified
A65: 2 | B65: Gaps categorised by type
A66: 3 | B66: Risk level assessed for each gap
A67: 4 | B67: Root cause analysis conducted
A68: 5 | B68: Critical gaps remediated within 30 days
A69: 6 | B69: High gaps remediated within 90 days
A70: 7 | B70: Exceptions formally approved
A71: 8 | B71: Compensating controls documented
A72: 9 | B72: Remediation plans documented
A73: 10 | B73: Gap remediation tracked
...

Sheet Evidence Register
A1: EVIDENCE REGISTER
A2: List all evidence files/documents referenced in this assessment (audit traceability).
A4: Evidence ID | B4: Assessment Area | C4: Evidence Type | D4: Description | E4: Location/Path | F4: Date Collected | G4: Collected By | H4: Verification Status
A5: EV-001 | B5: Coverage Assessment | C5: Report | D5: Monitoring coverage assessment report — Q1 2024 all critical systems | E5: \\fileserver\isms\evidence\monitoring\coverage-assessment-q1-2024.pdf | F5: 2024-03-01 | G5: Thomas Weber | H5: Verified

Sheet Summary Dashboard
A1: COVERAGE ASSESSMENT — SUMMARY DASHBOARD
A2: Summary Dashboard — Monitoring Activities | 10.03.2026
A4: TABLE 1: COMPLIANCE OVERVIEW
A5: Assessment Area | B5: Total Items | C5: Compliant | D5: Partial | E5: Non-Compliant | F5: N/A | G5: Compliance %
A6: 1. Asset Coverage | B6: =SUM(C6:F6) | C6: =COUNTIF('1. Asset Coverage'!W61:W75,"✅ Compliant") | D6: =COUNTIF('1. Asset Coverage'!W61:W75,"⚠️ Partial") | E6: =COUNTIF('1. Asset Coverage'!W61:W75,"❌ Non-Compliant") | F6: =COUNTIF('1. Asset Coverage'!W61:W75,"N/A") | G6: =IF((B6-F6)=0,0,C6/(B6-F6))
A7: 2. Network Coverage | B7: =SUM(C7:F7) | C7: =COUNTIF('2. Network Coverage'!T61:T70,"✅ Compliant") | D7: =COUNTIF('2. Network Coverage'!T61:T70,"⚠️ Partial") | E7: =COUNTIF('2. Network Coverage'!T61:T70,"❌ Non-Compliant") | F7: =COUNTIF('2. Network Coverage'!T61:T70,"N/A") | G7: =IF((B7-F7)=0,0,C7/(B7-F7))
A8: 3. User Identity Coverage | B8: =SUM(C8:F8) | C8: =COUNTIF('3. User Identity Coverage'!S61:S75,"✅ Compliant") | D8: =COUNTIF('3. User Identity Coverage'!S61:S75,"⚠️ Partial") | E8: =COUNTIF('3. User Identity Coverage'!S61:S75,"❌ Non-Compliant") | F8: =COUNTIF('3. User Identity Coverage'!S61:S75,"N/A") | G8: =IF((B8-F8)=0,0,C8/(B8-F8))
A9: 4. Application Coverage | B9: =SUM(C9:F9) | C9: =COUNTIF('4. Application Coverage'!U62:U76,"✅ Compliant") | D9: =COUNTIF('4. Application Coverage'!U62:U76,"⚠️ Partial") | E9: =COUNTIF('4. Application Coverage'!U62:U76,"❌ Non-Compliant") | F9: =COUNTIF('4. Application Coverage'!U62:U76,"N/A") | G9: =IF((B9-F9)=0,0,C9/(B9-F9))
A10: 5. Gap Analysis | B10: =SUM(C10:F10) | C10: =COUNTIF('5. Gap Analysis'!R64:R78,"✅ Compliant") | D10: =COUNTIF('5. Gap Analysis'!R64:R78,"⚠️ Partial") | E10: =COUNTIF('5. Gap Analysis'!R64:R78,"❌ Non-Compliant") | F10: =COUNTIF('5. Gap Analysis'!R64:R78,"N/A") | G10: =IF((B10-F10)=0,0,C10/(B10-F10))
A11: TOTAL | B11: =SUM(B6:B10) | C11: =SUM(C6:C10) | D11: =SUM(D6:D10) | E11: =SUM(E6:E10) | F11: =SUM(F6:F10) | G11: =IF((B11-F11)=0,0,C11/(B11-F11))
A13: TABLE 2: KEY METRICS
A14: Metric | F14: Value
A15: Assets — Full Monitoring Coverage | F15: =COUNTIF('1. Asset Coverage'!R8:R200,"✅ Full Coverage")
A16: Assets — No Monitoring Coverage | F16: =COUNTIF('1. Asset Coverage'!R8:R200,"❌ No Coverage")
A17: Critical Assets — Not Monitored | F17: =COUNTIFS('1. Asset Coverage'!I8:I200,"Critical",'1. Asset Coverage'!R8:R200,"❌ No Coverage")
A18: High Assets — Not Monitored | F18: =COUNTIFS('1. Asset Coverage'!I8:I200,"High",'1. Asset Coverage'!R8:R200,"❌ No Coverage")
A19: Network Segments — Full Coverage | F19: =COUNTIF('2. Network Coverage'!O8:O200,"✅ Full")
A20: Network Segments — No Coverage | F20: =COUNTIF('2. Network Coverage'!O8:O200,"❌ None")
A21: Gaps Identified (Gap Analysis) | F21: =COUNTA('5. Gap Analysis'!B8:B200)
A22: Mandatory Monitoring — Not Implemented | F22: =COUNTIFS('1. Asset Coverage'!K8:K200,"Mandatory",'1. Asset Coverage'!L8:L200,"No")
A24: TABLE 3: CRITICAL FINDINGS
A25: Category / Finding | F25: Count | G25: Action
A26: Assets — No Monitoring Coverage | F26: =COUNTIF('1. Asset Coverage'!R8:R200,"❌ No Coverage")
A27: Critical Assets — Not Monitored | F27: =COUNTIFS('1. Asset Coverage'!I8:I200,"Critical",'1. Asset Coverage'!R8:R200,"❌ No Coverage")
A28: High Assets — Not Monitored | F28: =COUNTIFS('1. Asset Coverage'!I8:I200,"High",'1. Asset Coverage'!R8:R200,"❌ No Coverage")
A29: Network Segments — No Coverage | F29: =COUNTIF('2. Network Coverage'!O8:O200,"❌ None")
A30: Mandatory Monitoring Not Done | F30: =COUNTIFS('1. Asset Coverage'!K8:K200,"Mandatory",'1. Asset Coverage'!L8:L200,"No")
A31: Filter source sheets using AutoFilter — see column headers above

Sheet Approval Sign-Off
A1: ASSESSMENT APPROVAL AND SIGN-OFF
A2: Assessment approval workflow for ISMS-IMP-A.8.16.3 - Coverage Assessment
A3: COMPLETED BY
A4: Name:
A5: Title:
A6: Date:
A7: Signature:
A9: REVIEWED BY
A10: Name:
A11: Title:
A12: Date:
A13: Signature:
... A29: Special Considerations:
