Workbook

Sheet Executive Summary
A1: ISMS-OP-CHK-A.6.7-8 — Remote Working and Security Event Reporting Compliance Checklist
A3: DOCUMENT INFORMATION
A4: Document ID | B4: ISMS-OP-CHK-A.6.7-8
A5: Source Policy | B5: ISMS-OP-POL-A.6.7-8
A6: ISO Controls | B6: Remote Working and Security Event Reporting
A7: Generated | B7: 30.09.2026
A8: Prepared By
A9: Organisation
A10: Review Cycle | B10: Annual
A12: OVERALL COMPLIANCE STATUS
A13: Overall Compliance | B13: ='Dashboard'!G17
A14: Status | B14: =IF(Dashboard!H17>0,"INCOMPLETE",IF(Dashboard!G17="N/A","NOT ASSESSED",IF(ISNUMBER(VALUE(SUBSTITUTE(Dashboard!G17,"%",""))),IF(VALUE(SUBSTITUTE(Dashboard!G17,"%",""))>=90,"GREEN",IF(VALUE(SUBSTITUTE(Dashboard!G17,"%",""))>=70,"AMBER","RED")),"NOT ASSESSED")))
A16: KEY METRICS
A17: Total Requirements | B17: ='Dashboard'!B17
A18: Compliant | B18: ='Dashboard'!C17
A19: Partial | B19: ='Dashboard'!D17
A20: Non-Compliant | B20: ='Dashboard'!E17
A21: Not Applicable | B21: ='Dashboard'!F17
A22: Unanswered | B22: ='Dashboard'!H17
A23: Owner Coverage | B23: =IF(Dashboard!B17=0,"N/A",ROUND((COUNTA('Remote Work Authorisation'!F4:F9)+COUNTA('Mobile Device Reg and Resp'!F4:F7)+COUNTA('Remote Wipe and Backup'!F4:F5)+COUNTA('Physical Security'!F4:F6)+COUNTA('Technical Security'!F4:F10)+COUNTA('Data Handling'!F4:F5)+COUNTA('Corporate and BYOD Device Reqs'!F4:F10)+COUNTA('Remote Work Termination'!F4:F8)+COUNTA('Reporting Channels'!F4:F8)+COUNTA('Non-Blame Culture'!F4:F4)+COUNTA('Response and Feedback'!F4:F5)+COUNTA('Reporting Metrics'!F4:F6)+COUNTA('Remote Work Compliance Verif'!F4:F4))/Dashboard!B17*100,0)&"%")
A25: DOMAIN STATUS SUMMARY
A26: Domain | B26: Compliance % | C26: Compliant | D26: Gaps | E26: Status
A27: Remote Work Authorisation | B27: ='Dashboard'!G4 | C27: ='Dashboard'!C4 | D27: ='Dashboard'!E4 | E27: =IF(Dashboard!H4>0,"INCOMPLETE",IF(Dashboard!G4="N/A","--",IF(ISNUMBER(VALUE(SUBSTITUTE(Dashboard!G4,"%",""))),IF(VALUE(SUBSTITUTE(Dashboard!G4,"%",""))>=90,"PASS",IF(VALUE(SUBSTITUTE(Dashboard!G4,"%",""))>=70,"REVIEW","FAIL")),"--")))
A28: Mobile Device Reg and Resp | B28: ='Dashboard'!G5 | C28: ='Dashboard'!C5 | D28: ='Dashboard'!E5 | E28: =IF(Dashboard!H5>0,"INCOMPLETE",IF(Dashboard!G5="N/A","--",IF(ISNUMBER(VALUE(SUBSTITUTE(Dashboard!G5,"%",""))),IF(VALUE(SUBSTITUTE(Dashboard!G5,"%",""))>=90,"PASS",IF(VALUE(SUBSTITUTE(Dashboard!G5,"%",""))>=70,"REVIEW","FAIL")),"--")))
A29: Remote Wipe and Backup | B29: ='Dashboard'!G6 | C29: ='Dashboard'!C6 | D29: ='Dashboard'!E6 | E29: =IF(Dashboard!H6>0,"INCOMPLETE",IF(Dashboard!G6="N/A","--",IF(ISNUMBER(VALUE(SUBSTITUTE(Dashboard!G6,"%",""))),IF(VALUE(SUBSTITUTE(Dashboard!G6,"%",""))>=90,"PASS",IF(VALUE(SUBSTITUTE(Dashboard!G6,"%",""))>=70,"REVIEW","FAIL")),"--")))
A30: Physical Security | B30: ='Dashboard'!G7 | C30: ='Dashboard'!C7 | D30: ='Dashboard'!E7 | E30: =IF(Dashboard!H7>0,"INCOMPLETE",IF(Dashboard!G7="N/A","--",IF(ISNUMBER(VALUE(SUBSTITUTE(Dashboard!G7,"%",""))),IF(VALUE(SUBSTITUTE(Dashboard!G7,"%",""))>=90,"PASS",IF(VALUE(SUBSTITUTE(Dashboard!G7,"%",""))>=70,"REVIEW","FAIL")),"--")))
A31: Technical Security | B31: ='Dashboard'!G8 | C31: ='Dashboard'!C8 | D31: ='Dashboard'!E8 | E31: =IF(Dashboard!H8>0,"INCOMPLETE",IF(Dashboard!G8="N/A","--",IF(ISNUMBER(VALUE(SUBSTITUTE(Dashboard!G8,"%",""))),IF(VALUE(SUBSTITUTE(Dashboard!G8,"%",""))>=90,"PASS",IF(VALUE(SUBSTITUTE(Dashboard!G8,"%",""))>=70,"REVIEW","FAIL")),"--")))
A32: Data Handling | B32: ='Dashboard'!G9 | C32: ='Dashboard'!C9 | D32: ='Dashboard'!E9 | E32: =IF(Dashboard!H9>0,"INCOMPLETE",IF(Dashboard!G9="N/A","--",IF(ISNUMBER(VALUE(SUBSTITUTE(Dashboard!G9,"%",""))),IF(VALUE(SUBSTITUTE(Dashboard!G9,"%",""))>=90,"PASS",IF(VALUE(SUBSTITUTE(Dashboard!G9,"%",""))>=70,"REVIEW","FAIL")),"--")))
A33: Corporate and BYOD Device Reqs | B33: ='Dashboard'!G10 | C33: ='Dashboard'!C10 | D33: ='Dashboard'!E10 | E33: =IF(Dashboard!H10>0,"INCOMPLETE",IF(Dashboard!G10="N/A","--",IF(ISNUMBER(VALUE(SUBSTITUTE(Dashboard!G10,"%",""))),IF(VALUE(SUBSTITUTE(Dashboard!G10,"%",""))>=90,"PASS",IF(VALUE(SUBSTITUTE(Dashboard!G10,"%",""))>=70,"REVIEW","FAIL")),"--")))
A34: Remote Work Termination | B34: ='Dashboard'!G11 | C34: ='Dashboard'!C11 | D34: ='Dashboard'!E11 | E34: =IF(Dashboard!H11>0,"INCOMPLETE",IF(Dashboard!G11="N/A","--",IF(ISNUMBER(VALUE(SUBSTITUTE(Dashboard!G11,"%",""))),IF(VALUE(SUBSTITUTE(Dashboard!G11,"%",""))>=90,"PASS",IF(VALUE(SUBSTITUTE(Dashboard!G11,"%",""))>=70,"REVIEW","FAIL")),"--")))
A35: Reporting Channels | B35: ='Dashboard'!G12 | C35: ='Dashboard'!C12 | D35: ='Dashboard'!E12 | E35: =IF(Dashboard!H12>0,"INCOMPLETE",IF(Dashboard!G12="N/A","--",IF(ISNUMBER(VALUE(SUBSTITUTE(Dashboard!G12,"%",""))),IF(VALUE(SUBSTITUTE(Dashboard!G12,"%",""))>=90,"PASS",IF(VALUE(SUBSTITUTE(Dashboard!G12,"%",""))>=70,"REVIEW","FAIL")),"--")))
A36: Non-Blame Culture | B36: ='Dashboard'!G13 | C36: ='Dashboard'!C13 | D36: ='Dashboard'!E13 | E36: =IF(Dashboard!H13>0,"INCOMPLETE",IF(Dashboard!G13="N/A","--",IF(ISNUMBER(VALUE(SUBSTITUTE(Dashboard!G13,"%",""))),IF(VALUE(SUBSTITUTE(Dashboard!G13,"%",""))>=90,"PASS",IF(VALUE(SUBSTITUTE(Dashboard!G13,"%",""))>=70,"REVIEW","FAIL")),"--")))
A37: Response and Feedback | B37: ='Dashboard'!G14 | C37: ='Dashboard'!C14 | D37: ='Dashboard'!E14 | E37: =IF(Dashboard!H14>0,"INCOMPLETE",IF(Dashboard!G14="N/A","--",IF(ISNUMBER(VALUE(SUBSTITUTE(Dashboard!G14,"%",""))),IF(VALUE(SUBSTITUTE(Dashboard!G14,"%",""))>=90,"PASS",IF(VALUE(SUBSTITUTE(Dashboard!G14,"%",""))>=70,"REVIEW","FAIL")),"--")))
A38: Reporting Metrics | B38: ='Dashboard'!G15 | C38: ='Dashboard'!C15 | D38: ='Dashboard'!E15 | E38: =IF(Dashboard!H15>0,"INCOMPLETE",IF(Dashboard!G15="N/A","--",IF(ISNUMBER(VALUE(SUBSTITUTE(Dashboard!G15,"%",""))),IF(VALUE(SUBSTITUTE(Dashboard!G15,"%",""))>=90,"PASS",IF(VALUE(SUBSTITUTE(Dashboard!G15,"%",""))>=70,"REVIEW","FAIL")),"--")))
A39: Remote Work Compliance Verif | B39: ='Dashboard'!G16 | C39: ='Dashboard'!C16 | D39: ='Dashboard'!E16 | E39: =IF(Dashboard!H16>0,"INCOMPLETE",IF(Dashboard!G16="N/A","--",IF(ISNUMBER(VALUE(SUBSTITUTE(Dashboard!G16,"%",""))),IF(VALUE(SUBSTITUTE(Dashboard!G16,"%",""))>=90,"PASS",IF(VALUE(SUBSTITUTE(Dashboard!G16,"%",""))>=70,"REVIEW","FAIL")),"--")))
A41: CRITICAL ISSUES
A42: # | B42: Issue Description | C42: Domain | D42: Owner | E42: Due Date
A43: 1
A44: 2
A45: 3
...

Sheet Dashboard
A1: Remote Working and Security Event Reporting — Compliance Dashboard
A3: Domain | B3: Total Reqs | C3: Compliant | D3: Partial | E3: Non-Compliant | F3: N/A | G3: Compliance % | H3: Unassessed
A4: Remote Work Authorisation | B4: =COUNTA('Remote Work Authorisation'!A4:A9) | C4: =COUNTIF('Remote Work Authorisation'!D4:D9,"Compliant") | D4: =COUNTIF('Remote Work Authorisation'!D4:D9,"Partial") | E4: =COUNTIF('Remote Work Authorisation'!D4:D9,"Non-Compliant") | F4: =COUNTIF('Remote Work Authorisation'!D4:D9,"N/A") | G4: =IF((B4-F4)=0,"N/A",ROUND(C4/(B4-F4)*100,1)&"%") | H4: =B4-(C4+D4+E4+F4)
A5: Mobile Device Reg and Resp | B5: =COUNTA('Mobile Device Reg and Resp'!A4:A7) | C5: =COUNTIF('Mobile Device Reg and Resp'!D4:D7,"Compliant") | D5: =COUNTIF('Mobile Device Reg and Resp'!D4:D7,"Partial") | E5: =COUNTIF('Mobile Device Reg and Resp'!D4:D7,"Non-Compliant") | F5: =COUNTIF('Mobile Device Reg and Resp'!D4:D7,"N/A") | G5: =IF((B5-F5)=0,"N/A",ROUND(C5/(B5-F5)*100,1)&"%") | H5: =B5-(C5+D5+E5+F5)
A6: Remote Wipe and Backup | B6: =COUNTA('Remote Wipe and Backup'!A4:A5) | C6: =COUNTIF('Remote Wipe and Backup'!D4:D5,"Compliant") | D6: =COUNTIF('Remote Wipe and Backup'!D4:D5,"Partial") | E6: =COUNTIF('Remote Wipe and Backup'!D4:D5,"Non-Compliant") | F6: =COUNTIF('Remote Wipe and Backup'!D4:D5,"N/A") | G6: =IF((B6-F6)=0,"N/A",ROUND(C6/(B6-F6)*100,1)&"%") | H6: =B6-(C6+D6+E6+F6)
A7: Physical Security | B7: =COUNTA('Physical Security'!A4:A6) | C7: =COUNTIF('Physical Security'!D4:D6,"Compliant") | D7: =COUNTIF('Physical Security'!D4:D6,"Partial") | E7: =COUNTIF('Physical Security'!D4:D6,"Non-Compliant") | F7: =COUNTIF('Physical Security'!D4:D6,"N/A") | G7: =IF((B7-F7)=0,"N/A",ROUND(C7/(B7-F7)*100,1)&"%") | H7: =B7-(C7+D7+E7+F7)
A8: Technical Security | B8: =COUNTA('Technical Security'!A4:A10) | C8: =COUNTIF('Technical Security'!D4:D10,"Compliant") | D8: =COUNTIF('Technical Security'!D4:D10,"Partial") | E8: =COUNTIF('Technical Security'!D4:D10,"Non-Compliant") | F8: =COUNTIF('Technical Security'!D4:D10,"N/A") | G8: =IF((B8-F8)=0,"N/A",ROUND(C8/(B8-F8)*100,1)&"%") | H8: =B8-(C8+D8+E8+F8)
A9: Data Handling | B9: =COUNTA('Data Handling'!A4:A5) | C9: =COUNTIF('Data Handling'!D4:D5,"Compliant") | D9: =COUNTIF('Data Handling'!D4:D5,"Partial") | E9: =COUNTIF('Data Handling'!D4:D5,"Non-Compliant") | F9: =COUNTIF('Data Handling'!D4:D5,"N/A") | G9: =IF((B9-F9)=0,"N/A",ROUND(C9/(B9-F9)*100,1)&"%") | H9: =B9-(C9+D9+E9+F9)
A10: Corporate and BYOD Device Reqs | B10: =COUNTA('Corporate and BYOD Device Reqs'!A4:A10) | C10: =COUNTIF('Corporate and BYOD Device Reqs'!D4:D10,"Compliant") | D10: =COUNTIF('Corporate and BYOD Device Reqs'!D4:D10,"Partial") | E10: =COUNTIF('Corporate and BYOD Device Reqs'!D4:D10,"Non-Compliant") | F10: =COUNTIF('Corporate and BYOD Device Reqs'!D4:D10,"N/A") | G10: =IF((B10-F10)=0,"N/A",ROUND(C10/(B10-F10)*100,1)&"%") | H10: =B10-(C10+D10+E10+F10)
A11: Remote Work Termination | B11: =COUNTA('Remote Work Termination'!A4:A8) | C11: =COUNTIF('Remote Work Termination'!D4:D8,"Compliant") | D11: =COUNTIF('Remote Work Termination'!D4:D8,"Partial") | E11: =COUNTIF('Remote Work Termination'!D4:D8,"Non-Compliant") | F11: =COUNTIF('Remote Work Termination'!D4:D8,"N/A") | G11: =IF((B11-F11)=0,"N/A",ROUND(C11/(B11-F11)*100,1)&"%") | H11: =B11-(C11+D11+E11+F11)
A12: Reporting Channels | B12: =COUNTA('Reporting Channels'!A4:A8) | C12: =COUNTIF('Reporting Channels'!D4:D8,"Compliant") | D12: =COUNTIF('Reporting Channels'!D4:D8,"Partial") | E12: =COUNTIF('Reporting Channels'!D4:D8,"Non-Compliant") | F12: =COUNTIF('Reporting Channels'!D4:D8,"N/A") | G12: =IF((B12-F12)=0,"N/A",ROUND(C12/(B12-F12)*100,1)&"%") | H12: =B12-(C12+D12+E12+F12)
A13: Non-Blame Culture | B13: =COUNTA('Non-Blame Culture'!A4:A4) | C13: =COUNTIF('Non-Blame Culture'!D4:D4,"Compliant") | D13: =COUNTIF('Non-Blame Culture'!D4:D4,"Partial") | E13: =COUNTIF('Non-Blame Culture'!D4:D4,"Non-Compliant") | F13: =COUNTIF('Non-Blame Culture'!D4:D4,"N/A") | G13: =IF((B13-F13)=0,"N/A",ROUND(C13/(B13-F13)*100,1)&"%") | H13: =B13-(C13+D13+E13+F13)
A14: Response and Feedback | B14: =COUNTA('Response and Feedback'!A4:A5) | C14: =COUNTIF('Response and Feedback'!D4:D5,"Compliant") | D14: =COUNTIF('Response and Feedback'!D4:D5,"Partial") | E14: =COUNTIF('Response and Feedback'!D4:D5,"Non-Compliant") | F14: =COUNTIF('Response and Feedback'!D4:D5,"N/A") | G14: =IF((B14-F14)=0,"N/A",ROUND(C14/(B14-F14)*100,1)&"%") | H14: =B14-(C14+D14+E14+F14)
A15: Reporting Metrics | B15: =COUNTA('Reporting Metrics'!A4:A6) | C15: =COUNTIF('Reporting Metrics'!D4:D6,"Compliant") | D15: =COUNTIF('Reporting Metrics'!D4:D6,"Partial") | E15: =COUNTIF('Reporting Metrics'!D4:D6,"Non-Compliant") | F15: =COUNTIF('Reporting Metrics'!D4:D6,"N/A") | G15: =IF((B15-F15)=0,"N/A",ROUND(C15/(B15-F15)*100,1)&"%") | H15: =B15-(C15+D15+E15+F15)
A16: Remote Work Compliance Verif | B16: =COUNTA('Remote Work Compliance Verif'!A4:A4) | C16: =COUNTIF('Remote Work Compliance Verif'!D4:D4,"Compliant") | D16: =COUNTIF('Remote Work Compliance Verif'!D4:D4,"Partial") | E16: =COUNTIF('Remote Work Compliance Verif'!D4:D4,"Non-Compliant") | F16: =COUNTIF('Remote Work Compliance Verif'!D4:D4,"N/A") | G16: =IF((B16-F16)=0,"N/A",ROUND(C16/(B16-F16)*100,1)&"%") | H16: =B16-(C16+D16+E16+F16)
A17: TOTAL | B17: =SUM(B4:B16) | C17: =SUM(C4:C16) | D17: =SUM(D4:D16) | E17: =SUM(E4:E16) | F17: =SUM(F4:F16) | G17: =IF((B17-F17)=0,"N/A",ROUND(C17/(B17-F17)*100,1)&"%") | H17: =SUM(H4:H16)
A19: COMPLIANCE BY STATUS
A20: Compliant | B20: =C17 | C20: =IF(B17=0,"",ROUND(B20/B17*100,1)&"%")
A21: Partial | B21: =D17 | C21: =IF(B17=0,"",ROUND(B21/B17*100,1)&"%")
A22: Non-Compliant | B22: =E17 | C22: =IF(B17=0,"",ROUND(B22/B17*100,1)&"%")
A23: N/A | B23: =F17 | C23: =IF(B17=0,"",ROUND(B23/B17*100,1)&"%")
A25: TOP GAPS (Manual Entry)
A26: Priority | B26: Domain | C26: Requirement | D26: Owner | E26: Due Date | F26: Status
A38: COMPLIANCE TREND (Manual Entry)
A39: Assessment Date | B39: Overall % | C39: Compliant | D39: Gaps | E39: Assessor | F39: Notes

Sheet Remote Work Authorisation
A1: Remote Work Authorisation — Compliance Checklist
A2: ISO/IEC 27001:2022 — Controls A.6.7-8: Remote Working and Security Event Reporting
A3: Req # | B3: Section | C3: Requirement | D3: Status | E3: Evidence | F3: Owner | G3: Due Date | H3: Notes
A4: A.6.7-8-01 | B4: Regular Remote Work Arrangements | C4: All regular remote work arrangements shall be formally approved before commencement.
A5: A.6.7-8-02 | B5: Risk Assessment: A Risk Assessment | C5: Risk assessment: A risk assessment shall be performed for roles that handle Confidential or Restricted data remotely. The assessment shall evaluate at minimum: (a) classification level of data accessed remotely; (b) physical security capability of the remote location; (c) network security posture at the remote site; (d) device security baseline compliance; and (e) any regulatory or contractual restrictions.
A6: A.6.7-8-03 | B6: Documented Acknowledgment: Remote | C6: Documented acknowledgment: Remote workers shall sign an acknowledgment confirming they understand and accept the security requirements in this policy.
A7: A.6.7-8-04 | B7: Annual Review: All Remote Work | C7: Annual review: All remote work authorisations shall be reviewed at least annually. Reviews shall confirm that the authorisation remains appropriate, security requirements are maintained, and any changes to role, data access, or work location are reflected.
A8: A.6.7-8-05 | B8: Location Changes: Permanent Changes To | C8: Location changes: Permanent changes to remote work location (e.g., move to new home, extended travel) shall be reported to line manager and IT Security within 14 days*.
A9: A.6.7-8-06 | B9: Revocation*: Remote Work Authorisation | C9: Revocation*: Remote work authorisation shall be revoked when employment or contract terminates, the role changes to one unsuitable for remote work, security requirements are not maintained, policy violations occur, or business needs require on-premises presence.

Sheet Mobile Device Reg and Resp
A1: Mobile Device Reg and Resp — Compliance Checklist
A2: ISO/IEC 27001:2022 — Controls A.6.7-8: Remote Working and Security Event Reporting
A3: Req # | B3: Section | C3: Requirement | D3: Status | E3: Evidence | F3: Owner | G3: Due Date | H3: Notes
A4: A.6.7-8-07 | B4: Mobile Devices Issued Or Approved For | C4: Mobile devices issued or approved for remote work shall be recorded in the asset register and assigned to a named individual.
A5: A.6.7-8-08 | B5: Mobile Devices (Corporate And Approved | C5: All mobile devices (corporate and approved BYOD) shall be registered in the asset register with the assigned owner, device type, serial number, and purpose.
A6: A.6.7-8-09 | B6: Assigned Owners | C6: Assigned owners shall receive a copy of this policy and be informed of their responsibilities.
A7: A.6.7-8-10 | B7: Have Appropriate Encryption, | C7: Devices shall have appropriate encryption, anti-virus/endpoint protection, and access controls installed.

Sheet Remote Wipe and Backup
A1: Remote Wipe and Backup — Compliance Checklist
A2: ISO/IEC 27001:2022 — Controls A.6.7-8: Remote Working and Security Event Reporting
A3: Req # | B3: Section | C3: Requirement | D3: Status | E3: Evidence | F3: Owner | G3: Due Date | H3: Notes
A4: A.6.7-8-11 | B4: Remote Wipe: All Corporate Mobile | C4: Remote wipe: All corporate mobile devices shall have remote wipe capability enabled before the device is issued to the user. Automatic lockout shall be enabled (maximum 5 failed authentication attempts).
A5: A.6.7-8-12 | B5: Backup: Mobile Devices Are Not Backed | C5: Backup: Mobile devices are not backed up by default to corporate backup solutions. Users shall store work files in approved cloud or network locations (e.g., SharePoint, OneDrive for Business, approved file server). Critical work data shall not reside solely on local device storage.

Sheet Physical Security
A1: Physical Security — Compliance Checklist
A2: ISO/IEC 27001:2022 — Controls A.6.7-8: Remote Working and Security Event Reporting
A3: Req # | B3: Section | C3: Requirement | D3: Status | E3: Evidence | F3: Owner | G3: Due Date | H3: Notes
A4: A.6.7-8-13 | B4: Remote Workers | C4: Remote workers shall maintain physical security appropriate to the classification of information being handled:.
A5: A.6.7-8-14 | B5: Clear Desk: The Clear Desk Policy | C5: Clear desk: The clear desk policy (A.7.7 — see Physical and Environmental Security Policy) extends to remote work environments. Sensitive documents shall not be left visible when not actively in use. Work materials shall be secured at the end of each work session.
A6: A.6.7-8-15 | B6: Document Disposal: Sensitive Documents | C6: Document disposal: Sensitive documents shall be disposed of using approved methods (shredding). Where a shredder is not available at the remote location, sensitive documents shall be returned to the office for secure disposal.

Sheet Technical Security
A1: Technical Security — Compliance Checklist
A2: ISO/IEC 27001:2022 — Controls A.6.7-8: Remote Working and Security Event Reporting
A3: Req # | B3: Section | C3: Requirement | D3: Status | E3: Evidence | F3: Owner | G3: Due Date | H3: Notes
A4: A.6.7-8-16 | B4: The Following Technical Security | C4: The following technical security controls shall apply to all remote access:.
A5: A.6.7-8-17 | B5: Vpn Or Zero Trust: All Connections | C5: VPN or Zero Trust: All connections to internal organisational resources shall use a VPN or equivalent Zero Trust architecture. Split tunnelling may be permitted only where a risk assessment demonstrates acceptable residual risk and all organisational resources are accessed via the encrypted tunnel.
A6: A.6.7-8-18 | B6: Multi-Factor Authentication (Mfa): Mfa | C6: Multi-factor authentication (MFA): MFA shall be required for all remote access to organisational systems. This includes VPN connections, cloud services, email, and any system containing Internal, Confidential, or Restricted data.
A7: A.6.7-8-19 | B7: Encryption In Transit: All Data | C7: Encryption in transit: All data transmitted between remote endpoints and organisational systems shall be encrypted using TLS 1.2 as a minimum (TLS 1.3 preferred).
A8: A.6.7-8-20 | B8: Wi-Fi Security: Remote Workers | C8: Wi-Fi security: Remote workers shall use only secure, encrypted wireless networks (WPA2 minimum, WPA3 preferred).
A9: A.6.7-8-21 | B9: Prohibited Without Vpn: Public, | C9: Prohibited without VPN: Public, unsecured Wi-Fi (airports, hotels, cafes) shall not be used for organisational work without VPN protection.
A10: A.6.7-8-22 | B10: Session Timeout: Remote Access Sessions | C10: Session timeout: Remote access sessions shall be configured to disconnect after a defined period of inactivity (maximum 15 minutes for systems handling Confidential or Restricted data; maximum 30 minutes for other systems).

Sheet Data Handling
A1: Data Handling — Compliance Checklist
A2: ISO/IEC 27001:2022 — Controls A.6.7-8: Remote Working and Security Event Reporting
A3: Req # | B3: Section | C3: Requirement | D3: Status | E3: Evidence | F3: Owner | G3: Due Date | H3: Notes
A4: A.6.7-8-23 | B4: Remote Workers | C4: Remote workers shall handle data according to its classification level per the Information Classification and Handling Policy:.
A5: A.6.7-8-24 | B5: Remote Workers | C5: Remote workers shall follow the Information Transfer Policy when sending or receiving organisational data from remote locations. Organisational data shall not be transferred to personal cloud storage, personal email accounts, or unapproved file sharing services.

Sheet Corporate and BYOD Device Reqs
A1: Corporate and BYOD Device Reqs — Compliance Checklist
A2: ISO/IEC 27001:2022 — Controls A.6.7-8: Remote Working and Security Event Reporting
A3: Req # | B3: Section | C3: Requirement | D3: Status | E3: Evidence | F3: Owner | G3: Due Date | H3: Notes
A4: A.6.7-8-25 | B4: Corporate-Issued Devices Used For Remote | C4: Corporate-issued devices used for remote work shall:.
A5: A.6.7-8-26 | B5: The Device | C5: The device shall be registered in the asset register.
A6: A.6.7-8-27 | B6: The User | C6: The user shall receive training and sign an acknowledgment of responsibility.
A7: A.6.7-8-28 | B7: Organisation Policies | C7: All organisation policies, including this policy and the Access Control Policy, shall apply.
A8: A.6.7-8-29 | B8: An Mdm (Mobile Device Management) Or | C8: An MDM (mobile device management) or containerisation solution shall be installed to separate personal and organisational data.
A9: A.6.7-8-30 | B9: No Personal Data Or Sensitive Personal | C9: No personal data or sensitive personal data (per nFADP) shall be stored on the device outside the managed container.
A10: A.6.7-8-31 | B10: The Following | C10: The following shall not be used for organisational work:.

Sheet Remote Work Termination
A1: Remote Work Termination — Compliance Checklist
A2: ISO/IEC 27001:2022 — Controls A.6.7-8: Remote Working and Security Event Reporting
A3: Req # | B3: Section | C3: Requirement | D3: Status | E3: Evidence | F3: Owner | G3: Due Date | H3: Notes
A4: A.6.7-8-32 | B4: Remote Access Credentials | C4: Remote access credentials shall be revoked immediately (same day).
A5: A.6.7-8-33 | B5: Vpn And Remote Access Tokens | C5: VPN and remote access tokens shall be disabled.
A6: A.6.7-8-34 | B6: Organisational Equipment | C6: All organisational equipment shall be returned per the Return of Assets Policy (A.5.11).
A7: A.6.7-8-35 | B7: Organisational Data | C7: All organisational data shall be removed from personal devices. For BYOD devices, the MDM remote wipe of the organisational container shall be executed.
A8: A.6.7-8-36 | B8: Return And Data Removal | C8: Return and data removal shall be verified and documented.

Sheet Reporting Channels
A1: Reporting Channels — Compliance Checklist
A2: ISO/IEC 27001:2022 — Controls A.6.7-8: Remote Working and Security Event Reporting
A3: Req # | B3: Section | C3: Requirement | D3: Status | E3: Evidence | F3: Owner | G3: Due Date | H3: Notes
A4: A.6.7-8-37 | B4: Provide Accessible Mechanisms For All | C4: The organisation shall provide accessible mechanisms for all personnel to report observed or suspected information security events.
A5: A.6.7-8-38 | B5: At Least Two Distinct Reporting Channels | C5: At least two distinct reporting channels shall be available.
A6: A.6.7-8-39 | B6: At Least One Channel | C6: At least one channel shall be available outside business hours (24/7).
A7: A.6.7-8-40 | B7: Be Accessible From Remote Locations | C7: All channels shall be accessible from remote locations without requiring access to internal systems (to allow reporting of access-related events).
A8: A.6.7-8-41 | B8: Publication*: Reporting Channels | C8: Publication*: Reporting channels shall be published on the intranet, included in employee onboarding materials, referenced in annual security awareness training, and displayed on login screens or desktop wallpapers.

Sheet Non-Blame Culture
A1: Non-Blame Culture — Compliance Checklist
A2: ISO/IEC 27001:2022 — Controls A.6.7-8: Remote Working and Security Event Reporting
A3: Req # | B3: Section | C3: Requirement | D3: Status | E3: Evidence | F3: Owner | G3: Due Date | H3: Notes
A4: A.6.7-8-42 | B4: Recognise And Encourage Exemplary | C4: The organisation shall recognise and encourage exemplary reporting behaviour. Reported events shall be used as learning opportunities, not as triggers for punishment.

Sheet Response and Feedback
A1: Response and Feedback — Compliance Checklist
A2: ISO/IEC 27001:2022 — Controls A.6.7-8: Remote Working and Security Event Reporting
A3: Req # | B3: Section | C3: Requirement | D3: Status | E3: Evidence | F3: Owner | G3: Due Date | H3: Notes
A4: A.6.7-8-43 | B4: Respond To All Security Event Reports | C4: The organisation shall respond to all security event reports within defined timeframes:.
A5: A.6.7-8-44 | B5: The Organisation | C5: The organisation shall:.

Sheet Reporting Metrics
A1: Reporting Metrics — Compliance Checklist
A2: ISO/IEC 27001:2022 — Controls A.6.7-8: Remote Working and Security Event Reporting
A3: Req # | B3: Section | C3: Requirement | D3: Status | E3: Evidence | F3: Owner | G3: Due Date | H3: Notes
A4: A.6.7-8-45 | B4: Track The Following Security Event | C4: The organisation shall track the following security event reporting metrics:.
A5: A.6.7-8-46 | B5: Be Reported To The Ciso Monthly | C5: Metrics shall be reported to the CISO monthly and to the Management Review Team quarterly.
A6: A.6.7-8-47 | B6: Event Reporting Kpis Integrated Into | C6: Event reporting KPIs integrated into awareness training*: Annual training shall include reporting volume and success stories to reinforce the non-blame culture.

Sheet Remote Work Compliance Verif
A1: Remote Work Compliance Verif — Compliance Checklist
A2: ISO/IEC 27001:2022 — Controls A.6.7-8: Remote Working and Security Event Reporting
A3: Req # | B3: Section | C3: Requirement | D3: Status | E3: Evidence | F3: Owner | G3: Due Date | H3: Notes
A4: A.6.7-8-48 | B4: Remote Work Security Compliance | C4: Remote work security compliance shall be verified through:.
