Workbook

Sheet Executive Summary
A1: ISMS-OP-CHK-A.6.3 — Information Security Awareness and Training Compliance Checklist
A3: DOCUMENT INFORMATION
A4: Document ID | B4: ISMS-OP-CHK-A.6.3
A5: Source Policy | B5: ISMS-OP-POL-A.6.3
A6: ISO Controls | B6: Information Security Awareness and Training
A7: Generated | B7: 30.09.2026
A8: Prepared By
A9: Organisation
A10: Review Cycle | B10: Annual
A12: OVERALL COMPLIANCE STATUS
A13: Overall Compliance | B13: ='Dashboard'!G13
A14: Status | B14: =IF(Dashboard!H13>0,"INCOMPLETE",IF(Dashboard!G13="N/A","NOT ASSESSED",IF(ISNUMBER(VALUE(SUBSTITUTE(Dashboard!G13,"%",""))),IF(VALUE(SUBSTITUTE(Dashboard!G13,"%",""))>=90,"GREEN",IF(VALUE(SUBSTITUTE(Dashboard!G13,"%",""))>=70,"AMBER","RED")),"NOT ASSESSED")))
A16: KEY METRICS
A17: Total Requirements | B17: ='Dashboard'!B13
A18: Compliant | B18: ='Dashboard'!C13
A19: Partial | B19: ='Dashboard'!D13
A20: Non-Compliant | B20: ='Dashboard'!E13
A21: Not Applicable | B21: ='Dashboard'!F13
A22: Unanswered | B22: ='Dashboard'!H13
A23: Owner Coverage | B23: =IF(Dashboard!B13=0,"N/A",ROUND((COUNTA('Awareness & Training Programme'!F4:F4)+COUNTA('Training Topics'!F4:F4)+COUNTA('Training Schedule'!F4:F8)+COUNTA('Phishing Simulation Programme'!F4:F10)+COUNTA('Assessment and Acknowledgement'!F4:F7)+COUNTA('Training Records'!F4:F6)+COUNTA('Training Content Updates'!F4:F5)+COUNTA('Training Effectiveness Metrics'!F4:F4)+COUNTA('Language and Accessibility'!F4:F7))/Dashboard!B13*100,0)&"%")
A25: DOMAIN STATUS SUMMARY
A26: Domain | B26: Compliance % | C26: Compliant | D26: Gaps | E26: Status
A27: Awareness & Training Programme | B27: ='Dashboard'!G4 | C27: ='Dashboard'!C4 | D27: ='Dashboard'!E4 | E27: =IF(Dashboard!H4>0,"INCOMPLETE",IF(Dashboard!G4="N/A","--",IF(ISNUMBER(VALUE(SUBSTITUTE(Dashboard!G4,"%",""))),IF(VALUE(SUBSTITUTE(Dashboard!G4,"%",""))>=90,"PASS",IF(VALUE(SUBSTITUTE(Dashboard!G4,"%",""))>=70,"REVIEW","FAIL")),"--")))
A28: Training Topics | B28: ='Dashboard'!G5 | C28: ='Dashboard'!C5 | D28: ='Dashboard'!E5 | E28: =IF(Dashboard!H5>0,"INCOMPLETE",IF(Dashboard!G5="N/A","--",IF(ISNUMBER(VALUE(SUBSTITUTE(Dashboard!G5,"%",""))),IF(VALUE(SUBSTITUTE(Dashboard!G5,"%",""))>=90,"PASS",IF(VALUE(SUBSTITUTE(Dashboard!G5,"%",""))>=70,"REVIEW","FAIL")),"--")))
A29: Training Schedule | B29: ='Dashboard'!G6 | C29: ='Dashboard'!C6 | D29: ='Dashboard'!E6 | E29: =IF(Dashboard!H6>0,"INCOMPLETE",IF(Dashboard!G6="N/A","--",IF(ISNUMBER(VALUE(SUBSTITUTE(Dashboard!G6,"%",""))),IF(VALUE(SUBSTITUTE(Dashboard!G6,"%",""))>=90,"PASS",IF(VALUE(SUBSTITUTE(Dashboard!G6,"%",""))>=70,"REVIEW","FAIL")),"--")))
A30: Phishing Simulation Programme | B30: ='Dashboard'!G7 | C30: ='Dashboard'!C7 | D30: ='Dashboard'!E7 | E30: =IF(Dashboard!H7>0,"INCOMPLETE",IF(Dashboard!G7="N/A","--",IF(ISNUMBER(VALUE(SUBSTITUTE(Dashboard!G7,"%",""))),IF(VALUE(SUBSTITUTE(Dashboard!G7,"%",""))>=90,"PASS",IF(VALUE(SUBSTITUTE(Dashboard!G7,"%",""))>=70,"REVIEW","FAIL")),"--")))
A31: Assessment and Acknowledgement | B31: ='Dashboard'!G8 | C31: ='Dashboard'!C8 | D31: ='Dashboard'!E8 | E31: =IF(Dashboard!H8>0,"INCOMPLETE",IF(Dashboard!G8="N/A","--",IF(ISNUMBER(VALUE(SUBSTITUTE(Dashboard!G8,"%",""))),IF(VALUE(SUBSTITUTE(Dashboard!G8,"%",""))>=90,"PASS",IF(VALUE(SUBSTITUTE(Dashboard!G8,"%",""))>=70,"REVIEW","FAIL")),"--")))
A32: Training Records | B32: ='Dashboard'!G9 | C32: ='Dashboard'!C9 | D32: ='Dashboard'!E9 | E32: =IF(Dashboard!H9>0,"INCOMPLETE",IF(Dashboard!G9="N/A","--",IF(ISNUMBER(VALUE(SUBSTITUTE(Dashboard!G9,"%",""))),IF(VALUE(SUBSTITUTE(Dashboard!G9,"%",""))>=90,"PASS",IF(VALUE(SUBSTITUTE(Dashboard!G9,"%",""))>=70,"REVIEW","FAIL")),"--")))
A33: Training Content Updates | B33: ='Dashboard'!G10 | C33: ='Dashboard'!C10 | D33: ='Dashboard'!E10 | E33: =IF(Dashboard!H10>0,"INCOMPLETE",IF(Dashboard!G10="N/A","--",IF(ISNUMBER(VALUE(SUBSTITUTE(Dashboard!G10,"%",""))),IF(VALUE(SUBSTITUTE(Dashboard!G10,"%",""))>=90,"PASS",IF(VALUE(SUBSTITUTE(Dashboard!G10,"%",""))>=70,"REVIEW","FAIL")),"--")))
A34: Training Effectiveness Metrics | B34: ='Dashboard'!G11 | C34: ='Dashboard'!C11 | D34: ='Dashboard'!E11 | E34: =IF(Dashboard!H11>0,"INCOMPLETE",IF(Dashboard!G11="N/A","--",IF(ISNUMBER(VALUE(SUBSTITUTE(Dashboard!G11,"%",""))),IF(VALUE(SUBSTITUTE(Dashboard!G11,"%",""))>=90,"PASS",IF(VALUE(SUBSTITUTE(Dashboard!G11,"%",""))>=70,"REVIEW","FAIL")),"--")))
A35: Language and Accessibility | B35: ='Dashboard'!G12 | C35: ='Dashboard'!C12 | D35: ='Dashboard'!E12 | E35: =IF(Dashboard!H12>0,"INCOMPLETE",IF(Dashboard!G12="N/A","--",IF(ISNUMBER(VALUE(SUBSTITUTE(Dashboard!G12,"%",""))),IF(VALUE(SUBSTITUTE(Dashboard!G12,"%",""))>=90,"PASS",IF(VALUE(SUBSTITUTE(Dashboard!G12,"%",""))>=70,"REVIEW","FAIL")),"--")))
A37: CRITICAL ISSUES
A38: # | B38: Issue Description | C38: Domain | D38: Owner | E38: Due Date
A39: 1
A40: 2
A41: 3
A42: 4
A43: 5
A45: MANAGEMENT COMMENTARY
A46: [Enter management commentary on information security awareness and training posture]
...

Sheet Dashboard
A1: Information Security Awareness and Training — Compliance Dashboard
A3: Domain | B3: Total Reqs | C3: Compliant | D3: Partial | E3: Non-Compliant | F3: N/A | G3: Compliance % | H3: Unassessed
A4: Awareness & Training Programme | B4: =COUNTA('Awareness & Training Programme'!A4:A4) | C4: =COUNTIF('Awareness & Training Programme'!D4:D4,"Compliant") | D4: =COUNTIF('Awareness & Training Programme'!D4:D4,"Partial") | E4: =COUNTIF('Awareness & Training Programme'!D4:D4,"Non-Compliant") | F4: =COUNTIF('Awareness & Training Programme'!D4:D4,"N/A") | G4: =IF((B4-F4)=0,"N/A",ROUND(C4/(B4-F4)*100,1)&"%") | H4: =B4-(C4+D4+E4+F4)
A5: Training Topics | B5: =COUNTA('Training Topics'!A4:A4) | C5: =COUNTIF('Training Topics'!D4:D4,"Compliant") | D5: =COUNTIF('Training Topics'!D4:D4,"Partial") | E5: =COUNTIF('Training Topics'!D4:D4,"Non-Compliant") | F5: =COUNTIF('Training Topics'!D4:D4,"N/A") | G5: =IF((B5-F5)=0,"N/A",ROUND(C5/(B5-F5)*100,1)&"%") | H5: =B5-(C5+D5+E5+F5)
A6: Training Schedule | B6: =COUNTA('Training Schedule'!A4:A8) | C6: =COUNTIF('Training Schedule'!D4:D8,"Compliant") | D6: =COUNTIF('Training Schedule'!D4:D8,"Partial") | E6: =COUNTIF('Training Schedule'!D4:D8,"Non-Compliant") | F6: =COUNTIF('Training Schedule'!D4:D8,"N/A") | G6: =IF((B6-F6)=0,"N/A",ROUND(C6/(B6-F6)*100,1)&"%") | H6: =B6-(C6+D6+E6+F6)
A7: Phishing Simulation Programme | B7: =COUNTA('Phishing Simulation Programme'!A4:A10) | C7: =COUNTIF('Phishing Simulation Programme'!D4:D10,"Compliant") | D7: =COUNTIF('Phishing Simulation Programme'!D4:D10,"Partial") | E7: =COUNTIF('Phishing Simulation Programme'!D4:D10,"Non-Compliant") | F7: =COUNTIF('Phishing Simulation Programme'!D4:D10,"N/A") | G7: =IF((B7-F7)=0,"N/A",ROUND(C7/(B7-F7)*100,1)&"%") | H7: =B7-(C7+D7+E7+F7)
A8: Assessment and Acknowledgement | B8: =COUNTA('Assessment and Acknowledgement'!A4:A7) | C8: =COUNTIF('Assessment and Acknowledgement'!D4:D7,"Compliant") | D8: =COUNTIF('Assessment and Acknowledgement'!D4:D7,"Partial") | E8: =COUNTIF('Assessment and Acknowledgement'!D4:D7,"Non-Compliant") | F8: =COUNTIF('Assessment and Acknowledgement'!D4:D7,"N/A") | G8: =IF((B8-F8)=0,"N/A",ROUND(C8/(B8-F8)*100,1)&"%") | H8: =B8-(C8+D8+E8+F8)
A9: Training Records | B9: =COUNTA('Training Records'!A4:A6) | C9: =COUNTIF('Training Records'!D4:D6,"Compliant") | D9: =COUNTIF('Training Records'!D4:D6,"Partial") | E9: =COUNTIF('Training Records'!D4:D6,"Non-Compliant") | F9: =COUNTIF('Training Records'!D4:D6,"N/A") | G9: =IF((B9-F9)=0,"N/A",ROUND(C9/(B9-F9)*100,1)&"%") | H9: =B9-(C9+D9+E9+F9)
A10: Training Content Updates | B10: =COUNTA('Training Content Updates'!A4:A5) | C10: =COUNTIF('Training Content Updates'!D4:D5,"Compliant") | D10: =COUNTIF('Training Content Updates'!D4:D5,"Partial") | E10: =COUNTIF('Training Content Updates'!D4:D5,"Non-Compliant") | F10: =COUNTIF('Training Content Updates'!D4:D5,"N/A") | G10: =IF((B10-F10)=0,"N/A",ROUND(C10/(B10-F10)*100,1)&"%") | H10: =B10-(C10+D10+E10+F10)
A11: Training Effectiveness Metrics | B11: =COUNTA('Training Effectiveness Metrics'!A4:A4) | C11: =COUNTIF('Training Effectiveness Metrics'!D4:D4,"Compliant") | D11: =COUNTIF('Training Effectiveness Metrics'!D4:D4,"Partial") | E11: =COUNTIF('Training Effectiveness Metrics'!D4:D4,"Non-Compliant") | F11: =COUNTIF('Training Effectiveness Metrics'!D4:D4,"N/A") | G11: =IF((B11-F11)=0,"N/A",ROUND(C11/(B11-F11)*100,1)&"%") | H11: =B11-(C11+D11+E11+F11)
A12: Language and Accessibility | B12: =COUNTA('Language and Accessibility'!A4:A7) | C12: =COUNTIF('Language and Accessibility'!D4:D7,"Compliant") | D12: =COUNTIF('Language and Accessibility'!D4:D7,"Partial") | E12: =COUNTIF('Language and Accessibility'!D4:D7,"Non-Compliant") | F12: =COUNTIF('Language and Accessibility'!D4:D7,"N/A") | G12: =IF((B12-F12)=0,"N/A",ROUND(C12/(B12-F12)*100,1)&"%") | H12: =B12-(C12+D12+E12+F12)
A13: TOTAL | B13: =SUM(B4:B12) | C13: =SUM(C4:C12) | D13: =SUM(D4:D12) | E13: =SUM(E4:E12) | F13: =SUM(F4:F12) | G13: =IF((B13-F13)=0,"N/A",ROUND(C13/(B13-F13)*100,1)&"%") | H13: =SUM(H4:H12)
A15: COMPLIANCE BY STATUS
A16: Compliant | B16: =C13 | C16: =IF(B13=0,"",ROUND(B16/B13*100,1)&"%")
A17: Partial | B17: =D13 | C17: =IF(B13=0,"",ROUND(B17/B13*100,1)&"%")
A18: Non-Compliant | B18: =E13 | C18: =IF(B13=0,"",ROUND(B18/B13*100,1)&"%")
A19: N/A | B19: =F13 | C19: =IF(B13=0,"",ROUND(B19/B13*100,1)&"%")
A21: TOP GAPS (Manual Entry)
A22: Priority | B22: Domain | C22: Requirement | D22: Owner | E22: Due Date | F22: Status
A34: COMPLIANCE TREND (Manual Entry)
A35: Assessment Date | B35: Overall % | C35: Compliant | D35: Gaps | E35: Assessor | F35: Notes

Sheet Awareness & Training Programme
A1: Awareness & Training Programme — Compliance Checklist
A2: ISO/IEC 27001:2022 — Control A.6.3: Information Security Awareness and Training
A3: Req # | B3: Section | C3: Requirement | D3: Status | E3: Evidence | F3: Owner | G3: Due Date | H3: Notes
A4: A.6.3-01 | B4: Executive Management | C4: Executive management shall visibly support and promote the information security awareness and training programme. This includes endorsing training requirements, allocating resources, and setting the expectation that all personnel complete required training.

Sheet Training Topics
A1: Training Topics — Compliance Checklist
A2: ISO/IEC 27001:2022 — Control A.6.3: Information Security Awareness and Training
A3: Req # | B3: Section | C3: Requirement | D3: Status | E3: Evidence | F3: Owner | G3: Due Date | H3: Notes
A4: A.6.3-02 | B4: The Following Topics | C4: The following topics shall be covered in baseline security awareness training:.

Sheet Training Schedule
A1: Training Schedule — Compliance Checklist
A2: ISO/IEC 27001:2022 — Control A.6.3: Information Security Awareness and Training
A3: Req # | B3: Section | C3: Requirement | D3: Status | E3: Evidence | F3: Owner | G3: Due Date | H3: Notes
A4: A.6.3-03 | B4: Information Security Awareness Training | C4: Information security awareness training shall be provided to new starters before they are granted access to systems that process, store, or transmit confidential or personal data. Training shall be completed within 5 business days of the start date.
A5: A.6.3-04 | B5: The Information Security Policy And | C5: The information security policy and acceptable use policy shall be provided to new starters as part of the onboarding process. Acknowledgement of these policies shall be obtained before system access is granted.
A6: A.6.3-05 | B6: General Information Security Awareness | C6: General information security awareness training shall be conducted for all employees at least annually. Training shall be refreshed to reflect current threats, policy changes, and lessons learned from incidents.
A7: A.6.3-06 | B7: Information Security Awareness | C7: Information security awareness shall be reinforced throughout the year using a variety of methods:.
A8: A.6.3-07 | B8: Additional Training | C8: When an employee's role changes significantly or their access to data types changes, additional training shall be provided appropriate to the new role and its associated risks.

Sheet Phishing Simulation Programme
A1: Phishing Simulation Programme — Compliance Checklist
A2: ISO/IEC 27001:2022 — Control A.6.3: Information Security Awareness and Training
A3: Req # | B3: Section | C3: Requirement | D3: Status | E3: Evidence | F3: Owner | G3: Due Date | H3: Notes
A4: A.6.3-08 | B4: Conduct A Phishing Simulation Programme | C4: The organisation shall conduct a phishing simulation programme to assess and improve employee resilience to social engineering attacks.
A5: A.6.3-09 | B5: Use Realistic, Work-Relevant Scenarios | C5: Simulations shall use realistic, work-relevant scenarios (e.g., delivery notifications, meeting invitations, password reset requests) — not deceptive or humiliating content.
A6: A.6.3-10 | B6: Employees Who Interact With Simulated | C6: Employees who interact with simulated phishing shall receive immediate feedback explaining what was suspicious and how to recognise similar attacks.
A7: A.6.3-11 | B7: The Programme Is Educational, Not | C7: The programme is educational, not punitive. Simulation results shall be used to identify training needs, not for disciplinary action.
A8: A.6.3-12 | B8: Employees Who Report Simulated Phishing | C8: Employees who report simulated phishing shall be positively recognised.
A9: A.6.3-13 | B9: Simulation Difficulty | C9: Simulation difficulty shall be gradually increased over time.
A10: A.6.3-14 | B10: A Single, Standardised Method For | C10: A single, standardised method for reporting suspected phishing shall be provided to all employees (e.g., a 'Report Phishing' button in the email client). Employees shall be trained to use this reporting mechanism.

Sheet Assessment and Acknowledgement
A1: Assessment and Acknowledgement — Compliance Checklist
A2: ISO/IEC 27001:2022 — Control A.6.3: Information Security Awareness and Training
A3: Req # | B3: Section | C3: Requirement | D3: Status | E3: Evidence | F3: Owner | G3: Due Date | H3: Notes
A4: A.6.3-15 | B4: Be Assessed On Their Understanding Of | C4: Employees shall be assessed on their understanding of information security at the completion of awareness training. Assessment may include quizzes, scenario-based questions, or practical exercises.
A5: A.6.3-16 | B5: The Minimum Passing Score For All | C5: The minimum passing score for all assessments shall be 80%. Employees who do not achieve the passing score shall be required to repeat the training within 10 business days. Two consecutive failures shall be escalated to the employee's line manager for additional support.
A6: A.6.3-17 | B6: Formally Acknowledge That They Have | C6: All employees shall formally acknowledge that they have received training and understand their information security responsibilities. Acknowledgement shall be recorded and retained.
A7: A.6.3-18 | B7: New Starters | C7: New starters shall acknowledge the information security policy and acceptable use policy during onboarding before system access is granted.

Sheet Training Records
A1: Training Records — Compliance Checklist
A2: ISO/IEC 27001:2022 — Control A.6.3: Information Security Awareness and Training
A3: Req # | B3: Section | C3: Requirement | D3: Status | E3: Evidence | F3: Owner | G3: Due Date | H3: Notes
A4: A.6.3-19 | B4: A Register Of Information Security | C4: A register of information security training and competency shall be maintained for all employees. The register shall record:.
A5: A.6.3-20 | B5: Training Records | C5: Training records shall be retained for the duration of employment plus 2 years after departure.
A6: A.6.3-21 | B6: Training Completion Rates | C6: Training completion rates shall be monitored. Non-completion shall be escalated:.

Sheet Training Content Updates
A1: Training Content Updates — Compliance Checklist
A2: ISO/IEC 27001:2022 — Control A.6.3: Information Security Awareness and Training
A3: Req # | B3: Section | C3: Requirement | D3: Status | E3: Evidence | F3: Owner | G3: Due Date | H3: Notes
A4: A.6.3-22 | B4: Training Content | C4: Training content shall be reviewed and updated in response to:.
A5: A.6.3-23 | B5: Phishing Simulation Results: If Phishing | C5: Phishing simulation results: If phishing metrics breach red thresholds, targeted training content shall be developed within 30 days.

Sheet Training Effectiveness Metrics
A1: Training Effectiveness Metrics — Compliance Checklist
A2: ISO/IEC 27001:2022 — Control A.6.3: Information Security Awareness and Training
A3: Req # | B3: Section | C3: Requirement | D3: Status | E3: Evidence | F3: Owner | G3: Due Date | H3: Notes
A4: A.6.3-24 | B4: The Information Security Management Team | C4: The information security management team shall measure the effectiveness of the awareness and training programme using the following framework:.

Sheet Language and Accessibility
A1: Language and Accessibility — Compliance Checklist
A2: ISO/IEC 27001:2022 — Control A.6.3: Information Security Awareness and Training
A3: Req # | B3: Section | C3: Requirement | D3: Status | E3: Evidence | F3: Owner | G3: Due Date | H3: Notes
A4: A.6.3-25 | B4: Training Materials | C4: Training materials shall be provided in the languages used within the organisation, reflecting Switzerland's multilingual context:.
A5: A.6.3-26 | B5: Primary Language: Training | C5: Primary language: Training shall be available in the organisation's primary business language.
A6: A.6.3-27 | B6: Additional Languages: Where The | C6: Additional languages: Where the workforce includes employees whose primary language differs from the business language, key training materials (at minimum: annual awareness, onboarding, and phishing reporting instructions) shall be made available in the relevant additional languages (e.g., German, French, Italian, English).
A7: A.6.3-28 | B7: Accessibility: Training Platforms | C7: Accessibility: Training platforms shall support accessibility features (screen readers, subtitles for video content, adjustable text size) where reasonably practicable.
